File: 2024_11_12_DSC_CBD_Xtal_5Cmin_x3.csv
Filename,2024_11_12_DSC_CBD_Xtal_5Cmin_x3
Instrument name,DSC2A-00468 (192.168.1.100)
Operator,Yarger
rundate,11/12/2024
Sample name,2024_11_12_DSC_CBD_Xtal_5Cmin_x3
proceduresegments,Data Off ; Equilibrate -50.00 °C; Data On ; Ramp 5.00 °C/min to 100.00 °C; Data Off ; Isothermal 1.0 min; Data On ; Ramp 5.00 °C/min to -50.00 °C; Data Off ; Isothermal 1.0 min; Data On ; Ramp 5.00 °C/min to 100.00 °C; Data Off ; Isothermal 1.0 min; Data On ; Ramp 5.00 °C/min to -50.00 °C; Data Off ; Isothermal 1.0 min; Data On ; Ramp 5.00 °C/min to 170.00 °C
[File Parameters]
Run date,11/12/2024 5:37:11 PM
Trios version,5.1.1.46572
Original File Name,
Current File Name,D:\DSC2500\JYarger\2024_11_12_DSC_CBD_Xtal_5Cmin_x3.tri
[Procedure]
Procedure Name,CBD Xtalline
Sample Name,2024_11_12_DSC_CBD_Xtal_5Cmin_x3
Sample Mass,5.09 mg
Reference Sample Mass,0 mg
Pan Mass,54.65 mg
Pan Number,14
Reference Pan Mass,53.32 mg
Reference Pan Number,10
Pan Type,Tzero Aluminum Hermetic
Comments,CBD xtal made 08/23 by SBK.  Doesn't show that its been melted or run yet.  Al hermetic Pan/Lid.
Project Name,CoCrystals
Operator,Yarger
Test,Custom
Unload Max Temperature,30
Unload Min Temperature,30
Load Max Temperature,30
Load Min Temperature,30
Stop on Gas Flow Error,Yes
[Signal List]
Signal #1,Time (min)
Signal #2,Temperature (°C)
Signal #3,Heat Flow (mW)
Signal #4,Delta T (µV)
Signal #5,Delta Tzero (µV)
Signal #6,Tzero Temperature (°C)
Signal #7,Cell Purge (mL/min)
Signal #8,Heater Temp (°C)
Signal #9,Power Delivered (W)
Signal #10,Reference Junction Temperature (°C)
Signal #11,Flange Temperature (°C)
Signal #12,Heat Flow Phase (rad)
Signal #13,Total Heat Capacity (J/°C)
Signal #14,Heat Capacity (J/°C)
[Configuration]
Company Name,ASU
Instrument Name,DSC2A-00468
Instrument Type,DSC2500
Serial Number,DSC2A-00468
IP,192.168.1.100
Location of Instrument,MRRC
DisplayType,Unknown
Sample Interval ,0.1 s/pt
Selected Heat Flow,T4P
Exotherm Direction,Down
Cell Serial,DRC2-00792
Lid Type,Standard
Cooler,RCS 90
Leave Cooler on at End of Sequence,On
Gas 2,Nitrogen
Gas Selected,Channel 1
Flow Rate,50 mL/min
Secondary Purge,On
Licensed Heat Flow,Heat Flow T4P
Modulation Licensed,Yes
[Versions]
Common IDD Version,1
Cortex Version,VER 2.10.2.31
Driver,5.0.0.6
GDM Version,1.0.3.3
TouchscreenVersion,1.0.0.16145
FEP Version,1.2.1.21
FEP Bootloader,2.0.0.5
AutoSampler Version,2.1.1.26
Auto Sampler Bootloader,2.0.0.5
FCM Version,1.1.0.3
FCM Bootloader,2.0.0.5
[Experiment Logs]
Experiment Log Entry # 1,Air Cool is off.
Experiment Log Entry # 3,Data On set to 0
Experiment Log Entry # 5,Equilibrate Segment -50 (C) Started
Experiment Log Entry # 7,Data On set to 1
Experiment Log Entry # 9,Ramp Segment 5 C/min to 100 Started
Experiment Log Entry # 11,Data On set to 0
Experiment Log Entry # 13,Isothermal Segment 1 min started
Experiment Log Entry # 15,Data On set to 1
Experiment Log Entry # 17,Ramp Segment 5 C/min to -50 Started
Experiment Log Entry # 19,Data On set to 0
Experiment Log Entry # 21,Isothermal Segment 1 min started
Experiment Log Entry # 23,Data On set to 1
Experiment Log Entry # 25,Ramp Segment 5 C/min to 100 Started
Experiment Log Entry # 27,Data On set to 0
Experiment Log Entry # 29,Isothermal Segment 1 min started
Experiment Log Entry # 31,Data On set to 1
Experiment Log Entry # 33,Ramp Segment 5 C/min to -50 Started
Experiment Log Entry # 35,Data On set to 0
Experiment Log Entry # 37,Isothermal Segment 1 min started
Experiment Log Entry # 39,Data On set to 1
Experiment Log Entry # 41,Ramp Segment 5 C/min to 170 Started
[Method Log]
Method Log Entry # 1,Data Off
Method Log Entry # 2,Equilibrate -50 °C
Method Log Entry # 3,Data On
Method Log Entry # 4,(Ramp 180254) Ramp 5 °C/minute to 100 °C
Method Log Entry # 5,Data Off
Method Log Entry # 6,Isothermal 1 minutes
Method Log Entry # 7,Data On
Method Log Entry # 8,(Ramp 180258) Ramp 5 °C/minute to -50 °C
Method Log Entry # 9,Data Off
Method Log Entry # 10,Isothermal 1 minutes
Method Log Entry # 11,Data On
Method Log Entry # 12,(Ramp 180262) Ramp 5 °C/minute to 100 °C
Method Log Entry # 13,Data Off
Method Log Entry # 14,Isothermal 1 minutes
Method Log Entry # 15,Data On
Method Log Entry # 16,(Ramp 180266) Ramp 5 °C/minute to -50 °C
Method Log Entry # 17,Data Off
Method Log Entry # 18,Isothermal 1 minutes
Method Log Entry # 19,Data On
Method Log Entry # 20,(Ramp 180270) Ramp 5 °C/minute to 170 °C
Cell Serial,DRC2-00792
[T1 Calibration]
Slope,-0.008529666
Offset,9.636258
Initial Temperature,98.23
GUID,f8bfdadc-4977-4fdf-ba6d-0ba9134940c3
[TZero Calibration]
Date Applied,11/29/2022 4:06:13 PM
Description,From -89.059 °C to 396.009 °C at 20.000°C/min
Gas Type,Nitrogen
Pan Type,None
Source Files 1,C:\Users\yargerlab\Desktop\DSC Data\General\TZero_calibration_11_29_22_2nd(2).tri
Source Files 2,C:\Users\yargerlab\Desktop\DSC Data\General\TZero_calibration_11_29_22_2nd(3).tri
Delta T Offset,13.05235
Delta T Slope,-0.007271007
Delta T0 Offset,-13.69128
Delta T0 Slope,0.06063341
[Temperature Calibration]
Date Applied,11/29/2022 7:12:28 PM
Description,From 106.590 °C to 186.590 °C at 10.000°C/min
Gas Type,Nitrogen
Pan Type,Tzero Aluminum Hermetic
Source Files 1,C:\Users\yargerlab\Desktop\DSC Data\General\Indium(6).tri
Measured 1,157.391
Known 1,156.598
[Cell Constant Calibration]
Date Applied,11/29/2022 7:12:29 PM
Description,From 106.590 °C to 186.590 °C at 10.000°C/min
Gas Type,Nitrogen
Pan Type,Tzero Aluminum Hermetic
Source Files 1,C:\Users\yargerlab\Desktop\DSC Data\General\Indium(6).tri
T4P KCell,1.006051
Onset Slope,63.26126 mW/°C
[Direct Cp Calibration]
Date Applied,11/30/2022 11:04:51 AM
Description,From -79.983 °C to 298.409 °C at 10.000°C/min
Gas Type,Nitrogen
Pan Type,Tzero Aluminum Hermetic
Source Files 1,C:\Users\yargerlab\Desktop\DSC Data\General\Sapphire_Heat_Capacity_11_30_22.tri
[Rev Cp Calibration]
Date Applied,11/30/2022 1:58:51 PM
Description,From -79.996 °C to 292.812 °C at 3.000°C/min
Gas Type,Nitrogen
Pan Type,Tzero Aluminum Hermetic
Source Files 1,C:\Users\yargerlab\Desktop\DSC Data\General\Sapphire_MDSC_Calibration_11_30_22.tri
[step]
Ramp 5.00 °C/min to 100.00 °C
Time,Temperature,Heat Flow (Normalized)
min,°C,W/g
0.00,-49.68,-0.064
0.02,-49.70,-0.068
0.04,-49.71,-0.059
0.06,-49.71,-0.054
0.08,-49.70,-0.052
0.10,-49.68,-0.052
0.12,-49.65,-0.051
0.14,-49.61,-0.046
0.16,-49.55,-0.035
0.18,-49.49,-0.022
0.20,-49.42,-0.007
0.22,-49.35,0.007
0.24,-49.27,0.020
0.26,-49.19,0.032
0.28,-49.10,0.044
0.30,-49.01,0.051
0.32,-48.93,0.060
0.34,-48.84,0.066
0.36,-48.75,0.070
0.38,-48.66,0.075
0.40,-48.56,0.079
0.42,-48.47,0.081
0.44,-48.38,0.084
0.46,-48.29,0.086
0.48,-48.19,0.088
0.50,-48.10,0.089
0.52,-48.00,0.090
0.54,-47.90,0.092
0.56,-47.81,0.092
0.58,-47.71,0.093
0.60,-47.62,0.094
0.62,-47.52,0.094
0.64,-47.42,0.095
0.66,-47.33,0.095
0.68,-47.23,0.095
0.70,-47.13,0.096
0.72,-47.03,0.096
0.74,-46.94,0.096
0.76,-46.84,0.097
0.78,-46.74,0.097
0.80,-46.64,0.097
0.82,-46.55,0.098
0.84,-46.45,0.098
0.86,-46.35,0.098
0.88,-46.25,0.098
0.90,-46.15,0.099
0.92,-46.06,0.099
0.94,-45.96,0.099
0.96,-45.86,0.099
0.98,-45.76,0.099
1.00,-45.66,0.100
1.02,-45.56,0.100
1.04,-45.47,0.100
1.06,-45.37,0.100
1.08,-45.27,0.100
1.10,-45.17,0.100
1.12,-45.07,0.100
1.14,-44.97,0.100
1.16,-44.87,0.101
1.18,-44.77,0.101
1.20,-44.67,0.101
1.22,-44.57,0.101
1.24,-44.47,0.101
1.26,-44.38,0.101
1.28,-44.28,0.101
1.30,-44.18,0.101
1.32,-44.08,0.101
1.34,-43.98,0.101
1.36,-43.88,0.101
1.38,-43.78,0.101
1.40,-43.68,0.101
1.42,-43.58,0.101
1.44,-43.48,0.101
1.46,-43.38,0.101
1.48,-43.28,0.101
1.50,-43.18,0.101
1.52,-43.08,0.101
1.54,-42.98,0.101
1.56,-42.89,0.101
1.58,-42.79,0.101
1.60,-42.68,0.101
1.62,-42.58,0.101
1.64,-42.48,0.101
1.66,-42.39,0.101
1.68,-42.29,0.102
1.70,-42.19,0.102
1.72,-42.09,0.102
1.74,-41.99,0.102
1.76,-41.89,0.102
1.78,-41.79,0.102
1.80,-41.69,0.102
1.82,-41.59,0.102
1.84,-41.49,0.102
1.86,-41.39,0.101
1.88,-41.29,0.101
1.90,-41.19,0.101
1.92,-41.09,0.101
1.94,-40.99,0.101
1.96,-40.89,0.101
1.98,-40.79,0.101
2.00,-40.69,0.101
2.02,-40.59,0.101
2.04,-40.49,0.101
2.06,-40.39,0.101
2.08,-40.29,0.101
2.10,-40.19,0.101
2.12,-40.09,0.101
2.14,-39.99,0.101
2.16,-39.89,0.101
2.18,-39.79,0.101
2.20,-39.69,0.101
2.22,-39.59,0.101
2.24,-39.49,0.101
2.26,-39.39,0.101
2.28,-39.29,0.101
2.30,-39.19,0.101
2.32,-39.09,0.101
2.34,-38.99,0.101
2.36,-38.89,0.101
2.38,-38.79,0.101
2.40,-38.69,0.101
2.42,-38.59,0.101
2.44,-38.49,0.101
2.46,-38.39,0.101
2.48,-38.29,0.101
2.50,-38.19,0.101
2.52,-38.09,0.101
2.54,-37.99,0.101
2.56,-37.89,0.101
2.58,-37.79,0.101
2.60,-37.69,0.101
2.62,-37.59,0.101
2.64,-37.49,0.101
2.66,-37.39,0.101
2.68,-37.29,0.101
2.70,-37.19,0.101
2.72,-37.09,0.101
2.74,-36.99,0.101
2.76,-36.89,0.101
2.78,-36.79,0.101
2.80,-36.69,0.101
2.82,-36.59,0.101
2.84,-36.49,0.101
2.86,-36.39,0.101
2.88,-36.29,0.101
2.90,-36.19,0.101
2.92,-36.09,0.101
2.94,-35.99,0.101
2.96,-35.89,0.101
2.98,-35.79,0.101
3.00,-35.69,0.101
3.02,-35.58,0.101
3.04,-35.48,0.101
3.06,-35.39,0.101
3.08,-35.28,0.101
3.10,-35.18,0.101
3.12,-35.08,0.101
3.14,-34.98,0.101
3.16,-34.89,0.101
3.18,-34.79,0.101
3.20,-34.68,0.101
3.22,-34.59,0.101
3.24,-34.48,0.101
3.26,-34.38,0.101
3.28,-34.28,0.101
3.30,-34.18,0.101
3.32,-34.08,0.101
3.34,-33.98,0.101
3.36,-33.88,0.101
3.38,-33.78,0.101
3.40,-33.68,0.101
3.42,-33.58,0.101
3.44,-33.48,0.101
3.46,-33.38,0.101
3.48,-33.28,0.101
3.50,-33.18,0.101
3.52,-33.08,0.101
3.54,-32.98,0.101
3.56,-32.88,0.101
3.58,-32.78,0.101
3.60,-32.68,0.101
3.62,-32.58,0.101
3.64,-32.48,0.101
3.66,-32.38,0.101
3.68,-32.28,0.101
3.70,-32.18,0.101
3.72,-32.08,0.101
3.74,-31.98,0.101
3.76,-31.88,0.101
3.78,-31.78,0.101
3.80,-31.68,0.101
3.82,-31.58,0.101
3.84,-31.48,0.101
3.86,-31.38,0.101
3.88,-31.28,0.101
3.90,-31.18,0.101
3.92,-31.08,0.101
3.94,-30.98,0.101
3.96,-30.88,0.101
3.98,-30.78,0.101
4.00,-30.68,0.101
4.02,-30.58,0.101
4.04,-30.48,0.101
4.06,-30.38,0.101
4.08,-30.28,0.101
4.10,-30.18,0.101
4.12,-30.08,0.101
4.14,-29.98,0.101
4.16,-29.88,0.101
4.18,-29.78,0.101
4.20,-29.68,0.101
4.22,-29.58,0.101
4.24,-29.48,0.101
4.26,-29.38,0.101
4.28,-29.28,0.101
4.30,-29.18,0.101
4.32,-29.08,0.101
4.34,-28.98,0.101
4.36,-28.88,0.101
4.38,-28.78,0.101
4.40,-28.68,0.101
4.42,-28.58,0.101
4.44,-28.48,0.101
4.46,-28.38,0.101
4.48,-28.28,0.101
4.50,-28.18,0.101
4.52,-28.08,0.101
4.54,-27.98,0.101
4.56,-27.88,0.101
4.58,-27.78,0.101
4.60,-27.68,0.101
4.62,-27.58,0.101
4.64,-27.48,0.101
4.66,-27.38,0.101
4.68,-27.28,0.101
4.70,-27.18,0.101
4.72,-27.08,0.101
4.74,-26.98,0.101
4.76,-26.88,0.101
4.78,-26.78,0.101
4.80,-26.68,0.101
4.82,-26.58,0.101
4.84,-26.48,0.101
4.86,-26.38,0.101
4.88,-26.28,0.101
4.90,-26.18,0.101
4.92,-26.08,0.101
4.94,-25.98,0.101
4.96,-25.88,0.101
4.98,-25.78,0.101
5.00,-25.67,0.101
5.02,-25.57,0.101
5.04,-25.48,0.101
5.06,-25.38,0.101
5.08,-25.28,0.101
5.10,-25.18,0.101
5.12,-25.08,0.101
5.14,-24.98,0.101
5.16,-24.88,0.101
5.18,-24.78,0.101
5.20,-24.68,0.101
5.22,-24.58,0.101
5.24,-24.48,0.101
5.26,-24.38,0.101
5.28,-24.28,0.101
5.30,-24.18,0.101
5.32,-24.08,0.101
5.34,-23.98,0.101
5.36,-23.88,0.101
5.38,-23.78,0.101
5.40,-23.68,0.101
5.42,-23.58,0.101
5.44,-23.48,0.101
5.46,-23.38,0.101
5.48,-23.28,0.101
5.50,-23.18,0.101
5.52,-23.07,0.101
5.54,-22.98,0.101
5.56,-22.87,0.101
5.58,-22.77,0.101
5.60,-22.67,0.101
5.62,-22.57,0.101
5.64,-22.47,0.101
5.66,-22.37,0.101
5.68,-22.27,0.102
5.70,-22.17,0.102
5.72,-22.07,0.102
5.74,-21.97,0.102
5.76,-21.87,0.102
5.78,-21.77,0.102
5.80,-21.67,0.102
5.82,-21.57,0.102
5.84,-21.47,0.102
5.86,-21.37,0.102
5.88,-21.27,0.102
5.90,-21.17,0.102
5.92,-21.07,0.102
5.94,-20.97,0.102
5.96,-20.87,0.102
5.98,-20.77,0.102
6.00,-20.67,0.102
6.02,-20.57,0.102
6.04,-20.47,0.102
6.06,-20.37,0.102
6.08,-20.27,0.102
6.10,-20.17,0.102
6.12,-20.07,0.102
6.14,-19.97,0.102
6.16,-19.87,0.102
6.18,-19.77,0.102
6.20,-19.67,0.102
6.22,-19.57,0.102
6.24,-19.47,0.102
6.26,-19.37,0.102
6.28,-19.27,0.102
6.30,-19.17,0.102
6.32,-19.07,0.102
6.34,-18.97,0.102
6.36,-18.87,0.102
6.38,-18.77,0.102
6.40,-18.67,0.102
6.42,-18.57,0.102
6.44,-18.47,0.102
6.46,-18.37,0.102
6.48,-18.27,0.102
6.50,-18.17,0.102
6.52,-18.07,0.102
6.54,-17.97,0.102
6.56,-17.87,0.102
6.58,-17.77,0.102
6.60,-17.67,0.102
6.62,-17.57,0.102
6.64,-17.47,0.102
6.66,-17.37,0.102
6.68,-17.27,0.102
6.70,-17.17,0.102
6.72,-17.07,0.102
6.74,-16.97,0.102
6.76,-16.87,0.102
6.78,-16.77,0.102
6.80,-16.67,0.102
6.82,-16.57,0.102
6.84,-16.47,0.102
6.86,-16.37,0.102
6.88,-16.27,0.102
6.90,-16.17,0.102
6.92,-16.07,0.102
6.94,-15.97,0.102
6.96,-15.87,0.102
6.98,-15.77,0.102
7.00,-15.67,0.102
7.02,-15.57,0.102
7.04,-15.47,0.102
7.06,-15.37,0.102
7.08,-15.27,0.103
7.10,-15.17,0.103
7.12,-15.07,0.103
7.14,-14.97,0.103
7.16,-14.87,0.103
7.18,-14.77,0.103
7.20,-14.67,0.103
7.22,-14.57,0.103
7.24,-14.47,0.103
7.26,-14.37,0.103
7.28,-14.27,0.103
7.30,-14.17,0.103
7.32,-14.06,0.103
7.34,-13.97,0.103
7.36,-13.87,0.103
7.38,-13.76,0.103
7.40,-13.67,0.103
7.42,-13.56,0.103
7.44,-13.47,0.103
7.46,-13.37,0.103
7.48,-13.27,0.103
7.50,-13.16,0.103
7.52,-13.06,0.103
7.54,-12.96,0.103
7.56,-12.86,0.103
7.58,-12.76,0.103
7.60,-12.66,0.103
7.62,-12.56,0.103
7.64,-12.47,0.103
7.66,-12.37,0.103
7.68,-12.26,0.103
7.70,-12.16,0.103
7.72,-12.06,0.103
7.74,-11.96,0.103
7.76,-11.86,0.103
7.78,-11.76,0.103
7.80,-11.66,0.103
7.82,-11.56,0.103
7.84,-11.46,0.103
7.86,-11.36,0.103
7.88,-11.26,0.103
7.90,-11.16,0.103
7.92,-11.06,0.103
7.94,-10.96,0.103
7.96,-10.86,0.103
7.98,-10.76,0.103
8.00,-10.66,0.103
8.02,-10.56,0.103
8.04,-10.46,0.103
8.06,-10.36,0.103
8.08,-10.26,0.103
8.10,-10.16,0.103
8.12,-10.06,0.103
8.14,-9.96,0.103
8.16,-9.86,0.103
8.18,-9.76,0.103
8.20,-9.66,0.103
8.22,-9.56,0.104
8.24,-9.46,0.104
8.26,-9.36,0.104
8.28,-9.26,0.104
8.30,-9.16,0.104
8.32,-9.06,0.104
8.34,-8.96,0.104
8.36,-8.86,0.104
8.38,-8.76,0.104
8.40,-8.66,0.104
8.42,-8.56,0.104
8.44,-8.46,0.104
8.46,-8.36,0.104
8.48,-8.26,0.104
8.50,-8.16,0.104
8.52,-8.06,0.104
8.54,-7.96,0.104
8.56,-7.86,0.104
8.58,-7.76,0.104
8.60,-7.66,0.104
8.62,-7.56,0.104
8.64,-7.46,0.104
8.66,-7.36,0.104
8.68,-7.26,0.104
8.70,-7.16,0.104
8.72,-7.05,0.104
8.74,-6.96,0.104
8.76,-6.86,0.105
8.78,-6.76,0.105
8.80,-6.66,0.105
8.82,-6.56,0.105
8.84,-6.46,0.105
8.86,-6.36,0.105
8.88,-6.26,0.105
8.90,-6.16,0.105
8.92,-6.06,0.105
8.94,-5.96,0.105
8.96,-5.85,0.105
8.98,-5.76,0.105
9.00,-5.66,0.105
9.02,-5.56,0.105
9.04,-5.46,0.105
9.06,-5.36,0.105
9.08,-5.26,0.105
9.10,-5.16,0.105
9.12,-5.06,0.105
9.14,-4.96,0.104
9.16,-4.86,0.104
9.18,-4.76,0.104
9.20,-4.66,0.104
9.22,-4.56,0.104
9.24,-4.46,0.104
9.26,-4.36,0.104
9.28,-4.26,0.104
9.30,-4.16,0.104
9.32,-4.06,0.105
9.34,-3.96,0.105
9.36,-3.86,0.105
9.38,-3.76,0.105
9.40,-3.66,0.105
9.42,-3.56,0.105
9.44,-3.46,0.105
9.46,-3.36,0.105
9.48,-3.26,0.105
9.50,-3.16,0.105
9.52,-3.06,0.105
9.54,-2.96,0.105
9.56,-2.86,0.105
9.58,-2.76,0.105
9.60,-2.66,0.105
9.62,-2.56,0.105
9.64,-2.46,0.105
9.66,-2.35,0.105
9.68,-2.26,0.105
9.70,-2.15,0.105
9.72,-2.05,0.105
9.74,-1.96,0.105
9.76,-1.86,0.105
9.78,-1.76,0.105
9.80,-1.65,0.105
9.82,-1.55,0.105
9.84,-1.45,0.105
9.86,-1.35,0.105
9.88,-1.26,0.105
9.90,-1.15,0.105
9.92,-1.06,0.105
9.94,-0.95,0.105
9.96,-0.86,0.105
9.98,-0.76,0.105
10.00,-0.65,0.105
10.02,-0.55,0.105
10.04,-0.45,0.105
10.06,-0.35,0.105
10.08,-0.25,0.105
10.10,-0.15,0.105
10.12,-0.05,0.105
10.14,0.05,0.106
10.16,0.15,0.106
10.18,0.25,0.106
10.20,0.35,0.106
10.22,0.45,0.106
10.24,0.55,0.106
10.26,0.65,0.106
10.28,0.75,0.106
10.30,0.84,0.106
10.32,0.95,0.106
10.34,1.05,0.106
10.36,1.15,0.106
10.38,1.25,0.106
10.40,1.35,0.106
10.42,1.45,0.106
10.44,1.55,0.106
10.46,1.65,0.106
10.48,1.75,0.106
10.50,1.85,0.106
10.52,1.95,0.106
10.54,2.05,0.106
10.56,2.15,0.106
10.58,2.25,0.106
10.60,2.35,0.106
10.62,2.45,0.106
10.64,2.55,0.106
10.66,2.65,0.106
10.68,2.75,0.106
10.70,2.85,0.107
10.72,2.95,0.107
10.74,3.05,0.107
10.76,3.15,0.107
10.78,3.25,0.107
10.80,3.35,0.107
10.82,3.45,0.107
10.84,3.55,0.107
10.86,3.65,0.107
10.88,3.75,0.107
10.90,3.85,0.107
10.92,3.95,0.107
10.94,4.05,0.107
10.96,4.15,0.107
10.98,4.25,0.107
11.00,4.35,0.107
11.02,4.45,0.107
11.04,4.55,0.107
11.06,4.65,0.107
11.08,4.75,0.107
11.10,4.85,0.107
11.12,4.95,0.107
11.14,5.05,0.107
11.16,5.15,0.107
11.18,5.25,0.107
11.20,5.35,0.107
11.22,5.45,0.107
11.24,5.55,0.107
11.26,5.65,0.107
11.28,5.75,0.107
11.30,5.85,0.107
11.32,5.95,0.107
11.34,6.05,0.107
11.36,6.15,0.107
11.38,6.25,0.107
11.40,6.35,0.107
11.42,6.45,0.107
11.44,6.55,0.107
11.46,6.65,0.108
11.48,6.75,0.107
11.50,6.85,0.108
11.52,6.95,0.108
11.54,7.05,0.108
11.56,7.15,0.108
11.58,7.25,0.108
11.60,7.35,0.108
11.62,7.45,0.108
11.64,7.55,0.108
11.66,7.65,0.108
11.68,7.75,0.108
11.70,7.85,0.108
11.72,7.95,0.108
11.74,8.05,0.108
11.76,8.15,0.108
11.78,8.25,0.108
11.80,8.35,0.108
11.82,8.45,0.108
11.84,8.55,0.108
11.86,8.65,0.108
11.88,8.75,0.108
11.90,8.85,0.108
11.92,8.95,0.108
11.94,9.05,0.108
11.96,9.15,0.109
11.98,9.25,0.109
12.00,9.35,0.109
12.02,9.45,0.109
12.04,9.55,0.109
12.06,9.65,0.109
12.08,9.75,0.109
12.10,9.85,0.109
12.12,9.95,0.109
12.14,10.05,0.109
12.16,10.15,0.109
12.18,10.25,0.109
12.20,10.35,0.109
12.22,10.45,0.109
12.24,10.55,0.109
12.26,10.65,0.109
12.28,10.75,0.109
12.30,10.85,0.109
12.32,10.95,0.109
12.34,11.05,0.109
12.36,11.15,0.109
12.38,11.25,0.109
12.40,11.35,0.109
12.42,11.45,0.109
12.44,11.55,0.109
12.46,11.66,0.109
12.48,11.75,0.109
12.50,11.86,0.109
12.52,11.96,0.109
12.54,12.06,0.109
12.56,12.16,0.110
12.58,12.26,0.110
12.60,12.36,0.110
12.62,12.46,0.110
12.64,12.56,0.110
12.66,12.66,0.110
12.68,12.76,0.110
12.70,12.86,0.110
12.72,12.96,0.110
12.74,13.06,0.110
12.76,13.16,0.110
12.78,13.26,0.110
12.80,13.36,0.110
12.82,13.46,0.110
12.84,13.56,0.110
12.86,13.66,0.110
12.88,13.76,0.110
12.90,13.86,0.110
12.92,13.96,0.110
12.94,14.06,0.110
12.96,14.16,0.110
12.98,14.26,0.110
13.00,14.36,0.110
13.02,14.46,0.110
13.04,14.56,0.110
13.06,14.66,0.110
13.08,14.76,0.110
13.10,14.86,0.110
13.12,14.96,0.110
13.14,15.06,0.110
13.16,15.16,0.110
13.18,15.26,0.110
13.20,15.36,0.110
13.22,15.46,0.111
13.24,15.56,0.111
13.26,15.66,0.111
13.28,15.76,0.111
13.30,15.86,0.111
13.32,15.96,0.111
13.34,16.06,0.111
13.36,16.16,0.111
13.38,16.26,0.111
13.40,16.36,0.111
13.42,16.46,0.111
13.44,16.56,0.111
13.46,16.66,0.111
13.48,16.76,0.111
13.50,16.86,0.111
13.52,16.96,0.111
13.54,17.06,0.111
13.56,17.16,0.111
13.58,17.26,0.111
13.60,17.36,0.111
13.62,17.46,0.111
13.64,17.56,0.111
13.66,17.66,0.111
13.68,17.76,0.111
13.70,17.86,0.111
13.72,17.96,0.111
13.74,18.06,0.111
13.76,18.16,0.111
13.78,18.26,0.111
13.80,18.36,0.112
13.82,18.46,0.112
13.84,18.56,0.112
13.86,18.66,0.112
13.88,18.76,0.112
13.90,18.86,0.112
13.92,18.96,0.112
13.94,19.06,0.112
13.96,19.16,0.112
13.98,19.26,0.112
14.00,19.36,0.112
14.02,19.46,0.112
14.04,19.56,0.112
14.06,19.66,0.112
14.08,19.76,0.112
14.10,19.86,0.112
14.12,19.96,0.112
14.14,20.06,0.112
14.16,20.16,0.112
14.18,20.26,0.112
14.20,20.36,0.112
14.22,20.46,0.112
14.24,20.56,0.112
14.26,20.66,0.112
14.28,20.76,0.112
14.30,20.86,0.112
14.32,20.96,0.112
14.34,21.06,0.112
14.36,21.16,0.112
14.38,21.26,0.112
14.40,21.36,0.113
14.42,21.46,0.113
14.44,21.56,0.113
14.46,21.66,0.113
14.48,21.76,0.113
14.50,21.86,0.113
14.52,21.96,0.113
14.54,22.06,0.113
14.56,22.16,0.113
14.58,22.26,0.113
14.60,22.36,0.113
14.62,22.46,0.113
14.64,22.56,0.113
14.66,22.66,0.113
14.68,22.76,0.113
14.70,22.86,0.113
14.72,22.96,0.113
14.74,23.06,0.113
14.76,23.16,0.113
14.78,23.26,0.113
14.80,23.36,0.113
14.82,23.46,0.113
14.84,23.56,0.113
14.86,23.66,0.113
14.88,23.76,0.114
14.90,23.86,0.114
14.92,23.96,0.114
14.94,24.06,0.114
14.96,24.16,0.114
14.98,24.26,0.114
15.00,24.36,0.114
15.02,24.46,0.114
15.04,24.56,0.114
15.06,24.66,0.114
15.08,24.76,0.114
15.10,24.86,0.114
15.12,24.96,0.114
15.14,25.06,0.114
15.16,25.16,0.114
15.18,25.26,0.114
15.20,25.36,0.114
15.22,25.46,0.114
15.24,25.56,0.114
15.26,25.66,0.114
15.28,25.76,0.115
15.30,25.86,0.115
15.32,25.96,0.115
15.34,26.06,0.115
15.36,26.16,0.115
15.38,26.26,0.115
15.40,26.36,0.115
15.42,26.46,0.115
15.44,26.56,0.115
15.46,26.66,0.115
15.48,26.76,0.115
15.50,26.86,0.115
15.52,26.96,0.115
15.54,27.06,0.115
15.56,27.16,0.115
15.58,27.26,0.115
15.60,27.36,0.115
15.62,27.46,0.115
15.64,27.56,0.115
15.66,27.66,0.115
15.68,27.76,0.115
15.70,27.86,0.115
15.72,27.96,0.115
15.74,28.06,0.115
15.76,28.16,0.115
15.78,28.26,0.115
15.80,28.36,0.115
15.82,28.46,0.115
15.84,28.56,0.115
15.86,28.66,0.116
15.88,28.76,0.115
15.90,28.86,0.116
15.92,28.96,0.116
15.94,29.06,0.116
15.96,29.16,0.116
15.98,29.27,0.116
16.00,29.36,0.116
16.02,29.46,0.116
16.04,29.56,0.116
16.06,29.67,0.116
16.08,29.77,0.116
16.10,29.87,0.116
16.12,29.97,0.116
16.14,30.07,0.116
16.16,30.17,0.116
16.18,30.27,0.116
16.20,30.37,0.116
16.22,30.46,0.116
16.24,30.57,0.116
16.26,30.67,0.116
16.28,30.77,0.116
16.30,30.87,0.116
16.32,30.97,0.116
16.34,31.07,0.116
16.36,31.17,0.117
16.38,31.27,0.117
16.40,31.37,0.117
16.42,31.47,0.117
16.44,31.57,0.117
16.46,31.67,0.117
16.48,31.77,0.117
16.50,31.87,0.117
16.52,31.97,0.117
16.54,32.07,0.117
16.56,32.17,0.117
16.58,32.27,0.117
16.60,32.37,0.117
16.62,32.47,0.117
16.64,32.57,0.117
16.66,32.67,0.117
16.68,32.77,0.117
16.70,32.87,0.117
16.72,32.97,0.117
16.74,33.07,0.117
16.76,33.17,0.117
16.78,33.27,0.117
16.80,33.37,0.117
16.82,33.47,0.117
16.84,33.57,0.117
16.86,33.67,0.117
16.88,33.77,0.117
16.90,33.87,0.118
16.92,33.97,0.118
16.94,34.07,0.118
16.96,34.17,0.118
16.98,34.27,0.118
17.00,34.37,0.118
17.02,34.47,0.118
17.04,34.57,0.118
17.06,34.67,0.118
17.08,34.77,0.118
17.10,34.87,0.118
17.12,34.97,0.118
17.14,35.07,0.118
17.16,35.17,0.118
17.18,35.27,0.118
17.20,35.37,0.118
17.22,35.47,0.118
17.24,35.57,0.118
17.26,35.67,0.118
17.28,35.77,0.118
17.30,35.87,0.118
17.32,35.97,0.118
17.34,36.07,0.118
17.36,36.17,0.118
17.38,36.27,0.118
17.40,36.37,0.118
17.42,36.47,0.119
17.44,36.57,0.119
17.46,36.67,0.119
17.48,36.77,0.119
17.50,36.87,0.119
17.52,36.97,0.119
17.54,37.07,0.119
17.56,37.17,0.119
17.58,37.27,0.119
17.60,37.37,0.119
17.62,37.47,0.119
17.64,37.57,0.119
17.66,37.67,0.119
17.68,37.77,0.119
17.70,37.87,0.119
17.72,37.97,0.119
17.74,38.07,0.119
17.76,38.17,0.119
17.78,38.27,0.119
17.80,38.37,0.119
17.82,38.47,0.119
17.84,38.57,0.120
17.86,38.67,0.119
17.88,38.77,0.120
17.90,38.87,0.119
17.92,38.97,0.120
17.94,39.07,0.120
17.96,39.17,0.120
17.98,39.27,0.120
18.00,39.37,0.120
18.02,39.47,0.120
18.04,39.57,0.120
18.06,39.67,0.120
18.08,39.77,0.120
18.10,39.87,0.120
18.12,39.97,0.120
18.14,40.07,0.120
18.16,40.17,0.120
18.18,40.27,0.120
18.20,40.37,0.120
18.22,40.47,0.120
18.24,40.57,0.120
18.26,40.67,0.120
18.28,40.77,0.120
18.30,40.87,0.120
18.32,40.97,0.120
18.34,41.07,0.120
18.36,41.17,0.120
18.38,41.27,0.120
18.40,41.37,0.121
18.42,41.47,0.121
18.44,41.57,0.121
18.46,41.67,0.121
18.48,41.77,0.121
18.50,41.87,0.121
18.52,41.97,0.121
18.54,42.07,0.121
18.56,42.17,0.121
18.58,42.27,0.121
18.60,42.37,0.121
18.62,42.47,0.121
18.64,42.57,0.121
18.66,42.67,0.121
18.68,42.77,0.121
18.70,42.87,0.121
18.72,42.97,0.121
18.74,43.07,0.121
18.76,43.17,0.121
18.78,43.27,0.121
18.80,43.37,0.121
18.82,43.47,0.121
18.84,43.57,0.121
18.86,43.67,0.121
18.88,43.77,0.121
18.90,43.87,0.121
18.92,43.97,0.122
18.94,44.07,0.122
18.96,44.17,0.122
18.98,44.27,0.122
19.00,44.37,0.122
19.02,44.47,0.122
19.04,44.57,0.122
19.06,44.67,0.122
19.08,44.77,0.122
19.10,44.87,0.122
19.12,44.97,0.122
19.14,45.07,0.122
19.16,45.18,0.122
19.18,45.27,0.122
19.20,45.38,0.122
19.22,45.47,0.122
19.24,45.57,0.122
19.26,45.67,0.122
19.28,45.77,0.122
19.30,45.87,0.122
19.32,45.97,0.122
19.34,46.08,0.122
19.36,46.18,0.123
19.38,46.27,0.123
19.40,46.38,0.123
19.42,46.47,0.123
19.44,46.57,0.123
19.46,46.67,0.123
19.48,46.78,0.123
19.50,46.88,0.123
19.52,46.98,0.123
19.54,47.07,0.123
19.56,47.18,0.123
19.58,47.27,0.123
19.60,47.38,0.123
19.62,47.48,0.123
19.64,47.58,0.123
19.66,47.68,0.123
19.68,47.77,0.123
19.70,47.88,0.123
19.72,47.98,0.123
19.74,48.08,0.123
19.76,48.18,0.123
19.78,48.28,0.123
19.80,48.38,0.124
19.82,48.48,0.124
19.84,48.58,0.124
19.86,48.68,0.124
19.88,48.77,0.124
19.90,48.88,0.124
19.92,48.98,0.124
19.94,49.08,0.124
19.96,49.18,0.124
19.98,49.28,0.124
20.00,49.38,0.124
20.02,49.48,0.124
20.04,49.58,0.124
20.06,49.68,0.124
20.08,49.78,0.124
20.10,49.88,0.124
20.12,49.98,0.124
20.14,50.08,0.125
20.16,50.18,0.125
20.18,50.28,0.125
20.20,50.38,0.125
20.22,50.48,0.125
20.24,50.58,0.125
20.26,50.68,0.125
20.28,50.78,0.125
20.30,50.88,0.125
20.32,50.98,0.125
20.34,51.08,0.125
20.36,51.18,0.125
20.38,51.28,0.125
20.40,51.38,0.125
20.42,51.48,0.125
20.44,51.58,0.125
20.46,51.68,0.126
20.48,51.78,0.126
20.50,51.88,0.126
20.52,51.98,0.126
20.54,52.08,0.126
20.56,52.18,0.126
20.58,52.28,0.126
20.60,52.38,0.126
20.62,52.48,0.126
20.64,52.58,0.126
20.66,52.68,0.126
20.68,52.78,0.126
20.70,52.88,0.126
20.72,52.98,0.126
20.74,53.08,0.126
20.76,53.18,0.127
20.78,53.28,0.127
20.80,53.38,0.127
20.82,53.48,0.127
20.84,53.58,0.127
20.86,53.68,0.127
20.88,53.78,0.127
20.90,53.88,0.127
20.92,53.98,0.127
20.94,54.08,0.127
20.96,54.18,0.127
20.98,54.28,0.128
21.00,54.38,0.128
21.02,54.48,0.128
21.04,54.58,0.128
21.06,54.68,0.128
21.08,54.78,0.128
21.10,54.88,0.128
21.12,54.98,0.128
21.14,55.08,0.128
21.16,55.18,0.128
21.18,55.28,0.128
21.20,55.38,0.128
21.22,55.48,0.129
21.24,55.58,0.129
21.26,55.68,0.129
21.28,55.78,0.129
21.30,55.88,0.129
21.32,55.98,0.129
21.34,56.08,0.129
21.36,56.18,0.129
21.38,56.28,0.130
21.40,56.38,0.130
21.42,56.48,0.130
21.44,56.58,0.130
21.46,56.68,0.130
21.48,56.78,0.130
21.50,56.88,0.130
21.52,56.98,0.131
21.54,57.08,0.131
21.56,57.18,0.131
21.58,57.28,0.131
21.60,57.38,0.131
21.62,57.48,0.131
21.64,57.58,0.132
21.66,57.68,0.132
21.68,57.78,0.132
21.70,57.88,0.132
21.72,57.98,0.132
21.74,58.08,0.133
21.76,58.18,0.133
21.78,58.28,0.133
21.80,58.38,0.133
21.82,58.48,0.133
21.84,58.58,0.134
21.86,58.68,0.134
21.88,58.78,0.134
21.90,58.88,0.134
21.92,58.98,0.135
21.94,59.08,0.135
21.96,59.18,0.135
21.98,59.28,0.136
22.00,59.38,0.136
22.02,59.48,0.137
22.04,59.58,0.137
22.06,59.68,0.137
22.08,59.78,0.138
22.10,59.88,0.138
22.12,59.98,0.139
22.14,60.08,0.140
22.16,60.18,0.140
22.18,60.28,0.141
22.20,60.38,0.141
22.22,60.48,0.142
22.24,60.58,0.143
22.26,60.68,0.144
22.28,60.78,0.145
22.30,60.88,0.147
22.32,60.98,0.148
22.34,61.07,0.150
22.36,61.17,0.151
22.38,61.27,0.154
22.40,61.37,0.156
22.42,61.47,0.159
22.44,61.57,0.162
22.46,61.67,0.165
22.48,61.77,0.170
22.50,61.87,0.173
22.52,61.97,0.177
22.54,62.07,0.182
22.56,62.17,0.186
22.58,62.26,0.193
22.60,62.36,0.198
22.62,62.46,0.205
22.64,62.56,0.211
22.66,62.66,0.219
22.68,62.75,0.228
22.70,62.85,0.237
22.72,62.95,0.248
22.74,63.05,0.258
22.76,63.14,0.270
22.78,63.24,0.282
22.80,63.34,0.296
22.82,63.43,0.312
22.84,63.53,0.326
22.86,63.62,0.343
22.88,63.72,0.361
22.90,63.81,0.382
22.92,63.90,0.404
22.94,64.00,0.427
22.96,64.09,0.453
22.98,64.18,0.482
23.00,64.27,0.511
23.02,64.36,0.545
23.04,64.45,0.580
23.06,64.54,0.620
23.08,64.63,0.662
23.10,64.71,0.706
23.12,64.80,0.752
23.14,64.89,0.803
23.16,64.97,0.857
23.18,65.05,0.913
23.20,65.13,0.976
23.22,65.21,1.040
23.24,65.29,1.111
23.26,65.37,1.184
23.28,65.45,1.266
23.30,65.52,1.360
23.32,65.59,1.450
23.34,65.66,1.524
23.36,65.73,1.617
23.38,65.80,1.693
23.40,65.88,1.738
23.42,65.96,1.774
23.44,66.04,1.805
23.46,66.12,1.834
23.48,66.21,1.859
23.50,66.30,1.873
23.52,66.39,1.870
23.54,66.49,1.853
23.56,66.58,1.823
23.58,66.69,1.781
23.60,66.80,1.726
23.62,66.91,1.661
23.64,67.03,1.589
23.66,67.15,1.510
23.68,67.27,1.427
23.70,67.40,1.339
23.72,67.52,1.248
23.74,67.65,1.154
23.76,67.78,1.061
23.78,67.92,0.967
23.80,68.05,0.887
23.82,68.18,0.794
23.84,68.31,0.712
23.86,68.44,0.631
23.88,68.57,0.556
23.90,68.70,0.488
23.92,68.82,0.428
23.94,68.94,0.379
23.96,69.07,0.338
23.98,69.18,0.304
24.00,69.30,0.278
24.02,69.41,0.258
24.04,69.52,0.239
24.06,69.63,0.226
24.08,69.74,0.216
24.10,69.85,0.207
24.12,69.95,0.199
24.14,70.06,0.192
24.16,70.16,0.188
24.18,70.26,0.184
24.20,70.37,0.180
24.22,70.47,0.178
24.24,70.57,0.177
24.26,70.67,0.175
24.28,70.77,0.174
24.30,70.87,0.173
24.32,70.97,0.172
24.34,71.07,0.172
24.36,71.18,0.171
24.38,71.28,0.171
24.40,71.38,0.170
24.42,71.48,0.170
24.44,71.58,0.170
24.46,71.68,0.169
24.48,71.78,0.169
24.50,71.88,0.169
24.52,71.98,0.169
24.54,72.08,0.168
24.56,72.18,0.168
24.58,72.28,0.168
24.60,72.38,0.168
24.62,72.48,0.167
24.64,72.58,0.167
24.66,72.68,0.167
24.68,72.78,0.167
24.70,72.88,0.167
24.72,72.98,0.167
24.74,73.08,0.167
24.76,73.18,0.166
24.78,73.28,0.166
24.80,73.38,0.166
24.82,73.48,0.166
24.84,73.58,0.166
24.86,73.68,0.166
24.88,73.78,0.166
24.90,73.88,0.166
24.92,73.98,0.166
24.94,74.08,0.166
24.96,74.18,0.166
24.98,74.28,0.166
25.00,74.38,0.166
25.02,74.48,0.166
25.04,74.58,0.166
25.06,74.68,0.166
25.08,74.78,0.166
25.10,74.88,0.166
25.12,74.98,0.166
25.14,75.08,0.166
25.16,75.18,0.166
25.18,75.28,0.166
25.20,75.38,0.166
25.22,75.48,0.166
25.24,75.58,0.166
25.26,75.68,0.166
25.28,75.78,0.166
25.30,75.88,0.166
25.32,75.98,0.166
25.34,76.08,0.166
25.36,76.18,0.166
25.38,76.28,0.166
25.40,76.38,0.166
25.42,76.48,0.166
25.44,76.58,0.166
25.46,76.68,0.166
25.48,76.78,0.166
25.50,76.88,0.166
25.52,76.98,0.166
25.54,77.08,0.166
25.56,77.18,0.166
25.58,77.28,0.166
25.60,77.38,0.166
25.62,77.48,0.166
25.64,77.58,0.166
25.66,77.68,0.166
25.68,77.78,0.166
25.70,77.88,0.166
25.72,77.98,0.166
25.74,78.08,0.166
25.76,78.18,0.167
25.78,78.28,0.167
25.80,78.38,0.167
25.82,78.48,0.167
25.84,78.58,0.167
25.86,78.68,0.167
25.88,78.78,0.167
25.90,78.88,0.167
25.92,78.98,0.167
25.94,79.08,0.167
25.96,79.18,0.167
25.98,79.28,0.167
26.00,79.38,0.167
26.02,79.48,0.167
26.04,79.58,0.167
26.06,79.68,0.167
26.08,79.78,0.167
26.10,79.88,0.167
26.12,79.98,0.167
26.14,80.08,0.167
26.16,80.18,0.167
26.18,80.28,0.167
26.20,80.38,0.167
26.22,80.48,0.167
26.24,80.58,0.167
26.26,80.68,0.167
26.28,80.78,0.167
26.30,80.88,0.167
26.32,80.98,0.167
26.34,81.08,0.167
26.36,81.18,0.167
26.38,81.28,0.167
26.40,81.38,0.167
26.42,81.48,0.167
26.44,81.58,0.168
26.46,81.68,0.168
26.48,81.78,0.168
26.50,81.88,0.168
26.52,81.98,0.168
26.54,82.08,0.168
26.56,82.18,0.168
26.58,82.28,0.168
26.60,82.38,0.168
26.62,82.48,0.168
26.64,82.58,0.168
26.66,82.68,0.168
26.68,82.78,0.168
26.70,82.88,0.168
26.72,82.98,0.168
26.74,83.08,0.168
26.76,83.18,0.168
26.78,83.28,0.168
26.80,83.38,0.168
26.82,83.48,0.168
26.84,83.58,0.168
26.86,83.68,0.168
26.88,83.78,0.168
26.90,83.88,0.168
26.92,83.98,0.168
26.94,84.08,0.168
26.96,84.18,0.168
26.98,84.28,0.168
27.00,84.39,0.168
27.02,84.48,0.168
27.04,84.58,0.168
27.06,84.68,0.168
27.08,84.78,0.168
27.10,84.88,0.168
27.12,84.98,0.168
27.14,85.09,0.168
27.16,85.19,0.168
27.18,85.29,0.168
27.20,85.38,0.168
27.22,85.49,0.168
27.24,85.58,0.168
27.26,85.69,0.168
27.28,85.78,0.168
27.30,85.89,0.168
27.32,85.99,0.168
27.34,86.09,0.169
27.36,86.19,0.168
27.38,86.28,0.169
27.40,86.38,0.169
27.42,86.49,0.169
27.44,86.59,0.169
27.46,86.69,0.169
27.48,86.78,0.169
27.50,86.89,0.169
27.52,86.99,0.169
27.54,87.09,0.169
27.56,87.19,0.169
27.58,87.29,0.169
27.60,87.39,0.169
27.62,87.49,0.169
27.64,87.59,0.169
27.66,87.69,0.169
27.68,87.79,0.169
27.70,87.89,0.169
27.72,87.99,0.169
27.74,88.09,0.169
27.76,88.19,0.169
27.78,88.29,0.169
27.80,88.39,0.169
27.82,88.49,0.169
27.84,88.59,0.169
27.86,88.69,0.169
27.88,88.79,0.169
27.90,88.89,0.169
27.92,88.99,0.169
27.94,89.09,0.169
27.96,89.19,0.169
27.98,89.29,0.169
28.00,89.39,0.169
28.02,89.49,0.169
28.04,89.59,0.169
28.06,89.69,0.170
28.08,89.79,0.170
28.10,89.89,0.170
28.12,89.99,0.170
28.14,90.09,0.170
28.16,90.19,0.170
28.18,90.29,0.170
28.20,90.39,0.170
28.22,90.49,0.170
28.24,90.59,0.170
28.26,90.69,0.170
28.28,90.79,0.170
28.30,90.89,0.170
28.32,90.99,0.170
28.34,91.09,0.170
28.36,91.19,0.170
28.38,91.29,0.170
28.40,91.39,0.170
28.42,91.49,0.170
28.44,91.59,0.170
28.46,91.69,0.170
28.48,91.79,0.170
28.50,91.89,0.170
28.52,91.99,0.170
28.54,92.09,0.170
28.56,92.19,0.170
28.58,92.29,0.170
28.60,92.39,0.170
28.62,92.49,0.170
28.64,92.59,0.170
28.66,92.69,0.170
28.68,92.79,0.170
28.70,92.89,0.170
28.72,92.99,0.171
28.74,93.09,0.171
28.76,93.19,0.171
28.78,93.29,0.171
28.80,93.39,0.171
28.82,93.49,0.171
28.84,93.59,0.171
28.86,93.69,0.171
28.88,93.79,0.171
28.90,93.89,0.171
28.92,93.99,0.171
28.94,94.09,0.171
28.96,94.19,0.171
28.98,94.29,0.171
29.00,94.39,0.171
29.02,94.49,0.171
29.04,94.59,0.171
29.06,94.69,0.171
29.08,94.79,0.171
29.10,94.89,0.171
29.12,94.99,0.171
29.14,95.09,0.171
29.16,95.19,0.171
29.18,95.29,0.171
29.20,95.39,0.171
29.22,95.49,0.171
29.24,95.59,0.171
29.26,95.69,0.171
29.28,95.79,0.171
29.30,95.89,0.171
29.32,95.99,0.171
29.34,96.09,0.171
29.36,96.19,0.171
29.38,96.29,0.171
29.40,96.39,0.172
29.42,96.49,0.172
29.44,96.59,0.172
29.46,96.69,0.172
29.48,96.79,0.172
29.50,96.89,0.172
29.52,96.99,0.172
29.54,97.09,0.172
29.56,97.19,0.172
29.58,97.29,0.172
29.60,97.39,0.172
29.62,97.49,0.172
29.64,97.59,0.172
29.66,97.69,0.172
29.68,97.79,0.172
29.70,97.89,0.172
29.72,97.99,0.172
29.74,98.09,0.172
29.76,98.19,0.172
29.78,98.29,0.172
29.80,98.39,0.172
29.82,98.49,0.172
29.84,98.59,0.172
29.86,98.69,0.172
29.88,98.79,0.172
29.90,98.89,0.172
29.92,98.99,0.172
29.94,99.09,
29.96,99.19,
29.98,,
29.99,,

[step]
Ramp 5.00 °C/min to -50.00 °C
Time,Temperature,Heat Flow (Normalized)
min,°C,W/g
30.99,100.11,-0.021
31.01,100.11,-0.021
31.03,100.11,-0.022
31.05,100.10,-0.021
31.07,100.08,-0.020
31.09,100.05,-0.020
31.11,100.00,-0.036
31.13,99.95,-0.060
31.15,99.89,-0.086
31.17,99.82,-0.110
31.19,99.74,-0.131
31.21,99.66,-0.144
31.23,99.58,-0.157
31.25,99.50,-0.168
31.27,99.41,-0.176
31.29,99.32,-0.182
31.31,99.23,-0.189
31.33,99.14,-0.192
31.35,99.04,-0.198
31.37,98.95,-0.200
31.39,98.85,-0.203
31.41,98.76,-0.204
31.43,98.66,-0.205
31.45,98.57,-0.207
31.47,98.47,-0.208
31.49,98.37,-0.209
31.51,98.28,-0.210
31.53,98.18,-0.211
31.55,98.08,-0.212
31.57,97.98,-0.212
31.59,97.89,-0.212
31.61,97.78,-0.213
31.63,97.69,-0.213
31.65,97.59,-0.213
31.67,97.49,-0.214
31.69,97.39,-0.214
31.71,97.29,-0.214
31.73,97.19,-0.215
31.75,97.10,-0.215
31.77,97.00,-0.215
31.79,96.90,-0.215
31.81,96.80,-0.216
31.83,96.70,-0.216
31.85,96.60,-0.216
31.87,96.50,-0.216
31.89,96.40,-0.216
31.91,96.30,-0.216
31.93,96.20,-0.217
31.95,96.10,-0.217
31.97,96.00,-0.217
31.99,95.90,-0.217
32.01,95.80,-0.217
32.03,95.70,-0.217
32.05,95.61,-0.217
32.07,95.50,-0.217
32.09,95.41,-0.217
32.11,95.31,-0.217
32.13,95.21,-0.218
32.15,95.11,-0.218
32.17,95.01,-0.218
32.19,94.91,-0.218
32.21,94.81,-0.218
32.23,94.71,-0.218
32.25,94.61,-0.218
32.27,94.51,-0.218
32.29,94.41,-0.218
32.31,94.31,-0.218
32.33,94.21,-0.218
32.35,94.11,-0.218
32.37,94.01,-0.218
32.39,93.91,-0.218
32.41,93.81,-0.217
32.43,93.71,-0.217
32.45,93.61,-0.217
32.47,93.51,-0.217
32.49,93.41,-0.217
32.51,93.31,-0.217
32.53,93.21,-0.217
32.55,93.11,-0.217
32.57,93.01,-0.217
32.59,92.91,-0.217
32.61,92.81,-0.217
32.63,92.71,-0.217
32.65,92.61,-0.217
32.67,92.51,-0.217
32.69,92.41,-0.217
32.71,92.31,-0.217
32.73,92.21,-0.217
32.75,92.11,-0.217
32.77,92.01,-0.217
32.79,91.92,-0.217
32.81,91.81,-0.217
32.83,91.72,-0.217
32.85,91.62,-0.217
32.87,91.52,-0.216
32.89,91.42,-0.216
32.91,91.32,-0.217
32.93,91.22,-0.216
32.95,91.12,-0.216
32.97,91.02,-0.216
32.99,90.92,-0.216
33.01,90.82,-0.216
33.03,90.72,-0.216
33.05,90.62,-0.216
33.07,90.52,-0.216
33.09,90.42,-0.216
33.11,90.32,-0.216
33.13,90.22,-0.216
33.15,90.12,-0.216
33.17,90.02,-0.216
33.19,89.92,-0.216
33.21,89.82,-0.216
33.23,89.72,-0.216
33.25,89.62,-0.216
33.27,89.52,-0.216
33.29,89.42,-0.216
33.31,89.32,-0.216
33.33,89.22,-0.215
33.35,89.12,-0.215
33.37,89.02,-0.215
33.39,88.92,-0.215
33.41,88.82,-0.215
33.43,88.72,-0.215
33.45,88.62,-0.215
33.47,88.52,-0.215
33.49,88.42,-0.215
33.51,88.32,-0.215
33.53,88.22,-0.215
33.55,88.12,-0.215
33.57,88.02,-0.215
33.59,87.92,-0.215
33.61,87.82,-0.214
33.63,87.72,-0.214
33.65,87.62,-0.214
33.67,87.52,-0.214
33.69,87.42,-0.214
33.71,87.32,-0.214
33.73,87.22,-0.214
33.75,87.12,-0.214
33.77,87.02,-0.214
33.79,86.92,-0.214
33.81,86.82,-0.214
33.83,86.72,-0.214
33.85,86.62,-0.213
33.87,86.52,-0.214
33.89,86.42,-0.214
33.91,86.32,-0.213
33.93,86.22,-0.213
33.95,86.12,-0.213
33.97,86.02,-0.213
33.99,85.92,-0.213
34.01,85.82,-0.213
34.03,85.72,-0.213
34.05,85.62,-0.213
34.07,85.52,-0.213
34.09,85.42,-0.213
34.11,85.32,-0.213
34.13,85.22,-0.213
34.15,85.12,-0.213
34.17,85.02,-0.213
34.19,84.92,-0.213
34.21,84.82,-0.213
34.23,84.72,-0.213
34.25,84.62,-0.213
34.27,84.52,-0.213
34.29,84.42,-0.213
34.31,84.32,-0.213
34.33,84.22,-0.213
34.35,84.12,-0.213
34.37,84.02,-0.213
34.39,83.92,-0.213
34.41,83.82,-0.213
34.43,83.72,-0.213
34.45,83.62,-0.212
34.47,83.52,-0.212
34.49,83.42,-0.212
34.51,83.32,-0.212
34.53,83.22,-0.212
34.55,83.12,-0.212
34.57,83.02,-0.212
34.59,82.92,-0.212
34.61,82.82,-0.212
34.63,82.72,-0.212
34.65,82.62,-0.212
34.67,82.52,-0.212
34.69,82.42,-0.212
34.71,82.32,-0.212
34.73,82.22,-0.212
34.75,82.12,-0.212
34.77,82.02,-0.212
34.79,81.92,-0.212
34.81,81.82,-0.212
34.83,81.72,-0.212
34.85,81.62,-0.212
34.87,81.52,-0.212
34.89,81.42,-0.212
34.91,81.32,-0.212
34.93,81.22,-0.212
34.95,81.12,-0.212
34.97,81.02,-0.212
34.99,80.92,-0.212
35.01,80.82,-0.212
35.03,80.72,-0.212
35.05,80.62,-0.212
35.07,80.52,-0.212
35.09,80.42,-0.212
35.11,80.32,-0.212
35.13,80.22,-0.212
35.15,80.12,-0.212
35.17,80.02,-0.212
35.19,79.92,-0.212
35.21,79.82,-0.212
35.23,79.72,-0.212
35.25,79.62,-0.212
35.27,79.52,-0.212
35.29,79.42,-0.212
35.31,79.32,-0.212
35.33,79.22,-0.212
35.35,79.12,-0.211
35.37,79.02,-0.211
35.39,78.92,-0.211
35.41,78.82,-0.211
35.43,78.72,-0.211
35.45,78.62,-0.211
35.47,78.52,-0.211
35.49,78.42,-0.211
35.51,78.32,-0.211
35.53,78.22,-0.211
35.55,78.12,-0.211
35.57,78.02,-0.211
35.59,77.92,-0.211
35.61,77.82,-0.211
35.63,77.72,-0.211
35.65,77.62,-0.211
35.67,77.52,-0.211
35.69,77.42,-0.211
35.71,77.32,-0.211
35.73,77.23,-0.211
35.75,77.12,-0.211
35.77,77.02,-0.211
35.79,76.92,-0.210
35.81,76.82,-0.210
35.83,76.72,-0.210
35.85,76.62,-0.210
35.87,76.53,-0.210
35.89,76.42,-0.210
35.91,76.32,-0.210
35.93,76.23,-0.210
35.95,76.12,-0.210
35.97,76.03,-0.210
35.99,75.93,-0.210
36.01,75.83,-0.210
36.03,75.73,-0.210
36.05,75.63,-0.210
36.07,75.53,-0.210
36.09,75.43,-0.210
36.11,75.33,-0.210
36.13,75.23,-0.210
36.15,75.13,-0.210
36.17,75.03,-0.210
36.19,74.93,-0.209
36.21,74.83,-0.210
36.23,74.73,-0.210
36.25,74.63,-0.210
36.27,74.53,-0.210
36.29,74.43,-0.209
36.31,74.33,-0.209
36.33,74.23,-0.209
36.35,74.13,-0.209
36.37,74.03,-0.209
36.39,73.93,-0.209
36.41,73.83,-0.209
36.43,73.73,-0.209
36.45,73.63,-0.209
36.47,73.53,-0.209
36.49,73.43,-0.209
36.51,73.33,-0.209
36.53,73.23,-0.209
36.55,73.13,-0.209
36.57,73.03,-0.209
36.59,72.93,-0.209
36.61,72.83,-0.209
36.63,72.73,-0.209
36.65,72.63,-0.209
36.67,72.53,-0.209
36.69,72.43,-0.209
36.71,72.33,-0.209
36.73,72.23,-0.209
36.75,72.13,-0.209
36.77,72.03,-0.209
36.79,71.93,-0.209
36.81,71.83,-0.209
36.83,71.73,-0.209
36.85,71.63,-0.208
36.87,71.53,-0.208
36.89,71.43,-0.208
36.91,71.33,-0.208
36.93,71.23,-0.208
36.95,71.13,-0.208
36.97,71.03,-0.208
36.99,70.93,-0.208
37.01,70.83,-0.208
37.03,70.73,-0.208
37.05,70.63,-0.208
37.07,70.53,-0.208
37.09,70.43,-0.208
37.11,70.33,-0.208
37.13,70.23,-0.208
37.15,70.13,-0.208
37.17,70.03,-0.208
37.19,69.93,-0.208
37.21,69.83,-0.208
37.23,69.73,-0.208
37.25,69.63,-0.208
37.27,69.53,-0.208
37.29,69.43,-0.208
37.31,69.33,-0.208
37.33,69.23,-0.207
37.35,69.13,-0.207
37.37,69.03,-0.207
37.39,68.93,-0.207
37.41,68.83,-0.207
37.43,68.73,-0.207
37.45,68.63,-0.207
37.47,68.53,-0.207
37.49,68.43,-0.207
37.51,68.33,-0.207
37.53,68.23,-0.207
37.55,68.13,-0.207
37.57,68.03,-0.207
37.59,67.93,-0.207
37.61,67.83,-0.207
37.63,67.73,-0.207
37.65,67.63,-0.207
37.67,67.53,-0.207
37.69,67.43,-0.207
37.71,67.33,-0.207
37.73,67.23,-0.207
37.75,67.13,-0.207
37.77,67.03,-0.207
37.79,66.93,-0.207
37.81,66.83,-0.207
37.83,66.73,-0.207
37.85,66.63,-0.207
37.87,66.53,-0.206
37.89,66.43,-0.206
37.91,66.33,-0.206
37.93,66.23,-0.206
37.95,66.13,-0.206
37.97,66.03,-0.206
37.99,65.93,-0.206
38.01,65.83,-0.206
38.03,65.73,-0.206
38.05,65.63,-0.206
38.07,65.53,-0.206
38.09,65.43,-0.206
38.11,65.33,-0.206
38.13,65.23,-0.206
38.15,65.13,-0.206
38.17,65.03,-0.206
38.19,64.93,-0.206
38.21,64.83,-0.206
38.23,64.73,-0.206
38.25,64.63,-0.206
38.27,64.53,-0.206
38.29,64.43,-0.206
[...]
137.16,15.08,0.141
137.19,15.23,0.141
137.22,15.38,0.141
137.25,15.54,0.141
137.28,15.68,0.141
137.31,15.83,0.141
137.34,15.98,0.141
137.37,16.14,0.141
137.40,16.29,0.142
137.43,16.44,0.142
137.46,16.59,0.142
137.49,16.74,0.142
137.52,16.89,0.142
137.55,17.04,0.142
137.58,17.19,0.142
137.61,17.34,0.142
137.64,17.49,0.142
137.67,17.64,0.142
137.70,17.79,0.142
137.73,17.94,0.142
137.76,18.09,0.142
137.79,18.24,0.142
137.82,18.39,0.142
137.85,18.54,0.142
137.88,18.69,0.142
137.91,18.84,0.142
137.94,18.99,0.142
137.97,19.14,0.142
138.00,19.29,0.143
138.03,19.44,0.142
138.06,19.59,0.143
138.09,19.74,0.143
138.12,19.89,0.143
138.15,20.04,0.143
138.18,20.19,0.143
138.21,20.34,0.143
138.24,20.49,0.143
138.27,20.64,0.143
138.30,20.79,0.143
138.33,20.94,0.143
138.36,21.09,0.143
138.39,21.24,0.143
138.42,21.39,0.143
138.45,21.54,0.143
138.48,21.69,0.143
138.51,21.84,0.143
138.54,21.99,0.143
138.57,22.14,0.143
138.60,22.29,0.143
138.63,22.44,0.143
138.66,22.59,0.144
138.69,22.74,0.144
138.72,22.89,0.144
138.75,23.04,0.144
138.78,23.19,0.144
138.81,23.34,0.144
138.84,23.49,0.144
138.87,23.64,0.144
138.90,23.79,0.144
138.93,23.94,0.144
138.96,24.09,0.144
138.99,24.24,0.144
139.02,24.39,0.144
139.05,24.54,0.144
139.08,24.69,0.144
139.11,24.84,0.144
139.14,24.99,0.144
139.17,25.14,0.145
139.20,25.29,0.145
139.23,25.44,0.145
139.26,25.59,0.145
139.29,25.74,0.145
139.32,25.89,0.145
139.35,26.04,0.145
139.38,26.19,0.145
139.41,26.34,0.145
139.44,26.49,0.145
139.47,26.64,0.145
139.50,26.79,0.145
139.53,26.94,0.145
139.56,27.09,0.145
139.59,27.24,0.145
139.62,27.39,0.145
139.65,27.54,0.145
139.68,27.69,0.145
139.71,27.84,0.145
139.74,27.99,0.145
139.77,28.14,0.146
139.80,28.29,0.146
139.83,28.44,0.146
139.86,28.59,0.146
139.89,28.74,0.146
139.92,28.89,0.146
139.95,29.05,0.146
139.98,29.20,0.146
140.01,29.35,0.146
140.04,29.49,0.146
140.07,29.64,0.146
140.10,29.80,0.146
140.13,29.95,0.146
140.16,30.10,0.146
140.19,30.25,0.146
140.22,30.40,0.146
140.25,30.54,0.146
140.28,30.70,0.146
140.31,30.85,0.146
140.34,31.00,0.147
140.37,31.15,0.147
140.40,31.30,0.147
140.43,31.45,0.147
140.46,31.60,0.147
140.49,31.75,0.147
140.52,31.90,0.147
140.55,32.05,0.147
140.58,32.20,0.147
140.61,32.35,0.147
140.64,32.50,0.147
140.67,32.65,0.147
140.70,32.80,0.147
140.73,32.95,0.147
140.76,33.10,0.147
140.79,33.25,0.147
140.82,33.40,0.147
140.85,33.55,0.147
140.88,33.70,0.147
140.91,33.85,0.148
140.94,34.00,0.148
140.97,34.15,0.148
141.00,34.30,0.148
141.03,34.45,0.148
141.06,34.60,0.148
141.09,34.75,0.148
141.12,34.90,0.148
141.15,35.05,0.148
141.18,35.20,0.148
141.21,35.35,0.148
141.24,35.50,0.148
141.27,35.65,0.148
141.30,35.80,0.148
141.33,35.95,0.148
141.36,36.10,0.148
141.39,36.25,0.148
141.42,36.40,0.148
141.45,36.55,0.148
141.48,36.70,0.148
141.51,36.85,0.148
141.54,37.00,0.148
141.57,37.15,0.148
141.60,37.30,0.148
141.63,37.45,0.148
141.66,37.60,0.148
141.69,37.75,0.149
141.72,37.90,0.149
141.75,38.05,0.149
141.78,38.20,0.149
141.81,38.35,0.149
141.84,38.50,0.149
141.87,38.65,0.149
141.90,38.80,0.149
141.93,38.95,0.149
141.96,39.10,0.149
141.99,39.25,0.149
142.02,39.40,0.149
142.05,39.55,0.149
142.08,39.70,0.149
142.11,39.85,0.149
142.14,40.00,0.149
142.17,40.15,0.149
142.20,40.30,0.149
142.23,40.45,0.149
142.26,40.60,0.149
142.29,40.75,0.150
142.32,40.90,0.150
142.35,41.05,0.150
142.38,41.20,0.150
142.41,41.35,0.150
142.44,41.50,0.150
142.47,41.65,0.150
142.50,41.80,0.150
142.53,41.95,0.150
142.56,42.10,0.150
142.59,42.25,0.150
142.62,42.40,0.150
142.65,42.55,0.150
142.68,42.70,0.150
142.71,42.85,0.150
142.74,43.00,0.150
142.77,43.15,0.150
142.80,43.30,0.150
142.83,43.45,0.150
142.86,43.60,0.150
142.89,43.75,0.150
142.92,43.90,0.150
142.95,44.05,0.150
142.98,44.20,0.150
143.01,44.35,0.151
143.04,44.50,0.151
143.07,44.65,0.151
143.10,44.80,0.151
143.13,44.95,0.151
143.16,45.10,0.151
143.19,45.25,0.151
143.22,45.40,0.151
143.25,45.55,0.151
143.28,45.71,0.151
143.31,45.85,0.151
143.34,46.00,0.151
143.37,46.16,0.151
143.40,46.30,0.151
143.43,46.46,0.151
143.46,46.60,0.151
143.49,46.76,0.151
143.52,46.91,0.151
143.55,47.06,0.152
143.58,47.21,0.152
143.61,47.36,0.152
143.64,47.51,0.152
143.67,47.66,0.152
143.70,47.81,0.152
143.73,47.96,0.152
143.76,48.11,0.152
143.79,48.26,0.152
143.82,48.41,0.152
143.85,48.56,0.152
143.88,48.71,0.152
143.91,48.86,0.152
143.94,49.01,0.152
143.97,49.16,0.152
144.00,49.31,0.152
144.03,49.46,0.152
144.06,49.61,0.152
144.09,49.76,0.152
144.12,49.91,0.152
144.15,50.06,0.153
144.18,50.21,0.153
144.21,50.36,0.153
144.24,50.51,0.153
144.27,50.66,0.153
144.30,50.81,0.153
144.33,50.96,0.153
144.36,51.11,0.153
144.39,51.26,0.153
144.42,51.41,0.153
144.45,51.56,0.153
144.48,51.71,0.153
144.51,51.86,0.153
144.54,52.01,0.153
144.57,52.16,0.153
144.60,52.31,0.153
144.63,52.46,0.153
144.66,52.61,0.153
144.69,52.76,0.153
144.72,52.91,0.153
144.75,53.06,0.153
144.78,53.21,0.153
144.81,53.36,0.154
144.84,53.51,0.154
144.87,53.66,0.154
144.90,53.81,0.154
144.93,53.96,0.154
144.96,54.11,0.154
144.99,54.26,0.154
145.02,54.41,0.154
145.05,54.56,0.154
145.08,54.71,0.154
145.11,54.86,0.154
145.14,55.01,0.154
145.17,55.16,0.154
145.20,55.31,0.154
145.23,55.46,0.154
145.26,55.61,0.154
145.29,55.76,0.154
145.32,55.91,0.154
145.35,56.06,0.154
145.38,56.21,0.154
145.41,56.36,0.154
145.44,56.51,0.154
145.47,56.66,0.154
145.50,56.81,0.154
145.53,56.96,0.155
145.56,57.11,0.155
145.59,57.26,0.155
145.62,57.41,0.155
145.65,57.56,0.155
145.68,57.71,0.155
145.71,57.87,0.155
145.74,58.01,0.155
145.77,58.16,0.155
145.80,58.31,0.155
145.83,58.47,0.155
145.86,58.62,0.155
145.89,58.77,0.155
145.92,58.92,0.155
145.95,59.06,0.155
145.98,59.22,0.155
146.01,59.37,0.155
146.04,59.52,0.155
146.07,59.67,0.155
146.10,59.82,0.155
146.13,59.97,0.155
146.16,60.12,0.155
146.19,60.27,0.156
146.22,60.42,0.156
146.25,60.57,0.156
146.28,60.72,0.156
146.31,60.86,0.156
146.34,61.01,0.156
146.37,61.17,0.156
146.40,61.31,0.156
146.43,61.47,0.156
146.46,61.62,0.156
146.49,61.76,0.156
146.52,61.91,0.156
146.55,62.07,0.156
146.58,62.21,0.156
146.61,62.37,0.156
146.64,62.51,0.156
146.67,62.66,0.156
146.70,62.81,0.156
146.73,62.96,0.156
146.76,63.11,0.156
146.79,63.27,0.156
146.82,63.41,0.156
146.85,63.56,0.156
146.88,63.72,0.156
146.91,63.86,0.156
146.94,64.02,0.156
146.97,64.17,0.157
147.00,64.32,0.157
147.03,64.47,0.157
147.06,64.62,0.157
147.09,64.77,0.157
147.12,64.92,0.157
147.15,65.07,0.157
147.18,65.22,0.157
147.21,65.37,0.157
147.24,65.52,0.157
147.27,65.67,0.157
147.30,65.82,0.157
147.33,65.97,0.157
147.36,66.12,0.157
147.39,66.27,0.157
147.42,66.42,0.157
147.45,66.57,0.157
147.48,66.72,0.157
147.51,66.87,0.157
147.54,67.02,0.158
147.57,67.17,0.158
147.60,67.32,0.158
147.63,67.47,0.158
147.66,67.62,0.158
147.69,67.77,0.158
147.72,67.92,0.158
147.75,68.07,0.158
147.78,68.22,0.158
147.81,68.37,0.158
147.84,68.52,0.158
147.87,68.67,0.158
147.90,68.82,0.158
147.93,68.97,0.158
147.96,69.12,0.158
147.99,69.27,0.158
148.02,69.42,0.158
148.05,69.57,0.158
148.08,69.72,0.158
148.11,69.87,0.158
148.14,70.02,0.158
148.17,70.17,0.158
148.20,70.32,0.158
148.23,70.47,0.158
148.26,70.62,0.158
148.29,70.77,0.158
148.32,70.92,0.159
148.35,71.07,0.159
148.38,71.22,0.159
148.41,71.37,0.159
148.44,71.52,0.159
148.47,71.67,0.159
148.50,71.82,0.159
148.53,71.97,0.159
148.56,72.12,0.159
148.59,72.27,0.159
148.62,72.42,0.159
148.65,72.57,0.159
148.68,72.72,0.159
148.71,72.87,0.159
148.74,73.02,0.159
148.77,73.17,0.159
148.80,73.32,0.159
148.83,73.47,0.159
148.86,73.62,0.159
148.89,73.77,0.159
148.92,73.92,0.159
148.95,74.07,0.159
148.98,74.22,0.159
149.01,74.37,0.160
149.04,74.52,0.160
149.07,74.67,0.160
149.10,74.82,0.160
149.13,74.97,0.160
149.16,75.12,0.160
149.19,75.27,0.160
149.22,75.42,0.160
149.25,75.57,0.160
149.28,75.72,0.160
149.31,75.87,0.160
149.34,76.02,0.160
149.37,76.17,0.160
149.40,76.32,0.160
149.43,76.47,0.160
149.46,76.62,0.160
149.49,76.77,0.160
149.52,76.92,0.160
149.55,77.07,0.160
149.58,77.22,0.160
149.61,77.37,0.160
149.64,77.52,0.160
149.67,77.67,0.160
149.70,77.82,0.160
149.73,77.97,0.160
149.76,78.12,0.161
149.79,78.27,0.161
149.82,78.42,0.161
149.85,78.57,0.161
149.88,78.73,0.161
149.91,78.88,0.161
149.94,79.03,0.161
149.97,79.17,0.161
150.00,79.32,0.161
150.03,79.47,0.161
150.06,79.63,0.161
150.09,79.78,0.161
150.12,79.93,0.161
150.15,80.08,0.161
150.18,80.22,0.161
150.21,80.38,0.161
150.24,80.52,0.161
150.27,80.68,0.161
150.30,80.82,0.161
150.33,80.97,0.161
150.36,81.12,0.161
150.39,81.27,0.161
150.42,81.43,0.161
150.45,81.58,0.161
150.48,81.72,0.161
150.51,81.88,0.161
150.54,82.02,0.161
150.57,82.18,0.161
150.60,82.33,0.162
150.63,82.47,0.162
150.66,82.63,0.162
150.69,82.78,0.162
150.72,82.93,0.162
150.75,83.08,0.162
150.78,83.23,0.162
150.81,83.38,0.162
150.84,83.53,0.162
150.87,83.68,0.162
150.90,83.83,0.162
150.93,83.98,0.162
150.96,84.13,0.162
150.99,84.28,0.162
151.02,84.43,0.162
151.05,84.58,0.162
151.08,84.73,0.162
151.11,84.88,0.162
151.14,85.03,0.162
151.17,85.18,0.162
151.20,85.33,0.162
151.23,85.48,0.162
151.26,85.63,0.162
151.29,85.78,0.162
151.32,85.93,0.162
151.35,86.08,0.162
151.38,86.23,0.162
151.41,86.38,0.162
151.44,86.53,0.162
151.47,86.68,0.162
151.50,86.83,0.162
151.53,86.98,0.162
151.56,87.13,0.162
151.59,87.28,0.162
151.62,87.43,0.162
151.65,87.58,0.163
151.68,87.73,0.163
151.71,87.88,0.163
151.74,88.03,0.163
151.77,88.18,0.163
151.80,88.33,0.163
151.83,88.48,0.163
151.86,88.63,0.163
151.89,88.78,0.163
151.92,88.93,0.163
151.95,89.08,0.163
151.98,89.23,0.163
152.01,89.38,0.163
152.04,89.53,0.163
152.07,89.68,0.163
152.10,89.83,0.163
152.13,89.98,0.163
152.16,90.13,0.163
152.19,90.28,0.163
152.22,90.43,0.163
152.25,90.58,0.163
152.28,90.73,0.163
152.31,90.88,0.164
152.34,91.03,0.164
152.37,91.18,0.164
152.40,91.33,0.164
152.43,91.48,0.164
152.46,91.63,0.164
152.49,91.78,0.164
152.52,91.93,0.164
152.55,92.08,0.164
152.58,92.23,0.164
152.61,92.38,0.164
152.64,92.53,0.164
152.67,92.68,0.164
152.70,92.83,0.164
152.73,92.98,0.164
152.76,93.13,0.164
152.79,93.28,0.164
152.82,93.43,0.164
152.85,93.58,0.164
152.88,93.73,0.164
152.91,93.88,0.164
152.94,94.03,0.164
152.97,94.18,0.165
153.00,94.33,0.164
153.03,94.48,0.165
153.06,94.63,0.165
153.09,94.78,0.165
153.12,94.93,0.165
153.15,95.08,0.165
153.18,95.23,0.165
153.21,95.38,0.165
153.24,95.53,0.165
153.27,95.68,0.165
153.30,95.83,0.165
153.33,95.98,0.165
153.36,96.13,0.165
153.39,96.28,0.165
153.42,96.43,0.165
153.45,96.58,0.165
153.48,96.73,0.165
153.51,96.88,0.165
153.54,97.03,0.165
153.57,97.18,0.165
153.60,97.33,0.166
153.63,97.48,0.166
153.66,97.63,0.166
153.69,97.78,0.166
153.72,97.93,0.166
153.75,98.08,0.166
153.78,98.23,0.166
153.81,98.38,0.166
153.84,98.53,0.166
153.87,98.68,0.166
153.90,98.83,0.166
153.93,98.98,0.166
153.96,99.13,0.166
153.99,99.28,0.166
154.02,99.43,0.166
154.05,99.59,0.166
154.08,99.73,0.166
154.11,99.89,0.166
154.14,100.04,0.166
154.17,100.19,0.166
154.20,100.34,0.166
154.23,100.49,0.167
154.26,100.64,0.167
154.29,100.79,0.167
154.32,100.93,0.167
154.35,101.09,0.167
154.38,101.24,0.167
154.41,101.39,0.167
154.44,101.54,0.167
154.47,101.69,0.167
154.50,101.84,0.167
154.53,101.99,0.167
154.56,102.14,0.167
154.59,102.29,0.167
154.62,102.44,0.167
154.65,102.59,0.167
154.68,102.74,0.167
154.71,102.89,0.167
154.74,103.04,0.167
154.77,103.19,0.167
154.80,103.34,0.167
154.83,103.49,0.167
154.86,103.64,0.167
154.89,103.79,0.167
154.92,103.94,0.167
154.95,104.09,0.167
154.98,104.24,0.167
155.01,104.39,0.167
155.04,104.54,0.167
155.07,104.69,0.167
155.10,104.84,0.168
155.13,104.99,0.168
155.16,105.14,0.168
155.19,105.29,0.168
155.22,105.44,0.168
155.25,105.59,0.168
155.28,105.74,0.168
155.31,105.89,0.168
155.34,106.04,0.168
155.37,106.19,0.168
155.40,106.34,0.168
155.43,106.49,0.168
155.46,106.64,0.168
155.49,106.79,0.168
155.52,106.94,0.168
155.55,107.09,0.168
155.58,107.24,0.168
155.61,107.39,0.168
155.64,107.54,0.168
155.67,107.69,0.168
155.70,107.84,0.168
155.73,107.99,0.168
155.76,108.14,0.168
155.79,108.29,0.168
155.82,108.44,0.168
155.85,108.59,0.168
155.88,108.74,0.168
155.91,108.89,0.168
155.94,109.04,0.169
155.97,109.19,0.169
156.00,109.34,0.169
156.03,109.49,0.169
156.06,109.64,0.169
156.09,109.79,0.169
156.12,109.94,0.169
156.15,110.09,0.169
156.18,110.24,0.169
156.21,110.39,0.169
156.24,110.54,0.169
156.27,110.69,0.169
156.30,110.84,0.169
156.33,110.99,0.169
156.36,111.14,0.169
156.39,111.29,0.169
156.42,111.44,0.169
156.45,111.59,0.169
156.48,111.74,0.169
156.51,111.89,0.169
156.54,112.04,0.169
156.57,112.19,0.169
156.60,112.34,0.170
156.63,112.49,0.170
156.66,112.64,0.170
156.69,112.79,0.170
156.72,112.94,0.170
156.75,113.09,0.170
156.78,113.24,0.170
156.81,113.39,0.170
156.84,113.54,0.170
156.87,113.69,0.170
156.90,113.84,0.170
156.93,113.99,0.170
156.96,114.14,0.170
156.99,114.29,0.170
157.02,114.44,0.170
157.05,114.59,0.170
157.08,114.74,0.170
157.11,114.89,0.170
157.14,115.04,0.170
157.17,115.19,0.170
157.20,115.34,0.170
157.23,115.49,0.170
157.26,115.64,0.170
157.29,115.79,0.170
157.32,115.94,0.170
157.35,116.09,0.170
157.38,116.24,0.170
157.41,116.39,0.170
157.44,116.54,0.170
157.47,116.69,0.170
157.50,116.84,0.170
157.53,116.99,0.170
157.56,117.14,0.170
157.59,117.29,0.170
157.62,117.44,0.170
157.65,117.59,0.170
157.68,117.74,0.170
157.71,117.89,0.170
157.74,118.04,0.171
157.77,118.19,0.171
157.80,118.34,0.171
157.83,118.49,0.171
157.86,118.64,0.171
157.89,118.79,0.171
157.92,118.94,0.171
157.95,119.09,0.171
157.98,119.24,0.171
158.01,119.39,0.171
158.04,119.54,0.171
158.07,119.69,0.171
158.10,119.84,0.171
158.13,119.99,0.171
158.16,120.14,0.171
158.19,120.29,0.171
158.22,120.44,0.171
158.25,120.59,0.171
158.28,120.74,0.171
158.31,120.89,0.171
158.34,121.04,0.171
158.37,121.19,0.171
158.40,121.34,0.171
158.43,121.49,0.171
158.46,121.64,0.171
158.49,121.79,0.171
158.52,121.94,0.171
158.55,122.09,0.172
158.58,122.24,0.172
158.61,122.39,0.172
158.64,122.54,0.172
158.67,122.69,0.172
158.70,122.84,0.172
158.73,122.99,0.172
158.76,123.14,0.172
158.79,123.29,0.172
158.82,123.44,0.172
158.85,123.59,0.172
158.88,123.74,0.172
158.91,123.89,0.172
158.94,124.04,0.172
158.97,124.19,0.172
159.00,124.34,0.172
159.03,124.49,0.172
159.06,124.64,0.172
159.09,124.80,0.172
159.12,124.95,0.172
159.15,125.09,0.172
159.18,125.25,0.172
159.21,125.39,0.172
159.24,125.54,0.172
159.27,125.69,0.172
159.30,125.84,0.172
159.33,125.99,0.172
159.36,126.14,0.172
159.39,126.30,0.172
159.42,126.45,0.172
159.45,126.59,0.172
159.48,126.74,0.172
159.51,126.90,0.173
159.54,127.05,0.172
159.57,127.19,0.173
159.60,127.34,0.173
159.63,127.50,0.173
159.66,127.65,0.173
159.69,127.79,0.173
159.72,127.95,0.173
159.75,128.10,0.173
159.78,128.25,0.173
159.81,128.40,0.173
159.84,128.55,0.173
159.87,128.70,0.173
159.90,128.85,0.173
159.93,129.00,0.173
159.96,129.15,0.173
159.99,129.30,0.173
160.02,129.45,0.173
160.05,129.60,0.173
160.08,129.75,0.173
160.11,129.90,0.173
160.14,130.05,0.173
160.17,130.20,0.173
160.20,130.35,0.173
160.23,130.50,0.173
160.26,130.65,0.173
160.29,130.80,0.173
160.32,130.95,0.173
160.35,131.10,0.173
160.38,131.25,0.173
160.41,131.40,0.173
160.44,131.55,0.173
160.47,131.70,0.173
160.50,131.85,0.173
160.53,132.00,0.174
160.56,132.15,0.174
160.59,132.30,0.174
160.62,132.45,0.174
160.65,132.60,0.174
160.68,132.75,0.174
160.71,132.90,0.174
160.74,133.05,0.174
160.77,133.20,0.174
160.80,133.35,0.174
160.83,133.50,0.174
160.86,133.65,0.174
160.89,133.80,0.174
160.92,133.95,0.174
160.95,134.10,0.174
160.98,134.25,0.174
161.01,134.40,0.174
161.04,134.55,0.174
161.07,134.70,0.174
161.10,134.85,0.174
161.13,135.00,0.174
161.16,135.15,0.174
161.19,135.30,0.174
161.22,135.45,0.174
161.25,135.60,0.174
161.28,135.75,0.174
161.31,135.90,0.174
161.34,136.05,0.174
161.37,136.20,0.174
161.40,136.35,0.174
161.43,136.50,0.174
161.46,136.65,0.174
161.49,136.80,0.174
161.52,136.95,0.174
161.55,137.10,0.174
161.58,137.25,0.174
161.61,137.40,0.174
161.64,137.55,0.174
161.67,137.70,0.174
161.70,137.85,0.174
161.73,138.00,0.174
161.76,138.15,0.174
161.79,138.30,0.174
161.82,138.45,0.174
161.85,138.60,0.174
161.88,138.75,0.174
161.91,138.90,0.174
161.94,139.05,0.174
161.97,139.20,0.174
162.00,139.35,0.174
162.03,139.50,0.174
162.06,139.65,0.174
162.09,139.80,0.174
162.12,139.95,0.174
162.15,140.10,0.174
162.18,140.25,0.174
162.21,140.40,0.174
162.24,140.55,0.174
162.27,140.70,0.174
162.30,140.85,0.174
162.33,141.00,0.174
162.36,141.15,0.174
162.39,141.30,0.174
162.42,141.45,0.174
162.45,141.60,0.174
162.48,141.75,0.174
162.51,141.90,0.174
162.54,142.05,0.174
162.57,142.20,0.174
162.60,142.35,0.174
162.63,142.50,0.174
162.66,142.65,0.174
162.69,142.80,0.174
162.72,142.95,0.174
162.75,143.10,0.174
162.78,143.25,0.174
162.81,143.40,0.174
162.84,143.55,0.174
162.87,143.70,0.174
162.90,143.85,0.174
162.93,144.00,0.174
162.96,144.15,0.174
162.99,144.30,0.174
163.02,144.45,0.174
163.05,144.60,0.174
163.08,144.75,0.174
163.11,144.90,0.174
163.14,145.05,0.174
163.17,145.20,0.174
163.20,145.35,0.174
163.23,145.50,0.174
163.26,145.65,0.174
163.29,145.80,0.174
163.32,145.95,0.174
163.35,146.10,0.174
163.38,146.25,0.174
163.41,146.40,0.174
163.44,146.55,0.174
163.47,146.70,0.174
163.50,146.85,0.174
163.53,147.00,0.174
163.56,147.15,0.174
163.59,147.30,0.174
163.62,147.45,0.174
163.65,147.60,0.174
163.68,147.75,0.173
163.71,147.90,0.173
163.74,148.05,0.173
163.77,148.20,0.173
163.80,148.35,0.173
163.83,148.50,0.173
163.86,148.65,0.173
163.89,148.80,0.173
163.92,148.95,0.173
163.95,149.10,0.173
163.98,149.25,0.173
164.01,149.40,0.173
164.04,149.55,0.173
164.07,149.70,0.173
164.10,149.85,0.173
164.13,150.00,0.173
164.16,150.15,0.173
164.19,150.30,0.173
164.22,150.45,0.173
164.25,150.60,0.173
164.28,150.75,0.172
164.31,150.90,0.172
164.34,151.05,0.172
164.37,151.20,0.172
164.40,151.35,0.172
164.43,151.50,0.172
164.46,151.65,0.172
164.49,151.80,0.172
164.52,151.95,0.172
164.55,152.10,0.172
164.58,152.25,0.172
164.61,152.41,0.172
164.64,152.55,0.172
164.67,152.70,0.172
164.70,152.85,0.172
164.73,153.00,0.172
164.76,153.15,0.172
164.79,153.30,0.172
164.82,153.45,0.172
164.85,153.61,0.172
164.88,153.76,0.171
164.91,153.91,0.171
164.94,154.06,0.171
164.97,154.21,0.171
165.00,154.35,0.171
165.03,154.51,0.171
165.06,154.66,0.171
165.09,154.81,0.171
165.12,154.96,0.171
165.15,155.11,0.170
165.18,155.26,0.170
165.21,155.41,0.170
165.24,155.56,0.170
165.27,155.71,0.170
165.30,155.86,0.170
165.33,156.01,0.170
165.36,156.16,0.170
165.39,156.31,0.170
165.42,156.46,0.169
165.45,156.61,0.169
165.48,156.76,0.169
165.51,156.91,0.169
165.54,157.06,0.169
165.57,157.21,0.168
165.60,157.36,0.168
165.63,157.51,0.168
165.66,157.66,0.168
165.69,157.81,0.168
165.72,157.96,0.168
165.75,158.11,0.168
165.78,158.26,0.167
165.81,158.41,0.167
165.84,158.56,0.167
165.87,158.71,0.167
165.90,158.86,0.167
165.93,159.01,0.167
165.96,159.16,0.166
165.99,159.31,0.166
166.02,159.46,0.166
166.05,159.61,0.166
166.08,159.76,0.165
166.11,159.91,0.165
166.14,160.06,0.165
166.17,160.21,0.165
166.20,160.36,0.164
166.23,160.51,0.164
166.26,160.66,0.164
166.29,160.81,0.164
166.32,160.96,0.163
166.35,161.11,0.163
166.38,161.26,0.163
166.41,161.41,0.163
166.44,161.56,0.163
166.47,161.71,0.162
166.50,161.86,0.162
166.53,162.01,0.162
166.56,162.16,0.161
166.59,162.31,0.161
166.62,162.46,0.161
166.65,162.61,0.161
166.68,162.76,0.160
166.71,162.91,0.160
166.74,163.06,0.160
166.77,163.21,0.159
166.80,163.36,0.159
166.83,163.51,0.159
166.86,163.66,0.159
166.89,163.81,0.158
166.92,163.96,0.158
166.95,164.11,0.158
166.98,164.26,0.157
167.01,164.41,0.157
167.04,164.56,0.157
167.07,164.71,0.156
167.10,164.86,0.156
167.13,165.01,0.156
167.16,165.16,0.155
167.19,165.31,0.155
167.22,165.46,0.154
167.25,165.61,0.154
167.28,165.76,0.154
167.31,165.91,0.154
167.34,166.06,0.153
167.37,166.21,0.153
167.40,166.36,0.153
167.43,166.52,0.152
167.46,166.67,0.152
167.49,166.82,0.152
167.52,166.97,0.151
167.55,167.12,0.151
167.58,167.27,0.151
167.61,167.42,0.150
167.64,167.57,0.150
167.67,167.72,0.150
167.70,167.87,0.149
167.73,168.02,0.149
167.76,168.17,0.149
167.79,168.32,0.148
167.82,168.47,0.148
167.85,168.62,0.148
167.88,168.77,0.147
167.91,168.92,0.147
167.94,169.07,
167.97,169.22,
167.99,,