File: DSC/2024_11_12_DSC_Sapphire_5Cmin_x4.csv
Filename,2024_11_12_DSC_Sapphire_5Cmin_x4
Instrument name,DSC2A-00468 (192.168.1.100)
Operator,Yarger
rundate,11/13/2024
Sample name,2024_11_12_DSC_Sapphire_5Cmin_x4
proceduresegments,Data Off ; Equilibrate -50.00 °C; Data On ; Ramp 5.00 °C/min to 100.00 °C; Data Off ; Isothermal 1.0 min; Data On ; Ramp 5.00 °C/min to -50.00 °C; Data Off ; Isothermal 1.0 min; Data On ; Ramp 5.00 °C/min to 100.00 °C; Data Off ; Isothermal 1.0 min; Data On ; Ramp 5.00 °C/min to -50.00 °C; Data Off ; Isothermal 1.0 min; Data On ; Ramp 5.00 °C/min to 170.00 °C; Data Off ; Isothermal 1.0 min; Data On ; Ramp 5.00 °C/min to -50.00 °C; Data Off ; Isothermal 1.0 min; Data On ; Ramp 5.00 °C/min to 170.00 °C
[File Parameters]
Run date,11/13/2024 2:22:50 PM
Trios version,5.1.1.46572
Original File Name,
Current File Name,D:\DSC2500\JYarger\2024_11_12_DSC_Sapphire_5Cmin_x4.tri
[Procedure]
Procedure Name,Sapphire Baselines
Sample Name,2024_11_12_DSC_Sapphire_5Cmin_x4
Sample Mass,23.5 mg
Reference Sample Mass,0 mg
Pan Mass,52.18 mg
Pan Number,2
Reference Pan Mass,53.32 mg
Reference Pan Number,10
Pan Type,Tzero Aluminum Hermetic
Comments,"Sapphire Disc, Cp standard. Al hermetic Pan/Lid.  DSC_BST1_Tray_Nov2024 google sheet."
Project Name,CoCrystals
Operator,Yarger
Test,Custom
Unload Max Temperature,30
Unload Min Temperature,30
Load Max Temperature,30
Load Min Temperature,30
Stop on Gas Flow Error,Yes
[Signal List]
Signal #1,Time (min)
Signal #2,Temperature (°C)
Signal #3,Heat Flow (mW)
Signal #4,Delta T (µV)
Signal #5,Delta Tzero (µV)
Signal #6,Tzero Temperature (°C)
Signal #7,Cell Purge (mL/min)
Signal #8,Heater Temp (°C)
Signal #9,Power Delivered (W)
Signal #10,Reference Junction Temperature (°C)
Signal #11,Flange Temperature (°C)
Signal #12,Heat Flow Phase (rad)
Signal #13,Total Heat Capacity (J/°C)
Signal #14,Heat Capacity (J/°C)
[Configuration]
Company Name,ASU
Instrument Name,DSC2A-00468
Instrument Type,DSC2500
Serial Number,DSC2A-00468
IP,192.168.1.100
Location of Instrument,MRRC
DisplayType,Unknown
Sample Interval ,0.1 s/pt
Selected Heat Flow,T4P
Exotherm Direction,Down
Cell Serial,DRC2-00792
Lid Type,Standard
Cooler,RCS 90
Leave Cooler on at End of Sequence,On
Gas 2,Nitrogen
Gas Selected,Channel 1
Flow Rate,50 mL/min
Secondary Purge,On
Licensed Heat Flow,Heat Flow T4P
Modulation Licensed,Yes
[Versions]
Common IDD Version,1
Cortex Version,VER 2.10.2.31
Driver,5.0.0.6
GDM Version,1.0.3.3
TouchscreenVersion,1.0.0.16145
FEP Version,1.2.1.21
FEP Bootloader,2.0.0.5
AutoSampler Version,2.1.1.26
Auto Sampler Bootloader,2.0.0.5
FCM Version,1.1.0.3
FCM Bootloader,2.0.0.5
[Experiment Logs]
Experiment Log Entry # 1,Lid Close
Experiment Log Entry # 3,Data On set to 0
Experiment Log Entry # 5,Equilibrate Segment -50 (C) Started
Experiment Log Entry # 7,Air Cool is off.
Experiment Log Entry # 9,Data On set to 1
Experiment Log Entry # 11,Ramp Segment 5 C/min to 100 Started
Experiment Log Entry # 13,Data On set to 0
Experiment Log Entry # 15,Isothermal Segment 1 min started
Experiment Log Entry # 17,Data On set to 1
Experiment Log Entry # 19,Ramp Segment 5 C/min to -50 Started
Experiment Log Entry # 21,Data On set to 0
Experiment Log Entry # 23,Isothermal Segment 1 min started
Experiment Log Entry # 25,Data On set to 1
Experiment Log Entry # 27,Ramp Segment 5 C/min to 100 Started
Experiment Log Entry # 29,Data On set to 0
Experiment Log Entry # 31,Isothermal Segment 1 min started
Experiment Log Entry # 33,Data On set to 1
Experiment Log Entry # 35,Ramp Segment 5 C/min to -50 Started
Experiment Log Entry # 37,Data On set to 0
Experiment Log Entry # 39,Isothermal Segment 1 min started
Experiment Log Entry # 41,Data On set to 1
Experiment Log Entry # 43,Ramp Segment 5 C/min to 170 Started
Experiment Log Entry # 45,Data On set to 0
Experiment Log Entry # 47,Isothermal Segment 1 min started
Experiment Log Entry # 49,Data On set to 1
Experiment Log Entry # 51,Ramp Segment 5 C/min to -50 Started
Experiment Log Entry # 53,Data On set to 0
Experiment Log Entry # 55,Isothermal Segment 1 min started
Experiment Log Entry # 57,Data On set to 1
Experiment Log Entry # 59,Ramp Segment 5 C/min to 170 Started
[Method Log]
Method Log Entry # 1,Data Off
Method Log Entry # 2,Equilibrate -50 °C
Method Log Entry # 3,Data On
Method Log Entry # 4,(Ramp 490827) Ramp 5 °C/minute to 100 °C
Method Log Entry # 5,Data Off
Method Log Entry # 6,Isothermal 1 minutes
Method Log Entry # 7,Data On
Method Log Entry # 8,(Ramp 490831) Ramp 5 °C/minute to -50 °C
Method Log Entry # 9,Data Off
Method Log Entry # 10,Isothermal 1 minutes
Method Log Entry # 11,Data On
Method Log Entry # 12,(Ramp 490835) Ramp 5 °C/minute to 100 °C
Method Log Entry # 13,Data Off
Method Log Entry # 14,Isothermal 1 minutes
Method Log Entry # 15,Data On
Method Log Entry # 16,(Ramp 490839) Ramp 5 °C/minute to -50 °C
Method Log Entry # 17,Data Off
Method Log Entry # 18,Isothermal 1 minutes
Method Log Entry # 19,Data On
Method Log Entry # 20,(Ramp 490843) Ramp 5 °C/minute to 170 °C
Method Log Entry # 21,Data Off
Method Log Entry # 22,Isothermal 1 minutes
Method Log Entry # 23,Data On
Method Log Entry # 24,(Ramp 490847) Ramp 5 °C/minute to -50 °C
Method Log Entry # 25,Data Off
Method Log Entry # 26,Isothermal 1 minutes
Method Log Entry # 27,Data On
Method Log Entry # 28,(Ramp 490851) Ramp 5 °C/minute to 170 °C
Cell Serial,DRC2-00792
[T1 Calibration]
Slope,-0.008529666
Offset,9.636258
Initial Temperature,98.23
GUID,f8bfdadc-4977-4fdf-ba6d-0ba9134940c3
[TZero Calibration]
Date Applied,11/29/2022 4:06:13 PM
Description,From -89.059 °C to 396.009 °C at 20.000°C/min
Gas Type,Nitrogen
Pan Type,None
Source Files 1,C:\Users\yargerlab\Desktop\DSC Data\General\TZero_calibration_11_29_22_2nd(2).tri
Source Files 2,C:\Users\yargerlab\Desktop\DSC Data\General\TZero_calibration_11_29_22_2nd(3).tri
Delta T Offset,13.05235
Delta T Slope,-0.007271007
Delta T0 Offset,-13.69128
Delta T0 Slope,0.06063341
[Temperature Calibration]
Date Applied,11/29/2022 7:12:28 PM
Description,From 106.590 °C to 186.590 °C at 10.000°C/min
Gas Type,Nitrogen
Pan Type,Tzero Aluminum Hermetic
Source Files 1,C:\Users\yargerlab\Desktop\DSC Data\General\Indium(6).tri
Measured 1,157.391
Known 1,156.598
[Cell Constant Calibration]
Date Applied,11/29/2022 7:12:29 PM
Description,From 106.590 °C to 186.590 °C at 10.000°C/min
Gas Type,Nitrogen
Pan Type,Tzero Aluminum Hermetic
Source Files 1,C:\Users\yargerlab\Desktop\DSC Data\General\Indium(6).tri
T4P KCell,1.006051
Onset Slope,63.26126 mW/°C
[Direct Cp Calibration]
Date Applied,11/30/2022 11:04:51 AM
Description,From -79.983 °C to 298.409 °C at 10.000°C/min
Gas Type,Nitrogen
Pan Type,Tzero Aluminum Hermetic
Source Files 1,C:\Users\yargerlab\Desktop\DSC Data\General\Sapphire_Heat_Capacity_11_30_22.tri
[Rev Cp Calibration]
Date Applied,11/30/2022 1:58:51 PM
Description,From -79.996 °C to 292.812 °C at 3.000°C/min
Gas Type,Nitrogen
Pan Type,Tzero Aluminum Hermetic
Source Files 1,C:\Users\yargerlab\Desktop\DSC Data\General\Sapphire_MDSC_Calibration_11_30_22.tri
[step]
Ramp 5.00 °C/min to 100.00 °C
Time,Temperature,Heat Flow (Normalized)
min,°C,W/g
0.00,-49.69,-0.018
0.02,-49.70,-0.019
0.04,-49.71,-0.016
0.06,-49.72,-0.014
0.08,-49.71,-0.010
0.10,-49.70,-0.006
0.12,-49.67,-0.001
0.14,-49.63,0.004
0.16,-49.58,0.010
0.18,-49.52,0.016
0.20,-49.46,0.020
0.22,-49.38,0.025
0.24,-49.31,0.029
0.26,-49.23,0.032
0.28,-49.15,0.035
0.30,-49.06,0.037
0.32,-48.97,0.039
0.34,-48.88,0.040
0.36,-48.79,0.042
0.38,-48.70,0.043
0.40,-48.61,0.043
0.42,-48.52,0.044
0.44,-48.42,0.045
0.46,-48.33,0.045
0.48,-48.24,0.046
0.50,-48.14,0.046
0.52,-48.05,0.046
0.54,-47.95,0.047
0.56,-47.85,0.047
0.58,-47.76,0.047
0.60,-47.66,0.047
0.62,-47.56,0.047
0.64,-47.47,0.047
0.66,-47.37,0.047
0.68,-47.27,0.048
0.70,-47.18,0.048
0.72,-47.08,0.048
0.74,-46.98,0.048
0.76,-46.88,0.048
0.78,-46.79,0.048
0.80,-46.69,0.048
0.82,-46.59,0.048
0.84,-46.49,0.048
0.86,-46.39,0.048
0.88,-46.30,0.049
0.90,-46.20,0.049
0.92,-46.10,0.049
0.94,-46.00,0.049
0.96,-45.90,0.049
0.98,-45.80,0.049
1.00,-45.70,0.049
1.02,-45.61,0.049
1.04,-45.51,0.049
1.06,-45.41,0.049
1.08,-45.31,0.049
1.10,-45.21,0.049
1.12,-45.11,0.049
1.14,-45.01,0.049
1.16,-44.91,0.049
1.18,-44.82,0.049
1.20,-44.72,0.049
1.22,-44.62,0.049
1.24,-44.52,0.050
1.26,-44.42,0.050
1.28,-44.32,0.050
1.30,-44.22,0.050
1.32,-44.12,0.050
1.34,-44.02,0.050
1.36,-43.92,0.050
1.38,-43.82,0.050
1.40,-43.72,0.050
1.42,-43.62,0.050
1.44,-43.52,0.050
1.46,-43.42,0.050
1.48,-43.33,0.050
1.50,-43.22,0.050
1.52,-43.13,0.050
1.54,-43.03,0.050
1.56,-42.93,0.050
1.58,-42.83,0.050
1.60,-42.73,0.050
1.62,-42.63,0.050
1.64,-42.53,0.050
1.66,-42.43,0.050
1.68,-42.33,0.050
1.70,-42.23,0.050
1.72,-42.13,0.050
1.74,-42.03,0.050
1.76,-41.93,0.050
1.78,-41.83,0.050
1.80,-41.73,0.050
1.82,-41.63,0.050
1.84,-41.53,0.050
1.86,-41.43,0.050
1.88,-41.33,0.050
1.90,-41.23,0.050
1.92,-41.13,0.050
1.94,-41.03,0.050
1.96,-40.93,0.050
1.98,-40.83,0.050
2.00,-40.73,0.050
2.02,-40.63,0.050
2.04,-40.53,0.050
2.06,-40.43,0.050
2.08,-40.33,0.050
2.10,-40.23,0.050
2.12,-40.13,0.050
2.14,-40.03,0.050
2.16,-39.93,0.051
2.18,-39.83,0.051
2.20,-39.73,0.051
2.22,-39.63,0.051
2.24,-39.53,0.051
2.26,-39.43,0.051
2.28,-39.33,0.051
2.30,-39.23,0.051
2.32,-39.13,0.051
2.34,-39.03,0.051
2.36,-38.93,0.051
2.38,-38.83,0.051
2.40,-38.73,0.051
2.42,-38.63,0.051
2.44,-38.53,0.051
2.46,-38.43,0.051
2.48,-38.33,0.051
2.50,-38.23,0.051
2.52,-38.13,0.051
2.54,-38.03,0.051
2.56,-37.93,0.051
2.58,-37.83,0.051
2.60,-37.73,0.051
2.62,-37.63,0.051
2.64,-37.53,0.051
2.66,-37.43,0.051
2.68,-37.33,0.051
2.70,-37.23,0.051
2.72,-37.13,0.051
2.74,-37.03,0.051
2.76,-36.93,0.051
2.78,-36.83,0.051
2.80,-36.73,0.051
2.82,-36.63,0.051
2.84,-36.53,0.051
2.86,-36.43,0.051
2.88,-36.33,0.051
2.90,-36.23,0.051
2.92,-36.13,0.051
2.94,-36.03,0.051
2.96,-35.93,0.051
2.98,-35.83,0.051
3.00,-35.73,0.051
3.02,-35.63,0.051
3.04,-35.53,0.051
3.06,-35.43,0.051
3.08,-35.33,0.051
3.10,-35.23,0.051
3.12,-35.13,0.051
3.14,-35.03,0.051
3.16,-34.93,0.051
3.18,-34.83,0.051
3.20,-34.73,0.051
3.22,-34.63,0.051
3.24,-34.53,0.051
3.26,-34.43,0.051
3.28,-34.33,0.051
3.30,-34.23,0.051
3.32,-34.13,0.051
3.34,-34.03,0.051
3.36,-33.93,0.051
3.38,-33.83,0.051
3.40,-33.73,0.051
3.42,-33.63,0.051
3.44,-33.53,0.051
3.46,-33.43,0.051
3.48,-33.33,0.051
3.50,-33.23,0.051
3.52,-33.13,0.052
3.54,-33.03,0.052
3.56,-32.93,0.052
3.58,-32.83,0.052
3.60,-32.73,0.052
3.62,-32.63,0.052
3.64,-32.53,0.052
3.66,-32.43,0.052
3.68,-32.33,0.052
3.70,-32.23,0.052
3.72,-32.13,0.052
3.74,-32.03,0.052
3.76,-31.93,0.052
3.78,-31.83,0.052
3.80,-31.73,0.052
3.82,-31.63,0.052
3.84,-31.53,0.052
3.86,-31.42,0.052
3.88,-31.33,0.052
3.90,-31.23,0.052
3.92,-31.13,0.052
3.94,-31.03,0.052
3.96,-30.93,0.052
3.98,-30.83,0.052
4.00,-30.72,0.052
4.02,-30.62,0.052
4.04,-30.53,0.052
4.06,-30.42,0.052
4.08,-30.33,0.052
4.10,-30.23,0.052
4.12,-30.12,0.052
4.14,-30.02,0.052
4.16,-29.92,0.052
4.18,-29.82,0.052
4.20,-29.72,0.052
4.22,-29.62,0.052
4.24,-29.52,0.052
4.26,-29.42,0.052
4.28,-29.32,0.052
4.30,-29.22,0.052
4.32,-29.12,0.052
4.34,-29.02,0.052
4.36,-28.92,0.052
4.38,-28.82,0.052
4.40,-28.72,0.052
4.42,-28.62,0.052
4.44,-28.52,0.052
4.46,-28.42,0.052
4.48,-28.32,0.052
4.50,-28.22,0.052
4.52,-28.12,0.052
4.54,-28.02,0.052
4.56,-27.92,0.052
4.58,-27.82,0.052
4.60,-27.72,0.052
4.62,-27.62,0.052
4.64,-27.52,0.052
4.66,-27.42,0.052
4.68,-27.32,0.052
4.70,-27.22,0.052
4.72,-27.12,0.052
4.74,-27.02,0.052
4.76,-26.92,0.052
4.78,-26.82,0.053
4.80,-26.72,0.053
4.82,-26.62,0.053
4.84,-26.52,0.053
4.86,-26.42,0.053
4.88,-26.32,0.053
4.90,-26.22,0.053
4.92,-26.12,0.053
4.94,-26.02,0.053
4.96,-25.92,0.053
4.98,-25.82,0.053
5.00,-25.72,0.053
5.02,-25.62,0.053
5.04,-25.52,0.053
5.06,-25.42,0.053
5.08,-25.32,0.053
5.10,-25.22,0.053
5.12,-25.12,0.053
5.14,-25.02,0.053
5.16,-24.92,0.053
5.18,-24.82,0.053
5.20,-24.72,0.053
5.22,-24.62,0.053
5.24,-24.52,0.053
5.26,-24.42,0.053
5.28,-24.32,0.053
5.30,-24.22,0.053
5.32,-24.12,0.053
5.34,-24.02,0.053
5.36,-23.92,0.053
5.38,-23.82,0.053
5.40,-23.72,0.053
5.42,-23.62,0.053
5.44,-23.52,0.053
5.46,-23.42,0.053
5.48,-23.32,0.053
5.50,-23.22,0.053
5.52,-23.12,0.053
5.54,-23.02,0.053
5.56,-22.92,0.053
5.58,-22.82,0.053
5.60,-22.72,0.053
5.62,-22.62,0.053
5.64,-22.52,0.053
5.66,-22.42,0.053
5.68,-22.32,0.053
5.70,-22.22,0.053
5.72,-22.12,0.053
5.74,-22.02,0.053
5.76,-21.92,0.053
5.78,-21.82,0.053
5.80,-21.72,0.053
5.82,-21.62,0.053
5.84,-21.52,0.053
5.86,-21.42,0.053
5.88,-21.32,0.053
5.90,-21.22,0.053
5.92,-21.12,0.054
5.94,-21.02,0.054
5.96,-20.92,0.054
5.98,-20.82,0.054
6.00,-20.72,0.054
6.02,-20.62,0.054
6.04,-20.52,0.054
6.06,-20.42,0.054
6.08,-20.32,0.054
6.10,-20.22,0.054
6.12,-20.12,0.054
6.14,-20.02,0.054
6.16,-19.92,0.054
6.18,-19.82,0.054
6.20,-19.72,0.054
6.22,-19.62,0.054
6.24,-19.52,0.054
6.26,-19.42,0.054
6.28,-19.32,0.054
6.30,-19.22,0.054
6.32,-19.12,0.054
6.34,-19.02,0.054
6.36,-18.92,0.054
6.38,-18.82,0.054
6.40,-18.72,0.054
6.42,-18.62,0.054
6.44,-18.52,0.054
6.46,-18.42,0.054
6.48,-18.32,0.054
6.50,-18.22,0.054
6.52,-18.12,0.054
6.54,-18.02,0.054
6.56,-17.92,0.054
6.58,-17.82,0.054
6.60,-17.72,0.054
6.62,-17.62,0.054
6.64,-17.52,0.054
6.66,-17.42,0.054
6.68,-17.32,0.054
6.70,-17.22,0.054
6.72,-17.11,0.054
6.74,-17.02,0.054
6.76,-16.92,0.054
6.78,-16.82,0.054
6.80,-16.72,0.054
6.82,-16.62,0.054
6.84,-16.51,0.054
6.86,-16.42,0.054
6.88,-16.32,0.054
6.90,-16.22,0.054
6.92,-16.12,0.054
6.94,-16.02,0.054
6.96,-15.92,0.054
6.98,-15.82,0.054
7.00,-15.72,0.054
7.02,-15.62,0.054
7.04,-15.51,0.054
7.06,-15.42,0.054
7.08,-15.32,0.054
7.10,-15.22,0.055
7.12,-15.12,0.055
7.14,-15.02,0.055
7.16,-14.92,0.055
7.18,-14.81,0.055
7.20,-14.71,0.055
7.22,-14.61,0.055
7.24,-14.51,0.055
7.26,-14.41,0.055
7.28,-14.31,0.055
7.30,-14.21,0.055
7.32,-14.11,0.055
7.34,-14.01,0.055
7.36,-13.92,0.055
7.38,-13.81,0.055
7.40,-13.71,0.055
7.42,-13.61,0.055
7.44,-13.51,0.055
7.46,-13.41,0.055
7.48,-13.31,0.055
7.50,-13.21,0.055
7.52,-13.11,0.055
7.54,-13.01,0.055
7.56,-12.91,0.055
7.58,-12.81,0.055
7.60,-12.71,0.055
7.62,-12.61,0.055
7.64,-12.51,0.055
7.66,-12.41,0.055
7.68,-12.31,0.055
7.70,-12.21,0.055
7.72,-12.11,0.055
7.74,-12.01,0.055
7.76,-11.91,0.055
7.78,-11.81,0.055
7.80,-11.71,0.055
7.82,-11.61,0.055
7.84,-11.51,0.055
7.86,-11.41,0.055
7.88,-11.31,0.055
7.90,-11.21,0.055
7.92,-11.11,0.055
7.94,-11.01,0.055
7.96,-10.91,0.055
7.98,-10.81,0.055
8.00,-10.71,0.055
8.02,-10.61,0.055
8.04,-10.51,0.055
8.06,-10.41,0.055
8.08,-10.31,0.055
8.10,-10.21,0.055
8.12,-10.11,0.055
8.14,-10.01,0.055
8.16,-9.91,0.055
8.18,-9.81,0.055
8.20,-9.71,0.056
8.22,-9.61,0.056
8.24,-9.51,0.056
8.26,-9.41,0.056
8.28,-9.31,0.056
8.30,-9.21,0.056
8.32,-9.11,0.056
8.34,-9.01,0.056
8.36,-8.91,0.056
8.38,-8.81,0.056
8.40,-8.71,0.056
8.42,-8.61,0.056
8.44,-8.51,0.056
8.46,-8.41,0.056
8.48,-8.31,0.056
8.50,-8.21,0.056
8.52,-8.11,0.056
8.54,-8.01,0.056
8.56,-7.91,0.056
8.58,-7.81,0.056
8.60,-7.71,0.056
8.62,-7.61,0.056
8.64,-7.51,0.056
8.66,-7.41,0.056
8.68,-7.31,0.056
8.70,-7.21,0.056
8.72,-7.11,0.056
8.74,-7.01,0.056
8.76,-6.91,0.056
8.78,-6.81,0.056
8.80,-6.71,0.056
8.82,-6.61,0.056
8.84,-6.51,0.056
8.86,-6.41,0.056
8.88,-6.31,0.056
8.90,-6.21,0.056
8.92,-6.11,0.056
8.94,-6.01,0.056
8.96,-5.91,0.056
8.98,-5.81,0.056
9.00,-5.71,0.056
9.02,-5.61,0.056
9.04,-5.51,0.056
9.06,-5.41,0.056
9.08,-5.31,0.056
9.10,-5.21,0.056
9.12,-5.11,0.056
9.14,-5.01,0.056
9.16,-4.91,0.056
9.18,-4.81,0.056
9.20,-4.71,0.056
9.22,-4.61,0.056
9.24,-4.51,0.057
9.26,-4.41,0.057
9.28,-4.31,0.057
9.30,-4.21,0.057
9.32,-4.11,0.057
9.34,-4.01,0.057
9.36,-3.91,0.057
9.38,-3.81,0.057
9.40,-3.71,0.057
9.42,-3.61,0.057
9.44,-3.51,0.057
9.46,-3.41,0.057
9.48,-3.31,0.057
9.50,-3.21,0.057
9.52,-3.11,0.057
9.54,-3.01,0.057
9.56,-2.91,0.057
9.58,-2.81,0.057
9.60,-2.71,0.057
9.62,-2.61,0.057
9.64,-2.51,0.057
9.66,-2.41,0.057
9.68,-2.31,0.057
9.70,-2.21,0.057
9.72,-2.11,0.057
9.74,-2.01,0.057
9.76,-1.91,0.057
9.78,-1.81,0.057
9.80,-1.70,0.057
9.82,-1.61,0.057
9.84,-1.51,0.057
9.86,-1.41,0.057
9.88,-1.31,0.057
9.90,-1.21,0.057
9.92,-1.11,0.057
9.94,-1.01,0.057
9.96,-0.91,0.057
9.98,-0.81,0.057
10.00,-0.71,0.057
10.02,-0.61,0.057
10.04,-0.51,0.057
10.06,-0.40,0.057
10.08,-0.30,0.057
10.10,-0.21,0.057
10.12,-0.11,0.057
10.14,-0.01,0.057
10.16,0.09,0.057
10.18,0.20,0.057
10.20,0.29,0.057
10.22,0.40,0.057
10.24,0.50,0.057
10.26,0.59,0.057
10.28,0.69,0.057
10.30,0.79,0.057
10.32,0.89,0.057
10.34,1.00,0.057
10.36,1.10,0.057
10.38,1.19,0.057
10.40,1.29,0.057
10.42,1.40,0.057
10.44,1.50,0.058
10.46,1.60,0.058
10.48,1.70,0.058
10.50,1.80,0.058
10.52,1.90,0.058
10.54,1.99,0.058
10.56,2.10,0.058
10.58,2.20,0.058
10.60,2.29,0.058
10.62,2.39,0.058
10.64,2.50,0.058
10.66,2.60,0.058
10.68,2.70,0.058
10.70,2.80,0.058
10.72,2.90,0.058
10.74,3.00,0.058
10.76,3.10,0.058
10.78,3.20,0.058
10.80,3.30,0.058
10.82,3.40,0.058
10.84,3.50,0.058
10.86,3.60,0.058
10.88,3.70,0.058
10.90,3.80,0.058
10.92,3.90,0.058
10.94,4.00,0.058
10.96,4.10,0.058
10.98,4.20,0.058
11.00,4.30,0.058
11.02,4.40,0.058
11.04,4.50,0.058
11.06,4.60,0.058
11.08,4.70,0.058
11.10,4.80,0.058
11.12,4.90,0.058
11.14,5.00,0.058
11.16,5.10,0.058
11.18,5.20,0.058
11.20,5.30,0.058
11.22,5.40,0.058
11.24,5.50,0.058
11.26,5.60,0.058
11.28,5.70,0.058
11.30,5.80,0.058
11.32,5.90,0.058
11.34,6.00,0.058
11.36,6.10,0.058
11.38,6.20,0.058
11.40,6.30,0.058
11.42,6.40,0.058
11.44,6.50,0.058
11.46,6.60,0.058
11.48,6.70,0.058
11.50,6.80,0.058
11.52,6.90,0.058
11.54,7.00,0.058
11.56,7.10,0.058
11.58,7.20,0.059
11.60,7.30,0.059
11.62,7.40,0.059
11.64,7.50,0.059
11.66,7.60,0.059
11.68,7.70,0.059
11.70,7.80,0.059
11.72,7.90,0.059
11.74,8.00,0.059
11.76,8.10,0.059
11.78,8.20,0.059
11.80,8.30,0.059
11.82,8.40,0.059
11.84,8.50,0.059
11.86,8.60,0.059
11.88,8.70,0.059
11.90,8.80,0.059
11.92,8.90,0.059
11.94,9.00,0.059
11.96,9.10,0.059
11.98,9.20,0.059
12.00,9.30,0.059
12.02,9.40,0.059
12.04,9.50,0.059
12.06,9.60,0.059
12.08,9.70,0.059
12.10,9.80,0.059
12.12,9.90,0.059
12.14,10.00,0.059
12.16,10.10,0.059
12.18,10.20,0.059
12.20,10.30,0.059
12.22,10.40,0.059
12.24,10.50,0.059
12.26,10.60,0.059
12.28,10.70,0.059
12.30,10.80,0.059
12.32,10.90,0.059
12.34,11.00,0.059
12.36,11.10,0.059
12.38,11.20,0.059
12.40,11.30,0.059
12.42,11.40,0.059
12.44,11.50,0.059
12.46,11.60,0.059
12.48,11.70,0.059
12.50,11.80,0.059
12.52,11.90,0.059
12.54,12.00,0.059
12.56,12.10,0.059
12.58,12.20,0.059
12.60,12.30,0.059
12.62,12.40,0.059
12.64,12.50,0.060
12.66,12.60,0.060
12.68,12.70,0.060
12.70,12.80,0.060
12.72,12.90,0.060
12.74,13.00,0.060
12.76,13.10,0.060
12.78,13.20,0.060
12.80,13.30,0.060
12.82,13.40,0.060
12.84,13.50,0.060
12.86,13.60,0.060
12.88,13.70,0.060
12.90,13.80,0.060
12.92,13.90,0.060
12.94,14.00,0.060
12.96,14.10,0.060
12.98,14.20,0.060
13.00,14.30,0.060
13.02,14.40,0.060
13.04,14.50,0.060
13.06,14.60,0.060
13.08,14.70,0.060
13.10,14.80,0.060
13.12,14.90,0.060
13.14,15.00,0.060
13.16,15.11,0.060
13.18,15.20,0.060
13.20,15.30,0.060
13.22,15.40,0.060
13.24,15.51,0.060
13.26,15.60,0.060
13.28,15.71,0.060
13.30,15.80,0.060
13.32,15.90,0.060
13.34,16.00,0.060
13.36,16.10,0.060
13.38,16.20,0.060
13.40,16.30,0.060
13.42,16.41,0.060
13.44,16.51,0.060
13.46,16.60,0.060
13.48,16.71,0.060
13.50,16.80,0.060
13.52,16.91,0.060
13.54,17.01,0.060
13.56,17.10,0.060
13.58,17.20,0.060
13.60,17.31,0.060
13.62,17.40,0.060
13.64,17.51,0.060
13.66,17.60,0.060
13.68,17.70,0.060
13.70,17.80,0.060
13.72,17.90,0.060
13.74,18.00,0.060
13.76,18.11,0.060
13.78,18.21,0.061
13.80,18.31,0.061
13.82,18.41,0.061
13.84,18.51,0.061
13.86,18.61,0.061
13.88,18.71,0.061
13.90,18.81,0.061
13.92,18.91,0.061
13.94,19.01,0.061
13.96,19.11,0.061
13.98,19.21,0.061
14.00,19.31,0.061
14.02,19.41,0.061
14.04,19.51,0.061
14.06,19.61,0.061
14.08,19.71,0.061
14.10,19.81,0.061
14.12,19.91,0.061
14.14,20.01,0.061
14.16,20.11,0.061
14.18,20.21,0.061
14.20,20.31,0.061
14.22,20.41,0.061
14.24,20.51,0.061
14.26,20.61,0.061
14.28,20.71,0.061
14.30,20.81,0.061
14.32,20.91,0.061
14.34,21.01,0.061
14.36,21.11,0.061
14.38,21.21,0.061
14.40,21.31,0.061
14.42,21.41,0.061
14.44,21.51,0.061
14.46,21.61,0.061
14.48,21.71,0.061
14.50,21.81,0.061
14.52,21.91,0.061
14.54,22.01,0.061
14.56,22.11,0.061
14.58,22.21,0.061
14.60,22.31,0.061
14.62,22.41,0.061
14.64,22.51,0.061
14.66,22.61,0.061
14.68,22.71,0.061
14.70,22.81,0.061
14.72,22.91,0.061
14.74,23.01,0.061
14.76,23.11,0.061
14.78,23.21,0.061
14.80,23.31,0.061
14.82,23.41,0.061
14.84,23.51,0.061
14.86,23.61,0.061
14.88,23.71,0.061
14.90,23.81,0.061
14.92,23.91,0.061
14.94,24.01,0.061
14.96,24.11,0.062
14.98,24.21,0.062
15.00,24.31,0.062
15.02,24.41,0.062
15.04,24.51,0.062
15.06,24.61,0.062
15.08,24.71,0.062
15.10,24.81,0.062
15.12,24.91,0.062
15.14,25.01,0.062
15.16,25.11,0.062
15.18,25.21,0.062
15.20,25.31,0.062
15.22,25.41,0.062
15.24,25.51,0.062
15.26,25.61,0.062
15.28,25.71,0.062
15.30,25.81,0.062
15.32,25.91,0.062
15.34,26.01,0.062
15.36,26.11,0.062
15.38,26.21,0.062
15.40,26.31,0.062
15.42,26.41,0.062
15.44,26.51,0.062
15.46,26.61,0.062
15.48,26.71,0.062
15.50,26.81,0.062
15.52,26.91,0.062
15.54,27.01,0.062
15.56,27.11,0.062
15.58,27.21,0.062
15.60,27.31,0.062
15.62,27.41,0.062
15.64,27.51,0.062
15.66,27.61,0.062
15.68,27.71,0.062
15.70,27.81,0.062
15.72,27.91,0.062
15.74,28.01,0.062
15.76,28.11,0.062
15.78,28.21,0.062
15.80,28.31,0.062
15.82,28.41,0.062
15.84,28.51,0.062
15.86,28.61,0.062
15.88,28.71,0.062
15.90,28.81,0.062
15.92,28.91,0.062
15.94,29.01,0.062
15.96,29.11,0.062
15.98,29.21,0.062
16.00,29.31,0.062
16.02,29.41,0.062
16.04,29.51,0.063
16.06,29.61,0.063
16.08,29.71,0.063
16.10,29.81,0.063
16.12,29.91,0.063
16.14,30.01,0.063
16.16,30.11,0.063
16.18,30.21,0.063
16.20,30.31,0.063
16.22,30.41,0.063
16.24,30.51,0.063
16.26,30.61,0.063
16.28,30.71,0.063
16.30,30.81,0.063
16.32,30.91,0.063
16.34,31.01,0.063
16.36,31.11,0.063
16.38,31.21,0.063
16.40,31.31,0.063
16.42,31.41,0.063
16.44,31.51,0.063
16.46,31.61,0.063
16.48,31.71,0.063
16.50,31.81,0.063
16.52,31.91,0.063
16.54,32.01,0.063
16.56,32.11,0.063
16.58,32.21,0.063
16.60,32.31,0.063
16.62,32.41,0.063
16.64,32.51,0.063
16.66,32.61,0.063
16.68,32.71,0.063
16.70,32.81,0.063
16.72,32.91,0.063
16.74,33.01,0.063
16.76,33.11,0.063
16.78,33.21,0.063
16.80,33.31,0.063
16.82,33.41,0.063
16.84,33.51,0.063
16.86,33.61,0.063
16.88,33.71,0.063
16.90,33.81,0.063
16.92,33.91,0.063
16.94,34.01,0.063
16.96,34.11,0.063
16.98,34.21,0.063
17.00,34.31,0.063
17.02,34.41,0.063
17.04,34.51,0.063
17.06,34.62,0.063
17.08,34.71,0.063
17.10,34.81,0.063
17.12,34.92,0.063
17.14,35.01,0.063
17.16,35.11,0.063
17.18,35.21,0.063
17.20,35.31,0.063
17.22,35.41,0.063
17.24,35.51,0.063
17.26,35.61,0.063
17.28,35.72,0.064
17.30,35.82,0.064
17.32,35.92,0.064
17.34,36.02,0.064
17.36,36.11,0.064
17.38,36.22,0.064
17.40,36.32,0.064
17.42,36.42,0.064
17.44,36.52,0.064
17.46,36.62,0.064
17.48,36.72,0.064
17.50,36.82,0.064
17.52,36.92,0.064
17.54,37.02,0.064
17.56,37.12,0.064
17.58,37.22,0.064
17.60,37.32,0.064
17.62,37.42,0.064
17.64,37.52,0.064
17.66,37.62,0.064
17.68,37.72,0.064
17.70,37.82,0.064
17.72,37.92,0.064
17.74,38.02,0.064
17.76,38.12,0.064
17.78,38.22,0.064
17.80,38.32,0.064
17.82,38.42,0.064
17.84,38.52,0.064
17.86,38.62,0.064
17.88,38.72,0.064
17.90,38.82,0.064
17.92,38.92,0.064
17.94,39.02,0.064
17.96,39.12,0.064
17.98,39.22,0.064
18.00,39.32,0.064
18.02,39.42,0.064
18.04,39.52,0.064
18.06,39.62,0.064
18.08,39.72,0.064
18.10,39.82,0.064
18.12,39.92,0.064
18.14,40.02,0.064
18.16,40.12,0.064
18.18,40.22,0.064
18.20,40.32,0.064
18.22,40.42,0.064
18.24,40.52,0.064
18.26,40.62,0.064
18.28,40.72,0.064
18.30,40.82,0.064
18.32,40.92,0.064
18.34,41.02,0.064
18.36,41.12,0.064
18.38,41.22,0.064
18.40,41.32,0.064
18.42,41.42,0.064
18.44,41.52,0.064
18.46,41.62,0.064
18.48,41.72,0.064
18.50,41.82,0.064
18.52,41.92,0.064
18.54,42.02,0.064
18.56,42.12,0.064
18.58,42.22,0.065
18.60,42.32,0.065
18.62,42.42,0.065
18.64,42.52,0.065
18.66,42.62,0.065
18.68,42.72,0.065
18.70,42.82,0.065
18.72,42.92,0.065
18.74,43.02,0.065
18.76,43.12,0.065
18.78,43.22,0.065
18.80,43.32,0.065
18.82,43.42,0.065
18.84,43.52,0.065
18.86,43.62,0.065
18.88,43.72,0.065
18.90,43.82,0.065
18.92,43.92,0.065
18.94,44.02,0.065
18.96,44.12,0.065
18.98,44.22,0.065
19.00,44.32,0.065
19.02,44.42,0.065
19.04,44.52,0.065
19.06,44.62,0.065
19.08,44.72,0.065
19.10,44.82,0.065
19.12,44.92,0.065
19.14,45.02,0.065
19.16,45.12,0.065
19.18,45.22,0.065
19.20,45.32,0.065
19.22,45.42,0.065
19.24,45.52,0.065
19.26,45.62,0.065
19.28,45.72,0.065
19.30,45.82,0.065
19.32,45.92,0.065
19.34,46.02,0.065
19.36,46.12,0.065
19.38,46.22,0.065
19.40,46.32,0.065
19.42,46.42,0.065
19.44,46.52,0.065
19.46,46.62,0.065
19.48,46.72,0.065
19.50,46.82,0.065
19.52,46.92,0.065
19.54,47.02,0.065
19.56,47.12,0.065
19.58,47.22,0.065
19.60,47.32,0.065
19.62,47.42,0.065
19.64,47.52,0.065
19.66,47.62,0.065
19.68,47.72,0.065
19.70,47.82,0.065
19.72,47.92,0.065
19.74,48.03,0.065
19.76,48.12,0.065
19.78,48.22,0.065
19.80,48.32,0.065
19.82,48.42,0.065
19.84,48.52,0.065
19.86,48.62,0.065
19.88,48.72,0.066
19.90,48.82,0.066
19.92,48.92,0.066
19.94,49.02,0.066
19.96,49.12,0.066
19.98,49.22,0.066
20.00,49.32,0.066
20.02,49.42,0.066
20.04,49.52,0.066
20.06,49.62,0.066
20.08,49.72,0.066
20.10,49.82,0.066
20.12,49.92,0.066
20.14,50.02,0.066
20.16,50.12,0.066
20.18,50.22,0.066
20.20,50.32,0.066
20.22,50.42,0.066
20.24,50.52,0.066
20.26,50.62,0.066
20.28,50.72,0.066
20.30,50.82,0.066
20.32,50.92,0.066
20.34,51.02,0.066
20.36,51.12,0.066
20.38,51.22,0.066
20.40,51.32,0.066
20.42,51.42,0.066
20.44,51.52,0.066
20.46,51.62,0.066
20.48,51.72,0.066
20.50,51.82,0.066
20.52,51.92,0.066
20.54,52.03,0.066
20.56,52.13,0.066
20.58,52.23,0.066
20.60,52.33,0.066
20.62,52.42,0.066
20.64,52.53,0.066
20.66,52.62,0.066
20.68,52.72,0.066
20.70,52.83,0.066
20.72,52.92,0.066
20.74,53.03,0.066
20.76,53.13,0.066
20.78,53.23,0.066
20.80,53.33,0.066
20.82,53.43,0.066
20.84,53.53,0.066
20.86,53.63,0.066
20.88,53.73,0.066
20.90,53.83,0.066
20.92,53.93,0.066
20.94,54.03,0.066
20.96,54.13,0.066
20.98,54.23,0.066
21.00,54.33,0.066
21.02,54.43,0.066
21.04,54.53,0.066
21.06,54.63,0.066
21.08,54.73,0.066
21.10,54.83,0.066
21.12,54.93,0.066
21.14,55.03,0.066
21.16,55.13,0.066
21.18,55.23,0.066
21.20,55.33,0.066
21.22,55.43,0.067
21.24,55.53,0.067
21.26,55.63,0.067
21.28,55.73,0.067
21.30,55.83,0.067
21.32,55.93,0.067
21.34,56.03,0.067
21.36,56.13,0.067
21.38,56.23,0.067
21.40,56.33,0.067
21.42,56.43,0.067
21.44,56.53,0.067
21.46,56.63,0.067
21.48,56.73,0.067
21.50,56.83,0.067
21.52,56.93,0.067
21.54,57.03,0.067
21.56,57.13,0.067
21.58,57.23,0.067
21.60,57.33,0.067
21.62,57.43,0.067
21.64,57.53,0.067
21.66,57.63,0.067
21.68,57.73,0.067
21.70,57.83,0.067
21.72,57.93,0.067
21.74,58.03,0.067
21.76,58.13,0.067
21.78,58.23,0.067
21.80,58.33,0.067
21.82,58.43,0.067
21.84,58.53,0.067
21.86,58.63,0.067
21.88,58.73,0.067
21.90,58.83,0.067
21.92,58.93,0.067
21.94,59.03,0.067
21.96,59.13,0.067
21.98,59.23,0.067
22.00,59.33,0.067
22.02,59.43,0.067
22.04,59.53,0.067
22.06,59.63,0.067
22.08,59.73,0.067
22.10,59.83,0.067
22.12,59.93,0.067
22.14,60.03,0.067
22.16,60.13,0.067
22.18,60.23,0.067
22.20,60.33,0.067
22.22,60.43,0.067
22.24,60.53,0.067
22.26,60.63,0.067
22.28,60.73,0.067
22.30,60.83,0.067
22.32,60.93,0.067
22.34,61.03,0.067
22.36,61.13,0.067
22.38,61.23,0.067
22.40,61.33,0.067
22.42,61.43,0.067
22.44,61.53,0.067
22.46,61.63,0.067
22.48,61.73,0.067
22.50,61.83,0.067
22.52,61.93,0.067
22.54,62.03,0.067
22.56,62.13,0.067
22.58,62.23,0.067
22.60,62.33,0.067
22.62,62.43,0.067
22.64,62.53,0.067
22.66,62.63,0.067
22.68,62.73,0.067
22.70,62.83,0.067
22.72,62.93,0.067
22.74,63.03,0.067
22.76,63.13,0.067
22.78,63.23,0.067
22.80,63.33,0.067
22.82,63.43,0.068
22.84,63.53,0.068
22.86,63.63,0.068
22.88,63.73,0.068
22.90,63.83,0.068
22.92,63.93,0.068
22.94,64.03,0.068
22.96,64.13,0.068
22.98,64.23,0.068
23.00,64.33,0.068
23.02,64.43,0.068
23.04,64.53,0.068
23.06,64.63,0.068
23.08,64.73,0.068
23.10,64.83,0.068
23.12,64.93,0.068
23.14,65.03,0.068
23.16,65.13,0.068
23.18,65.23,0.068
23.20,65.33,0.068
23.22,65.43,0.068
23.24,65.53,0.068
23.26,65.63,0.068
23.28,65.73,0.068
23.30,65.83,0.068
23.32,65.93,0.068
23.34,66.03,0.068
23.36,66.13,0.068
23.38,66.23,0.068
23.40,66.33,0.068
23.42,66.43,0.068
23.44,66.53,0.068
23.46,66.63,0.068
23.48,66.73,0.068
23.50,66.83,0.068
23.52,66.93,0.068
23.54,67.03,0.068
23.56,67.13,0.068
23.58,67.23,0.068
23.60,67.33,0.068
23.62,67.43,0.068
23.64,67.53,0.068
23.66,67.63,0.068
23.68,67.73,0.068
23.70,67.83,0.068
23.72,67.93,0.068
23.74,68.03,0.068
23.76,68.13,0.068
23.78,68.23,0.068
23.80,68.33,0.068
23.82,68.43,0.068
23.84,68.53,0.068
23.86,68.63,0.068
23.88,68.73,0.068
23.90,68.83,0.068
23.92,68.93,0.068
23.94,69.04,0.068
23.96,69.13,0.068
23.98,69.23,0.068
24.00,69.33,0.068
24.02,69.43,0.068
24.04,69.54,0.068
24.06,69.63,0.068
24.08,69.74,0.068
24.10,69.84,0.068
24.12,69.93,0.068
24.14,70.03,0.068
24.16,70.13,0.068
24.18,70.23,0.068
24.20,70.34,0.068
24.22,70.44,0.068
24.24,70.54,0.068
24.26,70.64,0.068
24.28,70.74,0.068
24.30,70.84,0.069
24.32,70.94,0.069
24.34,71.03,0.069
24.36,71.14,0.069
24.38,71.24,0.069
24.40,71.34,0.069
24.42,71.44,0.069
24.44,71.54,0.069
24.46,71.64,0.069
24.48,71.74,0.069
24.50,71.84,0.069
24.52,71.94,0.069
24.54,72.04,0.069
24.56,72.14,0.069
24.58,72.24,0.069
24.60,72.34,0.069
24.62,72.44,0.069
24.64,72.54,0.069
24.66,72.64,0.069
24.68,72.74,0.069
24.70,72.84,0.069
24.72,72.94,0.069
24.74,73.04,0.069
24.76,73.14,0.069
24.78,73.24,0.069
24.80,73.34,0.069
24.82,73.44,0.069
24.84,73.54,0.069
24.86,73.64,0.069
24.88,73.74,0.069
24.90,73.84,0.069
24.92,73.94,0.069
24.94,74.04,0.069
24.96,74.14,0.069
24.98,74.24,0.069
25.00,74.34,0.069
25.02,74.44,0.069
25.04,74.54,0.069
25.06,74.64,0.069
25.08,74.74,0.069
25.10,74.84,0.069
25.12,74.94,0.069
25.14,75.04,0.069
25.16,75.14,0.069
25.18,75.24,0.069
25.20,75.34,0.069
25.22,75.44,0.069
25.24,75.54,0.069
25.26,75.64,0.069
25.28,75.74,0.069
25.30,75.84,0.069
25.32,75.94,0.069
25.34,76.04,0.069
25.36,76.14,0.069
25.38,76.24,0.069
25.40,76.34,0.069
25.42,76.44,0.069
25.44,76.54,0.069
25.46,76.64,0.069
25.48,76.74,0.069
25.50,76.84,0.069
25.52,76.94,0.069
25.54,77.04,0.069
25.56,77.14,0.069
25.58,77.24,0.069
25.60,77.34,0.069
25.62,77.44,0.069
25.64,77.54,0.069
25.66,77.64,0.069
25.68,77.74,0.069
25.70,77.84,0.069
25.72,77.94,0.069
25.74,78.04,0.069
25.76,78.14,0.069
25.78,78.24,0.069
25.80,78.34,0.069
25.82,78.44,0.070
25.84,78.54,0.070
25.86,78.64,0.070
25.88,78.74,0.070
25.90,78.84,0.070
25.92,78.94,0.070
25.94,79.04,0.070
25.96,79.14,0.070
25.98,79.24,0.070
26.00,79.34,0.070
26.02,79.44,0.070
26.04,79.54,0.070
26.06,79.64,0.070
26.08,79.74,0.070
26.10,79.84,0.070
26.12,79.94,0.070
26.14,80.04,0.070
26.16,80.14,0.070
26.18,80.24,0.070
26.20,80.34,0.070
26.22,80.44,0.070
26.24,80.54,0.070
26.26,80.64,0.070
26.28,80.74,0.070
26.30,80.84,0.070
26.32,80.94,0.070
26.34,81.04,0.070
26.36,81.14,0.070
26.38,81.24,0.070
26.40,81.34,0.070
26.42,81.44,0.070
26.44,81.54,0.070
26.46,81.64,0.070
26.48,81.74,0.070
26.50,81.84,0.070
26.52,81.94,0.070
26.54,82.04,0.070
26.56,82.14,0.070
26.58,82.24,0.070
26.60,82.34,0.070
26.62,82.44,0.070
26.64,82.54,0.070
26.66,82.64,0.070
26.68,82.74,0.070
26.70,82.84,0.070
26.72,82.94,0.070
26.74,83.04,0.070
26.76,83.14,0.070
26.78,83.24,0.070
26.80,83.34,0.070
26.82,83.44,0.070
26.84,83.54,0.070
26.86,83.64,0.070
26.88,83.74,0.070
26.90,83.84,0.070
26.92,83.94,0.070
26.94,84.04,0.070
26.96,84.14,0.070
26.98,84.24,0.070
27.00,84.34,0.070
27.02,84.44,0.070
27.04,84.54,0.070
27.06,84.64,0.070
27.08,84.74,0.070
27.10,84.84,0.070
27.12,84.94,0.070
27.14,85.04,0.070
27.16,85.14,0.070
27.18,85.24,0.070
27.20,85.34,0.070
27.22,85.44,0.070
27.24,85.54,0.070
27.26,85.64,0.070
27.28,85.74,0.070
27.30,85.84,0.070
27.32,85.94,0.070
27.34,86.04,0.070
27.36,86.14,0.070
27.38,86.24,0.070
27.40,86.34,0.070
27.42,86.44,0.070
27.44,86.54,0.070
27.46,86.64,0.070
27.48,86.74,0.070
27.50,86.84,0.070
27.52,86.95,0.070
27.54,87.04,0.070
27.56,87.14,0.070
27.58,87.24,0.071
27.60,87.34,0.071
27.62,87.44,0.071
27.64,87.54,0.071
27.66,87.64,0.071
27.68,87.74,0.071
27.70,87.84,0.071
27.72,87.94,0.071
27.74,88.05,0.071
27.76,88.14,0.071
27.78,88.25,0.071
27.80,88.35,0.071
27.82,88.44,0.071
27.84,88.54,0.071
27.86,88.64,0.071
27.88,88.74,0.071
27.90,88.85,0.071
27.92,88.94,0.071
27.94,89.04,0.071
27.96,89.14,0.071
27.98,89.24,0.071
28.00,89.34,0.071
28.02,89.44,0.071
28.04,89.54,0.071
28.06,89.64,0.071
28.08,89.74,0.071
28.10,89.84,0.071
28.12,89.95,0.071
28.14,90.04,0.071
28.16,90.14,0.071
28.18,90.24,0.071
28.20,90.34,0.071
28.22,90.44,0.071
28.24,90.54,0.071
28.26,90.64,0.071
28.28,90.75,0.071
28.30,90.85,0.071
28.32,90.95,0.071
28.34,91.05,0.071
28.36,91.15,0.071
28.38,91.25,0.071
28.40,91.34,0.071
28.42,91.45,0.071
28.44,91.55,0.071
28.46,91.65,0.071
28.48,91.75,0.071
28.50,91.85,0.071
28.52,91.94,0.071
28.54,92.05,0.071
28.56,92.15,0.071
28.58,92.25,0.071
28.60,92.35,0.071
28.62,92.45,0.071
28.64,92.55,0.071
28.66,92.65,0.071
28.68,92.75,0.071
28.70,92.85,0.071
28.72,92.95,0.071
28.74,93.05,0.071
28.76,93.15,0.071
28.78,93.25,0.071
28.80,93.35,0.071
28.82,93.45,0.071
28.84,93.55,0.071
28.86,93.65,0.071
28.88,93.75,0.071
28.90,93.85,0.071
28.92,93.95,0.071
28.94,94.05,0.071
28.96,94.15,0.071
28.98,94.25,0.071
29.00,94.35,0.071
29.02,94.45,0.071
29.04,94.55,0.071
29.06,94.65,0.071
29.08,94.75,0.071
29.10,94.85,0.071
29.12,94.95,0.071
29.14,95.05,0.071
29.16,95.15,0.071
29.18,95.25,0.071
29.20,95.35,0.071
29.22,95.45,0.072
29.24,95.55,0.072
29.26,95.65,0.072
29.28,95.75,0.072
29.30,95.85,0.072
29.32,95.95,0.072
29.34,96.05,0.072
29.36,96.15,0.072
29.38,96.25,0.072
29.40,96.35,0.072
29.42,96.45,0.072
29.44,96.55,0.072
29.46,96.65,0.072
29.48,96.75,0.072
29.50,96.85,0.072
29.52,96.95,0.072
29.54,97.05,0.072
29.56,97.15,0.072
29.58,97.25,0.072
29.60,97.35,0.072
29.62,97.45,0.072
29.64,97.55,0.072
29.66,97.65,0.072
29.68,97.75,0.072
29.70,97.85,0.072
29.72,97.95,0.072
29.74,98.05,0.072
29.76,98.15,0.072
29.78,98.25,0.072
29.80,98.35,0.072
29.82,98.45,0.072
29.84,98.55,0.072
29.86,98.65,0.072
29.88,98.75,0.072
29.90,98.85,0.072
29.92,98.95,0.072
29.94,99.05,
29.96,99.15,
29.98,99.25,
29.99,,

[step]
Ramp 5.00 °C/min to -50.00 °C
Time,Temperature,Heat Flow (Normalized)
min,°C,W/g
30.99,100.11,-0.008
31.01,100.11,-0.008
31.03,100.11,-0.008
31.05,100.10,-0.010
31.07,100.09,-0.016
31.09,100.06,-0.023
31.11,100.02,-0.032
31.13,99.97,-0.042
31.15,99.91,-0.050
31.17,99.85,-0.057
31.19,99.77,-0.063
31.21,99.70,-0.067
31.23,99.62,-0.071
31.25,99.54,-0.074
31.27,99.45,-0.076
31.29,99.36,-0.078
31.31,99.27,-0.081
31.33,99.18,-0.082
31.35,99.09,-0.083
31.37,99.00,-0.084
31.39,98.90,-0.085
31.41,98.81,-0.085
31.43,98.71,-0.086
31.45,98.61,-0.086
31.47,98.52,-0.087
31.49,98.42,-0.087
31.51,98.32,-0.087
31.53,98.23,-0.087
31.55,98.13,-0.087
31.57,98.03,-0.088
31.59,97.93,-0.088
31.61,97.83,-0.088
31.63,97.74,-0.088
31.65,97.64,-0.088
31.67,97.54,-0.088
31.69,97.44,-0.088
31.71,97.34,-0.088
31.73,97.24,-0.088
31.75,97.14,-0.088
31.77,97.04,-0.088
31.79,96.94,-0.088
31.81,96.85,-0.089
31.83,96.75,-0.089
31.85,96.65,-0.089
31.87,96.55,-0.089
31.89,96.45,-0.089
31.91,96.35,-0.089
31.93,96.25,-0.089
31.95,96.15,-0.089
31.97,96.05,-0.089
31.99,95.95,-0.089
32.01,95.85,-0.089
32.03,95.75,-0.089
32.05,95.65,-0.089
32.07,95.55,-0.089
32.09,95.45,-0.089
32.11,95.35,-0.089
32.13,95.25,-0.089
32.15,95.16,-0.089
32.17,95.05,-0.089
32.19,94.96,-0.089
32.21,94.86,-0.089
32.23,94.76,-0.089
32.25,94.66,-0.089
32.27,94.56,-0.089
32.29,94.46,-0.089
32.31,94.36,-0.089
32.33,94.26,-0.089
32.35,94.16,-0.089
32.37,94.06,-0.089
32.39,93.96,-0.089
32.41,93.86,-0.089
32.43,93.76,-0.089
32.45,93.66,-0.089
32.47,93.56,-0.089
32.49,93.46,-0.089
32.51,93.36,-0.089
32.53,93.26,-0.089
32.55,93.16,-0.089
32.57,93.06,-0.089
32.59,92.96,-0.089
32.61,92.86,-0.089
32.63,92.76,-0.089
32.65,92.66,-0.089
32.67,92.56,-0.089
32.69,92.46,-0.089
32.71,92.36,-0.089
32.73,92.26,-0.089
32.75,92.16,-0.089
32.77,92.06,-0.089
32.79,91.96,-0.089
32.81,91.86,-0.089
32.83,91.76,-0.089
32.85,91.66,-0.089
32.87,91.56,-0.089
32.89,91.46,-0.089
32.91,91.36,-0.089
32.93,91.26,-0.089
32.95,91.16,-0.089
32.97,91.06,-0.089
32.99,90.96,-0.089
33.01,90.86,-0.089
33.03,90.76,-0.089
33.05,90.66,-0.089
33.07,90.56,-0.089
33.09,90.46,-0.089
33.11,90.36,-0.089
33.13,90.26,-0.089
33.15,90.16,-0.089
33.17,90.06,-0.089
33.19,89.96,-0.088
33.21,89.86,-0.088
33.23,89.76,-0.088
33.25,89.66,-0.088
33.27,89.56,-0.088
33.29,89.46,-0.088
33.31,89.36,-0.088
33.33,89.26,-0.088
33.35,89.16,-0.088
33.37,89.06,-0.088
33.39,88.96,-0.088
33.41,88.86,-0.088
33.43,88.76,-0.088
33.45,88.66,-0.088
33.47,88.56,-0.088
33.49,88.46,-0.088
33.51,88.36,-0.088
33.53,88.26,-0.088
33.55,88.16,-0.088
33.57,88.06,-0.088
33.59,87.96,-0.088
33.61,87.86,-0.088
33.63,87.76,-0.088
33.65,87.66,-0.088
33.67,87.56,-0.088
33.69,87.46,-0.088
33.71,87.36,-0.088
33.73,87.26,-0.088
33.75,87.16,-0.088
33.77,87.06,-0.088
33.79,86.96,-0.088
33.81,86.86,-0.088
33.83,86.76,-0.088
33.85,86.67,-0.088
33.87,86.56,-0.088
33.89,86.47,-0.088
33.91,86.37,-0.088
33.93,86.27,-0.088
33.95,86.17,-0.088
33.97,86.06,-0.088
33.99,85.97,-0.088
34.01,85.87,-0.088
34.03,85.77,-0.088
34.05,85.67,-0.088
34.07,85.57,-0.088
34.09,85.47,-0.088
34.11,85.37,-0.088
34.13,85.27,-0.088
34.15,85.17,-0.088
34.17,85.07,-0.088
34.19,84.97,-0.088
34.21,84.87,-0.088
34.23,84.77,-0.088
34.25,84.67,-0.087
34.27,84.57,-0.087
34.29,84.47,-0.087
34.31,84.37,-0.087
34.33,84.27,-0.087
34.35,84.17,-0.087
34.37,84.07,-0.087
34.39,83.97,-0.087
34.41,83.87,-0.087
34.43,83.77,-0.087
34.45,83.67,-0.087
34.47,83.57,-0.087
34.49,83.47,-0.087
34.51,83.37,-0.087
34.53,83.27,-0.087
34.55,83.17,-0.087
34.57,83.07,-0.087
34.59,82.97,-0.087
34.61,82.87,-0.087
34.63,82.77,-0.087
34.65,82.67,-0.087
34.67,82.57,-0.087
34.69,82.47,-0.087
34.71,82.37,-0.087
34.73,82.27,-0.087
34.75,82.17,-0.087
34.77,82.07,-0.087
34.79,81.97,-0.087
34.81,81.87,-0.087
34.83,81.77,-0.087
34.85,81.67,-0.087
34.87,81.57,-0.087
34.89,81.47,-0.087
34.91,81.37,-0.087
34.93,81.27,-0.087
34.95,81.17,-0.087
34.97,81.07,-0.087
34.99,80.97,-0.087
35.01,80.87,-0.087
35.03,80.77,-0.087
35.05,80.67,-0.087
35.07,80.57,-0.087
35.09,80.47,-0.087
35.11,80.37,-0.087
35.13,80.27,-0.087
35.15,80.17,-0.087
35.17,80.07,-0.087
35.19,79.97,-0.087
35.21,79.87,-0.087
35.23,79.77,-0.087
35.25,79.67,-0.087
35.27,79.57,-0.087
35.29,79.47,-0.087
35.31,79.37,-0.087
35.33,79.27,-0.087
35.35,79.17,-0.087
35.37,79.07,-0.087
35.39,78.97,-0.087
35.41,78.87,-0.087
35.43,78.77,-0.087
35.45,78.67,-0.087
35.47,78.57,-0.087
35.49,78.47,-0.087
35.51,78.37,-0.087
35.53,78.27,-0.087
35.55,78.17,-0.087
35.57,78.07,-0.087
35.59,77.97,-0.087
35.61,77.87,-0.086
35.63,77.77,-0.086
35.65,77.67,-0.086
35.67,77.57,-0.086
35.69,77.47,-0.086
35.71,77.37,-0.086
35.73,77.27,-0.086
35.75,77.17,-0.086
35.77,77.07,-0.086
35.79,76.97,-0.086
35.81,76.87,-0.086
35.83,76.77,-0.086
35.85,76.67,-0.086
35.87,76.57,-0.086
35.89,76.47,-0.086
35.91,76.37,-0.086
35.93,76.27,-0.086
35.95,76.17,-0.086
35.97,76.07,-0.086
35.99,75.97,-0.086
36.01,75.87,-0.086
36.03,75.77,-0.086
36.05,75.67,-0.086
36.07,75.57,-0.086
36.09,75.47,-0.086
36.11,75.37,-0.086
36.13,75.27,-0.086
36.15,75.17,-0.086
36.17,75.07,-0.086
36.19,74.97,-0.086
36.21,74.87,-0.086
36.23,74.77,-0.086
36.25,74.67,-0.086
36.27,74.57,-0.086
36.29,74.47,-0.086
36.31,74.37,-0.086
36.33,74.27,-0.086
36.35,74.17,-0.086
36.37,74.07,-0.086
36.39,73.97,-0.086
36.41,73.87,-0.086
36.43,73.77,-0.086
36.45,73.67,-0.086
36.47,73.57,-0.086
36.49,73.47,-0.086
36.51,73.37,-0.086
36.53,73.27,-0.086
36.55,73.17,-0.086
36.57,73.07,-0.086
36.59,72.97,-0.086
36.61,72.87,-0.086
36.63,72.77,-0.086
36.65,72.67,-0.086
36.67,72.57,-0.086
36.69,72.47,-0.086
36.71,72.37,-0.086
36.73,72.27,-0.085
36.75,72.17,-0.085
36.77,72.07,-0.085
36.79,71.97,-0.085
36.81,71.87,-0.085
36.83,71.77,-0.085
36.85,71.67,-0.085
36.87,71.57,-0.085
36.89,71.47,-0.085
36.91,71.37,-0.085
36.93,71.27,-0.085
36.95,71.17,-0.085
36.97,71.07,-0.085
36.99,70.97,-0.085
37.01,70.87,-0.085
37.03,70.77,-0.085
37.05,70.68,-0.085
37.07,70.57,-0.085
37.09,70.47,-0.085
37.11,70.37,-0.085
37.13,70.27,-0.085
37.15,70.17,-0.085
37.17,70.07,-0.085
37.19,69.97,-0.085
37.21,69.87,-0.085
37.23,69.77,-0.085
37.25,69.67,-0.085
37.27,69.57,-0.085
37.29,69.47,-0.085
37.31,69.37,-0.085
[...]
227.16,15.05,0.060
227.19,15.20,0.060
227.22,15.35,0.060
227.25,15.50,0.060
227.28,15.65,0.060
227.31,15.80,0.060
227.34,15.95,0.060
227.37,16.10,0.060
227.40,16.25,0.060
227.43,16.40,0.060
227.46,16.55,0.060
227.49,16.70,0.060
227.52,16.85,0.060
227.55,17.00,0.060
227.58,17.15,0.060
227.61,17.30,0.060
227.64,17.45,0.060
227.67,17.60,0.060
227.70,17.75,0.060
227.73,17.90,0.060
227.76,18.05,0.061
227.79,18.20,0.061
227.82,18.35,0.061
227.85,18.50,0.061
227.88,18.65,0.061
227.91,18.80,0.061
227.94,18.95,0.061
227.97,19.10,0.061
228.00,19.25,0.061
228.03,19.40,0.061
228.06,19.55,0.061
228.09,19.71,0.061
228.12,19.85,0.061
228.15,20.00,0.061
228.18,20.15,0.061
228.21,20.31,0.061
228.24,20.46,0.061
228.27,20.60,0.061
228.30,20.76,0.061
228.33,20.91,0.061
228.36,21.06,0.061
228.39,21.21,0.061
228.42,21.36,0.061
228.45,21.51,0.061
228.48,21.66,0.061
228.51,21.81,0.061
228.54,21.96,0.061
228.57,22.11,0.061
228.60,22.26,0.061
228.63,22.41,0.061
228.66,22.56,0.061
228.69,22.71,0.061
228.72,22.86,0.061
228.75,23.01,0.061
228.78,23.16,0.061
228.81,23.31,0.061
228.84,23.46,0.061
228.87,23.61,0.061
228.90,23.76,0.061
228.93,23.91,0.062
228.96,24.06,0.062
228.99,24.21,0.062
229.02,24.36,0.062
229.05,24.51,0.062
229.08,24.66,0.062
229.11,24.81,0.062
229.14,24.96,0.062
229.17,25.11,0.062
229.20,25.26,0.062
229.23,25.41,0.062
229.26,25.56,0.062
229.29,25.71,0.062
229.32,25.86,0.062
229.35,26.01,0.062
229.38,26.16,0.062
229.41,26.31,0.062
229.44,26.46,0.062
229.47,26.61,0.062
229.50,26.76,0.062
229.53,26.91,0.062
229.56,27.06,0.062
229.59,27.21,0.062
229.62,27.36,0.062
229.65,27.51,0.062
229.68,27.66,0.062
229.71,27.81,0.062
229.74,27.96,0.062
229.77,28.11,0.062
229.80,28.26,0.062
229.83,28.41,0.062
229.86,28.56,0.062
229.89,28.71,0.062
229.92,28.86,0.062
229.95,29.01,0.062
229.98,29.16,0.062
230.01,29.31,0.063
230.04,29.46,0.063
230.07,29.61,0.063
230.10,29.76,0.063
230.13,29.91,0.063
230.16,30.06,0.063
230.19,30.21,0.063
230.22,30.36,0.063
230.25,30.51,0.063
230.28,30.66,0.063
230.31,30.81,0.063
230.34,30.96,0.063
230.37,31.11,0.063
230.40,31.26,0.063
230.43,31.41,0.063
230.46,31.56,0.063
230.49,31.71,0.063
230.52,31.86,0.063
230.55,32.01,0.063
230.58,32.16,0.063
230.61,32.31,0.063
230.64,32.46,0.063
230.67,32.61,0.063
230.70,32.76,0.063
230.73,32.91,0.063
230.76,33.06,0.063
230.79,33.21,0.063
230.82,33.36,0.063
230.85,33.51,0.063
230.88,33.66,0.063
230.91,33.81,0.063
230.94,33.96,0.063
230.97,34.11,0.063
231.00,34.26,0.063
231.03,34.41,0.063
231.06,34.56,0.063
231.09,34.71,0.063
231.12,34.86,0.063
231.15,35.01,0.063
231.18,35.16,0.063
231.21,35.31,0.063
231.24,35.46,0.064
231.27,35.61,0.064
231.30,35.76,0.064
231.33,35.91,0.064
231.36,36.06,0.064
231.39,36.21,0.064
231.42,36.36,0.064
231.45,36.51,0.064
231.48,36.66,0.064
231.51,36.81,0.064
231.54,36.96,0.064
231.57,37.11,0.064
231.60,37.26,0.064
231.63,37.41,0.064
231.66,37.56,0.064
231.69,37.71,0.064
231.72,37.86,0.064
231.75,38.01,0.064
231.78,38.16,0.064
231.81,38.31,0.064
231.84,38.46,0.064
231.87,38.62,0.064
231.90,38.77,0.064
231.93,38.91,0.064
231.96,39.06,0.064
231.99,39.22,0.064
232.02,39.37,0.064
232.05,39.52,0.064
232.08,39.66,0.064
232.11,39.82,0.064
232.14,39.97,0.064
232.17,40.11,0.064
232.20,40.27,0.064
232.23,40.42,0.064
232.26,40.57,0.064
232.29,40.72,0.064
232.32,40.87,0.064
232.35,41.02,0.064
232.38,41.17,0.064
232.41,41.32,0.064
232.44,41.47,0.064
232.47,41.62,0.064
232.50,41.77,0.065
232.53,41.92,0.065
232.56,42.07,0.065
232.59,42.22,0.065
232.62,42.37,0.065
232.65,42.52,0.065
232.68,42.67,0.065
232.71,42.82,0.065
232.74,42.97,0.065
232.77,43.12,0.065
232.80,43.27,0.065
232.83,43.42,0.065
232.86,43.57,0.065
232.89,43.72,0.065
232.92,43.87,0.065
232.95,44.02,0.065
232.98,44.17,0.065
233.01,44.32,0.065
233.04,44.47,0.065
233.07,44.62,0.065
233.10,44.77,0.065
233.13,44.92,0.065
233.16,45.07,0.065
233.19,45.22,0.065
233.22,45.37,0.065
233.25,45.52,0.065
233.28,45.67,0.065
233.31,45.82,0.065
233.34,45.97,0.065
233.37,46.12,0.065
233.40,46.27,0.065
233.43,46.42,0.065
233.46,46.57,0.065
233.49,46.72,0.065
233.52,46.87,0.065
233.55,47.02,0.065
233.58,47.17,0.065
233.61,47.32,0.065
233.64,47.47,0.065
233.67,47.62,0.065
233.70,47.77,0.065
233.73,47.92,0.065
233.76,48.07,0.065
233.79,48.22,0.066
233.82,48.37,0.066
233.85,48.52,0.066
233.88,48.67,0.066
233.91,48.82,0.066
233.94,48.97,0.066
233.97,49.12,0.066
234.00,49.27,0.066
234.03,49.42,0.066
234.06,49.57,0.066
234.09,49.72,0.066
234.12,49.87,0.066
234.15,50.02,0.066
234.18,50.17,0.066
234.21,50.32,0.066
234.24,50.47,0.066
234.27,50.62,0.066
234.30,50.77,0.066
234.33,50.92,0.066
234.36,51.07,0.066
234.39,51.22,0.066
234.42,51.37,0.066
234.45,51.52,0.066
234.48,51.67,0.066
234.51,51.82,0.066
234.54,51.97,0.066
234.57,52.12,0.066
234.60,52.27,0.066
234.63,52.42,0.066
234.66,52.57,0.066
234.69,52.72,0.066
234.72,52.87,0.066
234.75,53.03,0.066
234.78,53.17,0.066
234.81,53.33,0.066
234.84,53.48,0.066
234.87,53.63,0.066
234.90,53.78,0.066
234.93,53.93,0.066
234.96,54.08,0.066
234.99,54.23,0.066
235.02,54.38,0.066
235.05,54.53,0.066
235.08,54.68,0.066
235.11,54.83,0.066
235.14,54.98,0.066
235.17,55.13,0.067
235.20,55.28,0.067
235.23,55.43,0.067
235.26,55.58,0.067
235.29,55.73,0.067
235.32,55.88,0.067
235.35,56.03,0.067
235.38,56.18,0.067
235.41,56.33,0.067
235.44,56.48,0.067
235.47,56.63,0.067
235.50,56.78,0.067
235.53,56.93,0.067
235.56,57.08,0.067
235.59,57.23,0.067
235.62,57.38,0.067
235.65,57.53,0.067
235.68,57.68,0.067
235.71,57.83,0.067
235.74,57.98,0.067
235.77,58.13,0.067
235.80,58.28,0.067
235.83,58.43,0.067
235.86,58.58,0.067
235.89,58.73,0.067
235.92,58.88,0.067
235.95,59.03,0.067
235.98,59.18,0.067
236.01,59.33,0.067
236.04,59.48,0.067
236.07,59.63,0.067
236.10,59.78,0.067
236.13,59.93,0.067
236.16,60.08,0.067
236.19,60.23,0.067
236.22,60.38,0.067
236.25,60.53,0.067
236.28,60.68,0.067
236.31,60.83,0.067
236.34,60.98,0.067
236.37,61.13,0.067
236.40,61.28,0.067
236.43,61.43,0.067
236.46,61.58,0.067
236.49,61.73,0.067
236.52,61.88,0.067
236.55,62.03,0.067
236.58,62.18,0.067
236.61,62.33,0.067
236.64,62.48,0.068
236.67,62.63,0.068
236.70,62.78,0.068
236.73,62.93,0.068
236.76,63.08,0.068
236.79,63.23,0.068
236.82,63.38,0.068
236.85,63.53,0.068
236.88,63.68,0.068
236.91,63.83,0.068
236.94,63.98,0.068
236.97,64.13,0.068
237.00,64.28,0.068
237.03,64.43,0.068
237.06,64.58,0.068
237.09,64.73,0.068
237.12,64.88,0.068
237.15,65.03,0.068
237.18,65.18,0.068
237.21,65.33,0.068
237.24,65.48,0.068
237.27,65.63,0.068
237.30,65.78,0.068
237.33,65.93,0.068
237.36,66.08,0.068
237.39,66.23,0.068
237.42,66.38,0.068
237.45,66.53,0.068
237.48,66.68,0.068
237.51,66.83,0.068
237.54,66.98,0.068
237.57,67.13,0.068
237.60,67.28,0.068
237.63,67.43,0.068
237.66,67.58,0.068
237.69,67.73,0.068
237.72,67.88,0.068
237.75,68.03,0.068
237.78,68.18,0.068
237.81,68.33,0.068
237.84,68.48,0.068
237.87,68.63,0.068
237.90,68.78,0.068
237.93,68.93,0.068
237.96,69.08,0.068
237.99,69.23,0.068
238.02,69.38,0.068
238.05,69.53,0.068
238.08,69.68,0.068
238.11,69.83,0.068
238.14,69.98,0.068
238.17,70.13,0.069
238.20,70.28,0.069
238.23,70.43,0.069
238.26,70.58,0.069
238.29,70.73,0.069
238.32,70.88,0.069
238.35,71.03,0.069
238.38,71.18,0.069
238.41,71.33,0.069
238.44,71.48,0.069
238.47,71.63,0.069
238.50,71.78,0.069
238.53,71.93,0.069
238.56,72.08,0.069
238.59,72.23,0.069
238.62,72.38,0.069
238.65,72.53,0.069
238.68,72.68,0.069
238.71,72.83,0.069
238.74,72.98,0.069
238.77,73.13,0.069
238.80,73.29,0.069
238.83,73.44,0.069
238.86,73.59,0.069
238.89,73.74,0.069
238.92,73.89,0.069
238.95,74.04,0.069
238.98,74.19,0.069
239.01,74.34,0.069
239.04,74.49,0.069
239.07,74.64,0.069
239.10,74.79,0.069
239.13,74.94,0.069
239.16,75.09,0.069
239.19,75.24,0.069
239.22,75.39,0.069
239.25,75.54,0.069
239.28,75.69,0.069
239.31,75.84,0.069
239.34,75.99,0.069
239.37,76.14,0.069
239.40,76.29,0.069
239.43,76.44,0.069
239.46,76.59,0.069
239.49,76.74,0.069
239.52,76.89,0.069
239.55,77.04,0.069
239.58,77.19,0.069
239.61,77.34,0.069
239.64,77.49,0.070
239.67,77.64,0.070
239.70,77.79,0.070
239.73,77.94,0.070
239.76,78.09,0.070
239.79,78.24,0.070
239.82,78.39,0.070
239.85,78.54,0.070
239.88,78.69,0.070
239.91,78.84,0.070
239.94,78.99,0.070
239.97,79.14,0.070
240.00,79.29,0.070
240.03,79.44,0.070
240.06,79.59,0.070
240.09,79.74,0.070
240.12,79.89,0.070
240.15,80.04,0.070
240.18,80.19,0.070
240.21,80.34,0.070
240.24,80.49,0.070
240.27,80.64,0.070
240.30,80.79,0.070
240.33,80.94,0.070
240.36,81.09,0.070
240.39,81.24,0.070
240.42,81.39,0.070
240.45,81.54,0.070
240.48,81.69,0.070
240.51,81.84,0.070
240.54,81.99,0.070
240.57,82.14,0.070
240.60,82.29,0.070
240.63,82.44,0.070
240.66,82.59,0.070
240.69,82.74,0.070
240.72,82.89,0.070
240.75,83.04,0.070
240.78,83.19,0.070
240.81,83.34,0.070
240.84,83.49,0.070
240.87,83.64,0.070
240.90,83.79,0.070
240.93,83.94,0.070
240.96,84.09,0.070
240.99,84.24,0.070
241.02,84.39,0.070
241.05,84.54,0.070
241.08,84.69,0.070
241.11,84.84,0.070
241.14,84.99,0.070
241.17,85.14,0.070
241.20,85.29,0.070
241.23,85.44,0.070
241.26,85.59,0.070
241.29,85.74,0.070
241.32,85.89,0.070
241.35,86.04,0.070
241.38,86.19,0.070
241.41,86.34,0.070
241.44,86.49,0.070
241.47,86.64,0.070
241.50,86.79,0.070
241.53,86.94,0.071
241.56,87.09,0.071
241.59,87.24,0.071
241.62,87.39,0.071
241.65,87.54,0.071
241.68,87.69,0.071
241.71,87.84,0.071
241.74,87.99,0.071
241.77,88.14,0.071
241.80,88.29,0.071
241.83,88.44,0.071
241.86,88.59,0.071
241.89,88.74,0.071
241.92,88.89,0.071
241.95,89.04,0.071
241.98,89.19,0.071
242.01,89.34,0.071
242.04,89.49,0.071
242.07,89.64,0.071
242.10,89.79,0.071
242.13,89.94,0.071
242.16,90.09,0.071
242.19,90.24,0.071
242.22,90.39,0.071
242.25,90.54,0.071
242.28,90.69,0.071
242.31,90.84,0.071
242.34,90.99,0.071
242.37,91.14,0.071
242.40,91.29,0.071
242.43,91.44,0.071
242.46,91.59,0.071
242.49,91.74,0.071
242.52,91.89,0.071
242.55,92.04,0.071
242.58,92.19,0.071
242.61,92.34,0.071
242.64,92.49,0.071
242.67,92.64,0.071
242.70,92.79,0.071
242.73,92.94,0.071
242.76,93.09,0.071
242.79,93.24,0.071
242.82,93.39,0.071
242.85,93.55,0.071
242.88,93.70,0.071
242.91,93.85,0.071
242.94,94.00,0.071
242.97,94.15,0.071
243.00,94.30,0.071
243.03,94.44,0.071
243.06,94.60,0.071
243.09,94.75,0.071
243.12,94.89,0.071
243.15,95.05,0.071
243.18,95.20,0.072
243.21,95.34,0.072
243.24,95.50,0.072
243.27,95.65,0.072
243.30,95.80,0.072
243.33,95.94,0.072
243.36,96.10,0.072
243.39,96.25,0.072
243.42,96.40,0.072
243.45,96.55,0.072
243.48,96.70,0.072
243.51,96.85,0.072
243.54,97.00,0.072
243.57,97.15,0.072
243.60,97.30,0.072
243.63,97.45,0.072
243.66,97.60,0.072
243.69,97.75,0.072
243.72,97.90,0.072
243.75,98.05,0.072
243.78,98.20,0.072
243.81,98.35,0.072
243.84,98.50,0.072
243.87,98.65,0.072
243.90,98.80,0.072
243.93,98.95,0.072
243.96,99.10,0.072
243.99,99.25,0.072
244.02,99.40,0.072
244.05,99.55,0.072
244.08,99.70,0.072
244.11,99.85,0.072
244.14,100.00,0.072
244.17,100.15,0.072
244.20,100.30,0.072
244.23,100.45,0.072
244.26,100.60,0.072
244.29,100.75,0.072
244.32,100.90,0.072
244.35,101.05,0.072
244.38,101.20,0.072
244.41,101.35,0.072
244.44,101.50,0.072
244.47,101.65,0.072
244.50,101.80,0.072
244.53,101.95,0.072
244.56,102.10,0.072
244.59,102.25,0.072
244.62,102.40,0.072
244.65,102.55,0.072
244.68,102.70,0.072
244.71,102.85,0.072
244.74,103.00,0.072
244.77,103.15,0.072
244.80,103.30,0.072
244.83,103.45,0.072
244.86,103.60,0.072
244.89,103.75,0.072
244.92,103.90,0.072
244.95,104.05,0.072
244.98,104.20,0.073
245.01,104.35,0.073
245.04,104.50,0.073
245.07,104.65,0.073
245.10,104.80,0.073
245.13,104.95,0.073
245.16,105.10,0.073
245.19,105.25,0.073
245.22,105.40,0.073
245.25,105.55,0.073
245.28,105.70,0.073
245.31,105.85,0.073
245.34,106.00,0.073
245.37,106.15,0.073
245.40,106.30,0.073
245.43,106.45,0.073
245.46,106.60,0.073
245.49,106.75,0.073
245.52,106.90,0.073
245.55,107.05,0.073
245.58,107.20,0.073
245.61,107.35,0.073
245.64,107.50,0.073
245.67,107.65,0.073
245.70,107.80,0.073
245.73,107.95,0.073
245.76,108.10,0.073
245.79,108.25,0.073
245.82,108.40,0.073
245.85,108.55,0.073
245.88,108.70,0.073
245.91,108.85,0.073
245.94,109.00,0.073
245.97,109.15,0.073
246.00,109.30,0.073
246.03,109.45,0.073
246.06,109.60,0.073
246.09,109.75,0.073
246.12,109.90,0.073
246.15,110.05,0.073
246.18,110.20,0.073
246.21,110.35,0.073
246.24,110.50,0.073
246.27,110.65,0.073
246.30,110.80,0.073
246.33,110.95,0.073
246.36,111.10,0.073
246.39,111.25,0.073
246.42,111.40,0.073
246.45,111.55,0.073
246.48,111.70,0.073
246.51,111.85,0.073
246.54,112.00,0.073
246.57,112.15,0.073
246.60,112.30,0.073
246.63,112.45,0.073
246.66,112.60,0.073
246.69,112.75,0.073
246.72,112.90,0.073
246.75,113.05,0.073
246.78,113.20,0.073
246.81,113.35,0.073
246.84,113.50,0.073
246.87,113.65,0.073
246.90,113.80,0.073
246.93,113.95,0.074
246.96,114.10,0.074
246.99,114.25,0.074
247.02,114.41,0.074
247.05,114.55,0.074
247.08,114.70,0.074
247.11,114.85,0.074
247.14,115.00,0.074
247.17,115.15,0.074
247.20,115.30,0.074
247.23,115.45,0.074
247.26,115.60,0.074
247.29,115.75,0.074
247.32,115.90,0.074
247.35,116.05,0.074
247.38,116.20,0.074
247.41,116.35,0.074
247.44,116.51,0.074
247.47,116.65,0.074
247.50,116.81,0.074
247.53,116.95,0.074
247.56,117.10,0.074
247.59,117.25,0.074
247.62,117.40,0.074
247.65,117.55,0.074
247.68,117.71,0.074
247.71,117.86,0.074
247.74,118.00,0.074
247.77,118.16,0.074
247.80,118.30,0.074
247.83,118.46,0.074
247.86,118.61,0.074
247.89,118.76,0.074
247.92,118.91,0.074
247.95,119.06,0.074
247.98,119.21,0.074
248.01,119.36,0.074
248.04,119.50,0.074
248.07,119.66,0.074
248.10,119.81,0.074
248.13,119.96,0.074
248.16,120.11,0.074
248.19,120.26,0.074
248.22,120.41,0.074
248.25,120.56,0.074
248.28,120.71,0.074
248.31,120.86,0.074
248.34,121.01,0.074
248.37,121.16,0.074
248.40,121.31,0.074
248.43,121.46,0.074
248.46,121.61,0.074
248.49,121.76,0.074
248.52,121.91,0.074
248.55,122.06,0.074
248.58,122.21,0.074
248.61,122.36,0.074
248.64,122.51,0.074
248.67,122.66,0.074
248.70,122.81,0.074
248.73,122.96,0.074
248.76,123.11,0.074
248.79,123.26,0.074
248.82,123.41,0.074
248.85,123.56,0.074
248.88,123.71,0.074
248.91,123.86,0.074
248.94,124.01,0.074
248.97,124.16,0.074
249.00,124.31,0.074
249.03,124.46,0.074
249.06,124.61,0.075
249.09,124.76,0.075
249.12,124.91,0.075
249.15,125.06,0.075
249.18,125.21,0.075
249.21,125.36,0.075
249.24,125.51,0.075
249.27,125.66,0.075
249.30,125.81,0.075
249.33,125.96,0.075
249.36,126.11,0.075
249.39,126.26,0.075
249.42,126.41,0.075
249.45,126.56,0.075
249.48,126.71,0.075
249.51,126.86,0.075
249.54,127.01,0.075
249.57,127.16,0.075
249.60,127.31,0.075
249.63,127.46,0.075
249.66,127.61,0.075
249.69,127.76,0.075
249.72,127.91,0.075
249.75,128.06,0.075
249.78,128.21,0.075
249.81,128.36,0.075
249.84,128.51,0.075
249.87,128.66,0.075
249.90,128.81,0.075
249.93,128.96,0.075
249.96,129.11,0.075
249.99,129.26,0.075
250.02,129.41,0.075
250.05,129.56,0.075
250.08,129.71,0.075
250.11,129.86,0.075
250.14,130.01,0.075
250.17,130.16,0.075
250.20,130.31,0.075
250.23,130.46,0.075
250.26,130.61,0.075
250.29,130.76,0.075
250.32,130.91,0.075
250.35,131.06,0.075
250.38,131.21,0.075
250.41,131.36,0.075
250.44,131.51,0.075
250.47,131.66,0.075
250.50,131.81,0.075
250.53,131.96,0.075
250.56,132.11,0.075
250.59,132.26,0.075
250.62,132.41,0.075
250.65,132.56,0.075
250.68,132.71,0.075
250.71,132.86,0.075
250.74,133.01,0.075
250.77,133.16,0.075
250.80,133.31,0.075
250.83,133.46,0.075
250.86,133.61,0.075
250.89,133.76,0.075
250.92,133.91,0.075
250.95,134.06,0.075
250.98,134.21,0.075
251.01,134.36,0.075
251.04,134.51,0.075
251.07,134.66,0.075
251.10,134.81,0.075
251.13,134.96,0.075
251.16,135.11,0.075
251.19,135.26,0.075
251.22,135.41,0.075
251.25,135.56,0.076
251.28,135.71,0.076
251.31,135.86,0.076
251.34,136.01,0.076
251.37,136.16,0.076
251.40,136.31,0.076
251.43,136.46,0.076
251.46,136.61,0.076
251.49,136.76,0.076
251.52,136.91,0.076
251.55,137.06,0.076
251.58,137.21,0.076
251.61,137.36,0.076
251.64,137.51,0.076
251.67,137.66,0.076
251.70,137.81,0.076
251.73,137.96,0.076
251.76,138.11,0.076
251.79,138.26,0.076
251.82,138.41,0.076
251.85,138.56,0.076
251.88,138.71,0.076
251.91,138.86,0.076
251.94,139.01,0.076
251.97,139.16,0.076
252.00,139.31,0.076
252.03,139.46,0.076
252.06,139.61,0.076
252.09,139.76,0.076
252.12,139.91,0.076
252.15,140.06,0.076
252.18,140.21,0.076
252.21,140.36,0.076
252.24,140.51,0.076
252.27,140.66,0.076
252.30,140.81,0.076
252.33,140.96,0.076
252.36,141.11,0.076
252.39,141.26,0.076
252.42,141.41,0.076
252.45,141.56,0.076
252.48,141.71,0.076
252.51,141.86,0.076
252.54,142.01,0.076
252.57,142.16,0.076
252.60,142.31,0.076
252.63,142.46,0.076
252.66,142.61,0.076
252.69,142.76,0.076
252.72,142.91,0.076
252.75,143.06,0.076
252.78,143.21,0.076
252.81,143.36,0.076
252.84,143.51,0.076
252.87,143.66,0.076
252.90,143.81,0.076
252.93,143.96,0.076
252.96,144.11,0.076
252.99,144.26,0.076
253.02,144.42,0.076
253.05,144.56,0.076
253.08,144.71,0.076
253.11,144.86,0.076
253.14,145.01,0.076
253.17,145.16,0.076
253.20,145.31,0.076
253.23,145.46,0.076
253.26,145.61,0.076
253.29,145.76,0.076
253.32,145.92,0.076
253.35,146.06,0.076
253.38,146.22,0.076
253.41,146.37,0.076
253.44,146.52,0.076
253.47,146.66,0.076
253.50,146.82,0.076
253.53,146.96,0.076
253.56,147.12,0.076
253.59,147.26,0.076
253.62,147.42,0.076
253.65,147.57,0.076
253.68,147.72,0.076
253.71,147.86,0.077
253.74,148.01,0.077
253.77,148.16,0.077
253.80,148.32,0.077
253.83,148.47,0.077
253.86,148.61,0.077
253.89,148.77,0.077
253.92,148.92,0.077
253.95,149.07,0.077
253.98,149.22,0.077
254.01,149.37,0.077
254.04,149.52,0.077
254.07,149.67,0.077
254.10,149.82,0.077
254.13,149.97,0.077
254.16,150.11,0.077
254.19,150.27,0.077
254.22,150.42,0.077
254.25,150.57,0.077
254.28,150.72,0.077
254.31,150.87,0.077
254.34,151.02,0.077
254.37,151.17,0.077
254.40,151.32,0.077
254.43,151.47,0.077
254.46,151.62,0.077
254.49,151.77,0.077
254.52,151.92,0.077
254.55,152.07,0.077
254.58,152.22,0.077
254.61,152.37,0.077
254.64,152.52,0.077
254.67,152.67,0.077
254.70,152.82,0.077
254.73,152.97,0.077
254.76,153.12,0.077
254.79,153.27,0.077
254.82,153.42,0.077
254.85,153.57,0.077
254.88,153.72,0.077
254.91,153.87,0.077
254.94,154.02,0.077
254.97,154.17,0.077
255.00,154.32,0.077
255.03,154.47,0.077
255.06,154.62,0.077
255.09,154.77,0.077
255.12,154.92,0.077
255.15,155.07,0.077
255.18,155.22,0.077
255.21,155.37,0.077
255.24,155.52,0.077
255.27,155.67,0.077
255.30,155.82,0.077
255.33,155.97,0.077
255.36,156.12,0.077
255.39,156.27,0.077
255.42,156.42,0.077
255.45,156.57,0.077
255.48,156.72,0.077
255.51,156.87,0.077
255.54,157.02,0.077
255.57,157.17,0.077
255.60,157.32,0.077
255.63,157.47,0.077
255.66,157.62,0.077
255.69,157.77,0.077
255.72,157.92,0.077
255.75,158.07,0.077
255.78,158.22,0.077
255.81,158.37,0.077
255.84,158.52,0.077
255.87,158.67,0.077
255.90,158.82,0.077
255.93,158.97,0.077
255.96,159.12,0.077
255.99,159.27,0.077
256.02,159.42,0.077
256.05,159.57,0.077
256.08,159.72,0.077
256.11,159.87,0.077
256.14,160.02,0.077
256.17,160.17,0.077
256.20,160.32,0.077
256.23,160.47,0.077
256.26,160.62,0.077
256.29,160.77,0.077
256.32,160.92,0.077
256.35,161.07,0.077
256.38,161.22,0.077
256.41,161.37,0.077
256.44,161.52,0.077
256.47,161.67,0.077
256.50,161.82,0.077
256.53,161.97,0.077
256.56,162.12,0.078
256.59,162.27,0.078
256.62,162.42,0.078
256.65,162.57,0.078
256.68,162.72,0.078
256.71,162.87,0.078
256.74,163.02,0.078
256.77,163.17,0.078
256.80,163.32,0.078
256.83,163.47,0.078
256.86,163.62,0.078
256.89,163.77,0.078
256.92,163.92,0.078
256.95,164.07,0.078
256.98,164.22,0.078
257.01,164.37,0.078
257.04,164.52,0.078
257.07,164.67,0.078
257.10,164.82,0.078
257.13,164.97,0.078
257.16,165.12,0.078
257.19,165.27,0.078
257.22,165.42,0.078
257.25,165.57,0.078
257.28,165.72,0.078
257.31,165.87,0.078
257.34,166.02,0.078
257.37,166.17,0.078
257.40,166.32,0.078
257.43,166.47,0.078
257.46,166.62,0.078
257.49,166.77,0.078
257.52,166.92,0.078
257.55,167.07,0.078
257.58,167.22,0.078
257.61,167.37,0.078
257.64,167.52,0.078
257.67,167.67,0.078
257.70,167.82,0.078
257.73,167.97,0.078
257.76,168.12,0.078
257.79,168.27,0.078
257.82,168.42,0.078
257.85,168.57,0.078
257.88,168.72,0.078
257.91,168.87,0.078
257.94,169.02,
257.97,169.17,
257.99,,