File: DSC/2024_11_12_DSC_THCa_Pro_Mechanochem_5Cmin_x4.csv
Filename,2024_11_12_DSC_THCa_Pro_Mechanochem_5Cmin_x4
Instrument name,DSC2A-00468 (192.168.1.100)
Operator,Yarger
rundate,11/13/2024
Sample name,2024_11_12_DSC_THCa_Pro_Mechanochem_5Cmin_x4
proceduresegments,Data Off ; Equilibrate -50.00 °C; Data On ; Ramp 5.00 °C/min to 100.00 °C; Data Off ; Isothermal 1.0 min; Data On ; Ramp 5.00 °C/min to -50.00 °C; Data Off ; Isothermal 1.0 min; Data On ; Ramp 5.00 °C/min to 100.00 °C; Data Off ; Isothermal 1.0 min; Data On ; Ramp 5.00 °C/min to -50.00 °C; Data Off ; Isothermal 1.0 min; Data On ; Ramp 5.00 °C/min to 170.00 °C; Data Off ; Isothermal 1.0 min; Data On ; Ramp 5.00 °C/min to -50.00 °C; Data Off ; Isothermal 1.0 min; Data On ; Ramp 5.00 °C/min to 170.00 °C
[File Parameters]
Run date,11/13/2024 5:28:34 AM
Trios version,5.1.1.46572
Original File Name,
Current File Name,D:\DSC2500\JYarger\2024_11_12_DSC_THCa_Pro_Mechanochem_5Cmin_x4.tri
[Procedure]
Procedure Name,THCa-Pro MechanoChem
Sample Name,2024_11_12_DSC_THCa_Pro_Mechanochem_5Cmin_x4
Sample Mass,4.18 mg
Reference Sample Mass,0 mg
Pan Mass,52.67 mg
Pan Number,15
Reference Pan Mass,53.32 mg
Reference Pan Number,10
Pan Type,Tzero Aluminum Hermetic
Comments,THCa_Pro Cocrystal Mechanochem 'flake'.  Al hermetic Pan/Lid.  DSC_BST1_Tray_Nov2024 google sheet.
Project Name,CoCrystals
Operator,Yarger
Test,Custom
Unload Max Temperature,30
Unload Min Temperature,30
Load Max Temperature,30
Load Min Temperature,30
Stop on Gas Flow Error,Yes
[Signal List]
Signal #1,Time (min)
Signal #2,Temperature (°C)
Signal #3,Heat Flow (mW)
Signal #4,Delta T (µV)
Signal #5,Delta Tzero (µV)
Signal #6,Tzero Temperature (°C)
Signal #7,Cell Purge (mL/min)
Signal #8,Heater Temp (°C)
Signal #9,Power Delivered (W)
Signal #10,Reference Junction Temperature (°C)
Signal #11,Flange Temperature (°C)
Signal #12,Heat Flow Phase (rad)
Signal #13,Total Heat Capacity (J/°C)
Signal #14,Heat Capacity (J/°C)
[Configuration]
Company Name,ASU
Instrument Name,DSC2A-00468
Instrument Type,DSC2500
Serial Number,DSC2A-00468
IP,192.168.1.100
Location of Instrument,MRRC
DisplayType,Unknown
Sample Interval ,0.1 s/pt
Selected Heat Flow,T4P
Exotherm Direction,Down
Cell Serial,DRC2-00792
Lid Type,Standard
Cooler,RCS 90
Leave Cooler on at End of Sequence,On
Gas 2,Nitrogen
Gas Selected,Channel 1
Flow Rate,50 mL/min
Secondary Purge,On
Licensed Heat Flow,Heat Flow T4P
Modulation Licensed,Yes
[Versions]
Common IDD Version,1
Cortex Version,VER 2.10.2.31
Driver,5.0.0.6
GDM Version,1.0.3.3
TouchscreenVersion,1.0.0.16145
FEP Version,1.2.1.21
FEP Bootloader,2.0.0.5
AutoSampler Version,2.1.1.26
Auto Sampler Bootloader,2.0.0.5
FCM Version,1.1.0.3
FCM Bootloader,2.0.0.5
[Experiment Logs]
Experiment Log Entry # 1,Data On set to 0
Experiment Log Entry # 3,Equilibrate Segment -50 (C) Started
Experiment Log Entry # 5,Air Cool is off.
Experiment Log Entry # 7,Data On set to 1
Experiment Log Entry # 9,Ramp Segment 5 C/min to 100 Started
Experiment Log Entry # 11,Data On set to 0
Experiment Log Entry # 13,Isothermal Segment 1 min started
Experiment Log Entry # 15,Data On set to 1
Experiment Log Entry # 17,Ramp Segment 5 C/min to -50 Started
Experiment Log Entry # 19,Data On set to 0
Experiment Log Entry # 21,Isothermal Segment 1 min started
Experiment Log Entry # 23,Data On set to 1
Experiment Log Entry # 25,Ramp Segment 5 C/min to 100 Started
Experiment Log Entry # 27,Data On set to 0
Experiment Log Entry # 29,Isothermal Segment 1 min started
Experiment Log Entry # 31,Data On set to 1
Experiment Log Entry # 33,Ramp Segment 5 C/min to -50 Started
Experiment Log Entry # 35,Data On set to 0
Experiment Log Entry # 37,Isothermal Segment 1 min started
Experiment Log Entry # 39,Data On set to 1
Experiment Log Entry # 41,Ramp Segment 5 C/min to 170 Started
Experiment Log Entry # 43,Data On set to 0
Experiment Log Entry # 45,Isothermal Segment 1 min started
Experiment Log Entry # 47,Data On set to 1
Experiment Log Entry # 49,Ramp Segment 5 C/min to -50 Started
Experiment Log Entry # 51,Data On set to 0
Experiment Log Entry # 53,Isothermal Segment 1 min started
Experiment Log Entry # 55,Data On set to 1
Experiment Log Entry # 57,Ramp Segment 5 C/min to 170 Started
[Method Log]
Method Log Entry # 1,Data Off
Method Log Entry # 2,Equilibrate -50 °C
Method Log Entry # 3,Data On
Method Log Entry # 4,(Ramp 355057) Ramp 5 °C/minute to 100 °C
Method Log Entry # 5,Data Off
Method Log Entry # 6,Isothermal 1 minutes
Method Log Entry # 7,Data On
Method Log Entry # 8,(Ramp 355061) Ramp 5 °C/minute to -50 °C
Method Log Entry # 9,Data Off
Method Log Entry # 10,Isothermal 1 minutes
Method Log Entry # 11,Data On
Method Log Entry # 12,(Ramp 355065) Ramp 5 °C/minute to 100 °C
Method Log Entry # 13,Data Off
Method Log Entry # 14,Isothermal 1 minutes
Method Log Entry # 15,Data On
Method Log Entry # 16,(Ramp 355069) Ramp 5 °C/minute to -50 °C
Method Log Entry # 17,Data Off
Method Log Entry # 18,Isothermal 1 minutes
Method Log Entry # 19,Data On
Method Log Entry # 20,(Ramp 355073) Ramp 5 °C/minute to 170 °C
Method Log Entry # 21,Data Off
Method Log Entry # 22,Isothermal 1 minutes
Method Log Entry # 23,Data On
Method Log Entry # 24,(Ramp 355077) Ramp 5 °C/minute to -50 °C
Method Log Entry # 25,Data Off
Method Log Entry # 26,Isothermal 1 minutes
Method Log Entry # 27,Data On
Method Log Entry # 28,(Ramp 355081) Ramp 5 °C/minute to 170 °C
Cell Serial,DRC2-00792
[T1 Calibration]
Slope,-0.008529666
Offset,9.636258
Initial Temperature,98.23
GUID,f8bfdadc-4977-4fdf-ba6d-0ba9134940c3
[TZero Calibration]
Date Applied,11/29/2022 4:06:13 PM
Description,From -89.059 °C to 396.009 °C at 20.000°C/min
Gas Type,Nitrogen
Pan Type,None
Source Files 1,C:\Users\yargerlab\Desktop\DSC Data\General\TZero_calibration_11_29_22_2nd(2).tri
Source Files 2,C:\Users\yargerlab\Desktop\DSC Data\General\TZero_calibration_11_29_22_2nd(3).tri
Delta T Offset,13.05235
Delta T Slope,-0.007271007
Delta T0 Offset,-13.69128
Delta T0 Slope,0.06063341
[Temperature Calibration]
Date Applied,11/29/2022 7:12:28 PM
Description,From 106.590 °C to 186.590 °C at 10.000°C/min
Gas Type,Nitrogen
Pan Type,Tzero Aluminum Hermetic
Source Files 1,C:\Users\yargerlab\Desktop\DSC Data\General\Indium(6).tri
Measured 1,157.391
Known 1,156.598
[Cell Constant Calibration]
Date Applied,11/29/2022 7:12:29 PM
Description,From 106.590 °C to 186.590 °C at 10.000°C/min
Gas Type,Nitrogen
Pan Type,Tzero Aluminum Hermetic
Source Files 1,C:\Users\yargerlab\Desktop\DSC Data\General\Indium(6).tri
T4P KCell,1.006051
Onset Slope,63.26126 mW/°C
[Direct Cp Calibration]
Date Applied,11/30/2022 11:04:51 AM
Description,From -79.983 °C to 298.409 °C at 10.000°C/min
Gas Type,Nitrogen
Pan Type,Tzero Aluminum Hermetic
Source Files 1,C:\Users\yargerlab\Desktop\DSC Data\General\Sapphire_Heat_Capacity_11_30_22.tri
[Rev Cp Calibration]
Date Applied,11/30/2022 1:58:51 PM
Description,From -79.996 °C to 292.812 °C at 3.000°C/min
Gas Type,Nitrogen
Pan Type,Tzero Aluminum Hermetic
Source Files 1,C:\Users\yargerlab\Desktop\DSC Data\General\Sapphire_MDSC_Calibration_11_30_22.tri
[step]
Ramp 5.00 °C/min to 100.00 °C
Time,Temperature,Heat Flow (Normalized)
min,°C,W/g
0.00,-49.70,-0.064
0.02,-49.71,-0.067
0.04,-49.72,-0.060
0.06,-49.72,-0.054
0.08,-49.72,-0.048
0.10,-49.70,-0.043
0.12,-49.66,-0.037
0.14,-49.62,-0.027
0.16,-49.57,-0.015
0.18,-49.50,-0.003
0.20,-49.43,0.011
0.22,-49.35,0.024
0.24,-49.27,0.035
0.26,-49.19,0.044
0.28,-49.10,0.054
0.30,-49.01,0.061
0.32,-48.92,0.068
0.34,-48.83,0.072
0.36,-48.74,0.076
0.38,-48.65,0.080
0.40,-48.56,0.083
0.42,-48.46,0.084
0.44,-48.37,0.087
0.46,-48.27,0.088
0.48,-48.18,0.089
0.50,-48.08,0.090
0.52,-47.99,0.091
0.54,-47.89,0.092
0.56,-47.80,0.092
0.58,-47.70,0.093
0.60,-47.60,0.093
0.62,-47.51,0.094
0.64,-47.41,0.094
0.66,-47.31,0.095
0.68,-47.22,0.095
0.70,-47.12,0.096
0.72,-47.02,0.096
0.74,-46.92,0.096
0.76,-46.83,0.097
0.78,-46.73,0.097
0.80,-46.63,0.097
0.82,-46.53,0.098
0.84,-46.43,0.098
0.86,-46.34,0.098
0.88,-46.24,0.099
0.90,-46.14,0.099
0.92,-46.04,0.099
0.94,-45.94,0.099
0.96,-45.84,0.100
0.98,-45.74,0.100
1.00,-45.65,0.100
1.02,-45.55,0.100
1.04,-45.45,0.100
1.06,-45.35,0.100
1.08,-45.25,0.101
1.10,-45.15,0.101
1.12,-45.05,0.101
1.14,-44.96,0.101
1.16,-44.86,0.101
1.18,-44.75,0.101
1.20,-44.66,0.101
1.22,-44.56,0.101
1.24,-44.46,0.101
1.26,-44.36,0.101
1.28,-44.26,0.102
1.30,-44.16,0.102
1.32,-44.06,0.102
1.34,-43.96,0.102
1.36,-43.86,0.102
1.38,-43.76,0.102
1.40,-43.67,0.102
1.42,-43.56,0.102
1.44,-43.46,0.102
1.46,-43.37,0.102
1.48,-43.27,0.102
1.50,-43.17,0.102
1.52,-43.07,0.102
1.54,-42.97,0.102
1.56,-42.87,0.102
1.58,-42.77,0.102
1.60,-42.67,0.102
1.62,-42.57,0.102
1.64,-42.47,0.102
1.66,-42.37,0.102
1.68,-42.27,0.102
1.70,-42.17,0.102
1.72,-42.07,0.102
1.74,-41.97,0.102
1.76,-41.87,0.102
1.78,-41.77,0.102
1.80,-41.67,0.102
1.82,-41.57,0.102
1.84,-41.47,0.102
1.86,-41.37,0.102
1.88,-41.27,0.102
1.90,-41.17,0.102
1.92,-41.07,0.102
1.94,-40.97,0.102
1.96,-40.87,0.102
1.98,-40.77,0.102
2.00,-40.67,0.102
2.02,-40.57,0.102
2.04,-40.47,0.102
2.06,-40.37,0.102
2.08,-40.27,0.102
2.10,-40.17,0.102
2.12,-40.07,0.102
2.14,-39.97,0.102
2.16,-39.87,0.102
2.18,-39.77,0.102
2.20,-39.67,0.102
2.22,-39.57,0.101
2.24,-39.47,0.101
2.26,-39.37,0.101
2.28,-39.27,0.101
2.30,-39.17,0.101
2.32,-39.07,0.101
2.34,-38.97,0.101
2.36,-38.87,0.101
2.38,-38.77,0.101
2.40,-38.67,0.101
2.42,-38.57,0.101
2.44,-38.47,0.101
2.46,-38.37,0.101
2.48,-38.27,0.101
2.50,-38.17,0.101
2.52,-38.07,0.101
2.54,-37.97,0.101
2.56,-37.87,0.101
2.58,-37.77,0.101
2.60,-37.67,0.101
2.62,-37.57,0.101
2.64,-37.47,0.101
2.66,-37.37,0.101
2.68,-37.27,0.101
2.70,-37.17,0.101
2.72,-37.07,0.101
2.74,-36.97,0.101
2.76,-36.87,0.101
2.78,-36.77,0.101
2.80,-36.67,0.101
2.82,-36.57,0.101
2.84,-36.47,0.101
2.86,-36.37,0.101
2.88,-36.27,0.101
2.90,-36.17,0.101
2.92,-36.07,0.101
2.94,-35.97,0.101
2.96,-35.87,0.101
2.98,-35.77,0.101
3.00,-35.67,0.101
3.02,-35.57,0.101
3.04,-35.47,0.101
3.06,-35.37,0.101
3.08,-35.27,0.101
3.10,-35.17,0.101
3.12,-35.07,0.101
3.14,-34.97,0.101
3.16,-34.87,0.101
3.18,-34.77,0.101
3.20,-34.67,0.101
3.22,-34.57,0.101
3.24,-34.47,0.101
3.26,-34.37,0.101
3.28,-34.27,0.100
3.30,-34.17,0.101
3.32,-34.06,0.101
3.34,-33.97,0.101
3.36,-33.86,0.101
3.38,-33.77,0.101
3.40,-33.66,0.101
3.42,-33.56,0.100
3.44,-33.46,0.101
3.46,-33.36,0.100
3.48,-33.27,0.101
3.50,-33.16,0.100
3.52,-33.07,0.100
3.54,-32.97,0.101
3.56,-32.86,0.100
3.58,-32.76,0.100
3.60,-32.67,0.100
3.62,-32.57,0.100
3.64,-32.47,0.100
3.66,-32.37,0.100
3.68,-32.27,0.100
3.70,-32.17,0.100
3.72,-32.07,0.100
3.74,-31.96,0.100
3.76,-31.86,0.100
3.78,-31.76,0.100
3.80,-31.66,0.100
3.82,-31.56,0.100
3.84,-31.46,0.100
3.86,-31.36,0.100
3.88,-31.26,0.100
3.90,-31.16,0.100
3.92,-31.06,0.100
3.94,-30.96,0.100
3.96,-30.86,0.100
3.98,-30.76,0.100
4.00,-30.66,0.100
4.02,-30.56,0.100
4.04,-30.46,0.100
4.06,-30.36,0.100
4.08,-30.26,0.100
4.10,-30.16,0.100
4.12,-30.06,0.100
4.14,-29.96,0.100
4.16,-29.86,0.100
4.18,-29.76,0.100
4.20,-29.66,0.100
4.22,-29.56,0.100
4.24,-29.46,0.100
4.26,-29.36,0.100
4.28,-29.26,0.100
4.30,-29.16,0.100
4.32,-29.06,0.100
4.34,-28.96,0.100
4.36,-28.86,0.100
4.38,-28.76,0.100
4.40,-28.66,0.100
4.42,-28.56,0.100
4.44,-28.46,0.100
4.46,-28.36,0.100
4.48,-28.26,0.100
4.50,-28.16,0.100
4.52,-28.06,0.100
4.54,-27.96,0.100
4.56,-27.86,0.100
4.58,-27.76,0.100
4.60,-27.66,0.100
4.62,-27.56,0.100
4.64,-27.46,0.100
4.66,-27.36,0.100
4.68,-27.26,0.100
4.70,-27.16,0.100
4.72,-27.06,0.100
4.74,-26.96,0.100
4.76,-26.86,0.100
4.78,-26.76,0.100
4.80,-26.66,0.100
4.82,-26.56,0.100
4.84,-26.46,0.100
4.86,-26.36,0.100
4.88,-26.26,0.100
4.90,-26.16,0.100
4.92,-26.06,0.100
4.94,-25.96,0.100
4.96,-25.86,0.100
4.98,-25.76,0.100
5.00,-25.66,0.100
5.02,-25.56,0.100
5.04,-25.46,0.100
5.06,-25.35,0.101
5.08,-25.25,0.101
5.10,-25.15,0.101
5.12,-25.05,0.101
5.14,-24.95,0.101
5.16,-24.85,0.101
5.18,-24.75,0.101
5.20,-24.65,0.101
5.22,-24.55,0.101
5.24,-24.45,0.101
5.26,-24.35,0.101
5.28,-24.25,0.101
5.30,-24.15,0.101
5.32,-24.05,0.101
5.34,-23.95,0.101
5.36,-23.85,0.101
5.38,-23.75,0.101
5.40,-23.65,0.101
5.42,-23.55,0.101
5.44,-23.45,0.101
5.46,-23.35,0.101
5.48,-23.25,0.101
5.50,-23.15,0.101
5.52,-23.05,0.101
5.54,-22.95,0.101
5.56,-22.85,0.101
5.58,-22.75,0.101
5.60,-22.65,0.101
5.62,-22.55,0.101
5.64,-22.45,0.101
5.66,-22.35,0.101
5.68,-22.25,0.101
5.70,-22.16,0.101
5.72,-22.06,0.101
5.74,-21.96,0.101
5.76,-21.86,0.101
5.78,-21.76,0.100
5.80,-21.66,0.100
5.82,-21.56,0.100
5.84,-21.46,0.100
5.86,-21.36,0.100
5.88,-21.26,0.100
5.90,-21.16,0.100
5.92,-21.06,0.100
5.94,-20.96,0.100
5.96,-20.86,0.100
5.98,-20.76,0.100
6.00,-20.66,0.101
6.02,-20.56,0.101
6.04,-20.46,0.101
6.06,-20.36,0.101
6.08,-20.26,0.101
6.10,-20.16,0.101
6.12,-20.05,0.101
6.14,-19.96,0.101
6.16,-19.86,0.101
6.18,-19.76,0.101
6.20,-19.65,0.101
6.22,-19.56,0.101
6.24,-19.46,0.101
6.26,-19.35,0.101
6.28,-19.25,0.101
6.30,-19.15,0.101
6.32,-19.05,0.101
6.34,-18.95,0.101
6.36,-18.85,0.101
6.38,-18.75,0.101
6.40,-18.65,0.101
6.42,-18.55,0.101
6.44,-18.45,0.101
6.46,-18.35,0.101
6.48,-18.25,0.101
6.50,-18.15,0.101
6.52,-18.05,0.101
6.54,-17.95,0.101
6.56,-17.85,0.101
6.58,-17.75,0.101
6.60,-17.65,0.101
6.62,-17.55,0.101
6.64,-17.45,0.101
6.66,-17.35,0.101
6.68,-17.25,0.101
6.70,-17.15,0.101
6.72,-17.05,0.101
6.74,-16.95,0.101
6.76,-16.85,0.101
6.78,-16.75,0.101
6.80,-16.65,0.101
6.82,-16.55,0.102
6.84,-16.45,0.102
6.86,-16.35,0.102
6.88,-16.25,0.102
6.90,-16.15,0.102
6.92,-16.05,0.101
6.94,-15.95,0.101
6.96,-15.85,0.101
6.98,-15.75,0.101
7.00,-15.65,0.101
7.02,-15.55,0.101
7.04,-15.45,0.101
7.06,-15.35,0.101
7.08,-15.25,0.101
7.10,-15.15,0.101
7.12,-15.05,0.101
7.14,-14.95,0.102
7.16,-14.85,0.102
7.18,-14.75,0.102
7.20,-14.65,0.102
7.22,-14.55,0.102
7.24,-14.45,0.102
7.26,-14.35,0.102
7.28,-14.25,0.102
7.30,-14.15,0.102
7.32,-14.05,0.102
7.34,-13.95,0.102
7.36,-13.85,0.102
7.38,-13.75,0.101
7.40,-13.65,0.101
7.42,-13.55,0.102
7.44,-13.45,0.102
7.46,-13.35,0.102
7.48,-13.25,0.102
7.50,-13.15,0.102
7.52,-13.05,0.102
7.54,-12.95,0.102
7.56,-12.85,0.102
7.58,-12.75,0.102
7.60,-12.65,0.102
7.62,-12.55,0.102
7.64,-12.45,0.102
7.66,-12.35,0.102
7.68,-12.25,0.102
7.70,-12.15,0.102
7.72,-12.05,0.102
7.74,-11.95,0.102
7.76,-11.85,0.102
7.78,-11.75,0.102
7.80,-11.65,0.102
7.82,-11.55,0.102
7.84,-11.45,0.102
7.86,-11.35,0.103
7.88,-11.25,0.103
7.90,-11.14,0.103
7.92,-11.04,0.103
7.94,-10.94,0.103
7.96,-10.84,0.103
7.98,-10.74,0.103
8.00,-10.64,0.103
8.02,-10.54,0.103
8.04,-10.44,0.103
8.06,-10.34,0.103
8.08,-10.24,0.103
8.10,-10.14,0.103
8.12,-10.04,0.103
8.14,-9.94,0.103
8.16,-9.84,0.103
8.18,-9.74,0.103
8.20,-9.64,0.103
8.22,-9.54,0.103
8.24,-9.44,0.103
8.26,-9.34,0.103
8.28,-9.24,0.103
8.30,-9.14,0.103
8.32,-9.04,0.103
8.34,-8.94,0.103
8.36,-8.84,0.103
8.38,-8.74,0.103
8.40,-8.64,0.103
8.42,-8.54,0.103
8.44,-8.44,0.103
8.46,-8.34,0.103
8.48,-8.24,0.103
8.50,-8.14,0.103
8.52,-8.05,0.103
8.54,-7.94,0.103
8.56,-7.84,0.103
8.58,-7.74,0.103
8.60,-7.64,0.103
8.62,-7.54,0.103
8.64,-7.44,0.103
8.66,-7.34,0.103
8.68,-7.24,0.103
8.70,-7.15,0.103
8.72,-7.04,0.103
8.74,-6.94,0.103
8.76,-6.84,0.103
8.78,-6.74,0.103
8.80,-6.64,0.103
8.82,-6.54,0.103
8.84,-6.44,0.103
8.86,-6.34,0.103
8.88,-6.24,0.103
8.90,-6.14,0.104
8.92,-6.04,0.104
8.94,-5.94,0.104
8.96,-5.84,0.104
8.98,-5.74,0.104
9.00,-5.64,0.104
9.02,-5.54,0.104
9.04,-5.44,0.104
9.06,-5.34,0.104
9.08,-5.24,0.104
9.10,-5.14,0.104
9.12,-5.04,0.104
9.14,-4.94,0.104
9.16,-4.84,0.104
9.18,-4.74,0.104
9.20,-4.64,0.104
9.22,-4.54,0.104
9.24,-4.44,0.104
9.26,-4.34,0.104
9.28,-4.24,0.104
9.30,-4.14,0.104
9.32,-4.04,0.104
9.34,-3.94,0.104
9.36,-3.84,0.104
9.38,-3.74,0.104
9.40,-3.64,0.104
9.42,-3.54,0.104
9.44,-3.44,0.104
9.46,-3.34,0.104
9.48,-3.24,0.104
9.50,-3.14,0.104
9.52,-3.04,0.104
9.54,-2.94,0.104
9.56,-2.84,0.104
9.58,-2.74,0.105
9.60,-2.64,0.105
9.62,-2.54,0.105
9.64,-2.44,0.105
9.66,-2.34,0.105
9.68,-2.24,0.105
9.70,-2.14,0.105
9.72,-2.04,0.105
9.74,-1.94,0.105
9.76,-1.84,0.105
9.78,-1.74,0.105
9.80,-1.64,0.105
9.82,-1.54,0.105
9.84,-1.44,0.105
9.86,-1.34,0.105
9.88,-1.24,0.105
9.90,-1.14,0.105
9.92,-1.04,0.105
9.94,-0.94,0.105
9.96,-0.84,0.105
9.98,-0.74,0.105
10.00,-0.64,0.105
10.02,-0.54,0.105
10.04,-0.44,0.105
10.06,-0.34,0.105
10.08,-0.24,0.105
10.10,-0.14,0.105
10.12,-0.04,0.105
10.14,0.06,0.105
10.16,0.16,0.105
10.18,0.26,0.105
10.20,0.36,0.105
10.22,0.46,0.105
10.24,0.56,0.105
10.26,0.66,0.105
10.28,0.76,0.105
10.30,0.86,0.105
10.32,0.96,0.105
10.34,1.06,0.105
10.36,1.16,0.105
10.38,1.26,0.105
10.40,1.36,0.106
10.42,1.46,0.105
10.44,1.56,0.106
10.46,1.66,0.106
10.48,1.76,0.106
10.50,1.86,0.106
10.52,1.96,0.106
10.54,2.06,0.106
10.56,2.16,0.106
10.58,2.26,0.106
10.60,2.36,0.106
10.62,2.46,0.106
10.64,2.56,0.106
10.66,2.66,0.106
10.68,2.76,0.106
10.70,2.86,0.106
10.72,2.96,0.106
10.74,3.06,0.106
10.76,3.16,0.106
10.78,3.26,0.106
10.80,3.36,0.106
10.82,3.46,0.106
10.84,3.56,0.106
10.86,3.66,0.106
10.88,3.76,0.106
10.90,3.86,0.106
10.92,3.96,0.106
10.94,4.06,0.106
10.96,4.16,0.106
10.98,4.26,0.106
11.00,4.36,0.106
11.02,4.46,0.106
11.04,4.56,0.106
11.06,4.66,0.106
11.08,4.76,0.107
11.10,4.86,0.107
11.12,4.96,0.107
11.14,5.06,0.107
11.16,5.16,0.107
11.18,5.26,0.107
11.20,5.36,0.107
11.22,5.46,0.107
11.24,5.56,0.107
11.26,5.66,0.107
11.28,5.77,0.107
11.30,5.87,0.107
11.32,5.97,0.107
11.34,6.06,0.107
11.36,6.17,0.107
11.38,6.27,0.107
11.40,6.37,0.107
11.42,6.47,0.107
11.44,6.56,0.107
11.46,6.67,0.107
11.48,6.77,0.107
11.50,6.87,0.107
11.52,6.97,0.107
11.54,7.07,0.107
11.56,7.17,0.107
11.58,7.27,0.107
11.60,7.37,0.107
11.62,7.47,0.107
11.64,7.57,0.107
11.66,7.67,0.107
11.68,7.77,0.107
11.70,7.87,0.107
11.72,7.97,0.108
11.74,8.07,0.108
11.76,8.17,0.108
11.78,8.27,0.108
11.80,8.37,0.108
11.82,8.47,0.108
11.84,8.57,0.108
11.86,8.67,0.108
11.88,8.77,0.108
11.90,8.87,0.108
11.92,8.97,0.108
11.94,9.07,0.108
11.96,9.17,0.108
11.98,9.27,0.108
12.00,9.37,0.108
12.02,9.47,0.108
12.04,9.57,0.108
12.06,9.67,0.108
12.08,9.77,0.108
12.10,9.87,0.108
12.12,9.97,0.108
12.14,10.07,0.108
12.16,10.17,0.108
12.18,10.27,0.108
12.20,10.37,0.108
12.22,10.47,0.108
12.24,10.57,0.108
12.26,10.67,0.108
12.28,10.77,0.108
12.30,10.87,0.108
12.32,10.97,0.108
12.34,11.07,0.108
12.36,11.17,0.108
12.38,11.27,0.109
12.40,11.37,0.109
12.42,11.47,0.109
12.44,11.57,0.109
12.46,11.67,0.109
12.48,11.77,0.109
12.50,11.87,0.109
12.52,11.97,0.109
12.54,12.07,0.109
12.56,12.17,0.109
12.58,12.27,0.109
12.60,12.37,0.109
12.62,12.47,0.109
12.64,12.57,0.109
12.66,12.67,0.109
12.68,12.77,0.109
12.70,12.87,0.109
12.72,12.97,0.109
12.74,13.07,0.109
12.76,13.17,0.109
12.78,13.27,0.109
12.80,13.37,0.109
12.82,13.47,0.109
12.84,13.57,0.109
12.86,13.67,0.109
12.88,13.77,0.110
12.90,13.87,0.110
12.92,13.97,0.110
12.94,14.07,0.110
12.96,14.17,0.110
12.98,14.27,0.110
13.00,14.37,0.110
13.02,14.47,0.110
13.04,14.57,0.110
13.06,14.67,0.110
13.08,14.77,0.110
13.10,14.87,0.110
13.12,14.97,0.110
13.14,15.07,0.110
13.16,15.17,0.110
13.18,15.27,0.110
13.20,15.37,0.110
13.22,15.47,0.110
13.24,15.57,0.110
13.26,15.67,0.110
13.28,15.77,0.110
13.30,15.87,0.110
13.32,15.97,0.110
13.34,16.07,0.110
13.36,16.17,0.110
13.38,16.27,0.110
13.40,16.37,0.110
13.42,16.47,0.110
13.44,16.57,0.110
13.46,16.67,0.110
13.48,16.77,0.110
13.50,16.87,0.111
13.52,16.97,0.111
13.54,17.07,0.111
13.56,17.17,0.111
13.58,17.27,0.111
13.60,17.37,0.111
13.62,17.47,0.111
13.64,17.57,0.111
13.66,17.67,0.111
13.68,17.77,0.111
13.70,17.87,0.111
13.72,17.97,0.111
13.74,18.07,0.111
13.76,18.17,0.111
13.78,18.27,0.111
13.80,18.37,0.111
13.82,18.47,0.111
13.84,18.57,0.111
13.86,18.67,0.111
13.88,18.77,0.111
13.90,18.87,0.111
13.92,18.98,0.111
13.94,19.07,0.111
13.96,19.17,0.111
13.98,19.27,0.111
14.00,19.37,0.111
14.02,19.47,0.111
14.04,19.57,0.112
14.06,19.67,0.112
14.08,19.77,0.112
14.10,19.87,0.112
14.12,19.97,0.112
14.14,20.07,0.112
14.16,20.17,0.112
14.18,20.27,0.112
14.20,20.37,0.112
14.22,20.47,0.112
14.24,20.58,0.112
14.26,20.68,0.112
14.28,20.78,0.112
14.30,20.87,0.112
14.32,20.97,0.112
14.34,21.07,0.112
14.36,21.18,0.112
14.38,21.28,0.112
14.40,21.38,0.112
14.42,21.48,0.112
14.44,21.58,0.112
14.46,21.68,0.112
14.48,21.78,0.112
14.50,21.88,0.112
14.52,21.98,0.113
14.54,22.08,0.113
14.56,22.18,0.113
14.58,22.28,0.113
14.60,22.38,0.113
14.62,22.47,0.113
14.64,22.58,0.113
14.66,22.68,0.113
14.68,22.78,0.113
14.70,22.88,0.113
14.72,22.98,0.113
14.74,23.08,0.113
14.76,23.18,0.113
14.78,23.28,0.113
14.80,23.38,0.113
14.82,23.48,0.113
14.84,23.58,0.113
14.86,23.68,0.113
14.88,23.78,0.113
14.90,23.88,0.113
14.92,23.98,0.113
14.94,24.08,0.113
14.96,24.18,0.113
14.98,24.28,0.113
15.00,24.38,0.113
15.02,24.48,0.113
15.04,24.58,0.114
15.06,24.68,0.114
15.08,24.78,0.114
15.10,24.88,0.114
15.12,24.98,0.114
15.14,25.08,0.114
15.16,25.18,0.114
15.18,25.28,0.114
15.20,25.38,0.114
15.22,25.48,0.114
15.24,25.58,0.114
15.26,25.68,0.114
15.28,25.78,0.114
15.30,25.88,0.114
15.32,25.98,0.114
15.34,26.08,0.114
15.36,26.18,0.114
15.38,26.28,0.114
15.40,26.38,0.114
15.42,26.48,0.114
15.44,26.58,0.114
15.46,26.68,0.114
15.48,26.78,0.114
15.50,26.88,0.115
15.52,26.98,0.115
15.54,27.08,0.115
15.56,27.18,0.115
15.58,27.28,0.115
15.60,27.38,0.115
15.62,27.48,0.115
15.64,27.58,0.115
15.66,27.68,0.115
15.68,27.78,0.115
15.70,27.88,0.115
15.72,27.98,0.115
15.74,28.08,0.115
15.76,28.18,0.115
15.78,28.28,0.115
15.80,28.38,0.115
15.82,28.48,0.115
15.84,28.58,0.115
15.86,28.68,0.115
15.88,28.78,0.115
15.90,28.88,0.115
15.92,28.98,0.115
15.94,29.08,0.116
15.96,29.18,0.116
15.98,29.28,0.116
16.00,29.38,0.116
16.02,29.48,0.116
16.04,29.58,0.116
16.06,29.68,0.116
16.08,29.78,0.116
16.10,29.88,0.116
16.12,29.98,0.116
16.14,30.08,0.116
16.16,30.18,0.116
16.18,30.28,0.116
16.20,30.38,0.116
16.22,30.48,0.116
16.24,30.58,0.116
16.26,30.68,0.116
16.28,30.78,0.116
16.30,30.88,0.116
16.32,30.98,0.116
16.34,31.08,0.116
16.36,31.18,0.116
16.38,31.28,0.116
16.40,31.38,0.116
16.42,31.48,0.116
16.44,31.58,0.116
16.46,31.68,0.116
16.48,31.78,0.116
16.50,31.88,0.116
16.52,31.98,0.117
16.54,32.08,0.117
16.56,32.18,0.117
16.58,32.28,0.117
16.60,32.38,0.117
16.62,32.48,0.117
16.64,32.58,0.117
16.66,32.68,0.117
16.68,32.78,0.117
16.70,32.88,0.117
16.72,32.98,0.117
16.74,33.08,0.117
16.76,33.18,0.117
16.78,33.28,0.117
16.80,33.38,0.117
16.82,33.48,0.117
16.84,33.58,0.117
16.86,33.68,0.117
16.88,33.78,0.117
16.90,33.88,0.117
16.92,33.98,0.117
16.94,34.08,0.117
16.96,34.18,0.117
16.98,34.28,0.118
17.00,34.38,0.118
17.02,34.48,0.118
17.04,34.58,0.118
17.06,34.68,0.118
17.08,34.78,0.118
17.10,34.88,0.118
17.12,34.98,0.118
17.14,35.08,0.118
17.16,35.18,0.118
17.18,35.28,0.118
17.20,35.38,0.118
17.22,35.48,0.118
17.24,35.58,0.118
17.26,35.68,0.118
17.28,35.78,0.118
17.30,35.88,0.118
17.32,35.98,0.118
17.34,36.08,0.118
17.36,36.18,0.118
17.38,36.28,0.118
17.40,36.38,0.118
17.42,36.48,0.118
17.44,36.58,0.118
17.46,36.68,0.118
17.48,36.78,0.118
17.50,36.88,0.118
17.52,36.98,0.118
17.54,37.08,0.118
17.56,37.18,0.119
17.58,37.28,0.119
17.60,37.38,0.119
17.62,37.48,0.119
17.64,37.58,0.119
17.66,37.69,0.119
17.68,37.78,0.119
17.70,37.89,0.119
17.72,37.99,0.119
17.74,38.08,0.119
17.76,38.18,0.119
17.78,38.29,0.119
17.80,38.38,0.119
17.82,38.49,0.119
17.84,38.58,0.119
17.86,38.68,0.119
17.88,38.78,0.119
17.90,38.89,0.119
17.92,38.99,0.119
17.94,39.08,0.119
17.96,39.19,0.119
17.98,39.29,0.119
18.00,39.38,0.119
18.02,39.49,0.120
18.04,39.59,0.120
18.06,39.69,0.120
18.08,39.79,0.120
18.10,39.89,0.120
18.12,39.99,0.120
18.14,40.09,0.120
18.16,40.19,0.120
18.18,40.29,0.120
18.20,40.39,0.120
18.22,40.49,0.120
18.24,40.59,0.120
18.26,40.69,0.120
18.28,40.79,0.120
18.30,40.89,0.120
18.32,40.99,0.120
18.34,41.09,0.120
18.36,41.19,0.120
18.38,41.29,0.120
18.40,41.39,0.120
18.42,41.49,0.120
18.44,41.59,0.120
18.46,41.69,0.120
18.48,41.79,0.120
18.50,41.89,0.120
18.52,41.99,0.120
18.54,42.09,0.121
18.56,42.19,0.120
18.58,42.29,0.121
18.60,42.39,0.121
18.62,42.49,0.121
18.64,42.59,0.121
18.66,42.69,0.121
18.68,42.79,0.121
18.70,42.89,0.121
18.72,42.99,0.121
18.74,43.09,0.121
18.76,43.19,0.121
18.78,43.29,0.121
18.80,43.39,0.121
18.82,43.49,0.121
18.84,43.59,0.121
18.86,43.69,0.121
18.88,43.79,0.121
18.90,43.89,0.121
18.92,43.99,0.121
18.94,44.09,0.121
18.96,44.19,0.121
18.98,44.29,0.121
19.00,44.39,0.121
19.02,44.49,0.122
19.04,44.59,0.122
19.06,44.69,0.122
19.08,44.79,0.122
19.10,44.89,0.122
19.12,44.99,0.122
19.14,45.09,0.122
19.16,45.19,0.122
19.18,45.29,0.122
19.20,45.39,0.122
19.22,45.49,0.122
19.24,45.59,0.122
19.26,45.69,0.122
19.28,45.79,0.122
19.30,45.89,0.122
19.32,45.99,0.122
19.34,46.09,0.122
19.36,46.19,0.122
19.38,46.29,0.122
19.40,46.39,0.122
19.42,46.49,0.122
19.44,46.59,0.122
19.46,46.69,0.122
19.48,46.79,0.122
19.50,46.89,0.123
19.52,46.99,0.123
19.54,47.09,0.123
19.56,47.19,0.123
19.58,47.29,0.123
19.60,47.39,0.123
19.62,47.49,0.123
19.64,47.59,0.123
19.66,47.69,0.123
19.68,47.79,0.123
19.70,47.89,0.123
19.72,47.99,0.123
19.74,48.09,0.123
19.76,48.19,0.123
19.78,48.29,0.123
19.80,48.39,0.123
19.82,48.49,0.123
19.84,48.59,0.123
19.86,48.69,0.123
19.88,48.79,0.123
19.90,48.89,0.123
19.92,48.99,0.124
19.94,49.09,0.124
19.96,49.19,0.124
19.98,49.29,0.124
20.00,49.39,0.124
20.02,49.49,0.124
20.04,49.59,0.124
20.06,49.69,0.124
20.08,49.79,0.124
20.10,49.89,0.124
20.12,49.99,0.124
20.14,50.09,0.124
20.16,50.19,0.124
20.18,50.29,0.124
20.20,50.39,0.124
20.22,50.49,0.124
20.24,50.59,0.124
20.26,50.69,0.124
20.28,50.79,0.125
20.30,50.89,0.125
20.32,50.99,0.125
20.34,51.09,0.125
20.36,51.19,0.125
20.38,51.29,0.125
20.40,51.39,0.125
20.42,51.49,0.125
20.44,51.59,0.125
20.46,51.69,0.125
20.48,51.79,0.125
20.50,51.89,0.125
20.52,51.99,0.125
20.54,52.09,0.125
20.56,52.19,0.125
20.58,52.29,0.125
20.60,52.39,0.125
20.62,52.49,0.125
20.64,52.59,0.125
20.66,52.69,0.125
20.68,52.79,0.125
20.70,52.89,0.126
20.72,52.99,0.126
20.74,53.09,0.126
20.76,53.19,0.126
20.78,53.29,0.126
20.80,53.39,0.126
20.82,53.49,0.126
20.84,53.59,0.126
20.86,53.69,0.126
20.88,53.79,0.126
20.90,53.89,0.126
20.92,53.99,0.126
20.94,54.09,0.126
20.96,54.19,0.126
20.98,54.30,0.126
21.00,54.40,0.126
21.02,54.49,0.126
21.04,54.59,0.126
21.06,54.69,0.126
21.08,54.79,0.127
21.10,54.90,0.127
21.12,55.00,0.127
21.14,55.10,0.127
21.16,55.20,0.127
21.18,55.29,0.127
21.20,55.39,0.127
21.22,55.49,0.127
21.24,55.59,0.127
21.26,55.69,0.127
21.28,55.79,0.127
21.30,55.90,0.127
21.32,55.99,0.127
21.34,56.10,0.127
21.36,56.20,0.127
21.38,56.30,0.127
21.40,56.40,0.127
21.42,56.50,0.127
21.44,56.60,0.128
21.46,56.70,0.128
21.48,56.80,0.128
21.50,56.90,0.128
21.52,57.00,0.128
21.54,57.10,0.128
21.56,57.20,0.128
21.58,57.30,0.128
21.60,57.40,0.128
21.62,57.50,0.128
21.64,57.60,0.128
21.66,57.70,0.128
21.68,57.80,0.128
21.70,57.90,0.128
21.72,58.00,0.128
21.74,58.10,0.128
21.76,58.20,0.128
21.78,58.30,0.128
21.80,58.40,0.128
21.82,58.50,0.128
21.84,58.60,0.128
21.86,58.70,0.128
21.88,58.80,0.128
21.90,58.90,0.128
21.92,59.00,0.128
21.94,59.10,0.128
21.96,59.20,0.128
21.98,59.30,0.128
22.00,59.40,0.128
22.02,59.50,0.128
22.04,59.60,0.128
22.06,59.70,0.128
22.08,59.80,0.129
22.10,59.90,0.129
22.12,60.00,0.129
22.14,60.10,0.129
22.16,60.20,0.129
22.18,60.30,0.129
22.20,60.40,0.129
22.22,60.50,0.129
22.24,60.60,0.129
22.26,60.70,0.129
22.28,60.80,0.129
22.30,60.90,0.129
22.32,61.00,0.129
22.34,61.10,0.129
22.36,61.20,0.129
22.38,61.30,0.129
22.40,61.40,0.129
22.42,61.50,0.129
22.44,61.60,0.129
22.46,61.70,0.129
22.48,61.80,0.129
22.50,61.90,0.129
22.52,62.00,0.129
22.54,62.10,0.129
22.56,62.20,0.130
22.58,62.30,0.130
22.60,62.40,0.130
22.62,62.50,0.130
22.64,62.60,0.130
22.66,62.70,0.130
22.68,62.80,0.130
22.70,62.90,0.130
22.72,63.00,0.130
22.74,63.10,0.130
22.76,63.20,0.130
22.78,63.30,0.130
22.80,63.40,0.130
22.82,63.50,0.130
22.84,63.60,0.130
22.86,63.70,0.130
22.88,63.80,0.130
22.90,63.90,0.130
22.92,64.00,0.130
22.94,64.10,0.131
22.96,64.20,0.131
22.98,64.30,0.131
23.00,64.40,0.131
23.02,64.50,0.131
23.04,64.60,0.131
23.06,64.70,0.131
23.08,64.80,0.131
23.10,64.90,0.131
23.12,65.00,0.131
23.14,65.10,0.131
23.16,65.20,0.131
23.18,65.30,0.131
23.20,65.40,0.131
23.22,65.50,0.131
23.24,65.60,0.131
23.26,65.70,0.131
23.28,65.80,0.131
23.30,65.90,0.131
23.32,66.00,0.131
23.34,66.10,0.131
23.36,66.20,0.131
23.38,66.30,0.131
23.40,66.40,0.131
23.42,66.50,0.131
23.44,66.60,0.132
23.46,66.70,0.132
23.48,66.80,0.132
23.50,66.90,0.132
23.52,67.00,0.132
23.54,67.10,0.132
23.56,67.20,0.132
23.58,67.30,0.132
23.60,67.40,0.132
23.62,67.50,0.132
23.64,67.60,0.132
23.66,67.70,0.132
23.68,67.80,0.132
23.70,67.90,0.132
23.72,68.00,0.132
23.74,68.10,0.132
23.76,68.20,0.132
23.78,68.30,0.132
23.80,68.40,0.132
23.82,68.50,0.132
23.84,68.60,0.132
23.86,68.70,0.133
23.88,68.80,0.133
23.90,68.90,0.133
23.92,69.00,0.133
23.94,69.10,0.133
23.96,69.20,0.133
23.98,69.30,0.133
24.00,69.40,0.133
24.02,69.50,0.133
24.04,69.60,0.133
24.06,69.70,0.133
24.08,69.80,0.133
24.10,69.90,0.133
24.12,70.00,0.133
24.14,70.10,0.133
24.16,70.20,0.133
24.18,70.30,0.133
24.20,70.40,0.133
24.22,70.50,0.133
24.24,70.60,0.133
24.26,70.70,0.133
24.28,70.80,0.133
24.30,70.90,0.133
24.32,71.00,0.133
24.34,71.10,0.133
24.36,71.20,0.134
24.38,71.30,0.134
24.40,71.40,0.134
24.42,71.50,0.134
24.44,71.60,0.134
24.46,71.70,0.134
24.48,71.80,0.134
24.50,71.90,0.134
24.52,72.00,0.134
24.54,72.10,0.134
24.56,72.20,0.134
24.58,72.30,0.134
24.60,72.40,0.134
24.62,72.50,0.134
24.64,72.60,0.134
24.66,72.70,0.134
24.68,72.80,0.134
24.70,72.90,0.134
24.72,73.00,0.134
24.74,73.10,0.134
24.76,73.20,0.134
24.78,73.30,0.134
24.80,73.40,0.134
24.82,73.50,0.134
24.84,73.60,0.135
24.86,73.70,0.135
24.88,73.80,0.135
24.90,73.90,0.135
24.92,74.00,0.135
24.94,74.10,0.135
24.96,74.20,0.135
24.98,74.30,0.135
25.00,74.40,0.135
25.02,74.50,0.135
25.04,74.60,0.135
25.06,74.70,0.135
25.08,74.81,0.135
25.10,74.90,0.135
25.12,75.00,0.135
25.14,75.10,0.135
25.16,75.21,0.135
25.18,75.30,0.135
25.20,75.40,0.135
25.22,75.50,0.135
25.24,75.60,0.135
25.26,75.70,0.135
25.28,75.80,0.135
25.30,75.90,0.135
25.32,76.00,0.135
25.34,76.10,0.135
25.36,76.20,0.135
25.38,76.30,0.135
25.40,76.40,0.135
25.42,76.50,0.136
25.44,76.61,0.136
25.46,76.71,0.136
25.48,76.81,0.136
25.50,76.91,0.136
25.52,77.01,0.136
25.54,77.10,0.136
25.56,77.21,0.136
25.58,77.30,0.136
25.60,77.41,0.136
25.62,77.51,0.136
25.64,77.61,0.136
25.66,77.71,0.136
25.68,77.81,0.136
25.70,77.91,0.136
25.72,78.01,0.136
25.74,78.11,0.136
25.76,78.21,0.136
25.78,78.31,0.136
25.80,78.41,0.136
25.82,78.51,0.137
25.84,78.61,0.137
25.86,78.71,0.137
25.88,78.81,0.137
25.90,78.91,0.137
25.92,79.01,0.137
25.94,79.11,0.137
25.96,79.21,0.137
25.98,79.31,0.137
26.00,79.41,0.137
26.02,79.51,0.137
26.04,79.61,0.137
26.06,79.71,0.137
26.08,79.81,0.137
26.10,79.91,0.137
26.12,80.01,0.137
26.14,80.11,0.137
26.16,80.21,0.137
26.18,80.31,0.137
26.20,80.41,0.137
26.22,80.51,0.137
26.24,80.61,0.137
26.26,80.71,0.137
26.28,80.81,0.137
26.30,80.91,0.137
26.32,81.01,0.137
26.34,81.11,0.137
26.36,81.21,0.137
26.38,81.31,0.137
26.40,81.41,0.137
26.42,81.51,0.137
26.44,81.61,0.138
26.46,81.71,0.138
26.48,81.81,0.138
26.50,81.91,0.138
26.52,82.01,0.138
26.54,82.11,0.138
26.56,82.21,0.138
26.58,82.31,0.138
26.60,82.41,0.138
26.62,82.51,0.138
26.64,82.61,0.138
26.66,82.71,0.138
26.68,82.81,0.138
26.70,82.91,0.138
26.72,83.01,0.138
26.74,83.11,0.138
26.76,83.21,0.138
26.78,83.31,0.138
26.80,83.41,0.138
26.82,83.51,0.138
26.84,83.61,0.138
26.86,83.71,0.138
26.88,83.81,0.138
26.90,83.91,0.138
26.92,84.01,0.138
26.94,84.11,0.139
26.96,84.21,0.139
26.98,84.31,0.139
27.00,84.41,0.139
27.02,84.51,0.139
27.04,84.61,0.139
27.06,84.71,0.139
27.08,84.81,0.139
27.10,84.91,0.139
27.12,85.01,0.139
27.14,85.11,0.139
27.16,85.21,0.139
27.18,85.31,0.139
27.20,85.41,0.139
27.22,85.51,0.139
27.24,85.61,0.139
27.26,85.71,0.139
27.28,85.81,0.139
27.30,85.91,0.139
27.32,86.01,0.139
27.34,86.11,0.139
27.36,86.21,0.139
27.38,86.31,0.139
27.40,86.41,0.139
27.42,86.51,0.139
27.44,86.61,0.139
27.46,86.71,0.139
27.48,86.81,0.139
27.50,86.91,0.139
27.52,87.01,0.139
27.54,87.11,0.139
27.56,87.21,0.139
27.58,87.31,0.140
27.60,87.41,0.140
27.62,87.51,0.140
27.64,87.61,0.140
27.66,87.71,0.140
27.68,87.81,0.140
27.70,87.91,0.140
27.72,88.01,0.140
27.74,88.11,0.140
27.76,88.21,0.140
27.78,88.31,0.140
27.80,88.41,0.140
27.82,88.51,0.140
27.84,88.61,0.140
27.86,88.71,0.140
27.88,88.81,0.140
27.90,88.91,0.140
27.92,89.01,0.140
27.94,89.11,0.140
27.96,89.21,0.140
27.98,89.31,0.140
28.00,89.41,0.140
28.02,89.51,0.140
28.04,89.61,0.140
28.06,89.71,0.140
28.08,89.81,0.141
28.10,89.91,0.141
28.12,90.01,0.141
28.14,90.11,0.141
28.16,90.21,0.141
28.18,90.31,0.141
28.20,90.41,0.141
28.22,90.51,0.141
28.24,90.61,0.141
28.26,90.71,0.141
28.28,90.81,0.141
28.30,90.91,0.141
28.32,91.01,0.141
28.34,91.11,0.141
28.36,91.21,0.141
28.38,91.31,0.141
28.40,91.41,0.141
28.42,91.51,0.141
28.44,91.61,0.141
28.46,91.71,0.141
28.48,91.81,0.141
28.50,91.91,0.142
28.52,92.01,0.142
28.54,92.11,0.142
28.56,92.21,0.142
28.58,92.31,0.142
28.60,92.41,0.142
28.62,92.51,0.142
28.64,92.61,0.142
28.66,92.71,0.142
28.68,92.81,0.142
28.70,92.91,0.142
28.72,93.01,0.142
28.74,93.11,0.142
28.76,93.21,0.142
28.78,93.31,0.142
28.80,93.41,0.142
28.82,93.51,0.142
28.84,93.61,0.142
28.86,93.71,0.142
28.88,93.81,0.142
28.90,93.91,0.142
28.92,94.01,0.142
28.94,94.11,0.142
28.96,94.21,0.143
28.98,94.31,0.143
29.00,94.41,0.143
29.02,94.51,0.143
29.04,94.61,0.143
29.06,94.71,0.143
29.08,94.81,0.143
29.10,94.91,0.143
29.12,95.01,0.143
29.14,95.11,0.143
29.16,95.21,0.143
29.18,95.31,0.143
29.20,95.41,0.143
29.22,95.51,0.143
29.24,95.61,0.143
29.26,95.71,0.143
29.28,95.81,0.143
29.30,95.91,0.143
29.32,96.01,0.144
29.34,96.11,0.144
29.36,96.21,0.144
29.38,96.31,0.144
29.40,96.41,0.144
29.42,96.51,0.144
29.44,96.61,0.144
29.46,96.71,0.144
29.48,96.81,0.144
29.50,96.91,0.144
29.52,97.01,0.144
29.54,97.11,0.144
29.56,97.21,0.144
29.58,97.31,0.144
29.60,97.41,0.144
29.62,97.51,0.144
29.64,97.61,0.144
29.66,97.71,0.144
29.68,97.81,0.144
29.70,97.91,0.144
29.72,98.01,0.145
29.74,98.11,0.145
29.76,98.21,0.145
29.78,98.31,0.145
29.80,98.42,0.145
29.82,98.51,0.145
29.84,98.61,0.145
29.86,98.71,0.145
29.88,98.81,0.145
29.90,98.91,0.145
29.92,99.01,0.145
29.94,99.11,
29.96,99.21,
29.98,99.31,
29.99,,

[step]
Ramp 5.00 °C/min to -50.00 °C
Time,Temperature,Heat Flow (Normalized)
min,°C,W/g
30.99,100.11,-0.039
31.01,100.11,-0.039
31.03,100.11,-0.039
31.05,100.10,-0.039
31.07,100.08,-0.040
31.09,100.05,-0.045
31.11,100.00,-0.063
31.13,99.95,-0.081
31.15,99.88,-0.104
31.17,99.81,-0.119
31.19,99.73,-0.138
31.21,99.65,-0.152
31.23,99.57,-0.161
31.25,99.48,-0.171
31.27,99.39,-0.181
31.29,99.30,-0.188
31.31,99.21,-0.195
31.33,99.12,-0.198
31.35,99.02,-0.203
31.37,98.93,-0.205
31.39,98.83,-0.209
31.41,98.74,-0.210
31.43,98.64,-0.212
31.45,98.54,-0.213
31.47,98.44,-0.214
31.49,98.35,-0.216
31.51,98.25,-0.217
31.53,98.15,-0.217
31.55,98.05,-0.218
31.57,97.96,-0.218
31.59,97.86,-0.219
31.61,97.76,-0.219
31.63,97.66,-0.220
31.65,97.56,-0.220
31.67,97.46,-0.221
31.69,97.36,-0.221
31.71,97.26,-0.222
31.73,97.17,-0.222
31.75,97.07,-0.222
31.77,96.97,-0.223
31.79,96.87,-0.223
31.81,96.77,-0.223
31.83,96.67,-0.223
31.85,96.57,-0.224
31.87,96.47,-0.224
31.89,96.37,-0.224
31.91,96.27,-0.224
31.93,96.17,-0.224
31.95,96.08,-0.225
31.97,95.97,-0.225
31.99,95.88,-0.225
32.01,95.78,-0.225
32.03,95.68,-0.225
32.05,95.58,-0.225
32.07,95.48,-0.225
32.09,95.38,-0.225
32.11,95.28,-0.225
32.13,95.18,-0.225
32.15,95.08,-0.226
32.17,94.98,-0.226
32.19,94.88,-0.226
32.21,94.78,-0.226
32.23,94.68,-0.226
32.25,94.58,-0.226
32.27,94.48,-0.226
32.29,94.38,-0.226
32.31,94.28,-0.226
32.33,94.18,-0.226
32.35,94.08,-0.226
32.37,93.98,-0.226
32.39,93.88,-0.226
32.41,93.78,-0.226
32.43,93.68,-0.226
32.45,93.58,-0.226
32.47,93.48,-0.226
32.49,93.38,-0.226
32.51,93.28,-0.226
32.53,93.18,-0.226
32.55,93.08,-0.226
32.57,92.98,-0.226
32.59,92.88,-0.225
32.61,92.78,-0.225
32.63,92.68,-0.225
32.65,92.58,-0.225
32.67,92.48,-0.225
32.69,92.38,-0.225
32.71,92.29,-0.225
32.73,92.19,-0.225
32.75,92.09,-0.225
32.77,91.99,-0.225
32.79,91.89,-0.225
32.81,91.79,-0.225
32.83,91.69,-0.225
32.85,91.59,-0.225
32.87,91.49,-0.224
32.89,91.39,-0.224
32.91,91.29,-0.224
32.93,91.19,-0.224
32.95,91.09,-0.224
32.97,90.99,-0.224
32.99,90.89,-0.224
33.01,90.79,-0.224
33.03,90.69,-0.224
33.05,90.59,-0.224
33.07,90.49,-0.224
33.09,90.39,-0.224
33.11,90.29,-0.224
33.13,90.19,-0.224
33.15,90.09,-0.223
33.17,89.99,-0.223
33.19,89.89,-0.223
33.21,89.78,-0.223
33.23,89.69,-0.223
33.25,89.59,-0.223
33.27,89.49,-0.223
33.29,89.39,-0.223
33.31,89.29,-0.223
33.33,89.19,-0.223
33.35,89.09,-0.223
33.37,88.99,-0.223
33.39,88.89,-0.223
33.41,88.79,-0.222
33.43,88.69,-0.222
33.45,88.59,-0.222
33.47,88.49,-0.222
33.49,88.39,-0.222
33.51,88.29,-0.222
33.53,88.19,-0.222
33.55,88.09,-0.222
33.57,87.99,-0.222
33.59,87.89,-0.222
33.61,87.79,-0.221
33.63,87.69,-0.221
33.65,87.59,-0.221
33.67,87.49,-0.221
33.69,87.39,-0.221
33.71,87.29,-0.221
33.73,87.19,-0.221
33.75,87.09,-0.221
33.77,86.99,-0.221
33.79,86.89,-0.221
33.81,86.79,-0.221
33.83,86.69,-0.221
33.85,86.59,-0.221
33.87,86.49,-0.220
33.89,86.39,-0.221
33.91,86.29,-0.220
33.93,86.19,-0.220
33.95,86.09,-0.220
33.97,85.99,-0.220
33.99,85.89,-0.220
34.01,85.79,-0.220
34.03,85.69,-0.220
34.05,85.59,-0.220
34.07,85.49,-0.220
34.09,85.39,-0.220
34.11,85.29,-0.220
34.13,85.19,-0.220
34.15,85.09,-0.220
34.17,84.99,-0.219
34.19,84.89,-0.219
34.21,84.79,-0.219
34.23,84.69,-0.219
34.25,84.59,-0.219
34.27,84.49,-0.219
34.29,84.39,-0.219
34.31,84.29,-0.219
34.33,84.19,-0.219
34.35,84.09,-0.219
34.37,83.99,-0.219
34.39,83.89,-0.219
34.41,83.79,-0.219
34.43,83.69,-0.219
34.45,83.59,-0.219
34.47,83.49,-0.219
34.49,83.39,-0.219
34.51,83.29,-0.219
34.53,83.19,-0.219
34.55,83.09,-0.219
34.57,82.99,-0.219
34.59,82.89,-0.219
34.61,82.79,-0.219
34.63,82.69,-0.219
34.65,82.59,-0.219
34.67,82.49,-0.219
34.69,82.39,-0.219
34.71,82.29,-0.219
34.73,82.19,-0.219
34.75,82.09,-0.219
34.77,81.99,-0.219
34.79,81.89,-0.218
34.81,81.79,-0.218
34.83,81.69,-0.218
34.85,81.59,-0.218
34.87,81.49,-0.218
34.89,81.39,-0.218
34.91,81.29,-0.218
34.93,81.19,-0.218
34.95,81.09,-0.218
34.97,80.99,-0.218
34.99,80.89,-0.218
35.01,80.79,-0.218
35.03,80.69,-0.218
35.05,80.59,-0.218
35.07,80.49,-0.218
35.09,80.39,-0.218
35.11,80.29,-0.218
35.13,80.19,-0.218
35.15,80.09,-0.218
35.17,79.99,-0.218
35.19,79.89,-0.218
35.21,79.79,-0.218
35.23,79.69,-0.218
35.25,79.59,-0.218
35.27,79.49,-0.217
35.29,79.39,-0.217
35.31,79.29,-0.217
35.33,79.19,-0.217
35.35,79.09,-0.217
35.37,78.99,-0.217
35.39,78.89,-0.217
35.41,78.79,-0.217
35.43,78.69,-0.217
35.45,78.59,-0.217
35.47,78.49,-0.217
35.49,78.39,-0.217
35.51,78.29,-0.217
35.53,78.19,-0.217
35.55,78.09,-0.217
35.57,77.99,-0.217
35.59,77.89,-0.217
35.61,77.79,-0.217
35.63,77.69,-0.217
35.65,77.59,-0.216
35.67,77.49,-0.216
35.69,77.39,-0.216
35.71,77.29,-0.216
35.73,77.19,-0.216
35.75,77.09,-0.216
35.77,76.99,-0.216
35.79,76.89,-0.216
35.81,76.79,-0.216
35.83,76.69,-0.216
35.85,76.60,-0.216
35.87,76.49,-0.216
35.89,76.39,-0.216
35.91,76.29,-0.216
35.93,76.20,-0.216
35.95,76.10,-0.216
35.97,75.99,-0.215
35.99,75.90,-0.215
36.01,75.80,-0.215
36.03,75.69,-0.215
36.05,75.60,-0.215
36.07,75.50,-0.215
36.09,75.40,-0.215
36.11,75.29,-0.215
36.13,75.20,-0.215
36.15,75.10,-0.215
36.17,75.00,-0.215
36.19,74.90,-0.215
36.21,74.80,-0.215
36.23,74.70,-0.215
36.25,74.60,-0.215
36.27,74.50,-0.215
36.29,74.40,-0.215
36.31,74.30,-0.215
36.33,74.20,-0.214
36.35,74.10,-0.214
36.37,74.00,-0.214
36.39,73.90,-0.214
36.41,73.80,-0.214
36.43,73.70,-0.214
36.45,73.60,-0.214
36.47,73.50,-0.214
36.49,73.40,-0.214
36.51,73.30,-0.214
36.53,73.20,-0.214
36.55,73.10,-0.214
36.57,73.00,-0.214
36.59,72.90,-0.214
36.61,72.80,-0.214
36.63,72.70,-0.214
36.65,72.60,-0.214
36.67,72.50,-0.214
36.69,72.40,-0.214
36.71,72.30,-0.214
36.73,72.20,-0.213
36.75,72.10,-0.213
36.77,72.00,-0.213
36.79,71.90,-0.213
36.81,71.80,-0.213
36.83,71.70,-0.213
36.85,71.60,-0.213
36.87,71.50,-0.213
36.89,71.40,-0.213
36.91,71.30,-0.213
36.93,71.20,-0.213
36.95,71.10,-0.213
36.97,71.00,-0.213
36.99,70.90,-0.213
37.01,70.80,-0.213
37.03,70.70,-0.213
37.05,70.60,-0.213
37.07,70.50,-0.213
37.09,70.40,-0.212
37.11,70.30,-0.212
37.13,70.20,-0.212
37.15,70.10,-0.212
37.17,70.00,-0.212
37.19,69.90,-0.212
37.21,69.80,-0.212
37.23,69.70,-0.212
37.25,69.60,-0.212
37.27,69.50,-0.212
[...]
227.16,15.11,0.132
227.19,15.26,0.132
227.22,15.41,0.132
227.25,15.56,0.133
227.28,15.71,0.133
227.31,15.86,0.134
227.34,16.01,0.134
227.37,16.16,0.135
227.40,16.31,0.135
227.43,16.46,0.136
227.46,16.61,0.136
227.49,16.76,0.137
227.52,16.91,0.138
227.55,17.06,0.138
227.58,17.21,0.139
227.61,17.36,0.139
227.64,17.51,0.140
227.67,17.66,0.141
227.70,17.82,0.141
227.73,17.96,0.142
227.76,18.11,0.142
227.79,18.26,0.143
227.82,18.41,0.144
227.85,18.56,0.144
227.88,18.71,0.145
227.91,18.86,0.146
227.94,19.01,0.146
227.97,19.16,0.147
228.00,19.31,0.147
228.03,19.46,0.148
228.06,19.61,0.149
228.09,19.76,0.149
228.12,19.91,0.150
228.15,20.06,0.150
228.18,20.21,0.151
228.21,20.36,0.151
228.24,20.51,0.152
228.27,20.66,0.152
228.30,20.81,0.152
228.33,20.96,0.153
228.36,21.11,0.153
228.39,21.26,0.153
228.42,21.41,0.153
228.45,21.56,0.154
228.48,21.71,0.154
228.51,21.86,0.154
228.54,22.01,0.154
228.57,22.16,0.154
228.60,22.31,0.154
228.63,22.46,0.154
228.66,22.61,0.154
228.69,22.76,0.154
228.72,22.91,0.154
228.75,23.06,0.154
228.78,23.21,0.154
228.81,23.36,0.154
228.84,23.51,0.154
228.87,23.66,0.154
228.90,23.81,0.154
228.93,23.96,0.154
228.96,24.11,0.154
228.99,24.26,0.154
229.02,24.41,0.154
229.05,24.57,0.154
229.08,24.72,0.153
229.11,24.87,0.153
229.14,25.01,0.153
229.17,25.17,0.153
229.20,25.32,0.153
229.23,25.47,0.153
229.26,25.62,0.153
229.29,25.77,0.153
229.32,25.92,0.153
229.35,26.07,0.153
229.38,26.22,0.153
229.41,26.37,0.153
229.44,26.52,0.153
229.47,26.67,0.153
229.50,26.82,0.153
229.53,26.97,0.153
229.56,27.12,0.153
229.59,27.27,0.153
229.62,27.42,0.153
229.65,27.57,0.154
229.68,27.72,0.154
229.71,27.87,0.154
229.74,28.02,0.154
229.77,28.17,0.154
229.80,28.32,0.154
229.83,28.47,0.154
229.86,28.62,0.154
229.89,28.77,0.154
229.92,28.92,0.154
229.95,29.07,0.154
229.98,29.22,0.154
230.01,29.37,0.155
230.04,29.52,0.155
230.07,29.67,0.155
230.10,29.82,0.155
230.13,29.97,0.155
230.16,30.12,0.155
230.19,30.27,0.155
230.22,30.42,0.155
230.25,30.57,0.155
230.28,30.72,0.156
230.31,30.87,0.156
230.34,31.02,0.156
230.37,31.17,0.156
230.40,31.32,0.156
230.43,31.47,0.156
230.46,31.62,0.156
230.49,31.77,0.156
230.52,31.92,0.156
230.55,32.07,0.156
230.58,32.22,0.156
230.61,32.37,0.156
230.64,32.52,0.156
230.67,32.67,0.157
230.70,32.82,0.157
230.73,32.97,0.157
230.76,33.12,0.157
230.79,33.27,0.157
230.82,33.42,0.157
230.85,33.57,0.157
230.88,33.72,0.157
230.91,33.87,0.157
230.94,34.02,0.157
230.97,34.17,0.157
231.00,34.32,0.157
231.03,34.47,0.157
231.06,34.62,0.157
231.09,34.77,0.157
231.12,34.92,0.157
231.15,35.07,0.157
231.18,35.22,0.158
231.21,35.37,0.158
231.24,35.52,0.158
231.27,35.67,0.158
231.30,35.82,0.158
231.33,35.97,0.158
231.36,36.12,0.158
231.39,36.27,0.158
231.42,36.42,0.158
231.45,36.57,0.158
231.48,36.72,0.158
231.51,36.87,0.158
231.54,37.02,0.158
231.57,37.17,0.158
231.60,37.32,0.158
231.63,37.47,0.159
231.66,37.62,0.159
231.69,37.77,0.159
231.72,37.92,0.159
231.75,38.07,0.159
231.78,38.22,0.159
231.81,38.37,0.159
231.84,38.52,0.159
231.87,38.67,0.159
231.90,38.82,0.159
231.93,38.97,0.159
231.96,39.12,0.159
231.99,39.28,0.159
232.02,39.43,0.159
232.05,39.57,0.159
232.08,39.72,0.159
232.11,39.88,0.160
232.14,40.02,0.160
232.17,40.17,0.160
232.20,40.33,0.160
232.23,40.47,0.160
232.26,40.62,0.160
232.29,40.78,0.160
232.32,40.93,0.160
232.35,41.08,0.160
232.38,41.23,0.160
232.41,41.38,0.160
232.44,41.53,0.160
232.47,41.68,0.161
232.50,41.83,0.161
232.53,41.98,0.161
232.56,42.13,0.161
232.59,42.28,0.161
232.62,42.43,0.161
232.65,42.58,0.161
232.68,42.73,0.161
232.71,42.88,0.161
232.74,43.03,0.161
232.77,43.18,0.161
232.80,43.33,0.161
232.83,43.48,0.161
232.86,43.63,0.162
232.89,43.78,0.162
232.92,43.93,0.162
232.95,44.08,0.162
232.98,44.23,0.162
233.01,44.38,0.162
233.04,44.53,0.162
233.07,44.68,0.162
233.10,44.83,0.162
233.13,44.98,0.162
233.16,45.13,0.162
233.19,45.28,0.162
233.22,45.43,0.163
233.25,45.58,0.163
233.28,45.73,0.163
233.31,45.88,0.163
233.34,46.03,0.163
233.37,46.18,0.163
233.40,46.33,0.163
233.43,46.48,0.163
233.46,46.63,0.163
233.49,46.78,0.163
233.52,46.93,0.163
233.55,47.08,0.163
233.58,47.23,0.163
233.61,47.38,0.163
233.64,47.53,0.164
233.67,47.68,0.164
233.70,47.83,0.164
233.73,47.98,0.164
233.76,48.13,0.164
233.79,48.28,0.164
233.82,48.43,0.164
233.85,48.58,0.164
233.88,48.73,0.164
233.91,48.88,0.164
233.94,49.03,0.164
233.97,49.18,0.164
234.00,49.33,0.165
234.03,49.48,0.165
234.06,49.63,0.165
234.09,49.78,0.165
234.12,49.93,0.165
234.15,50.08,0.165
234.18,50.23,0.165
234.21,50.38,0.165
234.24,50.53,0.165
234.27,50.68,0.165
234.30,50.83,0.165
234.33,50.98,0.165
234.36,51.13,0.165
234.39,51.28,0.166
234.42,51.43,0.166
234.45,51.58,0.166
234.48,51.73,0.166
234.51,51.88,0.166
234.54,52.03,0.166
234.57,52.18,0.166
234.60,52.33,0.166
234.63,52.48,0.166
234.66,52.63,0.166
234.69,52.78,0.166
234.72,52.93,0.166
234.75,53.08,0.166
234.78,53.23,0.166
234.81,53.38,0.166
234.84,53.53,0.166
234.87,53.68,0.167
234.90,53.83,0.167
234.93,53.98,0.167
234.96,54.13,0.167
234.99,54.28,0.167
235.02,54.43,0.167
235.05,54.58,0.167
235.08,54.73,0.167
235.11,54.88,0.167
235.14,55.03,0.167
235.17,55.19,0.168
235.20,55.34,0.168
235.23,55.49,0.168
235.26,55.64,0.168
235.29,55.79,0.168
235.32,55.94,0.168
235.35,56.09,0.168
235.38,56.24,0.168
235.41,56.39,0.168
235.44,56.54,0.168
235.47,56.69,0.168
235.50,56.84,0.168
235.53,56.99,0.169
235.56,57.14,0.169
235.59,57.29,0.169
235.62,57.44,0.169
235.65,57.59,0.169
235.68,57.74,0.169
235.71,57.89,0.169
235.74,58.04,0.169
235.77,58.19,0.169
235.80,58.34,0.169
235.83,58.49,0.169
235.86,58.64,0.169
235.89,58.79,0.169
235.92,58.94,0.169
235.95,59.09,0.169
235.98,59.24,0.170
236.01,59.39,0.170
236.04,59.54,0.170
236.07,59.69,0.170
236.10,59.84,0.170
236.13,59.99,0.170
236.16,60.14,0.170
236.19,60.29,0.170
236.22,60.44,0.170
236.25,60.59,0.170
236.28,60.74,0.170
236.31,60.89,0.170
236.34,61.04,0.170
236.37,61.19,0.170
236.40,61.34,0.171
236.43,61.49,0.171
236.46,61.64,0.171
236.49,61.79,0.171
236.52,61.94,0.171
236.55,62.08,0.171
236.58,62.24,0.171
236.61,62.39,0.171
236.64,62.54,0.171
236.67,62.69,0.171
236.70,62.84,0.171
236.73,62.99,0.172
236.76,63.14,0.172
236.79,63.29,0.172
236.82,63.44,0.172
236.85,63.59,0.172
236.88,63.74,0.172
236.91,63.89,0.172
236.94,64.04,0.172
236.97,64.19,0.172
237.00,64.34,0.172
237.03,64.49,0.172
237.06,64.64,0.173
237.09,64.79,0.173
237.12,64.94,0.173
237.15,65.09,0.173
237.18,65.24,0.173
237.21,65.39,0.173
237.24,65.54,0.173
237.27,65.69,0.173
237.30,65.84,0.173
237.33,65.99,0.173
237.36,66.14,0.173
237.39,66.29,0.173
237.42,66.44,0.173
237.45,66.59,0.173
237.48,66.74,0.174
237.51,66.89,0.174
237.54,67.04,0.174
237.57,67.19,0.174
237.60,67.34,0.174
237.63,67.49,0.174
237.66,67.64,0.174
237.69,67.79,0.174
237.72,67.94,0.174
237.75,68.09,0.174
237.78,68.24,0.174
237.81,68.39,0.174
237.84,68.54,0.175
237.87,68.69,0.175
237.90,68.84,0.175
237.93,68.99,0.175
237.96,69.14,0.175
237.99,69.29,0.175
238.02,69.44,0.175
238.05,69.59,0.175
238.08,69.74,0.175
238.11,69.89,0.175
238.14,70.04,0.176
238.17,70.19,0.176
238.20,70.34,0.176
238.23,70.49,0.176
238.26,70.64,0.176
238.29,70.79,0.176
238.32,70.94,0.176
238.35,71.09,0.176
238.38,71.24,0.176
238.41,71.39,0.176
238.44,71.54,0.176
238.47,71.69,0.176
238.50,71.84,0.176
238.53,71.99,0.177
238.56,72.14,0.177
238.59,72.29,0.177
238.62,72.44,0.177
238.65,72.59,0.177
238.68,72.74,0.177
238.71,72.89,0.177
238.74,73.04,0.177
238.77,73.19,0.177
238.80,73.34,0.177
238.83,73.49,0.177
238.86,73.64,0.177
238.89,73.79,0.177
238.92,73.94,0.177
238.95,74.09,0.178
238.98,74.24,0.178
239.01,74.39,0.178
239.04,74.54,0.178
239.07,74.69,0.178
239.10,74.84,0.178
239.13,74.99,0.178
239.16,75.14,0.178
239.19,75.29,0.178
239.22,75.44,0.178
239.25,75.59,0.178
239.28,75.74,0.178
239.31,75.89,0.179
239.34,76.04,0.179
239.37,76.19,0.179
239.40,76.34,0.179
239.43,76.49,0.179
239.46,76.64,0.179
239.49,76.79,0.179
239.52,76.94,0.179
239.55,77.09,0.179
239.58,77.24,0.179
239.61,77.39,0.179
239.64,77.54,0.179
239.67,77.69,0.180
239.70,77.84,0.180
239.73,77.99,0.180
239.76,78.14,0.180
239.79,78.29,0.180
239.82,78.45,0.180
239.85,78.59,0.180
239.88,78.74,0.180
239.91,78.90,0.180
239.94,79.05,0.180
239.97,79.20,0.180
240.00,79.35,0.180
240.03,79.50,0.181
240.06,79.65,0.181
240.09,79.80,0.181
240.12,79.95,0.181
240.15,80.10,0.181
240.18,80.25,0.181
240.21,80.40,0.181
240.24,80.55,0.181
240.27,80.70,0.181
240.30,80.85,0.181
240.33,81.00,0.181
240.36,81.15,0.181
240.39,81.30,0.181
240.42,81.45,0.181
240.45,81.60,0.181
240.48,81.75,0.182
240.51,81.90,0.182
240.54,82.05,0.182
240.57,82.20,0.182
240.60,82.35,0.182
240.63,82.50,0.182
240.66,82.65,0.182
240.69,82.80,0.182
240.72,82.95,0.182
240.75,83.10,0.182
240.78,83.25,0.182
240.81,83.40,0.182
240.84,83.55,0.182
240.87,83.70,0.182
240.90,83.85,0.182
240.93,84.00,0.182
240.96,84.15,0.183
240.99,84.30,0.183
241.02,84.45,0.183
241.05,84.60,0.183
241.08,84.75,0.183
241.11,84.90,0.183
241.14,85.05,0.183
241.17,85.20,0.183
241.20,85.35,0.183
241.23,85.50,0.183
241.26,85.65,0.183
241.29,85.80,0.183
241.32,85.95,0.183
241.35,86.10,0.183
241.38,86.25,0.183
241.41,86.40,0.183
241.44,86.55,0.184
241.47,86.70,0.184
241.50,86.85,0.184
241.53,87.00,0.184
241.56,87.15,0.184
241.59,87.30,0.184
241.62,87.45,0.184
241.65,87.60,0.184
241.68,87.75,0.184
241.71,87.90,0.184
241.74,88.05,0.184
241.77,88.20,0.184
241.80,88.35,0.184
241.83,88.50,0.185
241.86,88.65,0.185
241.89,88.80,0.185
241.92,88.95,0.185
241.95,89.10,0.185
241.98,89.25,0.185
242.01,89.40,0.185
242.04,89.55,0.185
242.07,89.70,0.185
242.10,89.85,0.185
242.13,90.00,0.185
242.16,90.15,0.186
242.19,90.30,0.186
242.22,90.45,0.186
242.25,90.60,0.186
242.28,90.75,0.186
242.31,90.90,0.186
242.34,91.05,0.186
242.37,91.20,0.186
242.40,91.35,0.186
242.43,91.50,0.186
242.46,91.65,0.187
242.49,91.80,0.187
242.52,91.95,0.187
242.55,92.10,0.187
242.58,92.25,0.187
242.61,92.40,0.187
242.64,92.55,0.187
242.67,92.70,0.187
242.70,92.85,0.187
242.73,93.00,0.187
242.76,93.15,0.187
242.79,93.30,0.188
242.82,93.45,0.188
242.85,93.60,0.188
242.88,93.75,0.188
242.91,93.90,0.188
242.94,94.05,0.188
242.97,94.20,0.188
243.00,94.35,0.188
243.03,94.50,0.188
243.06,94.65,0.188
243.09,94.80,0.188
243.12,94.95,0.189
243.15,95.10,0.189
243.18,95.25,0.189
243.21,95.40,0.189
243.24,95.55,0.189
243.27,95.70,0.189
243.30,95.85,0.189
243.33,96.00,0.189
243.36,96.15,0.189
243.39,96.30,0.189
243.42,96.45,0.189
243.45,96.60,0.189
243.48,96.75,0.190
243.51,96.90,0.190
243.54,97.05,0.190
243.57,97.20,0.190
243.60,97.35,0.190
243.63,97.50,0.190
243.66,97.65,0.190
243.69,97.80,0.190
243.72,97.95,0.190
243.75,98.10,0.190
243.78,98.25,0.190
243.81,98.40,0.191
243.84,98.55,0.191
243.87,98.70,0.191
243.90,98.85,0.191
243.93,99.00,0.191
243.96,99.15,0.191
243.99,99.30,0.191
244.02,99.45,0.191
244.05,99.60,0.191
244.08,99.75,0.192
244.11,99.90,0.192
244.14,100.05,0.192
244.17,100.20,0.192
244.20,100.35,0.192
244.23,100.50,0.192
244.26,100.65,0.192
244.29,100.80,0.192
244.32,100.95,0.192
244.35,101.10,0.192
244.38,101.25,0.192
244.41,101.40,0.192
244.44,101.55,0.192
244.47,101.70,0.193
244.50,101.85,0.193
244.53,102.00,0.193
244.56,102.15,0.193
244.59,102.30,0.193
244.62,102.45,0.193
244.65,102.61,0.193
244.68,102.76,0.193
244.71,102.90,0.193
244.74,103.05,0.193
244.77,103.21,0.193
244.80,103.36,0.194
244.83,103.50,0.194
244.86,103.65,0.194
244.89,103.81,0.194
244.92,103.95,0.194
244.95,104.10,0.194
244.98,104.26,0.194
245.01,104.41,0.194
245.04,104.55,0.194
245.07,104.71,0.194
245.10,104.85,0.194
245.13,105.00,0.194
245.16,105.15,0.195
245.19,105.30,0.195
245.22,105.45,0.195
245.25,105.60,0.195
245.28,105.76,0.195
245.31,105.91,0.195
245.34,106.06,0.195
245.37,106.21,0.195
245.40,106.36,0.195
245.43,106.51,0.195
245.46,106.66,0.196
245.49,106.81,0.196
245.52,106.96,0.196
245.55,107.11,0.196
245.58,107.26,0.196
245.61,107.41,0.196
245.64,107.56,0.196
245.67,107.71,0.196
245.70,107.86,0.196
245.73,108.01,0.196
245.76,108.16,0.196
245.79,108.31,0.196
245.82,108.46,0.196
245.85,108.61,0.196
245.88,108.76,0.196
245.91,108.91,0.197
245.94,109.06,0.197
245.97,109.21,0.197
246.00,109.36,0.197
246.03,109.51,0.197
246.06,109.66,0.197
246.09,109.81,0.197
246.12,109.96,0.197
246.15,110.11,0.197
246.18,110.26,0.197
246.21,110.41,0.198
246.24,110.56,0.198
246.27,110.71,0.198
246.30,110.86,0.198
246.33,111.01,0.198
246.36,111.16,0.198
246.39,111.31,0.198
246.42,111.46,0.198
246.45,111.61,0.198
246.48,111.76,0.198
246.51,111.91,0.198
246.54,112.06,0.198
246.57,112.21,0.199
246.60,112.36,0.199
246.63,112.51,0.199
246.66,112.66,0.199
246.69,112.81,0.199
246.72,112.96,0.199
246.75,113.11,0.199
246.78,113.26,0.199
246.81,113.41,0.199
246.84,113.56,0.199
246.87,113.71,0.199
246.90,113.86,0.200
246.93,114.01,0.200
246.96,114.16,0.200
246.99,114.31,0.200
247.02,114.46,0.200
247.05,114.61,0.200
247.08,114.76,0.200
247.11,114.91,0.200
247.14,115.06,0.200
247.17,115.21,0.200
247.20,115.36,0.200
247.23,115.51,0.200
247.26,115.66,0.200
247.29,115.81,0.201
247.32,115.96,0.201
247.35,116.11,0.201
247.38,116.26,0.201
247.41,116.41,0.201
247.44,116.56,0.201
247.47,116.71,0.201
247.50,116.86,0.201
247.53,117.01,0.201
247.56,117.16,0.201
247.59,117.31,0.201
247.62,117.46,0.201
247.65,117.61,0.201
247.68,117.76,0.201
247.71,117.91,0.202
247.74,118.06,0.202
247.77,118.21,0.202
247.80,118.36,0.202
247.83,118.51,0.202
247.86,118.66,0.202
247.89,118.81,0.202
247.92,118.96,0.202
247.95,119.11,0.202
247.98,119.26,0.202
248.01,119.41,0.202
248.04,119.56,0.202
248.07,119.71,0.203
248.10,119.86,0.203
248.13,120.01,0.203
248.16,120.16,0.203
248.19,120.31,0.203
248.22,120.46,0.203
248.25,120.61,0.203
248.28,120.76,0.203
248.31,120.91,0.203
248.34,121.06,0.203
248.37,121.21,0.203
248.40,121.36,0.203
248.43,121.51,0.203
248.46,121.66,0.203
248.49,121.81,0.204
248.52,121.96,0.204
248.55,122.11,0.204
248.58,122.26,0.204
248.61,122.41,0.204
248.64,122.56,0.204
248.67,122.71,0.204
248.70,122.86,0.204
248.73,123.01,0.204
248.76,123.16,0.205
248.79,123.31,0.205
248.82,123.46,0.205
248.85,123.61,0.205
248.88,123.76,0.205
248.91,123.91,0.205
248.94,124.06,0.205
248.97,124.21,0.205
249.00,124.36,0.205
249.03,124.51,0.205
249.06,124.66,0.205
249.09,124.81,0.205
249.12,124.96,0.206
249.15,125.11,0.206
249.18,125.26,0.206
249.21,125.41,0.206
249.24,125.56,0.206
249.27,125.71,0.206
249.30,125.86,0.206
249.33,126.01,0.206
249.36,126.16,0.206
249.39,126.31,0.206
249.42,126.46,0.206
249.45,126.61,0.207
249.48,126.76,0.207
249.51,126.91,0.207
249.54,127.06,0.207
249.57,127.21,0.207
249.60,127.36,0.207
249.63,127.51,0.207
249.66,127.66,0.207
249.69,127.81,0.207
249.72,127.96,0.207
249.75,128.11,0.207
249.78,128.26,0.207
249.81,128.41,0.208
249.84,128.56,0.208
249.87,128.71,0.208
249.90,128.86,0.208
249.93,129.01,0.208
249.96,129.16,0.208
249.99,129.31,0.208
250.02,129.46,0.208
250.05,129.61,0.208
250.08,129.76,0.208
250.11,129.91,0.208
250.14,130.06,0.208
250.17,130.21,0.208
250.20,130.36,0.208
250.23,130.51,0.208
250.26,130.66,0.209
250.29,130.81,0.209
250.32,130.96,0.209
250.35,131.11,0.209
250.38,131.26,0.209
250.41,131.41,0.209
250.44,131.56,0.209
250.47,131.71,0.209
250.50,131.86,0.209
250.53,132.01,0.209
250.56,132.16,0.209
250.59,132.31,0.209
250.62,132.46,0.210
250.65,132.61,0.210
250.68,132.76,0.210
250.71,132.91,0.210
250.74,133.06,0.210
250.77,133.21,0.210
250.80,133.36,0.210
250.83,133.51,0.210
250.86,133.66,0.210
250.89,133.81,0.210
250.92,133.96,0.210
250.95,134.11,0.210
250.98,134.26,0.211
251.01,134.41,0.211
251.04,134.56,0.211
251.07,134.71,0.211
251.10,134.86,0.211
251.13,135.01,0.211
251.16,135.16,0.211
251.19,135.31,0.211
251.22,135.46,0.211
251.25,135.61,0.211
251.28,135.76,0.211
251.31,135.91,0.211
251.34,136.07,0.212
251.37,136.22,0.212
251.40,136.36,0.212
251.43,136.51,0.212
251.46,136.66,0.212
251.49,136.81,0.212
251.52,136.96,0.212
251.55,137.11,0.212
251.58,137.26,0.212
251.61,137.41,0.212
251.64,137.56,0.212
251.67,137.71,0.212
251.70,137.86,0.212
251.73,138.01,0.213
251.76,138.16,0.213
251.79,138.31,0.213
251.82,138.46,0.213
251.85,138.62,0.213
251.88,138.76,0.213
251.91,138.91,0.213
251.94,139.06,0.213
251.97,139.21,0.213
252.00,139.36,0.213
252.03,139.51,0.213
252.06,139.67,0.214
252.09,139.82,0.214
252.12,139.97,0.214
252.15,140.12,0.214
252.18,140.26,0.214
252.21,140.41,0.214
252.24,140.57,0.214
252.27,140.71,0.214
252.30,140.86,0.214
252.33,141.01,0.214
252.36,141.17,0.215
252.39,141.32,0.215
252.42,141.46,0.215
252.45,141.62,0.215
252.48,141.76,0.215
252.51,141.92,0.215
252.54,142.07,0.215
252.57,142.21,0.215
252.60,142.36,0.215
252.63,142.51,0.215
252.66,142.66,0.215
252.69,142.81,0.215
252.72,142.96,0.215
252.75,143.12,0.215
252.78,143.26,0.215
252.81,143.42,0.216
252.84,143.57,0.216
252.87,143.72,0.216
252.90,143.86,0.216
252.93,144.02,0.216
252.96,144.17,0.216
252.99,144.32,0.216
253.02,144.47,0.216
253.05,144.62,0.217
253.08,144.77,0.217
253.11,144.92,0.217
253.14,145.07,0.217
253.17,145.22,0.217
253.20,145.37,0.217
253.23,145.52,0.217
253.26,145.67,0.217
253.29,145.82,0.217
253.32,145.97,0.217
253.35,146.12,0.218
253.38,146.27,0.218
253.41,146.42,0.218
253.44,146.57,0.218
253.47,146.72,0.218
253.50,146.87,0.218
253.53,147.02,0.218
253.56,147.17,0.218
253.59,147.32,0.218
253.62,147.47,0.218
253.65,147.62,0.219
253.68,147.77,0.219
253.71,147.92,0.219
253.74,148.07,0.219
253.77,148.22,0.219
253.80,148.37,0.219
253.83,148.52,0.219
253.86,148.67,0.219
253.89,148.81,0.219
253.92,148.97,0.219
253.95,149.12,0.219
253.98,149.27,0.220
254.01,149.42,0.220
254.04,149.57,0.220
254.07,149.72,0.220
254.10,149.87,0.220
254.13,150.02,0.220
254.16,150.17,0.220
254.19,150.32,0.220
254.22,150.47,0.220
254.25,150.62,0.220
254.28,150.77,0.220
254.31,150.92,0.220
254.34,151.07,0.221
254.37,151.22,0.221
254.40,151.37,0.221
254.43,151.52,0.221
254.46,151.67,0.221
254.49,151.82,0.221
254.52,151.97,0.221
254.55,152.12,0.221
254.58,152.27,0.221
254.61,152.42,0.221
254.64,152.57,0.221
254.67,152.71,0.222
254.70,152.87,0.222
254.73,153.02,0.222
254.76,153.17,0.222
254.79,153.32,0.222
254.82,153.47,0.222
254.85,153.62,0.222
254.88,153.77,0.222
254.91,153.92,0.222
254.94,154.07,0.223
254.97,154.22,0.223
255.00,154.37,0.223
255.03,154.52,0.223
255.06,154.67,0.223
255.09,154.82,0.223
255.12,154.97,0.223
255.15,155.12,0.223
255.18,155.27,0.223
255.21,155.42,0.223
255.24,155.57,0.224
255.27,155.72,0.224
255.30,155.87,0.224
255.33,156.02,0.224
255.36,156.17,0.224
255.39,156.32,0.224
255.42,156.47,0.224
255.45,156.62,0.224
255.48,156.77,0.224
255.51,156.92,0.224
255.54,157.07,0.225
255.57,157.22,0.225
255.60,157.37,0.225
255.63,157.52,0.225
255.66,157.67,0.225
255.69,157.82,0.225
255.72,157.97,0.225
255.75,158.12,0.225
255.78,158.27,0.226
255.81,158.42,0.226
255.84,158.57,0.226
255.87,158.72,0.226
255.90,158.87,0.226
255.93,159.02,0.226
255.96,159.17,0.226
255.99,159.32,0.226
256.02,159.47,0.226
256.05,159.62,0.227
256.08,159.77,0.227
256.11,159.92,0.227
256.14,160.07,0.227
256.17,160.22,0.227
256.20,160.37,0.227
256.23,160.52,0.227
256.26,160.67,0.227
256.29,160.82,0.227
256.32,160.97,0.227
256.35,161.12,0.228
256.38,161.27,0.228
256.41,161.42,0.228
256.44,161.57,0.228
256.47,161.72,0.228
256.50,161.87,0.228
256.53,162.02,0.228
256.56,162.17,0.228
256.59,162.32,0.229
256.62,162.47,0.229
256.65,162.62,0.229
256.68,162.77,0.229
256.71,162.92,0.229
256.74,163.07,0.229
256.77,163.22,0.229
256.80,163.37,0.230
256.83,163.52,0.230
256.86,163.67,0.230
256.89,163.82,0.230
256.92,163.97,0.230
256.95,164.12,0.230
256.98,164.27,0.230
257.01,164.42,0.230
257.04,164.57,0.230
257.07,164.72,0.231
257.10,164.87,0.231
257.13,165.02,0.231
257.16,165.17,0.231
257.19,165.32,0.231
257.22,165.47,0.231
257.25,165.62,0.231
257.28,165.77,0.232
257.31,165.92,0.232
257.34,166.07,0.232
257.37,166.22,0.232
257.40,166.37,0.232
257.43,166.52,0.232
257.46,166.67,0.232
257.49,166.82,0.232
257.52,166.97,0.233
257.55,167.12,0.233
257.58,167.27,0.233
257.61,167.42,0.233
257.64,167.57,0.233
257.67,167.72,0.233
257.70,167.87,0.233
257.73,168.02,0.234
257.76,168.17,0.234
257.79,168.32,0.234
257.82,168.47,0.234
257.85,168.62,0.234
257.88,168.77,0.234
257.91,168.92,0.234
257.94,169.07,
257.97,169.22,
257.99,,