File: DSC/2024_11_12_DSC_CBD_Pro_Mechanochem_5Cmin_x4.txt
Filename	2024_11_12_DSC_CBD_Pro_Mechanochem_5Cmin_x4
Instrument name	DSC2A-00468 (192.168.1.100)
Operator	Yarger
rundate	11/12/2024
Sample name	2024_11_12_DSC_CBD_Pro_Mechanochem_5Cmin_x4
proceduresegments	Data Off ; Equilibrate -50.00 °C; Data On ; Ramp 5.00 °C/min to 100.00 °C; Data Off ; Isothermal 1.0 min; Data On ; Ramp 5.00 °C/min to -50.00 °C; Data Off ; Isothermal 1.0 min; Data On ; Ramp 5.00 °C/min to 100.00 °C; Data Off ; Isothermal 1.0 min; Data On ; Ramp 5.00 °C/min to -50.00 °C; Data Off ; Isothermal 1.0 min; Data On ; Ramp 5.00 °C/min to 170.00 °C; Data Off ; Isothermal 1.0 min; Data On ; Ramp 5.00 °C/min to -50.00 °C; Data Off ; Isothermal 1.0 min; Data On ; Ramp 5.00 °C/min to 170.00 °C
[File Parameters]
Run date	11/12/2024 8:34:20 PM
Trios version	5.1.1.46572
Original File Name
Current File Name	D:\DSC2500\JYarger\2024_11_12_DSC_CBD_Pro_Mechanochem_5Cmin_x4.tri
[Procedure]
Procedure Name	CBD-Pro Cocrystal
Sample Name	2024_11_12_DSC_CBD_Pro_Mechanochem_5Cmin_x4
Sample Mass	4 mg
Reference Sample Mass	0 mg
Pan Mass	53.27 mg
Pan Number	4
Reference Pan Mass	53.32 mg
Reference Pan Number	10
Pan Type	Tzero Aluminum Hermetic
Comments	CBD-Proline mechanochem, potential cocyrstal (Steve/Jose Oct/Nov 2024)   Al hermetic Pan/Lid.  DSC_BST1_Tray_Nov2024 google sheet.
Project Name	CoCrystals
Operator	Yarger
Test	Custom
Unload Max Temperature	30
Unload Min Temperature	30
Load Max Temperature	30
Load Min Temperature	30
Stop on Gas Flow Error	Yes
[Signal List]
Signal #1	Time (min)
Signal #2	Temperature (°C)
Signal #3	Heat Flow (mW)
Signal #4	Delta T (µV)
Signal #5	Delta Tzero (µV)
Signal #6	Tzero Temperature (°C)
Signal #7	Cell Purge (mL/min)
Signal #8	Heater Temp (°C)
Signal #9	Power Delivered (W)
Signal #10	Reference Junction Temperature (°C)
Signal #11	Flange Temperature (°C)
Signal #12	Heat Flow Phase (rad)
Signal #13	Total Heat Capacity (J/°C)
Signal #14	Heat Capacity (J/°C)
[Configuration]
Company Name	ASU
Instrument Name	DSC2A-00468
Instrument Type	DSC2500
Serial Number	DSC2A-00468
IP	192.168.1.100
Location of Instrument	MRRC
DisplayType	Unknown
Sample Interval 	0.1 s/pt
Selected Heat Flow	T4P
Exotherm Direction	Down
Cell Serial	DRC2-00792
Lid Type	Standard
Cooler	RCS 90
Leave Cooler on at End of Sequence	On
Gas 2	Nitrogen
Gas Selected	Channel 1
Flow Rate	50 mL/min
Secondary Purge	On
Licensed Heat Flow	Heat Flow T4P
Modulation Licensed	Yes
[Versions]
Common IDD Version	1
Cortex Version	VER 2.10.2.31
Driver	5.0.0.6
GDM Version	1.0.3.3
TouchscreenVersion	1.0.0.16145
FEP Version	1.2.1.21
FEP Bootloader	2.0.0.5
AutoSampler Version	2.1.1.26
Auto Sampler Bootloader	2.0.0.5
FCM Version	1.1.0.3
FCM Bootloader	2.0.0.5
[Experiment Logs]
Experiment Log Entry # 2	Data On set to 0
Experiment Log Entry # 4	Equilibrate Segment -50 (C) Started
Experiment Log Entry # 6	Air Cool is off.
Experiment Log Entry # 8	Data On set to 1
Experiment Log Entry # 10	Ramp Segment 5 C/min to 100 Started
Experiment Log Entry # 12	Data On set to 0
Experiment Log Entry # 14	Isothermal Segment 1 min started
Experiment Log Entry # 16	Data On set to 1
Experiment Log Entry # 18	Ramp Segment 5 C/min to -50 Started
Experiment Log Entry # 20	Data On set to 0
Experiment Log Entry # 22	Isothermal Segment 1 min started
Experiment Log Entry # 24	Data On set to 1
Experiment Log Entry # 26	Ramp Segment 5 C/min to 100 Started
Experiment Log Entry # 28	Data On set to 0
Experiment Log Entry # 30	Isothermal Segment 1 min started
Experiment Log Entry # 32	Data On set to 1
Experiment Log Entry # 34	Ramp Segment 5 C/min to -50 Started
Experiment Log Entry # 36	Data On set to 0
Experiment Log Entry # 38	Isothermal Segment 1 min started
Experiment Log Entry # 40	Data On set to 1
Experiment Log Entry # 42	Ramp Segment 5 C/min to 170 Started
Experiment Log Entry # 44	Data On set to 0
Experiment Log Entry # 46	Isothermal Segment 1 min started
Experiment Log Entry # 48	Data On set to 1
Experiment Log Entry # 50	Ramp Segment 5 C/min to -50 Started
Experiment Log Entry # 52	Data On set to 0
Experiment Log Entry # 54	Isothermal Segment 1 min started
Experiment Log Entry # 56	Data On set to 1
Experiment Log Entry # 58	Ramp Segment 5 C/min to 170 Started
[Method Log]
Method Log Entry # 1	Data Off
Method Log Entry # 2	Equilibrate -50 °C
Method Log Entry # 3	Data On
Method Log Entry # 4	(Ramp 219554) Ramp 5 °C/minute to 100 °C
Method Log Entry # 5	Data Off
Method Log Entry # 6	Isothermal 1 minutes
Method Log Entry # 7	Data On
Method Log Entry # 8	(Ramp 219558) Ramp 5 °C/minute to -50 °C
Method Log Entry # 9	Data Off
Method Log Entry # 10	Isothermal 1 minutes
Method Log Entry # 11	Data On
Method Log Entry # 12	(Ramp 219562) Ramp 5 °C/minute to 100 °C
Method Log Entry # 13	Data Off
Method Log Entry # 14	Isothermal 1 minutes
Method Log Entry # 15	Data On
Method Log Entry # 16	(Ramp 219566) Ramp 5 °C/minute to -50 °C
Method Log Entry # 17	Data Off
Method Log Entry # 18	Isothermal 1 minutes
Method Log Entry # 19	Data On
Method Log Entry # 20	(Ramp 219570) Ramp 5 °C/minute to 170 °C
Method Log Entry # 21	Data Off
Method Log Entry # 22	Isothermal 1 minutes
Method Log Entry # 23	Data On
Method Log Entry # 24	(Ramp 219574) Ramp 5 °C/minute to -50 °C
Method Log Entry # 25	Data Off
Method Log Entry # 26	Isothermal 1 minutes
Method Log Entry # 27	Data On
Method Log Entry # 28	(Ramp 219578) Ramp 5 °C/minute to 170 °C
Cell Serial	DRC2-00792
[T1 Calibration]
Slope	-0.008529666
Offset	9.636258
Initial Temperature	98.23
GUID	f8bfdadc-4977-4fdf-ba6d-0ba9134940c3
[TZero Calibration]
Date Applied	11/29/2022 4:06:13 PM
Description	From -89.059 °C to 396.009 °C at 20.000°C/min
Gas Type	Nitrogen
Pan Type	None
Source Files 1	C:\Users\yargerlab\Desktop\DSC Data\General\TZero_calibration_11_29_22_2nd(2).tri
Source Files 2	C:\Users\yargerlab\Desktop\DSC Data\General\TZero_calibration_11_29_22_2nd(3).tri
Delta T Offset	13.05235
Delta T Slope	-0.007271007
Delta T0 Offset	-13.69128
Delta T0 Slope	0.06063341
[Temperature Calibration]
Date Applied	11/29/2022 7:12:28 PM
Description	From 106.590 °C to 186.590 °C at 10.000°C/min
Gas Type	Nitrogen
Pan Type	Tzero Aluminum Hermetic
Source Files 1	C:\Users\yargerlab\Desktop\DSC Data\General\Indium(6).tri
Measured 1	157.391
Known 1	156.598
[Cell Constant Calibration]
Date Applied	11/29/2022 7:12:29 PM
Description	From 106.590 °C to 186.590 °C at 10.000°C/min
Gas Type	Nitrogen
Pan Type	Tzero Aluminum Hermetic
Source Files 1	C:\Users\yargerlab\Desktop\DSC Data\General\Indium(6).tri
T4P KCell	1.006051
Onset Slope	63.26126 mW/°C
[Direct Cp Calibration]
Date Applied	11/30/2022 11:04:51 AM
Description	From -79.983 °C to 298.409 °C at 10.000°C/min
Gas Type	Nitrogen
Pan Type	Tzero Aluminum Hermetic
Source Files 1	C:\Users\yargerlab\Desktop\DSC Data\General\Sapphire_Heat_Capacity_11_30_22.tri
[Rev Cp Calibration]
Date Applied	11/30/2022 1:58:51 PM
Description	From -79.996 °C to 292.812 °C at 3.000°C/min
Gas Type	Nitrogen
Pan Type	Tzero Aluminum Hermetic
Source Files 1	C:\Users\yargerlab\Desktop\DSC Data\General\Sapphire_MDSC_Calibration_11_30_22.tri
[step]
Ramp 5.00 °C/min to 100.00 °C
Time	Temperature	Heat Flow (Normalized)
min	°C	W/g
0.00	-49.69	-0.076
0.02	-49.71	-0.080
0.04	-49.72	-0.070
0.06	-49.72	-0.066
0.08	-49.71	-0.067
0.10	-49.68	-0.072
0.12	-49.65	-0.080
0.14	-49.60	-0.084
0.16	-49.54	-0.084
0.18	-49.48	-0.078
0.20	-49.40	-0.059
0.22	-49.33	-0.041
0.24	-49.25	-0.026
0.26	-49.16	-0.011
0.28	-49.08	0.003
0.30	-48.99	0.014
0.32	-48.90	0.023
0.34	-48.81	0.031
0.36	-48.72	0.038
0.38	-48.63	0.042
0.40	-48.54	0.047
0.42	-48.45	0.052
0.44	-48.35	0.054
0.46	-48.26	0.056
0.48	-48.17	0.059
0.50	-48.07	0.061
0.52	-47.98	0.062
0.54	-47.88	0.062
0.56	-47.78	0.064
0.58	-47.69	0.065
0.60	-47.59	0.065
0.62	-47.50	0.066
0.64	-47.40	0.067
0.66	-47.30	0.067
0.68	-47.20	0.068
0.70	-47.11	0.068
0.72	-47.01	0.069
0.74	-46.91	0.069
0.76	-46.82	0.070
0.78	-46.72	0.070
0.80	-46.62	0.070
0.82	-46.52	0.071
0.84	-46.42	0.071
0.86	-46.33	0.071
0.88	-46.23	0.072
0.90	-46.13	0.072
0.92	-46.03	0.073
0.94	-45.93	0.073
0.96	-45.83	0.073
0.98	-45.74	0.073
1.00	-45.64	0.073
1.02	-45.54	0.074
1.04	-45.44	0.074
1.06	-45.34	0.074
1.08	-45.24	0.074
1.10	-45.14	0.074
1.12	-45.04	0.074
1.14	-44.95	0.074
1.16	-44.85	0.075
1.18	-44.75	0.075
1.20	-44.65	0.075
1.22	-44.55	0.075
1.24	-44.45	0.075
1.26	-44.35	0.075
1.28	-44.25	0.075
1.30	-44.15	0.075
1.32	-44.05	0.075
1.34	-43.95	0.075
1.36	-43.85	0.075
1.38	-43.75	0.075
1.40	-43.66	0.075
1.42	-43.56	0.075
1.44	-43.46	0.075
1.46	-43.36	0.075
1.48	-43.26	0.075
1.50	-43.16	0.075
1.52	-43.06	0.075
1.54	-42.96	0.075
1.56	-42.86	0.075
1.58	-42.76	0.075
1.60	-42.66	0.075
1.62	-42.56	0.075
1.64	-42.46	0.075
1.66	-42.36	0.075
1.68	-42.26	0.075
1.70	-42.16	0.075
1.72	-42.06	0.075
1.74	-41.96	0.075
1.76	-41.86	0.075
1.78	-41.76	0.075
1.80	-41.66	0.075
1.82	-41.56	0.075
1.84	-41.46	0.075
1.86	-41.36	0.075
1.88	-41.26	0.075
1.90	-41.16	0.075
1.92	-41.06	0.075
1.94	-40.96	0.075
1.96	-40.86	0.075
1.98	-40.76	0.075
2.00	-40.66	0.075
2.02	-40.56	0.075
2.04	-40.46	0.074
2.06	-40.36	0.074
2.08	-40.26	0.074
2.10	-40.16	0.074
2.12	-40.06	0.074
2.14	-39.96	0.074
2.16	-39.86	0.074
2.18	-39.76	0.074
2.20	-39.66	0.074
2.22	-39.56	0.074
2.24	-39.46	0.074
2.26	-39.36	0.074
2.28	-39.26	0.074
2.30	-39.16	0.074
2.32	-39.06	0.074
2.34	-38.96	0.074
2.36	-38.86	0.074
2.38	-38.76	0.074
2.40	-38.66	0.074
2.42	-38.56	0.074
2.44	-38.46	0.074
2.46	-38.36	0.074
2.48	-38.26	0.074
2.50	-38.16	0.074
2.52	-38.06	0.074
2.54	-37.96	0.074
2.56	-37.86	0.074
2.58	-37.76	0.074
2.60	-37.66	0.074
2.62	-37.56	0.074
2.64	-37.46	0.074
2.66	-37.36	0.074
2.68	-37.26	0.074
2.70	-37.16	0.073
2.72	-37.06	0.073
2.74	-36.96	0.073
2.76	-36.86	0.073
2.78	-36.76	0.073
2.80	-36.66	0.073
2.82	-36.56	0.073
2.84	-36.46	0.073
2.86	-36.36	0.073
2.88	-36.26	0.073
2.90	-36.16	0.073
2.92	-36.06	0.073
2.94	-35.96	0.073
2.96	-35.86	0.073
2.98	-35.76	0.073
3.00	-35.66	0.073
3.02	-35.56	0.073
3.04	-35.46	0.073
3.06	-35.36	0.073
3.08	-35.26	0.073
3.10	-35.16	0.073
3.12	-35.06	0.073
3.14	-34.96	0.073
3.16	-34.86	0.073
3.18	-34.76	0.073
3.20	-34.66	0.072
3.22	-34.56	0.073
3.24	-34.46	0.072
3.26	-34.36	0.072
3.28	-34.26	0.072
3.30	-34.16	0.072
3.32	-34.06	0.072
3.34	-33.96	0.072
3.36	-33.86	0.072
3.38	-33.76	0.072
3.40	-33.66	0.072
3.42	-33.56	0.072
3.44	-33.46	0.072
3.46	-33.36	0.072
3.48	-33.26	0.072
3.50	-33.16	0.072
3.52	-33.06	0.072
3.54	-32.96	0.072
3.56	-32.85	0.072
3.58	-32.76	0.072
3.60	-32.66	0.072
3.62	-32.56	0.072
3.64	-32.45	0.072
3.66	-32.36	0.072
3.68	-32.25	0.072
3.70	-32.15	0.072
3.72	-32.06	0.072
3.74	-31.96	0.072
3.76	-31.86	0.072
3.78	-31.76	0.072
3.80	-31.66	0.072
3.82	-31.56	0.072
3.84	-31.45	0.072
3.86	-31.36	0.072
3.88	-31.25	0.072
3.90	-31.15	0.072
3.92	-31.05	0.072
3.94	-30.95	0.072
3.96	-30.85	0.072
3.98	-30.75	0.072
4.00	-30.65	0.072
4.02	-30.55	0.071
4.04	-30.46	0.072
4.06	-30.35	0.071
4.08	-30.25	0.071
4.10	-30.15	0.071
4.12	-30.05	0.071
4.14	-29.95	0.071
4.16	-29.85	0.071
4.18	-29.75	0.071
4.20	-29.65	0.071
4.22	-29.55	0.071
4.24	-29.45	0.071
4.26	-29.35	0.071
4.28	-29.25	0.071
4.30	-29.15	0.071
4.32	-29.05	0.071
4.34	-28.95	0.071
4.36	-28.85	0.071
4.38	-28.75	0.071
4.40	-28.65	0.071
4.42	-28.55	0.071
4.44	-28.45	0.071
4.46	-28.35	0.071
4.48	-28.25	0.071
4.50	-28.15	0.071
4.52	-28.05	0.071
4.54	-27.95	0.071
4.56	-27.85	0.071
4.58	-27.75	0.071
4.60	-27.65	0.071
4.62	-27.55	0.071
4.64	-27.45	0.071
4.66	-27.35	0.071
4.68	-27.25	0.071
4.70	-27.15	0.071
4.72	-27.05	0.071
4.74	-26.95	0.071
4.76	-26.85	0.071
4.78	-26.75	0.071
4.80	-26.65	0.071
4.82	-26.55	0.071
4.84	-26.45	0.071
4.86	-26.35	0.071
4.88	-26.25	0.071
4.90	-26.15	0.071
4.92	-26.05	0.071
4.94	-25.95	0.071
4.96	-25.85	0.071
4.98	-25.75	0.071
5.00	-25.65	0.071
5.02	-25.55	0.071
5.04	-25.45	0.071
5.06	-25.35	0.071
5.08	-25.25	0.071
5.10	-25.15	0.071
5.12	-25.05	0.071
5.14	-24.95	0.071
5.16	-24.85	0.071
5.18	-24.75	0.071
5.20	-24.65	0.071
5.22	-24.55	0.071
5.24	-24.45	0.071
5.26	-24.35	0.071
5.28	-24.25	0.071
5.30	-24.15	0.071
5.32	-24.05	0.071
5.34	-23.95	0.071
5.36	-23.85	0.071
5.38	-23.75	0.071
5.40	-23.65	0.071
5.42	-23.55	0.071
5.44	-23.45	0.071
5.46	-23.35	0.071
5.48	-23.25	0.071
5.50	-23.15	0.071
5.52	-23.05	0.071
5.54	-22.95	0.071
5.56	-22.85	0.071
5.58	-22.75	0.071
5.60	-22.65	0.071
5.62	-22.55	0.071
5.64	-22.45	0.071
5.66	-22.35	0.071
5.68	-22.25	0.071
5.70	-22.15	0.071
5.72	-22.04	0.071
5.74	-21.95	0.071
5.76	-21.85	0.071
5.78	-21.75	0.071
5.80	-21.65	0.071
5.82	-21.55	0.071
5.84	-21.45	0.071
5.86	-21.35	0.071
5.88	-21.25	0.071
5.90	-21.15	0.071
5.92	-21.05	0.071
5.94	-20.94	0.071
5.96	-20.85	0.071
5.98	-20.75	0.071
6.00	-20.64	0.071
6.02	-20.54	0.071
6.04	-20.45	0.071
6.06	-20.34	0.071
6.08	-20.25	0.071
6.10	-20.15	0.071
6.12	-20.04	0.071
6.14	-19.95	0.071
6.16	-19.84	0.071
6.18	-19.74	0.071
6.20	-19.65	0.071
6.22	-19.55	0.071
6.24	-19.45	0.071
6.26	-19.35	0.071
6.28	-19.24	0.071
6.30	-19.14	0.071
6.32	-19.04	0.071
6.34	-18.94	0.071
6.36	-18.84	0.071
6.38	-18.74	0.071
6.40	-18.64	0.072
6.42	-18.54	0.071
6.44	-18.44	0.072
6.46	-18.34	0.072
6.48	-18.24	0.072
6.50	-18.14	0.072
6.52	-18.04	0.072
6.54	-17.94	0.072
6.56	-17.84	0.072
6.58	-17.74	0.071
6.60	-17.64	0.072
6.62	-17.54	0.071
6.64	-17.44	0.072
6.66	-17.34	0.071
6.68	-17.24	0.071
6.70	-17.14	0.071
6.72	-17.04	0.072
6.74	-16.94	0.072
6.76	-16.84	0.072
6.78	-16.74	0.072
6.80	-16.64	0.072
6.82	-16.54	0.072
6.84	-16.44	0.072
6.86	-16.34	0.072
6.88	-16.24	0.072
6.90	-16.14	0.072
6.92	-16.04	0.072
6.94	-15.94	0.072
6.96	-15.84	0.072
6.98	-15.74	0.072
7.00	-15.64	0.072
7.02	-15.54	0.072
7.04	-15.44	0.072
7.06	-15.34	0.072
7.08	-15.24	0.072
7.10	-15.14	0.072
7.12	-15.04	0.072
7.14	-14.94	0.072
7.16	-14.84	0.072
7.18	-14.74	0.072
7.20	-14.64	0.072
7.22	-14.54	0.072
7.24	-14.44	0.072
7.26	-14.34	0.072
7.28	-14.24	0.072
7.30	-14.14	0.072
7.32	-14.04	0.072
7.34	-13.94	0.072
7.36	-13.84	0.072
7.38	-13.74	0.072
7.40	-13.64	0.072
7.42	-13.54	0.072
7.44	-13.44	0.072
7.46	-13.34	0.072
7.48	-13.24	0.072
7.50	-13.14	0.072
7.52	-13.04	0.072
7.54	-12.94	0.072
7.56	-12.84	0.072
7.58	-12.74	0.072
7.60	-12.64	0.072
7.62	-12.54	0.072
7.64	-12.44	0.072
7.66	-12.34	0.072
7.68	-12.24	0.072
7.70	-12.14	0.072
7.72	-12.04	0.072
7.74	-11.94	0.072
7.76	-11.84	0.072
7.78	-11.74	0.072
7.80	-11.64	0.072
7.82	-11.54	0.072
7.84	-11.44	0.072
7.86	-11.34	0.072
7.88	-11.24	0.073
7.90	-11.14	0.073
7.92	-11.04	0.073
7.94	-10.94	0.073
7.96	-10.84	0.073
7.98	-10.74	0.073
8.00	-10.64	0.073
8.02	-10.54	0.073
8.04	-10.44	0.073
8.06	-10.34	0.073
8.08	-10.24	0.073
8.10	-10.14	0.073
8.12	-10.04	0.073
8.14	-9.94	0.073
8.16	-9.84	0.073
8.18	-9.74	0.073
8.20	-9.64	0.073
8.22	-9.54	0.073
8.24	-9.44	0.073
8.26	-9.34	0.073
8.28	-9.24	0.073
8.30	-9.14	0.073
8.32	-9.04	0.073
8.34	-8.94	0.073
8.36	-8.84	0.073
8.38	-8.74	0.073
8.40	-8.64	0.073
8.42	-8.54	0.073
8.44	-8.44	0.073
8.46	-8.34	0.073
8.48	-8.24	0.073
8.50	-8.14	0.073
8.52	-8.04	0.073
8.54	-7.94	0.073
8.56	-7.84	0.073
8.58	-7.74	0.073
8.60	-7.64	0.073
8.62	-7.54	0.073
8.64	-7.44	0.073
8.66	-7.34	0.073
8.68	-7.24	0.073
8.70	-7.14	0.073
8.72	-7.04	0.073
8.74	-6.94	0.073
8.76	-6.84	0.073
8.78	-6.74	0.073
8.80	-6.64	0.073
8.82	-6.54	0.073
8.84	-6.44	0.073
8.86	-6.34	0.073
8.88	-6.24	0.073
8.90	-6.14	0.074
8.92	-6.04	0.074
8.94	-5.94	0.074
8.96	-5.83	0.074
8.98	-5.74	0.074
9.00	-5.64	0.074
9.02	-5.54	0.074
9.04	-5.44	0.074
9.06	-5.34	0.074
9.08	-5.23	0.074
9.10	-5.14	0.074
9.12	-5.03	0.074
9.14	-4.93	0.074
9.16	-4.83	0.074
9.18	-4.74	0.074
9.20	-4.63	0.074
9.22	-4.53	0.074
9.24	-4.43	0.074
9.26	-4.33	0.074
9.28	-4.24	0.074
9.30	-4.13	0.074
9.32	-4.03	0.074
9.34	-3.93	0.074
9.36	-3.83	0.074
9.38	-3.73	0.074
9.40	-3.63	0.074
9.42	-3.53	0.074
9.44	-3.43	0.074
9.46	-3.33	0.074
9.48	-3.23	0.074
9.50	-3.13	0.074
9.52	-3.03	0.074
9.54	-2.93	0.074
9.56	-2.83	0.074
9.58	-2.73	0.074
9.60	-2.63	0.074
9.62	-2.53	0.074
9.64	-2.43	0.074
9.66	-2.33	0.074
9.68	-2.23	0.074
9.70	-2.13	0.074
9.72	-2.03	0.074
9.74	-1.93	0.074
9.76	-1.83	0.074
9.78	-1.73	0.074
9.80	-1.63	0.074
9.82	-1.53	0.074
9.84	-1.43	0.074
9.86	-1.33	0.074
9.88	-1.23	0.074
9.90	-1.13	0.074
9.92	-1.03	0.074
9.94	-0.93	0.074
9.96	-0.83	0.074
9.98	-0.73	0.074
10.00	-0.63	0.074
10.02	-0.53	0.074
10.04	-0.43	0.074
10.06	-0.33	0.074
10.08	-0.23	0.074
10.10	-0.13	0.074
10.12	-0.03	0.074
10.14	0.07	0.074
10.16	0.17	0.074
10.18	0.27	0.074
10.20	0.37	0.074
10.22	0.47	0.074
10.24	0.57	0.074
10.26	0.67	0.074
10.28	0.77	0.074
10.30	0.87	0.074
10.32	0.97	0.074
10.34	1.07	0.074
10.36	1.17	0.074
10.38	1.27	0.074
10.40	1.37	0.074
10.42	1.47	0.074
10.44	1.57	0.074
10.46	1.67	0.074
10.48	1.77	0.074
10.50	1.87	0.074
10.52	1.97	0.074
10.54	2.07	0.074
10.56	2.17	0.074
10.58	2.27	0.074
10.60	2.37	0.075
10.62	2.47	0.075
10.64	2.57	0.075
10.66	2.67	0.075
10.68	2.77	0.074
10.70	2.87	0.075
10.72	2.97	0.075
10.74	3.07	0.075
10.76	3.17	0.075
10.78	3.27	0.075
10.80	3.37	0.075
10.82	3.47	0.075
10.84	3.57	0.075
10.86	3.67	0.075
10.88	3.77	0.075
10.90	3.87	0.075
10.92	3.97	0.075
10.94	4.07	0.075
10.96	4.17	0.075
10.98	4.27	0.075
11.00	4.37	0.075
11.02	4.47	0.075
11.04	4.57	0.075
11.06	4.67	0.075
11.08	4.77	0.075
11.10	4.87	0.075
11.12	4.97	0.075
11.14	5.07	0.075
11.16	5.17	0.075
11.18	5.27	0.075
11.20	5.37	0.075
11.22	5.47	0.075
11.24	5.57	0.075
11.26	5.67	0.075
11.28	5.77	0.075
11.30	5.87	0.075
11.32	5.97	0.075
11.34	6.07	0.075
11.36	6.17	0.075
11.38	6.27	0.075
11.40	6.37	0.075
11.42	6.47	0.075
11.44	6.57	0.075
11.46	6.67	0.075
11.48	6.77	0.075
11.50	6.87	0.075
11.52	6.97	0.075
11.54	7.07	0.075
11.56	7.18	0.075
11.58	7.27	0.075
11.60	7.37	0.075
11.62	7.47	0.075
11.64	7.58	0.075
11.66	7.67	0.076
11.68	7.77	0.076
11.70	7.87	0.076
11.72	7.97	0.076
11.74	8.07	0.076
11.76	8.17	0.076
11.78	8.27	0.076
11.80	8.38	0.076
11.82	8.47	0.076
11.84	8.57	0.076
11.86	8.67	0.076
11.88	8.78	0.076
11.90	8.88	0.076
11.92	8.98	0.076
11.94	9.08	0.076
11.96	9.17	0.076
11.98	9.28	0.076
12.00	9.38	0.076
12.02	9.48	0.076
12.04	9.58	0.076
12.06	9.68	0.076
12.08	9.78	0.076
12.10	9.88	0.076
12.12	9.98	0.076
12.14	10.08	0.076
12.16	10.17	0.076
12.18	10.28	0.076
12.20	10.38	0.076
12.22	10.48	0.076
12.24	10.58	0.076
12.26	10.68	0.076
12.28	10.78	0.076
12.30	10.88	0.076
12.32	10.98	0.076
12.34	11.08	0.076
12.36	11.18	0.076
12.38	11.28	0.076
12.40	11.38	0.076
12.42	11.48	0.076
12.44	11.58	0.076
12.46	11.68	0.076
12.48	11.78	0.076
12.50	11.88	0.076
12.52	11.98	0.076
12.54	12.08	0.076
12.56	12.18	0.076
12.58	12.28	0.076
12.60	12.38	0.076
12.62	12.48	0.076
12.64	12.58	0.076
12.66	12.68	0.077
12.68	12.78	0.077
12.70	12.88	0.077
12.72	12.98	0.077
12.74	13.08	0.077
12.76	13.18	0.077
12.78	13.28	0.077
12.80	13.38	0.077
12.82	13.48	0.077
12.84	13.58	0.077
12.86	13.68	0.077
12.88	13.78	0.077
12.90	13.88	0.077
12.92	13.98	0.077
12.94	14.08	0.077
12.96	14.18	0.077
12.98	14.28	0.077
13.00	14.38	0.077
13.02	14.48	0.077
13.04	14.58	0.077
13.06	14.68	0.077
13.08	14.78	0.077
13.10	14.88	0.077
13.12	14.98	0.077
13.14	15.08	0.077
13.16	15.18	0.077
13.18	15.28	0.077
13.20	15.38	0.077
13.22	15.48	0.077
13.24	15.58	0.077
13.26	15.68	0.077
13.28	15.78	0.077
13.30	15.88	0.077
13.32	15.98	0.077
13.34	16.08	0.077
13.36	16.18	0.077
13.38	16.28	0.077
13.40	16.38	0.077
13.42	16.48	0.077
13.44	16.58	0.077
13.46	16.68	0.077
13.48	16.78	0.077
13.50	16.88	0.077
13.52	16.98	0.077
13.54	17.08	0.077
13.56	17.18	0.078
13.58	17.28	0.077
13.60	17.38	0.078
13.62	17.48	0.078
13.64	17.58	0.078
13.66	17.68	0.078
13.68	17.78	0.078
13.70	17.88	0.078
13.72	17.98	0.078
13.74	18.08	0.078
13.76	18.18	0.078
13.78	18.28	0.078
13.80	18.38	0.078
13.82	18.48	0.078
13.84	18.58	0.078
13.86	18.68	0.078
13.88	18.78	0.078
13.90	18.88	0.078
13.92	18.98	0.078
13.94	19.08	0.078
13.96	19.18	0.078
13.98	19.28	0.078
14.00	19.38	0.078
14.02	19.48	0.078
14.04	19.58	0.078
14.06	19.68	0.078
14.08	19.78	0.078
14.10	19.88	0.078
14.12	19.98	0.078
14.14	20.08	0.078
14.16	20.18	0.078
14.18	20.28	0.078
14.20	20.38	0.078
14.22	20.48	0.078
14.24	20.58	0.078
14.26	20.68	0.078
14.28	20.78	0.078
14.30	20.88	0.079
14.32	20.98	0.079
14.34	21.08	0.079
14.36	21.18	0.079
14.38	21.28	0.079
14.40	21.38	0.079
14.42	21.48	0.079
14.44	21.58	0.079
14.46	21.68	0.079
14.48	21.78	0.079
14.50	21.88	0.079
14.52	21.98	0.079
14.54	22.08	0.079
14.56	22.18	0.079
14.58	22.28	0.079
14.60	22.38	0.079
14.62	22.48	0.079
14.64	22.58	0.079
14.66	22.68	0.079
14.68	22.78	0.079
14.70	22.88	0.079
14.72	22.98	0.079
14.74	23.08	0.079
14.76	23.18	0.079
14.78	23.28	0.079
14.80	23.38	0.079
14.82	23.48	0.079
14.84	23.58	0.079
14.86	23.68	0.079
14.88	23.78	0.079
14.90	23.88	0.079
14.92	23.99	0.079
14.94	24.08	0.079
14.96	24.18	0.079
14.98	24.28	0.079
15.00	24.38	0.079
15.02	24.48	0.079
15.04	24.59	0.080
15.06	24.68	0.080
15.08	24.79	0.080
15.10	24.88	0.080
15.12	24.98	0.080
15.14	25.09	0.080
15.16	25.19	0.080
15.18	25.29	0.080
15.20	25.39	0.080
15.22	25.49	0.080
15.24	25.59	0.080
15.26	25.68	0.080
15.28	25.79	0.080
15.30	25.89	0.080
15.32	25.99	0.080
15.34	26.09	0.080
15.36	26.19	0.080
15.38	26.29	0.080
15.40	26.39	0.080
15.42	26.49	0.080
15.44	26.59	0.080
15.46	26.69	0.080
15.48	26.79	0.080
15.50	26.89	0.080
15.52	26.99	0.080
15.54	27.09	0.081
15.56	27.19	0.081
15.58	27.29	0.081
15.60	27.39	0.081
15.62	27.49	0.081
15.64	27.59	0.081
15.66	27.69	0.081
15.68	27.79	0.081
15.70	27.89	0.081
15.72	27.99	0.081
15.74	28.09	0.081
15.76	28.19	0.081
15.78	28.29	0.081
15.80	28.39	0.081
15.82	28.49	0.081
15.84	28.59	0.081
15.86	28.69	0.081
15.88	28.79	0.081
15.90	28.89	0.081
15.92	28.99	0.081
15.94	29.09	0.081
15.96	29.19	0.081
15.98	29.29	0.081
16.00	29.39	0.081
16.02	29.49	0.081
16.04	29.59	0.081
16.06	29.69	0.081
16.08	29.79	0.081
16.10	29.89	0.081
16.12	29.99	0.081
16.14	30.09	0.081
16.16	30.19	0.081
16.18	30.29	0.081
16.20	30.39	0.081
16.22	30.49	0.081
16.24	30.59	0.081
16.26	30.69	0.082
16.28	30.79	0.082
16.30	30.89	0.082
16.32	30.99	0.082
16.34	31.09	0.082
16.36	31.19	0.082
16.38	31.29	0.082
16.40	31.39	0.082
16.42	31.49	0.082
16.44	31.59	0.082
16.46	31.69	0.082
16.48	31.79	0.082
16.50	31.89	0.082
16.52	31.99	0.082
16.54	32.09	0.082
16.56	32.19	0.082
16.58	32.29	0.082
16.60	32.39	0.082
16.62	32.49	0.082
16.64	32.59	0.082
16.66	32.69	0.083
16.68	32.79	0.083
16.70	32.89	0.083
16.72	32.99	0.083
16.74	33.09	0.083
16.76	33.19	0.083
16.78	33.29	0.083
16.80	33.39	0.083
16.82	33.49	0.083
16.84	33.59	0.083
16.86	33.69	0.083
16.88	33.79	0.083
16.90	33.89	0.083
16.92	33.99	0.083
16.94	34.09	0.083
16.96	34.19	0.083
16.98	34.29	0.083
17.00	34.39	0.084
17.02	34.49	0.084
17.04	34.59	0.084
17.06	34.69	0.084
17.08	34.79	0.084
17.10	34.89	0.084
17.12	34.99	0.084
17.14	35.09	0.084
17.16	35.19	0.084
17.18	35.29	0.084
17.20	35.39	0.084
17.22	35.49	0.084
17.24	35.59	0.084
17.26	35.69	0.084
17.28	35.79	0.084
17.30	35.89	0.084
17.32	35.99	0.084
17.34	36.09	0.084
17.36	36.19	0.085
17.38	36.29	0.085
17.40	36.39	0.085
17.42	36.49	0.085
17.44	36.59	0.085
17.46	36.69	0.085
17.48	36.79	0.085
17.50	36.89	0.085
17.52	36.99	0.085
17.54	37.09	0.085
17.56	37.19	0.085
17.58	37.29	0.085
17.60	37.39	0.085
17.62	37.49	0.085
17.64	37.59	0.086
17.66	37.69	0.086
17.68	37.80	0.086
17.70	37.89	0.086
17.72	37.99	0.086
17.74	38.09	0.086
17.76	38.19	0.086
17.78	38.29	0.086
17.80	38.39	0.086
17.82	38.49	0.086
17.84	38.59	0.086
17.86	38.69	0.086
17.88	38.79	0.086
17.90	38.89	0.087
17.92	38.99	0.087
17.94	39.09	0.087
17.96	39.19	0.087
17.98	39.29	0.087
18.00	39.39	0.087
18.02	39.49	0.087
18.04	39.59	0.087
18.06	39.69	0.087
18.08	39.79	0.087
18.10	39.89	0.087
18.12	39.99	0.087
18.14	40.09	0.087
18.16	40.19	0.088
18.18	40.29	0.088
18.20	40.39	0.088
18.22	40.49	0.088
18.24	40.59	0.088
18.26	40.69	0.088
18.28	40.79	0.088
18.30	40.89	0.088
18.32	40.99	0.088
18.34	41.09	0.088
18.36	41.19	0.088
18.38	41.29	0.089
18.40	41.39	0.089
18.42	41.49	0.089
18.44	41.59	0.089
18.46	41.69	0.089
18.48	41.80	0.089
18.50	41.90	0.089
18.52	41.99	0.089
18.54	42.09	0.089
18.56	42.19	0.089
18.58	42.30	0.089
18.60	42.40	0.090
18.62	42.50	0.090
18.64	42.59	0.090
18.66	42.70	0.090
18.68	42.79	0.090
18.70	42.90	0.090
18.72	42.99	0.090
18.74	43.10	0.090
18.76	43.19	0.090
18.78	43.29	0.090
18.80	43.40	0.091
18.82	43.49	0.091
18.84	43.60	0.091
18.86	43.70	0.091
18.88	43.80	0.091
18.90	43.90	0.091
18.92	43.99	0.091
18.94	44.09	0.091
18.96	44.20	0.091
18.98	44.30	0.091
19.00	44.39	0.092
19.02	44.49	0.092
19.04	44.60	0.092
19.06	44.70	0.092
19.08	44.80	0.092
19.10	44.90	0.092
19.12	45.00	0.092
19.14	45.10	0.092
19.16	45.20	0.093
19.18	45.30	0.093
19.20	45.40	0.093
19.22	45.50	0.093
19.24	45.60	0.093
19.26	45.70	0.093
19.28	45.80	0.093
19.30	45.90	0.094
19.32	46.00	0.094
19.34	46.10	0.094
19.36	46.20	0.094
19.38	46.30	0.094
19.40	46.40	0.094
19.42	46.50	0.094
19.44	46.60	0.094
19.46	46.70	0.095
19.48	46.80	0.095
19.50	46.90	0.095
19.52	47.00	0.095
19.54	47.10	0.095
19.56	47.20	0.095
19.58	47.30	0.096
19.60	47.40	0.096
19.62	47.50	0.096
19.64	47.60	0.096
19.66	47.70	0.096
19.68	47.80	0.096
19.70	47.90	0.097
19.72	48.00	0.097
19.74	48.10	0.097
19.76	48.20	0.097
19.78	48.30	0.097
19.80	48.40	0.098
19.82	48.50	0.098
19.84	48.60	0.098
19.86	48.70	0.098
19.88	48.80	0.098
19.90	48.90	0.098
19.92	49.00	0.099
19.94	49.10	0.099
19.96	49.20	0.099
19.98	49.30	0.099
20.00	49.40	0.099
20.02	49.50	0.100
20.04	49.60	0.100
20.06	49.70	0.100
20.08	49.80	0.101
20.10	49.90	0.101
20.12	50.00	0.101
20.14	50.10	0.101
20.16	50.20	0.102
20.18	50.30	0.102
20.20	50.40	0.102
20.22	50.50	0.102
20.24	50.60	0.102
20.26	50.69	0.103
20.28	50.80	0.103
20.30	50.90	0.103
20.32	51.00	0.104
20.34	51.10	0.104
20.36	51.20	0.104
20.38	51.30	0.105
20.40	51.40	0.105
20.42	51.50	0.105
20.44	51.60	0.105
20.46	51.70	0.106
20.48	51.80	0.106
20.50	51.89	0.106
20.52	52.00	0.107
20.54	52.10	0.107
20.56	52.19	0.108
20.58	52.30	0.108
20.60	52.39	0.108
20.62	52.50	0.109
20.64	52.60	0.109
20.66	52.70	0.109
20.68	52.80	0.110
20.70	52.90	0.110
20.72	52.99	0.111
20.74	53.10	0.111
20.76	53.19	0.112
20.78	53.29	0.112
20.80	53.39	0.113
20.82	53.49	0.113
20.84	53.59	0.113
20.86	53.69	0.114
20.88	53.79	0.114
20.90	53.89	0.115
20.92	53.99	0.115
20.94	54.09	0.116
20.96	54.19	0.117
20.98	54.29	0.117
21.00	54.39	0.118
21.02	54.49	0.118
21.04	54.59	0.119
21.06	54.69	0.120
21.08	54.79	0.120
21.10	54.89	0.121
21.12	54.99	0.122
21.14	55.09	0.122
21.16	55.19	0.123
21.18	55.29	0.124
21.20	55.39	0.124
21.22	55.49	0.125
21.24	55.59	0.126
21.26	55.69	0.127
21.28	55.79	0.127
21.30	55.89	0.128
21.32	55.99	0.129
21.34	56.09	0.130
21.36	56.19	0.131
21.38	56.29	0.132
21.40	56.39	0.133
21.42	56.49	0.134
21.44	56.59	0.135
21.46	56.69	0.136
21.48	56.79	0.137
21.50	56.89	0.138
21.52	56.99	0.139
21.54	57.09	0.141
21.56	57.19	0.142
21.58	57.29	0.143
21.60	57.39	0.144
21.62	57.49	0.146
21.64	57.59	0.147
21.66	57.69	0.149
21.68	57.79	0.150
21.70	57.89	0.151
21.72	57.99	0.152
21.74	58.09	0.154
21.76	58.19	0.156
21.78	58.29	0.158
21.80	58.39	0.159
21.82	58.48	0.162
21.84	58.58	0.163
21.86	58.68	0.164
21.88	58.78	0.166
21.90	58.88	0.168
21.92	58.98	0.170
21.94	59.08	0.173
21.96	59.18	0.175
21.98	59.28	0.177
22.00	59.38	0.179
22.02	59.48	0.181
22.04	59.58	0.184
22.06	59.68	0.185
22.08	59.78	0.187
22.10	59.88	0.190
22.12	59.98	0.193
22.14	60.08	0.195
22.16	60.18	0.196
22.18	60.27	0.199
22.20	60.38	0.202
22.22	60.47	0.204
22.24	60.57	0.205
22.26	60.67	0.208
22.28	60.77	0.211
22.30	60.87	0.212
22.32	60.97	0.214
22.34	61.07	0.216
22.36	61.17	0.219
22.38	61.27	0.220
22.40	61.37	0.222
22.42	61.47	0.223
22.44	61.57	0.224
22.46	61.67	0.226
22.48	61.77	0.226
22.50	61.87	0.227
22.52	61.97	0.228
22.54	62.07	0.228
22.56	62.17	0.229
22.58	62.27	0.229
22.60	62.37	0.229
22.62	62.47	0.229
22.64	62.57	0.228
22.66	62.67	0.227
22.68	62.77	0.224
22.70	62.87	0.219
22.72	62.97	0.214
22.74	63.07	0.206
22.76	63.17	0.200
22.78	63.28	0.192
22.80	63.38	0.185
22.82	63.48	0.178
22.84	63.58	0.172
22.86	63.68	0.165
22.88	63.78	0.159
22.90	63.89	0.153
22.92	63.99	0.148
22.94	64.09	0.143
22.96	64.19	0.141
22.98	64.29	0.139
23.00	64.39	0.139
23.02	64.50	0.138
23.04	64.59	0.137
23.06	64.70	0.137
23.08	64.80	0.137
23.10	64.90	0.137
23.12	65.00	0.137
23.14	65.10	0.138
23.16	65.19	0.140
23.18	65.29	0.142
23.20	65.39	0.143
23.22	65.49	0.146
23.24	65.59	0.147
23.26	65.69	0.147
23.28	65.79	0.147
23.30	65.89	0.146
23.32	65.99	0.142
23.34	66.10	0.135
23.36	66.20	0.130
23.38	66.30	0.126
23.40	66.40	0.124
23.42	66.50	0.120
23.44	66.60	0.118
23.46	66.70	0.117
23.48	66.80	0.115
23.50	66.90	0.113
23.52	67.00	0.111
23.54	67.10	0.110
23.56	67.20	0.109
23.58	67.30	0.108
23.60	67.41	0.107
23.62	67.51	0.107
23.64	67.61	0.106
23.66	67.71	0.105
23.68	67.81	0.105
23.70	67.91	0.104
23.72	68.01	0.104
23.74	68.11	0.104
23.76	68.21	0.103
23.78	68.31	0.103
23.80	68.41	0.102
23.82	68.51	0.102
23.84	68.61	0.102
23.86	68.71	0.101
23.88	68.81	0.101
23.90	68.91	0.101
23.92	69.01	0.101
23.94	69.11	0.100
23.96	69.21	0.100
23.98	69.31	0.100
24.00	69.41	0.100
24.02	69.51	0.100
24.04	69.61	0.099
24.06	69.71	0.099
24.08	69.81	0.099
24.10	69.91	0.099
24.12	70.01	0.099
24.14	70.11	0.099
24.16	70.21	0.099
24.18	70.31	0.099
24.20	70.41	0.099
24.22	70.51	0.099
24.24	70.61	0.099
24.26	70.71	0.098
24.28	70.81	0.098
24.30	70.91	0.098
24.32	71.01	0.098
24.34	71.11	0.098
24.36	71.21	0.098
24.38	71.31	0.098
24.40	71.41	0.098
24.42	71.51	0.098
24.44	71.61	0.098
24.46	71.71	0.098
24.48	71.81	0.098
24.50	71.91	0.098
24.52	72.01	0.098
24.54	72.11	0.098
24.56	72.21	0.098
24.58	72.31	0.098
24.60	72.41	0.098
24.62	72.51	0.098
24.64	72.61	0.098
24.66	72.71	0.098
24.68	72.81	0.098
24.70	72.91	0.098
24.72	73.01	0.098
24.74	73.11	0.099
24.76	73.21	0.099
24.78	73.31	0.099
24.80	73.41	0.099
24.82	73.51	0.099
24.84	73.61	0.099
24.86	73.71	0.099
24.88	73.81	0.099
24.90	73.91	0.099
24.92	74.01	0.099
24.94	74.11	0.099
24.96	74.21	0.099
24.98	74.31	0.099
25.00	74.41	0.099
25.02	74.51	0.099
25.04	74.61	0.099
25.06	74.71	0.099
25.08	74.81	0.099
25.10	74.91	0.099
25.12	75.01	0.099
25.14	75.11	0.099
25.16	75.21	0.099
25.18	75.31	0.099
25.20	75.41	0.099
25.22	75.51	0.099
25.24	75.61	0.099
25.26	75.71	0.099
25.28	75.81	0.099
25.30	75.91	0.099
25.32	76.01	0.099
25.34	76.11	0.099
25.36	76.21	0.099
25.38	76.31	0.099
25.40	76.41	0.099
25.42	76.51	0.099
25.44	76.61	0.099
25.46	76.71	0.099
25.48	76.81	0.099
25.50	76.91	0.099
25.52	77.01	0.099
25.54	77.11	0.099
25.56	77.21	0.099
25.58	77.31	0.100
25.60	77.41	0.100
25.62	77.51	0.100
25.64	77.61	0.100
25.66	77.71	0.100
25.68	77.81	0.100
25.70	77.91	0.100
25.72	78.01	0.100
25.74	78.11	0.100
25.76	78.21	0.100
25.78	78.31	0.100
25.80	78.41	0.100
25.82	78.51	0.100
25.84	78.62	0.100
25.86	78.71	0.100
25.88	78.82	0.100
25.90	78.91	0.100
25.92	79.01	0.100
25.94	79.12	0.100
25.96	79.22	0.100
25.98	79.31	0.100
26.00	79.41	0.100
26.02	79.52	0.100
26.04	79.62	0.100
26.06	79.72	0.100
26.08	79.82	0.100
26.10	79.92	0.100
26.12	80.01	0.100
26.14	80.12	0.100
26.16	80.21	0.100
26.18	80.32	0.100
26.20	80.41	0.100
26.22	80.51	0.100
26.24	80.62	0.100
26.26	80.71	0.100
26.28	80.82	0.100
26.30	80.91	0.100
26.32	81.01	0.100
26.34	81.12	0.100
26.36	81.22	0.100
26.38	81.32	0.100
26.40	81.42	0.100
26.42	81.52	0.100
26.44	81.62	0.100
26.46	81.72	0.100
26.48	81.82	0.100
26.50	81.92	0.100
26.52	82.02	0.100
26.54	82.12	0.101
26.56	82.22	0.100
26.58	82.32	0.101
26.60	82.42	0.101
26.62	82.52	0.101
26.64	82.62	0.101
26.66	82.72	0.101
26.68	82.82	0.101
26.70	82.92	0.101
26.72	83.02	0.101
26.74	83.12	0.101
26.76	83.22	0.101
26.78	83.32	0.101
26.80	83.42	0.101
26.82	83.52	0.101
26.84	83.62	0.101
26.86	83.72	0.101
26.88	83.82	0.101
26.90	83.92	0.101
26.92	84.02	0.101
26.94	84.12	0.101
26.96	84.22	0.101
26.98	84.32	0.101
27.00	84.42	0.101
27.02	84.52	0.101
27.04	84.62	0.101
27.06	84.72	0.101
27.08	84.82	0.101
27.10	84.92	0.101
27.12	85.02	0.101
27.14	85.12	0.101
27.16	85.22	0.101
27.18	85.32	0.101
27.20	85.42	0.101
27.22	85.52	0.101
27.24	85.62	0.101
27.26	85.72	0.101
27.28	85.82	0.101
27.30	85.92	0.101
27.32	86.02	0.101
27.34	86.12	0.101
27.36	86.22	0.101
27.38	86.32	0.101
27.40	86.42	0.101
27.42	86.52	0.101
27.44	86.62	0.101
27.46	86.72	0.101
27.48	86.82	0.101
27.50	86.92	0.101
27.52	87.02	0.101
27.54	87.12	0.101
27.56	87.22	0.101
27.58	87.32	0.101
27.60	87.42	0.101
27.62	87.52	0.101
27.64	87.62	0.101
27.66	87.72	0.101
27.68	87.82	0.101
27.70	87.92	0.101
27.72	88.02	0.101
27.74	88.12	0.101
27.76	88.22	0.101
27.78	88.32	0.101
27.80	88.42	0.101
27.82	88.52	0.101
27.84	88.62	0.101
27.86	88.72	0.101
27.88	88.82	0.101
27.90	88.92	0.101
27.92	89.02	0.101
27.94	89.12	0.101
27.96	89.22	0.101
27.98	89.32	0.102
28.00	89.42	0.102
28.02	89.52	0.102
28.04	89.62	0.102
28.06	89.72	0.102
28.08	89.82	0.102
28.10	89.92	0.102
28.12	90.02	0.102
28.14	90.12	0.102
28.16	90.22	0.102
28.18	90.32	0.102
28.20	90.42	0.102
28.22	90.52	0.102
28.24	90.62	0.102
28.26	90.72	0.102
28.28	90.82	0.102
28.30	90.92	0.102
28.32	91.02	0.102
28.34	91.12	0.102
28.36	91.22	0.102
28.38	91.32	0.102
28.40	91.42	0.102
28.42	91.52	0.102
28.44	91.62	0.102
28.46	91.72	0.102
28.48	91.82	0.102
28.50	91.92	0.102
28.52	92.02	0.102
28.54	92.12	0.102
28.56	92.22	0.102
28.58	92.32	0.102
28.60	92.42	0.102
28.62	92.52	0.102
28.64	92.62	0.102
28.66	92.72	0.102
28.68	92.82	0.102
28.70	92.92	0.102
28.72	93.02	0.102
28.74	93.12	0.102
28.76	93.22	0.102
28.78	93.32	0.102
28.80	93.42	0.102
28.82	93.52	0.102
28.84	93.62	0.102
28.86	93.72	0.102
28.88	93.82	0.102
28.90	93.92	0.102
28.92	94.02	0.102
28.94	94.12	0.102
28.96	94.22	0.102
28.98	94.32	0.102
29.00	94.42	0.102
29.02	94.52	0.102
29.04	94.62	0.102
29.06	94.72	0.102
29.08	94.82	0.102
29.10	94.92	0.103
29.12	95.02	0.103
29.14	95.12	0.103
29.16	95.22	0.103
29.18	95.32	0.103
29.20	95.42	0.103
29.22	95.52	0.103
29.24	95.62	0.102
29.26	95.72	0.103
29.28	95.82	0.102
29.30	95.92	0.102
29.32	96.02	0.102
29.34	96.12	0.102
29.36	96.22	0.102
29.38	96.32	0.102
29.40	96.42	0.102
29.42	96.52	0.102
29.44	96.62	0.102
29.46	96.72	0.102
29.48	96.82	0.102
29.50	96.92	0.102
29.52	97.02	0.102
29.54	97.12	0.102
29.56	97.22	0.102
29.58	97.32	0.102
29.60	97.42	0.102
29.62	97.52	0.102
29.64	97.62	0.102
29.66	97.72	0.102
29.68	97.82	0.102
29.70	97.92	0.102
29.72	98.02	0.102
29.74	98.12	0.102
29.76	98.22	0.102
29.78	98.32	0.102
29.80	98.42	0.102
29.82	98.52	0.102
29.84	98.62	0.102
29.86	98.72	0.102
29.88	98.82	0.102
29.90	98.92	0.102
29.92	99.02	0.102
29.94	99.12
29.96	99.22
29.98	99.32
29.99

[step]
Ramp 5.00 °C/min to -50.00 °C
Time	Temperature	Heat Flow (Normalized)
min	°C	W/g
30.99	100.11	-0.050
31.01	100.11	-0.050
31.03	100.11	-0.051
31.05	100.10	-0.042
31.07	100.08	-0.015
31.09	100.05	0.002
31.11	100.00	0.005
31.13	99.94	-0.003
31.15	99.87	-0.035
31.17	99.80	-0.062
31.19	99.72	-0.085
31.21	99.64	-0.105
31.23	99.56	-0.121
31.25	99.47	-0.134
31.27	99.38	-0.144
31.29	99.29	-0.155
31.31	99.20	-0.163
31.33	99.11	-0.169
31.35	99.02	-0.173
31.37	98.92	-0.179
31.39	98.83	-0.182
31.41	98.73	-0.185
31.43	98.64	-0.187
31.45	98.54	-0.189
31.47	98.44	-0.191
31.49	98.35	-0.193
31.51	98.25	-0.195
31.53	98.15	-0.195
31.55	98.05	-0.196
31.57	97.95	-0.196
31.59	97.86	-0.197
31.61	97.76	-0.197
31.63	97.66	-0.197
31.65	97.56	-0.198
31.67	97.46	-0.198
31.69	97.36	-0.198
31.71	97.26	-0.199
31.73	97.17	-0.199
31.75	97.07	-0.199
31.77	96.97	-0.200
31.79	96.87	-0.200
31.81	96.77	-0.201
31.83	96.67	-0.201
31.85	96.57	-0.201
31.87	96.47	-0.201
31.89	96.37	-0.201
31.91	96.27	-0.201
31.93	96.17	-0.201
31.95	96.07	-0.202
31.97	95.98	-0.202
31.99	95.88	-0.202
32.01	95.78	-0.202
32.03	95.68	-0.202
32.05	95.58	-0.202
32.07	95.48	-0.202
32.09	95.38	-0.202
32.11	95.28	-0.202
32.13	95.18	-0.202
32.15	95.08	-0.202
32.17	94.98	-0.202
32.19	94.88	-0.202
32.21	94.78	-0.202
32.23	94.68	-0.203
32.25	94.58	-0.203
32.27	94.48	-0.203
32.29	94.38	-0.202
32.31	94.28	-0.202
32.33	94.18	-0.202
32.35	94.08	-0.202
32.37	93.98	-0.202
32.39	93.88	-0.202
32.41	93.78	-0.202
32.43	93.68	-0.202
32.45	93.58	-0.202
32.47	93.48	-0.202
32.49	93.38	-0.202
32.51	93.28	-0.202
32.53	93.18	-0.202
32.55	93.08	-0.201
32.57	92.98	-0.201
32.59	92.88	-0.201
32.61	92.78	-0.201
32.63	92.68	-0.201
32.65	92.58	-0.201
32.67	92.48	-0.201
32.69	92.38	-0.201
32.71	92.28	-0.200
32.73	92.18	-0.200
32.75	92.08	-0.200
32.77	91.98	-0.200
32.79	91.88	-0.200
32.81	91.78	-0.200
32.83	91.68	-0.200
32.85	91.58	-0.200
32.87	91.48	-0.200
32.89	91.39	-0.200
32.91	91.29	-0.199
32.93	91.18	-0.199
32.95	91.09	-0.199
32.97	90.99	-0.199
32.99	90.89	-0.199
33.01	90.79	-0.199
33.03	90.68	-0.199
33.05	90.59	-0.198
33.07	90.49	-0.198
33.09	90.39	-0.198
33.11	90.29	-0.198
33.13	90.18	-0.198
33.15	90.09	-0.198
33.17	89.99	-0.198
33.19	89.89	-0.198
33.21	89.79	-0.198
33.23	89.69	-0.198
33.25	89.59	-0.198
33.27	89.49	-0.197
33.29	89.39	-0.197
33.31	89.29	-0.197
33.33	89.19	-0.197
33.35	89.09	-0.197
33.37	88.99	-0.197
33.39	88.89	-0.197
33.41	88.79	-0.196
33.43	88.69	-0.196
33.45	88.59	-0.196
33.47	88.49	-0.196
33.49	88.39	-0.196
33.51	88.29	-0.196
33.53	88.19	-0.196
33.55	88.09	-0.195
33.57	87.99	-0.195
33.59	87.89	-0.195
33.61	87.79	-0.195
33.63	87.69	-0.195
33.65	87.59	-0.195
33.67	87.49	-0.195
33.69	87.39	-0.195
33.71	87.29	-0.195
33.73	87.19	-0.194
33.75	87.09	-0.194
33.77	86.99	-0.194
33.79	86.89	-0.194
33.81	86.79	-0.194
33.83	86.69	-0.194
33.85	86.59	-0.194
33.87	86.49	-0.194
33.89	86.39	-0.194
33.91	86.29	-0.193
33.93	86.19	-0.193
33.95	86.09	-0.193
33.97	85.99	-0.193
33.99	85.89	-0.193
34.01	85.79	-0.193
34.03	85.69	-0.193
34.05	85.59	-0.193
34.07	85.49	-0.193
34.09	85.39	-0.193
34.11	85.29	-0.193
34.13	85.19	-0.193
34.15	85.09	-0.193
34.17	84.99	-0.192
34.19	84.89	-0.192
34.21	84.79	-0.192
34.23	84.69	-0.192
34.25	84.59	-0.192
34.27	84.49	-0.192
34.29	84.39	-0.192
34.31	84.29	-0.192
34.33	84.19	-0.192
34.35	84.09	-0.192
34.37	83.99	-0.192
34.39	83.89	-0.191
34.41	83.79	-0.191
34.43	83.69	-0.191
34.45	83.59	-0.191
34.47	83.49	-0.191
34.49	83.39	-0.191
34.51	83.29	-0.191
34.53	83.19	-0.191
34.55	83.09	-0.191
34.57	82.99	-0.191
34.59	82.89	-0.191
34.61	82.79	-0.190
34.63	82.69	-0.190
34.65	82.59	-0.190
34.67	82.49	-0.190
34.69	82.39	-0.190
34.71	82.29	-0.190
34.73	82.19	-0.190
34.75	82.09	-0.190
34.77	81.99	-0.190
34.79	81.89	-0.190
34.81	81.79	-0.190
34.83	81.69	-0.190
34.85	81.59	-0.190
34.87	81.49	-0.190
34.89	81.39	-0.190
34.91	81.29	-0.190
34.93	81.19	-0.189
34.95	81.09	-0.189
34.97	80.99	-0.189
34.99	80.89	-0.189
35.01	80.79	-0.189
35.03	80.69	-0.189
35.05	80.59	-0.189
35.07	80.49	-0.189
35.09	80.39	-0.189
35.11	80.29	-0.189
35.13	80.19	-0.189
35.15	80.09	-0.189
35.17	79.99	-0.188
35.19	79.89	-0.189
35.21	79.79	-0.188
35.23	79.69	-0.188
35.25	79.59	-0.188
35.27	79.49	-0.188
35.29	79.39	-0.188
35.31	79.29	-0.188
35.33	79.19	-0.188
35.35	79.09	-0.188
35.37	78.99	-0.188
35.39	78.89	-0.188
35.41	78.79	-0.188
35.43	78.69	-0.188
35.45	78.59	-0.188
35.47	78.49	-0.188
35.49	78.39	-0.188
35.51	78.29	-0.188
35.53	78.19	-0.188
35.55	78.09	-0.187
35.57	77.99	-0.187
35.59	77.89	-0.187
35.61	77.79	-0.187
35.63	77.69	-0.187
35.65	77.59	-0.187
35.67	77.49	-0.187
35.69	77.39	-0.187
35.71	77.29	-0.187
35.73	77.19	-0.187
35.75	77.09	-0.187
35.77	76.99	-0.187
35.79	76.89	-0.187
35.81	76.79	-0.186
35.83	76.69	-0.186
35.85	76.59	-0.186
35.87	76.49	-0.186
35.89	76.39	-0.186
35.91	76.29	-0.186
35.93	76.19	-0.186
35.95	76.09	-0.186
35.97	75.99	-0.186
35.99	75.89	-0.186
36.01	75.79	-0.186
36.03	75.69	-0.186
36.05	75.59	-0.186
36.07	75.49	-0.186
36.09	75.39	-0.186
36.11	75.29	-0.186
36.13	75.19	-0.185
36.15	75.09	-0.185
36.17	74.99	-0.185
36.19	74.89	-0.185
36.21	74.79	-0.185
36.23	74.69	-0.185
36.25	74.59	-0.185
36.27	74.49	-0.185
36.29	74.39	-0.184
36.31	74.30	-0.184
36.33	74.19	-0.184
36.35	74.09	-0.184
36.37	73.99	-0.184
36.39	73.89	-0.184
36.41	73.79	-0.184
36.43	73.70	-0.184
36.45	73.59	-0.184
36.47	73.49	-0.184
36.49	73.39	-0.184
36.51	73.29	-0.184
36.53	73.19	-0.184
36.55	73.09	-0.184
36.57	72.99	-0.184
36.59	72.90	-0.184
36.61	72.80	-0.184
36.63	72.69	-0.183
36.65	72.60	-0.183
36.67	72.49	-0.183
36.69	72.39	-0.183
36.71	72.30	-0.183
36.73	72.20	-0.183
36.75	72.09	-0.183
36.77	71.99	-0.183
36.79	71.89	-0.183
36.81	71.79	-0.183
36.83	71.69	-0.183
36.85	71.59	-0.183
36.87	71.49	-0.183
36.89	71.40	-0.183
36.91	71.30	-0.183
36.93	71.19	-0.182
36.95	71.10	-0.182
36.97	70.99	-0.182
36.99	70.89	-0.182
37.01	70.80	-0.182
37.03	70.70	-0.182
37.05	70.59	-0.182
37.07	70.50	-0.182
37.09	70.40	-0.182
37.11	70.30	-0.182
37.13	70.19	-0.182
37.15	70.10	-0.182
37.17	70.00	-0.182
37.19	69.89	-0.182
37.21	69.79	-0.182
37.23	69.70	-0.182
37.25	69.60	-0.181
37.27	69.50	-0.181
[...]
227.16	15.12	0.125
227.19	15.27	0.125
227.22	15.42	0.125
227.25	15.57	0.125
227.28	15.72	0.125
227.31	15.87	0.125
227.34	16.02	0.125
227.37	16.17	0.125
227.40	16.32	0.125
227.43	16.47	0.125
227.46	16.62	0.125
227.49	16.77	0.125
227.52	16.92	0.125
227.55	17.07	0.125
227.58	17.22	0.125
227.61	17.37	0.125
227.64	17.52	0.125
227.67	17.67	0.125
227.70	17.82	0.125
227.73	17.97	0.125
227.76	18.12	0.125
227.79	18.27	0.125
227.82	18.42	0.125
227.85	18.57	0.125
227.88	18.72	0.125
227.91	18.87	0.125
227.94	19.02	0.125
227.97	19.17	0.125
228.00	19.32	0.125
228.03	19.47	0.125
228.06	19.62	0.125
228.09	19.77	0.125
228.12	19.92	0.125
228.15	20.07	0.125
228.18	20.22	0.125
228.21	20.37	0.125
228.24	20.52	0.125
228.27	20.67	0.125
228.30	20.82	0.125
228.33	20.97	0.125
228.36	21.12	0.126
228.39	21.27	0.126
228.42	21.42	0.126
228.45	21.57	0.126
228.48	21.72	0.126
228.51	21.87	0.126
228.54	22.02	0.126
228.57	22.17	0.126
228.60	22.32	0.126
228.63	22.47	0.126
228.66	22.62	0.126
228.69	22.78	0.126
228.72	22.93	0.126
228.75	23.07	0.126
228.78	23.23	0.126
228.81	23.38	0.126
228.84	23.52	0.126
228.87	23.68	0.126
228.90	23.82	0.126
228.93	23.97	0.126
228.96	24.12	0.126
228.99	24.28	0.126
229.02	24.42	0.126
229.05	24.58	0.126
229.08	24.73	0.126
229.11	24.87	0.126
229.14	25.03	0.127
229.17	25.18	0.127
229.20	25.33	0.127
229.23	25.48	0.127
229.26	25.63	0.127
229.29	25.78	0.127
229.32	25.93	0.127
229.35	26.08	0.127
229.38	26.23	0.127
229.41	26.38	0.127
229.44	26.53	0.127
229.47	26.68	0.127
229.50	26.83	0.127
229.53	26.98	0.127
229.56	27.13	0.127
229.59	27.28	0.127
229.62	27.43	0.127
229.65	27.58	0.128
229.68	27.73	0.128
229.71	27.88	0.128
229.74	28.03	0.128
229.77	28.18	0.128
229.80	28.33	0.128
229.83	28.48	0.128
229.86	28.63	0.128
229.89	28.78	0.128
229.92	28.93	0.128
229.95	29.08	0.128
229.98	29.23	0.128
230.01	29.38	0.128
230.04	29.53	0.128
230.07	29.68	0.128
230.10	29.83	0.128
230.13	29.98	0.128
230.16	30.13	0.128
230.19	30.28	0.128
230.22	30.43	0.128
230.25	30.58	0.128
230.28	30.73	0.129
230.31	30.88	0.129
230.34	31.03	0.129
230.37	31.18	0.129
230.40	31.33	0.129
230.43	31.48	0.129
230.46	31.63	0.129
230.49	31.78	0.129
230.52	31.93	0.129
230.55	32.08	0.129
230.58	32.23	0.129
230.61	32.38	0.129
230.64	32.53	0.129
230.67	32.68	0.129
230.70	32.83	0.129
230.73	32.98	0.129
230.76	33.13	0.129
230.79	33.28	0.129
230.82	33.43	0.129
230.85	33.58	0.129
230.88	33.73	0.129
230.91	33.88	0.129
230.94	34.03	0.129
230.97	34.18	0.129
231.00	34.33	0.130
231.03	34.48	0.130
231.06	34.63	0.130
231.09	34.78	0.130
231.12	34.93	0.130
231.15	35.08	0.130
231.18	35.23	0.130
231.21	35.38	0.130
231.24	35.53	0.130
231.27	35.68	0.130
231.30	35.83	0.130
231.33	35.98	0.130
231.36	36.13	0.130
231.39	36.28	0.130
231.42	36.43	0.130
231.45	36.58	0.130
231.48	36.73	0.130
231.51	36.88	0.130
231.54	37.03	0.130
231.57	37.18	0.130
231.60	37.33	0.130
231.63	37.48	0.130
231.66	37.63	0.130
231.69	37.79	0.130
231.72	37.94	0.130
231.75	38.09	0.130
231.78	38.23	0.131
231.81	38.39	0.131
231.84	38.54	0.131
231.87	38.69	0.131
231.90	38.84	0.131
231.93	38.99	0.131
231.96	39.14	0.131
231.99	39.29	0.131
232.02	39.44	0.131
232.05	39.59	0.131
232.08	39.74	0.131
232.11	39.89	0.131
232.14	40.04	0.131
232.17	40.19	0.131
232.20	40.34	0.131
232.23	40.49	0.131
232.26	40.64	0.131
232.29	40.79	0.131
232.32	40.94	0.131
232.35	41.09	0.131
232.38	41.24	0.131
232.41	41.39	0.131
232.44	41.54	0.131
232.47	41.69	0.131
232.50	41.84	0.131
232.53	41.99	0.131
232.56	42.14	0.131
232.59	42.29	0.131
232.62	42.44	0.131
232.65	42.59	0.131
232.68	42.74	0.131
232.71	42.89	0.131
232.74	43.04	0.132
232.77	43.19	0.132
232.80	43.34	0.132
232.83	43.49	0.132
232.86	43.64	0.132
232.89	43.79	0.132
232.92	43.94	0.132
232.95	44.09	0.132
232.98	44.24	0.132
233.01	44.39	0.132
233.04	44.54	0.132
233.07	44.69	0.132
233.10	44.84	0.132
233.13	44.99	0.132
233.16	45.14	0.132
233.19	45.29	0.132
233.22	45.44	0.132
233.25	45.59	0.132
233.28	45.74	0.132
233.31	45.89	0.132
233.34	46.04	0.132
233.37	46.19	0.132
233.40	46.34	0.132
233.43	46.49	0.132
233.46	46.64	0.132
233.49	46.79	0.132
233.52	46.94	0.132
233.55	47.09	0.132
233.58	47.24	0.132
233.61	47.39	0.132
233.64	47.54	0.132
233.67	47.69	0.132
233.70	47.84	0.132
233.73	47.99	0.132
233.76	48.14	0.132
233.79	48.29	0.132
233.82	48.44	0.132
233.85	48.59	0.132
233.88	48.74	0.132
233.91	48.89	0.132
233.94	49.04	0.132
233.97	49.19	0.132
234.00	49.34	0.132
234.03	49.49	0.132
234.06	49.64	0.133
234.09	49.79	0.132
234.12	49.94	0.132
234.15	50.09	0.132
234.18	50.24	0.132
234.21	50.39	0.132
234.24	50.54	0.132
234.27	50.69	0.132
234.30	50.84	0.132
234.33	50.99	0.132
234.36	51.14	0.132
234.39	51.29	0.132
234.42	51.44	0.132
234.45	51.59	0.132
234.48	51.74	0.132
234.51	51.89	0.132
234.54	52.04	0.132
234.57	52.19	0.132
234.60	52.35	0.132
234.63	52.50	0.132
234.66	52.65	0.132
234.69	52.80	0.133
234.72	52.95	0.132
234.75	53.09	0.132
234.78	53.25	0.132
234.81	53.40	0.132
234.84	53.55	0.132
234.87	53.70	0.132
234.90	53.85	0.132
234.93	54.00	0.132
234.96	54.15	0.132
234.99	54.30	0.132
235.02	54.45	0.132
235.05	54.60	0.132
235.08	54.75	0.132
235.11	54.90	0.132
235.14	55.05	0.132
235.17	55.20	0.132
235.20	55.35	0.132
235.23	55.50	0.132
235.26	55.65	0.132
235.29	55.80	0.132
235.32	55.95	0.132
235.35	56.10	0.132
235.38	56.25	0.132
235.41	56.40	0.132
235.44	56.55	0.132
235.47	56.70	0.132
235.50	56.85	0.132
235.53	57.00	0.132
235.56	57.15	0.132
235.59	57.30	0.132
235.62	57.45	0.132
235.65	57.60	0.132
235.68	57.75	0.132
235.71	57.90	0.132
235.74	58.05	0.132
235.77	58.20	0.132
235.80	58.35	0.132
235.83	58.50	0.132
235.86	58.65	0.132
235.89	58.80	0.131
235.92	58.95	0.131
235.95	59.10	0.131
235.98	59.25	0.131
236.01	59.40	0.131
236.04	59.55	0.131
236.07	59.70	0.131
236.10	59.85	0.131
236.13	60.00	0.131
236.16	60.15	0.131
236.19	60.30	0.130
236.22	60.45	0.130
236.25	60.60	0.130
236.28	60.75	0.130
236.31	60.90	0.130
236.34	61.05	0.130
236.37	61.20	0.130
236.40	61.35	0.130
236.43	61.50	0.130
236.46	61.65	0.130
236.49	61.80	0.130
236.52	61.95	0.129
236.55	62.10	0.129
236.58	62.25	0.129
236.61	62.40	0.129
236.64	62.55	0.129
236.67	62.70	0.129
236.70	62.85	0.129
236.73	63.00	0.129
236.76	63.15	0.129
236.79	63.30	0.128
236.82	63.45	0.128
236.85	63.60	0.128
236.88	63.75	0.128
236.91	63.90	0.128
236.94	64.05	0.128
236.97	64.20	0.128
237.00	64.35	0.128
237.03	64.50	0.128
237.06	64.65	0.127
237.09	64.80	0.127
237.12	64.95	0.127
237.15	65.10	0.127
237.18	65.25	0.127
237.21	65.40	0.127
237.24	65.56	0.127
237.27	65.71	0.126
237.30	65.86	0.126
237.33	66.01	0.126
237.36	66.16	0.126
237.39	66.31	0.126
237.42	66.46	0.126
237.45	66.61	0.125
237.48	66.76	0.125
237.51	66.91	0.125
237.54	67.06	0.125
237.57	67.21	0.124
237.60	67.36	0.124
237.63	67.51	0.124
237.66	67.66	0.124
237.69	67.81	0.124
237.72	67.96	0.123
237.75	68.11	0.123
237.78	68.26	0.123
237.81	68.41	0.123
237.84	68.56	0.122
237.87	68.71	0.122
237.90	68.86	0.122
237.93	69.01	0.122
237.96	69.16	0.121
237.99	69.31	0.121
238.02	69.46	0.121
238.05	69.61	0.121
238.08	69.76	0.120
238.11	69.91	0.120
238.14	70.06	0.120
238.17	70.21	0.119
238.20	70.36	0.119
238.23	70.51	0.119
238.26	70.66	0.118
238.29	70.81	0.118
238.32	70.96	0.117
238.35	71.11	0.117
238.38	71.26	0.117
238.41	71.41	0.116
238.44	71.56	0.116
238.47	71.71	0.115
238.50	71.86	0.115
238.53	72.01	0.115
238.56	72.16	0.114
238.59	72.31	0.114
238.62	72.46	0.113
238.65	72.61	0.113
238.68	72.76	0.112
238.71	72.91	0.112
238.74	73.06	0.111
238.77	73.21	0.110
238.80	73.37	0.110
238.83	73.52	0.109
238.86	73.67	0.109
238.89	73.82	0.108
238.92	73.97	0.107
238.95	74.12	0.107
238.98	74.27	0.106
239.01	74.42	0.105
239.04	74.57	0.105
239.07	74.72	0.104
239.10	74.87	0.103
239.13	75.02	0.102
239.16	75.17	0.102
239.19	75.32	0.101
239.22	75.47	0.100
239.25	75.62	0.099
239.28	75.77	0.098
239.31	75.92	0.098
239.34	76.07	0.097
239.37	76.22	0.096
239.40	76.37	0.095
239.43	76.52	0.094
239.46	76.67	0.093
239.49	76.82	0.092
239.52	76.97	0.091
239.55	77.12	0.089
239.58	77.27	0.088
239.61	77.42	0.087
239.64	77.58	0.086
239.67	77.72	0.085
239.70	77.88	0.083
239.73	78.03	0.082
239.76	78.18	0.080
239.79	78.33	0.079
239.82	78.48	0.078
239.85	78.63	0.076
239.88	78.78	0.075
239.91	78.93	0.073
239.94	79.08	0.071
239.97	79.23	0.070
240.00	79.38	0.069
240.03	79.53	0.067
240.06	79.68	0.066
240.09	79.83	0.064
240.12	79.98	0.062
240.15	80.13	0.060
240.18	80.28	0.059
240.21	80.43	0.057
240.24	80.58	0.056
240.27	80.74	0.053
240.30	80.89	0.052
240.33	81.04	0.050
240.36	81.19	0.048
240.39	81.34	0.047
240.42	81.49	0.045
240.45	81.64	0.043
240.48	81.79	0.041
240.51	81.94	0.039
240.54	82.09	0.038
240.57	82.24	0.036
240.60	82.39	0.035
240.63	82.54	0.034
240.66	82.69	0.032
240.69	82.84	0.030
240.72	82.99	0.029
240.75	83.14	0.028
240.78	83.30	0.026
240.81	83.45	0.025
240.84	83.60	0.024
240.87	83.75	0.023
240.90	83.90	0.021
240.93	84.05	0.020
240.96	84.20	0.019
240.99	84.35	0.018
241.02	84.50	0.017
241.05	84.65	0.016
241.08	84.80	0.015
241.11	84.95	0.014
241.14	85.10	0.013
241.17	85.25	0.013
241.20	85.40	0.012
241.23	85.55	0.011
241.26	85.70	0.011
241.29	85.85	0.010
241.32	86.00	0.010
241.35	86.15	0.010
241.38	86.30	0.009
241.41	86.45	0.009
241.44	86.60	0.009
241.47	86.75	0.009
241.50	86.90	0.009
241.53	87.05	0.009
241.56	87.20	0.009
241.59	87.35	0.009
241.62	87.50	0.010
241.65	87.65	0.010
241.68	87.80	0.010
241.71	87.95	0.011
241.74	88.10	0.011
241.77	88.25	0.012
241.80	88.40	0.013
241.83	88.55	0.013
241.86	88.70	0.014
241.89	88.85	0.015
241.92	89.00	0.016
241.95	89.15	0.017
241.98	89.30	0.018
242.01	89.45	0.019
242.04	89.60	0.020
242.07	89.75	0.021
242.10	89.89	0.022
242.13	90.04	0.024
242.16	90.19	0.025
242.19	90.34	0.027
242.22	90.49	0.029
242.25	90.64	0.030
242.28	90.79	0.031
242.31	90.94	0.033
242.34	91.09	0.034
242.37	91.24	0.035
242.40	91.39	0.037
242.43	91.54	0.038
242.46	91.69	0.040
242.49	91.84	0.041
242.52	91.99	0.043
242.55	92.14	0.044
242.58	92.29	0.045
242.61	92.44	0.047
242.64	92.59	0.048
242.67	92.74	0.050
242.70	92.89	0.051
242.73	93.04	0.053
242.76	93.19	0.054
242.79	93.34	0.056
242.82	93.49	0.058
242.85	93.64	0.060
242.88	93.79	0.061
242.91	93.94	0.063
242.94	94.09	0.064
242.97	94.24	0.065
243.00	94.39	0.066
243.03	94.54	0.068
243.06	94.69	0.069
243.09	94.84	0.070
243.12	94.99	0.071
243.15	95.13	0.073
243.18	95.28	0.074
243.21	95.43	0.075
243.24	95.58	0.076
243.27	95.73	0.077
243.30	95.88	0.079
243.33	96.03	0.080
243.36	96.18	0.081
243.39	96.33	0.082
243.42	96.48	0.083
243.45	96.63	0.084
243.48	96.78	0.085
243.51	96.93	0.086
243.54	97.08	0.087
243.57	97.23	0.088
243.60	97.38	0.089
243.63	97.53	0.089
243.66	97.68	0.090
243.69	97.83	0.091
243.72	97.98	0.092
243.75	98.13	0.093
243.78	98.28	0.094
243.81	98.43	0.095
243.84	98.58	0.095
243.87	98.73	0.096
243.90	98.88	0.097
243.93	99.03	0.097
243.96	99.18	0.098
243.99	99.33	0.099
244.02	99.48	0.099
244.05	99.63	0.100
244.08	99.78	0.101
244.11	99.93	0.101
244.14	100.08	0.102
244.17	100.23	0.102
244.20	100.38	0.103
244.23	100.53	0.104
244.26	100.68	0.104
244.29	100.83	0.104
244.32	100.98	0.105
244.35	101.13	0.105
244.38	101.28	0.106
244.41	101.43	0.106
244.44	101.58	0.107
244.47	101.73	0.107
244.50	101.88	0.108
244.53	102.03	0.108
244.56	102.18	0.108
244.59	102.33	0.109
244.62	102.48	0.109
244.65	102.63	0.110
244.68	102.78	0.110
244.71	102.93	0.110
244.74	103.08	0.111
244.77	103.23	0.111
244.80	103.38	0.111
244.83	103.53	0.112
244.86	103.68	0.112
244.89	103.83	0.112
244.92	103.98	0.113
244.95	104.13	0.113
244.98	104.28	0.113
245.01	104.43	0.113
245.04	104.58	0.114
245.07	104.73	0.114
245.10	104.88	0.114
245.13	105.03	0.115
245.16	105.18	0.115
245.19	105.33	0.115
245.22	105.48	0.116
245.25	105.63	0.116
245.28	105.78	0.116
245.31	105.93	0.116
245.34	106.08	0.117
245.37	106.23	0.117
245.40	106.38	0.117
245.43	106.53	0.118
245.46	106.68	0.118
245.49	106.83	0.118
245.52	106.98	0.119
245.55	107.13	0.119
245.58	107.28	0.119
245.61	107.43	0.119
245.64	107.58	0.120
245.67	107.73	0.120
245.70	107.88	0.120
245.73	108.03	0.120
245.76	108.18	0.121
245.79	108.33	0.121
245.82	108.48	0.121
245.85	108.63	0.121
245.88	108.78	0.122
245.91	108.93	0.122
245.94	109.08	0.122
245.97	109.23	0.123
246.00	109.38	0.123
246.03	109.53	0.123
246.06	109.68	0.123
246.09	109.83	0.124
246.12	109.98	0.124
246.15	110.13	0.124
246.18	110.28	0.124
246.21	110.43	0.125
246.24	110.58	0.125
246.27	110.73	0.125
246.30	110.88	0.125
246.33	111.03	0.126
246.36	111.18	0.126
246.39	111.33	0.126
246.42	111.48	0.126
246.45	111.63	0.127
246.48	111.78	0.127
246.51	111.93	0.127
246.54	112.08	0.127
246.57	112.23	0.128
246.60	112.38	0.128
246.63	112.53	0.128
246.66	112.68	0.129
246.69	112.83	0.129
246.72	112.98	0.129
246.75	113.13	0.129
246.78	113.28	0.129
246.81	113.43	0.130
246.84	113.58	0.130
246.87	113.73	0.130
246.90	113.88	0.130
246.93	114.03	0.130
246.96	114.18	0.130
246.99	114.33	0.131
247.02	114.48	0.131
247.05	114.63	0.131
247.08	114.78	0.131
247.11	114.93	0.131
247.14	115.08	0.132
247.17	115.23	0.132
247.20	115.38	0.132
247.23	115.53	0.132
247.26	115.68	0.132
247.29	115.83	0.132
247.32	115.98	0.133
247.35	116.13	0.133
247.38	116.28	0.133
247.41	116.43	0.133
247.44	116.58	0.133
247.47	116.73	0.133
247.50	116.88	0.133
247.53	117.03	0.133
247.56	117.18	0.134
247.59	117.33	0.134
247.62	117.48	0.134
247.65	117.63	0.134
247.68	117.78	0.134
247.71	117.93	0.134
247.74	118.08	0.134
247.77	118.23	0.134
247.80	118.38	0.134
247.83	118.53	0.134
247.86	118.68	0.135
247.89	118.83	0.135
247.92	118.98	0.135
247.95	119.13	0.135
247.98	119.28	0.135
248.01	119.43	0.135
248.04	119.58	0.135
248.07	119.73	0.135
248.10	119.88	0.135
248.13	120.03	0.135
248.16	120.18	0.135
248.19	120.33	0.135
248.22	120.48	0.135
248.25	120.63	0.135
248.28	120.78	0.135
248.31	120.93	0.135
248.34	121.08	0.135
248.37	121.23	0.135
248.40	121.38	0.135
248.43	121.53	0.135
248.46	121.68	0.135
248.49	121.83	0.135
248.52	121.98	0.135
248.55	122.13	0.136
248.58	122.28	0.136
248.61	122.43	0.136
248.64	122.58	0.136
248.67	122.73	0.136
248.70	122.88	0.136
248.73	123.03	0.136
248.76	123.18	0.136
248.79	123.33	0.136
248.82	123.48	0.136
248.85	123.63	0.136
248.88	123.78	0.136
248.91	123.93	0.137
248.94	124.08	0.137
248.97	124.23	0.137
249.00	124.38	0.137
249.03	124.53	0.137
249.06	124.68	0.138
249.09	124.83	0.138
249.12	124.98	0.138
249.15	125.13	0.138
249.18	125.28	0.139
249.21	125.43	0.139
249.24	125.58	0.139
249.27	125.73	0.140
249.30	125.88	0.140
249.33	126.03	0.141
249.36	126.18	0.141
249.39	126.33	0.142
249.42	126.48	0.142
249.45	126.63	0.143
249.48	126.78	0.143
249.51	126.93	0.144
249.54	127.08	0.145
249.57	127.23	0.145
249.60	127.38	0.146
249.63	127.53	0.147
249.66	127.68	0.147
249.69	127.83	0.148
249.72	127.98	0.149
249.75	128.13	0.150
249.78	128.28	0.151
249.81	128.43	0.152
249.84	128.58	0.153
249.87	128.73	0.154
249.90	128.88	0.155
249.93	129.03	0.156
249.96	129.18	0.157
249.99	129.33	0.158
250.02	129.48	0.160
250.05	129.63	0.161
250.08	129.78	0.162
250.11	129.93	0.164
250.14	130.08	0.166
250.17	130.23	0.168
250.20	130.37	0.170
250.23	130.52	0.172
250.26	130.67	0.174
250.29	130.82	0.176
250.32	130.97	0.178
250.35	131.12	0.180
250.38	131.27	0.183
250.41	131.42	0.186
250.44	131.57	0.188
250.47	131.72	0.191
250.50	131.87	0.194
250.53	132.02	0.199
250.56	132.17	0.202
250.59	132.32	0.205
250.62	132.47	0.209
250.65	132.62	0.213
250.68	132.77	0.216
250.71	132.92	0.220
250.74	133.06	0.225
250.77	133.21	0.229
250.80	133.36	0.232
250.83	133.51	0.236
250.86	133.66	0.240
250.89	133.81	0.247
250.92	133.96	0.250
250.95	134.11	0.254
250.98	134.26	0.259
251.01	134.40	0.265
251.04	134.55	0.271
251.07	134.70	0.277
251.10	134.85	0.282
251.13	135.00	0.289
251.16	135.15	0.294
251.19	135.30	0.302
251.22	135.44	0.308
251.25	135.59	0.314
251.28	135.74	0.322
251.31	135.89	0.328
251.34	136.04	0.333
251.37	136.19	0.340
251.40	136.34	0.348
251.43	136.48	0.356
251.46	136.63	0.364
251.49	136.78	0.371
251.52	136.93	0.379
251.55	137.08	0.386
251.58	137.23	0.394
251.61	137.37	0.403
251.64	137.52	0.411
251.67	137.67	0.421
251.70	137.82	0.430
251.73	137.97	0.439
251.76	138.11	0.450
251.79	138.26	0.460
251.82	138.41	0.471
251.85	138.56	0.482
251.88	138.70	0.494
251.91	138.85	0.506
251.94	139.00	0.518
251.97	139.14	0.532
252.00	139.29	0.546
252.03	139.44	0.559
252.06	139.59	0.573
252.09	139.73	0.589
252.12	139.88	0.605
252.15	140.03	0.621
252.18	140.17	0.634
252.21	140.32	0.651
252.24	140.46	0.667
252.27	140.61	0.683
252.30	140.76	0.699
252.33	140.90	0.713
252.36	141.05	0.726
252.39	141.20	0.738
252.42	141.34	0.746
252.45	141.49	0.753
252.48	141.64	0.757
252.51	141.79	0.758
252.54	141.94	0.758
252.57	142.09	0.755
252.60	142.24	0.741
252.63	142.39	0.723
252.66	142.55	0.699
252.69	142.70	0.670
252.72	142.86	0.630
252.75	143.02	0.578
252.78	143.18	0.509
252.81	143.34	0.431
252.84	143.51	0.351
252.87	143.68	0.284
252.90	143.84	0.238
252.93	144.01	0.210
252.96	144.16	0.191
252.99	144.32	0.178
253.02	144.48	0.169
253.05	144.63	0.164
253.08	144.78	0.160
253.11	144.93	0.157
253.14	145.08	0.155
253.17	145.23	0.154
253.20	145.38	0.153
253.23	145.53	0.152
253.26	145.69	0.152
253.29	145.84	0.151
253.32	145.99	0.151
253.35	146.14	0.150
253.38	146.29	0.150
253.41	146.44	0.150
253.44	146.59	0.150
253.47	146.74	0.150
253.50	146.89	0.149
253.53	147.04	0.149
253.56	147.19	0.149
253.59	147.34	0.149
253.62	147.49	0.149
253.65	147.64	0.149
253.68	147.79	0.149
253.71	147.94	0.149
253.74	148.09	0.149
253.77	148.24	0.149
253.80	148.39	0.149
253.83	148.54	0.149
253.86	148.69	0.150
253.89	148.84	0.150
253.92	148.99	0.150
253.95	149.14	0.150
253.98	149.29	0.150
254.01	149.44	0.150
254.04	149.59	0.150
254.07	149.74	0.150
254.10	149.89	0.151
254.13	150.04	0.151
254.16	150.19	0.151
254.19	150.34	0.151
254.22	150.49	0.151
254.25	150.64	0.151
254.28	150.79	0.151
254.31	150.94	0.151
254.34	151.09	0.151
254.37	151.24	0.151
254.40	151.39	0.151
254.43	151.54	0.151
254.46	151.69	0.151
254.49	151.84	0.152
254.52	151.99	0.152
254.55	152.14	0.152
254.58	152.29	0.152
254.61	152.44	0.152
254.64	152.59	0.152
254.67	152.74	0.152
254.70	152.89	0.152
254.73	153.04	0.152
254.76	153.19	0.152
254.79	153.34	0.152
254.82	153.49	0.152
254.85	153.64	0.152
254.88	153.79	0.152
254.91	153.94	0.152
254.94	154.09	0.152
254.97	154.24	0.152
255.00	154.39	0.152
255.03	154.54	0.153
255.06	154.69	0.152
255.09	154.84	0.152
255.12	154.99	0.153
255.15	155.14	0.153
255.18	155.29	0.153
255.21	155.44	0.153
255.24	155.59	0.153
255.27	155.74	0.153
255.30	155.89	0.153
255.33	156.04	0.153
255.36	156.19	0.153
255.39	156.34	0.153
255.42	156.49	0.153
255.45	156.64	0.153
255.48	156.79	0.153
255.51	156.94	0.153
255.54	157.09	0.153
255.57	157.24	0.153
255.60	157.39	0.153
255.63	157.54	0.153
255.66	157.69	0.153
255.69	157.84	0.153
255.72	157.99	0.153
255.75	158.14	0.154
255.78	158.29	0.154
255.81	158.44	0.154
255.84	158.59	0.154
255.87	158.74	0.154
255.90	158.89	0.154
255.93	159.04	0.154
255.96	159.19	0.154
255.99	159.34	0.154
256.02	159.49	0.154
256.05	159.64	0.154
256.08	159.79	0.154
256.11	159.94	0.154
256.14	160.09	0.154
256.17	160.24	0.154
256.20	160.39	0.154
256.23	160.54	0.154
256.26	160.69	0.154
256.29	160.84	0.154
256.32	160.99	0.154
256.35	161.14	0.154
256.38	161.29	0.154
256.41	161.44	0.154
256.44	161.59	0.154
256.47	161.74	0.154
256.50	161.89	0.155
256.53	162.04	0.155
256.56	162.19	0.155
256.59	162.34	0.155
256.62	162.49	0.155
256.65	162.64	0.155
256.68	162.79	0.155
256.71	162.94	0.155
256.74	163.09	0.155
256.77	163.24	0.155
256.80	163.39	0.155
256.83	163.54	0.155
256.86	163.69	0.155
256.89	163.84	0.155
256.92	163.99	0.156
256.95	164.14	0.156
256.98	164.29	0.156
257.01	164.44	0.156
257.04	164.59	0.156
257.07	164.74	0.156
257.10	164.89	0.156
257.13	165.04	0.156
257.16	165.19	0.156
257.19	165.34	0.156
257.22	165.49	0.156
257.25	165.64	0.156
257.28	165.79	0.156
257.31	165.94	0.156
257.34	166.09	0.157
257.37	166.24	0.157
257.40	166.39	0.157
257.43	166.54	0.157
257.46	166.69	0.157
257.49	166.84	0.157
257.52	166.99	0.157
257.55	167.14	0.157
257.58	167.29	0.157
257.61	167.44	0.157
257.64	167.59	0.157
257.67	167.74	0.157
257.70	167.89	0.157
257.73	168.04	0.158
257.76	168.19	0.158
257.79	168.34	0.158
257.82	168.49	0.158
257.85	168.64	0.158
257.88	168.79	0.158
257.91	168.94	0.158
257.94	169.09
257.97	169.24
257.99