File: DSC/2024_11_12_DSC_Empty_Pans_Baseline_5Cmin_x4.csv
Filename,2024_11_12_DSC_Empty_Pans_Baseline_5Cmin_x4
Instrument name,DSC2A-00468 (192.168.1.100)
Operator,Yarger
rundate,11/13/2024
Sample name,2024_11_12_DSC_Empty_Pans_Baseline_5Cmin_x4
proceduresegments,Data Off ; Equilibrate -50.00 °C; Data On ; Ramp 5.00 °C/min to 100.00 °C; Data Off ; Isothermal 1.0 min; Data On ; Ramp 5.00 °C/min to -50.00 °C; Data Off ; Isothermal 1.0 min; Data On ; Ramp 5.00 °C/min to 100.00 °C; Data Off ; Isothermal 1.0 min; Data On ; Ramp 5.00 °C/min to -50.00 °C; Data Off ; Isothermal 1.0 min; Data On ; Ramp 5.00 °C/min to 170.00 °C; Data Off ; Isothermal 1.0 min; Data On ; Ramp 5.00 °C/min to -50.00 °C; Data Off ; Isothermal 1.0 min; Data On ; Ramp 5.00 °C/min to 170.00 °C
[File Parameters]
Run date,11/13/2024 9:55:43 AM
Trios version,5.1.1.46572
Original File Name,
Current File Name,D:\DSC2500\JYarger\2024_11_12_DSC_Empty_Pans_Baseline_5Cmin_x4.tri
[Procedure]
Procedure Name,Empyt Pan Baselines
Sample Name,2024_11_12_DSC_Empty_Pans_Baseline_5Cmin_x4
Sample Mass,0 mg
Reference Sample Mass,0 mg
Pan Mass,54.47 mg
Pan Number,11
Reference Pan Mass,53.32 mg
Reference Pan Number,10
Pan Type,Tzero Aluminum Hermetic
Comments,Two empty Al hermetic Pan/Lid.  DSC_BST1_Tray_Nov2024 google sheet.
Project Name,CoCrystals
Operator,Yarger
Test,Custom
Unload Max Temperature,30
Unload Min Temperature,30
Load Max Temperature,30
Load Min Temperature,30
Stop on Gas Flow Error,Yes
[Signal List]
Signal #1,Time (min)
Signal #2,Temperature (°C)
Signal #3,Heat Flow (mW)
Signal #4,Delta T (µV)
Signal #5,Delta Tzero (µV)
Signal #6,Tzero Temperature (°C)
Signal #7,Cell Purge (mL/min)
Signal #8,Heater Temp (°C)
Signal #9,Power Delivered (W)
Signal #10,Reference Junction Temperature (°C)
Signal #11,Flange Temperature (°C)
Signal #12,Heat Flow Phase (rad)
Signal #13,Total Heat Capacity (J/°C)
Signal #14,Heat Capacity (J/°C)
[Configuration]
Company Name,ASU
Instrument Name,DSC2A-00468
Instrument Type,DSC2500
Serial Number,DSC2A-00468
IP,192.168.1.100
Location of Instrument,MRRC
DisplayType,Unknown
Sample Interval ,0.1 s/pt
Selected Heat Flow,T4P
Exotherm Direction,Down
Cell Serial,DRC2-00792
Lid Type,Standard
Cooler,RCS 90
Leave Cooler on at End of Sequence,On
Gas 2,Nitrogen
Gas Selected,Channel 1
Flow Rate,50 mL/min
Secondary Purge,On
Licensed Heat Flow,Heat Flow T4P
Modulation Licensed,Yes
[Versions]
Common IDD Version,1
Cortex Version,VER 2.10.2.31
Driver,5.0.0.6
GDM Version,1.0.3.3
TouchscreenVersion,1.0.0.16145
FEP Version,1.2.1.21
FEP Bootloader,2.0.0.5
AutoSampler Version,2.1.1.26
Auto Sampler Bootloader,2.0.0.5
FCM Version,1.1.0.3
FCM Bootloader,2.0.0.5
[Experiment Logs]
Experiment Log Entry # 1,Data On set to 0
Experiment Log Entry # 3,Equilibrate Segment -50 (C) Started
Experiment Log Entry # 5,Air Cool is off.
Experiment Log Entry # 7,Data On set to 1
Experiment Log Entry # 9,Ramp Segment 5 C/min to 100 Started
Experiment Log Entry # 11,Data On set to 0
Experiment Log Entry # 13,Isothermal Segment 1 min started
Experiment Log Entry # 15,Data On set to 1
Experiment Log Entry # 17,Ramp Segment 5 C/min to -50 Started
Experiment Log Entry # 19,Data On set to 0
Experiment Log Entry # 21,Isothermal Segment 1 min started
Experiment Log Entry # 23,Data On set to 1
Experiment Log Entry # 25,Ramp Segment 5 C/min to 100 Started
Experiment Log Entry # 27,Data On set to 0
Experiment Log Entry # 29,Isothermal Segment 1 min started
Experiment Log Entry # 31,Data On set to 1
Experiment Log Entry # 33,Ramp Segment 5 C/min to -50 Started
Experiment Log Entry # 35,Data On set to 0
Experiment Log Entry # 37,Isothermal Segment 1 min started
Experiment Log Entry # 39,Data On set to 1
Experiment Log Entry # 41,Ramp Segment 5 C/min to 170 Started
Experiment Log Entry # 43,Data On set to 0
Experiment Log Entry # 45,Isothermal Segment 1 min started
Experiment Log Entry # 47,Data On set to 1
Experiment Log Entry # 49,Ramp Segment 5 C/min to -50 Started
Experiment Log Entry # 51,Data On set to 0
Experiment Log Entry # 53,Isothermal Segment 1 min started
Experiment Log Entry # 55,Data On set to 1
Experiment Log Entry # 57,Ramp Segment 5 C/min to 170 Started
Experiment Log Entry # 59,Auto sampler has detected that FEP has gone offline
[Method Log]
Method Log Entry # 1,Data Off
Method Log Entry # 2,Equilibrate -50 °C
Method Log Entry # 3,Data On
Method Log Entry # 4,(Ramp 423068) Ramp 5 °C/minute to 100 °C
Method Log Entry # 5,Data Off
Method Log Entry # 6,Isothermal 1 minutes
Method Log Entry # 7,Data On
Method Log Entry # 8,(Ramp 423072) Ramp 5 °C/minute to -50 °C
Method Log Entry # 9,Data Off
Method Log Entry # 10,Isothermal 1 minutes
Method Log Entry # 11,Data On
Method Log Entry # 12,(Ramp 423076) Ramp 5 °C/minute to 100 °C
Method Log Entry # 13,Data Off
Method Log Entry # 14,Isothermal 1 minutes
Method Log Entry # 15,Data On
Method Log Entry # 16,(Ramp 423080) Ramp 5 °C/minute to -50 °C
Method Log Entry # 17,Data Off
Method Log Entry # 18,Isothermal 1 minutes
Method Log Entry # 19,Data On
Method Log Entry # 20,(Ramp 423084) Ramp 5 °C/minute to 170 °C
Method Log Entry # 21,Data Off
Method Log Entry # 22,Isothermal 1 minutes
Method Log Entry # 23,Data On
Method Log Entry # 24,(Ramp 423088) Ramp 5 °C/minute to -50 °C
Method Log Entry # 25,Data Off
Method Log Entry # 26,Isothermal 1 minutes
Method Log Entry # 27,Data On
Method Log Entry # 28,(Ramp 423092) Ramp 5 °C/minute to 170 °C
Cell Serial,DRC2-00792
[T1 Calibration]
Slope,-0.008529666
Offset,9.636258
Initial Temperature,98.23
GUID,f8bfdadc-4977-4fdf-ba6d-0ba9134940c3
[TZero Calibration]
Date Applied,11/29/2022 4:06:13 PM
Description,From -89.059 °C to 396.009 °C at 20.000°C/min
Gas Type,Nitrogen
Pan Type,None
Source Files 1,C:\Users\yargerlab\Desktop\DSC Data\General\TZero_calibration_11_29_22_2nd(2).tri
Source Files 2,C:\Users\yargerlab\Desktop\DSC Data\General\TZero_calibration_11_29_22_2nd(3).tri
Delta T Offset,13.05235
Delta T Slope,-0.007271007
Delta T0 Offset,-13.69128
Delta T0 Slope,0.06063341
[Temperature Calibration]
Date Applied,11/29/2022 7:12:28 PM
Description,From 106.590 °C to 186.590 °C at 10.000°C/min
Gas Type,Nitrogen
Pan Type,Tzero Aluminum Hermetic
Source Files 1,C:\Users\yargerlab\Desktop\DSC Data\General\Indium(6).tri
Measured 1,157.391
Known 1,156.598
[Cell Constant Calibration]
Date Applied,11/29/2022 7:12:29 PM
Description,From 106.590 °C to 186.590 °C at 10.000°C/min
Gas Type,Nitrogen
Pan Type,Tzero Aluminum Hermetic
Source Files 1,C:\Users\yargerlab\Desktop\DSC Data\General\Indium(6).tri
T4P KCell,1.006051
Onset Slope,63.26126 mW/°C
[Direct Cp Calibration]
Date Applied,11/30/2022 11:04:51 AM
Description,From -79.983 °C to 298.409 °C at 10.000°C/min
Gas Type,Nitrogen
Pan Type,Tzero Aluminum Hermetic
Source Files 1,C:\Users\yargerlab\Desktop\DSC Data\General\Sapphire_Heat_Capacity_11_30_22.tri
[Rev Cp Calibration]
Date Applied,11/30/2022 1:58:51 PM
Description,From -79.996 °C to 292.812 °C at 3.000°C/min
Gas Type,Nitrogen
Pan Type,Tzero Aluminum Hermetic
Source Files 1,C:\Users\yargerlab\Desktop\DSC Data\General\Sapphire_MDSC_Calibration_11_30_22.tri
[step]
Ramp 5.00 °C/min to 100.00 °C
Time,Temperature,Heat Flow (Normalized)
min,°C,W/g
0.00,-49.71,
0.02,-49.72,
0.04,-49.73,
0.06,-49.73,
0.08,-49.73,
0.10,-49.71,
0.12,-49.67,
0.14,-49.63,
0.16,-49.57,
0.18,-49.51,
0.20,-49.43,
0.22,-49.36,
0.24,-49.27,
0.26,-49.19,
0.28,-49.10,
0.30,-49.01,
0.32,-48.91,
0.34,-48.82,
0.36,-48.73,
0.38,-48.64,
0.40,-48.54,
0.42,-48.45,
0.44,-48.35,
0.46,-48.26,
0.48,-48.16,
0.50,-48.06,
0.52,-47.97,
0.54,-47.87,
0.56,-47.77,
0.58,-47.68,
0.60,-47.58,
0.62,-47.48,
0.64,-47.39,
0.66,-47.29,
0.68,-47.19,
0.70,-47.09,
0.72,-47.00,
0.74,-46.90,
0.76,-46.80,
0.78,-46.70,
0.80,-46.61,
0.82,-46.51,
0.84,-46.41,
0.86,-46.31,
0.88,-46.21,
0.90,-46.12,
0.92,-46.02,
0.94,-45.92,
0.96,-45.82,
0.98,-45.72,
1.00,-45.62,
1.02,-45.52,
1.04,-45.43,
1.06,-45.33,
1.08,-45.23,
1.10,-45.13,
1.12,-45.03,
1.14,-44.93,
1.16,-44.83,
1.18,-44.73,
1.20,-44.63,
1.22,-44.53,
1.24,-44.43,
1.26,-44.34,
1.28,-44.24,
1.30,-44.14,
1.32,-44.04,
1.34,-43.94,
1.36,-43.84,
1.38,-43.74,
1.40,-43.64,
1.42,-43.54,
1.44,-43.44,
1.46,-43.34,
1.48,-43.24,
1.50,-43.14,
1.52,-43.04,
1.54,-42.94,
1.56,-42.84,
1.58,-42.74,
1.60,-42.64,
1.62,-42.54,
1.64,-42.44,
1.66,-42.34,
1.68,-42.24,
1.70,-42.15,
1.72,-42.05,
1.74,-41.95,
1.76,-41.85,
1.78,-41.75,
1.80,-41.65,
1.82,-41.55,
1.84,-41.45,
1.86,-41.35,
1.88,-41.25,
1.90,-41.15,
1.92,-41.05,
1.94,-40.95,
1.96,-40.85,
1.98,-40.75,
2.00,-40.65,
2.02,-40.55,
2.04,-40.45,
2.06,-40.35,
2.08,-40.25,
2.10,-40.15,
2.12,-40.05,
2.14,-39.95,
2.16,-39.85,
2.18,-39.75,
2.20,-39.65,
2.22,-39.55,
2.24,-39.45,
2.26,-39.35,
2.28,-39.25,
2.30,-39.15,
2.32,-39.05,
2.34,-38.95,
2.36,-38.85,
2.38,-38.75,
2.40,-38.65,
2.42,-38.55,
2.44,-38.45,
2.46,-38.35,
2.48,-38.25,
2.50,-38.15,
2.52,-38.05,
2.54,-37.95,
2.56,-37.85,
2.58,-37.75,
2.60,-37.65,
2.62,-37.55,
2.64,-37.45,
2.66,-37.35,
2.68,-37.25,
2.70,-37.14,
2.72,-37.04,
2.74,-36.94,
2.76,-36.84,
2.78,-36.74,
2.80,-36.64,
2.82,-36.54,
2.84,-36.44,
2.86,-36.35,
2.88,-36.24,
2.90,-36.15,
2.92,-36.04,
2.94,-35.94,
2.96,-35.84,
2.98,-35.74,
3.00,-35.64,
3.02,-35.54,
3.04,-35.44,
3.06,-35.34,
3.08,-35.24,
3.10,-35.14,
3.12,-35.04,
3.14,-34.94,
3.16,-34.84,
3.18,-34.74,
3.20,-34.64,
3.22,-34.54,
3.24,-34.44,
3.26,-34.34,
3.28,-34.24,
3.30,-34.14,
3.32,-34.04,
3.34,-33.94,
3.36,-33.84,
3.38,-33.74,
3.40,-33.64,
3.42,-33.54,
3.44,-33.44,
3.46,-33.34,
3.48,-33.24,
3.50,-33.14,
3.52,-33.04,
3.54,-32.94,
3.56,-32.84,
3.58,-32.74,
3.60,-32.64,
3.62,-32.54,
3.64,-32.44,
3.66,-32.34,
3.68,-32.24,
3.70,-32.14,
3.72,-32.04,
3.74,-31.94,
3.76,-31.84,
3.78,-31.74,
3.80,-31.64,
3.82,-31.54,
3.84,-31.44,
3.86,-31.34,
3.88,-31.24,
3.90,-31.14,
3.92,-31.04,
3.94,-30.94,
3.96,-30.84,
3.98,-30.74,
4.00,-30.64,
4.02,-30.54,
4.04,-30.44,
4.06,-30.34,
4.08,-30.24,
4.10,-30.14,
4.12,-30.04,
4.14,-29.94,
4.16,-29.84,
4.18,-29.74,
4.20,-29.64,
4.22,-29.54,
4.24,-29.44,
4.26,-29.34,
4.28,-29.24,
4.30,-29.14,
4.32,-29.04,
4.34,-28.94,
4.36,-28.84,
4.38,-28.74,
4.40,-28.64,
4.42,-28.54,
4.44,-28.43,
4.46,-28.34,
4.48,-28.23,
4.50,-28.14,
4.52,-28.04,
4.54,-27.94,
4.56,-27.84,
4.58,-27.73,
4.60,-27.63,
4.62,-27.54,
4.64,-27.44,
4.66,-27.33,
4.68,-27.24,
4.70,-27.14,
4.72,-27.03,
4.74,-26.93,
4.76,-26.84,
4.78,-26.73,
4.80,-26.63,
4.82,-26.54,
4.84,-26.43,
4.86,-26.33,
4.88,-26.23,
4.90,-26.13,
4.92,-26.03,
4.94,-25.93,
4.96,-25.83,
4.98,-25.73,
5.00,-25.63,
5.02,-25.53,
5.04,-25.43,
5.06,-25.33,
5.08,-25.23,
5.10,-25.13,
5.12,-25.03,
5.14,-24.93,
5.16,-24.83,
5.18,-24.73,
5.20,-24.63,
5.22,-24.53,
5.24,-24.43,
5.26,-24.33,
5.28,-24.23,
5.30,-24.13,
5.32,-24.03,
5.34,-23.93,
5.36,-23.83,
5.38,-23.73,
5.40,-23.63,
5.42,-23.53,
5.44,-23.43,
5.46,-23.33,
5.48,-23.23,
5.50,-23.13,
5.52,-23.03,
5.54,-22.93,
5.56,-22.83,
5.58,-22.73,
5.60,-22.63,
5.62,-22.53,
5.64,-22.43,
5.66,-22.33,
5.68,-22.23,
5.70,-22.13,
5.72,-22.03,
5.74,-21.93,
5.76,-21.83,
5.78,-21.73,
5.80,-21.63,
5.82,-21.53,
5.84,-21.43,
5.86,-21.33,
5.88,-21.23,
5.90,-21.13,
5.92,-21.03,
5.94,-20.93,
5.96,-20.83,
5.98,-20.73,
6.00,-20.63,
6.02,-20.53,
6.04,-20.43,
6.06,-20.33,
6.08,-20.23,
6.10,-20.13,
6.12,-20.03,
6.14,-19.93,
6.16,-19.83,
6.18,-19.73,
6.20,-19.63,
6.22,-19.53,
6.24,-19.43,
6.26,-19.33,
6.28,-19.23,
6.30,-19.13,
6.32,-19.03,
6.34,-18.93,
6.36,-18.83,
6.38,-18.73,
6.40,-18.63,
6.42,-18.53,
6.44,-18.43,
6.46,-18.33,
6.48,-18.23,
6.50,-18.13,
6.52,-18.03,
6.54,-17.93,
6.56,-17.83,
6.58,-17.73,
6.60,-17.63,
6.62,-17.53,
6.64,-17.43,
6.66,-17.33,
6.68,-17.23,
6.70,-17.13,
6.72,-17.03,
6.74,-16.93,
6.76,-16.83,
6.78,-16.73,
6.80,-16.63,
6.82,-16.53,
6.84,-16.43,
6.86,-16.33,
6.88,-16.23,
6.90,-16.13,
6.92,-16.02,
6.94,-15.93,
6.96,-15.83,
6.98,-15.73,
7.00,-15.63,
7.02,-15.52,
7.04,-15.43,
7.06,-15.33,
7.08,-15.22,
7.10,-15.12,
7.12,-15.03,
7.14,-14.92,
7.16,-14.82,
7.18,-14.73,
7.20,-14.62,
7.22,-14.52,
7.24,-14.43,
7.26,-14.32,
7.28,-14.22,
7.30,-14.12,
7.32,-14.02,
7.34,-13.92,
7.36,-13.82,
7.38,-13.72,
7.40,-13.62,
7.42,-13.52,
7.44,-13.42,
7.46,-13.32,
7.48,-13.22,
7.50,-13.12,
7.52,-13.02,
7.54,-12.92,
7.56,-12.82,
7.58,-12.72,
7.60,-12.62,
7.62,-12.52,
7.64,-12.43,
7.66,-12.32,
7.68,-12.22,
7.70,-12.12,
7.72,-12.02,
7.74,-11.92,
7.76,-11.82,
7.78,-11.72,
7.80,-11.62,
7.82,-11.52,
7.84,-11.42,
7.86,-11.32,
7.88,-11.22,
7.90,-11.12,
7.92,-11.02,
7.94,-10.92,
7.96,-10.82,
7.98,-10.72,
8.00,-10.62,
8.02,-10.52,
8.04,-10.42,
8.06,-10.32,
8.08,-10.22,
8.10,-10.12,
8.12,-10.02,
8.14,-9.92,
8.16,-9.82,
8.18,-9.72,
8.20,-9.62,
8.22,-9.52,
8.24,-9.42,
8.26,-9.32,
8.28,-9.22,
8.30,-9.12,
8.32,-9.02,
8.34,-8.92,
8.36,-8.82,
8.38,-8.72,
8.40,-8.62,
8.42,-8.52,
8.44,-8.42,
8.46,-8.32,
8.48,-8.22,
8.50,-8.12,
8.52,-8.02,
8.54,-7.92,
8.56,-7.82,
8.58,-7.72,
8.60,-7.62,
8.62,-7.52,
8.64,-7.42,
8.66,-7.32,
8.68,-7.22,
8.70,-7.12,
8.72,-7.02,
8.74,-6.92,
8.76,-6.82,
8.78,-6.72,
8.80,-6.62,
8.82,-6.52,
8.84,-6.42,
8.86,-6.32,
8.88,-6.22,
8.90,-6.12,
8.92,-6.02,
8.94,-5.92,
8.96,-5.82,
8.98,-5.72,
9.00,-5.62,
9.02,-5.52,
9.04,-5.42,
9.06,-5.32,
9.08,-5.22,
9.10,-5.12,
9.12,-5.02,
9.14,-4.92,
9.16,-4.82,
9.18,-4.72,
9.20,-4.61,
9.22,-4.52,
9.24,-4.42,
9.26,-4.32,
9.28,-4.22,
9.30,-4.12,
9.32,-4.02,
9.34,-3.91,
9.36,-3.82,
9.38,-3.72,
9.40,-3.62,
9.42,-3.52,
9.44,-3.42,
9.46,-3.32,
9.48,-3.22,
9.50,-3.12,
9.52,-3.02,
9.54,-2.92,
9.56,-2.82,
9.58,-2.72,
9.60,-2.62,
9.62,-2.52,
9.64,-2.42,
9.66,-2.32,
9.68,-2.21,
9.70,-2.12,
9.72,-2.01,
9.74,-1.91,
9.76,-1.82,
9.78,-1.71,
9.80,-1.61,
9.82,-1.51,
9.84,-1.41,
9.86,-1.31,
9.88,-1.21,
9.90,-1.12,
9.92,-1.01,
9.94,-0.92,
9.96,-0.81,
9.98,-0.71,
10.00,-0.61,
10.02,-0.51,
10.04,-0.41,
10.06,-0.31,
10.08,-0.21,
10.10,-0.11,
10.12,-0.01,
10.14,0.09,
10.16,0.19,
10.18,0.29,
10.20,0.39,
10.22,0.49,
10.24,0.59,
10.26,0.69,
10.28,0.79,
10.30,0.89,
10.32,0.99,
10.34,1.09,
10.36,1.19,
10.38,1.29,
10.40,1.39,
10.42,1.49,
10.44,1.59,
10.46,1.69,
10.48,1.79,
10.50,1.89,
10.52,1.99,
10.54,2.09,
10.56,2.19,
10.58,2.29,
10.60,2.39,
10.62,2.49,
10.64,2.59,
10.66,2.69,
10.68,2.79,
10.70,2.89,
10.72,2.99,
10.74,3.09,
10.76,3.19,
10.78,3.29,
10.80,3.39,
10.82,3.49,
10.84,3.59,
10.86,3.69,
10.88,3.79,
10.90,3.89,
10.92,3.99,
10.94,4.09,
10.96,4.19,
10.98,4.29,
11.00,4.39,
11.02,4.49,
11.04,4.59,
11.06,4.69,
11.08,4.79,
11.10,4.89,
11.12,4.99,
11.14,5.09,
11.16,5.19,
11.18,5.29,
11.20,5.39,
11.22,5.49,
11.24,5.59,
11.26,5.69,
11.28,5.79,
11.30,5.89,
11.32,5.99,
11.34,6.09,
11.36,6.19,
11.38,6.29,
11.40,6.39,
11.42,6.49,
11.44,6.59,
11.46,6.69,
11.48,6.79,
11.50,6.89,
11.52,6.99,
11.54,7.09,
11.56,7.19,
11.58,7.29,
11.60,7.39,
11.62,7.49,
11.64,7.59,
11.66,7.69,
11.68,7.79,
11.70,7.89,
11.72,7.99,
11.74,8.09,
11.76,8.19,
11.78,8.29,
11.80,8.39,
11.82,8.49,
11.84,8.59,
11.86,8.69,
11.88,8.79,
11.90,8.89,
11.92,8.99,
11.94,9.09,
11.96,9.19,
11.98,9.29,
12.00,9.39,
12.02,9.49,
12.04,9.59,
12.06,9.69,
12.08,9.79,
12.10,9.89,
12.12,9.99,
12.14,10.09,
12.16,10.20,
12.18,10.29,
12.20,10.39,
12.22,10.49,
12.24,10.59,
12.26,10.69,
12.28,10.80,
12.30,10.89,
12.32,10.99,
12.34,11.09,
12.36,11.19,
12.38,11.29,
12.40,11.39,
12.42,11.49,
12.44,11.59,
12.46,11.69,
12.48,11.80,
12.50,11.90,
12.52,12.00,
12.54,12.10,
12.56,12.20,
12.58,12.30,
12.60,12.40,
12.62,12.50,
12.64,12.60,
12.66,12.70,
12.68,12.80,
12.70,12.90,
12.72,13.00,
12.74,13.10,
12.76,13.20,
12.78,13.30,
12.80,13.40,
12.82,13.50,
12.84,13.60,
12.86,13.70,
12.88,13.80,
12.90,13.90,
12.92,14.00,
12.94,14.10,
12.96,14.20,
12.98,14.30,
13.00,14.40,
13.02,14.50,
13.04,14.60,
13.06,14.70,
13.08,14.80,
13.10,14.90,
13.12,15.00,
13.14,15.10,
13.16,15.20,
13.18,15.30,
13.20,15.40,
13.22,15.50,
13.24,15.60,
13.26,15.70,
13.28,15.80,
13.30,15.90,
13.32,16.00,
13.34,16.10,
13.36,16.20,
13.38,16.30,
13.40,16.40,
13.42,16.50,
13.44,16.60,
13.46,16.70,
13.48,16.80,
13.50,16.90,
13.52,17.00,
13.54,17.10,
13.56,17.20,
13.58,17.30,
13.60,17.40,
13.62,17.50,
13.64,17.60,
13.66,17.70,
13.68,17.80,
13.70,17.90,
13.72,18.00,
13.74,18.10,
13.76,18.20,
13.78,18.30,
13.80,18.40,
13.82,18.50,
13.84,18.60,
13.86,18.70,
13.88,18.80,
13.90,18.90,
13.92,19.00,
13.94,19.10,
13.96,19.20,
13.98,19.30,
14.00,19.40,
14.02,19.50,
14.04,19.60,
14.06,19.70,
14.08,19.80,
14.10,19.90,
14.12,20.00,
14.14,20.10,
14.16,20.20,
14.18,20.30,
14.20,20.40,
14.22,20.50,
14.24,20.60,
14.26,20.70,
14.28,20.80,
14.30,20.90,
14.32,21.00,
14.34,21.10,
14.36,21.20,
14.38,21.30,
14.40,21.40,
14.42,21.50,
14.44,21.60,
14.46,21.70,
14.48,21.80,
14.50,21.90,
14.52,22.00,
14.54,22.10,
14.56,22.20,
14.58,22.30,
14.60,22.40,
14.62,22.50,
14.64,22.60,
14.66,22.70,
14.68,22.80,
14.70,22.90,
14.72,23.00,
14.74,23.10,
14.76,23.20,
14.78,23.30,
14.80,23.40,
14.82,23.50,
14.84,23.60,
14.86,23.70,
14.88,23.80,
14.90,23.90,
14.92,24.00,
14.94,24.10,
14.96,24.20,
14.98,24.30,
15.00,24.40,
15.02,24.50,
15.04,24.60,
15.06,24.70,
15.08,24.80,
15.10,24.90,
15.12,25.00,
15.14,25.10,
15.16,25.21,
15.18,25.30,
15.20,25.41,
15.22,25.51,
15.24,25.60,
15.26,25.70,
15.28,25.80,
15.30,25.90,
15.32,26.01,
15.34,26.11,
15.36,26.21,
15.38,26.31,
15.40,26.40,
15.42,26.51,
15.44,26.61,
15.46,26.71,
15.48,26.81,
15.50,26.90,
15.52,27.01,
15.54,27.11,
15.56,27.21,
15.58,27.31,
15.60,27.41,
15.62,27.51,
15.64,27.61,
15.66,27.71,
15.68,27.81,
15.70,27.91,
15.72,28.01,
15.74,28.11,
15.76,28.21,
15.78,28.31,
15.80,28.41,
15.82,28.51,
15.84,28.61,
15.86,28.71,
15.88,28.81,
15.90,28.91,
15.92,29.01,
15.94,29.11,
15.96,29.21,
15.98,29.31,
16.00,29.41,
16.02,29.51,
16.04,29.61,
16.06,29.71,
16.08,29.81,
16.10,29.91,
16.12,30.01,
16.14,30.11,
16.16,30.21,
16.18,30.31,
16.20,30.41,
16.22,30.51,
16.24,30.61,
16.26,30.71,
16.28,30.81,
16.30,30.91,
16.32,31.01,
16.34,31.11,
16.36,31.21,
16.38,31.31,
16.40,31.41,
16.42,31.51,
16.44,31.61,
16.46,31.71,
16.48,31.81,
16.50,31.91,
16.52,32.01,
16.54,32.11,
16.56,32.21,
16.58,32.31,
16.60,32.41,
16.62,32.51,
16.64,32.61,
16.66,32.71,
16.68,32.81,
16.70,32.91,
16.72,33.01,
16.74,33.11,
16.76,33.21,
16.78,33.31,
16.80,33.41,
16.82,33.51,
16.84,33.61,
16.86,33.71,
16.88,33.81,
16.90,33.91,
16.92,34.01,
16.94,34.11,
16.96,34.21,
16.98,34.31,
17.00,34.41,
17.02,34.51,
17.04,34.61,
17.06,34.71,
17.08,34.81,
17.10,34.91,
17.12,35.01,
17.14,35.11,
17.16,35.21,
17.18,35.31,
17.20,35.41,
17.22,35.51,
17.24,35.61,
17.26,35.71,
17.28,35.81,
17.30,35.91,
17.32,36.01,
17.34,36.11,
17.36,36.21,
17.38,36.31,
17.40,36.41,
17.42,36.51,
17.44,36.61,
17.46,36.71,
17.48,36.81,
17.50,36.91,
17.52,37.01,
17.54,37.11,
17.56,37.21,
17.58,37.31,
17.60,37.41,
17.62,37.51,
17.64,37.61,
17.66,37.71,
17.68,37.81,
17.70,37.91,
17.72,38.01,
17.74,38.11,
17.76,38.21,
17.78,38.31,
17.80,38.41,
17.82,38.51,
17.84,38.61,
17.86,38.71,
17.88,38.81,
17.90,38.91,
17.92,39.01,
17.94,39.11,
17.96,39.21,
17.98,39.31,
18.00,39.41,
18.02,39.51,
18.04,39.61,
18.06,39.71,
18.08,39.81,
18.10,39.91,
18.12,40.01,
18.14,40.11,
18.16,40.21,
18.18,40.31,
18.20,40.41,
18.22,40.51,
18.24,40.61,
18.26,40.71,
18.28,40.81,
18.30,40.91,
18.32,41.01,
18.34,41.12,
18.36,41.21,
18.38,41.32,
18.40,41.41,
18.42,41.52,
18.44,41.62,
18.46,41.71,
18.48,41.82,
18.50,41.92,
18.52,42.01,
18.54,42.12,
18.56,42.22,
18.58,42.31,
18.60,42.42,
18.62,42.52,
18.64,42.62,
18.66,42.71,
18.68,42.82,
18.70,42.92,
18.72,43.01,
18.74,43.12,
18.76,43.22,
18.78,43.31,
18.80,43.42,
18.82,43.51,
18.84,43.62,
18.86,43.72,
18.88,43.82,
18.90,43.92,
18.92,44.02,
18.94,44.12,
18.96,44.22,
18.98,44.32,
19.00,44.42,
19.02,44.52,
19.04,44.62,
19.06,44.72,
19.08,44.82,
19.10,44.92,
19.12,45.02,
19.14,45.12,
19.16,45.22,
19.18,45.32,
19.20,45.42,
19.22,45.52,
19.24,45.62,
19.26,45.72,
19.28,45.82,
19.30,45.92,
19.32,46.02,
19.34,46.12,
19.36,46.22,
19.38,46.32,
19.40,46.42,
19.42,46.52,
19.44,46.62,
19.46,46.72,
19.48,46.82,
19.50,46.92,
19.52,47.02,
19.54,47.12,
19.56,47.22,
19.58,47.32,
19.60,47.42,
19.62,47.52,
19.64,47.62,
19.66,47.72,
19.68,47.82,
19.70,47.92,
19.72,48.02,
19.74,48.12,
19.76,48.22,
19.78,48.32,
19.80,48.42,
19.82,48.52,
19.84,48.62,
19.86,48.72,
19.88,48.82,
19.90,48.92,
19.92,49.02,
19.94,49.12,
19.96,49.22,
19.98,49.32,
20.00,49.42,
20.02,49.52,
20.04,49.62,
20.06,49.72,
20.08,49.82,
20.10,49.92,
20.12,50.02,
20.14,50.12,
20.16,50.22,
20.18,50.32,
20.20,50.42,
20.22,50.52,
20.24,50.62,
20.26,50.72,
20.28,50.82,
20.30,50.92,
20.32,51.02,
20.34,51.12,
20.36,51.22,
20.38,51.32,
20.40,51.42,
20.42,51.52,
20.44,51.62,
20.46,51.72,
20.48,51.82,
20.50,51.92,
20.52,52.02,
20.54,52.12,
20.56,52.22,
20.58,52.32,
20.60,52.42,
20.62,52.52,
20.64,52.62,
20.66,52.72,
20.68,52.82,
20.70,52.92,
20.72,53.02,
20.74,53.12,
20.76,53.22,
20.78,53.32,
20.80,53.42,
20.82,53.52,
20.84,53.62,
20.86,53.72,
20.88,53.82,
20.90,53.92,
20.92,54.02,
20.94,54.12,
20.96,54.22,
20.98,54.32,
21.00,54.42,
21.02,54.52,
21.04,54.62,
21.06,54.73,
21.08,54.82,
21.10,54.92,
21.12,55.02,
21.14,55.12,
21.16,55.22,
21.18,55.32,
21.20,55.42,
21.22,55.52,
21.24,55.62,
21.26,55.72,
21.28,55.82,
21.30,55.92,
21.32,56.03,
21.34,56.12,
21.36,56.22,
21.38,56.33,
21.40,56.43,
21.42,56.53,
21.44,56.63,
21.46,56.73,
21.48,56.83,
21.50,56.93,
21.52,57.03,
21.54,57.13,
21.56,57.23,
21.58,57.33,
21.60,57.43,
21.62,57.53,
21.64,57.63,
21.66,57.73,
21.68,57.83,
21.70,57.93,
21.72,58.03,
21.74,58.13,
21.76,58.23,
21.78,58.33,
21.80,58.43,
21.82,58.53,
21.84,58.63,
21.86,58.73,
21.88,58.83,
21.90,58.93,
21.92,59.03,
21.94,59.13,
21.96,59.23,
21.98,59.33,
22.00,59.43,
22.02,59.53,
22.04,59.63,
22.06,59.73,
22.08,59.83,
22.10,59.93,
22.12,60.03,
22.14,60.13,
22.16,60.23,
22.18,60.33,
22.20,60.43,
22.22,60.53,
22.24,60.63,
22.26,60.73,
22.28,60.83,
22.30,60.93,
22.32,61.03,
22.34,61.13,
22.36,61.23,
22.38,61.33,
22.40,61.43,
22.42,61.53,
22.44,61.63,
22.46,61.73,
22.48,61.83,
22.50,61.93,
22.52,62.03,
22.54,62.13,
22.56,62.23,
22.58,62.33,
22.60,62.43,
22.62,62.53,
22.64,62.63,
22.66,62.73,
22.68,62.83,
22.70,62.93,
22.72,63.03,
22.74,63.13,
22.76,63.23,
22.78,63.33,
22.80,63.43,
22.82,63.53,
22.84,63.63,
22.86,63.73,
22.88,63.83,
22.90,63.93,
22.92,64.03,
22.94,64.13,
22.96,64.23,
22.98,64.33,
23.00,64.43,
23.02,64.53,
23.04,64.63,
23.06,64.73,
23.08,64.83,
23.10,64.93,
23.12,65.03,
23.14,65.13,
23.16,65.23,
23.18,65.33,
23.20,65.43,
23.22,65.53,
23.24,65.63,
23.26,65.73,
23.28,65.83,
23.30,65.93,
23.32,66.03,
23.34,66.13,
23.36,66.23,
23.38,66.33,
23.40,66.43,
23.42,66.53,
23.44,66.63,
23.46,66.73,
23.48,66.83,
23.50,66.93,
23.52,67.03,
23.54,67.13,
23.56,67.23,
23.58,67.33,
23.60,67.43,
23.62,67.53,
23.64,67.63,
23.66,67.73,
23.68,67.83,
23.70,67.93,
23.72,68.03,
23.74,68.13,
23.76,68.23,
23.78,68.33,
23.80,68.43,
23.82,68.53,
23.84,68.63,
23.86,68.73,
23.88,68.83,
23.90,68.93,
23.92,69.03,
23.94,69.13,
23.96,69.23,
23.98,69.33,
24.00,69.43,
24.02,69.53,
24.04,69.63,
24.06,69.73,
24.08,69.83,
24.10,69.93,
24.12,70.03,
24.14,70.13,
24.16,70.23,
24.18,70.33,
24.20,70.43,
24.22,70.53,
24.24,70.63,
24.26,70.73,
24.28,70.83,
24.30,70.93,
24.32,71.03,
24.34,71.13,
24.36,71.23,
24.38,71.33,
24.40,71.43,
24.42,71.53,
24.44,71.63,
24.46,71.73,
24.48,71.83,
24.50,71.93,
24.52,72.03,
24.54,72.13,
24.56,72.23,
24.58,72.33,
24.60,72.43,
24.62,72.53,
24.64,72.63,
24.66,72.73,
24.68,72.83,
24.70,72.93,
24.72,73.03,
24.74,73.13,
24.76,73.23,
24.78,73.33,
24.80,73.43,
24.82,73.53,
24.84,73.63,
24.86,73.73,
24.88,73.83,
24.90,73.93,
24.92,74.03,
24.94,74.13,
24.96,74.23,
24.98,74.33,
25.00,74.43,
25.02,74.53,
25.04,74.63,
25.06,74.73,
25.08,74.83,
25.10,74.93,
25.12,75.03,
25.14,75.13,
25.16,75.23,
25.18,75.33,
25.20,75.43,
25.22,75.53,
25.24,75.63,
25.26,75.73,
25.28,75.83,
25.30,75.93,
25.32,76.03,
25.34,76.14,
25.36,76.23,
25.38,76.33,
25.40,76.43,
25.42,76.53,
25.44,76.63,
25.46,76.73,
25.48,76.84,
25.50,76.94,
25.52,77.03,
25.54,77.13,
25.56,77.23,
25.58,77.34,
25.60,77.43,
25.62,77.54,
25.64,77.64,
25.66,77.74,
25.68,77.84,
25.70,77.94,
25.72,78.04,
25.74,78.14,
25.76,78.24,
25.78,78.34,
25.80,78.44,
25.82,78.54,
25.84,78.64,
25.86,78.74,
25.88,78.84,
25.90,78.94,
25.92,79.04,
25.94,79.14,
25.96,79.24,
25.98,79.34,
26.00,79.44,
26.02,79.54,
26.04,79.64,
26.06,79.74,
26.08,79.84,
26.10,79.94,
26.12,80.04,
26.14,80.14,
26.16,80.24,
26.18,80.34,
26.20,80.44,
26.22,80.54,
26.24,80.64,
26.26,80.74,
26.28,80.84,
26.30,80.94,
26.32,81.04,
26.34,81.14,
26.36,81.24,
26.38,81.34,
26.40,81.44,
26.42,81.54,
26.44,81.64,
26.46,81.74,
26.48,81.84,
26.50,81.94,
26.52,82.04,
26.54,82.14,
26.56,82.24,
26.58,82.34,
26.60,82.44,
26.62,82.54,
26.64,82.64,
26.66,82.74,
26.68,82.84,
26.70,82.94,
26.72,83.04,
26.74,83.14,
26.76,83.24,
26.78,83.34,
26.80,83.44,
26.82,83.54,
26.84,83.64,
26.86,83.74,
26.88,83.84,
26.90,83.94,
26.92,84.04,
26.94,84.14,
26.96,84.24,
26.98,84.34,
27.00,84.44,
27.02,84.54,
27.04,84.64,
27.06,84.74,
27.08,84.84,
27.10,84.94,
27.12,85.04,
27.14,85.14,
27.16,85.24,
27.18,85.34,
27.20,85.44,
27.22,85.54,
27.24,85.64,
27.26,85.74,
27.28,85.84,
27.30,85.94,
27.32,86.04,
27.34,86.14,
27.36,86.24,
27.38,86.34,
27.40,86.44,
27.42,86.54,
27.44,86.64,
27.46,86.74,
27.48,86.84,
27.50,86.94,
27.52,87.04,
27.54,87.14,
27.56,87.24,
27.58,87.34,
27.60,87.44,
27.62,87.54,
27.64,87.64,
27.66,87.74,
27.68,87.84,
27.70,87.94,
27.72,88.04,
27.74,88.14,
27.76,88.24,
27.78,88.34,
27.80,88.44,
27.82,88.54,
27.84,88.64,
27.86,88.74,
27.88,88.84,
27.90,88.94,
27.92,89.04,
27.94,89.14,
27.96,89.24,
27.98,89.34,
28.00,89.44,
28.02,89.54,
28.04,89.64,
28.06,89.74,
28.08,89.84,
28.10,89.94,
28.12,90.04,
28.14,90.14,
28.16,90.24,
28.18,90.34,
28.20,90.44,
28.22,90.54,
28.24,90.64,
28.26,90.74,
28.28,90.84,
28.30,90.94,
28.32,91.04,
28.34,91.14,
28.36,91.24,
28.38,91.34,
28.40,91.44,
28.42,91.54,
28.44,91.64,
28.46,91.74,
28.48,91.84,
28.50,91.94,
28.52,92.04,
28.54,92.14,
28.56,92.24,
28.58,92.34,
28.60,92.44,
28.62,92.54,
28.64,92.64,
28.66,92.74,
28.68,92.84,
28.70,92.94,
28.72,93.04,
28.74,93.14,
28.76,93.24,
28.78,93.34,
28.80,93.44,
28.82,93.54,
28.84,93.64,
28.86,93.74,
28.88,93.84,
28.90,93.94,
28.92,94.04,
28.94,94.14,
28.96,94.24,
28.98,94.34,
29.00,94.44,
29.02,94.54,
29.04,94.64,
29.06,94.74,
29.08,94.84,
29.10,94.94,
29.12,95.04,
29.14,95.14,
29.16,95.24,
29.18,95.34,
29.20,95.44,
29.22,95.54,
29.24,95.64,
29.26,95.74,
29.28,95.85,
29.30,95.94,
29.32,96.04,
29.34,96.14,
29.36,96.24,
29.38,96.35,
29.40,96.45,
29.42,96.54,
29.44,96.64,
29.46,96.74,
29.48,96.84,
29.50,96.94,
29.52,97.04,
29.54,97.15,
29.56,97.24,
29.58,97.34,
29.60,97.44,
29.62,97.54,
29.64,97.64,
29.66,97.74,
29.68,97.84,
29.70,97.94,
29.72,98.05,
29.74,98.14,
29.76,98.24,
29.78,98.34,
29.80,98.44,
29.82,98.55,
29.84,98.65,
29.86,98.74,
29.88,98.84,
29.90,98.94,
29.92,99.05,
29.94,99.15,
29.96,99.25,
29.98,99.35,
29.99,,

[step]
Ramp 5.00 °C/min to -50.00 °C
Time,Temperature,Heat Flow (Normalized)
min,°C,W/g
30.99,100.11,
31.01,100.11,
31.03,100.11,
31.05,100.10,
31.07,100.08,
31.09,100.05,
31.11,100.01,
31.13,99.95,
31.15,99.89,
31.17,99.81,
31.19,99.73,
31.21,99.65,
31.23,99.56,
31.25,99.47,
31.27,99.38,
31.29,99.29,
31.31,99.20,
31.33,99.10,
31.35,99.01,
31.37,98.91,
31.39,98.81,
31.41,98.72,
31.43,98.62,
31.45,98.52,
31.47,98.42,
31.49,98.33,
31.51,98.23,
31.53,98.13,
31.55,98.03,
31.57,97.93,
31.59,97.83,
31.61,97.73,
31.63,97.64,
31.65,97.54,
31.67,97.44,
31.69,97.34,
31.71,97.24,
31.73,97.14,
31.75,97.04,
31.77,96.95,
31.79,96.85,
31.81,96.75,
31.83,96.65,
31.85,96.55,
31.87,96.45,
31.89,96.35,
31.91,96.25,
31.93,96.15,
31.95,96.05,
31.97,95.95,
31.99,95.85,
32.01,95.75,
32.03,95.65,
32.05,95.55,
32.07,95.45,
32.09,95.35,
32.11,95.26,
32.13,95.15,
32.15,95.06,
32.17,94.96,
32.19,94.86,
32.21,94.76,
32.23,94.66,
32.25,94.56,
32.27,94.46,
32.29,94.36,
32.31,94.26,
32.33,94.16,
32.35,94.06,
32.37,93.96,
32.39,93.86,
32.41,93.76,
32.43,93.66,
32.45,93.56,
32.47,93.46,
32.49,93.36,
32.51,93.26,
32.53,93.16,
32.55,93.06,
32.57,92.96,
32.59,92.86,
32.61,92.76,
32.63,92.66,
32.65,92.56,
32.67,92.46,
32.69,92.36,
32.71,92.26,
32.73,92.16,
32.75,92.06,
32.77,91.96,
32.79,91.86,
32.81,91.76,
32.83,91.66,
32.85,91.56,
32.87,91.46,
32.89,91.36,
32.91,91.26,
32.93,91.16,
32.95,91.06,
32.97,90.96,
32.99,90.86,
33.01,90.76,
33.03,90.66,
33.05,90.56,
33.07,90.46,
33.09,90.36,
33.11,90.26,
33.13,90.16,
33.15,90.06,
33.17,89.96,
33.19,89.87,
33.21,89.76,
33.23,89.67,
33.25,89.56,
33.27,89.47,
33.29,89.37,
33.31,89.27,
33.33,89.17,
33.35,89.07,
33.37,88.97,
33.39,88.87,
33.41,88.76,
33.43,88.67,
33.45,88.56,
33.47,88.46,
33.49,88.36,
33.51,88.26,
33.53,88.16,
33.55,88.07,
33.57,87.96,
33.59,87.87,
33.61,87.77,
33.63,87.66,
33.65,87.56,
33.67,87.46,
33.69,87.36,
33.71,87.26,
33.73,87.16,
33.75,87.06,
33.77,86.97,
33.79,86.87,
33.81,86.77,
33.83,86.67,
33.85,86.57,
33.87,86.47,
33.89,86.37,
33.91,86.27,
33.93,86.17,
33.95,86.07,
33.97,85.97,
33.99,85.87,
34.01,85.77,
34.03,85.67,
34.05,85.57,
34.07,85.47,
34.09,85.37,
34.11,85.27,
34.13,85.17,
34.15,85.07,
34.17,84.97,
34.19,84.87,
34.21,84.77,
34.23,84.67,
34.25,84.57,
34.27,84.47,
34.29,84.37,
34.31,84.27,
34.33,84.17,
34.35,84.07,
34.37,83.97,
34.39,83.87,
34.41,83.77,
34.43,83.67,
34.45,83.57,
34.47,83.47,
34.49,83.37,
34.51,83.27,
34.53,83.17,
34.55,83.07,
34.57,82.97,
34.59,82.87,
34.61,82.77,
34.63,82.67,
34.65,82.57,
34.67,82.47,
34.69,82.37,
34.71,82.27,
34.73,82.17,
34.75,82.07,
34.77,81.97,
34.79,81.87,
34.81,81.77,
34.83,81.67,
34.85,81.57,
34.87,81.47,
34.89,81.37,
34.91,81.27,
34.93,81.17,
34.95,81.07,
34.97,80.97,
34.99,80.87,
35.01,80.77,
35.03,80.67,
35.05,80.57,
35.07,80.47,
35.09,80.37,
35.11,80.27,
35.13,80.17,
35.15,80.07,
35.17,79.97,
35.19,79.87,
35.21,79.77,
35.23,79.67,
35.25,79.57,
35.27,79.47,
35.29,79.37,
35.31,79.27,
35.33,79.17,
35.35,79.07,
35.37,78.97,
35.39,78.87,
35.41,78.77,
35.43,78.67,
35.45,78.57,
35.47,78.47,
35.49,78.37,
35.51,78.27,
35.53,78.17,
35.55,78.07,
35.57,77.97,
35.59,77.87,
35.61,77.77,
35.63,77.67,
35.65,77.57,
35.67,77.47,
35.69,77.37,
35.71,77.27,
35.73,77.17,
35.75,77.07,
35.77,76.97,
35.79,76.87,
35.81,76.77,
35.83,76.67,
35.85,76.57,
35.87,76.47,
35.89,76.37,
35.91,76.27,
35.93,76.17,
35.95,76.07,
35.97,75.97,
35.99,75.87,
36.01,75.77,
36.03,75.67,
36.05,75.57,
36.07,75.47,
36.09,75.37,
36.11,75.27,
36.13,75.17,
36.15,75.07,
36.17,74.97,
36.19,74.87,
36.21,74.77,
36.23,74.67,
36.25,74.57,
36.27,74.47,
36.29,74.37,
36.31,74.27,
36.33,74.17,
36.35,74.07,
36.37,73.97,
36.39,73.87,
36.41,73.77,
36.43,73.67,
36.45,73.58,
36.47,73.48,
36.49,73.37,
36.51,73.27,
36.53,73.17,
36.55,73.07,
36.57,72.98,
36.59,72.88,
36.61,72.78,
36.63,72.68,
36.65,72.58,
36.67,72.48,
36.69,72.38,
36.71,72.27,
36.73,72.17,
36.75,72.07,
36.77,71.97,
36.79,71.87,
36.81,71.77,
36.83,71.67,
36.85,71.57,
36.87,71.47,
36.89,71.38,
36.91,71.27,
36.93,71.17,
36.95,71.08,
36.97,70.97,
36.99,70.87,
37.01,70.77,
37.03,70.68,
37.05,70.57,
37.07,70.48,
37.09,70.38,
37.11,70.28,
37.13,70.18,
37.15,70.08,
37.17,69.98,
37.19,69.88,
37.21,69.78,
37.23,69.68,
37.25,69.58,
37.27,69.48,
37.29,69.38,
37.31,69.28,
37.33,69.18,
37.35,69.08,
37.37,68.98,
37.39,68.88,
37.41,68.78,
37.43,68.68,
37.45,68.58,
37.47,68.48,
37.49,68.38,
37.51,68.28,
37.53,68.18,
37.55,68.08,
37.57,67.98,
37.59,67.88,
37.61,67.78,
37.63,67.68,
37.65,67.58,
37.67,67.48,
37.69,67.38,
37.71,67.28,
37.73,67.18,
37.75,67.08,
37.77,66.98,
37.79,66.88,
37.81,66.78,
37.83,66.68,
37.85,66.58,
37.87,66.48,
37.89,66.38,
37.91,66.28,
37.93,66.18,
37.95,66.08,
37.97,65.98,
37.99,65.88,
38.01,65.78,
38.03,65.68,
38.05,65.58,
38.07,65.48,
38.09,65.38,
38.11,65.28,
38.13,65.18,
38.15,65.08,
38.17,64.98,
38.19,64.88,
38.21,64.78,
38.23,64.68,
38.25,64.58,
38.27,64.48,
38.29,64.38,
38.31,64.28,
38.33,64.18,
38.35,64.08,
38.37,63.98,
38.39,63.88,
38.41,63.78,
38.43,63.68,
38.45,63.58,
38.47,63.48,
38.49,63.38,
38.51,63.28,
38.53,63.18,
38.55,63.08,
38.57,62.98,
38.59,62.88,
38.61,62.78,
38.63,62.68,
38.65,62.58,
38.67,62.48,
38.69,62.38,
38.71,62.28,
38.73,62.18,
38.75,62.08,
38.77,61.98,
38.79,61.88,
38.81,61.78,
38.83,61.68,
38.85,61.58,
38.87,61.48,
38.89,61.38,
38.91,61.28,
38.93,61.18,
38.95,61.08,
38.97,60.98,
38.99,60.88,
39.01,60.78,
39.03,60.68,
39.05,60.58,
39.07,60.48,
39.09,60.38,
39.11,60.28,
39.13,60.18,
39.15,60.08,
39.17,59.98,
39.19,59.88,
39.21,59.78,
39.23,59.68,
39.25,59.58,
39.27,59.48,
39.29,59.38,
39.31,59.28,
39.33,59.18,
39.35,59.08,
39.37,58.98,
39.39,58.88,
39.41,58.78,
39.43,58.68,
39.45,58.58,
39.47,58.48,
39.49,58.38,
39.51,58.28,
39.53,58.18,
39.55,58.08,
39.57,57.98,
39.59,57.88,
39.61,57.78,
39.63,57.68,
39.65,57.58,
39.67,57.48,
39.69,57.38,
39.71,57.28,
39.73,57.18,
39.75,57.08,
39.77,56.98,
39.79,56.88,
39.81,56.78,
39.83,56.68,
39.85,56.58,
39.87,56.48,
39.89,56.38,
39.91,56.28,
39.93,56.18,
39.95,56.08,
39.97,55.98,
39.99,55.88,
40.01,55.78,
40.03,55.68,
40.05,55.58,
40.07,55.48,
40.09,55.38,
40.11,55.28,
40.13,55.18,
40.15,55.08,
40.17,54.98,
40.19,54.88,
40.21,54.78,
40.23,54.68,
40.25,54.58,
40.27,54.48,
40.29,54.38,
40.31,54.28,
40.33,54.18,
40.35,54.08,
40.37,53.98,
40.39,53.88,
40.41,53.79,
40.43,53.69,
40.45,53.58,
40.47,53.48,
40.49,53.39,
40.51,53.28,
40.53,53.18,
40.55,53.08,
40.57,52.98,
40.59,52.88,
40.61,52.78,
40.63,52.68,
40.65,52.58,
40.67,52.48,
40.69,52.38,
40.71,52.28,
40.73,52.18,
40.75,52.08,
40.77,51.98,
40.79,51.88,
40.81,51.78,
40.83,51.68,
40.85,51.58,
40.87,51.48,
40.89,51.38,
40.91,51.28,
40.93,51.18,
40.95,51.08,
40.97,50.98,
40.99,50.88,
41.01,50.78,
41.03,50.69,
41.05,50.59,
41.07,50.49,
41.09,50.39,
41.11,50.29,
41.13,50.19,
41.15,50.08,
41.17,49.98,
41.19,49.88,
41.21,49.79,
41.23,49.69,
41.25,49.59,
41.27,49.49,
41.29,49.39,
41.31,49.29,
41.33,49.19,
41.35,49.09,
41.37,48.99,
41.39,48.89,
41.41,48.79,
41.43,48.69,
41.45,48.59,
41.47,48.49,
41.49,48.39,
41.51,48.29,
41.53,48.19,
41.55,48.09,
41.57,47.99,
41.59,47.89,
41.61,47.79,
41.63,47.69,
41.65,47.59,
41.67,47.49,
41.69,47.39,
41.71,47.29,
41.73,47.19,
41.75,47.09,
41.77,46.99,
41.79,46.89,
41.81,46.79,
41.83,46.69,
41.85,46.59,
41.87,46.49,
41.89,46.39,
41.91,46.29,
41.93,46.19,
41.95,46.09,
41.97,45.99,
41.99,45.89,
42.01,45.79,
42.03,45.69,
42.05,45.59,
42.07,45.49,
42.09,45.39,
42.11,45.29,
42.13,45.19,
42.15,45.09,
42.17,44.99,
42.19,44.89,
42.21,44.79,
42.23,44.69,
42.25,44.59,
42.27,44.49,
42.29,44.39,
42.31,44.29,
42.33,44.19,
42.35,44.09,
42.37,43.99,
42.39,43.89,
42.41,43.79,
42.43,43.69,
42.45,43.59,
42.47,43.49,
42.49,43.39,
42.51,43.29,
42.53,43.19,
42.55,43.09,
42.57,42.99,
42.59,42.89,
42.61,42.79,
42.63,42.69,
42.65,42.59,
42.67,42.49,
42.69,42.39,
42.71,42.29,
42.73,42.19,
42.75,42.09,
42.77,41.99,
42.79,41.89,
42.81,41.79,
42.83,41.69,
42.85,41.59,
42.87,41.49,
42.89,41.39,
42.91,41.29,
42.93,41.19,
42.95,41.09,
42.97,40.99,
42.99,40.89,
43.01,40.79,
43.03,40.69,
43.05,40.59,
43.07,40.49,
43.09,40.39,
43.11,40.29,
43.13,40.19,
43.15,40.09,
43.17,39.99,
43.19,39.89,
43.21,39.79,
43.23,39.69,
43.25,39.59,
43.27,39.49,
43.29,39.39,
43.31,39.29,
43.33,39.19,
43.35,39.09,
43.37,38.99,
43.39,38.89,
43.41,38.79,
43.43,38.69,
43.45,38.59,
43.47,38.49,
43.49,38.39,
43.51,38.29,
43.53,38.19,
43.55,38.09,
43.57,37.99,
43.59,37.89,
43.61,37.79,
43.63,37.69,
43.65,37.59,
43.67,37.49,
43.69,37.39,
43.71,37.29,
43.73,37.19,
43.75,37.09,
43.77,36.99,
43.79,36.89,
43.81,36.79,
43.83,36.69,
43.85,36.59,
43.87,36.49,
43.89,36.39,
43.91,36.29,
43.93,36.19,
43.95,36.09,
43.97,35.99,
43.99,35.89,
44.01,35.79,
44.03,35.69,
44.05,35.59,
44.07,35.49,
44.09,35.39,
44.11,35.29,
44.13,35.19,
44.15,35.09,
44.17,34.99,
44.19,34.89,
44.21,34.79,
44.23,34.69,
44.25,34.59,
44.27,34.49,
44.29,34.39,
44.31,34.29,
44.33,34.19,
44.35,34.09,
44.37,33.99,
44.39,33.89,
44.41,33.79,
44.43,33.69,
44.45,33.59,
44.47,33.49,
44.49,33.39,
44.51,33.29,
44.53,33.19,
44.55,33.09,
44.57,32.99,
44.59,32.89,
44.61,32.79,
44.63,32.69,
44.65,32.59,
44.67,32.49,
44.69,32.39,
44.71,32.29,
44.73,32.19,
44.75,32.09,
44.77,31.99,
44.79,31.89,
44.81,31.79,
44.83,31.69,
44.85,31.59,
44.87,31.49,
44.89,31.39,
44.91,31.29,
44.93,31.19,
44.95,31.09,
44.97,30.99,
44.99,30.89,
45.01,30.80,
45.03,30.70,
45.05,30.59,
45.07,30.49,
45.09,30.39,
45.11,30.29,
45.13,30.19,
45.15,30.09,
45.17,29.99,
45.19,29.89,
45.21,29.79,
45.23,29.69,
45.25,29.59,
45.27,29.49,
45.29,29.40,
45.31,29.29,
45.33,29.19,
45.35,29.10,
45.37,28.99,
45.39,28.89,
45.41,28.80,
45.43,28.69,
45.45,28.60,
45.47,28.49,
45.49,28.40,
45.51,28.30,
45.53,28.20,
45.55,28.10,
45.57,27.99,
45.59,27.90,
45.61,27.79,
45.63,27.70,
45.65,27.60,
45.67,27.50,
45.69,27.40,
45.71,27.30,
45.73,27.20,
45.75,27.10,
45.77,27.00,
45.79,26.90,
45.81,26.80,
45.83,26.70,
45.85,26.60,
45.87,26.50,
45.89,26.40,
45.91,26.30,
45.93,26.20,
45.95,26.10,
45.97,26.00,
45.99,25.90,
46.01,25.80,
46.03,25.70,
46.05,25.60,
46.07,25.50,
46.09,25.40,
46.11,25.30,
46.13,25.20,
46.15,25.10,
46.17,25.00,
46.19,24.90,
46.21,24.80,
46.23,24.70,
46.25,24.60,
46.27,24.50,
46.29,24.40,
46.31,24.30,
46.33,24.20,
46.35,24.10,
46.37,24.00,
46.39,23.90,
46.41,23.80,
46.43,23.70,
46.45,23.60,
46.47,23.50,
46.49,23.40,
46.51,23.30,
46.53,23.20,
46.55,23.10,
46.57,23.00,
46.59,22.90,
46.61,22.80,
46.63,22.70,
46.65,22.60,
46.67,22.50,
46.69,22.40,
46.71,22.30,
46.73,22.20,
46.75,22.10,
46.77,22.00,
46.79,21.90,
46.81,21.80,
46.83,21.70,
46.85,21.60,
46.87,21.50,
46.89,21.40,
46.91,21.30,
46.93,21.20,
46.95,21.10,
46.97,21.00,
46.99,20.90,
47.01,20.80,
47.03,20.70,
47.05,20.60,
47.07,20.50,
47.09,20.40,
47.11,20.30,
47.13,20.20,
47.15,20.10,
47.17,20.00,
47.19,19.90,
47.21,19.80,
47.23,19.70,
47.25,19.60,
47.27,19.50,
47.29,19.40,
47.31,19.30,
47.33,19.20,
47.35,19.10,
47.37,19.00,
47.39,18.90,
47.41,18.80,
47.43,18.70,
47.45,18.60,
47.47,18.50,
47.49,18.40,
47.51,18.30,
47.53,18.20,
47.55,18.10,
47.57,18.00,
47.59,17.90,
47.61,17.80,
47.63,17.70,
47.65,17.60,
47.67,17.50,
47.69,17.40,
47.71,17.30,
47.73,17.20,
47.75,17.10,
47.77,17.00,
47.79,16.90,
47.81,16.80,
47.83,16.70,
47.85,16.60,
47.87,16.50,
47.89,16.40,
47.91,16.30,
47.93,16.20,
47.95,16.10,
47.97,16.00,
47.99,15.90,
48.01,15.80,
48.03,15.70,
48.05,15.60,
48.07,15.50,
48.09,15.40,
48.11,15.30,
48.13,15.20,
48.15,15.10,
48.17,15.00,
48.19,14.90,
48.21,14.80,
48.23,14.70,
48.25,14.60,
48.27,14.50,
48.29,14.40,
48.31,14.30,
48.33,14.20,
48.35,14.10,
48.37,14.00,
48.39,13.90,
48.41,13.80,
48.43,13.70,
48.45,13.60,
48.47,13.50,
48.49,13.40,
48.51,13.30,
48.53,13.20,
48.55,13.09,
48.57,12.99,
48.59,12.90,
48.61,12.79,
48.63,12.70,
48.65,12.60,
48.67,12.50,
48.69,12.40,
48.71,12.30,
48.73,12.20,
48.75,12.10,
48.77,12.00,
48.79,11.90,
48.81,11.80,
48.83,11.70,
48.85,11.60,
48.87,11.50,
48.89,11.40,
48.91,11.30,
48.93,11.20,
48.95,11.10,
48.97,11.01,
48.99,10.90,
49.01,10.81,
49.03,10.71,
49.05,10.61,
49.07,10.51,
49.09,10.41,
49.11,10.31,
49.13,10.21,
49.15,10.11,
49.17,10.01,
49.19,9.91,
49.21,9.81,
49.23,9.71,
49.25,9.61,
49.27,9.51,
49.29,9.41,
49.31,9.31,
49.33,9.21,
49.35,9.11,
49.37,9.01,
49.39,8.91,
49.41,8.81,
49.43,8.71,
49.45,8.61,
49.47,8.50,
49.49,8.40,
49.51,8.30,
49.53,8.21,
49.55,8.11,
49.57,8.01,
49.59,7.90,
49.61,7.80,
49.63,7.70,
49.65,7.61,
49.67,7.51,
49.69,7.41,
49.71,7.31,
49.73,7.20,
49.75,7.10,
49.77,7.01,
49.79,6.91,
49.81,6.81,
49.83,6.70,
49.85,6.61,
49.87,6.51,
49.89,6.41,
49.91,6.31,
49.93,6.21,
49.95,6.11,
49.97,6.01,
49.99,5.91,
50.01,5.81,
50.03,5.71,
50.05,5.61,
50.07,5.51,
50.09,5.41,
50.11,5.30,
50.13,5.21,
50.15,5.11,
50.17,5.01,
50.19,4.91,
50.21,4.81,
50.23,4.71,
50.25,4.61,
50.27,4.51,
50.29,4.41,
50.31,4.31,
50.33,4.21,
50.35,4.10,
50.37,4.01,
50.39,3.91,
50.41,3.81,
50.43,3.71,
50.45,3.61,
50.47,3.50,
50.49,3.41,
50.51,3.31,
50.53,3.21,
50.55,3.11,
50.57,3.01,
50.59,2.91,
50.61,2.81,
50.63,2.71,
50.65,2.61,
50.67,2.51,
50.69,2.41,
50.71,2.31,
50.73,2.21,
50.75,2.11,
50.77,2.01,
50.79,1.91,
50.81,1.81,
50.83,1.71,
50.85,1.61,
50.87,1.51,
50.89,1.41,
50.91,1.31,
50.93,1.21,
50.95,1.11,
50.97,1.01,
50.99,0.91,
51.01,0.81,
51.03,0.71,
51.05,0.61,
51.07,0.51,
51.09,0.41,
51.11,0.31,
51.13,0.21,
51.15,0.11,
51.17,0.01,
51.19,-0.09,
51.21,-0.19,
51.23,-0.29,
51.25,-0.39,
51.27,-0.49,
51.29,-0.59,
51.31,-0.69,
51.33,-0.79,
51.35,-0.89,
51.37,-0.99,
51.39,-1.09,
51.41,-1.19,
51.43,-1.29,
51.45,-1.39,
51.47,-1.49,
51.49,-1.59,
51.51,-1.69,
51.53,-1.79,
51.55,-1.89,
51.57,-1.99,
51.59,-2.09,
51.61,-2.19,
51.63,-2.29,
51.65,-2.39,
51.67,-2.49,
51.69,-2.59,
51.71,-2.69,
51.73,-2.79,
51.75,-2.89,
51.77,-2.99,
51.79,-3.09,
51.81,-3.19,
51.83,-3.29,
[...]
228.72,22.95,,0.057
228.75,23.10,,0.056
228.78,23.25,,0.057
228.81,23.40,,0.057
228.84,23.55,,0.057
228.87,23.70,,0.056
228.90,23.85,,0.056
228.93,24.00,,0.056
228.96,24.15,,0.056
228.99,24.30,,0.056
229.02,24.45,,0.056
229.05,24.60,,0.056
229.08,24.75,,0.057
229.11,24.90,,0.057
229.14,25.05,,0.057
229.17,25.20,,0.057
229.20,25.35,,0.057
229.23,25.50,,0.057
229.26,25.65,,0.057
229.29,25.80,,0.057
229.32,25.95,,0.057
229.35,26.10,,0.057
229.38,26.25,,0.057
229.41,26.40,,0.057
229.44,26.55,,0.057
229.47,26.70,,0.057
229.50,26.85,,0.057
229.53,27.00,,0.057
229.56,27.15,,0.057
229.59,27.30,,0.057
229.62,27.45,,0.057
229.65,27.60,,0.057
229.68,27.75,,0.057
229.71,27.91,,0.057
229.74,28.06,,0.057
229.77,28.21,,0.057
229.80,28.36,,0.057
229.83,28.50,,0.057
229.86,28.65,,0.057
229.89,28.81,,0.057
229.92,28.96,,0.057
229.95,29.11,,0.057
229.98,29.26,,0.057
230.01,29.41,,0.057
230.04,29.56,,0.057
230.07,29.71,,0.057
230.10,29.86,,0.057
230.13,30.01,,0.057
230.16,30.16,,0.057
230.19,30.31,,0.057
230.22,30.46,,0.057
230.25,30.61,,0.057
230.28,30.76,,0.057
230.31,30.91,,0.057
230.34,31.06,,0.057
230.37,31.21,,0.057
230.40,31.36,,0.057
230.43,31.51,,0.057
230.46,31.66,,0.057
230.49,31.81,,0.057
230.52,31.96,,0.057
230.55,32.11,,0.057
230.58,32.26,,0.057
230.61,32.41,,0.057
230.64,32.56,,0.057
230.67,32.71,,0.057
230.70,32.86,,0.057
230.73,33.01,,0.057
230.76,33.16,,0.057
230.79,33.31,,0.057
230.82,33.46,,0.057
230.85,33.61,,0.057
230.88,33.76,,0.057
230.91,33.91,,0.057
230.94,34.06,,0.057
230.97,34.21,,0.058
231.00,34.36,,0.058
231.03,34.51,,0.057
231.06,34.66,,0.057
231.09,34.81,,0.058
231.12,34.96,,0.058
231.15,35.11,,0.058
231.18,35.26,,0.058
231.21,35.41,,0.058
231.24,35.56,,0.058
231.27,35.71,,0.058
231.30,35.86,,0.058
231.33,36.01,,0.058
231.36,36.16,,0.058
231.39,36.31,,0.058
231.42,36.46,,0.058
231.45,36.61,,0.058
231.48,36.76,,0.058
231.51,36.91,,0.058
231.54,37.06,,0.058
231.57,37.21,,0.058
231.60,37.36,,0.059
231.63,37.51,,0.059
231.66,37.66,,0.059
231.69,37.81,,0.059
231.72,37.96,,0.059
231.75,38.11,,0.059
231.78,38.26,,0.059
231.81,38.41,,0.059
231.84,38.56,,0.059
231.87,38.71,,0.059
231.90,38.86,,0.059
231.93,39.01,,0.059
231.96,39.16,,0.059
231.99,39.31,,0.059
232.02,39.46,,0.059
232.05,39.61,,0.059
232.08,39.76,,0.059
232.11,39.91,,0.059
232.14,40.06,,0.059
232.17,40.21,,0.059
232.20,40.36,,0.059
232.23,40.51,,0.059
232.26,40.66,,0.059
232.29,40.81,,0.059
232.32,40.96,,0.059
232.35,41.11,,0.059
232.38,41.26,,0.059
232.41,41.41,,0.059
232.44,41.57,,0.059
232.47,41.71,,0.059
232.50,41.86,,0.059
232.53,42.01,,0.059
232.56,42.17,,0.059
232.59,42.32,,0.059
232.62,42.47,,0.059
232.65,42.61,,0.059
232.68,42.77,,0.059
232.71,42.92,,0.059
232.74,43.07,,0.059
232.77,43.21,,0.059
232.80,43.37,,0.059
232.83,43.52,,0.059
232.86,43.67,,0.059
232.89,43.82,,0.060
232.92,43.97,,0.059
232.95,44.11,,0.059
232.98,44.27,,0.060
233.01,44.42,,0.060
233.04,44.57,,0.060
233.07,44.71,,0.060
233.10,44.87,,0.060
233.13,45.02,,0.060
233.16,45.17,,0.060
233.19,45.32,,0.060
233.22,45.47,,0.060
233.25,45.62,,0.060
233.28,45.77,,0.060
233.31,45.92,,0.061
233.34,46.07,,0.061
233.37,46.22,,0.060
233.40,46.37,,0.061
233.43,46.52,,0.061
233.46,46.67,,0.061
233.49,46.82,,0.060
233.52,46.97,,0.061
233.55,47.12,,0.061
233.58,47.27,,0.061
233.61,47.42,,0.061
233.64,47.57,,0.061
233.67,47.72,,0.061
233.70,47.87,,0.061
233.73,48.02,,0.061
233.76,48.17,,0.061
233.79,48.32,,0.061
233.82,48.47,,0.061
233.85,48.62,,0.061
233.88,48.77,,0.061
233.91,48.92,,0.061
233.94,49.07,,0.061
233.97,49.22,,0.061
234.00,49.37,,0.061
234.03,49.52,,0.061
234.06,49.67,,0.061
234.09,49.82,,0.061
234.12,49.97,,0.061
234.15,50.12,,0.061
234.18,50.27,,0.061
234.21,50.42,,0.061
234.24,50.57,,0.061
234.27,50.72,,0.061
234.30,50.87,,0.061
234.33,51.02,,0.061
234.36,51.17,,0.061
234.39,51.32,,0.062
234.42,51.47,,0.061
234.45,51.62,,0.061
234.48,51.77,,0.061
234.51,51.92,,0.061
234.54,52.07,,0.061
234.57,52.22,,0.061
234.60,52.37,,0.061
234.63,52.52,,0.061
234.66,52.67,,0.062
234.69,52.82,,0.062
234.72,52.97,,0.062
234.75,53.12,,0.062
234.78,53.27,,0.061
234.81,53.42,,0.062
234.84,53.57,,0.062
234.87,53.72,,0.062
234.90,53.87,,0.062
234.93,54.02,,0.062
234.96,54.17,,0.062
234.99,54.32,,0.062
235.02,54.47,,0.062
235.05,54.63,,0.063
235.08,54.78,,0.062
235.11,54.93,,0.062
235.14,55.08,,0.063
235.17,55.23,,0.062
235.20,55.37,,0.063
235.23,55.53,,0.063
235.26,55.67,,0.063
235.29,55.83,,0.063
235.32,55.98,,0.063
235.35,56.12,,0.063
235.38,56.27,,0.063
235.41,56.42,,0.063
235.44,56.58,,0.063
235.47,56.72,,0.063
235.50,56.87,,0.063
235.53,57.03,,0.063
235.56,57.17,,0.063
235.59,57.32,,0.063
235.62,57.47,,0.063
235.65,57.62,,0.063
235.68,57.78,,0.063
235.71,57.93,,0.063
235.74,58.08,,0.063
235.77,58.23,,0.063
235.80,58.38,,0.064
235.83,58.53,,0.064
235.86,58.68,,0.064
235.89,58.83,,0.064
235.92,58.98,,0.064
235.95,59.13,,0.064
235.98,59.28,,0.064
236.01,59.43,,0.064
236.04,59.58,,0.064
236.07,59.72,,0.064
236.10,59.88,,0.064
236.13,60.02,,0.064
236.16,60.18,,0.064
236.19,60.33,,0.065
236.22,60.47,,0.065
236.25,60.63,,0.065
236.28,60.77,,0.065
236.31,60.92,,0.065
236.34,61.07,,0.065
236.37,61.22,,0.065
236.40,61.38,,0.065
236.43,61.52,,0.065
236.46,61.68,,0.065
236.49,61.82,,0.065
236.52,61.97,,0.065
236.55,62.13,,0.065
236.58,62.28,,0.065
236.61,62.43,,0.066
236.64,62.58,,0.066
236.67,62.73,,0.066
236.70,62.88,,0.066
236.73,63.03,,0.066
236.76,63.18,,0.066
236.79,63.33,,0.066
236.82,63.48,,0.066
236.85,63.63,,0.066
236.88,63.78,,0.066
236.91,63.93,,0.066
236.94,64.08,,0.066
236.97,64.23,,0.066
237.00,64.38,,0.066
237.03,64.53,,0.066
237.06,64.68,,0.066
237.09,64.83,,0.067
237.12,64.98,,0.067
237.15,65.13,,0.067
237.18,65.28,,0.067
237.21,65.43,,0.067
237.24,65.58,,0.067
237.27,65.73,,0.067
237.30,65.88,,0.067
237.33,66.03,,0.067
237.36,66.18,,0.067
237.39,66.33,,0.068
237.42,66.48,,0.068
237.45,66.63,,0.068
237.48,66.78,,0.068
237.51,66.93,,0.068
237.54,67.08,,0.068
237.57,67.23,,0.068
237.60,67.38,,0.068
237.63,67.53,,0.068
237.66,67.68,,0.068
237.69,67.83,,0.068
237.72,67.98,,0.068
237.75,68.13,,0.068
237.78,68.28,,0.068
237.81,68.43,,0.068
237.84,68.58,,0.068
237.87,68.73,,0.068
237.90,68.88,,0.068
237.93,69.03,,0.068
237.96,69.18,,0.068
237.99,69.33,,0.068
238.02,69.48,,0.068
238.05,69.63,,0.068
238.08,69.78,,0.068
238.11,69.93,,0.068
238.14,70.08,,0.069
238.17,70.23,,0.068
238.20,70.38,,0.068
238.23,70.53,,0.068
238.26,70.68,,0.068
238.29,70.83,,0.068
238.32,70.98,,0.069
238.35,71.13,,0.069
238.38,71.28,,0.069
238.41,71.43,,0.069
238.44,71.58,,0.069
238.47,71.73,,0.069
238.50,71.88,,0.069
238.53,72.03,,0.069
238.56,72.18,,0.069
238.59,72.33,,0.069
238.62,72.48,,0.069
238.65,72.63,,0.069
238.68,72.78,,0.069
238.71,72.93,,0.069
238.74,73.08,,0.069
238.77,73.23,,0.069
238.80,73.38,,0.069
238.83,73.53,,0.069
238.86,73.68,,0.069
238.89,73.83,,0.069
238.92,73.98,,0.069
238.95,74.13,,0.069
238.98,74.28,,0.069
239.01,74.43,,0.070
239.04,74.58,,0.070
239.07,74.73,,0.070
239.10,74.88,,0.070
239.13,75.03,,0.070
239.16,75.18,,0.070
239.19,75.33,,0.070
239.22,75.48,,0.070
239.25,75.63,,0.070
239.28,75.78,,0.070
239.31,75.93,,0.070
239.34,76.08,,0.070
239.37,76.23,,0.070
239.40,76.38,,0.070
239.43,76.53,,0.070
239.46,76.68,,0.070
239.49,76.83,,0.071
239.52,76.98,,0.071
239.55,77.13,,0.071
239.58,77.28,,0.071
239.61,77.43,,0.071
239.64,77.58,,0.071
239.67,77.73,,0.071
239.70,77.88,,0.071
239.73,78.03,,0.071
239.76,78.18,,0.072
239.79,78.33,,0.072
239.82,78.49,,0.072
239.85,78.64,,0.072
239.88,78.78,,0.072
239.91,78.94,,0.072
239.94,79.09,,0.072
239.97,79.24,,0.072
240.00,79.39,,0.072
240.03,79.54,,0.072
240.06,79.69,,0.072
240.09,79.84,,0.072
240.12,79.99,,0.072
240.15,80.14,,0.072
240.18,80.29,,0.072
240.21,80.44,,0.072
240.24,80.59,,0.072
240.27,80.74,,0.072
240.30,80.89,,0.072
240.33,81.04,,0.072
240.36,81.19,,0.072
240.39,81.34,,0.072
240.42,81.49,,0.073
240.45,81.64,,0.073
240.48,81.79,,0.073
240.51,81.94,,0.073
240.54,82.09,,0.073
240.57,82.24,,0.073
240.60,82.39,,0.073
240.63,82.54,,0.073
240.66,82.69,,0.073
240.69,82.84,,0.073
240.72,82.99,,0.073
240.75,83.14,,0.073
240.78,83.29,,0.073
240.81,83.44,,0.073
240.84,83.59,,0.073
240.87,83.74,,0.073
240.90,83.89,,0.073
240.93,84.04,,0.073
240.96,84.19,,0.073
240.99,84.34,,0.073
241.02,84.49,,0.073
241.05,84.64,,0.073
241.08,84.79,,0.074
241.11,84.94,,0.073
241.14,85.09,,0.073
241.17,85.24,,0.073
241.20,85.39,,0.073
241.23,85.54,,0.074
241.26,85.69,,0.073
241.29,85.84,,0.073
241.32,85.99,,0.073
241.35,86.14,,0.073
241.38,86.29,,0.074
241.41,86.44,,0.074
241.44,86.59,,0.074
241.47,86.74,,0.074
241.50,86.89,,0.074
241.53,87.04,,0.074
241.56,87.19,,0.074
241.59,87.34,,0.074
241.62,87.49,,0.073
241.65,87.64,,0.074
241.68,87.79,,0.074
241.71,87.94,,0.074
241.74,88.09,,0.074
241.77,88.24,,0.074
241.80,88.39,,0.074
241.83,88.54,,0.074
241.86,88.69,,0.075
241.89,88.84,,0.074
241.92,88.99,,0.075
241.95,89.14,,0.075
241.98,89.29,,0.075
242.01,89.44,,0.075
242.04,89.59,,0.075
242.07,89.74,,0.075
242.10,89.89,,0.075
242.13,90.04,,0.075
242.16,90.19,,0.075
242.19,90.34,,0.075
242.22,90.49,,0.076
242.25,90.64,,0.076
242.28,90.79,,0.076
242.31,90.94,,0.076
242.34,91.09,,0.076
242.37,91.24,,0.076
242.40,91.39,,0.076
242.43,91.54,,0.076
242.46,91.69,,0.076
242.49,91.84,,0.076
242.52,91.99,,0.076
242.55,92.14,,0.076
242.58,92.29,,0.077
242.61,92.44,,0.077
242.64,92.59,,0.077
242.67,92.74,,0.077
242.70,92.89,,0.077
242.73,93.04,,0.077
242.76,93.19,,0.077
242.79,93.34,,0.077
242.82,93.49,,0.078
242.85,93.64,,0.078
242.88,93.79,,0.078
242.91,93.94,,0.078
242.94,94.09,,0.078
242.97,94.24,,0.078
243.00,94.39,,0.078
243.03,94.54,,0.078
243.06,94.69,,0.078
243.09,94.84,,0.078
243.12,94.99,,0.079
243.15,95.14,,0.079
243.18,95.29,,0.079
243.21,95.44,,0.079
243.24,95.59,,0.079
243.27,95.74,,0.079
243.30,95.89,,0.079
243.33,96.04,,0.079
243.36,96.19,,0.079
243.39,96.34,,0.079
243.42,96.49,,0.079
243.45,96.64,,0.080
243.48,96.79,,0.080
243.51,96.94,,0.080
243.54,97.09,,0.080
243.57,97.24,,0.080
243.60,97.39,,0.080
243.63,97.54,,0.080
243.66,97.69,,0.080
243.69,97.84,,0.080
243.72,97.99,,0.080
243.75,98.14,,0.080
243.78,98.29,,0.080
243.81,98.44,,0.080
243.84,98.59,,0.080
243.87,98.74,,0.081
243.90,98.90,,0.081
243.93,99.04,,0.081
243.96,99.20,,0.081
243.99,99.35,,0.081
244.02,99.50,,0.081
244.05,99.64,,0.081
244.08,99.80,,0.081
244.11,99.95,,0.081
244.14,100.09,,0.082
244.17,100.24,,0.082
244.20,100.39,,0.082
244.23,100.54,,0.082
244.26,100.69,,0.082
244.29,100.84,,0.081
244.32,100.99,,0.082
244.35,101.15,,0.082
244.38,101.29,,0.082
244.41,101.44,,0.082
244.44,101.60,,0.082
244.47,101.75,,0.083
244.50,101.90,,0.082
244.53,102.05,,0.083
244.56,102.20,,0.083
244.59,102.35,,0.083
244.62,102.50,,0.083
244.65,102.65,,0.083
244.68,102.80,,0.083
244.71,102.95,,0.083
244.74,103.10,,0.083
244.77,103.25,,0.083
244.80,103.40,,0.083
244.83,103.55,,0.083
244.86,103.70,,0.083
244.89,103.85,,0.084
244.92,104.00,,0.084
244.95,104.15,,0.084
244.98,104.30,,0.084
245.01,104.45,,0.084
245.04,104.60,,0.084
245.07,104.75,,0.084
245.10,104.90,,0.084
245.13,105.05,,0.084
245.16,105.20,,0.084
245.19,105.35,,0.084
245.22,105.50,,0.084
245.25,105.65,,0.084
245.28,105.80,,0.084
245.31,105.95,,0.084
245.34,106.10,,0.084
245.37,106.25,,0.085
245.40,106.40,,0.085
245.43,106.55,,0.085
245.46,106.70,,0.085
245.49,106.85,,0.085
245.52,107.00,,0.085
245.55,107.15,,0.085
245.58,107.30,,0.085
245.61,107.45,,0.085
245.64,107.60,,0.086
245.67,107.75,,0.086
245.70,107.90,,0.086
245.73,108.05,,0.086
245.76,108.20,,0.086
245.79,108.35,,0.086
245.82,108.50,,0.086
245.85,108.65,,0.086
245.88,108.80,,0.086
245.91,108.95,,0.086
245.94,109.10,,0.087
245.97,109.25,,0.087
246.00,109.40,,0.086
246.03,109.55,,0.086
246.06,109.70,,0.087
246.09,109.85,,0.087
246.12,110.00,,0.087
246.15,110.15,,0.087
246.18,110.30,,0.087
246.21,110.45,,0.087
246.24,110.60,,0.087
246.27,110.75,,0.087
246.30,110.90,,0.087
246.33,111.05,,0.087
246.36,111.20,,0.087
246.39,111.35,,0.087
246.42,111.50,,0.087
246.45,111.65,,0.087
246.48,111.80,,0.088
246.51,111.95,,0.088
246.54,112.10,,0.088
246.57,112.25,,0.088
246.60,112.40,,0.088
246.63,112.55,,0.088
246.66,112.70,,0.088
246.69,112.85,,0.088
246.72,113.00,,0.088
246.75,113.15,,0.088
246.78,113.30,,0.088
246.81,113.45,,0.089
246.84,113.60,,0.089
246.87,113.75,,0.089
246.90,113.90,,0.089
246.93,114.05,,0.089
246.96,114.20,,0.089
246.99,114.35,,0.089
247.02,114.50,,0.089
247.05,114.65,,0.089
247.08,114.80,,0.090
247.11,114.95,,0.090
247.14,115.10,,0.090
247.17,115.25,,0.090
247.20,115.40,,0.090
247.23,115.55,,0.091
247.26,115.70,,0.090
247.29,115.85,,0.090
247.32,116.00,,0.090
247.35,116.15,,0.090
247.38,116.30,,0.090
247.41,116.45,,0.090
247.44,116.60,,0.090
247.47,116.75,,0.090
247.50,116.90,,0.091
247.53,117.05,,0.091
247.56,117.20,,0.091
247.59,117.35,,0.091
247.62,117.50,,0.091
247.65,117.65,,0.091
247.68,117.80,,0.091
247.71,117.95,,0.091
247.74,118.10,,0.091
247.77,118.25,,0.091
247.80,118.40,,0.091
247.83,118.55,,0.091
247.86,118.70,,0.091
247.89,118.85,,0.091
247.92,119.00,,0.091
247.95,119.15,,0.091
247.98,119.30,,0.091
248.01,119.45,,0.092
248.04,119.60,,0.092
248.07,119.75,,0.092
248.10,119.90,,0.092
248.13,120.05,,0.092
248.16,120.20,,0.092
248.19,120.35,,0.092
248.22,120.50,,0.092
248.25,120.65,,0.092
248.28,120.80,,0.092
248.31,120.95,,0.092
248.34,121.10,,0.092
248.37,121.25,,0.092
248.40,121.40,,0.092
248.43,121.55,,0.092
248.46,121.70,,0.092
248.49,121.85,,0.092
248.52,122.00,,0.093
248.55,122.15,,0.092
248.58,122.30,,0.093
248.61,122.45,,0.093
248.64,122.60,,0.093
248.67,122.75,,0.093
248.70,122.90,,0.093
248.73,123.05,,0.093
248.76,123.20,,0.093
248.79,123.35,,0.093
248.82,123.50,,0.093
248.85,123.65,,0.094
248.88,123.80,,0.094
248.91,123.95,,0.094
248.94,124.10,,0.094
248.97,124.25,,0.094
249.00,124.40,,0.094
249.03,124.55,,0.094
249.06,124.71,,0.094
249.09,124.85,,0.094
249.12,125.00,,0.094
249.15,125.15,,0.094
249.18,125.30,,0.094
249.21,125.45,,0.094
249.24,125.60,,0.094
249.27,125.75,,0.095
249.30,125.90,,0.095
249.33,126.05,,0.095
249.36,126.20,,0.095
249.39,126.36,,0.095
249.42,126.50,,0.095
249.45,126.66,,0.095
249.48,126.80,,0.096
249.51,126.95,,0.096
249.54,127.10,,0.095
249.57,127.26,,0.096
249.60,127.40,,0.096
249.63,127.56,,0.096
249.66,127.71,,0.096
249.69,127.86,,0.097
249.72,128.01,,0.097
249.75,128.16,,0.097
249.78,128.31,,0.097
249.81,128.46,,0.097
249.84,128.61,,0.097
249.87,128.76,,0.097
249.90,128.91,,0.097
249.93,129.06,,0.097
249.96,129.20,,0.097
249.99,129.36,,0.097
250.02,129.51,,0.097
250.05,129.65,,0.097
250.08,129.80,,0.097
250.11,129.96,,0.097
250.14,130.10,,0.097
250.17,130.26,,0.098
250.20,130.41,,0.098
250.23,130.56,,0.098
250.26,130.71,,0.098
250.29,130.86,,0.098
250.32,131.01,,0.098
250.35,131.16,,0.098
250.38,131.31,,0.098
250.41,131.46,,0.098
250.44,131.60,,0.099
250.47,131.76,,0.099
250.50,131.91,,0.099
250.53,132.06,,0.099
250.56,132.21,,0.099
250.59,132.36,,0.099
250.62,132.51,,0.099
250.65,132.66,,0.099
250.68,132.81,,0.099
250.71,132.96,,0.099
250.74,133.11,,0.099
250.77,133.26,,0.099
250.80,133.41,,0.099
250.83,133.56,,0.100
250.86,133.71,,0.100
250.89,133.86,,0.100
250.92,134.01,,0.100
250.95,134.16,,0.100
250.98,134.31,,0.100
251.01,134.46,,0.100
251.04,134.61,,0.100
251.07,134.76,,0.100
251.10,134.91,,0.100
251.13,135.06,,0.100
251.16,135.21,,0.101
251.19,135.36,,0.101
251.22,135.51,,0.101
251.25,135.66,,0.101
251.28,135.81,,0.101
251.31,135.96,,0.101
251.34,136.11,,0.101
251.37,136.26,,0.101
251.40,136.41,,0.101
251.43,136.56,,0.101
251.46,136.71,,0.101
251.49,136.86,,0.101
251.52,137.01,,0.101
251.55,137.16,,0.101
251.58,137.31,,0.101
251.61,137.46,,0.101
251.64,137.61,,0.101
251.67,137.76,,0.101
251.70,137.91,,0.102
251.73,138.06,,0.102
251.76,138.21,,0.102
251.79,138.36,,0.102
251.82,138.51,,0.102
251.85,138.66,,0.102
251.88,138.81,,0.102
251.91,138.96,,0.102
251.94,139.11,,0.103
251.97,139.26,,0.103
252.00,139.41,,0.103
252.03,139.56,,0.103
252.06,139.71,,0.103
252.09,139.86,,0.103
252.12,140.01,,0.103
252.15,140.16,,0.103
252.18,140.31,,0.103
252.21,140.46,,0.103
252.24,140.61,,0.103
252.27,140.76,,0.103
252.30,140.91,,0.103
252.33,141.06,,0.103
252.36,141.21,,0.103
252.39,141.36,,0.104
252.42,141.51,,0.104
252.45,141.66,,0.104
252.48,141.81,,0.104
252.51,141.96,,0.104
252.54,142.11,,0.104
252.57,142.26,,0.105
252.60,142.41,,0.105
252.63,142.56,,0.105
252.66,142.71,,0.105
252.69,142.86,,0.105
252.72,143.01,,0.105
252.75,143.16,,0.105
252.78,143.31,,0.105
252.81,143.46,,0.105
252.84,143.61,,0.105
252.87,143.76,,0.105
252.90,143.91,,0.105
252.93,144.06,,0.105
252.96,144.21,,0.105
252.99,144.36,,0.106
253.02,144.51,,0.106
253.05,144.66,,0.106
253.08,144.81,,0.106
253.11,144.96,,0.106
253.14,145.11,,0.106
253.17,145.26,,0.106
253.20,145.41,,0.106
253.23,145.56,,0.106
253.26,145.71,,0.106
253.29,145.86,,0.106
253.32,146.01,,0.106
253.35,146.16,,0.106
253.38,146.31,,0.107
253.41,146.46,,0.107
253.44,146.61,,0.107
253.47,146.76,,0.107
253.50,146.91,,0.107
253.53,147.06,,0.107
253.56,147.21,,0.107
253.59,147.36,,0.107
253.62,147.51,,0.108
253.65,147.66,,0.108
253.68,147.81,,0.108
253.71,147.96,,0.108
253.74,148.11,,0.108
253.77,148.26,,0.108
253.80,148.41,,0.109
253.83,148.56,,0.109
253.86,148.71,,0.109
253.89,148.86,,0.109
253.92,149.01,,0.109
253.95,149.16,,0.109
253.98,149.31,,0.109
254.01,149.46,,0.109
254.04,149.61,,0.109
254.07,149.76,,0.110
254.10,149.91,,0.110
254.13,150.06,,0.110
254.16,150.21,,0.110
254.19,150.36,,0.110
254.22,150.51,,0.110
254.25,150.66,,0.110
254.28,150.81,,0.110
254.31,150.96,,0.110
254.34,151.11,,0.110
254.37,151.26,,0.110
254.40,151.41,,0.110
254.43,151.56,,0.110
254.46,151.71,,0.110
254.49,151.86,,0.110
254.52,152.01,,0.110
254.55,152.16,,0.110
254.58,152.31,,0.110
254.61,152.46,,0.110
254.64,152.61,,0.110
254.67,152.76,,0.111
254.70,152.91,,0.111
254.73,153.06,,0.111
254.76,153.21,,0.111
254.79,153.36,,0.111
254.82,153.51,,0.111
254.85,153.66,,0.111
254.88,153.81,,0.111
254.91,153.96,,0.111
254.94,154.11,,0.111
254.97,154.26,,0.111
255.00,154.41,,0.111
255.03,154.56,,0.111
255.06,154.71,,0.111
255.09,154.86,,0.111
255.12,155.01,,0.111
255.15,155.16,,0.111
255.18,155.31,,0.111
255.21,155.46,,0.111
255.24,155.61,,0.111
255.27,155.76,,0.111
255.30,155.91,,0.111
255.33,156.06,,0.111
255.36,156.21,,0.111
255.39,156.36,,0.112
255.42,156.51,,0.112
255.45,156.66,,0.112
255.48,156.81,,0.112
255.51,156.96,,0.112
255.54,157.11,,0.112
255.57,157.26,,0.112
255.60,157.41,,0.113
255.63,157.56,,0.113
255.66,157.71,,0.113
255.69,157.86,,0.113
255.72,158.01,,0.113
255.75,158.16,,0.113
255.78,158.31,,0.114
255.81,158.46,,0.114
255.84,158.61,,0.114
255.87,158.76,,0.114
255.90,158.91,,0.114
255.93,159.06,,0.114
255.96,159.21,,0.114
255.99,159.36,,0.114
256.02,159.51,,0.114
256.05,159.66,,0.114
256.08,159.81,,0.114
256.11,159.96,,0.115
256.14,160.11,,0.115
256.17,160.26,,0.115
256.20,160.41,,0.115
256.23,160.56,,0.115
256.26,160.71,,0.115
256.29,160.86,,0.115
256.32,161.01,,0.116
256.35,161.16,,0.116
256.38,161.31,,0.115
256.41,161.46,,0.116
256.44,161.61,,0.116
256.47,161.76,,0.116
256.50,161.91,,0.116
256.53,162.06,,0.116
256.56,162.21,,0.116
256.59,162.36,,0.116
256.62,162.51,,0.116
256.65,162.66,,0.116
256.68,162.81,,0.116
256.71,162.96,,0.116
256.74,163.11,,0.116
256.77,163.26,,0.116
256.80,163.41,,0.116
256.83,163.56,,0.116
256.86,163.71,,0.117
256.89,163.86,,0.116
256.92,164.01,,0.116
256.95,164.16,,0.116
256.98,164.31,,0.116
257.01,164.46,,0.116
257.04,164.61,,0.116
257.07,164.76,,0.117
257.10,164.91,,0.117
257.13,165.06,,0.117
257.16,165.21,,0.117
257.19,165.36,,0.117
257.22,165.51,,0.117
257.25,165.66,,0.117
257.28,165.81,,0.117
257.31,165.96,,0.118
257.34,166.11,,0.118
257.37,166.26,,0.118
257.40,166.41,,0.118
257.43,166.56,,0.118
257.46,166.71,,0.118
257.49,166.86,,0.119
257.52,167.01,,0.119
257.55,167.16,,0.119
257.58,167.31,,0.119
257.61,167.46,,0.119
257.64,167.61,,0.119
257.67,167.76,,0.119
257.70,167.91,,0.120
257.73,168.06,,0.120
257.76,168.21,,0.120
257.79,168.36,,0.120
257.82,168.52,,0.120
257.85,168.66,,0.120
257.88,168.81,,0.120
257.91,168.96,,0.120
257.94,169.11,,
257.97,169.26,,
257.99,,,