File: DSC/2024_11_11_DSC_In_Wire_Std_5Cmin_x3.csv
Filename,2024_11_11_DSC_In_Wire_Std_5Cmin_x3
Instrument name,DSC2A-00468 (192.168.1.100)
Operator,Yarger
rundate,11/11/2024
Sample name,2024_11_11_DSC_In_Wire_Std_5Cmin_x3
proceduresegments,Data Off ; Equilibrate 30.00 °C; Data On ; Ramp 5.00 °C/min to 200.00 °C; Data Off ; Isothermal 1.0 min; Data On ; Ramp 5.00 °C/min to 30.00 °C; Data Off ; Isothermal 1.0 min; Data On ; Ramp 5.00 °C/min to 200.00 °C; Data Off ; Isothermal 1.0 min; Data On ; Ramp 5.00 °C/min to 30.00 °C; Data Off ; Isothermal 1.0 min; Data On ; Ramp 5.00 °C/min to 200.00 °C
[File Parameters]
Run date,11/11/2024 5:39:27 PM
Trios version,5.1.1.46572
Original File Name,
Current File Name,D:\DSC2500\JYarger\2024_11_11_DSC_In_Wire_Std_5Cmin_x3.tri
[Procedure]
Procedure Name,Indium
Sample Name,2024_11_11_DSC_In_Wire_Std_5Cmin_x3
Sample Mass,3.36 mg
Reference Sample Mass,0 mg
Pan Mass,53.42 mg
Pan Number,9
Reference Pan Mass,53.32 mg
Reference Pan Number,10
Pan Type,Tzero Aluminum Hermetic
Comments,Indium Wire Std.
Project Name,ASDs
Operator,Yarger
Test,Custom
Unload Max Temperature,30
Unload Min Temperature,30
Load Max Temperature,30
Load Min Temperature,30
Stop on Gas Flow Error,Yes
[Signal List]
Signal #1,Time (min)
Signal #2,Temperature (°C)
Signal #3,Heat Flow (mW)
Signal #4,Delta T (µV)
Signal #5,Delta Tzero (µV)
Signal #6,Tzero Temperature (°C)
Signal #7,Cell Purge (mL/min)
Signal #8,Heater Temp (°C)
Signal #9,Power Delivered (W)
Signal #10,Reference Junction Temperature (°C)
Signal #11,Flange Temperature (°C)
Signal #12,Heat Flow Phase (rad)
Signal #13,Total Heat Capacity (J/°C)
Signal #14,Heat Capacity (J/°C)
[Configuration]
Company Name,ASU
Instrument Name,DSC2A-00468
Instrument Type,DSC2500
Serial Number,DSC2A-00468
IP,192.168.1.100
Location of Instrument,MRRC
DisplayType,Unknown
Sample Interval ,0.1 s/pt
Selected Heat Flow,T4P
Exotherm Direction,Down
Cell Serial,DRC2-00792
Lid Type,Standard
Cooler,RCS 90
Leave Cooler on at End of Sequence,On
Gas 2,Nitrogen
Gas Selected,Channel 1
Flow Rate,50 mL/min
Secondary Purge,On
Licensed Heat Flow,Heat Flow T4P
Modulation Licensed,Yes
[Versions]
Common IDD Version,1
Cortex Version,VER 2.10.2.31
Driver,5.0.0.6
GDM Version,1.0.3.3
TouchscreenVersion,1.0.0.16145
FEP Version,1.2.1.21
FEP Bootloader,2.0.0.5
AutoSampler Version,2.1.1.26
Auto Sampler Bootloader,2.0.0.5
FCM Version,1.1.0.3
FCM Bootloader,2.0.0.5
[Experiment Logs]
Experiment Log Entry # 1,Data On set to 0
Experiment Log Entry # 3,Equilibrate Segment 30 (C) Started
Experiment Log Entry # 5,Air Cool is off.
Experiment Log Entry # 7,Data On set to 1
Experiment Log Entry # 9,Ramp Segment 5 C/min to 200 Started
Experiment Log Entry # 11,Data On set to 0
Experiment Log Entry # 13,Isothermal Segment 1 min started
Experiment Log Entry # 15,Data On set to 1
Experiment Log Entry # 17,Ramp Segment 5 C/min to 30 Started
Experiment Log Entry # 19,Data On set to 0
Experiment Log Entry # 21,Isothermal Segment 1 min started
Experiment Log Entry # 23,Data On set to 1
Experiment Log Entry # 25,Ramp Segment 5 C/min to 200 Started
Experiment Log Entry # 27,Data On set to 0
Experiment Log Entry # 29,Isothermal Segment 1 min started
Experiment Log Entry # 31,Data On set to 1
Experiment Log Entry # 33,Ramp Segment 5 C/min to 30 Started
Experiment Log Entry # 35,Auto sampler has detected that GDM has gone offline
Experiment Log Entry # 37,Data On set to 0
Experiment Log Entry # 39,Isothermal Segment 1 min started
Experiment Log Entry # 41,Data On set to 1
Experiment Log Entry # 43,Ramp Segment 5 C/min to 200 Started
[Method Log]
Method Log Entry # 1,Data Off
Method Log Entry # 2,Equilibrate 30 °C
Method Log Entry # 3,Data On
Method Log Entry # 4,(Ramp 1117) Ramp 5 °C/minute to 200 °C
Method Log Entry # 5,Data Off
Method Log Entry # 6,Isothermal 1 minutes
Method Log Entry # 7,Data On
Method Log Entry # 8,(Ramp 1121) Ramp 5 °C/minute to 30 °C
Method Log Entry # 9,Data Off
Method Log Entry # 10,Isothermal 1 minutes
Method Log Entry # 11,Data On
Method Log Entry # 12,(Ramp 1125) Ramp 5 °C/minute to 200 °C
Method Log Entry # 13,Data Off
Method Log Entry # 14,Isothermal 1 minutes
Method Log Entry # 15,Data On
Method Log Entry # 16,(Ramp 1129) Ramp 5 °C/minute to 30 °C
Method Log Entry # 17,Data Off
Method Log Entry # 18,Isothermal 1 minutes
Method Log Entry # 19,Data On
Method Log Entry # 20,(Ramp 1133) Ramp 5 °C/minute to 200 °C
Cell Serial,DRC2-00792
[T1 Calibration]
Slope,-0.008529666
Offset,9.636258
Initial Temperature,98.23
GUID,f8bfdadc-4977-4fdf-ba6d-0ba9134940c3
[TZero Calibration]
Date Applied,11/29/2022 4:06:13 PM
Description,From -89.059 °C to 396.009 °C at 20.000°C/min
Gas Type,Nitrogen
Pan Type,None
Source Files 1,C:\Users\yargerlab\Desktop\DSC Data\General\TZero_calibration_11_29_22_2nd(2).tri
Source Files 2,C:\Users\yargerlab\Desktop\DSC Data\General\TZero_calibration_11_29_22_2nd(3).tri
Delta T Offset,13.05235
Delta T Slope,-0.007271007
Delta T0 Offset,-13.69128
Delta T0 Slope,0.06063341
[Temperature Calibration]
Date Applied,11/29/2022 7:12:28 PM
Description,From 106.590 °C to 186.590 °C at 10.000°C/min
Gas Type,Nitrogen
Pan Type,Tzero Aluminum Hermetic
Source Files 1,C:\Users\yargerlab\Desktop\DSC Data\General\Indium(6).tri
Measured 1,157.391
Known 1,156.598
[Cell Constant Calibration]
Date Applied,11/29/2022 7:12:29 PM
Description,From 106.590 °C to 186.590 °C at 10.000°C/min
Gas Type,Nitrogen
Pan Type,Tzero Aluminum Hermetic
Source Files 1,C:\Users\yargerlab\Desktop\DSC Data\General\Indium(6).tri
T4P KCell,1.006051
Onset Slope,63.26126 mW/°C
[Direct Cp Calibration]
Date Applied,11/30/2022 11:04:51 AM
Description,From -79.983 °C to 298.409 °C at 10.000°C/min
Gas Type,Nitrogen
Pan Type,Tzero Aluminum Hermetic
Source Files 1,C:\Users\yargerlab\Desktop\DSC Data\General\Sapphire_Heat_Capacity_11_30_22.tri
[Rev Cp Calibration]
Date Applied,11/30/2022 1:58:51 PM
Description,From -79.996 °C to 292.812 °C at 3.000°C/min
Gas Type,Nitrogen
Pan Type,Tzero Aluminum Hermetic
Source Files 1,C:\Users\yargerlab\Desktop\DSC Data\General\Sapphire_MDSC_Calibration_11_30_22.tri
[step]
Ramp 5.00 °C/min to 200.00 °C
Time,Temperature,Heat Flow (Normalized)
min,°C,W/g
0.00,30.02,-0.011
0.02,30.02,-0.012
0.05,30.04,-0.013
0.07,30.05,-0.018
0.09,30.09,-0.032
0.12,30.14,-0.041
0.14,30.22,-0.042
0.16,30.30,-0.040
0.19,30.39,-0.026
0.21,30.48,-0.014
0.23,30.59,-0.007
0.26,30.69,-0.003
0.28,30.79,0.002
0.30,30.90,0.005
0.33,31.01,0.008
0.35,31.13,0.009
0.37,31.24,0.011
0.40,31.35,0.012
0.42,31.47,0.013
0.44,31.58,0.014
0.47,31.70,0.015
0.49,31.81,0.016
0.51,31.93,0.016
0.54,32.04,0.017
0.56,32.16,0.017
0.58,32.27,0.018
0.61,32.39,0.018
0.63,32.51,0.019
0.65,32.62,0.019
0.68,32.74,0.019
0.70,32.85,0.020
0.72,32.97,0.020
0.75,33.09,0.020
0.77,33.20,0.021
0.79,33.32,0.021
0.82,33.43,0.021
0.84,33.55,0.021
0.86,33.67,0.021
0.89,33.78,0.022
0.91,33.90,0.022
0.93,34.02,0.022
0.96,34.13,0.022
0.98,34.25,0.022
1.00,34.37,0.022
1.03,34.48,0.022
1.05,34.60,0.022
1.07,34.71,0.022
1.10,34.83,0.022
1.12,34.95,0.022
1.14,35.06,0.022
1.17,35.18,0.022
1.19,35.30,0.022
1.21,35.41,0.022
1.24,35.53,0.022
1.26,35.65,0.022
1.28,35.76,0.022
1.31,35.88,0.022
1.33,36.00,0.023
1.35,36.11,0.022
1.38,36.23,0.023
1.40,36.35,0.023
1.42,36.46,0.023
1.45,36.58,0.023
1.47,36.70,0.022
1.49,36.81,0.023
1.52,36.93,0.022
1.54,37.05,0.022
1.56,37.16,0.022
1.59,37.28,0.022
1.61,37.40,0.022
1.63,37.51,0.022
1.66,37.63,0.022
1.68,37.74,0.022
1.70,37.86,0.022
1.73,37.98,0.022
1.75,38.10,0.022
1.77,38.21,0.022
1.80,38.33,0.022
1.82,38.45,0.022
1.84,38.56,0.022
1.87,38.68,0.022
1.89,38.80,0.022
1.91,38.91,0.022
1.94,39.03,0.022
1.96,39.15,0.022
1.98,39.26,0.022
2.01,39.38,0.022
2.03,39.50,0.022
2.05,39.61,0.022
2.08,39.73,0.022
2.10,39.85,0.022
2.12,39.96,0.022
2.15,40.08,0.022
2.17,40.20,0.022
2.19,40.31,0.022
2.22,40.43,0.022
2.24,40.55,0.021
2.26,40.66,0.021
2.29,40.78,0.021
2.31,40.90,0.021
2.33,41.01,0.021
2.36,41.13,0.021
2.38,41.25,0.021
2.40,41.36,0.021
2.43,41.48,0.021
2.45,41.60,0.021
2.47,41.71,0.021
2.50,41.83,0.021
2.52,41.95,0.021
2.54,42.06,0.021
2.57,42.18,0.021
2.59,42.30,0.021
2.61,42.42,0.021
2.64,42.53,0.021
2.66,42.65,0.021
2.68,42.76,0.021
2.71,42.88,0.021
2.73,43.00,0.021
2.75,43.12,0.021
2.78,43.23,0.021
2.80,43.35,0.021
2.82,43.46,0.021
2.85,43.58,0.021
2.87,43.70,0.021
2.89,43.81,0.021
2.92,43.93,0.021
2.94,44.05,0.021
2.96,44.16,0.021
2.99,44.28,0.021
3.01,44.40,0.021
3.03,44.51,0.021
3.06,44.63,0.021
3.08,44.75,0.021
3.10,44.87,0.021
3.13,44.98,0.021
3.15,45.10,0.021
3.17,45.22,0.021
3.20,45.33,0.021
3.22,45.45,0.021
3.24,45.57,0.021
3.27,45.68,0.021
3.29,45.80,0.021
3.31,45.92,0.021
3.34,46.03,0.021
3.36,46.15,0.021
3.38,46.27,0.021
3.41,46.38,0.021
3.43,46.50,0.021
3.45,46.62,0.021
3.48,46.73,0.021
3.50,46.85,0.021
3.52,46.97,0.021
3.55,47.08,0.021
3.57,47.20,0.021
3.59,47.32,0.021
3.62,47.44,0.021
3.64,47.55,0.021
3.66,47.67,0.021
3.69,47.78,0.021
3.71,47.90,0.021
3.73,48.02,0.021
3.76,48.13,0.021
3.78,48.25,0.021
3.80,48.37,0.021
3.83,48.49,0.021
3.85,48.60,0.021
3.87,48.72,0.021
3.90,48.83,0.021
3.92,48.95,0.021
3.94,49.07,0.021
3.97,49.18,0.021
3.99,49.30,0.021
4.01,49.42,0.020
4.04,49.53,0.020
4.06,49.65,0.020
4.08,49.77,0.020
4.11,49.89,0.020
4.13,50.00,0.020
4.15,50.12,0.020
4.18,50.24,0.020
4.20,50.35,0.020
4.22,50.47,0.020
4.25,50.59,0.020
4.27,50.70,0.020
4.29,50.82,0.020
4.32,50.94,0.020
4.34,51.05,0.020
4.36,51.17,0.020
4.39,51.29,0.020
4.41,51.40,0.020
4.43,51.52,0.020
4.46,51.64,0.020
4.48,51.75,0.020
4.50,51.87,0.020
4.53,51.99,0.020
4.55,52.10,0.020
4.57,52.22,0.020
4.60,52.34,0.020
4.62,52.45,0.020
4.64,52.57,0.020
4.67,52.69,0.020
4.69,52.80,0.020
4.71,52.92,0.020
4.74,53.04,0.020
4.76,53.15,0.020
4.78,53.27,0.020
4.81,53.39,0.020
4.83,53.50,0.020
4.85,53.62,0.020
4.88,53.74,0.020
4.90,53.85,0.020
4.92,53.97,0.020
4.95,54.09,0.020
4.97,54.20,0.020
4.99,54.32,0.020
5.02,54.44,0.020
5.04,54.55,0.020
5.06,54.67,0.020
5.09,54.79,0.020
5.11,54.90,0.020
5.13,55.02,0.020
5.16,55.14,0.020
5.18,55.25,0.020
5.20,55.37,0.020
5.23,55.49,0.020
5.25,55.61,0.020
5.27,55.72,0.020
5.30,55.84,0.020
5.32,55.95,0.020
5.34,56.07,0.020
5.37,56.19,0.020
5.39,56.31,0.020
5.41,56.42,0.020
5.44,56.54,0.020
5.46,56.66,0.020
5.48,56.77,0.020
5.51,56.89,0.020
5.53,57.01,0.020
5.55,57.12,0.020
5.58,57.24,0.020
5.60,57.36,0.020
5.62,57.47,0.020
5.65,57.59,0.020
5.67,57.71,0.020
5.69,57.82,0.020
5.72,57.94,0.020
5.74,58.06,0.020
5.76,58.17,0.020
5.79,58.29,0.020
5.81,58.41,0.020
5.83,58.52,0.020
5.86,58.64,0.020
5.88,58.76,0.020
5.90,58.87,0.020
5.93,58.99,0.020
5.95,59.11,0.020
5.97,59.22,0.020
6.00,59.34,0.020
6.02,59.46,0.020
6.04,59.58,0.020
6.07,59.69,0.020
6.09,59.81,0.020
6.11,59.93,0.020
6.14,60.04,0.020
6.16,60.16,0.020
6.18,60.28,0.020
6.21,60.39,0.020
6.23,60.51,0.020
6.25,60.63,0.020
6.28,60.74,0.020
6.30,60.86,0.020
6.32,60.98,0.020
6.35,61.09,0.020
6.37,61.21,0.020
6.39,61.33,0.020
6.42,61.44,0.020
6.44,61.56,0.020
6.46,61.68,0.020
6.49,61.79,0.020
6.51,61.91,0.020
6.53,62.03,0.020
6.56,62.14,0.020
6.58,62.26,0.020
6.60,62.38,0.020
6.63,62.49,0.020
6.65,62.61,0.020
6.67,62.73,0.020
6.70,62.84,0.020
6.72,62.96,0.020
6.74,63.08,0.020
6.77,63.19,0.020
6.79,63.31,0.020
6.81,63.43,0.020
6.84,63.54,0.020
6.86,63.66,0.020
6.88,63.78,0.020
6.91,63.89,0.020
6.93,64.01,0.020
6.95,64.13,0.020
6.98,64.24,0.020
7.00,64.36,0.020
7.02,64.48,0.020
7.05,64.59,0.020
7.07,64.71,0.020
7.09,64.83,0.020
7.12,64.94,0.020
7.14,65.06,0.020
7.16,65.18,0.020
7.19,65.29,0.020
7.21,65.41,0.020
7.23,65.53,0.019
7.26,65.64,0.020
7.28,65.76,0.019
7.30,65.88,0.019
7.33,65.99,0.019
7.35,66.11,0.019
7.37,66.23,0.019
7.40,66.34,0.019
7.42,66.46,0.019
7.44,66.58,0.019
7.47,66.69,0.019
7.49,66.81,0.019
7.51,66.93,0.020
7.54,67.05,0.020
7.56,67.16,0.020
7.58,67.28,0.020
7.61,67.39,0.019
7.63,67.51,0.019
7.65,67.63,0.019
7.68,67.74,0.020
7.70,67.86,0.019
7.72,67.98,0.019
7.75,68.09,0.019
7.77,68.21,0.019
7.79,68.33,0.019
7.82,68.45,0.019
7.84,68.56,0.019
7.86,68.68,0.019
7.89,68.79,0.019
7.91,68.91,0.019
7.93,69.03,0.019
7.96,69.15,0.019
7.98,69.26,0.019
8.00,69.38,0.019
8.03,69.50,0.019
8.05,69.61,0.020
8.07,69.73,0.020
8.10,69.85,0.019
8.12,69.96,0.019
8.14,70.08,0.019
8.17,70.20,0.020
8.19,70.31,0.020
8.21,70.43,0.020
8.24,70.54,0.019
8.26,70.66,0.020
8.28,70.78,0.020
8.31,70.90,0.020
8.33,71.01,0.020
8.35,71.13,0.020
8.38,71.25,0.020
8.40,71.36,0.020
8.42,71.48,0.020
8.45,71.60,0.020
8.47,71.71,0.020
8.49,71.83,0.020
8.52,71.95,0.020
8.54,72.06,0.020
8.56,72.18,0.020
8.59,72.30,0.020
8.61,72.41,0.020
8.63,72.53,0.020
8.66,72.65,0.020
8.68,72.77,0.020
8.70,72.88,0.020
8.73,73.00,0.020
8.75,73.11,0.020
8.77,73.23,0.020
8.80,73.35,0.020
8.82,73.46,0.020
8.84,73.58,0.020
8.87,73.70,0.020
8.89,73.81,0.020
8.91,73.93,0.020
8.94,74.05,0.020
8.96,74.16,0.020
8.98,74.28,0.020
9.01,74.40,0.020
9.03,74.52,0.020
9.05,74.63,0.020
9.08,74.75,0.020
9.10,74.87,0.020
9.12,74.98,0.020
9.15,75.10,0.020
9.17,75.22,0.020
9.19,75.33,0.020
9.22,75.45,0.020
9.24,75.57,0.020
9.26,75.68,0.020
9.29,75.80,0.020
9.31,75.92,0.020
9.33,76.03,0.020
9.36,76.15,0.020
9.38,76.27,0.020
9.40,76.38,0.020
9.43,76.50,0.020
9.45,76.62,0.020
9.47,76.73,0.020
9.50,76.85,0.020
9.52,76.97,0.020
9.54,77.08,0.020
9.57,77.20,0.020
9.59,77.32,0.020
9.61,77.43,0.020
9.64,77.55,0.020
9.66,77.67,0.020
9.68,77.78,0.020
9.71,77.90,0.020
9.73,78.02,0.020
9.75,78.14,0.020
9.78,78.25,0.020
9.80,78.37,0.020
9.82,78.49,0.020
9.85,78.60,0.020
9.87,78.72,0.020
9.89,78.83,0.020
9.92,78.95,0.020
9.94,79.07,0.020
9.96,79.19,0.020
9.99,79.30,0.020
10.01,79.42,0.020
10.03,79.54,0.020
10.06,79.65,0.020
10.08,79.77,0.020
10.10,79.89,0.020
10.13,80.00,0.020
10.15,80.12,0.020
10.17,80.24,0.020
10.20,80.35,0.020
10.22,80.47,0.020
10.24,80.59,0.020
10.27,80.70,0.020
10.29,80.82,0.020
10.31,80.94,0.020
10.34,81.05,0.020
10.36,81.17,0.020
10.38,81.29,0.020
10.41,81.40,0.020
10.43,81.52,0.020
10.45,81.64,0.020
10.48,81.75,0.020
10.50,81.87,0.020
10.52,81.99,0.020
10.55,82.10,0.020
10.57,82.22,0.020
10.59,82.34,0.020
10.62,82.45,0.020
10.64,82.57,0.020
10.66,82.69,0.020
10.69,82.80,0.019
10.71,82.92,0.019
10.73,83.04,0.019
10.76,83.15,0.019
10.78,83.27,0.019
10.80,83.39,0.020
10.83,83.50,0.019
10.85,83.62,0.019
10.87,83.74,0.019
10.90,83.85,0.019
10.92,83.97,0.019
10.94,84.09,0.019
10.97,84.20,0.020
10.99,84.32,0.019
11.01,84.44,0.019
11.04,84.55,0.019
11.06,84.67,0.019
11.08,84.79,0.019
11.11,84.90,0.020
11.13,85.02,0.019
11.15,85.14,0.019
11.18,85.25,0.019
11.20,85.37,0.019
11.22,85.49,0.019
11.25,85.60,0.019
11.27,85.72,0.019
11.29,85.84,0.019
11.32,85.95,0.019
11.34,86.07,0.019
11.36,86.19,0.019
11.39,86.30,0.019
11.41,86.42,0.019
11.43,86.54,0.019
11.46,86.65,0.019
11.48,86.77,0.019
11.50,86.89,0.019
11.53,87.01,0.019
11.55,87.12,0.019
11.57,87.24,0.019
11.60,87.35,0.019
11.62,87.47,0.019
11.64,87.59,0.019
11.67,87.71,0.019
11.69,87.82,0.019
11.71,87.94,0.019
11.74,88.06,0.019
11.76,88.17,0.019
11.78,88.29,0.019
11.81,88.41,0.019
11.83,88.52,0.019
11.85,88.64,0.019
11.88,88.75,0.019
11.90,88.87,0.019
11.92,88.99,0.020
11.95,89.10,0.020
11.97,89.22,0.020
11.99,89.34,0.020
12.02,89.46,0.019
12.04,89.57,0.020
12.06,89.69,0.020
12.09,89.81,0.020
12.11,89.92,0.020
12.13,90.04,0.020
12.16,90.16,0.020
12.18,90.27,0.020
12.20,90.39,0.020
12.23,90.51,0.020
12.25,90.62,0.020
12.27,90.74,0.020
12.30,90.86,0.020
12.32,90.97,0.020
12.34,91.09,0.020
12.37,91.21,0.020
12.39,91.32,0.020
12.41,91.44,0.020
12.44,91.56,0.020
12.46,91.67,0.020
12.48,91.79,0.020
12.51,91.91,0.020
12.53,92.02,0.020
12.55,92.14,0.020
12.58,92.26,0.020
12.60,92.37,0.020
12.62,92.49,0.020
12.65,92.61,0.020
12.67,92.72,0.020
12.69,92.84,0.020
12.72,92.96,0.020
12.74,93.07,0.020
12.76,93.19,0.020
12.79,93.31,0.020
12.81,93.42,0.020
12.83,93.54,0.020
12.86,93.66,0.020
12.88,93.77,0.020
12.90,93.89,0.020
12.93,94.01,0.020
12.95,94.12,0.020
12.97,94.24,0.020
13.00,94.36,0.020
13.02,94.47,0.020
13.04,94.59,0.020
13.07,94.71,0.020
13.09,94.82,0.020
13.11,94.94,0.020
13.14,95.06,0.020
13.16,95.17,0.020
13.18,95.29,0.020
13.21,95.41,0.020
13.23,95.52,0.020
13.25,95.64,0.020
13.28,95.76,0.020
13.30,95.87,0.020
13.32,95.99,0.020
13.35,96.11,0.020
13.37,96.22,0.020
13.39,96.34,0.020
13.42,96.46,0.020
13.44,96.57,0.020
13.46,96.69,0.020
13.49,96.81,0.020
13.51,96.92,0.020
13.53,97.04,0.020
13.56,97.16,0.020
13.58,97.27,0.020
13.60,97.39,0.020
13.63,97.51,0.021
13.65,97.63,0.021
13.67,97.74,0.020
13.70,97.86,0.020
13.72,97.98,0.020
13.74,98.09,0.020
13.77,98.21,0.020
13.79,98.33,0.020
13.81,98.44,0.020
13.84,98.56,0.020
13.86,98.68,0.021
13.88,98.79,0.020
13.91,98.91,0.021
13.93,99.03,0.021
13.95,99.14,0.021
13.98,99.26,0.021
14.00,99.38,0.021
14.02,99.49,0.021
14.05,99.61,0.021
14.07,99.73,0.021
14.09,99.84,0.021
14.12,99.96,0.021
14.14,100.08,0.021
14.16,100.19,0.021
14.19,100.31,0.021
14.21,100.43,0.021
14.23,100.54,0.021
14.26,100.66,0.021
14.28,100.78,0.021
14.30,100.89,0.021
14.33,101.01,0.021
14.35,101.13,0.021
14.37,101.24,0.021
14.40,101.36,0.021
14.42,101.48,0.021
14.44,101.59,0.021
14.47,101.71,0.021
14.49,101.83,0.020
14.51,101.94,0.020
14.54,102.06,0.020
14.56,102.18,0.020
14.58,102.29,0.021
14.61,102.41,0.021
14.63,102.53,0.021
14.65,102.64,0.021
14.68,102.76,0.020
14.70,102.88,0.021
14.72,102.99,0.021
14.75,103.11,0.021
14.77,103.23,0.021
14.79,103.34,0.021
14.82,103.46,0.021
14.84,103.58,0.021
14.86,103.69,0.021
14.89,103.81,0.021
14.91,103.93,0.021
14.93,104.05,0.021
14.96,104.16,0.021
14.98,104.28,0.021
15.00,104.40,0.021
15.03,104.51,0.021
15.05,104.63,0.021
15.07,104.75,0.021
15.10,104.86,0.021
15.12,104.98,0.021
15.14,105.09,0.021
15.17,105.21,0.021
15.19,105.33,0.021
15.21,105.44,0.021
15.24,105.56,0.021
15.26,105.68,0.021
15.28,105.80,0.021
15.31,105.91,0.021
15.33,106.03,0.021
15.35,106.14,0.021
15.38,106.26,0.021
15.40,106.38,0.021
15.42,106.49,0.021
15.45,106.61,0.021
15.47,106.73,0.021
15.49,106.85,0.021
15.52,106.96,0.021
15.54,107.08,0.021
15.56,107.20,0.021
15.59,107.31,0.021
15.61,107.43,0.021
15.63,107.55,0.021
15.66,107.66,0.021
15.68,107.78,0.021
15.70,107.90,0.021
15.73,108.01,0.021
15.75,108.13,0.021
15.77,108.25,0.021
15.80,108.36,0.021
15.82,108.48,0.021
15.84,108.60,0.021
15.87,108.71,0.021
15.89,108.83,0.021
15.91,108.95,0.021
15.94,109.06,0.021
15.96,109.18,0.021
15.98,109.30,0.021
16.01,109.41,0.021
16.03,109.53,0.021
16.05,109.65,0.021
16.08,109.76,0.021
16.10,109.88,0.021
16.12,110.00,0.021
16.15,110.11,0.021
16.17,110.23,0.021
16.19,110.35,0.021
16.22,110.46,0.021
16.24,110.58,0.021
16.26,110.70,0.021
16.29,110.81,0.021
16.31,110.93,0.021
16.33,111.05,0.021
16.36,111.16,0.021
16.38,111.28,0.021
16.40,111.40,0.021
16.43,111.51,0.021
16.45,111.63,0.021
16.47,111.75,0.021
16.50,111.86,0.021
16.52,111.98,0.021
16.54,112.10,0.021
16.57,112.22,0.021
16.59,112.33,0.021
16.61,112.45,0.021
16.64,112.56,0.021
16.66,112.68,0.021
16.68,112.80,0.021
16.71,112.92,0.021
16.73,113.03,0.021
16.75,113.15,0.021
16.78,113.26,0.021
16.80,113.38,0.021
16.82,113.50,0.021
16.85,113.61,0.021
16.87,113.73,0.021
16.89,113.85,0.021
16.92,113.97,0.021
16.94,114.08,0.021
16.96,114.20,0.021
16.99,114.32,0.021
17.01,114.43,0.021
17.03,114.55,0.021
17.06,114.67,0.021
17.08,114.78,0.021
17.10,114.90,0.021
17.13,115.02,0.021
17.15,115.13,0.021
17.17,115.25,0.021
17.20,115.37,0.021
17.22,115.48,0.021
17.24,115.60,0.021
17.27,115.72,0.021
17.29,115.83,0.021
17.31,115.95,0.021
17.34,116.07,0.021
17.36,116.18,0.021
17.38,116.30,0.021
17.41,116.42,0.021
17.43,116.53,0.021
17.45,116.65,0.021
17.48,116.76,0.021
17.50,116.88,0.021
17.52,117.00,0.021
17.55,117.12,0.021
17.57,117.23,0.021
17.59,117.35,0.021
17.62,117.47,0.021
17.64,117.58,0.021
17.66,117.70,0.021
17.69,117.82,0.021
17.71,117.93,0.021
17.73,118.05,0.021
17.76,118.17,0.021
17.78,118.28,0.021
17.80,118.40,0.021
17.83,118.52,0.021
17.85,118.63,0.021
17.87,118.75,0.021
17.90,118.87,0.021
17.92,118.98,0.021
17.94,119.10,0.021
17.97,119.22,0.021
17.99,119.33,0.021
18.01,119.45,0.021
18.04,119.57,0.021
18.06,119.68,0.021
18.08,119.80,0.021
18.11,119.92,0.021
18.13,120.03,0.021
18.15,120.15,0.021
18.18,120.27,0.021
18.20,120.39,0.021
18.22,120.50,0.021
18.25,120.62,0.021
18.27,120.74,0.021
18.29,120.85,0.021
18.32,120.97,0.021
18.34,121.09,0.022
18.36,121.20,0.021
18.39,121.32,0.021
18.41,121.44,0.021
18.43,121.55,0.022
18.46,121.67,0.022
18.48,121.79,0.022
18.50,121.90,0.022
18.53,122.02,0.022
18.55,122.14,0.022
18.57,122.25,0.022
18.60,122.37,0.022
18.62,122.49,0.022
18.64,122.60,0.022
18.67,122.72,0.022
18.69,122.84,0.021
18.71,122.95,0.021
18.74,123.07,0.021
18.76,123.19,0.021
18.78,123.30,0.021
18.81,123.42,0.021
18.83,123.53,0.021
18.85,123.65,0.021
18.88,123.77,0.021
18.90,123.89,0.021
18.92,124.00,0.021
18.95,124.12,0.022
18.97,124.23,0.022
18.99,124.35,0.022
19.02,124.47,0.022
19.04,124.58,0.022
19.06,124.70,0.022
19.09,124.82,0.022
19.11,124.93,0.022
19.13,125.05,0.022
19.16,125.17,0.022
19.18,125.29,0.022
19.20,125.40,0.022
19.23,125.52,0.022
19.25,125.63,0.022
19.27,125.75,0.022
19.30,125.87,0.021
19.32,125.98,0.022
19.34,126.10,0.022
19.37,126.22,0.022
19.39,126.34,0.022
19.41,126.45,0.022
19.44,126.57,0.022
19.46,126.69,0.021
19.48,126.80,0.022
19.51,126.92,0.021
19.53,127.04,0.022
19.55,127.15,0.021
19.58,127.27,0.022
19.60,127.39,0.022
19.62,127.50,0.022
19.65,127.62,0.022
19.67,127.74,0.022
19.69,127.85,0.021
19.72,127.97,0.021
19.74,128.09,0.021
19.76,128.20,0.021
19.79,128.32,0.021
19.81,128.44,0.021
19.83,128.55,0.021
19.86,128.67,0.021
19.88,128.79,0.021
19.90,128.90,0.021
19.93,129.02,0.022
19.95,129.14,0.021
19.97,129.25,0.022
20.00,129.37,0.021
20.02,129.49,0.022
20.04,129.60,0.022
20.07,129.72,0.022
20.09,129.84,0.022
20.11,129.95,0.022
20.14,130.07,0.022
20.16,130.19,0.021
20.18,130.30,0.021
20.21,130.42,0.021
20.23,130.54,0.021
20.25,130.65,0.021
20.28,130.77,0.021
20.30,130.89,0.021
20.32,131.00,0.021
20.35,131.12,0.021
20.37,131.24,0.021
20.39,131.35,0.021
20.42,131.47,0.021
20.44,131.59,0.022
20.46,131.70,0.021
20.49,131.82,0.021
20.51,131.94,0.022
20.53,132.05,0.022
20.56,132.17,0.021
20.58,132.29,0.022
20.60,132.40,0.022
20.63,132.52,0.022
20.65,132.64,0.021
20.67,132.75,0.022
20.70,132.87,0.022
20.72,132.99,0.022
20.74,133.10,0.022
20.77,133.22,0.022
20.79,133.34,0.022
20.81,133.45,0.022
20.84,133.57,0.022
20.86,133.69,0.022
20.88,133.80,0.022
20.91,133.92,0.022
20.93,134.04,0.022
20.95,134.15,0.022
20.98,134.27,0.022
21.00,134.39,0.022
21.02,134.50,0.022
21.05,134.62,0.022
21.07,134.74,0.022
21.09,134.85,0.022
21.12,134.97,0.022
21.14,135.09,0.022
21.16,135.20,0.022
21.19,135.32,0.022
21.21,135.44,0.022
21.23,135.55,0.022
21.26,135.67,0.022
21.28,135.79,0.022
21.30,135.90,0.022
21.33,136.02,0.022
21.35,136.14,0.022
21.37,136.26,0.022
21.40,136.37,0.022
21.42,136.49,0.022
21.44,136.61,0.022
21.47,136.72,0.022
21.49,136.84,0.022
21.51,136.96,0.022
21.54,137.07,0.022
21.56,137.19,0.022
21.58,137.30,0.022
21.61,137.42,0.022
21.63,137.54,0.022
21.65,137.65,0.022
21.68,137.77,0.022
21.70,137.89,0.022
21.72,138.01,0.022
21.75,138.12,0.022
21.77,138.24,0.022
21.79,138.36,0.022
21.82,138.47,0.022
21.84,138.59,0.022
21.86,138.71,0.022
21.89,138.82,0.022
21.91,138.94,0.022
21.93,139.06,0.022
21.96,139.17,0.022
21.98,139.29,0.022
22.00,139.41,0.022
22.03,139.52,0.022
22.05,139.64,0.023
22.07,139.76,0.022
22.10,139.87,0.023
22.12,139.99,0.023
22.14,140.11,0.023
22.17,140.22,0.023
22.19,140.34,0.023
22.21,140.46,0.023
22.24,140.57,0.023
22.26,140.69,0.023
22.28,140.81,0.023
22.31,140.92,0.023
22.33,141.04,0.023
22.35,141.16,0.023
22.38,141.27,0.023
22.40,141.39,0.023
22.42,141.51,0.023
22.45,141.62,0.023
22.47,141.74,0.023
22.49,141.86,0.023
22.52,141.97,0.023
22.54,142.09,0.023
22.56,142.21,0.023
22.59,142.32,0.023
22.61,142.44,0.023
22.63,142.56,0.023
22.66,142.67,0.023
22.68,142.79,0.023
22.70,142.91,0.023
22.73,143.02,0.023
22.75,143.14,0.023
22.77,143.26,0.023
22.80,143.37,0.023
22.82,143.49,0.023
22.84,143.61,0.023
22.87,143.72,0.023
22.89,143.84,0.023
22.91,143.96,0.023
22.94,144.07,0.023
22.96,144.19,0.023
22.98,144.31,0.023
23.01,144.42,0.023
23.03,144.54,0.023
23.05,144.66,0.023
23.08,144.77,0.023
23.10,144.89,0.023
23.12,145.01,0.023
23.15,145.12,0.023
23.17,145.24,0.023
23.19,145.36,0.023
23.22,145.47,0.023
23.24,145.59,0.023
23.26,145.71,0.023
23.29,145.82,0.023
23.31,145.94,0.023
23.33,146.06,0.023
23.36,146.17,0.023
23.38,146.29,0.023
23.40,146.41,0.023
23.43,146.52,0.023
23.45,146.64,0.023
23.47,146.76,0.023
23.50,146.87,0.023
23.52,146.99,0.023
23.54,147.11,0.023
23.57,147.22,0.023
23.59,147.34,0.023
23.61,147.46,0.023
23.64,147.57,0.023
23.66,147.69,0.023
23.68,147.81,0.023
23.71,147.92,0.023
23.73,148.04,0.023
23.75,148.16,0.023
23.78,148.27,0.023
23.80,148.39,0.023
23.82,148.51,0.023
23.85,148.62,0.023
23.87,148.74,0.023
23.89,148.86,0.023
23.92,148.97,0.023
23.94,149.09,0.023
23.96,149.21,0.023
23.99,149.32,0.023
24.01,149.44,0.023
24.03,149.56,0.023
24.06,149.68,0.023
24.08,149.79,0.024
24.10,149.91,0.024
24.13,150.03,0.024
24.15,150.14,0.024
24.17,150.26,0.024
24.20,150.38,0.024
24.22,150.49,0.024
24.24,150.61,0.024
24.27,150.72,0.024
24.29,150.84,0.024
24.31,150.96,0.024
24.34,151.07,0.024
24.36,151.19,0.024
24.38,151.31,0.024
24.41,151.42,0.024
24.43,151.54,0.024
24.45,151.66,0.024
24.48,151.77,0.024
24.50,151.89,0.024
24.52,152.01,0.024
24.55,152.13,0.024
24.57,152.24,0.024
24.59,152.36,0.024
24.62,152.47,0.024
24.64,152.59,0.024
24.66,152.71,0.024
24.69,152.82,0.024
24.71,152.94,0.024
24.73,153.06,0.024
24.76,153.17,0.024
24.78,153.29,0.024
24.80,153.41,0.024
24.83,153.52,0.024
24.85,153.64,0.024
24.87,153.76,0.024
24.90,153.87,0.024
24.92,153.99,0.024
24.94,154.11,0.024
24.97,154.23,0.024
24.99,154.34,0.024
25.01,154.46,0.024
25.04,154.58,0.024
25.06,154.69,0.024
25.08,154.81,0.024
25.11,154.92,0.025
25.13,155.04,0.025
25.15,155.16,0.025
25.18,155.28,0.025
25.20,155.39,0.025
25.22,155.51,0.025
25.25,155.63,0.025
25.27,155.74,0.025
25.29,155.86,0.025
25.32,155.98,0.025
25.34,156.09,0.025
25.36,156.21,0.025
25.39,156.32,0.025
25.41,156.44,0.025
25.43,156.56,0.026
25.46,156.67,0.032
25.48,156.79,0.077
25.50,156.90,0.134
25.53,157.01,0.231
25.55,157.11,0.382
25.57,157.20,0.518
25.60,157.29,0.658
25.62,157.38,0.800
25.64,157.48,0.952
25.67,157.56,1.126
25.69,157.65,1.335
25.71,157.73,1.523
25.74,157.81,1.580
25.76,157.91,1.612
25.78,158.01,1.640
25.81,158.11,1.650
25.83,158.23,1.670
25.85,158.34,1.653
25.88,158.47,1.043
25.90,158.66,0.521
25.92,158.84,0.379
25.95,159.00,0.289
25.97,159.15,0.219
25.99,159.29,0.171
26.02,159.43,0.133
26.04,159.56,0.106
26.06,159.68,0.085
26.09,159.80,0.069
26.11,159.93,0.057
26.13,160.05,0.050
26.16,160.17,0.045
26.18,160.29,0.040
26.20,160.40,0.036
26.23,160.52,0.035
26.25,160.64,0.033
26.27,160.76,0.033
26.30,160.87,0.032
26.32,160.99,0.030
26.34,161.11,0.029
26.37,161.22,0.029
26.39,161.34,0.029
26.41,161.46,0.028
26.44,161.58,0.028
26.46,161.69,0.028
26.48,161.81,0.028
26.51,161.93,0.027
26.53,162.04,0.027
26.55,162.16,0.027
26.58,162.28,0.027
26.60,162.39,0.027
26.62,162.51,0.027
26.65,162.63,0.026
26.67,162.74,0.026
26.69,162.86,0.026
26.72,162.98,0.026
26.74,163.09,0.026
26.76,163.21,0.026
26.79,163.33,0.026
26.81,163.44,0.026
26.83,163.56,0.026
26.86,163.68,0.026
26.88,163.79,0.026
26.90,163.91,0.026
26.93,164.03,0.026
26.95,164.14,0.026
26.97,164.26,0.026
27.00,164.38,0.026
27.02,164.49,0.026
27.04,164.61,0.026
27.07,164.73,0.026
27.09,164.84,0.026
27.11,164.96,0.026
27.14,165.08,0.026
27.16,165.19,0.026
27.18,165.31,0.026
27.21,165.43,0.026
27.23,165.54,0.026
27.25,165.66,0.026
27.28,165.78,0.026
27.30,165.89,0.026
27.32,166.01,0.026
27.35,166.13,0.026
27.37,166.24,0.026
27.39,166.36,0.026
27.42,166.48,0.026
27.44,166.59,0.026
27.46,166.71,0.026
27.49,166.83,0.026
27.51,166.94,0.026
27.53,167.06,0.026
27.56,167.18,0.026
27.58,167.29,0.026
27.60,167.41,0.026
27.63,167.53,0.026
27.65,167.64,0.026
27.67,167.76,0.026
27.70,167.88,0.026
27.72,167.99,0.026
27.74,168.11,0.026
27.77,168.23,0.026
27.79,168.34,0.026
27.81,168.46,0.026
27.84,168.58,0.026
27.86,168.69,0.026
27.88,168.81,0.026
27.91,168.93,0.026
27.93,169.04,0.026
27.95,169.16,0.026
27.98,169.28,0.026
28.00,169.39,0.026
28.02,169.51,0.026
28.05,169.63,0.026
28.07,169.74,0.027
28.09,169.86,0.027
28.12,169.98,0.026
28.14,170.09,0.026
28.16,170.21,0.026
28.19,170.33,0.026
28.21,170.44,0.026
28.23,170.56,0.026
28.26,170.68,0.026
28.28,170.79,0.026
28.30,170.91,0.026
28.33,171.03,0.026
28.35,171.14,0.026
28.37,171.26,0.026
28.40,171.38,0.026
28.42,171.49,0.026
28.44,171.61,0.027
28.47,171.73,0.027
28.49,171.84,0.027
28.51,171.96,0.027
28.54,172.08,0.027
28.56,172.19,0.027
28.58,172.31,0.027
28.61,172.43,0.027
28.63,172.55,0.027
28.65,172.66,0.027
28.68,172.78,0.027
28.70,172.89,0.027
28.72,173.01,0.027
28.75,173.13,0.027
28.77,173.24,0.027
28.79,173.36,0.027
28.82,173.48,0.027
28.84,173.59,0.027
28.86,173.71,0.027
28.89,173.83,0.027
28.91,173.94,0.027
28.93,174.06,0.027
28.96,174.18,0.027
28.98,174.29,0.027
29.00,174.41,0.027
29.03,174.53,0.027
29.05,174.64,0.027
29.07,174.76,0.027
29.10,174.88,0.027
29.12,174.99,0.027
29.14,175.11,0.027
29.17,175.23,0.027
29.19,175.34,0.027
29.21,175.46,0.027
29.24,175.58,0.027
29.26,175.69,0.027
29.28,175.81,0.027
29.31,175.93,0.027
29.33,176.04,0.027
29.35,176.16,0.027
29.38,176.28,0.027
29.40,176.39,0.027
29.42,176.51,0.027
29.45,176.63,0.027
29.47,176.74,0.027
29.49,176.86,0.027
29.52,176.98,0.027
29.54,177.09,0.027
29.56,177.21,0.027
29.59,177.33,0.027
29.61,177.44,0.027
29.63,177.56,0.027
29.66,177.68,0.027
29.68,177.79,0.027
29.70,177.91,0.027
29.73,178.03,0.027
29.75,178.14,0.027
29.77,178.26,0.027
29.80,178.38,0.027
29.82,178.49,0.027
29.84,178.61,0.027
29.87,178.73,0.027
29.89,178.84,0.027
29.91,178.96,0.027
29.94,179.08,0.027
29.96,179.19,0.027
29.98,179.31,0.027
30.01,179.43,0.027
30.03,179.55,0.027
30.05,179.66,0.027
30.08,179.78,0.027
30.10,179.90,0.027
30.12,180.01,0.027
30.15,180.13,0.027
30.17,180.25,0.027
30.19,180.36,0.027
30.22,180.48,0.027
30.24,180.59,0.027
30.26,180.71,0.027
30.29,180.83,0.027
30.31,180.94,0.027
30.33,181.06,0.027
30.36,181.18,0.027
30.38,181.30,0.027
30.40,181.41,0.027
30.43,181.53,0.028
30.45,181.65,0.028
30.47,181.76,0.028
30.50,181.88,0.028
30.52,182.00,0.028
30.54,182.11,0.028
30.57,182.23,0.028
30.59,182.34,0.028
30.61,182.46,0.028
30.64,182.58,0.028
30.66,182.69,0.028
30.68,182.81,0.028
30.71,182.93,0.028
30.73,183.04,0.028
30.75,183.16,0.028
30.78,183.28,0.028
30.80,183.39,0.028
30.82,183.51,0.028
30.85,183.63,0.028
30.87,183.74,0.028
30.89,183.86,0.028
30.92,183.98,0.028
30.94,184.09,0.028
30.96,184.21,0.028
30.99,184.33,0.028
31.01,184.44,0.028
31.03,184.56,0.028
31.06,184.68,0.028
31.08,184.79,0.028
31.10,184.91,0.028
31.13,185.03,0.028
31.15,185.14,0.028
31.17,185.26,0.028
31.20,185.38,0.028
31.22,185.49,0.028
31.24,185.61,0.028
31.27,185.73,0.028
31.29,185.84,0.028
31.31,185.96,0.028
31.34,186.08,0.028
31.36,186.20,0.028
31.38,186.31,0.028
31.41,186.43,0.028
31.43,186.55,0.029
31.45,186.66,0.029
31.48,186.78,0.029
31.50,186.90,0.029
31.52,187.01,0.029
31.55,187.13,0.029
31.57,187.25,0.029
31.59,187.36,0.029
31.62,187.48,0.029
31.64,187.60,0.029
31.66,187.71,0.029
31.69,187.83,0.029
31.71,187.95,0.029
31.73,188.06,0.029
31.76,188.18,0.029
31.78,188.29,0.029
31.80,188.41,0.029
31.83,188.53,0.029
31.85,188.64,0.029
31.87,188.76,0.029
31.90,188.88,0.029
31.92,188.99,0.029
31.94,189.11,0.029
31.97,189.23,0.029
31.99,189.34,0.029
32.01,189.46,0.029
32.04,189.58,0.029
32.06,189.69,0.029
32.08,189.81,0.029
32.11,189.93,0.029
32.13,190.05,0.029
32.15,190.16,0.029
32.18,190.28,0.029
32.20,190.40,0.029
32.22,190.51,0.029
32.25,190.63,0.029
32.27,190.74,0.029
32.29,190.86,0.029
32.32,190.98,0.029
32.34,191.09,0.029
32.36,191.21,0.029
32.39,191.33,0.029
32.41,191.44,0.029
32.43,191.56,0.029
32.46,191.68,0.029
32.48,191.79,0.029
32.50,191.91,0.029
32.53,192.03,0.029
32.55,192.14,0.029
32.57,192.26,0.029
32.60,192.38,0.029
32.62,192.49,0.029
32.64,192.61,0.029
32.67,192.73,0.029
32.69,192.85,0.029
32.71,192.96,0.029
32.74,193.08,0.029
32.76,193.19,0.029
32.78,193.31,0.030
32.81,193.43,0.030
32.83,193.54,0.030
32.85,193.66,0.030
32.88,193.78,0.030
32.90,193.90,0.030
32.92,194.01,0.030
32.95,194.13,0.030
32.97,194.25,0.030
32.99,194.36,0.030
33.02,194.48,0.030
33.04,194.60,0.030
33.06,194.71,0.030
33.09,194.83,0.030
33.11,194.94,0.030
33.13,195.06,0.030
33.16,195.18,0.030
33.18,195.29,0.030
33.20,195.41,0.030
33.23,195.53,0.030
33.25,195.64,0.030
33.27,195.76,0.030
33.30,195.88,0.030
33.32,196.00,0.030
33.34,196.11,0.030
33.37,196.23,0.030
33.39,196.34,0.030
33.41,196.46,0.030
33.44,196.58,0.030
33.46,196.69,0.030
33.48,196.81,0.030
33.51,196.93,0.030
33.53,197.04,0.030
33.55,197.16,0.030
33.58,197.28,0.030
33.60,197.39,0.030
33.62,197.51,0.030
33.65,197.63,0.031
33.67,197.75,0.031
33.69,197.86,0.031
33.72,197.98,0.031
33.74,198.09,0.031
33.76,198.21,0.031
33.79,198.33,0.031
33.81,198.44,0.031
33.83,198.56,0.031
33.86,198.68,0.031
33.88,198.79,0.031
33.90,198.91,0.031
33.93,199.03,0.031
33.95,199.14,
33.97,199.26,
34.00,,
34.00,,

[step]
Ramp 5.00 °C/min to 30.00 °C
Time,Temperature,Heat Flow (Normalized)
min,°C,W/g
35.00,200.09,-0.041
35.02,200.09,-0.041
35.05,200.08,-0.041
35.07,200.07,-0.038
35.09,200.04,-0.032
35.12,200.00,-0.027
35.14,199.94,-0.027
35.16,199.86,-0.038
35.19,199.77,-0.058
35.21,199.67,-0.073
35.23,199.57,-0.085
35.26,199.47,-0.089
35.28,199.36,-0.096
35.30,199.25,-0.099
35.33,199.14,-0.101
35.35,199.03,-0.102
35.37,198.91,-0.104
35.40,198.80,-0.105
35.42,198.69,-0.105
35.44,198.57,-0.106
35.47,198.46,-0.107
35.49,198.35,-0.108
35.51,198.23,-0.108
35.54,198.12,-0.109
35.56,198.00,-0.109
35.58,197.89,-0.110
35.61,197.77,-0.110
35.63,197.66,-0.110
35.65,197.54,-0.111
35.68,197.43,-0.111
35.70,197.31,-0.112
35.72,197.19,-0.112
35.75,197.08,-0.112
35.77,196.96,-0.112
35.79,196.85,-0.113
35.82,196.73,-0.113
35.84,196.62,-0.113
35.86,196.50,-0.113
35.89,196.38,-0.113
35.91,196.27,-0.114
35.93,196.15,-0.114
35.96,196.04,-0.114
35.98,195.92,-0.114
36.00,195.81,-0.114
36.03,195.69,-0.114
36.05,195.57,-0.114
36.07,195.46,-0.114
36.10,195.34,-0.114
36.12,195.22,-0.114
36.14,195.11,-0.115
36.17,194.99,-0.115
36.19,194.88,-0.115
36.21,194.76,-0.115
36.24,194.64,-0.115
36.26,194.53,-0.115
36.28,194.41,-0.115
36.31,194.30,-0.115
36.33,194.18,-0.115
36.35,194.06,-0.115
36.38,193.95,-0.115
36.40,193.83,-0.115
36.42,193.71,-0.115
36.45,193.60,-0.115
36.47,193.48,-0.115
36.49,193.36,-0.115
36.52,193.25,-0.115
36.54,193.13,-0.115
36.56,193.02,-0.115
36.59,192.90,-0.115
36.61,192.78,-0.115
36.63,192.67,-0.115
36.66,192.55,-0.115
36.68,192.43,-0.115
36.70,192.32,-0.115
36.73,192.20,-0.115
36.75,192.08,-0.115
36.77,191.97,-0.115
36.80,191.85,-0.115
36.82,191.73,-0.115
36.84,191.62,-0.115
36.87,191.50,-0.115
36.89,191.38,-0.115
36.91,191.27,-0.115
36.94,191.15,-0.114
36.96,191.04,-0.114
36.98,190.92,-0.115
37.01,190.80,-0.114
37.03,190.69,-0.114
37.05,190.57,-0.114
37.08,190.45,-0.114
37.10,190.34,-0.114
37.12,190.22,-0.114
37.15,190.10,-0.114
37.17,189.99,-0.114
37.19,189.87,-0.114
37.22,189.75,-0.114
37.24,189.64,-0.114
37.26,189.52,-0.114
37.29,189.40,-0.114
37.31,189.29,-0.114
37.33,189.17,-0.114
37.36,189.05,-0.114
37.38,188.94,-0.114
37.40,188.82,-0.114
37.43,188.70,-0.114
37.45,188.59,-0.114
37.47,188.47,-0.114
37.50,188.36,-0.114
37.52,188.24,-0.113
37.54,188.12,-0.113
37.57,188.01,-0.113
37.59,187.89,-0.113
37.61,187.77,-0.113
37.64,187.66,-0.113
37.66,187.54,-0.113
37.68,187.42,-0.113
37.71,187.31,-0.113
37.73,187.19,-0.114
37.75,187.07,-0.113
37.78,186.96,-0.114
37.80,186.84,-0.114
37.82,186.72,-0.114
37.85,186.61,-0.114
37.87,186.49,-0.114
37.89,186.37,-0.114
37.92,186.26,-0.113
37.94,186.14,-0.114
37.96,186.02,-0.114
37.99,185.91,-0.114
38.01,185.79,-0.114
38.03,185.68,-0.114
38.06,185.56,-0.114
38.08,185.44,-0.113
38.10,185.32,-0.114
38.13,185.21,-0.114
38.15,185.09,-0.114
38.17,184.98,-0.114
38.20,184.86,-0.114
38.22,184.74,-0.114
38.24,184.62,-0.114
38.27,184.51,-0.114
38.29,184.39,-0.114
38.31,184.28,-0.114
38.34,184.16,-0.114
38.36,184.04,-0.114
38.38,183.93,-0.113
38.41,183.81,-0.113
38.43,183.69,-0.113
38.45,183.58,-0.113
38.48,183.46,-0.113
38.50,183.34,-0.113
38.52,183.23,-0.113
38.55,183.11,-0.113
38.57,182.99,-0.113
38.59,182.88,-0.113
38.62,182.76,-0.113
38.64,182.64,-0.113
38.66,182.53,-0.113
38.69,182.41,-0.113
38.71,182.29,-0.113
38.73,182.18,-0.113
38.76,182.06,-0.113
38.78,181.94,-0.113
38.80,181.83,-0.113
38.83,181.71,-0.113
38.85,181.59,-0.113
38.87,181.48,-0.113
38.90,181.36,-0.113
38.92,181.24,-0.113
38.94,181.13,-0.113
38.97,181.01,-0.113
38.99,180.89,-0.113
39.01,180.78,-0.113
39.04,180.66,-0.113
39.06,180.55,-0.113
39.08,180.43,-0.113
39.11,180.31,-0.113
39.13,180.20,-0.113
39.15,180.08,-0.113
39.18,179.96,-0.113
39.20,179.85,-0.113
39.22,179.73,-0.113
39.25,179.61,-0.113
39.27,179.50,-0.113
39.29,179.38,-0.113
39.32,179.26,-0.113
39.34,179.15,-0.113
39.36,179.03,-0.113
39.39,178.91,-0.113
39.41,178.80,-0.113
39.43,178.68,-0.113
39.46,178.56,-0.113
39.48,178.45,-0.113
39.50,178.33,-0.113
39.53,178.21,-0.113
39.55,178.10,-0.113
39.57,177.98,-0.113
39.60,177.86,-0.113
39.62,177.75,-0.113
39.64,177.63,-0.113
39.67,177.52,-0.113
39.69,177.40,-0.113
39.71,177.28,-0.113
39.74,177.16,-0.113
39.76,177.05,-0.113
39.78,176.93,-0.113
39.81,176.81,-0.113
39.83,176.70,-0.113
39.85,176.58,-0.113
39.88,176.47,-0.113
39.90,176.35,-0.113
39.92,176.23,-0.113
39.95,176.11,-0.113
39.97,176.00,-0.113
39.99,175.88,-0.113
40.02,175.77,-0.113
40.04,175.65,-0.113
40.06,175.53,-0.113
40.09,175.42,-0.113
40.11,175.30,-0.113
40.13,175.18,-0.113
40.16,175.07,-0.112
40.18,174.95,-0.112
40.20,174.83,-0.112
40.23,174.72,-0.112
40.25,174.60,-0.112
40.27,174.48,-0.113
40.30,174.37,-0.113
40.32,174.25,-0.113
40.34,174.13,-0.113
40.37,174.02,-0.113
40.39,173.90,-0.113
40.41,173.78,-0.112
40.44,173.67,-0.112
40.46,173.55,-0.112
40.48,173.43,-0.112
40.51,173.32,-0.112
40.53,173.20,-0.112
40.55,173.08,-0.112
40.58,172.97,-0.112
40.60,172.85,-0.113
40.62,172.73,-0.113
40.65,172.62,-0.113
40.67,172.50,-0.113
40.69,172.39,-0.113
40.72,172.27,-0.112
40.74,172.15,-0.112
40.76,172.04,-0.113
40.79,171.92,-0.112
40.81,171.80,-0.112
40.83,171.69,-0.113
40.86,171.57,-0.112
40.88,171.45,-0.113
40.90,171.34,-0.113
40.93,171.22,-0.113
40.95,171.10,-0.113
40.97,170.99,-0.113
41.00,170.87,-0.113
41.02,170.75,-0.113
41.04,170.64,-0.113
41.07,170.52,-0.113
41.09,170.40,-0.113
41.11,170.29,-0.113
41.14,170.17,-0.113
41.16,170.05,-0.113
41.18,169.94,-0.113
41.21,169.82,-0.113
41.23,169.70,-0.113
41.25,169.59,-0.113
41.28,169.47,-0.113
41.30,169.35,-0.113
41.32,169.24,-0.113
41.35,169.12,-0.113
41.37,169.00,-0.113
41.39,168.89,-0.113
41.42,168.77,-0.113
41.44,168.65,-0.113
41.46,168.54,-0.112
41.49,168.42,-0.112
41.51,168.30,-0.112
41.53,168.19,-0.112
41.56,168.07,-0.112
41.58,167.96,-0.112
41.60,167.84,-0.113
41.63,167.72,-0.112
41.65,167.61,-0.113
41.67,167.49,-0.113
41.70,167.37,-0.112
41.72,167.26,-0.112
41.74,167.14,-0.112
41.77,167.02,-0.112
41.79,166.91,-0.112
41.81,166.79,-0.112
41.84,166.67,-0.112
41.86,166.56,-0.112
41.88,166.44,-0.112
41.91,166.32,-0.112
41.93,166.21,-0.113
41.95,166.09,-0.113
41.98,165.97,-0.113
42.00,165.86,-0.113
42.02,165.74,-0.113
42.05,165.62,-0.113
42.07,165.51,-0.113
42.09,165.39,-0.113
42.12,165.27,-0.112
42.14,165.16,-0.113
42.16,165.04,-0.112
42.19,164.92,-0.113
42.21,164.81,-0.112
42.23,164.69,-0.113
42.26,164.57,-0.113
42.28,164.46,-0.113
42.30,164.34,-0.113
42.33,164.22,-0.113
42.35,164.11,-0.113
42.37,163.99,-0.113
42.40,163.87,-0.113
42.42,163.76,-0.113
42.44,163.64,-0.113
42.47,163.53,-0.113
42.49,163.41,-0.113
42.51,163.29,-0.113
42.54,163.18,-0.113
42.56,163.06,-0.112
42.58,162.94,-0.112
42.61,162.83,-0.112
42.63,162.71,-0.112
42.65,162.59,-0.112
42.68,162.48,-0.112
42.70,162.36,-0.112
42.72,162.24,-0.112
42.75,162.13,-0.113
42.77,162.01,-0.113
42.79,161.89,-0.112
42.82,161.78,-0.112
42.84,161.66,-0.112
42.86,161.54,-0.112
42.89,161.43,-0.112
42.91,161.31,-0.112
42.93,161.19,-0.112
42.96,161.08,-0.113
42.98,160.96,-0.113
43.00,160.84,-0.113
43.03,160.73,-0.113
43.05,160.61,-0.113
43.07,160.49,-0.113
43.10,160.38,-0.113
43.12,160.26,-0.113
43.14,160.14,-0.113
43.17,160.03,-0.113
43.19,159.91,-0.113
43.21,159.79,-0.113
43.24,159.68,-0.113
43.26,159.56,-0.113
43.28,159.44,-0.113
[...]
150.50,81.88,0.021
150.52,81.99,0.021
150.55,82.11,0.021
150.57,82.22,0.021
150.59,82.34,0.021
150.62,82.46,0.021
150.64,82.57,0.021
150.66,82.69,0.021
150.69,82.81,0.021
150.71,82.93,0.021
150.73,83.04,0.021
150.76,83.16,0.021
150.78,83.28,0.021
150.80,83.39,0.020
150.83,83.51,0.020
150.85,83.63,0.020
150.87,83.74,0.020
150.90,83.86,0.020
150.92,83.98,0.020
150.94,84.09,0.020
150.97,84.21,0.020
150.99,84.33,0.020
151.01,84.44,0.020
151.04,84.56,0.020
151.06,84.68,0.020
151.08,84.79,0.020
151.11,84.91,0.020
151.13,85.03,0.020
151.15,85.14,0.020
151.18,85.26,0.020
151.20,85.38,0.020
151.22,85.49,0.020
151.25,85.61,0.020
151.27,85.73,0.020
151.29,85.84,0.020
151.32,85.96,0.020
151.34,86.08,0.020
151.36,86.19,0.020
151.39,86.31,0.020
151.41,86.43,0.020
151.43,86.54,0.020
151.46,86.66,0.020
151.48,86.78,0.020
151.50,86.89,0.020
151.53,87.01,0.020
151.55,87.13,0.020
151.57,87.24,0.020
151.60,87.36,0.020
151.62,87.48,0.020
151.64,87.59,0.020
151.67,87.71,0.020
151.69,87.83,0.020
151.71,87.94,0.020
151.74,88.06,0.020
151.76,88.18,0.020
151.78,88.29,0.020
151.81,88.41,0.020
151.83,88.53,0.020
151.85,88.64,0.020
151.88,88.76,0.020
151.90,88.88,0.020
151.92,89.00,0.020
151.95,89.11,0.020
151.97,89.23,0.020
151.99,89.34,0.021
152.02,89.46,0.021
152.04,89.58,0.020
152.06,89.70,0.021
152.09,89.81,0.021
152.11,89.93,0.021
152.13,90.04,0.021
152.16,90.16,0.021
152.18,90.28,0.021
152.20,90.39,0.021
152.23,90.51,0.021
152.25,90.63,0.021
152.27,90.75,0.021
152.30,90.86,0.021
152.32,90.98,0.021
152.34,91.09,0.021
152.37,91.21,0.021
152.39,91.33,0.021
152.41,91.45,0.021
152.44,91.56,0.021
152.46,91.68,0.021
152.48,91.80,0.021
152.51,91.91,0.021
152.53,92.03,0.021
152.55,92.15,0.021
152.58,92.26,0.021
152.60,92.38,0.021
152.62,92.50,0.021
152.65,92.61,0.021
152.67,92.73,0.021
152.69,92.85,0.021
152.72,92.96,0.021
152.74,93.08,0.021
152.76,93.20,0.021
152.79,93.31,0.021
152.81,93.43,0.021
152.83,93.55,0.021
152.86,93.67,0.021
152.88,93.78,0.021
152.90,93.90,0.021
152.93,94.01,0.021
152.95,94.13,0.021
152.97,94.25,0.021
153.00,94.36,0.021
153.02,94.48,0.021
153.04,94.60,0.021
153.07,94.71,0.021
153.09,94.83,0.021
153.11,94.95,0.021
153.14,95.06,0.021
153.16,95.18,0.021
153.18,95.30,0.021
153.21,95.41,0.021
153.23,95.53,0.021
153.25,95.65,0.021
153.28,95.76,0.021
153.30,95.88,0.021
153.32,96.00,0.021
153.35,96.11,0.021
153.37,96.23,0.021
153.39,96.35,0.021
153.42,96.46,0.021
153.44,96.58,0.021
153.46,96.70,0.021
153.49,96.81,0.021
153.51,96.93,0.022
153.53,97.05,0.021
153.56,97.16,0.021
153.58,97.28,0.022
153.60,97.40,0.022
153.63,97.52,0.022
153.65,97.63,0.022
153.67,97.75,0.022
153.70,97.87,0.022
153.72,97.98,0.022
153.74,98.10,0.022
153.77,98.22,0.022
153.79,98.33,0.022
153.81,98.45,0.022
153.84,98.56,0.022
153.86,98.68,0.022
153.88,98.80,0.022
153.91,98.92,0.022
153.93,99.03,0.022
153.95,99.15,0.022
153.98,99.27,0.022
154.00,99.38,0.022
154.02,99.50,0.022
154.05,99.62,0.022
154.07,99.73,0.022
154.09,99.85,0.022
154.12,99.97,0.022
154.14,100.08,0.022
154.16,100.20,0.022
154.19,100.32,0.022
154.21,100.43,0.022
154.23,100.55,0.022
154.26,100.67,0.022
154.28,100.78,0.022
154.30,100.90,0.022
154.33,101.02,0.022
154.35,101.13,0.022
154.37,101.25,0.022
154.40,101.37,0.022
154.42,101.48,0.022
154.44,101.60,0.022
154.47,101.72,0.022
154.49,101.83,0.022
154.51,101.95,0.022
154.54,102.07,0.022
154.56,102.18,0.022
154.58,102.30,0.022
154.61,102.42,0.022
154.63,102.53,0.022
154.65,102.65,0.022
154.68,102.77,0.022
154.70,102.88,0.022
154.72,103.00,0.022
154.75,103.12,0.022
154.77,103.23,0.022
154.79,103.35,0.022
154.82,103.47,0.022
154.84,103.58,0.022
154.86,103.70,0.022
154.89,103.82,0.022
154.91,103.93,0.022
154.93,104.05,0.022
154.96,104.17,0.022
154.98,104.28,0.022
155.00,104.40,0.022
155.03,104.51,0.022
155.05,104.63,0.022
155.07,104.75,0.022
155.10,104.87,0.022
155.12,104.98,0.022
155.14,105.10,0.022
155.17,105.22,0.022
155.19,105.33,0.022
155.21,105.45,0.022
155.24,105.57,0.022
155.26,105.68,0.022
155.28,105.80,0.022
155.31,105.92,0.022
155.33,106.03,0.022
155.35,106.15,0.022
155.38,106.27,0.022
155.40,106.38,0.022
155.42,106.50,0.022
155.45,106.62,0.022
155.47,106.73,0.022
155.49,106.85,0.022
155.52,106.97,0.022
155.54,107.08,0.022
155.56,107.20,0.022
155.59,107.32,0.022
155.61,107.43,0.022
155.63,107.55,0.022
155.66,107.67,0.022
155.68,107.78,0.022
155.70,107.90,0.022
155.73,108.02,0.022
155.75,108.14,0.022
155.77,108.25,0.022
155.80,108.37,0.022
155.82,108.49,0.022
155.84,108.60,0.022
155.87,108.72,0.022
155.89,108.84,0.022
155.91,108.95,0.022
155.94,109.07,0.022
155.96,109.19,0.022
155.98,109.30,0.022
156.01,109.42,0.022
156.03,109.54,0.022
156.05,109.65,0.022
156.08,109.77,0.022
156.10,109.89,0.022
156.12,110.00,0.022
156.15,110.12,0.022
156.17,110.24,0.022
156.19,110.35,0.022
156.22,110.47,0.022
156.24,110.59,0.022
156.26,110.70,0.023
156.29,110.82,0.023
156.31,110.94,0.023
156.33,111.05,0.023
156.36,111.17,0.023
156.38,111.29,0.023
156.40,111.40,0.022
156.43,111.52,0.023
156.45,111.64,0.023
156.47,111.75,0.023
156.50,111.87,0.023
156.52,111.99,0.023
156.54,112.10,0.023
156.57,112.22,0.023
156.59,112.34,0.023
156.61,112.45,0.023
156.64,112.57,0.023
156.66,112.69,0.023
156.68,112.80,0.023
156.71,112.92,0.023
156.73,113.04,0.023
156.75,113.15,0.023
156.78,113.27,0.023
156.80,113.39,0.023
156.82,113.50,0.023
156.85,113.62,0.023
156.87,113.74,0.023
156.89,113.85,0.023
156.92,113.97,0.023
156.94,114.09,0.023
156.96,114.20,0.023
156.99,114.32,0.023
157.01,114.44,0.023
157.03,114.55,0.023
157.06,114.67,0.023
157.08,114.79,0.023
157.10,114.91,0.023
157.13,115.02,0.023
157.15,115.14,0.023
157.17,115.26,0.023
157.20,115.37,0.023
157.22,115.49,0.023
157.24,115.61,0.023
157.27,115.72,0.023
157.29,115.84,0.023
157.31,115.95,0.023
157.34,116.07,0.023
157.36,116.19,0.023
157.38,116.31,0.023
157.41,116.42,0.023
157.43,116.54,0.023
157.45,116.66,0.023
157.48,116.77,0.023
157.50,116.89,0.023
157.52,117.01,0.023
157.55,117.12,0.023
157.57,117.24,0.023
157.59,117.35,0.023
157.62,117.47,0.023
157.64,117.59,0.023
157.66,117.70,0.023
157.69,117.82,0.023
157.71,117.94,0.023
157.73,118.06,0.023
157.76,118.17,0.023
157.78,118.29,0.023
157.80,118.41,0.023
157.83,118.52,0.023
157.85,118.64,0.023
157.87,118.76,0.023
157.90,118.87,0.023
157.92,118.99,0.023
157.94,119.11,0.023
157.97,119.22,0.023
157.99,119.34,0.023
158.01,119.46,0.023
158.04,119.57,0.023
158.06,119.69,0.024
158.08,119.81,0.024
158.11,119.92,0.024
158.13,120.04,0.024
158.15,120.16,0.024
158.18,120.27,0.024
158.20,120.39,0.024
158.22,120.51,0.024
158.25,120.62,0.024
158.27,120.74,0.024
158.29,120.86,0.024
158.32,120.97,0.024
158.34,121.09,0.024
158.36,121.21,0.024
158.39,121.32,0.024
158.41,121.44,0.024
158.43,121.56,0.024
158.46,121.67,0.024
158.48,121.79,0.024
158.50,121.91,0.024
158.53,122.02,0.024
158.55,122.14,0.024
158.57,122.26,0.024
158.60,122.37,0.024
158.62,122.49,0.024
158.64,122.61,0.024
158.67,122.72,0.024
158.69,122.84,0.024
158.71,122.96,0.024
158.74,123.07,0.024
158.76,123.19,0.024
158.78,123.31,0.024
158.81,123.42,0.024
158.83,123.54,0.024
158.85,123.66,0.024
158.88,123.77,0.024
158.90,123.89,0.024
158.92,124.01,0.024
158.95,124.12,0.024
158.97,124.24,0.024
158.99,124.36,0.024
159.02,124.47,0.024
159.04,124.59,0.024
159.06,124.71,0.024
159.09,124.82,0.024
159.11,124.94,0.024
159.13,125.06,0.024
159.16,125.17,0.024
159.18,125.29,0.024
159.20,125.41,0.024
159.23,125.52,0.024
159.25,125.64,0.024
159.27,125.76,0.024
159.30,125.87,0.024
159.32,125.99,0.024
159.34,126.11,0.024
159.37,126.22,0.024
159.39,126.34,0.024
159.41,126.46,0.024
159.44,126.57,0.024
159.46,126.69,0.024
159.48,126.81,0.024
159.51,126.92,0.024
159.53,127.04,0.024
159.55,127.16,0.024
159.58,127.27,0.024
159.60,127.39,0.024
159.62,127.51,0.024
159.65,127.62,0.024
159.67,127.74,0.024
159.69,127.86,0.024
159.72,127.98,0.024
159.74,128.09,0.024
159.76,128.21,0.024
159.79,128.33,0.024
159.81,128.44,0.024
159.83,128.56,0.024
159.86,128.67,0.024
159.88,128.79,0.024
159.90,128.91,0.024
159.93,129.02,0.024
159.95,129.14,0.024
159.97,129.26,0.024
160.00,129.37,0.024
160.02,129.49,0.024
160.04,129.61,0.024
160.07,129.72,0.024
160.09,129.84,0.024
160.11,129.96,0.024
160.14,130.07,0.024
160.16,130.19,0.024
160.18,130.31,0.024
160.21,130.42,0.024
160.23,130.54,0.024
160.25,130.66,0.024
160.28,130.77,0.024
160.30,130.89,0.024
160.32,131.01,0.024
160.35,131.12,0.024
160.37,131.24,0.024
160.39,131.36,0.024
160.42,131.48,0.024
160.44,131.59,0.024
160.46,131.71,0.024
160.49,131.83,0.024
160.51,131.94,0.024
160.53,132.06,0.024
160.56,132.18,0.024
160.58,132.29,0.024
160.60,132.41,0.024
160.63,132.53,0.024
160.65,132.64,0.024
160.67,132.76,0.024
160.70,132.88,0.024
160.72,132.99,0.024
160.74,133.11,0.024
160.77,133.23,0.024
160.79,133.34,0.024
160.81,133.46,0.024
160.84,133.58,0.024
160.86,133.69,0.024
160.88,133.81,0.024
160.91,133.93,0.024
160.93,134.04,0.024
160.95,134.16,0.024
160.98,134.28,0.024
161.00,134.39,0.024
161.02,134.51,0.024
161.05,134.63,0.024
161.07,134.74,0.024
161.09,134.86,0.024
161.12,134.98,0.024
161.14,135.09,0.024
161.16,135.21,0.024
161.19,135.33,0.024
161.21,135.44,0.025
161.23,135.56,0.025
161.26,135.68,0.025
161.28,135.79,0.025
161.30,135.91,0.025
161.33,136.03,0.025
161.35,136.14,0.025
161.37,136.26,0.025
161.40,136.38,0.025
161.42,136.49,0.025
161.44,136.61,0.025
161.47,136.73,0.025
161.49,136.84,0.025
161.51,136.96,0.025
161.54,137.08,0.025
161.56,137.19,0.025
161.58,137.31,0.025
161.61,137.43,0.025
161.63,137.54,0.025
161.65,137.66,0.025
161.68,137.78,0.025
161.70,137.89,0.025
161.72,138.01,0.025
161.75,138.13,0.025
161.77,138.25,0.025
161.79,138.36,0.025
161.82,138.48,0.025
161.84,138.60,0.025
161.86,138.71,0.025
161.89,138.83,0.025
161.91,138.95,0.025
161.93,139.06,0.025
161.96,139.18,0.025
161.98,139.29,0.025
162.00,139.41,0.025
162.03,139.53,0.025
162.05,139.64,0.025
162.07,139.76,0.025
162.10,139.88,0.025
162.12,139.99,0.025
162.14,140.11,0.025
162.17,140.23,0.025
162.19,140.34,0.025
162.21,140.46,0.025
162.24,140.58,0.025
162.26,140.69,0.025
162.28,140.81,0.025
162.31,140.93,0.025
162.33,141.04,0.025
162.35,141.16,0.025
162.38,141.28,0.025
162.40,141.40,0.025
162.42,141.51,0.025
162.45,141.63,0.025
162.47,141.74,0.025
162.49,141.86,0.025
162.52,141.98,0.025
162.54,142.09,0.025
162.56,142.21,0.025
162.59,142.33,0.025
162.61,142.44,0.025
162.63,142.56,0.025
162.66,142.68,0.025
162.68,142.79,0.025
162.70,142.91,0.025
162.73,143.03,0.025
162.75,143.14,0.025
162.77,143.26,0.025
162.80,143.38,0.025
162.82,143.49,0.025
162.84,143.61,0.025
162.87,143.73,0.025
162.89,143.84,0.025
162.91,143.96,0.025
162.94,144.08,0.025
162.96,144.19,0.025
162.98,144.31,0.025
163.01,144.43,0.025
163.03,144.55,0.025
163.05,144.66,0.025
163.08,144.78,0.025
163.10,144.90,0.025
163.12,145.01,0.026
163.15,145.13,0.026
163.17,145.25,0.026
163.19,145.36,0.026
163.22,145.48,0.026
163.24,145.60,0.026
163.26,145.71,0.026
163.29,145.83,0.026
163.31,145.95,0.026
163.33,146.06,0.026
163.36,146.18,0.026
163.38,146.30,0.026
163.40,146.41,0.026
163.43,146.53,0.026
163.45,146.65,0.026
163.47,146.76,0.026
163.50,146.88,0.026
163.52,147.00,0.026
163.54,147.11,0.026
163.57,147.23,0.026
163.59,147.35,0.026
163.61,147.46,0.026
163.64,147.58,0.026
163.66,147.69,0.026
163.68,147.81,0.026
163.71,147.93,0.026
163.73,148.04,0.026
163.75,148.16,0.026
163.78,148.28,0.026
163.80,148.39,0.026
163.82,148.51,0.026
163.85,148.63,0.026
163.87,148.75,0.026
163.89,148.86,0.026
163.92,148.98,0.026
163.94,149.10,0.026
163.96,149.21,0.026
163.99,149.33,0.026
164.01,149.45,0.026
164.03,149.56,0.026
164.06,149.68,0.026
164.08,149.79,0.026
164.10,149.91,0.026
164.13,150.03,0.026
164.15,150.14,0.026
164.17,150.26,0.026
164.20,150.38,0.026
164.22,150.49,0.026
164.24,150.61,0.026
164.27,150.73,0.026
164.29,150.85,0.026
164.31,150.96,0.026
164.34,151.08,0.026
164.36,151.20,0.026
164.38,151.31,0.026
164.41,151.43,0.026
164.43,151.55,0.026
164.45,151.66,0.026
164.48,151.78,0.026
164.50,151.90,0.026
164.52,152.01,0.026
164.55,152.13,0.026
164.57,152.25,0.026
164.59,152.36,0.026
164.62,152.48,0.026
164.64,152.60,0.026
164.66,152.71,0.026
164.69,152.83,0.026
164.71,152.95,0.026
164.73,153.06,0.026
164.76,153.18,0.026
164.78,153.30,0.026
164.80,153.41,0.026
164.83,153.53,0.026
164.85,153.65,0.026
164.87,153.76,0.026
164.90,153.88,0.026
164.92,154.00,0.026
164.94,154.11,0.027
164.97,154.23,0.027
164.99,154.35,0.026
165.01,154.46,0.026
165.04,154.58,0.026
165.06,154.70,0.027
165.08,154.81,0.027
165.11,154.93,0.027
165.13,155.05,0.027
165.15,155.16,0.027
165.18,155.28,0.027
165.20,155.40,0.027
165.22,155.52,0.027
165.25,155.63,0.027
165.27,155.75,0.027
165.29,155.87,0.027
165.32,155.98,0.027
165.34,156.10,0.027
165.36,156.22,0.027
165.39,156.33,0.027
165.41,156.45,0.028
165.43,156.56,0.034
165.46,156.68,0.123
165.48,156.78,0.306
165.50,156.87,0.505
165.53,156.95,0.700
165.55,157.04,0.888
165.57,157.12,1.074
165.60,157.20,1.261
165.62,157.28,1.457
165.64,157.36,1.652
165.67,157.44,1.794
165.69,157.53,1.816
165.71,157.63,1.888
165.74,157.72,1.974
165.76,157.83,1.854
165.78,157.97,1.113
165.81,158.17,0.569
165.83,158.36,0.418
165.85,158.52,0.316
165.88,158.68,0.242
165.90,158.82,0.186
165.92,158.96,0.144
165.95,159.09,0.114
165.97,159.22,0.091
165.99,159.34,0.074
166.02,159.46,0.065
166.04,159.58,0.055
166.06,159.70,0.047
166.09,159.82,0.043
166.11,159.94,0.039
166.13,160.06,0.037
166.16,160.18,0.035
166.18,160.29,0.034
166.20,160.41,0.033
166.23,160.53,0.032
166.25,160.65,0.031
166.27,160.76,0.031
166.30,160.88,0.031
166.32,161.00,0.030
166.34,161.11,0.030
166.37,161.23,0.030
166.39,161.35,0.030
166.41,161.47,0.030
166.44,161.58,0.029
166.46,161.70,0.029
166.48,161.82,0.029
166.51,161.93,0.029
166.53,162.05,0.029
166.55,162.17,0.029
166.58,162.28,0.028
166.60,162.40,0.028
166.62,162.51,0.028
166.65,162.63,0.028
166.67,162.75,0.028
166.69,162.86,0.028
166.72,162.98,0.028
166.74,163.10,0.028
166.76,163.21,0.028
166.79,163.33,0.028
166.81,163.45,0.028
166.83,163.57,0.028
166.86,163.68,0.028
166.88,163.80,0.028
166.90,163.91,0.028
166.93,164.03,0.028
166.95,164.15,0.028
166.97,164.26,0.028
167.00,164.38,0.028
167.02,164.50,0.028
167.04,164.61,0.028
167.07,164.73,0.028
167.09,164.85,0.028
167.11,164.96,0.027
167.14,165.08,0.027
167.16,165.20,0.027
167.18,165.31,0.028
167.21,165.43,0.028
167.23,165.55,0.028
167.25,165.67,0.028
167.28,165.78,0.028
167.30,165.90,0.028
167.32,166.02,0.028
167.35,166.13,0.028
167.37,166.25,0.028
167.39,166.37,0.028
167.42,166.48,0.028
167.44,166.60,0.028
167.46,166.72,0.028
167.49,166.83,0.028
167.51,166.95,0.028
167.53,167.07,0.028
167.56,167.18,0.028
167.58,167.30,0.028
167.60,167.42,0.028
167.63,167.53,0.028
167.65,167.65,0.028
167.67,167.77,0.028
167.70,167.88,0.028
167.72,168.00,0.028
167.74,168.11,0.028
167.77,168.23,0.028
167.79,168.35,0.028
167.81,168.47,0.028
167.84,168.58,0.028
167.86,168.70,0.028
167.88,168.82,0.028
167.91,168.93,0.028
167.93,169.05,0.028
167.95,169.17,0.028
167.98,169.28,0.028
168.00,169.40,0.028
168.02,169.52,0.028
168.05,169.63,0.028
168.07,169.75,0.028
168.09,169.87,0.028
168.12,169.98,0.028
168.14,170.10,0.028
168.16,170.22,0.028
168.19,170.33,0.028
168.21,170.45,0.028
168.23,170.56,0.028
168.26,170.68,0.028
168.28,170.80,0.028
168.30,170.91,0.028
168.33,171.03,0.028
168.35,171.15,0.028
168.37,171.27,0.028
168.40,171.38,0.028
168.42,171.50,0.028
168.44,171.62,0.028
168.47,171.73,0.028
168.49,171.85,0.028
168.51,171.97,0.028
168.54,172.08,0.028
168.56,172.20,0.028
168.58,172.32,0.028
168.61,172.43,0.028
168.63,172.55,0.028
168.65,172.67,0.028
168.68,172.78,0.028
168.70,172.90,0.028
168.72,173.02,0.028
168.75,173.13,0.028
168.77,173.25,0.028
168.79,173.37,0.028
168.82,173.48,0.028
168.84,173.60,0.028
168.86,173.71,0.028
168.89,173.83,0.028
168.91,173.95,0.028
168.93,174.07,0.028
168.96,174.18,0.028
168.98,174.30,0.028
169.00,174.41,0.028
169.03,174.53,0.028
169.05,174.65,0.028
169.07,174.77,0.028
169.10,174.88,0.028
169.12,175.00,0.028
169.14,175.12,0.028
169.17,175.23,0.028
169.19,175.35,0.028
169.21,175.47,0.028
169.24,175.58,0.028
169.26,175.70,0.028
169.28,175.82,0.028
169.31,175.93,0.028
169.33,176.05,0.028
169.35,176.17,0.028
169.38,176.28,0.028
169.40,176.40,0.028
169.42,176.52,0.028
169.45,176.63,0.028
169.47,176.75,0.028
169.49,176.87,0.028
169.52,176.98,0.028
169.54,177.10,0.028
169.56,177.22,0.028
169.59,177.33,0.028
169.61,177.45,0.028
169.63,177.57,0.028
169.66,177.68,0.028
169.68,177.80,0.028
169.70,177.92,0.028
169.73,178.03,0.028
169.75,178.15,0.028
169.77,178.27,0.028
169.80,178.38,0.028
169.82,178.50,0.028
169.84,178.62,0.028
169.87,178.73,0.028
169.89,178.85,0.028
169.91,178.97,0.028
169.94,179.08,0.028
169.96,179.20,0.028
169.98,179.32,0.028
170.01,179.43,0.028
170.03,179.55,0.028
170.05,179.67,0.028
170.08,179.78,0.028
170.10,179.90,0.029
170.12,180.02,0.029
170.15,180.13,0.029
170.17,180.25,0.029
170.19,180.37,0.029
170.22,180.48,0.029
170.24,180.60,0.029
170.26,180.72,0.029
170.29,180.83,0.029
170.31,180.95,0.029
170.33,181.07,0.029
170.36,181.18,0.029
170.38,181.30,0.029
170.40,181.42,0.029
170.43,181.53,0.029
170.45,181.65,0.029
170.47,181.77,0.029
170.50,181.88,0.029
170.52,182.00,0.029
170.54,182.12,0.029
170.57,182.23,0.029
170.59,182.35,0.029
170.61,182.47,0.029
170.64,182.58,0.029
170.66,182.70,0.029
170.68,182.81,0.029
170.71,182.93,0.029
170.73,183.05,0.029
170.75,183.17,0.029
170.78,183.28,0.029
170.80,183.40,0.029
170.82,183.52,0.029
170.85,183.63,0.029
170.87,183.75,0.029
170.89,183.87,0.029
170.92,183.98,0.029
170.94,184.10,0.029
170.96,184.22,0.029
170.99,184.33,0.029
171.01,184.45,0.029
171.03,184.57,0.029
171.06,184.68,0.029
171.08,184.80,0.029
171.10,184.92,0.029
171.13,185.03,0.029
171.15,185.15,0.029
171.17,185.27,0.029
171.20,185.38,0.029
171.22,185.50,0.029
171.24,185.62,0.029
171.27,185.73,0.029
171.29,185.85,0.029
171.31,185.97,0.029
171.34,186.09,0.029
171.36,186.20,0.029
171.38,186.32,0.029
171.41,186.43,0.029
171.43,186.55,0.029
171.45,186.67,0.029
171.48,186.78,0.029
171.50,186.90,0.029
171.52,187.02,0.029
171.55,187.13,0.029
171.57,187.25,0.029
171.59,187.37,0.029
171.62,187.48,0.029
171.64,187.60,0.029
171.66,187.72,0.029
171.69,187.83,0.029
171.71,187.95,0.029
171.73,188.07,0.029
171.76,188.18,0.029
171.78,188.30,0.029
171.80,188.42,0.029
171.83,188.53,0.029
171.85,188.65,0.029
171.87,188.77,0.029
171.90,188.88,0.029
171.92,189.00,0.029
171.94,189.12,0.029
171.97,189.23,0.029
171.99,189.35,0.029
172.01,189.47,0.029
172.04,189.58,0.029
172.06,189.70,0.029
172.08,189.82,0.029
172.11,189.93,0.029
172.13,190.05,0.029
172.15,190.17,0.029
172.18,190.28,0.029
172.20,190.40,0.030
172.22,190.52,0.029
172.25,190.63,0.029
172.27,190.75,0.029
172.29,190.87,0.030
172.32,190.98,0.030
172.34,191.10,0.030
172.36,191.22,0.030
172.39,191.33,0.030
172.41,191.45,0.030
172.43,191.57,0.030
172.46,191.68,0.030
172.48,191.80,0.030
172.50,191.92,0.030
172.53,192.03,0.030
172.55,192.15,0.030
172.57,192.27,0.030
172.60,192.39,0.030
172.62,192.50,0.030
172.64,192.62,0.030
172.67,192.74,0.030
172.69,192.85,0.030
172.71,192.97,0.030
172.74,193.09,0.030
172.76,193.20,0.030
172.78,193.32,0.030
172.81,193.44,0.030
172.83,193.55,0.030
172.85,193.67,0.030
172.88,193.79,0.030
172.90,193.90,0.030
172.92,194.02,0.030
172.95,194.14,0.030
172.97,194.25,0.030
172.99,194.37,0.030
173.02,194.48,0.030
173.04,194.60,0.030
173.06,194.72,0.030
173.09,194.83,0.030
173.11,194.95,0.030
173.13,195.07,0.030
173.16,195.18,0.030
173.18,195.30,0.030
173.20,195.42,0.030
173.23,195.53,0.030
173.25,195.65,0.030
173.27,195.77,0.030
173.30,195.88,0.030
173.32,196.00,0.030
173.34,196.12,0.030
173.37,196.23,0.030
173.39,196.35,0.030
173.41,196.47,0.030
173.44,196.58,0.030
173.46,196.70,0.030
173.48,196.82,0.030
173.51,196.93,0.030
173.53,197.05,0.030
173.55,197.17,0.030
173.58,197.28,0.030
173.60,197.40,0.030
173.62,197.52,0.030
173.65,197.63,0.030
173.67,197.75,0.030
173.69,197.87,0.030
173.72,197.98,0.030
173.74,198.10,0.030
173.76,198.22,0.030
173.79,198.33,0.030
173.81,198.45,0.030
173.83,198.57,0.030
173.86,198.68,0.030
173.88,198.80,0.030
173.90,198.92,0.030
173.93,199.03,0.030
173.95,199.15,
173.97,199.27,
174.00,,
174.00,,