File: DSC/2025_04_18_THCa_Pro_n60C_170C_10Cmin_x3.csv
Filename,2025_04_18_THCa_Pro_n60C_170C_10Cmin_x3
Instrument name,DSC2A-00468 (192.168.1.100)
Operator,Yarger
rundate,4/18/2025
Sample name,2025_04_18_THCa_Pro_n60C_170C_10Cmin_x3
proceduresegments,Data Off ; Equilibrate -60.00 °C; Data On ; Ramp 10.00 °C/min to 170.00 °C; Data Off ; Isothermal 0.1 min; Data On ; Ramp 10.00 °C/min to -60.00 °C; Data Off ; Isothermal 1.0 min; Data On ; Ramp 10.00 °C/min to 170.00 °C; Data Off ; Isothermal 0.1 min; Data On ; Ramp 10.00 °C/min to -60.00 °C; Data Off ; Isothermal 1.0 min; Data On ; Ramp 10.00 °C/min to 30.00 °C
[File Parameters]
Run date,4/18/2025 4:53:04 PM
Trios version,5.1.1.46572
Original File Name,
Current File Name,D:\DSC2500\JYarger\2025_04_18_THCa_Pro_n60C_170C_10Cmin_x3.tri
[Procedure]
Procedure Name,THCa_Pro_n60_170C_10Cmin_x3
Sample Name,2025_04_18_THCa_Pro_n60C_170C_10Cmin_x3
Sample Mass,7.08 mg
Reference Sample Mass,0 mg
Pan Mass,53.81 mg
Pan Number,50
Reference Pan Mass,53.66 mg
Reference Pan Number,46
Pan Type,Tzero Aluminum Hermetic
Comments,Hermetic Sealed Al DSC Consumables Pan/Lids.
Project Name,CA
Operator,Yarger
Test,Custom
Unload Max Temperature,30
Unload Min Temperature,30
Load Max Temperature,30
Load Min Temperature,30
Stop on Gas Flow Error,Yes
[Signal List]
Signal #1,Time (min)
Signal #2,Temperature (°C)
Signal #3,Heat Flow (mW)
Signal #4,Delta T (µV)
Signal #5,Delta Tzero (µV)
Signal #6,Tzero Temperature (°C)
Signal #7,Cell Purge (mL/min)
Signal #8,Heater Temp (°C)
Signal #9,Power Delivered (W)
Signal #10,Reference Junction Temperature (°C)
Signal #11,Flange Temperature (°C)
Signal #12,Heat Flow Phase (rad)
Signal #13,Total Heat Capacity (J/°C)
Signal #14,Heat Capacity (J/°C)
[Configuration]
Company Name,ASU
Instrument Name,DSC2A-00468
Instrument Type,DSC2500
Serial Number,DSC2A-00468
IP,192.168.1.100
Location of Instrument,MRRC
DisplayType,Unknown
Sample Interval ,0.1 s/pt
Selected Heat Flow,T4P
Exotherm Direction,Down
Cell Serial,DRC2-00792
Lid Type,Standard
Cooler,RCS 90
Leave Cooler on at End of Sequence,On
Gas 2,Nitrogen
Gas Selected,Channel 1
Flow Rate,50 mL/min
Secondary Purge,On
Licensed Heat Flow,Heat Flow T4P
Modulation Licensed,Yes
[Versions]
Common IDD Version,1
Cortex Version,VER 2.10.2.31
Driver,5.0.0.6
GDM Version,1.0.3.3
TouchscreenVersion,1.0.0.16145
FEP Version,1.2.1.21
FEP Bootloader,2.0.0.5
AutoSampler Version,2.1.1.26
Auto Sampler Bootloader,2.0.0.5
FCM Version,1.1.0.3
FCM Bootloader,2.0.0.5
[Experiment Logs]
Experiment Log Entry # 1,Data On set to 0
Experiment Log Entry # 3,Equilibrate Segment -60 (C) Started
Experiment Log Entry # 5,Air Cool is off.
Experiment Log Entry # 7,Data On set to 1
Experiment Log Entry # 9,Ramp Segment 10 C/min to 170 Started
Experiment Log Entry # 11,Data On set to 0
Experiment Log Entry # 13,Isothermal Segment 0.1 min started
Experiment Log Entry # 15,Data On set to 1
Experiment Log Entry # 17,Ramp Segment 10 C/min to -60 Started
Experiment Log Entry # 19,Data On set to 0
Experiment Log Entry # 21,Isothermal Segment 1 min started
Experiment Log Entry # 23,Data On set to 1
Experiment Log Entry # 25,Ramp Segment 10 C/min to 170 Started
Experiment Log Entry # 27,Data On set to 0
Experiment Log Entry # 29,Isothermal Segment 0.1 min started
Experiment Log Entry # 31,Data On set to 1
Experiment Log Entry # 33,Ramp Segment 10 C/min to -60 Started
Experiment Log Entry # 35,Data On set to 0
Experiment Log Entry # 37,Isothermal Segment 1 min started
Experiment Log Entry # 39,Data On set to 1
Experiment Log Entry # 41,Ramp Segment 10 C/min to 30 Started
[Method Log]
Method Log Entry # 1,Data Off
Method Log Entry # 2,Equilibrate -60 °C
Method Log Entry # 3,Data On
Method Log Entry # 4,(Ramp 41301) Ramp 10 °C/minute to 170 °C
Method Log Entry # 5,Data Off
Method Log Entry # 6,Isothermal 0.1 minutes
Method Log Entry # 7,Data On
Method Log Entry # 8,(Ramp 41305) Ramp 10 °C/minute to -60 °C
Method Log Entry # 9,Data Off
Method Log Entry # 10,Isothermal 1 minutes
Method Log Entry # 11,Data On
Method Log Entry # 12,(Ramp 41309) Ramp 10 °C/minute to 170 °C
Method Log Entry # 13,Data Off
Method Log Entry # 14,Isothermal 0.1 minutes
Method Log Entry # 15,Data On
Method Log Entry # 16,(Ramp 41313) Ramp 10 °C/minute to -60 °C
Method Log Entry # 17,Data Off
Method Log Entry # 18,Isothermal 1 minutes
Method Log Entry # 19,Data On
Method Log Entry # 20,(Ramp 41317) Ramp 10 °C/minute to 30 °C
Cell Serial,DRC2-00792
[T1 Calibration]
Slope,-0.008529666
Offset,9.636258
Initial Temperature,98.23
GUID,f8bfdadc-4977-4fdf-ba6d-0ba9134940c3
[TZero Calibration]
Date Applied,11/29/2022 4:06:13 PM
Description,From -89.059 °C to 396.009 °C at 20.000°C/min
Gas Type,Nitrogen
Pan Type,None
Source Files 1,C:\Users\yargerlab\Desktop\DSC Data\General\TZero_calibration_11_29_22_2nd(2).tri
Source Files 2,C:\Users\yargerlab\Desktop\DSC Data\General\TZero_calibration_11_29_22_2nd(3).tri
Delta T Offset,13.05235
Delta T Slope,-0.007271007
Delta T0 Offset,-13.69128
Delta T0 Slope,0.06063341
[Temperature Calibration]
Date Applied,11/29/2022 7:12:28 PM
Description,From 106.590 °C to 186.590 °C at 10.000°C/min
Gas Type,Nitrogen
Pan Type,Tzero Aluminum Hermetic
Source Files 1,C:\Users\yargerlab\Desktop\DSC Data\General\Indium(6).tri
Measured 1,157.391
Known 1,156.598
[Cell Constant Calibration]
Date Applied,11/29/2022 7:12:29 PM
Description,From 106.590 °C to 186.590 °C at 10.000°C/min
Gas Type,Nitrogen
Pan Type,Tzero Aluminum Hermetic
Source Files 1,C:\Users\yargerlab\Desktop\DSC Data\General\Indium(6).tri
T4P KCell,1.006051
Onset Slope,63.26126 mW/°C
[Direct Cp Calibration]
Date Applied,11/30/2022 11:04:51 AM
Description,From -79.983 °C to 298.409 °C at 10.000°C/min
Gas Type,Nitrogen
Pan Type,Tzero Aluminum Hermetic
Source Files 1,C:\Users\yargerlab\Desktop\DSC Data\General\Sapphire_Heat_Capacity_11_30_22.tri
[Rev Cp Calibration]
Date Applied,11/30/2022 1:58:51 PM
Description,From -79.996 °C to 292.812 °C at 3.000°C/min
Gas Type,Nitrogen
Pan Type,Tzero Aluminum Hermetic
Source Files 1,C:\Users\yargerlab\Desktop\DSC Data\General\Sapphire_MDSC_Calibration_11_30_22.tri
[step]
Ramp 10.00 °C/min to 170.00 °C
Time,Temperature,Heat Flow (Normalized)
min,°C,W/g
0.00,-59.66,-0.052
0.02,-59.67,-0.052
0.03,-59.67,-0.047
0.05,-59.68,-0.042
0.07,-59.67,-0.041
0.08,-59.64,-0.039
0.10,-59.60,-0.038
0.12,-59.54,-0.036
0.13,-59.47,-0.031
0.15,-59.38,-0.022
0.17,-59.28,-0.011
0.18,-59.17,0.000
0.20,-59.05,0.014
0.22,-58.93,0.027
0.23,-58.79,0.040
0.25,-58.66,0.053
0.27,-58.52,0.065
0.28,-58.38,0.075
0.30,-58.24,0.087
0.32,-58.09,0.095
0.33,-57.94,0.102
0.35,-57.80,0.111
0.37,-57.65,0.116
0.38,-57.50,0.123
0.40,-57.34,0.128
0.42,-57.19,0.133
0.43,-57.04,0.137
0.45,-56.88,0.140
0.47,-56.72,0.143
0.48,-56.57,0.147
0.50,-56.41,0.149
0.52,-56.25,0.152
0.53,-56.09,0.155
0.55,-55.93,0.155
0.57,-55.77,0.157
0.58,-55.61,0.159
0.60,-55.45,0.160
0.62,-55.29,0.161
0.63,-55.13,0.162
0.65,-54.97,0.163
0.67,-54.81,0.164
0.68,-54.64,0.165
0.70,-54.48,0.165
0.72,-54.32,0.166
0.73,-54.16,0.166
0.75,-53.99,0.167
0.77,-53.83,0.168
0.78,-53.67,0.168
0.80,-53.50,0.169
0.82,-53.34,0.169
0.83,-53.18,0.169
0.85,-53.01,0.169
0.87,-52.85,0.169
0.88,-52.69,0.170
0.90,-52.52,0.170
0.92,-52.36,0.170
0.93,-52.19,0.170
0.95,-52.03,0.171
0.97,-51.87,0.171
0.98,-51.70,0.171
1.00,-51.54,0.171
1.02,-51.37,0.171
1.03,-51.21,0.172
1.05,-51.04,0.172
1.07,-50.88,0.172
1.08,-50.71,0.172
1.10,-50.55,0.172
1.12,-50.38,0.173
1.13,-50.22,0.173
1.15,-50.05,0.173
1.17,-49.88,0.173
1.18,-49.72,0.174
1.20,-49.55,0.174
1.22,-49.39,0.174
1.23,-49.22,0.174
1.25,-49.05,0.174
1.27,-48.89,0.174
1.28,-48.72,0.174
1.30,-48.56,0.175
1.32,-48.39,0.175
1.33,-48.22,0.175
1.35,-48.06,0.175
1.37,-47.89,0.175
1.38,-47.73,0.175
1.40,-47.56,0.175
1.42,-47.39,0.175
1.43,-47.23,0.175
1.45,-47.06,0.176
1.47,-46.90,0.176
1.48,-46.73,0.176
1.50,-46.56,0.176
1.52,-46.40,0.176
1.53,-46.23,0.176
1.55,-46.06,0.176
1.57,-45.90,0.176
1.58,-45.73,0.176
1.60,-45.57,0.176
1.62,-45.40,0.176
1.63,-45.23,0.177
1.65,-45.07,0.177
1.67,-44.90,0.177
1.68,-44.73,0.177
1.70,-44.57,0.177
1.72,-44.40,0.177
1.73,-44.24,0.177
1.75,-44.07,0.177
1.77,-43.90,0.177
1.78,-43.74,0.177
1.80,-43.57,0.177
1.82,-43.40,0.177
1.83,-43.24,0.177
1.85,-43.07,0.177
1.87,-42.90,0.177
1.88,-42.74,0.178
1.90,-42.57,0.178
1.92,-42.40,0.178
1.93,-42.23,0.178
1.95,-42.07,0.178
1.97,-41.90,0.178
1.98,-41.74,0.178
2.00,-41.57,0.178
2.02,-41.40,0.178
2.03,-41.24,0.178
2.05,-41.07,0.178
2.07,-40.90,0.178
2.08,-40.74,0.178
2.10,-40.57,0.178
2.12,-40.40,0.178
2.13,-40.24,0.178
2.15,-40.07,0.178
2.17,-39.90,0.178
2.18,-39.73,0.179
2.20,-39.57,0.179
2.22,-39.40,0.179
2.23,-39.23,0.179
2.25,-39.07,0.179
2.27,-38.90,0.179
2.28,-38.73,0.179
2.30,-38.57,0.179
2.32,-38.40,0.179
2.33,-38.23,0.179
2.35,-38.07,0.179
2.37,-37.90,0.179
2.38,-37.73,0.179
2.40,-37.56,0.179
2.42,-37.40,0.179
2.43,-37.23,0.179
2.45,-37.07,0.179
2.47,-36.90,0.180
2.48,-36.73,0.180
2.50,-36.57,0.180
2.52,-36.40,0.180
2.53,-36.23,0.180
2.55,-36.06,0.180
2.57,-35.90,0.180
2.58,-35.73,0.180
2.60,-35.56,0.180
2.62,-35.40,0.180
2.63,-35.23,0.180
2.65,-35.07,0.180
2.67,-34.90,0.180
2.68,-34.73,0.180
2.70,-34.56,0.180
2.72,-34.40,0.180
2.73,-34.23,0.181
2.75,-34.06,0.181
2.77,-33.89,0.181
2.78,-33.73,0.181
2.80,-33.56,0.181
2.82,-33.40,0.181
2.83,-33.23,0.181
2.85,-33.06,0.181
2.87,-32.90,0.181
2.88,-32.73,0.181
2.90,-32.56,0.181
2.92,-32.39,0.181
2.93,-32.23,0.182
2.95,-32.06,0.182
2.97,-31.89,0.182
2.98,-31.73,0.182
3.00,-31.56,0.182
3.02,-31.39,0.182
3.03,-31.23,0.182
3.05,-31.06,0.182
3.07,-30.89,0.182
3.08,-30.72,0.182
3.10,-30.56,0.182
3.12,-30.39,0.182
3.13,-30.22,0.182
3.15,-30.06,0.182
3.17,-29.89,0.182
3.18,-29.72,0.183
3.20,-29.56,0.183
3.22,-29.39,0.183
3.23,-29.22,0.183
3.25,-29.06,0.183
3.27,-28.89,0.183
3.28,-28.72,0.183
3.30,-28.56,0.183
3.32,-28.39,0.183
3.33,-28.22,0.183
3.35,-28.06,0.183
3.37,-27.89,0.183
3.38,-27.72,0.183
3.40,-27.55,0.184
3.42,-27.39,0.184
3.43,-27.22,0.184
3.45,-27.05,0.184
3.47,-26.89,0.184
3.48,-26.72,0.184
3.50,-26.55,0.184
3.52,-26.39,0.184
3.53,-26.22,0.184
3.55,-26.05,0.184
3.57,-25.89,0.184
3.58,-25.72,0.184
3.60,-25.55,0.184
3.62,-25.39,0.185
3.63,-25.22,0.185
3.65,-25.05,0.185
3.67,-24.88,0.185
3.68,-24.72,0.185
3.70,-24.55,0.185
3.72,-24.38,0.185
3.73,-24.22,0.185
3.75,-24.05,0.185
3.77,-23.88,0.185
3.78,-23.72,0.185
3.80,-23.55,0.185
3.82,-23.38,0.186
3.83,-23.21,0.186
3.85,-23.05,0.186
3.87,-22.88,0.186
3.88,-22.72,0.186
3.90,-22.55,0.186
3.92,-22.38,0.186
3.93,-22.22,0.186
3.95,-22.05,0.186
3.97,-21.88,0.186
3.98,-21.71,0.186
4.00,-21.55,0.186
4.02,-21.38,0.186
4.03,-21.21,0.186
4.05,-21.05,0.187
4.07,-20.88,0.187
4.08,-20.71,0.187
4.10,-20.55,0.187
4.12,-20.38,0.187
4.13,-20.21,0.187
4.15,-20.05,0.187
4.17,-19.88,0.187
4.18,-19.71,0.187
4.20,-19.54,0.187
4.22,-19.38,0.188
4.23,-19.21,0.188
4.25,-19.04,0.188
4.27,-18.88,0.188
4.28,-18.71,0.188
4.30,-18.54,0.188
4.32,-18.38,0.188
4.33,-18.21,0.188
4.35,-18.04,0.188
4.37,-17.88,0.188
4.38,-17.71,0.188
4.40,-17.54,0.188
4.42,-17.38,0.189
4.43,-17.21,0.189
4.45,-17.04,0.189
4.47,-16.88,0.189
4.48,-16.71,0.189
4.50,-16.54,0.189
4.52,-16.37,0.189
4.53,-16.21,0.189
4.55,-16.04,0.189
4.57,-15.87,0.189
4.58,-15.71,0.190
4.60,-15.54,0.190
4.62,-15.37,0.190
4.63,-15.21,0.190
4.65,-15.04,0.190
4.67,-14.87,0.190
4.68,-14.71,0.190
4.70,-14.54,0.190
4.72,-14.37,0.190
4.73,-14.21,0.190
4.75,-14.04,0.190
4.77,-13.87,0.190
4.78,-13.71,0.190
4.80,-13.54,0.191
4.82,-13.37,0.191
4.83,-13.20,0.191
4.85,-13.04,0.191
4.87,-12.87,0.191
4.88,-12.70,0.191
4.90,-12.54,0.191
4.92,-12.37,0.191
4.93,-12.20,0.191
4.95,-12.04,0.191
4.97,-11.87,0.191
4.98,-11.70,0.192
5.00,-11.54,0.192
5.02,-11.37,0.192
5.03,-11.20,0.192
5.05,-11.04,0.192
5.07,-10.87,0.192
5.08,-10.70,0.192
5.10,-10.54,0.192
5.12,-10.37,0.192
5.13,-10.20,0.192
5.15,-10.04,0.192
5.17,-9.87,0.192
5.18,-9.70,0.193
5.20,-9.54,0.193
5.22,-9.37,0.193
5.23,-9.20,0.193
5.25,-9.04,0.193
5.27,-8.87,0.193
5.28,-8.70,0.193
5.30,-8.53,0.193
5.32,-8.37,0.193
5.33,-8.20,0.193
5.35,-8.03,0.194
5.37,-7.87,0.194
5.38,-7.70,0.194
5.40,-7.53,0.194
5.42,-7.36,0.194
5.43,-7.20,0.194
5.45,-7.03,0.194
5.47,-6.87,0.194
5.48,-6.70,0.194
5.50,-6.53,0.195
5.52,-6.36,0.195
5.53,-6.20,0.195
5.55,-6.03,0.195
5.57,-5.86,0.195
5.58,-5.70,0.195
5.60,-5.53,0.195
5.62,-5.36,0.195
5.63,-5.20,0.195
5.65,-5.03,0.195
5.67,-4.86,0.196
5.68,-4.70,0.196
5.70,-4.53,0.196
5.72,-4.36,0.196
5.73,-4.20,0.196
5.75,-4.03,0.196
5.77,-3.86,0.196
5.78,-3.69,0.196
5.80,-3.53,0.196
5.82,-3.36,0.196
5.83,-3.19,0.197
5.85,-3.03,0.197
5.87,-2.86,0.197
5.88,-2.70,0.197
5.90,-2.53,0.197
5.92,-2.36,0.197
5.93,-2.19,0.197
5.95,-2.03,0.197
5.97,-1.86,0.197
5.98,-1.69,0.198
6.00,-1.53,0.198
6.02,-1.36,0.198
6.03,-1.19,0.198
6.05,-1.02,0.198
6.07,-0.86,0.198
6.08,-0.69,0.198
6.10,-0.52,0.198
6.12,-0.36,0.198
6.13,-0.19,0.198
6.15,-0.02,0.199
6.17,0.14,0.199
6.18,0.31,0.199
6.20,0.48,0.199
6.22,0.64,0.199
6.23,0.81,0.199
6.25,0.98,0.199
6.27,1.14,0.199
6.28,1.31,0.199
6.30,1.48,0.200
6.32,1.65,0.200
6.33,1.81,0.200
6.35,1.98,0.200
6.37,2.15,0.200
6.38,2.31,0.200
6.40,2.48,0.200
6.42,2.65,0.200
6.43,2.81,0.200
6.45,2.98,0.201
6.47,3.15,0.201
6.48,3.31,0.201
6.50,3.48,0.201
6.52,3.65,0.201
6.53,3.81,0.201
6.55,3.98,0.201
6.57,4.15,0.201
6.58,4.31,0.202
6.60,4.48,0.202
6.62,4.65,0.202
6.63,4.82,0.202
6.65,4.98,0.202
6.67,5.15,0.202
6.68,5.32,0.202
6.70,5.48,0.202
6.72,5.65,0.202
6.73,5.82,0.203
6.75,5.98,0.203
6.77,6.15,0.203
6.78,6.32,0.203
6.80,6.48,0.203
6.82,6.65,0.203
6.83,6.82,0.203
6.85,6.99,0.203
6.87,7.15,0.204
6.88,7.32,0.204
6.90,7.49,0.204
6.92,7.65,0.204
6.93,7.82,0.204
6.95,7.99,0.204
6.97,8.15,0.204
6.98,8.32,0.204
7.00,8.49,0.205
7.02,8.65,0.205
7.03,8.82,0.205
7.05,8.99,0.205
7.07,9.15,0.205
7.08,9.32,0.205
7.10,9.49,0.205
7.12,9.65,0.205
7.13,9.82,0.205
7.15,9.99,0.206
7.17,10.16,0.206
7.18,10.32,0.206
7.20,10.49,0.206
7.22,10.66,0.206
7.23,10.82,0.206
7.25,10.99,0.206
7.27,11.16,0.206
7.28,11.32,0.207
7.30,11.49,0.207
7.32,11.66,0.207
7.33,11.82,0.207
7.35,11.99,0.207
7.37,12.16,0.207
7.38,12.32,0.207
7.40,12.49,0.207
7.42,12.66,0.208
7.43,12.83,0.208
7.45,12.99,0.208
7.47,13.16,0.208
7.48,13.33,0.208
7.50,13.49,0.208
7.52,13.66,0.208
7.53,13.83,0.209
7.55,13.99,0.209
7.57,14.16,0.209
7.58,14.33,0.209
7.60,14.49,0.209
7.62,14.66,0.209
7.63,14.83,0.209
7.65,14.99,0.209
7.67,15.16,0.209
7.68,15.33,0.209
7.70,15.49,0.209
7.72,15.66,0.209
7.73,15.83,0.210
7.75,15.99,0.210
7.77,16.16,0.210
7.78,16.33,0.210
7.80,16.50,0.210
7.82,16.66,0.210
7.83,16.83,0.210
7.85,17.00,0.211
7.87,17.16,0.211
7.88,17.33,0.211
7.90,17.50,0.211
7.92,17.66,0.211
7.93,17.83,0.211
7.95,18.00,0.211
7.97,18.16,0.211
7.98,18.33,0.212
8.00,18.50,0.212
8.02,18.66,0.212
8.03,18.83,0.212
8.05,19.00,0.212
8.07,19.16,0.212
8.08,19.33,0.212
8.10,19.50,0.213
8.12,19.66,0.213
8.13,19.83,0.213
8.15,20.00,0.213
8.17,20.17,0.213
8.18,20.33,0.213
8.20,20.50,0.213
8.22,20.66,0.213
8.23,20.83,0.214
8.25,21.00,0.214
8.27,21.17,0.214
8.28,21.33,0.214
8.30,21.50,0.214
8.32,21.67,0.214
8.33,21.83,0.214
8.35,22.00,0.215
8.37,22.17,0.215
8.38,22.33,0.215
8.40,22.50,0.215
8.42,22.67,0.215
8.43,22.83,0.215
8.45,23.00,0.215
8.47,23.17,0.215
8.48,23.33,0.216
8.50,23.50,0.216
8.52,23.67,0.216
8.53,23.83,0.216
8.55,24.00,0.216
8.57,24.17,0.216
8.58,24.33,0.216
8.60,24.50,0.217
8.62,24.67,0.217
8.63,24.83,0.217
8.65,25.00,0.217
8.67,25.17,0.217
8.68,25.34,0.217
8.70,25.50,0.217
8.72,25.67,0.217
8.73,25.84,0.218
8.75,26.00,0.218
8.77,26.17,0.218
8.78,26.34,0.218
8.80,26.50,0.218
8.82,26.67,0.218
8.83,26.84,0.218
8.85,27.00,0.219
8.87,27.17,0.219
8.88,27.34,0.219
8.90,27.50,0.219
8.92,27.67,0.219
8.93,27.84,0.219
8.95,28.01,0.219
8.97,28.17,0.219
8.98,28.34,0.220
9.00,28.51,0.220
9.02,28.67,0.220
9.03,28.84,0.220
9.05,29.01,0.220
9.07,29.17,0.220
9.08,29.34,0.221
9.10,29.51,0.221
9.12,29.67,0.221
9.13,29.84,0.221
9.15,30.01,0.221
9.17,30.17,0.221
9.18,30.34,0.221
9.20,30.51,0.221
9.22,30.67,0.222
9.23,30.84,0.222
9.25,31.01,0.222
9.27,31.17,0.222
9.28,31.34,0.222
9.30,31.51,0.222
9.32,31.67,0.223
9.33,31.84,0.223
9.35,32.01,0.223
9.37,32.18,0.223
9.38,32.34,0.223
9.40,32.51,0.223
9.42,32.68,0.224
9.43,32.84,0.224
9.45,33.01,0.224
9.47,33.18,0.224
9.48,33.34,0.224
9.50,33.51,0.224
9.52,33.68,0.224
9.53,33.84,0.225
9.55,34.01,0.225
9.57,34.18,0.225
9.58,34.34,0.225
9.60,34.51,0.225
9.62,34.68,0.226
9.63,34.84,0.226
9.65,35.01,0.226
9.67,35.18,0.226
9.68,35.34,0.227
9.70,35.51,0.227
9.72,35.68,0.227
9.73,35.84,0.228
9.75,36.01,0.228
9.77,36.18,0.229
9.78,36.34,0.229
9.80,36.51,0.230
9.82,36.68,0.230
9.83,36.84,0.230
9.85,37.01,0.231
9.87,37.18,0.231
9.88,37.34,0.232
9.90,37.51,0.232
9.92,37.68,0.233
9.93,37.85,0.233
9.95,38.01,0.234
9.97,38.18,0.234
9.98,38.34,0.235
10.00,38.51,0.236
10.02,38.68,0.237
10.03,38.84,0.238
10.05,39.01,0.240
10.07,39.18,0.241
10.08,39.34,0.242
10.10,39.51,0.244
10.12,39.68,0.245
10.13,39.84,0.247
10.15,40.01,0.248
10.17,40.17,0.250
10.18,40.34,0.251
10.20,40.51,0.251
10.22,40.67,0.251
10.23,40.84,0.251
10.25,41.01,0.250
10.27,41.17,0.250
10.28,41.34,0.249
10.30,41.51,0.248
10.32,41.68,0.247
10.33,41.84,0.247
10.35,42.01,0.246
10.37,42.18,0.246
10.38,42.35,0.245
10.40,42.51,0.245
10.42,42.68,0.245
10.43,42.85,0.245
10.45,43.01,0.245
10.47,43.18,0.244
10.48,43.35,0.244
10.50,43.51,0.244
10.52,43.68,0.244
10.53,43.85,0.244
10.55,44.01,0.244
10.57,44.18,0.244
10.58,44.35,0.243
10.60,44.52,0.243
10.62,44.68,0.243
10.63,44.85,0.243
10.65,45.02,0.243
10.67,45.18,0.243
10.68,45.35,0.243
10.70,45.52,0.243
10.72,45.68,0.243
10.73,45.85,0.243
10.75,46.02,0.243
10.77,46.19,0.243
10.78,46.35,0.243
10.80,46.52,0.243
10.82,46.69,0.243
10.83,46.85,0.243
10.85,47.02,0.243
10.87,47.19,0.243
10.88,47.35,0.243
10.90,47.52,0.243
10.92,47.69,0.243
10.93,47.85,0.243
10.95,48.02,0.243
10.97,48.19,0.244
10.98,48.35,0.244
11.00,48.52,0.244
11.02,48.69,0.244
11.03,48.85,0.244
11.05,49.02,0.244
11.07,49.19,0.244
11.08,49.35,0.244
11.10,49.52,0.244
11.12,49.69,0.244
11.13,49.85,0.244
11.15,50.02,0.245
11.17,50.19,0.245
11.18,50.36,0.245
11.20,50.52,0.245
11.22,50.69,0.245
11.23,50.86,0.245
11.25,51.02,0.245
11.27,51.19,0.245
11.28,51.36,0.245
11.30,51.52,0.246
11.32,51.69,0.246
11.33,51.86,0.246
11.35,52.02,0.246
11.37,52.19,0.246
11.38,52.36,0.246
11.40,52.53,0.246
11.42,52.69,0.246
11.43,52.86,0.246
11.45,53.03,0.247
11.47,53.19,0.247
11.48,53.36,0.247
11.50,53.53,0.247
11.52,53.69,0.247
11.53,53.86,0.247
11.55,54.03,0.247
11.57,54.19,0.247
11.58,54.36,0.247
11.60,54.53,0.248
11.62,54.69,0.248
11.63,54.86,0.248
11.65,55.03,0.248
11.67,55.20,0.248
11.68,55.36,0.248
11.70,55.53,0.248
11.72,55.70,0.248
11.73,55.86,0.249
11.75,56.03,0.249
11.77,56.20,0.249
11.78,56.36,0.249
11.80,56.53,0.249
11.82,56.70,0.249
11.83,56.86,0.249
11.85,57.03,0.250
11.87,57.20,0.250
11.88,57.36,0.250
11.90,57.53,0.250
11.92,57.70,0.250
11.93,57.86,0.250
11.95,58.03,0.250
11.97,58.20,0.250
11.98,58.37,0.251
12.00,58.53,0.251
12.02,58.70,0.251
12.03,58.87,0.251
12.05,59.03,0.251
12.07,59.20,0.251
12.08,59.37,0.251
12.10,59.53,0.251
12.12,59.70,0.252
12.13,59.87,0.252
12.15,60.03,0.252
12.17,60.20,0.252
12.18,60.37,0.252
12.20,60.53,0.252
12.22,60.70,0.252
12.23,60.87,0.253
12.25,61.03,0.253
12.27,61.20,0.253
12.28,61.37,0.253
12.30,61.53,0.253
12.32,61.70,0.253
12.33,61.87,0.253
12.35,62.03,0.254
12.37,62.20,0.254
12.38,62.37,0.254
12.40,62.53,0.254
12.42,62.70,0.254
12.43,62.87,0.254
12.45,63.04,0.254
12.47,63.20,0.255
12.48,63.37,0.255
12.50,63.54,0.255
12.52,63.70,0.255
12.53,63.87,0.255
12.55,64.04,0.255
12.57,64.20,0.255
12.58,64.37,0.255
12.60,64.53,0.256
12.62,64.70,0.256
12.63,64.87,0.256
12.65,65.04,0.256
12.67,65.20,0.256
12.68,65.37,0.256
12.70,65.54,0.256
12.72,65.70,0.256
12.73,65.87,0.257
12.75,66.04,0.257
12.77,66.20,0.257
12.78,66.37,0.257
12.80,66.54,0.257
12.82,66.70,0.257
12.83,66.87,0.257
12.85,67.04,0.257
12.87,67.20,0.258
12.88,67.37,0.258
12.90,67.54,0.258
12.92,67.71,0.258
12.93,67.87,0.258
12.95,68.04,0.258
12.97,68.21,0.258
12.98,68.37,0.258
13.00,68.54,0.259
13.02,68.71,0.259
13.03,68.87,0.259
13.05,69.04,0.259
13.07,69.21,0.259
13.08,69.37,0.259
13.10,69.54,0.259
13.12,69.70,0.259
13.13,69.87,0.260
13.15,70.04,0.260
13.17,70.20,0.260
13.18,70.37,0.260
13.20,70.54,0.260
13.22,70.70,0.260
13.23,70.87,0.260
13.25,71.04,0.260
13.27,71.21,0.261
13.28,71.37,0.261
13.30,71.54,0.261
13.32,71.71,0.261
13.33,71.87,0.261
13.35,72.04,0.261
13.37,72.21,0.261
13.38,72.37,0.262
13.40,72.54,0.262
13.42,72.71,0.262
13.43,72.87,0.262
13.45,73.04,0.262
13.47,73.21,0.262
13.48,73.37,0.262
13.50,73.54,0.262
13.52,73.71,0.263
13.53,73.88,0.263
13.55,74.04,0.263
13.57,74.21,0.263
13.58,74.38,0.263
13.60,74.54,0.263
13.62,74.71,0.263
13.63,74.88,0.264
13.65,75.04,0.264
13.67,75.21,0.264
13.68,75.38,0.264
13.70,75.54,0.264
13.72,75.71,0.264
13.73,75.88,0.264
13.75,76.04,0.264
13.77,76.21,0.265
13.78,76.38,0.265
13.80,76.54,0.265
13.82,76.71,0.265
13.83,76.88,0.265
13.85,77.05,0.265
13.87,77.21,0.265
13.88,77.38,0.265
13.90,77.55,0.266
13.92,77.71,0.266
13.93,77.88,0.266
13.95,78.05,0.266
13.97,78.21,0.266
13.98,78.38,0.266
14.00,78.55,0.266
14.02,78.71,0.267
14.03,78.88,0.267
14.05,79.05,0.267
14.07,79.21,0.267
14.08,79.38,0.267
14.10,79.55,0.267
14.12,79.71,0.267
14.13,79.88,0.267
14.15,80.05,0.267
14.17,80.21,0.268
14.18,80.38,0.268
14.20,80.55,0.268
14.22,80.72,0.268
14.23,80.88,0.268
14.25,81.05,0.268
14.27,81.21,0.268
14.28,81.38,0.268
14.30,81.55,0.268
14.32,81.72,0.269
14.33,81.88,0.269
14.35,82.05,0.269
14.37,82.22,0.269
14.38,82.38,0.269
14.40,82.55,0.269
14.42,82.72,0.269
14.43,82.88,0.269
14.45,83.05,0.270
14.47,83.22,0.270
14.48,83.38,0.270
14.50,83.55,0.270
14.52,83.72,0.270
14.53,83.88,0.270
14.55,84.05,0.270
14.57,84.22,0.270
14.58,84.38,0.270
14.60,84.55,0.270
14.62,84.72,0.270
14.63,84.88,0.271
14.65,85.05,0.271
14.67,85.22,0.271
14.68,85.39,0.271
14.70,85.55,0.271
14.72,85.72,0.271
14.73,85.89,0.271
14.75,86.05,0.271
14.77,86.22,0.271
14.78,86.39,0.271
14.80,86.55,0.272
14.82,86.72,0.272
14.83,86.89,0.272
14.85,87.05,0.272
14.87,87.22,0.272
14.88,87.39,0.272
14.90,87.56,0.272
14.92,87.72,0.272
14.93,87.89,0.272
14.95,88.05,0.273
14.97,88.22,0.273
14.98,88.39,0.273
15.00,88.55,0.273
15.02,88.72,0.273
15.03,88.89,0.273
15.05,89.06,0.273
15.07,89.22,0.273
15.08,89.39,0.273
15.10,89.56,0.274
15.12,89.72,0.274
15.13,89.89,0.274
15.15,90.06,0.274
15.17,90.22,0.274
15.18,90.39,0.274
15.20,90.56,0.274
15.22,90.72,0.274
15.23,90.89,0.275
15.25,91.06,0.275
15.27,91.22,0.275
15.28,91.39,0.275
15.30,91.56,0.275
15.32,91.72,0.275
15.33,91.89,0.275
15.35,92.06,0.275
15.37,92.22,0.276
15.38,92.39,0.276
15.40,92.56,0.276
15.42,92.72,0.276
15.43,92.89,0.276
15.45,93.06,0.276
15.47,93.23,0.276
15.48,93.39,0.276
15.50,93.56,0.276
15.52,93.73,0.277
15.53,93.89,0.277
15.55,94.06,0.277
15.57,94.23,0.277
15.58,94.39,0.277
15.60,94.56,0.277
15.62,94.73,0.277
15.63,94.89,0.277
15.65,95.06,0.277
15.67,95.23,0.278
15.68,95.39,0.278
15.70,95.56,0.278
15.72,95.73,0.278
15.73,95.89,0.278
15.75,96.06,0.278
15.77,96.23,0.278
15.78,96.39,0.278
15.80,96.56,0.279
15.82,96.73,0.279
15.83,96.90,0.279
15.85,97.06,0.279
15.87,97.23,0.279
15.88,97.40,0.279
15.90,97.56,0.279
15.92,97.73,0.279
15.93,97.90,0.280
15.95,98.06,0.280
15.97,98.23,0.280
15.98,98.40,0.280
16.00,98.56,0.280
16.02,98.73,0.280
16.03,98.90,0.280
16.05,99.06,0.280
16.07,99.23,0.280
16.08,99.40,0.281
16.10,99.56,0.281
16.12,99.73,0.281
16.13,99.90,0.281
16.15,100.06,0.281
16.17,100.23,0.281
16.18,100.40,0.281
16.20,100.56,0.281
16.22,100.73,0.281
16.23,100.90,0.282
16.25,101.06,0.282
16.27,101.23,0.282
16.28,101.40,0.282
16.30,101.56,0.282
16.32,101.73,0.282
16.33,101.90,0.282
16.35,102.07,0.282
16.37,102.23,0.283
16.38,102.40,0.283
16.40,102.57,0.283
16.42,102.73,0.283
16.43,102.90,0.283
16.45,103.07,0.283
16.47,103.23,0.283
16.48,103.40,0.283
16.50,103.57,0.284
16.52,103.73,0.284
16.53,103.90,0.284
16.55,104.07,0.284
16.57,104.23,0.284
16.58,104.40,0.284
16.60,104.57,0.284
16.62,104.73,0.284
16.63,104.90,0.284
16.65,105.07,0.285
16.67,105.23,0.285
16.68,105.40,0.285
16.70,105.57,0.285
16.72,105.74,0.285
16.73,105.90,0.285
16.75,106.07,0.285
16.77,106.24,0.285
16.78,106.40,0.285
16.80,106.57,0.286
16.82,106.74,0.286
16.83,106.90,0.286
16.85,107.07,0.286
16.87,107.24,0.286
16.88,107.40,0.286
16.90,107.57,0.286
16.92,107.74,0.286
16.93,107.90,0.286
16.95,108.07,0.287
16.97,108.24,0.287
16.98,108.40,0.287
17.00,108.57,0.287
17.02,108.74,0.287
17.03,108.90,0.287
17.05,109.07,0.287
17.07,109.24,0.287
17.08,109.40,0.288
17.10,109.57,0.288
17.12,109.74,0.288
17.13,109.90,0.288
17.15,110.07,0.288
17.17,110.24,0.288
17.18,110.41,0.288
17.20,110.57,0.288
17.22,110.74,0.288
17.23,110.91,0.289
17.25,111.07,0.289
17.27,111.24,0.289
17.28,111.41,0.289
17.30,111.57,0.289
17.32,111.74,0.289
17.33,111.91,0.289
17.35,112.07,0.289
17.37,112.24,0.290
17.38,112.41,0.290
17.40,112.57,0.290
17.42,112.74,0.290
17.43,112.91,0.290
17.45,113.07,0.290
17.47,113.24,0.290
17.48,113.41,0.290
17.50,113.57,0.291
17.52,113.74,0.291
17.53,113.91,0.291
17.55,114.08,0.291
17.57,114.24,0.291
17.58,114.41,0.291
17.60,114.57,0.291
17.62,114.74,0.291
17.63,114.91,0.292
17.65,115.08,0.292
17.67,115.24,0.292
17.68,115.41,0.292
17.70,115.58,0.292
17.72,115.74,0.292
17.73,115.91,0.292
17.75,116.08,0.292
17.77,116.24,0.293
17.78,116.41,0.293
17.80,116.58,0.293
17.82,116.74,0.293
17.83,116.91,0.293
17.85,117.08,0.293
17.87,117.24,0.293
17.88,117.41,0.293
17.90,117.58,0.294
17.92,117.74,0.294
17.93,117.91,0.294
17.95,118.08,0.294
17.97,118.24,0.294
17.98,118.41,0.294
18.00,118.58,0.294
18.02,118.74,0.295
18.03,118.91,0.295
18.05,119.08,0.295
18.07,119.24,0.295
18.08,119.41,0.295
18.10,119.58,0.295
18.12,119.74,0.295
18.13,119.91,0.296
18.15,120.08,0.296
18.17,120.24,0.296
18.18,120.41,0.296
18.20,120.58,0.296
18.22,120.75,0.296
18.23,120.91,0.296
18.25,121.08,0.297
18.27,121.24,0.297
18.28,121.41,0.297
18.30,121.58,0.297
18.32,121.75,0.297
18.33,121.91,0.297
18.35,122.08,0.298
18.37,122.25,0.298
18.38,122.41,0.298
18.40,122.58,0.298
18.42,122.75,0.298
18.43,122.91,0.299
18.45,123.08,0.299
18.47,123.24,0.299
18.48,123.41,0.299
18.50,123.58,0.299
18.52,123.75,0.299
18.53,123.91,0.300
18.55,124.08,0.300
18.57,124.24,0.300
18.58,124.41,0.300
18.60,124.58,0.301
18.62,124.75,0.301
18.63,124.91,0.301
18.65,125.08,0.301
18.67,125.25,0.302
18.68,125.41,0.302
18.70,125.58,0.302
18.72,125.75,0.302
18.73,125.91,0.303
18.75,126.08,0.303
18.77,126.25,0.304
18.78,126.41,0.304
18.80,126.58,0.304
18.82,126.75,0.305
18.83,126.91,0.305
18.85,127.08,0.305
18.87,127.25,0.306
18.88,127.41,0.307
18.90,127.58,0.307
18.92,127.74,0.308
18.93,127.91,0.308
18.95,128.08,0.309
18.97,128.25,0.310
18.98,128.41,0.310
19.00,128.58,0.311
19.02,128.75,0.312
19.03,128.91,0.313
19.05,129.08,0.314
19.07,129.24,0.315
19.08,129.41,0.316
19.10,129.58,0.318
19.12,129.74,0.320
19.13,129.91,0.321
19.15,130.08,0.322
19.17,130.24,0.324
19.18,130.41,0.326
19.20,130.57,0.328
19.22,130.74,0.330
19.23,130.91,0.332
19.25,131.07,0.334
19.27,131.24,0.337
19.28,131.40,0.339
19.30,131.57,0.342
19.32,131.74,0.344
19.33,131.90,0.347
19.35,132.07,0.350
19.37,132.23,0.353
19.38,132.40,0.357
19.40,132.57,0.360
19.42,132.73,0.363
19.43,132.90,0.367
19.45,133.06,0.371
19.47,133.23,0.375
19.48,133.39,0.379
19.50,133.56,0.383
19.52,133.72,0.389
19.53,133.89,0.396
19.55,134.05,0.399
19.57,134.22,0.405
19.58,134.38,0.410
19.60,134.55,0.418
19.62,134.71,0.424
19.63,134.87,0.431
19.65,135.04,0.439
19.67,135.20,0.447
19.68,135.37,0.455
19.70,135.53,0.464
19.72,135.69,0.474
19.73,135.86,0.485
19.75,136.02,0.494
19.77,136.18,0.505
19.78,136.34,0.517
19.80,136.51,0.529
19.82,136.67,0.542
19.83,136.83,0.556
19.85,136.99,0.571
19.87,137.15,0.585
19.88,137.31,0.601
19.90,137.47,0.616
19.92,137.63,0.634
19.93,137.79,0.651
19.95,137.95,0.669
19.97,138.11,0.689
19.98,138.27,0.708
20.00,138.43,0.728
20.02,138.59,0.746
20.03,138.75,0.769
20.05,138.91,0.790
20.07,139.06,0.815
20.08,139.22,0.839
20.10,139.38,0.860
20.12,139.54,0.882
20.13,139.69,0.904
20.15,139.85,0.930
20.17,140.01,0.955
20.18,140.16,0.984
20.20,140.32,1.013
20.22,140.48,1.035
20.23,140.63,1.062
20.25,140.79,1.089
20.27,140.94,1.110
20.28,141.10,1.133
20.30,141.26,1.159
20.32,141.41,1.185
20.33,141.57,1.216
20.35,141.72,1.244
20.37,141.88,1.272
20.38,142.03,1.304
20.40,142.19,1.331
20.42,142.34,1.362
20.43,142.50,1.394
20.45,142.65,1.408
20.47,142.81,1.438
20.48,142.96,1.454
20.50,143.12,1.451
20.52,143.28,1.467
20.53,143.44,1.486
20.55,143.60,1.467
20.57,143.77,1.461
20.58,143.93,1.480
20.60,144.09,1.515
20.62,144.26,1.520
20.63,144.42,1.513
20.65,144.58,1.532
20.67,144.75,1.506
20.68,144.91,1.506
20.70,145.07,1.599
20.72,145.23,1.606
20.73,145.39,1.639
20.75,145.54,1.721
20.77,145.69,1.806
20.78,145.82,2.021
20.80,145.95,2.039
20.82,146.08,2.210
20.83,146.21,2.157
20.85,146.36,2.113
20.87,146.53,1.969
20.88,146.72,1.769
20.90,146.91,1.668
20.92,147.11,1.616
20.93,147.31,1.508
20.95,147.51,1.378
20.97,147.72,1.249
20.98,147.93,1.163
21.00,148.14,1.092
21.02,148.34,1.020
21.03,148.55,0.960
21.05,148.75,0.897
21.07,148.94,0.847
21.08,149.14,0.795
21.10,149.33,0.748
21.12,149.52,0.703
21.13,149.71,0.672
21.15,149.90,0.635
21.17,150.08,0.601
21.18,150.26,0.582
21.20,150.45,0.551
21.22,150.63,0.524
21.23,150.81,0.497
21.25,150.99,0.469
21.27,151.17,0.444
21.28,151.34,0.420
21.30,151.52,0.399
21.32,151.70,0.382
21.33,151.88,0.367
21.35,152.05,0.351
21.37,152.23,0.339
21.38,152.40,0.327
21.40,152.58,0.318
21.42,152.75,0.307
21.43,152.92,0.299
21.45,153.09,0.291
21.47,153.26,0.284
21.48,153.43,0.278
21.50,153.60,0.271
21.52,153.77,0.266
21.53,153.94,0.260
21.55,154.11,0.255
21.57,154.28,0.252
21.58,154.45,0.247
21.60,154.62,0.246
21.62,154.79,0.242
21.63,154.96,0.240
21.65,155.12,0.237
21.67,155.29,0.236
21.68,155.46,0.234
21.70,155.63,0.233
21.72,155.80,0.232
21.73,155.96,0.231
21.75,156.13,0.229
21.77,156.30,0.228
21.78,156.47,0.226
21.80,156.63,0.225
21.82,156.80,0.224
21.83,156.97,0.222
21.85,157.13,0.222
21.87,157.30,0.221
21.88,157.47,0.221
21.90,157.64,0.220
21.92,157.80,0.220
21.93,157.97,0.219
21.95,158.14,0.219
21.97,158.30,0.218
21.98,158.47,0.218
22.00,158.64,0.217
22.02,158.81,0.217
22.03,158.97,0.216
22.05,159.14,0.214
22.07,159.31,0.214
22.08,159.47,0.213
22.10,159.64,0.213
22.12,159.81,0.212
22.13,159.98,0.212
22.15,160.14,0.212
22.17,160.31,0.211
22.18,160.48,0.210
22.20,160.64,0.210
22.22,160.81,0.210
22.23,160.98,0.209
22.25,161.14,0.209
22.27,161.31,0.208
22.28,161.48,0.208
22.30,161.65,0.207
22.32,161.81,0.207
22.33,161.98,0.207
22.35,162.15,0.206
22.37,162.31,0.206
22.38,162.48,0.206
22.40,162.65,0.205
22.42,162.81,0.204
22.43,162.98,0.203
22.45,163.15,0.203
22.47,163.32,0.202
22.48,163.48,0.202
22.50,163.65,0.202
22.52,163.82,0.202
22.53,163.98,0.201
22.55,164.15,0.201
22.57,164.32,0.201
22.58,164.48,0.200
22.60,164.65,0.200
22.62,164.82,0.200
22.63,164.98,0.199
22.65,165.15,0.199
22.67,165.32,0.198
22.68,165.49,0.198
22.70,165.65,0.197
22.72,165.82,0.197
22.73,165.99,0.196
22.75,166.15,0.196
22.77,166.32,0.196
22.78,166.49,0.196
22.80,166.66,0.195
22.82,166.82,0.195
22.83,166.99,0.195
22.85,167.16,0.195
22.87,167.32,0.195
22.88,167.49,0.195
22.90,167.66,0.194
22.92,167.82,0.194
22.93,167.99,0.194
22.95,168.15,
22.97,168.32,
22.98,168.49,
22.99,,

[step]
Ramp 10.00 °C/min to -60.00 °C
Time,Temperature,Heat Flow (Normalized)
min,°C,W/g
23.09,169.45,0.302
23.11,169.54,0.295
23.13,169.60,0.338
23.14,169.65,0.371
23.16,169.68,0.400
23.18,169.68,0.435
23.19,169.66,0.475
23.21,169.61,0.506
23.23,169.53,0.518
23.24,169.45,0.505
23.26,169.35,0.468
23.28,169.24,0.420
23.29,169.13,0.363
23.31,169.02,0.307
23.33,168.89,0.254
23.34,168.77,0.206
23.36,168.64,0.164
23.38,168.51,0.125
23.39,168.38,0.089
23.41,168.24,0.058
23.43,168.10,0.028
23.44,167.95,0.003
23.46,167.81,-0.022
23.48,167.66,-0.044
23.49,167.51,-0.063
23.51,167.36,-0.082
23.53,167.21,-0.097
23.54,167.06,-0.112
23.56,166.91,-0.124
23.58,166.75,-0.137
23.59,166.60,-0.148
23.61,166.44,-0.157
23.63,166.28,-0.166
23.64,166.12,-0.174
23.66,165.97,-0.182
23.68,165.81,-0.187
23.69,165.65,-0.192
23.71,165.49,-0.198
23.73,165.33,-0.203
23.74,165.16,-0.208
23.76,165.00,-0.211
23.78,164.84,-0.215
23.79,164.68,-0.218
23.81,164.52,-0.221
23.83,164.35,-0.224
23.84,164.19,-0.226
23.86,164.03,-0.228
23.88,163.87,-0.229
23.89,163.70,-0.232
23.91,163.54,-0.234
23.93,163.38,-0.234
23.94,163.21,-0.236
23.96,163.05,-0.236
23.98,162.88,-0.237
23.99,162.72,-0.238
24.01,162.55,-0.239
24.03,162.39,-0.240
24.04,162.22,-0.240
24.06,162.06,-0.242
24.08,161.89,-0.242
24.09,161.73,-0.243
24.11,161.56,-0.243
24.13,161.40,-0.243
24.14,161.23,-0.243
24.16,161.07,-0.244
24.18,160.90,-0.244
24.19,160.74,-0.244
24.21,160.57,-0.245
24.23,160.41,-0.245
24.24,160.24,-0.245
24.26,160.08,-0.245
24.28,159.91,-0.245
24.29,159.75,-0.245
24.31,159.58,-0.245
24.33,159.41,-0.246
24.34,159.25,-0.246
24.36,159.08,-0.246
24.38,158.92,-0.246
24.39,158.75,-0.246
24.41,158.58,-0.246
24.43,158.42,-0.246
24.44,158.25,-0.246
24.46,158.09,-0.246
24.48,157.92,-0.246
24.49,157.76,-0.246
24.51,157.59,-0.246
24.53,157.42,-0.246
24.54,157.26,-0.246
24.56,157.09,-0.246
24.58,156.92,-0.246
24.59,156.76,-0.246
24.61,156.59,-0.246
24.63,156.43,-0.246
24.64,156.26,-0.245
24.66,156.09,-0.245
24.68,155.93,-0.245
24.69,155.76,-0.245
24.71,155.60,-0.245
24.73,155.43,-0.244
24.74,155.26,-0.244
24.76,155.10,-0.244
24.78,154.93,-0.244
24.79,154.76,-0.244
24.81,154.60,-0.243
24.83,154.43,-0.243
24.84,154.26,-0.243
24.86,154.10,-0.243
24.88,153.93,-0.243
24.89,153.76,-0.243
24.91,153.60,-0.242
24.93,153.43,-0.242
24.94,153.26,-0.242
24.96,153.10,-0.242
24.98,152.93,-0.242
24.99,152.77,-0.242
25.01,152.60,-0.241
25.03,152.43,-0.241
25.04,152.27,-0.241
25.06,152.10,-0.241
25.08,151.93,-0.241
25.09,151.77,-0.240
25.11,151.60,-0.240
25.13,151.44,-0.239
25.14,151.27,-0.239
25.16,151.10,-0.239
25.18,150.94,-0.239
25.19,150.77,-0.239
25.21,150.60,-0.238
25.23,150.44,-0.238
25.24,150.27,-0.238
25.26,150.10,-0.238
25.28,149.94,-0.237
25.29,149.77,-0.237
25.31,149.60,-0.237
25.33,149.44,-0.237
25.34,149.27,-0.236
25.36,149.10,-0.236
25.38,148.94,-0.236
25.39,148.77,-0.236
25.41,148.61,-0.235
25.43,148.44,-0.235
25.44,148.27,-0.235
25.46,148.11,-0.235
25.48,147.94,-0.235
25.49,147.77,-0.234
25.51,147.61,-0.234
25.53,147.44,-0.234
25.54,147.27,-0.234
25.56,147.11,-0.234
25.58,146.94,-0.233
25.59,146.77,-0.233
25.61,146.61,-0.233
25.63,146.44,-0.233
25.64,146.27,-0.232
25.66,146.11,-0.232
25.68,145.94,-0.232
25.69,145.77,-0.232
25.71,145.61,-0.231
25.73,145.44,-0.231
25.74,145.27,-0.231
25.76,145.11,-0.231
25.78,144.94,-0.230
25.79,144.78,-0.230
25.81,144.61,-0.230
25.83,144.44,-0.230
25.84,144.28,-0.229
25.86,144.11,-0.229
25.88,143.94,-0.229
25.89,143.78,-0.228
25.91,143.61,-0.228
25.93,143.44,-0.228
25.94,143.28,-0.228
25.96,143.11,-0.228
25.98,142.94,-0.227
25.99,142.78,-0.227
26.01,142.61,-0.227
26.03,142.44,-0.226
26.04,142.28,-0.226
26.06,142.11,-0.226
26.08,141.94,-0.226
26.09,141.78,-0.226
26.11,141.61,-0.226
26.13,141.44,-0.225
26.14,141.28,-0.225
26.16,141.11,-0.225
26.18,140.95,-0.225
26.19,140.78,-0.224
26.21,140.61,-0.224
26.23,140.45,-0.224
26.24,140.28,-0.224
26.26,140.11,-0.224
26.28,139.95,-0.224
26.29,139.78,-0.224
26.31,139.61,-0.224
26.33,139.45,-0.223
26.34,139.28,-0.223
26.36,139.12,-0.223
26.38,138.95,-0.223
26.39,138.78,-0.223
26.41,138.61,-0.223
26.43,138.45,-0.222
26.44,138.28,-0.222
26.46,138.12,-0.222
26.48,137.95,-0.222
26.49,137.78,-0.222
26.51,137.62,-0.222
26.53,137.45,-0.222
26.54,137.28,-0.222
26.56,137.12,-0.222
26.58,136.95,-0.222
26.59,136.78,-0.221
26.61,136.62,-0.221
26.63,136.45,-0.221
26.64,136.28,-0.221
26.66,136.12,-0.221
26.68,135.95,-0.221
26.69,135.78,-0.221
26.71,135.62,-0.221
26.73,135.45,-0.221
26.74,135.28,-0.221
26.76,135.12,-0.221
26.78,134.95,-0.221
26.79,134.79,-0.221
26.81,134.62,-0.220
26.83,134.45,-0.220
26.84,134.28,-0.220
26.86,134.12,-0.220
26.88,133.95,-0.220
26.89,133.79,-0.220
26.91,133.62,-0.220
26.93,133.45,-0.220
26.94,133.29,-0.220
26.96,133.12,-0.220
26.98,132.95,-0.220
26.99,132.79,-0.219
27.01,132.62,-0.219
27.03,132.45,-0.219
27.04,132.29,-0.219
27.06,132.12,-0.219
27.08,131.95,-0.219
27.09,131.79,-0.219
27.11,131.62,-0.219
27.13,131.46,-0.219
27.14,131.29,-0.219
27.16,131.12,-0.219
27.18,130.96,-0.219
27.19,130.79,-0.219
27.21,130.62,-0.219
27.23,130.46,-0.219
27.24,130.29,-0.218
27.26,130.12,-0.218
27.28,129.96,-0.218
27.29,129.79,-0.218
27.31,129.62,-0.218
27.33,129.46,-0.218
27.34,129.29,-0.218
27.36,129.13,-0.218
27.38,128.96,-0.218
27.39,128.79,-0.218
27.41,128.63,-0.218
27.43,128.46,-0.218
27.44,128.29,-0.218
27.46,128.12,-0.218
27.48,127.96,-0.218
27.49,127.79,-0.217
27.51,127.63,-0.217
27.53,127.46,-0.217
27.54,127.29,-0.218
27.56,127.13,-0.218
27.58,126.96,-0.218
27.59,126.79,-0.217
27.61,126.63,-0.217
27.63,126.46,-0.217
27.64,126.30,-0.217
27.66,126.13,-0.217
27.68,125.96,-0.217
27.69,125.79,-0.217
27.71,125.63,-0.217
27.73,125.46,-0.217
27.74,125.30,-0.217
27.76,125.13,-0.217
27.78,124.96,-0.217
27.79,124.80,-0.217
27.81,124.63,-0.217
27.83,124.46,-0.217
27.84,124.30,-0.217
27.86,124.13,-0.217
27.88,123.96,-0.217
27.89,123.80,-0.217
27.91,123.63,-0.217
27.93,123.46,-0.217
27.94,123.30,-0.217
27.96,123.13,-0.216
27.98,122.97,-0.216
27.99,122.80,-0.216
28.01,122.63,-0.216
28.03,122.47,-0.216
28.04,122.30,-0.216
28.06,122.13,-0.216
28.08,121.97,-0.216
28.09,121.80,-0.216
28.11,121.63,-0.216
28.13,121.47,-0.216
28.14,121.30,-0.216
28.16,121.14,-0.216
28.18,120.97,-0.216
28.19,120.80,-0.216
28.21,120.64,-0.216
28.23,120.47,-0.216
28.24,120.30,-0.216
28.26,120.14,-0.216
28.28,119.97,-0.216
28.29,119.80,-0.216
28.31,119.64,-0.216
28.33,119.47,-0.216
28.34,119.30,-0.216
28.36,119.14,-0.216
28.38,118.97,-0.215
28.39,118.81,-0.215
28.41,118.64,-0.215
28.43,118.47,-0.215
28.44,118.31,-0.215
28.46,118.14,-0.215
28.48,117.97,-0.215
28.49,117.81,-0.215
28.51,117.64,-0.215
28.53,117.47,-0.215
28.54,117.31,-0.215
28.56,117.14,-0.215
28.58,116.97,-0.215
28.59,116.81,-0.215
28.61,116.64,-0.215
28.63,116.47,-0.215
28.64,116.31,-0.215
28.66,116.14,-0.215
28.68,115.97,-0.215
28.69,115.81,-0.215
28.71,115.64,-0.215
28.73,115.48,-0.215
28.74,115.31,-0.215
28.76,115.14,-0.215
28.78,114.98,-0.215
28.79,114.81,-0.215
28.81,114.64,-0.215
28.83,114.48,-0.215
28.84,114.31,-0.215
28.86,114.14,-0.215
28.88,113.98,-0.215
28.89,113.81,-0.215
28.91,113.64,-0.215
28.93,113.48,-0.214
28.94,113.31,-0.214
28.96,113.15,-0.214
28.98,112.98,-0.214
28.99,112.81,-0.214
29.01,112.64,-0.214
29.03,112.48,-0.214
29.04,112.31,-0.214
29.06,112.15,-0.214
29.08,111.98,-0.214
29.09,111.81,-0.214
29.11,111.65,-0.214
29.13,111.48,-0.214
29.14,111.31,-0.214
29.16,111.15,-0.214
29.18,110.98,-0.214
29.19,110.81,-0.214
29.21,110.65,-0.214
29.23,110.48,-0.214
29.24,110.31,-0.214
29.26,110.15,-0.214
29.28,109.98,-0.214
29.29,109.82,-0.214
29.31,109.65,-0.214
29.33,109.48,-0.213
29.34,109.32,-0.214
29.36,109.15,-0.214
29.38,108.98,-0.214
29.39,108.82,-0.214
29.41,108.65,-0.213
29.43,108.48,-0.213
29.44,108.32,-0.213
29.46,108.15,-0.213
29.48,107.98,-0.213
29.49,107.82,-0.213
29.51,107.65,-0.213
29.53,107.48,-0.213
29.54,107.32,-0.213
29.56,107.15,-0.213
29.58,106.99,-0.213
29.59,106.82,-0.213
29.61,106.65,-0.213
29.63,106.49,-0.213
29.64,106.32,-0.213
29.66,106.15,-0.213
29.68,105.99,-0.213
29.69,105.82,-0.213
29.71,105.65,-0.213
29.73,105.49,-0.213
29.74,105.32,-0.213
29.76,105.15,-0.213
29.78,104.99,-0.213
29.79,104.82,-0.213
29.81,104.65,-0.213
29.83,104.49,-0.213
29.84,104.32,-0.213
29.86,104.16,-0.213
29.88,103.99,-0.213
29.89,103.82,-0.213
29.91,103.66,-0.213
29.93,103.49,-0.213
29.94,103.32,-0.213
29.96,103.16,-0.213
29.98,102.99,-0.212
29.99,102.82,-0.212
30.01,102.66,-0.212
30.03,102.49,-0.212
30.04,102.32,-0.212
30.06,102.16,-0.212
30.08,101.99,-0.212
30.09,101.82,-0.212
30.11,101.66,-0.212
30.13,101.49,-0.212
30.14,101.32,-0.212
30.16,101.16,-0.212
30.18,100.99,-0.212
30.19,100.83,-0.212
30.21,100.66,-0.212
30.23,100.49,-0.212
30.24,100.33,-0.212
30.26,100.16,-0.212
30.28,99.99,-0.212
30.29,99.83,-0.212
30.31,99.66,-0.212
30.33,99.49,-0.212
30.34,99.33,-0.212
30.36,99.16,-0.212
30.38,98.99,-0.211
30.39,98.83,-0.211
30.41,98.66,-0.211
30.43,98.50,-0.211
30.44,98.33,-0.211
30.46,98.16,-0.211
30.48,98.00,-0.211
30.49,97.83,-0.211
[...]
96.09,-42.76,0.050
96.10,-42.69,0.051
96.11,-42.62,0.051
96.11,-42.56,0.051
96.12,-42.49,0.051
96.13,-42.42,0.051
96.13,-42.36,0.051
96.14,-42.29,0.051
96.15,-42.22,0.051
96.15,-42.16,0.051
96.16,-42.09,0.051
96.17,-42.03,0.052
96.17,-41.96,0.052
96.18,-41.89,0.052
96.19,-41.82,0.052
96.19,-41.76,0.052
96.20,-41.69,0.052
96.21,-41.62,0.052
96.21,-41.56,0.052
96.22,-41.49,0.052
96.23,-41.42,0.052
96.23,-41.36,0.052
96.24,-41.29,0.052
96.25,-41.22,0.052
96.25,-41.16,0.052
96.26,-41.09,0.053
96.27,-41.02,0.053
96.27,-40.96,0.053
96.28,-40.89,0.053
96.29,-40.82,0.053
96.29,-40.75,0.053
96.30,-40.69,0.053
96.31,-40.62,0.053
96.31,-40.56,0.053
96.32,-40.49,0.053
96.33,-40.42,0.053
96.33,-40.35,0.053
96.34,-40.29,0.053
96.35,-40.22,0.053
96.35,-40.16,0.053
96.36,-40.09,0.054
96.37,-40.02,0.054
96.37,-39.96,0.054
96.38,-39.89,0.054
96.39,-39.82,0.054
96.39,-39.76,0.054
96.40,-39.69,0.054
96.41,-39.62,0.054
96.41,-39.56,0.054
96.42,-39.49,0.054
96.43,-39.42,0.054
96.43,-39.36,0.054
96.44,-39.29,0.054
96.45,-39.22,0.054
96.45,-39.16,0.054
96.46,-39.09,0.054
96.47,-39.02,0.054
96.47,-38.95,0.054
96.48,-38.89,0.055
96.49,-38.82,0.055
96.49,-38.75,0.055
96.50,-38.69,0.055
96.51,-38.62,0.055
96.51,-38.56,0.055
96.52,-38.49,0.055
96.53,-38.42,0.055
96.53,-38.35,0.055
96.54,-38.29,0.055
96.55,-38.22,0.055
96.55,-38.16,0.055
96.56,-38.09,0.055
96.57,-38.02,0.055
96.57,-37.95,0.055
96.58,-37.89,0.055
96.59,-37.82,0.055
96.59,-37.76,0.055
96.60,-37.69,0.055
96.61,-37.62,0.056
96.61,-37.55,0.056
96.62,-37.49,0.056
96.63,-37.42,0.056
96.63,-37.35,0.056
96.64,-37.29,0.056
96.65,-37.22,0.056
96.65,-37.15,0.056
96.66,-37.09,0.056
96.67,-37.02,0.056
96.67,-36.95,0.056
96.68,-36.89,0.056
96.69,-36.82,0.056
96.69,-36.75,0.056
96.70,-36.69,0.056
96.71,-36.62,0.056
96.71,-36.55,0.056
96.72,-36.49,0.056
96.73,-36.42,0.056
96.73,-36.35,0.056
96.74,-36.29,0.056
96.75,-36.22,0.057
96.75,-36.15,0.057
96.76,-36.09,0.057
96.77,-36.02,0.057
96.77,-35.95,0.057
96.78,-35.89,0.057
96.79,-35.82,0.057
96.79,-35.75,0.057
96.80,-35.69,0.057
96.81,-35.62,0.057
96.81,-35.55,0.057
96.82,-35.49,0.057
96.83,-35.42,0.057
96.83,-35.35,0.057
96.84,-35.29,0.057
96.85,-35.22,0.057
96.85,-35.15,0.057
96.86,-35.08,0.057
96.87,-35.02,0.057
96.87,-34.95,0.057
96.88,-34.89,0.057
96.89,-34.82,0.057
96.89,-34.75,0.057
96.90,-34.68,0.057
96.91,-34.62,0.057
96.91,-34.55,0.058
96.92,-34.49,0.058
96.93,-34.42,0.058
96.93,-34.35,0.058
96.94,-34.29,0.058
96.95,-34.22,0.058
96.95,-34.15,0.058
96.96,-34.09,0.058
96.97,-34.02,0.058
96.97,-33.95,0.058
96.98,-33.88,0.058
96.99,-33.82,0.058
96.99,-33.75,0.058
97.00,-33.69,0.058
97.01,-33.62,0.058
97.01,-33.55,0.058
97.02,-33.48,0.058
97.03,-33.42,0.058
97.03,-33.35,0.058
97.04,-33.28,0.058
97.05,-33.22,0.058
97.05,-33.15,0.058
97.06,-33.08,0.058
97.07,-33.02,0.058
97.07,-32.95,0.058
97.08,-32.88,0.058
97.09,-32.82,0.059
97.09,-32.75,0.059
97.10,-32.68,0.059
97.11,-32.62,0.059
97.11,-32.55,0.059
97.12,-32.49,0.059
97.13,-32.42,0.059
97.13,-32.35,0.059
97.14,-32.28,0.059
97.15,-32.22,0.059
97.15,-32.15,0.059
97.16,-32.08,0.059
97.17,-32.02,0.059
97.17,-31.95,0.059
97.18,-31.88,0.059
97.19,-31.82,0.059
97.19,-31.75,0.059
97.20,-31.68,0.059
97.21,-31.62,0.059
97.21,-31.55,0.059
97.22,-31.48,0.059
97.23,-31.42,0.059
97.23,-31.35,0.059
97.24,-31.28,0.059
97.25,-31.22,0.059
97.25,-31.15,0.059
97.26,-31.08,0.059
97.27,-31.02,0.060
97.27,-30.95,0.060
97.28,-30.88,0.060
97.29,-30.82,0.060
97.29,-30.75,0.060
97.30,-30.68,0.060
97.31,-30.62,0.060
97.31,-30.55,0.060
97.32,-30.48,0.060
97.33,-30.42,0.060
97.33,-30.35,0.060
97.34,-30.28,0.060
97.35,-30.22,0.060
97.35,-30.15,0.060
97.36,-30.08,0.060
97.37,-30.02,0.060
97.37,-29.95,0.060
97.38,-29.88,0.060
97.39,-29.82,0.060
97.39,-29.75,0.060
97.40,-29.68,0.060
97.41,-29.62,0.060
97.41,-29.55,0.060
97.42,-29.48,0.060
97.43,-29.41,0.060
97.43,-29.35,0.060
97.44,-29.28,0.060
97.45,-29.21,0.060
97.45,-29.15,0.060
97.46,-29.08,0.060
97.47,-29.01,0.060
97.47,-28.95,0.060
97.48,-28.88,0.061
97.49,-28.81,0.061
97.49,-28.75,0.061
97.50,-28.68,0.061
97.51,-28.61,0.061
97.51,-28.55,0.061
97.52,-28.48,0.061
97.53,-28.41,0.061
97.53,-28.35,0.061
97.54,-28.28,0.060
97.55,-28.21,0.060
97.55,-28.14,0.060
97.56,-28.08,0.060
97.57,-28.01,0.060
97.57,-27.94,0.060
97.58,-27.88,0.060
97.59,-27.81,0.060
97.59,-27.74,0.060
97.60,-27.67,0.060
97.61,-27.61,0.060
97.61,-27.54,0.061
97.62,-27.47,0.061
97.63,-27.41,0.061
97.63,-27.34,0.061
97.64,-27.27,0.061
97.65,-27.21,0.062
97.65,-27.14,0.062
97.66,-27.07,0.062
97.67,-27.01,0.062
97.67,-26.94,0.062
97.68,-26.87,0.063
97.69,-26.81,0.063
97.69,-26.74,0.063
97.70,-26.67,0.063
97.71,-26.60,0.063
97.71,-26.54,0.063
97.72,-26.47,0.063
97.73,-26.41,0.063
97.73,-26.34,0.063
97.74,-26.27,0.063
97.75,-26.21,0.063
97.75,-26.14,0.063
97.76,-26.07,0.063
97.77,-26.00,0.063
97.77,-25.94,0.063
97.78,-25.87,0.063
97.79,-25.81,0.063
97.79,-25.74,0.063
97.80,-25.67,0.063
97.81,-25.61,0.063
97.81,-25.54,0.063
97.82,-25.47,0.063
97.83,-25.41,0.063
97.83,-25.34,0.064
97.84,-25.27,0.064
97.85,-25.21,0.064
97.85,-25.14,0.064
97.86,-25.07,0.064
97.87,-25.01,0.064
97.87,-24.94,0.064
97.88,-24.87,0.064
97.89,-24.81,0.064
97.89,-24.74,0.064
97.90,-24.67,0.064
97.91,-24.61,0.064
97.91,-24.54,0.064
97.92,-24.47,0.064
97.93,-24.41,0.064
97.93,-24.34,0.064
97.94,-24.27,0.064
97.95,-24.20,0.064
97.95,-24.14,0.064
97.96,-24.07,0.064
97.97,-24.00,0.064
97.97,-23.94,0.064
97.98,-23.87,0.064
97.99,-23.81,0.064
97.99,-23.74,0.064
98.00,-23.67,0.064
98.01,-23.61,0.064
98.01,-23.54,0.064
98.02,-23.47,0.064
98.03,-23.40,0.064
98.03,-23.34,0.064
98.04,-23.27,0.064
98.05,-23.21,0.064
98.05,-23.14,0.064
98.06,-23.07,0.064
98.07,-23.01,0.064
98.07,-22.94,0.064
98.08,-22.87,0.064
98.09,-22.81,0.064
98.09,-22.74,0.064
98.10,-22.67,0.064
98.11,-22.61,0.064
98.11,-22.54,0.064
98.12,-22.47,0.064
98.13,-22.41,0.064
98.13,-22.34,0.064
98.14,-22.27,0.064
98.15,-22.21,0.064
98.15,-22.14,0.064
98.16,-22.07,0.064
98.17,-22.01,0.064
98.17,-21.94,0.064
98.18,-21.87,0.064
98.19,-21.80,0.064
98.19,-21.74,0.064
98.20,-21.67,0.064
98.21,-21.61,0.064
98.21,-21.54,0.064
98.22,-21.47,0.064
98.23,-21.40,0.064
98.23,-21.34,0.064
98.24,-21.27,0.064
98.25,-21.20,0.064
98.25,-21.14,0.064
98.26,-21.07,0.064
98.27,-21.00,0.065
98.27,-20.94,0.065
98.28,-20.87,0.065
98.29,-20.81,0.065
98.29,-20.74,0.065
98.30,-20.67,0.065
98.31,-20.60,0.065
98.31,-20.54,0.065
98.32,-20.47,0.065
98.33,-20.40,0.065
98.33,-20.34,0.065
98.34,-20.27,0.065
98.35,-20.20,0.065
98.35,-20.14,0.065
98.36,-20.07,0.065
98.37,-20.00,0.065
98.37,-19.94,0.065
98.38,-19.87,0.065
98.39,-19.80,0.065
98.39,-19.74,0.065
98.40,-19.67,0.065
98.41,-19.60,0.065
98.41,-19.54,0.066
98.42,-19.47,0.066
98.43,-19.40,0.066
98.43,-19.34,0.066
98.44,-19.27,0.066
98.45,-19.20,0.066
98.45,-19.14,0.066
98.46,-19.07,0.066
98.47,-19.00,0.066
98.47,-18.94,0.066
98.48,-18.87,0.066
98.49,-18.80,0.066
98.49,-18.74,0.066
98.50,-18.67,0.066
98.51,-18.60,0.066
98.51,-18.54,0.066
98.52,-18.47,0.066
98.53,-18.40,0.066
98.53,-18.34,0.066
98.54,-18.27,0.066
98.55,-18.20,0.066
98.55,-18.14,0.066
98.56,-18.07,0.066
98.57,-18.00,0.066
98.57,-17.93,0.066
98.58,-17.87,0.066
98.59,-17.80,0.066
98.59,-17.74,0.066
98.60,-17.67,0.066
98.61,-17.60,0.066
98.61,-17.53,0.066
98.62,-17.47,0.066
98.63,-17.40,0.066
98.63,-17.34,0.066
98.64,-17.27,0.066
98.65,-17.20,0.067
98.65,-17.13,0.067
98.66,-17.07,0.067
98.67,-17.00,0.067
98.67,-16.93,0.067
98.68,-16.87,0.067
98.69,-16.80,0.067
98.69,-16.73,0.067
98.70,-16.67,0.067
98.71,-16.60,0.067
98.71,-16.53,0.067
98.72,-16.47,0.067
98.73,-16.40,0.067
98.73,-16.33,0.067
98.74,-16.27,0.067
98.75,-16.20,0.067
98.75,-16.13,0.067
98.76,-16.07,0.067
98.77,-16.00,0.067
98.77,-15.93,0.067
98.78,-15.87,0.067
98.79,-15.80,0.067
98.79,-15.73,0.067
98.80,-15.67,0.067
98.81,-15.60,0.067
98.81,-15.53,0.067
98.82,-15.47,0.067
98.83,-15.40,0.067
98.83,-15.33,0.067
98.84,-15.27,0.067
98.85,-15.20,0.068
98.85,-15.13,0.068
98.86,-15.06,0.068
98.87,-15.00,0.068
98.87,-14.93,0.068
98.88,-14.86,0.068
98.89,-14.80,0.068
98.89,-14.73,0.068
98.90,-14.66,0.068
98.91,-14.60,0.068
98.91,-14.53,0.068
98.92,-14.46,0.068
98.93,-14.40,0.068
98.93,-14.33,0.068
98.94,-14.26,0.068
98.95,-14.20,0.068
98.95,-14.13,0.068
98.96,-14.06,0.068
98.97,-14.00,0.068
98.97,-13.93,0.068
98.98,-13.86,0.068
98.99,-13.80,0.068
98.99,-13.73,0.069
99.00,-13.66,0.069
99.01,-13.60,0.069
99.01,-13.53,0.069
99.02,-13.46,0.069
99.03,-13.40,0.069
99.03,-13.33,0.069
99.04,-13.26,0.069
99.05,-13.20,0.069
99.05,-13.13,0.069
99.06,-13.06,0.069
99.07,-13.00,0.069
99.07,-12.93,0.069
99.08,-12.86,0.069
99.09,-12.80,0.069
99.09,-12.73,0.069
99.10,-12.66,0.069
99.11,-12.60,0.069
99.11,-12.53,0.069
99.12,-12.46,0.069
99.13,-12.40,0.069
99.13,-12.33,0.069
99.14,-12.26,0.069
99.15,-12.20,0.069
99.15,-12.13,0.070
99.16,-12.06,0.070
99.17,-11.99,0.070
99.17,-11.93,0.070
99.18,-11.86,0.070
99.19,-11.80,0.070
99.19,-11.73,0.070
99.20,-11.66,0.070
99.21,-11.60,0.070
99.21,-11.53,0.070
99.22,-11.46,0.070
99.23,-11.39,0.070
99.23,-11.33,0.070
99.24,-11.26,0.070
99.25,-11.19,0.070
99.25,-11.13,0.070
99.26,-11.06,0.070
99.27,-11.00,0.070
99.27,-10.93,0.070
99.28,-10.86,0.070
99.29,-10.80,0.070
99.29,-10.73,0.070
99.30,-10.66,0.070
99.31,-10.60,0.070
99.31,-10.53,0.070
99.32,-10.46,0.070
99.33,-10.40,0.070
99.33,-10.33,0.070
99.34,-10.26,0.070
99.35,-10.20,0.071
99.35,-10.13,0.071
99.36,-10.06,0.071
99.37,-10.00,0.071
99.37,-9.93,0.071
99.38,-9.86,0.071
99.39,-9.80,0.071
99.39,-9.73,0.071
99.40,-9.66,0.071
99.41,-9.59,0.071
99.41,-9.53,0.071
99.42,-9.46,0.071
99.43,-9.39,0.071
99.43,-9.33,0.071
99.44,-9.26,0.071
99.45,-9.19,0.071
99.45,-9.13,0.071
99.46,-9.06,0.071
99.47,-8.99,0.071
99.47,-8.93,0.071
99.48,-8.86,0.071
99.49,-8.79,0.071
99.49,-8.73,0.071
99.50,-8.66,0.071
99.51,-8.59,0.071
99.51,-8.53,0.071
99.52,-8.46,0.071
99.53,-8.39,0.071
99.53,-8.33,0.071
99.54,-8.26,0.071
99.55,-8.19,0.071
99.55,-8.13,0.071
99.56,-8.06,0.072
99.57,-7.99,0.072
99.57,-7.93,0.072
99.58,-7.86,0.072
99.59,-7.79,0.072
99.59,-7.73,0.072
99.60,-7.66,0.072
99.61,-7.59,0.072
99.61,-7.53,0.072
99.62,-7.46,0.072
99.63,-7.39,0.072
99.63,-7.33,0.072
99.64,-7.26,0.072
99.65,-7.19,0.072
99.65,-7.13,0.072
99.66,-7.06,0.072
99.67,-6.99,0.072
99.67,-6.93,0.072
99.68,-6.86,0.072
99.69,-6.79,0.072
99.69,-6.73,0.072
99.70,-6.66,0.072
99.71,-6.59,0.072
99.71,-6.53,0.073
99.72,-6.46,0.073
99.73,-6.39,0.073
99.73,-6.33,0.073
99.74,-6.26,0.073
99.75,-6.19,0.073
99.75,-6.12,0.073
99.76,-6.06,0.073
99.77,-5.99,0.073
99.77,-5.93,0.073
99.78,-5.86,0.073
99.79,-5.79,0.073
99.79,-5.72,0.073
99.80,-5.66,0.073
99.81,-5.59,0.073
99.81,-5.53,0.073
99.82,-5.46,0.073
99.83,-5.39,0.073
99.83,-5.32,0.073
99.84,-5.26,0.074
99.85,-5.19,0.074
99.85,-5.12,0.074
99.86,-5.06,0.074
99.87,-4.99,0.074
99.87,-4.92,0.074
99.88,-4.86,0.074
99.89,-4.79,0.074
99.89,-4.72,0.074
99.90,-4.66,0.074
99.91,-4.59,0.074
99.91,-4.52,0.074
99.92,-4.46,0.074
99.93,-4.39,0.074
99.93,-4.32,0.074
99.94,-4.26,0.074
99.95,-4.19,0.074
99.95,-4.12,0.074
99.96,-4.06,0.074
99.97,-3.99,0.074
99.97,-3.92,0.074
99.98,-3.86,0.075
99.99,-3.79,0.075
99.99,-3.72,0.075
100.00,-3.66,0.075
100.01,-3.59,0.075
100.01,-3.52,0.075
100.02,-3.46,0.075
100.03,-3.39,0.075
100.03,-3.32,0.075
100.04,-3.25,0.075
100.05,-3.19,0.075
100.05,-3.12,0.075
100.06,-3.06,0.075
100.07,-2.99,0.075
100.07,-2.92,0.075
100.08,-2.86,0.075
100.09,-2.79,0.075
100.09,-2.72,0.075
100.10,-2.66,0.075
100.11,-2.59,0.075
100.11,-2.52,0.076
100.12,-2.46,0.076
100.13,-2.39,0.076
100.13,-2.32,0.076
100.14,-2.26,0.076
100.15,-2.19,0.076
100.15,-2.12,0.076
100.16,-2.05,0.076
100.17,-1.99,0.076
100.17,-1.92,0.076
100.18,-1.85,0.076
100.19,-1.79,0.076
100.19,-1.72,0.076
100.20,-1.65,0.076
100.21,-1.59,0.076
100.21,-1.52,0.076
100.22,-1.45,0.076
100.23,-1.39,0.077
100.23,-1.32,0.077
100.24,-1.25,0.077
100.25,-1.19,0.077
100.25,-1.12,0.077
100.26,-1.05,0.077
100.27,-0.99,0.077
100.27,-0.92,0.077
100.28,-0.85,0.077
100.29,-0.79,0.077
100.29,-0.72,0.077
100.30,-0.65,0.077
100.31,-0.59,0.077
100.31,-0.52,0.077
100.32,-0.45,0.077
100.33,-0.39,0.077
100.33,-0.32,0.077
100.34,-0.25,0.077
100.35,-0.19,0.077
100.35,-0.12,0.077
100.36,-0.05,0.077
100.37,0.01,0.077
100.37,0.08,0.077
100.38,0.15,0.078
100.39,0.22,0.078
100.39,0.28,0.078
100.40,0.35,0.078
100.41,0.41,0.078
100.41,0.48,0.078
100.42,0.55,0.078
100.43,0.62,0.078
100.43,0.68,0.078
100.44,0.75,0.078
100.45,0.81,0.078
100.45,0.88,0.078
100.46,0.95,0.078
100.47,1.02,0.078
100.47,1.08,0.078
100.48,1.15,0.078
100.49,1.22,0.078
100.49,1.28,0.078
100.50,1.35,0.078
100.51,1.41,0.078
100.51,1.48,0.079
100.52,1.55,0.079
100.53,1.62,0.079
100.53,1.68,0.079
100.54,1.75,0.079
100.55,1.82,0.079
100.55,1.88,0.079
100.56,1.95,0.079
100.57,2.02,0.079
100.57,2.08,0.079
100.58,2.15,0.079
100.59,2.22,0.079
100.59,2.28,0.079
100.60,2.35,0.079
100.61,2.42,0.079
100.61,2.48,0.079
100.62,2.55,0.079
100.63,2.62,0.079
100.63,2.68,0.080
100.64,2.75,0.080
100.65,2.82,0.080
100.65,2.88,0.080
100.66,2.95,0.080
100.67,3.02,0.080
100.67,3.08,0.080
100.68,3.15,0.080
100.69,3.22,0.080
100.69,3.28,0.080
100.70,3.35,0.080
100.71,3.42,0.080
100.71,3.48,0.080
100.72,3.55,0.080
100.73,3.62,0.081
100.73,3.68,0.081
100.74,3.75,0.081
100.75,3.82,0.081
100.75,3.88,0.081
100.76,3.95,0.081
100.77,4.02,0.081
100.77,4.08,0.081
100.78,4.15,0.081
100.79,4.22,0.081
100.79,4.28,0.081
100.80,4.35,0.081
100.81,4.42,0.081
100.81,4.48,0.082
100.82,4.55,0.082
100.83,4.62,0.082
100.83,4.68,0.082
100.84,4.75,0.082
100.85,4.82,0.082
100.85,4.88,0.082
100.86,4.95,0.082
100.87,5.02,0.082
100.87,5.08,0.082
100.88,5.15,0.082
100.89,5.22,0.083
100.89,5.28,0.083
100.90,5.35,0.083
100.91,5.42,0.083
100.91,5.48,0.083
100.92,5.55,0.083
100.93,5.62,0.083
100.93,5.68,0.083
100.94,5.75,0.083
100.95,5.82,0.083
100.95,5.88,0.084
100.96,5.95,0.084
100.97,6.02,0.084
100.97,6.08,0.084
100.98,6.15,0.084
100.99,6.22,0.084
100.99,6.29,0.084
101.00,6.35,0.084
101.01,6.42,0.084
101.01,6.48,0.084
101.02,6.55,0.084
101.03,6.62,0.084
101.03,6.69,0.084
101.04,6.75,0.084
101.05,6.82,0.084
101.05,6.88,0.084
101.06,6.95,0.085
101.07,7.02,0.085
101.07,7.09,0.085
101.08,7.15,0.085
101.09,7.22,0.085
101.09,7.28,0.085
101.10,7.35,0.085
101.11,7.42,0.086
101.11,7.49,0.086
101.12,7.55,0.086
101.13,7.62,0.086
101.13,7.69,0.086
101.14,7.75,0.086
101.15,7.82,0.086
101.15,7.89,0.086
101.16,7.95,0.086
101.17,8.02,0.086
101.17,8.09,0.087
101.18,8.15,0.087
101.19,8.22,0.087
101.19,8.29,0.087
101.20,8.35,0.087
101.21,8.42,0.087
101.21,8.48,0.087
101.22,8.55,0.087
101.23,8.62,0.087
101.23,8.69,0.088
101.24,8.75,0.088
101.25,8.82,0.088
101.25,8.89,0.088
101.26,8.95,0.088
101.27,9.02,0.088
101.27,9.09,0.088
101.28,9.15,0.089
101.29,9.22,0.089
101.29,9.28,0.090
101.30,9.35,0.090
101.31,9.42,0.090
101.31,9.49,0.090
101.32,9.55,0.090
101.33,9.62,0.090
101.33,9.68,0.090
101.34,9.75,0.090
101.35,9.82,0.091
101.35,9.89,0.091
101.36,9.95,0.091
101.37,10.02,0.091
101.37,10.08,0.091
101.38,10.15,0.091
101.39,10.22,0.092
101.39,10.28,0.092
101.40,10.35,0.092
101.41,10.42,0.092
101.41,10.49,0.092
101.42,10.55,0.092
101.43,10.62,0.093
101.43,10.69,0.093
101.44,10.75,0.093
101.45,10.82,0.093
101.45,10.88,0.093
101.46,10.95,0.093
101.47,11.02,0.094
101.47,11.08,0.094
101.48,11.15,0.094
101.49,11.22,0.094
101.49,11.28,0.094
101.50,11.35,0.095
101.51,11.42,0.095
101.51,11.48,0.095
101.52,11.55,0.095
101.53,11.62,0.095
101.53,11.68,0.096
101.54,11.75,0.096
101.55,11.82,0.096
101.55,11.88,0.096
101.56,11.95,0.096
101.57,12.02,0.097
101.57,12.08,0.098
101.58,12.15,0.098
101.59,12.22,0.099
101.59,12.28,0.099
101.60,12.35,0.100
101.61,12.42,0.100
101.61,12.48,0.100
101.62,12.55,0.101
101.63,12.62,0.101
101.63,12.68,0.102
101.64,12.75,0.102
101.65,12.82,0.103
101.65,12.88,0.103
101.66,12.95,0.104
101.67,13.02,0.104
101.67,13.08,0.104
101.68,13.15,0.105
101.69,13.22,0.105
101.69,13.28,0.106
101.70,13.35,0.106
101.71,13.42,0.106
101.71,13.48,0.106
101.72,13.55,0.107
101.73,13.62,0.108
101.73,13.68,0.108
101.74,13.75,0.108
101.75,13.82,0.109
101.75,13.88,0.109
101.76,13.95,0.110
101.77,14.01,0.110
101.77,14.08,0.110
101.78,14.15,0.110
101.79,14.21,0.110
101.79,14.28,0.111
101.80,14.35,0.111
101.81,14.42,0.111
101.81,14.48,0.112
101.82,14.55,0.112
101.83,14.61,0.112
101.83,14.68,0.113
101.84,14.75,0.114
101.85,14.81,0.115
101.85,14.88,0.115
101.86,14.95,0.115
101.87,15.01,0.116
101.87,15.08,0.116
101.88,15.15,0.117
101.89,15.21,0.118
101.89,15.28,0.118
101.90,15.34,0.118
101.91,15.41,0.119
101.91,15.48,0.119
101.92,15.55,0.119
101.93,15.61,0.120
101.93,15.68,0.120
101.94,15.74,0.120
101.95,15.81,0.120
101.95,15.88,0.121
101.96,15.94,0.121
101.97,16.01,0.121
101.97,16.08,0.122
101.98,16.14,0.123
101.99,16.21,0.123
101.99,16.28,0.123
102.00,16.34,0.124
102.01,16.41,0.124
102.01,16.48,0.124
102.02,16.54,0.125
102.03,16.61,0.125
102.03,16.68,0.126
102.04,16.74,0.127
102.05,16.81,0.128
102.05,16.88,0.128
102.06,16.94,0.129
102.07,17.01,0.129
102.07,17.07,0.129
102.08,17.14,0.130
102.09,17.21,0.130
102.09,17.27,0.130
102.10,17.34,0.130
102.11,17.41,0.131
102.11,17.47,0.131
102.12,17.54,0.131
102.13,17.61,0.132
102.13,17.67,0.132
102.14,17.74,0.132
102.15,17.81,0.132
102.15,17.87,0.132
102.16,17.94,0.133
102.17,18.01,0.133
102.17,18.07,0.133
102.18,18.14,0.133
102.19,18.21,0.133
102.19,18.27,0.133
102.20,18.34,0.134
102.21,18.41,0.134
102.21,18.47,0.134
102.22,18.54,0.134
102.23,18.61,0.134
102.23,18.67,0.135
102.24,18.74,0.135
102.25,18.81,0.135
102.25,18.87,0.135
102.26,18.94,0.135
102.27,19.01,0.135
102.27,19.07,0.135
102.28,19.14,0.135
102.29,19.21,0.135
102.29,19.27,0.135
102.30,19.34,0.135
102.31,19.41,0.136
102.31,19.47,0.136
102.32,19.54,0.136
102.33,19.61,0.136
102.33,19.67,0.136
102.34,19.74,0.136
102.35,19.81,0.136
102.35,19.87,0.136
102.36,19.94,0.136
102.37,20.01,0.136
102.37,20.07,0.136
102.38,20.14,0.136
102.39,20.21,0.136
102.39,20.27,0.137
102.40,20.34,0.137
102.41,20.41,0.137
102.41,20.47,0.137
102.42,20.54,0.137
102.43,20.61,0.137
102.43,20.67,0.137
102.44,20.74,0.137
102.45,20.81,0.137
102.45,20.88,0.137
102.46,20.94,0.137
102.47,21.01,0.137
102.47,21.07,0.137
102.48,21.14,0.137
102.49,21.21,0.137
102.49,21.28,0.137
102.50,21.34,0.137
102.51,21.41,0.137
102.51,21.48,0.137
102.52,21.54,0.137
102.53,21.61,0.137
102.53,21.67,0.137
102.54,21.74,0.137
102.55,21.81,0.137
102.55,21.88,0.137
102.56,21.94,0.137
102.57,22.01,0.137
102.57,22.08,0.137
102.58,22.14,0.137
102.59,22.21,0.137
102.59,22.28,0.137
102.60,22.34,0.137
102.61,22.41,0.137
102.61,22.48,0.137
102.62,22.54,0.137
102.63,22.61,0.137
102.63,22.68,0.137
102.64,22.74,0.137
102.65,22.81,0.137
102.65,22.88,0.137
102.66,22.94,0.137
102.67,23.01,0.137
102.67,23.08,0.137
102.68,23.14,0.137
102.69,23.21,0.137
102.69,23.28,0.137
102.70,23.34,0.137
102.71,23.41,0.137
102.71,23.48,0.137
102.72,23.54,0.137
102.73,23.61,0.137
102.73,23.68,0.137
102.74,23.75,0.137
102.75,23.81,0.137
102.75,23.88,0.137
102.76,23.95,0.137
102.77,24.01,0.137
102.77,24.08,0.137
102.78,24.15,0.137
102.79,24.21,0.137
102.79,24.28,0.137
102.80,24.35,0.137
102.81,24.41,0.137
102.81,24.48,0.137
102.82,24.55,0.137
102.83,24.61,0.137
102.83,24.68,0.137
102.84,24.75,0.137
102.85,24.81,0.137
102.85,24.88,0.137
102.86,24.95,0.137
102.87,25.01,0.137
102.87,25.08,0.137
102.88,25.15,0.137
102.89,25.21,0.137
102.89,25.28,0.137
102.90,25.35,0.137
102.91,25.41,0.137
102.91,25.48,0.137
102.92,25.55,0.137
102.93,25.61,0.137
102.93,25.68,0.137
102.94,25.75,0.137
102.95,25.81,0.137
102.95,25.88,0.137
102.96,25.95,0.137
102.97,26.01,0.137
102.97,26.08,0.137
102.98,26.15,0.137
102.99,26.21,0.137
102.99,26.28,0.137
103.00,26.35,0.138
103.01,26.41,0.138
103.01,26.48,0.138
103.02,26.55,0.138
103.03,26.62,0.138
103.03,26.68,0.138
103.04,26.75,0.138
103.05,26.82,0.138
103.05,26.88,0.138
103.06,26.95,0.138
103.07,27.02,0.138
103.07,27.08,0.138
103.08,27.15,0.138
103.09,27.22,0.138
103.09,27.28,0.138
103.10,27.35,0.138
103.11,27.42,0.138
103.11,27.48,0.138
103.12,27.55,0.138
103.13,27.62,0.138
103.13,27.68,0.138
103.14,27.75,0.138
103.15,27.82,0.138
103.15,27.88,
103.16,27.95,
103.17,28.02,
103.17,28.08,
103.18,28.15,
103.19,28.22,
103.19,28.28,
103.20,,
103.20,,