File: DSC/2025_04_13_CBD_Single_Xtal_n60C_150C_10Cmin_x3.csv
Filename,2025_04_13_CBD_Single_Xtal_n60C_150C_10Cmin_x3
Instrument name,DSC2A-00468 (192.168.1.100)
Operator,Yarger
rundate,4/13/2025
Sample name,2025_04_13_CBD_Single_Xtal_n60C_150C_10Cmin_x3
proceduresegments,Data Off ; Equilibrate -60.00 °C; Data On ; Ramp 10.00 °C/min to 150.00 °C; Data Off ; Isothermal 1.0 min; Data On ; Ramp 10.00 °C/min to -60.00 °C; Data Off ; Isothermal 1.0 min; Data On ; Ramp 10.00 °C/min to 150.00 °C; Data Off ; Isothermal 1.0 min; Data On ; Ramp 10.00 °C/min to -60.00 °C; Data Off ; Isothermal 1.0 min; Data On ; Ramp 10.00 °C/min to 150.00 °C
[File Parameters]
Run date,4/13/2025 12:07:27 AM
Trios version,5.1.1.46572
Original File Name,
Current File Name,D:\DSC2500\JYarger\2025_04_13_CBD_Single_Xtal_n60C_150C_10Cmin_x3.tri
[Procedure]
Procedure Name,CBD_n60_150C_10Cmin_x3
Sample Name,2025_04_13_CBD_Single_Xtal_n60C_150C_10Cmin_x3
Sample Mass,5.89 mg
Reference Sample Mass,0 mg
Pan Mass,53.23 mg
Pan Number,38
Reference Pan Mass,53.32 mg
Reference Pan Number,10
Pan Type,Tzero Aluminum Hermetic
Comments,Hermetic Sealed Al DSC Consumables Pan/Lids.
Project Name,CA
Operator,Yarger
Test,Custom
Unload Max Temperature,30
Unload Min Temperature,30
Load Max Temperature,30
Load Min Temperature,30
Stop on Gas Flow Error,Yes
[Signal List]
Signal #1,Time (min)
Signal #2,Temperature (°C)
Signal #3,Heat Flow (mW)
Signal #4,Delta T (µV)
Signal #5,Delta Tzero (µV)
Signal #6,Tzero Temperature (°C)
Signal #7,Cell Purge (mL/min)
Signal #8,Heater Temp (°C)
Signal #9,Power Delivered (W)
Signal #10,Reference Junction Temperature (°C)
Signal #11,Flange Temperature (°C)
Signal #12,Heat Flow Phase (rad)
Signal #13,Total Heat Capacity (J/°C)
Signal #14,Heat Capacity (J/°C)
[Configuration]
Company Name,ASU
Instrument Name,DSC2A-00468
Instrument Type,DSC2500
Serial Number,DSC2A-00468
IP,192.168.1.100
Location of Instrument,MRRC
DisplayType,Unknown
Sample Interval ,0.1 s/pt
Selected Heat Flow,T4P
Exotherm Direction,Down
Cell Serial,DRC2-00792
Lid Type,Standard
Cooler,RCS 90
Leave Cooler on at End of Sequence,On
Gas 2,Nitrogen
Gas Selected,Channel 1
Flow Rate,50 mL/min
Secondary Purge,On
Licensed Heat Flow,Heat Flow T4P
Modulation Licensed,Yes
[Versions]
Common IDD Version,1
Cortex Version,VER 2.10.2.31
Driver,5.0.0.6
GDM Version,1.0.3.3
TouchscreenVersion,1.0.0.16145
FEP Version,1.2.1.21
FEP Bootloader,2.0.0.5
AutoSampler Version,2.1.1.26
Auto Sampler Bootloader,2.0.0.5
FCM Version,1.1.0.3
FCM Bootloader,2.0.0.5
[Experiment Logs]
Experiment Log Entry # 1,Data On set to 0
Experiment Log Entry # 3,Equilibrate Segment -60 (C) Started
Experiment Log Entry # 5,Air Cool is off.
Experiment Log Entry # 7,Data On set to 1
Experiment Log Entry # 9,Ramp Segment 10 C/min to 150 Started
Experiment Log Entry # 11,Data On set to 0
Experiment Log Entry # 13,Isothermal Segment 1 min started
Experiment Log Entry # 15,Data On set to 1
Experiment Log Entry # 17,Ramp Segment 10 C/min to -60 Started
Experiment Log Entry # 19,Data On set to 0
Experiment Log Entry # 21,Isothermal Segment 1 min started
Experiment Log Entry # 23,Data On set to 1
Experiment Log Entry # 25,Ramp Segment 10 C/min to 150 Started
Experiment Log Entry # 27,Data On set to 0
Experiment Log Entry # 29,Isothermal Segment 1 min started
Experiment Log Entry # 31,Data On set to 1
Experiment Log Entry # 33,Ramp Segment 10 C/min to -60 Started
Experiment Log Entry # 35,Data On set to 0
Experiment Log Entry # 37,Isothermal Segment 1 min started
Experiment Log Entry # 39,Data On set to 1
Experiment Log Entry # 41,Ramp Segment 10 C/min to 150 Started
[Method Log]
Method Log Entry # 1,Data Off
Method Log Entry # 2,Equilibrate -60 °C
Method Log Entry # 3,Data On
Method Log Entry # 4,(Ramp 269286) Ramp 10 °C/minute to 150 °C
Method Log Entry # 5,Data Off
Method Log Entry # 6,Isothermal 1 minutes
Method Log Entry # 7,Data On
Method Log Entry # 8,(Ramp 269290) Ramp 10 °C/minute to -60 °C
Method Log Entry # 9,Data Off
Method Log Entry # 10,Isothermal 1 minutes
Method Log Entry # 11,Data On
Method Log Entry # 12,(Ramp 269294) Ramp 10 °C/minute to 150 °C
Method Log Entry # 13,Data Off
Method Log Entry # 14,Isothermal 1 minutes
Method Log Entry # 15,Data On
Method Log Entry # 16,(Ramp 269298) Ramp 10 °C/minute to -60 °C
Method Log Entry # 17,Data Off
Method Log Entry # 18,Isothermal 1 minutes
Method Log Entry # 19,Data On
Method Log Entry # 20,(Ramp 269302) Ramp 10 °C/minute to 150 °C
Cell Serial,DRC2-00792
[T1 Calibration]
Slope,-0.008529666
Offset,9.636258
Initial Temperature,98.23
GUID,f8bfdadc-4977-4fdf-ba6d-0ba9134940c3
[TZero Calibration]
Date Applied,11/29/2022 4:06:13 PM
Description,From -89.059 °C to 396.009 °C at 20.000°C/min
Gas Type,Nitrogen
Pan Type,None
Source Files 1,C:\Users\yargerlab\Desktop\DSC Data\General\TZero_calibration_11_29_22_2nd(2).tri
Source Files 2,C:\Users\yargerlab\Desktop\DSC Data\General\TZero_calibration_11_29_22_2nd(3).tri
Delta T Offset,13.05235
Delta T Slope,-0.007271007
Delta T0 Offset,-13.69128
Delta T0 Slope,0.06063341
[Temperature Calibration]
Date Applied,11/29/2022 7:12:28 PM
Description,From 106.590 °C to 186.590 °C at 10.000°C/min
Gas Type,Nitrogen
Pan Type,Tzero Aluminum Hermetic
Source Files 1,C:\Users\yargerlab\Desktop\DSC Data\General\Indium(6).tri
Measured 1,157.391
Known 1,156.598
[Cell Constant Calibration]
Date Applied,11/29/2022 7:12:29 PM
Description,From 106.590 °C to 186.590 °C at 10.000°C/min
Gas Type,Nitrogen
Pan Type,Tzero Aluminum Hermetic
Source Files 1,C:\Users\yargerlab\Desktop\DSC Data\General\Indium(6).tri
T4P KCell,1.006051
Onset Slope,63.26126 mW/°C
[Direct Cp Calibration]
Date Applied,11/30/2022 11:04:51 AM
Description,From -79.983 °C to 298.409 °C at 10.000°C/min
Gas Type,Nitrogen
Pan Type,Tzero Aluminum Hermetic
Source Files 1,C:\Users\yargerlab\Desktop\DSC Data\General\Sapphire_Heat_Capacity_11_30_22.tri
[Rev Cp Calibration]
Date Applied,11/30/2022 1:58:51 PM
Description,From -79.996 °C to 292.812 °C at 3.000°C/min
Gas Type,Nitrogen
Pan Type,Tzero Aluminum Hermetic
Source Files 1,C:\Users\yargerlab\Desktop\DSC Data\General\Sapphire_MDSC_Calibration_11_30_22.tri
[step]
Ramp 10.00 °C/min to 150.00 °C
Time,Temperature,Heat Flow (Normalized)
min,°C,W/g
0.00,-59.69,-0.045
0.01,-59.70,-0.044
0.03,-59.71,-0.040
0.05,-59.71,-0.035
0.06,-59.71,-0.032
0.08,-59.69,-0.027
0.09,-59.67,-0.023
0.11,-59.63,-0.017
0.12,-59.57,-0.009
0.14,-59.51,0.001
0.15,-59.43,0.011
0.16,-59.34,0.024
0.18,-59.24,0.038
0.19,-59.14,0.051
0.21,-59.02,0.065
0.23,-58.91,0.078
0.24,-58.79,0.089
0.26,-58.66,0.101
0.27,-58.53,0.111
0.29,-58.40,0.121
0.30,-58.27,0.129
0.31,-58.14,0.136
0.33,-58.01,0.143
0.35,-57.87,0.149
0.36,-57.73,0.155
0.38,-57.60,0.159
0.39,-57.46,0.163
0.40,-57.32,0.166
0.42,-57.18,0.170
0.44,-57.04,0.172
0.45,-56.90,0.176
0.46,-56.75,0.177
0.48,-56.61,0.180
0.50,-56.47,0.181
0.51,-56.32,0.183
0.53,-56.18,0.184
0.54,-56.04,0.185
0.55,-55.89,0.186
0.57,-55.75,0.188
0.58,-55.60,0.188
0.60,-55.46,0.188
0.62,-55.31,0.189
0.63,-55.16,0.190
0.65,-55.02,0.190
0.66,-54.87,0.191
0.68,-54.73,0.191
0.69,-54.58,0.191
0.70,-54.43,0.191
0.72,-54.29,0.192
0.73,-54.14,0.192
0.75,-53.99,0.192
0.77,-53.85,0.192
0.78,-53.70,0.193
0.80,-53.55,0.193
0.81,-53.40,0.193
0.83,-53.26,0.193
0.84,-53.11,0.194
0.85,-52.96,0.194
0.87,-52.82,0.194
0.88,-52.67,0.194
0.90,-52.52,0.194
0.92,-52.37,0.194
0.93,-52.22,0.195
0.95,-52.08,0.195
0.96,-51.93,0.195
0.98,-51.78,0.195
0.99,-51.63,0.195
1.00,-51.48,0.196
1.02,-51.33,0.196
1.03,-51.18,0.196
1.05,-51.04,0.196
1.07,-50.89,0.196
1.08,-50.74,0.196
1.09,-50.59,0.196
1.11,-50.44,0.197
1.13,-50.29,0.197
1.14,-50.14,0.197
1.16,-49.99,0.197
1.17,-49.85,0.197
1.18,-49.70,0.197
1.20,-49.55,0.198
1.22,-49.40,0.198
1.23,-49.25,0.198
1.24,-49.10,0.198
1.26,-48.95,0.198
1.28,-48.80,0.198
1.29,-48.65,0.198
1.31,-48.50,0.198
1.32,-48.35,0.199
1.33,-48.20,0.199
1.35,-48.06,0.199
1.37,-47.90,0.199
1.38,-47.76,0.199
1.39,-47.60,0.199
1.41,-47.46,0.199
1.43,-47.31,0.199
1.44,-47.16,0.199
1.46,-47.01,0.199
1.47,-46.86,0.200
1.48,-46.71,0.200
1.50,-46.56,0.200
1.52,-46.41,0.200
1.53,-46.26,0.200
1.54,-46.11,0.200
1.56,-45.96,0.200
1.58,-45.81,0.200
1.59,-45.66,0.200
1.61,-45.51,0.200
1.62,-45.36,0.200
1.63,-45.21,0.201
1.65,-45.06,0.201
1.67,-44.91,0.201
1.68,-44.76,0.201
1.69,-44.61,0.201
1.71,-44.46,0.201
1.73,-44.31,0.201
1.74,-44.16,0.201
1.76,-44.01,0.201
1.77,-43.86,0.201
1.78,-43.71,0.201
1.80,-43.56,0.201
1.82,-43.41,0.201
1.83,-43.26,0.201
1.84,-43.11,0.202
1.86,-42.96,0.202
1.88,-42.81,0.202
1.89,-42.66,0.202
1.91,-42.51,0.202
1.92,-42.36,0.202
1.93,-42.21,0.202
1.95,-42.06,0.202
1.97,-41.91,0.202
1.98,-41.76,0.202
1.99,-41.61,0.202
2.01,-41.46,0.202
2.03,-41.31,0.202
2.04,-41.16,0.202
2.06,-41.01,0.202
2.07,-40.86,0.202
2.08,-40.71,0.202
2.10,-40.56,0.203
2.12,-40.41,0.203
2.13,-40.26,0.203
2.14,-40.11,0.203
2.16,-39.96,0.203
2.18,-39.81,0.203
2.19,-39.66,0.203
2.21,-39.51,0.203
2.22,-39.36,0.203
2.24,-39.21,0.203
2.25,-39.06,0.203
2.26,-38.91,0.203
2.28,-38.76,0.203
2.29,-38.61,0.203
2.31,-38.46,0.203
2.33,-38.31,0.204
2.34,-38.16,0.204
2.36,-38.01,0.204
2.37,-37.86,0.204
2.39,-37.71,0.204
2.40,-37.56,0.204
2.41,-37.41,0.204
2.43,-37.26,0.204
2.44,-37.11,0.204
2.46,-36.96,0.204
2.48,-36.81,0.204
2.49,-36.66,0.204
2.51,-36.51,0.204
2.52,-36.36,0.204
2.54,-36.21,0.204
2.55,-36.06,0.204
2.56,-35.91,0.205
2.58,-35.76,0.205
2.59,-35.61,0.205
2.61,-35.46,0.205
2.63,-35.31,0.205
2.64,-35.16,0.205
2.66,-35.01,0.205
2.67,-34.86,0.205
2.69,-34.71,0.205
2.70,-34.56,0.205
2.71,-34.41,0.205
2.73,-34.26,0.205
2.74,-34.11,0.205
2.76,-33.96,0.205
2.78,-33.81,0.205
2.79,-33.66,0.205
2.81,-33.50,0.205
2.82,-33.35,0.205
2.84,-33.20,0.205
2.85,-33.05,0.206
2.86,-32.90,0.206
2.88,-32.75,0.206
2.89,-32.60,0.206
2.91,-32.45,0.206
2.93,-32.30,0.206
2.94,-32.15,0.206
2.96,-32.00,0.206
2.97,-31.85,0.206
2.99,-31.70,0.206
3.00,-31.55,0.206
3.01,-31.40,0.206
3.03,-31.25,0.206
3.04,-31.10,0.206
3.06,-30.95,0.206
3.08,-30.80,0.206
3.09,-30.65,0.206
3.11,-30.50,0.206
3.12,-30.35,0.207
3.14,-30.20,0.207
3.15,-30.05,0.207
3.16,-29.90,0.207
3.18,-29.75,0.207
3.19,-29.60,0.207
3.21,-29.45,0.207
3.23,-29.30,0.207
3.24,-29.15,0.207
3.26,-29.00,0.207
3.27,-28.85,0.207
3.29,-28.70,0.207
3.30,-28.55,0.207
3.31,-28.40,0.207
3.33,-28.25,0.208
3.34,-28.10,0.208
3.36,-27.95,0.208
3.38,-27.80,0.208
3.39,-27.65,0.208
3.41,-27.50,0.208
3.42,-27.35,0.208
3.44,-27.20,0.208
3.45,-27.05,0.208
3.46,-26.90,0.208
3.48,-26.75,0.208
3.49,-26.60,0.208
3.51,-26.45,0.208
3.53,-26.29,0.208
3.54,-26.14,0.208
3.56,-26.00,0.208
3.57,-25.84,0.208
3.59,-25.70,0.208
3.60,-25.54,0.208
3.61,-25.39,0.209
3.63,-25.24,0.209
3.64,-25.09,0.209
3.66,-24.94,0.209
3.68,-24.79,0.209
3.69,-24.64,0.209
3.71,-24.49,0.209
3.72,-24.34,0.209
3.74,-24.19,0.209
3.75,-24.04,0.209
3.76,-23.89,0.209
3.78,-23.74,0.209
3.79,-23.59,0.209
3.81,-23.44,0.209
3.83,-23.29,0.209
3.84,-23.14,0.209
3.86,-22.99,0.209
3.87,-22.84,0.210
3.89,-22.69,0.210
3.90,-22.54,0.210
3.91,-22.39,0.210
3.93,-22.24,0.210
3.94,-22.09,0.210
3.96,-21.94,0.210
3.98,-21.79,0.210
3.99,-21.64,0.210
4.01,-21.49,0.210
4.02,-21.34,0.210
4.04,-21.19,0.210
4.05,-21.04,0.210
4.06,-20.89,0.210
4.08,-20.74,0.210
4.09,-20.59,0.210
4.11,-20.44,0.210
4.13,-20.29,0.210
4.14,-20.14,0.211
4.16,-19.99,0.211
4.17,-19.84,0.211
4.19,-19.69,0.211
4.20,-19.54,0.211
4.21,-19.39,0.211
4.23,-19.24,0.211
4.24,-19.09,0.211
4.26,-18.94,0.211
4.28,-18.79,0.211
4.29,-18.64,0.211
4.30,-18.49,0.211
4.32,-18.34,0.211
4.34,-18.19,0.211
4.35,-18.04,0.211
4.36,-17.88,0.211
4.38,-17.74,0.211
4.40,-17.59,0.212
4.41,-17.44,0.212
4.43,-17.28,0.212
4.44,-17.14,0.212
4.45,-16.98,0.212
4.47,-16.83,0.212
4.49,-16.68,0.212
4.50,-16.53,0.212
4.51,-16.38,0.212
4.53,-16.23,0.212
4.55,-16.08,0.212
4.56,-15.93,0.212
4.58,-15.78,0.214
4.59,-15.63,0.215
4.60,-15.48,0.215
4.62,-15.33,0.215
4.64,-15.18,0.215
4.65,-15.03,0.215
4.66,-14.88,0.215
4.68,-14.73,0.215
4.70,-14.58,0.215
4.71,-14.43,0.215
4.73,-14.28,0.214
4.74,-14.13,0.215
4.75,-13.98,0.214
4.77,-13.83,0.214
4.79,-13.68,0.214
4.80,-13.53,0.214
4.81,-13.38,0.214
4.83,-13.23,0.214
4.85,-13.08,0.214
4.86,-12.93,0.214
4.88,-12.78,0.214
4.89,-12.63,0.214
4.90,-12.48,0.214
4.92,-12.33,0.214
4.94,-12.18,0.214
4.95,-12.03,0.214
4.96,-11.88,0.214
4.98,-11.73,0.215
5.00,-11.58,0.214
5.01,-11.43,0.215
5.03,-11.28,0.215
5.04,-11.13,0.215
5.05,-10.98,0.215
5.07,-10.83,0.215
5.09,-10.68,0.215
5.10,-10.53,0.215
5.11,-10.38,0.215
5.13,-10.23,0.215
5.15,-10.08,0.215
5.16,-9.93,0.215
5.18,-9.78,0.215
5.19,-9.63,0.215
5.20,-9.48,0.215
5.22,-9.33,0.215
5.24,-9.18,0.215
5.25,-9.03,0.215
5.26,-8.88,0.215
5.28,-8.73,0.215
5.30,-8.58,0.215
5.31,-8.43,0.215
5.33,-8.27,0.215
5.34,-8.13,0.216
5.35,-7.97,0.216
5.37,-7.82,0.216
5.39,-7.67,0.216
5.40,-7.52,0.216
5.41,-7.37,0.216
5.43,-7.22,0.216
5.45,-7.07,0.216
5.46,-6.92,0.216
5.48,-6.77,0.216
5.49,-6.62,0.216
5.50,-6.47,0.216
5.52,-6.32,0.216
5.54,-6.17,0.217
5.55,-6.02,0.217
5.56,-5.87,0.217
5.58,-5.72,0.217
5.60,-5.57,0.217
5.61,-5.42,0.217
5.63,-5.27,0.217
5.64,-5.12,0.217
5.65,-4.97,0.217
5.67,-4.82,0.217
5.69,-4.67,0.217
5.70,-4.52,0.217
5.71,-4.37,0.217
5.73,-4.22,0.218
5.75,-4.07,0.218
5.76,-3.92,0.218
5.78,-3.77,0.218
5.79,-3.62,0.218
5.80,-3.47,0.218
5.82,-3.32,0.218
5.84,-3.17,0.218
5.85,-3.02,0.218
5.86,-2.87,0.218
5.88,-2.72,0.218
5.90,-2.57,0.218
5.91,-2.42,0.218
5.93,-2.27,0.219
5.94,-2.12,0.219
5.95,-1.97,0.219
5.97,-1.81,0.219
5.99,-1.67,0.219
6.00,-1.52,0.219
6.01,-1.37,0.219
6.03,-1.22,0.219
6.05,-1.07,0.219
6.06,-0.91,0.219
6.08,-0.77,0.219
6.09,-0.61,0.219
6.10,-0.46,0.219
6.12,-0.31,0.220
6.14,-0.16,0.220
6.15,-0.01,0.220
6.16,0.14,0.220
6.18,0.29,0.220
6.20,0.44,0.220
6.21,0.59,0.220
6.23,0.74,0.220
6.24,0.89,0.220
6.25,1.04,0.220
6.27,1.19,0.220
6.29,1.34,0.220
6.30,1.49,0.220
6.31,1.64,0.221
6.33,1.79,0.221
6.35,1.94,0.221
6.36,2.09,0.221
6.38,2.24,0.221
6.39,2.39,0.221
6.40,2.54,0.221
6.42,2.69,0.221
6.44,2.84,0.221
6.45,2.99,0.221
6.46,3.14,0.221
6.48,3.29,0.221
6.50,3.44,0.222
6.51,3.59,0.222
6.53,3.74,0.222
6.54,3.89,0.222
6.55,4.04,0.222
6.57,4.19,0.222
6.59,4.34,0.222
6.60,4.49,0.222
6.61,4.64,0.222
6.63,4.79,0.222
6.65,4.94,0.222
6.66,5.09,0.223
6.68,5.24,0.223
6.69,5.39,0.223
6.70,5.54,0.223
6.72,5.69,0.223
6.74,5.84,0.223
6.75,5.99,0.223
6.76,6.14,0.223
6.78,6.29,0.223
6.80,6.44,0.223
6.81,6.59,0.224
6.83,6.74,0.224
6.84,6.89,0.224
6.85,7.04,0.224
6.87,7.19,0.224
6.89,7.34,0.224
6.90,7.49,0.224
6.91,7.64,0.224
6.93,7.79,0.224
6.95,7.94,0.224
6.96,8.10,0.224
6.98,8.24,0.225
6.99,8.39,0.225
7.00,8.55,0.225
7.02,8.70,0.225
7.04,8.85,0.225
7.05,9.00,0.225
7.06,9.15,0.225
7.08,9.30,0.225
7.10,9.45,0.225
7.11,9.60,0.226
7.13,9.75,0.226
7.14,9.90,0.226
7.15,10.05,0.226
7.17,10.20,0.226
7.19,10.35,0.226
7.20,10.50,0.226
7.21,10.65,0.226
7.23,10.80,0.226
7.25,10.95,0.227
7.26,11.10,0.227
7.28,11.25,0.227
7.29,11.40,0.227
7.30,11.55,0.227
7.32,11.70,0.227
7.34,11.85,0.227
7.35,12.00,0.227
7.36,12.15,0.227
7.38,12.30,0.227
7.40,12.45,0.227
7.41,12.60,0.228
7.43,12.75,0.228
7.44,12.90,0.228
7.45,13.05,0.228
7.47,13.20,0.228
7.49,13.35,0.221
7.50,13.50,0.200
7.51,13.66,0.203
7.53,13.81,0.205
7.55,13.96,0.207
7.56,14.11,0.208
7.58,14.26,0.210
7.59,14.41,0.213
7.60,14.56,0.214
7.62,14.71,0.217
7.64,14.86,0.218
7.65,15.01,0.220
7.66,15.16,0.221
7.68,15.31,0.221
7.70,15.46,0.223
7.71,15.61,0.223
7.73,15.76,0.224
7.74,15.91,0.225
7.75,16.06,0.225
7.77,16.21,0.225
7.79,16.36,0.226
7.80,16.51,0.226
7.81,16.66,0.226
7.83,16.81,0.227
7.85,16.96,0.227
7.86,17.11,0.227
7.88,17.26,0.227
7.89,17.41,0.228
7.90,17.56,0.228
7.92,17.71,0.228
7.94,17.86,0.228
7.95,18.01,0.229
7.96,18.16,0.229
7.98,18.31,0.229
8.00,18.46,0.229
8.01,18.61,0.229
8.03,18.76,0.230
8.04,18.91,0.230
8.05,19.06,0.230
8.07,19.21,0.230
8.09,19.36,0.230
8.10,19.51,0.231
8.11,19.66,0.231
8.13,19.81,0.231
8.15,19.96,0.231
8.16,20.11,0.231
8.18,20.26,0.232
8.19,20.41,0.232
8.20,20.56,0.232
8.22,20.71,0.232
8.24,20.86,0.232
8.25,21.01,0.232
8.26,21.16,0.233
8.28,21.31,0.233
8.30,21.46,0.233
8.31,21.61,0.233
8.33,21.76,0.233
8.34,21.91,0.233
8.35,22.06,0.234
8.37,22.21,0.234
8.39,22.36,0.234
8.40,22.51,0.234
8.41,22.66,0.234
8.43,22.81,0.234
8.45,22.96,0.234
8.46,23.11,0.235
8.48,23.26,0.235
8.49,23.41,0.235
8.50,23.56,0.235
8.52,23.71,0.235
8.53,23.86,0.235
8.55,24.01,0.235
8.57,24.16,0.235
8.58,24.31,0.235
8.60,24.46,0.236
8.61,24.61,0.236
8.63,24.76,0.236
8.64,24.91,0.236
8.65,25.06,0.236
8.67,25.21,0.236
8.68,25.36,0.236
8.70,25.51,0.236
8.72,25.66,0.237
8.73,25.81,0.237
8.75,25.96,0.237
8.76,26.11,0.237
8.78,26.26,0.237
8.79,26.41,0.237
8.80,26.56,0.237
8.82,26.72,0.237
8.83,26.86,0.238
8.85,27.01,0.238
8.87,27.17,0.238
8.88,27.31,0.238
8.90,27.47,0.238
8.91,27.61,0.238
8.93,27.76,0.238
8.94,27.92,0.238
8.95,28.07,0.239
8.97,28.21,0.239
8.98,28.37,0.239
9.00,28.52,0.239
9.02,28.67,0.239
9.03,28.82,0.239
9.05,28.97,0.239
9.06,29.12,0.239
9.08,29.27,0.240
9.09,29.42,0.240
9.10,29.57,0.240
9.12,29.72,0.240
9.13,29.87,0.240
9.15,30.02,0.240
9.17,30.17,0.241
9.18,30.32,0.241
9.20,30.47,0.241
9.21,30.62,0.241
9.23,30.77,0.241
9.24,30.92,0.241
9.25,31.07,0.241
9.27,31.22,0.241
9.28,31.37,0.242
9.30,31.52,0.242
9.32,31.67,0.242
9.33,31.82,0.242
9.35,31.97,0.242
9.36,32.12,0.242
9.38,32.27,0.242
9.39,32.42,0.266
9.40,32.57,0.260
9.42,32.72,0.259
9.43,32.87,0.258
9.45,33.02,0.256
9.47,33.17,0.254
9.48,33.32,0.253
9.50,33.47,0.252
9.51,33.62,0.252
9.53,33.77,0.251
9.54,33.92,0.251
9.55,34.07,0.251
9.57,34.22,0.250
9.58,34.37,0.250
9.60,34.52,0.250
9.62,34.67,0.250
9.63,34.82,0.250
9.65,34.97,0.249
9.66,35.12,0.249
9.68,35.27,0.249
9.69,35.42,0.249
9.70,35.57,0.249
9.72,35.72,0.249
9.73,35.87,0.248
9.75,36.02,0.248
9.77,36.17,0.248
9.78,36.32,0.248
9.80,36.47,0.248
9.81,36.62,0.248
9.83,36.77,0.248
9.84,36.92,0.248
9.85,37.07,0.248
9.87,37.22,0.248
9.88,37.37,0.248
9.90,37.53,0.248
9.92,37.68,0.248
9.93,37.83,0.248
9.95,37.98,0.248
9.96,38.13,0.248
9.98,38.28,0.248
9.99,38.42,0.248
10.00,38.58,0.248
10.02,38.73,0.248
10.03,38.88,0.248
10.05,39.03,0.249
10.07,39.18,0.249
10.08,39.33,0.249
10.10,39.48,0.249
10.11,39.63,0.249
10.13,39.78,0.249
10.14,39.93,0.249
10.15,40.08,0.249
10.17,40.23,0.249
10.18,40.38,0.249
10.20,40.53,0.249
10.22,40.68,0.249
10.23,40.83,0.250
10.25,40.98,0.250
10.26,41.13,0.250
10.28,41.28,0.250
10.29,41.43,0.250
10.30,41.58,0.250
10.32,41.73,0.250
10.33,41.88,0.250
10.35,42.03,0.250
10.37,42.18,0.251
10.38,42.33,0.251
10.40,42.48,0.251
10.41,42.63,0.251
10.43,42.78,0.251
10.44,42.93,0.251
10.45,43.08,0.251
10.47,43.23,0.251
10.48,43.38,0.251
10.50,43.53,0.252
10.52,43.68,0.252
10.53,43.83,0.252
10.55,43.98,0.252
10.56,44.13,0.252
10.58,44.28,0.252
10.59,44.43,0.252
10.60,44.58,0.253
10.62,44.73,0.253
10.63,44.88,0.253
10.65,45.03,0.253
10.67,45.18,0.253
10.68,45.33,0.253
10.70,45.48,0.253
10.71,45.63,0.253
10.73,45.78,0.254
10.74,45.93,0.254
10.75,46.08,0.254
10.77,46.23,0.254
10.78,46.38,0.254
10.80,46.53,0.254
10.82,46.68,0.254
10.83,46.83,0.255
10.85,46.98,0.255
10.86,47.13,0.255
10.88,47.28,0.255
10.89,47.43,0.255
10.90,47.58,0.255
10.92,47.73,0.255
10.93,47.89,0.256
10.95,48.03,0.256
10.97,48.18,0.256
10.98,48.33,0.256
11.00,48.48,0.256
11.01,48.63,0.256
11.03,48.78,0.257
11.04,48.93,0.257
11.05,49.08,0.257
11.07,49.24,0.257
11.08,49.39,0.257
11.10,49.54,0.258
11.12,49.69,0.258
11.13,49.84,0.258
11.15,49.99,0.258
11.16,50.14,0.258
11.18,50.29,0.274
11.19,50.43,0.281
11.20,50.58,0.278
11.22,50.73,0.276
11.23,50.88,0.276
11.25,51.03,0.275
11.27,51.18,0.274
11.28,51.33,0.272
11.30,51.48,0.272
11.31,51.63,0.271
11.33,51.78,0.271
11.34,51.93,0.271
11.35,52.08,0.270
11.37,52.23,0.270
11.38,52.38,0.270
11.40,52.54,0.270
11.42,52.69,0.269
11.43,52.84,0.269
11.45,52.99,0.269
11.46,53.14,0.269
11.48,53.29,0.268
11.49,53.44,0.268
11.50,53.59,0.268
11.52,53.74,0.268
11.53,53.89,0.268
11.55,54.04,0.268
11.57,54.19,0.268
11.58,54.34,0.267
11.60,54.49,0.267
11.61,54.64,0.267
11.63,54.79,0.267
11.64,54.94,0.267
11.65,55.09,0.267
11.67,55.24,0.267
11.68,55.39,0.267
11.70,55.54,0.267
11.72,55.69,0.267
11.73,55.84,0.267
11.75,55.99,0.268
11.76,56.14,0.268
11.78,56.29,0.268
11.79,56.44,0.268
11.80,56.59,0.268
11.82,56.74,0.268
11.83,56.89,0.268
11.85,57.04,0.268
11.87,57.19,0.269
11.88,57.34,0.269
11.90,57.49,0.269
11.91,57.64,0.269
11.93,57.79,0.270
11.94,57.94,0.270
11.95,58.09,0.270
11.97,58.24,0.270
11.98,58.39,0.271
12.00,58.54,0.271
12.02,58.69,0.271
12.03,58.84,0.272
12.05,58.99,0.272
12.06,59.14,0.272
12.08,59.29,0.273
12.09,59.44,0.273
12.10,59.59,0.274
12.12,59.74,0.274
12.13,59.89,0.275
12.15,60.04,0.275
12.17,60.19,0.276
12.18,60.34,0.277
12.20,60.49,0.278
12.21,60.64,0.280
12.23,60.79,0.280
12.24,60.94,0.281
12.25,61.09,0.282
12.27,61.24,0.283
12.28,61.39,0.284
12.30,61.54,0.286
12.32,61.69,0.288
12.33,61.84,0.290
12.35,61.99,0.293
12.36,62.14,0.296
12.38,62.29,0.299
12.39,62.44,0.300
12.40,62.59,0.303
12.42,62.74,0.306
12.43,62.89,0.308
12.45,63.03,0.311
12.47,63.18,0.315
12.48,63.33,0.317
12.50,63.48,0.321
12.51,63.63,0.326
12.53,63.78,0.329
12.54,63.93,0.334
12.55,64.08,0.339
12.57,64.22,0.345
12.58,64.37,0.351
12.60,64.52,0.356
12.62,64.67,0.365
12.63,64.82,0.372
12.65,64.96,0.380
12.66,65.11,0.391
12.68,65.26,0.402
12.69,65.40,0.412
12.70,65.55,0.426
12.72,65.70,0.443
12.73,65.84,0.465
12.75,65.99,0.481
12.77,66.13,0.497
12.78,66.28,0.515
12.80,66.42,0.534
12.81,66.56,0.567
12.83,66.70,0.590
12.84,66.84,0.615
12.85,66.99,0.641
12.87,67.13,0.673
12.88,67.27,0.703
12.90,67.40,0.737
12.92,67.54,0.772
12.93,67.68,0.812
12.95,67.82,0.853
12.96,67.95,0.901
12.98,68.09,0.953
12.99,68.22,1.012
13.00,68.35,1.073
13.02,68.48,1.131
13.03,68.61,1.186
13.05,68.74,1.245
13.07,68.87,1.303
13.08,69.00,1.346
13.10,69.12,1.398
13.11,69.25,1.447
13.13,69.38,1.489
13.14,69.51,1.525
13.15,69.65,1.558
13.17,69.78,1.590
13.18,69.91,1.615
13.20,70.05,1.646
13.22,70.19,1.681
13.23,70.32,1.700
13.25,70.46,1.804
13.26,70.58,1.904
13.28,70.71,1.924
13.29,70.84,1.964
13.30,70.97,2.041
13.32,71.10,2.176
13.33,71.22,2.176
13.35,71.35,2.202
13.37,71.48,2.215
13.38,71.62,2.262
13.40,71.75,2.295
13.41,71.89,2.284
13.43,72.03,2.273
13.44,72.17,2.249
13.45,72.32,2.249
13.47,72.47,2.240
13.48,72.62,2.217
13.50,72.77,2.171
13.52,72.93,2.121
13.53,73.09,2.058
13.55,73.26,1.974
13.56,73.43,1.869
13.58,73.61,1.751
13.59,73.79,1.623
13.60,73.98,1.491
13.62,74.17,1.360
13.63,74.36,1.231
13.65,74.56,1.102
13.67,74.76,0.975
13.68,74.95,0.857
13.70,75.15,0.763
13.71,75.34,0.675
13.73,75.53,0.623
13.74,75.72,0.571
13.75,75.90,0.539
13.77,76.08,0.510
13.78,76.25,0.487
13.80,76.42,0.466
13.82,76.58,0.448
13.83,76.75,0.433
13.85,76.91,0.420
13.86,77.07,0.411
13.88,77.23,0.400
13.89,77.39,0.392
13.90,77.55,0.386
13.92,77.70,0.381
13.93,77.86,0.376
13.95,78.01,0.370
13.97,78.17,0.368
13.98,78.32,0.363
14.00,78.47,0.361
14.01,78.62,0.359
14.03,78.77,0.357
14.04,78.93,0.356
14.05,79.08,0.355
14.07,79.23,0.354
14.08,79.38,0.353
14.10,79.53,0.352
14.12,79.68,0.352
14.13,79.83,0.351
14.15,79.98,0.351
14.16,80.14,0.351
14.18,80.29,0.350
14.19,80.44,0.350
14.20,80.59,0.350
14.22,80.74,0.349
14.23,80.89,0.349
14.25,81.04,0.349
14.27,81.19,0.349
14.28,81.34,0.349
14.30,81.49,0.349
14.31,81.64,0.349
14.33,81.79,0.348
14.34,81.94,0.348
14.35,82.09,0.348
14.37,82.24,0.348
14.38,82.39,0.348
14.40,82.54,0.348
14.42,82.69,0.348
14.43,82.84,0.348
14.45,82.99,0.348
14.46,83.14,0.347
14.48,83.29,0.347
14.49,83.44,0.347
14.50,83.59,0.347
14.52,83.74,0.347
14.53,83.89,0.347
14.55,84.04,0.347
14.57,84.19,0.347
14.58,84.34,0.347
14.60,84.49,0.347
14.61,84.64,0.347
14.63,84.79,0.347
14.64,84.94,0.347
14.65,85.09,0.347
14.67,85.24,0.347
14.68,85.39,0.347
14.70,85.54,0.347
14.72,85.69,0.347
14.73,85.84,0.347
14.75,85.99,0.347
14.76,86.14,0.347
14.78,86.29,0.347
14.79,86.44,0.347
14.80,86.59,0.347
14.82,86.74,0.347
14.83,86.89,0.347
14.85,87.04,0.347
14.87,87.20,0.347
14.88,87.34,0.347
14.90,87.49,0.347
14.91,87.64,0.347
14.93,87.80,0.347
14.94,87.95,0.348
14.95,88.09,0.348
14.97,88.24,0.348
14.98,88.40,0.348
15.00,88.55,0.348
15.02,88.70,0.348
15.03,88.85,0.348
15.05,89.00,0.348
15.06,89.15,0.348
15.08,89.30,0.348
15.09,89.45,0.348
15.10,89.60,0.348
15.12,89.75,0.348
15.13,89.90,0.348
15.15,90.05,0.348
15.17,90.20,0.348
15.18,90.35,0.349
15.20,90.50,0.349
15.21,90.65,0.349
15.23,90.80,0.349
15.24,90.95,0.349
15.25,91.10,0.349
15.27,91.25,0.349
15.28,91.40,0.349
15.30,91.55,0.349
15.32,91.70,0.349
15.33,91.85,0.349
15.35,92.00,0.349
15.36,92.15,0.350
15.38,92.30,0.350
15.39,92.45,0.350
15.40,92.60,0.350
15.42,92.75,0.350
15.43,92.90,0.350
15.45,93.05,0.350
15.47,93.20,0.350
15.48,93.35,0.350
15.50,93.50,0.350
15.51,93.65,0.350
15.53,93.80,0.350
15.54,93.95,0.350
15.55,94.10,0.351
15.57,94.25,0.351
15.58,94.40,0.351
15.60,94.55,0.351
15.62,94.70,0.351
15.63,94.85,0.351
15.65,95.00,0.351
15.66,95.15,0.351
15.68,95.30,0.351
15.69,95.45,0.351
15.70,95.60,0.351
15.72,95.75,0.351
15.73,95.90,0.352
15.75,96.05,0.352
15.77,96.20,0.352
15.78,96.35,0.352
15.80,96.50,0.352
15.81,96.65,0.352
15.83,96.80,0.352
15.84,96.95,0.352
15.85,97.10,0.352
15.87,97.25,0.352
15.88,97.40,0.352
15.90,97.55,0.352
15.92,97.70,0.353
15.93,97.85,0.353
15.95,98.00,0.353
15.96,98.15,0.353
15.98,98.30,0.353
15.99,98.45,0.353
16.00,98.60,0.353
16.02,98.76,0.353
16.03,98.90,0.353
16.05,99.05,0.353
16.07,99.21,0.353
16.08,99.36,0.353
16.10,99.51,0.354
16.11,99.66,0.354
16.13,99.81,0.354
16.14,99.96,0.354
16.15,100.11,0.354
16.17,100.26,0.354
16.18,100.41,0.354
16.20,100.56,0.354
16.22,100.71,0.354
16.23,100.86,0.354
16.25,101.01,0.354
16.26,101.16,0.354
16.28,101.31,0.354
16.29,101.46,0.354
16.30,101.61,0.354
16.32,101.76,0.355
16.33,101.91,0.355
16.35,102.06,0.355
16.37,102.21,0.355
16.38,102.36,0.355
16.40,102.51,0.355
16.41,102.66,0.355
16.43,102.81,0.355
16.44,102.96,0.355
16.45,103.11,0.355
16.47,103.26,0.355
16.48,103.41,0.355
16.50,103.56,0.355
16.52,103.71,0.355
16.53,103.86,0.356
16.55,104.01,0.356
16.56,104.16,0.356
16.58,104.31,0.356
16.59,104.46,0.356
16.60,104.61,0.356
16.62,104.76,0.356
16.63,104.91,0.356
16.65,105.06,0.356
16.67,105.21,0.356
16.68,105.36,0.356
16.70,105.51,0.356
16.71,105.66,0.357
16.73,105.81,0.357
16.74,105.96,0.357
16.75,106.11,0.357
16.77,106.26,0.357
16.78,106.41,0.357
16.80,106.56,0.357
16.82,106.71,0.357
16.83,106.86,0.357
16.85,107.01,0.357
16.86,107.16,0.357
16.88,107.31,0.357
16.89,107.46,0.357
16.90,107.61,0.357
16.92,107.76,0.357
16.93,107.91,0.357
16.95,108.06,0.358
16.97,108.21,0.358
16.98,108.36,0.358
17.00,108.51,0.358
17.01,108.66,0.358
17.03,108.81,0.358
17.04,108.96,0.358
17.05,109.11,0.358
17.07,109.26,0.358
17.08,109.42,0.358
17.10,109.57,0.358
17.12,109.71,0.358
17.13,109.87,0.358
17.14,110.02,0.358
17.16,110.17,0.359
17.18,110.32,0.359
17.19,110.47,0.359
17.21,110.62,0.359
17.22,110.77,0.359
17.23,110.91,0.359
17.25,111.07,0.359
17.27,111.22,0.359
17.28,111.37,0.359
17.29,111.52,0.359
17.31,111.67,0.359
17.33,111.82,0.359
17.34,111.97,0.359
17.36,112.12,0.359
17.37,112.27,0.359
17.38,112.42,0.359
17.40,112.57,0.359
17.42,112.72,0.359
17.43,112.87,0.360
17.44,113.02,0.360
17.46,113.17,0.360
17.48,113.32,0.360
17.49,113.47,0.360
17.51,113.62,0.360
17.52,113.77,0.360
17.53,113.92,0.360
17.55,114.07,0.360
17.57,114.22,0.360
17.58,114.37,0.360
17.59,114.52,0.360
17.61,114.67,0.360
17.63,114.82,0.360
17.64,114.97,0.360
17.66,115.12,0.361
17.67,115.27,0.361
17.68,115.42,0.361
17.70,115.57,0.361
17.72,115.72,0.361
17.73,115.87,0.361
17.74,116.02,0.361
17.76,116.17,0.361
17.78,116.32,0.361
17.79,116.47,0.361
17.81,116.62,0.361
17.82,116.77,0.361
17.83,116.92,0.361
17.85,117.07,0.361
17.87,117.22,0.361
17.88,117.37,0.362
17.89,117.52,0.362
17.91,117.67,0.362
17.93,117.82,0.362
17.94,117.97,0.362
17.96,118.12,0.362
17.97,118.27,0.362
17.98,118.42,0.362
18.00,118.57,0.362
18.02,118.72,0.362
18.03,118.87,0.362
18.04,119.02,0.362
18.06,119.17,0.362
18.08,119.32,0.362
18.09,119.47,0.363
18.11,119.62,0.363
18.12,119.77,0.363
18.13,119.92,0.363
18.15,120.07,0.363
18.17,120.22,0.363
18.18,120.37,0.363
18.19,120.52,0.363
18.21,120.67,0.363
18.23,120.82,0.363
18.24,120.97,0.363
18.26,121.12,0.363
18.27,121.27,0.363
18.28,121.42,0.363
18.30,121.57,0.363
18.32,121.72,0.363
18.33,121.88,0.363
18.34,122.03,0.364
18.36,122.18,0.364
18.38,122.32,0.364
18.39,122.48,0.364
18.41,122.63,0.364
18.42,122.78,0.364
18.43,122.92,0.364
18.45,123.08,0.364
18.47,123.23,0.364
18.48,123.38,0.364
18.49,123.53,0.364
18.51,123.68,0.364
18.53,123.83,0.364
18.54,123.98,0.364
18.56,124.13,0.364
18.57,124.28,0.364
18.58,124.43,0.364
18.60,124.58,0.364
18.62,124.73,0.364
18.63,124.88,0.365
18.64,125.03,0.365
18.66,125.18,0.365
18.68,125.33,0.365
18.69,125.48,0.365
18.71,125.63,0.365
18.72,125.78,0.365
18.73,125.93,0.365
18.75,126.08,0.365
18.77,126.23,0.365
18.78,126.38,0.365
18.79,126.53,0.365
18.81,126.68,0.365
18.83,126.83,0.365
18.84,126.98,0.366
18.86,127.13,0.366
18.87,127.28,0.366
18.88,127.43,0.366
18.90,127.58,0.366
18.92,127.73,0.366
18.93,127.88,0.366
18.94,128.03,0.366
18.96,128.18,0.366
18.98,128.33,0.366
18.99,128.48,0.366
19.01,128.63,0.366
19.02,128.78,0.366
19.03,128.93,0.366
19.05,129.08,0.366
19.07,129.23,0.366
19.08,129.38,0.366
19.09,129.53,0.366
19.11,129.68,0.366
19.13,129.83,0.367
19.14,129.98,0.367
19.16,130.13,0.367
19.17,130.28,0.367
19.18,130.43,0.367
19.20,130.58,0.367
19.22,130.73,0.367
19.23,130.88,0.367
19.24,131.03,0.367
19.26,131.18,0.367
19.28,131.33,0.367
19.29,131.48,0.367
19.31,131.63,0.367
19.32,131.78,0.367
19.33,131.93,0.367
19.35,132.08,0.367
19.37,132.23,0.367
19.38,132.38,0.368
19.39,132.53,0.368
19.41,132.68,0.368
19.43,132.83,0.368
19.44,132.98,0.368
19.46,133.13,0.368
19.47,133.28,0.368
19.48,133.43,0.368
19.50,133.58,0.368
19.52,133.73,0.368
19.53,133.88,0.368
19.54,134.04,0.368
19.56,134.18,0.368
19.58,134.33,0.368
19.59,134.49,0.368
19.61,134.64,0.368
19.62,134.79,0.368
19.63,134.94,0.368
19.65,135.09,0.368
19.67,135.24,0.368
19.68,135.38,0.368
19.69,135.54,0.368
19.71,135.69,0.368
19.73,135.84,0.369
19.74,135.99,0.369
19.76,136.14,0.369
19.77,136.29,0.369
19.78,136.44,0.369
19.80,136.59,0.369
19.82,136.74,0.369
19.83,136.89,0.369
19.84,137.04,0.369
19.86,137.19,0.369
19.88,137.34,0.369
19.89,137.49,0.369
19.91,137.64,0.369
19.92,137.79,0.369
19.93,137.94,0.369
19.95,138.09,0.369
19.97,138.24,0.369
19.98,138.39,0.369
19.99,138.54,0.369
20.01,138.69,0.369
20.03,138.84,0.369
20.04,138.99,0.369
20.06,139.14,0.369
20.07,139.29,0.369
20.08,139.44,0.369
20.10,139.59,0.370
20.12,139.74,0.370
20.13,139.89,0.370
20.14,140.04,0.370
20.16,140.19,0.370
20.18,140.34,0.370
20.19,140.49,0.370
20.21,140.64,0.370
20.22,140.79,0.370
20.23,140.94,0.370
20.25,141.09,0.370
20.27,141.24,0.370
20.28,141.39,0.370
20.29,141.54,0.370
20.31,141.69,0.370
20.33,141.84,0.370
20.34,141.99,0.370
20.36,142.14,0.370
20.37,142.29,0.370
20.38,142.44,0.370
20.40,142.59,0.370
20.42,142.74,0.370
20.43,142.89,0.370
20.44,143.04,0.370
20.46,143.19,0.370
20.48,143.34,0.370
20.49,143.49,0.370
20.51,143.64,0.370
20.52,143.79,0.370
20.53,143.94,0.370
20.55,144.09,0.370
20.57,144.24,0.370
20.58,144.39,0.371
20.59,144.54,0.371
20.61,144.69,0.371
20.63,144.84,0.371
20.64,144.99,0.371
20.66,145.14,0.371
20.67,145.29,0.371
20.68,145.44,0.371
20.70,145.59,0.371
20.72,145.74,0.371
20.73,145.89,0.371
20.74,146.04,0.371
20.76,146.19,0.371
20.78,146.34,0.371
20.79,146.49,0.371
20.81,146.64,0.371
20.82,146.79,0.371
20.83,146.94,0.371
20.85,147.09,0.371
20.87,147.24,0.371
20.88,147.39,0.371
20.89,147.54,0.371
20.91,147.69,0.371
20.93,147.85,0.371
20.94,148.00,
20.96,148.15,
20.97,148.29,
20.98,,
20.99,,

[step]
Ramp 10.00 °C/min to -60.00 °C
Time,Temperature,Heat Flow (Normalized)
min,°C,W/g
21.99,150.09,-0.040
22.01,150.09,-0.040
22.02,150.09,-0.040
22.04,150.08,-0.040
22.05,150.07,-0.043
22.07,150.05,-0.056
22.08,150.02,-0.075
22.10,149.97,-0.100
22.11,149.90,-0.131
22.13,149.83,-0.168
22.14,149.74,-0.205
22.16,149.64,-0.240
22.17,149.53,-0.270
22.19,149.42,-0.298
22.20,149.30,-0.319
22.22,149.18,-0.338
22.23,149.06,-0.353
22.25,148.93,-0.367
22.26,148.80,-0.378
22.28,148.66,-0.388
22.29,148.53,-0.396
22.31,148.39,-0.404
22.32,148.25,-0.411
22.34,148.11,-0.416
22.35,147.97,-0.421
22.37,147.83,-0.424
22.38,147.68,-0.428
22.40,147.54,-0.430
22.41,147.40,-0.432
22.43,147.25,-0.434
22.44,147.11,-0.436
22.46,146.96,-0.438
22.47,146.82,-0.439
22.49,146.67,-0.440
22.50,146.52,-0.440
22.52,146.38,-0.442
22.53,146.23,-0.442
22.55,146.08,-0.443
22.56,145.93,-0.443
22.58,145.79,-0.443
22.59,145.64,-0.444
22.61,145.49,-0.444
22.62,145.34,-0.444
22.64,145.20,-0.445
22.65,145.05,-0.445
22.67,144.90,-0.445
22.68,144.75,-0.446
22.70,144.60,-0.446
22.71,144.46,-0.446
22.73,144.31,-0.446
22.74,144.16,-0.446
22.76,144.01,-0.446
22.77,143.86,-0.446
22.79,143.71,-0.446
22.80,143.56,-0.447
22.82,143.42,-0.447
22.83,143.27,-0.447
22.85,143.12,-0.447
22.86,142.97,-0.447
22.88,142.82,-0.447
22.89,142.67,-0.447
22.91,142.52,-0.447
22.92,142.37,-0.447
22.94,142.22,-0.447
22.95,142.08,-0.447
22.97,141.93,-0.447
22.98,141.78,-0.447
23.00,141.63,-0.447
23.01,141.48,-0.447
23.03,141.33,-0.447
23.04,141.18,-0.447
23.06,141.03,-0.447
23.07,140.88,-0.447
23.09,140.73,-0.447
23.10,140.58,-0.447
23.12,140.43,-0.447
23.13,140.28,-0.447
23.15,140.14,-0.447
23.16,139.99,-0.447
23.18,139.84,-0.447
23.19,139.69,-0.447
23.21,139.54,-0.447
23.22,139.39,-0.447
23.24,139.24,-0.447
23.25,139.09,-0.447
23.27,138.94,-0.447
23.28,138.79,-0.447
23.30,138.64,-0.446
23.31,138.49,-0.446
23.33,138.34,-0.446
23.34,138.19,-0.446
23.36,138.04,-0.446
23.37,137.89,-0.446
23.39,137.74,-0.446
23.40,137.59,-0.446
23.42,137.44,-0.446
23.43,137.29,-0.445
23.45,137.14,-0.445
23.46,137.00,-0.445
23.48,136.84,-0.445
23.49,136.69,-0.445
23.51,136.55,-0.445
23.52,136.40,-0.445
23.54,136.25,-0.445
23.55,136.10,-0.445
23.57,135.95,-0.444
23.58,135.80,-0.444
23.60,135.65,-0.444
23.61,135.50,-0.444
23.63,135.35,-0.444
23.64,135.20,-0.444
23.66,135.05,-0.444
23.67,134.90,-0.444
23.69,134.75,-0.443
23.70,134.60,-0.443
23.72,134.45,-0.443
23.73,134.30,-0.443
23.75,134.15,-0.443
23.76,134.00,-0.443
23.78,133.85,-0.443
23.79,133.70,-0.443
23.81,133.55,-0.442
23.82,133.40,-0.442
23.84,133.25,-0.442
23.85,133.10,-0.442
23.87,132.95,-0.442
23.88,132.80,-0.442
23.90,132.65,-0.442
23.91,132.50,-0.442
23.93,132.35,-0.441
23.94,132.20,-0.441
23.96,132.05,-0.441
23.97,131.90,-0.441
23.99,131.75,-0.441
24.00,131.60,-0.441
24.02,131.45,-0.441
24.03,131.30,-0.441
24.05,131.16,-0.441
24.06,131.01,-0.441
24.08,130.86,-0.440
24.09,130.71,-0.440
24.11,130.56,-0.440
24.12,130.41,-0.440
24.14,130.26,-0.440
24.15,130.11,-0.440
24.17,129.96,-0.440
24.18,129.81,-0.439
24.20,129.66,-0.439
24.21,129.51,-0.439
24.23,129.36,-0.439
24.24,129.21,-0.439
24.26,129.06,-0.439
24.27,128.91,-0.439
24.29,128.76,-0.439
24.30,128.61,-0.438
24.32,128.46,-0.438
24.33,128.31,-0.438
24.35,128.16,-0.438
24.36,128.01,-0.438
24.38,127.86,-0.438
24.39,127.71,-0.438
24.41,127.56,-0.438
24.42,127.41,-0.437
24.44,127.26,-0.437
24.45,127.11,-0.437
24.47,126.96,-0.437
24.48,126.81,-0.437
24.50,126.66,-0.437
24.51,126.51,-0.437
24.53,126.36,-0.437
24.54,126.21,-0.436
24.56,126.06,-0.436
24.57,125.91,-0.436
24.59,125.76,-0.436
24.60,125.61,-0.436
24.62,125.46,-0.436
24.63,125.31,-0.436
24.65,125.16,-0.436
24.66,125.01,-0.435
24.68,124.86,-0.435
24.69,124.71,-0.435
24.71,124.56,-0.435
24.72,124.41,-0.435
24.74,124.26,-0.435
24.75,124.11,-0.435
24.77,123.96,-0.435
24.78,123.81,-0.434
24.80,123.66,-0.434
24.81,123.51,-0.434
24.83,123.36,-0.434
24.84,123.21,-0.434
24.86,123.06,-0.434
24.87,122.92,-0.434
24.89,122.77,-0.434
24.90,122.62,-0.434
24.92,122.47,-0.433
24.93,122.32,-0.433
24.95,122.17,-0.433
24.96,122.02,-0.433
24.98,121.87,-0.433
24.99,121.72,-0.433
25.01,121.57,-0.433
25.02,121.42,-0.433
25.04,121.27,-0.433
25.05,121.12,-0.432
25.07,120.97,-0.432
25.08,120.82,-0.432
25.10,120.67,-0.432
25.11,120.52,-0.432
25.13,120.37,-0.432
25.14,120.22,-0.432
25.16,120.07,-0.432
25.17,119.92,-0.432
25.19,119.77,-0.432
25.20,119.62,-0.431
25.22,119.47,-0.431
25.23,119.32,-0.431
25.25,119.17,-0.431
25.26,119.02,-0.431
25.28,118.87,-0.431
25.29,118.72,-0.430
25.31,118.57,-0.430
25.32,118.42,-0.430
25.34,118.27,-0.430
25.35,118.12,-0.430
25.37,117.97,-0.430
25.38,117.82,-0.430
25.40,117.67,-0.430
25.41,117.52,-0.430
25.43,117.37,-0.430
25.44,117.22,-0.429
25.46,117.07,-0.429
25.47,116.92,-0.429
25.49,116.77,-0.429
25.50,116.62,-0.429
25.52,116.47,-0.429
25.53,116.32,-0.429
25.55,116.17,-0.429
25.56,116.02,-0.429
25.58,115.87,-0.428
25.59,115.72,-0.428
25.61,115.57,-0.428
25.62,115.42,-0.428
25.64,115.27,-0.428
25.65,115.12,-0.428
25.67,114.97,-0.428
25.68,114.82,-0.428
25.70,114.67,-0.428
25.71,114.52,-0.428
25.73,114.37,-0.427
25.74,114.22,-0.427
25.76,114.07,-0.427
25.77,113.92,-0.427
25.79,113.78,-0.427
25.80,113.62,-0.427
25.82,113.47,-0.427
25.83,113.32,-0.426
25.85,113.18,-0.426
25.86,113.02,-0.426
25.88,112.88,-0.426
25.89,112.73,-0.426
25.91,112.58,-0.426
25.92,112.43,-0.426
25.94,112.28,-0.426
25.95,112.13,-0.426
25.97,111.98,-0.425
25.98,111.83,-0.425
26.00,111.68,-0.425
26.01,111.53,-0.425
26.03,111.38,-0.425
26.04,111.23,-0.425
26.06,111.08,-0.425
26.07,110.93,-0.424
26.09,110.78,-0.424
26.10,110.63,-0.424
26.12,110.48,-0.424
26.13,110.33,-0.424
26.15,110.18,-0.424
26.16,110.03,-0.424
26.18,109.88,-0.424
26.19,109.73,-0.424
26.21,109.58,-0.424
26.22,109.43,-0.423
26.24,109.28,-0.423
26.25,109.13,-0.423
26.27,108.98,-0.423
26.28,108.83,-0.423
26.30,108.68,-0.423
26.31,108.53,-0.423
26.33,108.38,-0.423
26.34,108.23,-0.423
26.36,108.08,-0.423
26.37,107.93,-0.423
26.39,107.78,-0.423
26.40,107.63,-0.422
26.42,107.48,-0.422
26.43,107.33,-0.422
26.45,107.18,-0.422
26.46,107.03,-0.422
26.48,106.88,-0.422
26.49,106.73,-0.422
26.51,106.58,-0.422
26.52,106.43,-0.422
26.54,106.28,-0.422
26.55,106.13,-0.421
26.57,105.98,-0.421
26.58,105.83,-0.421
26.60,105.69,-0.421
26.61,105.53,-0.421
26.63,105.38,-0.421
26.64,105.23,-0.421
26.66,105.08,-0.421
26.67,104.93,-0.421
26.69,104.78,-0.421
26.70,104.64,-0.420
26.72,104.49,-0.420
26.73,104.34,-0.420
26.75,104.18,-0.420
26.76,104.04,-0.420
26.78,103.89,-0.420
26.79,103.74,-0.420
26.81,103.59,-0.420
26.82,103.44,-0.420
26.84,103.29,-0.420
26.85,103.14,-0.419
26.87,102.99,-0.419
26.88,102.84,-0.419
26.90,102.69,-0.419
26.91,102.54,-0.419
26.93,102.39,-0.419
26.94,102.24,-0.419
26.96,102.09,-0.419
26.97,101.94,-0.419
26.99,101.79,-0.419
27.00,101.64,-0.418
27.02,101.49,-0.418
27.03,101.34,-0.418
27.05,101.19,-0.418
27.06,101.04,-0.418
27.08,100.89,-0.418
27.09,100.74,-0.418
27.11,100.59,-0.418
27.12,100.44,-0.418
27.14,100.29,-0.417
27.15,100.14,-0.417
27.17,99.99,-0.417
27.18,99.84,-0.417
27.20,99.69,-0.417
27.21,99.54,-0.417
27.23,99.39,-0.417
27.24,99.24,-0.417
27.26,99.09,-0.417
27.27,98.94,-0.417
27.29,98.79,-0.417
27.30,98.64,-0.416
27.32,98.49,-0.416
27.33,98.34,-0.416
27.35,98.19,-0.416
27.36,98.04,-0.416
27.38,97.89,-0.416
27.39,97.74,-0.416
27.41,97.59,-0.416
27.42,97.44,-0.416
27.44,97.29,-0.415
27.45,97.14,-0.415
27.47,96.99,-0.415
27.48,96.84,-0.415
27.50,96.69,-0.415
27.51,96.54,-0.415
27.53,96.39,-0.415
27.54,96.25,-0.415
27.56,96.09,-0.415
27.57,95.94,-0.415
27.59,95.80,-0.414
27.60,95.65,-0.414
27.62,95.50,-0.414
27.63,95.35,-0.414
27.65,95.20,-0.414
27.66,95.05,-0.414
27.68,94.89,-0.414
27.69,94.75,-0.414
27.71,94.60,-0.413
27.72,94.45,-0.413
27.74,94.30,-0.413
27.75,94.15,-0.413
27.77,94.00,-0.413
27.78,93.85,-0.413
27.80,93.70,-0.413
27.81,93.55,-0.413
27.83,93.40,-0.413
27.84,93.25,-0.412
27.86,93.10,-0.412
27.87,92.95,-0.412
27.89,92.80,-0.412
27.90,92.65,-0.412
27.92,92.50,-0.412
27.93,92.35,-0.412
27.95,92.20,-0.412
27.96,92.05,-0.412
27.98,91.90,-0.411
27.99,91.75,-0.411
28.01,91.60,-0.411
28.02,91.45,-0.411
28.04,91.30,-0.411
28.05,91.15,-0.411
28.07,91.00,-0.411
28.08,90.85,-0.411
28.10,90.70,-0.410
28.11,90.55,-0.410
28.13,90.40,-0.410
28.14,90.25,-0.410
28.16,90.10,-0.410
28.17,89.95,-0.410
28.19,89.80,-0.410
28.20,89.65,-0.410
28.22,89.50,-0.409
28.23,89.35,-0.409
28.25,89.20,-0.409
28.26,89.05,-0.409
28.28,88.90,-0.409
28.29,88.75,-0.409
28.31,88.60,-0.409
28.32,88.45,-0.409
28.34,88.30,-0.409
28.35,88.15,-0.408
28.37,88.00,-0.408
28.38,87.85,-0.408
28.40,87.70,-0.408
28.41,87.55,-0.408
28.43,87.40,-0.408
28.44,87.25,-0.408
28.46,87.10,-0.408
28.47,86.95,-0.407
28.49,86.80,-0.407
28.50,86.65,-0.407
[...]
93.05,-11.13,0.297
93.06,-10.98,0.297
93.08,-10.83,0.297
93.09,-10.68,0.297
93.11,-10.53,0.296
93.12,-10.38,0.294
93.14,-10.23,0.293
93.15,-10.08,0.291
93.17,-9.93,0.288
93.18,-9.78,0.287
93.20,-9.63,0.285
93.21,-9.47,0.284
93.23,-9.32,0.283
93.24,-9.17,0.281
93.26,-9.02,0.280
93.27,-8.87,0.279
93.29,-8.72,0.278
93.30,-8.57,0.278
93.32,-8.42,0.277
93.33,-8.27,0.277
93.35,-8.12,0.277
93.36,-7.97,0.276
93.38,-7.82,0.276
93.39,-7.67,0.276
93.41,-7.52,0.275
93.42,-7.37,0.275
93.44,-7.22,0.275
93.45,-7.07,0.275
93.47,-6.92,0.275
93.48,-6.76,0.274
93.50,-6.61,0.274
93.51,-6.46,0.274
93.53,-6.31,0.274
93.54,-6.16,0.274
93.56,-6.01,0.273
93.57,-5.86,0.273
93.59,-5.71,0.273
93.60,-5.56,0.273
93.62,-5.41,0.273
93.63,-5.26,0.273
93.65,-5.11,0.272
93.66,-4.96,0.272
93.68,-4.81,0.272
93.69,-4.66,0.272
93.71,-4.51,0.272
93.72,-4.36,0.272
93.74,-4.21,0.272
93.75,-4.06,0.272
93.77,-3.91,0.272
93.78,-3.76,0.272
93.80,-3.61,0.272
93.81,-3.46,0.272
93.83,-3.31,0.272
93.84,-3.16,0.272
93.86,-3.01,0.272
93.87,-2.86,0.272
93.89,-2.71,0.272
93.90,-2.56,0.272
93.92,-2.41,0.272
93.93,-2.26,0.272
93.95,-2.11,0.272
93.96,-1.96,0.272
93.98,-1.81,0.272
93.99,-1.66,0.272
94.01,-1.51,0.272
94.02,-1.36,0.272
94.04,-1.21,0.272
94.05,-1.06,0.272
94.07,-0.91,0.272
94.08,-0.76,0.272
94.10,-0.60,0.272
94.11,-0.45,0.272
94.13,-0.31,0.272
94.14,-0.16,0.272
94.16,0.00,0.272
94.17,0.15,0.272
94.19,0.30,0.272
94.20,0.45,0.272
94.22,0.60,0.272
94.23,0.75,0.272
94.25,0.90,0.272
94.26,1.05,0.272
94.28,1.20,0.272
94.29,1.35,0.272
94.31,1.50,0.272
94.32,1.65,0.272
94.34,1.80,0.272
94.35,1.95,0.273
94.37,2.10,0.273
94.38,2.25,0.273
94.40,2.40,0.273
94.41,2.55,0.273
94.43,2.70,0.273
94.44,2.85,0.273
94.46,3.00,0.273
94.47,3.15,0.273
94.49,3.30,0.273
94.50,3.45,0.273
94.52,3.60,0.273
94.53,3.75,0.273
94.55,3.90,0.273
94.56,4.05,0.273
94.58,4.20,0.274
94.59,4.35,0.274
94.61,4.50,0.274
94.62,4.65,0.274
94.64,4.80,0.274
94.65,4.95,0.274
94.67,5.10,0.274
94.68,5.25,0.274
94.70,5.40,0.274
94.71,5.55,0.274
94.73,5.70,0.274
94.74,5.85,0.274
94.76,6.00,0.275
94.77,6.15,0.275
94.79,6.30,0.275
94.80,6.46,0.275
94.82,6.60,0.275
94.83,6.75,0.275
94.85,6.90,0.275
94.86,7.05,0.275
94.88,7.21,0.275
94.89,7.36,0.275
94.91,7.50,0.275
94.92,7.66,0.276
94.94,7.81,0.276
94.95,7.96,0.276
94.97,8.11,0.276
94.98,8.26,0.276
95.00,8.41,0.276
95.01,8.56,0.276
95.03,8.71,0.276
95.04,8.86,0.276
95.06,9.01,0.276
95.07,9.16,0.276
95.09,9.31,0.276
95.10,9.46,0.277
95.12,9.61,0.277
95.13,9.76,0.277
95.15,9.91,0.277
95.16,10.06,0.277
95.18,10.21,0.277
95.19,10.36,0.277
95.21,10.51,0.277
95.22,10.66,0.277
95.24,10.81,0.277
95.25,10.96,0.278
95.27,11.11,0.278
95.28,11.26,0.278
95.30,11.41,0.278
95.31,11.56,0.278
95.33,11.71,0.278
95.34,11.86,0.278
95.36,12.01,0.278
95.37,12.16,0.278
95.39,12.31,0.278
95.40,12.46,0.278
95.42,12.61,0.279
95.43,12.76,0.279
95.45,12.91,0.279
95.46,13.06,0.279
95.48,13.21,0.279
95.49,13.36,0.279
95.51,13.51,0.279
95.52,13.66,0.279
95.54,13.81,0.279
95.55,13.96,0.279
95.57,14.11,0.279
95.58,14.26,0.280
95.60,14.41,0.280
95.61,14.56,0.280
95.63,14.71,0.280
95.64,14.86,0.280
95.66,15.01,0.280
95.67,15.16,0.280
95.69,15.31,0.280
95.70,15.46,0.280
95.72,15.61,0.280
95.73,15.76,0.280
95.75,15.91,0.280
95.76,16.06,0.281
95.78,16.21,0.281
95.79,16.37,0.281
95.81,16.51,0.281
95.82,16.67,0.281
95.84,16.82,0.281
95.85,16.97,0.281
95.87,17.12,0.281
95.88,17.27,0.281
95.90,17.42,0.281
95.91,17.57,0.281
95.93,17.72,0.281
95.94,17.87,0.282
95.96,18.02,0.282
95.97,18.17,0.282
95.99,18.32,0.282
96.00,18.47,0.282
96.02,18.62,0.282
96.03,18.77,0.282
96.05,18.92,0.282
96.06,19.07,0.282
96.08,19.22,0.282
96.09,19.37,0.283
96.11,19.52,0.283
96.12,19.67,0.283
96.14,19.82,0.283
96.15,19.97,0.283
96.17,20.12,0.283
96.18,20.27,0.283
96.20,20.42,0.283
96.21,20.57,0.283
96.23,20.72,0.284
96.24,20.87,0.284
96.26,21.02,0.284
96.27,21.17,0.284
96.29,21.32,0.284
96.30,21.47,0.284
96.32,21.62,0.284
96.33,21.77,0.284
96.35,21.92,0.284
96.36,22.07,0.284
96.38,22.22,0.285
96.39,22.37,0.285
96.41,22.52,0.285
96.42,22.67,0.285
96.44,22.82,0.285
96.45,22.97,0.285
96.47,23.12,0.285
96.48,23.27,0.285
96.50,23.42,0.285
96.51,23.57,0.285
96.53,23.72,0.285
96.54,23.87,0.286
96.56,24.02,0.286
96.57,24.17,0.286
96.59,24.32,0.286
96.60,24.47,0.286
96.62,24.62,0.286
96.63,24.77,0.286
96.65,24.92,0.286
96.66,25.07,0.286
96.68,25.22,0.286
96.69,25.38,0.286
96.71,25.52,0.287
96.72,25.68,0.287
96.74,25.83,0.287
96.75,25.98,0.287
96.77,26.13,0.287
96.78,26.27,0.287
96.80,26.43,0.287
96.81,26.58,0.287
96.83,26.73,0.287
96.84,26.88,0.288
96.86,27.03,0.288
96.87,27.18,0.288
96.89,27.33,0.288
96.90,27.48,0.288
96.92,27.63,0.288
96.93,27.78,0.288
96.95,27.93,0.288
96.96,28.08,0.289
96.98,28.23,0.289
96.99,28.38,0.289
97.01,28.53,0.289
97.02,28.68,0.289
97.04,28.83,0.289
97.05,28.98,0.289
97.07,29.13,0.289
97.08,29.28,0.289
97.10,29.43,0.289
97.11,29.58,0.290
97.13,29.73,0.290
97.14,29.88,0.290
97.16,30.03,0.290
97.17,30.18,0.290
97.19,30.33,0.290
97.20,30.48,0.290
97.22,30.63,0.290
97.23,30.78,0.290
97.25,30.93,0.291
97.26,31.08,0.291
97.28,31.23,0.291
97.29,31.38,0.291
97.31,31.53,0.291
97.32,31.68,0.291
97.34,31.83,0.291
97.35,31.98,0.291
97.37,32.13,0.291
97.38,32.28,0.291
97.40,32.43,0.291
97.41,32.58,0.291
97.43,32.73,0.292
97.44,32.88,0.292
97.46,33.03,0.292
97.47,33.18,0.292
97.49,33.33,0.292
97.50,33.48,0.292
97.52,33.63,0.292
97.53,33.78,0.292
97.55,33.93,0.292
97.56,34.08,0.292
97.58,34.23,0.292
97.59,34.38,0.292
97.61,34.53,0.293
97.62,34.69,0.293
97.64,34.83,0.293
97.65,34.99,0.293
97.67,35.14,0.293
97.68,35.28,0.293
97.70,35.43,0.293
97.71,35.59,0.293
97.73,35.74,0.293
97.74,35.89,0.293
97.76,36.04,0.293
97.77,36.19,0.294
97.79,36.34,0.294
97.80,36.49,0.294
97.82,36.64,0.294
97.83,36.79,0.294
97.85,36.94,0.294
97.86,37.09,0.294
97.88,37.24,0.294
97.89,37.39,0.294
97.91,37.54,0.294
97.92,37.69,0.294
97.94,37.84,0.294
97.95,37.99,0.295
97.97,38.14,0.295
97.98,38.29,0.295
98.00,38.44,0.295
98.01,38.59,0.295
98.03,38.74,0.295
98.04,38.89,0.295
98.06,39.04,0.295
98.07,39.19,0.295
98.09,39.34,0.295
98.10,39.49,0.296
98.12,39.64,0.296
98.13,39.79,0.296
98.15,39.94,0.296
98.16,40.09,0.296
98.18,40.24,0.296
98.19,40.39,0.296
98.21,40.54,0.296
98.22,40.69,0.296
98.24,40.84,0.296
98.25,40.99,0.296
98.27,41.14,0.297
98.28,41.29,0.297
98.30,41.44,0.297
98.31,41.59,0.297
98.33,41.74,0.297
98.34,41.89,0.297
98.36,42.04,0.297
98.37,42.19,0.297
98.39,42.34,0.297
98.40,42.49,0.297
98.42,42.64,0.297
98.43,42.79,0.298
98.45,42.94,0.298
98.46,43.10,0.298
98.48,43.24,0.298
98.49,43.39,0.298
98.51,43.55,0.298
98.52,43.69,0.298
98.54,43.84,0.298
98.55,44.00,0.298
98.57,44.15,0.298
98.58,44.30,0.298
98.60,44.45,0.298
98.61,44.60,0.299
98.63,44.75,0.299
98.64,44.90,0.299
98.66,45.05,0.299
98.67,45.20,0.299
98.69,45.35,0.299
98.70,45.50,0.299
98.72,45.65,0.299
98.73,45.80,0.299
98.75,45.95,0.300
98.76,46.10,0.300
98.78,46.25,0.300
98.79,46.40,0.300
98.81,46.55,0.300
98.82,46.70,0.300
98.84,46.85,0.300
98.85,47.00,0.300
98.87,47.15,0.300
98.88,47.30,0.300
98.90,47.45,0.300
98.91,47.60,0.301
98.93,47.75,0.301
98.94,47.90,0.301
98.96,48.05,0.301
98.97,48.20,0.301
98.99,48.35,0.301
99.00,48.50,0.301
99.02,48.65,0.301
99.03,48.80,0.301
99.05,48.95,0.301
99.06,49.10,0.301
99.08,49.25,0.302
99.09,49.40,0.302
99.11,49.55,0.302
99.12,49.70,0.302
99.14,49.85,0.302
99.15,50.00,0.302
99.17,50.15,0.302
99.18,50.30,0.302
99.20,50.45,0.302
99.21,50.60,0.302
99.23,50.75,0.302
99.24,50.90,0.303
99.26,51.05,0.303
99.27,51.20,0.303
99.29,51.35,0.303
99.30,51.50,0.303
99.32,51.65,0.303
99.33,51.80,0.303
99.35,51.95,0.303
99.36,52.10,0.303
99.38,52.25,0.303
99.39,52.41,0.303
99.41,52.56,0.304
99.42,52.71,0.304
99.44,52.86,0.304
99.45,53.00,0.304
99.47,53.16,0.304
99.48,53.31,0.304
99.50,53.46,0.304
99.51,53.60,0.304
99.53,53.76,0.304
99.54,53.91,0.304
99.56,54.06,0.304
99.57,54.21,0.304
99.59,54.36,0.305
99.60,54.51,0.305
99.62,54.66,0.305
99.63,54.81,0.305
99.65,54.96,0.305
99.66,55.11,0.305
99.68,55.26,0.305
99.69,55.41,0.305
99.71,55.56,0.305
99.72,55.71,0.305
99.74,55.86,0.305
99.75,56.01,0.306
99.77,56.16,0.306
99.78,56.31,0.306
99.80,56.46,0.306
99.81,56.61,0.306
99.83,56.76,0.306
99.84,56.91,0.306
99.86,57.06,0.306
99.87,57.21,0.306
99.89,57.36,0.306
99.90,57.51,0.306
99.92,57.66,0.307
99.93,57.81,0.307
99.95,57.96,0.307
99.96,58.11,0.307
99.98,58.26,0.307
99.99,58.41,0.307
100.01,58.56,0.307
100.02,58.71,0.307
100.04,58.86,0.307
100.05,59.01,0.307
100.07,59.16,0.307
100.08,59.31,0.307
100.10,59.46,0.308
100.11,59.61,0.308
100.13,59.76,0.308
100.14,59.91,0.308
100.16,60.06,0.308
100.17,60.21,0.308
100.19,60.36,0.308
100.20,60.51,0.308
100.22,60.66,0.308
100.23,60.82,0.308
100.25,60.97,0.308
100.26,61.12,0.308
100.28,61.27,0.309
100.29,61.42,0.309
100.31,61.57,0.309
100.32,61.71,0.309
100.34,61.87,0.309
100.35,62.02,0.309
100.37,62.17,0.309
100.38,62.32,0.309
100.40,62.47,0.309
100.41,62.62,0.309
100.43,62.77,0.309
100.44,62.92,0.309
100.46,63.07,0.309
100.47,63.22,0.309
100.49,63.37,0.310
100.50,63.52,0.310
100.52,63.67,0.310
100.53,63.82,0.310
100.55,63.97,0.310
100.56,64.12,0.310
100.58,64.27,0.310
100.59,64.42,0.310
100.61,64.57,0.310
100.62,64.72,0.310
100.64,64.87,0.310
100.65,65.02,0.310
100.67,65.17,0.311
100.68,65.32,0.311
100.70,65.47,0.311
100.71,65.62,0.311
100.73,65.77,0.311
100.74,65.92,0.311
100.76,66.07,0.311
100.77,66.22,0.311
100.79,66.37,0.311
100.80,66.52,0.311
100.82,66.67,0.311
100.83,66.82,0.311
100.85,66.97,0.311
100.86,67.12,0.311
100.88,67.27,0.312
100.89,67.42,0.312
100.91,67.57,0.312
100.92,67.72,0.312
100.94,67.87,0.312
100.95,68.02,0.312
100.97,68.17,0.312
100.98,68.32,0.312
101.00,68.47,0.312
101.01,68.62,0.312
101.03,68.77,0.312
101.04,68.92,0.312
101.06,69.07,0.313
101.07,69.22,0.313
101.09,69.37,0.313
101.10,69.52,0.313
101.12,69.67,0.313
101.13,69.82,0.313
101.15,69.97,0.313
101.16,70.12,0.313
101.18,70.27,0.313
101.19,70.42,0.313
101.21,70.57,0.313
101.22,70.72,0.314
101.24,70.87,0.314
101.25,71.02,0.314
101.27,71.17,0.314
101.28,71.32,0.314
101.30,71.47,0.314
101.31,71.62,0.314
101.33,71.77,0.314
101.34,71.93,0.314
101.36,72.07,0.314
101.37,72.23,0.314
101.39,72.37,0.314
101.40,72.52,0.315
101.42,72.67,0.315
101.43,72.83,0.315
101.45,72.97,0.315
101.46,73.12,0.315
101.48,73.28,0.315
101.49,73.43,0.315
101.51,73.58,0.315
101.52,73.73,0.315
101.54,73.88,0.315
101.55,74.03,0.315
101.57,74.18,0.316
101.58,74.33,0.316
101.60,74.48,0.316
101.61,74.63,0.316
101.63,74.78,0.316
101.64,74.93,0.316
101.66,75.08,0.316
101.67,75.23,0.316
101.69,75.38,0.316
101.70,75.53,0.316
101.72,75.68,0.316
101.73,75.83,0.316
101.75,75.98,0.317
101.76,76.13,0.317
101.78,76.28,0.317
101.79,76.43,0.317
101.81,76.58,0.317
101.82,76.73,0.317
101.84,76.88,0.317
101.85,77.03,0.317
101.87,77.18,0.317
101.88,77.33,0.317
101.90,77.48,0.317
101.91,77.63,0.317
101.93,77.78,0.317
101.94,77.93,0.317
101.96,78.08,0.318
101.97,78.23,0.318
101.99,78.38,0.318
102.00,78.53,0.318
102.02,78.68,0.318
102.03,78.83,0.318
102.05,78.98,0.318
102.06,79.13,0.318
102.08,79.28,0.318
102.09,79.43,0.318
102.11,79.58,0.318
102.12,79.73,0.318
102.14,79.88,0.318
102.15,80.03,0.318
102.17,80.18,0.318
102.18,80.33,0.319
102.20,80.48,0.319
102.21,80.63,0.319
102.23,80.78,0.319
102.24,80.93,0.319
102.26,81.08,0.319
102.27,81.23,0.319
102.29,81.38,0.319
102.30,81.53,0.319
102.32,81.68,0.319
102.33,81.83,0.319
102.35,81.98,0.319
102.36,82.13,0.319
102.38,82.28,0.319
102.39,82.44,0.320
102.41,82.59,0.320
102.42,82.74,0.320
102.44,82.89,0.320
102.45,83.04,0.320
102.47,83.19,0.320
102.48,83.34,0.320
102.50,83.49,0.320
102.51,83.64,0.320
102.53,83.79,0.320
102.54,83.94,0.320
102.56,84.09,0.320
102.57,84.24,0.320
102.59,84.39,0.320
102.60,84.54,0.320
102.62,84.69,0.321
102.63,84.84,0.321
102.65,84.99,0.321
102.66,85.14,0.321
102.68,85.29,0.321
102.69,85.44,0.321
102.71,85.59,0.321
102.72,85.74,0.321
102.74,85.89,0.321
102.75,86.04,0.321
102.77,86.19,0.321
102.78,86.34,0.321
102.80,86.49,0.321
102.81,86.64,0.321
102.83,86.79,0.321
102.84,86.94,0.321
102.86,87.09,0.321
102.87,87.24,0.321
102.89,87.39,0.322
102.90,87.54,0.322
102.92,87.69,0.322
102.93,87.84,0.322
102.95,87.99,0.322
102.96,88.14,0.322
102.98,88.29,0.322
102.99,88.44,0.322
103.01,88.59,0.322
103.02,88.74,0.322
103.04,88.89,0.322
103.05,89.04,0.322
103.07,89.19,0.322
103.08,89.34,0.322
103.10,89.49,0.323
103.11,89.64,0.323
103.13,89.79,0.323
103.14,89.94,0.323
103.16,90.09,0.323
103.17,90.24,0.323
103.19,90.39,0.323
103.20,90.54,0.323
103.22,90.69,0.323
103.23,90.84,0.323
103.25,90.99,0.323
103.26,91.14,0.323
103.28,91.29,0.324
103.29,91.44,0.324
103.31,91.59,0.324
103.32,91.74,0.324
103.34,91.89,0.324
103.35,92.04,0.324
103.37,92.19,0.324
103.38,92.34,0.324
103.40,92.49,0.324
103.41,92.64,0.324
103.43,92.79,0.324
103.44,92.95,0.324
103.46,93.10,0.325
103.47,93.25,0.325
103.49,93.40,0.325
103.50,93.55,0.325
103.52,93.70,0.325
103.53,93.85,0.325
103.55,94.00,0.325
103.56,94.15,0.325
103.58,94.30,0.325
103.59,94.45,0.325
103.61,94.60,0.325
103.62,94.75,0.326
103.64,94.90,0.326
103.65,95.05,0.326
103.67,95.20,0.326
103.68,95.35,0.326
103.70,95.50,0.326
103.71,95.65,0.326
103.73,95.80,0.326
103.74,95.95,0.326
103.76,96.10,0.326
103.77,96.25,0.326
103.79,96.40,0.326
103.80,96.55,0.327
103.82,96.70,0.327
103.83,96.85,0.327
103.85,97.00,0.327
103.86,97.15,0.327
103.88,97.30,0.327
103.89,97.45,0.327
103.91,97.60,0.327
103.92,97.75,0.327
103.94,97.90,0.327
103.95,98.05,0.327
103.97,98.20,0.327
103.98,98.35,0.328
104.00,98.50,0.328
104.01,98.65,0.328
104.03,98.80,0.328
104.04,98.95,0.328
104.06,99.10,0.328
104.07,99.25,0.328
104.09,99.40,0.328
104.10,99.55,0.328
104.12,99.70,0.328
104.13,99.85,0.328
104.15,100.00,0.328
104.16,100.15,0.328
104.18,100.30,0.328
104.19,100.45,0.328
104.21,100.60,0.329
104.22,100.75,0.329
104.24,100.90,0.329
104.25,101.05,0.329
104.27,101.20,0.329
104.28,101.35,0.329
104.30,101.50,0.329
104.31,101.65,0.329
104.33,101.80,0.329
104.34,101.95,0.329
104.36,102.10,0.329
104.37,102.25,0.329
104.39,102.40,0.329
104.40,102.55,0.329
104.42,102.70,0.330
104.43,102.85,0.330
104.45,103.00,0.330
104.46,103.15,0.330
104.48,103.30,0.330
104.49,103.45,0.330
104.51,103.60,0.330
104.52,103.75,0.330
104.54,103.90,0.330
104.55,104.05,0.330
104.57,104.20,0.330
104.58,104.35,0.330
104.60,104.50,0.330
104.61,104.65,0.331
104.63,104.80,0.331
104.64,104.95,0.331
104.66,105.11,0.331
104.67,105.26,0.331
104.69,105.41,0.331
104.70,105.56,0.331
104.72,105.71,0.331
104.73,105.86,0.331
104.75,106.01,0.331
104.76,106.16,0.331
104.78,106.30,0.331
104.79,106.46,0.331
104.81,106.61,0.331
104.82,106.76,0.331
104.84,106.91,0.331
104.85,107.06,0.332
104.87,107.21,0.332
104.88,107.36,0.332
104.90,107.51,0.332
104.91,107.66,0.332
104.93,107.81,0.332
104.94,107.96,0.332
104.96,108.11,0.332
104.97,108.26,0.332
104.99,108.41,0.332
105.00,108.56,0.332
105.02,108.71,0.332
105.03,108.86,0.332
105.05,109.01,0.332
105.06,109.16,0.333
105.08,109.31,0.333
105.09,109.46,0.333
105.11,109.61,0.333
105.12,109.76,0.333
105.14,109.91,0.333
105.15,110.06,0.333
105.17,110.21,0.333
105.18,110.36,0.333
105.20,110.51,0.333
105.21,110.66,0.333
105.23,110.81,0.333
105.24,110.96,0.333
105.26,111.11,0.333
105.27,111.26,0.333
105.29,111.41,0.333
105.30,111.56,0.333
105.32,111.71,0.333
105.33,111.86,0.334
105.35,112.01,0.334
105.36,112.16,0.334
105.38,112.31,0.334
105.39,112.46,0.334
105.41,112.61,0.334
105.42,112.76,0.334
105.44,112.91,0.334
105.45,113.06,0.334
105.47,113.21,0.334
105.48,113.36,0.334
105.50,113.51,0.334
105.51,113.66,0.334
105.53,113.81,0.334
105.54,113.96,0.335
105.56,114.11,0.335
105.57,114.26,0.335
105.59,114.41,0.335
105.60,114.56,0.335
105.62,114.71,0.335
105.63,114.86,0.335
105.65,115.01,0.335
105.66,115.16,0.335
105.68,115.31,0.335
105.69,115.46,0.335
105.71,115.61,0.335
105.72,115.76,0.335
105.74,115.92,0.335
105.75,116.06,0.335
105.77,116.21,0.335
105.78,116.36,0.335
105.80,116.51,0.336
105.81,116.66,0.336
105.83,116.81,0.336
105.84,116.96,0.336
105.86,117.11,0.336
105.87,117.26,0.336
105.89,117.41,0.336
105.90,117.56,0.336
105.92,117.71,0.336
105.93,117.86,0.336
105.95,118.01,0.336
105.96,118.17,0.336
105.98,118.32,0.336
105.99,118.47,0.336
106.01,118.62,0.336
106.02,118.77,0.336
106.04,118.92,0.337
106.05,119.07,0.337
106.07,119.22,0.337
106.08,119.37,0.337
106.10,119.52,0.337
106.11,119.67,0.337
106.13,119.82,0.337
106.14,119.97,0.337
106.16,120.12,0.337
106.17,120.27,0.337
106.19,120.42,0.337
106.20,120.57,0.337
106.22,120.72,0.337
106.23,120.87,0.337
106.25,121.02,0.337
106.26,121.17,0.337
106.28,121.32,0.337
106.29,121.47,0.337
106.31,121.62,0.337
106.32,121.77,0.338
106.34,121.92,0.338
106.35,122.07,0.338
106.37,122.22,0.338
106.38,122.37,0.338
106.40,122.52,0.338
106.41,122.67,0.338
106.43,122.82,0.338
106.44,122.97,0.338
106.46,123.12,0.338
106.47,123.27,0.338
106.49,123.42,0.338
106.50,123.57,0.338
106.52,123.72,0.338
106.53,123.87,0.338
106.55,124.02,0.338
106.56,124.17,0.338
106.58,124.32,0.338
106.59,124.47,0.338
106.61,124.62,0.338
106.62,124.77,0.339
106.64,124.92,0.339
106.65,125.07,0.339
106.67,125.22,0.339
106.68,125.37,0.339
106.70,125.52,0.339
106.71,125.67,0.339
106.73,125.82,0.339
106.74,125.97,0.339
106.76,126.12,0.339
106.77,126.27,0.339
106.79,126.42,0.339
106.80,126.57,0.339
106.82,126.72,0.339
106.83,126.87,0.340
106.85,127.02,0.340
106.86,127.17,0.340
106.88,127.32,0.340
106.89,127.47,0.340
106.91,127.62,0.340
106.92,127.77,0.340
106.94,127.92,0.340
106.95,128.07,0.340
106.97,128.22,0.340
106.98,128.37,0.340
107.00,128.52,0.340
107.01,128.67,0.340
107.03,128.82,0.340
107.04,128.97,0.340
107.06,129.12,0.340
107.07,129.27,0.341
107.09,129.43,0.341
107.10,129.57,0.341
107.12,129.72,0.341
107.13,129.87,0.341
107.15,130.03,0.341
107.16,130.17,0.341
107.18,130.33,0.341
107.19,130.47,0.341
107.21,130.63,0.341
107.22,130.78,0.341
107.24,130.93,0.341
107.25,131.08,0.341
107.27,131.23,0.341
107.28,131.37,0.341
107.30,131.53,0.341
107.31,131.68,0.341
107.33,131.83,0.341
107.34,131.98,0.341
107.36,132.13,0.341
107.37,132.28,0.341
107.39,132.43,0.341
107.40,132.58,0.342
107.42,132.73,0.342
107.43,132.88,0.342
107.45,133.03,0.342
107.46,133.18,0.342
107.48,133.33,0.342
107.49,133.48,0.342
107.51,133.63,0.342
107.52,133.78,0.342
107.54,133.93,0.342
107.55,134.08,0.342
107.57,134.23,0.342
107.58,134.38,0.342
107.60,134.53,0.342
107.61,134.68,0.342
107.63,134.83,0.342
107.64,134.98,0.342
107.66,135.13,0.342
107.67,135.28,0.342
107.69,135.43,0.342
107.70,135.58,0.342
107.72,135.73,0.342
107.73,135.88,0.342
107.75,136.03,0.342
107.76,136.18,0.342
107.78,136.33,0.343
107.79,136.48,0.343
107.81,136.63,0.343
107.82,136.78,0.343
107.84,136.93,0.343
107.85,137.08,0.343
107.87,137.23,0.343
107.88,137.38,0.343
107.90,137.53,0.343
107.91,137.68,0.343
107.93,137.83,0.343
107.94,137.98,0.343
107.96,138.13,0.343
107.97,138.28,0.343
107.99,138.43,0.343
108.00,138.58,0.343
108.02,138.73,0.343
108.03,138.88,0.343
108.05,139.03,0.343
108.06,139.18,0.343
108.08,139.33,0.343
108.09,139.48,0.343
108.11,139.63,0.343
108.12,139.78,0.343
108.14,139.93,0.343
108.15,140.08,0.343
108.17,140.23,0.343
108.18,140.38,0.343
108.20,140.53,0.343
108.21,140.68,0.343
108.23,140.83,0.343
108.24,140.98,0.343
108.26,141.13,0.343
108.27,141.28,0.343
108.29,141.43,0.343
108.30,141.58,0.343
108.32,141.73,0.343
108.33,141.88,0.343
108.35,142.03,0.343
108.36,142.18,0.343
108.38,142.33,0.343
108.39,142.49,0.343
108.41,142.64,0.343
108.42,142.79,0.344
108.44,142.94,0.344
108.45,143.09,0.344
108.47,143.23,0.344
108.48,143.39,0.344
108.50,143.54,0.344
108.51,143.69,0.344
108.53,143.84,0.344
108.54,143.99,0.344
108.56,144.14,0.344
108.57,144.29,0.344
108.59,144.44,0.344
108.60,144.59,0.344
108.62,144.74,0.344
108.63,144.89,0.344
108.65,145.04,0.344
108.66,145.19,0.344
108.68,145.34,0.344
108.69,145.49,0.344
108.71,145.64,0.344
108.72,145.79,0.344
108.74,145.94,0.344
108.75,146.09,0.344
108.77,146.24,0.344
108.78,146.39,0.344
108.80,146.54,0.344
108.81,146.69,0.344
108.83,146.84,0.344
108.84,146.99,0.344
108.86,147.14,0.344
108.87,147.29,0.344
108.89,147.44,0.344
108.90,147.59,0.344
108.92,147.74,0.344
108.93,147.89,0.344
108.95,148.04,
108.96,148.19,
108.98,148.34,
108.99,,