File: DSC/2025_04_18_THCa_Pro_n60C_170C_10Cmin_x3_2.csv
Filename,2025_04_18_THCa_Pro_n60C_170C_10Cmin_x3(1)
Instrument name,DSC2A-00468 (192.168.1.100)
Operator,Yarger
rundate,4/19/2025
Sample name,2025_04_18_THCa_Pro_n60C_170C_10Cmin_x3
proceduresegments,Data Off ; Equilibrate -60.00 °C; Data On ; Ramp 10.00 °C/min to 170.00 °C; Data Off ; Isothermal 0.1 min; Data On ; Ramp 10.00 °C/min to -60.00 °C; Data Off ; Isothermal 1.0 min; Data On ; Ramp 10.00 °C/min to 170.00 °C; Data Off ; Isothermal 0.1 min; Data On ; Ramp 10.00 °C/min to -60.00 °C; Data Off ; Isothermal 1.0 min; Data On ; Ramp 10.00 °C/min to 30.00 °C
[File Parameters]
Run date,4/19/2025 3:45:52 AM
Trios version,5.1.1.46572
Original File Name,
Current File Name,D:\DSC2500\JYarger\2025_04_18_THCa_Pro_n60C_170C_10Cmin_x3(1).tri
[Procedure]
Procedure Name,THCa_Pro_n60_170C_10Cmin_x3
Sample Name,2025_04_18_THCa_Pro_n60C_170C_10Cmin_x3
Sample Mass,7.13 mg
Reference Sample Mass,0 mg
Pan Mass,53.33 mg
Pan Number,18
Reference Pan Mass,53.66 mg
Reference Pan Number,46
Pan Type,Tzero Aluminum Hermetic
Comments,Hermetic Sealed Al DSC Consumables Pan/Lids.
Project Name,CA
Operator,Yarger
Test,Custom
Unload Max Temperature,30
Unload Min Temperature,30
Load Max Temperature,30
Load Min Temperature,30
Stop on Gas Flow Error,Yes
[Signal List]
Signal #1,Time (min)
Signal #2,Temperature (°C)
Signal #3,Heat Flow (mW)
Signal #4,Delta T (µV)
Signal #5,Delta Tzero (µV)
Signal #6,Tzero Temperature (°C)
Signal #7,Cell Purge (mL/min)
Signal #8,Heater Temp (°C)
Signal #9,Power Delivered (W)
Signal #10,Reference Junction Temperature (°C)
Signal #11,Flange Temperature (°C)
Signal #12,Heat Flow Phase (rad)
Signal #13,Total Heat Capacity (J/°C)
Signal #14,Heat Capacity (J/°C)
[Configuration]
Company Name,ASU
Instrument Name,DSC2A-00468
Instrument Type,DSC2500
Serial Number,DSC2A-00468
IP,192.168.1.100
Location of Instrument,MRRC
DisplayType,Unknown
Sample Interval ,0.1 s/pt
Selected Heat Flow,T4P
Exotherm Direction,Down
Cell Serial,DRC2-00792
Lid Type,Standard
Cooler,RCS 90
Leave Cooler on at End of Sequence,On
Gas 2,Nitrogen
Gas Selected,Channel 1
Flow Rate,50 mL/min
Secondary Purge,On
Licensed Heat Flow,Heat Flow T4P
Modulation Licensed,Yes
[Versions]
Common IDD Version,1
Cortex Version,VER 2.10.2.31
Driver,5.0.0.6
GDM Version,1.0.3.3
TouchscreenVersion,1.0.0.16145
FEP Version,1.2.1.21
FEP Bootloader,2.0.0.5
AutoSampler Version,2.1.1.26
Auto Sampler Bootloader,2.0.0.5
FCM Version,1.1.0.3
FCM Bootloader,2.0.0.5
[Experiment Logs]
Experiment Log Entry # 1,Data On set to 0
Experiment Log Entry # 3,Equilibrate Segment -60 (C) Started
Experiment Log Entry # 5,Air Cool is off.
Experiment Log Entry # 7,Data On set to 1
Experiment Log Entry # 9,Ramp Segment 10 C/min to 170 Started
Experiment Log Entry # 11,Data On set to 0
Experiment Log Entry # 13,Isothermal Segment 0.1 min started
Experiment Log Entry # 15,Data On set to 1
Experiment Log Entry # 17,Ramp Segment 10 C/min to -60 Started
Experiment Log Entry # 19,Data On set to 0
Experiment Log Entry # 21,Isothermal Segment 1 min started
Experiment Log Entry # 23,Data On set to 1
Experiment Log Entry # 25,Ramp Segment 10 C/min to 170 Started
Experiment Log Entry # 27,Data On set to 0
Experiment Log Entry # 29,Isothermal Segment 0.1 min started
Experiment Log Entry # 31,Data On set to 1
Experiment Log Entry # 33,Ramp Segment 10 C/min to -60 Started
Experiment Log Entry # 35,Data On set to 0
Experiment Log Entry # 37,Isothermal Segment 1 min started
Experiment Log Entry # 39,Data On set to 1
Experiment Log Entry # 41,Ramp Segment 10 C/min to 30 Started
[Method Log]
Method Log Entry # 1,Data Off
Method Log Entry # 2,Equilibrate -60 °C
Method Log Entry # 3,Data On
Method Log Entry # 4,(Ramp 184043) Ramp 10 °C/minute to 170 °C
Method Log Entry # 5,Data Off
Method Log Entry # 6,Isothermal 0.1 minutes
Method Log Entry # 7,Data On
Method Log Entry # 8,(Ramp 184047) Ramp 10 °C/minute to -60 °C
Method Log Entry # 9,Data Off
Method Log Entry # 10,Isothermal 1 minutes
Method Log Entry # 11,Data On
Method Log Entry # 12,(Ramp 184051) Ramp 10 °C/minute to 170 °C
Method Log Entry # 13,Data Off
Method Log Entry # 14,Isothermal 0.1 minutes
Method Log Entry # 15,Data On
Method Log Entry # 16,(Ramp 184055) Ramp 10 °C/minute to -60 °C
Method Log Entry # 17,Data Off
Method Log Entry # 18,Isothermal 1 minutes
Method Log Entry # 19,Data On
Method Log Entry # 20,(Ramp 184059) Ramp 10 °C/minute to 30 °C
Cell Serial,DRC2-00792
[T1 Calibration]
Slope,-0.008529666
Offset,9.636258
Initial Temperature,98.23
GUID,f8bfdadc-4977-4fdf-ba6d-0ba9134940c3
[TZero Calibration]
Date Applied,11/29/2022 4:06:13 PM
Description,From -89.059 °C to 396.009 °C at 20.000°C/min
Gas Type,Nitrogen
Pan Type,None
Source Files 1,C:\Users\yargerlab\Desktop\DSC Data\General\TZero_calibration_11_29_22_2nd(2).tri
Source Files 2,C:\Users\yargerlab\Desktop\DSC Data\General\TZero_calibration_11_29_22_2nd(3).tri
Delta T Offset,13.05235
Delta T Slope,-0.007271007
Delta T0 Offset,-13.69128
Delta T0 Slope,0.06063341
[Temperature Calibration]
Date Applied,11/29/2022 7:12:28 PM
Description,From 106.590 °C to 186.590 °C at 10.000°C/min
Gas Type,Nitrogen
Pan Type,Tzero Aluminum Hermetic
Source Files 1,C:\Users\yargerlab\Desktop\DSC Data\General\Indium(6).tri
Measured 1,157.391
Known 1,156.598
[Cell Constant Calibration]
Date Applied,11/29/2022 7:12:29 PM
Description,From 106.590 °C to 186.590 °C at 10.000°C/min
Gas Type,Nitrogen
Pan Type,Tzero Aluminum Hermetic
Source Files 1,C:\Users\yargerlab\Desktop\DSC Data\General\Indium(6).tri
T4P KCell,1.006051
Onset Slope,63.26126 mW/°C
[Direct Cp Calibration]
Date Applied,11/30/2022 11:04:51 AM
Description,From -79.983 °C to 298.409 °C at 10.000°C/min
Gas Type,Nitrogen
Pan Type,Tzero Aluminum Hermetic
Source Files 1,C:\Users\yargerlab\Desktop\DSC Data\General\Sapphire_Heat_Capacity_11_30_22.tri
[Rev Cp Calibration]
Date Applied,11/30/2022 1:58:51 PM
Description,From -79.996 °C to 292.812 °C at 3.000°C/min
Gas Type,Nitrogen
Pan Type,Tzero Aluminum Hermetic
Source Files 1,C:\Users\yargerlab\Desktop\DSC Data\General\Sapphire_MDSC_Calibration_11_30_22.tri
[step]
Ramp 10.00 °C/min to 170.00 °C
Time,Temperature,Heat Flow (Normalized)
min,°C,W/g
0.00,-59.67,-0.046
0.02,-59.68,-0.046
0.03,-59.69,-0.041
0.05,-59.69,-0.036
0.07,-59.68,-0.030
0.08,-59.66,-0.024
0.10,-59.62,-0.017
0.12,-59.56,-0.008
0.13,-59.49,0.002
0.15,-59.40,0.012
0.17,-59.30,0.024
0.18,-59.19,0.037
0.20,-59.08,0.049
0.22,-58.95,0.060
0.23,-58.82,0.072
0.25,-58.68,0.083
0.27,-58.54,0.092
0.28,-58.40,0.102
0.30,-58.26,0.110
0.32,-58.11,0.116
0.33,-57.96,0.124
0.35,-57.81,0.130
0.37,-57.66,0.135
0.38,-57.51,0.141
0.40,-57.35,0.145
0.42,-57.20,0.149
0.43,-57.05,0.151
0.45,-56.89,0.156
0.47,-56.73,0.157
0.48,-56.57,0.161
0.50,-56.41,0.162
0.52,-56.26,0.164
0.53,-56.10,0.165
0.55,-55.94,0.166
0.57,-55.78,0.168
0.58,-55.62,0.170
0.60,-55.45,0.170
0.62,-55.29,0.171
0.63,-55.13,0.172
0.65,-54.97,0.173
0.67,-54.81,0.173
0.68,-54.65,0.174
0.70,-54.48,0.174
0.72,-54.32,0.175
0.73,-54.16,0.175
0.75,-53.99,0.176
0.77,-53.83,0.176
0.78,-53.67,0.176
0.80,-53.50,0.176
0.82,-53.34,0.176
0.83,-53.18,0.177
0.85,-53.01,0.177
0.87,-52.85,0.177
0.88,-52.68,0.177
0.90,-52.52,0.178
0.92,-52.36,0.178
0.93,-52.19,0.178
0.95,-52.03,0.178
0.97,-51.86,0.178
0.98,-51.70,0.179
1.00,-51.53,0.179
1.02,-51.37,0.179
1.03,-51.20,0.179
1.05,-51.04,0.179
1.07,-50.87,0.180
1.08,-50.71,0.180
1.10,-50.54,0.180
1.12,-50.38,0.180
1.13,-50.21,0.180
1.15,-50.05,0.180
1.17,-49.88,0.181
1.18,-49.72,0.181
1.20,-49.55,0.181
1.22,-49.38,0.181
1.23,-49.22,0.181
1.25,-49.05,0.181
1.27,-48.89,0.182
1.28,-48.72,0.182
1.30,-48.56,0.182
1.32,-48.39,0.182
1.33,-48.22,0.182
1.35,-48.06,0.182
1.37,-47.89,0.182
1.38,-47.73,0.182
1.40,-47.56,0.182
1.42,-47.39,0.182
1.43,-47.23,0.183
1.45,-47.06,0.183
1.47,-46.90,0.183
1.48,-46.73,0.183
1.50,-46.56,0.183
1.52,-46.40,0.183
1.53,-46.23,0.183
1.55,-46.06,0.183
1.57,-45.90,0.183
1.58,-45.73,0.183
1.60,-45.56,0.183
1.62,-45.40,0.183
1.63,-45.23,0.184
1.65,-45.07,0.184
1.67,-44.90,0.184
1.68,-44.73,0.184
1.70,-44.57,0.184
1.72,-44.40,0.184
1.73,-44.23,0.184
1.75,-44.07,0.184
1.77,-43.90,0.184
1.78,-43.73,0.184
1.80,-43.57,0.184
1.82,-43.40,0.184
1.83,-43.23,0.184
1.85,-43.07,0.184
1.87,-42.90,0.184
1.88,-42.73,0.185
1.90,-42.57,0.185
1.92,-42.40,0.185
1.93,-42.23,0.185
1.95,-42.07,0.185
1.97,-41.90,0.185
1.98,-41.73,0.185
2.00,-41.57,0.185
2.02,-41.40,0.185
2.03,-41.23,0.185
2.05,-41.07,0.185
2.07,-40.90,0.185
2.08,-40.73,0.185
2.10,-40.57,0.185
2.12,-40.40,0.185
2.13,-40.23,0.185
2.15,-40.07,0.185
2.17,-39.90,0.186
2.18,-39.73,0.186
2.20,-39.57,0.186
2.22,-39.40,0.186
2.23,-39.23,0.186
2.25,-39.07,0.186
2.27,-38.90,0.186
2.28,-38.73,0.186
2.30,-38.56,0.186
2.32,-38.40,0.186
2.33,-38.23,0.186
2.35,-38.06,0.186
2.37,-37.90,0.186
2.38,-37.73,0.186
2.40,-37.56,0.186
2.42,-37.40,0.186
2.43,-37.23,0.186
2.45,-37.06,0.187
2.47,-36.89,0.187
2.48,-36.73,0.187
2.50,-36.56,0.187
2.52,-36.40,0.187
2.53,-36.23,0.187
2.55,-36.06,0.187
2.57,-35.90,0.187
2.58,-35.73,0.187
2.60,-35.56,0.187
2.62,-35.40,0.187
2.63,-35.23,0.187
2.65,-35.06,0.187
2.67,-34.89,0.187
2.68,-34.73,0.187
2.70,-34.56,0.188
2.72,-34.39,0.188
2.73,-34.23,0.188
2.75,-34.06,0.188
2.77,-33.89,0.188
2.78,-33.72,0.188
2.80,-33.56,0.188
2.82,-33.39,0.188
2.83,-33.23,0.188
2.85,-33.06,0.188
2.87,-32.89,0.188
2.88,-32.72,0.188
2.90,-32.56,0.188
2.92,-32.39,0.188
2.93,-32.22,0.188
2.95,-32.06,0.188
2.97,-31.89,0.188
2.98,-31.72,0.189
3.00,-31.56,0.189
3.02,-31.39,0.189
3.03,-31.22,0.189
3.05,-31.06,0.189
3.07,-30.89,0.189
3.08,-30.72,0.189
3.10,-30.55,0.189
3.12,-30.39,0.189
3.13,-30.22,0.189
3.15,-30.05,0.189
3.17,-29.89,0.189
3.18,-29.72,0.189
3.20,-29.55,0.189
3.22,-29.39,0.189
3.23,-29.22,0.190
3.25,-29.05,0.190
3.27,-28.89,0.190
3.28,-28.72,0.190
3.30,-28.55,0.190
3.32,-28.39,0.190
3.33,-28.22,0.190
3.35,-28.05,0.190
3.37,-27.89,0.190
3.38,-27.72,0.190
3.40,-27.55,0.190
3.42,-27.39,0.190
3.43,-27.22,0.190
3.45,-27.05,0.190
3.47,-26.88,0.190
3.48,-26.72,0.191
3.50,-26.55,0.191
3.52,-26.38,0.191
3.53,-26.22,0.191
3.55,-26.05,0.191
3.57,-25.88,0.191
3.58,-25.72,0.191
3.60,-25.55,0.191
3.62,-25.38,0.191
3.63,-25.22,0.191
3.65,-25.05,0.191
3.67,-24.88,0.191
3.68,-24.72,0.192
3.70,-24.55,0.192
3.72,-24.38,0.192
3.73,-24.21,0.192
3.75,-24.05,0.192
3.77,-23.88,0.192
3.78,-23.71,0.192
3.80,-23.55,0.192
3.82,-23.38,0.192
3.83,-23.21,0.192
3.85,-23.05,0.192
3.87,-22.88,0.192
3.88,-22.71,0.192
3.90,-22.55,0.192
3.92,-22.38,0.192
3.93,-22.21,0.193
3.95,-22.05,0.193
3.97,-21.88,0.193
3.98,-21.71,0.193
4.00,-21.54,0.193
4.02,-21.38,0.193
4.03,-21.21,0.193
4.05,-21.04,0.193
4.07,-20.88,0.193
4.08,-20.71,0.193
4.10,-20.54,0.193
4.12,-20.38,0.193
4.13,-20.21,0.194
4.15,-20.04,0.194
4.17,-19.88,0.194
4.18,-19.71,0.194
4.20,-19.54,0.194
4.22,-19.38,0.194
4.23,-19.21,0.194
4.25,-19.04,0.194
4.27,-18.87,0.194
4.28,-18.71,0.194
4.30,-18.54,0.194
4.32,-18.37,0.194
4.33,-18.21,0.195
4.35,-18.04,0.195
4.37,-17.87,0.195
4.38,-17.71,0.195
4.40,-17.54,0.195
4.42,-17.37,0.195
4.43,-17.21,0.195
4.45,-17.04,0.195
4.47,-16.87,0.195
4.48,-16.70,0.195
4.50,-16.54,0.195
4.52,-16.37,0.195
4.53,-16.21,0.195
4.55,-16.04,0.196
4.57,-15.87,0.196
4.58,-15.70,0.196
4.60,-15.54,0.196
4.62,-15.37,0.196
4.63,-15.20,0.196
4.65,-15.04,0.196
4.67,-14.87,0.196
4.68,-14.70,0.196
4.70,-14.54,0.196
4.72,-14.37,0.196
4.73,-14.20,0.197
4.75,-14.04,0.197
4.77,-13.87,0.197
4.78,-13.70,0.197
4.80,-13.54,0.197
4.82,-13.37,0.197
4.83,-13.20,0.197
4.85,-13.04,0.197
4.87,-12.87,0.197
4.88,-12.70,0.197
4.90,-12.53,0.197
4.92,-12.37,0.198
4.93,-12.20,0.198
4.95,-12.03,0.198
4.97,-11.87,0.198
4.98,-11.70,0.198
5.00,-11.53,0.198
5.02,-11.37,0.198
5.03,-11.20,0.198
5.05,-11.03,0.198
5.07,-10.87,0.198
5.08,-10.70,0.198
5.10,-10.53,0.199
5.12,-10.37,0.199
5.13,-10.20,0.199
5.15,-10.03,0.199
5.17,-9.87,0.199
5.18,-9.70,0.199
5.20,-9.53,0.199
5.22,-9.36,0.199
5.23,-9.20,0.199
5.25,-9.03,0.199
5.27,-8.86,0.199
5.28,-8.70,0.199
5.30,-8.53,0.200
5.32,-8.36,0.200
5.33,-8.20,0.200
5.35,-8.03,0.200
5.37,-7.86,0.200
5.38,-7.70,0.200
5.40,-7.53,0.200
5.42,-7.36,0.200
5.43,-7.20,0.200
5.45,-7.03,0.201
5.47,-6.86,0.201
5.48,-6.69,0.201
5.50,-6.53,0.201
5.52,-6.36,0.201
5.53,-6.20,0.201
5.55,-6.03,0.201
5.57,-5.86,0.201
5.58,-5.69,0.201
5.60,-5.53,0.201
5.62,-5.36,0.202
5.63,-5.19,0.202
5.65,-5.03,0.202
5.67,-4.86,0.202
5.68,-4.69,0.202
5.70,-4.53,0.202
5.72,-4.36,0.202
5.73,-4.19,0.202
5.75,-4.03,0.202
5.77,-3.86,0.202
5.78,-3.69,0.203
5.80,-3.53,0.203
5.82,-3.36,0.203
5.83,-3.19,0.203
5.85,-3.02,0.203
5.87,-2.86,0.203
5.88,-2.69,0.203
5.90,-2.53,0.204
5.92,-2.36,0.204
5.93,-2.19,0.204
5.95,-2.02,0.204
5.97,-1.85,0.204
5.98,-1.69,0.204
6.00,-1.52,0.204
6.02,-1.36,0.204
6.03,-1.19,0.204
6.05,-1.02,0.204
6.07,-0.85,0.204
6.08,-0.69,0.205
6.10,-0.52,0.205
6.12,-0.35,0.205
6.13,-0.19,0.205
6.15,-0.02,0.205
6.17,0.15,0.205
6.18,0.31,0.205
6.20,0.48,0.205
6.22,0.65,0.205
6.23,0.81,0.205
6.25,0.98,0.206
6.27,1.15,0.206
6.28,1.31,0.206
6.30,1.48,0.206
6.32,1.65,0.206
6.33,1.81,0.206
6.35,1.98,0.206
6.37,2.15,0.206
6.38,2.31,0.206
6.40,2.48,0.207
6.42,2.65,0.207
6.43,2.82,0.207
6.45,2.98,0.207
6.47,3.15,0.207
6.48,3.31,0.207
6.50,3.48,0.207
6.52,3.65,0.207
6.53,3.82,0.207
6.55,3.98,0.208
6.57,4.15,0.208
6.58,4.32,0.208
6.60,4.48,0.208
6.62,4.65,0.208
6.63,4.82,0.208
6.65,4.98,0.208
6.67,5.15,0.208
6.68,5.32,0.209
6.70,5.49,0.209
6.72,5.65,0.209
6.73,5.82,0.209
6.75,5.99,0.209
6.77,6.15,0.209
6.78,6.32,0.209
6.80,6.49,0.209
6.82,6.65,0.210
6.83,6.82,0.210
6.85,6.99,0.210
6.87,7.15,0.210
6.88,7.32,0.210
6.90,7.49,0.210
6.92,7.65,0.210
6.93,7.82,0.210
6.95,7.99,0.211
6.97,8.15,0.211
6.98,8.32,0.211
7.00,8.49,0.211
7.02,8.66,0.211
7.03,8.82,0.211
7.05,8.99,0.211
7.07,9.16,0.212
7.08,9.32,0.212
7.10,9.49,0.212
7.12,9.66,0.212
7.13,9.82,0.212
7.15,9.99,0.212
7.17,10.16,0.212
7.18,10.32,0.212
7.20,10.49,0.213
7.22,10.66,0.213
7.23,10.82,0.213
7.25,10.99,0.213
7.27,11.16,0.213
7.28,11.32,0.213
7.30,11.49,0.213
7.32,11.66,0.213
7.33,11.82,0.214
7.35,11.99,0.214
7.37,12.16,0.214
7.38,12.32,0.214
7.40,12.49,0.214
7.42,12.66,0.214
7.43,12.83,0.214
7.45,12.99,0.214
7.47,13.16,0.214
7.48,13.33,0.215
7.50,13.49,0.215
7.52,13.66,0.215
7.53,13.83,0.215
7.55,13.99,0.215
7.57,14.16,0.215
7.58,14.33,0.215
7.60,14.49,0.215
7.62,14.66,0.216
7.63,14.83,0.216
7.65,14.99,0.216
7.67,15.16,0.216
7.68,15.33,0.216
7.70,15.49,0.216
7.72,15.66,0.216
7.73,15.83,0.216
7.75,16.00,0.216
7.77,16.16,0.216
7.78,16.33,0.217
7.80,16.50,0.217
7.82,16.66,0.217
7.83,16.83,0.217
7.85,17.00,0.217
7.87,17.16,0.217
7.88,17.33,0.217
7.90,17.50,0.218
7.92,17.66,0.218
7.93,17.83,0.218
7.95,18.00,0.218
7.97,18.17,0.218
7.98,18.33,0.218
8.00,18.50,0.218
8.02,18.67,0.219
8.03,18.83,0.219
8.05,19.00,0.219
8.07,19.16,0.219
8.08,19.33,0.219
8.10,19.50,0.219
8.12,19.67,0.219
8.13,19.83,0.219
8.15,20.00,0.220
8.17,20.17,0.220
8.18,20.33,0.220
8.20,20.50,0.220
8.22,20.67,0.220
8.23,20.83,0.220
8.25,21.00,0.220
8.27,21.17,0.221
8.28,21.33,0.221
8.30,21.50,0.221
8.32,21.67,0.221
8.33,21.83,0.221
8.35,22.00,0.221
8.37,22.17,0.221
8.38,22.33,0.222
8.40,22.50,0.222
8.42,22.67,0.222
8.43,22.84,0.222
8.45,23.00,0.222
8.47,23.17,0.222
8.48,23.34,0.222
8.50,23.50,0.222
8.52,23.67,0.223
8.53,23.84,0.223
8.55,24.00,0.223
8.57,24.17,0.223
8.58,24.34,0.223
8.60,24.50,0.223
8.62,24.67,0.223
8.63,24.84,0.224
8.65,25.00,0.224
8.67,25.17,0.224
8.68,25.34,0.224
8.70,25.50,0.224
8.72,25.67,0.224
8.73,25.84,0.224
8.75,26.00,0.224
8.77,26.17,0.225
8.78,26.34,0.225
8.80,26.51,0.225
8.82,26.67,0.225
8.83,26.84,0.225
8.85,27.01,0.225
8.87,27.17,0.225
8.88,27.34,0.226
8.90,27.50,0.226
8.92,27.67,0.226
8.93,27.84,0.226
8.95,28.01,0.226
8.97,28.17,0.226
8.98,28.34,0.226
9.00,28.51,0.226
9.02,28.67,0.227
9.03,28.84,0.227
9.05,29.01,0.227
9.07,29.17,0.227
9.08,29.34,0.227
9.10,29.51,0.227
9.12,29.67,0.227
9.13,29.84,0.228
9.15,30.01,0.228
9.17,30.17,0.228
9.18,30.34,0.228
9.20,30.51,0.228
9.22,30.68,0.228
9.23,30.84,0.228
9.25,31.01,0.229
9.27,31.18,0.229
9.28,31.34,0.229
9.30,31.51,0.229
9.32,31.68,0.229
9.33,31.84,0.229
9.35,32.01,0.229
9.37,32.18,0.230
9.38,32.34,0.230
9.40,32.51,0.230
9.42,32.68,0.230
9.43,32.84,0.230
9.45,33.01,0.230
9.47,33.18,0.230
9.48,33.34,0.230
9.50,33.51,0.231
9.52,33.68,0.231
9.53,33.85,0.231
9.55,34.01,0.231
9.57,34.18,0.231
9.58,34.35,0.231
9.60,34.51,0.231
9.62,34.68,0.231
9.63,34.85,0.232
9.65,35.01,0.232
9.67,35.18,0.232
9.68,35.35,0.232
9.70,35.51,0.232
9.72,35.68,0.232
9.73,35.85,0.232
9.75,36.01,0.232
9.77,36.18,0.233
9.78,36.35,0.233
9.80,36.51,0.233
9.82,36.68,0.233
9.83,36.85,0.233
9.85,37.01,0.233
9.87,37.18,0.233
9.88,37.35,0.233
9.90,37.51,0.234
9.92,37.68,0.234
9.93,37.85,0.234
9.95,38.02,0.234
9.97,38.18,0.234
9.98,38.35,0.234
10.00,38.52,0.234
10.02,38.68,0.234
10.03,38.85,0.235
10.05,39.02,0.235
10.07,39.18,0.235
10.08,39.35,0.235
10.10,39.52,0.235
10.12,39.68,0.235
10.13,39.85,0.235
10.15,40.02,0.236
10.17,40.18,0.236
10.18,40.35,0.236
10.20,40.52,0.236
10.22,40.68,0.236
10.23,40.85,0.236
10.25,41.02,0.236
10.27,41.19,0.236
10.28,41.35,0.236
10.30,41.52,0.237
10.32,41.69,0.237
10.33,41.85,0.237
10.35,42.02,0.237
10.37,42.19,0.237
10.38,42.35,0.237
10.40,42.52,0.237
10.42,42.69,0.238
10.43,42.85,0.238
10.45,43.02,0.238
10.47,43.19,0.238
10.48,43.35,0.238
10.50,43.52,0.238
10.52,43.69,0.238
10.53,43.86,0.238
10.55,44.02,0.239
10.57,44.19,0.239
10.58,44.36,0.239
10.60,44.52,0.239
10.62,44.69,0.239
10.63,44.85,0.239
10.65,45.02,0.239
10.67,45.19,0.239
10.68,45.36,0.240
10.70,45.52,0.240
10.72,45.69,0.240
10.73,45.86,0.240
10.75,46.02,0.240
10.77,46.19,0.240
10.78,46.36,0.240
10.80,46.52,0.241
10.82,46.69,0.241
10.83,46.86,0.241
10.85,47.02,0.241
10.87,47.19,0.241
10.88,47.36,0.241
10.90,47.53,0.241
10.92,47.69,0.241
10.93,47.86,0.242
10.95,48.02,0.242
10.97,48.19,0.242
10.98,48.36,0.242
11.00,48.53,0.242
11.02,48.69,0.242
11.03,48.86,0.242
11.05,49.03,0.242
11.07,49.19,0.243
11.08,49.36,0.243
11.10,49.53,0.243
11.12,49.69,0.243
11.13,49.86,0.243
11.15,50.03,0.243
11.17,50.19,0.243
11.18,50.36,0.244
11.20,50.53,0.244
11.22,50.70,0.244
11.23,50.86,0.244
11.25,51.03,0.244
11.27,51.20,0.244
11.28,51.36,0.244
11.30,51.53,0.244
11.32,51.70,0.245
11.33,51.86,0.245
11.35,52.03,0.245
11.37,52.20,0.245
11.38,52.36,0.245
11.40,52.53,0.245
11.42,52.70,0.245
11.43,52.86,0.245
11.45,53.03,0.246
11.47,53.20,0.246
11.48,53.36,0.246
11.50,53.53,0.246
11.52,53.70,0.246
11.53,53.87,0.246
11.55,54.03,0.246
11.57,54.20,0.246
11.58,54.37,0.247
11.60,54.53,0.247
11.62,54.70,0.247
11.63,54.87,0.247
11.65,55.03,0.247
11.67,55.20,0.247
11.68,55.37,0.247
11.70,55.53,0.247
11.72,55.70,0.248
11.73,55.87,0.248
11.75,56.03,0.248
11.77,56.20,0.248
11.78,56.37,0.248
11.80,56.53,0.248
11.82,56.70,0.248
11.83,56.87,0.248
11.85,57.03,0.249
11.87,57.20,0.249
11.88,57.37,0.249
11.90,57.53,0.249
11.92,57.70,0.249
11.93,57.87,0.249
11.95,58.03,0.250
11.97,58.20,0.250
11.98,58.37,0.250
12.00,58.54,0.250
12.02,58.70,0.250
12.03,58.87,0.250
12.05,59.04,0.250
12.07,59.20,0.250
12.08,59.37,0.251
12.10,59.54,0.251
12.12,59.70,0.251
12.13,59.87,0.251
12.15,60.04,0.251
12.17,60.20,0.251
12.18,60.37,0.251
12.20,60.54,0.251
12.22,60.70,0.252
12.23,60.87,0.252
12.25,61.04,0.252
12.27,61.20,0.252
12.28,61.37,0.252
12.30,61.54,0.252
12.32,61.70,0.252
12.33,61.87,0.253
12.35,62.04,0.253
12.37,62.21,0.253
12.38,62.37,0.253
12.40,62.54,0.253
12.42,62.71,0.253
12.43,62.87,0.253
12.45,63.04,0.253
12.47,63.21,0.254
12.48,63.37,0.254
12.50,63.54,0.254
12.52,63.71,0.254
12.53,63.87,0.254
12.55,64.04,0.254
12.57,64.21,0.254
12.58,64.37,0.254
12.60,64.54,0.255
12.62,64.71,0.255
12.63,64.87,0.255
12.65,65.04,0.255
12.67,65.21,0.255
12.68,65.37,0.255
12.70,65.54,0.255
12.72,65.71,0.255
12.73,65.88,0.256
12.75,66.04,0.256
12.77,66.21,0.256
12.78,66.37,0.256
12.80,66.54,0.256
12.82,66.71,0.256
12.83,66.87,0.256
12.85,67.04,0.256
12.87,67.21,0.257
12.88,67.38,0.257
12.90,67.54,0.257
12.92,67.71,0.257
12.93,67.88,0.257
12.95,68.04,0.257
12.97,68.21,0.257
12.98,68.38,0.257
13.00,68.54,0.258
13.02,68.71,0.258
13.03,68.88,0.258
13.05,69.04,0.258
13.07,69.21,0.258
13.08,69.38,0.258
13.10,69.54,0.258
13.12,69.71,0.258
13.13,69.88,0.259
13.15,70.04,0.259
13.17,70.21,0.259
13.18,70.38,0.259
13.20,70.54,0.259
13.22,70.71,0.259
13.23,70.88,0.259
13.25,71.05,0.259
13.27,71.21,0.260
13.28,71.38,0.260
13.30,71.54,0.260
13.32,71.71,0.260
13.33,71.88,0.260
13.35,72.05,0.260
13.37,72.21,0.260
13.38,72.38,0.261
13.40,72.55,0.261
13.42,72.71,0.261
13.43,72.88,0.261
13.45,73.05,0.261
13.47,73.21,0.261
13.48,73.38,0.261
13.50,73.55,0.261
13.52,73.72,0.262
13.53,73.88,0.262
13.55,74.05,0.262
13.57,74.22,0.262
13.58,74.38,0.262
13.60,74.55,0.262
13.62,74.72,0.262
13.63,74.88,0.263
13.65,75.05,0.263
13.67,75.22,0.263
13.68,75.38,0.263
13.70,75.55,0.263
13.72,75.72,0.263
13.73,75.88,0.263
13.75,76.05,0.263
13.77,76.22,0.264
13.78,76.38,0.264
13.80,76.55,0.264
13.82,76.72,0.264
13.83,76.88,0.264
13.85,77.05,0.264
13.87,77.22,0.264
13.88,77.38,0.264
13.90,77.55,0.265
13.92,77.72,0.265
13.93,77.88,0.265
13.95,78.05,0.265
13.97,78.22,0.265
13.98,78.38,0.265
14.00,78.55,0.265
14.02,78.72,0.265
14.03,78.89,0.266
14.05,79.05,0.266
14.07,79.22,0.266
14.08,79.39,0.266
14.10,79.55,0.266
14.12,79.72,0.266
14.13,79.89,0.266
14.15,80.05,0.266
14.17,80.22,0.267
14.18,80.39,0.267
14.20,80.55,0.267
14.22,80.72,0.267
14.23,80.89,0.267
14.25,81.05,0.267
14.27,81.22,0.267
14.28,81.39,0.267
14.30,81.55,0.268
14.32,81.72,0.268
14.33,81.89,0.268
14.35,82.05,0.268
14.37,82.22,0.268
14.38,82.39,0.268
14.40,82.55,0.268
14.42,82.72,0.268
14.43,82.89,0.269
14.45,83.06,0.269
14.47,83.22,0.269
14.48,83.39,0.269
14.50,83.56,0.269
14.52,83.72,0.269
14.53,83.89,0.269
14.55,84.06,0.269
14.57,84.22,0.269
14.58,84.39,0.270
14.60,84.55,0.270
14.62,84.72,0.270
14.63,84.89,0.270
14.65,85.06,0.270
14.67,85.22,0.270
14.68,85.39,0.270
14.70,85.56,0.270
14.72,85.72,0.270
14.73,85.89,0.271
14.75,86.06,0.271
14.77,86.23,0.271
14.78,86.39,0.271
14.80,86.56,0.271
14.82,86.73,0.271
14.83,86.89,0.271
14.85,87.06,0.271
14.87,87.23,0.271
14.88,87.39,0.272
14.90,87.56,0.272
14.92,87.73,0.272
14.93,87.89,0.272
14.95,88.06,0.272
14.97,88.23,0.272
14.98,88.39,0.272
15.00,88.56,0.272
15.02,88.73,0.272
15.03,88.89,0.272
15.05,89.06,0.273
15.07,89.23,0.273
15.08,89.39,0.273
15.10,89.56,0.273
15.12,89.73,0.273
15.13,89.89,0.273
15.15,90.06,0.273
15.17,90.23,0.273
15.18,90.40,0.273
15.20,90.56,0.274
15.22,90.73,0.274
15.23,90.89,0.274
15.25,91.06,0.274
15.27,91.23,0.274
15.28,91.39,0.274
15.30,91.56,0.274
15.32,91.73,0.275
15.33,91.90,0.275
15.35,92.06,0.275
15.37,92.23,0.275
15.38,92.40,0.275
15.40,92.56,0.275
15.42,92.73,0.275
15.43,92.90,0.275
15.45,93.06,0.275
15.47,93.23,0.276
15.48,93.40,0.276
15.50,93.56,0.276
15.52,93.73,0.276
15.53,93.90,0.276
15.55,94.06,0.276
15.57,94.23,0.276
15.58,94.40,0.276
15.60,94.56,0.277
15.62,94.73,0.277
15.63,94.90,0.277
15.65,95.06,0.277
15.67,95.23,0.277
15.68,95.40,0.277
15.70,95.56,0.277
15.72,95.73,0.277
15.73,95.90,0.278
15.75,96.07,0.278
15.77,96.23,0.278
15.78,96.40,0.278
15.80,96.57,0.278
15.82,96.73,0.278
15.83,96.90,0.278
15.85,97.07,0.278
15.87,97.23,0.279
15.88,97.40,0.279
15.90,97.57,0.279
15.92,97.73,0.279
15.93,97.90,0.279
15.95,98.07,0.279
15.97,98.23,0.279
15.98,98.40,0.279
16.00,98.57,0.280
16.02,98.73,0.280
16.03,98.90,0.280
16.05,99.07,0.280
16.07,99.23,0.280
16.08,99.40,0.280
16.10,99.57,0.280
16.12,99.74,0.280
16.13,99.90,0.281
16.15,100.07,0.281
16.17,100.24,0.281
16.18,100.40,0.281
16.20,100.57,0.281
16.22,100.74,0.281
16.23,100.90,0.281
16.25,101.07,0.282
16.27,101.24,0.282
16.28,101.40,0.282
16.30,101.57,0.282
16.32,101.74,0.282
16.33,101.90,0.282
16.35,102.07,0.282
16.37,102.24,0.282
16.38,102.40,0.283
16.40,102.57,0.283
16.42,102.74,0.283
16.43,102.90,0.283
16.45,103.07,0.283
16.47,103.24,0.283
16.48,103.40,0.283
16.50,103.57,0.283
16.52,103.74,0.283
16.53,103.90,0.284
16.55,104.07,0.284
16.57,104.24,0.284
16.58,104.41,0.284
16.60,104.57,0.284
16.62,104.74,0.284
16.63,104.91,0.284
16.65,105.07,0.284
16.67,105.24,0.285
16.68,105.41,0.285
16.70,105.57,0.285
16.72,105.74,0.285
16.73,105.91,0.285
16.75,106.07,0.285
16.77,106.24,0.285
16.78,106.41,0.285
16.80,106.57,0.286
16.82,106.74,0.286
16.83,106.91,0.286
16.85,107.07,0.286
16.87,107.24,0.286
16.88,107.41,0.286
16.90,107.57,0.286
16.92,107.74,0.286
16.93,107.91,0.287
16.95,108.07,0.287
16.97,108.24,0.287
16.98,108.41,0.287
17.00,108.58,0.287
17.02,108.74,0.287
17.03,108.91,0.287
17.05,109.07,0.287
17.07,109.24,0.288
17.08,109.41,0.288
17.10,109.58,0.288
17.12,109.74,0.288
17.13,109.91,0.288
17.15,110.08,0.288
17.17,110.24,0.288
17.18,110.41,0.288
17.20,110.58,0.289
17.22,110.74,0.289
17.23,110.91,0.289
17.25,111.08,0.289
17.27,111.24,0.289
17.28,111.41,0.289
17.30,111.58,0.289
17.32,111.74,0.289
17.33,111.91,0.290
17.35,112.08,0.290
17.37,112.25,0.290
17.38,112.41,0.290
17.40,112.58,0.290
17.42,112.74,0.290
17.43,112.91,0.290
17.45,113.08,0.290
17.47,113.25,0.291
17.48,113.41,0.291
17.50,113.58,0.291
17.52,113.74,0.291
17.53,113.91,0.291
17.55,114.08,0.291
17.57,114.24,0.291
17.58,114.41,0.291
17.60,114.58,0.292
17.62,114.75,0.292
17.63,114.91,0.292
17.65,115.08,0.292
17.67,115.25,0.292
17.68,115.41,0.292
17.70,115.58,0.292
17.72,115.75,0.292
17.73,115.91,0.293
17.75,116.08,0.293
17.77,116.25,0.293
17.78,116.41,0.293
17.80,116.58,0.293
17.82,116.75,0.293
17.83,116.91,0.293
17.85,117.08,0.294
17.87,117.25,0.294
17.88,117.41,0.294
17.90,117.58,0.294
17.92,117.75,0.294
17.93,117.91,0.294
17.95,118.08,0.294
17.97,118.25,0.294
17.98,118.41,0.295
18.00,118.58,0.295
18.02,118.75,0.295
18.03,118.91,0.295
18.05,119.08,0.295
18.07,119.25,0.295
18.08,119.41,0.295
18.10,119.58,0.295
18.12,119.75,0.296
18.13,119.92,0.296
18.15,120.08,0.296
18.17,120.25,0.296
18.18,120.42,0.296
18.20,120.58,0.296
18.22,120.75,0.297
18.23,120.92,0.297
18.25,121.08,0.297
18.27,121.25,0.297
18.28,121.42,0.297
18.30,121.58,0.297
18.32,121.75,0.297
18.33,121.92,0.298
18.35,122.08,0.298
18.37,122.25,0.298
18.38,122.42,0.298
18.40,122.58,0.298
18.42,122.75,0.298
18.43,122.92,0.298
18.45,123.08,0.299
18.47,123.25,0.299
18.48,123.42,0.299
18.50,123.58,0.299
18.52,123.75,0.299
18.53,123.92,0.299
18.55,124.08,0.299
18.57,124.25,0.300
18.58,124.42,0.300
18.60,124.58,0.300
18.62,124.75,0.300
18.63,124.92,0.300
18.65,125.09,0.301
18.67,125.25,0.301
18.68,125.42,0.301
18.70,125.59,0.301
18.72,125.75,0.301
18.73,125.92,0.301
18.75,126.09,0.302
18.77,126.25,0.302
18.78,126.42,0.302
18.80,126.58,0.302
18.82,126.75,0.302
18.83,126.92,0.303
18.85,127.08,0.303
18.87,127.25,0.303
18.88,127.42,0.303
18.90,127.58,0.303
18.92,127.75,0.304
18.93,127.92,0.304
18.95,128.09,0.304
18.97,128.25,0.305
18.98,128.42,0.305
19.00,128.59,0.305
19.02,128.75,0.305
19.03,128.92,0.306
19.05,129.08,0.306
19.07,129.25,0.307
19.08,129.42,0.307
19.10,129.59,0.308
19.12,129.75,0.308
19.13,129.92,0.309
19.15,130.09,0.309
19.17,130.25,0.310
19.18,130.42,0.310
19.20,130.59,0.311
19.22,130.75,0.312
19.23,130.92,0.313
19.25,131.08,0.314
19.27,131.25,0.315
19.28,131.42,0.316
19.30,131.58,0.318
19.32,131.75,0.319
19.33,131.92,0.321
19.35,132.08,0.323
19.37,132.25,0.325
19.38,132.41,0.326
19.40,132.58,0.329
19.42,132.75,0.330
19.43,132.91,0.333
19.45,133.08,0.335
19.47,133.24,0.339
19.48,133.41,0.342
19.50,133.58,0.344
19.52,133.74,0.347
19.53,133.91,0.351
19.55,134.07,0.354
19.57,134.24,0.358
19.58,134.40,0.362
19.60,134.57,0.366
19.62,134.73,0.371
19.63,134.90,0.377
19.65,135.07,0.382
19.67,135.23,0.386
19.68,135.39,0.394
19.70,135.56,0.401
19.72,135.72,0.407
19.73,135.89,0.415
19.75,136.05,0.423
19.77,136.21,0.433
19.78,136.38,0.442
19.80,136.54,0.451
19.82,136.70,0.461
19.83,136.87,0.472
19.85,137.03,0.485
19.87,137.19,0.496
19.88,137.35,0.509
19.90,137.52,0.522
19.92,137.68,0.537
19.93,137.84,0.550
19.95,138.00,0.566
19.97,138.16,0.582
19.98,138.32,0.598
20.00,138.48,0.614
20.02,138.64,0.631
20.03,138.80,0.646
20.05,138.96,0.662
20.07,139.12,0.679
20.08,139.28,0.694
20.10,139.44,0.705
20.12,139.60,0.719
20.13,139.76,0.732
20.15,139.92,0.750
20.17,140.08,0.758
20.18,140.24,0.765
20.20,140.41,0.786
20.22,140.57,0.809
20.23,140.73,0.816
20.25,140.89,0.824
20.27,141.05,0.834
20.28,141.21,0.849
20.30,141.37,0.869
20.32,141.53,0.896
20.33,141.69,0.914
20.35,141.85,0.926
20.37,142.01,0.946
20.38,142.17,0.960
20.40,142.33,0.981
20.42,142.49,1.003
20.43,142.64,1.022
20.45,142.80,1.043
20.47,142.96,1.067
20.48,143.12,1.092
20.50,143.28,1.129
20.52,143.43,1.151
20.53,143.59,1.176
20.55,143.74,1.186
20.57,143.90,1.198
20.58,144.06,1.221
20.60,144.22,1.252
20.62,144.37,1.315
20.63,144.52,1.376
20.65,144.67,1.435
20.67,144.82,1.489
20.68,144.96,1.539
20.70,145.11,1.580
20.72,145.26,1.608
20.73,145.41,1.683
20.75,145.54,1.828
20.77,145.68,1.828
20.78,145.83,1.820
20.80,145.98,1.821
20.82,146.13,2.008
20.83,146.26,2.114
20.85,146.39,2.119
20.87,146.55,2.045
20.88,146.71,2.027
20.90,146.86,2.224
20.92,146.99,2.301
20.93,147.15,2.143
20.95,147.32,2.039
20.97,147.50,2.005
20.98,147.68,1.982
21.00,147.85,2.088
21.02,148.01,2.020
21.03,148.20,1.811
21.05,148.40,1.726
21.07,148.59,1.700
21.08,148.78,1.619
21.10,148.98,1.502
21.12,149.18,1.422
21.13,149.38,1.338
21.15,149.59,1.236
21.17,149.79,1.138
21.18,149.99,1.071
21.20,150.20,1.002
21.22,150.40,0.941
21.23,150.59,0.877
21.25,150.79,0.823
21.27,150.99,0.780
21.28,151.18,0.735
21.30,151.37,0.700
21.32,151.55,0.672
21.33,151.74,0.640
21.35,151.92,0.612
21.37,152.10,0.590
21.38,152.28,0.566
21.40,152.46,0.547
21.42,152.64,0.529
21.43,152.82,0.516
21.45,152.99,0.503
21.47,153.17,0.489
21.48,153.34,0.476
21.50,153.52,0.466
21.52,153.69,0.455
21.53,153.86,0.446
21.55,154.03,0.438
21.57,154.20,0.430
21.58,154.37,0.421
21.60,154.55,0.414
21.62,154.72,0.408
21.63,154.89,0.403
21.65,155.06,0.397
21.67,155.23,0.392
21.68,155.40,0.388
21.70,155.56,0.384
21.72,155.73,0.380
21.73,155.90,0.378
21.75,156.07,0.373
21.77,156.24,0.372
21.78,156.41,0.368
21.80,156.58,0.365
21.82,156.74,0.362
21.83,156.91,0.359
21.85,157.08,0.358
21.87,157.25,0.355
21.88,157.42,0.352
21.90,157.59,0.350
21.92,157.75,0.348
21.93,157.92,0.346
21.95,158.09,0.344
21.97,158.26,0.343
21.98,158.42,0.341
22.00,158.59,0.339
22.02,158.76,0.337
22.03,158.93,0.335
22.05,159.10,0.334
22.07,159.26,0.333
22.08,159.43,0.332
22.10,159.60,0.331
22.12,159.77,0.330
22.13,159.93,0.328
22.15,160.10,0.326
22.17,160.27,0.325
22.18,160.43,0.324
22.20,160.60,0.323
22.22,160.77,0.321
22.23,160.94,0.320
22.25,161.10,0.319
22.27,161.27,0.318
22.28,161.44,0.317
22.30,161.60,0.316
22.32,161.77,0.316
22.33,161.94,0.315
22.35,162.11,0.314
22.37,162.27,0.314
22.38,162.44,0.313
22.40,162.61,0.311
22.42,162.77,0.311
22.43,162.94,0.310
22.45,163.11,0.309
22.47,163.28,0.308
22.48,163.44,0.308
22.50,163.61,0.308
22.52,163.78,0.308
22.53,163.94,0.307
22.55,164.11,0.307
22.57,164.28,0.307
22.58,164.44,0.307
22.60,164.61,0.306
22.62,164.78,0.305
22.63,164.95,0.304
22.65,165.11,0.304
22.67,165.28,0.303
22.68,165.45,0.302
22.70,165.62,0.302
22.72,165.78,0.302
22.73,165.95,0.302
22.75,166.12,0.302
22.77,166.28,0.301
22.78,166.45,0.301
22.80,166.62,0.301
22.82,166.78,0.301
22.83,166.95,0.301
22.85,167.12,0.301
22.87,167.28,0.300
22.88,167.45,0.300
22.90,167.62,0.300
22.92,167.78,0.300
22.93,167.95,0.299
22.95,168.12,
22.97,168.29,
22.98,168.45,
22.99,,

[step]
Ramp 10.00 °C/min to -60.00 °C
Time,Temperature,Heat Flow (Normalized)
min,°C,W/g
23.09,169.42,0.378
23.11,169.51,0.371
23.13,169.58,0.398
23.14,169.64,0.415
23.16,169.67,0.427
23.18,169.68,0.442
23.19,169.66,0.458
23.21,169.62,0.465
23.23,169.55,0.455
23.24,169.47,0.425
23.26,169.38,0.378
23.28,169.28,0.322
23.29,169.17,0.264
23.31,169.06,0.208
23.33,168.94,0.157
23.34,168.81,0.111
23.36,168.68,0.071
23.38,168.55,0.036
23.39,168.42,0.004
23.41,168.28,-0.024
23.43,168.14,-0.050
23.44,167.99,-0.073
23.46,167.85,-0.094
23.48,167.70,-0.113
23.49,167.55,-0.130
23.51,167.40,-0.146
23.53,167.24,-0.158
23.54,167.09,-0.170
23.56,166.93,-0.182
23.58,166.78,-0.190
23.59,166.62,-0.200
23.61,166.46,-0.208
23.63,166.30,-0.215
23.64,166.15,-0.221
23.66,165.99,-0.226
23.68,165.83,-0.231
23.69,165.67,-0.236
23.71,165.51,-0.241
23.73,165.34,-0.243
23.74,165.18,-0.247
23.76,165.02,-0.249
23.78,164.86,-0.252
23.79,164.70,-0.254
23.81,164.53,-0.256
23.83,164.37,-0.258
23.84,164.21,-0.260
23.86,164.04,-0.262
23.88,163.88,-0.264
23.89,163.72,-0.267
23.91,163.55,-0.268
23.93,163.39,-0.268
23.94,163.22,-0.269
23.96,163.06,-0.270
23.98,162.89,-0.270
23.99,162.73,-0.271
24.01,162.57,-0.272
24.03,162.40,-0.273
24.04,162.24,-0.273
24.06,162.07,-0.274
24.08,161.91,-0.274
24.09,161.74,-0.275
24.11,161.58,-0.275
24.13,161.41,-0.276
24.14,161.25,-0.276
24.16,161.08,-0.276
24.18,160.92,-0.277
24.19,160.75,-0.277
24.21,160.58,-0.277
24.23,160.42,-0.278
24.24,160.25,-0.278
24.26,160.09,-0.278
24.28,159.92,-0.278
24.29,159.76,-0.279
24.31,159.59,-0.279
24.33,159.43,-0.279
24.34,159.26,-0.280
24.36,159.09,-0.280
24.38,158.93,-0.280
24.39,158.76,-0.280
24.41,158.60,-0.280
24.43,158.43,-0.281
24.44,158.27,-0.281
24.46,158.10,-0.281
24.48,157.93,-0.281
24.49,157.77,-0.281
24.51,157.60,-0.282
24.53,157.44,-0.282
24.54,157.27,-0.282
24.56,157.10,-0.282
24.58,156.94,-0.282
24.59,156.77,-0.282
24.61,156.61,-0.282
24.63,156.44,-0.282
24.64,156.27,-0.283
24.66,156.11,-0.283
24.68,155.94,-0.283
24.69,155.78,-0.283
24.71,155.61,-0.283
24.73,155.44,-0.283
24.74,155.28,-0.283
24.76,155.11,-0.284
24.78,154.94,-0.284
24.79,154.78,-0.284
24.81,154.61,-0.284
24.83,154.45,-0.284
24.84,154.28,-0.284
24.86,154.11,-0.284
24.88,153.95,-0.284
24.89,153.78,-0.284
24.91,153.61,-0.284
24.93,153.45,-0.284
24.94,153.28,-0.284
24.96,153.12,-0.284
24.98,152.95,-0.284
24.99,152.78,-0.284
25.01,152.62,-0.284
25.03,152.45,-0.284
25.04,152.28,-0.284
25.06,152.12,-0.284
25.08,151.95,-0.284
25.09,151.78,-0.284
25.11,151.62,-0.284
25.13,151.45,-0.284
25.14,151.29,-0.284
25.16,151.12,-0.284
25.18,150.95,-0.284
25.19,150.79,-0.284
25.21,150.62,-0.284
25.23,150.45,-0.284
25.24,150.29,-0.284
25.26,150.12,-0.284
25.28,149.95,-0.284
25.29,149.79,-0.284
25.31,149.62,-0.284
25.33,149.45,-0.284
25.34,149.29,-0.284
25.36,149.12,-0.284
25.38,148.96,-0.284
25.39,148.79,-0.284
25.41,148.62,-0.284
25.43,148.46,-0.284
25.44,148.29,-0.284
25.46,148.12,-0.284
25.48,147.96,-0.284
25.49,147.79,-0.284
25.51,147.63,-0.284
25.53,147.46,-0.284
25.54,147.29,-0.284
25.56,147.12,-0.284
25.58,146.96,-0.284
25.59,146.79,-0.284
25.61,146.63,-0.284
25.63,146.46,-0.284
25.64,146.29,-0.284
25.66,146.13,-0.284
25.68,145.96,-0.284
25.69,145.79,-0.284
25.71,145.63,-0.284
25.73,145.46,-0.284
25.74,145.29,-0.284
25.76,145.13,-0.284
25.78,144.96,-0.284
25.79,144.80,-0.284
25.81,144.63,-0.284
25.83,144.46,-0.284
25.84,144.29,-0.284
25.86,144.13,-0.284
25.88,143.96,-0.284
25.89,143.80,-0.284
25.91,143.63,-0.283
25.93,143.46,-0.283
25.94,143.30,-0.283
25.96,143.13,-0.283
25.98,142.96,-0.283
25.99,142.80,-0.283
26.01,142.63,-0.283
26.03,142.46,-0.283
26.04,142.30,-0.283
26.06,142.13,-0.283
26.08,141.96,-0.283
26.09,141.80,-0.283
26.11,141.63,-0.283
26.13,141.47,-0.283
26.14,141.30,-0.283
26.16,141.13,-0.283
26.18,140.97,-0.283
26.19,140.80,-0.283
26.21,140.64,-0.283
26.23,140.47,-0.283
26.24,140.30,-0.283
26.26,140.13,-0.283
26.28,139.97,-0.283
26.29,139.80,-0.283
26.31,139.64,-0.283
26.33,139.47,-0.283
26.34,139.30,-0.282
26.36,139.14,-0.282
26.38,138.97,-0.282
26.39,138.80,-0.282
26.41,138.64,-0.282
26.43,138.47,-0.282
26.44,138.30,-0.282
26.46,138.14,-0.282
26.48,137.97,-0.282
26.49,137.81,-0.282
26.51,137.64,-0.282
26.53,137.47,-0.282
26.54,137.31,-0.282
26.56,137.14,-0.282
26.58,136.97,-0.282
26.59,136.81,-0.282
26.61,136.64,-0.282
26.63,136.47,-0.282
26.64,136.31,-0.282
26.66,136.14,-0.282
26.68,135.98,-0.282
26.69,135.81,-0.282
26.71,135.64,-0.282
26.73,135.47,-0.282
26.74,135.31,-0.282
26.76,135.14,-0.282
26.78,134.97,-0.282
26.79,134.81,-0.281
26.81,134.64,-0.282
26.83,134.48,-0.281
26.84,134.31,-0.281
26.86,134.14,-0.281
26.88,133.98,-0.281
26.89,133.81,-0.281
26.91,133.64,-0.281
26.93,133.48,-0.281
26.94,133.31,-0.281
26.96,133.14,-0.281
26.98,132.98,-0.281
26.99,132.81,-0.281
27.01,132.64,-0.281
27.03,132.48,-0.281
27.04,132.31,-0.281
27.06,132.15,-0.281
27.08,131.98,-0.281
27.09,131.81,-0.281
27.11,131.65,-0.281
27.13,131.48,-0.281
27.14,131.31,-0.281
27.16,131.15,-0.281
27.18,130.98,-0.281
27.19,130.81,-0.281
27.21,130.65,-0.281
27.23,130.48,-0.281
27.24,130.31,-0.281
27.26,130.15,-0.281
27.28,129.98,-0.281
27.29,129.82,-0.281
27.31,129.65,-0.281
27.33,129.48,-0.281
27.34,129.32,-0.280
27.36,129.15,-0.280
27.38,128.98,-0.280
27.39,128.82,-0.280
27.41,128.65,-0.280
27.43,128.48,-0.280
27.44,128.32,-0.280
27.46,128.15,-0.280
27.48,127.98,-0.280
27.49,127.82,-0.280
27.51,127.65,-0.280
27.53,127.48,-0.280
27.54,127.32,-0.280
27.56,127.15,-0.280
27.58,126.98,-0.280
27.59,126.82,-0.280
27.61,126.65,-0.280
27.63,126.48,-0.280
27.64,126.32,-0.280
27.66,126.15,-0.280
27.68,125.99,-0.280
27.69,125.82,-0.280
27.71,125.65,-0.280
27.73,125.49,-0.280
27.74,125.32,-0.280
27.76,125.15,-0.280
27.78,124.99,-0.280
27.79,124.82,-0.280
27.81,124.65,-0.280
27.83,124.49,-0.280
27.84,124.32,-0.279
27.86,124.15,-0.279
27.88,123.99,-0.279
27.89,123.82,-0.279
27.91,123.65,-0.279
27.93,123.49,-0.279
27.94,123.32,-0.279
27.96,123.16,-0.279
27.98,122.99,-0.279
27.99,122.82,-0.279
28.01,122.66,-0.279
28.03,122.49,-0.279
28.04,122.32,-0.279
28.06,122.16,-0.279
28.08,121.99,-0.279
28.09,121.82,-0.279
28.11,121.66,-0.279
28.13,121.49,-0.279
28.14,121.32,-0.279
28.16,121.16,-0.279
28.18,120.99,-0.279
28.19,120.82,-0.278
28.21,120.66,-0.278
28.23,120.49,-0.278
28.24,120.33,-0.278
28.26,120.16,-0.278
28.28,119.99,-0.278
28.29,119.83,-0.278
28.31,119.66,-0.278
28.33,119.49,-0.278
28.34,119.33,-0.278
28.36,119.16,-0.278
28.38,118.99,-0.278
28.39,118.83,-0.278
28.41,118.66,-0.278
28.43,118.50,-0.278
28.44,118.33,-0.278
28.46,118.16,-0.278
28.48,118.00,-0.278
28.49,117.83,-0.278
28.51,117.66,-0.278
28.53,117.50,-0.278
28.54,117.33,-0.278
28.56,117.16,-0.278
28.58,117.00,-0.278
28.59,116.83,-0.278
28.61,116.66,-0.278
28.63,116.50,-0.278
28.64,116.33,-0.278
28.66,116.16,-0.278
28.68,116.00,-0.277
28.69,115.83,-0.277
28.71,115.66,-0.277
28.73,115.50,-0.277
28.74,115.33,-0.277
28.76,115.17,-0.277
28.78,115.00,-0.277
28.79,114.83,-0.277
28.81,114.67,-0.277
28.83,114.50,-0.277
28.84,114.33,-0.277
28.86,114.17,-0.277
28.88,114.00,-0.277
28.89,113.83,-0.277
28.91,113.67,-0.277
28.93,113.50,-0.277
28.94,113.33,-0.276
28.96,113.17,-0.276
28.98,113.00,-0.276
28.99,112.84,-0.276
29.01,112.67,-0.276
29.03,112.50,-0.276
29.04,112.34,-0.276
29.06,112.17,-0.276
29.08,112.00,-0.276
29.09,111.84,-0.276
29.11,111.67,-0.276
29.13,111.50,-0.276
29.14,111.34,-0.276
29.16,111.17,-0.276
29.18,111.00,-0.276
29.19,110.84,-0.276
29.21,110.67,-0.276
29.23,110.50,-0.276
29.24,110.34,-0.276
29.26,110.17,-0.276
29.28,110.01,-0.275
29.29,109.84,-0.275
29.31,109.67,-0.275
29.33,109.51,-0.275
29.34,109.34,-0.275
29.36,109.17,-0.275
29.38,109.01,-0.275
29.39,108.84,-0.275
29.41,108.67,-0.275
29.43,108.51,-0.275
29.44,108.34,-0.275
29.46,108.17,-0.275
29.48,108.01,-0.275
29.49,107.84,-0.275
29.51,107.67,-0.275
29.53,107.51,-0.275
29.54,107.34,-0.275
29.56,107.18,-0.275
29.58,107.01,-0.275
29.59,106.84,-0.275
29.61,106.68,-0.275
29.63,106.51,-0.274
29.64,106.34,-0.274
29.66,106.18,-0.274
29.68,106.01,-0.274
29.69,105.84,-0.274
29.71,105.68,-0.274
29.73,105.51,-0.274
29.74,105.34,-0.274
29.76,105.18,-0.274
29.78,105.01,-0.274
29.79,104.84,-0.274
29.81,104.68,-0.274
29.83,104.51,-0.274
29.84,104.35,-0.274
29.86,104.18,-0.274
29.88,104.01,-0.274
29.89,103.85,-0.274
29.91,103.68,-0.273
29.93,103.51,-0.273
29.94,103.35,-0.273
29.96,103.18,-0.273
29.98,103.01,-0.273
29.99,102.85,-0.273
30.01,102.68,-0.273
30.03,102.51,-0.273
30.04,102.35,-0.273
30.06,102.18,-0.273
30.08,102.02,-0.273
30.09,101.85,-0.273
30.11,101.68,-0.273
30.13,101.52,-0.273
30.14,101.35,-0.273
30.16,101.18,-0.273
30.18,101.02,-0.273
30.19,100.85,-0.273
30.21,100.68,-0.273
30.23,100.52,-0.273
30.24,100.35,-0.272
30.26,100.18,-0.272
30.28,100.02,-0.272
30.29,99.85,-0.272
30.31,99.68,-0.272
30.33,99.52,-0.272
30.34,99.35,-0.272
30.36,99.18,-0.272
30.38,99.02,-0.272
30.39,98.85,-0.272
30.41,98.69,-0.272
30.43,98.52,-0.272
30.44,98.35,-0.272
30.46,98.19,-0.272
30.48,98.02,-0.272
[...]
96.09,-42.75,0.068
96.10,-42.69,0.068
96.11,-42.62,0.068
96.11,-42.55,0.068
96.12,-42.49,0.068
96.13,-42.42,0.068
96.13,-42.36,0.069
96.14,-42.29,0.069
96.15,-42.22,0.069
96.15,-42.16,0.069
96.16,-42.09,0.069
96.17,-42.02,0.069
96.17,-41.95,0.069
96.18,-41.89,0.069
96.19,-41.82,0.069
96.19,-41.75,0.069
96.20,-41.69,0.069
96.21,-41.62,0.069
96.21,-41.55,0.069
96.22,-41.49,0.069
96.23,-41.42,0.069
96.23,-41.35,0.069
96.24,-41.29,0.070
96.25,-41.22,0.070
96.25,-41.15,0.070
96.26,-41.09,0.070
96.27,-41.02,0.070
96.27,-40.95,0.070
96.28,-40.89,0.070
96.29,-40.82,0.070
96.29,-40.75,0.070
96.30,-40.69,0.070
96.31,-40.62,0.070
96.31,-40.55,0.070
96.32,-40.49,0.070
96.33,-40.42,0.070
96.33,-40.35,0.070
96.34,-40.29,0.070
96.35,-40.22,0.071
96.35,-40.15,0.071
96.36,-40.09,0.071
96.37,-40.02,0.071
96.37,-39.95,0.071
96.38,-39.89,0.071
96.39,-39.82,0.071
96.39,-39.75,0.071
96.40,-39.69,0.071
96.41,-39.62,0.071
96.41,-39.55,0.071
96.42,-39.49,0.071
96.43,-39.42,0.071
96.43,-39.35,0.071
96.44,-39.29,0.071
96.45,-39.22,0.071
96.45,-39.16,0.071
96.46,-39.09,0.071
96.47,-39.02,0.071
96.47,-38.95,0.071
96.48,-38.89,0.072
96.49,-38.82,0.072
96.49,-38.75,0.072
96.50,-38.69,0.072
96.51,-38.62,0.072
96.51,-38.55,0.072
96.52,-38.49,0.072
96.53,-38.42,0.072
96.53,-38.35,0.072
96.54,-38.29,0.072
96.55,-38.22,0.072
96.55,-38.15,0.072
96.56,-38.09,0.072
96.57,-38.02,0.072
96.57,-37.95,0.072
96.58,-37.89,0.072
96.59,-37.82,0.072
96.59,-37.75,0.072
96.60,-37.69,0.072
96.61,-37.62,0.072
96.61,-37.55,0.072
96.62,-37.48,0.072
96.63,-37.42,0.072
96.63,-37.35,0.072
96.64,-37.28,0.072
96.65,-37.22,0.072
96.65,-37.15,0.072
96.66,-37.08,0.072
96.67,-37.02,0.072
96.67,-36.95,0.072
96.68,-36.88,0.072
96.69,-36.82,0.073
96.69,-36.75,0.073
96.70,-36.68,0.073
96.71,-36.62,0.073
96.71,-36.55,0.073
96.72,-36.48,0.073
96.73,-36.42,0.073
96.73,-36.35,0.073
96.74,-36.28,0.073
96.75,-36.22,0.073
96.75,-36.15,0.073
96.76,-36.08,0.073
96.77,-36.01,0.073
96.77,-35.95,0.073
96.78,-35.88,0.074
96.79,-35.82,0.074
96.79,-35.75,0.074
96.80,-35.68,0.074
96.81,-35.62,0.074
96.81,-35.55,0.074
96.82,-35.48,0.074
96.83,-35.42,0.074
96.83,-35.35,0.074
96.84,-35.28,0.074
96.85,-35.22,0.074
96.85,-35.15,0.074
96.86,-35.08,0.074
96.87,-35.02,0.074
96.87,-34.95,0.074
96.88,-34.88,0.074
96.89,-34.82,0.074
96.89,-34.75,0.074
96.90,-34.68,0.074
96.91,-34.61,0.074
96.91,-34.55,0.074
96.92,-34.48,0.074
96.93,-34.41,0.074
96.93,-34.35,0.074
96.94,-34.28,0.074
96.95,-34.22,0.074
96.95,-34.15,0.074
96.96,-34.08,0.075
96.97,-34.01,0.075
96.97,-33.95,0.075
96.98,-33.88,0.075
96.99,-33.81,0.075
96.99,-33.75,0.075
97.00,-33.68,0.075
97.01,-33.61,0.075
97.01,-33.55,0.075
97.02,-33.48,0.075
97.03,-33.41,0.075
97.03,-33.35,0.075
97.04,-33.28,0.075
97.05,-33.21,0.075
97.05,-33.15,0.075
97.06,-33.08,0.075
97.07,-33.01,0.075
97.07,-32.95,0.075
97.08,-32.88,0.075
97.09,-32.81,0.075
97.09,-32.75,0.075
97.10,-32.68,0.075
97.11,-32.61,0.075
97.11,-32.55,0.075
97.12,-32.48,0.075
97.13,-32.41,0.075
97.13,-32.35,0.075
97.14,-32.28,0.075
97.15,-32.21,0.075
97.15,-32.15,0.075
97.16,-32.08,0.075
97.17,-32.01,0.075
97.17,-31.94,0.075
97.18,-31.88,0.076
97.19,-31.81,0.076
97.19,-31.75,0.076
97.20,-31.68,0.076
97.21,-31.61,0.076
97.21,-31.55,0.076
97.22,-31.48,0.076
97.23,-31.41,0.076
97.23,-31.35,0.076
97.24,-31.28,0.076
97.25,-31.21,0.076
97.25,-31.15,0.076
97.26,-31.08,0.076
97.27,-31.01,0.076
97.27,-30.95,0.076
97.28,-30.88,0.076
97.29,-30.81,0.076
97.29,-30.74,0.076
97.30,-30.68,0.076
97.31,-30.61,0.076
97.31,-30.54,0.076
97.32,-30.48,0.076
97.33,-30.41,0.076
97.33,-30.34,0.076
97.34,-30.28,0.076
97.35,-30.21,0.076
97.35,-30.14,0.076
97.36,-30.08,0.077
97.37,-30.01,0.077
97.37,-29.94,0.077
97.38,-29.88,0.077
97.39,-29.81,0.077
97.39,-29.74,0.077
97.40,-29.68,0.077
97.41,-29.61,0.077
97.41,-29.54,0.077
97.42,-29.48,0.077
97.43,-29.41,0.077
97.43,-29.34,0.077
97.44,-29.28,0.077
97.45,-29.21,0.077
97.45,-29.14,0.077
97.46,-29.08,0.077
97.47,-29.01,0.077
97.47,-28.94,0.077
97.48,-28.88,0.077
97.49,-28.81,0.077
97.49,-28.74,0.077
97.50,-28.68,0.077
97.51,-28.61,0.077
97.51,-28.54,0.077
97.52,-28.47,0.077
97.53,-28.41,0.077
97.53,-28.34,0.077
97.54,-28.28,0.077
97.55,-28.21,0.077
97.55,-28.14,0.077
97.56,-28.07,0.077
97.57,-28.01,0.077
97.57,-27.94,0.078
97.58,-27.87,0.078
97.59,-27.81,0.078
97.59,-27.74,0.078
97.60,-27.68,0.078
97.61,-27.61,0.078
97.61,-27.54,0.078
97.62,-27.47,0.078
97.63,-27.41,0.078
97.63,-27.34,0.078
97.64,-27.27,0.078
97.65,-27.21,0.078
97.65,-27.14,0.078
97.66,-27.08,0.078
97.67,-27.01,0.078
97.67,-26.94,0.078
97.68,-26.87,0.078
97.69,-26.81,0.078
97.69,-26.74,0.078
97.70,-26.68,0.078
97.71,-26.61,0.078
97.71,-26.54,0.078
97.72,-26.47,0.078
97.73,-26.41,0.078
97.73,-26.34,0.078
97.74,-26.27,0.078
97.75,-26.21,0.078
97.75,-26.14,0.078
97.76,-26.07,0.078
97.77,-26.01,0.078
97.77,-25.94,0.078
97.78,-25.87,0.078
97.79,-25.80,0.078
97.79,-25.74,0.078
97.80,-25.67,0.079
97.81,-25.60,0.079
97.81,-25.54,0.079
97.82,-25.47,0.079
97.83,-25.40,0.079
97.83,-25.34,0.079
97.84,-25.27,0.079
97.85,-25.20,0.079
97.85,-25.14,0.079
97.86,-25.07,0.079
97.87,-25.00,0.079
97.87,-24.94,0.079
97.88,-24.87,0.079
97.89,-24.80,0.079
97.89,-24.74,0.079
97.90,-24.67,0.079
97.91,-24.60,0.079
97.91,-24.54,0.079
97.92,-24.47,0.079
97.93,-24.40,0.079
97.93,-24.34,0.080
97.94,-24.27,0.080
97.95,-24.20,0.080
97.95,-24.14,0.080
97.96,-24.07,0.080
97.97,-24.00,0.080
97.97,-23.94,0.080
97.98,-23.87,0.080
97.99,-23.80,0.080
97.99,-23.74,0.080
98.00,-23.67,0.080
98.01,-23.60,0.080
98.01,-23.54,0.080
98.02,-23.47,0.080
98.03,-23.40,0.080
98.03,-23.34,0.080
98.04,-23.27,0.080
98.05,-23.20,0.080
98.05,-23.14,0.080
98.06,-23.07,0.080
98.07,-23.00,0.080
98.07,-22.94,0.080
98.08,-22.87,0.080
98.09,-22.80,0.080
98.09,-22.74,0.080
98.10,-22.67,0.080
98.11,-22.60,0.080
98.11,-22.54,0.080
98.12,-22.47,0.080
98.13,-22.40,0.080
98.13,-22.34,0.080
98.14,-22.27,0.080
98.15,-22.20,0.080
98.15,-22.14,0.080
98.16,-22.07,0.080
98.17,-22.00,0.080
98.17,-21.94,0.080
98.18,-21.87,0.081
98.19,-21.80,0.081
98.19,-21.74,0.081
98.20,-21.67,0.081
98.21,-21.60,0.081
98.21,-21.54,0.081
98.22,-21.47,0.081
98.23,-21.40,0.081
98.23,-21.34,0.081
98.24,-21.27,0.081
98.25,-21.20,0.081
98.25,-21.14,0.081
98.26,-21.07,0.081
98.27,-21.00,0.081
98.27,-20.94,0.081
98.28,-20.87,0.081
98.29,-20.80,0.081
98.29,-20.74,0.081
98.30,-20.67,0.081
98.31,-20.60,0.081
98.31,-20.53,0.081
98.32,-20.47,0.081
98.33,-20.40,0.081
98.33,-20.34,0.081
98.34,-20.27,0.081
98.35,-20.20,0.081
98.35,-20.13,0.081
98.36,-20.07,0.081
98.37,-20.00,0.081
98.37,-19.93,0.081
98.38,-19.87,0.081
98.39,-19.80,0.081
98.39,-19.73,0.081
98.40,-19.67,0.081
98.41,-19.60,0.081
98.41,-19.53,0.082
98.42,-19.47,0.082
98.43,-19.40,0.082
98.43,-19.33,0.082
98.44,-19.27,0.082
98.45,-19.20,0.082
98.45,-19.13,0.082
98.46,-19.07,0.082
98.47,-19.00,0.082
98.47,-18.93,0.082
98.48,-18.87,0.082
98.49,-18.80,0.082
98.49,-18.73,0.082
98.50,-18.67,0.082
98.51,-18.60,0.082
98.51,-18.53,0.082
98.52,-18.46,0.082
98.53,-18.40,0.082
98.53,-18.33,0.082
98.54,-18.27,0.082
98.55,-18.20,0.082
98.55,-18.13,0.083
98.56,-18.06,0.083
98.57,-18.00,0.083
98.57,-17.93,0.083
98.58,-17.86,0.083
98.59,-17.80,0.083
98.59,-17.73,0.083
98.60,-17.66,0.083
98.61,-17.60,0.083
98.61,-17.53,0.083
98.62,-17.46,0.083
98.63,-17.40,0.083
98.63,-17.33,0.083
98.64,-17.26,0.083
98.65,-17.20,0.083
98.65,-17.13,0.083
98.66,-17.06,0.083
98.67,-17.00,0.083
98.67,-16.93,0.083
98.68,-16.86,0.083
98.69,-16.80,0.083
98.69,-16.73,0.083
98.70,-16.66,0.083
98.71,-16.60,0.083
98.71,-16.53,0.083
98.72,-16.46,0.083
98.73,-16.40,0.083
98.73,-16.33,0.083
98.74,-16.26,0.084
98.75,-16.20,0.084
98.75,-16.13,0.084
98.76,-16.06,0.084
98.77,-16.00,0.084
98.77,-15.93,0.084
98.78,-15.86,0.084
98.79,-15.80,0.084
98.79,-15.73,0.084
98.80,-15.66,0.084
98.81,-15.60,0.084
98.81,-15.53,0.084
98.82,-15.46,0.084
98.83,-15.40,0.084
98.83,-15.33,0.084
98.84,-15.26,0.084
98.85,-15.19,0.084
98.85,-15.13,0.084
98.86,-15.06,0.084
98.87,-15.00,0.084
98.87,-14.93,0.084
98.88,-14.86,0.084
98.89,-14.79,0.084
98.89,-14.73,0.084
98.90,-14.66,0.084
98.91,-14.59,0.084
98.91,-14.53,0.084
98.92,-14.46,0.084
98.93,-14.39,0.084
98.93,-14.33,0.084
98.94,-14.26,0.084
98.95,-14.19,0.085
98.95,-14.13,0.085
98.96,-14.06,0.085
98.97,-13.99,0.085
98.97,-13.93,0.085
98.98,-13.86,0.085
98.99,-13.79,0.085
98.99,-13.73,0.085
99.00,-13.66,0.085
99.01,-13.59,0.085
99.01,-13.53,0.085
99.02,-13.46,0.085
99.03,-13.39,0.085
99.03,-13.33,0.085
99.04,-13.26,0.085
99.05,-13.19,0.085
99.05,-13.13,0.085
99.06,-13.06,0.085
99.07,-12.99,0.085
99.07,-12.93,0.085
99.08,-12.86,0.085
99.09,-12.79,0.085
99.09,-12.73,0.085
99.10,-12.66,0.085
99.11,-12.59,0.085
99.11,-12.53,0.085
99.12,-12.46,0.085
99.13,-12.39,0.085
99.13,-12.33,0.085
99.14,-12.26,0.085
99.15,-12.19,0.086
99.15,-12.13,0.086
99.16,-12.06,0.086
99.17,-11.99,0.086
99.17,-11.93,0.086
99.18,-11.86,0.086
99.19,-11.79,0.086
99.19,-11.73,0.086
99.20,-11.66,0.086
99.21,-11.59,0.086
99.21,-11.53,0.086
99.22,-11.46,0.086
99.23,-11.39,0.086
99.23,-11.32,0.086
99.24,-11.26,0.086
99.25,-11.19,0.086
99.25,-11.13,0.086
99.26,-11.06,0.086
99.27,-10.99,0.086
99.27,-10.92,0.086
99.28,-10.86,0.086
99.29,-10.79,0.086
99.29,-10.72,0.086
99.30,-10.66,0.086
99.31,-10.59,0.086
99.31,-10.52,0.086
99.32,-10.46,0.086
99.33,-10.39,0.086
99.33,-10.32,0.086
99.34,-10.26,0.086
99.35,-10.19,0.086
99.35,-10.12,0.087
99.36,-10.06,0.087
99.37,-9.99,0.087
99.37,-9.92,0.087
99.38,-9.86,0.087
99.39,-9.79,0.087
99.39,-9.72,0.087
99.40,-9.66,0.087
99.41,-9.59,0.087
99.41,-9.52,0.087
99.42,-9.46,0.087
99.43,-9.39,0.087
99.43,-9.32,0.087
99.44,-9.26,0.087
99.45,-9.19,0.087
99.45,-9.12,0.087
99.46,-9.06,0.087
99.47,-8.99,0.087
99.47,-8.92,0.087
99.48,-8.86,0.087
99.49,-8.79,0.087
99.49,-8.72,0.087
99.50,-8.65,0.087
99.51,-8.59,0.087
99.51,-8.52,0.087
99.52,-8.46,0.087
99.53,-8.39,0.088
99.53,-8.32,0.088
99.54,-8.25,0.088
99.55,-8.19,0.088
99.55,-8.12,0.088
99.56,-8.05,0.088
99.57,-7.99,0.088
99.57,-7.92,0.088
99.58,-7.85,0.088
99.59,-7.79,0.088
99.59,-7.72,0.088
99.60,-7.65,0.088
99.61,-7.59,0.088
99.61,-7.52,0.088
99.62,-7.45,0.088
99.63,-7.39,0.088
99.63,-7.32,0.088
99.64,-7.25,0.088
99.65,-7.19,0.088
99.65,-7.12,0.088
99.66,-7.05,0.088
99.67,-6.99,0.088
99.67,-6.92,0.088
99.68,-6.86,0.088
99.69,-6.79,0.089
99.69,-6.72,0.089
99.70,-6.65,0.089
99.71,-6.59,0.089
99.71,-6.52,0.089
99.72,-6.45,0.089
99.73,-6.39,0.089
99.73,-6.32,0.089
99.74,-6.25,0.089
99.75,-6.19,0.089
99.75,-6.12,0.089
99.76,-6.05,0.089
99.77,-5.99,0.089
99.77,-5.92,0.089
99.78,-5.85,0.089
99.79,-5.79,0.089
99.79,-5.72,0.089
99.80,-5.65,0.089
99.81,-5.59,0.089
99.81,-5.52,0.089
99.82,-5.45,0.089
99.83,-5.39,0.090
99.83,-5.32,0.090
99.84,-5.25,0.090
99.85,-5.19,0.090
99.85,-5.12,0.090
99.86,-5.05,0.090
99.87,-4.99,0.090
99.87,-4.92,0.090
99.88,-4.85,0.090
99.89,-4.79,0.090
99.89,-4.72,0.090
99.90,-4.65,0.090
99.91,-4.59,0.090
99.91,-4.52,0.090
99.92,-4.45,0.090
99.93,-4.38,0.090
99.93,-4.32,0.090
99.94,-4.25,0.090
99.95,-4.19,0.090
99.95,-4.12,0.091
99.96,-4.05,0.091
99.97,-3.99,0.091
99.97,-3.92,0.091
99.98,-3.85,0.091
99.99,-3.79,0.091
99.99,-3.72,0.091
100.00,-3.65,0.091
100.01,-3.58,0.091
100.01,-3.52,0.091
100.02,-3.45,0.091
100.03,-3.39,0.091
100.03,-3.32,0.091
100.04,-3.25,0.091
100.05,-3.18,0.091
100.05,-3.12,0.091
100.06,-3.05,0.091
100.07,-2.98,0.091
100.07,-2.92,0.091
100.08,-2.85,0.091
100.09,-2.78,0.091
100.09,-2.72,0.091
100.10,-2.65,0.091
100.11,-2.58,0.091
100.11,-2.52,0.091
100.12,-2.45,0.091
100.13,-2.38,0.092
100.13,-2.32,0.092
100.14,-2.25,0.092
100.15,-2.18,0.092
100.15,-2.12,0.092
100.16,-2.05,0.092
100.17,-1.98,0.092
100.17,-1.92,0.092
100.18,-1.85,0.092
100.19,-1.78,0.092
100.19,-1.72,0.092
100.20,-1.65,0.092
100.21,-1.58,0.092
100.21,-1.52,0.092
100.22,-1.45,0.092
100.23,-1.38,0.092
100.23,-1.32,0.093
100.24,-1.25,0.093
100.25,-1.18,0.093
100.25,-1.12,0.093
100.26,-1.05,0.093
100.27,-0.98,0.093
100.27,-0.91,0.093
100.28,-0.85,0.093
100.29,-0.78,0.093
100.29,-0.72,0.093
100.30,-0.65,0.093
100.31,-0.58,0.093
100.31,-0.52,0.093
100.32,-0.45,0.093
100.33,-0.38,0.093
100.33,-0.31,0.093
100.34,-0.25,0.093
100.35,-0.18,0.093
100.35,-0.12,0.093
100.36,-0.05,0.093
100.37,0.02,0.093
100.37,0.09,0.093
100.38,0.15,0.093
100.39,0.22,0.093
100.39,0.29,0.093
100.40,0.35,0.094
100.41,0.42,0.094
100.41,0.49,0.094
100.42,0.55,0.094
100.43,0.62,0.094
100.43,0.68,0.094
100.44,0.75,0.094
100.45,0.82,0.094
100.45,0.89,0.094
100.46,0.95,0.094
100.47,1.02,0.094
100.47,1.09,0.094
100.48,1.15,0.094
100.49,1.22,0.094
100.49,1.29,0.094
100.50,1.35,0.094
100.51,1.42,0.094
100.51,1.49,0.094
100.52,1.55,0.094
100.53,1.62,0.094
100.53,1.69,0.095
100.54,1.75,0.095
100.55,1.82,0.095
100.55,1.89,0.095
100.56,1.95,0.095
100.57,2.02,0.095
100.57,2.09,0.095
100.58,2.15,0.095
100.59,2.22,0.095
100.59,2.29,0.095
100.60,2.35,0.095
100.61,2.42,0.095
100.61,2.49,0.095
100.62,2.55,0.095
100.63,2.62,0.095
100.63,2.69,0.095
100.64,2.75,0.095
100.65,2.82,0.095
100.65,2.89,0.095
100.66,2.96,0.095
100.67,3.02,0.095
100.67,3.09,0.096
100.68,3.16,0.096
100.69,3.22,0.096
100.69,3.29,0.096
100.70,3.36,0.096
100.71,3.42,0.096
100.71,3.49,0.096
100.72,3.55,0.096
100.73,3.62,0.096
100.73,3.69,0.096
100.74,3.75,0.096
100.75,3.82,0.096
100.75,3.89,0.096
100.76,3.95,0.096
100.77,4.02,0.096
100.77,4.09,0.096
100.78,4.15,0.097
100.79,4.22,0.097
100.79,4.29,0.097
100.80,4.36,0.097
100.81,4.42,0.097
100.81,4.49,0.097
100.82,4.55,0.097
100.83,4.62,0.097
100.83,4.69,0.097
100.84,4.76,0.097
100.85,4.82,0.097
100.85,4.89,0.097
100.86,4.96,0.097
100.87,5.02,0.097
100.87,5.09,0.097
100.88,5.16,0.097
100.89,5.22,0.097
100.89,5.29,0.097
100.90,5.36,0.097
100.91,5.42,0.097
100.91,5.49,0.098
100.92,5.56,0.098
100.93,5.62,0.098
100.93,5.69,0.098
100.94,5.76,0.098
100.95,5.82,0.098
100.95,5.89,0.098
100.96,5.96,0.098
100.97,6.02,0.098
100.97,6.09,0.098
100.98,6.16,0.098
100.99,6.22,0.098
100.99,6.29,0.098
101.00,6.36,0.098
101.01,6.42,0.098
101.01,6.49,0.099
101.02,6.56,0.099
101.03,6.62,0.099
101.03,6.69,0.099
101.04,6.76,0.099
101.05,6.82,0.099
101.05,6.89,0.099
101.06,6.96,0.099
101.07,7.03,0.100
101.07,7.09,0.100
101.08,7.16,0.100
101.09,7.22,0.100
101.09,7.29,0.100
101.10,7.36,0.100
101.11,7.43,0.100
101.11,7.49,0.100
101.12,7.56,0.100
101.13,7.62,0.100
101.13,7.69,0.100
101.14,7.76,0.101
101.15,7.83,0.101
101.15,7.89,0.101
101.16,7.96,0.101
101.17,8.03,0.101
101.17,8.09,0.101
101.18,8.16,0.101
101.19,8.23,0.101
101.19,8.29,0.101
101.20,8.36,0.101
101.21,8.43,0.101
101.21,8.49,0.101
101.22,8.56,0.101
101.23,8.63,0.102
101.23,8.69,0.102
101.24,8.76,0.102
101.25,8.83,0.102
101.25,8.89,0.102
101.26,8.96,0.102
101.27,9.03,0.102
101.27,9.09,0.102
101.28,9.16,0.102
101.29,9.23,0.102
101.29,9.29,0.102
101.30,9.36,0.103
101.31,9.43,0.103
101.31,9.49,0.103
101.32,9.56,0.103
101.33,9.63,0.103
101.33,9.69,0.103
101.34,9.76,0.103
101.35,9.82,0.103
101.35,9.89,0.103
101.36,9.96,0.104
101.37,10.03,0.104
101.37,10.09,0.104
101.38,10.16,0.104
101.39,10.23,0.104
101.39,10.29,0.104
101.40,10.36,0.104
101.41,10.43,0.104
101.41,10.49,0.104
101.42,10.56,0.104
101.43,10.63,0.105
101.43,10.69,0.105
101.44,10.76,0.105
101.45,10.83,0.106
101.45,10.89,0.106
101.46,10.96,0.106
101.47,11.03,0.106
101.47,11.09,0.106
101.48,11.16,0.106
101.49,11.23,0.106
101.49,11.29,0.106
101.50,11.36,0.107
101.51,11.43,0.107
101.51,11.49,0.107
101.52,11.56,0.107
101.53,11.62,0.107
101.53,11.69,0.107
101.54,11.76,0.107
101.55,11.83,0.107
101.55,11.89,0.107
101.56,11.96,0.107
101.57,12.02,0.108
101.57,12.09,0.108
101.58,12.16,0.108
101.59,12.23,0.109
101.59,12.29,0.109
101.60,12.36,0.109
101.61,12.43,0.109
101.61,12.49,0.110
101.62,12.56,0.110
101.63,12.63,0.111
101.63,12.69,0.111
101.64,12.76,0.111
101.65,12.83,0.111
101.65,12.89,0.111
101.66,12.96,0.111
101.67,13.03,0.111
101.67,13.09,0.111
101.68,13.16,0.111
101.69,13.23,0.112
101.69,13.29,0.112
101.70,13.36,0.112
101.71,13.43,0.112
101.71,13.49,0.112
101.72,13.56,0.112
101.73,13.63,0.113
101.73,13.69,0.113
101.74,13.76,0.113
101.75,13.83,0.114
101.75,13.89,0.114
101.76,13.96,0.114
101.77,14.03,0.115
101.77,14.09,0.115
101.78,14.16,0.115
101.79,14.22,0.115
101.79,14.29,0.116
101.80,14.36,0.116
101.81,14.42,0.116
101.81,14.49,0.117
101.82,14.56,0.117
101.83,14.62,0.117
101.83,14.69,0.117
101.84,14.76,0.118
101.85,14.82,0.118
101.85,14.89,0.119
101.86,14.96,0.119
101.87,15.02,0.119
101.87,15.09,0.119
101.88,15.16,0.119
101.89,15.22,0.119
101.89,15.29,0.120
101.90,15.36,0.120
101.91,15.42,0.120
101.91,15.49,0.121
101.92,15.56,0.121
101.93,15.62,0.122
101.93,15.69,0.122
101.94,15.76,0.123
101.95,15.82,0.123
101.95,15.89,0.123
101.96,15.96,0.124
101.97,16.02,0.124
101.97,16.09,0.125
101.98,16.16,0.125
101.99,16.22,0.126
101.99,16.29,0.126
102.00,16.36,0.127
102.01,16.42,0.127
102.01,16.49,0.127
102.02,16.55,0.128
102.03,16.62,0.128
102.03,16.69,0.129
102.04,16.76,0.129
102.05,16.82,0.131
102.05,16.89,0.132
102.06,16.96,0.132
102.07,17.02,0.133
102.07,17.09,0.134
102.08,17.15,0.134
102.09,17.22,0.135
102.09,17.29,0.135
102.10,17.35,0.135
102.11,17.42,0.136
102.11,17.49,0.136
102.12,17.55,0.136
102.13,17.62,0.137
102.13,17.69,0.137
102.14,17.75,0.138
102.15,17.82,0.139
102.15,17.89,0.139
102.16,17.95,0.140
102.17,18.02,0.140
102.17,18.09,0.141
102.18,18.15,0.141
102.19,18.22,0.142
102.19,18.28,0.142
102.20,18.35,0.143
102.21,18.42,0.143
102.21,18.49,0.144
102.22,18.55,0.145
102.23,18.62,0.145
102.23,18.68,0.146
102.24,18.75,0.146
102.25,18.82,0.146
102.25,18.88,0.146
102.26,18.95,0.147
102.27,19.02,0.147
102.27,19.08,0.148
102.28,19.15,0.148
102.29,19.22,0.148
102.29,19.28,0.149
102.30,19.35,0.149
102.31,19.42,0.149
102.31,19.48,0.150
102.32,19.55,0.150
102.33,19.62,0.150
102.33,19.68,0.150
102.34,19.75,0.151
102.35,19.81,0.151
102.35,19.88,0.151
102.36,19.95,0.152
102.37,20.01,0.152
102.37,20.08,0.152
102.38,20.15,0.153
102.39,20.21,0.153
102.39,20.28,0.153
102.40,20.35,0.153
102.41,20.41,0.153
102.41,20.48,0.154
102.42,20.55,0.154
102.43,20.61,0.154
102.43,20.68,0.154
102.44,20.75,0.154
102.45,20.81,0.154
102.45,20.88,0.155
102.46,20.95,0.155
102.47,21.01,0.155
102.47,21.08,0.155
102.48,21.15,0.155
102.49,21.21,0.155
102.49,21.28,0.155
102.50,21.35,0.155
102.51,21.41,0.156
102.51,21.48,0.156
102.52,21.55,0.156
102.53,21.61,0.156
102.53,21.68,0.156
102.54,21.75,0.156
102.55,21.81,0.156
102.55,21.88,0.156
102.56,21.95,0.156
102.57,22.01,0.156
102.57,22.08,0.156
102.58,22.15,0.156
102.59,22.21,0.156
102.59,22.28,0.156
102.60,22.35,0.157
102.61,22.41,0.157
102.61,22.48,0.157
102.62,22.55,0.157
102.63,22.61,0.157
102.63,22.68,0.157
102.64,22.75,0.157
102.65,22.81,0.157
102.65,22.88,0.157
102.66,22.95,0.157
102.67,23.01,0.157
102.67,23.08,0.157
102.68,23.15,0.157
102.69,23.21,0.157
102.69,23.28,0.157
102.70,23.35,0.157
102.71,23.41,0.157
102.71,23.48,0.157
102.72,23.55,0.157
102.73,23.62,0.157
102.73,23.68,0.157
102.74,23.75,0.157
102.75,23.82,0.157
102.75,23.88,0.157
102.76,23.95,0.157
102.77,24.02,0.157
102.77,24.08,0.157
102.78,24.15,0.157
102.79,24.22,0.157
102.79,24.28,0.157
102.80,24.35,0.157
102.81,24.42,0.157
102.81,24.48,0.157
102.82,24.55,0.157
102.83,24.62,0.157
102.83,24.68,0.157
102.84,24.75,0.157
102.85,24.82,0.157
102.85,24.88,0.157
102.86,24.95,0.157
102.87,25.02,0.157
102.87,25.08,0.157
102.88,25.15,0.157
102.89,25.22,0.157
102.89,25.29,0.157
102.90,25.35,0.157
102.91,25.42,0.157
102.91,25.48,0.157
102.92,25.55,0.157
102.93,25.62,0.157
102.93,25.69,0.157
102.94,25.75,0.157
102.95,25.82,0.157
102.95,25.89,0.157
102.96,25.95,0.157
102.97,26.02,0.157
102.97,26.09,0.157
102.98,26.15,0.157
102.99,26.22,0.157
102.99,26.29,0.157
103.00,26.35,0.157
103.01,26.42,0.157
103.01,26.49,0.157
103.02,26.55,0.157
103.03,26.62,0.157
103.03,26.69,0.157
103.04,26.75,0.157
103.05,26.82,0.157
103.05,26.89,0.157
103.06,26.95,0.157
103.07,27.02,0.157
103.07,27.09,0.157
103.08,27.15,0.157
103.09,27.22,0.157
103.09,27.29,0.157
103.10,27.35,0.157
103.11,27.42,0.157
103.11,27.49,0.157
103.12,27.56,0.157
103.13,27.62,0.157
103.13,27.69,0.157
103.14,27.76,0.157
103.15,27.82,0.157
103.15,27.89,
103.16,27.95,
103.17,28.02,
103.17,28.09,
103.18,28.15,
103.19,28.22,
103.19,28.29,
103.20,,
103.20,,