File: DSC/2025_04_20_Indium_n60C_200C_10Cmin_x3.csv
Filename,2025_04_20_Indium_n60C_200C_10Cmin_x3
Instrument name,DSC2A-00468 (192.168.1.100)
Operator,Yarger
rundate,4/20/2025
Sample name,2025_04_20_Indium_n60C_200C_10Cmin_x3
proceduresegments,Data Off ; Equilibrate -60.00 °C; Data On ; Ramp 10.00 °C/min to 200.00 °C; Data Off ; Isothermal 1.0 min; Data On ; Ramp 10.00 °C/min to -60.00 °C; Data Off ; Isothermal 1.0 min; Data On ; Ramp 10.00 °C/min to 200.00 °C; Data Off ; Isothermal 1.0 min; Data On ; Ramp 10.00 °C/min to -60.00 °C; Data Off ; Isothermal 1.0 min; Data On ; Ramp 10.00 °C/min to 200.00 °C
[File Parameters]
Run date,4/20/2025 11:55:51 AM
Trios version,5.1.1.46572
Original File Name,
Current File Name,D:\DSC2500\JYarger\2025_04_20_Indium_n60C_200C_10Cmin_x3.tri
[Procedure]
Procedure Name,Indium_n60_200C_2Cmin_x3
Sample Name,2025_04_20_Indium_n60C_200C_10Cmin_x3
Sample Mass,4.29 mg
Reference Sample Mass,0 mg
Pan Mass,25.66 mg
Pan Number,32
Reference Pan Mass,25.8 mg
Reference Pan Number,28
Pan Type,Tzero Aluminum
Comments,"Al Pan/Lid, Not sealed."
Project Name,CA
Operator,Yarger
Test,Custom
Unload Max Temperature,30
Unload Min Temperature,30
Load Max Temperature,30
Load Min Temperature,30
Stop on Gas Flow Error,Yes
[Signal List]
Signal #1,Time (min)
Signal #2,Temperature (°C)
Signal #3,Heat Flow (mW)
Signal #4,Delta T (µV)
Signal #5,Delta Tzero (µV)
Signal #6,Tzero Temperature (°C)
Signal #7,Cell Purge (mL/min)
Signal #8,Heater Temp (°C)
Signal #9,Power Delivered (W)
Signal #10,Reference Junction Temperature (°C)
Signal #11,Flange Temperature (°C)
Signal #12,Heat Flow Phase (rad)
Signal #13,Total Heat Capacity (J/°C)
Signal #14,Heat Capacity (J/°C)
[Configuration]
Company Name,ASU
Instrument Name,DSC2A-00468
Instrument Type,DSC2500
Serial Number,DSC2A-00468
IP,192.168.1.100
Location of Instrument,MRRC
DisplayType,Unknown
Sample Interval ,0.1 s/pt
Selected Heat Flow,T4P
Exotherm Direction,Down
Cell Serial,DRC2-00792
Lid Type,Standard
Cooler,RCS 90
Leave Cooler on at End of Sequence,On
Gas 2,Nitrogen
Gas Selected,Channel 1
Flow Rate,50 mL/min
Secondary Purge,On
Licensed Heat Flow,Heat Flow T4P
Modulation Licensed,Yes
[Versions]
Common IDD Version,1
Cortex Version,VER 2.10.2.31
Driver,5.0.0.6
GDM Version,1.0.3.3
TouchscreenVersion,1.0.0.16145
FEP Version,1.2.1.21
FEP Bootloader,2.0.0.5
AutoSampler Version,2.1.1.26
Auto Sampler Bootloader,2.0.0.5
FCM Version,1.1.0.3
FCM Bootloader,2.0.0.5
[Experiment Logs]
Experiment Log Entry # 1,Air Cool is off.
Experiment Log Entry # 3,Data On set to 0
Experiment Log Entry # 5,Equilibrate Segment -60 (C) Started
Experiment Log Entry # 7,Data On set to 1
Experiment Log Entry # 9,Ramp Segment 10 C/min to 200 Started
Experiment Log Entry # 11,Data On set to 0
Experiment Log Entry # 13,Isothermal Segment 1 min started
Experiment Log Entry # 15,Data On set to 1
Experiment Log Entry # 17,Ramp Segment 10 C/min to -60 Started
Experiment Log Entry # 19,Data On set to 0
Experiment Log Entry # 21,Isothermal Segment 1 min started
Experiment Log Entry # 23,Data On set to 1
Experiment Log Entry # 25,Ramp Segment 10 C/min to 200 Started
Experiment Log Entry # 27,Data On set to 0
Experiment Log Entry # 29,Isothermal Segment 1 min started
Experiment Log Entry # 31,Data On set to 1
Experiment Log Entry # 33,Ramp Segment 10 C/min to -60 Started
Experiment Log Entry # 35,Data On set to 0
Experiment Log Entry # 37,Isothermal Segment 1 min started
Experiment Log Entry # 39,Data On set to 1
Experiment Log Entry # 41,Ramp Segment 10 C/min to 200 Started
[Method Log]
Method Log Entry # 1,Data Off
Method Log Entry # 2,Equilibrate -60 °C
Method Log Entry # 3,Data On
Method Log Entry # 4,(Ramp 503712) Ramp 10 °C/minute to 200 °C
Method Log Entry # 5,Data Off
Method Log Entry # 6,Isothermal 1 minutes
Method Log Entry # 7,Data On
Method Log Entry # 8,(Ramp 503716) Ramp 10 °C/minute to -60 °C
Method Log Entry # 9,Data Off
Method Log Entry # 10,Isothermal 1 minutes
Method Log Entry # 11,Data On
Method Log Entry # 12,(Ramp 503720) Ramp 10 °C/minute to 200 °C
Method Log Entry # 13,Data Off
Method Log Entry # 14,Isothermal 1 minutes
Method Log Entry # 15,Data On
Method Log Entry # 16,(Ramp 503724) Ramp 10 °C/minute to -60 °C
Method Log Entry # 17,Data Off
Method Log Entry # 18,Isothermal 1 minutes
Method Log Entry # 19,Data On
Method Log Entry # 20,(Ramp 503728) Ramp 10 °C/minute to 200 °C
Cell Serial,DRC2-00792
[T1 Calibration]
Slope,-0.008529666
Offset,9.636258
Initial Temperature,98.23
GUID,f8bfdadc-4977-4fdf-ba6d-0ba9134940c3
[TZero Calibration]
Date Applied,11/29/2022 4:06:13 PM
Description,From -89.059 °C to 396.009 °C at 20.000°C/min
Gas Type,Nitrogen
Pan Type,None
Source Files 1,C:\Users\yargerlab\Desktop\DSC Data\General\TZero_calibration_11_29_22_2nd(2).tri
Source Files 2,C:\Users\yargerlab\Desktop\DSC Data\General\TZero_calibration_11_29_22_2nd(3).tri
Delta T Offset,13.05235
Delta T Slope,-0.007271007
Delta T0 Offset,-13.69128
Delta T0 Slope,0.06063341
[Temperature Calibration]
Date Applied,11/29/2022 7:12:28 PM
Description,From 106.590 °C to 186.590 °C at 10.000°C/min
Gas Type,Nitrogen
Pan Type,Tzero Aluminum Hermetic
Source Files 1,C:\Users\yargerlab\Desktop\DSC Data\General\Indium(6).tri
Measured 1,157.391
Known 1,156.598
[Cell Constant Calibration]
Date Applied,11/29/2022 7:12:29 PM
Description,From 106.590 °C to 186.590 °C at 10.000°C/min
Gas Type,Nitrogen
Pan Type,Tzero Aluminum Hermetic
Source Files 1,C:\Users\yargerlab\Desktop\DSC Data\General\Indium(6).tri
T4P KCell,1.006051
Onset Slope,63.26126 mW/°C
[Direct Cp Calibration]
Date Applied,11/30/2022 11:04:51 AM
Description,From -79.983 °C to 298.409 °C at 10.000°C/min
Gas Type,Nitrogen
Pan Type,Tzero Aluminum Hermetic
Source Files 1,C:\Users\yargerlab\Desktop\DSC Data\General\Sapphire_Heat_Capacity_11_30_22.tri
[Rev Cp Calibration]
Date Applied,11/30/2022 1:58:51 PM
Description,From -79.996 °C to 292.812 °C at 3.000°C/min
Gas Type,Nitrogen
Pan Type,Tzero Aluminum Hermetic
Source Files 1,C:\Users\yargerlab\Desktop\DSC Data\General\Sapphire_MDSC_Calibration_11_30_22.tri
[step]
Ramp 10.00 °C/min to 200.00 °C
Time,Temperature,Heat Flow (Normalized)
min,°C,W/g
0.00,-59.80,-0.036
0.02,-59.81,-0.035
0.04,-59.81,-0.034
0.05,-59.80,-0.031
0.07,-59.76,-0.028
0.09,-59.71,-0.025
0.11,-59.62,-0.020
0.13,-59.51,-0.013
0.15,-59.38,-0.005
0.16,-59.24,0.005
0.18,-59.08,0.013
0.20,-58.91,0.021
0.22,-58.74,0.029
0.24,-58.57,0.034
0.26,-58.39,0.039
0.28,-58.22,0.044
0.29,-58.04,0.045
0.31,-57.86,0.047
0.33,-57.68,0.049
0.35,-57.50,0.051
0.37,-57.33,0.051
0.39,-57.15,0.052
0.40,-56.97,0.052
0.42,-56.79,0.053
0.44,-56.61,0.053
0.46,-56.43,0.053
0.48,-56.25,0.054
0.50,-56.07,0.054
0.51,-55.89,0.054
0.53,-55.71,0.055
0.55,-55.53,0.055
0.57,-55.35,0.056
0.59,-55.17,0.056
0.60,-54.99,0.056
0.62,-54.81,0.056
0.64,-54.63,0.057
0.66,-54.45,0.057
0.68,-54.27,0.057
0.70,-54.09,0.058
0.72,-53.91,0.058
0.73,-53.72,0.058
0.75,-53.54,0.058
0.77,-53.36,0.059
0.79,-53.18,0.059
0.81,-53.00,0.059
0.83,-52.82,0.059
0.84,-52.64,0.059
0.86,-52.45,0.060
0.88,-52.27,0.060
0.90,-52.09,0.060
0.92,-51.91,0.060
0.93,-51.73,0.060
0.95,-51.55,0.060
0.97,-51.36,0.061
0.99,-51.18,0.061
1.01,-51.00,0.061
1.03,-50.82,0.061
1.05,-50.63,0.061
1.06,-50.45,0.061
1.08,-50.27,0.061
1.10,-50.09,0.061
1.12,-49.90,0.061
1.14,-49.72,0.061
1.16,-49.54,0.061
1.17,-49.36,0.061
1.19,-49.17,0.061
1.21,-48.99,0.062
1.23,-48.81,0.062
1.25,-48.63,0.062
1.27,-48.44,0.062
1.28,-48.26,0.062
1.30,-48.08,0.062
1.32,-47.90,0.062
1.34,-47.71,0.062
1.36,-47.53,0.062
1.38,-47.35,0.062
1.39,-47.16,0.062
1.41,-46.98,0.062
1.43,-46.80,0.062
1.45,-46.61,0.062
1.47,-46.43,0.062
1.48,-46.25,0.062
1.50,-46.06,0.062
1.52,-45.88,0.062
1.54,-45.70,0.062
1.56,-45.52,0.062
1.58,-45.33,0.062
1.59,-45.15,0.062
1.61,-44.97,0.062
1.63,-44.78,0.062
1.65,-44.60,0.062
1.67,-44.42,0.061
1.69,-44.23,0.061
1.71,-44.05,0.061
1.72,-43.86,0.061
1.74,-43.68,0.061
1.76,-43.50,0.061
1.78,-43.32,0.061
1.80,-43.13,0.061
1.82,-42.95,0.061
1.83,-42.77,0.061
1.85,-42.58,0.061
1.87,-42.40,0.061
1.89,-42.22,0.061
1.91,-42.03,0.061
1.93,-41.85,0.061
1.94,-41.67,0.061
1.96,-41.48,0.061
1.98,-41.30,0.060
2.00,-41.11,0.060
2.02,-40.93,0.060
2.03,-40.75,0.060
2.05,-40.56,0.060
2.07,-40.38,0.060
2.09,-40.20,0.060
2.11,-40.01,0.060
2.13,-39.83,0.060
2.14,-39.65,0.060
2.16,-39.46,0.060
2.18,-39.28,0.060
2.20,-39.09,0.060
2.22,-38.91,0.060
2.24,-38.73,0.059
2.26,-38.54,0.059
2.27,-38.36,0.059
2.29,-38.18,0.059
2.31,-37.99,0.059
2.33,-37.81,0.059
2.35,-37.63,0.059
2.36,-37.44,0.059
2.38,-37.26,0.059
2.40,-37.08,0.059
2.42,-36.89,0.059
2.44,-36.71,0.059
2.46,-36.52,0.058
2.48,-36.34,0.058
2.49,-36.16,0.058
2.51,-35.97,0.058
2.53,-35.79,0.058
2.55,-35.61,0.058
2.57,-35.42,0.058
2.59,-35.24,0.058
2.60,-35.06,0.058
2.62,-34.87,0.058
2.64,-34.69,0.058
2.66,-34.51,0.058
2.68,-34.32,0.057
2.69,-34.14,0.057
2.71,-33.95,0.057
2.73,-33.77,0.057
2.75,-33.59,0.057
2.77,-33.40,0.057
2.79,-33.22,0.057
2.81,-33.04,0.057
2.82,-32.85,0.057
2.84,-32.67,0.057
2.86,-32.49,0.057
2.88,-32.30,0.057
2.90,-32.12,0.057
2.91,-31.94,0.056
2.93,-31.75,0.056
2.95,-31.57,0.056
2.97,-31.38,0.056
2.99,-31.20,0.056
3.01,-31.02,0.056
3.03,-30.83,0.056
3.04,-30.65,0.056
3.06,-30.47,0.056
3.08,-30.28,0.056
3.10,-30.10,0.056
3.12,-29.92,0.056
3.14,-29.73,0.055
3.15,-29.55,0.055
3.17,-29.37,0.055
3.19,-29.18,0.055
3.21,-29.00,0.055
3.23,-28.81,0.055
3.24,-28.63,0.055
3.26,-28.45,0.055
3.28,-28.26,0.055
3.30,-28.08,0.055
3.32,-27.90,0.055
3.34,-27.71,0.055
3.36,-27.53,0.055
3.37,-27.35,0.055
3.39,-27.16,0.054
3.41,-26.98,0.054
3.43,-26.80,0.054
3.45,-26.61,0.054
3.46,-26.43,0.054
3.48,-26.24,0.054
3.50,-26.06,0.054
3.52,-25.88,0.054
3.54,-25.69,0.054
3.56,-25.51,0.054
3.58,-25.33,0.054
3.59,-25.14,0.054
3.61,-24.96,0.054
3.63,-24.78,0.054
3.65,-24.59,0.054
3.67,-24.41,0.054
3.69,-24.22,0.053
3.70,-24.04,0.053
3.72,-23.86,0.053
3.74,-23.67,0.053
3.76,-23.49,0.053
3.78,-23.31,0.053
3.79,-23.12,0.053
3.81,-22.94,0.053
3.83,-22.76,0.053
3.85,-22.57,0.053
3.87,-22.39,0.053
3.89,-22.20,0.053
3.91,-22.02,0.053
3.92,-21.84,0.053
3.94,-21.65,0.053
3.96,-21.47,0.053
3.98,-21.29,0.053
4.00,-21.10,0.052
4.01,-20.92,0.052
4.03,-20.74,0.052
4.05,-20.55,0.052
4.07,-20.37,0.052
4.09,-20.19,0.052
4.11,-20.00,0.052
4.13,-19.82,0.052
4.14,-19.64,0.052
4.16,-19.45,0.052
4.18,-19.27,0.052
4.20,-19.09,0.052
4.22,-18.90,0.052
4.24,-18.72,0.052
4.25,-18.53,0.052
4.27,-18.35,0.051
4.29,-18.17,0.051
4.31,-17.98,0.051
4.33,-17.80,0.051
4.35,-17.62,0.051
4.36,-17.43,0.051
4.38,-17.25,0.051
4.40,-17.07,0.051
4.42,-16.88,0.051
4.44,-16.70,0.051
4.45,-16.52,0.051
4.47,-16.33,0.051
4.49,-16.15,0.051
4.51,-15.97,0.051
4.53,-15.78,0.051
4.55,-15.60,0.051
4.56,-15.42,0.051
4.58,-15.23,0.051
4.60,-15.05,0.051
4.62,-14.86,0.050
4.64,-14.68,0.050
4.66,-14.50,0.050
4.68,-14.31,0.050
4.69,-14.13,0.050
4.71,-13.95,0.050
4.73,-13.76,0.050
4.75,-13.58,0.050
4.77,-13.40,0.050
4.79,-13.21,0.050
4.80,-13.03,0.050
4.82,-12.84,0.050
4.84,-12.66,0.050
4.86,-12.48,0.050
4.88,-12.29,0.050
4.90,-12.11,0.050
4.91,-11.93,0.050
4.93,-11.74,0.050
4.95,-11.56,0.050
4.97,-11.38,0.050
4.99,-11.19,0.050
5.00,-11.01,0.049
5.02,-10.82,0.049
5.04,-10.64,0.049
5.06,-10.46,0.049
5.08,-10.27,0.049
5.10,-10.09,0.049
5.11,-9.91,0.049
5.13,-9.72,0.049
5.15,-9.54,0.049
5.17,-9.36,0.049
5.19,-9.17,0.049
5.21,-8.99,0.049
5.23,-8.81,0.049
5.24,-8.62,0.049
5.26,-8.44,0.049
5.28,-8.26,0.049
5.30,-8.07,0.049
5.32,-7.89,0.049
5.34,-7.71,0.049
5.35,-7.52,0.049
5.37,-7.34,0.049
5.39,-7.16,0.049
5.41,-6.97,0.049
5.43,-6.79,0.049
5.45,-6.60,0.048
5.46,-6.42,0.048
5.48,-6.24,0.048
5.50,-6.05,0.048
5.52,-5.87,0.048
5.54,-5.69,0.048
5.55,-5.50,0.048
5.57,-5.32,0.048
5.59,-5.14,0.048
5.61,-4.95,0.048
5.63,-4.77,0.048
5.65,-4.58,0.048
5.66,-4.40,0.048
5.68,-4.22,0.048
5.70,-4.03,0.048
5.72,-3.85,0.048
5.74,-3.67,0.048
5.76,-3.48,0.048
5.78,-3.30,0.048
5.79,-3.12,0.048
5.81,-2.93,0.048
5.83,-2.75,0.048
5.85,-2.56,0.048
5.87,-2.38,0.048
5.89,-2.20,0.048
5.90,-2.01,0.048
5.92,-1.83,0.048
5.94,-1.65,0.048
5.96,-1.46,0.047
5.98,-1.28,0.047
6.00,-1.10,0.047
6.01,-0.91,0.047
6.03,-0.73,0.047
6.05,-0.55,0.047
6.07,-0.36,0.047
6.09,-0.18,0.047
6.10,0.00,0.047
6.12,0.19,0.047
6.14,0.37,0.047
6.16,0.56,0.047
6.18,0.74,0.047
6.20,0.92,0.047
6.21,1.11,0.047
6.23,1.29,0.047
6.25,1.47,0.047
6.27,1.66,0.047
6.29,1.84,0.047
6.31,2.02,0.047
6.33,2.21,0.047
6.34,2.39,0.047
6.36,2.57,0.047
6.38,2.76,0.047
6.40,2.94,0.047
6.42,3.12,0.047
6.44,3.31,0.047
6.45,3.49,0.047
6.47,3.68,0.047
6.49,3.86,0.046
6.51,4.04,0.046
6.53,4.23,0.046
6.55,4.41,0.046
6.56,4.59,0.046
6.58,4.78,0.046
6.60,4.96,0.046
6.62,5.14,0.046
6.64,5.33,0.046
6.65,5.51,0.046
6.67,5.69,0.046
6.69,5.88,0.046
6.71,6.06,0.046
6.73,6.24,0.046
6.75,6.43,0.046
6.76,6.61,0.046
6.78,6.79,0.046
6.80,6.98,0.046
6.82,7.16,0.046
6.84,7.35,0.046
6.86,7.53,0.046
6.88,7.71,0.046
6.89,7.90,0.046
6.91,8.08,0.046
6.93,8.26,0.046
6.95,8.45,0.046
6.97,8.63,0.046
6.99,8.81,0.046
7.00,9.00,0.046
7.02,9.18,0.046
7.04,9.36,0.046
7.06,9.55,0.046
7.08,9.73,0.046
7.10,9.92,0.046
7.11,10.10,0.046
7.13,10.28,0.046
7.15,10.47,0.046
7.17,10.65,0.046
7.19,10.83,0.046
7.20,11.02,0.046
7.22,11.20,0.046
7.24,11.38,0.046
7.26,11.57,0.046
7.28,11.75,0.046
7.30,11.93,0.046
7.31,12.12,0.046
7.33,12.30,0.045
7.35,12.48,0.045
7.37,12.67,0.045
7.39,12.85,0.045
7.41,13.04,0.045
7.43,13.22,0.045
7.44,13.40,0.045
7.46,13.58,0.045
7.48,13.77,0.045
7.50,13.95,0.045
7.52,14.14,0.045
7.54,14.32,0.045
7.55,14.50,0.045
7.57,14.69,0.045
7.59,14.87,0.045
7.61,15.05,0.045
7.63,15.24,0.045
7.65,15.42,0.045
7.66,15.60,0.045
7.68,15.79,0.045
7.70,15.97,0.045
7.72,16.15,0.045
7.74,16.34,0.045
7.75,16.52,0.045
7.77,16.71,0.045
7.79,16.89,0.045
7.81,17.07,0.045
7.83,17.26,0.045
7.85,17.44,0.045
7.86,17.62,0.045
7.88,17.81,0.045
7.90,17.99,0.045
7.92,18.17,0.045
7.94,18.36,0.045
7.96,18.54,0.045
7.98,18.73,0.045
7.99,18.91,0.045
8.01,19.09,0.045
8.03,19.28,0.045
8.05,19.46,0.045
8.07,19.64,0.045
8.09,19.83,0.045
8.10,20.01,0.045
8.12,20.19,0.045
8.14,20.38,0.045
8.16,20.56,0.045
8.18,20.74,0.045
8.20,20.93,0.045
8.21,21.11,0.045
8.23,21.29,0.045
8.25,21.48,0.045
8.27,21.66,0.045
8.29,21.84,0.045
8.30,22.03,0.045
8.32,22.21,0.044
8.34,22.40,0.045
8.36,22.58,0.045
8.38,22.76,0.044
8.40,22.95,0.044
8.41,23.13,0.044
8.43,23.31,0.044
8.45,23.50,0.044
8.47,23.68,0.044
8.49,23.86,0.044
8.51,24.05,0.044
8.53,24.23,0.044
8.54,24.41,0.044
8.56,24.60,0.044
8.58,24.78,0.044
8.60,24.96,0.044
8.62,25.15,0.044
8.63,25.33,0.044
8.65,25.51,0.044
8.67,25.70,0.044
8.69,25.88,0.044
8.71,26.07,0.044
8.73,26.25,0.044
8.75,26.43,0.044
8.76,26.62,0.044
8.78,26.80,0.044
8.80,26.98,0.044
8.82,27.17,0.044
8.84,27.35,0.044
8.85,27.53,0.044
8.87,27.72,0.044
8.89,27.90,0.044
8.91,28.08,0.044
8.93,28.27,0.044
8.95,28.45,0.044
8.97,28.63,0.044
8.98,28.82,0.044
9.00,29.00,0.044
9.02,29.18,0.044
9.04,29.37,0.044
9.06,29.55,0.044
9.08,29.74,0.044
9.09,29.92,0.044
9.11,30.10,0.044
9.13,30.29,0.044
9.15,30.47,0.044
9.17,30.65,0.044
9.18,30.84,0.044
9.20,31.02,0.044
9.22,31.20,0.044
9.24,31.39,0.044
9.26,31.57,0.044
9.28,31.75,0.044
9.30,31.94,0.044
9.31,32.12,0.044
9.33,32.30,0.044
9.35,32.49,0.044
9.37,32.67,0.044
9.39,32.86,0.044
9.40,33.04,0.044
9.42,33.22,0.044
9.44,33.41,0.044
9.46,33.59,0.044
9.48,33.77,0.044
9.50,33.96,0.044
9.52,34.14,0.044
9.53,34.32,0.044
9.55,34.51,0.044
9.57,34.69,0.044
9.59,34.87,0.044
9.61,35.06,0.044
9.63,35.24,0.044
9.64,35.42,0.044
9.66,35.61,0.044
9.68,35.79,0.044
9.70,35.97,0.044
9.72,36.16,0.044
9.73,36.34,0.044
9.75,36.53,0.044
9.77,36.71,0.044
9.79,36.89,0.044
9.81,37.08,0.044
9.83,37.26,0.044
9.85,37.44,0.044
9.86,37.63,0.044
9.88,37.81,0.044
9.90,37.99,0.044
9.92,38.18,0.044
9.94,38.36,0.044
9.95,38.54,0.044
9.97,38.73,0.044
9.99,38.91,0.044
10.01,39.09,0.044
10.03,39.28,0.044
10.05,39.46,0.044
10.07,39.65,0.044
10.08,39.83,0.044
10.10,40.01,0.044
10.12,40.20,0.044
10.14,40.38,0.044
10.16,40.56,0.044
10.18,40.75,0.044
10.19,40.93,0.044
10.21,41.11,0.044
10.23,41.30,0.044
10.25,41.48,0.044
10.27,41.66,0.044
10.28,41.85,0.044
10.30,42.03,0.044
10.32,42.21,0.044
10.34,42.40,0.044
10.36,42.58,0.044
10.38,42.76,0.044
10.40,42.95,0.044
10.41,43.13,0.044
10.43,43.31,0.044
10.45,43.50,0.044
10.47,43.68,0.044
10.49,43.87,0.044
10.50,44.05,0.044
10.52,44.23,0.044
10.54,44.41,0.044
10.56,44.60,0.044
10.58,44.78,0.044
10.60,44.97,0.044
10.62,45.15,0.044
10.63,45.33,0.044
10.65,45.52,0.044
10.67,45.70,0.044
10.69,45.88,0.044
10.71,46.07,0.044
10.73,46.25,0.044
10.74,46.44,0.044
10.76,46.62,0.044
10.78,46.80,0.044
10.80,46.99,0.044
10.82,47.17,0.044
10.83,47.35,0.044
10.85,47.54,0.044
10.87,47.72,0.044
10.89,47.90,0.044
10.91,48.09,0.044
10.93,48.27,0.044
10.95,48.45,0.044
10.96,48.64,0.044
10.98,48.82,0.044
11.00,49.00,0.044
11.02,49.19,0.044
11.04,49.37,0.044
11.05,49.56,0.044
11.07,49.74,0.044
11.09,49.92,0.044
11.11,50.11,0.044
11.13,50.29,0.044
11.15,50.47,0.044
11.17,50.66,0.044
11.18,50.84,0.044
11.20,51.02,0.044
11.22,51.21,0.044
11.24,51.39,0.044
11.26,51.57,0.044
11.28,51.76,0.044
11.29,51.94,0.044
11.31,52.12,0.044
11.33,52.31,0.044
11.35,52.49,0.044
11.37,52.68,0.044
11.38,52.86,0.044
11.40,53.04,0.044
11.42,53.23,0.044
11.44,53.41,0.044
11.46,53.59,0.044
11.48,53.78,0.044
11.50,53.96,0.044
11.51,54.14,0.044
11.53,54.33,0.044
11.55,54.51,0.044
11.57,54.69,0.044
11.59,54.88,0.044
11.60,55.06,0.044
11.62,55.24,0.044
11.64,55.43,0.044
11.66,55.61,0.044
11.68,55.79,0.044
11.70,55.98,0.044
11.72,56.16,0.044
11.73,56.34,0.044
11.75,56.53,0.044
11.77,56.71,0.044
11.79,56.90,0.044
11.81,57.08,0.044
11.83,57.26,0.044
11.84,57.45,0.044
11.86,57.63,0.044
11.88,57.81,0.044
11.90,58.00,0.044
11.92,58.18,0.044
11.93,58.36,0.044
11.95,58.55,0.044
11.97,58.73,0.044
11.99,58.92,0.044
12.01,59.10,0.044
12.03,59.28,0.044
12.05,59.47,0.044
12.06,59.65,0.044
12.08,59.83,0.044
12.10,60.02,0.044
12.12,60.20,0.044
12.14,60.38,0.044
12.15,60.56,0.044
12.17,60.75,0.044
12.19,60.93,0.044
12.21,61.12,0.044
12.23,61.30,0.044
12.25,61.48,0.044
12.27,61.67,0.044
12.28,61.85,0.044
12.30,62.03,0.044
12.32,62.22,0.044
12.34,62.40,0.044
12.36,62.58,0.044
12.38,62.77,0.044
12.39,62.95,0.044
12.41,63.13,0.044
12.43,63.32,0.044
12.45,63.50,0.044
12.47,63.68,0.044
12.48,63.87,0.044
12.50,64.05,0.044
12.52,64.23,0.044
12.54,64.42,0.044
12.56,64.60,0.044
12.58,64.79,0.044
12.60,64.97,0.044
12.61,65.15,0.044
12.63,65.33,0.044
12.65,65.52,0.044
12.67,65.70,0.044
12.69,65.89,0.044
12.70,66.07,0.044
12.72,66.25,0.044
12.74,66.44,0.044
12.76,66.62,0.044
12.78,66.80,0.044
12.80,66.99,0.044
12.82,67.17,0.044
12.83,67.35,0.044
12.85,67.54,0.044
12.87,67.72,0.044
12.89,67.90,0.045
12.91,68.09,0.045
12.93,68.27,0.045
12.94,68.45,0.045
12.96,68.64,0.045
12.98,68.82,0.045
13.00,69.00,0.045
13.02,69.19,0.045
13.03,69.37,0.045
13.05,69.55,0.045
13.07,69.74,0.045
13.09,69.92,0.045
13.11,70.11,0.045
13.13,70.29,0.045
13.15,70.47,0.045
13.16,70.66,0.045
13.18,70.84,0.045
13.20,71.02,0.045
13.22,71.21,0.045
13.24,71.39,0.045
13.25,71.57,0.045
13.27,71.76,0.045
13.29,71.94,0.045
13.31,72.12,0.045
13.33,72.31,0.045
13.35,72.49,0.045
13.37,72.67,0.045
13.38,72.86,0.045
13.40,73.04,0.045
13.42,73.22,0.045
13.44,73.41,0.045
13.46,73.59,0.045
13.48,73.77,0.045
13.49,73.96,0.045
13.51,74.14,0.045
13.53,74.32,0.045
13.55,74.51,0.045
13.57,74.69,0.045
13.58,74.88,0.045
13.60,75.06,0.045
13.62,75.24,0.045
13.64,75.43,0.045
13.66,75.61,0.045
13.68,75.79,0.045
13.70,75.98,0.045
13.71,76.16,0.045
13.73,76.34,0.045
13.75,76.53,0.045
13.77,76.71,0.045
13.79,76.90,0.045
13.80,77.08,0.045
13.82,77.26,0.045
13.84,77.45,0.045
13.86,77.63,0.045
13.88,77.81,0.045
13.90,78.00,0.045
13.92,78.18,0.045
13.93,78.36,0.045
13.95,78.55,0.045
13.97,78.73,0.045
13.99,78.91,0.045
14.01,79.10,0.045
14.03,79.28,0.045
14.04,79.46,0.045
14.06,79.65,0.045
14.08,79.83,0.045
14.10,80.01,0.045
14.12,80.20,0.045
14.13,80.38,0.045
14.15,80.56,0.045
14.17,80.75,0.045
14.19,80.93,0.045
14.21,81.12,0.045
14.23,81.30,0.045
14.25,81.48,0.045
14.26,81.67,0.045
14.28,81.85,0.045
14.30,82.03,0.045
14.32,82.22,0.045
14.34,82.40,0.045
14.35,82.58,0.045
14.37,82.77,0.045
14.39,82.95,0.045
14.41,83.13,0.045
14.43,83.32,0.045
14.45,83.50,0.045
14.47,83.68,0.045
14.48,83.87,0.045
14.50,84.05,0.045
14.52,84.23,0.045
14.54,84.42,0.045
14.56,84.60,0.045
14.58,84.78,0.045
14.59,84.97,0.045
14.61,85.15,0.045
14.63,85.34,0.045
14.65,85.52,0.045
14.67,85.70,0.045
14.68,85.89,0.045
14.70,86.07,0.045
14.72,86.25,0.045
14.74,86.44,0.045
14.76,86.62,0.045
14.78,86.80,0.045
14.80,86.99,0.045
14.81,87.17,0.045
14.83,87.35,0.045
14.85,87.54,0.045
14.87,87.72,0.045
14.89,87.90,0.045
14.90,88.09,0.045
14.92,88.27,0.045
14.94,88.46,0.045
14.96,88.64,0.045
14.98,88.82,0.045
15.00,89.01,0.045
15.02,89.19,0.045
15.03,89.37,0.045
15.05,89.56,0.045
15.07,89.74,0.045
15.09,89.92,0.045
15.11,90.11,0.045
15.13,90.29,0.045
15.14,90.47,0.045
15.16,90.66,0.045
15.18,90.84,0.045
15.20,91.03,0.045
15.22,91.21,0.045
15.23,91.39,0.045
15.25,91.58,0.045
15.27,91.76,0.045
15.29,91.94,0.045
15.31,92.13,0.045
15.33,92.31,0.045
15.35,92.49,0.045
15.36,92.68,0.045
15.38,92.86,0.045
15.40,93.04,0.045
15.42,93.23,0.045
15.44,93.41,0.045
15.45,93.60,0.045
15.47,93.78,0.045
15.49,93.96,0.045
15.51,94.14,0.045
15.53,94.33,0.045
15.55,94.51,0.045
15.57,94.69,0.045
15.58,94.88,0.045
15.60,95.06,0.045
15.62,95.24,0.045
15.64,95.43,0.045
15.66,95.61,0.045
15.68,95.80,0.045
15.69,95.98,0.045
15.71,96.16,0.045
15.73,96.35,0.045
15.75,96.53,0.045
15.77,96.71,0.045
15.78,96.90,0.045
15.80,97.08,0.045
15.82,97.26,0.045
15.84,97.45,0.045
15.86,97.63,0.045
15.88,97.81,0.045
15.90,98.00,0.045
15.91,98.18,0.045
15.93,98.36,0.045
15.95,98.55,0.045
15.97,98.73,0.045
15.99,98.91,0.045
16.00,99.10,0.045
16.02,99.28,0.045
16.04,99.46,0.045
16.06,99.65,0.045
16.08,99.83,0.045
16.10,100.01,0.045
16.12,100.20,0.045
16.13,100.38,0.045
16.15,100.56,0.045
16.17,100.75,0.045
16.19,100.93,0.045
16.21,101.12,0.045
16.23,101.30,0.045
16.24,101.48,0.045
16.26,101.67,0.045
16.28,101.85,0.045
16.30,102.03,0.045
16.32,102.22,0.045
16.33,102.40,0.045
16.35,102.58,0.045
16.37,102.77,0.045
16.39,102.95,0.045
16.41,103.13,0.045
16.43,103.32,0.045
16.45,103.50,0.045
16.46,103.68,0.045
16.48,103.87,0.045
16.50,104.05,0.045
16.52,104.23,0.045
16.54,104.42,0.045
16.55,104.60,0.045
16.57,104.78,0.045
16.59,104.97,0.045
16.61,105.15,0.045
16.63,105.33,0.046
16.65,105.52,0.046
16.67,105.70,0.046
16.68,105.88,0.046
16.70,106.07,0.046
16.72,106.25,0.046
16.74,106.44,0.046
16.76,106.62,0.046
16.78,106.80,0.046
16.79,106.99,0.046
16.81,107.17,0.046
16.83,107.35,0.046
16.85,107.54,0.046
16.87,107.72,0.046
16.88,107.90,0.046
16.90,108.09,0.046
16.92,108.27,0.046
16.94,108.45,0.046
16.96,108.64,0.046
16.98,108.82,0.046
17.00,109.00,0.046
17.01,109.19,0.046
17.03,109.37,0.046
17.05,109.55,0.046
17.07,109.74,0.046
17.09,109.92,0.046
17.11,110.10,0.046
17.12,110.29,0.046
17.14,110.47,0.046
17.16,110.65,0.046
17.18,110.84,0.046
17.20,111.02,0.046
17.22,111.20,0.046
17.23,111.39,0.046
17.25,111.57,0.046
17.27,111.76,0.047
17.29,111.94,0.047
17.31,112.12,0.047
17.33,112.31,0.047
17.34,112.49,0.047
17.36,112.67,0.047
17.38,112.86,0.047
17.40,113.04,0.047
17.42,113.22,0.047
17.43,113.41,0.047
17.45,113.59,0.047
17.47,113.77,0.047
17.49,113.96,0.047
17.51,114.14,0.047
17.53,114.32,0.047
17.54,114.51,0.047
17.56,114.69,0.047
17.58,114.87,0.047
17.60,115.06,0.047
17.62,115.24,0.047
17.64,115.42,0.047
17.66,115.61,0.047
17.67,115.79,0.047
17.69,115.97,0.047
17.71,116.16,0.047
17.73,116.34,0.047
17.75,116.53,0.047
17.77,116.71,0.047
17.78,116.89,0.047
17.80,117.08,0.047
17.82,117.26,0.047
17.84,117.44,0.047
17.86,117.63,0.047
17.88,117.81,0.047
17.89,117.99,0.047
17.91,118.18,0.047
17.93,118.36,0.047
17.95,118.54,0.047
17.97,118.73,0.048
17.98,118.91,0.048
18.00,119.09,0.048
18.02,119.28,0.048
18.04,119.46,0.048
18.06,119.64,0.048
18.08,119.83,0.048
18.09,120.01,0.048
18.11,120.20,0.048
18.13,120.38,0.048
18.15,120.56,0.048
18.17,120.75,0.048
18.19,120.93,0.048
18.21,121.11,0.048
18.22,121.30,0.048
18.24,121.48,0.048
18.26,121.66,0.048
18.28,121.85,0.048
18.30,122.03,0.048
18.32,122.21,0.048
18.33,122.40,0.048
18.35,122.58,0.048
18.37,122.76,0.048
18.39,122.95,0.048
18.41,123.13,0.048
18.43,123.31,0.048
18.44,123.50,0.048
18.46,123.68,0.048
18.48,123.86,0.048
18.50,124.05,0.048
18.52,124.23,0.048
18.53,124.41,0.048
18.55,124.60,0.048
18.57,124.78,0.048
18.59,124.96,0.048
18.61,125.15,0.048
18.63,125.33,0.048
18.64,125.51,0.048
18.66,125.70,0.048
18.68,125.88,0.048
18.70,126.06,0.048
18.72,126.25,0.048
18.74,126.43,0.048
18.76,126.62,0.048
18.77,126.80,0.048
18.79,126.98,0.048
18.81,127.17,0.048
18.83,127.35,0.048
18.85,127.53,0.049
18.87,127.72,0.049
18.88,127.90,0.049
18.90,128.08,0.049
18.92,128.27,0.049
18.94,128.45,0.049
18.96,128.63,0.049
18.98,128.82,0.049
18.99,129.00,0.049
19.01,129.18,0.049
19.03,129.37,0.049
19.05,129.55,0.049
19.07,129.73,0.049
19.08,129.92,0.049
19.10,130.10,0.049
19.12,130.29,0.049
19.14,130.47,0.049
19.16,130.65,0.049
19.18,130.83,0.049
19.19,131.02,0.049
19.21,131.20,0.049
19.23,131.38,0.049
19.25,131.57,0.049
19.27,131.75,0.049
19.29,131.93,0.049
19.31,132.12,0.049
19.32,132.30,0.049
19.34,132.48,0.049
19.36,132.67,0.049
19.38,132.85,0.049
19.40,133.04,0.049
19.42,133.22,0.049
19.43,133.40,0.049
19.45,133.59,0.049
19.47,133.77,0.049
19.49,133.95,0.049
19.51,134.13,0.049
19.53,134.32,0.049
19.54,134.50,0.049
19.56,134.69,0.049
19.58,134.87,0.049
19.60,135.05,0.049
19.62,135.24,0.049
19.63,135.42,0.049
19.65,135.61,0.049
19.67,135.79,0.049
19.69,135.97,0.049
19.71,136.16,0.049
19.73,136.34,0.050
19.74,136.52,0.050
19.76,136.71,0.050
19.78,136.89,0.050
19.80,137.07,0.050
19.82,137.25,0.050
19.84,137.44,0.050
19.86,137.62,0.050
19.87,137.81,0.050
19.89,137.99,0.050
19.91,138.17,0.050
19.93,138.36,0.050
19.95,138.54,0.050
19.97,138.72,0.050
19.98,138.91,0.050
20.00,139.09,0.050
20.02,139.27,0.050
20.04,139.46,0.050
20.06,139.64,0.050
20.08,139.82,0.050
20.09,140.01,0.050
20.11,140.19,0.050
20.13,140.37,0.050
20.15,140.56,0.050
20.17,140.74,0.050
20.18,140.92,0.050
20.20,141.11,0.050
20.22,141.29,0.050
20.24,141.47,0.050
20.26,141.66,0.050
20.28,141.84,0.050
20.29,142.02,0.050
20.31,142.21,0.050
20.33,142.39,0.050
20.35,142.57,0.050
20.37,142.76,0.050
20.39,142.94,0.050
20.41,143.13,0.050
20.42,143.31,0.050
20.44,143.49,0.050
20.46,143.68,0.050
20.48,143.86,0.050
20.50,144.04,0.050
20.52,144.23,0.050
20.53,144.41,0.050
20.55,144.59,0.050
20.57,144.78,0.050
20.59,144.96,0.051
20.61,145.14,0.051
20.63,145.33,0.051
20.64,145.51,0.051
20.66,145.69,0.051
20.68,145.88,0.051
20.70,146.06,0.051
20.72,146.24,0.051
20.73,146.43,0.051
20.75,146.61,0.051
20.77,146.79,0.051
20.79,146.98,0.051
20.81,147.16,0.051
20.83,147.35,0.051
20.84,147.53,0.051
20.86,147.71,0.051
20.88,147.90,0.051
20.90,148.08,0.051
20.92,148.26,0.051
20.94,148.45,0.051
20.96,148.63,0.051
20.97,148.81,0.051
20.99,149.00,0.051
21.01,149.18,0.051
21.03,149.36,0.051
21.05,149.55,0.051
21.07,149.73,0.051
21.08,149.91,0.051
21.10,150.10,0.051
21.12,150.28,0.051
21.14,150.46,0.051
21.16,150.65,0.051
21.18,150.83,0.051
21.19,151.01,0.051
21.21,151.20,0.051
21.23,151.38,0.051
21.25,151.56,0.051
21.27,151.75,0.051
21.28,151.93,0.051
21.30,152.11,0.052
21.32,152.30,0.052
21.34,152.48,0.052
21.36,152.66,0.052
21.38,152.85,0.052
21.39,153.03,0.052
21.41,153.21,0.052
21.43,153.40,0.052
21.45,153.58,0.052
21.47,153.77,0.052
21.49,153.95,0.052
21.51,154.13,0.052
21.52,154.32,0.052
21.54,154.50,0.052
21.56,154.68,0.052
21.58,154.87,0.052
21.60,155.05,0.052
21.62,155.23,0.052
21.63,155.42,0.052
21.65,155.60,0.052
21.67,155.78,0.052
21.69,155.97,0.052
21.71,156.15,0.052
21.73,156.33,0.052
21.74,156.52,0.053
21.76,156.70,0.060
21.78,156.87,0.175
21.80,157.03,0.405
21.82,157.18,0.608
21.83,157.31,0.842
21.85,157.44,1.117
21.87,157.57,1.361
21.89,157.69,1.579
21.91,157.82,1.788
21.93,157.95,1.990
21.94,158.08,2.206
21.96,158.21,2.404
21.98,158.35,2.527
22.00,158.51,2.526
22.02,158.68,2.333
22.04,158.91,1.983
22.06,159.17,1.182
22.07,159.48,0.680
22.09,159.76,0.468
22.11,160.01,0.342
22.13,160.25,0.256
22.15,160.47,0.196
22.17,160.68,0.155
22.18,160.88,0.124
22.20,161.07,0.104
22.22,161.27,0.089
22.24,161.45,0.079
22.26,161.64,0.071
22.28,161.83,0.066
22.29,162.01,0.063
22.31,162.20,0.060
22.33,162.38,0.058
22.35,162.57,0.057
22.37,162.75,0.056
22.38,162.93,0.055
22.40,163.12,0.055
22.42,163.30,0.055
22.44,163.49,0.054
22.46,163.67,0.054
22.48,163.85,0.054
22.49,164.04,0.054
22.51,164.22,0.054
22.53,164.40,0.054
22.55,164.59,0.054
22.57,164.77,0.054
22.59,164.95,0.054
22.61,165.14,0.054
22.62,165.32,0.053
22.64,165.50,0.053
22.66,165.69,0.053
22.68,165.87,0.053
22.70,166.06,0.053
22.72,166.24,0.053
22.73,166.42,0.053
22.75,166.61,0.053
22.77,166.79,0.053
22.79,166.97,0.053
22.81,167.16,0.053
22.83,167.34,0.053
22.84,167.52,0.053
22.86,167.71,0.053
22.88,167.89,0.053
22.90,168.07,0.053
22.92,168.26,0.053
22.93,168.44,0.053
22.95,168.62,0.053
22.97,168.80,0.053
22.99,168.99,0.053
23.01,169.17,0.053
23.03,169.35,0.053
23.04,169.54,0.053
23.06,169.72,0.053
23.08,169.91,0.053
23.10,170.09,0.053
23.12,170.27,0.053
23.14,170.46,0.053
23.16,170.64,0.053
23.17,170.82,0.053
23.19,171.01,0.053
23.21,171.19,0.053
23.23,171.37,0.053
23.25,171.56,0.053
23.27,171.74,0.053
23.28,171.92,0.053
23.30,172.11,0.053
23.32,172.29,0.053
23.34,172.47,0.053
23.36,172.66,0.053
23.38,172.84,0.053
23.39,173.02,0.053
23.41,173.21,0.053
23.43,173.39,0.053
23.45,173.58,0.053
23.47,173.76,0.053
23.48,173.94,0.053
23.50,174.13,0.053
23.52,174.31,0.053
23.54,174.49,0.053
23.56,174.68,0.053
23.58,174.86,0.053
23.59,175.04,0.053
23.61,175.23,0.053
23.63,175.41,0.053
23.65,175.60,0.053
23.67,175.78,0.053
23.69,175.96,0.054
23.71,176.14,0.054
23.72,176.33,0.054
23.74,176.51,0.054
23.76,176.69,0.054
23.78,176.88,0.054
23.80,177.06,0.054
23.82,177.24,0.054
23.83,177.43,0.054
23.85,177.61,0.054
23.87,177.79,0.054
23.89,177.98,0.054
23.91,178.16,0.054
23.93,178.35,0.054
23.94,178.53,0.054
23.96,178.71,0.054
23.98,178.90,0.054
24.00,179.08,0.054
24.02,179.26,0.054
24.03,179.45,0.054
24.05,179.63,0.054
24.07,179.81,0.054
24.09,180.00,0.054
24.11,180.18,0.054
24.13,180.36,0.054
24.14,180.55,0.054
24.16,180.73,0.054
24.18,180.91,0.054
24.20,181.10,0.054
24.22,181.28,0.054
24.24,181.46,0.054
24.26,181.65,0.054
24.27,181.83,0.054
24.29,182.01,0.054
24.31,182.20,0.054
24.33,182.38,0.054
24.35,182.56,0.054
24.37,182.75,0.054
24.38,182.93,0.054
24.40,183.11,0.054
24.42,183.30,0.054
24.44,183.48,0.054
24.46,183.66,0.054
24.48,183.85,0.054
24.49,184.03,0.054
24.51,184.21,0.054
24.53,184.40,0.054
24.55,184.58,0.054
24.57,184.77,0.054
24.58,184.95,0.054
24.60,185.13,0.054
24.62,185.32,0.054
24.64,185.50,0.054
24.66,185.68,0.054
24.68,185.87,0.054
24.69,186.05,0.054
24.71,186.23,0.054
24.73,186.41,0.054
24.75,186.60,0.054
24.77,186.78,0.054
24.79,186.97,0.054
24.81,187.15,0.054
24.82,187.33,0.054
24.84,187.52,0.054
24.86,187.70,0.055
24.88,187.88,0.055
24.90,188.07,0.055
24.92,188.25,0.055
24.93,188.43,0.055
24.95,188.62,0.055
24.97,188.80,0.055
24.99,188.98,0.055
25.01,189.17,0.055
25.03,189.35,0.055
25.04,189.53,0.055
25.06,189.72,0.055
25.08,189.90,0.055
25.10,190.08,0.055
25.12,190.27,0.055
25.13,190.45,0.055
25.15,190.63,0.055
25.17,190.82,0.055
25.19,191.00,0.055
25.21,191.18,0.055
25.23,191.37,0.055
25.24,191.55,0.055
25.26,191.73,0.055
25.28,191.92,0.055
25.30,192.10,0.055
25.32,192.29,0.055
25.34,192.47,0.055
25.36,192.65,0.055
25.37,192.84,0.055
25.39,193.02,0.055
25.41,193.20,0.055
25.43,193.38,0.055
25.45,193.57,0.055
25.47,193.75,0.055
25.48,193.94,0.055
25.50,194.12,0.055
25.52,194.30,0.055
25.54,194.49,0.055
25.56,194.67,0.055
25.58,194.85,0.055
25.59,195.04,0.055
25.61,195.22,0.055
25.63,195.40,0.055
25.65,195.59,0.055
25.67,195.77,0.055
25.68,195.95,0.055
25.70,196.14,0.055
25.72,196.32,0.055
25.74,196.50,0.055
25.76,196.69,0.055
25.78,196.87,0.055
25.79,197.05,0.055
25.81,197.24,0.055
25.83,197.42,0.055
25.85,197.61,0.055
25.87,197.79,0.055
25.89,197.97,0.055
25.91,198.15,0.055
25.92,198.34,0.055
25.94,198.52,
25.96,198.71,
25.98,198.89,
25.99,,

[step]
Ramp 10.00 °C/min to -60.00 °C
Time,Temperature,Heat Flow (Normalized)
min,°C,W/g
26.99,200.14,-0.037
27.01,200.14,-0.037
27.03,200.13,-0.037
27.05,200.12,-0.037
27.07,200.09,-0.037
27.08,200.03,-0.040
27.10,199.95,-0.049
27.12,199.83,-0.061
27.14,199.69,-0.074
27.16,199.54,-0.086
27.18,199.38,-0.096
27.19,199.20,-0.105
27.21,199.03,-0.108
27.23,198.85,-0.114
27.25,198.67,-0.116
27.27,198.49,-0.118
27.29,198.31,-0.119
27.31,198.13,-0.120
27.32,197.95,-0.120
27.34,197.77,-0.121
27.36,197.59,-0.121
27.38,197.41,-0.121
27.40,197.22,-0.121
27.42,197.04,-0.122
27.43,196.86,-0.122
27.45,196.68,-0.123
27.47,196.50,-0.123
27.49,196.32,-0.123
27.51,196.13,-0.124
27.53,195.95,-0.124
27.54,195.77,-0.124
27.56,195.59,-0.125
27.58,195.41,-0.125
27.60,195.23,-0.125
27.62,195.05,-0.126
27.63,194.86,-0.126
27.65,194.68,-0.126
27.67,194.50,-0.126
27.69,194.32,-0.127
27.71,194.14,-0.127
27.73,193.95,-0.127
27.74,193.77,-0.127
27.76,193.59,-0.128
27.78,193.41,-0.128
27.80,193.22,-0.128
27.82,193.04,-0.128
27.84,192.86,-0.128
27.86,192.68,-0.128
27.87,192.49,-0.128
27.89,192.31,-0.129
27.91,192.13,-0.129
27.93,191.95,-0.129
27.95,191.76,-0.129
27.97,191.58,-0.129
27.98,191.40,-0.129
28.00,191.22,-0.129
28.02,191.03,-0.129
28.04,190.85,-0.129
28.06,190.67,-0.129
28.08,190.49,-0.129
28.09,190.30,-0.129
28.11,190.12,-0.129
28.13,189.94,-0.129
28.15,189.76,-0.129
28.17,189.57,-0.129
28.18,189.39,-0.129
28.20,189.21,-0.130
28.22,189.02,-0.129
28.24,188.84,-0.129
28.26,188.66,-0.129
28.28,188.47,-0.130
28.29,188.29,-0.129
28.31,188.11,-0.129
28.33,187.93,-0.129
28.35,187.74,-0.129
28.37,187.56,-0.129
28.39,187.38,-0.129
28.41,187.19,-0.129
28.42,187.01,-0.129
28.44,186.83,-0.129
28.46,186.64,-0.129
28.48,186.46,-0.129
28.50,186.28,-0.129
28.52,186.10,-0.129
28.53,185.91,-0.129
28.55,185.73,-0.129
28.57,185.55,-0.129
28.59,185.36,-0.129
28.61,185.18,-0.129
28.63,185.00,-0.129
28.64,184.82,-0.129
28.66,184.63,-0.129
28.68,184.45,-0.129
28.70,184.27,-0.129
28.72,184.08,-0.129
28.73,183.90,-0.129
28.75,183.72,-0.129
28.77,183.53,-0.129
28.79,183.35,-0.129
28.81,183.17,-0.129
28.83,182.98,-0.129
28.84,182.80,-0.129
28.86,182.62,-0.129
28.88,182.43,-0.128
28.90,182.25,-0.128
28.92,182.07,-0.128
28.94,181.88,-0.128
28.96,181.70,-0.128
28.97,181.52,-0.128
28.99,181.33,-0.128
29.01,181.15,-0.128
29.03,180.97,-0.128
29.05,180.79,-0.128
29.07,180.60,-0.128
29.08,180.42,-0.128
29.10,180.24,-0.128
29.12,180.05,-0.128
29.14,179.87,-0.128
29.16,179.69,-0.128
29.18,179.50,-0.128
29.19,179.32,-0.128
29.21,179.14,-0.128
29.23,178.95,-0.127
29.25,178.77,-0.127
29.27,178.59,-0.127
29.28,178.40,-0.127
29.30,178.22,-0.127
29.32,178.04,-0.127
29.34,177.85,-0.127
29.36,177.67,-0.127
29.38,177.49,-0.127
29.39,177.30,-0.127
29.41,177.12,-0.127
29.43,176.94,-0.127
29.45,176.75,-0.127
29.47,176.57,-0.127
29.49,176.39,-0.127
29.51,176.20,-0.127
29.52,176.02,-0.127
29.54,175.84,-0.127
29.56,175.65,-0.127
29.58,175.47,-0.127
29.60,175.29,-0.127
29.62,175.10,-0.127
29.63,174.92,-0.126
29.65,174.74,-0.126
29.67,174.55,-0.126
29.69,174.37,-0.126
29.71,174.19,-0.126
29.73,174.01,-0.126
29.74,173.82,-0.126
29.76,173.64,-0.126
29.78,173.45,-0.126
29.80,173.27,-0.126
29.82,173.09,-0.126
29.83,172.90,-0.126
29.85,172.72,-0.126
29.87,172.54,-0.126
29.89,172.35,-0.126
29.91,172.17,-0.126
29.93,171.99,-0.126
29.94,171.80,-0.126
29.96,171.62,-0.126
29.98,171.44,-0.126
30.00,171.26,-0.126
30.02,171.07,-0.126
30.04,170.89,-0.126
30.06,170.70,-0.126
30.07,170.52,-0.126
30.09,170.34,-0.126
30.11,170.16,-0.126
30.13,169.97,-0.126
30.15,169.79,-0.126
30.17,169.61,-0.126
30.18,169.42,-0.126
30.20,169.24,-0.126
30.22,169.06,-0.126
30.24,168.87,-0.126
30.26,168.69,-0.126
30.28,168.51,-0.126
30.29,168.32,-0.126
30.31,168.14,-0.126
30.33,167.96,-0.126
30.35,167.77,-0.126
30.37,167.59,-0.126
30.38,167.41,-0.126
30.40,167.22,-0.126
30.42,167.04,-0.126
30.44,166.86,-0.126
30.46,166.67,-0.126
30.48,166.49,-0.126
30.49,166.31,-0.126
30.51,166.12,-0.126
30.53,165.94,-0.126
30.55,165.76,-0.126
30.57,165.57,-0.126
30.59,165.39,-0.126
30.61,165.21,-0.126
30.62,165.02,-0.126
30.64,164.84,-0.126
30.66,164.66,-0.126
30.68,164.48,-0.126
30.70,164.29,-0.126
30.72,164.11,-0.126
30.73,163.92,-0.126
30.75,163.74,-0.126
30.77,163.56,-0.126
30.79,163.38,-0.126
30.81,163.19,-0.126
30.83,163.01,-0.126
30.84,162.83,-0.126
30.86,162.64,-0.125
30.88,162.46,-0.126
30.90,162.28,-0.125
30.92,162.09,-0.125
30.93,161.91,-0.125
30.95,161.73,-0.125
30.97,161.54,-0.125
30.99,161.36,-0.125
31.01,161.18,-0.125
31.03,160.99,-0.125
31.04,160.81,-0.125
31.06,160.63,-0.125
31.08,160.44,-0.125
31.10,160.26,-0.125
31.12,160.07,-0.125
31.14,159.89,-0.125
31.16,159.71,-0.125
31.17,159.53,-0.125
31.19,159.34,-0.125
31.21,159.16,-0.125
31.23,158.97,-0.125
31.25,158.79,-0.125
31.27,158.61,-0.125
31.28,158.43,-0.125
31.30,158.24,-0.125
31.32,158.06,-0.125
31.34,157.88,-0.125
31.36,157.69,-0.125
31.38,157.51,-0.125
31.39,157.33,-0.125
31.41,157.14,-0.125
31.43,156.96,-0.125
31.45,156.78,-0.125
31.47,156.59,-0.125
31.48,156.41,-0.125
31.50,156.23,-0.125
31.52,156.04,-0.125
31.54,155.86,-0.125
31.56,155.68,-0.125
31.58,155.49,-0.125
31.59,155.31,-0.125
31.61,155.13,-0.125
31.63,154.94,-0.125
31.65,154.76,-0.125
31.67,154.58,-0.125
31.69,154.39,-0.125
31.71,154.21,-0.125
31.72,154.03,-0.233
31.74,153.97,-2.957
31.76,154.06,-4.180
31.78,154.08,-4.258
31.80,154.03,-4.208
31.82,153.93,-3.747
31.83,153.74,-3.186
31.85,153.53,-2.900
31.87,153.22,-0.946
31.89,152.86,-0.415
31.91,152.54,-0.281
31.93,152.25,-0.227
31.94,152.00,-0.196
31.96,151.77,-0.177
31.98,151.55,-0.162
32.00,151.34,-0.151
32.02,151.14,-0.144
32.03,150.94,-0.139
32.05,150.75,-0.135
32.07,150.56,-0.132
32.09,150.37,-0.130
32.11,150.19,-0.130
32.13,150.00,-0.129
32.14,149.82,-0.129
32.16,149.63,-0.128
32.18,149.45,-0.128
32.20,149.26,-0.127
32.22,149.08,-0.127
32.24,148.90,-0.127
32.26,148.71,-0.127
32.27,148.53,-0.126
32.29,148.35,-0.126
32.31,148.16,-0.126
32.33,147.98,-0.126
32.35,147.80,-0.126
32.37,147.61,-0.126
32.38,147.43,-0.126
32.40,147.25,-0.126
32.42,147.06,-0.126
32.44,146.88,-0.126
32.46,146.70,-0.126
32.48,146.51,-0.126
32.49,146.33,-0.126
32.51,146.15,-0.125
32.53,145.96,-0.125
32.55,145.78,-0.125
32.57,145.60,-0.125
32.58,145.41,-0.125
32.60,145.23,-0.125
32.62,145.05,-0.125
32.64,144.86,-0.125
32.66,144.68,-0.125
32.68,144.50,-0.125
32.69,144.31,-0.125
32.71,144.13,-0.125
32.73,143.95,-0.125
32.75,143.76,-0.125
32.77,143.58,-0.125
32.79,143.40,-0.125
32.81,143.22,-0.125
32.82,143.03,-0.125
32.84,142.85,-0.125
32.86,142.67,-0.125
32.88,142.48,-0.125
32.90,142.30,-0.125
32.92,142.12,-0.125
32.93,141.93,-0.125
32.95,141.75,-0.125
32.97,141.57,-0.125
32.99,141.38,-0.125
33.01,141.20,-0.125
33.03,141.02,-0.125
33.04,140.83,-0.125
33.06,140.65,-0.125
33.08,140.47,-0.125
33.10,140.28,-0.125
33.12,140.10,-0.125
33.13,139.92,-0.125
33.15,139.73,-0.125
33.17,139.55,-0.125
33.19,139.37,-0.125
33.21,139.18,-0.125
33.23,139.00,-0.125
33.24,138.82,-0.125
33.26,138.63,-0.125
33.28,138.45,-0.125
33.30,138.27,-0.125
33.32,138.08,-0.125
33.34,137.90,-0.125
33.36,137.71,-0.125
33.37,137.53,-0.125
33.39,137.35,-0.125
33.41,137.17,-0.125
33.43,136.98,-0.125
33.45,136.80,-0.125
33.47,136.62,-0.125
33.48,136.43,-0.125
33.50,136.25,-0.125
33.52,136.07,-0.125
33.54,135.88,-0.125
33.56,135.70,-0.125
33.58,135.52,-0.125
33.59,135.33,-0.125
33.61,135.15,-0.125
33.63,134.97,-0.125
33.65,134.78,-0.124
33.67,134.60,-0.124
33.68,134.42,-0.124
33.70,134.23,-0.124
33.72,134.05,-0.124
33.74,133.87,-0.124
33.76,133.68,-0.124
33.78,133.50,-0.124
33.79,133.32,-0.124
33.81,133.13,-0.124
33.83,132.95,-0.124
33.85,132.77,-0.124
33.87,132.58,-0.124
33.89,132.40,-0.124
33.91,132.22,-0.124
33.92,132.03,-0.124
33.94,131.85,-0.124
33.96,131.67,-0.124
33.98,131.48,-0.124
34.00,131.30,-0.124
34.02,131.12,-0.124
34.03,130.94,-0.124
34.05,130.75,-0.124
34.07,130.57,-0.124
34.09,130.38,-0.124
34.11,130.20,-0.124
34.13,130.02,-0.124
34.14,129.83,-0.124
34.16,129.65,-0.124
34.18,129.47,-0.124
34.20,129.29,-0.124
34.22,129.10,-0.124
34.24,128.92,-0.124
34.25,128.74,-0.124
34.27,128.55,-0.124
34.29,128.37,-0.124
34.31,128.19,-0.124
34.33,128.00,-0.124
34.34,127.82,-0.124
34.36,127.63,-0.124
[...]
115.21,11.08,0.048
115.23,11.26,0.048
115.25,11.45,0.048
115.27,11.63,0.048
115.29,11.81,0.048
115.31,12.00,0.048
115.33,12.18,0.048
115.34,12.36,0.048
115.36,12.55,0.048
115.38,12.73,0.048
115.40,12.92,0.048
115.42,13.10,0.048
115.44,13.28,0.048
115.45,13.47,0.048
115.47,13.65,0.048
115.49,13.83,0.048
115.51,14.02,0.048
115.53,14.20,0.048
115.55,14.38,0.048
115.56,14.57,0.048
115.58,14.75,0.048
115.60,14.93,0.048
115.62,15.12,0.048
115.64,15.30,0.048
115.65,15.48,0.048
115.67,15.67,0.048
115.69,15.85,0.048
115.71,16.03,0.048
115.73,16.22,0.048
115.75,16.40,0.048
115.76,16.59,0.048
115.78,16.77,0.048
115.80,16.95,0.048
115.82,17.14,0.048
115.84,17.32,0.048
115.86,17.50,0.048
115.88,17.69,0.048
115.89,17.87,0.048
115.91,18.05,0.048
115.93,18.24,0.048
115.95,18.42,0.048
115.97,18.60,0.048
115.99,18.79,0.048
116.00,18.97,0.048
116.02,19.15,0.048
116.04,19.34,0.048
116.06,19.52,0.048
116.08,19.70,0.048
116.10,19.89,0.048
116.11,20.07,0.048
116.13,20.26,0.048
116.15,20.44,0.048
116.17,20.62,0.048
116.19,20.81,0.048
116.20,20.99,0.048
116.22,21.17,0.048
116.24,21.36,0.048
116.26,21.54,0.047
116.28,21.72,0.047
116.30,21.91,0.047
116.31,22.09,0.048
116.33,22.27,0.048
116.35,22.46,0.048
116.37,22.64,0.048
116.39,22.82,0.047
116.41,23.01,0.047
116.43,23.19,0.047
116.44,23.38,0.047
116.46,23.56,0.047
116.48,23.74,0.047
116.50,23.93,0.047
116.52,24.11,0.047
116.54,24.29,0.047
116.55,24.48,0.047
116.57,24.66,0.047
116.59,24.84,0.047
116.61,25.03,0.047
116.63,25.21,0.047
116.65,25.39,0.047
116.66,25.58,0.047
116.68,25.76,0.047
116.70,25.94,0.047
116.72,26.13,0.047
116.74,26.31,0.047
116.75,26.49,0.047
116.77,26.68,0.047
116.79,26.86,0.047
116.81,27.05,0.047
116.83,27.23,0.047
116.85,27.41,0.047
116.86,27.60,0.047
116.88,27.78,0.047
116.90,27.96,0.047
116.92,28.15,0.047
116.94,28.33,0.047
116.96,28.51,0.047
116.98,28.70,0.047
116.99,28.88,0.047
117.01,29.06,0.047
117.03,29.25,0.047
117.05,29.43,0.047
117.07,29.61,0.047
117.09,29.80,0.047
117.10,29.98,0.047
117.12,30.16,0.047
117.14,30.35,0.047
117.16,30.53,0.047
117.18,30.72,0.047
117.20,30.90,0.047
117.21,31.08,0.047
117.23,31.27,0.047
117.25,31.45,0.047
117.27,31.63,0.047
117.29,31.82,0.047
117.30,32.00,0.047
117.32,32.18,0.047
117.34,32.37,0.047
117.36,32.55,0.047
117.38,32.73,0.047
117.40,32.92,0.047
117.41,33.10,0.047
117.43,33.29,0.047
117.45,33.47,0.047
117.47,33.65,0.047
117.49,33.84,0.047
117.51,34.02,0.047
117.53,34.20,0.047
117.54,34.39,0.047
117.56,34.57,0.047
117.58,34.75,0.047
117.60,34.94,0.047
117.62,35.12,0.047
117.64,35.30,0.047
117.65,35.49,0.047
117.67,35.67,0.047
117.69,35.85,0.047
117.71,36.04,0.047
117.73,36.22,0.047
117.75,36.41,0.047
117.76,36.59,0.047
117.78,36.77,0.047
117.80,36.96,0.047
117.82,37.14,0.047
117.84,37.32,0.047
117.85,37.51,0.047
117.87,37.69,0.047
117.89,37.87,0.047
117.91,38.06,0.047
117.93,38.24,0.047
117.95,38.42,0.047
117.96,38.61,0.047
117.98,38.79,0.047
118.00,38.97,0.047
118.02,39.16,0.047
118.04,39.34,0.047
118.06,39.53,0.047
118.08,39.71,0.047
118.09,39.89,0.047
118.11,40.08,0.047
118.13,40.26,0.047
118.15,40.44,0.047
118.17,40.63,0.047
118.19,40.81,0.047
118.20,40.99,0.047
118.22,41.18,0.047
118.24,41.36,0.047
118.26,41.54,0.047
118.28,41.73,0.047
118.30,41.91,0.047
118.31,42.09,0.047
118.33,42.28,0.047
118.35,42.46,0.047
118.37,42.64,0.047
118.39,42.83,0.047
118.40,43.01,0.047
118.42,43.20,0.047
118.44,43.38,0.047
118.46,43.56,0.047
118.48,43.75,0.047
118.50,43.93,0.047
118.51,44.11,0.047
118.53,44.30,0.047
118.55,44.48,0.047
118.57,44.66,0.047
118.59,44.85,0.047
118.61,45.03,0.047
118.63,45.21,0.047
118.64,45.40,0.047
118.66,45.58,0.047
118.68,45.76,0.047
118.70,45.95,0.047
118.72,46.13,0.047
118.74,46.31,0.047
118.75,46.50,0.047
118.77,46.68,0.047
118.79,46.86,0.047
118.81,47.05,0.047
118.83,47.23,0.047
118.85,47.41,0.047
118.86,47.60,0.047
118.88,47.78,0.047
118.90,47.97,0.047
118.92,48.15,0.047
118.94,48.33,0.047
118.95,48.52,0.047
118.97,48.70,0.047
118.99,48.88,0.047
119.01,49.07,0.047
119.03,49.25,0.047
119.05,49.43,0.047
119.06,49.62,0.047
119.08,49.80,0.047
119.10,49.99,0.047
119.12,50.17,0.047
119.14,50.35,0.047
119.16,50.53,0.047
119.18,50.72,0.047
119.19,50.90,0.047
119.21,51.09,0.047
119.23,51.27,0.047
119.25,51.45,0.047
119.27,51.64,0.047
119.29,51.82,0.047
119.30,52.00,0.047
119.32,52.19,0.047
119.34,52.37,0.047
119.36,52.55,0.047
119.38,52.74,0.047
119.40,52.92,0.047
119.41,53.11,0.047
119.43,53.29,0.047
119.45,53.47,0.047
119.47,53.66,0.047
119.49,53.84,0.047
119.50,54.02,0.047
119.52,54.21,0.047
119.54,54.39,0.047
119.56,54.57,0.047
119.58,54.76,0.047
119.60,54.94,0.047
119.61,55.12,0.047
119.63,55.31,0.047
119.65,55.49,0.047
119.67,55.67,0.047
119.69,55.86,0.047
119.71,56.04,0.047
119.73,56.22,0.047
119.74,56.41,0.047
119.76,56.59,0.047
119.78,56.77,0.047
119.80,56.96,0.047
119.82,57.14,0.047
119.84,57.33,0.047
119.85,57.51,0.047
119.87,57.69,0.047
119.89,57.88,0.047
119.91,58.06,0.047
119.93,58.24,0.047
119.95,58.43,0.047
119.96,58.61,0.047
119.98,58.79,0.047
120.00,58.98,0.047
120.02,59.16,0.047
120.04,59.34,0.047
120.05,59.53,0.047
120.07,59.71,0.047
120.09,59.90,0.047
120.11,60.08,0.047
120.13,60.26,0.047
120.15,60.45,0.047
120.16,60.63,0.047
120.18,60.81,0.047
120.20,61.00,0.047
120.22,61.18,0.047
120.24,61.36,0.047
120.26,61.55,0.047
120.28,61.73,0.047
120.29,61.91,0.047
120.31,62.10,0.047
120.33,62.28,0.047
120.35,62.47,0.047
120.37,62.65,0.047
120.39,62.83,0.047
120.40,63.02,0.047
120.42,63.20,0.047
120.44,63.38,0.047
120.46,63.57,0.047
120.48,63.75,0.047
120.50,63.93,0.047
120.51,64.12,0.047
120.53,64.30,0.047
120.55,64.48,0.047
120.57,64.67,0.047
120.59,64.85,0.047
120.60,65.03,0.047
120.62,65.22,0.047
120.64,65.40,0.047
120.66,65.58,0.047
120.68,65.77,0.047
120.70,65.95,0.047
120.71,66.13,0.047
120.73,66.32,0.047
120.75,66.50,0.047
120.77,66.68,0.047
120.79,66.87,0.047
120.81,67.05,0.047
120.83,67.23,0.047
120.84,67.42,0.047
120.86,67.60,0.047
120.88,67.78,0.047
120.90,67.97,0.047
120.92,68.15,0.047
120.94,68.33,0.047
120.95,68.52,0.047
120.97,68.70,0.047
120.99,68.88,0.047
121.01,69.07,0.047
121.03,69.25,0.047
121.05,69.44,0.047
121.06,69.62,0.047
121.08,69.80,0.047
121.10,69.99,0.047
121.12,70.17,0.047
121.14,70.35,0.047
121.15,70.54,0.047
121.17,70.72,0.047
121.19,70.90,0.047
121.21,71.09,0.047
121.23,71.27,0.047
121.25,71.45,0.047
121.26,71.64,0.047
121.28,71.82,0.047
121.30,72.00,0.047
121.32,72.19,0.047
121.34,72.37,0.047
121.36,72.55,0.047
121.38,72.74,0.047
121.39,72.92,0.047
121.41,73.11,0.047
121.43,73.29,0.047
121.45,73.47,0.047
121.47,73.66,0.047
121.49,73.84,0.047
121.50,74.02,0.047
121.52,74.21,0.047
121.54,74.39,0.047
121.56,74.57,0.047
121.58,74.76,0.047
121.60,74.94,0.047
121.61,75.12,0.047
121.63,75.31,0.047
121.65,75.49,0.047
121.67,75.68,0.047
121.69,75.86,0.047
121.70,76.04,0.047
121.72,76.23,0.047
121.74,76.41,0.047
121.76,76.59,0.047
121.78,76.78,0.047
121.80,76.96,0.047
121.81,77.14,0.047
121.83,77.33,0.047
121.85,77.51,0.047
121.87,77.69,0.047
121.89,77.88,0.047
121.91,78.06,0.047
121.93,78.24,0.047
121.94,78.43,0.047
121.96,78.61,0.047
121.98,78.79,0.047
122.00,78.98,0.047
122.02,79.16,0.047
122.04,79.35,0.047
122.05,79.53,0.047
122.07,79.71,0.047
122.09,79.90,0.047
122.11,80.08,0.047
122.13,80.26,0.047
122.15,80.45,0.047
122.16,80.63,0.047
122.18,80.82,0.047
122.20,81.00,0.047
122.22,81.18,0.047
122.24,81.37,0.047
122.25,81.55,0.047
122.27,81.73,0.047
122.29,81.92,0.047
122.31,82.10,0.047
122.33,82.28,0.047
122.35,82.46,0.047
122.36,82.65,0.047
122.38,82.83,0.047
122.40,83.02,0.047
122.42,83.20,0.047
122.44,83.38,0.047
122.46,83.57,0.047
122.48,83.75,0.047
122.49,83.93,0.047
122.51,84.11,0.047
122.53,84.30,0.047
122.55,84.48,0.047
122.57,84.66,0.047
122.59,84.85,0.047
122.60,85.03,0.047
122.62,85.22,0.047
122.64,85.40,0.047
122.66,85.58,0.047
122.68,85.77,0.047
122.70,85.95,0.047
122.71,86.13,0.047
122.73,86.32,0.047
122.75,86.50,0.047
122.77,86.68,0.047
122.79,86.87,0.047
122.80,87.05,0.047
122.82,87.23,0.047
122.84,87.42,0.047
122.86,87.60,0.047
122.88,87.79,0.047
122.90,87.97,0.047
122.91,88.15,0.047
122.93,88.34,0.047
122.95,88.52,0.047
122.97,88.70,0.047
122.99,88.89,0.047
123.01,89.07,0.047
123.03,89.25,0.047
123.04,89.44,0.047
123.06,89.62,0.047
123.08,89.80,0.047
123.10,89.99,0.047
123.12,90.17,0.047
123.14,90.35,0.047
123.15,90.54,0.047
123.17,90.72,0.047
123.19,90.90,0.047
123.21,91.09,0.047
123.23,91.27,0.047
123.25,91.45,0.047
123.26,91.64,0.047
123.28,91.82,0.047
123.30,92.01,0.047
123.32,92.19,0.047
123.34,92.37,0.047
123.35,92.56,0.047
123.37,92.74,0.047
123.39,92.92,0.047
123.41,93.10,0.047
123.43,93.29,0.047
123.45,93.47,0.047
123.46,93.66,0.047
123.48,93.84,0.047
123.50,94.02,0.047
123.52,94.21,0.047
123.54,94.39,0.047
123.56,94.57,0.047
123.58,94.76,0.047
123.59,94.94,0.047
123.61,95.13,0.047
123.63,95.31,0.047
123.65,95.49,0.047
123.67,95.67,0.047
123.69,95.86,0.047
123.70,96.04,0.047
123.72,96.22,0.047
123.74,96.41,0.047
123.76,96.59,0.047
123.78,96.78,0.047
123.80,96.96,0.047
123.81,97.14,0.047
123.83,97.33,0.047
123.85,97.51,0.047
123.87,97.69,0.047
123.89,97.88,0.047
123.90,98.06,0.047
123.92,98.24,0.047
123.94,98.43,0.047
123.96,98.61,0.047
123.98,98.79,0.047
124.00,98.98,0.047
124.01,99.16,0.047
124.03,99.34,0.047
124.05,99.53,0.047
124.07,99.71,0.047
124.09,99.89,0.047
124.11,100.08,0.047
124.13,100.26,0.047
124.14,100.45,0.047
124.16,100.63,0.047
124.18,100.81,0.047
124.20,101.00,0.047
124.22,101.18,0.047
124.24,101.36,0.047
124.25,101.54,0.047
124.27,101.73,0.047
124.29,101.91,0.047
124.31,102.10,0.047
124.33,102.28,0.047
124.35,102.46,0.047
124.36,102.65,0.047
124.38,102.83,0.047
124.40,103.01,0.047
124.42,103.20,0.047
124.44,103.38,0.047
124.45,103.56,0.047
124.47,103.75,0.047
124.49,103.93,0.047
124.51,104.11,0.047
124.53,104.30,0.047
124.55,104.48,0.047
124.56,104.66,0.047
124.58,104.85,0.047
124.60,105.03,0.047
124.62,105.22,0.047
124.64,105.40,0.047
124.66,105.58,0.047
124.68,105.76,0.047
124.69,105.95,0.047
124.71,106.13,0.047
124.73,106.32,0.047
124.75,106.50,0.047
124.77,106.68,0.047
124.79,106.87,0.047
124.80,107.05,0.048
124.82,107.23,0.048
124.84,107.41,0.048
124.86,107.60,0.048
124.88,107.78,0.048
124.90,107.97,0.048
124.91,108.15,0.048
124.93,108.33,0.048
124.95,108.52,0.048
124.97,108.70,0.048
124.99,108.89,0.048
125.00,109.07,0.048
125.02,109.25,0.048
125.04,109.44,0.048
125.06,109.62,0.048
125.08,109.80,0.048
125.10,109.99,0.048
125.11,110.17,0.048
125.13,110.35,0.048
125.15,110.53,0.048
125.17,110.72,0.048
125.19,110.90,0.048
125.21,111.09,0.048
125.23,111.27,0.048
125.24,111.45,0.048
125.26,111.64,0.048
125.28,111.82,0.048
125.30,112.00,0.048
125.32,112.19,0.048
125.34,112.37,0.048
125.35,112.55,0.048
125.37,112.74,0.048
125.39,112.92,0.048
125.41,113.10,0.048
125.43,113.29,0.048
125.45,113.47,0.048
125.46,113.65,0.048
125.48,113.84,0.048
125.50,114.02,0.048
125.52,114.20,0.048
125.54,114.39,0.048
125.55,114.57,0.048
125.57,114.75,0.048
125.59,114.94,0.048
125.61,115.12,0.048
125.63,115.30,0.048
125.65,115.49,0.048
125.66,115.67,0.048
125.68,115.85,0.048
125.70,116.04,0.048
125.72,116.22,0.048
125.74,116.41,0.048
125.76,116.59,0.048
125.78,116.77,0.048
125.79,116.96,0.048
125.81,117.14,0.048
125.83,117.32,0.048
125.85,117.50,0.048
125.87,117.69,0.048
125.89,117.87,0.048
125.90,118.06,0.048
125.92,118.24,0.048
125.94,118.42,0.048
125.96,118.61,0.048
125.98,118.79,0.048
126.00,118.97,0.048
126.01,119.16,0.048
126.03,119.34,0.048
126.05,119.52,0.048
126.07,119.71,0.048
126.09,119.89,0.048
126.10,120.07,0.048
126.12,120.26,0.048
126.14,120.44,0.048
126.16,120.62,0.048
126.18,120.81,0.048
126.20,120.99,0.048
126.21,121.18,0.048
126.23,121.36,0.048
126.25,121.54,0.048
126.27,121.73,0.048
126.29,121.91,0.048
126.31,122.09,0.048
126.33,122.28,0.049
126.34,122.46,0.049
126.36,122.64,0.049
126.38,122.83,0.049
126.40,123.01,0.049
126.42,123.19,0.049
126.44,123.38,0.049
126.45,123.56,0.049
126.47,123.74,0.049
126.49,123.93,0.049
126.51,124.11,0.049
126.53,124.29,0.049
126.55,124.48,0.049
126.56,124.66,0.049
126.58,124.85,0.049
126.60,125.03,0.049
126.62,125.21,0.049
126.64,125.40,0.049
126.65,125.58,0.049
126.67,125.76,0.049
126.69,125.95,0.049
126.71,126.13,0.049
126.73,126.31,0.049
126.75,126.50,0.049
126.76,126.68,0.049
126.78,126.86,0.049
126.80,127.05,0.049
126.82,127.23,0.049
126.84,127.41,0.049
126.86,127.60,0.049
126.88,127.78,0.049
126.89,127.96,0.049
126.91,128.15,0.049
126.93,128.33,0.049
126.95,128.51,0.049
126.97,128.70,0.049
126.99,128.88,0.049
127.00,129.06,0.049
127.02,129.25,0.049
127.04,129.43,0.049
127.06,129.61,0.049
127.08,129.80,0.049
127.10,129.98,0.049
127.11,130.16,0.049
127.13,130.35,0.049
127.15,130.53,0.049
127.17,130.71,0.049
127.19,130.90,0.049
127.20,131.08,0.049
127.22,131.26,0.049
127.24,131.45,0.049
127.26,131.63,0.049
127.28,131.82,0.049
127.30,132.00,0.049
127.31,132.18,0.049
127.33,132.37,0.049
127.35,132.55,0.049
127.37,132.73,0.049
127.39,132.92,0.049
127.41,133.10,0.049
127.43,133.28,0.049
127.44,133.47,0.049
127.46,133.65,0.050
127.48,133.83,0.050
127.50,134.02,0.050
127.52,134.20,0.050
127.54,134.38,0.050
127.55,134.57,0.050
127.57,134.75,0.050
127.59,134.93,0.050
127.61,135.12,0.050
127.63,135.30,0.050
127.65,135.49,0.050
127.66,135.67,0.050
127.68,135.85,0.050
127.70,136.04,0.050
127.72,136.22,0.050
127.74,136.40,0.050
127.75,136.58,0.050
127.77,136.77,0.050
127.79,136.95,0.050
127.81,137.14,0.050
127.83,137.32,0.050
127.85,137.50,0.050
127.86,137.69,0.050
127.88,137.87,0.050
127.90,138.05,0.050
127.92,138.24,0.050
127.94,138.42,0.050
127.96,138.60,0.050
127.98,138.79,0.050
127.99,138.97,0.050
128.01,139.16,0.050
128.03,139.34,0.050
128.05,139.52,0.050
128.07,139.70,0.050
128.09,139.89,0.050
128.10,140.07,0.050
128.12,140.25,0.050
128.14,140.44,0.050
128.16,140.62,0.050
128.18,140.80,0.050
128.20,140.99,0.050
128.21,141.17,0.050
128.23,141.35,0.050
128.25,141.54,0.050
128.27,141.72,0.050
128.29,141.91,0.050
128.30,142.09,0.050
128.32,142.27,0.050
128.34,142.45,0.050
128.36,142.64,0.050
128.38,142.82,0.050
128.40,143.01,0.050
128.41,143.19,0.050
128.43,143.37,0.050
128.45,143.56,0.050
128.47,143.74,0.050
128.49,143.92,0.050
128.51,144.11,0.050
128.53,144.29,0.050
128.54,144.47,0.050
128.56,144.66,0.050
128.58,144.84,0.050
128.60,145.02,0.050
128.62,145.21,0.050
128.64,145.39,0.050
128.65,145.57,0.050
128.67,145.76,0.050
128.69,145.94,0.051
128.71,146.12,0.050
128.73,146.31,0.051
128.75,146.49,0.051
128.76,146.67,0.051
128.78,146.86,0.051
128.80,147.04,0.051
128.82,147.23,0.051
128.84,147.41,0.051
128.85,147.59,0.051
128.87,147.78,0.051
128.89,147.96,0.051
128.91,148.14,0.051
128.93,148.33,0.051
128.95,148.51,0.051
128.96,148.69,0.051
128.98,148.88,0.051
129.00,149.06,0.051
129.02,149.24,0.051
129.04,149.43,0.051
129.06,149.61,0.051
129.08,149.79,0.051
129.09,149.98,0.051
129.11,150.16,0.051
129.13,150.34,0.051
129.15,150.53,0.051
129.17,150.71,0.051
129.19,150.89,0.051
129.20,151.08,0.051
129.22,151.26,0.051
129.24,151.44,0.051
129.26,151.63,0.051
129.28,151.81,0.051
129.30,151.99,0.051
129.31,152.18,0.051
129.33,152.36,0.051
129.35,152.55,0.051
129.37,152.73,0.051
129.39,152.91,0.051
129.40,153.10,0.051
129.42,153.28,0.051
129.44,153.46,0.051
129.46,153.65,0.051
129.48,153.83,0.051
129.50,154.02,0.052
129.51,154.20,0.052
129.53,154.38,0.052
129.55,154.56,0.052
129.57,154.75,0.052
129.59,154.93,0.052
129.61,155.11,0.052
129.63,155.30,0.052
129.64,155.48,0.052
129.66,155.66,0.052
129.68,155.85,0.052
129.70,156.03,0.052
129.72,156.21,0.052
129.74,156.40,0.052
129.75,156.58,0.053
129.77,156.76,0.083
129.79,156.93,0.235
129.81,157.09,0.459
129.83,157.23,0.690
129.85,157.36,0.906
129.86,157.50,1.128
129.88,157.62,1.371
129.90,157.75,1.584
129.92,157.88,1.776
129.94,158.02,1.971
129.95,158.15,2.182
129.97,158.28,2.360
129.99,158.42,2.509
130.01,158.57,2.544
130.03,158.77,2.147
130.05,158.99,1.947
130.06,159.24,1.212
130.08,159.55,0.684
130.10,159.83,0.466
130.12,160.08,0.339
130.14,160.31,0.254
130.16,160.53,0.194
130.18,160.74,0.153
130.19,160.94,0.123
130.21,161.14,0.103
130.23,161.33,0.087
130.25,161.52,0.077
130.27,161.71,0.070
130.29,161.89,0.065
130.30,162.08,0.062
130.32,162.26,0.058
130.34,162.45,0.057
130.36,162.63,0.056
130.38,162.82,0.056
130.40,163.00,0.055
130.41,163.18,0.055
130.43,163.37,0.055
130.45,163.55,0.054
130.47,163.74,0.054
130.49,163.92,0.053
130.50,164.10,0.053
130.52,164.29,0.053
130.54,164.47,0.053
130.56,164.65,0.053
130.58,164.84,0.053
130.60,165.02,0.053
130.61,165.20,0.053
130.63,165.39,0.053
130.65,165.57,0.053
130.67,165.76,0.053
130.69,165.94,0.053
130.71,166.12,0.053
130.73,166.31,0.053
130.74,166.49,0.053
130.76,166.67,0.053
130.78,166.86,0.053
130.80,167.04,0.053
130.82,167.22,0.053
130.84,167.41,0.053
130.85,167.59,0.052
130.87,167.77,0.052
130.89,167.95,0.052
130.91,168.14,0.052
130.93,168.32,0.052
130.95,168.50,0.052
130.96,168.69,0.052
130.98,168.87,0.052
131.00,169.05,0.052
131.02,169.24,0.052
131.04,169.42,0.052
131.05,169.60,0.052
131.07,169.79,0.052
131.09,169.97,0.052
131.11,170.16,0.052
131.13,170.34,0.052
131.15,170.52,0.052
131.16,170.71,0.052
131.18,170.89,0.052
131.20,171.07,0.052
131.22,171.26,0.052
131.24,171.44,0.052
131.26,171.62,0.052
131.28,171.81,0.052
131.29,171.99,0.052
131.31,172.17,0.052
131.33,172.36,0.052
131.35,172.54,0.052
131.37,172.72,0.053
131.39,172.91,0.053
131.40,173.09,0.053
131.42,173.28,0.053
131.44,173.46,0.053
131.46,173.64,0.053
131.48,173.83,0.053
131.50,174.01,0.053
131.51,174.19,0.053
131.53,174.37,0.053
131.55,174.56,0.053
131.57,174.74,0.053
131.59,174.92,0.053
131.60,175.11,0.053
131.62,175.29,0.053
131.64,175.48,0.053
131.66,175.66,0.053
131.68,175.84,0.053
131.70,176.03,0.053
131.71,176.21,0.053
131.73,176.39,0.053
131.75,176.58,0.053
131.77,176.76,0.053
131.79,176.94,0.053
131.81,177.13,0.053
131.83,177.31,0.053
131.84,177.49,0.053
131.86,177.68,0.053
131.88,177.86,0.053
131.90,178.04,0.053
131.92,178.23,0.053
131.94,178.41,0.053
131.95,178.59,0.053
131.97,178.78,0.053
131.99,178.96,0.053
132.01,179.15,0.053
132.03,179.33,0.053
132.05,179.51,0.053
132.06,179.69,0.053
132.08,179.88,0.053
132.10,180.06,0.053
132.12,180.24,0.053
132.14,180.43,0.053
132.15,180.61,0.053
132.17,180.80,0.053
132.19,180.98,0.053
132.21,181.16,0.053
132.23,181.35,0.053
132.25,181.53,0.053
132.26,181.71,0.053
132.28,181.90,0.053
132.30,182.08,0.053
132.32,182.26,0.054
132.34,182.45,0.053
132.36,182.63,0.054
132.38,182.81,0.053
132.39,182.99,0.054
132.41,183.18,0.054
132.43,183.36,0.054
132.45,183.55,0.054
132.47,183.73,0.054
132.49,183.91,0.054
132.50,184.10,0.054
132.52,184.28,0.054
132.54,184.46,0.054
132.56,184.65,0.054
132.58,184.83,0.054
132.60,185.01,0.054
132.61,185.20,0.054
132.63,185.38,0.054
132.65,185.56,0.054
132.67,185.75,0.054
132.69,185.93,0.054
132.70,186.11,0.054
132.72,186.30,0.054
132.74,186.48,0.054
132.76,186.66,0.054
132.78,186.85,0.054
132.80,187.03,0.054
132.81,187.21,0.054
132.83,187.40,0.054
132.85,187.58,0.054
132.87,187.76,0.054
132.89,187.95,0.054
132.91,188.13,0.054
132.93,188.32,0.054
132.94,188.50,0.054
132.96,188.68,0.054
132.98,188.87,0.054
133.00,189.05,0.054
133.02,189.23,0.054
133.04,189.42,0.054
133.05,189.60,0.054
133.07,189.78,0.054
133.09,189.97,0.054
133.11,190.15,0.054
133.13,190.33,0.054
133.15,190.52,0.054
133.16,190.70,0.054
133.18,190.88,0.054
133.20,191.07,0.054
133.22,191.25,0.054
133.24,191.43,0.055
133.25,191.62,0.055
133.27,191.80,0.055
133.29,191.98,0.055
133.31,192.17,0.055
133.33,192.35,0.055
133.35,192.53,0.055
133.36,192.72,0.055
133.38,192.90,0.055
133.40,193.08,0.055
133.42,193.27,0.055
133.44,193.45,0.055
133.46,193.63,0.055
133.48,193.82,0.055
133.49,194.00,0.055
133.51,194.19,0.055
133.53,194.37,0.055
133.55,194.55,0.055
133.57,194.74,0.055
133.59,194.92,0.055
133.60,195.10,0.055
133.62,195.29,0.055
133.64,195.47,0.055
133.66,195.65,0.055
133.68,195.84,0.055
133.70,196.02,0.055
133.71,196.20,0.055
133.73,196.39,0.055
133.75,196.57,0.055
133.77,196.75,0.055
133.79,196.94,0.055
133.80,197.12,0.055
133.82,197.30,0.055
133.84,197.49,0.055
133.86,197.67,0.055
133.88,197.85,0.055
133.90,198.04,0.055
133.91,198.22,0.055
133.93,198.40,
133.95,198.59,
133.97,198.77,
133.99,,