File: DSC/2025_04_13_THC_Pro_Slurry_Heptane_n60C_200C_10Cmin_x3.csv
Filename,2025_04_13_THC_Pro_Slurry_Heptane_n60C_200C_10Cmin_x3
Instrument name,DSC2A-00468 (192.168.1.100)
Operator,Yarger
rundate,4/13/2025
Sample name,2025_04_13_THC_Pro_Slurry_Heptane_n60C_200C_10Cmin_x3
proceduresegments,Data Off ; Equilibrate -60.00 °C; Data On ; Ramp 10.00 °C/min to 200.00 °C; Data Off ; Isothermal 1.0 min; Data On ; Ramp 10.00 °C/min to -60.00 °C; Data Off ; Isothermal 1.0 min; Data On ; Ramp 10.00 °C/min to 200.00 °C; Data Off ; Isothermal 1.0 min; Data On ; Ramp 10.00 °C/min to -60.00 °C; Data Off ; Isothermal 1.0 min; Data On ; Ramp 10.00 °C/min to 200.00 °C
[File Parameters]
Run date,4/13/2025 12:44:37 PM
Trios version,5.1.1.46572
Original File Name,
Current File Name,D:\DSC2500\JYarger\2025_04_13_THC_Pro_Slurry_Heptane_n60C_200C_10Cmin_x3.tri
[Procedure]
Procedure Name,THC_Pro_n60_200C_10Cmin_x3
Sample Name,2025_04_13_THC_Pro_Slurry_Heptane_n60C_200C_10Cmin_x3
Sample Mass,3.85 mg
Reference Sample Mass,0 mg
Pan Mass,53.08 mg
Pan Number,49
Reference Pan Mass,53.32 mg
Reference Pan Number,10
Pan Type,Tzero Aluminum Hermetic
Comments,Hermetic Sealed Al DSC Consumables Pan/Lids.
Project Name,CA
Operator,Yarger
Test,Custom
Unload Max Temperature,30
Unload Min Temperature,30
Load Max Temperature,30
Load Min Temperature,30
Stop on Gas Flow Error,Yes
[Signal List]
Signal #1,Time (min)
Signal #2,Temperature (°C)
Signal #3,Heat Flow (mW)
Signal #4,Delta T (µV)
Signal #5,Delta Tzero (µV)
Signal #6,Tzero Temperature (°C)
Signal #7,Cell Purge (mL/min)
Signal #8,Heater Temp (°C)
Signal #9,Power Delivered (W)
Signal #10,Reference Junction Temperature (°C)
Signal #11,Flange Temperature (°C)
Signal #12,Heat Flow Phase (rad)
Signal #13,Total Heat Capacity (J/°C)
Signal #14,Heat Capacity (J/°C)
[Configuration]
Company Name,ASU
Instrument Name,DSC2A-00468
Instrument Type,DSC2500
Serial Number,DSC2A-00468
IP,192.168.1.100
Location of Instrument,MRRC
DisplayType,Unknown
Sample Interval ,0.1 s/pt
Selected Heat Flow,T4P
Exotherm Direction,Down
Cell Serial,DRC2-00792
Lid Type,Standard
Cooler,RCS 90
Leave Cooler on at End of Sequence,On
Gas 2,Nitrogen
Gas Selected,Channel 1
Flow Rate,50 mL/min
Secondary Purge,On
Licensed Heat Flow,Heat Flow T4P
Modulation Licensed,Yes
[Versions]
Common IDD Version,1
Cortex Version,VER 2.10.2.31
Driver,5.0.0.6
GDM Version,1.0.3.3
TouchscreenVersion,1.0.0.16145
FEP Version,1.2.1.21
FEP Bootloader,2.0.0.5
AutoSampler Version,2.1.1.26
Auto Sampler Bootloader,2.0.0.5
FCM Version,1.1.0.3
FCM Bootloader,2.0.0.5
[Experiment Logs]
Experiment Log Entry # 1,Data On set to 0
Experiment Log Entry # 3,Equilibrate Segment -60 (C) Started
Experiment Log Entry # 5,Air Cool is off.
Experiment Log Entry # 7,Data On set to 1
Experiment Log Entry # 9,Ramp Segment 10 C/min to 200 Started
Experiment Log Entry # 11,Data On set to 0
Experiment Log Entry # 13,Isothermal Segment 1 min started
Experiment Log Entry # 15,Data On set to 1
Experiment Log Entry # 17,Ramp Segment 10 C/min to -60 Started
Experiment Log Entry # 19,Data On set to 0
Experiment Log Entry # 21,Isothermal Segment 1 min started
Experiment Log Entry # 23,Data On set to 1
Experiment Log Entry # 25,Ramp Segment 10 C/min to 200 Started
Experiment Log Entry # 27,Data On set to 0
Experiment Log Entry # 29,Isothermal Segment 1 min started
Experiment Log Entry # 31,Data On set to 1
Experiment Log Entry # 33,Ramp Segment 10 C/min to -60 Started
Experiment Log Entry # 35,Data On set to 0
Experiment Log Entry # 37,Isothermal Segment 1 min started
Experiment Log Entry # 39,Data On set to 1
Experiment Log Entry # 41,Ramp Segment 10 C/min to 200 Started
[Method Log]
Method Log Entry # 1,Data Off
Method Log Entry # 2,Equilibrate -60 °C
Method Log Entry # 3,Data On
Method Log Entry # 4,(Ramp 432328) Ramp 10 °C/minute to 200 °C
Method Log Entry # 5,Data Off
Method Log Entry # 6,Isothermal 1 minutes
Method Log Entry # 7,Data On
Method Log Entry # 8,(Ramp 432332) Ramp 10 °C/minute to -60 °C
Method Log Entry # 9,Data Off
Method Log Entry # 10,Isothermal 1 minutes
Method Log Entry # 11,Data On
Method Log Entry # 12,(Ramp 432336) Ramp 10 °C/minute to 200 °C
Method Log Entry # 13,Data Off
Method Log Entry # 14,Isothermal 1 minutes
Method Log Entry # 15,Data On
Method Log Entry # 16,(Ramp 432340) Ramp 10 °C/minute to -60 °C
Method Log Entry # 17,Data Off
Method Log Entry # 18,Isothermal 1 minutes
Method Log Entry # 19,Data On
Method Log Entry # 20,(Ramp 432344) Ramp 10 °C/minute to 200 °C
Cell Serial,DRC2-00792
[T1 Calibration]
Slope,-0.008529666
Offset,9.636258
Initial Temperature,98.23
GUID,f8bfdadc-4977-4fdf-ba6d-0ba9134940c3
[TZero Calibration]
Date Applied,11/29/2022 4:06:13 PM
Description,From -89.059 °C to 396.009 °C at 20.000°C/min
Gas Type,Nitrogen
Pan Type,None
Source Files 1,C:\Users\yargerlab\Desktop\DSC Data\General\TZero_calibration_11_29_22_2nd(2).tri
Source Files 2,C:\Users\yargerlab\Desktop\DSC Data\General\TZero_calibration_11_29_22_2nd(3).tri
Delta T Offset,13.05235
Delta T Slope,-0.007271007
Delta T0 Offset,-13.69128
Delta T0 Slope,0.06063341
[Temperature Calibration]
Date Applied,11/29/2022 7:12:28 PM
Description,From 106.590 °C to 186.590 °C at 10.000°C/min
Gas Type,Nitrogen
Pan Type,Tzero Aluminum Hermetic
Source Files 1,C:\Users\yargerlab\Desktop\DSC Data\General\Indium(6).tri
Measured 1,157.391
Known 1,156.598
[Cell Constant Calibration]
Date Applied,11/29/2022 7:12:29 PM
Description,From 106.590 °C to 186.590 °C at 10.000°C/min
Gas Type,Nitrogen
Pan Type,Tzero Aluminum Hermetic
Source Files 1,C:\Users\yargerlab\Desktop\DSC Data\General\Indium(6).tri
T4P KCell,1.006051
Onset Slope,63.26126 mW/°C
[Direct Cp Calibration]
Date Applied,11/30/2022 11:04:51 AM
Description,From -79.983 °C to 298.409 °C at 10.000°C/min
Gas Type,Nitrogen
Pan Type,Tzero Aluminum Hermetic
Source Files 1,C:\Users\yargerlab\Desktop\DSC Data\General\Sapphire_Heat_Capacity_11_30_22.tri
[Rev Cp Calibration]
Date Applied,11/30/2022 1:58:51 PM
Description,From -79.996 °C to 292.812 °C at 3.000°C/min
Gas Type,Nitrogen
Pan Type,Tzero Aluminum Hermetic
Source Files 1,C:\Users\yargerlab\Desktop\DSC Data\General\Sapphire_MDSC_Calibration_11_30_22.tri
[step]
Ramp 10.00 °C/min to 200.00 °C
Time,Temperature,Heat Flow (Normalized)
min,°C,W/g
0.00,-59.69,-0.069
0.02,-59.70,-0.068
0.04,-59.71,-0.060
0.05,-59.70,-0.058
0.07,-59.68,-0.062
0.09,-59.65,-0.083
0.11,-59.59,-0.099
0.13,-59.51,-0.105
0.15,-59.41,-0.103
0.16,-59.30,-0.099
0.18,-59.17,-0.069
0.20,-59.04,-0.048
0.22,-58.90,-0.022
0.24,-58.75,0.001
0.26,-58.60,0.026
0.28,-58.44,0.044
0.29,-58.28,0.059
0.31,-58.12,0.075
0.33,-57.96,0.088
0.35,-57.79,0.097
0.37,-57.62,0.107
0.39,-57.45,0.113
0.40,-57.28,0.119
0.42,-57.11,0.125
0.44,-56.94,0.131
0.46,-56.77,0.133
0.48,-56.59,0.138
0.50,-56.41,0.141
0.51,-56.24,0.143
0.53,-56.06,0.146
0.55,-55.89,0.147
0.57,-55.71,0.149
0.59,-55.53,0.150
0.60,-55.35,0.151
0.62,-55.18,0.152
0.64,-55.00,0.152
0.66,-54.82,0.153
0.68,-54.64,0.154
0.70,-54.46,0.154
0.72,-54.28,0.155
0.73,-54.10,0.155
0.75,-53.92,0.156
0.77,-53.74,0.156
0.79,-53.56,0.157
0.81,-53.38,0.157
0.83,-53.20,0.158
0.84,-53.02,0.158
0.86,-52.84,0.158
0.88,-52.66,0.159
0.90,-52.48,0.159
0.92,-52.30,0.160
0.93,-52.12,0.160
0.95,-51.94,0.161
0.97,-51.76,0.161
0.99,-51.57,0.161
1.01,-51.39,0.162
1.03,-51.21,0.162
1.05,-51.03,0.162
1.06,-50.85,0.163
1.08,-50.67,0.163
1.10,-50.49,0.163
1.12,-50.30,0.163
1.14,-50.12,0.164
1.16,-49.94,0.164
1.17,-49.76,0.164
1.19,-49.58,0.164
1.21,-49.39,0.164
1.23,-49.21,0.165
1.25,-49.03,0.165
1.27,-48.85,0.165
1.28,-48.66,0.165
1.30,-48.48,0.165
1.32,-48.30,0.165
1.34,-48.12,0.166
1.36,-47.93,0.166
1.38,-47.75,0.166
1.39,-47.57,0.166
1.41,-47.38,0.166
1.43,-47.20,0.166
1.45,-47.02,0.166
1.47,-46.84,0.166
1.48,-46.65,0.166
1.50,-46.47,0.167
1.52,-46.29,0.167
1.54,-46.10,0.167
1.56,-45.92,0.167
1.58,-45.74,0.167
1.59,-45.56,0.167
1.61,-45.37,0.167
1.63,-45.19,0.167
1.65,-45.01,0.167
1.67,-44.82,0.167
1.69,-44.64,0.167
1.71,-44.46,0.167
1.72,-44.27,0.167
1.74,-44.09,0.167
1.76,-43.91,0.167
1.78,-43.72,0.168
1.80,-43.54,0.168
1.82,-43.36,0.168
1.83,-43.17,0.168
1.85,-42.99,0.168
1.87,-42.81,0.168
1.89,-42.62,0.168
1.91,-42.44,0.168
1.93,-42.26,0.168
1.94,-42.07,0.168
1.96,-41.89,0.168
1.98,-41.71,0.168
2.00,-41.52,0.168
2.02,-41.34,0.168
2.03,-41.16,0.168
2.05,-40.97,0.168
2.07,-40.79,0.168
2.09,-40.61,0.168
2.11,-40.42,0.168
2.13,-40.24,0.168
2.14,-40.06,0.168
2.16,-39.87,0.168
2.18,-39.69,0.168
2.20,-39.51,0.168
2.22,-39.32,0.168
2.24,-39.14,0.168
2.26,-38.95,0.168
2.27,-38.77,0.168
2.29,-38.59,0.168
2.31,-38.40,0.168
2.33,-38.22,0.168
2.35,-38.04,0.168
2.36,-37.85,0.168
2.38,-37.67,0.169
2.40,-37.49,0.169
2.42,-37.30,0.169
2.44,-37.12,0.169
2.46,-36.94,0.169
2.48,-36.75,0.169
2.49,-36.57,0.169
2.51,-36.38,0.169
2.53,-36.20,0.169
2.55,-36.02,0.169
2.57,-35.83,0.169
2.59,-35.65,0.169
2.60,-35.47,0.169
2.62,-35.28,0.169
2.64,-35.10,0.169
2.66,-34.92,0.169
2.68,-34.73,0.169
2.69,-34.55,0.169
2.71,-34.37,0.169
2.73,-34.18,0.169
2.75,-34.00,0.169
2.77,-33.81,0.169
2.79,-33.63,0.169
2.81,-33.45,0.169
2.82,-33.27,0.169
2.84,-33.08,0.169
2.86,-32.90,0.169
2.88,-32.71,0.169
2.90,-32.53,0.170
2.91,-32.35,0.170
2.93,-32.16,0.169
2.95,-31.98,0.170
2.97,-31.80,0.169
2.99,-31.61,0.169
3.01,-31.43,0.170
3.03,-31.25,0.170
3.04,-31.06,0.170
3.06,-30.88,0.170
3.08,-30.69,0.170
3.10,-30.51,0.170
3.12,-30.33,0.170
3.14,-30.14,0.170
3.15,-29.96,0.170
3.17,-29.78,0.170
3.19,-29.59,0.170
3.21,-29.41,0.170
3.23,-29.23,0.170
3.24,-29.04,0.170
3.26,-28.86,0.170
3.28,-28.68,0.170
3.30,-28.49,0.170
3.32,-28.31,0.170
3.34,-28.13,0.170
3.36,-27.94,0.170
3.37,-27.76,0.170
3.39,-27.57,0.170
3.41,-27.39,0.170
3.43,-27.21,0.170
3.45,-27.02,0.170
3.46,-26.84,0.171
3.48,-26.66,0.171
3.50,-26.47,0.171
3.52,-26.29,0.171
3.54,-26.10,0.171
3.56,-25.92,0.171
3.58,-25.74,0.171
3.59,-25.56,0.171
3.61,-25.37,0.171
3.63,-25.19,0.171
3.65,-25.00,0.171
3.67,-24.82,0.171
3.69,-24.64,0.171
3.70,-24.45,0.171
3.72,-24.27,0.171
3.74,-24.09,0.171
3.76,-23.90,0.171
3.78,-23.72,0.171
3.79,-23.54,0.171
3.81,-23.35,0.171
3.83,-23.17,0.171
3.85,-22.98,0.171
3.87,-22.80,0.172
3.89,-22.62,0.172
3.91,-22.43,0.172
3.92,-22.25,0.172
3.94,-22.07,0.172
3.96,-21.88,0.172
3.98,-21.70,0.172
4.00,-21.52,0.172
4.01,-21.33,0.172
4.03,-21.15,0.172
4.05,-20.97,0.172
4.07,-20.78,0.172
4.09,-20.60,0.172
4.11,-20.42,0.172
4.13,-20.23,0.173
4.14,-20.05,0.173
4.16,-19.86,0.173
4.18,-19.68,0.173
4.20,-19.50,0.173
4.22,-19.31,0.173
4.24,-19.13,0.173
4.25,-18.95,0.173
4.27,-18.76,0.173
4.29,-18.58,0.173
4.31,-18.40,0.173
4.33,-18.21,0.173
4.35,-18.03,0.173
4.36,-17.85,0.173
4.38,-17.66,0.173
4.40,-17.48,0.174
4.42,-17.30,0.174
4.44,-17.11,0.174
4.45,-16.93,0.174
4.47,-16.75,0.174
4.49,-16.56,0.174
4.51,-16.38,0.174
4.53,-16.20,0.174
4.55,-16.01,0.174
4.56,-15.83,0.174
4.58,-15.64,0.174
4.60,-15.46,0.174
4.62,-15.28,0.175
4.64,-15.09,0.175
4.66,-14.91,0.175
4.68,-14.73,0.175
4.69,-14.54,0.175
4.71,-14.36,0.175
4.73,-14.18,0.175
4.75,-13.99,0.175
4.77,-13.81,0.175
4.79,-13.63,0.176
4.80,-13.44,0.176
4.82,-13.26,0.176
4.84,-13.08,0.176
4.86,-12.89,0.176
4.88,-12.71,0.176
4.90,-12.52,0.176
4.91,-12.34,0.176
4.93,-12.16,0.176
4.95,-11.97,0.176
4.97,-11.79,0.176
4.99,-11.61,0.177
5.00,-11.42,0.177
5.02,-11.24,0.177
5.04,-11.06,0.177
5.06,-10.87,0.177
5.08,-10.69,0.177
5.10,-10.50,0.177
5.11,-10.32,0.177
5.13,-10.14,0.177
5.15,-9.95,0.178
5.17,-9.77,0.178
5.19,-9.59,0.178
5.21,-9.40,0.178
5.23,-9.22,0.178
5.24,-9.04,0.178
5.26,-8.85,0.179
5.28,-8.67,0.179
5.30,-8.49,0.179
5.32,-8.30,0.179
5.34,-8.12,0.179
5.35,-7.94,0.179
5.37,-7.75,0.180
5.39,-7.57,0.180
5.41,-7.39,0.180
5.43,-7.20,0.180
5.45,-7.02,0.180
5.46,-6.84,0.180
5.48,-6.65,0.181
5.50,-6.47,0.181
5.52,-6.28,0.181
5.54,-6.10,0.181
5.55,-5.92,0.181
5.57,-5.73,0.181
5.59,-5.55,0.182
5.61,-5.37,0.182
5.63,-5.18,0.182
5.65,-5.00,0.182
5.66,-4.82,0.182
5.68,-4.63,0.182
5.70,-4.45,0.183
5.72,-4.27,0.183
5.74,-4.08,0.183
5.76,-3.90,0.183
5.78,-3.72,0.183
5.79,-3.53,0.183
5.81,-3.35,0.184
5.83,-3.17,0.184
5.85,-2.98,0.184
5.87,-2.80,0.184
5.89,-2.62,0.184
5.90,-2.43,0.185
5.92,-2.25,0.185
5.94,-2.06,0.185
5.96,-1.88,0.185
5.98,-1.70,0.185
6.00,-1.51,0.186
6.01,-1.33,0.186
6.03,-1.14,0.186
6.05,-0.96,0.186
6.07,-0.78,0.186
6.09,-0.59,0.186
6.10,-0.41,0.187
6.12,-0.23,0.187
6.14,-0.04,0.187
6.16,0.14,0.187
6.18,0.32,0.187
6.20,0.51,0.187
6.21,0.69,0.187
6.23,0.87,0.187
6.25,1.06,0.188
6.27,1.24,0.188
6.29,1.42,0.188
6.31,1.61,0.188
6.33,1.79,0.188
6.34,1.97,0.188
6.36,2.16,0.189
6.38,2.34,0.189
6.40,2.53,0.189
6.42,2.71,0.189
6.44,2.89,0.189
6.45,3.08,0.189
6.47,3.26,0.189
6.49,3.44,0.189
6.51,3.63,0.190
6.53,3.81,0.190
6.55,3.99,0.190
6.56,4.18,0.190
6.58,4.36,0.190
6.60,4.54,0.190
6.62,4.73,0.190
6.64,4.91,0.191
6.65,5.09,0.191
6.67,5.28,0.191
6.69,5.46,0.191
6.71,5.64,0.191
6.73,5.83,0.191
6.75,6.01,0.191
6.76,6.20,0.192
6.78,6.38,0.192
6.80,6.56,0.192
6.82,6.75,0.192
6.84,6.93,0.192
6.86,7.11,0.192
6.88,7.30,0.192
6.89,7.48,0.193
6.91,7.66,0.193
6.93,7.85,0.193
6.95,8.03,0.193
6.97,8.21,0.193
6.99,8.40,0.193
7.00,8.58,0.193
7.02,8.77,0.194
7.04,8.95,0.194
7.06,9.13,0.194
7.08,9.32,0.194
7.10,9.50,0.194
7.11,9.68,0.194
7.13,9.87,0.194
7.15,10.05,0.195
7.17,10.23,0.195
7.19,10.42,0.195
7.20,10.60,0.195
7.22,10.78,0.195
7.24,10.97,0.195
7.26,11.15,0.195
7.28,11.34,0.195
7.30,11.52,0.196
7.31,11.70,0.196
7.33,11.89,0.196
7.35,12.07,0.196
7.37,12.25,0.196
7.39,12.44,0.196
7.41,12.62,0.196
7.43,12.80,0.196
7.44,12.99,0.197
7.46,13.17,0.197
7.48,13.35,0.197
7.50,13.54,0.197
7.52,13.72,0.197
7.54,13.90,0.197
7.55,14.09,0.197
7.57,14.27,0.197
7.59,14.45,0.197
7.61,14.64,0.198
7.63,14.82,0.198
7.65,15.00,0.198
7.66,15.19,0.198
7.68,15.37,0.198
7.70,15.56,0.198
7.72,15.74,0.198
7.74,15.92,0.199
7.75,16.11,0.199
7.77,16.29,0.199
7.79,16.47,0.199
7.81,16.66,0.199
7.83,16.84,0.199
7.85,17.02,0.199
7.86,17.21,0.200
7.88,17.39,0.200
7.90,17.57,0.200
7.92,17.76,0.200
7.94,17.94,0.200
7.96,18.13,0.200
7.98,18.31,0.200
7.99,18.49,0.200
8.01,18.68,0.200
8.03,18.86,0.200
8.05,19.04,0.201
8.07,19.23,0.201
8.09,19.41,0.201
8.10,19.59,0.201
8.12,19.78,0.201
8.14,19.96,0.201
8.16,20.14,0.201
8.18,20.33,0.202
8.20,20.51,0.202
8.21,20.69,0.202
8.23,20.88,0.202
8.25,21.06,0.202
8.27,21.24,0.202
8.29,21.43,0.202
8.30,21.61,0.203
8.32,21.80,0.203
8.34,21.98,0.203
8.36,22.16,0.203
8.38,22.35,0.203
8.40,22.53,0.203
8.41,22.71,0.204
8.43,22.90,0.204
8.45,23.08,0.204
8.47,23.26,0.204
8.49,23.45,0.204
8.51,23.63,0.204
8.53,23.81,0.204
8.54,24.00,0.205
8.56,24.18,0.205
8.58,24.36,0.205
8.60,24.55,0.205
8.62,24.73,0.205
8.63,24.91,0.205
8.65,25.10,0.205
8.67,25.28,0.205
8.69,25.47,0.206
8.71,25.65,0.206
8.73,25.83,0.206
8.75,26.02,0.206
8.76,26.20,0.206
8.78,26.38,0.206
8.80,26.57,0.206
8.82,26.75,0.207
8.84,26.93,0.207
8.85,27.12,0.207
8.87,27.30,0.207
8.89,27.48,0.208
8.91,27.67,0.208
8.93,27.85,0.208
8.95,28.03,0.208
8.97,28.22,0.208
8.98,28.40,0.208
9.00,28.59,0.208
9.02,28.77,0.209
9.04,28.95,0.209
9.06,29.14,0.209
9.08,29.32,0.209
9.09,29.50,0.209
9.11,29.69,0.209
9.13,29.87,0.210
9.15,30.05,0.210
9.17,30.24,0.210
9.18,30.42,0.210
9.20,30.60,0.210
9.22,30.79,0.210
9.24,30.97,0.210
9.26,31.16,0.211
9.28,31.34,0.211
9.30,31.52,0.211
9.31,31.71,0.211
9.33,31.89,0.211
9.35,32.07,0.211
9.37,32.26,0.212
9.39,32.44,0.212
9.40,32.62,0.212
9.42,32.81,0.212
9.44,32.99,0.212
9.46,33.17,0.212
9.48,33.36,0.212
9.50,33.54,0.213
9.52,33.72,0.213
9.53,33.91,0.213
9.55,34.09,0.213
9.57,34.27,0.213
9.59,34.46,0.213
9.61,34.64,0.214
9.63,34.83,0.214
9.64,35.01,0.214
9.66,35.19,0.214
9.68,35.38,0.214
9.70,35.56,0.214
9.72,35.74,0.215
9.73,35.93,0.215
9.75,36.11,0.215
9.77,36.29,0.215
9.79,36.48,0.215
9.81,36.66,0.215
9.83,36.84,0.215
9.85,37.03,0.216
9.86,37.21,0.216
9.88,37.39,0.216
9.90,37.58,0.216
9.92,37.76,0.216
9.94,37.94,0.216
9.95,38.13,0.217
9.97,38.31,0.217
9.99,38.50,0.217
10.01,38.68,0.217
10.03,38.86,0.217
10.05,39.05,0.217
10.07,39.23,0.218
10.08,39.41,0.218
10.10,39.60,0.218
10.12,39.78,0.218
10.14,39.96,0.218
10.16,40.15,0.218
10.18,40.33,0.218
10.19,40.51,0.219
10.21,40.70,0.219
10.23,40.88,0.219
10.25,41.07,0.219
10.27,41.25,0.219
10.28,41.43,0.219
10.30,41.62,0.219
10.32,41.80,0.220
10.34,41.98,0.220
10.36,42.17,0.220
10.38,42.35,0.220
10.40,42.53,0.220
10.41,42.72,0.220
10.43,42.90,0.221
10.45,43.08,0.221
10.47,43.27,0.221
10.49,43.45,0.221
10.50,43.63,0.221
10.52,43.82,0.222
10.54,44.00,0.222
10.56,44.18,0.222
10.58,44.37,0.222
10.60,44.55,0.222
10.62,44.74,0.222
10.63,44.92,0.223
10.65,45.10,0.223
10.67,45.29,0.223
10.69,45.47,0.223
10.71,45.65,0.223
10.73,45.84,0.224
10.74,46.02,0.224
10.76,46.20,0.224
10.78,46.39,0.224
10.80,46.57,0.224
10.82,46.75,0.224
10.83,46.94,0.225
10.85,47.12,0.225
10.87,47.30,0.225
10.89,47.49,0.225
10.91,47.67,0.225
10.93,47.85,0.225
10.95,48.04,0.226
10.96,48.22,0.226
10.98,48.40,0.226
11.00,48.59,0.226
11.02,48.77,0.227
11.04,48.96,0.227
11.05,49.14,0.227
11.07,49.32,0.227
11.09,49.51,0.227
11.11,49.69,0.228
11.13,49.87,0.228
11.15,50.06,0.228
11.17,50.24,0.228
11.18,50.42,0.228
11.20,50.61,0.229
11.22,50.79,0.229
11.24,50.97,0.229
11.26,51.16,0.229
11.28,51.34,0.229
11.29,51.52,0.230
11.31,51.71,0.230
11.33,51.89,0.230
11.35,52.08,0.230
11.37,52.26,0.230
11.38,52.44,0.230
11.40,52.62,0.231
11.42,52.81,0.231
11.44,52.99,0.231
11.46,53.17,0.231
11.48,53.36,0.231
11.50,53.54,0.232
11.51,53.73,0.232
11.53,53.91,0.232
11.55,54.09,0.232
11.57,54.28,0.232
11.59,54.46,0.233
11.60,54.64,0.233
11.62,54.83,0.233
11.64,55.01,0.233
11.66,55.19,0.233
11.68,55.38,0.234
11.70,55.56,0.234
11.72,55.74,0.234
11.73,55.93,0.234
11.75,56.11,0.234
11.77,56.29,0.234
11.79,56.48,0.235
11.81,56.66,0.235
11.83,56.84,0.235
11.84,57.03,0.235
11.86,57.21,0.236
11.88,57.40,0.236
11.90,57.58,0.236
11.92,57.76,0.236
11.93,57.95,0.236
11.95,58.13,0.237
11.97,58.31,0.237
11.99,58.50,0.237
12.01,58.68,0.237
12.03,58.86,0.237
12.05,59.05,0.238
12.06,59.23,0.238
12.08,59.41,0.238
12.10,59.60,0.238
12.12,59.78,0.238
12.14,59.97,0.239
12.15,60.15,0.239
12.17,60.33,0.239
12.19,60.52,0.239
12.21,60.70,0.240
12.23,60.88,0.240
12.25,61.07,0.240
12.27,61.25,0.240
12.28,61.43,0.240
12.30,61.62,0.241
12.32,61.80,0.241
12.34,61.98,0.241
12.36,62.17,0.241
12.38,62.35,0.241
12.39,62.53,0.242
12.41,62.72,0.242
12.43,62.90,0.242
12.45,63.08,0.242
12.47,63.27,0.242
12.48,63.45,0.243
12.50,63.64,0.243
12.52,63.82,0.243
12.54,64.00,0.243
12.56,64.19,0.244
12.58,64.37,0.244
12.60,64.55,0.244
12.61,64.74,0.244
12.63,64.92,0.244
12.65,65.10,0.245
12.67,65.29,0.245
12.69,65.47,0.245
12.70,65.65,0.245
12.72,65.84,0.245
12.74,66.02,0.246
12.76,66.20,0.246
12.78,66.39,0.246
12.80,66.57,0.246
12.82,66.75,0.247
12.83,66.94,0.247
12.85,67.12,0.247
12.87,67.30,0.247
12.89,67.49,0.247
12.91,67.67,0.247
12.93,67.85,0.248
12.94,68.04,0.248
12.96,68.22,0.248
12.98,68.41,0.248
13.00,68.59,0.249
13.02,68.77,0.249
13.03,68.95,0.249
13.05,69.14,0.249
13.07,69.32,0.249
13.09,69.50,0.250
13.11,69.69,0.250
13.13,69.87,0.250
13.15,70.05,0.250
13.16,70.24,0.250
13.18,70.42,0.251
13.20,70.61,0.251
13.22,70.79,0.251
13.24,70.97,0.251
13.25,71.16,0.252
13.27,71.34,0.252
13.29,71.52,0.252
13.31,71.71,0.252
13.33,71.89,0.253
13.35,72.07,0.253
13.37,72.26,0.253
13.38,72.44,0.253
13.40,72.63,0.254
13.42,72.81,0.254
13.44,72.99,0.254
13.46,73.17,0.254
13.48,73.36,0.254
13.49,73.54,0.255
13.51,73.73,0.255
13.53,73.91,0.255
13.55,74.09,0.255
13.57,74.28,0.256
13.58,74.46,0.256
13.60,74.64,0.256
13.62,74.83,0.256
13.64,75.01,0.257
13.66,75.19,0.257
13.68,75.38,0.257
13.70,75.56,0.257
13.71,75.74,0.258
13.73,75.93,0.258
13.75,76.11,0.258
13.77,76.29,0.258
13.79,76.48,0.259
13.80,76.66,0.259
13.82,76.84,0.259
13.84,77.03,0.259
13.86,77.21,0.260
13.88,77.39,0.260
13.90,77.58,0.260
13.92,77.76,0.260
13.93,77.95,0.260
13.95,78.13,0.261
13.97,78.31,0.261
13.99,78.49,0.261
14.01,78.68,0.262
14.03,78.86,0.262
14.04,79.05,0.262
14.06,79.23,0.263
14.08,79.41,0.263
14.10,79.60,0.263
14.12,79.78,0.263
14.13,79.96,0.263
14.15,80.15,0.264
14.17,80.33,0.264
14.19,80.51,0.264
14.21,80.70,0.264
14.23,80.88,0.265
14.25,81.06,0.265
14.26,81.25,0.265
14.28,81.43,0.266
14.30,81.61,0.266
14.32,81.80,0.266
14.34,81.98,0.266
14.35,82.16,0.267
14.37,82.35,0.267
14.39,82.53,0.267
14.41,82.71,0.267
14.43,82.90,0.267
14.45,83.08,0.268
14.47,83.26,0.268
14.48,83.45,0.268
14.50,83.63,0.268
14.52,83.81,0.269
14.54,84.00,0.269
14.56,84.18,0.269
14.58,84.37,0.270
14.59,84.55,0.270
14.61,84.73,0.270
14.63,84.92,0.270
14.65,85.10,0.271
14.67,85.28,0.271
14.68,85.47,0.271
14.70,85.65,0.272
14.72,85.83,0.272
14.74,86.02,0.272
14.76,86.20,0.273
14.78,86.38,0.273
14.80,86.57,0.273
14.81,86.75,0.274
14.83,86.93,0.274
14.85,87.12,0.274
14.87,87.30,0.275
14.89,87.48,0.275
14.90,87.67,0.275
14.92,87.85,0.276
14.94,88.03,0.276
14.96,88.22,0.277
14.98,88.40,0.277
15.00,88.58,0.277
15.02,88.77,0.278
15.03,88.95,0.278
15.05,89.13,0.279
15.07,89.32,0.279
15.09,89.50,0.280
15.11,89.69,0.280
15.13,89.87,0.281
15.14,90.05,0.281
15.16,90.23,0.282
15.18,90.42,0.283
15.20,90.60,0.283
15.22,90.78,0.284
15.23,90.97,0.284
15.25,91.15,0.285
15.27,91.34,0.285
15.29,91.52,0.286
15.31,91.70,0.287
15.33,91.88,0.288
15.35,92.07,0.288
15.36,92.25,0.289
15.38,92.43,0.289
15.40,92.62,0.290
15.42,92.80,0.291
15.44,92.98,0.291
15.45,93.17,0.292
15.47,93.35,0.292
15.49,93.53,0.293
15.51,93.72,0.294
15.53,93.90,0.295
15.55,94.08,0.296
15.57,94.27,0.297
15.58,94.45,0.298
15.60,94.63,0.299
15.62,94.82,0.299
15.64,95.00,0.300
15.66,95.19,0.300
15.68,95.37,0.301
15.69,95.55,0.302
15.71,95.74,0.303
15.73,95.92,0.304
15.75,96.10,0.306
15.77,96.28,0.307
15.78,96.47,0.307
15.80,96.65,0.308
15.82,96.84,0.309
15.84,97.02,0.310
15.86,97.20,0.311
15.88,97.38,0.312
15.90,97.57,0.313
15.91,97.75,0.313
15.93,97.93,0.314
15.95,98.12,0.315
15.97,98.30,0.316
15.99,98.48,0.317
16.00,98.67,0.320
16.02,98.85,0.321
16.04,99.03,0.323
16.06,99.22,0.324
16.08,99.40,0.324
16.10,99.58,0.327
16.12,99.77,0.328
16.13,99.95,0.329
16.15,100.13,0.330
16.17,100.32,0.332
16.19,100.50,0.333
16.21,100.68,0.334
16.23,100.86,0.335
16.24,101.05,0.336
16.26,101.23,0.338
16.28,101.41,0.340
16.30,101.60,0.341
16.32,101.78,0.342
16.33,101.96,0.345
16.35,102.15,0.347
16.37,102.33,0.348
16.39,102.51,0.348
16.41,102.70,0.351
16.43,102.88,0.353
16.45,103.06,0.354
16.46,103.24,0.357
16.48,103.43,0.358
16.50,103.61,0.359
16.52,103.79,0.362
16.54,103.98,0.364
16.55,104.16,0.365
16.57,104.35,0.367
16.59,104.53,0.369
16.61,104.71,0.372
16.63,104.89,0.373
16.65,105.08,0.375
16.67,105.26,0.376
16.68,105.44,0.378
16.70,105.63,0.381
16.72,105.81,0.382
16.74,105.99,0.384
16.76,106.17,0.386
16.78,106.36,0.389
16.79,106.54,0.390
16.81,106.72,0.393
16.83,106.91,0.395
16.85,107.09,0.397
16.87,107.27,0.400
16.88,107.46,0.402
16.90,107.64,0.406
16.92,107.82,0.408
16.94,108.00,0.410
16.96,108.19,0.413
16.98,108.37,0.415
17.00,108.55,0.416
17.01,108.74,0.419
17.03,108.92,0.424
17.05,109.10,0.425
17.07,109.28,0.428
17.09,109.47,0.433
17.11,109.65,0.434
17.12,109.83,0.436
17.14,110.02,0.440
17.16,110.20,0.442
17.18,110.38,0.449
17.20,110.56,0.451
17.22,110.75,0.454
17.23,110.93,0.458
17.25,111.11,0.462
17.27,111.29,0.464
17.29,111.48,0.467
17.31,111.66,0.471
17.33,111.84,0.477
17.34,112.03,0.479
17.36,112.21,0.484
17.38,112.39,0.487
17.40,112.57,0.492
17.42,112.76,0.497
17.43,112.94,0.500
17.45,113.12,0.504
17.47,113.31,0.508
17.49,113.49,0.512
17.51,113.67,0.518
17.53,113.85,0.525
17.54,114.03,0.529
17.56,114.22,0.533
17.58,114.40,0.539
17.60,114.58,0.543
17.62,114.76,0.549
17.64,114.94,0.554
17.66,115.13,0.560
17.67,115.31,0.566
17.69,115.49,0.571
17.71,115.67,0.579
17.73,115.86,0.584
17.75,116.04,0.589
17.77,116.22,0.597
17.78,116.40,0.603
17.80,116.58,0.610
17.82,116.77,0.617
17.84,116.95,0.619
17.86,117.13,0.626
17.88,117.31,0.631
17.89,117.49,0.637
17.91,117.68,0.647
17.93,117.86,0.652
17.95,118.04,0.661
17.97,118.22,0.670
17.98,118.40,0.679
18.00,118.59,0.693
18.02,118.77,0.700
18.04,118.95,0.710
18.06,119.13,0.718
18.08,119.31,0.729
18.09,119.49,0.741
18.11,119.67,0.747
18.13,119.85,0.754
18.15,120.04,0.762
18.17,120.22,0.770
18.19,120.40,0.784
18.21,120.58,0.795
18.22,120.76,0.818
18.24,120.94,0.854
18.26,121.12,0.894
18.28,121.29,0.893
18.30,121.47,0.881
18.32,121.66,0.876
18.33,121.84,0.874
18.35,122.02,0.874
18.37,122.21,0.873
18.39,122.39,0.876
18.41,122.57,0.874
18.43,122.76,0.849
18.44,122.94,0.829
18.46,123.13,0.806
18.48,123.32,0.796
18.50,123.50,0.761
18.52,123.69,0.716
18.53,123.88,0.661
18.55,124.08,0.600
18.57,124.27,0.537
18.59,124.47,0.482
18.61,124.66,0.440
18.63,124.86,0.410
18.64,125.05,0.387
18.66,125.24,0.370
18.68,125.43,0.357
18.70,125.62,0.347
18.72,125.81,0.340
18.74,126.00,0.332
18.76,126.18,0.328
18.77,126.37,0.325
18.79,126.56,0.321
18.81,126.74,0.320
18.83,126.92,0.318
18.85,127.11,0.316
18.87,127.29,0.315
18.88,127.48,0.315
18.90,127.66,0.314
18.92,127.85,0.313
18.94,128.03,0.313
18.96,128.21,0.312
18.98,128.40,0.312
18.99,128.58,0.312
19.01,128.76,0.311
19.03,128.95,0.311
19.05,129.13,0.311
19.07,129.31,0.311
19.08,129.50,0.310
19.10,129.68,0.310
19.12,129.87,0.310
19.14,130.05,0.310
19.16,130.23,0.309
19.18,130.42,0.309
19.19,130.60,0.309
19.21,130.78,0.309
19.23,130.97,0.309
19.25,131.15,0.309
19.27,131.33,0.309
19.29,131.52,0.308
19.31,131.70,0.308
19.32,131.88,0.308
19.34,132.07,0.308
19.36,132.25,0.308
19.38,132.43,0.308
19.40,132.62,0.307
19.42,132.80,0.307
19.43,132.98,0.307
19.45,133.17,0.307
19.47,133.35,0.307
19.49,133.54,0.307
19.51,133.72,0.307
19.53,133.90,0.306
19.54,134.09,0.306
19.56,134.27,0.306
19.58,134.45,0.306
19.60,134.64,0.305
19.62,134.82,0.305
19.63,135.00,0.305
19.65,135.19,0.305
19.67,135.37,0.304
19.69,135.55,0.304
19.71,135.74,0.304
19.73,135.92,0.304
19.74,136.11,0.303
19.76,136.29,0.303
19.78,136.47,0.303
19.80,136.65,0.303
19.82,136.84,0.303
19.84,137.02,0.302
19.86,137.21,0.302
19.87,137.39,0.302
19.89,137.57,0.301
19.91,137.76,0.301
19.93,137.94,0.301
19.95,138.12,0.301
19.97,138.31,0.300
19.98,138.49,0.300
20.00,138.67,0.300
20.02,138.86,0.300
20.04,139.04,0.300
20.06,139.22,0.299
20.08,139.41,0.299
20.09,139.59,0.299
20.11,139.77,0.299
20.13,139.96,0.299
20.15,140.14,0.299
20.17,140.33,0.298
20.18,140.51,0.298
20.20,140.69,0.298
20.22,140.88,0.298
20.24,141.06,0.298
20.26,141.24,0.298
20.28,141.43,0.298
20.29,141.61,0.298
20.31,141.79,0.297
20.33,141.98,0.297
20.35,142.16,0.297
20.37,142.34,0.297
20.39,142.53,0.297
20.41,142.71,0.297
20.42,142.90,0.297
20.44,143.08,0.297
20.46,143.26,0.297
20.48,143.44,0.297
20.50,143.63,0.297
20.52,143.81,0.297
20.53,143.99,0.297
20.55,144.18,0.297
20.57,144.36,0.297
20.59,144.55,0.297
20.61,144.73,0.297
20.63,144.91,0.297
20.64,145.10,0.297
20.66,145.28,0.297
20.68,145.46,0.297
20.70,145.65,0.296
20.72,145.83,0.297
20.73,146.01,0.297
20.75,146.20,0.296
20.77,146.38,0.296
20.79,146.56,0.296
20.81,146.75,0.296
20.83,146.93,0.296
20.84,147.11,0.296
20.86,147.30,0.296
20.88,147.48,0.296
20.90,147.67,0.296
20.92,147.85,0.296
20.94,148.03,0.296
20.96,148.21,0.296
20.97,148.40,0.296
20.99,148.58,0.296
21.01,148.76,0.296
21.03,148.95,0.296
21.05,149.13,0.296
21.07,149.32,0.296
21.08,149.50,0.296
21.10,149.68,0.296
21.12,149.87,0.297
21.14,150.05,0.297
21.16,150.23,0.297
21.18,150.42,0.297
21.19,150.60,0.297
21.21,150.78,0.297
21.23,150.97,0.297
21.25,151.15,0.297
21.27,151.33,0.297
21.28,151.52,0.297
21.30,151.70,0.297
21.32,151.88,0.298
21.34,152.07,0.298
21.36,152.25,0.298
21.38,152.43,0.298
21.39,152.62,0.298
21.41,152.80,0.298
21.43,152.98,0.298
21.45,153.17,0.298
21.47,153.35,0.299
21.49,153.53,0.299
21.51,153.72,0.299
21.52,153.90,0.299
21.54,154.08,0.300
21.56,154.27,0.300
21.58,154.45,0.300
21.60,154.63,0.300
21.62,154.82,0.301
21.63,155.00,0.301
21.65,155.18,0.301
21.67,155.37,0.302
21.69,155.55,0.302
21.71,155.73,0.302
21.73,155.92,0.302
21.74,156.10,0.303
21.76,156.28,0.303
21.78,156.47,0.303
21.80,156.65,0.304
21.82,156.83,0.304
21.83,157.02,0.304
21.85,157.20,0.305
21.87,157.38,0.306
21.89,157.57,0.307
21.91,157.75,0.307
21.93,157.93,0.308
21.94,158.12,0.308
21.96,158.30,0.308
21.98,158.48,0.309
22.00,158.67,0.309
22.02,158.85,0.309
22.04,159.03,0.309
22.06,159.22,0.310
22.07,159.40,0.311
22.09,159.58,0.313
22.11,159.77,0.313
22.13,159.95,0.314
22.15,160.14,0.314
22.17,160.32,0.314
22.18,160.50,0.315
22.20,160.69,0.315
22.22,160.87,0.316
22.24,161.05,0.316
22.26,161.23,0.316
22.28,161.42,0.317
22.29,161.60,0.318
22.31,161.79,0.318
22.33,161.97,0.319
22.35,162.15,0.320
22.37,162.34,0.320
22.38,162.52,0.322
22.40,162.70,0.322
22.42,162.88,0.323
22.44,163.07,0.324
22.46,163.25,0.324
22.48,163.43,0.325
22.49,163.62,0.326
22.51,163.80,0.328
22.53,163.98,0.329
22.55,164.17,0.330
22.57,164.35,0.330
22.59,164.53,0.330
22.61,164.72,0.331
22.62,164.90,0.331
22.64,165.08,0.332
22.66,165.27,0.332
22.68,165.45,0.333
22.70,165.63,0.334
22.72,165.82,0.334
22.73,166.00,0.335
22.75,166.18,0.335
22.77,166.37,0.337
22.79,166.55,0.338
22.81,166.73,0.338
22.83,166.92,0.339
22.84,167.10,0.339
22.86,167.29,0.340
22.88,167.47,0.340
22.90,167.65,0.340
22.92,167.84,0.341
22.93,168.02,0.341
22.95,168.20,0.342
22.97,168.38,0.342
22.99,168.57,0.343
23.01,168.75,0.343
23.03,168.93,0.344
23.04,169.12,0.344
23.06,169.30,0.344
23.08,169.48,0.346
23.10,169.67,0.346
23.12,169.85,0.347
23.14,170.03,0.347
23.16,170.22,0.348
23.17,170.40,0.349
23.19,170.58,0.350
23.21,170.77,0.350
23.23,170.95,0.351
23.25,171.13,0.351
23.27,171.32,0.352
23.28,171.50,0.353
23.30,171.68,0.354
23.32,171.87,0.354
23.34,172.05,0.355
23.36,172.23,0.355
23.38,172.42,0.356
23.39,172.60,0.357
23.41,172.78,0.358
23.43,172.97,0.360
23.45,173.15,0.360
23.47,173.33,0.361
23.48,173.52,0.361
23.50,173.70,0.362
23.52,173.88,0.362
23.54,174.07,0.364
23.56,174.25,0.365
23.58,174.43,0.366
23.59,174.62,0.366
23.61,174.80,0.367
23.63,174.98,0.368
23.65,175.17,0.368
23.67,175.35,0.369
23.69,175.53,0.370
23.71,175.72,0.371
23.72,175.90,0.372
23.74,176.08,0.372
23.76,176.27,0.373
23.78,176.45,0.375
23.80,176.63,0.375
23.82,176.81,0.376
23.83,177.00,0.377
23.85,177.18,0.377
23.87,177.37,0.378
23.89,177.55,0.379
23.91,177.73,0.381
23.93,177.91,0.381
23.94,178.10,0.382
23.96,178.28,0.383
23.98,178.46,0.384
24.00,178.65,0.385
24.02,178.83,0.386
24.03,179.01,0.389
24.05,179.20,0.390
24.07,179.38,0.392
24.09,179.56,0.394
24.11,179.75,0.396
24.13,179.93,0.397
24.14,180.11,0.399
24.16,180.30,0.401
24.18,180.48,0.402
24.20,180.66,0.403
24.22,180.85,0.404
24.24,181.03,0.406
24.26,181.21,0.408
24.27,181.40,0.410
24.29,181.58,0.411
24.31,181.76,0.413
24.33,181.94,0.415
24.35,182.13,0.417
24.37,182.31,0.419
24.38,182.49,0.420
24.40,182.68,0.422
24.42,182.86,0.424
24.44,183.04,0.425
24.46,183.22,0.425
24.48,183.41,0.428
24.49,183.59,0.431
24.51,183.77,0.433
24.53,183.96,0.434
24.55,184.14,0.436
24.57,184.32,0.437
24.58,184.51,0.439
24.60,184.69,0.442
24.62,184.87,0.443
24.64,185.06,0.444
24.66,185.24,0.446
24.68,185.42,0.448
24.69,185.61,0.450
24.71,185.79,0.454
24.73,185.97,0.457
24.75,186.15,0.459
24.77,186.34,0.460
24.79,186.52,0.461
24.81,186.70,0.461
24.82,186.89,0.462
24.84,187.07,0.465
24.86,187.25,0.469
24.88,187.43,0.475
24.90,187.62,0.478
24.92,187.80,0.486
24.93,187.98,0.492
24.95,188.16,0.501
24.97,188.35,0.505
24.99,188.53,0.513
25.01,188.71,0.515
25.03,188.90,0.519
25.04,189.08,0.524
25.06,189.26,0.527
25.08,189.44,0.531
25.10,189.63,0.537
25.12,189.81,0.543
25.13,189.99,0.546
25.15,190.17,0.550
25.17,190.35,0.555
25.19,190.54,0.558
25.21,190.72,0.563
25.23,190.90,0.567
25.24,191.08,0.573
25.26,191.27,0.576
25.28,191.45,0.578
25.30,191.63,0.583
25.32,191.81,0.590
25.34,192.00,0.593
25.36,192.18,0.597
25.37,192.36,0.603
25.39,192.54,0.608
25.41,192.73,0.613
25.43,192.91,0.616
25.45,193.09,0.618
25.47,193.27,0.623
25.48,193.46,0.626
25.50,193.64,0.630
25.52,193.82,0.635
25.54,194.00,0.640
25.56,194.19,0.648
25.58,194.37,0.659
25.59,194.55,0.667
25.61,194.73,0.673
25.63,194.92,0.676
25.65,195.10,0.678
25.67,195.28,0.679
25.68,195.46,0.681
25.70,195.65,0.684
25.72,195.83,0.693
25.74,196.01,0.698
25.76,196.19,0.702
25.78,196.38,0.704
25.79,196.56,0.705
25.81,196.74,0.708
25.83,196.92,0.713
25.85,197.11,0.718
25.87,197.29,0.720
25.89,197.47,0.720
25.91,197.66,0.720
25.92,197.84,0.720
25.94,198.02,
25.96,198.21,
25.98,198.39,
25.99,,

[step]
Ramp 10.00 °C/min to -60.00 °C
Time,Temperature,Heat Flow (Normalized)
min,°C,W/g
26.99,200.02,0.198
27.01,200.02,0.195
27.03,200.02,0.193
27.05,200.01,0.191
27.07,199.99,0.185
27.08,199.95,0.165
27.10,199.89,0.136
27.12,199.80,0.092
27.14,199.70,0.039
27.16,199.58,-0.015
27.18,199.44,-0.070
27.19,199.30,-0.115
27.21,199.15,-0.155
27.23,198.99,-0.184
27.25,198.83,-0.212
27.27,198.67,-0.234
27.29,198.50,-0.252
27.31,198.33,-0.268
27.32,198.16,-0.280
27.34,197.99,-0.293
27.36,197.81,-0.301
27.38,197.64,-0.309
27.40,197.46,-0.317
27.42,197.28,-0.323
27.43,197.11,-0.332
27.45,196.93,-0.338
27.47,196.75,-0.341
27.49,196.57,-0.346
27.51,196.39,-0.351
27.53,196.21,-0.357
27.54,196.03,-0.359
27.56,195.86,-0.361
27.58,195.67,-0.365
27.60,195.50,-0.367
27.62,195.32,-0.369
27.63,195.13,-0.371
27.65,194.95,-0.375
27.67,194.77,-0.383
27.69,194.59,-0.387
27.71,194.41,-0.389
27.73,194.23,-0.392
27.74,194.05,-0.397
27.76,193.87,-0.399
27.78,193.69,-0.400
27.80,193.51,-0.403
27.82,193.33,-0.406
27.84,193.14,-0.408
27.86,192.96,-0.409
27.87,192.78,-0.409
27.89,192.60,-0.410
27.91,192.42,-0.411
27.93,192.24,-0.412
27.95,192.06,-0.413
27.97,191.87,-0.414
27.98,191.69,-0.414
28.00,191.51,-0.415
28.02,191.33,-0.415
28.04,191.14,-0.416
28.06,190.96,-0.417
28.08,190.78,-0.419
28.09,190.60,-0.419
28.11,190.42,-0.421
28.13,190.23,-0.426
28.15,190.05,-0.427
28.17,189.87,-0.428
28.18,189.69,-0.428
28.20,189.51,-0.429
28.22,189.32,-0.430
28.24,189.14,-0.430
28.26,188.96,-0.433
28.28,188.78,-0.436
28.29,188.59,-0.437
28.31,188.41,-0.437
28.33,188.23,-0.437
28.35,188.05,-0.438
28.37,187.86,-0.438
28.39,187.68,-0.438
28.41,187.50,-0.439
28.42,187.32,-0.440
28.44,187.13,-0.440
28.46,186.95,-0.441
28.48,186.77,-0.441
28.50,186.59,-0.442
28.52,186.40,-0.442
28.53,186.22,-0.443
28.55,186.04,-0.443
28.57,185.86,-0.443
28.59,185.67,-0.444
28.61,185.49,-0.445
28.63,185.31,-0.445
28.64,185.13,-0.446
28.66,184.94,-0.446
28.68,184.76,-0.447
28.70,184.58,-0.447
28.72,184.39,-0.448
28.73,184.21,-0.448
28.75,184.03,-0.449
28.77,183.84,-0.449
28.79,183.66,-0.450
28.81,183.48,-0.450
28.83,183.30,-0.452
28.84,183.11,-0.452
28.86,182.93,-0.453
28.88,182.75,-0.453
28.90,182.56,-0.453
28.92,182.38,-0.454
28.94,182.20,-0.454
28.96,182.02,-0.454
28.97,181.83,-0.454
28.99,181.65,-0.455
29.01,181.47,-0.455
29.03,181.28,-0.455
29.05,181.10,-0.456
29.07,180.92,-0.456
29.08,180.74,-0.456
29.10,180.55,-0.457
29.12,180.37,-0.457
29.14,180.18,-0.458
29.16,180.00,-0.458
29.18,179.82,-0.458
29.19,179.64,-0.458
29.21,179.45,-0.458
29.23,179.27,-0.459
29.25,179.09,-0.459
29.27,178.91,-0.459
29.28,178.72,-0.459
29.30,178.54,-0.460
29.32,178.36,-0.461
29.34,178.17,-0.462
29.36,177.99,-0.462
29.38,177.81,-0.462
29.39,177.63,-0.463
29.41,177.44,-0.463
29.43,177.26,-0.463
29.45,177.08,-0.464
29.47,176.89,-0.464
29.49,176.71,-0.465
29.51,176.53,-0.465
29.52,176.34,-0.465
29.54,176.16,-0.466
29.56,175.98,-0.466
29.58,175.80,-0.467
29.60,175.61,-0.467
29.62,175.43,-0.467
29.63,175.25,-0.467
29.65,175.06,-0.467
29.67,174.88,-0.468
29.69,174.70,-0.468
29.71,174.51,-0.468
29.73,174.33,-0.468
29.74,174.15,-0.468
29.76,173.96,-0.468
29.78,173.78,-0.468
29.80,173.60,-0.468
29.82,173.42,-0.468
29.83,173.23,-0.469
29.85,173.05,-0.469
29.87,172.87,-0.469
29.89,172.68,-0.469
29.91,172.50,-0.469
29.93,172.32,-0.469
29.94,172.13,-0.469
29.96,171.95,-0.470
29.98,171.77,-0.470
30.00,171.58,-0.470
30.02,171.40,-0.470
30.04,171.22,-0.470
30.06,171.03,-0.470
30.07,170.85,-0.470
30.09,170.67,-0.470
30.11,170.48,-0.470
30.13,170.30,-0.470
30.15,170.12,-0.470
30.17,169.93,-0.470
30.18,169.75,-0.470
30.20,169.57,-0.470
30.22,169.39,-0.470
30.24,169.20,-0.470
30.26,169.02,-0.470
30.28,168.84,-0.470
30.29,168.65,-0.470
30.31,168.47,-0.469
30.33,168.29,-0.469
30.35,168.10,-0.469
30.37,167.92,-0.469
30.38,167.74,-0.469
30.40,167.55,-0.469
30.42,167.37,-0.469
30.44,167.19,-0.469
30.46,167.00,-0.469
30.48,166.82,-0.469
30.49,166.64,-0.469
30.51,166.45,-0.469
30.53,166.27,-0.469
30.55,166.09,-0.469
30.57,165.90,-0.469
30.59,165.72,-0.468
30.61,165.54,-0.468
30.62,165.35,-0.468
30.64,165.17,-0.468
30.66,164.99,-0.468
30.68,164.81,-0.468
30.70,164.62,-0.468
30.72,164.44,-0.468
30.73,164.26,-0.468
30.75,164.07,-0.467
30.77,163.89,-0.467
30.79,163.71,-0.467
30.81,163.53,-0.467
30.83,163.34,-0.467
30.84,163.16,-0.467
30.86,162.98,-0.467
30.88,162.80,-0.467
30.90,162.61,-0.466
30.92,162.43,-0.466
30.93,162.25,-0.466
30.95,162.06,-0.466
30.97,161.88,-0.466
30.99,161.70,-0.466
31.01,161.52,-0.466
31.03,161.33,-0.466
31.04,161.15,-0.466
31.06,160.97,-0.466
31.08,160.78,-0.466
31.10,160.60,-0.466
31.12,160.42,-0.466
31.14,160.23,-0.466
31.16,160.05,-0.466
31.17,159.87,-0.466
31.19,159.68,-0.466
31.21,159.50,-0.466
31.23,159.32,-0.466
31.25,159.13,-0.466
31.27,158.95,-0.466
31.28,158.77,-0.466
31.30,158.58,-0.466
31.32,158.40,-0.466
31.34,158.22,-0.466
31.36,158.03,-0.466
31.38,157.85,-0.466
31.39,157.67,-0.466
31.41,157.49,-0.466
31.43,157.30,-0.466
31.45,157.12,-0.466
31.47,156.94,-0.466
31.48,156.75,-0.465
31.50,156.57,-0.465
31.52,156.39,-0.465
31.54,156.20,-0.465
31.56,156.02,-0.465
31.58,155.84,-0.465
31.59,155.65,-0.465
31.61,155.47,-0.465
31.63,155.29,-0.465
31.65,155.10,-0.465
31.67,154.92,-0.465
31.69,154.74,-0.465
31.71,154.55,-0.465
31.72,154.37,-0.465
31.74,154.18,-0.465
31.76,154.00,-0.464
31.78,153.82,-0.464
31.80,153.64,-0.464
31.82,153.45,-0.464
31.83,153.27,-0.464
31.85,153.09,-0.464
31.87,152.90,-0.463
31.89,152.72,-0.463
31.91,152.54,-0.463
31.93,152.35,-0.463
31.94,152.17,-0.463
31.96,151.99,-0.462
31.98,151.80,-0.462
32.00,151.62,-0.462
32.02,151.44,-0.462
32.03,151.26,-0.461
32.05,151.07,-0.461
32.07,150.89,-0.461
32.09,150.71,-0.461
32.11,150.52,-0.461
32.13,150.34,-0.461
32.14,150.16,-0.460
32.16,149.98,-0.460
32.18,149.79,-0.460
32.20,149.61,-0.460
32.22,149.43,-0.460
32.24,149.25,-0.460
32.26,149.06,-0.460
32.27,148.88,-0.460
32.29,148.70,-0.460
32.31,148.51,-0.460
32.33,148.33,-0.460
32.35,148.15,-0.460
32.37,147.96,-0.460
32.38,147.78,-0.460
32.40,147.60,-0.460
32.42,147.41,-0.460
32.44,147.23,-0.460
32.46,147.05,-0.460
32.48,146.86,-0.459
32.49,146.68,-0.459
32.51,146.50,-0.459
32.53,146.31,-0.459
32.55,146.13,-0.459
32.57,145.95,-0.459
32.58,145.77,-0.459
32.60,145.58,-0.459
32.62,145.40,-0.459
32.64,145.22,-0.458
32.66,145.03,-0.458
32.68,144.85,-0.458
32.69,144.67,-0.458
32.71,144.48,-0.458
32.73,144.30,-0.458
32.75,144.12,-0.458
32.77,143.93,-0.458
32.79,143.75,-0.458
32.81,143.57,-0.458
32.82,143.38,-0.457
32.84,143.20,-0.457
32.86,143.02,-0.457
32.88,142.84,-0.457
32.90,142.65,-0.457
32.92,142.47,-0.457
32.93,142.28,-0.457
32.95,142.10,-0.457
32.97,141.92,-0.456
32.99,141.74,-0.456
33.01,141.55,-0.456
33.03,141.37,-0.456
33.04,141.19,-0.456
33.06,141.00,-0.456
33.08,140.82,-0.456
33.10,140.64,-0.456
33.12,140.45,-0.456
33.13,140.27,-0.456
33.15,140.08,-0.456
33.17,139.90,-0.455
33.19,139.72,-0.455
33.21,139.54,-0.455
33.23,139.35,-0.455
33.24,139.17,-0.455
33.26,138.99,-0.455
33.28,138.80,-0.455
33.30,138.62,-0.455
33.32,138.44,-0.454
33.34,138.25,-0.454
33.36,138.07,-0.454
33.37,137.89,-0.454
33.39,137.71,-0.454
33.41,137.52,-0.454
33.43,137.34,-0.454
33.45,137.16,-0.454
33.47,136.97,-0.453
33.48,136.79,-0.453
33.50,136.61,-0.453
33.52,136.42,-0.453
33.54,136.24,-0.453
33.56,136.06,-0.453
33.58,135.87,-0.453
33.59,135.69,-0.453
33.61,135.51,-0.453
33.63,135.32,-0.453
33.65,135.14,-0.452
33.67,134.96,-0.452
33.68,134.78,-0.452
33.70,134.59,-0.452
33.72,134.41,-0.452
33.74,134.22,-0.452
33.76,134.04,-0.452
33.78,133.86,-0.452
33.79,133.67,-0.451
33.81,133.49,-0.451
33.83,133.31,-0.451
33.85,133.13,-0.451
33.87,132.94,-0.451
33.89,132.76,-0.451
33.91,132.57,-0.451
33.92,132.39,-0.451
33.94,132.21,-0.450
33.96,132.03,-0.450
33.98,131.84,-0.450
34.00,131.66,-0.450
34.02,131.48,-0.450
34.03,131.30,-0.449
34.05,131.11,-0.449
34.07,130.93,-0.449
34.09,130.74,-0.449
34.11,130.56,-0.449
34.13,130.38,-0.449
34.14,130.20,-0.449
34.16,130.01,-0.448
34.18,129.83,-0.448
34.20,129.65,-0.448
34.22,129.46,-0.448
34.24,129.28,-0.448
34.25,129.10,-0.448
34.27,128.91,-0.448
[...]
115.21,10.66,0.250
115.23,10.84,0.252
115.25,11.03,0.253
115.27,11.21,0.253
115.29,11.39,0.254
115.31,11.58,0.254
115.33,11.76,0.255
115.34,11.94,0.255
115.36,12.13,0.256
115.38,12.31,0.256
115.40,12.49,0.257
115.42,12.68,0.258
115.44,12.86,0.258
115.45,13.04,0.258
115.47,13.23,0.259
115.49,13.41,0.259
115.51,13.59,0.259
115.53,13.78,0.259
115.55,13.96,0.259
115.56,14.15,0.260
115.58,14.33,0.260
115.60,14.51,0.260
115.62,14.70,0.260
115.64,14.88,0.260
115.65,15.06,0.260
115.67,15.25,0.260
115.69,15.43,0.260
115.71,15.61,0.260
115.73,15.80,0.260
115.75,15.98,0.261
115.76,16.17,0.261
115.78,16.35,0.261
115.80,16.53,0.260
115.82,16.72,0.261
115.84,16.90,0.260
115.86,17.08,0.260
115.88,17.27,0.260
115.89,17.45,0.260
115.91,17.64,0.260
115.93,17.82,0.260
115.95,18.00,0.260
115.97,18.19,0.260
115.99,18.37,0.260
116.00,18.55,0.260
116.02,18.74,0.260
116.04,18.92,0.260
116.06,19.10,0.260
116.08,19.29,0.260
116.10,19.47,0.260
116.11,19.65,0.260
116.13,19.84,0.260
116.15,20.02,0.260
116.17,20.20,0.260
116.19,20.39,0.260
116.20,20.57,0.260
116.22,20.76,0.260
116.24,20.94,0.260
116.26,21.12,0.260
116.28,21.31,0.261
116.30,21.49,0.261
116.31,21.67,0.261
116.33,21.86,0.261
116.35,22.04,0.261
116.37,22.22,0.261
116.39,22.41,0.261
116.41,22.59,0.261
116.43,22.77,0.261
116.44,22.96,0.261
116.46,23.14,0.261
116.48,23.32,0.262
116.50,23.51,0.262
116.52,23.69,0.262
116.54,23.87,0.262
116.55,24.06,0.262
116.57,24.24,0.262
116.59,24.42,0.262
116.61,24.61,0.262
116.63,24.79,0.262
116.65,24.97,0.262
116.66,25.16,0.263
116.68,25.34,0.263
116.70,25.53,0.263
116.72,25.71,0.263
116.74,25.89,0.263
116.75,26.08,0.263
116.77,26.26,0.263
116.79,26.44,0.264
116.81,26.63,0.264
116.83,26.81,0.264
116.85,26.99,0.264
116.86,27.18,0.264
116.88,27.36,0.264
116.90,27.54,0.265
116.92,27.73,0.265
116.94,27.91,0.265
116.96,28.09,0.265
116.98,28.28,0.265
116.99,28.46,0.265
117.01,28.65,0.266
117.03,28.83,0.266
117.05,29.01,0.266
117.07,29.20,0.266
117.09,29.38,0.266
117.10,29.56,0.266
117.12,29.74,0.267
117.14,29.93,0.267
117.16,30.11,0.267
117.18,30.30,0.267
117.20,30.48,0.267
117.21,30.66,0.267
117.23,30.85,0.268
117.25,31.03,0.268
117.27,31.21,0.268
117.29,31.40,0.268
117.30,31.58,0.268
117.32,31.77,0.268
117.34,31.95,0.269
117.36,32.13,0.269
117.38,32.32,0.269
117.40,32.50,0.269
117.41,32.68,0.269
117.43,32.87,0.269
117.45,33.05,0.269
117.47,33.23,0.270
117.49,33.42,0.270
117.51,33.60,0.270
117.53,33.78,0.270
117.54,33.97,0.270
117.56,34.15,0.270
117.58,34.33,0.270
117.60,34.52,0.271
117.62,34.70,0.271
117.64,34.88,0.271
117.65,35.07,0.271
117.67,35.25,0.271
117.69,35.44,0.271
117.71,35.62,0.271
117.73,35.80,0.272
117.75,35.99,0.272
117.76,36.17,0.272
117.78,36.35,0.272
117.80,36.54,0.272
117.82,36.72,0.272
117.84,36.91,0.273
117.85,37.09,0.273
117.87,37.27,0.273
117.89,37.46,0.273
117.91,37.64,0.273
117.93,37.82,0.273
117.95,38.01,0.273
117.96,38.19,0.274
117.98,38.37,0.274
118.00,38.56,0.274
118.02,38.74,0.274
118.04,38.92,0.274
118.06,39.11,0.274
118.08,39.29,0.275
118.09,39.47,0.275
118.11,39.66,0.275
118.13,39.84,0.275
118.15,40.02,0.275
118.17,40.21,0.275
118.19,40.39,0.275
118.20,40.58,0.276
118.22,40.76,0.276
118.24,40.94,0.276
118.26,41.12,0.276
118.28,41.31,0.276
118.30,41.49,0.276
118.31,41.68,0.277
118.33,41.86,0.277
118.35,42.04,0.277
118.37,42.23,0.277
118.39,42.41,0.277
118.40,42.59,0.277
118.42,42.78,0.278
118.44,42.96,0.278
118.46,43.14,0.278
118.48,43.33,0.278
118.50,43.51,0.278
118.51,43.69,0.278
118.53,43.88,0.279
118.55,44.06,0.279
118.57,44.24,0.279
118.59,44.43,0.279
118.61,44.61,0.279
118.63,44.79,0.279
118.64,44.98,0.280
118.66,45.16,0.280
118.68,45.35,0.280
118.70,45.53,0.280
118.72,45.71,0.280
118.74,45.90,0.281
118.75,46.08,0.281
118.77,46.26,0.281
118.79,46.45,0.281
118.81,46.63,0.281
118.83,46.81,0.281
118.85,47.00,0.282
118.86,47.18,0.282
118.88,47.36,0.282
118.90,47.55,0.282
118.92,47.73,0.282
118.94,47.92,0.282
118.95,48.10,0.283
118.97,48.28,0.283
118.99,48.47,0.283
119.01,48.65,0.283
119.03,48.83,0.283
119.05,49.02,0.283
119.06,49.20,0.284
119.08,49.38,0.284
119.10,49.57,0.284
119.12,49.75,0.284
119.14,49.93,0.284
119.16,50.12,0.285
119.18,50.30,0.285
119.19,50.48,0.285
119.21,50.67,0.285
119.23,50.85,0.285
119.25,51.04,0.285
119.27,51.22,0.285
119.29,51.40,0.286
119.30,51.58,0.286
119.32,51.77,0.286
119.34,51.95,0.286
119.36,52.14,0.287
119.38,52.32,0.287
119.40,52.50,0.287
119.41,52.69,0.287
119.43,52.87,0.287
119.45,53.05,0.287
119.47,53.24,0.288
119.49,53.42,0.288
119.50,53.60,0.288
119.52,53.79,0.288
119.54,53.97,0.288
119.56,54.15,0.289
119.58,54.34,0.289
119.60,54.52,0.289
119.61,54.71,0.289
119.63,54.89,0.289
119.65,55.07,0.289
119.67,55.26,0.290
119.69,55.44,0.290
119.71,55.62,0.290
119.73,55.81,0.290
119.74,55.99,0.290
119.76,56.17,0.291
119.78,56.36,0.291
119.80,56.54,0.291
119.82,56.72,0.291
119.84,56.91,0.291
119.85,57.09,0.291
119.87,57.27,0.292
119.89,57.46,0.292
119.91,57.64,0.292
119.93,57.82,0.292
119.95,58.01,0.292
119.96,58.19,0.293
119.98,58.37,0.293
120.00,58.56,0.293
120.02,58.74,0.293
120.04,58.93,0.293
120.05,59.11,0.293
120.07,59.29,0.294
120.09,59.48,0.294
120.11,59.66,0.294
120.13,59.84,0.294
120.15,60.03,0.294
120.16,60.21,0.295
120.18,60.39,0.295
120.20,60.58,0.295
120.22,60.76,0.295
120.24,60.94,0.295
120.26,61.13,0.295
120.28,61.31,0.296
120.29,61.50,0.296
120.31,61.68,0.296
120.33,61.86,0.296
120.35,62.05,0.296
120.37,62.23,0.297
120.39,62.41,0.297
120.40,62.60,0.297
120.42,62.78,0.297
120.44,62.96,0.298
120.46,63.15,0.298
120.48,63.33,0.298
120.50,63.51,0.298
120.51,63.70,0.298
120.53,63.88,0.298
120.55,64.06,0.299
120.57,64.25,0.299
120.59,64.43,0.299
120.60,64.62,0.299
120.62,64.80,0.299
120.64,64.98,0.300
120.66,65.17,0.300
120.68,65.35,0.300
120.70,65.53,0.300
120.71,65.72,0.300
120.73,65.90,0.301
120.75,66.08,0.301
120.77,66.27,0.301
120.79,66.45,0.301
120.81,66.64,0.301
120.83,66.82,0.302
120.84,67.00,0.302
120.86,67.19,0.302
120.88,67.37,0.302
120.90,67.55,0.302
120.92,67.74,0.302
120.94,67.92,0.302
120.95,68.10,0.303
120.97,68.29,0.303
120.99,68.47,0.303
121.01,68.65,0.303
121.03,68.84,0.303
121.05,69.02,0.304
121.06,69.20,0.304
121.08,69.39,0.304
121.10,69.57,0.304
121.12,69.75,0.304
121.14,69.94,0.304
121.15,70.12,0.304
121.17,70.30,0.305
121.19,70.49,0.305
121.21,70.67,0.305
121.23,70.85,0.305
121.25,71.04,0.305
121.26,71.22,0.305
121.28,71.40,0.306
121.30,71.59,0.306
121.32,71.77,0.306
121.34,71.96,0.306
121.36,72.14,0.307
121.38,72.32,0.307
121.39,72.51,0.307
121.41,72.69,0.307
121.43,72.87,0.307
121.45,73.06,0.307
121.47,73.24,0.308
121.49,73.42,0.308
121.50,73.61,0.308
121.52,73.79,0.308
121.54,73.97,0.308
121.56,74.15,0.308
121.58,74.34,0.309
121.60,74.52,0.309
121.61,74.71,0.309
121.63,74.89,0.309
121.65,75.07,0.309
121.67,75.26,0.309
121.69,75.44,0.310
121.70,75.62,0.310
121.72,75.81,0.310
121.74,75.99,0.310
121.76,76.17,0.311
121.78,76.36,0.311
121.80,76.54,0.311
121.81,76.72,0.311
121.83,76.91,0.311
121.85,77.09,0.312
121.87,77.27,0.312
121.89,77.46,0.312
121.91,77.64,0.312
121.93,77.82,0.312
121.94,78.01,0.313
121.96,78.19,0.313
121.98,78.37,0.313
122.00,78.56,0.313
122.02,78.74,0.313
122.04,78.92,0.313
122.05,79.11,0.314
122.07,79.29,0.314
122.09,79.48,0.314
122.11,79.66,0.314
122.13,79.84,0.314
122.15,80.03,0.315
122.16,80.21,0.315
122.18,80.39,0.315
122.20,80.58,0.315
122.22,80.76,0.315
122.24,80.95,0.316
122.25,81.13,0.316
122.27,81.31,0.316
122.29,81.49,0.316
122.31,81.68,0.316
122.33,81.86,0.317
122.35,82.04,0.317
122.36,82.23,0.317
122.38,82.41,0.317
122.40,82.60,0.317
122.42,82.78,0.317
122.44,82.96,0.318
122.46,83.15,0.318
122.48,83.33,0.318
122.49,83.51,0.318
122.51,83.70,0.318
122.53,83.88,0.318
122.55,84.06,0.318
122.57,84.25,0.319
122.59,84.43,0.319
122.60,84.61,0.319
122.62,84.80,0.319
122.64,84.98,0.319
122.66,85.16,0.319
122.68,85.35,0.320
122.70,85.53,0.320
122.71,85.71,0.320
122.73,85.90,0.320
122.75,86.08,0.320
122.77,86.26,0.320
122.79,86.45,0.321
122.80,86.63,0.321
122.82,86.82,0.321
122.84,87.00,0.321
122.86,87.18,0.321
122.88,87.37,0.321
122.90,87.55,0.322
122.91,87.73,0.322
122.93,87.92,0.322
122.95,88.10,0.322
122.97,88.28,0.322
122.99,88.47,0.323
123.01,88.65,0.323
123.03,88.83,0.323
123.04,89.02,0.323
123.06,89.20,0.323
123.08,89.38,0.324
123.10,89.57,0.324
123.12,89.75,0.324
123.14,89.93,0.324
123.15,90.12,0.324
123.17,90.30,0.325
123.19,90.48,0.325
123.21,90.67,0.325
123.23,90.85,0.325
123.25,91.03,0.325
123.26,91.22,0.326
123.28,91.40,0.326
123.30,91.58,0.326
123.32,91.77,0.326
123.34,91.95,0.327
123.35,92.13,0.327
123.37,92.32,0.327
123.39,92.50,0.327
123.41,92.69,0.327
123.43,92.87,0.328
123.45,93.05,0.328
123.46,93.24,0.328
123.48,93.42,0.328
123.50,93.60,0.329
123.52,93.79,0.329
123.54,93.97,0.329
123.56,94.15,0.329
123.58,94.34,0.329
123.59,94.52,0.330
123.61,94.70,0.330
123.63,94.89,0.330
123.65,95.07,0.330
123.67,95.26,0.331
123.69,95.44,0.331
123.70,95.62,0.331
123.72,95.81,0.331
123.74,95.99,0.331
123.76,96.17,0.332
123.78,96.36,0.332
123.80,96.54,0.332
123.81,96.72,0.332
123.83,96.91,0.332
123.85,97.09,0.332
123.87,97.27,0.333
123.89,97.46,0.333
123.90,97.64,0.333
123.92,97.82,0.333
123.94,98.01,0.333
123.96,98.19,0.334
123.98,98.37,0.334
124.00,98.56,0.334
124.01,98.74,0.334
124.03,98.92,0.334
124.05,99.11,0.334
124.07,99.29,0.335
124.09,99.47,0.335
124.11,99.66,0.335
124.13,99.84,0.335
124.14,100.02,0.335
124.16,100.21,0.335
124.18,100.39,0.336
124.20,100.57,0.336
124.22,100.76,0.336
124.24,100.94,0.336
124.25,101.12,0.336
124.27,101.31,0.336
124.29,101.49,0.337
124.31,101.67,0.337
124.33,101.86,0.337
124.35,102.04,0.337
124.36,102.23,0.337
124.38,102.41,0.338
124.40,102.59,0.338
124.42,102.78,0.338
124.44,102.96,0.338
124.45,103.14,0.338
124.47,103.33,0.338
124.49,103.51,0.338
124.51,103.70,0.339
124.53,103.88,0.339
124.55,104.06,0.339
124.56,104.24,0.339
124.58,104.43,0.339
124.60,104.61,0.339
124.62,104.79,0.340
124.64,104.98,0.340
124.66,105.16,0.340
124.68,105.34,0.340
124.69,105.53,0.340
124.71,105.71,0.340
124.73,105.90,0.341
124.75,106.08,0.341
124.77,106.26,0.341
124.79,106.45,0.341
124.80,106.63,0.341
124.82,106.81,0.341
124.84,107.00,0.341
124.86,107.18,0.342
124.88,107.37,0.342
124.90,107.55,0.342
124.91,107.73,0.342
124.93,107.91,0.342
124.95,108.10,0.342
124.97,108.28,0.342
124.99,108.47,0.342
125.00,108.65,0.343
125.02,108.83,0.343
125.04,109.02,0.343
125.06,109.20,0.343
125.08,109.38,0.343
125.10,109.57,0.343
125.11,109.75,0.343
125.13,109.93,0.344
125.15,110.12,0.344
125.17,110.30,0.344
125.19,110.49,0.344
125.21,110.67,0.344
125.23,110.85,0.344
125.24,111.03,0.344
125.26,111.22,0.344
125.28,111.40,0.344
125.30,111.59,0.344
125.32,111.77,0.344
125.34,111.95,0.344
125.35,112.13,0.345
125.37,112.32,0.345
125.39,112.50,0.345
125.41,112.69,0.345
125.43,112.87,0.345
125.45,113.05,0.345
125.46,113.24,0.345
125.48,113.42,0.345
125.50,113.60,0.346
125.52,113.79,0.346
125.54,113.97,0.346
125.55,114.15,0.346
125.57,114.34,0.346
125.59,114.52,0.346
125.61,114.70,0.346
125.63,114.89,0.346
125.65,115.07,0.346
125.66,115.25,0.346
125.68,115.44,0.346
125.70,115.62,0.347
125.72,115.80,0.347
125.74,115.99,0.347
125.76,116.17,0.347
125.78,116.36,0.347
125.79,116.54,0.347
125.81,116.72,0.347
125.83,116.91,0.347
125.85,117.09,0.347
125.87,117.27,0.347
125.89,117.46,0.347
125.90,117.64,0.348
125.92,117.82,0.348
125.94,118.01,0.348
125.96,118.19,0.348
125.98,118.37,0.348
126.00,118.56,0.348
126.01,118.74,0.348
126.03,118.92,0.348
126.05,119.11,0.348
126.07,119.29,0.348
126.09,119.47,0.349
126.10,119.66,0.349
126.12,119.84,0.349
126.14,120.02,0.349
126.16,120.21,0.349
126.18,120.39,0.349
126.20,120.57,0.349
126.21,120.76,0.349
126.23,120.94,0.349
126.25,121.12,0.350
126.27,121.31,0.350
126.29,121.49,0.350
126.31,121.67,0.350
126.33,121.86,0.350
126.34,122.04,0.350
126.36,122.23,0.350
126.38,122.41,0.350
126.40,122.59,0.350
126.42,122.77,0.350
126.44,122.96,0.351
126.45,123.14,0.351
126.47,123.33,0.351
126.49,123.51,0.351
126.51,123.69,0.351
126.53,123.88,0.351
126.55,124.06,0.351
126.56,124.24,0.351
126.58,124.43,0.351
126.60,124.61,0.351
126.62,124.80,0.352
126.64,124.98,0.352
126.65,125.16,0.352
126.67,125.35,0.352
126.69,125.53,0.352
126.71,125.71,0.352
126.73,125.90,0.352
126.75,126.08,0.352
126.76,126.26,0.352
126.78,126.45,0.353
126.80,126.63,0.353
126.82,126.81,0.353
126.84,127.00,0.353
126.86,127.18,0.353
126.88,127.36,0.353
126.89,127.55,0.353
126.91,127.73,0.353
126.93,127.91,0.353
126.95,128.10,0.353
126.97,128.28,0.354
126.99,128.46,0.354
127.00,128.65,0.354
127.02,128.83,0.354
127.04,129.01,0.354
127.06,129.20,0.354
127.08,129.38,0.354
127.10,129.57,0.354
127.11,129.75,0.354
127.13,129.93,0.354
127.15,130.12,0.355
127.17,130.30,0.355
127.19,130.48,0.355
127.20,130.67,0.355
127.22,130.85,0.355
127.24,131.03,0.355
127.26,131.22,0.355
127.28,131.40,0.355
127.30,131.58,0.355
127.31,131.76,0.356
127.33,131.95,0.356
127.35,132.13,0.356
127.37,132.32,0.356
127.39,132.50,0.356
127.41,132.68,0.356
127.43,132.87,0.356
127.44,133.05,0.356
127.46,133.23,0.356
127.48,133.42,0.357
127.50,133.60,0.357
127.52,133.78,0.357
127.54,133.97,0.357
127.55,134.15,0.357
127.57,134.33,0.357
127.59,134.52,0.357
127.61,134.70,0.358
127.63,134.88,0.358
127.65,135.07,0.358
127.66,135.25,0.358
127.68,135.44,0.358
127.70,135.62,0.358
127.72,135.80,0.358
127.74,135.99,0.359
127.75,136.17,0.359
127.77,136.35,0.359
127.79,136.54,0.359
127.81,136.72,0.359
127.83,136.90,0.359
127.85,137.09,0.359
127.86,137.27,0.359
127.88,137.45,0.359
127.90,137.64,0.360
127.92,137.82,0.360
127.94,138.00,0.360
127.96,138.19,0.360
127.98,138.37,0.360
127.99,138.55,0.360
128.01,138.74,0.360
128.03,138.92,0.361
128.05,139.10,0.361
128.07,139.29,0.361
128.09,139.47,0.361
128.10,139.65,0.361
128.12,139.84,0.361
128.14,140.02,0.361
128.16,140.20,0.362
128.18,140.39,0.362
128.20,140.57,0.362
128.21,140.75,0.362
128.23,140.94,0.362
128.25,141.12,0.362
128.27,141.30,0.363
128.29,141.49,0.363
128.30,141.67,0.363
128.32,141.85,0.363
128.34,142.04,0.363
128.36,142.22,0.363
128.38,142.40,0.364
128.40,142.59,0.364
128.41,142.77,0.364
128.43,142.96,0.364
128.45,143.14,0.364
128.47,143.32,0.364
128.49,143.50,0.365
128.51,143.69,0.365
128.53,143.87,0.365
128.54,144.05,0.365
128.56,144.24,0.365
128.58,144.42,0.366
128.60,144.61,0.366
128.62,144.79,0.366
128.64,144.97,0.366
128.65,145.16,0.366
128.67,145.34,0.367
128.69,145.52,0.367
128.71,145.71,0.367
128.73,145.89,0.367
128.75,146.07,0.367
128.76,146.26,0.368
128.78,146.44,0.368
128.80,146.62,0.368
128.82,146.81,0.368
128.84,146.99,0.368
128.85,147.17,0.369
128.87,147.36,0.369
128.89,147.54,0.369
128.91,147.72,0.369
128.93,147.91,0.369
128.95,148.09,0.370
128.96,148.27,0.370
128.98,148.46,0.370
129.00,148.64,0.370
129.02,148.82,0.370
129.04,149.01,0.371
129.06,149.19,0.371
129.08,149.37,0.371
129.09,149.56,0.371
129.11,149.74,0.372
129.13,149.92,0.372
129.15,150.11,0.372
129.17,150.29,0.372
129.19,150.48,0.373
129.20,150.66,0.373
129.22,150.84,0.373
129.24,151.03,0.373
129.26,151.21,0.374
129.28,151.39,0.374
129.30,151.58,0.374
129.31,151.76,0.374
129.33,151.94,0.374
129.35,152.13,0.374
129.37,152.31,0.375
129.39,152.49,0.375
129.40,152.68,0.375
129.42,152.86,0.375
129.44,153.04,0.376
129.46,153.23,0.376
129.48,153.41,0.376
129.50,153.59,0.376
129.51,153.78,0.377
129.53,153.96,0.377
129.55,154.15,0.377
129.57,154.33,0.377
129.59,154.51,0.378
129.61,154.69,0.378
129.63,154.88,0.378
129.64,155.06,0.378
129.66,155.24,0.378
129.68,155.43,0.379
129.70,155.61,0.379
129.72,155.79,0.379
129.74,155.98,0.379
129.75,156.16,0.380
129.77,156.34,0.380
129.79,156.53,0.380
129.81,156.71,0.381
129.83,156.90,0.381
129.85,157.08,0.381
129.86,157.26,0.382
129.88,157.45,0.382
129.90,157.63,0.382
129.92,157.81,0.383
129.94,158.00,0.383
129.95,158.18,0.383
129.97,158.36,0.383
129.99,158.54,0.384
130.01,158.73,0.384
130.03,158.91,0.384
130.05,159.10,0.385
130.06,159.28,0.385
130.08,159.46,0.385
130.10,159.65,0.386
130.12,159.83,0.386
130.14,160.01,0.387
130.16,160.20,0.387
130.18,160.38,0.387
130.19,160.56,0.388
130.21,160.75,0.388
130.23,160.93,0.389
130.25,161.11,0.389
130.27,161.30,0.389
130.29,161.48,0.390
130.30,161.66,0.390
130.32,161.85,0.390
130.34,162.03,0.391
130.36,162.21,0.391
130.38,162.40,0.392
130.40,162.58,0.392
130.41,162.76,0.392
130.43,162.95,0.393
130.45,163.13,0.393
130.47,163.31,0.394
130.49,163.49,0.394
130.50,163.68,0.394
130.52,163.86,0.395
130.54,164.04,0.395
130.56,164.23,0.396
130.58,164.41,0.396
130.60,164.60,0.397
130.61,164.78,0.397
130.63,164.96,0.398
130.65,165.15,0.398
130.67,165.33,0.399
130.69,165.51,0.399
130.71,165.70,0.400
130.73,165.88,0.400
130.74,166.06,0.401
130.76,166.24,0.401
130.78,166.43,0.401
130.80,166.61,0.402
130.82,166.80,0.402
130.84,166.98,0.403
130.85,167.16,0.404
130.87,167.35,0.406
130.89,167.53,0.406
130.91,167.71,0.407
130.93,167.90,0.407
130.95,168.08,0.407
130.96,168.26,0.408
130.98,168.45,0.408
131.00,168.63,0.408
131.02,168.81,0.409
131.04,169.00,0.409
131.05,169.18,0.410
131.07,169.36,0.410
131.09,169.54,0.410
131.11,169.73,0.411
131.13,169.91,0.411
131.15,170.09,0.412
131.16,170.28,0.412
131.18,170.46,0.413
131.20,170.64,0.414
131.22,170.83,0.414
131.24,171.01,0.415
131.26,171.20,0.415
131.28,171.38,0.416
131.29,171.56,0.417
131.31,171.74,0.417
131.33,171.93,0.418
131.35,172.11,0.418
131.37,172.30,0.419
131.39,172.48,0.420
131.40,172.66,0.420
131.42,172.84,0.421
131.44,173.03,0.421
131.46,173.21,0.422
131.48,173.39,0.423
131.50,173.58,0.424
131.51,173.76,0.424
131.53,173.95,0.426
131.55,174.13,0.426
131.57,174.31,0.427
131.59,174.50,0.428
131.60,174.68,0.429
131.62,174.86,0.429
131.64,175.04,0.430
131.66,175.23,0.430
131.68,175.41,0.431
131.70,175.60,0.432
131.71,175.78,0.432
131.73,175.96,0.433
131.75,176.15,0.434
131.77,176.33,0.435
131.79,176.51,0.436
131.81,176.69,0.437
131.83,176.88,0.437
131.84,177.06,0.438
131.86,177.25,0.439
131.88,177.43,0.440
131.90,177.61,0.441
131.92,177.80,0.441
131.94,177.98,0.442
131.95,178.16,0.443
131.97,178.34,0.444
131.99,178.53,0.444
132.01,178.71,0.445
132.03,178.89,0.446
132.05,179.08,0.447
132.06,179.26,0.448
132.08,179.44,0.449
132.10,179.63,0.450
132.12,179.81,0.451
132.14,179.99,0.451
132.15,180.18,0.452
132.17,180.36,0.454
132.19,180.54,0.455
132.21,180.73,0.455
132.23,180.91,0.457
132.25,181.09,0.458
132.26,181.28,0.459
132.28,181.46,0.460
132.30,181.64,0.460
132.32,181.83,0.461
132.34,182.01,0.462
132.36,182.19,0.463
132.38,182.38,0.464
132.39,182.56,0.465
132.41,182.74,0.466
132.43,182.93,0.467
132.45,183.11,0.468
132.47,183.29,0.469
132.49,183.48,0.470
132.50,183.66,0.471
132.52,183.84,0.472
132.54,184.03,0.473
132.56,184.21,0.474
132.58,184.39,0.475
132.60,184.57,0.476
132.61,184.76,0.477
132.63,184.94,0.479
132.65,185.12,0.479
132.67,185.31,0.483
132.69,185.49,0.484
132.70,185.67,0.485
132.72,185.86,0.486
132.74,186.04,0.487
132.76,186.22,0.489
132.78,186.41,0.491
132.80,186.59,0.491
132.81,186.77,0.492
132.83,186.96,0.493
132.85,187.14,0.495
132.87,187.32,0.496
132.89,187.51,0.498
132.91,187.69,0.499
132.93,187.87,0.501
132.94,188.06,0.502
132.96,188.24,0.503
132.98,188.42,0.505
133.00,188.60,0.507
133.02,188.79,0.509
133.04,188.97,0.510
133.05,189.15,0.511
133.07,189.34,0.513
133.09,189.52,0.515
133.11,189.70,0.516
133.13,189.88,0.517
133.15,190.07,0.519
133.16,190.25,0.521
133.18,190.43,0.522
133.20,190.62,0.524
133.22,190.80,0.525
133.24,190.98,0.528
133.25,191.17,0.530
133.27,191.35,0.532
133.29,191.53,0.534
133.31,191.72,0.536
133.33,191.90,0.538
133.35,192.08,0.539
133.36,192.26,0.541
133.38,192.45,0.544
133.40,192.63,0.546
133.42,192.81,0.548
133.44,193.00,0.550
133.46,193.18,0.552
133.48,193.36,0.554
133.49,193.55,0.555
133.51,193.73,0.557
133.53,193.91,0.560
133.55,194.10,0.562
133.57,194.28,0.564
133.59,194.46,0.567
133.60,194.65,0.570
133.62,194.83,0.573
133.64,195.01,0.573
133.66,195.19,0.575
133.68,195.38,0.576
133.70,195.56,0.578
133.71,195.74,0.581
133.73,195.93,0.583
133.75,196.11,0.586
133.77,196.29,0.589
133.79,196.48,0.592
133.80,196.66,0.597
133.82,196.84,0.599
133.84,197.02,0.601
133.86,197.21,0.603
133.88,197.39,0.606
133.90,197.57,0.609
133.91,197.76,0.612
133.93,197.94,
133.95,198.12,
133.97,198.30,
133.99,,