File: DSC/2025_04_18_CBD_n60C_170C_5Cmin_x3.csv
Filename,2025_04_18_CBD_n60C_170C_5Cmin_x3
Instrument name,DSC2A-00468 (192.168.1.100)
Operator,Yarger
rundate,4/19/2025
Sample name,2025_04_18_CBD_n60C_170C_5Cmin_x3
proceduresegments,Data Off ; Equilibrate -60.00 °C; Data On ; Ramp 5.00 °C/min to 170.00 °C; Data Off ; Isothermal 0.1 min; Data On ; Ramp 10.00 °C/min to -60.00 °C; Data Off ; Isothermal 1.0 min; Data On ; Ramp 10.00 °C/min to 170.00 °C; Data Off ; Isothermal 0.1 min; Data On ; Ramp 10.00 °C/min to -60.00 °C; Data Off ; Isothermal 1.0 min; Data On ; Ramp 5.00 °C/min to 30.00 °C
[File Parameters]
Run date,4/19/2025 7:25:08 AM
Trios version,5.1.1.46572
Original File Name,
Current File Name,D:\DSC2500\JYarger\2025_04_18_CBD_n60C_170C_5Cmin_x3.tri
[Procedure]
Procedure Name,CBD_n60_170C_5Cmin_x3
Sample Name,2025_04_18_CBD_n60C_170C_5Cmin_x3
Sample Mass,3.48 mg
Reference Sample Mass,0 mg
Pan Mass,54.13 mg
Pan Number,39
Reference Pan Mass,53.66 mg
Reference Pan Number,46
Pan Type,Tzero Aluminum Hermetic
Comments,Hermetic Sealed Al DSC Consumables Pan/Lids.
Project Name,CA
Operator,Yarger
Test,Custom
Unload Max Temperature,30
Unload Min Temperature,30
Load Max Temperature,30
Load Min Temperature,30
Stop on Gas Flow Error,Yes
[Signal List]
Signal #1,Time (min)
Signal #2,Temperature (°C)
Signal #3,Heat Flow (mW)
Signal #4,Delta T (µV)
Signal #5,Delta Tzero (µV)
Signal #6,Tzero Temperature (°C)
Signal #7,Cell Purge (mL/min)
Signal #8,Heater Temp (°C)
Signal #9,Power Delivered (W)
Signal #10,Reference Junction Temperature (°C)
Signal #11,Flange Temperature (°C)
Signal #12,Heat Flow Phase (rad)
Signal #13,Total Heat Capacity (J/°C)
Signal #14,Heat Capacity (J/°C)
[Configuration]
Company Name,ASU
Instrument Name,DSC2A-00468
Instrument Type,DSC2500
Serial Number,DSC2A-00468
IP,192.168.1.100
Location of Instrument,MRRC
DisplayType,Unknown
Sample Interval ,0.1 s/pt
Selected Heat Flow,T4P
Exotherm Direction,Down
Cell Serial,DRC2-00792
Lid Type,Standard
Cooler,RCS 90
Leave Cooler on at End of Sequence,On
Gas 2,Nitrogen
Gas Selected,Channel 1
Flow Rate,50 mL/min
Secondary Purge,On
Licensed Heat Flow,Heat Flow T4P
Modulation Licensed,Yes
[Versions]
Common IDD Version,1
Cortex Version,VER 2.10.2.31
Driver,5.0.0.6
GDM Version,1.0.3.3
TouchscreenVersion,1.0.0.16145
FEP Version,1.2.1.21
FEP Bootloader,2.0.0.5
AutoSampler Version,2.1.1.26
Auto Sampler Bootloader,2.0.0.5
FCM Version,1.1.0.3
FCM Bootloader,2.0.0.5
[Experiment Logs]
Experiment Log Entry # 1,Data On set to 0
Experiment Log Entry # 3,Equilibrate Segment -60 (C) Started
Experiment Log Entry # 5,Air Cool is off.
Experiment Log Entry # 7,Data On set to 1
Experiment Log Entry # 9,Ramp Segment 5 C/min to 170 Started
Experiment Log Entry # 11,Data On set to 0
Experiment Log Entry # 13,Isothermal Segment 0.1 min started
Experiment Log Entry # 15,Data On set to 1
Experiment Log Entry # 17,Ramp Segment 10 C/min to -60 Started
Experiment Log Entry # 19,Data On set to 0
Experiment Log Entry # 21,Isothermal Segment 1 min started
Experiment Log Entry # 23,Data On set to 1
Experiment Log Entry # 25,Ramp Segment 10 C/min to 170 Started
Experiment Log Entry # 27,Data On set to 0
Experiment Log Entry # 29,Isothermal Segment 0.1 min started
Experiment Log Entry # 31,Data On set to 1
Experiment Log Entry # 33,Ramp Segment 10 C/min to -60 Started
Experiment Log Entry # 35,Data On set to 0
Experiment Log Entry # 37,Isothermal Segment 1 min started
Experiment Log Entry # 39,Data On set to 1
Experiment Log Entry # 41,Ramp Segment 5 C/min to 30 Started
[Method Log]
Method Log Entry # 1,Data Off
Method Log Entry # 2,Equilibrate -60 °C
Method Log Entry # 3,Data On
Method Log Entry # 4,(Ramp 230953) Ramp 5 °C/minute to 170 °C
Method Log Entry # 5,Data Off
Method Log Entry # 6,Isothermal 0.1 minutes
Method Log Entry # 7,Data On
Method Log Entry # 8,(Ramp 230957) Ramp 10 °C/minute to -60 °C
Method Log Entry # 9,Data Off
Method Log Entry # 10,Isothermal 1 minutes
Method Log Entry # 11,Data On
Method Log Entry # 12,(Ramp 230961) Ramp 10 °C/minute to 170 °C
Method Log Entry # 13,Data Off
Method Log Entry # 14,Isothermal 0.1 minutes
Method Log Entry # 15,Data On
Method Log Entry # 16,(Ramp 230965) Ramp 10 °C/minute to -60 °C
Method Log Entry # 17,Data Off
Method Log Entry # 18,Isothermal 1 minutes
Method Log Entry # 19,Data On
Method Log Entry # 20,(Ramp 230969) Ramp 5 °C/minute to 30 °C
Cell Serial,DRC2-00792
[T1 Calibration]
Slope,-0.008529666
Offset,9.636258
Initial Temperature,98.23
GUID,f8bfdadc-4977-4fdf-ba6d-0ba9134940c3
[TZero Calibration]
Date Applied,11/29/2022 4:06:13 PM
Description,From -89.059 °C to 396.009 °C at 20.000°C/min
Gas Type,Nitrogen
Pan Type,None
Source Files 1,C:\Users\yargerlab\Desktop\DSC Data\General\TZero_calibration_11_29_22_2nd(2).tri
Source Files 2,C:\Users\yargerlab\Desktop\DSC Data\General\TZero_calibration_11_29_22_2nd(3).tri
Delta T Offset,13.05235
Delta T Slope,-0.007271007
Delta T0 Offset,-13.69128
Delta T0 Slope,0.06063341
[Temperature Calibration]
Date Applied,11/29/2022 7:12:28 PM
Description,From 106.590 °C to 186.590 °C at 10.000°C/min
Gas Type,Nitrogen
Pan Type,Tzero Aluminum Hermetic
Source Files 1,C:\Users\yargerlab\Desktop\DSC Data\General\Indium(6).tri
Measured 1,157.391
Known 1,156.598
[Cell Constant Calibration]
Date Applied,11/29/2022 7:12:29 PM
Description,From 106.590 °C to 186.590 °C at 10.000°C/min
Gas Type,Nitrogen
Pan Type,Tzero Aluminum Hermetic
Source Files 1,C:\Users\yargerlab\Desktop\DSC Data\General\Indium(6).tri
T4P KCell,1.006051
Onset Slope,63.26126 mW/°C
[Direct Cp Calibration]
Date Applied,11/30/2022 11:04:51 AM
Description,From -79.983 °C to 298.409 °C at 10.000°C/min
Gas Type,Nitrogen
Pan Type,Tzero Aluminum Hermetic
Source Files 1,C:\Users\yargerlab\Desktop\DSC Data\General\Sapphire_Heat_Capacity_11_30_22.tri
[Rev Cp Calibration]
Date Applied,11/30/2022 1:58:51 PM
Description,From -79.996 °C to 292.812 °C at 3.000°C/min
Gas Type,Nitrogen
Pan Type,Tzero Aluminum Hermetic
Source Files 1,C:\Users\yargerlab\Desktop\DSC Data\General\Sapphire_MDSC_Calibration_11_30_22.tri
[step]
Ramp 5.00 °C/min to 170.00 °C
Time,Temperature,Heat Flow (Normalized)
min,°C,W/g
0.00,-59.67,-0.046
0.03,-59.69,-0.045
0.06,-59.69,-0.032
0.09,-59.66,-0.024
0.13,-59.60,-0.015
0.16,-59.50,0.000
0.19,-59.39,0.018
0.22,-59.27,0.032
0.25,-59.14,0.047
0.29,-59.00,0.058
0.32,-58.86,0.065
0.35,-58.72,0.071
0.38,-58.57,0.075
0.41,-58.43,0.078
0.44,-58.28,0.081
0.48,-58.13,0.083
0.51,-57.98,0.084
0.54,-57.83,0.086
0.57,-57.67,0.087
0.60,-57.52,0.088
0.63,-57.37,0.088
0.67,-57.21,0.089
0.70,-57.06,0.090
0.73,-56.90,0.090
0.76,-56.75,0.091
0.79,-56.59,0.091
0.82,-56.44,0.091
0.85,-56.28,0.092
0.89,-56.13,0.092
0.92,-55.97,0.092
0.95,-55.82,0.092
0.98,-55.66,0.092
1.01,-55.50,0.092
1.05,-55.35,0.092
1.08,-55.19,0.093
1.11,-55.03,0.093
1.14,-54.88,0.092
1.17,-54.72,0.093
1.20,-54.56,0.093
1.23,-54.41,0.092
1.27,-54.25,0.092
1.30,-54.09,0.092
1.33,-53.93,0.092
1.36,-53.78,0.092
1.39,-53.62,0.092
1.43,-53.46,0.092
1.46,-53.30,0.092
1.49,-53.15,0.092
1.52,-52.99,0.092
1.55,-52.83,0.092
1.58,-52.67,0.092
1.62,-52.52,0.092
1.65,-52.36,0.091
1.68,-52.20,0.091
1.71,-52.04,0.091
1.74,-51.88,0.092
1.77,-51.73,0.091
1.81,-51.57,0.091
1.84,-51.41,0.091
1.87,-51.25,0.091
1.90,-51.10,0.091
1.93,-50.94,0.091
1.96,-50.78,0.091
1.99,-50.62,0.091
2.03,-50.46,0.091
2.06,-50.30,0.091
2.09,-50.15,0.091
2.12,-49.99,0.090
2.15,-49.83,0.091
2.19,-49.67,0.090
2.22,-49.52,0.090
2.25,-49.36,0.090
2.28,-49.20,0.090
2.31,-49.04,0.090
2.34,-48.88,0.090
2.38,-48.72,0.090
2.41,-48.57,0.090
2.44,-48.41,0.090
2.47,-48.25,0.090
2.50,-48.09,0.090
2.53,-47.93,0.090
2.56,-47.78,0.090
2.60,-47.62,0.090
2.63,-47.46,0.090
2.66,-47.30,0.090
2.69,-47.14,0.090
2.72,-46.98,0.090
2.76,-46.83,0.089
2.79,-46.67,0.089
2.82,-46.51,0.089
2.85,-46.35,0.089
2.88,-46.19,0.089
2.91,-46.04,0.089
2.94,-45.88,0.089
2.98,-45.72,0.089
3.01,-45.56,0.089
3.04,-45.40,0.089
3.07,-45.24,0.089
3.10,-45.08,0.089
3.14,-44.93,0.089
3.17,-44.77,0.089
3.20,-44.61,0.089
3.23,-44.45,0.089
3.26,-44.29,0.089
3.29,-44.14,0.089
3.33,-43.98,0.089
3.36,-43.82,0.089
3.39,-43.66,0.089
3.42,-43.50,0.089
3.45,-43.34,0.089
3.48,-43.19,0.089
3.51,-43.03,0.089
3.55,-42.87,0.089
3.58,-42.71,0.089
3.61,-42.55,0.089
3.64,-42.39,0.089
3.67,-42.24,0.089
3.71,-42.08,0.089
3.74,-41.92,0.089
3.77,-41.76,0.089
3.80,-41.60,0.089
3.83,-41.44,0.089
3.86,-41.29,0.089
3.89,-41.13,0.089
3.93,-40.97,0.089
3.96,-40.81,0.089
3.99,-40.65,0.089
4.02,-40.49,0.089
4.05,-40.33,0.089
4.09,-40.18,0.089
4.12,-40.02,0.089
4.15,-39.86,0.089
4.18,-39.70,0.089
4.21,-39.54,0.089
4.24,-39.38,0.089
4.28,-39.22,0.089
4.31,-39.07,0.089
4.34,-38.91,0.089
4.37,-38.75,0.089
4.40,-38.59,0.089
4.43,-38.43,0.089
4.46,-38.27,0.089
4.50,-38.11,0.089
4.53,-37.95,0.089
4.56,-37.80,0.089
4.59,-37.64,0.089
4.62,-37.48,0.089
4.65,-37.32,0.089
4.69,-37.16,0.089
4.72,-37.00,0.089
4.75,-36.84,0.089
4.78,-36.69,0.089
4.81,-36.53,0.089
4.85,-36.37,0.089
4.88,-36.21,0.089
4.91,-36.05,0.089
4.94,-35.89,0.089
4.97,-35.74,0.089
5.00,-35.58,0.089
5.04,-35.42,0.089
5.07,-35.26,0.089
5.10,-35.10,0.089
5.13,-34.94,0.089
5.16,-34.78,0.089
5.19,-34.63,0.089
5.23,-34.47,0.089
5.26,-34.31,0.089
5.29,-34.15,0.089
5.32,-33.99,0.089
5.35,-33.83,0.089
5.38,-33.67,0.089
5.41,-33.52,0.089
5.45,-33.36,0.089
5.48,-33.20,0.089
5.51,-33.04,0.089
5.54,-32.88,0.089
5.57,-32.72,0.089
5.60,-32.57,0.089
5.64,-32.41,0.089
5.67,-32.25,0.089
5.70,-32.09,0.089
5.73,-31.93,0.089
5.76,-31.77,0.089
5.80,-31.61,0.089
5.83,-31.46,0.089
5.86,-31.30,0.089
5.89,-31.14,0.089
5.92,-30.98,0.089
5.95,-30.82,0.089
5.99,-30.66,0.089
6.02,-30.51,0.089
6.05,-30.35,0.089
6.08,-30.19,0.089
6.11,-30.03,0.089
6.14,-29.87,0.089
6.18,-29.71,0.089
6.21,-29.56,0.089
6.24,-29.40,0.089
6.27,-29.24,0.089
6.30,-29.08,0.089
6.33,-28.92,0.089
6.36,-28.76,0.089
6.40,-28.60,0.089
6.43,-28.45,0.089
6.46,-28.29,0.089
6.49,-28.13,0.089
6.52,-27.97,0.089
6.55,-27.81,0.089
6.59,-27.65,0.089
6.62,-27.49,0.089
6.65,-27.34,0.089
6.68,-27.18,0.089
6.71,-27.02,0.089
6.75,-26.86,0.089
6.78,-26.70,0.089
6.81,-26.54,0.089
6.84,-26.39,0.090
6.87,-26.23,0.090
6.90,-26.07,0.090
6.94,-25.91,0.090
6.97,-25.75,0.089
7.00,-25.59,0.089
7.03,-25.44,0.090
7.06,-25.28,0.089
7.09,-25.12,0.089
7.13,-24.96,0.089
7.16,-24.80,0.089
7.19,-24.64,0.089
7.22,-24.48,0.089
7.25,-24.32,0.089
7.28,-24.17,0.089
7.31,-24.01,0.089
7.35,-23.85,0.089
7.38,-23.69,0.089
7.41,-23.53,0.089
7.44,-23.37,0.089
7.47,-23.22,0.089
7.50,-23.06,0.089
7.54,-22.90,0.089
7.57,-22.74,0.089
7.60,-22.59,0.089
7.63,-22.43,0.089
7.66,-22.27,0.089
7.70,-22.11,0.089
7.73,-21.95,0.089
7.76,-21.79,0.089
7.79,-21.63,0.089
7.82,-21.47,0.090
7.85,-21.31,0.090
7.89,-21.16,0.090
7.92,-21.00,0.090
7.95,-20.84,0.090
7.98,-20.68,0.090
8.01,-20.52,0.090
8.04,-20.36,0.090
8.08,-20.21,0.090
8.11,-20.05,0.090
8.14,-19.89,0.090
8.17,-19.73,0.090
8.20,-19.57,0.090
8.23,-19.41,0.090
8.26,-19.25,0.090
8.30,-19.09,0.090
8.33,-18.94,0.090
8.36,-18.78,0.090
8.39,-18.62,0.090
8.42,-18.46,0.090
8.45,-18.30,0.090
8.49,-18.14,0.090
8.52,-17.99,0.090
8.55,-17.83,0.090
8.58,-17.67,0.090
8.61,-17.51,0.090
8.65,-17.35,0.090
8.68,-17.19,0.090
8.71,-17.03,0.090
8.74,-16.88,0.090
8.77,-16.72,0.090
8.80,-16.56,0.090
8.83,-16.40,0.090
8.87,-16.24,0.090
8.90,-16.08,0.090
8.93,-15.93,0.090
8.96,-15.77,0.090
8.99,-15.61,0.090
9.03,-15.45,0.090
9.06,-15.29,0.090
9.09,-15.13,0.090
9.12,-14.97,0.090
9.15,-14.82,0.090
9.18,-14.66,0.090
9.22,-14.50,0.090
9.25,-14.34,0.090
9.28,-14.18,0.090
9.31,-14.02,0.090
9.34,-13.87,0.090
9.37,-13.71,0.090
9.40,-13.55,0.090
9.44,-13.39,0.090
9.47,-13.23,0.090
9.50,-13.07,0.090
9.53,-12.91,0.090
9.56,-12.76,0.091
9.60,-12.60,0.091
9.63,-12.44,0.091
9.66,-12.28,0.091
9.69,-12.12,0.091
9.72,-11.97,0.091
9.75,-11.81,0.091
9.78,-11.65,0.091
9.82,-11.49,0.091
9.85,-11.33,0.091
9.88,-11.17,0.091
9.91,-11.01,0.091
9.94,-10.85,0.091
9.98,-10.70,0.091
10.01,-10.54,0.091
10.04,-10.38,0.091
10.07,-10.22,0.091
10.10,-10.06,0.091
10.13,-9.90,0.091
10.17,-9.75,0.091
10.20,-9.59,0.091
10.23,-9.43,0.091
10.26,-9.27,0.091
10.29,-9.11,0.091
10.32,-8.95,0.091
10.35,-8.79,0.091
10.39,-8.63,0.091
10.42,-8.48,0.091
10.45,-8.32,0.091
10.48,-8.16,0.091
10.51,-8.00,0.091
10.55,-7.84,0.091
10.58,-7.69,0.091
10.61,-7.53,0.091
10.64,-7.37,0.091
10.67,-7.21,0.091
10.70,-7.05,0.091
10.73,-6.89,0.091
10.77,-6.74,0.092
10.80,-6.58,0.092
10.83,-6.42,0.092
10.86,-6.26,0.092
10.89,-6.10,0.092
10.93,-5.94,0.092
10.96,-5.78,0.092
10.99,-5.63,0.092
11.02,-5.47,0.092
11.05,-5.31,0.092
11.08,-5.15,0.092
11.12,-4.99,0.092
11.15,-4.83,0.092
11.18,-4.67,0.092
11.21,-4.52,0.092
11.24,-4.36,0.092
11.27,-4.20,0.092
11.30,-4.04,0.092
11.34,-3.88,0.092
11.37,-3.72,0.092
11.40,-3.57,0.092
11.43,-3.41,0.092
11.46,-3.25,0.092
11.50,-3.09,0.092
11.53,-2.93,0.092
11.56,-2.77,0.092
11.59,-2.62,0.092
11.62,-2.46,0.092
11.65,-2.30,0.092
11.68,-2.14,0.092
11.72,-1.98,0.092
11.75,-1.82,0.092
11.78,-1.67,0.092
11.81,-1.51,0.092
11.84,-1.35,0.092
11.88,-1.19,0.093
11.91,-1.03,0.093
11.94,-0.87,0.093
11.97,-0.71,0.093
12.00,-0.56,0.093
12.03,-0.40,0.093
12.07,-0.24,0.093
12.10,-0.08,0.093
12.13,0.08,0.093
12.16,0.24,0.093
12.19,0.39,0.093
12.22,0.56,0.093
12.25,0.71,0.093
12.29,0.87,0.093
12.32,1.03,0.093
12.35,1.19,0.093
12.38,1.35,0.093
12.41,1.50,0.093
12.45,1.66,0.093
12.48,1.82,0.093
12.51,1.98,0.093
12.54,2.14,0.093
12.57,2.30,0.093
12.60,2.45,0.093
12.63,2.61,0.093
12.67,2.77,0.093
12.70,2.93,0.093
12.73,3.09,0.093
12.76,3.25,0.093
12.79,3.40,0.093
12.83,3.56,0.094
12.86,3.72,0.094
12.89,3.88,0.094
12.92,4.04,0.094
12.95,4.20,0.094
12.98,4.36,0.094
13.02,4.51,0.094
13.05,4.67,0.094
13.08,4.83,0.094
13.11,4.99,0.094
13.14,5.15,0.094
13.17,5.31,0.094
13.20,5.47,0.094
13.24,5.62,0.094
13.27,5.78,0.094
13.30,5.94,0.094
13.33,6.10,0.094
13.36,6.26,0.095
13.40,6.42,0.095
13.43,6.58,0.095
13.46,6.73,0.095
13.49,6.89,0.095
13.52,7.05,0.095
13.55,7.21,0.095
13.58,7.37,0.095
13.62,7.53,0.095
13.65,7.68,0.095
13.68,7.84,0.095
13.71,8.00,0.095
13.74,8.16,0.095
13.78,8.32,0.095
13.81,8.48,0.095
13.84,8.64,0.095
13.87,8.79,0.095
13.90,8.95,0.096
13.93,9.11,0.096
13.97,9.27,0.096
14.00,9.43,0.096
14.03,9.58,0.096
14.06,9.74,0.096
14.09,9.90,0.096
14.12,10.06,0.096
14.15,10.22,0.096
14.19,10.38,0.096
14.22,10.54,0.096
14.25,10.69,0.096
14.28,10.85,0.096
14.31,11.01,0.096
14.35,11.17,0.096
14.38,11.33,0.096
14.41,11.49,0.096
14.44,11.64,0.096
14.47,11.80,0.096
14.50,11.96,0.096
14.53,12.12,0.096
14.57,12.28,0.096
14.60,12.44,0.096
14.63,12.60,0.096
14.66,12.75,0.096
14.69,12.91,0.097
14.73,13.07,0.097
14.76,13.23,0.097
14.79,13.39,0.097
14.82,13.55,0.097
14.85,13.71,0.097
14.88,13.86,0.097
14.92,14.02,0.097
14.95,14.18,0.097
14.98,14.34,0.097
15.01,14.50,0.097
15.04,14.65,0.097
15.07,14.81,0.097
15.10,14.97,0.097
15.14,15.13,0.097
15.17,15.29,0.097
15.20,15.45,0.097
15.23,15.61,0.097
15.26,15.77,0.097
15.30,15.92,0.097
15.33,16.08,0.097
15.36,16.24,0.097
15.39,16.40,0.097
15.42,16.56,0.097
15.45,16.72,0.097
15.48,16.87,0.098
15.52,17.03,0.098
15.55,17.19,0.098
15.58,17.35,0.098
15.61,17.51,0.098
15.64,17.67,0.098
15.68,17.82,0.098
15.71,17.98,0.098
15.74,18.14,0.098
15.77,18.30,0.098
15.80,18.46,0.099
15.83,18.62,0.099
15.87,18.78,0.099
15.90,18.93,0.099
15.93,19.09,0.099
15.96,19.25,0.099
15.99,19.41,0.099
16.02,19.57,0.099
16.05,19.73,0.099
16.09,19.88,0.099
16.12,20.04,0.099
16.15,20.20,0.099
16.18,20.36,0.099
16.21,20.52,0.100
16.25,20.68,0.100
16.28,20.83,0.100
16.31,20.99,0.100
16.34,21.15,0.100
16.37,21.31,0.100
16.40,21.47,0.100
16.43,21.63,0.100
16.47,21.79,0.100
16.50,21.94,0.100
16.53,22.10,0.100
16.56,22.26,0.100
16.59,22.42,0.100
16.63,22.58,0.100
16.66,22.74,0.100
16.69,22.89,0.101
16.72,23.05,0.101
16.75,23.21,0.101
16.78,23.37,0.101
16.82,23.53,0.101
16.85,23.69,0.101
16.88,23.84,0.101
16.91,24.00,0.101
16.94,24.16,0.101
16.97,24.32,0.101
17.00,24.48,0.101
17.04,24.64,0.101
17.07,24.80,0.101
17.10,24.95,0.101
17.13,25.11,0.101
17.16,25.27,0.101
17.19,25.43,0.102
17.23,25.59,0.102
17.26,25.75,0.102
17.29,25.90,0.102
17.32,26.06,0.102
17.35,26.22,0.102
17.38,26.38,0.102
17.42,26.54,0.102
17.45,26.70,0.102
17.48,26.85,0.102
17.51,27.01,0.102
17.54,27.17,0.102
17.58,27.33,0.102
17.61,27.49,0.102
17.64,27.65,0.102
17.67,27.80,0.103
17.70,27.97,0.103
17.73,28.12,0.103
17.77,28.28,0.103
17.80,28.44,0.103
17.83,28.60,0.103
17.86,28.76,0.103
17.89,28.91,0.103
17.92,29.07,0.103
17.96,29.23,0.103
17.99,29.39,0.103
18.02,29.55,0.103
18.05,29.71,0.103
18.08,29.86,0.103
18.11,30.02,0.103
18.14,30.18,0.103
18.18,30.34,0.103
18.21,30.50,0.103
18.24,30.66,0.104
18.27,30.82,0.104
18.30,30.97,0.104
18.33,31.13,0.104
18.37,31.29,0.104
18.40,31.45,0.104
18.43,31.61,0.104
18.46,31.77,0.104
18.49,31.93,0.104
18.53,32.08,0.104
18.56,32.24,0.104
18.59,32.40,0.104
18.62,32.56,0.104
18.65,32.72,0.104
18.68,32.87,0.105
18.72,33.03,0.105
18.75,33.19,0.105
18.78,33.35,0.105
18.81,33.51,0.105
18.84,33.67,0.105
18.87,33.82,0.105
18.91,33.98,0.105
18.94,34.14,0.105
18.97,34.30,0.105
19.00,34.46,0.105
19.03,34.62,0.106
19.06,34.78,0.106
19.09,34.94,0.106
19.13,35.09,0.106
19.16,35.25,0.106
19.19,35.41,0.106
19.22,35.57,0.106
19.25,35.73,0.106
19.28,35.88,0.106
19.32,36.04,0.106
19.35,36.20,0.106
19.38,36.36,0.106
19.41,36.52,0.107
19.44,36.68,0.107
19.48,36.84,0.107
19.51,36.99,0.107
19.54,37.15,0.107
19.57,37.31,0.107
19.60,37.47,0.107
19.63,37.63,0.107
19.67,37.79,0.107
19.70,37.95,0.107
19.73,38.10,0.107
19.76,38.26,0.108
19.79,38.42,0.108
19.82,38.58,0.108
19.86,38.74,0.108
19.89,38.90,0.108
19.92,39.05,0.108
19.95,39.21,0.108
19.98,39.37,0.108
20.01,39.53,0.108
20.04,39.69,0.108
20.08,39.85,0.108
20.11,40.00,0.109
20.14,40.16,0.109
20.17,40.32,0.109
20.20,40.48,0.109
20.23,40.64,0.109
20.27,40.80,0.109
20.30,40.96,0.109
20.33,41.11,0.109
20.36,41.27,0.109
20.39,41.43,0.109
20.43,41.59,0.110
20.46,41.75,0.110
20.49,41.91,0.110
20.52,42.06,0.110
20.55,42.22,0.110
20.58,42.38,0.110
20.62,42.54,0.110
20.65,42.70,0.110
20.68,42.85,0.110
20.71,43.01,0.110
20.74,43.17,0.111
20.77,43.33,0.111
20.81,43.49,0.111
20.84,43.65,0.111
20.87,43.81,0.111
20.90,43.97,0.111
20.93,44.12,0.111
20.96,44.28,0.111
20.99,44.44,0.111
21.03,44.60,0.111
21.06,44.76,0.111
21.09,44.91,0.112
21.12,45.07,0.112
21.15,45.23,0.112
21.18,45.39,0.112
21.22,45.55,0.112
21.25,45.71,0.112
21.28,45.87,0.112
21.31,46.02,0.112
21.34,46.18,0.113
21.38,46.34,0.113
21.41,46.50,0.113
21.44,46.66,0.113
21.47,46.82,0.113
21.50,46.97,0.113
21.53,47.13,0.113
21.57,47.29,0.113
21.60,47.45,0.113
21.63,47.61,0.114
21.66,47.77,0.114
21.69,47.93,0.114
21.72,48.08,0.114
21.76,48.24,0.115
21.79,48.40,0.115
21.82,48.56,0.115
21.85,48.72,0.115
21.88,48.87,0.115
21.91,49.03,0.116
21.94,49.19,0.116
21.98,49.35,0.116
22.01,49.51,0.116
22.04,49.67,0.116
22.07,49.82,0.116
22.10,49.98,0.117
22.13,50.14,0.117
22.17,50.30,0.117
22.20,50.46,0.117
22.23,50.62,0.117
22.26,50.78,0.118
22.29,50.93,0.118
22.33,51.09,0.118
22.36,51.25,0.118
22.39,51.41,0.118
22.42,51.57,0.119
22.45,51.72,0.119
22.48,51.88,0.119
22.52,52.04,0.119
22.55,52.20,0.119
22.58,52.36,0.120
22.61,52.52,0.120
22.64,52.68,0.120
22.67,52.83,0.120
22.71,52.99,0.121
22.74,53.15,0.121
22.77,53.31,0.121
22.80,53.47,0.121
22.83,53.63,0.122
22.86,53.79,0.122
22.89,53.94,0.122
22.93,54.10,0.123
22.96,54.26,0.123
22.99,54.42,0.123
23.02,54.58,0.123
23.05,54.74,0.124
23.08,54.89,0.124
23.12,55.05,0.124
23.15,55.21,0.125
23.18,55.37,0.125
23.21,55.53,0.126
23.24,55.68,0.126
23.28,55.84,0.126
23.31,56.00,0.127
23.34,56.16,0.127
23.37,56.32,0.128
23.40,56.48,0.128
23.43,56.63,0.129
23.47,56.79,0.129
23.50,56.95,0.130
23.53,57.11,0.130
23.56,57.27,0.131
23.59,57.43,0.132
23.62,57.58,0.132
23.66,57.74,0.133
23.69,57.90,0.133
23.72,58.06,0.134
23.75,58.22,0.135
23.78,58.38,0.136
23.81,58.53,0.136
23.84,58.69,0.137
23.88,58.85,0.138
23.91,59.01,0.139
23.94,59.17,0.140
23.97,59.32,0.141
24.00,59.48,0.142
24.03,59.64,0.143
24.07,59.80,0.144
24.10,59.96,0.145
24.13,60.11,0.146
24.16,60.27,0.148
24.19,60.43,0.150
24.23,60.59,0.151
24.26,60.75,0.153
24.29,60.91,0.155
24.32,61.06,0.158
24.35,61.22,0.160
24.38,61.38,0.162
24.42,61.54,0.166
24.45,61.69,0.169
24.48,61.85,0.172
24.51,62.01,0.177
24.54,62.17,0.181
24.57,62.32,0.186
24.61,62.48,0.191
24.64,62.64,0.197
24.67,62.80,0.203
24.70,62.95,0.211
24.73,63.11,0.218
24.76,63.27,0.226
24.79,63.42,0.234
24.83,63.58,0.243
24.86,63.74,0.252
24.89,63.89,0.264
24.92,64.05,0.275
24.95,64.20,0.290
24.98,64.36,0.308
25.02,64.51,0.323
25.05,64.67,0.339
25.08,64.82,0.360
25.11,64.98,0.385
25.14,65.13,0.411
25.18,65.28,0.442
25.21,65.43,0.470
25.24,65.59,0.502
25.27,65.74,0.537
25.30,65.89,0.574
25.33,66.04,0.637
25.37,66.18,0.685
25.40,66.33,0.740
25.43,66.47,0.788
25.46,66.62,0.837
25.49,66.77,0.888
25.52,66.91,0.943
25.56,67.06,0.991
25.59,67.21,1.039
25.62,67.36,1.080
25.65,67.50,1.120
25.68,67.65,1.157
25.71,67.80,1.197
25.74,67.95,1.265
25.78,68.09,1.351
25.81,68.23,1.458
25.84,68.37,1.501
25.87,68.52,1.527
25.90,68.66,1.566
25.93,68.81,1.600
25.97,68.96,1.659
26.00,69.11,1.623
26.03,69.27,1.543
26.06,69.45,1.415
26.09,69.63,1.188
26.13,69.84,0.880
26.16,70.05,0.660
26.19,70.26,0.502
26.22,70.46,0.393
26.25,70.65,0.317
26.28,70.83,0.268
26.32,71.00,0.234
26.35,71.17,0.211
26.38,71.34,0.193
26.41,71.51,0.182
26.44,71.67,0.175
26.47,71.83,0.170
26.51,71.99,0.166
26.54,72.15,0.164
26.57,72.31,0.162
26.60,72.47,0.161
26.63,72.63,0.160
26.66,72.79,0.159
26.69,72.95,0.159
26.73,73.11,0.158
26.76,73.26,0.158
26.79,73.42,0.157
26.82,73.58,0.157
26.85,73.74,0.157
26.88,73.90,0.156
26.92,74.06,0.156
26.95,74.21,0.156
26.98,74.37,0.156
27.01,74.53,0.156
27.04,74.69,0.155
27.08,74.85,0.155
27.11,75.01,0.155
27.14,75.17,0.155
27.17,75.32,0.155
27.20,75.48,0.155
27.23,75.64,0.155
27.27,75.80,0.155
27.30,75.96,0.155
27.33,76.12,0.155
27.36,76.27,0.155
27.39,76.43,0.155
27.42,76.59,0.155
27.46,76.75,0.155
27.49,76.91,0.155
27.52,77.07,0.155
27.55,77.23,0.155
27.58,77.38,0.155
27.61,77.54,0.155
27.64,77.70,0.155
27.68,77.86,0.155
27.71,78.02,0.155
27.74,78.17,0.155
27.77,78.33,0.155
27.80,78.49,0.155
27.83,78.65,0.155
27.87,78.81,0.155
27.90,78.97,0.155
27.93,79.12,0.156
27.96,79.28,0.156
27.99,79.44,0.156
28.03,79.60,0.156
28.06,79.76,0.156
28.09,79.92,0.156
28.12,80.08,0.156
28.15,80.23,0.156
28.18,80.39,0.156
28.22,80.55,0.156
28.25,80.71,0.156
28.28,80.87,0.156
28.31,81.03,0.156
28.34,81.18,0.156
28.37,81.34,0.156
28.41,81.50,0.156
28.44,81.66,0.156
28.47,81.82,0.156
28.50,81.98,0.156
28.53,82.13,0.156
28.56,82.29,0.156
28.59,82.45,0.156
28.63,82.61,0.156
28.66,82.77,0.157
28.69,82.93,0.157
28.72,83.09,0.157
28.75,83.24,0.157
28.78,83.40,0.157
28.82,83.56,0.157
28.85,83.72,0.157
28.88,83.88,0.157
28.91,84.04,0.157
28.94,84.19,0.157
28.98,84.35,0.157
29.01,84.51,0.157
29.04,84.67,0.157
29.07,84.83,0.157
29.10,84.99,0.157
29.13,85.14,0.157
29.17,85.30,0.157
29.20,85.46,0.157
29.23,85.62,0.157
29.26,85.78,0.157
29.29,85.94,0.157
29.32,86.10,0.157
29.36,86.25,0.157
29.39,86.41,0.157
29.42,86.57,0.157
29.45,86.73,0.157
29.48,86.89,0.157
29.51,87.05,0.157
29.54,87.20,0.158
29.58,87.36,0.158
29.61,87.52,0.158
29.64,87.68,0.158
29.67,87.84,0.158
29.70,88.00,0.158
29.73,88.16,0.158
29.77,88.31,0.158
29.80,88.47,0.158
29.83,88.63,0.158
29.86,88.79,0.158
29.89,88.95,0.158
29.93,89.11,0.158
29.96,89.26,0.158
29.99,89.42,0.158
30.02,89.58,0.158
30.05,89.74,0.159
30.08,89.90,0.159
30.12,90.06,0.159
30.15,90.21,0.159
30.18,90.37,0.159
30.21,90.53,0.159
30.24,90.69,0.159
30.27,90.85,0.159
30.31,91.01,0.159
30.34,91.16,0.159
30.37,91.32,0.159
30.40,91.48,0.159
30.43,91.64,0.159
30.46,91.80,0.159
30.49,91.96,0.159
30.53,92.12,0.160
30.56,92.27,0.160
30.59,92.43,0.160
30.62,92.59,0.160
30.65,92.75,0.160
30.68,92.91,0.160
30.72,93.07,0.160
30.75,93.22,0.160
30.78,93.38,0.160
30.81,93.54,0.160
30.84,93.70,0.160
30.88,93.86,0.160
30.91,94.02,0.160
30.94,94.17,0.160
30.97,94.33,0.160
31.00,94.49,0.160
31.03,94.65,0.160
31.07,94.81,0.160
31.10,94.97,0.160
31.13,95.12,0.161
31.16,95.28,0.161
31.19,95.44,0.161
31.22,95.60,0.161
31.26,95.76,0.161
31.29,95.92,0.161
31.32,96.07,0.161
31.35,96.23,0.161
31.38,96.39,0.161
31.41,96.55,0.161
31.44,96.71,0.161
31.48,96.87,0.161
31.51,97.03,0.161
31.54,97.18,0.161
31.57,97.34,0.161
31.60,97.50,0.162
31.63,97.66,0.162
31.67,97.82,0.162
31.70,97.98,0.162
31.73,98.13,0.162
31.76,98.29,0.162
31.79,98.45,0.162
31.83,98.61,0.162
31.86,98.77,0.162
31.89,98.93,0.162
31.92,99.08,0.162
31.95,99.24,0.162
31.98,99.40,0.162
32.02,99.56,0.162
32.05,99.72,0.162
32.08,99.88,0.162
32.11,100.03,0.162
32.14,100.19,0.162
32.17,100.35,0.162
32.21,100.51,0.163
32.24,100.67,0.163
32.27,100.83,0.163
32.30,100.99,0.163
32.33,101.14,0.163
32.36,101.30,0.163
32.39,101.46,0.163
32.43,101.62,0.163
32.46,101.78,0.163
32.49,101.94,0.163
32.52,102.09,0.163
32.55,102.25,0.163
32.58,102.41,0.163
32.62,102.57,0.163
32.65,102.73,0.163
32.68,102.88,0.163
32.71,103.04,0.164
32.74,103.20,0.164
32.78,103.36,0.164
32.81,103.52,0.164
32.84,103.68,0.164
32.87,103.84,0.164
32.90,103.99,0.164
32.93,104.15,0.164
32.97,104.31,0.164
33.00,104.47,0.164
33.03,104.63,0.164
33.06,104.79,0.164
33.09,104.95,0.164
33.12,105.10,0.164
33.16,105.26,0.164
33.19,105.42,0.164
33.22,105.58,0.164
33.25,105.74,0.165
33.28,105.90,0.165
33.31,106.05,0.165
33.34,106.21,0.165
33.38,106.37,0.165
33.41,106.53,0.165
33.44,106.69,0.165
33.47,106.84,0.165
33.50,107.00,0.165
33.53,107.16,0.165
33.57,107.32,0.165
33.60,107.48,0.165
33.63,107.64,0.165
33.66,107.80,0.165
33.69,107.95,0.165
33.73,108.11,0.165
33.76,108.27,0.165
33.79,108.43,0.166
33.82,108.59,0.166
33.85,108.75,0.166
33.88,108.90,0.166
33.92,109.06,0.166
33.95,109.22,0.166
33.98,109.38,0.166
34.01,109.54,0.166
34.04,109.70,0.166
34.07,109.85,0.166
34.11,110.01,0.166
34.14,110.17,0.166
34.17,110.33,0.166
34.20,110.49,0.166
34.23,110.65,0.166
34.26,110.81,0.166
34.29,110.96,0.167
34.33,111.12,0.167
34.36,111.28,0.167
34.39,111.44,0.167
34.42,111.60,0.167
34.45,111.76,0.167
34.49,111.91,0.167
34.52,112.07,0.167
34.55,112.23,0.167
34.58,112.39,0.167
34.61,112.55,0.167
34.64,112.71,0.167
34.68,112.86,0.167
34.71,113.02,0.167
34.74,113.18,0.167
34.77,113.34,0.167
34.80,113.50,0.168
34.83,113.66,0.168
34.86,113.82,0.168
34.90,113.97,0.168
34.93,114.13,0.168
34.96,114.29,0.168
34.99,114.45,0.168
35.02,114.61,0.168
35.06,114.76,0.168
35.09,114.92,0.168
35.12,115.08,0.168
35.15,115.24,0.168
35.18,115.40,0.168
35.21,115.56,0.168
35.24,115.71,0.168
35.28,115.87,0.168
35.31,116.03,0.168
35.34,116.19,0.169
35.37,116.35,0.169
35.40,116.51,0.169
35.44,116.66,0.169
35.47,116.82,0.169
35.50,116.98,0.169
35.53,117.14,0.169
35.56,117.30,0.169
35.59,117.46,0.169
35.63,117.62,0.169
35.66,117.77,0.169
35.69,117.93,0.169
35.72,118.09,0.169
35.75,118.25,0.169
35.78,118.41,0.169
35.81,118.57,0.169
35.85,118.72,0.169
35.88,118.88,0.170
35.91,119.04,0.170
35.94,119.20,0.170
35.97,119.36,0.170
36.01,119.52,0.170
36.04,119.67,0.170
36.07,119.83,0.170
36.10,119.99,0.170
36.13,120.15,0.170
36.16,120.31,0.170
36.19,120.47,0.170
36.23,120.62,0.170
36.26,120.78,0.170
36.29,120.94,0.170
36.32,121.10,0.170
36.35,121.26,0.170
36.39,121.42,0.170
36.42,121.58,0.170
36.45,121.73,0.170
36.48,121.89,0.170
36.51,122.05,0.170
36.54,122.21,0.170
36.58,122.37,0.171
36.61,122.53,0.171
36.64,122.69,0.171
36.67,122.84,0.171
36.70,123.01,0.171
36.73,123.16,0.171
36.76,123.32,0.171
36.80,123.48,0.171
36.83,123.64,0.171
36.86,123.80,0.171
36.89,123.95,0.171
36.92,124.11,0.171
36.96,124.27,0.170
36.99,124.43,0.170
37.02,124.59,0.170
37.05,124.75,0.170
37.08,124.90,0.170
37.11,125.06,0.170
37.14,125.22,0.170
37.18,125.38,0.170
37.21,125.54,0.170
37.24,125.69,0.170
37.27,125.85,0.170
37.30,126.01,0.170
37.34,126.17,0.170
37.37,126.33,0.170
37.40,126.49,0.170
37.43,126.65,0.170
37.46,126.80,0.170
37.49,126.96,0.171
37.53,127.12,0.171
37.56,127.28,0.171
37.59,127.44,0.171
37.62,127.60,0.171
37.65,127.75,0.171
37.68,127.91,0.171
37.71,128.07,0.171
37.75,128.23,0.171
37.78,128.39,0.171
37.81,128.54,0.171
37.84,128.70,0.171
37.87,128.86,0.171
37.91,129.02,0.171
37.94,129.18,0.171
37.97,129.34,0.171
38.00,129.50,0.171
38.03,129.65,0.171
38.06,129.81,0.171
38.09,129.97,0.171
38.13,130.13,0.171
38.16,130.29,0.171
38.19,130.45,0.171
38.22,130.60,0.171
38.25,130.76,0.171
38.29,130.92,0.172
38.32,131.08,0.172
38.35,131.24,0.172
38.38,131.40,0.172
38.41,131.55,0.172
38.44,131.71,0.172
38.48,131.87,0.172
38.51,132.03,0.172
38.54,132.19,0.172
38.57,132.34,0.172
38.60,132.50,0.172
38.63,132.66,0.172
38.66,132.82,0.172
38.70,132.98,0.172
38.73,133.14,0.172
38.76,133.30,0.173
38.79,133.45,0.173
38.82,133.61,0.173
38.86,133.77,0.173
38.89,133.93,0.173
38.92,134.09,0.173
38.95,134.25,0.173
38.98,134.40,0.173
39.01,134.56,0.173
39.04,134.72,0.173
39.08,134.88,0.173
39.11,135.04,0.173
39.14,135.20,0.173
39.17,135.36,0.173
39.20,135.51,0.173
39.24,135.67,0.173
39.27,135.83,0.174
39.30,135.99,0.173
39.33,136.15,0.173
39.36,136.31,0.173
39.39,136.46,0.173
39.43,136.62,0.173
39.46,136.78,0.173
39.49,136.94,0.173
39.52,137.10,0.173
39.55,137.25,0.173
39.58,137.41,0.173
39.61,137.57,0.174
39.65,137.73,0.174
39.68,137.89,0.174
39.71,138.05,0.174
39.74,138.21,0.174
39.77,138.36,0.174
39.81,138.52,0.174
39.84,138.68,0.174
39.87,138.84,0.174
39.90,139.00,0.174
39.93,139.16,0.174
39.96,139.31,0.174
39.99,139.47,0.174
40.03,139.63,0.174
40.06,139.79,0.174
40.09,139.95,0.174
40.12,140.11,0.174
40.15,140.26,0.174
40.19,140.42,0.174
40.22,140.58,0.174
40.25,140.74,0.174
40.28,140.90,0.174
40.31,141.06,0.174
40.34,141.21,0.174
40.38,141.37,0.174
40.41,141.53,0.174
40.44,141.69,0.174
40.47,141.85,0.174
40.50,142.01,0.174
40.53,142.16,0.174
40.56,142.32,0.174
40.60,142.48,0.174
40.63,142.64,0.174
40.66,142.80,0.174
40.69,142.96,0.174
40.72,143.12,0.174
40.76,143.27,0.174
40.79,143.43,0.174
40.82,143.59,0.174
40.85,143.75,0.174
40.88,143.91,0.174
40.91,144.07,0.174
40.94,144.22,0.174
40.98,144.38,0.174
41.01,144.54,0.174
41.04,144.70,0.174
41.07,144.86,0.174
41.10,145.02,0.174
41.14,145.17,0.174
41.17,145.33,0.174
41.20,145.49,0.174
41.23,145.65,0.174
41.26,145.81,0.174
41.29,145.97,0.174
41.33,146.13,0.174
41.36,146.28,0.174
41.39,146.44,0.174
41.42,146.60,0.174
41.45,146.76,0.174
41.48,146.92,0.174
41.51,147.07,0.174
41.55,147.23,0.174
41.58,147.39,0.174
41.61,147.55,0.174
41.64,147.71,0.174
41.67,147.87,0.174
41.71,148.02,0.174
41.74,148.18,0.174
41.77,148.34,0.174
41.80,148.50,0.174
41.83,148.66,0.174
41.86,148.82,0.174
41.89,148.98,0.174
41.93,149.13,0.174
41.96,149.29,0.174
41.99,149.45,0.174
42.02,149.61,0.174
42.05,149.77,0.173
42.09,149.93,0.173
42.12,150.08,0.173
42.15,150.24,0.173
42.18,150.40,0.173
42.21,150.56,0.173
42.24,150.72,0.173
42.28,150.88,0.173
42.31,151.04,0.173
42.34,151.19,0.173
42.37,151.35,0.173
42.40,151.51,0.173
42.43,151.67,0.173
42.46,151.83,0.172
42.50,151.99,0.172
42.53,152.14,0.172
42.56,152.30,0.172
42.59,152.46,0.172
42.62,152.62,0.172
42.66,152.78,0.172
42.69,152.94,0.172
42.72,153.09,0.172
42.75,153.25,0.172
42.78,153.41,0.171
42.81,153.57,0.171
42.84,153.73,0.171
42.88,153.89,0.171
42.91,154.04,0.171
42.94,154.20,0.171
42.97,154.36,0.170
43.00,154.52,0.170
43.04,154.68,0.170
43.07,154.84,0.170
43.10,155.00,0.170
43.13,155.15,0.169
43.16,155.31,0.169
43.19,155.47,0.169
43.23,155.63,0.168
43.26,155.79,0.168
43.29,155.94,0.168
43.32,156.10,0.168
43.35,156.26,0.168
43.38,156.42,0.167
43.41,156.58,0.167
43.45,156.74,0.167
43.48,156.89,0.167
43.51,157.05,0.166
43.54,157.21,0.166
43.57,157.37,0.166
43.61,157.53,0.166
43.64,157.69,0.165
43.67,157.85,0.165
43.70,158.00,0.165
43.73,158.16,0.165
43.76,158.32,0.165
43.79,158.48,0.165
43.83,158.64,0.164
43.86,158.80,0.164
43.89,158.96,0.164
43.92,159.11,0.163
43.95,159.27,0.163
43.99,159.43,0.163
44.02,159.59,0.163
44.05,159.75,0.162
44.08,159.90,0.162
44.11,160.06,0.162
44.14,160.22,0.162
44.18,160.38,0.161
44.21,160.54,0.161
44.24,160.70,0.161
44.27,160.86,0.161
44.30,161.02,0.160
44.33,161.17,0.160
44.36,161.33,0.160
44.40,161.49,0.160
44.43,161.65,0.159
44.46,161.81,0.159
44.49,161.96,0.159
44.52,162.12,0.158
44.56,162.28,0.158
44.59,162.44,0.158
44.62,162.60,0.157
44.65,162.76,0.157
44.68,162.91,0.157
44.71,163.07,0.157
44.74,163.23,0.156
44.78,163.39,0.156
44.81,163.55,0.156
44.84,163.71,0.155
44.87,163.87,0.155
44.90,164.03,0.155
44.94,164.18,0.154
44.97,164.34,0.154
45.00,164.50,0.154
45.03,164.66,0.153
45.06,164.82,0.153
45.09,164.97,0.153
45.13,165.13,0.152
45.16,165.29,0.152
45.19,165.45,0.152
45.22,165.61,0.151
45.25,165.77,0.151
45.28,165.93,0.151
45.31,166.09,0.150
45.35,166.24,0.150
45.38,166.40,0.150
45.41,166.56,0.149
45.44,166.72,0.149
45.47,166.88,0.148
45.51,167.04,0.148
45.54,167.19,0.147
45.57,167.35,0.147
45.60,167.51,0.146
45.63,167.67,0.146
45.66,167.83,0.146
45.69,167.99,0.145
45.73,168.14,0.145
45.76,168.30,0.144
45.79,168.46,0.144
45.82,168.62,0.143
45.85,168.78,0.143
45.89,168.94,0.142
45.92,169.10,0.142
45.95,169.25,
45.98,,
45.98,,

[step]
Ramp 10.00 °C/min to -60.00 °C
Time,Temperature,Heat Flow (Normalized)
min,°C,W/g
46.09,169.89,0.113
46.10,169.94,0.100
46.12,169.98,0.082
46.14,170.01,0.060
46.15,170.03,0.034
46.17,170.03,0.000
46.19,170.02,-0.044
46.20,169.98,-0.093
46.22,169.92,-0.151
46.24,169.84,-0.207
46.25,169.74,-0.260
46.27,169.63,-0.305
46.29,169.51,-0.346
46.30,169.39,-0.377
46.32,169.25,-0.403
46.34,169.11,-0.427
46.35,168.97,-0.444
46.37,168.83,-0.459
46.39,168.68,-0.473
46.40,168.53,-0.483
46.42,168.37,-0.490
46.44,168.22,-0.499
46.45,168.06,-0.504
46.47,167.91,-0.509
46.49,167.75,-0.514
46.50,167.59,-0.515
46.52,167.43,-0.519
46.54,167.27,-0.521
46.55,167.10,-0.522
46.57,166.94,-0.524
46.59,166.78,-0.525
46.60,166.62,-0.526
46.62,166.45,-0.527
46.64,166.29,-0.527
46.65,166.13,-0.527
46.67,165.97,-0.528
46.69,165.80,-0.528
46.70,165.64,-0.528
46.72,165.47,-0.528
46.74,165.31,-0.529
46.75,165.15,-0.529
46.77,164.98,-0.529
46.79,164.82,-0.530
46.80,164.65,-0.530
46.82,164.49,-0.530
46.84,164.33,-0.530
46.85,164.16,-0.530
46.87,164.00,-0.530
46.89,163.83,-0.530
46.90,163.67,-0.530
46.92,163.50,-0.531
46.94,163.34,-0.531
46.95,163.17,-0.531
46.97,163.01,-0.531
46.99,162.84,-0.531
47.00,162.67,-0.531
47.02,162.51,-0.531
47.04,162.34,-0.530
47.05,162.18,-0.530
47.07,162.01,-0.530
47.09,161.85,-0.530
47.10,161.68,-0.530
47.12,161.51,-0.530
47.14,161.35,-0.530
47.15,161.18,-0.530
47.17,161.02,-0.529
47.19,160.85,-0.529
47.20,160.69,-0.529
47.22,160.52,-0.529
47.24,160.35,-0.528
47.25,160.19,-0.528
47.27,160.02,-0.527
47.29,159.86,-0.527
47.30,159.69,-0.527
47.32,159.53,-0.527
47.34,159.36,-0.526
47.35,159.19,-0.526
47.37,159.03,-0.526
47.39,158.86,-0.525
47.40,158.69,-0.525
47.42,158.53,-0.525
47.44,158.36,-0.524
47.45,158.20,-0.524
47.47,158.03,-0.524
47.49,157.86,-0.523
47.50,157.70,-0.523
47.52,157.53,-0.523
47.54,157.37,-0.523
47.55,157.20,-0.522
47.57,157.03,-0.522
47.59,156.87,-0.521
47.60,156.70,-0.521
47.62,156.53,-0.521
47.64,156.37,-0.520
47.65,156.20,-0.520
47.67,156.04,-0.519
47.69,155.87,-0.519
47.70,155.70,-0.519
47.72,155.54,-0.518
47.74,155.37,-0.518
47.75,155.20,-0.518
47.77,155.04,-0.517
47.79,154.87,-0.517
47.80,154.70,-0.517
47.82,154.54,-0.516
47.84,154.37,-0.516
47.85,154.21,-0.516
47.87,154.04,-0.515
47.89,153.87,-0.515
47.90,153.71,-0.514
47.92,153.54,-0.514
47.94,153.37,-0.514
47.95,153.21,-0.513
47.97,153.04,-0.513
47.99,152.88,-0.513
48.00,152.71,-0.512
48.02,152.54,-0.512
48.04,152.38,-0.512
48.05,152.21,-0.511
48.07,152.04,-0.511
48.09,151.88,-0.510
48.10,151.71,-0.510
48.12,151.54,-0.510
48.14,151.38,-0.510
48.15,151.21,-0.509
48.17,151.04,-0.509
48.19,150.88,-0.508
48.20,150.71,-0.508
48.22,150.54,-0.508
48.24,150.38,-0.507
48.25,150.21,-0.507
48.27,150.05,-0.507
48.29,149.88,-0.506
48.30,149.71,-0.506
48.32,149.55,-0.506
48.34,149.38,-0.505
48.35,149.21,-0.505
48.37,149.05,-0.505
48.39,148.88,-0.504
48.40,148.71,-0.504
48.42,148.55,-0.504
48.44,148.38,-0.503
48.45,148.21,-0.503
48.47,148.05,-0.503
48.49,147.88,-0.502
48.50,147.72,-0.502
48.52,147.55,-0.502
48.54,147.38,-0.502
48.55,147.21,-0.501
48.57,147.05,-0.501
48.59,146.88,-0.501
48.60,146.72,-0.500
48.62,146.55,-0.500
48.64,146.38,-0.500
48.65,146.22,-0.500
48.67,146.05,-0.499
48.69,145.88,-0.499
48.70,145.72,-0.499
48.72,145.55,-0.498
48.74,145.38,-0.498
48.75,145.22,-0.498
48.77,145.05,-0.498
48.79,144.88,-0.497
48.80,144.72,-0.497
48.82,144.55,-0.497
48.84,144.38,-0.497
48.85,144.22,-0.496
48.87,144.05,-0.496
48.89,143.88,-0.496
48.90,143.72,-0.496
48.92,143.55,-0.495
48.94,143.39,-0.495
48.95,143.22,-0.495
48.97,143.05,-0.494
48.99,142.89,-0.494
49.00,142.72,-0.494
49.02,142.55,-0.493
49.04,142.39,-0.493
49.05,142.22,-0.493
49.07,142.05,-0.493
49.09,141.89,-0.492
49.10,141.72,-0.492
49.12,141.56,-0.492
49.14,141.39,-0.492
49.15,141.22,-0.491
49.17,141.06,-0.491
49.19,140.89,-0.491
49.20,140.72,-0.491
49.22,140.56,-0.491
49.24,140.39,-0.490
49.25,140.22,-0.490
49.27,140.06,-0.490
49.29,139.89,-0.490
49.30,139.72,-0.489
49.32,139.56,-0.489
49.34,139.39,-0.489
49.35,139.22,-0.489
49.37,139.06,-0.488
49.39,138.89,-0.488
49.40,138.73,-0.488
49.42,138.56,-0.488
49.44,138.39,-0.488
49.45,138.22,-0.487
49.47,138.06,-0.487
49.49,137.89,-0.487
49.50,137.73,-0.487
49.52,137.56,-0.486
49.54,137.39,-0.486
49.55,137.23,-0.486
49.57,137.06,-0.486
49.59,136.89,-0.486
49.60,136.73,-0.485
49.62,136.56,-0.485
49.64,136.39,-0.485
49.65,136.23,-0.485
49.67,136.06,-0.484
49.69,135.89,-0.484
49.70,135.73,-0.484
49.72,135.56,-0.484
49.74,135.39,-0.484
49.75,135.23,-0.484
49.77,135.06,-0.483
49.79,134.90,-0.483
49.80,134.73,-0.483
49.82,134.56,-0.483
49.84,134.40,-0.483
49.85,134.23,-0.483
49.87,134.06,-0.482
49.89,133.90,-0.482
49.90,133.73,-0.482
49.92,133.56,-0.482
49.94,133.40,-0.482
49.95,133.23,-0.481
49.97,133.06,-0.481
49.99,132.90,-0.481
50.00,132.73,-0.481
50.02,132.56,-0.481
50.04,132.40,-0.481
50.05,132.23,-0.480
50.07,132.06,-0.480
50.09,131.90,-0.480
50.10,131.73,-0.480
50.12,131.57,-0.480
50.14,131.40,-0.479
50.15,131.23,-0.479
50.17,131.07,-0.479
50.19,130.90,-0.479
50.20,130.73,-0.478
50.22,130.57,-0.478
50.24,130.40,-0.478
50.25,130.23,-0.478
50.27,130.07,-0.478
50.29,129.90,-0.478
50.30,129.73,-0.477
50.32,129.57,-0.477
50.34,129.40,-0.477
50.35,129.24,-0.477
50.37,129.07,-0.477
50.39,128.90,-0.477
50.40,128.73,-0.477
50.42,128.57,-0.477
50.44,128.40,-0.476
50.45,128.23,-0.476
50.47,128.07,-0.476
50.49,127.90,-0.476
50.50,127.74,-0.476
50.52,127.57,-0.476
50.54,127.40,-0.475
50.55,127.24,-0.475
50.57,127.07,-0.475
50.59,126.90,-0.475
50.60,126.74,-0.475
50.62,126.57,-0.475
50.64,126.40,-0.475
50.65,126.24,-0.474
50.67,126.07,-0.474
50.69,125.91,-0.474
50.70,125.74,-0.474
50.72,125.57,-0.474
50.74,125.41,-0.474
50.75,125.24,-0.473
50.77,125.07,-0.473
50.79,124.91,-0.473
50.80,124.74,-0.473
50.82,124.57,-0.473
50.84,124.41,-0.473
50.85,124.24,-0.472
50.87,124.07,-0.472
50.89,123.91,-0.472
50.90,123.74,-0.472
50.92,123.57,-0.472
50.94,123.41,-0.472
50.95,123.24,-0.472
50.97,123.07,-0.471
50.99,122.91,-0.471
51.00,122.74,-0.471
51.02,122.57,-0.471
51.04,122.41,-0.471
51.05,122.24,-0.471
51.07,122.08,-0.470
51.09,121.91,-0.470
51.10,121.74,-0.470
51.12,121.58,-0.470
51.14,121.41,-0.470
51.15,121.24,-0.470
51.17,121.08,-0.469
51.19,120.91,-0.469
51.20,120.74,-0.469
51.22,120.58,-0.469
51.24,120.41,-0.469
51.25,120.24,-0.469
51.27,120.08,-0.469
51.29,119.91,-0.468
51.30,119.74,-0.468
51.32,119.58,-0.468
51.34,119.41,-0.468
51.35,119.25,-0.468
51.37,119.08,-0.468
51.39,118.91,-0.467
51.40,118.75,-0.467
51.42,118.58,-0.467
51.44,118.41,-0.467
51.45,118.25,-0.467
51.47,118.08,-0.467
51.49,117.91,-0.467
51.50,117.75,-0.467
51.52,117.58,-0.466
51.54,117.41,-0.466
51.55,117.25,-0.466
51.57,117.08,-0.466
51.59,116.91,-0.466
51.60,116.75,-0.465
51.62,116.58,-0.465
51.64,116.41,-0.465
51.65,116.25,-0.465
51.67,116.08,-0.465
51.69,115.92,-0.464
51.70,115.75,-0.464
51.72,115.58,-0.464
51.74,115.42,-0.464
51.75,115.25,-0.464
51.77,115.08,-0.464
51.79,114.92,-0.464
51.80,114.75,-0.464
51.82,114.58,-0.464
51.84,114.42,-0.463
51.85,114.25,-0.463
51.87,114.08,-0.463
51.89,113.92,-0.463
51.90,113.75,-0.463
51.92,113.59,-0.463
51.94,113.42,-0.463
51.95,113.25,-0.463
51.97,113.09,-0.462
51.99,112.92,-0.462
52.00,112.75,-0.462
52.02,112.59,-0.462
52.04,112.42,-0.462
52.05,112.25,-0.462
52.07,112.09,-0.462
52.09,111.92,-0.462
52.10,111.76,-0.461
52.12,111.59,-0.461
[...]
121.38,-39.85,0.083
121.39,-39.79,0.083
121.40,-39.72,0.083
121.41,-39.65,0.083
121.43,-39.59,0.083
121.44,-39.52,0.083
121.45,-39.45,0.083
121.47,-39.39,0.083
121.48,-39.32,0.083
121.50,-39.25,0.083
121.51,-39.19,0.083
121.52,-39.12,0.083
121.54,-39.05,0.083
121.55,-38.98,0.083
121.56,-38.92,0.083
121.58,-38.85,0.083
121.59,-38.78,0.083
121.60,-38.72,0.083
121.61,-38.65,0.083
121.63,-38.58,0.083
121.64,-38.52,0.083
121.65,-38.45,0.083
121.67,-38.38,0.083
121.68,-38.32,0.083
121.70,-38.25,0.083
121.71,-38.18,0.083
121.72,-38.12,0.083
121.74,-38.05,0.083
121.75,-37.98,0.083
121.76,-37.92,0.083
121.78,-37.85,0.083
121.79,-37.78,0.083
121.80,-37.72,0.083
121.81,-37.65,0.083
121.83,-37.58,0.083
121.84,-37.52,0.083
121.85,-37.45,0.083
121.87,-37.38,0.083
121.88,-37.32,0.083
121.90,-37.25,0.083
121.91,-37.18,0.083
121.92,-37.11,0.083
121.94,-37.05,0.083
121.95,-36.98,0.083
121.96,-36.91,0.083
121.98,-36.85,0.083
121.99,-36.78,0.083
122.00,-36.71,0.083
122.01,-36.65,0.083
122.03,-36.58,0.083
122.04,-36.52,0.083
122.05,-36.45,0.083
122.07,-36.38,0.083
122.08,-36.31,0.083
122.10,-36.25,0.083
122.11,-36.18,0.083
122.12,-36.12,0.083
122.14,-36.05,0.083
122.15,-35.98,0.083
122.16,-35.92,0.083
122.18,-35.85,0.083
122.19,-35.78,0.083
122.20,-35.71,0.083
122.21,-35.65,0.083
122.23,-35.58,0.083
122.24,-35.51,0.083
122.25,-35.45,0.083
122.27,-35.38,0.083
122.28,-35.31,0.083
122.30,-35.25,0.083
122.31,-35.18,0.083
122.32,-35.11,0.083
122.34,-35.05,0.083
122.35,-34.98,0.083
122.36,-34.91,0.083
122.38,-34.85,0.083
122.39,-34.78,0.083
122.40,-34.71,0.083
122.41,-34.65,0.083
122.43,-34.58,0.083
122.44,-34.51,0.083
122.45,-34.45,0.083
122.47,-34.38,0.083
122.48,-34.31,0.083
122.50,-34.24,0.083
122.51,-34.18,0.083
122.52,-34.11,0.083
122.54,-34.05,0.083
122.55,-33.98,0.083
122.56,-33.91,0.083
122.58,-33.85,0.083
122.59,-33.78,0.083
122.60,-33.71,0.083
122.61,-33.65,0.083
122.63,-33.58,0.083
122.64,-33.51,0.083
122.65,-33.44,0.083
122.67,-33.38,0.083
122.68,-33.31,0.083
122.70,-33.24,0.083
122.71,-33.18,0.083
122.72,-33.11,0.083
122.74,-33.05,0.083
122.75,-32.98,0.083
122.76,-32.91,0.083
122.78,-32.84,0.083
122.79,-32.78,0.083
122.80,-32.71,0.083
122.81,-32.64,0.083
122.83,-32.58,0.083
122.84,-32.51,0.083
122.85,-32.44,0.083
122.87,-32.38,0.084
122.88,-32.31,0.084
122.90,-32.24,0.084
122.91,-32.18,0.084
122.92,-32.11,0.084
122.94,-32.05,0.084
122.95,-31.98,0.084
122.96,-31.91,0.084
122.98,-31.85,0.084
122.99,-31.78,0.084
123.00,-31.71,0.084
123.01,-31.64,0.084
123.03,-31.58,0.084
123.04,-31.51,0.084
123.05,-31.44,0.084
123.07,-31.38,0.084
123.08,-31.31,0.084
123.10,-31.24,0.084
123.11,-31.18,0.084
123.12,-31.11,0.084
123.14,-31.04,0.084
123.15,-30.98,0.084
123.16,-30.91,0.084
123.18,-30.84,0.084
123.19,-30.78,0.084
123.20,-30.71,0.084
123.21,-30.64,0.084
123.23,-30.58,0.084
123.24,-30.51,0.084
123.25,-30.44,0.084
123.27,-30.38,0.084
123.28,-30.31,0.084
123.30,-30.24,0.084
123.31,-30.18,0.084
123.32,-30.11,0.084
123.34,-30.04,0.084
123.35,-29.98,0.084
123.36,-29.91,0.084
123.38,-29.84,0.084
123.39,-29.78,0.084
123.40,-29.71,0.084
123.41,-29.64,0.084
123.43,-29.58,0.084
123.44,-29.51,0.084
123.45,-29.44,0.084
123.47,-29.37,0.084
123.48,-29.31,0.084
123.50,-29.24,0.084
123.51,-29.17,0.084
123.52,-29.11,0.084
123.54,-29.04,0.084
123.55,-28.98,0.084
123.56,-28.91,0.084
123.58,-28.84,0.084
123.59,-28.78,0.084
123.60,-28.71,0.084
123.61,-28.64,0.084
123.63,-28.58,0.084
123.64,-28.51,0.084
123.65,-28.44,0.084
123.67,-28.38,0.084
123.68,-28.31,0.084
123.70,-28.24,0.084
123.71,-28.17,0.084
123.72,-28.11,0.084
123.74,-28.04,0.085
123.75,-27.97,0.085
123.76,-27.91,0.085
123.78,-27.84,0.085
123.79,-27.77,0.085
123.80,-27.71,0.085
123.81,-27.64,0.085
123.83,-27.57,0.085
123.84,-27.51,0.085
123.85,-27.44,0.085
123.87,-27.37,0.085
123.88,-27.31,0.085
123.90,-27.24,0.085
123.91,-27.17,0.085
123.92,-27.11,0.085
123.94,-27.04,0.085
123.95,-26.97,0.085
123.96,-26.91,0.085
123.98,-26.84,0.085
123.99,-26.77,0.085
124.00,-26.71,0.085
124.01,-26.64,0.085
124.03,-26.57,0.085
124.04,-26.51,0.085
124.05,-26.44,0.085
124.07,-26.37,0.085
124.08,-26.31,0.085
124.10,-26.24,0.085
124.11,-26.17,0.085
124.12,-26.11,0.085
124.14,-26.04,0.085
124.15,-25.97,0.085
124.16,-25.91,0.085
124.18,-25.84,0.086
124.19,-25.77,0.086
124.20,-25.71,0.085
124.21,-25.64,0.086
124.23,-25.57,0.086
124.24,-25.51,0.086
124.25,-25.44,0.086
124.27,-25.37,0.086
124.28,-25.30,0.086
124.30,-25.24,0.086
124.31,-25.17,0.086
124.32,-25.10,0.086
124.34,-25.04,0.086
124.35,-24.97,0.086
124.36,-24.91,0.086
124.38,-24.84,0.086
124.39,-24.77,0.086
124.40,-24.70,0.086
124.41,-24.64,0.086
124.43,-24.57,0.086
124.44,-24.51,0.086
124.45,-24.44,0.087
124.47,-24.37,0.087
124.48,-24.31,0.087
124.50,-24.24,0.087
124.51,-24.17,0.087
124.52,-24.10,0.087
124.54,-24.04,0.087
124.55,-23.97,0.087
124.56,-23.90,0.087
124.58,-23.84,0.087
124.59,-23.77,0.087
124.60,-23.70,0.087
124.61,-23.64,0.087
124.63,-23.57,0.087
124.64,-23.51,0.087
124.65,-23.44,0.087
124.67,-23.37,0.087
124.68,-23.30,0.087
124.70,-23.24,0.088
124.71,-23.17,0.088
124.72,-23.10,0.088
124.74,-23.04,0.088
124.75,-22.97,0.088
124.76,-22.90,0.088
124.78,-22.84,0.088
124.79,-22.77,0.088
124.80,-22.70,0.088
124.81,-22.64,0.088
124.83,-22.57,0.088
124.84,-22.50,0.088
124.85,-22.44,0.089
124.87,-22.37,0.089
124.88,-22.30,0.089
124.90,-22.24,0.089
124.91,-22.17,0.089
124.92,-22.10,0.089
124.94,-22.04,0.089
124.95,-21.97,0.089
124.96,-21.90,0.089
124.98,-21.84,0.089
124.99,-21.77,0.090
125.00,-21.70,0.090
125.01,-21.64,0.090
125.03,-21.57,0.090
125.04,-21.50,0.090
125.05,-21.44,0.090
125.07,-21.37,0.090
125.08,-21.30,0.090
125.10,-21.24,0.091
125.11,-21.17,0.091
125.12,-21.10,0.091
125.14,-21.04,0.091
125.15,-20.97,0.091
125.16,-20.90,0.091
125.18,-20.84,0.091
125.19,-20.77,0.092
125.20,-20.70,0.092
125.21,-20.64,0.092
125.23,-20.57,0.092
125.24,-20.50,0.092
125.25,-20.44,0.092
125.27,-20.37,0.093
125.28,-20.30,0.093
125.30,-20.24,0.093
125.31,-20.17,0.093
125.32,-20.10,0.093
125.34,-20.04,0.093
125.35,-19.97,0.094
125.36,-19.90,0.094
125.38,-19.84,0.094
125.39,-19.77,0.094
125.40,-19.70,0.094
125.41,-19.64,0.094
125.43,-19.57,0.095
125.44,-19.50,0.095
125.45,-19.44,0.095
125.47,-19.37,0.095
125.48,-19.30,0.095
125.50,-19.23,0.096
125.51,-19.17,0.096
125.52,-19.10,0.096
125.54,-19.03,0.096
125.55,-18.96,0.097
125.56,-18.90,0.097
125.58,-18.83,0.097
125.59,-18.77,0.098
125.60,-18.70,0.098
125.61,-18.63,0.098
125.63,-18.56,0.099
125.64,-18.50,0.099
125.65,-18.43,0.099
125.67,-18.37,0.099
125.68,-18.30,0.099
125.70,-18.23,0.100
125.71,-18.16,0.100
125.72,-18.10,0.100
125.74,-18.03,0.100
125.75,-17.97,0.101
125.76,-17.90,0.101
125.78,-17.83,0.101
125.79,-17.77,0.102
125.80,-17.70,0.102
125.81,-17.63,0.102
125.83,-17.57,0.103
125.84,-17.50,0.103
125.85,-17.43,0.103
125.87,-17.37,0.103
125.88,-17.30,0.104
125.90,-17.23,0.105
125.91,-17.17,0.105
125.92,-17.10,0.105
125.94,-17.04,0.106
125.95,-16.97,0.106
125.96,-16.90,0.107
125.98,-16.84,0.107
125.99,-16.77,0.107
126.00,-16.70,0.108
126.01,-16.64,0.108
126.03,-16.57,0.108
126.04,-16.50,0.109
126.05,-16.44,0.109
126.07,-16.37,0.110
126.08,-16.30,0.110
126.10,-16.24,0.111
126.11,-16.17,0.111
126.12,-16.10,0.112
126.14,-16.04,0.112
126.15,-15.97,0.113
126.16,-15.90,0.113
126.18,-15.84,0.114
126.19,-15.77,0.114
126.20,-15.71,0.115
126.21,-15.64,0.115
126.23,-15.57,0.115
126.24,-15.51,0.116
126.25,-15.44,0.116
126.27,-15.37,0.117
126.28,-15.31,0.117
126.30,-15.24,0.118
126.31,-15.17,0.118
126.32,-15.11,0.119
126.34,-15.04,0.119
126.35,-14.97,0.120
126.36,-14.91,0.120
126.38,-14.84,0.121
126.39,-14.77,0.121
126.40,-14.71,0.121
126.41,-14.64,0.122
126.43,-14.57,0.122
126.44,-14.51,0.123
126.45,-14.44,0.123
126.47,-14.37,0.123
126.48,-14.31,0.124
126.50,-14.24,0.124
126.51,-14.18,0.124
126.52,-14.11,0.125
126.54,-14.04,0.125
126.55,-13.97,0.125
126.56,-13.91,0.126
126.58,-13.84,0.126
126.59,-13.77,0.126
126.60,-13.71,0.126
126.61,-13.64,0.127
126.63,-13.57,0.127
126.64,-13.51,0.127
126.65,-13.44,0.127
126.67,-13.37,0.128
126.68,-13.31,0.128
126.70,-13.24,0.128
126.71,-13.17,0.128
126.72,-13.11,0.128
126.74,-13.04,0.128
126.75,-12.97,0.128
126.76,-12.91,0.128
126.78,-12.84,0.128
126.79,-12.77,0.128
126.80,-12.71,0.128
126.81,-12.64,0.128
126.83,-12.57,0.128
126.84,-12.51,0.128
126.85,-12.44,0.128
126.87,-12.37,0.128
126.88,-12.31,0.128
126.90,-12.24,0.128
126.91,-12.17,0.127
126.92,-12.11,0.127
126.94,-12.04,0.127
126.95,-11.97,0.127
126.96,-11.91,0.127
126.98,-11.84,0.127
126.99,-11.77,0.127
127.00,-11.70,0.126
127.01,-11.64,0.126
127.03,-11.57,0.126
127.04,-11.50,0.126
127.05,-11.44,0.125
127.07,-11.37,0.125
127.08,-11.30,0.125
127.10,-11.24,0.125
127.11,-11.17,0.125
127.12,-11.10,0.125
127.14,-11.04,0.125
127.15,-10.97,0.124
127.16,-10.90,0.124
127.18,-10.84,0.124
127.19,-10.77,0.124
127.20,-10.70,0.124
127.21,-10.64,0.124
127.23,-10.57,0.123
127.24,-10.50,0.123
127.25,-10.44,0.123
127.27,-10.37,0.123
127.28,-10.30,0.123
127.30,-10.24,0.123
127.31,-10.17,0.123
127.32,-10.10,0.123
127.34,-10.04,0.122
127.35,-9.97,0.122
127.36,-9.90,0.122
127.38,-9.84,0.122
127.39,-9.77,0.122
127.40,-9.70,0.122
127.41,-9.64,0.122
127.43,-9.57,0.122
127.44,-9.50,0.122
127.45,-9.44,0.122
127.47,-9.37,0.122
127.48,-9.30,0.122
127.50,-9.24,0.121
127.51,-9.17,0.121
127.52,-9.10,0.121
127.54,-9.04,0.121
127.55,-8.97,0.121
127.56,-8.90,0.121
127.58,-8.84,0.121
127.59,-8.77,0.121
127.60,-8.70,0.121
127.61,-8.64,0.121
127.63,-8.57,0.121
127.64,-8.50,0.121
127.65,-8.43,0.121
127.67,-8.37,0.121
127.68,-8.30,0.121
127.70,-8.24,0.121
127.71,-8.17,0.121
127.72,-8.10,0.121
127.74,-8.03,0.121
127.75,-7.97,0.121
127.76,-7.90,0.121
127.78,-7.83,0.121
127.79,-7.77,0.121
127.80,-7.70,0.121
127.81,-7.63,0.121
127.83,-7.57,0.121
127.84,-7.50,0.121
127.85,-7.43,0.121
127.87,-7.37,0.121
127.88,-7.30,0.121
127.90,-7.23,0.121
127.91,-7.17,0.121
127.92,-7.10,0.121
127.94,-7.03,0.121
127.95,-6.97,0.121
127.96,-6.90,0.121
127.98,-6.83,0.121
127.99,-6.77,0.121
128.00,-6.70,0.121
128.01,-6.63,0.121
128.03,-6.57,0.121
128.04,-6.50,0.121
128.05,-6.43,0.120
128.07,-6.37,0.121
128.08,-6.30,0.121
128.10,-6.23,0.120
128.11,-6.17,0.121
128.12,-6.10,0.121
128.14,-6.03,0.121
128.15,-5.97,0.121
128.16,-5.90,0.121
128.18,-5.83,0.121
128.19,-5.77,0.121
128.20,-5.70,0.121
128.21,-5.63,0.121
128.23,-5.57,0.121
128.24,-5.50,0.121
128.25,-5.43,0.121
128.27,-5.36,0.121
128.28,-5.30,0.121
128.30,-5.23,0.121
128.31,-5.17,0.121
128.32,-5.10,0.121
128.34,-5.03,0.121
128.35,-4.97,0.121
128.36,-4.90,0.121
128.38,-4.83,0.121
128.39,-4.76,0.121
128.40,-4.70,0.121
128.41,-4.63,0.121
128.43,-4.57,0.121
128.44,-4.50,0.121
128.45,-4.43,0.121
128.47,-4.36,0.121
128.48,-4.30,0.121
128.50,-4.23,0.121
128.51,-4.17,0.121
128.52,-4.10,0.121
128.54,-4.03,0.121
128.55,-3.96,0.121
128.56,-3.90,0.121
128.58,-3.83,0.121
128.59,-3.76,0.121
128.60,-3.70,0.121
128.61,-3.63,0.121
128.63,-3.56,0.121
128.64,-3.50,0.121
128.65,-3.43,0.121
128.67,-3.36,0.121
128.68,-3.30,0.121
128.70,-3.23,0.121
128.71,-3.16,0.121
128.72,-3.10,0.121
128.74,-3.03,0.121
128.75,-2.97,0.121
128.76,-2.90,0.121
128.78,-2.83,0.121
128.79,-2.76,0.121
128.80,-2.70,0.121
128.81,-2.63,0.121
128.83,-2.56,0.121
128.84,-2.50,0.121
128.85,-2.43,0.121
128.87,-2.36,0.121
128.88,-2.30,0.121
128.90,-2.23,0.121
128.91,-2.16,0.121
128.92,-2.10,0.121
128.94,-2.03,0.121
128.95,-1.96,0.121
128.96,-1.90,0.121
128.98,-1.83,0.121
128.99,-1.76,0.121
129.00,-1.70,0.121
129.01,-1.63,0.121
129.03,-1.56,0.121
129.04,-1.50,0.121
129.05,-1.43,0.121
129.07,-1.36,0.121
129.08,-1.30,0.121
129.10,-1.23,0.121
129.11,-1.16,0.121
129.12,-1.10,0.121
129.14,-1.03,0.121
129.15,-0.96,0.121
129.16,-0.89,0.121
129.18,-0.83,0.121
129.19,-0.76,0.121
129.20,-0.70,0.121
129.21,-0.63,0.122
129.23,-0.56,0.122
129.24,-0.50,0.122
129.25,-0.43,0.122
129.27,-0.36,0.122
129.28,-0.30,0.122
129.30,-0.23,0.122
129.31,-0.16,0.122
129.32,-0.10,0.122
129.34,-0.03,0.122
129.35,0.04,0.122
129.36,0.11,0.122
129.38,0.17,0.122
129.39,0.24,0.122
129.40,0.31,0.122
129.41,0.37,0.122
129.43,0.44,0.122
129.44,0.51,0.122
129.45,0.57,0.122
129.47,0.64,0.122
129.48,0.71,0.122
129.50,0.77,0.122
129.51,0.84,0.122
129.52,0.91,0.122
129.54,0.97,0.122
129.55,1.04,0.122
129.56,1.11,0.122
129.58,1.17,0.122
129.59,1.24,0.122
129.60,1.31,0.122
129.61,1.37,0.122
129.63,1.44,0.122
129.64,1.51,0.122
129.65,1.57,0.122
129.67,1.64,0.122
129.68,1.71,0.122
129.70,1.77,0.122
129.71,1.84,0.122
129.72,1.91,0.122
129.74,1.97,0.122
129.75,2.04,0.122
129.76,2.11,0.122
129.78,2.17,0.122
129.79,2.24,0.122
129.80,2.31,0.122
129.81,2.37,0.122
129.83,2.44,0.122
129.84,2.51,0.122
129.85,2.57,0.122
129.87,2.64,0.122
129.88,2.71,0.122
129.90,2.77,0.122
129.91,2.84,0.122
129.92,2.91,0.122
129.94,2.97,0.122
129.95,3.04,0.122
129.96,3.11,0.122
129.98,3.17,0.122
129.99,3.24,0.122
130.00,3.31,0.122
130.01,3.37,0.122
130.03,3.44,0.122
130.04,3.51,0.122
130.05,3.58,0.122
130.07,3.64,0.122
130.08,3.71,0.122
130.10,3.77,0.122
130.11,3.84,0.122
130.12,3.91,0.122
130.14,3.97,0.122
130.15,4.04,0.122
130.16,4.11,0.122
130.18,4.17,0.122
130.19,4.24,0.122
130.20,4.31,0.122
130.21,4.37,0.122
130.23,4.44,0.122
130.24,4.51,0.122
130.25,4.57,0.122
130.27,4.64,0.122
130.28,4.71,0.122
130.30,4.78,0.122
130.31,4.84,0.122
130.32,4.91,0.122
130.34,4.97,0.122
130.35,5.04,0.122
130.36,5.11,0.122
130.38,5.18,0.122
130.39,5.24,0.122
130.40,5.31,0.122
130.41,5.38,0.122
130.43,5.44,0.122
130.44,5.51,0.122
130.45,5.58,0.123
130.47,5.64,0.123
130.48,5.71,0.123
130.50,5.78,0.123
130.51,5.84,0.123
130.52,5.91,0.123
130.54,5.98,0.123
130.55,6.04,0.123
130.56,6.11,0.123
130.58,6.18,0.123
130.59,6.24,0.123
130.60,6.31,0.123
130.61,6.38,0.123
130.63,6.44,0.123
130.64,6.51,0.123
130.65,6.58,0.123
130.67,6.64,0.123
130.68,6.71,0.123
130.70,6.78,0.123
130.71,6.85,0.123
130.72,6.91,0.123
130.74,6.98,0.123
130.75,7.04,0.123
130.76,7.11,0.123
130.78,7.18,0.123
130.79,7.25,0.123
130.80,7.31,0.123
130.81,7.38,0.123
130.83,7.44,0.123
130.84,7.51,0.123
130.85,7.58,0.123
130.87,7.64,0.123
130.88,7.71,0.123
130.90,7.78,0.123
130.91,7.85,0.123
130.92,7.91,0.123
130.94,7.98,0.123
130.95,8.04,0.123
130.96,8.11,0.123
130.98,8.18,0.123
130.99,8.25,0.123
131.00,8.31,0.123
131.01,8.38,0.123
131.03,8.45,0.124
131.04,8.51,0.124
131.05,8.58,0.123
131.07,8.65,0.124
131.08,8.71,0.124
131.10,8.78,0.124
131.11,8.85,0.124
131.12,8.91,0.124
131.14,8.98,0.124
131.15,9.05,0.124
131.16,9.11,0.124
131.18,9.18,0.124
131.19,9.25,0.124
131.20,9.31,0.124
131.21,9.38,0.124
131.23,9.45,0.124
131.24,9.51,0.124
131.25,9.58,0.124
131.27,9.65,0.124
131.28,9.71,0.124
131.30,9.78,0.124
131.31,9.85,0.124
131.32,9.91,0.124
131.34,9.98,0.124
131.35,10.05,0.124
131.36,10.11,0.124
131.38,10.18,0.124
131.39,10.25,0.124
131.40,10.31,0.124
131.41,10.38,0.124
131.43,10.45,0.124
131.44,10.51,0.124
131.45,10.58,0.124
131.47,10.65,0.124
131.48,10.71,0.124
131.50,10.78,0.124
131.51,10.85,0.124
131.52,10.91,0.124
131.54,10.98,0.124
131.55,11.05,0.124
131.56,11.11,0.124
131.58,11.18,0.124
131.59,11.25,0.124
131.60,11.31,0.124
131.61,11.38,0.124
131.63,11.45,0.124
131.64,11.51,0.124
131.65,11.58,0.124
131.67,11.65,0.124
131.68,11.71,0.124
131.70,11.78,0.124
131.71,11.85,0.124
131.72,11.91,0.124
131.74,11.98,0.124
131.75,12.05,0.124
131.76,12.11,0.124
131.78,12.18,0.124
131.79,12.25,0.125
131.80,12.31,0.125
131.81,12.38,0.125
131.83,12.45,0.125
131.84,12.52,0.125
131.85,12.58,0.125
131.87,12.65,0.125
131.88,12.71,0.125
131.90,12.78,0.125
131.91,12.85,0.125
131.92,12.92,0.125
131.94,12.98,0.125
131.95,13.05,0.125
131.96,13.12,0.125
131.98,13.18,0.125
131.99,13.25,0.125
132.00,13.32,0.125
132.01,13.38,0.125
132.03,13.45,0.125
132.04,13.52,0.125
132.05,13.58,0.125
132.07,13.65,0.125
132.08,13.72,0.125
132.10,13.78,0.125
132.11,13.85,0.125
132.12,13.92,0.125
132.14,13.98,0.125
132.15,14.05,0.125
132.16,14.12,0.125
132.18,14.18,0.125
132.19,14.25,0.125
132.20,14.32,0.125
132.21,14.38,0.125
132.23,14.45,0.125
132.24,14.52,0.125
132.25,14.58,0.125
132.27,14.65,0.125
132.28,14.72,0.125
132.30,14.78,0.125
132.31,14.85,0.125
132.32,14.92,0.125
132.34,14.98,0.125
132.35,15.05,0.125
132.36,15.12,0.125
132.38,15.18,0.125
132.39,15.25,0.125
132.40,15.32,0.125
132.41,15.38,0.125
132.43,15.45,0.125
132.44,15.52,0.125
132.45,15.58,0.125
132.47,15.65,0.125
132.48,15.72,0.125
132.50,15.78,0.125
132.51,15.85,0.125
132.52,15.92,0.125
132.54,15.98,0.125
132.55,16.05,0.125
132.56,16.12,0.125
132.58,16.18,0.125
132.59,16.25,0.125
132.60,16.32,0.125
132.61,16.38,0.125
132.63,16.45,0.125
132.64,16.52,0.125
132.65,16.58,0.125
132.67,16.65,0.125
132.68,16.72,0.125
132.70,16.78,0.125
132.71,16.85,0.125
132.72,16.92,0.125
132.74,16.98,0.125
132.75,17.05,0.125
132.76,17.12,0.125
132.78,17.19,0.126
132.79,17.25,0.126
132.80,17.32,0.126
132.81,17.39,0.126
132.83,17.45,0.126
132.84,17.52,0.126
132.85,17.59,0.126
132.87,17.65,0.126
132.88,17.72,0.126
132.90,17.79,0.126
132.91,17.85,0.126
132.92,17.92,0.126
132.94,17.99,0.126
132.95,18.05,0.126
132.96,18.12,0.126
132.98,18.19,0.126
132.99,18.25,0.126
133.00,18.32,0.126
133.01,18.39,0.126
133.03,18.45,0.126
133.04,18.52,0.126
133.05,18.59,0.126
133.07,18.65,0.126
133.08,18.72,0.126
133.10,18.79,0.126
133.11,18.85,0.126
133.12,18.92,0.126
133.14,18.99,0.126
133.15,19.05,0.126
133.16,19.12,0.126
133.18,19.19,0.126
133.19,19.25,0.126
133.20,19.32,0.126
133.21,19.39,0.127
133.23,19.45,0.127
133.24,19.52,0.127
133.25,19.59,0.127
133.27,19.65,0.127
133.28,19.72,0.127
133.30,19.79,0.127
133.31,19.85,0.127
133.32,19.92,0.127
133.34,19.99,0.127
133.35,20.05,0.127
133.36,20.12,0.127
133.38,20.19,0.127
133.39,20.25,0.127
133.40,20.32,0.127
133.41,20.39,0.127
133.43,20.45,0.127
133.44,20.52,0.127
133.45,20.59,0.127
133.47,20.65,0.127
133.48,20.72,0.127
133.50,20.79,0.127
133.51,20.85,0.127
133.52,20.92,0.127
133.54,20.99,0.127
133.55,21.05,0.127
133.56,21.12,0.127
133.58,21.19,0.127
133.59,21.25,0.127
133.60,21.32,0.127
133.61,21.39,0.127
133.63,21.45,0.127
133.64,21.52,0.127
133.65,21.59,0.127
133.67,21.65,0.127
133.68,21.72,0.127
133.70,21.79,0.127
133.71,21.85,0.127
133.72,21.92,0.127
133.74,21.99,0.127
133.75,22.06,0.127
133.76,22.12,0.127
133.78,22.19,0.127
133.79,22.25,0.127
133.80,22.32,0.127
133.81,22.39,0.128
133.83,22.46,0.128
133.84,22.52,0.128
133.85,22.59,0.128
133.87,22.66,0.128
133.88,22.72,0.128
133.90,22.79,0.128
133.91,22.86,0.128
133.92,22.92,0.128
133.94,22.99,0.128
133.95,23.06,0.128
133.96,23.12,0.128
133.98,23.19,0.128
133.99,23.26,0.128
134.00,23.32,0.128
134.01,23.39,0.128
134.03,23.45,0.128
134.04,23.52,0.128
134.05,23.59,0.128
134.07,23.66,0.128
134.08,23.72,0.128
134.10,23.79,0.128
134.11,23.85,0.128
134.12,23.92,0.128
134.14,23.99,0.128
134.15,24.05,0.128
134.16,24.12,0.128
134.18,24.19,0.128
134.19,24.26,0.128
134.20,24.32,0.128
134.21,24.39,0.128
134.23,24.46,0.128
134.24,24.52,0.128
134.25,24.59,0.128
134.27,24.66,0.128
134.28,24.72,0.128
134.30,24.79,0.128
134.31,24.86,0.128
134.32,24.92,0.129
134.34,24.99,0.129
134.35,25.06,0.128
134.36,25.12,0.129
134.38,25.19,0.129
134.39,25.26,0.129
134.40,25.32,0.129
134.41,25.39,0.129
134.43,25.46,0.129
134.44,25.52,0.129
134.45,25.59,0.129
134.47,25.66,0.129
134.48,25.72,0.129
134.50,25.79,0.129
134.51,25.86,0.129
134.52,25.92,0.129
134.54,25.99,0.129
134.55,26.06,0.129
134.56,26.12,0.129
134.58,26.19,0.129
134.59,26.26,0.129
134.60,26.32,0.129
134.61,26.39,0.129
134.63,26.46,0.129
134.64,26.52,0.129
134.65,26.59,0.129
134.67,26.66,0.129
134.68,26.73,0.129
134.70,26.79,0.129
134.71,26.86,0.129
134.72,26.92,0.129
134.74,26.99,0.129
134.75,27.06,0.129
134.76,27.13,0.129
134.78,27.19,0.129
134.79,27.26,0.129
134.80,27.33,0.129
134.81,27.39,0.129
134.83,27.46,0.129
134.84,27.53,0.129
134.85,27.59,0.129
134.87,27.66,0.129
134.88,27.72,0.129
134.90,27.79,0.129
134.91,27.86,0.130
134.92,27.93,0.130
134.94,27.99,0.130
134.95,28.06,0.130
134.96,28.13,0.130
134.98,28.19,0.130
134.99,28.26,0.130
135.00,28.33,0.130
135.01,28.39,0.130
135.03,28.46,0.130
135.04,28.53,0.130
135.05,28.59,0.130
135.07,28.66,0.130
135.08,28.73,0.130
135.10,28.79,0.130
135.11,28.86,0.130
135.12,28.93,0.130
135.14,28.99,0.130
135.15,29.06,
135.16,29.13,
135.18,29.19,
135.19,29.26,
135.20,,