File: DSC/2025_04_12_CBN_10Cmin_n60C_150C_x3.csv
Filename,2025_04_12_CBN_10Cmin_n60C_150C_x3
Instrument name,DSC2A-00468 (192.168.1.100)
Operator,Yarger
rundate,4/12/2025
Sample name,2025_04_12_CBN_10Cmin_n60C_150C_x3
proceduresegments,Data Off ; Equilibrate -60.00 °C; Data On ; Ramp 10.00 °C/min to 150.00 °C; Data Off ; Isothermal 1.0 min; Data On ; Ramp 10.00 °C/min to -60.00 °C; Data Off ; Isothermal 1.0 min; Data On ; Ramp 10.00 °C/min to 150.00 °C; Data Off ; Isothermal 1.0 min; Data On ; Ramp 10.00 °C/min to -60.00 °C; Data Off ; Isothermal 1.0 min; Data On ; Ramp 10.00 °C/min to 150.00 °C
[File Parameters]
Run date,4/12/2025 2:37:56 AM
Trios version,5.1.1.46572
Original File Name,
Current File Name,D:\DSC2500\JYarger\2025_04_12_CBN_10Cmin_n60C_150C_x3.tri
[Procedure]
Procedure Name,CBN_n60_150C_10Cmin_x3
Sample Name,2025_04_12_CBN_10Cmin_n60C_150C_x3
Sample Mass,3.81 mg
Reference Sample Mass,0 mg
Pan Mass,53.38 mg
Pan Number,15
Reference Pan Mass,53.32 mg
Reference Pan Number,10
Pan Type,Tzero Aluminum Hermetic
Comments,Hermetic Sealed Al DSC Consumables Pan/Lids.
Project Name,CA
Operator,Yarger
Test,Custom
Unload Max Temperature,30
Unload Min Temperature,30
Load Max Temperature,30
Load Min Temperature,30
Stop on Gas Flow Error,Yes
[Signal List]
Signal #1,Time (min)
Signal #2,Temperature (°C)
Signal #3,Heat Flow (mW)
Signal #4,Delta T (µV)
Signal #5,Delta Tzero (µV)
Signal #6,Tzero Temperature (°C)
Signal #7,Cell Purge (mL/min)
Signal #8,Heater Temp (°C)
Signal #9,Power Delivered (W)
Signal #10,Reference Junction Temperature (°C)
Signal #11,Flange Temperature (°C)
Signal #12,Heat Flow Phase (rad)
Signal #13,Total Heat Capacity (J/°C)
Signal #14,Heat Capacity (J/°C)
[Configuration]
Company Name,ASU
Instrument Name,DSC2A-00468
Instrument Type,DSC2500
Serial Number,DSC2A-00468
IP,192.168.1.100
Location of Instrument,MRRC
DisplayType,Unknown
Sample Interval ,0.1 s/pt
Selected Heat Flow,T4P
Exotherm Direction,Down
Cell Serial,DRC2-00792
Lid Type,Standard
Cooler,RCS 90
Leave Cooler on at End of Sequence,On
Gas 2,Nitrogen
Gas Selected,Channel 1
Flow Rate,50 mL/min
Secondary Purge,On
Licensed Heat Flow,Heat Flow T4P
Modulation Licensed,Yes
[Versions]
Common IDD Version,1
Cortex Version,VER 2.10.2.31
Driver,5.0.0.6
GDM Version,1.0.3.3
TouchscreenVersion,1.0.0.16145
FEP Version,1.2.1.21
FEP Bootloader,2.0.0.5
AutoSampler Version,2.1.1.26
Auto Sampler Bootloader,2.0.0.5
FCM Version,1.1.0.3
FCM Bootloader,2.0.0.5
[Experiment Logs]
Experiment Log Entry # 1,Data On set to 0
Experiment Log Entry # 3,Equilibrate Segment -60 (C) Started
Experiment Log Entry # 5,Air Cool is off.
Experiment Log Entry # 7,Data On set to 1
Experiment Log Entry # 9,Ramp Segment 10 C/min to 150 Started
Experiment Log Entry # 11,Data On set to 0
Experiment Log Entry # 13,Isothermal Segment 1 min started
Experiment Log Entry # 15,Data On set to 1
Experiment Log Entry # 17,Ramp Segment 10 C/min to -60 Started
Experiment Log Entry # 19,Data On set to 0
Experiment Log Entry # 21,Isothermal Segment 1 min started
Experiment Log Entry # 23,Data On set to 1
Experiment Log Entry # 25,Ramp Segment 10 C/min to 150 Started
Experiment Log Entry # 27,Data On set to 0
Experiment Log Entry # 29,Isothermal Segment 1 min started
Experiment Log Entry # 31,Data On set to 1
Experiment Log Entry # 33,Ramp Segment 10 C/min to -60 Started
Experiment Log Entry # 35,Data On set to 0
Experiment Log Entry # 37,Isothermal Segment 1 min started
Experiment Log Entry # 39,Data On set to 1
Experiment Log Entry # 41,Ramp Segment 10 C/min to 150 Started
[Method Log]
Method Log Entry # 1,Data Off
Method Log Entry # 2,Equilibrate -60 °C
Method Log Entry # 3,Data On
Method Log Entry # 4,(Ramp 128633) Ramp 10 °C/minute to 150 °C
Method Log Entry # 5,Data Off
Method Log Entry # 6,Isothermal 1 minutes
Method Log Entry # 7,Data On
Method Log Entry # 8,(Ramp 128637) Ramp 10 °C/minute to -60 °C
Method Log Entry # 9,Data Off
Method Log Entry # 10,Isothermal 1 minutes
Method Log Entry # 11,Data On
Method Log Entry # 12,(Ramp 128641) Ramp 10 °C/minute to 150 °C
Method Log Entry # 13,Data Off
Method Log Entry # 14,Isothermal 1 minutes
Method Log Entry # 15,Data On
Method Log Entry # 16,(Ramp 128645) Ramp 10 °C/minute to -60 °C
Method Log Entry # 17,Data Off
Method Log Entry # 18,Isothermal 1 minutes
Method Log Entry # 19,Data On
Method Log Entry # 20,(Ramp 128649) Ramp 10 °C/minute to 150 °C
Cell Serial,DRC2-00792
[T1 Calibration]
Slope,-0.008529666
Offset,9.636258
Initial Temperature,98.23
GUID,f8bfdadc-4977-4fdf-ba6d-0ba9134940c3
[TZero Calibration]
Date Applied,11/29/2022 4:06:13 PM
Description,From -89.059 °C to 396.009 °C at 20.000°C/min
Gas Type,Nitrogen
Pan Type,None
Source Files 1,C:\Users\yargerlab\Desktop\DSC Data\General\TZero_calibration_11_29_22_2nd(2).tri
Source Files 2,C:\Users\yargerlab\Desktop\DSC Data\General\TZero_calibration_11_29_22_2nd(3).tri
Delta T Offset,13.05235
Delta T Slope,-0.007271007
Delta T0 Offset,-13.69128
Delta T0 Slope,0.06063341
[Temperature Calibration]
Date Applied,11/29/2022 7:12:28 PM
Description,From 106.590 °C to 186.590 °C at 10.000°C/min
Gas Type,Nitrogen
Pan Type,Tzero Aluminum Hermetic
Source Files 1,C:\Users\yargerlab\Desktop\DSC Data\General\Indium(6).tri
Measured 1,157.391
Known 1,156.598
[Cell Constant Calibration]
Date Applied,11/29/2022 7:12:29 PM
Description,From 106.590 °C to 186.590 °C at 10.000°C/min
Gas Type,Nitrogen
Pan Type,Tzero Aluminum Hermetic
Source Files 1,C:\Users\yargerlab\Desktop\DSC Data\General\Indium(6).tri
T4P KCell,1.006051
Onset Slope,63.26126 mW/°C
[Direct Cp Calibration]
Date Applied,11/30/2022 11:04:51 AM
Description,From -79.983 °C to 298.409 °C at 10.000°C/min
Gas Type,Nitrogen
Pan Type,Tzero Aluminum Hermetic
Source Files 1,C:\Users\yargerlab\Desktop\DSC Data\General\Sapphire_Heat_Capacity_11_30_22.tri
[Rev Cp Calibration]
Date Applied,11/30/2022 1:58:51 PM
Description,From -79.996 °C to 292.812 °C at 3.000°C/min
Gas Type,Nitrogen
Pan Type,Tzero Aluminum Hermetic
Source Files 1,C:\Users\yargerlab\Desktop\DSC Data\General\Sapphire_MDSC_Calibration_11_30_22.tri
[step]
Ramp 10.00 °C/min to 150.00 °C
Time,Temperature,Heat Flow (Normalized)
min,°C,W/g
0.00,-59.70,-0.030
0.01,-59.71,-0.029
0.03,-59.72,-0.026
0.05,-59.72,-0.022
0.06,-59.72,-0.016
0.08,-59.70,-0.009
0.09,-59.67,0.001
0.11,-59.63,0.011
0.12,-59.58,0.021
0.14,-59.51,0.034
0.15,-59.43,0.049
0.16,-59.34,0.063
0.18,-59.24,0.077
0.19,-59.13,0.091
0.21,-59.02,0.103
0.23,-58.90,0.116
0.24,-58.78,0.124
0.26,-58.65,0.135
0.27,-58.52,0.140
0.29,-58.39,0.145
0.30,-58.26,0.154
0.31,-58.12,0.158
0.33,-57.99,0.159
0.35,-57.85,0.164
0.36,-57.71,0.167
0.38,-57.57,0.169
0.39,-57.43,0.173
0.40,-57.29,0.174
0.42,-57.15,0.175
0.44,-57.01,0.176
0.45,-56.87,0.178
0.46,-56.72,0.178
0.48,-56.58,0.180
0.50,-56.44,0.180
0.51,-56.29,0.181
0.53,-56.15,0.182
0.54,-56.01,0.182
0.55,-55.86,0.183
0.57,-55.71,0.183
0.58,-55.57,0.184
0.60,-55.42,0.184
0.62,-55.28,0.184
0.63,-55.13,0.185
0.65,-54.98,0.185
0.66,-54.84,0.185
0.68,-54.69,0.185
0.69,-54.54,0.186
0.70,-54.40,0.186
0.72,-54.25,0.186
0.73,-54.10,0.187
0.75,-53.96,0.187
0.77,-53.81,0.187
0.78,-53.66,0.187
0.80,-53.52,0.187
0.81,-53.37,0.188
0.83,-53.22,0.188
0.84,-53.07,0.188
0.85,-52.93,0.188
0.87,-52.78,0.189
0.88,-52.63,0.189
0.90,-52.48,0.189
0.92,-52.33,0.189
0.93,-52.19,0.189
0.95,-52.04,0.189
0.96,-51.89,0.190
0.98,-51.74,0.190
0.99,-51.59,0.190
1.00,-51.44,0.190
1.02,-51.30,0.190
1.03,-51.15,0.190
1.05,-51.00,0.190
1.07,-50.85,0.190
1.08,-50.70,0.191
1.09,-50.55,0.191
1.11,-50.40,0.191
1.13,-50.25,0.191
1.14,-50.11,0.191
1.16,-49.96,0.191
1.17,-49.81,0.191
1.18,-49.66,0.191
1.20,-49.51,0.191
1.22,-49.36,0.191
1.23,-49.21,0.192
1.24,-49.06,0.192
1.26,-48.91,0.192
1.28,-48.76,0.192
1.29,-48.62,0.192
1.31,-48.47,0.192
1.32,-48.32,0.192
1.33,-48.17,0.192
1.35,-48.02,0.192
1.37,-47.87,0.192
1.38,-47.72,0.192
1.39,-47.57,0.192
1.41,-47.42,0.192
1.43,-47.27,0.192
1.44,-47.12,0.192
1.46,-46.97,0.192
1.47,-46.82,0.193
1.48,-46.67,0.193
1.50,-46.52,0.193
1.52,-46.37,0.193
1.53,-46.22,0.193
1.54,-46.07,0.193
1.56,-45.92,0.193
1.58,-45.77,0.193
1.59,-45.62,0.193
1.61,-45.47,0.193
1.62,-45.32,0.193
1.63,-45.17,0.193
1.65,-45.02,0.193
1.67,-44.87,0.193
1.68,-44.72,0.193
1.69,-44.58,0.193
1.71,-44.42,0.193
1.73,-44.27,0.193
1.74,-44.13,0.193
1.76,-43.97,0.193
1.77,-43.83,0.193
1.78,-43.68,0.193
1.80,-43.53,0.193
1.82,-43.38,0.193
1.83,-43.23,0.194
1.84,-43.08,0.194
1.86,-42.93,0.194
1.88,-42.78,0.194
1.89,-42.63,0.194
1.91,-42.48,0.194
1.92,-42.33,0.194
1.93,-42.17,0.194
1.95,-42.03,0.194
1.97,-41.88,0.194
1.98,-41.72,0.194
1.99,-41.57,0.194
2.01,-41.42,0.194
2.03,-41.28,0.194
2.04,-41.12,0.194
2.06,-40.98,0.194
2.07,-40.82,0.194
2.08,-40.67,0.194
2.10,-40.52,0.194
2.12,-40.37,0.194
2.13,-40.23,0.194
2.14,-40.07,0.194
2.16,-39.92,0.194
2.18,-39.77,0.194
2.19,-39.63,0.194
2.21,-39.47,0.194
2.22,-39.32,0.194
2.24,-39.17,0.194
2.25,-39.02,0.194
2.26,-38.87,0.194
2.28,-38.72,0.195
2.29,-38.57,0.195
2.31,-38.42,0.195
2.33,-38.27,0.195
2.34,-38.12,0.195
2.36,-37.97,0.195
2.37,-37.82,0.195
2.39,-37.67,0.195
2.40,-37.52,0.195
2.41,-37.37,0.195
2.43,-37.22,0.195
2.44,-37.07,0.195
2.46,-36.92,0.195
2.48,-36.77,0.195
2.49,-36.62,0.195
2.51,-36.47,0.195
2.52,-36.32,0.195
2.54,-36.17,0.195
2.55,-36.02,0.195
2.56,-35.87,0.195
2.58,-35.72,0.195
2.59,-35.57,0.195
2.61,-35.42,0.195
2.63,-35.27,0.195
2.64,-35.12,0.195
2.66,-34.97,0.195
2.67,-34.82,0.195
2.69,-34.67,0.195
2.70,-34.52,0.195
2.71,-34.37,0.195
2.73,-34.22,0.195
2.74,-34.07,0.195
2.76,-33.92,0.195
2.78,-33.77,0.195
2.79,-33.62,0.195
2.81,-33.47,0.196
2.82,-33.32,0.196
2.84,-33.17,0.196
2.85,-33.02,0.196
2.86,-32.87,0.196
2.88,-32.72,0.196
2.89,-32.57,0.196
2.91,-32.42,0.196
2.93,-32.26,0.196
2.94,-32.11,0.196
2.96,-31.97,0.196
2.97,-31.81,0.196
2.99,-31.66,0.196
3.00,-31.51,0.196
3.01,-31.36,0.196
3.03,-31.21,0.196
3.04,-31.06,0.196
3.06,-30.91,0.196
3.08,-30.76,0.197
3.09,-30.61,0.197
3.11,-30.46,0.197
3.12,-30.31,0.197
3.14,-30.16,0.197
3.15,-30.01,0.197
3.16,-29.86,0.197
3.18,-29.71,0.197
3.19,-29.56,0.197
3.21,-29.41,0.197
3.23,-29.26,0.197
3.24,-29.11,0.197
3.26,-28.96,0.197
3.27,-28.81,0.197
3.29,-28.66,0.197
3.30,-28.51,0.197
3.31,-28.36,0.197
3.33,-28.21,0.197
3.34,-28.06,0.197
3.36,-27.91,0.197
3.38,-27.76,0.197
3.39,-27.61,0.197
3.41,-27.46,0.197
3.42,-27.31,0.197
3.44,-27.16,0.198
3.45,-27.01,0.198
3.46,-26.86,0.198
3.48,-26.71,0.198
3.49,-26.56,0.198
3.51,-26.41,0.198
3.53,-26.26,0.198
3.54,-26.11,0.198
3.56,-25.96,0.198
3.57,-25.81,0.198
3.59,-25.66,0.198
3.60,-25.51,0.198
3.61,-25.36,0.198
3.63,-25.21,0.198
3.64,-25.05,0.198
3.66,-24.90,0.199
3.68,-24.76,0.199
3.69,-24.60,0.199
3.71,-24.45,0.199
3.72,-24.30,0.199
3.74,-24.15,0.199
3.75,-24.00,0.199
3.76,-23.85,0.199
3.78,-23.70,0.199
3.79,-23.55,0.199
3.81,-23.40,0.199
3.83,-23.25,0.199
3.84,-23.10,0.199
3.86,-22.95,0.199
3.87,-22.80,0.199
3.89,-22.65,0.199
3.90,-22.50,0.199
3.91,-22.35,0.199
3.93,-22.20,0.199
3.94,-22.05,0.199
3.96,-21.90,0.200
3.98,-21.75,0.200
3.99,-21.60,0.200
4.01,-21.45,0.200
4.02,-21.30,0.200
4.04,-21.15,0.200
4.05,-21.00,0.200
4.06,-20.85,0.200
4.08,-20.70,0.200
4.09,-20.55,0.200
4.11,-20.40,0.200
4.13,-20.25,0.200
4.14,-20.10,0.200
4.16,-19.95,0.200
4.17,-19.80,0.200
4.19,-19.65,0.200
4.20,-19.50,0.201
4.21,-19.35,0.201
4.23,-19.20,0.201
4.24,-19.05,0.201
4.26,-18.90,0.201
4.28,-18.75,0.201
4.29,-18.60,0.201
4.30,-18.45,0.201
4.32,-18.30,0.201
4.34,-18.15,0.201
4.35,-18.00,0.201
4.36,-17.84,0.202
4.38,-17.70,0.202
4.40,-17.54,0.202
4.41,-17.39,0.202
4.43,-17.25,0.202
4.44,-17.10,0.202
4.45,-16.95,0.202
4.47,-16.80,0.202
4.49,-16.65,0.202
4.50,-16.50,0.202
4.51,-16.34,0.202
4.53,-16.19,0.202
4.55,-16.04,0.202
4.56,-15.89,0.202
4.58,-15.74,0.202
4.59,-15.59,0.203
4.60,-15.44,0.203
4.62,-15.29,0.203
4.64,-15.14,0.203
4.65,-14.99,0.203
4.66,-14.84,0.203
4.68,-14.69,0.203
4.70,-14.54,0.203
4.71,-14.39,0.203
4.73,-14.24,0.203
4.74,-14.09,0.203
4.75,-13.94,0.204
4.77,-13.79,0.204
4.79,-13.64,0.204
4.80,-13.49,0.204
4.81,-13.34,0.204
4.83,-13.19,0.204
4.85,-13.04,0.204
4.86,-12.89,0.204
4.88,-12.74,0.204
4.89,-12.59,0.205
4.90,-12.44,0.205
4.92,-12.29,0.205
4.94,-12.14,0.205
4.95,-11.99,0.205
4.96,-11.84,0.205
4.98,-11.69,0.205
5.00,-11.54,0.205
5.01,-11.39,0.206
5.03,-11.24,0.206
5.04,-11.09,0.206
5.05,-10.94,0.206
5.07,-10.79,0.206
5.09,-10.64,0.206
5.10,-10.49,0.207
5.11,-10.34,0.207
5.13,-10.19,0.207
5.15,-10.04,0.207
5.16,-9.89,0.207
5.18,-9.74,0.208
5.19,-9.59,0.208
5.20,-9.44,0.208
5.22,-9.29,0.208
5.24,-9.14,0.208
5.25,-8.99,0.209
5.26,-8.84,0.209
5.28,-8.69,0.209
5.30,-8.54,0.209
5.31,-8.39,0.210
5.33,-8.24,0.210
5.34,-8.09,0.210
5.35,-7.94,0.211
5.37,-7.79,0.211
5.39,-7.64,0.211
5.40,-7.49,0.211
5.41,-7.34,0.212
5.43,-7.19,0.212
5.45,-7.04,0.212
5.46,-6.89,0.213
5.48,-6.74,0.213
5.49,-6.59,0.213
5.50,-6.44,0.214
5.52,-6.29,0.214
5.54,-6.14,0.215
5.55,-5.98,0.215
5.56,-5.84,0.215
5.58,-5.69,0.216
5.60,-5.54,0.217
5.61,-5.39,0.217
5.63,-5.24,0.218
5.64,-5.09,0.218
5.65,-4.94,0.219
5.67,-4.79,0.219
5.69,-4.64,0.220
5.70,-4.49,0.221
5.71,-4.34,0.221
5.73,-4.19,0.223
5.75,-4.03,0.224
5.76,-3.89,0.225
5.78,-3.74,0.225
5.79,-3.59,0.228
5.80,-3.44,0.229
5.82,-3.29,0.229
5.84,-3.14,0.231
5.85,-2.99,0.232
5.86,-2.84,0.234
5.88,-2.69,0.235
5.90,-2.54,0.237
5.91,-2.39,0.238
5.93,-2.24,0.240
5.94,-2.09,0.241
5.95,-1.94,0.244
5.97,-1.79,0.245
5.99,-1.64,0.247
6.00,-1.49,0.249
6.01,-1.34,0.253
6.03,-1.19,0.255
6.05,-1.04,0.257
6.06,-0.89,0.260
6.08,-0.74,0.262
6.09,-0.59,0.264
6.10,-0.44,0.269
6.12,-0.29,0.270
6.14,-0.14,0.273
6.15,0.01,0.275
6.16,0.16,0.279
6.18,0.31,0.281
6.20,0.45,0.283
6.21,0.61,0.286
6.23,0.75,0.289
6.24,0.90,0.291
6.25,1.05,0.293
6.27,1.20,0.296
6.29,1.35,0.297
6.30,1.50,0.299
6.31,1.65,0.302
6.33,1.80,0.303
6.35,1.95,0.303
6.36,2.10,0.304
6.38,2.25,0.305
6.39,2.40,0.306
6.40,2.55,0.306
6.42,2.70,0.307
6.44,2.85,0.307
6.45,3.00,0.307
6.46,3.15,0.307
6.48,3.30,0.307
6.50,3.45,0.307
6.51,3.60,0.307
6.53,3.75,0.307
6.54,3.90,0.305
6.55,4.05,0.305
6.57,4.20,0.304
6.59,4.35,0.303
6.60,4.50,0.303
6.61,4.66,0.302
6.63,4.81,0.301
6.65,4.96,0.301
6.66,5.11,0.300
6.68,5.26,0.300
6.69,5.41,0.300
6.70,5.56,0.299
6.72,5.71,0.299
6.74,5.86,0.298
6.75,6.01,0.298
6.76,6.16,0.298
6.78,6.31,0.297
6.80,6.46,0.297
6.81,6.61,0.297
6.83,6.76,0.296
6.84,6.91,0.296
6.85,7.06,0.296
6.87,7.21,0.295
6.89,7.36,0.295
6.90,7.51,0.295
6.91,7.66,0.295
6.93,7.81,0.294
6.95,7.96,0.294
6.96,8.11,0.294
6.98,8.26,0.294
6.99,8.41,0.294
7.00,8.56,0.294
7.02,8.71,0.294
7.04,8.86,0.293
7.05,9.01,0.293
7.06,9.16,0.293
7.08,9.31,0.293
7.10,9.46,0.293
7.11,9.61,0.293
7.13,9.76,0.293
7.14,9.91,0.293
7.15,10.06,0.293
7.17,10.21,0.293
7.19,10.36,0.293
7.20,10.52,0.293
7.21,10.66,0.293
7.23,10.82,0.293
7.25,10.97,0.293
7.26,11.12,0.293
7.28,11.27,0.293
7.29,11.42,0.293
7.30,11.57,0.293
7.32,11.72,0.293
7.34,11.87,0.293
7.35,12.02,0.293
7.36,12.17,0.293
7.38,12.32,0.293
7.40,12.47,0.293
7.41,12.62,0.293
7.43,12.77,0.293
7.44,12.92,0.293
7.45,13.07,0.294
7.47,13.22,0.294
7.49,13.37,0.294
7.50,13.52,0.294
7.51,13.67,0.294
7.53,13.82,0.294
7.55,13.97,0.294
7.56,14.12,0.294
7.58,14.27,0.294
7.59,14.42,0.294
7.60,14.57,0.294
7.62,14.72,0.294
7.64,14.87,0.294
7.65,15.02,0.295
7.66,15.17,0.295
7.68,15.32,0.295
7.70,15.47,0.295
7.71,15.62,0.295
7.73,15.77,0.295
7.74,15.92,0.295
7.75,16.07,0.295
7.77,16.22,0.295
7.79,16.37,0.295
7.80,16.52,0.295
7.81,16.67,0.296
7.83,16.82,0.296
7.85,16.97,0.296
7.86,17.12,0.296
7.88,17.27,0.296
7.89,17.42,0.296
7.90,17.57,0.296
7.92,17.72,0.296
7.94,17.87,0.296
7.95,18.03,0.296
7.96,18.18,0.296
7.98,18.32,0.296
8.00,18.47,0.296
8.01,18.62,0.297
8.03,18.78,0.297
8.04,18.92,0.297
8.05,19.08,0.297
8.07,19.23,0.297
8.09,19.37,0.297
8.10,19.52,0.297
8.11,19.68,0.298
8.13,19.83,0.298
8.15,19.98,0.298
8.16,20.13,0.298
8.18,20.28,0.298
8.19,20.43,0.298
8.20,20.58,0.298
8.22,20.73,0.298
8.24,20.88,0.298
8.25,21.03,0.299
8.26,21.18,0.299
8.28,21.33,0.299
8.30,21.48,0.299
8.31,21.63,0.299
8.33,21.78,0.299
8.34,21.93,0.299
8.35,22.08,0.299
8.37,22.23,0.300
8.39,22.38,0.300
8.40,22.53,0.300
8.41,22.68,0.300
8.43,22.83,0.300
8.45,22.98,0.300
8.46,23.13,0.300
8.48,23.28,0.300
8.49,23.43,0.300
8.50,23.58,0.301
8.52,23.73,0.301
8.53,23.88,0.301
8.55,24.03,0.301
8.57,24.18,0.301
8.58,24.33,0.301
8.60,24.48,0.301
8.61,24.63,0.301
8.63,24.78,0.301
8.64,24.93,0.301
8.65,25.08,0.302
8.67,25.23,0.302
8.68,25.38,0.302
8.70,25.53,0.302
8.72,25.68,0.302
8.73,25.83,0.302
8.75,25.98,0.302
8.76,26.13,0.303
8.78,26.28,0.303
8.79,26.43,0.303
8.80,26.58,0.303
8.82,26.73,0.303
8.83,26.88,0.303
8.85,27.03,0.303
8.87,27.19,0.304
8.88,27.33,0.304
8.90,27.48,0.304
8.91,27.64,0.304
8.93,27.79,0.304
8.94,27.94,0.304
8.95,28.09,0.304
8.97,28.24,0.305
8.98,28.39,0.305
9.00,28.54,0.305
9.02,28.69,0.305
9.03,28.84,0.305
9.05,28.99,0.305
9.06,29.14,0.305
9.08,29.29,0.306
9.09,29.44,0.306
9.10,29.59,0.306
9.12,29.74,0.306
9.13,29.89,0.306
9.15,30.04,0.306
9.17,30.19,0.306
9.18,30.34,0.306
9.20,30.49,0.307
9.21,30.64,0.307
9.23,30.79,0.307
9.24,30.94,0.307
9.25,31.09,0.307
9.27,31.24,0.307
9.28,31.39,0.307
9.30,31.54,0.308
9.32,31.69,0.308
9.33,31.84,0.308
9.35,31.99,0.308
9.36,32.14,0.308
9.38,32.29,0.308
9.39,32.44,0.308
9.40,32.59,0.308
9.42,32.74,0.309
9.43,32.89,0.309
9.45,33.04,0.309
9.47,33.19,0.309
9.48,33.34,0.309
9.50,33.49,0.309
9.51,33.64,0.309
9.53,33.79,0.309
9.54,33.94,0.310
9.55,34.09,0.310
9.57,34.24,0.310
9.58,34.39,0.310
9.60,34.54,0.310
9.62,34.69,0.310
9.63,34.84,0.310
9.65,34.99,0.310
9.66,35.14,0.311
9.68,35.29,0.311
9.69,35.44,0.311
9.70,35.59,0.311
9.72,35.74,0.311
9.73,35.90,0.311
9.75,36.05,0.311
9.77,36.19,0.311
9.78,36.35,0.311
9.80,36.50,0.312
9.81,36.65,0.312
9.83,36.79,0.312
9.84,36.95,0.312
9.85,37.10,0.312
9.87,37.25,0.312
9.88,37.40,0.312
9.90,37.55,0.312
9.92,37.70,0.313
9.93,37.85,0.313
9.95,38.00,0.313
9.96,38.15,0.313
9.98,38.30,0.313
9.99,38.45,0.313
10.00,38.60,0.313
10.02,38.75,0.313
10.03,38.90,0.313
10.05,39.05,0.313
10.07,39.20,0.314
10.08,39.35,0.314
10.10,39.50,0.314
10.11,39.65,0.314
10.13,39.80,0.314
10.14,39.95,0.314
10.15,40.10,0.314
10.17,40.25,0.314
10.18,40.40,0.314
10.20,40.55,0.315
10.22,40.70,0.315
10.23,40.85,0.315
10.25,41.00,0.315
10.26,41.15,0.315
10.28,41.30,0.315
10.29,41.45,0.315
10.30,41.60,0.315
10.32,41.75,0.316
10.33,41.90,0.316
10.35,42.05,0.316
10.37,42.20,0.316
10.38,42.35,0.316
10.40,42.50,0.316
10.41,42.65,0.316
10.43,42.80,0.316
10.44,42.95,0.317
10.45,43.10,0.317
10.47,43.25,0.317
10.48,43.40,0.317
10.50,43.55,0.317
10.52,43.70,0.317
10.53,43.85,0.317
10.55,44.00,0.317
10.56,44.15,0.317
10.58,44.30,0.318
10.59,44.45,0.318
10.60,44.60,0.318
10.62,44.75,0.318
10.63,44.90,0.318
10.65,45.05,0.318
10.67,45.20,0.318
10.68,45.36,0.318
10.70,45.50,0.318
10.71,45.66,0.318
10.73,45.80,0.319
10.74,45.96,0.319
10.75,46.11,0.319
10.77,46.25,0.319
10.78,46.40,0.319
10.80,46.55,0.319
10.82,46.71,0.319
10.83,46.86,0.319
10.85,47.01,0.320
10.86,47.16,0.320
10.88,47.31,0.320
10.89,47.46,0.320
10.90,47.61,0.320
10.92,47.76,0.320
10.93,47.91,0.320
10.95,48.06,0.320
10.97,48.21,0.320
10.98,48.36,0.321
11.00,48.51,0.321
11.01,48.66,0.321
11.03,48.81,0.321
11.04,48.96,0.321
11.05,49.11,0.321
11.07,49.26,0.321
11.08,49.41,0.321
11.10,49.56,0.322
11.12,49.71,0.322
11.13,49.86,0.322
11.15,50.01,0.322
11.16,50.16,0.322
11.18,50.31,0.322
11.19,50.46,0.322
11.20,50.61,0.322
11.22,50.76,0.322
11.23,50.91,0.323
11.25,51.06,0.323
11.27,51.21,0.323
11.28,51.36,0.323
11.30,51.51,0.323
11.31,51.66,0.323
11.33,51.81,0.323
11.34,51.96,0.323
11.35,52.11,0.323
11.37,52.26,0.324
11.38,52.41,0.324
11.40,52.56,0.324
11.42,52.71,0.324
11.43,52.86,0.324
11.45,53.01,0.324
11.46,53.16,0.324
11.48,53.31,0.324
11.49,53.46,0.325
11.50,53.61,0.325
11.52,53.76,0.325
11.53,53.91,0.325
11.55,54.06,0.325
11.57,54.21,0.325
11.58,54.36,0.325
11.60,54.51,0.325
11.61,54.67,0.325
11.63,54.81,0.326
11.64,54.97,0.326
11.65,55.12,0.326
11.67,55.27,0.326
11.68,55.42,0.326
11.70,55.57,0.326
11.72,55.72,0.326
11.73,55.87,0.326
11.75,56.02,0.327
11.76,56.17,0.327
11.78,56.32,0.327
11.79,56.47,0.327
11.80,56.62,0.327
11.82,56.77,0.327
11.83,56.92,0.327
11.85,57.07,0.327
11.87,57.22,0.327
11.88,57.37,0.327
11.90,57.52,0.328
11.91,57.67,0.328
11.93,57.82,0.328
11.94,57.97,0.328
11.95,58.12,0.328
11.97,58.27,0.328
11.98,58.42,0.328
12.00,58.57,0.328
12.02,58.72,0.328
12.03,58.87,0.328
12.05,59.02,0.328
12.06,59.17,0.329
12.08,59.32,0.329
12.09,59.47,0.329
12.10,59.62,0.329
12.12,59.77,0.329
12.13,59.92,0.329
12.15,60.07,0.329
12.17,60.22,0.330
12.18,60.37,0.330
12.20,60.52,0.330
12.21,60.67,0.330
12.23,60.82,0.330
12.24,60.97,0.330
12.25,61.12,0.330
12.27,61.27,0.330
12.28,61.42,0.330
12.30,61.57,0.330
12.32,61.72,0.331
12.33,61.87,0.331
12.35,62.02,0.331
12.36,62.17,0.331
12.38,62.32,0.331
12.39,62.47,0.331
12.40,62.62,0.331
12.42,62.77,0.331
12.43,62.92,0.331
12.45,63.07,0.332
12.47,63.22,0.332
12.48,63.37,0.332
12.50,63.52,0.332
12.51,63.68,0.332
12.53,63.83,0.332
12.54,63.97,0.332
12.55,64.12,0.332
12.57,64.28,0.332
12.58,64.43,0.333
12.60,64.58,0.333
12.62,64.73,0.333
12.63,64.88,0.333
12.65,65.03,0.333
12.66,65.18,0.333
12.68,65.33,0.333
12.69,65.48,0.333
12.70,65.63,0.333
12.72,65.78,0.333
12.73,65.93,0.334
12.75,66.08,0.334
12.77,66.23,0.334
12.78,66.38,0.334
12.80,66.53,0.334
12.81,66.68,0.334
12.83,66.83,0.334
12.84,66.98,0.334
12.85,67.13,0.334
12.87,67.28,0.335
12.88,67.43,0.335
12.90,67.58,0.335
12.92,67.73,0.335
12.93,67.88,0.335
12.95,68.03,0.335
12.96,68.18,0.335
12.98,68.33,0.335
12.99,68.48,0.335
13.00,68.63,0.336
13.02,68.78,0.336
13.03,68.93,0.336
13.05,69.08,0.336
13.07,69.23,0.336
13.08,69.38,0.336
13.10,69.53,0.336
13.11,69.68,0.337
13.13,69.83,0.337
13.14,69.98,0.337
13.15,70.13,0.337
13.17,70.28,0.337
13.18,70.43,0.337
13.20,70.58,0.337
13.22,70.73,0.337
13.23,70.88,0.337
13.25,71.03,0.337
13.26,71.18,0.337
13.28,71.33,0.338
13.29,71.48,0.338
13.30,71.63,0.338
13.32,71.78,0.338
13.33,71.93,0.338
13.35,72.08,0.338
13.37,72.23,0.338
13.38,72.38,0.338
13.40,72.53,0.338
13.41,72.68,0.339
13.43,72.83,0.339
13.44,72.98,0.339
13.45,73.13,0.339
13.47,73.28,0.339
13.48,73.43,0.339
13.50,73.58,0.339
13.52,73.73,0.339
13.53,73.88,0.339
13.55,74.03,0.339
13.56,74.18,0.340
13.58,74.33,0.340
13.59,74.49,0.340
13.60,74.63,0.340
13.62,74.78,0.340
13.63,74.93,0.340
13.65,75.08,0.340
13.67,75.23,0.340
13.68,75.39,0.340
13.70,75.54,0.340
13.71,75.69,0.341
13.73,75.84,0.341
13.74,75.99,0.341
13.75,76.14,0.341
13.77,76.29,0.341
13.78,76.44,0.341
13.80,76.59,0.341
13.82,76.74,0.341
13.83,76.89,0.341
13.85,77.04,0.342
13.86,77.19,0.342
13.88,77.34,0.342
13.89,77.49,0.342
13.90,77.64,0.342
13.92,77.79,0.342
13.93,77.94,0.342
13.95,78.09,0.343
13.97,78.24,0.343
13.98,78.39,0.343
14.00,78.54,0.343
14.01,78.69,0.343
14.03,78.84,0.343
14.04,78.99,0.343
14.05,79.14,0.343
14.07,79.29,0.343
14.08,79.44,0.343
14.10,79.59,0.344
14.12,79.74,0.344
14.13,79.89,0.344
14.15,80.04,0.344
14.16,80.19,0.344
14.18,80.34,0.344
14.19,80.49,0.344
14.20,80.64,0.344
14.22,80.79,0.344
14.23,80.94,0.344
14.25,81.09,0.345
14.27,81.24,0.345
14.28,81.39,0.345
14.30,81.54,0.345
14.31,81.69,0.345
14.33,81.84,0.345
14.34,81.99,0.345
14.35,82.14,0.345
14.37,82.29,0.345
14.38,82.44,0.345
14.40,82.59,0.346
14.42,82.74,0.346
14.43,82.89,0.346
14.45,83.04,0.346
14.46,83.19,0.346
14.48,83.34,0.346
14.49,83.49,0.346
14.50,83.64,0.346
14.52,83.79,0.346
14.53,83.94,0.346
14.55,84.09,0.346
14.57,84.24,0.346
14.58,84.39,0.346
14.60,84.54,0.346
14.61,84.69,0.347
14.63,84.84,0.347
14.64,84.99,0.347
14.65,85.15,0.347
14.67,85.30,0.347
14.68,85.45,0.347
14.70,85.59,0.347
14.72,85.75,0.347
14.73,85.90,0.347
14.75,86.04,0.347
14.76,86.20,0.347
14.78,86.35,0.347
14.79,86.50,0.347
14.80,86.65,0.347
14.82,86.80,0.348
14.83,86.95,0.348
14.85,87.10,0.348
14.87,87.25,0.348
14.88,87.40,0.348
14.90,87.55,0.348
14.91,87.70,0.348
14.93,87.85,0.348
14.94,88.00,0.348
14.95,88.15,0.348
14.97,88.30,0.349
14.98,88.45,0.349
15.00,88.60,0.349
15.02,88.75,0.349
15.03,88.90,0.349
15.05,89.05,0.349
15.06,89.20,0.349
15.08,89.35,0.349
15.09,89.50,0.349
15.10,89.65,0.349
15.12,89.80,0.350
15.13,89.95,0.350
15.15,90.10,0.350
15.17,90.25,0.350
15.18,90.40,0.350
15.20,90.55,0.350
15.21,90.70,0.350
15.23,90.85,0.350
15.24,91.00,0.351
15.25,91.15,0.351
15.27,91.30,0.351
15.28,91.45,0.351
15.30,91.60,0.351
15.32,91.75,0.351
15.33,91.90,0.351
15.35,92.05,0.351
15.36,92.20,0.352
15.38,92.35,0.352
15.39,92.50,0.352
15.40,92.65,0.352
15.42,92.80,0.352
15.43,92.95,0.352
15.45,93.10,0.352
15.47,93.25,0.352
15.48,93.40,0.352
15.50,93.55,0.353
15.51,93.70,0.353
15.53,93.85,0.353
15.54,94.00,0.353
15.55,94.15,0.353
15.57,94.30,0.353
15.58,94.45,0.353
15.60,94.60,0.353
15.62,94.75,0.354
15.63,94.90,0.354
15.65,95.05,0.354
15.66,95.20,0.354
15.68,95.35,0.354
15.69,95.50,0.354
15.70,95.65,0.354
15.72,95.80,0.354
15.73,95.95,0.355
15.75,96.10,0.355
15.77,96.26,0.355
15.78,96.41,0.355
15.80,96.56,0.355
15.81,96.71,0.355
15.83,96.86,0.355
15.84,97.01,0.355
15.85,97.16,0.355
15.87,97.31,0.356
15.88,97.46,0.356
15.90,97.61,0.356
15.92,97.76,0.356
15.93,97.91,0.356
15.95,98.06,0.356
15.96,98.21,0.356
15.98,98.36,0.356
15.99,98.51,0.356
16.00,98.66,0.356
16.02,98.81,0.356
16.03,98.96,0.357
16.05,99.11,0.357
16.07,99.26,0.357
16.08,99.41,0.357
16.10,99.56,0.357
16.11,99.71,0.357
16.13,99.86,0.357
16.14,100.01,0.357
16.15,100.16,0.357
16.17,100.31,0.357
16.18,100.46,0.357
16.20,100.61,0.358
16.22,100.76,0.358
16.23,100.91,0.358
16.25,101.06,0.358
16.26,101.21,0.358
16.28,101.36,0.358
16.29,101.51,0.358
16.30,101.66,0.359
16.32,101.81,0.359
16.33,101.96,0.359
16.35,102.11,0.359
16.37,102.26,0.359
16.38,102.41,0.359
16.40,102.56,0.359
16.41,102.71,0.359
16.43,102.86,0.359
16.44,103.01,0.360
16.45,103.16,0.360
16.47,103.31,0.360
16.48,103.46,0.360
16.50,103.61,0.360
16.52,103.76,0.360
16.53,103.91,0.360
16.55,104.06,0.360
16.56,104.21,0.361
16.58,104.36,0.361
16.59,104.51,0.361
16.60,104.66,0.361
16.62,104.81,0.361
16.63,104.96,0.361
16.65,105.11,0.361
16.67,105.26,0.361
16.68,105.41,0.361
16.70,105.56,0.362
16.71,105.71,0.362
16.73,105.86,0.362
16.74,106.01,0.362
16.75,106.16,0.362
16.77,106.31,0.362
16.78,106.46,0.362
16.80,106.62,0.362
16.82,106.76,0.362
16.83,106.91,0.362
16.85,107.06,0.362
16.86,107.21,0.362
16.88,107.36,0.363
16.89,107.51,0.363
16.90,107.66,0.363
16.92,107.81,0.363
16.93,107.96,0.363
16.95,108.11,0.363
16.97,108.26,0.363
16.98,108.41,0.363
17.00,108.56,0.363
17.01,108.71,0.363
17.03,108.87,0.363
17.04,109.01,0.364
17.05,109.17,0.364
17.07,109.32,0.364
17.08,109.47,0.364
17.10,109.62,0.364
17.12,109.77,0.364
17.13,109.92,0.364
17.14,110.07,0.364
17.16,110.22,0.364
17.18,110.37,0.364
17.19,110.52,0.365
17.21,110.67,0.365
17.22,110.82,0.365
17.23,110.97,0.365
17.25,111.12,0.365
17.27,111.27,0.365
17.28,111.42,0.365
17.29,111.57,0.365
17.31,111.72,0.365
17.33,111.87,0.366
17.34,112.02,0.366
17.36,112.17,0.366
17.37,112.32,0.366
17.38,112.47,0.366
17.40,112.62,0.366
17.42,112.77,0.366
17.43,112.92,0.366
17.44,113.07,0.366
17.46,113.22,0.366
17.48,113.37,0.367
17.49,113.52,0.367
17.51,113.67,0.367
17.52,113.82,0.367
17.53,113.97,0.367
17.55,114.12,0.367
17.57,114.27,0.367
17.58,114.42,0.367
17.59,114.57,0.367
17.61,114.72,0.367
17.63,114.87,0.367
17.64,115.02,0.367
17.66,115.17,0.367
17.67,115.32,0.367
17.68,115.47,0.368
17.70,115.62,0.368
17.72,115.77,0.368
17.73,115.92,0.368
17.74,116.07,0.368
17.76,116.22,0.368
17.78,116.37,0.368
17.79,116.52,0.368
17.81,116.67,0.368
17.82,116.82,0.368
17.83,116.97,0.368
17.85,117.12,0.368
17.87,117.27,0.369
17.88,117.42,0.369
17.89,117.57,0.369
17.91,117.72,0.369
17.93,117.87,0.369
17.94,118.02,0.369
17.96,118.17,0.369
17.97,118.32,0.369
17.98,118.47,0.369
18.00,118.62,0.369
18.02,118.77,0.370
18.03,118.92,0.370
18.04,119.07,0.370
18.06,119.22,0.370
18.08,119.37,0.370
18.09,119.52,0.370
18.11,119.67,0.370
18.12,119.83,0.371
18.13,119.97,0.371
18.15,120.12,0.371
18.17,120.28,0.371
18.18,120.43,0.371
18.19,120.57,0.371
18.21,120.72,0.371
18.23,120.87,0.371
18.24,121.02,0.371
18.26,121.17,0.371
18.27,121.32,0.371
18.28,121.47,0.371
18.30,121.62,0.371
18.32,121.77,0.371
18.33,121.92,0.371
18.34,122.07,0.372
18.36,122.22,0.372
18.38,122.38,0.372
18.39,122.53,0.372
18.41,122.67,0.372
18.42,122.83,0.372
18.43,122.98,0.372
18.45,123.13,0.373
18.47,123.28,0.373
18.48,123.43,0.373
18.49,123.58,0.373
18.51,123.73,0.373
18.53,123.88,0.373
18.54,124.03,0.373
18.56,124.18,0.373
18.57,124.33,0.373
18.58,124.48,0.373
18.60,124.63,0.373
18.62,124.78,0.374
18.63,124.93,0.374
18.64,125.08,0.374
18.66,125.23,0.374
18.68,125.38,0.374
18.69,125.53,0.374
18.71,125.68,0.374
18.72,125.83,0.374
18.73,125.98,0.374
18.75,126.13,0.374
18.77,126.28,0.375
18.78,126.43,0.375
18.79,126.58,0.375
18.81,126.73,0.375
18.83,126.88,0.375
18.84,127.03,0.375
18.86,127.18,0.375
18.87,127.33,0.375
18.88,127.48,0.375
18.90,127.63,0.375
18.92,127.78,0.376
18.93,127.93,0.376
18.94,128.08,0.376
18.96,128.23,0.376
18.98,128.38,0.376
18.99,128.53,0.376
19.01,128.68,0.376
19.02,128.83,0.376
19.03,128.98,0.376
19.05,129.13,0.376
19.07,129.28,0.376
19.08,129.43,0.377
19.09,129.58,0.377
19.11,129.73,0.377
19.13,129.88,0.377
19.14,130.03,0.377
19.16,130.18,0.377
19.17,130.33,0.377
19.18,130.48,0.377
19.20,130.63,0.377
19.22,130.78,0.377
19.23,130.93,0.377
19.24,131.08,0.378
19.26,131.23,0.378
19.28,131.38,0.378
19.29,131.53,0.378
19.31,131.68,0.378
19.32,131.83,0.378
19.33,131.98,0.378
19.35,132.13,0.378
19.37,132.28,0.378
19.38,132.43,0.378
19.39,132.58,0.378
19.41,132.73,0.378
19.43,132.88,0.379
19.44,133.03,0.379
19.46,133.18,0.379
19.47,133.33,0.379
19.48,133.48,0.379
19.50,133.63,0.379
19.52,133.78,0.379
19.53,133.93,0.379
19.54,134.08,0.379
19.56,134.23,0.380
19.58,134.38,0.380
19.59,134.54,0.380
19.61,134.69,0.380
19.62,134.84,0.380
19.63,134.99,0.380
19.65,135.14,0.380
19.67,135.29,0.380
19.68,135.44,0.381
19.69,135.59,0.381
19.71,135.74,0.381
19.73,135.89,0.381
19.74,136.04,0.381
19.76,136.19,0.381
19.77,136.34,0.381
19.78,136.49,0.381
19.80,136.64,0.381
19.82,136.79,0.381
19.83,136.94,0.381
19.84,137.09,0.381
19.86,137.24,0.381
19.88,137.39,0.382
19.89,137.54,0.382
19.91,137.69,0.382
19.92,137.84,0.382
19.93,137.99,0.382
19.95,138.14,0.382
19.97,138.29,0.382
19.98,138.44,0.382
19.99,138.59,0.382
20.01,138.74,0.382
20.03,138.89,0.382
20.04,139.04,0.382
20.06,139.19,0.382
20.07,139.34,0.383
20.08,139.49,0.383
20.10,139.64,0.383
20.12,139.79,0.383
20.13,139.94,0.383
20.14,140.09,0.383
20.16,140.24,0.383
20.18,140.39,0.383
20.19,140.54,0.384
20.21,140.69,0.384
20.22,140.84,0.384
20.23,140.99,0.384
20.25,141.14,0.384
20.27,141.29,0.384
20.28,141.44,0.384
20.29,141.59,0.384
20.31,141.74,0.384
20.33,141.89,0.384
20.34,142.04,0.384
20.36,142.19,0.384
20.37,142.34,0.384
20.38,142.49,0.385
20.40,142.64,0.385
20.42,142.79,0.385
20.43,142.94,0.385
20.44,143.09,0.385
20.46,143.24,0.385
20.48,143.39,0.385
20.49,143.54,0.385
20.51,143.69,0.385
20.52,143.84,0.385
20.53,143.99,0.385
20.55,144.14,0.386
20.57,144.29,0.386
20.58,144.44,0.386
20.59,144.59,0.386
20.61,144.74,0.386
20.63,144.89,0.386
20.64,145.04,0.386
20.66,145.19,0.386
20.67,145.34,0.386
20.68,145.49,0.386
20.70,145.64,0.386
20.72,145.79,0.386
20.73,145.94,0.386
20.74,146.09,0.386
20.76,146.24,0.386
20.78,146.39,0.386
20.79,146.54,0.386
20.81,146.69,0.386
20.82,146.84,0.386
20.83,146.99,0.386
20.85,147.14,0.386
20.87,147.29,0.387
20.88,147.44,0.387
20.89,147.59,0.387
20.91,147.75,0.387
20.93,147.90,0.387
20.94,148.04,
20.96,148.20,
20.97,148.34,
20.98,,
20.99,,

[step]
Ramp 10.00 °C/min to -60.00 °C
Time,Temperature,Heat Flow (Normalized)
min,°C,W/g
21.99,150.09,-0.047
22.01,150.09,-0.047
22.02,150.08,-0.047
22.04,150.08,-0.048
22.05,150.07,-0.065
22.07,150.04,-0.090
22.08,150.01,-0.121
22.10,149.96,-0.157
22.11,149.89,-0.196
22.13,149.81,-0.235
22.14,149.72,-0.272
22.16,149.62,-0.302
22.17,149.51,-0.328
22.19,149.39,-0.350
22.20,149.27,-0.371
22.22,149.15,-0.385
22.23,149.02,-0.400
22.25,148.89,-0.412
22.26,148.76,-0.420
22.28,148.62,-0.430
22.29,148.48,-0.438
22.31,148.34,-0.443
22.32,148.20,-0.448
22.34,148.06,-0.454
22.35,147.92,-0.457
22.37,147.78,-0.460
22.38,147.63,-0.461
22.40,147.49,-0.464
22.41,147.34,-0.466
22.43,147.20,-0.467
22.44,147.05,-0.469
22.46,146.91,-0.470
22.47,146.76,-0.470
22.49,146.61,-0.471
22.50,146.47,-0.471
22.52,146.32,-0.472
22.53,146.17,-0.473
22.55,146.03,-0.473
22.56,145.88,-0.473
22.58,145.73,-0.474
22.59,145.58,-0.474
22.61,145.43,-0.474
22.62,145.29,-0.475
22.64,145.14,-0.475
22.65,144.99,-0.475
22.67,144.84,-0.475
22.68,144.69,-0.476
22.70,144.55,-0.476
22.71,144.40,-0.476
22.73,144.25,-0.477
22.74,144.10,-0.477
22.76,143.95,-0.477
22.77,143.80,-0.477
22.79,143.66,-0.477
22.80,143.51,-0.478
22.82,143.36,-0.478
22.83,143.21,-0.478
22.85,143.06,-0.478
22.86,142.91,-0.478
22.88,142.76,-0.479
22.89,142.61,-0.479
22.91,142.47,-0.479
22.92,142.32,-0.479
22.94,142.17,-0.479
22.95,142.02,-0.479
22.97,141.87,-0.479
22.98,141.72,-0.479
23.00,141.57,-0.479
23.01,141.42,-0.479
23.03,141.27,-0.479
23.04,141.12,-0.479
23.06,140.97,-0.479
23.07,140.82,-0.479
23.09,140.67,-0.479
23.10,140.53,-0.479
23.12,140.38,-0.479
23.13,140.23,-0.479
23.15,140.08,-0.479
23.16,139.93,-0.479
23.18,139.78,-0.479
23.19,139.63,-0.479
23.21,139.48,-0.479
23.22,139.33,-0.479
23.24,139.18,-0.479
23.25,139.03,-0.479
23.27,138.88,-0.479
23.28,138.73,-0.479
23.30,138.58,-0.479
23.31,138.43,-0.479
23.33,138.28,-0.478
23.34,138.13,-0.478
23.36,137.98,-0.478
23.37,137.83,-0.478
23.39,137.68,-0.478
23.40,137.53,-0.478
23.42,137.38,-0.477
23.43,137.23,-0.477
23.45,137.08,-0.477
23.46,136.93,-0.477
23.48,136.78,-0.477
23.49,136.64,-0.476
23.51,136.49,-0.476
23.52,136.34,-0.476
23.54,136.19,-0.476
23.55,136.04,-0.476
23.57,135.89,-0.476
23.58,135.74,-0.475
23.60,135.59,-0.475
23.61,135.44,-0.475
23.63,135.29,-0.475
23.64,135.14,-0.475
23.66,134.99,-0.475
23.67,134.84,-0.475
23.69,134.69,-0.474
23.70,134.54,-0.474
23.72,134.39,-0.474
23.73,134.24,-0.474
23.75,134.09,-0.474
23.76,133.94,-0.474
23.78,133.79,-0.474
23.79,133.64,-0.473
23.81,133.49,-0.473
23.82,133.34,-0.473
23.84,133.19,-0.473
23.85,133.04,-0.473
23.87,132.89,-0.473
23.88,132.74,-0.472
23.90,132.59,-0.472
23.91,132.44,-0.472
23.93,132.30,-0.472
23.94,132.15,-0.472
23.96,132.00,-0.472
23.97,131.85,-0.471
23.99,131.70,-0.471
24.00,131.55,-0.471
24.02,131.40,-0.471
24.03,131.25,-0.471
24.05,131.10,-0.471
24.06,130.95,-0.471
24.08,130.80,-0.470
24.09,130.65,-0.470
24.11,130.50,-0.470
24.12,130.35,-0.470
24.14,130.20,-0.470
24.15,130.05,-0.470
24.17,129.90,-0.470
24.18,129.75,-0.470
24.20,129.60,-0.469
24.21,129.45,-0.469
24.23,129.30,-0.469
24.24,129.15,-0.469
24.26,129.00,-0.469
24.27,128.85,-0.469
24.29,128.70,-0.468
24.30,128.55,-0.468
24.32,128.40,-0.468
24.33,128.25,-0.468
24.35,128.10,-0.468
24.36,127.95,-0.468
24.38,127.80,-0.468
24.39,127.65,-0.467
24.41,127.50,-0.467
24.42,127.35,-0.467
24.44,127.20,-0.467
24.45,127.05,-0.467
24.47,126.90,-0.467
24.48,126.75,-0.467
24.50,126.60,-0.467
24.51,126.45,-0.466
24.53,126.30,-0.466
24.54,126.15,-0.466
24.56,126.00,-0.466
24.57,125.85,-0.466
24.59,125.70,-0.466
24.60,125.55,-0.465
24.62,125.40,-0.465
24.63,125.25,-0.465
24.65,125.11,-0.465
24.66,124.96,-0.465
24.68,124.81,-0.465
24.69,124.66,-0.465
24.71,124.51,-0.464
24.72,124.36,-0.464
24.74,124.21,-0.464
24.75,124.06,-0.464
24.77,123.91,-0.464
24.78,123.76,-0.464
24.80,123.61,-0.464
24.81,123.46,-0.463
24.83,123.31,-0.463
24.84,123.16,-0.463
24.86,123.01,-0.463
24.87,122.86,-0.463
24.89,122.71,-0.463
24.90,122.56,-0.463
24.92,122.41,-0.462
24.93,122.26,-0.462
24.95,122.11,-0.462
24.96,121.96,-0.462
24.98,121.81,-0.462
24.99,121.66,-0.462
25.01,121.51,-0.462
25.02,121.36,-0.462
25.04,121.21,-0.461
25.05,121.06,-0.461
25.07,120.91,-0.461
25.08,120.76,-0.461
25.10,120.61,-0.461
25.11,120.46,-0.461
25.13,120.31,-0.460
25.14,120.16,-0.460
25.16,120.01,-0.460
25.17,119.86,-0.460
25.19,119.71,-0.460
25.20,119.56,-0.460
25.22,119.41,-0.460
25.23,119.26,-0.460
25.25,119.11,-0.460
25.26,118.96,-0.459
25.28,118.81,-0.459
25.29,118.66,-0.459
25.31,118.51,-0.459
25.32,118.36,-0.459
25.34,118.21,-0.459
25.35,118.06,-0.459
25.37,117.91,-0.459
25.38,117.76,-0.458
25.40,117.61,-0.458
25.41,117.46,-0.458
25.43,117.31,-0.458
25.44,117.16,-0.458
25.46,117.01,-0.458
25.47,116.86,-0.457
25.49,116.71,-0.457
25.50,116.57,-0.457
25.52,116.42,-0.457
25.53,116.27,-0.457
25.55,116.12,-0.457
25.56,115.97,-0.457
25.58,115.82,-0.457
25.59,115.67,-0.456
25.61,115.52,-0.456
25.62,115.37,-0.456
25.64,115.22,-0.456
25.65,115.07,-0.456
25.67,114.92,-0.456
25.68,114.77,-0.456
25.70,114.62,-0.456
25.71,114.47,-0.456
25.73,114.32,-0.455
25.74,114.17,-0.455
25.76,114.02,-0.455
25.77,113.87,-0.455
25.79,113.72,-0.455
25.80,113.57,-0.455
25.82,113.42,-0.455
25.83,113.27,-0.454
25.85,113.12,-0.454
25.86,112.97,-0.454
25.88,112.82,-0.454
25.89,112.67,-0.454
25.91,112.52,-0.454
25.92,112.37,-0.454
25.94,112.22,-0.454
25.95,112.07,-0.453
25.97,111.92,-0.453
25.98,111.77,-0.453
26.00,111.62,-0.453
26.01,111.47,-0.453
26.03,111.32,-0.453
26.04,111.17,-0.453
26.06,111.02,-0.453
26.07,110.87,-0.453
26.09,110.72,-0.452
26.10,110.57,-0.452
26.12,110.42,-0.452
26.13,110.27,-0.452
26.15,110.12,-0.452
26.16,109.97,-0.452
26.18,109.82,-0.452
26.19,109.67,-0.452
26.21,109.52,-0.451
26.22,109.37,-0.451
26.24,109.22,-0.451
26.25,109.07,-0.451
26.27,108.92,-0.451
26.28,108.77,-0.451
26.30,108.62,-0.451
26.31,108.47,-0.450
26.33,108.32,-0.450
26.34,108.18,-0.450
26.36,108.02,-0.450
26.37,107.88,-0.450
26.39,107.72,-0.450
26.40,107.57,-0.450
26.42,107.43,-0.450
26.43,107.28,-0.449
26.45,107.12,-0.449
26.46,106.97,-0.449
26.48,106.83,-0.449
26.49,106.68,-0.449
26.51,106.53,-0.449
26.52,106.38,-0.449
26.54,106.23,-0.449
26.55,106.08,-0.448
26.57,105.93,-0.448
26.58,105.78,-0.448
26.60,105.63,-0.448
26.61,105.48,-0.448
26.63,105.33,-0.448
26.64,105.18,-0.447
26.66,105.03,-0.447
26.67,104.88,-0.447
26.69,104.73,-0.447
26.70,104.58,-0.447
26.72,104.43,-0.447
26.73,104.28,-0.447
26.75,104.13,-0.446
26.76,103.98,-0.446
26.78,103.83,-0.446
26.79,103.68,-0.446
26.81,103.53,-0.446
26.82,103.38,-0.446
26.84,103.23,-0.446
26.85,103.08,-0.446
26.87,102.93,-0.446
26.88,102.78,-0.446
26.90,102.63,-0.445
26.91,102.48,-0.445
26.93,102.33,-0.445
26.94,102.18,-0.445
26.96,102.03,-0.445
26.97,101.88,-0.445
26.99,101.73,-0.445
27.00,101.58,-0.445
27.02,101.43,-0.444
27.03,101.28,-0.444
27.05,101.13,-0.444
27.06,100.98,-0.444
27.08,100.83,-0.444
27.09,100.68,-0.444
27.11,100.53,-0.444
27.12,100.38,-0.443
27.14,100.23,-0.443
27.15,100.08,-0.443
27.17,99.93,-0.443
27.18,99.78,-0.443
27.20,99.63,-0.443
27.21,99.48,-0.443
27.23,99.33,-0.442
27.24,99.18,-0.442
27.26,99.04,-0.442
27.27,98.88,-0.442
27.29,98.74,-0.442
27.30,98.58,-0.442
27.32,98.44,-0.442
27.33,98.29,-0.442
27.35,98.14,-0.442
27.36,97.99,-0.441
27.38,97.84,-0.441
27.39,97.69,-0.441
27.41,97.54,-0.441
27.42,97.39,-0.441
27.44,97.24,-0.441
27.45,97.09,-0.441
27.47,96.94,-0.440
27.48,96.79,-0.440
27.50,96.64,-0.440
27.51,96.49,-0.440
27.53,96.34,-0.440
27.54,96.19,-0.440
27.56,96.04,-0.440
27.57,95.89,-0.440
27.59,95.74,-0.439
27.60,95.59,-0.439
27.62,95.44,-0.439
27.63,95.29,-0.439
27.65,95.14,-0.439
27.66,94.99,-0.439
27.68,94.84,-0.439
27.69,94.69,-0.439
27.71,94.54,-0.438
27.72,94.39,-0.438
27.74,94.24,-0.438
27.75,94.09,-0.438
27.77,93.94,-0.438
27.78,93.79,-0.438
27.80,93.64,-0.438
27.81,93.49,-0.437
27.83,93.34,-0.437
27.84,93.19,-0.437
27.86,93.04,-0.437
27.87,92.89,-0.437
27.89,92.74,-0.437
27.90,92.59,-0.437
27.92,92.44,-0.436
27.93,92.29,-0.436
27.95,92.14,-0.436
27.96,91.99,-0.436
27.98,91.84,-0.436
27.99,91.69,-0.436
28.01,91.54,-0.436
28.02,91.39,-0.435
28.04,91.24,-0.435
28.05,91.09,-0.435
28.07,90.94,-0.435
28.08,90.79,-0.435
28.10,90.64,-0.435
28.11,90.49,-0.434
28.13,90.34,-0.434
28.14,90.19,-0.434
28.16,90.04,-0.434
28.17,89.89,-0.433
28.19,89.74,-0.433
28.20,89.59,-0.433
28.22,89.44,-0.433
28.23,89.29,-0.433
28.25,89.14,-0.433
28.26,88.99,-0.433
28.28,88.84,-0.432
28.29,88.69,-0.432
28.31,88.54,-0.432
28.32,88.40,-0.432
28.34,88.24,-0.432
28.35,88.10,-0.432
28.37,87.94,-0.432
28.38,87.80,-0.431
28.40,87.65,-0.431
28.41,87.50,-0.431
28.43,87.35,-0.431
28.44,87.20,-0.431
28.46,87.05,-0.430
28.47,86.90,-0.430
28.49,86.75,-0.430
28.50,86.60,-0.430
28.52,86.45,-0.430
28.53,86.30,-0.430
28.55,86.15,-0.430
[...]
93.05,-11.06,0.209
93.06,-10.91,0.210
93.08,-10.76,0.210
93.09,-10.61,0.210
93.11,-10.46,0.211
93.12,-10.31,0.211
93.14,-10.16,0.211
93.15,-10.01,0.211
93.17,-9.86,0.211
93.18,-9.71,0.211
93.20,-9.56,0.212
93.21,-9.41,0.212
93.23,-9.26,0.212
93.24,-9.11,0.212
93.26,-8.96,0.212
93.27,-8.81,0.213
93.29,-8.66,0.213
93.30,-8.51,0.213
93.32,-8.36,0.214
93.33,-8.21,0.214
93.35,-8.06,0.214
93.36,-7.91,0.214
93.38,-7.76,0.215
93.39,-7.61,0.215
93.41,-7.46,0.216
93.42,-7.31,0.216
93.44,-7.16,0.216
93.45,-7.01,0.216
93.47,-6.86,0.217
93.48,-6.71,0.217
93.50,-6.56,0.218
93.51,-6.41,0.219
93.53,-6.26,0.219
93.54,-6.11,0.220
93.56,-5.96,0.220
93.57,-5.81,0.222
93.59,-5.66,0.222
93.60,-5.51,0.222
93.62,-5.36,0.223
93.63,-5.21,0.223
93.65,-5.06,0.224
93.66,-4.91,0.225
93.68,-4.76,0.225
93.69,-4.61,0.226
93.71,-4.46,0.226
93.72,-4.31,0.227
93.74,-4.16,0.228
93.75,-4.01,0.229
93.77,-3.86,0.230
93.78,-3.71,0.231
93.80,-3.56,0.233
93.81,-3.41,0.233
93.83,-3.26,0.236
93.84,-3.11,0.237
93.86,-2.96,0.240
93.87,-2.81,0.240
93.89,-2.66,0.243
93.90,-2.51,0.244
93.92,-2.36,0.246
93.93,-2.21,0.248
93.95,-2.06,0.250
93.96,-1.91,0.251
93.98,-1.76,0.254
93.99,-1.61,0.256
94.01,-1.46,0.259
94.02,-1.31,0.261
94.04,-1.16,0.264
94.05,-1.01,0.268
94.07,-0.86,0.269
94.08,-0.71,0.273
94.10,-0.56,0.275
94.11,-0.41,0.278
94.13,-0.26,0.281
94.14,-0.12,0.284
94.16,0.03,0.286
94.17,0.18,0.289
94.19,0.33,0.292
94.20,0.48,0.295
94.22,0.63,0.298
94.23,0.78,0.301
94.25,0.93,0.303
94.26,1.08,0.305
94.28,1.23,0.308
94.29,1.38,0.310
94.31,1.53,0.312
94.32,1.68,0.313
94.34,1.83,0.314
94.35,1.98,0.316
94.37,2.13,0.316
94.38,2.28,0.317
94.40,2.43,0.318
94.41,2.58,0.318
94.43,2.73,0.318
94.44,2.88,0.318
94.46,3.03,0.318
94.47,3.18,0.318
94.49,3.33,0.318
94.50,3.48,0.317
94.52,3.63,0.316
94.53,3.78,0.315
94.55,3.93,0.314
94.56,4.08,0.312
94.58,4.23,0.311
94.59,4.38,0.310
94.61,4.53,0.309
94.62,4.68,0.308
94.64,4.83,0.307
94.65,4.99,0.304
94.67,5.14,0.304
94.68,5.29,0.303
94.70,5.44,0.302
94.71,5.59,0.302
94.73,5.74,0.301
94.74,5.89,0.301
94.76,6.04,0.300
94.77,6.19,0.300
94.79,6.34,0.300
94.80,6.49,0.299
94.82,6.64,0.299
94.83,6.79,0.299
94.85,6.94,0.298
94.86,7.09,0.298
94.88,7.24,0.298
94.89,7.39,0.297
94.91,7.54,0.297
94.92,7.69,0.297
94.94,7.84,0.297
94.95,7.99,0.296
94.97,8.14,0.296
94.98,8.29,0.296
95.00,8.44,0.296
95.01,8.59,0.296
95.03,8.74,0.296
95.04,8.89,0.295
95.06,9.04,0.295
95.07,9.19,0.295
95.09,9.34,0.295
95.10,9.49,0.295
95.12,9.64,0.295
95.13,9.79,0.295
95.15,9.94,0.295
95.16,10.10,0.295
95.18,10.25,0.295
95.19,10.40,0.295
95.21,10.55,0.295
95.22,10.70,0.295
95.24,10.85,0.295
95.25,11.00,0.295
95.27,11.15,0.295
95.28,11.30,0.295
95.30,11.45,0.295
95.31,11.60,0.295
95.33,11.75,0.295
95.34,11.90,0.295
95.36,12.05,0.295
95.37,12.20,0.295
95.39,12.35,0.295
95.40,12.50,0.295
95.42,12.65,0.295
95.43,12.80,0.295
95.45,12.95,0.295
95.46,13.10,0.295
95.48,13.25,0.295
95.49,13.40,0.295
95.51,13.55,0.295
95.52,13.70,0.295
95.54,13.85,0.295
95.55,14.00,0.295
95.57,14.15,0.295
95.58,14.30,0.295
95.60,14.45,0.296
95.61,14.60,0.296
95.63,14.75,0.296
95.64,14.90,0.296
95.66,15.05,0.296
95.67,15.20,0.296
95.69,15.35,0.296
95.70,15.50,0.296
95.72,15.65,0.296
95.73,15.80,0.296
95.75,15.95,0.296
95.76,16.10,0.296
95.78,16.25,0.296
95.79,16.40,0.297
95.81,16.55,0.297
95.82,16.70,0.297
95.84,16.85,0.297
95.85,17.00,0.297
95.87,17.15,0.297
95.88,17.30,0.297
95.90,17.45,0.297
95.91,17.60,0.297
95.93,17.75,0.297
95.94,17.90,0.297
95.96,18.06,0.297
95.97,18.20,0.297
95.99,18.35,0.298
96.00,18.50,0.298
96.02,18.65,0.298
96.03,18.80,0.298
96.05,18.95,0.298
96.06,19.10,0.298
96.08,19.25,0.298
96.09,19.41,0.298
96.11,19.56,0.299
96.12,19.71,0.299
96.14,19.86,0.299
96.15,20.01,0.299
96.17,20.16,0.299
96.18,20.31,0.299
96.20,20.46,0.299
96.21,20.61,0.299
96.23,20.76,0.300
96.24,20.91,0.300
96.26,21.06,0.300
96.27,21.21,0.300
96.29,21.36,0.300
96.30,21.51,0.300
96.32,21.66,0.300
96.33,21.81,0.300
96.35,21.96,0.300
96.36,22.11,0.300
96.38,22.26,0.301
96.39,22.41,0.301
96.41,22.56,0.301
96.42,22.71,0.301
96.44,22.86,0.301
96.45,23.01,0.301
96.47,23.16,0.301
96.48,23.31,0.301
96.50,23.46,0.301
96.51,23.61,0.302
96.53,23.76,0.302
96.54,23.91,0.302
96.56,24.06,0.302
96.57,24.21,0.302
96.59,24.36,0.302
96.60,24.51,0.302
96.62,24.66,0.302
96.63,24.81,0.302
96.65,24.96,0.302
96.66,25.11,0.303
96.68,25.26,0.303
96.69,25.41,0.303
96.71,25.56,0.303
96.72,25.71,0.303
96.74,25.86,0.303
96.75,26.01,0.303
96.77,26.16,0.303
96.78,26.31,0.304
96.80,26.46,0.304
96.81,26.61,0.304
96.83,26.76,0.304
96.84,26.91,0.304
96.86,27.06,0.304
96.87,27.22,0.304
96.89,27.37,0.304
96.90,27.52,0.305
96.92,27.67,0.305
96.93,27.82,0.305
96.95,27.97,0.305
96.96,28.12,0.305
96.98,28.27,0.305
96.99,28.42,0.305
97.01,28.57,0.305
97.02,28.72,0.305
97.04,28.87,0.306
97.05,29.02,0.306
97.07,29.17,0.306
97.08,29.32,0.306
97.10,29.47,0.306
97.11,29.62,0.306
97.13,29.77,0.306
97.14,29.92,0.306
97.16,30.07,0.307
97.17,30.22,0.307
97.19,30.37,0.307
97.20,30.52,0.307
97.22,30.67,0.307
97.23,30.82,0.307
97.25,30.97,0.307
97.26,31.12,0.307
97.28,31.27,0.307
97.29,31.42,0.308
97.31,31.57,0.308
97.32,31.72,0.308
97.34,31.87,0.308
97.35,32.02,0.308
97.37,32.17,0.308
97.38,32.32,0.308
97.40,32.47,0.308
97.41,32.62,0.309
97.43,32.77,0.309
97.44,32.92,0.309
97.46,33.07,0.309
97.47,33.22,0.309
97.49,33.37,0.309
97.50,33.52,0.309
97.52,33.67,0.309
97.53,33.82,0.310
97.55,33.97,0.310
97.56,34.12,0.310
97.58,34.27,0.310
97.59,34.42,0.310
97.61,34.57,0.310
97.62,34.72,0.310
97.64,34.87,0.310
97.65,35.02,0.310
97.67,35.17,0.310
97.68,35.32,0.310
97.70,35.47,0.311
97.71,35.62,0.311
97.73,35.77,0.311
97.74,35.92,0.311
97.76,36.07,0.311
97.77,36.22,0.311
97.79,36.37,0.311
97.80,36.52,0.311
97.82,36.68,0.311
97.83,36.83,0.311
97.85,36.98,0.312
97.86,37.13,0.312
97.88,37.28,0.312
97.89,37.43,0.312
97.91,37.58,0.312
97.92,37.73,0.312
97.94,37.88,0.312
97.95,38.03,0.312
97.97,38.18,0.312
97.98,38.33,0.312
98.00,38.48,0.312
98.01,38.63,0.313
98.03,38.78,0.313
98.04,38.93,0.313
98.06,39.08,0.313
98.07,39.23,0.313
98.09,39.38,0.313
98.10,39.53,0.313
98.12,39.68,0.313
98.13,39.83,0.314
98.15,39.98,0.314
98.16,40.13,0.314
98.18,40.28,0.314
98.19,40.43,0.314
98.21,40.58,0.314
98.22,40.73,0.314
98.24,40.88,0.314
98.25,41.03,0.314
98.27,41.18,0.314
98.28,41.33,0.314
98.30,41.48,0.315
98.31,41.63,0.315
98.33,41.78,0.315
98.34,41.93,0.315
98.36,42.08,0.315
98.37,42.23,0.315
98.39,42.38,0.315
98.40,42.53,0.315
98.42,42.68,0.315
98.43,42.83,0.316
98.45,42.98,0.316
98.46,43.13,0.316
98.48,43.28,0.316
98.49,43.43,0.316
98.51,43.58,0.316
98.52,43.73,0.316
98.54,43.88,0.316
98.55,44.03,0.316
98.57,44.18,0.317
98.58,44.33,0.317
98.60,44.48,0.317
98.61,44.63,0.317
98.63,44.78,0.317
98.64,44.94,0.317
98.66,45.08,0.317
98.67,45.23,0.317
98.69,45.39,0.317
98.70,45.53,0.318
98.72,45.69,0.318
98.73,45.84,0.318
98.75,45.99,0.318
98.76,46.14,0.318
98.78,46.29,0.318
98.79,46.44,0.318
98.81,46.59,0.318
98.82,46.74,0.318
98.84,46.89,0.319
98.85,47.04,0.319
98.87,47.19,0.319
98.88,47.34,0.319
98.90,47.49,0.319
98.91,47.64,0.319
98.93,47.79,0.319
98.94,47.94,0.319
98.96,48.09,0.319
98.97,48.24,0.320
98.99,48.39,0.320
99.00,48.54,0.320
99.02,48.69,0.320
99.03,48.84,0.320
99.05,48.99,0.320
99.06,49.14,0.320
99.08,49.29,0.320
99.09,49.44,0.320
99.11,49.59,0.320
99.12,49.74,0.321
99.14,49.89,0.321
99.15,50.04,0.321
99.17,50.19,0.321
99.18,50.34,0.321
99.20,50.49,0.321
99.21,50.64,0.321
99.23,50.79,0.321
99.24,50.94,0.322
99.26,51.09,0.322
99.27,51.24,0.322
99.29,51.39,0.322
99.30,51.54,0.322
99.32,51.69,0.322
99.33,51.84,0.322
99.35,51.99,0.322
99.36,52.14,0.322
99.38,52.29,0.322
99.39,52.44,0.322
99.41,52.59,0.322
99.42,52.74,0.323
99.44,52.89,0.323
99.45,53.04,0.323
99.47,53.19,0.323
99.48,53.34,0.323
99.50,53.49,0.323
99.51,53.64,0.323
99.53,53.79,0.323
99.54,53.95,0.323
99.56,54.09,0.324
99.57,54.24,0.324
99.59,54.40,0.324
99.60,54.55,0.324
99.62,54.70,0.324
99.63,54.85,0.324
99.65,55.00,0.324
99.66,55.15,0.324
99.68,55.30,0.324
99.69,55.45,0.325
99.71,55.60,0.325
99.72,55.75,0.325
99.74,55.90,0.325
99.75,56.05,0.325
99.77,56.20,0.325
99.78,56.35,0.325
99.80,56.50,0.325
99.81,56.65,0.325
99.83,56.80,0.325
99.84,56.95,0.326
99.86,57.10,0.326
99.87,57.25,0.326
99.89,57.40,0.326
99.90,57.55,0.326
99.92,57.70,0.326
99.93,57.85,0.326
99.95,58.00,0.326
99.96,58.15,0.326
99.98,58.30,0.326
99.99,58.45,0.326
100.01,58.60,0.327
100.02,58.75,0.327
100.04,58.90,0.327
100.05,59.05,0.327
100.07,59.20,0.327
100.08,59.35,0.327
100.10,59.50,0.327
100.11,59.65,0.327
100.13,59.80,0.327
100.14,59.95,0.327
100.16,60.10,0.328
100.17,60.25,0.328
100.19,60.40,0.328
100.20,60.55,0.328
100.22,60.70,0.328
100.23,60.85,0.328
100.25,61.00,0.328
100.26,61.15,0.328
100.28,61.30,0.328
100.29,61.45,0.328
100.31,61.60,0.328
100.32,61.75,0.329
100.34,61.90,0.329
100.35,62.05,0.329
100.37,62.20,0.329
100.38,62.35,0.329
100.40,62.50,0.329
100.41,62.65,0.329
100.43,62.80,0.329
100.44,62.95,0.329
100.46,63.10,0.329
100.47,63.26,0.329
100.49,63.41,0.330
100.50,63.56,0.330
100.52,63.71,0.330
100.53,63.86,0.330
100.55,64.01,0.330
100.56,64.16,0.330
100.58,64.31,0.330
100.59,64.46,0.330
100.61,64.61,0.330
100.62,64.76,0.330
100.64,64.91,0.331
100.65,65.06,0.331
100.67,65.21,0.331
100.68,65.36,0.331
100.70,65.51,0.331
100.71,65.66,0.331
100.73,65.81,0.331
100.74,65.96,0.331
100.76,66.11,0.331
100.77,66.26,0.331
100.79,66.41,0.331
100.80,66.56,0.331
100.82,66.71,0.332
100.83,66.86,0.332
100.85,67.01,0.332
100.86,67.16,0.332
100.88,67.31,0.332
100.89,67.46,0.332
100.91,67.61,0.332
100.92,67.76,0.332
100.94,67.91,0.332
100.95,68.06,0.332
100.97,68.21,0.332
100.98,68.36,0.332
101.00,68.51,0.332
101.01,68.66,0.333
101.03,68.81,0.333
101.04,68.96,0.333
101.06,69.11,0.333
101.07,69.26,0.333
101.09,69.41,0.333
101.10,69.56,0.333
101.12,69.71,0.333
101.13,69.86,0.333
101.15,70.01,0.334
101.16,70.16,0.334
101.18,70.31,0.334
101.19,70.46,0.334
101.21,70.61,0.334
101.22,70.76,0.334
101.24,70.91,0.334
101.25,71.06,0.334
101.27,71.21,0.334
101.28,71.36,0.334
101.30,71.51,0.335
101.31,71.66,0.335
101.33,71.81,0.335
101.34,71.96,0.335
101.36,72.11,0.335
101.37,72.26,0.335
101.39,72.41,0.335
101.40,72.56,0.335
101.42,72.71,0.335
101.43,72.86,0.335
101.45,73.01,0.336
101.46,73.16,0.336
101.48,73.31,0.336
101.49,73.46,0.336
101.51,73.61,0.336
101.52,73.76,0.336
101.54,73.91,0.336
101.55,74.07,0.336
101.57,74.21,0.336
101.58,74.37,0.337
101.60,74.52,0.337
101.61,74.67,0.337
101.63,74.82,0.337
101.64,74.97,0.337
101.66,75.12,0.337
101.67,75.27,0.337
101.69,75.42,0.337
101.70,75.57,0.337
101.72,75.72,0.337
101.73,75.87,0.338
101.75,76.02,0.338
101.76,76.17,0.338
101.78,76.32,0.338
101.79,76.47,0.338
101.81,76.62,0.338
101.82,76.77,0.338
101.84,76.92,0.338
101.85,77.07,0.338
101.87,77.22,0.338
101.88,77.37,0.339
101.90,77.52,0.339
101.91,77.67,0.339
101.93,77.82,0.339
101.94,77.97,0.339
101.96,78.12,0.339
101.97,78.27,0.339
101.99,78.42,0.339
102.00,78.57,0.339
102.02,78.72,0.339
102.03,78.87,0.339
102.05,79.02,0.339
102.06,79.17,0.340
102.08,79.32,0.340
102.09,79.47,0.340
102.11,79.62,0.340
102.12,79.77,0.340
102.14,79.92,0.340
102.15,80.07,0.340
102.17,80.22,0.340
102.18,80.37,0.340
102.20,80.52,0.341
102.21,80.67,0.341
102.23,80.82,0.341
102.24,80.97,0.341
102.26,81.12,0.341
102.27,81.27,0.341
102.29,81.42,0.341
102.30,81.57,0.341
102.32,81.72,0.341
102.33,81.87,0.341
102.35,82.02,0.341
102.36,82.17,0.341
102.38,82.32,0.341
102.39,82.47,0.341
102.41,82.62,0.342
102.42,82.77,0.342
102.44,82.92,0.342
102.45,83.07,0.342
102.47,83.22,0.342
102.48,83.37,0.342
102.50,83.52,0.342
102.51,83.67,0.342
102.53,83.82,0.342
102.54,83.97,0.343
102.56,84.13,0.343
102.57,84.27,0.343
102.59,84.43,0.343
102.60,84.58,0.343
102.62,84.73,0.343
102.63,84.88,0.343
102.65,85.03,0.343
102.66,85.18,0.343
102.68,85.33,0.343
102.69,85.48,0.343
102.71,85.63,0.343
102.72,85.78,0.343
102.74,85.93,0.343
102.75,86.08,0.343
102.77,86.23,0.343
102.78,86.38,0.343
102.80,86.53,0.344
102.81,86.68,0.344
102.83,86.83,0.344
102.84,86.98,0.344
102.86,87.13,0.344
102.87,87.28,0.344
102.89,87.43,0.344
102.90,87.58,0.344
102.92,87.73,0.344
102.93,87.88,0.344
102.95,88.03,0.344
102.96,88.18,0.344
102.98,88.33,0.344
102.99,88.48,0.344
103.01,88.63,0.344
103.02,88.78,0.345
103.04,88.93,0.345
103.05,89.08,0.345
103.07,89.23,0.345
103.08,89.38,0.345
103.10,89.53,0.345
103.11,89.68,0.345
103.13,89.83,0.346
103.14,89.98,0.346
103.16,90.13,0.346
103.17,90.28,0.346
103.19,90.43,0.346
103.20,90.58,0.346
103.22,90.73,0.347
103.23,90.88,0.347
103.25,91.03,0.347
103.26,91.18,0.347
103.28,91.33,0.347
103.29,91.48,0.348
103.31,91.63,0.348
103.32,91.78,0.348
103.34,91.93,0.348
103.35,92.08,0.348
103.37,92.23,0.348
103.38,92.38,0.349
103.40,92.53,0.349
103.41,92.68,0.349
103.43,92.83,0.349
103.44,92.98,0.349
103.46,93.13,0.349
103.47,93.28,0.349
103.49,93.43,0.350
103.50,93.58,0.350
103.52,93.73,0.350
103.53,93.88,0.350
103.55,94.03,0.350
103.56,94.18,0.350
103.58,94.33,0.350
103.59,94.48,0.351
103.61,94.63,0.351
103.62,94.78,0.351
103.64,94.93,0.351
103.65,95.08,0.351
103.67,95.23,0.351
103.68,95.39,0.351
103.70,95.53,0.351
103.71,95.69,0.352
103.73,95.84,0.352
103.74,95.99,0.352
103.76,96.13,0.352
103.77,96.29,0.352
103.79,96.44,0.352
103.80,96.59,0.352
103.82,96.74,0.352
103.83,96.89,0.352
103.85,97.04,0.353
103.86,97.19,0.353
103.88,97.34,0.353
103.89,97.49,0.353
103.91,97.64,0.353
103.92,97.79,0.353
103.94,97.94,0.353
103.95,98.09,0.354
103.97,98.24,0.354
103.98,98.39,0.354
104.00,98.54,0.354
104.01,98.69,0.354
104.03,98.84,0.354
104.04,98.99,0.354
104.06,99.14,0.354
104.07,99.29,0.355
104.09,99.44,0.355
104.10,99.59,0.355
104.12,99.74,0.355
104.13,99.89,0.355
104.15,100.04,0.355
104.16,100.19,0.355
104.18,100.34,0.355
104.19,100.49,0.356
104.21,100.64,0.356
104.22,100.79,0.356
104.24,100.94,0.356
104.25,101.09,0.356
104.27,101.24,0.356
104.28,101.39,0.356
104.30,101.54,0.356
104.31,101.69,0.356
104.33,101.84,0.356
104.34,101.99,0.356
104.36,102.14,0.356
104.37,102.29,0.356
104.39,102.44,0.357
104.40,102.59,0.357
104.42,102.74,0.357
104.43,102.89,0.357
104.45,103.04,0.357
104.46,103.19,0.357
104.48,103.34,0.357
104.49,103.49,0.357
104.51,103.64,0.357
104.52,103.79,0.357
104.54,103.94,0.358
104.55,104.09,0.358
104.57,104.24,0.358
104.58,104.39,0.358
104.60,104.54,0.358
104.61,104.69,0.358
104.63,104.84,0.358
104.64,104.99,0.358
104.66,105.14,0.359
104.67,105.29,0.359
104.69,105.44,0.359
104.70,105.59,0.359
104.72,105.75,0.359
104.73,105.90,0.359
104.75,106.05,0.359
104.76,106.19,0.359
104.78,106.35,0.359
104.79,106.50,0.359
104.81,106.65,0.359
104.82,106.80,0.360
104.84,106.95,0.360
104.85,107.10,0.360
104.87,107.25,0.360
104.88,107.40,0.360
104.90,107.55,0.360
104.91,107.70,0.360
104.93,107.85,0.360
104.94,108.00,0.360
104.96,108.15,0.360
104.97,108.30,0.360
104.99,108.45,0.361
105.00,108.60,0.361
105.02,108.75,0.361
105.03,108.90,0.361
105.05,109.05,0.361
105.06,109.20,0.361
105.08,109.35,0.361
105.09,109.50,0.361
105.11,109.65,0.361
105.12,109.80,0.361
105.14,109.95,0.361
105.15,110.10,0.361
105.17,110.25,0.362
105.18,110.40,0.362
105.20,110.55,0.362
105.21,110.70,0.362
105.23,110.85,0.362
105.24,111.00,0.362
105.26,111.15,0.362
105.27,111.30,0.362
105.29,111.45,0.362
105.30,111.60,0.362
105.32,111.75,0.363
105.33,111.90,0.363
105.35,112.05,0.363
105.36,112.20,0.363
105.38,112.35,0.363
105.39,112.50,0.363
105.41,112.65,0.363
105.42,112.80,0.363
105.44,112.95,0.364
105.45,113.10,0.364
105.47,113.25,0.364
105.48,113.40,0.364
105.50,113.55,0.364
105.51,113.70,0.364
105.53,113.85,0.364
105.54,114.00,0.364
105.56,114.15,0.364
105.57,114.30,0.365
105.59,114.45,0.365
105.60,114.60,0.365
105.62,114.75,0.365
105.63,114.90,0.365
105.65,115.05,0.365
105.66,115.20,0.365
105.68,115.35,0.365
105.69,115.50,0.365
105.71,115.65,0.365
105.72,115.80,0.366
105.74,115.95,0.366
105.75,116.10,0.366
105.77,116.25,0.366
105.78,116.40,0.366
105.80,116.55,0.366
105.81,116.70,0.366
105.83,116.85,0.366
105.84,117.00,0.366
105.86,117.15,0.367
105.87,117.30,0.367
105.89,117.46,0.367
105.90,117.61,0.367
105.92,117.76,0.367
105.93,117.91,0.367
105.95,118.06,0.367
105.96,118.21,0.367
105.98,118.36,0.367
105.99,118.51,0.368
106.01,118.66,0.368
106.02,118.81,0.368
106.04,118.96,0.368
106.05,119.11,0.368
106.07,119.26,0.368
106.08,119.41,0.368
106.10,119.56,0.368
106.11,119.71,0.368
106.13,119.86,0.368
106.14,120.01,0.368
106.16,120.16,0.368
106.17,120.31,0.368
106.19,120.46,0.368
106.20,120.61,0.368
106.22,120.76,0.368
106.23,120.91,0.368
106.25,121.06,0.368
106.26,121.21,0.368
106.28,121.36,0.368
106.29,121.51,0.368
106.31,121.66,0.368
106.32,121.81,0.368
106.34,121.96,0.368
106.35,122.11,0.368
106.37,122.26,0.368
106.38,122.41,0.368
106.40,122.56,0.369
106.41,122.71,0.369
106.43,122.86,0.369
106.44,123.01,0.369
106.46,123.16,0.369
106.47,123.31,0.369
106.49,123.46,0.369
106.50,123.61,0.369
106.52,123.76,0.369
106.53,123.91,0.369
106.55,124.06,0.369
106.56,124.21,0.369
106.58,124.36,0.369
106.59,124.51,0.369
106.61,124.66,0.369
106.62,124.81,0.370
106.64,124.96,0.370
106.65,125.11,0.370
106.67,125.26,0.370
106.68,125.41,0.370
106.70,125.56,0.370
106.71,125.71,0.370
106.73,125.86,0.370
106.74,126.01,0.370
106.76,126.16,0.370
106.77,126.31,0.370
106.79,126.46,0.371
106.80,126.61,0.371
106.82,126.76,0.371
106.83,126.91,0.371
106.85,127.06,0.371
106.86,127.21,0.371
106.88,127.36,0.371
106.89,127.51,0.371
106.91,127.66,0.371
106.92,127.81,0.371
106.94,127.96,0.371
106.95,128.11,0.371
106.97,128.26,0.371
106.98,128.41,0.372
107.00,128.56,0.372
107.01,128.71,0.372
107.03,128.86,0.372
107.04,129.01,0.372
107.06,129.16,0.372
107.07,129.31,0.372
107.09,129.46,0.372
107.10,129.61,0.372
107.12,129.76,0.372
107.13,129.91,0.373
107.15,130.06,0.373
107.16,130.21,0.373
107.18,130.36,0.373
107.19,130.51,0.373
107.21,130.66,0.373
107.22,130.81,0.373
107.24,130.96,0.373
107.25,131.11,0.373
107.27,131.26,0.373
107.28,131.41,0.374
107.30,131.56,0.374
107.31,131.71,0.374
107.33,131.86,0.374
107.34,132.01,0.374
107.36,132.16,0.374
107.37,132.31,0.374
107.39,132.46,0.374
107.40,132.62,0.374
107.42,132.77,0.374
107.43,132.92,0.374
107.45,133.07,0.375
107.46,133.22,0.375
107.48,133.37,0.375
107.49,133.52,0.375
107.51,133.67,0.375
107.52,133.82,0.375
107.54,133.97,0.375
107.55,134.12,0.375
107.57,134.27,0.375
107.58,134.42,0.375
107.60,134.57,0.375
107.61,134.72,0.375
107.63,134.87,0.375
107.64,135.02,0.376
107.66,135.17,0.376
107.67,135.32,0.376
107.69,135.47,0.376
107.70,135.62,0.376
107.72,135.77,0.376
107.73,135.92,0.376
107.75,136.07,0.376
107.76,136.22,0.376
107.78,136.37,0.376
107.79,136.52,0.376
107.81,136.67,0.376
107.82,136.82,0.376
107.84,136.97,0.376
107.85,137.12,0.376
107.87,137.27,0.377
107.88,137.42,0.377
107.90,137.57,0.377
107.91,137.72,0.377
107.93,137.87,0.377
107.94,138.02,0.377
107.96,138.17,0.377
107.97,138.32,0.377
107.99,138.47,0.377
108.00,138.62,0.377
108.02,138.77,0.377
108.03,138.92,0.377
108.05,139.07,0.377
108.06,139.22,0.378
108.08,139.37,0.378
108.09,139.52,0.378
108.11,139.67,0.378
108.12,139.82,0.378
108.14,139.97,0.378
108.15,140.12,0.378
108.17,140.27,0.378
108.18,140.42,0.378
108.20,140.57,0.378
108.21,140.72,0.378
108.23,140.87,0.378
108.24,141.02,0.379
108.26,141.17,0.379
108.27,141.32,0.379
108.29,141.47,0.379
108.30,141.62,0.379
108.32,141.77,0.379
108.33,141.92,0.379
108.35,142.07,0.379
108.36,142.22,0.379
108.38,142.37,0.379
108.39,142.52,0.379
108.41,142.67,0.379
108.42,142.82,0.379
108.44,142.97,0.380
108.45,143.12,0.380
108.47,143.27,0.380
108.48,143.42,0.380
108.50,143.57,0.380
108.51,143.72,0.380
108.53,143.87,0.380
108.54,144.02,0.380
108.56,144.17,0.380
108.57,144.32,0.380
108.59,144.47,0.380
108.60,144.62,0.380
108.62,144.77,0.380
108.63,144.92,0.381
108.65,145.07,0.381
108.66,145.22,0.381
108.68,145.37,0.381
108.69,145.52,0.381
108.71,145.67,0.381
108.72,145.82,0.381
108.74,145.97,0.381
108.75,146.12,0.381
108.77,146.27,0.381
108.78,146.42,0.381
108.80,146.57,0.381
108.81,146.72,0.381
108.83,146.87,0.382
108.84,147.03,0.382
108.86,147.18,0.382
108.87,147.33,0.382
108.89,147.48,0.382
108.90,147.63,0.382
108.92,147.78,0.382
108.93,147.93,0.382
108.95,148.08,
108.96,148.23,
108.98,148.38,
108.99,,