File: DSC/2025_04_20_Empty_Open_Pans_n60C_200C_10Cmin_x3.csv
Filename,2025_04_20_Empty_Open_Pans_n60C_200C_10Cmin_x3
Instrument name,DSC2A-00468 (192.168.1.100)
Operator,Yarger
rundate,4/21/2025
Sample name,2025_04_20_Empty_Open_Pans_n60C_200C_10Cmin_x3
proceduresegments,Data Off ; Equilibrate -60.00 °C; Data On ; Ramp 10.00 °C/min to 200.00 °C; Data Off ; Isothermal 1.0 min; Data On ; Ramp 10.00 °C/min to -60.00 °C; Data Off ; Isothermal 1.0 min; Data On ; Ramp 10.00 °C/min to 200.00 °C; Data Off ; Isothermal 1.0 min; Data On ; Ramp 10.00 °C/min to -60.00 °C; Data Off ; Isothermal 1.0 min; Data On ; Ramp 10.00 °C/min to 200.00 °C
[File Parameters]
Run date,4/21/2025 1:49:56 AM
Trios version,5.1.1.46572
Original File Name,
Current File Name,D:\DSC2500\JYarger\2025_04_20_Empty_Open_Pans_n60C_200C_10Cmin_x3.tri
[Procedure]
Procedure Name,Open_Empty_n60_200C_10Cmin_x3
Sample Name,2025_04_20_Empty_Open_Pans_n60C_200C_10Cmin_x3
Sample Mass,0 mg
Reference Sample Mass,0 mg
Pan Mass,25.95 mg
Pan Number,31
Reference Pan Mass,25.8 mg
Reference Pan Number,28
Pan Type,Tzero Aluminum
Comments,"Al Pan/Lid, Not sealed."
Project Name,CA
Operator,Yarger
Test,Custom
Unload Max Temperature,30
Unload Min Temperature,30
Load Max Temperature,30
Load Min Temperature,30
Stop on Gas Flow Error,Yes
[Signal List]
Signal #1,Time (min)
Signal #2,Temperature (°C)
Signal #3,Heat Flow (mW)
Signal #4,Delta T (µV)
Signal #5,Delta Tzero (µV)
Signal #6,Tzero Temperature (°C)
Signal #7,Cell Purge (mL/min)
Signal #8,Heater Temp (°C)
Signal #9,Power Delivered (W)
Signal #10,Reference Junction Temperature (°C)
Signal #11,Flange Temperature (°C)
Signal #12,Heat Flow Phase (rad)
Signal #13,Total Heat Capacity (J/°C)
Signal #14,Heat Capacity (J/°C)
[Configuration]
Company Name,ASU
Instrument Name,DSC2A-00468
Instrument Type,DSC2500
Serial Number,DSC2A-00468
IP,192.168.1.100
Location of Instrument,MRRC
DisplayType,Unknown
Sample Interval ,0.1 s/pt
Selected Heat Flow,T4P
Exotherm Direction,Down
Cell Serial,DRC2-00792
Lid Type,Standard
Cooler,RCS 90
Leave Cooler on at End of Sequence,On
Gas 2,Nitrogen
Gas Selected,Channel 1
Flow Rate,50 mL/min
Secondary Purge,On
Licensed Heat Flow,Heat Flow T4P
Modulation Licensed,Yes
[Versions]
Common IDD Version,1
Cortex Version,VER 2.10.2.31
Driver,5.0.0.6
GDM Version,1.0.3.3
TouchscreenVersion,1.0.0.16145
FEP Version,1.2.1.21
FEP Bootloader,2.0.0.5
AutoSampler Version,2.1.1.26
Auto Sampler Bootloader,2.0.0.5
FCM Version,1.1.0.3
FCM Bootloader,2.0.0.5
[Experiment Logs]
Experiment Log Entry # 1,Data On set to 0
Experiment Log Entry # 3,Equilibrate Segment -60 (C) Started
Experiment Log Entry # 5,Air Cool is off.
Experiment Log Entry # 7,Data On set to 1
Experiment Log Entry # 9,Ramp Segment 10 C/min to 200 Started
Experiment Log Entry # 11,Data On set to 0
Experiment Log Entry # 13,Isothermal Segment 1 min started
Experiment Log Entry # 15,Data On set to 1
Experiment Log Entry # 17,Ramp Segment 10 C/min to -60 Started
Experiment Log Entry # 19,Data On set to 0
Experiment Log Entry # 21,Isothermal Segment 1 min started
Experiment Log Entry # 23,Data On set to 1
Experiment Log Entry # 25,Ramp Segment 10 C/min to 200 Started
Experiment Log Entry # 27,Data On set to 0
Experiment Log Entry # 29,Isothermal Segment 1 min started
Experiment Log Entry # 31,Data On set to 1
Experiment Log Entry # 33,Ramp Segment 10 C/min to -60 Started
Experiment Log Entry # 35,Data On set to 0
Experiment Log Entry # 37,Isothermal Segment 1 min started
Experiment Log Entry # 39,Data On set to 1
Experiment Log Entry # 41,Ramp Segment 10 C/min to 200 Started
[Method Log]
Method Log Entry # 1,Data Off
Method Log Entry # 2,Equilibrate -60 °C
Method Log Entry # 3,Data On
Method Log Entry # 4,(Ramp 684467) Ramp 10 °C/minute to 200 °C
Method Log Entry # 5,Data Off
Method Log Entry # 6,Isothermal 1 minutes
Method Log Entry # 7,Data On
Method Log Entry # 8,(Ramp 684471) Ramp 10 °C/minute to -60 °C
Method Log Entry # 9,Data Off
Method Log Entry # 10,Isothermal 1 minutes
Method Log Entry # 11,Data On
Method Log Entry # 12,(Ramp 684475) Ramp 10 °C/minute to 200 °C
Method Log Entry # 13,Data Off
Method Log Entry # 14,Isothermal 1 minutes
Method Log Entry # 15,Data On
Method Log Entry # 16,(Ramp 684479) Ramp 10 °C/minute to -60 °C
Method Log Entry # 17,Data Off
Method Log Entry # 18,Isothermal 1 minutes
Method Log Entry # 19,Data On
Method Log Entry # 20,(Ramp 684483) Ramp 10 °C/minute to 200 °C
Cell Serial,DRC2-00792
[T1 Calibration]
Slope,-0.008529666
Offset,9.636258
Initial Temperature,98.23
GUID,f8bfdadc-4977-4fdf-ba6d-0ba9134940c3
[TZero Calibration]
Date Applied,11/29/2022 4:06:13 PM
Description,From -89.059 °C to 396.009 °C at 20.000°C/min
Gas Type,Nitrogen
Pan Type,None
Source Files 1,C:\Users\yargerlab\Desktop\DSC Data\General\TZero_calibration_11_29_22_2nd(2).tri
Source Files 2,C:\Users\yargerlab\Desktop\DSC Data\General\TZero_calibration_11_29_22_2nd(3).tri
Delta T Offset,13.05235
Delta T Slope,-0.007271007
Delta T0 Offset,-13.69128
Delta T0 Slope,0.06063341
[Temperature Calibration]
Date Applied,11/29/2022 7:12:28 PM
Description,From 106.590 °C to 186.590 °C at 10.000°C/min
Gas Type,Nitrogen
Pan Type,Tzero Aluminum Hermetic
Source Files 1,C:\Users\yargerlab\Desktop\DSC Data\General\Indium(6).tri
Measured 1,157.391
Known 1,156.598
[Cell Constant Calibration]
Date Applied,11/29/2022 7:12:29 PM
Description,From 106.590 °C to 186.590 °C at 10.000°C/min
Gas Type,Nitrogen
Pan Type,Tzero Aluminum Hermetic
Source Files 1,C:\Users\yargerlab\Desktop\DSC Data\General\Indium(6).tri
T4P KCell,1.006051
Onset Slope,63.26126 mW/°C
[Direct Cp Calibration]
Date Applied,11/30/2022 11:04:51 AM
Description,From -79.983 °C to 298.409 °C at 10.000°C/min
Gas Type,Nitrogen
Pan Type,Tzero Aluminum Hermetic
Source Files 1,C:\Users\yargerlab\Desktop\DSC Data\General\Sapphire_Heat_Capacity_11_30_22.tri
[Rev Cp Calibration]
Date Applied,11/30/2022 1:58:51 PM
Description,From -79.996 °C to 292.812 °C at 3.000°C/min
Gas Type,Nitrogen
Pan Type,Tzero Aluminum Hermetic
Source Files 1,C:\Users\yargerlab\Desktop\DSC Data\General\Sapphire_MDSC_Calibration_11_30_22.tri
[step]
Ramp 10.00 °C/min to 200.00 °C
Time,Temperature,Heat Flow (Normalized)
min,°C,W/g
0.00,-59.80,
0.02,-59.81,
0.04,-59.81,
0.05,-59.80,
0.07,-59.76,
0.09,-59.70,
0.11,-59.62,
0.13,-59.51,
0.15,-59.38,
0.16,-59.23,
0.18,-59.07,
0.20,-58.91,
0.22,-58.73,
0.24,-58.56,
0.26,-58.38,
0.28,-58.20,
0.29,-58.03,
0.31,-57.85,
0.33,-57.67,
0.35,-57.49,
0.37,-57.31,
0.39,-57.14,
0.40,-56.96,
0.42,-56.78,
0.44,-56.60,
0.46,-56.42,
0.48,-56.24,
0.50,-56.06,
0.51,-55.88,
0.53,-55.70,
0.55,-55.52,
0.57,-55.34,
0.59,-55.16,
0.60,-54.98,
0.62,-54.80,
0.64,-54.62,
0.66,-54.44,
0.68,-54.26,
0.70,-54.08,
0.72,-53.89,
0.73,-53.71,
0.75,-53.53,
0.77,-53.35,
0.79,-53.17,
0.81,-52.99,
0.83,-52.81,
0.84,-52.62,
0.86,-52.44,
0.88,-52.26,
0.90,-52.08,
0.92,-51.90,
0.93,-51.72,
0.95,-51.54,
0.97,-51.35,
0.99,-51.17,
1.01,-50.99,
1.03,-50.81,
1.05,-50.63,
1.06,-50.44,
1.08,-50.26,
1.10,-50.08,
1.12,-49.90,
1.14,-49.71,
1.16,-49.53,
1.17,-49.35,
1.19,-49.16,
1.21,-48.98,
1.23,-48.80,
1.25,-48.62,
1.27,-48.43,
1.28,-48.25,
1.30,-48.07,
1.32,-47.89,
1.34,-47.70,
1.36,-47.52,
1.38,-47.34,
1.39,-47.15,
1.41,-46.97,
1.43,-46.79,
1.45,-46.60,
1.47,-46.42,
1.48,-46.24,
1.50,-46.06,
1.52,-45.87,
1.54,-45.69,
1.56,-45.50,
1.58,-45.32,
1.59,-45.14,
1.61,-44.96,
1.63,-44.77,
1.65,-44.59,
1.67,-44.41,
1.69,-44.22,
1.71,-44.04,
1.72,-43.86,
1.74,-43.67,
1.76,-43.49,
1.78,-43.31,
1.80,-43.12,
1.82,-42.94,
1.83,-42.76,
1.85,-42.57,
1.87,-42.39,
1.89,-42.21,
1.91,-42.02,
1.93,-41.84,
1.94,-41.66,
1.96,-41.47,
1.98,-41.29,
2.00,-41.10,
2.02,-40.92,
2.03,-40.74,
2.05,-40.55,
2.07,-40.37,
2.09,-40.19,
2.11,-40.00,
2.13,-39.82,
2.14,-39.64,
2.16,-39.45,
2.18,-39.27,
2.20,-39.08,
2.22,-38.90,
2.24,-38.72,
2.26,-38.54,
2.27,-38.35,
2.29,-38.17,
2.31,-37.99,
2.33,-37.80,
2.35,-37.62,
2.36,-37.43,
2.38,-37.25,
2.40,-37.07,
2.42,-36.88,
2.44,-36.70,
2.46,-36.52,
2.48,-36.33,
2.49,-36.15,
2.51,-35.97,
2.53,-35.78,
2.55,-35.60,
2.57,-35.41,
2.59,-35.23,
2.60,-35.05,
2.62,-34.86,
2.64,-34.68,
2.66,-34.50,
2.68,-34.31,
2.69,-34.13,
2.71,-33.95,
2.73,-33.76,
2.75,-33.58,
2.77,-33.39,
2.79,-33.21,
2.81,-33.03,
2.82,-32.84,
2.84,-32.66,
2.86,-32.48,
2.88,-32.29,
2.90,-32.11,
2.91,-31.93,
2.93,-31.74,
2.95,-31.56,
2.97,-31.38,
2.99,-31.19,
3.01,-31.01,
3.03,-30.83,
3.04,-30.64,
3.06,-30.46,
3.08,-30.27,
3.10,-30.09,
3.12,-29.91,
3.14,-29.72,
3.15,-29.54,
3.17,-29.36,
3.19,-29.17,
3.21,-28.99,
3.23,-28.80,
3.24,-28.62,
3.26,-28.44,
3.28,-28.25,
3.30,-28.07,
3.32,-27.89,
3.34,-27.70,
3.36,-27.52,
3.37,-27.34,
3.39,-27.15,
3.41,-26.97,
3.43,-26.79,
3.45,-26.60,
3.46,-26.42,
3.48,-26.24,
3.50,-26.05,
3.52,-25.87,
3.54,-25.68,
3.56,-25.50,
3.58,-25.32,
3.59,-25.13,
3.61,-24.95,
3.63,-24.77,
3.65,-24.58,
3.67,-24.40,
3.69,-24.22,
3.70,-24.03,
3.72,-23.85,
3.74,-23.67,
3.76,-23.48,
3.78,-23.30,
3.79,-23.11,
3.81,-22.93,
3.83,-22.75,
3.85,-22.56,
3.87,-22.38,
3.89,-22.20,
3.91,-22.01,
3.92,-21.83,
3.94,-21.65,
3.96,-21.46,
3.98,-21.28,
4.00,-21.10,
4.01,-20.91,
4.03,-20.73,
4.05,-20.55,
4.07,-20.36,
4.09,-20.18,
4.11,-19.99,
4.13,-19.81,
4.14,-19.63,
4.16,-19.44,
4.18,-19.26,
4.20,-19.08,
4.22,-18.89,
4.24,-18.71,
4.25,-18.53,
4.27,-18.34,
4.29,-18.16,
4.31,-17.98,
4.33,-17.79,
4.35,-17.61,
4.36,-17.42,
4.38,-17.24,
4.40,-17.06,
4.42,-16.87,
4.44,-16.69,
4.45,-16.51,
4.47,-16.32,
4.49,-16.14,
4.51,-15.96,
4.53,-15.77,
4.55,-15.59,
4.56,-15.41,
4.58,-15.22,
4.60,-15.04,
4.62,-14.86,
4.64,-14.67,
4.66,-14.49,
4.68,-14.30,
4.69,-14.12,
4.71,-13.94,
4.73,-13.75,
4.75,-13.57,
4.77,-13.39,
4.79,-13.20,
4.80,-13.02,
4.82,-12.84,
4.84,-12.65,
4.86,-12.47,
4.88,-12.29,
4.90,-12.10,
4.91,-11.92,
4.93,-11.73,
4.95,-11.55,
4.97,-11.37,
4.99,-11.18,
5.00,-11.00,
5.02,-10.82,
5.04,-10.64,
5.06,-10.45,
5.08,-10.27,
5.10,-10.08,
5.11,-9.90,
5.13,-9.71,
5.15,-9.53,
5.17,-9.35,
5.19,-9.17,
5.21,-8.98,
5.23,-8.80,
5.24,-8.61,
5.26,-8.43,
5.28,-8.25,
5.30,-8.06,
5.32,-7.88,
5.34,-7.70,
5.35,-7.51,
5.37,-7.33,
5.39,-7.15,
5.41,-6.96,
5.43,-6.78,
5.45,-6.60,
5.46,-6.41,
5.48,-6.23,
5.50,-6.05,
5.52,-5.86,
5.54,-5.68,
5.55,-5.49,
5.57,-5.31,
5.59,-5.13,
5.61,-4.94,
5.63,-4.76,
5.65,-4.58,
5.66,-4.39,
5.68,-4.21,
5.70,-4.03,
5.72,-3.84,
5.74,-3.66,
5.76,-3.48,
5.78,-3.29,
5.79,-3.11,
5.81,-2.92,
5.83,-2.74,
5.85,-2.56,
5.87,-2.37,
5.89,-2.19,
5.90,-2.01,
5.92,-1.82,
5.94,-1.64,
5.96,-1.46,
5.98,-1.27,
6.00,-1.09,
6.01,-0.91,
6.03,-0.72,
6.05,-0.54,
6.07,-0.36,
6.09,-0.17,
6.10,0.01,
6.12,0.20,
6.14,0.38,
6.16,0.56,
6.18,0.75,
6.20,0.93,
6.21,1.11,
6.23,1.30,
6.25,1.48,
6.27,1.66,
6.29,1.85,
6.31,2.03,
6.33,2.21,
6.34,2.40,
6.36,2.58,
6.38,2.77,
6.40,2.95,
6.42,3.13,
6.44,3.32,
6.45,3.50,
6.47,3.68,
6.49,3.87,
6.51,4.05,
6.53,4.23,
6.55,4.42,
6.56,4.60,
6.58,4.78,
6.60,4.97,
6.62,5.15,
6.64,5.33,
6.65,5.52,
6.67,5.70,
6.69,5.88,
6.71,6.07,
6.73,6.25,
6.75,6.44,
6.76,6.62,
6.78,6.80,
6.80,6.99,
6.82,7.17,
6.84,7.35,
6.86,7.54,
6.88,7.72,
6.89,7.90,
6.91,8.09,
6.93,8.27,
6.95,8.46,
6.97,8.64,
6.99,8.82,
7.00,9.01,
7.02,9.19,
7.04,9.37,
7.06,9.56,
7.08,9.74,
7.10,9.92,
7.11,10.11,
7.13,10.29,
7.15,10.47,
7.17,10.65,
7.19,10.84,
7.20,11.02,
7.22,11.20,
7.24,11.39,
7.26,11.57,
7.28,11.76,
7.30,11.94,
7.31,12.12,
7.33,12.31,
7.35,12.49,
7.37,12.67,
7.39,12.86,
7.41,13.04,
7.43,13.22,
7.44,13.41,
7.46,13.59,
7.48,13.77,
7.50,13.96,
7.52,14.14,
7.54,14.33,
7.55,14.51,
7.57,14.69,
7.59,14.88,
7.61,15.06,
7.63,15.24,
7.65,15.43,
7.66,15.61,
7.68,15.79,
7.70,15.98,
7.72,16.16,
7.74,16.35,
7.75,16.53,
7.77,16.71,
7.79,16.90,
7.81,17.08,
7.83,17.26,
7.85,17.45,
7.86,17.63,
7.88,17.81,
7.90,18.00,
7.92,18.18,
7.94,18.36,
7.96,18.55,
7.98,18.73,
7.99,18.91,
8.01,19.10,
8.03,19.28,
8.05,19.46,
8.07,19.65,
8.09,19.83,
8.10,20.02,
8.12,20.20,
8.14,20.38,
8.16,20.57,
8.18,20.75,
8.20,20.93,
8.21,21.12,
8.23,21.30,
8.25,21.48,
8.27,21.67,
8.29,21.85,
8.30,22.03,
8.32,22.22,
8.34,22.40,
8.36,22.58,
8.38,22.77,
8.40,22.95,
8.41,23.14,
8.43,23.32,
8.45,23.50,
8.47,23.69,
8.49,23.87,
8.51,24.05,
8.53,24.24,
8.54,24.42,
8.56,24.60,
8.58,24.79,
8.60,24.97,
8.62,25.15,
8.63,25.34,
8.65,25.52,
8.67,25.71,
8.69,25.89,
8.71,26.07,
8.73,26.26,
8.75,26.44,
8.76,26.62,
8.78,26.81,
8.80,26.99,
8.82,27.17,
8.84,27.36,
8.85,27.54,
8.87,27.72,
8.89,27.91,
8.91,28.09,
8.93,28.27,
8.95,28.46,
8.97,28.64,
8.98,28.83,
9.00,29.01,
9.02,29.19,
9.04,29.38,
9.06,29.56,
9.08,29.74,
9.09,29.93,
9.11,30.11,
9.13,30.29,
9.15,30.48,
9.17,30.66,
9.18,30.84,
9.20,31.03,
9.22,31.21,
9.24,31.39,
9.26,31.58,
9.28,31.76,
9.30,31.95,
9.31,32.13,
9.33,32.31,
9.35,32.50,
9.37,32.68,
9.39,32.86,
9.40,33.05,
9.42,33.23,
9.44,33.41,
9.46,33.60,
9.48,33.78,
9.50,33.96,
9.52,34.15,
9.53,34.33,
9.55,34.51,
9.57,34.70,
9.59,34.88,
9.61,35.06,
9.63,35.25,
9.64,35.43,
9.66,35.61,
9.68,35.80,
9.70,35.98,
9.72,36.17,
9.73,36.35,
9.75,36.53,
9.77,36.72,
9.79,36.90,
9.81,37.08,
9.83,37.27,
9.85,37.45,
9.86,37.63,
9.88,37.82,
9.90,38.00,
9.92,38.18,
9.94,38.37,
9.95,38.55,
9.97,38.73,
9.99,38.92,
10.01,39.10,
10.03,39.29,
10.05,39.47,
10.07,39.65,
10.08,39.84,
10.10,40.02,
10.12,40.20,
10.14,40.39,
10.16,40.57,
10.18,40.75,
10.19,40.94,
10.21,41.12,
10.23,41.30,
10.25,41.49,
10.27,41.67,
10.28,41.85,
10.30,42.04,
10.32,42.22,
10.34,42.41,
10.36,42.59,
10.38,42.77,
10.40,42.95,
10.41,43.14,
10.43,43.32,
10.45,43.51,
10.47,43.69,
10.49,43.87,
10.50,44.06,
10.52,44.24,
10.54,44.42,
10.56,44.61,
10.58,44.79,
10.60,44.97,
10.62,45.16,
10.63,45.34,
10.65,45.52,
10.67,45.71,
10.69,45.89,
10.71,46.07,
10.73,46.26,
10.74,46.44,
10.76,46.63,
10.78,46.81,
10.80,46.99,
10.82,47.18,
10.83,47.36,
10.85,47.54,
10.87,47.73,
10.89,47.91,
10.91,48.09,
10.93,48.28,
10.95,48.46,
10.96,48.64,
10.98,48.83,
11.00,49.01,
11.02,49.19,
11.04,49.38,
11.05,49.56,
11.07,49.74,
11.09,49.93,
11.11,50.11,
11.13,50.30,
11.15,50.48,
11.17,50.66,
11.18,50.85,
11.20,51.03,
11.22,51.21,
11.24,51.40,
11.26,51.58,
11.28,51.76,
11.29,51.95,
11.31,52.13,
11.33,52.31,
11.35,52.50,
11.37,52.68,
11.38,52.86,
11.40,53.05,
11.42,53.23,
11.44,53.41,
11.46,53.60,
11.48,53.78,
11.50,53.97,
11.51,54.15,
11.53,54.33,
11.55,54.52,
11.57,54.70,
11.59,54.88,
11.60,55.07,
11.62,55.25,
11.64,55.43,
11.66,55.62,
11.68,55.80,
11.70,55.98,
11.72,56.17,
11.73,56.35,
11.75,56.53,
11.77,56.72,
11.79,56.90,
11.81,57.08,
11.83,57.27,
11.84,57.45,
11.86,57.64,
11.88,57.82,
11.90,58.00,
11.92,58.19,
11.93,58.37,
11.95,58.55,
11.97,58.74,
11.99,58.92,
12.01,59.10,
12.03,59.29,
12.05,59.47,
12.06,59.65,
12.08,59.84,
12.10,60.02,
12.12,60.20,
12.14,60.39,
12.15,60.57,
12.17,60.76,
12.19,60.94,
12.21,61.12,
12.23,61.31,
12.25,61.49,
12.27,61.67,
12.28,61.86,
12.30,62.04,
12.32,62.22,
12.34,62.41,
12.36,62.59,
12.38,62.77,
12.39,62.96,
12.41,63.14,
12.43,63.32,
12.45,63.51,
12.47,63.69,
12.48,63.88,
12.50,64.06,
12.52,64.24,
12.54,64.43,
12.56,64.61,
12.58,64.79,
12.60,64.98,
12.61,65.16,
12.63,65.34,
12.65,65.53,
12.67,65.71,
12.69,65.89,
12.70,66.08,
12.72,66.26,
12.74,66.44,
12.76,66.63,
12.78,66.81,
12.80,66.99,
12.82,67.18,
12.83,67.36,
12.85,67.54,
12.87,67.73,
12.89,67.91,
12.91,68.10,
12.93,68.28,
12.94,68.46,
12.96,68.65,
12.98,68.83,
13.00,69.01,
13.02,69.20,
13.03,69.38,
13.05,69.56,
13.07,69.75,
13.09,69.93,
13.11,70.11,
13.13,70.30,
13.15,70.48,
13.16,70.66,
13.18,70.85,
13.20,71.03,
13.22,71.21,
13.24,71.40,
13.25,71.58,
13.27,71.76,
13.29,71.95,
13.31,72.13,
13.33,72.31,
13.35,72.50,
13.37,72.68,
13.38,72.86,
13.40,73.05,
13.42,73.23,
13.44,73.42,
13.46,73.60,
13.48,73.78,
13.49,73.97,
13.51,74.15,
13.53,74.33,
13.55,74.52,
13.57,74.70,
13.58,74.88,
13.60,75.07,
13.62,75.25,
13.64,75.43,
13.66,75.62,
13.68,75.80,
13.70,75.98,
13.71,76.17,
13.73,76.35,
13.75,76.54,
13.77,76.72,
13.79,76.90,
13.80,77.08,
13.82,77.27,
13.84,77.45,
13.86,77.63,
13.88,77.82,
13.90,78.00,
13.92,78.19,
13.93,78.37,
13.95,78.55,
13.97,78.74,
13.99,78.92,
14.01,79.10,
14.03,79.29,
14.04,79.47,
14.06,79.65,
14.08,79.84,
14.10,80.02,
14.12,80.20,
14.13,80.39,
14.15,80.57,
14.17,80.75,
14.19,80.94,
14.21,81.12,
14.23,81.31,
14.25,81.49,
14.26,81.67,
14.28,81.86,
14.30,82.04,
14.32,82.22,
14.34,82.41,
14.35,82.59,
14.37,82.77,
14.39,82.96,
14.41,83.14,
14.43,83.32,
14.45,83.51,
14.47,83.69,
14.48,83.87,
14.50,84.06,
14.52,84.24,
14.54,84.43,
14.56,84.61,
14.58,84.79,
14.59,84.98,
14.61,85.16,
14.63,85.34,
14.65,85.53,
14.67,85.71,
14.68,85.89,
14.70,86.08,
14.72,86.26,
14.74,86.45,
14.76,86.63,
14.78,86.81,
14.80,87.00,
14.81,87.18,
14.83,87.37,
14.85,87.55,
14.87,87.73,
14.89,87.92,
14.90,88.10,
14.92,88.28,
14.94,88.47,
14.96,88.65,
14.98,88.83,
15.00,89.02,
15.02,89.20,
15.03,89.38,
15.05,89.57,
15.07,89.75,
15.09,89.93,
15.11,90.12,
15.13,90.30,
15.14,90.48,
15.16,90.67,
15.18,90.85,
15.20,91.03,
15.22,91.22,
15.23,91.40,
15.25,91.58,
15.27,91.77,
15.29,91.95,
15.31,92.13,
15.33,92.32,
15.35,92.50,
15.36,92.68,
15.38,92.87,
15.40,93.05,
15.42,93.23,
15.44,93.42,
15.45,93.60,
15.47,93.78,
15.49,93.97,
15.51,94.15,
15.53,94.33,
15.55,94.52,
15.57,94.70,
15.58,94.88,
15.60,95.07,
15.62,95.25,
15.64,95.43,
15.66,95.62,
15.68,95.80,
15.69,95.99,
15.71,96.17,
15.73,96.35,
15.75,96.54,
15.77,96.72,
15.78,96.90,
15.80,97.09,
15.82,97.27,
15.84,97.45,
15.86,97.64,
15.88,97.82,
15.90,98.00,
15.91,98.19,
15.93,98.37,
15.95,98.55,
15.97,98.74,
15.99,98.92,
16.00,99.10,
16.02,99.29,
16.04,99.47,
16.06,99.65,
16.08,99.84,
16.10,100.02,
16.12,100.20,
16.13,100.39,
16.15,100.57,
16.17,100.75,
16.19,100.94,
16.21,101.12,
16.23,101.30,
16.24,101.49,
16.26,101.67,
16.28,101.85,
16.30,102.04,
16.32,102.22,
16.33,102.40,
16.35,102.59,
16.37,102.77,
16.39,102.96,
16.41,103.14,
16.43,103.32,
16.45,103.50,
16.46,103.69,
16.48,103.87,
16.50,104.05,
16.52,104.24,
16.54,104.42,
16.55,104.61,
16.57,104.79,
16.59,104.97,
16.61,105.16,
16.63,105.34,
16.65,105.52,
16.67,105.71,
16.68,105.89,
16.70,106.07,
16.72,106.26,
16.74,106.44,
16.76,106.62,
16.78,106.81,
16.79,106.99,
16.81,107.17,
16.83,107.36,
16.85,107.54,
16.87,107.73,
16.88,107.91,
16.90,108.09,
16.92,108.28,
16.94,108.46,
16.96,108.64,
16.98,108.83,
17.00,109.01,
17.01,109.19,
17.03,109.38,
17.05,109.56,
17.07,109.74,
17.09,109.93,
17.11,110.11,
17.12,110.29,
17.14,110.48,
17.16,110.66,
17.18,110.84,
17.20,111.03,
17.22,111.21,
17.23,111.39,
17.25,111.58,
17.27,111.76,
17.29,111.94,
17.31,112.13,
17.33,112.31,
17.34,112.50,
17.36,112.68,
17.38,112.86,
17.40,113.05,
17.42,113.23,
17.43,113.41,
17.45,113.60,
17.47,113.78,
17.49,113.96,
17.51,114.15,
17.53,114.33,
17.54,114.51,
17.56,114.70,
17.58,114.88,
17.60,115.06,
17.62,115.25,
17.64,115.43,
17.66,115.61,
17.67,115.80,
17.69,115.98,
17.71,116.17,
17.73,116.35,
17.75,116.53,
17.77,116.72,
17.78,116.90,
17.80,117.08,
17.82,117.27,
17.84,117.45,
17.86,117.63,
17.88,117.82,
17.89,118.00,
17.91,118.18,
17.93,118.37,
17.95,118.55,
17.97,118.73,
17.98,118.92,
18.00,119.10,
18.02,119.28,
18.04,119.47,
18.06,119.65,
18.08,119.83,
18.09,120.02,
18.11,120.20,
18.13,120.38,
18.15,120.57,
18.17,120.75,
18.19,120.93,
18.21,121.12,
18.22,121.30,
18.24,121.48,
18.26,121.67,
18.28,121.85,
18.30,122.04,
18.32,122.22,
18.33,122.40,
18.35,122.59,
18.37,122.77,
18.39,122.95,
18.41,123.14,
18.43,123.32,
18.44,123.50,
18.46,123.69,
18.48,123.87,
18.50,124.05,
18.52,124.24,
18.53,124.42,
18.55,124.60,
18.57,124.79,
18.59,124.97,
18.61,125.15,
18.63,125.34,
18.64,125.52,
18.66,125.70,
18.68,125.89,
18.70,126.07,
18.72,126.25,
18.74,126.44,
18.76,126.62,
18.77,126.80,
18.79,126.99,
18.81,127.17,
18.83,127.35,
18.85,127.54,
18.87,127.72,
18.88,127.90,
18.90,128.09,
18.92,128.27,
18.94,128.45,
18.96,128.64,
18.98,128.82,
18.99,129.01,
19.01,129.19,
19.03,129.37,
19.05,129.56,
19.07,129.74,
19.08,129.92,
19.10,130.11,
19.12,130.29,
19.14,130.47,
19.16,130.66,
19.18,130.84,
19.19,131.02,
19.21,131.21,
19.23,131.39,
19.25,131.57,
19.27,131.76,
19.29,131.94,
19.31,132.13,
19.32,132.31,
19.34,132.49,
19.36,132.68,
19.38,132.86,
19.40,133.04,
19.42,133.23,
19.43,133.41,
19.45,133.59,
19.47,133.78,
19.49,133.96,
19.51,134.14,
19.53,134.33,
19.54,134.51,
19.56,134.69,
19.58,134.87,
19.60,135.06,
19.62,135.24,
19.63,135.43,
19.65,135.61,
19.67,135.79,
19.69,135.98,
19.71,136.16,
19.73,136.34,
19.74,136.53,
19.76,136.71,
19.78,136.89,
19.80,137.08,
19.82,137.26,
19.84,137.45,
19.86,137.63,
19.87,137.81,
19.89,137.99,
19.91,138.18,
19.93,138.36,
19.95,138.55,
19.97,138.73,
19.98,138.91,
20.00,139.10,
20.02,139.28,
20.04,139.46,
20.06,139.65,
20.08,139.83,
20.09,140.01,
20.11,140.20,
20.13,140.38,
20.15,140.56,
20.17,140.75,
20.18,140.93,
20.20,141.11,
20.22,141.30,
20.24,141.48,
20.26,141.66,
20.28,141.85,
20.29,142.03,
20.31,142.22,
20.33,142.40,
20.35,142.58,
20.37,142.76,
20.39,142.95,
20.41,143.13,
20.42,143.32,
20.44,143.50,
20.46,143.68,
20.48,143.87,
20.50,144.05,
20.52,144.23,
20.53,144.42,
20.55,144.60,
20.57,144.78,
20.59,144.97,
20.61,145.15,
20.63,145.33,
20.64,145.52,
20.66,145.70,
20.68,145.88,
20.70,146.07,
20.72,146.25,
20.73,146.43,
20.75,146.62,
20.77,146.80,
20.79,146.98,
20.81,147.17,
20.83,147.35,
20.84,147.53,
20.86,147.72,
20.88,147.90,
20.90,148.08,
20.92,148.27,
20.94,148.45,
20.96,148.64,
20.97,148.82,
20.99,149.00,
21.01,149.19,
21.03,149.37,
21.05,149.55,
21.07,149.73,
21.08,149.92,
21.10,150.10,
21.12,150.29,
21.14,150.47,
21.16,150.65,
21.18,150.84,
21.19,151.02,
21.21,151.20,
21.23,151.39,
21.25,151.57,
21.27,151.75,
21.28,151.94,
21.30,152.12,
21.32,152.30,
21.34,152.49,
21.36,152.67,
21.38,152.85,
21.39,153.04,
21.41,153.22,
21.43,153.40,
21.45,153.59,
21.47,153.77,
21.49,153.95,
21.51,154.14,
21.52,154.32,
21.54,154.50,
21.56,154.69,
21.58,154.87,
21.60,155.06,
21.62,155.24,
21.63,155.42,
21.65,155.61,
21.67,155.79,
21.69,155.97,
21.71,156.15,
21.73,156.34,
21.74,156.52,
21.76,156.71,
21.78,156.89,
21.80,157.07,
21.82,157.26,
21.83,157.44,
21.85,157.62,
21.87,157.81,
21.89,157.99,
21.91,158.17,
21.93,158.36,
21.94,158.54,
21.96,158.72,
21.98,158.91,
22.00,159.09,
22.02,159.27,
22.04,159.46,
22.06,159.64,
22.07,159.82,
22.09,160.01,
22.11,160.19,
22.13,160.37,
22.15,160.56,
22.17,160.74,
22.18,160.92,
22.20,161.11,
22.22,161.29,
22.24,161.47,
22.26,161.66,
22.28,161.84,
22.29,162.03,
22.31,162.21,
22.33,162.39,
22.35,162.58,
22.37,162.76,
22.38,162.94,
22.40,163.13,
22.42,163.31,
22.44,163.49,
22.46,163.68,
22.48,163.86,
22.49,164.04,
22.51,164.23,
22.53,164.41,
22.55,164.59,
22.57,164.78,
22.59,164.96,
22.61,165.14,
22.62,165.33,
22.64,165.51,
22.66,165.69,
22.68,165.88,
22.70,166.06,
22.72,166.24,
22.73,166.43,
22.75,166.61,
22.77,166.79,
22.79,166.98,
22.81,167.16,
22.83,167.34,
22.84,167.53,
22.86,167.71,
22.88,167.90,
22.90,168.08,
22.92,168.26,
22.93,168.45,
22.95,168.63,
22.97,168.81,
22.99,168.99,
23.01,169.18,
23.03,169.36,
23.04,169.55,
23.06,169.73,
23.08,169.91,
23.10,170.10,
23.12,170.28,
23.14,170.46,
23.16,170.65,
23.17,170.83,
23.19,171.01,
23.21,171.20,
23.23,171.38,
23.25,171.56,
23.27,171.75,
23.28,171.93,
23.30,172.11,
23.32,172.30,
23.34,172.48,
23.36,172.66,
23.38,172.85,
23.39,173.03,
23.41,173.22,
23.43,173.40,
23.45,173.58,
23.47,173.77,
23.48,173.95,
23.50,174.13,
23.52,174.32,
23.54,174.50,
23.56,174.68,
23.58,174.87,
23.59,175.05,
23.61,175.23,
23.63,175.42,
23.65,175.60,
23.67,175.78,
23.69,175.97,
23.71,176.15,
23.72,176.33,
23.74,176.52,
23.76,176.70,
23.78,176.88,
23.80,177.07,
23.82,177.25,
23.83,177.43,
23.85,177.62,
23.87,177.80,
23.89,177.98,
23.91,178.17,
23.93,178.35,
23.94,178.53,
23.96,178.72,
23.98,178.90,
24.00,179.09,
24.02,179.27,
24.03,179.45,
24.05,179.64,
24.07,179.82,
24.09,180.00,
24.11,180.19,
24.13,180.37,
24.14,180.55,
24.16,180.74,
24.18,180.92,
24.20,181.10,
24.22,181.28,
24.24,181.47,
24.26,181.65,
24.27,181.84,
24.29,182.02,
24.31,182.20,
24.33,182.39,
24.35,182.57,
24.37,182.75,
24.38,182.94,
24.40,183.12,
24.42,183.30,
24.44,183.49,
24.46,183.67,
24.48,183.85,
24.49,184.04,
24.51,184.22,
24.53,184.41,
24.55,184.59,
24.57,184.77,
24.58,184.96,
24.60,185.14,
24.62,185.32,
24.64,185.50,
24.66,185.69,
24.68,185.87,
24.69,186.05,
24.71,186.24,
24.73,186.42,
24.75,186.60,
24.77,186.79,
24.79,186.97,
24.81,187.15,
24.82,187.34,
24.84,187.52,
24.86,187.70,
24.88,187.89,
24.90,188.07,
24.92,188.26,
24.93,188.44,
24.95,188.62,
24.97,188.81,
24.99,188.99,
25.01,189.17,
25.03,189.36,
25.04,189.54,
25.06,189.72,
25.08,189.91,
25.10,190.09,
25.12,190.27,
25.13,190.46,
25.15,190.64,
25.17,190.82,
25.19,191.01,
25.21,191.19,
25.23,191.37,
25.24,191.56,
25.26,191.74,
25.28,191.92,
25.30,192.11,
25.32,192.29,
25.34,192.47,
25.36,192.66,
25.37,192.84,
25.39,193.03,
25.41,193.21,
25.43,193.39,
25.45,193.57,
25.47,193.76,
25.48,193.94,
25.50,194.13,
25.52,194.31,
25.54,194.49,
25.56,194.67,
25.58,194.86,
25.59,195.04,
25.61,195.23,
25.63,195.41,
25.65,195.59,
25.67,195.78,
25.68,195.96,
25.70,196.14,
25.72,196.33,
25.74,196.51,
25.76,196.69,
25.78,196.88,
25.79,197.06,
25.81,197.24,
25.83,197.43,
25.85,197.61,
25.87,197.80,
25.89,197.98,
25.91,198.16,
25.92,198.35,
25.94,198.53,
25.96,198.71,
25.98,198.90,
25.99,,

[step]
Ramp 10.00 °C/min to -60.00 °C
Time,Temperature,Heat Flow (Normalized)
min,°C,W/g
26.99,200.14,
27.01,200.14,
27.03,200.13,
27.05,200.12,
27.07,200.09,
27.08,200.03,
27.10,199.94,
27.12,199.83,
27.14,199.69,
27.16,199.53,
27.18,199.37,
27.19,199.19,
27.21,199.02,
27.23,198.84,
27.25,198.66,
27.27,198.48,
27.29,198.30,
27.31,198.12,
27.32,197.94,
27.34,197.76,
27.36,197.58,
27.38,197.40,
27.40,197.21,
27.42,197.03,
27.43,196.85,
27.45,196.67,
27.47,196.49,
27.49,196.31,
27.51,196.13,
27.53,195.94,
27.54,195.76,
27.56,195.58,
27.58,195.40,
27.60,195.22,
27.62,195.03,
27.63,194.85,
27.65,194.67,
27.67,194.49,
27.69,194.31,
27.71,194.13,
27.73,193.94,
27.74,193.76,
27.76,193.58,
27.78,193.40,
27.80,193.22,
27.82,193.03,
27.84,192.85,
27.86,192.67,
27.87,192.49,
27.89,192.30,
27.91,192.12,
27.93,191.94,
27.95,191.76,
27.97,191.57,
27.98,191.39,
28.00,191.21,
28.02,191.02,
28.04,190.84,
28.06,190.66,
28.08,190.48,
28.09,190.29,
28.11,190.11,
28.13,189.93,
28.15,189.75,
28.17,189.56,
28.18,189.38,
28.20,189.20,
28.22,189.02,
28.24,188.83,
28.26,188.65,
28.28,188.47,
28.29,188.28,
28.31,188.10,
28.33,187.92,
28.35,187.74,
28.37,187.55,
28.39,187.37,
28.41,187.19,
28.42,187.00,
28.44,186.82,
28.46,186.64,
28.48,186.46,
28.50,186.27,
28.52,186.09,
28.53,185.91,
28.55,185.72,
28.57,185.54,
28.59,185.36,
28.61,185.17,
28.63,184.99,
28.64,184.81,
28.66,184.62,
28.68,184.44,
28.70,184.26,
28.72,184.07,
28.73,183.89,
28.75,183.71,
28.77,183.52,
28.79,183.34,
28.81,183.16,
28.83,182.97,
28.84,182.79,
28.86,182.61,
28.88,182.42,
28.90,182.24,
28.92,182.06,
28.94,181.88,
28.96,181.69,
28.97,181.51,
28.99,181.33,
29.01,181.14,
29.03,180.96,
29.05,180.78,
29.07,180.59,
29.08,180.41,
29.10,180.23,
29.12,180.04,
29.14,179.86,
29.16,179.68,
29.18,179.49,
29.19,179.31,
29.21,179.13,
29.23,178.94,
29.25,178.76,
29.27,178.58,
29.28,178.39,
29.30,178.21,
29.32,178.03,
29.34,177.84,
29.36,177.66,
29.38,177.48,
29.39,177.29,
29.41,177.11,
29.43,176.93,
29.45,176.75,
29.47,176.56,
29.49,176.38,
29.51,176.20,
29.52,176.01,
29.54,175.83,
29.56,175.65,
29.58,175.46,
29.60,175.28,
29.62,175.10,
29.63,174.91,
29.65,174.73,
29.67,174.55,
29.69,174.36,
29.71,174.18,
29.73,174.00,
29.74,173.81,
29.76,173.63,
29.78,173.45,
29.80,173.26,
29.82,173.08,
29.83,172.90,
29.85,172.71,
29.87,172.53,
29.89,172.35,
29.91,172.16,
29.93,171.98,
29.94,171.80,
29.96,171.61,
29.98,171.43,
30.00,171.25,
30.02,171.06,
30.04,170.88,
30.06,170.70,
30.07,170.51,
30.09,170.33,
30.11,170.15,
30.13,169.96,
30.15,169.78,
30.17,169.60,
30.18,169.41,
30.20,169.23,
30.22,169.05,
30.24,168.86,
30.26,168.68,
30.28,168.50,
30.29,168.31,
30.31,168.13,
30.33,167.95,
30.35,167.76,
30.37,167.58,
30.38,167.40,
30.40,167.21,
30.42,167.03,
30.44,166.85,
30.46,166.67,
30.48,166.48,
30.49,166.30,
30.51,166.12,
30.53,165.93,
30.55,165.75,
30.57,165.57,
30.59,165.38,
30.61,165.20,
30.62,165.02,
30.64,164.83,
30.66,164.65,
30.68,164.47,
30.70,164.28,
30.72,164.10,
30.73,163.91,
30.75,163.73,
30.77,163.55,
30.79,163.36,
30.81,163.18,
30.83,163.00,
30.84,162.82,
30.86,162.63,
30.88,162.45,
30.90,162.27,
30.92,162.08,
30.93,161.90,
30.95,161.71,
30.97,161.53,
30.99,161.35,
31.01,161.16,
31.03,160.98,
31.04,160.79,
31.06,160.61,
31.08,160.43,
31.10,160.25,
31.12,160.06,
31.14,159.88,
31.16,159.70,
31.17,159.51,
31.19,159.33,
31.21,159.15,
31.23,158.97,
31.25,158.78,
31.27,158.60,
31.28,158.42,
31.30,158.23,
31.32,158.05,
31.34,157.87,
31.36,157.68,
31.38,157.50,
31.39,157.32,
31.41,157.14,
31.43,156.95,
31.45,156.77,
31.47,156.59,
31.48,156.40,
31.50,156.22,
31.52,156.04,
31.54,155.85,
31.56,155.67,
31.58,155.49,
31.59,155.31,
31.61,155.12,
31.63,154.94,
31.65,154.75,
31.67,154.57,
31.69,154.39,
31.71,154.21,
31.72,154.02,
31.74,153.84,
31.76,153.66,
31.78,153.47,
31.80,153.29,
31.82,153.10,
31.83,152.92,
31.85,152.74,
31.87,152.55,
31.89,152.37,
31.91,152.19,
31.93,152.00,
31.94,151.82,
31.96,151.64,
31.98,151.45,
32.00,151.27,
32.02,151.09,
32.03,150.90,
32.05,150.72,
32.07,150.54,
32.09,150.35,
32.11,150.17,
32.13,149.99,
32.14,149.80,
32.16,149.62,
32.18,149.44,
32.20,149.25,
32.22,149.07,
32.24,148.89,
32.26,148.70,
32.27,148.52,
32.29,148.34,
32.31,148.15,
32.33,147.97,
32.35,147.79,
32.37,147.60,
32.38,147.42,
32.40,147.24,
32.42,147.05,
32.44,146.87,
32.46,146.69,
32.48,146.50,
32.49,146.32,
32.51,146.14,
32.53,145.95,
32.55,145.77,
32.57,145.59,
32.58,145.40,
32.60,145.22,
32.62,145.04,
32.64,144.85,
32.66,144.67,
32.68,144.49,
32.69,144.30,
32.71,144.12,
32.73,143.94,
32.75,143.75,
32.77,143.57,
32.79,143.39,
32.81,143.20,
32.82,143.02,
32.84,142.84,
32.86,142.65,
32.88,142.47,
32.90,142.29,
32.92,142.11,
32.93,141.92,
32.95,141.74,
32.97,141.56,
32.99,141.37,
33.01,141.19,
33.03,141.01,
33.04,140.82,
33.06,140.64,
33.08,140.46,
33.10,140.27,
33.12,140.09,
33.13,139.91,
33.15,139.72,
33.17,139.54,
33.19,139.36,
33.21,139.17,
33.23,138.99,
33.24,138.81,
33.26,138.62,
33.28,138.44,
33.30,138.26,
33.32,138.07,
33.34,137.89,
33.36,137.71,
33.37,137.52,
33.39,137.34,
33.41,137.16,
33.43,136.97,
33.45,136.79,
33.47,136.61,
33.48,136.42,
33.50,136.24,
33.52,136.06,
33.54,135.87,
33.56,135.69,
33.58,135.51,
33.59,135.32,
33.61,135.14,
33.63,134.96,
33.65,134.77,
33.67,134.59,
33.68,134.41,
33.70,134.23,
33.72,134.04,
33.74,133.86,
33.76,133.68,
33.78,133.49,
33.79,133.31,
33.81,133.13,
33.83,132.94,
33.85,132.76,
33.87,132.58,
33.89,132.39,
33.91,132.21,
33.92,132.03,
33.94,131.84,
33.96,131.66,
33.98,131.48,
34.00,131.29,
34.02,131.11,
34.03,130.93,
34.05,130.74,
34.07,130.56,
34.09,130.37,
34.11,130.19,
34.13,130.01,
34.14,129.83,
34.16,129.64,
34.18,129.46,
34.20,129.28,
34.22,129.09,
34.24,128.91,
34.25,128.73,
34.27,128.54,
34.29,128.36,
34.31,128.18,
34.33,127.99,
34.34,127.81,
34.36,127.63,
34.38,127.44,
34.40,127.26,
34.42,127.08,
34.44,126.89,
34.46,126.71,
34.47,126.53,
34.49,126.34,
34.51,126.16,
34.53,125.98,
34.55,125.79,
34.56,125.61,
34.58,125.43,
34.60,125.24,
34.62,125.06,
34.64,124.88,
34.66,124.69,
34.68,124.51,
34.69,124.33,
34.71,124.14,
34.73,123.96,
34.75,123.78,
34.77,123.60,
34.79,123.41,
34.80,123.23,
34.82,123.05,
34.84,122.86,
34.86,122.68,
34.88,122.49,
34.89,122.31,
34.91,122.13,
34.93,121.94,
34.95,121.76,
34.97,121.58,
34.99,121.39,
35.01,121.21,
35.02,121.03,
35.04,120.84,
35.06,120.66,
35.08,120.48,
35.10,120.30,
35.11,120.11,
35.13,119.93,
35.15,119.75,
35.17,119.56,
35.19,119.38,
35.21,119.19,
35.23,119.01,
35.24,118.83,
35.26,118.65,
35.28,118.46,
35.30,118.28,
35.32,118.10,
35.34,117.91,
35.35,117.73,
35.37,117.55,
35.39,117.36,
35.41,117.18,
35.43,117.00,
35.44,116.81,
35.46,116.63,
35.48,116.45,
35.50,116.26,
35.52,116.08,
35.54,115.90,
35.56,115.71,
35.57,115.53,
35.59,115.35,
35.61,115.16,
35.63,114.98,
35.65,114.80,
35.66,114.61,
35.68,114.43,
35.70,114.25,
35.72,114.06,
35.74,113.88,
35.76,113.70,
35.78,113.51,
35.79,113.33,
35.81,113.15,
35.83,112.96,
35.85,112.78,
35.87,112.60,
35.89,112.41,
35.90,112.23,
35.92,112.05,
35.94,111.86,
35.96,111.68,
35.98,111.50,
35.99,111.31,
36.01,111.13,
36.03,110.95,
36.05,110.76,
36.07,110.58,
36.09,110.40,
36.11,110.22,
36.12,110.03,
36.14,109.85,
36.16,109.67,
36.18,109.48,
36.20,109.30,
36.21,109.12,
36.23,108.93,
36.25,108.75,
36.27,108.57,
36.29,108.38,
36.31,108.20,
36.33,108.02,
36.34,107.83,
36.36,107.65,
36.38,107.47,
36.40,107.28,
36.42,107.10,
36.44,106.92,
36.45,106.73,
36.47,106.55,
36.49,106.37,
36.51,106.18,
36.53,106.00,
36.54,105.82,
36.56,105.63,
36.58,105.45,
36.60,105.27,
36.62,105.08,
36.64,104.90,
36.66,104.72,
36.67,104.53,
36.69,104.35,
36.71,104.17,
36.73,103.98,
36.75,103.80,
36.76,103.62,
36.78,103.43,
36.80,103.25,
36.82,103.07,
36.84,102.88,
36.86,102.70,
36.88,102.52,
36.89,102.33,
36.91,102.15,
36.93,101.97,
36.95,101.78,
36.97,101.60,
36.99,101.42,
37.00,101.23,
37.02,101.05,
37.04,100.87,
37.06,100.68,
37.08,100.50,
37.09,100.32,
37.11,100.13,
37.13,99.95,
37.15,99.77,
37.17,99.58,
37.19,99.40,
37.21,99.22,
37.22,99.03,
37.24,98.85,
37.26,98.67,
37.28,98.49,
37.30,98.30,
37.31,98.12,
37.33,97.94,
37.35,97.75,
37.37,97.57,
37.39,97.39,
37.41,97.20,
37.43,97.02,
37.44,96.84,
37.46,96.65,
37.48,96.47,
37.50,96.29,
37.52,96.10,
37.54,95.92,
37.55,95.74,
37.57,95.55,
37.59,95.37,
37.61,95.19,
37.63,95.00,
37.64,94.82,
37.66,94.63,
37.68,94.45,
37.70,94.27,
37.72,94.08,
37.74,93.90,
37.76,93.72,
37.77,93.54,
37.79,93.35,
37.81,93.17,
37.83,92.99,
37.85,92.80,
37.86,92.62,
37.88,92.44,
37.90,92.25,
37.92,92.07,
37.94,91.89,
37.96,91.70,
37.98,91.52,
37.99,91.34,
38.01,91.15,
38.03,90.97,
38.05,90.79,
38.07,90.60,
38.09,90.42,
38.10,90.24,
38.12,90.06,
38.14,89.87,
38.16,89.69,
38.18,89.51,
38.19,89.32,
38.21,89.14,
38.23,88.95,
38.25,88.77,
38.27,88.59,
38.29,88.40,
38.31,88.22,
38.32,88.04,
38.34,87.86,
38.36,87.67,
38.38,87.49,
38.40,87.30,
38.41,87.12,
38.43,86.94,
38.45,86.76,
38.47,86.57,
38.49,86.39,
38.51,86.20,
38.53,86.02,
38.54,85.84,
38.56,85.65,
38.58,85.47,
38.60,85.29,
38.62,85.10,
38.64,84.92,
38.65,84.74,
38.67,84.56,
38.69,84.37,
38.71,84.19,
38.73,84.00,
38.74,83.82,
38.76,83.64,
38.78,83.45,
38.80,83.27,
38.82,83.09,
38.84,82.91,
38.86,82.72,
38.87,82.54,
38.89,82.36,
38.91,82.17,
38.93,81.99,
38.95,81.81,
38.96,81.62,
38.98,81.44,
39.00,81.26,
39.02,81.07,
39.04,80.89,
39.06,80.71,
39.08,80.52,
39.09,80.34,
39.11,80.16,
39.13,79.97,
39.15,79.79,
39.17,79.61,
39.19,79.42,
39.20,79.24,
39.22,79.06,
39.24,78.87,
39.26,78.69,
39.28,78.51,
39.29,78.32,
39.31,78.14,
39.33,77.96,
39.35,77.77,
39.37,77.59,
39.39,77.41,
39.41,77.23,
39.42,77.04,
39.44,76.86,
39.46,76.67,
39.48,76.49,
39.50,76.31,
39.51,76.13,
39.53,75.94,
39.55,75.76,
39.57,75.58,
39.59,75.39,
39.61,75.21,
39.63,75.03,
39.64,74.84,
39.66,74.66,
39.68,74.48,
39.70,74.29,
39.72,74.11,
39.74,73.93,
39.75,73.74,
39.77,73.56,
39.79,73.38,
39.81,73.19,
39.83,73.01,
39.84,72.83,
39.86,72.64,
39.88,72.46,
39.90,72.28,
39.92,72.09,
39.94,71.91,
39.96,71.73,
39.97,71.54,
39.99,71.36,
40.01,71.18,
40.03,70.99,
40.05,70.81,
40.06,70.63,
40.08,70.44,
40.10,70.26,
40.12,70.08,
40.14,69.89,
40.16,69.71,
40.18,69.53,
40.19,69.34,
40.21,69.16,
40.23,68.98,
40.25,68.79,
40.27,68.61,
40.29,68.43,
40.30,68.24,
40.32,68.06,
40.34,67.88,
40.36,67.69,
40.38,67.51,
40.39,67.33,
40.41,67.14,
40.43,66.96,
40.45,66.78,
40.47,66.59,
40.49,66.41,
40.51,66.23,
40.52,66.04,
40.54,65.86,
40.56,65.68,
40.58,65.49,
40.60,65.31,
40.61,65.13,
40.63,64.94,
40.65,64.76,
40.67,64.58,
40.69,64.40,
40.71,64.21,
40.73,64.03,
40.74,63.84,
40.76,63.66,
40.78,63.48,
40.80,63.30,
40.82,63.11,
40.84,62.93,
40.85,62.75,
40.87,62.56,
40.89,62.38,
40.91,62.19,
40.93,62.01,
40.94,61.83,
40.96,61.65,
40.98,61.46,
41.00,61.28,
41.02,61.10,
41.04,60.91,
41.06,60.73,
41.07,60.55,
41.09,60.36,
41.11,60.18,
41.13,60.00,
41.15,59.81,
41.16,59.63,
41.18,59.45,
41.20,59.26,
41.22,59.08,
41.24,58.90,
41.26,58.71,
41.28,58.53,
41.29,58.35,
41.31,58.16,
41.33,57.98,
41.35,57.80,
41.37,57.61,
41.39,57.43,
41.40,57.25,
41.42,57.06,
41.44,56.88,
41.46,56.70,
41.48,56.51,
41.49,56.33,
41.51,56.15,
41.53,55.96,
41.55,55.78,
41.57,55.60,
41.59,55.41,
41.61,55.23,
41.62,55.05,
41.64,54.86,
41.66,54.68,
41.68,54.50,
41.70,54.32,
41.71,54.13,
41.73,53.95,
41.75,53.76,
41.77,53.58,
41.79,53.40,
41.81,53.21,
41.83,53.03,
41.84,52.85,
41.86,52.66,
41.88,52.48,
41.90,52.30,
41.92,52.12,
41.94,51.93,
41.95,51.75,
41.97,51.57,
41.99,51.38,
42.01,51.20,
42.03,51.02,
42.04,50.83,
42.06,50.65,
42.08,50.47,
42.10,50.28,
42.12,50.10,
42.14,49.91,
42.16,49.73,
42.17,49.55,
42.19,49.37,
42.21,49.18,
42.23,49.00,
42.25,48.81,
42.26,48.63,
42.28,48.45,
42.30,48.27,
42.32,48.08,
42.34,47.90,
42.36,47.72,
42.38,47.53,
42.39,47.35,
42.41,47.17,
42.43,46.98,
42.45,46.80,
42.47,46.62,
42.49,46.43,
42.50,46.25,
42.52,46.07,
42.54,45.88,
42.56,45.70,
42.58,45.52,
42.59,45.33,
42.61,45.15,
42.63,44.97,
42.65,44.78,
42.67,44.60,
42.69,44.42,
42.71,44.23,
42.72,44.05,
42.74,43.87,
42.76,43.69,
42.78,43.50,
42.80,43.32,
42.81,43.13,
42.83,42.95,
42.85,42.77,
42.87,42.58,
42.89,42.40,
42.91,42.22,
42.93,42.03,
42.94,41.85,
42.96,41.67,
42.98,41.48,
43.00,41.30,
43.02,41.12,
43.04,40.94,
43.05,40.75,
43.07,40.57,
43.09,40.39,
43.11,40.20,
43.13,40.02,
43.14,39.84,
43.16,39.65,
43.18,39.47,
43.20,39.29,
43.22,39.10,
43.24,38.92,
43.26,38.74,
43.27,38.55,
43.29,38.37,
43.31,38.19,
43.33,38.00,
43.35,37.82,
43.36,37.64,
43.38,37.45,
43.40,37.27,
43.42,37.09,
43.44,36.90,
43.46,36.72,
43.48,36.54,
43.49,36.35,
43.51,36.17,
43.53,35.99,
43.55,35.80,
43.57,35.62,
43.59,35.44,
43.60,35.25,
43.62,35.07,
43.64,34.89,
43.66,34.70,
43.68,34.52,
43.69,34.34,
43.71,34.15,
43.73,33.97,
43.75,33.79,
43.77,33.60,
43.79,33.42,
43.81,33.24,
43.82,33.06,
43.84,32.87,
43.86,32.69,
43.88,32.50,
43.90,32.32,
43.91,32.14,
43.93,31.96,
43.95,31.77,
43.97,31.59,
43.99,31.41,
44.01,31.22,
44.03,31.04,
44.04,30.86,
44.06,30.67,
44.08,30.49,
44.10,30.31,
44.12,30.12,
44.14,29.94,
44.15,29.76,
44.17,29.57,
44.19,29.39,
44.21,29.21,
44.23,29.02,
44.24,28.84,
44.26,28.66,
44.28,28.47,
44.30,28.29,
44.32,28.11,
44.34,27.92,
44.36,27.74,
44.37,27.56,
44.39,27.37,
44.41,27.19,
44.43,27.01,
44.45,26.83,
44.46,26.64,
44.48,26.46,
44.50,26.27,
44.52,26.09,
44.54,25.91,
44.56,25.73,
44.58,25.54,
44.59,25.36,
44.61,25.18,
44.63,24.99,
44.65,24.81,
44.67,24.63,
44.69,24.44,
44.70,24.26,
44.72,24.08,
44.74,23.89,
44.76,23.71,
44.78,23.53,
44.79,23.34,
44.81,23.16,
44.83,22.98,
44.85,22.79,
44.87,22.61,
44.89,22.43,
44.91,22.24,
44.92,22.06,
44.94,21.88,
44.96,21.69,
44.98,21.51,
45.00,21.33,
45.01,21.14,
45.03,20.96,
45.05,20.78,
45.07,20.59,
45.09,20.41,
45.11,20.23,
45.13,20.04,
45.14,19.86,
45.16,19.68,
45.18,19.49,
45.20,19.31,
45.22,19.13,
45.24,18.94,
45.25,18.76,
45.27,18.58,
45.29,18.40,
45.31,18.21,
45.33,18.03,
45.34,17.85,
45.36,17.66,
45.38,17.48,
45.40,17.30,
45.42,17.11,
45.44,16.93,
45.46,16.75,
45.47,16.56,
45.49,16.38,
45.51,16.19,
45.53,16.01,
45.55,15.83,
45.56,15.64,
45.58,15.46,
45.60,15.28,
45.62,15.10,
45.64,14.91,
45.66,14.73,
45.68,14.55,
45.69,14.36,
45.71,14.18,
45.73,14.00,
45.75,13.81,
45.77,13.63,
45.79,13.45,
45.80,13.26,
45.82,13.08,
45.84,12.90,
45.86,12.71,
45.88,12.53,
45.89,12.35,
45.91,12.16,
45.93,11.98,
45.95,11.80,
45.97,11.62,
45.99,11.43,
46.01,11.25,
46.02,11.07,
46.04,10.88,
46.06,10.70,
46.08,10.52,
46.10,10.34,
46.11,10.15,
46.13,9.97,
46.15,9.79,
46.17,9.60,
46.19,9.42,
46.21,9.24,
46.23,9.05,
46.24,8.87,
46.26,8.69,
46.28,8.50,
46.30,8.32,
46.32,8.14,
46.34,7.95,
46.35,7.77,
46.37,7.59,
46.39,7.40,
46.41,7.22,
46.43,7.04,
46.44,6.85,
46.46,6.67,
46.48,6.49,
46.50,6.31,
46.52,6.12,
46.54,5.94,
46.56,5.76,
46.57,5.57,
46.59,5.39,
46.61,5.21,
46.63,5.02,
46.65,4.84,
46.66,4.66,
46.68,4.47,
46.70,4.29,
46.72,4.11,
46.74,3.92,
46.76,3.74,
46.78,3.56,
46.79,3.37,
46.81,3.19,
46.83,3.01,
46.85,2.82,
46.87,2.64,
46.89,2.46,
46.90,2.27,
46.92,2.09,
46.94,1.90,
46.96,1.72,
46.98,1.54,
46.99,1.35,
47.01,1.17,
47.03,0.99,
47.05,0.80,
47.07,0.62,
47.09,0.44,
47.11,0.25,
47.12,0.07,
47.14,-0.12,
47.16,-0.30,
47.18,-0.48,
47.20,-0.67,
47.21,-0.85,
47.23,-1.03,
47.25,-1.22,
47.27,-1.40,
47.29,-1.58,
47.31,-1.77,
47.33,-1.95,
47.34,-2.13,
47.36,-2.32,
47.38,-2.50,
47.40,-2.68,
47.42,-2.87,
47.44,-3.05,
47.45,-3.23,
47.47,-3.42,
47.49,-3.60,
47.51,-3.79,
47.53,-3.97,
47.54,-4.15,
47.56,-4.34,
47.58,-4.52,
[...]
116.99,28.89,,-0.025
117.01,29.08,,-0.025
117.03,29.26,,-0.026
117.05,29.44,,-0.026
117.07,29.63,,-0.026
117.09,29.81,,-0.026
117.10,29.99,,-0.026
117.12,30.18,,-0.026
117.14,30.36,,-0.026
117.16,30.54,,-0.026
117.18,30.73,,-0.026
117.20,30.91,,-0.027
117.21,31.10,,-0.027
117.23,31.28,,-0.027
117.25,31.46,,-0.027
117.27,31.64,,-0.027
117.29,31.83,,-0.027
117.30,32.01,,-0.027
117.32,32.20,,-0.027
117.34,32.38,,-0.027
117.36,32.56,,-0.028
117.38,32.75,,-0.027
117.40,32.93,,-0.028
117.41,33.11,,-0.028
117.43,33.30,,-0.028
117.45,33.48,,-0.028
117.47,33.66,,-0.028
117.49,33.85,,-0.028
117.51,34.03,,-0.029
117.53,34.21,,-0.028
117.54,34.40,,-0.029
117.56,34.58,,-0.029
117.58,34.76,,-0.029
117.60,34.95,,-0.029
117.62,35.13,,-0.029
117.64,35.32,,-0.029
117.65,35.50,,-0.029
117.67,35.68,,-0.029
117.69,35.87,,-0.029
117.71,36.05,,-0.029
117.73,36.23,,-0.029
117.75,36.42,,-0.029
117.76,36.60,,-0.029
117.78,36.78,,-0.029
117.80,36.97,,-0.029
117.82,37.15,,-0.030
117.84,37.33,,-0.030
117.85,37.52,,-0.030
117.87,37.70,,-0.030
117.89,37.88,,-0.030
117.91,38.07,,-0.030
117.93,38.25,,-0.030
117.95,38.43,,-0.030
117.96,38.62,,-0.030
117.98,38.80,,-0.030
118.00,38.99,,-0.031
118.02,39.17,,-0.031
118.04,39.35,,-0.031
118.06,39.54,,-0.031
118.08,39.72,,-0.031
118.09,39.90,,-0.031
118.11,40.09,,-0.031
118.13,40.27,,-0.031
118.15,40.45,,-0.031
118.17,40.64,,-0.031
118.19,40.82,,-0.031
118.20,41.00,,-0.031
118.22,41.19,,-0.031
118.24,41.37,,-0.031
118.26,41.55,,-0.031
118.28,41.74,,-0.031
118.30,41.92,,-0.031
118.31,42.10,,-0.031
118.33,42.29,,-0.032
118.35,42.47,,-0.032
118.37,42.66,,-0.031
118.39,42.84,,-0.032
118.40,43.02,,-0.032
118.42,43.21,,-0.032
118.44,43.39,,-0.032
118.46,43.57,,-0.032
118.48,43.76,,-0.032
118.50,43.94,,-0.032
118.51,44.12,,-0.032
118.53,44.31,,-0.032
118.55,44.49,,-0.033
118.57,44.67,,-0.033
118.59,44.86,,-0.033
118.61,45.04,,-0.033
118.63,45.23,,-0.033
118.64,45.41,,-0.033
118.66,45.59,,-0.033
118.68,45.77,,-0.033
118.70,45.96,,-0.033
118.72,46.14,,-0.033
118.74,46.33,,-0.033
118.75,46.51,,-0.033
118.77,46.69,,-0.033
118.79,46.88,,-0.033
118.81,47.06,,-0.033
118.83,47.24,,-0.033
118.85,47.43,,-0.033
118.86,47.61,,-0.033
118.88,47.79,,-0.033
118.90,47.98,,-0.033
118.92,48.16,,-0.033
118.94,48.34,,-0.033
118.95,48.53,,-0.034
118.97,48.71,,-0.034
118.99,48.89,,-0.034
119.01,49.08,,-0.034
119.03,49.26,,-0.034
119.05,49.44,,-0.034
119.06,49.63,,-0.034
119.08,49.81,,-0.034
119.10,49.99,,-0.034
119.12,50.18,,-0.034
119.14,50.36,,-0.035
119.16,50.55,,-0.035
119.18,50.73,,-0.035
119.19,50.91,,-0.035
119.21,51.10,,-0.035
119.23,51.28,,-0.035
119.25,51.46,,-0.035
119.27,51.65,,-0.035
119.29,51.83,,-0.035
119.30,52.01,,-0.035
119.32,52.20,,-0.035
119.34,52.38,,-0.035
119.36,52.56,,-0.035
119.38,52.75,,-0.035
119.40,52.93,,-0.035
119.41,53.11,,-0.035
119.43,53.30,,-0.035
119.45,53.48,,-0.035
119.47,53.67,,-0.035
119.49,53.85,,-0.035
119.50,54.03,,-0.035
119.52,54.22,,-0.036
119.54,54.40,,-0.036
119.56,54.58,,-0.036
119.58,54.77,,-0.036
119.60,54.95,,-0.036
119.61,55.14,,-0.036
119.63,55.32,,-0.036
119.65,55.50,,-0.036
119.67,55.68,,-0.036
119.69,55.87,,-0.036
119.71,56.05,,-0.036
119.73,56.23,,-0.036
119.74,56.42,,-0.036
119.76,56.60,,-0.036
119.78,56.79,,-0.036
119.80,56.97,,-0.036
119.82,57.15,,-0.036
119.84,57.34,,-0.036
119.85,57.52,,-0.036
119.87,57.70,,-0.036
119.89,57.89,,-0.036
119.91,58.07,,-0.036
119.93,58.25,,-0.036
119.95,58.44,,-0.036
119.96,58.62,,-0.036
119.98,58.80,,-0.036
120.00,58.99,,-0.036
120.02,59.17,,-0.037
120.04,59.35,,-0.037
120.05,59.54,,-0.037
120.07,59.72,,-0.037
120.09,59.90,,-0.037
120.11,60.09,,-0.037
120.13,60.27,,-0.037
120.15,60.45,,-0.037
120.16,60.64,,-0.037
120.18,60.82,,-0.037
120.20,61.01,,-0.037
120.22,61.19,,-0.037
120.24,61.37,,-0.037
120.26,61.55,,-0.037
120.28,61.74,,-0.037
120.29,61.92,,-0.037
120.31,62.11,,-0.037
120.33,62.29,,-0.037
120.35,62.47,,-0.037
120.37,62.66,,-0.037
120.39,62.84,,-0.037
120.40,63.02,,-0.037
120.42,63.21,,-0.037
120.44,63.39,,-0.037
120.46,63.57,,-0.037
120.48,63.76,,-0.037
120.50,63.94,,-0.037
120.51,64.12,,-0.037
120.53,64.31,,-0.037
120.55,64.49,,-0.037
120.57,64.67,,-0.038
120.59,64.86,,-0.038
120.60,65.04,,-0.038
120.62,65.23,,-0.038
120.64,65.41,,-0.038
120.66,65.59,,-0.038
120.68,65.78,,-0.038
120.70,65.96,,-0.038
120.71,66.14,,-0.038
120.73,66.33,,-0.038
120.75,66.51,,-0.038
120.77,66.69,,-0.038
120.79,66.88,,-0.038
120.81,67.06,,-0.038
120.83,67.25,,-0.038
120.84,67.43,,-0.039
120.86,67.61,,-0.038
120.88,67.80,,-0.039
120.90,67.98,,-0.039
120.92,68.16,,-0.039
120.94,68.35,,-0.039
120.95,68.53,,-0.039
120.97,68.71,,-0.039
120.99,68.90,,-0.039
121.01,69.08,,-0.039
121.03,69.26,,-0.039
121.05,69.45,,-0.039
121.06,69.63,,-0.039
121.08,69.81,,-0.039
121.10,70.00,,-0.039
121.12,70.18,,-0.039
121.14,70.36,,-0.039
121.15,70.55,,-0.039
121.17,70.73,,-0.039
121.19,70.91,,-0.039
121.21,71.10,,-0.039
121.23,71.28,,-0.039
121.25,71.46,,-0.039
121.26,71.65,,-0.039
121.28,71.83,,-0.039
121.30,72.01,,-0.039
121.32,72.20,,-0.039
121.34,72.38,,-0.040
121.36,72.56,,-0.040
121.38,72.75,,-0.040
121.39,72.93,,-0.040
121.41,73.12,,-0.039
121.43,73.30,,-0.040
121.45,73.48,,-0.040
121.47,73.67,,-0.040
121.49,73.85,,-0.040
121.50,74.03,,-0.040
121.52,74.22,,-0.040
121.54,74.40,,-0.040
121.56,74.58,,-0.040
121.58,74.77,,-0.040
121.60,74.95,,-0.040
121.61,75.14,,-0.040
121.63,75.32,,-0.040
121.65,75.50,,-0.040
121.67,75.69,,-0.040
121.69,75.87,,-0.040
121.70,76.05,,-0.040
121.72,76.24,,-0.040
121.74,76.42,,-0.040
121.76,76.60,,-0.040
121.78,76.79,,-0.040
121.80,76.97,,-0.040
121.81,77.15,,-0.040
121.83,77.34,,-0.040
121.85,77.52,,-0.040
121.87,77.70,,-0.040
121.89,77.89,,-0.040
121.91,78.07,,-0.040
121.93,78.25,,-0.041
121.94,78.44,,-0.040
121.96,78.62,,-0.040
121.98,78.81,,-0.040
122.00,78.99,,-0.040
122.02,79.17,,-0.040
122.04,79.35,,-0.040
122.05,79.54,,-0.040
122.07,79.72,,-0.040
122.09,79.90,,-0.040
122.11,80.09,,-0.040
122.13,80.27,,-0.040
122.15,80.45,,-0.040
122.16,80.64,,-0.040
122.18,80.82,,-0.040
122.20,81.01,,-0.040
122.22,81.19,,-0.040
122.24,81.37,,-0.041
122.25,81.56,,-0.041
122.27,81.74,,-0.040
122.29,81.92,,-0.040
122.31,82.11,,-0.040
122.33,82.29,,-0.041
122.35,82.47,,-0.040
122.36,82.66,,-0.041
122.38,82.84,,-0.041
122.40,83.02,,-0.040
122.42,83.21,,-0.041
122.44,83.39,,-0.041
122.46,83.57,,-0.041
122.48,83.76,,-0.041
122.49,83.94,,-0.041
122.51,84.12,,-0.041
122.53,84.31,,-0.041
122.55,84.49,,-0.041
122.57,84.67,,-0.041
122.59,84.86,,-0.041
122.60,85.04,,-0.041
122.62,85.23,,-0.041
122.64,85.41,,-0.041
122.66,85.59,,-0.041
122.68,85.78,,-0.041
122.70,85.96,,-0.041
122.71,86.14,,-0.041
122.73,86.33,,-0.041
122.75,86.51,,-0.042
122.77,86.70,,-0.042
122.79,86.88,,-0.042
122.80,87.07,,-0.042
122.82,87.25,,-0.042
122.84,87.43,,-0.042
122.86,87.62,,-0.042
122.88,87.80,,-0.042
122.90,87.98,,-0.042
122.91,88.17,,-0.042
122.93,88.35,,-0.042
122.95,88.53,,-0.043
122.97,88.72,,-0.043
122.99,88.90,,-0.043
123.01,89.08,,-0.042
123.03,89.26,,-0.043
123.04,89.45,,-0.043
123.06,89.63,,-0.043
123.08,89.81,,-0.043
123.10,90.00,,-0.043
123.12,90.18,,-0.043
123.14,90.37,,-0.043
123.15,90.55,,-0.043
123.17,90.73,,-0.044
123.19,90.92,,-0.044
123.21,91.10,,-0.044
123.23,91.28,,-0.044
123.25,91.47,,-0.044
123.26,91.65,,-0.044
123.28,91.83,,-0.044
123.30,92.01,,-0.044
123.32,92.20,,-0.044
123.34,92.38,,-0.044
123.35,92.57,,-0.044
123.37,92.75,,-0.044
123.39,92.93,,-0.045
123.41,93.12,,-0.045
123.43,93.30,,-0.044
123.45,93.48,,-0.045
123.46,93.67,,-0.044
123.48,93.85,,-0.044
123.50,94.03,,-0.044
123.52,94.22,,-0.045
123.54,94.40,,-0.044
123.56,94.58,,-0.044
123.58,94.77,,-0.044
123.59,94.95,,-0.044
123.61,95.14,,-0.044
123.63,95.32,,-0.044
123.65,95.50,,-0.044
123.67,95.68,,-0.043
123.69,95.87,,-0.043
123.70,96.05,,-0.043
123.72,96.23,,-0.043
123.74,96.42,,-0.043
123.76,96.60,,-0.043
123.78,96.78,,-0.043
123.80,96.97,,-0.043
123.81,97.15,,-0.043
123.83,97.33,,-0.042
123.85,97.52,,-0.042
123.87,97.70,,-0.042
123.89,97.88,,-0.042
123.90,98.07,,-0.042
123.92,98.25,,-0.041
123.94,98.43,,-0.041
123.96,98.62,,-0.041
123.98,98.80,,-0.041
124.00,98.98,,-0.041
124.01,99.17,,-0.041
124.03,99.35,,-0.041
124.05,99.54,,-0.041
124.07,99.72,,-0.041
124.09,99.90,,-0.040
124.11,100.09,,-0.040
124.13,100.27,,-0.040
124.14,100.45,,-0.040
124.16,100.64,,-0.040
124.18,100.82,,-0.040
124.20,101.00,,-0.040
124.22,101.19,,-0.040
124.24,101.37,,-0.040
124.25,101.55,,-0.040
124.27,101.74,,-0.040
124.29,101.92,,-0.040
124.31,102.10,,-0.040
124.33,102.29,,-0.040
124.35,102.47,,-0.040
124.36,102.65,,-0.040
124.38,102.84,,-0.040
124.40,103.02,,-0.040
124.42,103.21,,-0.040
124.44,103.39,,-0.040
124.45,103.57,,-0.040
124.47,103.76,,-0.040
124.49,103.94,,-0.040
124.51,104.12,,-0.040
124.53,104.31,,-0.040
124.55,104.49,,-0.040
124.56,104.67,,-0.040
124.58,104.86,,-0.040
124.60,105.04,,-0.039
124.62,105.22,,-0.039
124.64,105.41,,-0.039
124.66,105.59,,-0.039
124.68,105.77,,-0.039
124.69,105.96,,-0.039
124.71,106.14,,-0.039
124.73,106.33,,-0.039
124.75,106.51,,-0.039
124.77,106.69,,-0.039
124.79,106.88,,-0.040
124.80,107.06,,-0.040
124.82,107.25,,-0.040
124.84,107.43,,-0.040
124.86,107.61,,-0.040
124.88,107.80,,-0.041
124.90,107.98,,-0.041
124.91,108.17,,-0.041
124.93,108.35,,-0.042
124.95,108.53,,-0.042
124.97,108.72,,-0.042
124.99,108.90,,-0.042
125.00,109.08,,-0.043
125.02,109.26,,-0.043
125.04,109.45,,-0.043
125.06,109.63,,-0.043
125.08,109.81,,-0.043
125.10,110.00,,-0.043
125.11,110.18,,-0.044
125.13,110.36,,-0.044
125.15,110.55,,-0.044
125.17,110.73,,-0.044
125.19,110.91,,-0.044
125.21,111.10,,-0.044
125.23,111.28,,-0.044
125.24,111.46,,-0.045
125.26,111.65,,-0.045
125.28,111.83,,-0.045
125.30,112.01,,-0.045
125.32,112.20,,-0.045
125.34,112.38,,-0.045
125.35,112.56,,-0.045
125.37,112.75,,-0.045
125.39,112.93,,-0.045
125.41,113.11,,-0.045
125.43,113.30,,-0.045
125.45,113.48,,-0.045
125.46,113.66,,-0.045
125.48,113.85,,-0.045
125.50,114.03,,-0.045
125.52,114.21,,-0.045
125.54,114.40,,-0.045
125.55,114.58,,-0.045
125.57,114.76,,-0.045
125.59,114.95,,-0.045
125.61,115.13,,-0.045
125.63,115.31,,-0.045
125.65,115.50,,-0.045
125.66,115.68,,-0.045
125.68,115.87,,-0.045
125.70,116.05,,-0.045
125.72,116.23,,-0.045
125.74,116.42,,-0.045
125.76,116.60,,-0.045
125.78,116.78,,-0.045
125.79,116.97,,-0.045
125.81,117.15,,-0.045
125.83,117.33,,-0.045
125.85,117.52,,-0.045
125.87,117.70,,-0.045
125.89,117.88,,-0.045
125.90,118.06,,-0.045
125.92,118.25,,-0.045
125.94,118.43,,-0.045
125.96,118.62,,-0.045
125.98,118.80,,-0.045
126.00,118.98,,-0.045
126.01,119.17,,-0.045
126.03,119.35,,-0.045
126.05,119.54,,-0.045
126.07,119.72,,-0.045
126.09,119.90,,-0.045
126.10,120.08,,-0.045
126.12,120.27,,-0.045
126.14,120.45,,-0.045
126.16,120.63,,-0.045
126.18,120.82,,-0.045
126.20,121.00,,-0.045
126.21,121.19,,-0.045
126.23,121.37,,-0.045
126.25,121.55,,-0.045
126.27,121.74,,-0.045
126.29,121.92,,-0.045
126.31,122.10,,-0.045
126.33,122.29,,-0.045
126.34,122.47,,-0.045
126.36,122.65,,-0.045
126.38,122.84,,-0.045
126.40,123.02,,-0.045
126.42,123.20,,-0.045
126.44,123.39,,-0.045
126.45,123.57,,-0.045
126.47,123.75,,-0.045
126.49,123.94,,-0.045
126.51,124.12,,-0.045
126.53,124.30,,-0.045
126.55,124.49,,-0.045
126.56,124.67,,-0.045
126.58,124.85,,-0.045
126.60,125.04,,-0.045
126.62,125.22,,-0.045
126.64,125.41,,-0.045
126.65,125.59,,-0.044
126.67,125.77,,-0.044
126.69,125.96,,-0.044
126.71,126.14,,-0.044
126.73,126.32,,-0.044
126.75,126.51,,-0.044
126.76,126.69,,-0.044
126.78,126.87,,-0.044
126.80,127.06,,-0.044
126.82,127.24,,-0.043
126.84,127.42,,-0.044
126.86,127.61,,-0.043
126.88,127.79,,-0.043
126.89,127.97,,-0.043
126.91,128.16,,-0.043
126.93,128.34,,-0.043
126.95,128.52,,-0.043
126.97,128.71,,-0.043
126.99,128.89,,-0.043
127.00,129.07,,-0.043
127.02,129.26,,-0.043
127.04,129.44,,-0.043
127.06,129.62,,-0.043
127.08,129.81,,-0.043
127.10,129.99,,-0.043
127.11,130.17,,-0.043
127.13,130.36,,-0.043
127.15,130.54,,-0.043
127.17,130.72,,-0.043
127.19,130.91,,-0.043
127.20,131.09,,-0.043
127.22,131.28,,-0.043
127.24,131.46,,-0.043
127.26,131.64,,-0.043
127.28,131.83,,-0.043
127.30,132.01,,-0.043
127.31,132.19,,-0.043
127.33,132.38,,-0.043
127.35,132.56,,-0.042
127.37,132.74,,-0.042
127.39,132.93,,-0.042
127.41,133.11,,-0.042
127.43,133.29,,-0.042
127.44,133.48,,-0.042
127.46,133.66,,-0.042
127.48,133.84,,-0.042
127.50,134.03,,-0.042
127.52,134.21,,-0.042
127.54,134.39,,-0.042
127.55,134.58,,-0.042
127.57,134.76,,-0.042
127.59,134.94,,-0.042
127.61,135.13,,-0.042
127.63,135.31,,-0.042
127.65,135.49,,-0.042
127.66,135.68,,-0.042
127.68,135.86,,-0.042
127.70,136.05,,-0.042
127.72,136.23,,-0.042
127.74,136.41,,-0.042
127.75,136.59,,-0.042
127.77,136.78,,-0.042
127.79,136.96,,-0.042
127.81,137.14,,-0.042
127.83,137.33,,-0.042
127.85,137.51,,-0.042
127.86,137.69,,-0.042
127.88,137.88,,-0.042
127.90,138.06,,-0.042
127.92,138.24,,-0.042
127.94,138.43,,-0.042
127.96,138.61,,-0.042
127.98,138.80,,-0.042
127.99,138.98,,-0.042
128.01,139.16,,-0.042
128.03,139.35,,-0.042
128.05,139.53,,-0.042
128.07,139.71,,-0.041
128.09,139.90,,-0.041
128.10,140.08,,-0.041
128.12,140.26,,-0.041
128.14,140.45,,-0.041
128.16,140.63,,-0.041
128.18,140.81,,-0.041
128.20,141.00,,-0.041
128.21,141.18,,-0.041
128.23,141.36,,-0.041
128.25,141.55,,-0.041
128.27,141.73,,-0.041
128.29,141.91,,-0.041
128.30,142.10,,-0.041
128.32,142.28,,-0.041
128.34,142.46,,-0.041
128.36,142.65,,-0.041
128.38,142.83,,-0.041
128.40,143.01,,-0.041
128.41,143.20,,-0.041
128.43,143.38,,-0.041
128.45,143.57,,-0.041
128.47,143.75,,-0.041
128.49,143.93,,-0.041
128.51,144.12,,-0.041
128.53,144.30,,-0.041
128.54,144.48,,-0.041
128.56,144.67,,-0.041
128.58,144.85,,-0.041
128.60,145.03,,-0.040
128.62,145.22,,-0.040
128.64,145.40,,-0.040
128.65,145.58,,-0.040
128.67,145.77,,-0.040
128.69,145.95,,-0.040
128.71,146.13,,-0.040
128.73,146.32,,-0.040
128.75,146.50,,-0.040
128.76,146.68,,-0.040
128.78,146.87,,-0.040
128.80,147.05,,-0.040
128.82,147.23,,-0.040
128.84,147.42,,-0.040
128.85,147.60,,-0.040
128.87,147.78,,-0.039
128.89,147.97,,-0.039
128.91,148.15,,-0.039
128.93,148.33,,-0.039
128.95,148.52,,-0.039
128.96,148.70,,-0.039
128.98,148.89,,-0.039
129.00,149.07,,-0.039
129.02,149.25,,-0.039
129.04,149.44,,-0.039
129.06,149.62,,-0.039
129.08,149.80,,-0.039
129.09,149.99,,-0.039
129.11,150.17,,-0.039
129.13,150.35,,-0.039
129.15,150.54,,-0.039
129.17,150.72,,-0.039
129.19,150.90,,-0.039
129.20,151.09,,-0.039
129.22,151.27,,-0.039
129.24,151.45,,-0.039
129.26,151.64,,-0.039
129.28,151.82,,-0.039
129.30,152.01,,-0.039
129.31,152.19,,-0.039
129.33,152.37,,-0.039
129.35,152.56,,-0.039
129.37,152.74,,-0.039
129.39,152.92,,-0.039
129.40,153.11,,-0.038
129.42,153.29,,-0.038
129.44,153.47,,-0.038
129.46,153.66,,-0.038
129.48,153.84,,-0.038
129.50,154.02,,-0.038
129.51,154.21,,-0.038
129.53,154.39,,-0.038
129.55,154.57,,-0.038
129.57,154.75,,-0.038
129.59,154.94,,-0.038
129.61,155.12,,-0.038
129.63,155.30,,-0.038
129.64,155.49,,-0.038
129.66,155.67,,-0.038
129.68,155.85,,-0.038
129.70,156.04,,-0.038
129.72,156.22,,-0.038
129.74,156.41,,-0.038
129.75,156.59,,-0.038
129.77,156.77,,-0.038
129.79,156.95,,-0.038
129.81,157.14,,-0.038
129.83,157.32,,-0.038
129.85,157.51,,-0.038
129.86,157.69,,-0.038
129.88,157.87,,-0.038
129.90,158.06,,-0.037
129.92,158.24,,-0.038
129.94,158.42,,-0.037
129.95,158.61,,-0.037
129.97,158.79,,-0.037
129.99,158.98,,-0.037
130.01,159.16,,-0.037
130.03,159.34,,-0.037
130.05,159.53,,-0.037
130.06,159.71,,-0.037
130.08,159.89,,-0.037
130.10,160.08,,-0.037
130.12,160.26,,-0.037
130.14,160.44,,-0.037
130.16,160.63,,-0.037
130.18,160.81,,-0.037
130.19,160.99,,-0.037
130.21,161.18,,-0.037
130.23,161.36,,-0.037
130.25,161.54,,-0.037
130.27,161.73,,-0.037
130.29,161.91,,-0.037
130.30,162.09,,-0.037
130.32,162.28,,-0.037
130.34,162.46,,-0.037
130.36,162.64,,-0.037
130.38,162.83,,-0.037
130.40,163.01,,-0.037
130.41,163.19,,-0.037
130.43,163.38,,-0.037
130.45,163.56,,-0.037
130.47,163.74,,-0.037
130.49,163.93,,-0.038
130.50,164.11,,-0.037
130.52,164.30,,-0.038
130.54,164.48,,-0.038
130.56,164.66,,-0.037
130.58,164.84,,-0.037
130.60,165.03,,-0.037
130.61,165.21,,-0.037
130.63,165.39,,-0.037
130.65,165.58,,-0.037
130.67,165.76,,-0.037
130.69,165.95,,-0.037
130.71,166.13,,-0.037
130.73,166.31,,-0.037
130.74,166.50,,-0.037
130.76,166.68,,-0.037
130.78,166.86,,-0.037
130.80,167.05,,-0.037
130.82,167.23,,-0.037
130.84,167.41,,-0.037
130.85,167.60,,-0.037
130.87,167.78,,-0.037
130.89,167.96,,-0.037
130.91,168.15,,-0.037
130.93,168.33,,-0.037
130.95,168.51,,-0.037
130.96,168.70,,-0.037
130.98,168.88,,-0.037
131.00,169.06,,-0.037
131.02,169.25,,-0.037
131.04,169.43,,-0.037
131.05,169.61,,-0.037
131.07,169.80,,-0.037
131.09,169.98,,-0.037
131.11,170.16,,-0.037
131.13,170.35,,-0.037
131.15,170.53,,-0.037
131.16,170.71,,-0.036
131.18,170.90,,-0.037
131.20,171.08,,-0.037
131.22,171.26,,-0.036
131.24,171.45,,-0.036
131.26,171.63,,-0.036
131.28,171.81,,-0.036
131.29,172.00,,-0.036
131.31,172.18,,-0.036
131.33,172.36,,-0.036
131.35,172.55,,-0.036
131.37,172.73,,-0.036
131.39,172.92,,-0.036
131.40,173.10,,-0.036
131.42,173.28,,-0.036
131.44,173.47,,-0.035
131.46,173.65,,-0.035
131.48,173.83,,-0.035
131.50,174.02,,-0.035
131.51,174.20,,-0.035
131.53,174.38,,-0.035
131.55,174.57,,-0.035
131.57,174.75,,-0.035
131.59,174.93,,-0.035
131.60,175.12,,-0.035
131.62,175.30,,-0.035
131.64,175.48,,-0.035
131.66,175.67,,-0.035
131.68,175.85,,-0.034
131.70,176.03,,-0.034
131.71,176.22,,-0.034
131.73,176.40,,-0.034
131.75,176.58,,-0.034
131.77,176.77,,-0.034
131.79,176.95,,-0.034
131.81,177.13,,-0.034
131.83,177.32,,-0.034
131.84,177.50,,-0.034
131.86,177.68,,-0.034
131.88,177.87,,-0.033
131.90,178.05,,-0.033
131.92,178.23,,-0.033
131.94,178.42,,-0.033
131.95,178.60,,-0.033
131.97,178.79,,-0.033
131.99,178.97,,-0.033
132.01,179.15,,-0.033
132.03,179.34,,-0.033
132.05,179.52,,-0.033
132.06,179.70,,-0.033
132.08,179.89,,-0.033
132.10,180.07,,-0.033
132.12,180.25,,-0.033
132.14,180.44,,-0.033
132.15,180.62,,-0.033
132.17,180.80,,-0.033
132.19,180.99,,-0.033
132.21,181.17,,-0.033
132.23,181.35,,-0.033
132.25,181.54,,-0.033
132.26,181.72,,-0.033
132.28,181.90,,-0.033
132.30,182.09,,-0.033
132.32,182.27,,-0.033
132.34,182.45,,-0.033
132.36,182.64,,-0.033
132.38,182.82,,-0.033
132.39,183.00,,-0.033
132.41,183.19,,-0.033
132.43,183.37,,-0.032
132.45,183.55,,-0.033
132.47,183.74,,-0.033
132.49,183.92,,-0.033
132.50,184.11,,-0.032
132.52,184.29,,-0.032
132.54,184.47,,-0.032
132.56,184.66,,-0.032
132.58,184.84,,-0.032
132.60,185.02,,-0.032
132.61,185.21,,-0.032
132.63,185.39,,-0.032
132.65,185.57,,-0.032
132.67,185.76,,-0.032
132.69,185.94,,-0.032
132.70,186.12,,-0.032
132.72,186.31,,-0.032
132.74,186.49,,-0.032
132.76,186.67,,-0.031
132.78,186.86,,-0.031
132.80,187.04,,-0.031
132.81,187.22,,-0.031
132.83,187.41,,-0.031
132.85,187.59,,-0.031
132.87,187.77,,-0.031
132.89,187.96,,-0.031
132.91,188.14,,-0.031
132.93,188.32,,-0.031
132.94,188.51,,-0.030
132.96,188.69,,-0.030
132.98,188.87,,-0.030
133.00,189.06,,-0.030
133.02,189.24,,-0.030
133.04,189.42,,-0.030
133.05,189.61,,-0.030
133.07,189.79,,-0.030
133.09,189.97,,-0.030
133.11,190.16,,-0.030
133.13,190.34,,-0.029
133.15,190.52,,-0.029
133.16,190.71,,-0.029
133.18,190.89,,-0.029
133.20,191.07,,-0.029
133.22,191.26,,-0.029
133.24,191.44,,-0.029
133.25,191.62,,-0.029
133.27,191.81,,-0.029
133.29,191.99,,-0.029
133.31,192.17,,-0.028
133.33,192.36,,-0.029
133.35,192.54,,-0.028
133.36,192.73,,-0.028
133.38,192.91,,-0.028
133.40,193.09,,-0.028
133.42,193.28,,-0.028
133.44,193.46,,-0.028
133.46,193.64,,-0.028
133.48,193.83,,-0.028
133.49,194.01,,-0.028
133.51,194.19,,-0.028
133.53,194.38,,-0.028
133.55,194.56,,-0.028
133.57,194.74,,-0.027
133.59,194.93,,-0.027
133.60,195.11,,-0.027
133.62,195.29,,-0.027
133.64,195.48,,-0.027
133.66,195.66,,-0.027
133.68,195.84,,-0.027
133.70,196.03,,-0.027
133.71,196.21,,-0.027
133.73,196.39,,-0.027
133.75,196.58,,-0.027
133.77,196.76,,-0.027
133.79,196.94,,-0.027
133.80,197.13,,-0.027
133.82,197.31,,-0.027
133.84,197.50,,-0.027
133.86,197.68,,-0.027
133.88,197.86,,-0.027
133.90,198.04,,-0.027
133.91,198.23,,-0.027
133.93,198.41,,
133.95,198.60,,
133.97,198.78,,
133.99,,,