File: DSC/2025_04_19_CBD_n60C_150C_5Cmin_x3.csv
Filename,2025_04_19_CBDa_n60C_150C_5Cmin_x3(1)
Instrument name,DSC2A-00468 (192.168.1.100)
Operator,Yarger
rundate,4/19/2025
Sample name,2025_04_19_CBDa_n60C_150C_5Cmin_x3
proceduresegments,Data Off ; Equilibrate -60.00 °C; Data On ; Ramp 5.00 °C/min to 150.00 °C; Data Off ; Isothermal 0.1 min; Data On ; Ramp 10.00 °C/min to -60.00 °C; Data Off ; Isothermal 1.0 min; Data On ; Ramp 5.00 °C/min to 150.00 °C; Data Off ; Isothermal 0.1 min; Data On ; Ramp 10.00 °C/min to -60.00 °C; Data Off ; Isothermal 1.0 min; Data On ; Ramp 5.00 °C/min to 30.00 °C
[File Parameters]
Run date,4/19/2025 12:19:23 PM
Trios version,5.1.1.46572
Original File Name,
Current File Name,D:\DSC2500\JYarger\2025_04_19_CBDa_n60C_150C_5Cmin_x3(1).tri
[Procedure]
Procedure Name,CBD_n60_150C_5Cmin_x3
Sample Name,2025_04_19_CBDa_n60C_150C_5Cmin_x3
Sample Mass,3.55 mg
Reference Sample Mass,0 mg
Pan Mass,53.51 mg
Pan Number,40
Reference Pan Mass,53.66 mg
Reference Pan Number,46
Pan Type,Tzero Aluminum Hermetic
Comments,Hermetic Sealed Al DSC Consumables Pan/Lids.
Project Name,CA
Operator,Yarger
Test,Custom
Unload Max Temperature,30
Unload Min Temperature,30
Load Max Temperature,30
Load Min Temperature,30
Stop on Gas Flow Error,Yes
[Signal List]
Signal #1,Time (min)
Signal #2,Temperature (°C)
Signal #3,Heat Flow (mW)
Signal #4,Delta T (µV)
Signal #5,Delta Tzero (µV)
Signal #6,Tzero Temperature (°C)
Signal #7,Cell Purge (mL/min)
Signal #8,Heater Temp (°C)
Signal #9,Power Delivered (W)
Signal #10,Reference Junction Temperature (°C)
Signal #11,Flange Temperature (°C)
Signal #12,Heat Flow Phase (rad)
Signal #13,Total Heat Capacity (J/°C)
Signal #14,Heat Capacity (J/°C)
[Configuration]
Company Name,ASU
Instrument Name,DSC2A-00468
Instrument Type,DSC2500
Serial Number,DSC2A-00468
IP,192.168.1.100
Location of Instrument,MRRC
DisplayType,Unknown
Sample Interval ,0.1 s/pt
Selected Heat Flow,T4P
Exotherm Direction,Down
Cell Serial,DRC2-00792
Lid Type,Standard
Cooler,RCS 90
Leave Cooler on at End of Sequence,On
Gas 2,Nitrogen
Gas Selected,Channel 1
Flow Rate,50 mL/min
Secondary Purge,On
Licensed Heat Flow,Heat Flow T4P
Modulation Licensed,Yes
[Versions]
Common IDD Version,1
Cortex Version,VER 2.10.2.31
Driver,5.0.0.6
GDM Version,1.0.3.3
TouchscreenVersion,1.0.0.16145
FEP Version,1.2.1.21
FEP Bootloader,2.0.0.5
AutoSampler Version,2.1.1.26
Auto Sampler Bootloader,2.0.0.5
FCM Version,1.1.0.3
FCM Bootloader,2.0.0.5
[Experiment Logs]
Experiment Log Entry # 1,Data On set to 0
Experiment Log Entry # 3,Equilibrate Segment -60 (C) Started
Experiment Log Entry # 5,Air Cool is off.
Experiment Log Entry # 7,Data On set to 1
Experiment Log Entry # 9,Ramp Segment 5 C/min to 150 Started
Experiment Log Entry # 11,Auto sampler has detected that FEP has gone offline
Experiment Log Entry # 13,Data On set to 0
Experiment Log Entry # 15,Isothermal Segment 0.1 min started
Experiment Log Entry # 17,Data On set to 1
Experiment Log Entry # 19,Ramp Segment 10 C/min to -60 Started
Experiment Log Entry # 21,Data On set to 0
Experiment Log Entry # 23,Isothermal Segment 1 min started
Experiment Log Entry # 25,Data On set to 1
Experiment Log Entry # 27,Ramp Segment 5 C/min to 150 Started
Experiment Log Entry # 29,Data On set to 0
Experiment Log Entry # 31,Isothermal Segment 0.1 min started
Experiment Log Entry # 33,Data On set to 1
Experiment Log Entry # 35,Ramp Segment 10 C/min to -60 Started
Experiment Log Entry # 37,Data On set to 0
Experiment Log Entry # 39,Isothermal Segment 1 min started
Experiment Log Entry # 41,Data On set to 1
Experiment Log Entry # 43,Ramp Segment 5 C/min to 30 Started
[Method Log]
Method Log Entry # 1,Data Off
Method Log Entry # 2,Equilibrate -60 °C
Method Log Entry # 3,Data On
Method Log Entry # 4,(Ramp 294663) Ramp 5 °C/minute to 150 °C
Method Log Entry # 5,Data Off
Method Log Entry # 6,Isothermal 0.1 minutes
Method Log Entry # 7,Data On
Method Log Entry # 8,(Ramp 294667) Ramp 10 °C/minute to -60 °C
Method Log Entry # 9,Data Off
Method Log Entry # 10,Isothermal 1 minutes
Method Log Entry # 11,Data On
Method Log Entry # 12,(Ramp 294671) Ramp 5 °C/minute to 150 °C
Method Log Entry # 13,Data Off
Method Log Entry # 14,Isothermal 0.1 minutes
Method Log Entry # 15,Data On
Method Log Entry # 16,(Ramp 294675) Ramp 10 °C/minute to -60 °C
Method Log Entry # 17,Data Off
Method Log Entry # 18,Isothermal 1 minutes
Method Log Entry # 19,Data On
Method Log Entry # 20,(Ramp 294679) Ramp 5 °C/minute to 30 °C
Cell Serial,DRC2-00792
[T1 Calibration]
Slope,-0.008529666
Offset,9.636258
Initial Temperature,98.23
GUID,f8bfdadc-4977-4fdf-ba6d-0ba9134940c3
[TZero Calibration]
Date Applied,11/29/2022 4:06:13 PM
Description,From -89.059 °C to 396.009 °C at 20.000°C/min
Gas Type,Nitrogen
Pan Type,None
Source Files 1,C:\Users\yargerlab\Desktop\DSC Data\General\TZero_calibration_11_29_22_2nd(2).tri
Source Files 2,C:\Users\yargerlab\Desktop\DSC Data\General\TZero_calibration_11_29_22_2nd(3).tri
Delta T Offset,13.05235
Delta T Slope,-0.007271007
Delta T0 Offset,-13.69128
Delta T0 Slope,0.06063341
[Temperature Calibration]
Date Applied,11/29/2022 7:12:28 PM
Description,From 106.590 °C to 186.590 °C at 10.000°C/min
Gas Type,Nitrogen
Pan Type,Tzero Aluminum Hermetic
Source Files 1,C:\Users\yargerlab\Desktop\DSC Data\General\Indium(6).tri
Measured 1,157.391
Known 1,156.598
[Cell Constant Calibration]
Date Applied,11/29/2022 7:12:29 PM
Description,From 106.590 °C to 186.590 °C at 10.000°C/min
Gas Type,Nitrogen
Pan Type,Tzero Aluminum Hermetic
Source Files 1,C:\Users\yargerlab\Desktop\DSC Data\General\Indium(6).tri
T4P KCell,1.006051
Onset Slope,63.26126 mW/°C
[Direct Cp Calibration]
Date Applied,11/30/2022 11:04:51 AM
Description,From -79.983 °C to 298.409 °C at 10.000°C/min
Gas Type,Nitrogen
Pan Type,Tzero Aluminum Hermetic
Source Files 1,C:\Users\yargerlab\Desktop\DSC Data\General\Sapphire_Heat_Capacity_11_30_22.tri
[Rev Cp Calibration]
Date Applied,11/30/2022 1:58:51 PM
Description,From -79.996 °C to 292.812 °C at 3.000°C/min
Gas Type,Nitrogen
Pan Type,Tzero Aluminum Hermetic
Source Files 1,C:\Users\yargerlab\Desktop\DSC Data\General\Sapphire_MDSC_Calibration_11_30_22.tri
[step]
Ramp 5.00 °C/min to 150.00 °C
Time,Temperature,Heat Flow (Normalized)
min,°C,W/g
0.00,-59.68,-0.054
0.03,-59.70,-0.054
0.06,-59.70,-0.043
0.08,-59.68,-0.038
0.11,-59.63,-0.033
0.14,-59.56,-0.023
0.17,-59.46,-0.009
0.20,-59.36,0.008
0.23,-59.25,0.024
0.26,-59.13,0.037
0.28,-59.01,0.046
0.31,-58.89,0.054
0.34,-58.76,0.061
0.37,-58.63,0.065
0.40,-58.50,0.070
0.43,-58.36,0.073
0.45,-58.23,0.076
0.48,-58.10,0.077
0.51,-57.96,0.079
0.54,-57.83,0.080
0.57,-57.69,0.081
0.60,-57.55,0.081
0.62,-57.42,0.082
0.65,-57.28,0.083
0.68,-57.14,0.084
0.71,-57.00,0.085
0.74,-56.86,0.085
0.77,-56.72,0.086
0.79,-56.59,0.086
0.82,-56.45,0.086
0.85,-56.31,0.087
0.88,-56.17,0.087
0.91,-56.03,0.087
0.93,-55.89,0.088
0.96,-55.75,0.088
0.99,-55.61,0.088
1.02,-55.47,0.088
1.05,-55.33,0.088
1.08,-55.19,0.088
1.11,-55.05,0.089
1.13,-54.91,0.089
1.16,-54.77,0.089
1.19,-54.63,0.089
1.22,-54.49,0.089
1.25,-54.35,0.089
1.28,-54.21,0.089
1.30,-54.06,0.089
1.33,-53.93,0.089
1.36,-53.78,0.088
1.39,-53.64,0.088
1.42,-53.50,0.088
1.44,-53.36,0.088
1.47,-53.22,0.088
1.50,-53.08,0.088
1.53,-52.94,0.088
1.56,-52.80,0.088
1.59,-52.66,0.088
1.62,-52.52,0.088
1.64,-52.38,0.088
1.67,-52.23,0.088
1.70,-52.09,0.088
1.73,-51.95,0.088
1.76,-51.81,0.088
1.78,-51.67,0.088
1.81,-51.53,0.088
1.84,-51.38,0.088
1.87,-51.24,0.087
1.90,-51.10,0.087
1.93,-50.96,0.087
1.96,-50.82,0.087
1.98,-50.68,0.087
2.01,-50.54,0.087
2.04,-50.40,0.087
2.07,-50.25,0.087
2.10,-50.11,0.087
2.13,-49.97,0.087
2.15,-49.83,0.087
2.18,-49.69,0.087
2.21,-49.55,0.087
2.24,-49.41,0.087
2.27,-49.26,0.087
2.29,-49.12,0.087
2.32,-48.98,0.087
2.35,-48.84,0.087
2.38,-48.70,0.087
2.41,-48.56,0.087
2.44,-48.42,0.086
2.46,-48.27,0.086
2.49,-48.13,0.086
2.52,-47.99,0.086
2.55,-47.85,0.086
2.58,-47.71,0.086
2.61,-47.57,0.086
2.64,-47.42,0.086
2.66,-47.28,0.086
2.69,-47.14,0.086
2.72,-47.00,0.086
2.75,-46.86,0.086
2.78,-46.72,0.086
2.81,-46.57,0.086
2.83,-46.43,0.086
2.86,-46.29,0.086
2.89,-46.15,0.086
2.92,-46.01,0.086
2.95,-45.87,0.086
2.98,-45.72,0.086
3.00,-45.58,0.086
3.03,-45.44,0.086
3.06,-45.30,0.086
3.09,-45.16,0.086
3.12,-45.02,0.086
3.14,-44.88,0.086
3.17,-44.73,0.086
3.20,-44.59,0.086
3.23,-44.45,0.085
3.26,-44.31,0.085
3.29,-44.17,0.085
3.31,-44.03,0.085
3.34,-43.88,0.086
3.37,-43.74,0.085
3.40,-43.60,0.085
3.43,-43.46,0.085
3.46,-43.32,0.085
3.49,-43.18,0.085
3.51,-43.03,0.085
3.54,-42.89,0.085
3.57,-42.75,0.085
3.60,-42.61,0.085
3.63,-42.47,0.085
3.66,-42.33,0.085
3.68,-42.18,0.085
3.71,-42.04,0.085
3.74,-41.90,0.085
3.77,-41.76,0.085
3.80,-41.62,0.085
3.83,-41.47,0.085
3.85,-41.33,0.085
3.88,-41.19,0.085
3.91,-41.05,0.085
3.94,-40.91,0.085
3.97,-40.76,0.085
3.99,-40.62,0.085
4.02,-40.48,0.085
4.05,-40.34,0.085
4.08,-40.20,0.085
4.11,-40.06,0.085
4.14,-39.91,0.085
4.16,-39.77,0.085
4.19,-39.63,0.085
4.22,-39.49,0.085
4.25,-39.35,0.085
4.28,-39.21,0.085
4.31,-39.06,0.085
4.34,-38.92,0.085
4.36,-38.78,0.085
4.39,-38.64,0.085
4.42,-38.50,0.085
4.45,-38.35,0.085
4.48,-38.21,0.085
4.50,-38.07,0.085
4.53,-37.93,0.085
4.56,-37.79,0.085
4.59,-37.65,0.085
4.62,-37.50,0.085
4.65,-37.36,0.085
4.68,-37.22,0.085
4.70,-37.08,0.085
4.73,-36.94,0.085
4.76,-36.79,0.085
4.79,-36.65,0.085
4.82,-36.51,0.085
4.85,-36.37,0.085
4.87,-36.23,0.085
4.90,-36.09,0.085
4.93,-35.94,0.085
4.96,-35.80,0.085
4.99,-35.66,0.085
5.01,-35.52,0.085
5.04,-35.38,0.085
5.07,-35.23,0.085
5.10,-35.09,0.085
5.13,-34.95,0.085
5.16,-34.81,0.085
5.19,-34.67,0.085
5.21,-34.52,0.085
5.24,-34.38,0.085
5.27,-34.24,0.085
5.30,-34.10,0.085
5.33,-33.96,0.085
5.35,-33.82,0.085
5.38,-33.67,0.085
5.41,-33.53,0.085
5.44,-33.39,0.085
5.47,-33.25,0.085
5.50,-33.11,0.085
5.53,-32.96,0.085
5.55,-32.82,0.085
5.58,-32.68,0.085
5.61,-32.54,0.085
5.64,-32.40,0.085
5.67,-32.25,0.085
5.70,-32.11,0.085
5.72,-31.97,0.085
5.75,-31.83,0.085
5.78,-31.69,0.085
5.81,-31.55,0.085
5.84,-31.40,0.085
5.86,-31.26,0.085
5.89,-31.12,0.085
5.92,-30.98,0.085
5.95,-30.84,0.085
5.98,-30.70,0.085
6.01,-30.55,0.085
6.04,-30.41,0.085
6.06,-30.27,0.085
6.09,-30.13,0.085
6.12,-29.98,0.085
6.15,-29.84,0.085
6.18,-29.70,0.085
6.20,-29.56,0.085
6.23,-29.42,0.085
6.26,-29.27,0.085
6.29,-29.13,0.085
6.32,-28.99,0.085
6.35,-28.85,0.085
6.38,-28.71,0.085
6.40,-28.57,0.085
6.43,-28.43,0.085
6.46,-28.28,0.085
6.49,-28.14,0.085
6.52,-28.00,0.085
6.55,-27.86,0.085
6.57,-27.72,0.085
6.60,-27.57,0.085
6.63,-27.43,0.085
6.66,-27.29,0.085
6.69,-27.15,0.085
6.71,-27.01,0.085
6.74,-26.87,0.085
6.77,-26.73,0.085
6.80,-26.58,0.085
6.83,-26.44,0.085
6.86,-26.30,0.085
6.89,-26.16,0.085
6.91,-26.02,0.085
6.94,-25.87,0.085
6.97,-25.73,0.085
7.00,-25.59,0.085
7.03,-25.45,0.085
7.05,-25.31,0.085
7.08,-25.17,0.085
7.11,-25.02,0.085
7.14,-24.88,0.085
7.17,-24.74,0.085
7.20,-24.60,0.085
7.23,-24.46,0.085
7.25,-24.31,0.085
7.28,-24.17,0.085
7.31,-24.03,0.085
7.34,-23.89,0.085
7.37,-23.75,0.085
7.40,-23.61,0.085
7.42,-23.46,0.085
7.45,-23.32,0.085
7.48,-23.18,0.085
7.51,-23.04,0.085
7.54,-22.90,0.085
7.56,-22.76,0.085
7.59,-22.61,0.085
7.62,-22.47,0.085
7.65,-22.33,0.085
7.68,-22.19,0.085
7.71,-22.05,0.085
7.74,-21.90,0.085
7.76,-21.76,0.085
7.79,-21.62,0.085
7.82,-21.48,0.085
7.85,-21.33,0.085
7.88,-21.19,0.085
7.90,-21.05,0.085
7.93,-20.91,0.085
7.96,-20.77,0.085
7.99,-20.63,0.085
8.02,-20.49,0.085
8.05,-20.34,0.085
8.08,-20.20,0.085
8.10,-20.06,0.085
8.13,-19.92,0.085
8.16,-19.78,0.085
8.19,-19.63,0.085
8.22,-19.49,0.085
8.25,-19.35,0.085
8.27,-19.21,0.085
8.30,-19.07,0.085
8.33,-18.93,0.085
8.36,-18.78,0.085
8.39,-18.64,0.085
8.41,-18.50,0.085
8.44,-18.36,0.085
8.47,-18.22,0.085
8.50,-18.07,0.085
8.53,-17.93,0.085
8.56,-17.79,0.085
8.58,-17.65,0.085
8.61,-17.51,0.085
8.64,-17.37,0.085
8.67,-17.23,0.085
8.70,-17.08,0.085
8.73,-16.94,0.085
8.75,-16.80,0.085
8.78,-16.66,0.085
8.81,-16.52,0.085
8.84,-16.37,0.085
8.87,-16.23,0.085
8.90,-16.09,0.085
8.93,-15.95,0.085
8.95,-15.81,0.085
8.98,-15.67,0.085
9.01,-15.52,0.085
9.04,-15.38,0.085
9.07,-15.24,0.085
9.10,-15.10,0.085
9.12,-14.96,0.085
9.15,-14.81,0.085
9.18,-14.67,0.085
9.21,-14.53,0.085
9.24,-14.39,0.085
9.27,-14.25,0.085
9.29,-14.11,0.085
9.32,-13.96,0.085
9.35,-13.82,0.085
9.38,-13.68,0.085
9.41,-13.54,0.085
9.43,-13.40,0.085
9.46,-13.26,0.085
9.49,-13.11,0.085
9.52,-12.97,0.085
9.55,-12.83,0.085
9.58,-12.69,0.085
9.60,-12.54,0.085
9.63,-12.41,0.085
9.66,-12.26,0.085
9.69,-12.12,0.085
9.72,-11.98,0.085
9.75,-11.84,0.085
9.78,-11.69,0.085
9.80,-11.55,0.085
9.83,-11.41,0.085
9.86,-11.27,0.085
9.89,-11.13,0.085
9.92,-10.99,0.085
9.95,-10.85,0.085
9.97,-10.70,0.085
10.00,-10.56,0.085
10.03,-10.42,0.085
10.06,-10.28,0.085
10.09,-10.13,0.085
10.12,-9.99,0.085
10.14,-9.85,0.085
10.17,-9.71,0.085
10.20,-9.57,0.085
10.23,-9.43,0.085
10.26,-9.28,0.085
10.28,-9.14,0.085
10.31,-9.00,0.085
10.34,-8.86,0.085
10.37,-8.72,0.086
10.40,-8.58,0.086
10.43,-8.43,0.086
10.45,-8.29,0.085
10.48,-8.15,0.085
10.51,-8.01,0.085
10.54,-7.87,0.085
10.57,-7.72,0.085
10.60,-7.58,0.085
10.63,-7.44,0.086
10.65,-7.30,0.085
10.68,-7.16,0.085
10.71,-7.02,0.086
10.74,-6.87,0.086
10.77,-6.73,0.086
10.80,-6.59,0.086
10.82,-6.45,0.086
10.85,-6.31,0.086
10.88,-6.17,0.086
10.91,-6.02,0.086
10.94,-5.88,0.086
10.97,-5.74,0.086
10.99,-5.60,0.086
11.02,-5.46,0.086
11.05,-5.31,0.086
11.08,-5.17,0.086
11.11,-5.03,0.086
11.13,-4.89,0.086
11.16,-4.75,0.086
11.19,-4.61,0.086
11.22,-4.46,0.086
11.25,-4.32,0.086
11.28,-4.18,0.086
11.30,-4.04,0.086
11.33,-3.90,0.086
11.36,-3.76,0.086
11.39,-3.61,0.086
11.42,-3.47,0.086
11.45,-3.33,0.086
11.48,-3.19,0.086
11.50,-3.05,0.086
11.53,-2.91,0.086
11.56,-2.76,0.086
11.59,-2.62,0.086
11.62,-2.48,0.086
11.65,-2.34,0.086
11.67,-2.20,0.086
11.70,-2.05,0.086
11.73,-1.91,0.086
11.76,-1.77,0.086
11.79,-1.63,0.086
11.82,-1.49,0.086
11.84,-1.34,0.086
11.87,-1.20,0.087
11.90,-1.06,0.087
11.93,-0.92,0.087
11.96,-0.78,0.087
11.98,-0.64,0.087
12.01,-0.49,0.087
12.04,-0.35,0.087
12.07,-0.21,0.087
12.10,-0.07,0.087
12.13,0.07,0.087
12.15,0.21,0.087
12.18,0.36,0.087
12.21,0.50,0.087
12.24,0.64,0.087
12.27,0.78,0.087
12.30,0.92,0.087
12.33,1.06,0.087
12.35,1.21,0.087
12.38,1.35,0.087
12.41,1.49,0.087
12.44,1.63,0.087
12.47,1.77,0.087
12.50,1.92,0.087
12.52,2.06,0.087
12.55,2.20,0.087
12.58,2.34,0.087
12.61,2.48,0.087
12.64,2.62,0.087
12.67,2.77,0.087
12.69,2.91,0.087
12.72,3.05,0.087
12.75,3.19,0.087
12.78,3.33,0.087
12.81,3.47,0.087
12.83,3.62,0.087
12.86,3.76,0.087
12.89,3.90,0.087
12.92,4.04,0.087
12.95,4.18,0.087
12.98,4.33,0.087
13.00,4.47,0.087
13.03,4.61,0.088
13.06,4.75,0.087
13.09,4.89,0.088
13.12,5.04,0.088
13.15,5.18,0.088
13.18,5.32,0.088
13.20,5.46,0.088
13.23,5.60,0.088
13.26,5.75,0.088
13.29,5.89,0.088
13.32,6.03,0.088
13.35,6.17,0.088
13.37,6.31,0.088
13.40,6.45,0.088
13.43,6.60,0.088
13.46,6.74,0.088
13.49,6.88,0.088
13.52,7.02,0.088
13.54,7.16,0.088
13.57,7.30,0.088
13.60,7.44,0.088
13.63,7.59,0.088
13.66,7.73,0.088
13.68,7.87,0.088
13.71,8.01,0.088
13.74,8.15,0.088
13.77,8.29,0.089
13.80,8.44,0.089
13.83,8.58,0.089
13.85,8.72,0.089
13.88,8.86,0.089
13.91,9.00,0.089
13.94,9.15,0.089
13.97,9.29,0.089
14.00,9.43,0.089
14.03,9.57,0.089
14.05,9.71,0.089
14.08,9.86,0.089
14.11,10.00,0.089
14.14,10.14,0.089
14.17,10.28,0.089
14.20,10.42,0.089
14.22,10.57,0.089
14.25,10.71,0.089
14.28,10.85,0.089
14.31,10.99,0.089
14.34,11.13,0.089
14.37,11.27,0.089
14.39,11.42,0.089
14.42,11.56,0.089
14.45,11.70,0.089
14.48,11.84,0.089
14.51,11.98,0.089
14.53,12.12,0.089
14.56,12.26,0.089
14.59,12.41,0.089
14.62,12.55,0.089
14.65,12.69,0.089
14.68,12.83,0.090
14.70,12.97,0.090
14.73,13.12,0.090
14.76,13.26,0.090
14.79,13.40,0.090
14.82,13.54,0.090
14.85,13.68,0.090
14.88,13.82,0.090
14.90,13.97,0.090
14.93,14.11,0.090
14.96,14.25,0.090
14.99,14.39,0.090
15.02,14.53,0.090
15.05,14.68,0.090
15.07,14.82,0.090
15.10,14.96,0.090
15.13,15.10,0.090
15.16,15.24,0.090
15.19,15.39,0.090
15.22,15.53,0.090
15.24,15.67,0.090
15.27,15.81,0.090
15.30,15.95,0.090
15.33,16.09,0.090
15.36,16.24,0.090
15.38,16.38,0.090
15.41,16.52,0.090
15.44,16.66,0.090
15.47,16.80,0.090
15.50,16.94,0.090
15.53,17.09,0.090
15.55,17.23,0.091
15.58,17.37,0.091
15.61,17.51,0.091
15.64,17.65,0.091
15.67,17.79,0.091
15.70,17.94,0.091
15.73,18.08,0.091
15.75,18.22,0.091
15.78,18.36,0.091
15.81,18.50,0.091
15.84,18.64,0.091
15.87,18.79,0.091
15.90,18.93,0.091
15.92,19.07,0.092
15.95,19.21,0.091
15.98,19.35,0.092
16.01,19.49,0.092
16.04,19.64,0.092
16.07,19.78,0.092
16.09,19.92,0.092
16.12,20.06,0.092
16.15,20.20,0.092
16.18,20.35,0.092
16.21,20.49,0.092
16.23,20.63,0.092
16.26,20.77,0.092
16.29,20.91,0.092
16.32,21.05,0.092
16.35,21.20,0.092
16.38,21.34,0.092
16.40,21.48,0.092
16.43,21.62,0.093
16.46,21.76,0.093
16.49,21.90,0.093
16.52,22.05,0.093
16.55,22.19,0.093
16.58,22.33,0.093
16.60,22.47,0.093
16.63,22.61,0.093
16.66,22.76,0.093
16.69,22.90,0.093
16.72,23.04,0.093
16.75,23.18,0.093
16.77,23.32,0.093
16.80,23.46,0.093
16.83,23.61,0.093
16.86,23.75,0.093
16.89,23.89,0.093
16.92,24.03,0.093
16.94,24.17,0.093
16.97,24.31,0.094
17.00,24.45,0.094
17.03,24.60,0.094
17.06,24.74,0.094
17.08,24.88,0.094
17.11,25.02,0.094
17.14,25.16,0.094
17.17,25.31,0.094
17.20,25.45,0.094
17.23,25.59,0.094
17.26,25.73,0.094
17.28,25.87,0.094
17.31,26.02,0.094
17.34,26.16,0.094
17.37,26.30,0.094
17.40,26.44,0.094
17.43,26.58,0.094
17.45,26.72,0.094
17.48,26.87,0.094
17.51,27.01,0.095
17.54,27.15,0.095
17.57,27.29,0.095
17.59,27.43,0.095
17.62,27.57,0.095
17.65,27.72,0.095
17.68,27.86,0.095
17.71,28.00,0.095
17.74,28.14,0.095
17.77,28.28,0.095
17.79,28.43,0.095
17.82,28.57,0.095
17.85,28.71,0.095
17.88,28.85,0.095
17.91,28.99,0.095
17.93,29.13,0.095
17.96,29.28,0.095
17.99,29.42,0.095
18.02,29.56,0.095
18.05,29.70,0.095
18.08,29.84,0.095
18.11,29.98,0.096
18.13,30.13,0.096
18.16,30.27,0.096
18.19,30.41,0.096
18.22,30.55,0.096
18.25,30.69,0.096
18.28,30.84,0.096
18.30,30.98,0.096
18.33,31.12,0.096
18.36,31.26,0.096
18.39,31.40,0.096
18.42,31.55,0.097
18.44,31.69,0.097
18.47,31.83,0.097
18.50,31.97,0.097
18.53,32.11,0.097
18.56,32.25,0.097
18.59,32.40,0.097
18.62,32.54,0.097
18.64,32.68,0.097
18.67,32.82,0.097
18.70,32.96,0.097
18.73,33.11,0.097
18.76,33.25,0.097
18.78,33.39,0.097
18.81,33.53,0.097
18.84,33.67,0.098
18.87,33.81,0.098
18.90,33.96,0.098
18.93,34.10,0.098
18.96,34.24,0.098
18.98,34.38,0.098
19.01,34.52,0.098
19.04,34.66,0.098
19.07,34.81,0.098
19.10,34.95,0.098
19.13,35.09,0.098
19.15,35.23,0.099
19.18,35.37,0.099
19.21,35.51,0.099
19.24,35.65,0.099
19.27,35.80,0.099
19.29,35.94,0.099
19.32,36.08,0.099
19.35,36.22,0.099
19.38,36.36,0.099
19.41,36.51,0.099
19.44,36.65,0.099
19.47,36.79,0.099
19.49,36.93,0.099
19.52,37.07,0.100
19.55,37.21,0.100
19.58,37.36,0.100
19.61,37.50,0.100
19.63,37.64,0.100
19.66,37.78,0.100
19.69,37.92,0.100
19.72,38.07,0.100
19.75,38.21,0.100
19.78,38.35,0.100
19.81,38.49,0.101
19.83,38.63,0.101
19.86,38.77,0.101
19.89,38.92,0.101
19.92,39.06,0.101
19.95,39.20,0.101
19.98,39.34,0.101
20.00,39.48,0.101
20.03,39.62,0.101
20.06,39.77,0.101
20.09,39.91,0.101
20.12,40.05,0.101
20.14,40.19,0.102
20.17,40.33,0.102
20.20,40.48,0.102
20.23,40.62,0.102
20.26,40.76,0.102
20.29,40.90,0.102
20.32,41.04,0.102
20.34,41.18,0.102
20.37,41.33,0.102
20.40,41.47,0.102
20.43,41.61,0.103
20.46,41.75,0.103
20.48,41.89,0.103
20.51,42.03,0.103
20.54,42.18,0.103
20.57,42.32,0.103
20.60,42.46,0.103
20.63,42.60,0.103
20.66,42.74,0.103
20.68,42.88,0.103
20.71,43.03,0.104
20.74,43.17,0.104
20.77,43.31,0.104
20.80,43.45,0.104
20.83,43.59,0.104
20.85,43.73,0.104
20.88,43.88,0.104
20.91,44.02,0.104
20.94,44.16,0.104
20.97,44.30,0.104
20.99,44.44,0.105
21.02,44.58,0.105
21.05,44.73,0.105
21.08,44.87,0.105
21.11,45.01,0.105
21.14,45.15,0.105
21.17,45.29,0.105
21.19,45.43,0.105
21.22,45.58,0.106
21.25,45.72,0.106
21.28,45.86,0.106
21.31,46.00,0.106
21.33,46.14,0.106
21.36,46.28,0.106
21.39,46.43,0.106
21.42,46.57,0.107
21.45,46.71,0.107
21.48,46.85,0.107
21.51,46.99,0.107
21.53,47.13,0.107
21.56,47.28,0.107
21.59,47.42,0.108
21.62,47.56,0.108
21.65,47.70,0.108
21.68,47.84,0.108
21.70,47.99,0.108
21.73,48.13,0.108
21.76,48.27,0.109
21.79,48.41,0.109
21.82,48.55,0.109
21.84,48.69,0.109
21.87,48.84,0.109
21.90,48.98,0.110
21.93,49.12,0.110
21.96,49.26,0.110
21.99,49.40,0.110
22.02,49.54,0.110
22.04,49.69,0.111
22.07,49.83,0.111
22.10,49.97,0.111
22.13,50.11,0.111
22.16,50.25,0.111
22.18,50.39,0.112
22.21,50.54,0.112
22.24,50.68,0.112
22.27,50.82,0.112
22.30,50.96,0.113
22.33,51.10,0.113
22.36,51.24,0.113
22.38,51.39,0.113
22.41,51.53,0.114
22.44,51.67,0.114
22.47,51.81,0.114
22.50,51.95,0.115
22.53,52.09,0.115
22.55,52.24,0.115
22.58,52.38,0.116
22.61,52.52,0.116
22.64,52.66,0.116
22.67,52.80,0.117
22.69,52.94,0.117
22.72,53.09,0.117
22.75,53.23,0.117
22.78,53.37,0.118
22.81,53.51,0.118
22.84,53.65,0.118
22.87,53.79,0.119
22.89,53.94,0.119
22.92,54.08,0.119
22.95,54.22,0.120
22.98,54.36,0.120
23.01,54.50,0.121
23.03,54.64,0.121
23.06,54.79,0.121
23.09,54.93,0.122
23.12,55.07,0.122
23.15,55.21,0.123
23.18,55.35,0.123
23.21,55.49,0.124
23.23,55.64,0.124
23.26,55.78,0.125
23.29,55.92,0.125
23.32,56.06,0.125
23.35,56.20,0.126
23.38,56.34,0.126
23.40,56.48,0.127
23.43,56.63,0.128
23.46,56.77,0.128
23.49,56.91,0.129
23.52,57.05,0.130
23.54,57.19,0.130
23.57,57.33,0.131
23.60,57.48,0.132
23.63,57.62,0.133
23.66,57.76,0.133
23.69,57.90,0.134
23.72,58.04,0.135
23.74,58.19,0.136
23.77,58.32,0.136
23.80,58.47,0.137
23.83,58.61,0.138
23.86,58.75,0.139
23.88,58.89,0.140
23.91,59.03,0.141
23.94,59.18,0.142
23.97,59.32,0.143
24.00,59.46,0.144
24.03,59.60,0.146
24.06,59.74,0.147
24.08,59.88,0.148
24.11,60.02,0.149
24.14,60.16,0.152
24.17,60.31,0.153
24.20,60.45,0.155
24.23,60.59,0.157
24.25,60.73,0.160
24.28,60.87,0.162
24.31,61.01,0.164
24.34,61.15,0.166
24.37,61.29,0.169
24.39,61.44,0.172
24.42,61.58,0.175
24.45,61.72,0.179
24.48,61.86,0.183
24.51,62.00,0.187
24.54,62.14,0.192
24.57,62.28,0.196
24.59,62.42,0.202
24.62,62.56,0.207
24.65,62.70,0.212
24.68,62.84,0.219
24.71,62.98,0.226
24.73,63.12,0.232
24.76,63.27,0.239
24.79,63.40,0.248
24.82,63.55,0.256
24.85,63.68,0.265
24.88,63.83,0.274
24.91,63.96,0.285
24.93,64.10,0.299
24.96,64.24,0.310
24.99,64.38,0.324
25.02,64.52,0.339
25.05,64.66,0.358
25.08,64.80,0.383
25.10,64.93,0.405
25.13,65.07,0.426
25.16,65.21,0.450
25.19,65.34,0.474
25.22,65.48,0.503
25.24,65.61,0.530
25.27,65.75,0.560
25.30,65.88,0.590
25.33,66.02,0.621
25.36,66.15,0.653
25.39,66.29,0.685
25.42,66.42,0.723
25.44,66.55,0.762
25.47,66.69,0.791
25.50,66.82,0.821
25.53,66.95,0.853
25.56,67.09,0.887
25.58,67.22,0.925
25.61,67.35,0.960
25.64,67.49,0.996
25.67,67.62,1.044
25.70,67.75,1.094
25.73,67.88,1.145
25.76,68.01,1.279
25.78,68.13,1.301
25.81,68.26,1.309
25.84,68.40,1.333
25.87,68.53,1.337
25.90,68.67,1.312
25.93,68.82,1.280
25.95,68.96,1.261
25.98,69.11,1.219
26.01,69.26,1.158
26.04,69.41,1.074
26.07,69.57,1.103
26.09,69.71,1.084
26.12,69.86,0.978
26.15,70.02,0.845
26.18,70.19,0.697
26.21,70.36,0.584
26.24,70.53,0.498
26.27,70.69,0.420
26.29,70.86,0.340
26.32,71.02,0.277
26.35,71.18,0.236
26.38,71.33,0.212
26.41,71.48,0.193
26.43,71.63,0.182
26.46,71.78,0.172
26.49,71.92,0.163
26.52,72.07,0.159
26.55,72.21,0.155
26.58,72.35,0.152
26.61,72.50,0.151
26.63,72.64,0.150
26.66,72.78,0.149
26.69,72.93,0.148
26.72,73.07,0.147
26.75,73.21,0.147
26.78,73.35,0.146
26.80,73.49,0.145
26.83,73.63,0.145
26.86,73.78,0.144
26.89,73.92,0.144
26.92,74.06,0.144
26.94,74.20,0.143
26.97,74.34,0.143
27.00,74.49,0.143
27.03,74.63,0.142
27.06,74.77,0.142
27.09,74.91,0.142
27.12,75.05,0.142
27.14,75.19,0.142
27.17,75.34,0.142
27.20,75.48,0.142
27.23,75.62,0.142
27.26,75.76,0.141
27.28,75.90,0.141
27.31,76.05,0.141
27.34,76.19,0.141
27.37,76.33,0.141
27.40,76.47,0.141
27.43,76.61,0.141
27.46,76.75,0.141
27.48,76.90,0.141
27.51,77.04,0.141
27.54,77.18,0.141
27.57,77.32,0.141
27.60,77.46,0.141
27.63,77.60,0.141
27.65,77.75,0.141
27.68,77.89,0.141
27.71,78.03,0.141
27.74,78.17,0.141
27.77,78.31,0.141
27.79,78.46,0.141
27.82,78.60,0.141
27.85,78.74,0.141
27.88,78.88,0.141
27.91,79.02,0.141
27.94,79.16,0.141
27.97,79.31,0.141
27.99,79.45,0.141
28.02,79.59,0.141
28.05,79.73,0.141
28.08,79.87,0.141
28.11,80.02,0.141
28.13,80.16,0.141
28.16,80.30,0.141
28.19,80.44,0.141
28.22,80.58,0.141
28.25,80.72,0.141
28.28,80.86,0.141
28.31,81.01,0.141
28.33,81.15,0.141
28.36,81.29,0.141
28.39,81.43,0.141
28.42,81.57,0.141
28.45,81.71,0.141
28.48,81.86,0.141
28.50,82.00,0.141
28.53,82.14,0.142
28.56,82.28,0.142
28.59,82.42,0.142
28.62,82.57,0.142
28.64,82.71,0.142
28.67,82.85,0.142
28.70,82.99,0.142
28.73,83.13,0.142
28.76,83.28,0.142
28.79,83.42,0.142
28.82,83.56,0.142
28.84,83.70,0.142
28.87,83.84,0.142
28.90,83.99,0.142
28.93,84.13,0.142
28.96,84.27,0.142
28.98,84.41,0.142
29.01,84.55,0.142
29.04,84.69,0.141
29.07,84.83,0.141
29.10,84.98,0.141
29.13,85.12,0.141
29.16,85.26,0.141
29.18,85.40,0.141
29.21,85.54,0.141
29.24,85.68,0.141
29.27,85.83,0.141
29.30,85.97,0.141
29.33,86.11,0.141
29.35,86.25,0.141
29.38,86.39,0.141
29.41,86.54,0.141
29.44,86.68,0.141
29.47,86.82,0.141
29.49,86.96,0.141
29.52,87.10,0.141
29.55,87.24,0.141
29.58,87.39,0.141
29.61,87.53,0.141
29.64,87.67,0.141
29.67,87.81,0.141
29.69,87.95,0.141
29.72,88.09,0.141
29.75,88.23,0.141
29.78,88.38,0.141
29.81,88.52,0.141
29.83,88.66,0.141
29.86,88.80,0.141
29.89,88.94,0.141
29.92,89.09,0.141
29.95,89.23,0.141
29.98,89.37,0.142
30.01,89.51,0.142
30.03,89.65,0.142
30.06,89.79,0.142
30.09,89.94,0.142
30.12,90.08,0.142
30.15,90.22,0.142
30.18,90.36,0.142
30.20,90.50,0.142
30.23,90.64,0.142
30.26,90.79,0.142
30.29,90.93,0.142
30.32,91.07,0.142
30.34,91.21,0.142
30.37,91.35,0.142
30.40,91.50,0.142
30.43,91.64,0.142
30.46,91.78,0.142
30.49,91.92,0.142
30.52,92.06,0.142
30.54,92.20,0.142
30.57,92.35,0.142
30.60,92.49,0.143
30.63,92.63,0.143
30.66,92.77,0.143
30.68,92.91,0.143
30.71,93.05,0.143
30.74,93.20,0.143
30.77,93.34,0.143
30.80,93.48,0.143
30.83,93.62,0.143
30.86,93.76,0.143
30.88,93.90,0.143
30.91,94.05,0.143
30.94,94.19,0.143
30.97,94.33,0.143
31.00,94.47,0.143
31.03,94.61,0.143
31.05,94.75,0.143
31.08,94.90,0.143
31.11,95.04,0.143
31.14,95.18,0.143
31.17,95.32,0.143
31.19,95.46,0.143
31.22,95.60,0.143
31.25,95.75,0.143
31.28,95.89,0.143
31.31,96.03,0.143
31.34,96.17,0.143
31.37,96.31,0.143
31.39,96.46,0.143
31.42,96.60,0.144
31.45,96.74,0.144
31.48,96.88,0.144
31.51,97.02,0.143
31.53,97.16,0.143
31.56,97.31,0.144
31.59,97.45,0.144
31.62,97.59,0.144
31.65,97.73,0.144
31.68,97.87,0.144
31.71,98.02,0.144
31.73,98.16,0.144
31.76,98.30,0.144
31.79,98.44,0.144
31.82,98.58,0.144
31.85,98.72,0.144
31.88,98.87,0.144
31.90,99.01,0.144
31.93,99.15,0.144
31.96,99.29,0.144
31.99,99.43,0.144
32.02,99.57,0.144
32.04,99.72,0.144
32.07,99.86,0.144
32.10,100.00,0.144
32.13,100.14,0.144
32.16,100.28,0.144
32.19,100.42,0.144
32.22,100.57,0.144
32.24,100.71,0.144
32.27,100.85,0.144
32.30,100.99,0.144
32.33,101.13,0.144
32.36,101.27,0.144
32.38,101.42,0.144
32.41,101.56,0.144
32.44,101.70,0.144
32.47,101.84,0.144
32.50,101.98,0.144
32.53,102.13,0.144
32.56,102.27,0.144
32.58,102.41,0.144
32.61,102.55,0.144
32.64,102.69,0.144
32.67,102.83,0.144
32.70,102.97,0.144
32.73,103.12,0.144
32.75,103.26,0.144
32.78,103.40,0.145
32.81,103.54,0.145
32.84,103.68,0.145
32.87,103.83,0.145
32.89,103.97,0.145
32.92,104.11,0.145
32.95,104.25,0.145
32.98,104.39,0.145
33.01,104.53,0.145
33.04,104.68,0.145
33.07,104.82,0.145
33.09,104.96,0.145
33.12,105.10,0.145
33.15,105.24,0.145
33.18,105.38,0.145
33.21,105.53,0.145
33.23,105.67,0.145
33.26,105.81,0.145
33.29,105.95,0.145
33.32,106.09,0.145
33.35,106.24,0.145
33.38,106.38,0.145
33.41,106.52,0.145
33.43,106.66,0.145
33.46,106.80,0.145
33.49,106.94,0.145
33.52,107.09,0.145
33.55,107.23,0.145
33.58,107.37,0.146
33.60,107.51,0.146
33.63,107.65,0.146
33.66,107.79,0.146
33.69,107.94,0.146
33.72,108.08,0.146
33.74,108.22,0.146
33.77,108.36,0.146
33.80,108.50,0.146
33.83,108.64,0.146
33.86,108.79,0.146
33.89,108.93,0.146
33.92,109.07,0.146
33.94,109.21,0.146
33.97,109.35,0.146
34.00,109.49,0.146
34.03,109.64,0.146
34.06,109.78,0.146
34.08,109.92,0.146
34.11,110.06,0.146
34.14,110.20,0.146
34.17,110.34,0.146
34.20,110.49,0.146
34.23,110.63,0.146
34.26,110.77,0.146
34.28,110.91,0.146
34.31,111.05,0.146
34.34,111.19,0.146
34.37,111.34,0.146
34.40,111.48,0.146
34.43,111.62,0.146
34.45,111.76,0.146
34.48,111.90,0.146
34.51,112.05,0.146
34.54,112.19,0.146
34.57,112.33,0.146
34.59,112.47,0.146
34.62,112.61,0.146
34.65,112.75,0.146
34.68,112.90,0.146
34.71,113.04,0.147
34.74,113.18,0.147
34.76,113.32,0.147
34.79,113.46,0.147
34.82,113.60,0.147
34.85,113.75,0.147
34.88,113.89,0.147
34.91,114.03,0.147
34.94,114.17,0.147
34.96,114.31,0.147
34.99,114.46,0.147
35.02,114.60,0.147
35.05,114.74,0.147
35.08,114.88,0.147
35.11,115.02,0.147
35.13,115.16,0.147
35.16,115.31,0.147
35.19,115.45,0.147
35.22,115.59,0.147
35.25,115.73,0.147
35.28,115.87,0.147
35.30,116.01,0.147
35.33,116.16,0.147
35.36,116.30,0.147
35.39,116.44,0.147
35.42,116.58,0.147
35.44,116.72,0.147
35.47,116.86,0.147
35.50,117.01,0.147
35.53,117.15,0.147
35.56,117.29,0.147
35.59,117.43,0.147
35.61,117.57,0.147
35.64,117.71,0.147
35.67,117.85,0.147
35.70,118.00,0.147
35.73,118.14,0.147
35.76,118.28,0.147
35.79,118.42,0.147
35.81,118.56,0.147
35.84,118.71,0.147
35.87,118.85,0.147
35.90,118.99,0.147
35.93,119.13,0.147
35.96,119.27,0.147
35.98,119.41,0.147
36.01,119.56,0.147
36.04,119.70,0.147
36.07,119.84,0.147
36.10,119.98,0.147
36.13,120.12,0.147
36.15,120.26,0.147
36.18,120.41,0.147
36.21,120.55,0.147
36.24,120.69,0.147
36.27,120.83,0.147
36.29,120.97,0.147
36.32,121.12,0.148
36.35,121.26,0.148
36.38,121.40,0.148
36.41,121.54,0.148
36.44,121.68,0.148
36.46,121.82,0.148
36.49,121.97,0.148
36.52,122.11,0.148
36.55,122.25,0.148
36.58,122.39,0.148
36.61,122.53,0.148
36.64,122.68,0.148
36.66,122.82,0.148
36.69,122.96,0.148
36.72,123.10,0.148
36.75,123.24,0.148
36.78,123.38,0.148
36.81,123.53,0.148
36.83,123.67,0.148
36.86,123.81,0.148
36.89,123.95,0.148
36.92,124.09,0.148
36.95,124.23,0.148
36.98,124.38,0.148
37.00,124.52,0.148
37.03,124.66,0.148
37.06,124.80,0.148
37.09,124.94,0.148
37.12,125.08,0.148
37.14,125.23,0.148
37.17,125.37,0.148
37.20,125.51,0.148
37.23,125.65,0.148
37.26,125.79,0.148
37.29,125.93,0.148
37.31,126.08,0.148
37.34,126.22,0.148
37.37,126.36,0.148
37.40,126.50,0.148
37.43,126.64,0.148
37.46,126.78,0.148
37.49,126.93,0.148
37.51,127.07,0.148
37.54,127.21,0.148
37.57,127.35,0.148
37.60,127.49,0.148
37.63,127.63,0.148
37.66,127.78,0.149
37.68,127.92,0.149
37.71,128.06,0.149
37.74,128.20,0.149
37.77,128.34,0.149
37.80,128.49,0.149
37.83,128.63,0.149
37.85,128.77,0.149
37.88,128.91,0.149
37.91,129.05,0.149
37.94,129.19,0.149
37.97,129.34,0.149
37.99,129.48,0.149
38.02,129.62,0.149
38.05,129.76,0.149
38.08,129.90,0.149
38.11,130.04,0.149
38.14,130.19,0.149
38.16,130.33,0.149
38.19,130.47,0.149
38.22,130.61,0.149
38.25,130.75,0.149
38.28,130.89,0.149
38.31,131.03,0.149
38.34,131.18,0.149
38.36,131.32,0.149
38.39,131.46,0.149
38.42,131.60,0.149
38.45,131.74,0.149
38.48,131.89,0.149
38.51,132.03,0.149
38.53,132.17,0.149
38.56,132.31,0.149
38.59,132.45,0.149
38.62,132.59,0.149
38.65,132.74,0.149
38.68,132.88,0.149
38.70,133.02,0.149
38.73,133.16,0.149
38.76,133.30,0.149
38.79,133.44,0.149
38.82,133.59,0.149
38.84,133.73,0.149
38.87,133.87,0.149
38.90,134.01,0.149
38.93,134.15,0.149
38.96,134.29,0.149
38.99,134.44,0.149
39.01,134.58,0.149
39.04,134.72,0.148
39.07,134.86,0.149
39.10,135.00,0.148
39.13,135.15,0.149
39.16,135.29,0.149
39.19,135.43,0.149
39.21,135.57,0.149
39.24,135.71,0.149
39.27,135.85,0.149
39.30,136.00,0.149
39.33,136.14,0.149
39.36,136.28,0.149
39.38,136.42,0.148
39.41,136.56,0.148
39.44,136.70,0.148
39.47,136.85,0.148
39.50,136.99,0.148
39.53,137.13,0.148
39.55,137.27,0.148
39.58,137.41,0.148
39.61,137.55,0.148
39.64,137.70,0.148
39.67,137.84,0.148
39.69,137.98,0.148
39.72,138.12,0.148
39.75,138.26,0.148
39.78,138.40,0.148
39.81,138.55,0.148
39.84,138.69,0.148
39.86,138.83,0.148
39.89,138.97,0.148
39.92,139.11,0.148
39.95,139.26,0.148
39.98,139.40,0.148
40.01,139.54,0.148
40.04,139.68,0.148
40.06,139.82,0.148
40.09,139.96,0.148
40.12,140.10,0.148
40.15,140.25,0.148
40.18,140.39,0.148
40.21,140.53,0.148
40.23,140.67,0.148
40.26,140.81,0.148
40.29,140.96,0.148
40.32,141.10,0.148
40.35,141.24,0.148
40.38,141.38,0.147
40.40,141.52,0.147
40.43,141.66,0.147
40.46,141.81,0.147
40.49,141.95,0.147
40.52,142.09,0.147
40.54,142.23,0.147
40.57,142.37,0.147
40.60,142.51,0.147
40.63,142.66,0.147
40.66,142.80,0.147
40.69,142.94,0.147
40.71,143.08,0.147
40.74,143.22,0.147
40.77,143.36,0.147
40.80,143.51,0.147
40.83,143.65,0.147
40.86,143.79,0.146
40.89,143.93,0.146
40.91,144.07,0.146
40.94,144.22,0.146
40.97,144.36,0.146
41.00,144.50,0.146
41.03,144.64,0.146
41.06,144.78,0.146
41.08,144.93,0.146
41.11,145.07,0.146
41.14,145.21,0.146
41.17,145.35,0.146
41.20,145.49,0.146
41.23,145.63,0.146
41.25,145.78,0.145
41.28,145.92,0.145
41.31,146.06,0.145
41.34,146.20,0.145
41.37,146.34,0.145
41.39,146.48,0.145
41.42,146.62,0.145
41.45,146.77,0.145
41.48,146.91,0.145
41.51,147.05,0.145
41.54,147.19,0.144
41.56,147.33,0.144
41.59,147.47,0.144
41.62,147.62,0.144
41.65,147.76,0.144
41.68,147.90,0.144
41.71,148.04,0.144
41.74,148.18,0.144
41.76,148.32,0.144
41.79,148.47,0.144
41.82,148.61,0.144
41.85,148.75,0.143
41.88,148.89,0.143
41.91,149.03,0.143
41.93,149.18,
41.96,149.32,
41.98,,

[step]
Ramp 10.00 °C/min to -60.00 °C
Time,Temperature,Heat Flow (Normalized)
min,°C,W/g
42.09,149.88,0.134
42.10,149.93,0.125
42.11,149.96,0.109
42.13,149.99,0.094
42.14,150.01,0.075
42.16,150.02,0.057
42.18,150.01,0.031
42.19,149.99,0.000
42.21,149.94,-0.037
42.22,149.88,-0.079
42.24,149.80,-0.127
42.25,149.72,-0.174
42.26,149.62,-0.218
42.28,149.51,-0.254
42.29,149.40,-0.289
42.31,149.29,-0.318
42.33,149.16,-0.339
42.34,149.04,-0.360
42.36,148.91,-0.377
42.37,148.78,-0.392
42.39,148.65,-0.405
42.40,148.51,-0.415
42.41,148.38,-0.427
42.43,148.24,-0.434
42.44,148.10,-0.441
42.46,147.96,-0.447
42.48,147.81,-0.454
42.49,147.67,-0.455
42.51,147.53,-0.460
42.52,147.38,-0.464
42.54,147.24,-0.465
42.55,147.10,-0.468
42.56,146.95,-0.470
42.58,146.81,-0.471
42.59,146.66,-0.472
42.61,146.51,-0.473
42.63,146.37,-0.476
42.64,146.22,-0.476
42.66,146.07,-0.476
42.67,145.93,-0.477
42.69,145.78,-0.478
42.70,145.63,-0.478
42.71,145.49,-0.479
42.73,145.34,-0.479
42.74,145.19,-0.479
42.76,145.04,-0.480
42.78,144.89,-0.480
42.79,144.75,-0.480
42.81,144.60,-0.480
42.82,144.45,-0.481
42.84,144.30,-0.481
42.85,144.15,-0.481
42.86,144.00,-0.481
42.88,143.86,-0.482
42.89,143.71,-0.482
42.91,143.56,-0.482
42.93,143.41,-0.482
42.94,143.26,-0.482
42.96,143.11,-0.483
42.97,142.96,-0.483
42.99,142.82,-0.483
43.00,142.67,-0.483
43.01,142.52,-0.483
43.03,142.37,-0.483
43.04,142.22,-0.483
43.06,142.07,-0.483
43.08,141.92,-0.484
43.09,141.77,-0.483
43.11,141.62,-0.484
43.12,141.48,-0.484
43.14,141.33,-0.484
43.15,141.18,-0.484
43.16,141.03,-0.484
43.18,140.88,-0.483
43.19,140.73,-0.484
43.21,140.58,-0.483
43.23,140.43,-0.483
43.24,140.28,-0.483
43.26,140.13,-0.483
43.27,139.98,-0.483
43.29,139.83,-0.483
43.30,139.68,-0.483
43.31,139.54,-0.483
43.33,139.39,-0.483
43.34,139.24,-0.483
43.36,139.09,-0.483
43.38,138.94,-0.483
43.39,138.79,-0.483
43.41,138.64,-0.483
43.42,138.49,-0.483
43.44,138.34,-0.482
43.45,138.19,-0.482
43.46,138.04,-0.482
43.48,137.89,-0.482
43.49,137.74,-0.482
43.51,137.59,-0.482
43.53,137.44,-0.482
43.54,137.29,-0.481
43.56,137.14,-0.481
43.57,136.99,-0.481
43.59,136.84,-0.481
43.60,136.69,-0.481
43.61,136.55,-0.481
43.63,136.40,-0.480
43.64,136.25,-0.480
43.66,136.10,-0.480
43.68,135.95,-0.480
43.69,135.80,-0.480
43.71,135.65,-0.480
43.72,135.50,-0.480
43.74,135.35,-0.479
43.75,135.20,-0.479
43.76,135.05,-0.479
43.78,134.90,-0.479
43.79,134.75,-0.479
43.81,134.60,-0.479
43.83,134.45,-0.479
43.84,134.30,-0.478
43.86,134.15,-0.478
43.87,134.00,-0.478
43.89,133.85,-0.478
43.90,133.70,-0.478
43.91,133.55,-0.478
43.93,133.40,-0.477
43.94,133.25,-0.477
43.96,133.10,-0.477
43.98,132.95,-0.477
43.99,132.80,-0.477
44.01,132.65,-0.477
44.02,132.50,-0.476
44.04,132.35,-0.476
44.05,132.20,-0.476
44.06,132.05,-0.476
44.08,131.90,-0.476
44.09,131.75,-0.475
44.11,131.60,-0.475
44.13,131.45,-0.475
44.14,131.31,-0.475
44.16,131.15,-0.475
44.17,131.01,-0.475
44.19,130.86,-0.475
44.20,130.71,-0.474
44.21,130.56,-0.474
44.23,130.41,-0.474
44.24,130.26,-0.474
44.26,130.11,-0.474
44.28,129.96,-0.473
44.29,129.81,-0.473
44.31,129.66,-0.473
44.32,129.51,-0.473
44.34,129.36,-0.473
44.35,129.21,-0.473
44.36,129.06,-0.472
44.38,128.91,-0.472
44.39,128.76,-0.472
44.41,128.61,-0.472
44.43,128.46,-0.472
44.44,128.31,-0.472
44.46,128.16,-0.471
44.47,128.01,-0.471
44.49,127.86,-0.471
44.50,127.71,-0.471
44.51,127.56,-0.471
44.53,127.41,-0.471
44.54,127.26,-0.470
44.56,127.11,-0.470
44.58,126.96,-0.470
44.59,126.81,-0.470
44.61,126.66,-0.470
44.62,126.51,-0.470
44.64,126.36,-0.469
44.65,126.21,-0.469
44.66,126.06,-0.469
44.68,125.91,-0.469
44.69,125.76,-0.469
44.71,125.61,-0.469
44.73,125.46,-0.468
44.74,125.31,-0.468
44.76,125.16,-0.468
44.77,125.01,-0.468
44.79,124.86,-0.467
44.80,124.71,-0.467
44.81,124.56,-0.467
44.83,124.41,-0.467
44.84,124.26,-0.467
44.86,124.11,-0.467
44.88,123.96,-0.466
44.89,123.81,-0.466
44.91,123.66,-0.466
44.92,123.51,-0.466
44.94,123.36,-0.466
44.95,123.22,-0.466
44.96,123.07,-0.465
44.98,122.92,-0.465
44.99,122.77,-0.465
45.01,122.62,-0.465
45.03,122.47,-0.465
45.04,122.32,-0.465
45.06,122.17,-0.465
45.07,122.02,-0.465
45.09,121.87,-0.464
45.10,121.72,-0.464
45.11,121.57,-0.464
45.13,121.42,-0.464
45.14,121.27,-0.464
45.16,121.12,-0.463
45.18,120.97,-0.463
45.19,120.82,-0.463
45.21,120.67,-0.463
45.22,120.52,-0.463
45.24,120.37,-0.463
45.25,120.22,-0.463
45.26,120.07,-0.463
45.28,119.92,-0.462
45.29,119.77,-0.462
45.31,119.62,-0.462
45.33,119.47,-0.462
45.34,119.32,-0.462
45.36,119.17,-0.462
45.37,119.02,-0.462
45.39,118.87,-0.461
45.40,118.72,-0.461
45.41,118.57,-0.461
45.43,118.42,-0.461
45.44,118.27,-0.461
45.46,118.12,-0.461
45.48,117.97,-0.461
45.49,117.82,-0.460
45.51,117.67,-0.460
45.52,117.52,-0.460
45.54,117.37,-0.460
45.55,117.22,-0.460
45.56,117.07,-0.460
45.58,116.92,-0.460
45.59,116.77,-0.460
45.61,116.62,-0.459
45.63,116.47,-0.459
45.64,116.32,-0.459
45.66,116.17,-0.459
45.67,116.02,-0.459
45.69,115.87,-0.459
45.70,115.73,-0.458
45.71,115.57,-0.458
45.73,115.42,-0.458
45.74,115.27,-0.458
45.76,115.12,-0.458
45.78,114.97,-0.458
45.79,114.82,-0.458
45.81,114.67,-0.458
45.82,114.52,-0.458
45.84,114.37,-0.458
45.85,114.22,-0.457
45.86,114.07,-0.457
45.88,113.92,-0.457
45.89,113.77,-0.457
45.91,113.62,-0.457
45.93,113.48,-0.457
45.94,113.33,-0.457
45.96,113.18,-0.457
45.97,113.03,-0.456
45.99,112.88,-0.456
46.00,112.73,-0.456
46.01,112.58,-0.456
46.03,112.43,-0.456
46.04,112.28,-0.456
46.06,112.13,-0.455
46.08,111.98,-0.455
46.09,111.83,-0.455
46.11,111.68,-0.455
46.12,111.53,-0.455
46.14,111.38,-0.455
46.15,111.23,-0.455
46.16,111.08,-0.455
46.18,110.93,-0.454
46.19,110.78,-0.454
46.21,110.63,-0.454
46.23,110.48,-0.454
46.24,110.33,-0.454
46.26,110.18,-0.454
46.27,110.03,-0.454
46.29,109.88,-0.453
46.30,109.73,-0.453
46.31,109.58,-0.453
46.33,109.43,-0.453
46.34,109.28,-0.453
46.36,109.13,-0.453
46.38,108.98,-0.453
46.39,108.83,-0.452
46.41,108.68,-0.452
46.42,108.53,-0.452
46.44,108.38,-0.452
46.45,108.23,-0.452
46.46,108.08,-0.452
46.48,107.93,-0.452
46.49,107.78,-0.451
46.51,107.63,-0.451
46.53,107.48,-0.451
46.54,107.33,-0.451
46.56,107.18,-0.451
46.57,107.03,-0.451
46.59,106.88,-0.451
46.60,106.73,-0.451
46.61,106.58,-0.450
46.63,106.43,-0.450
46.64,106.28,-0.450
46.66,106.13,-0.450
46.68,105.98,-0.450
46.69,105.83,-0.450
46.71,105.68,-0.450
46.72,105.54,-0.449
46.74,105.38,-0.449
46.75,105.24,-0.449
46.76,105.08,-0.449
46.78,104.94,-0.449
46.79,104.78,-0.449
46.81,104.63,-0.449
46.83,104.49,-0.449
46.84,104.33,-0.449
46.86,104.19,-0.449
46.87,104.04,-0.449
46.89,103.89,-0.448
46.90,103.74,-0.448
46.91,103.59,-0.448
46.93,103.44,-0.448
46.94,103.29,-0.448
46.96,103.14,-0.448
46.98,102.99,-0.448
46.99,102.84,-0.448
47.01,102.69,-0.448
47.02,102.54,-0.447
47.04,102.39,-0.447
47.05,102.24,-0.447
47.06,102.09,-0.447
47.08,101.94,-0.447
47.09,101.79,-0.447
47.11,101.64,-0.447
47.13,101.49,-0.447
47.14,101.34,-0.446
[...]
132.38,-39.84,0.078
132.39,-39.77,0.078
132.40,-39.71,0.079
132.41,-39.64,0.079
132.43,-39.57,0.079
132.44,-39.51,0.079
132.45,-39.44,0.079
132.47,-39.37,0.079
132.48,-39.31,0.079
132.50,-39.24,0.079
132.51,-39.17,0.079
132.52,-39.11,0.079
132.54,-39.04,0.079
132.55,-38.97,0.079
132.56,-38.91,0.079
132.58,-38.84,0.079
132.59,-38.77,0.079
132.60,-38.71,0.079
132.61,-38.64,0.079
132.63,-38.57,0.079
132.64,-38.51,0.079
132.65,-38.44,0.079
132.67,-38.37,0.079
132.68,-38.30,0.079
132.70,-38.24,0.079
132.71,-38.17,0.079
132.72,-38.10,0.079
132.74,-38.04,0.079
132.75,-37.97,0.079
132.76,-37.91,0.079
132.78,-37.84,0.079
132.79,-37.77,0.079
132.80,-37.71,0.079
132.81,-37.64,0.079
132.83,-37.57,0.079
132.84,-37.50,0.079
132.85,-37.44,0.079
132.87,-37.37,0.079
132.88,-37.30,0.079
132.90,-37.24,0.079
132.91,-37.17,0.079
132.92,-37.10,0.079
132.94,-37.04,0.079
132.95,-36.97,0.079
132.96,-36.90,0.079
132.98,-36.84,0.079
132.99,-36.77,0.079
133.00,-36.70,0.079
133.01,-36.63,0.079
133.03,-36.57,0.079
133.04,-36.50,0.079
133.05,-36.44,0.079
133.07,-36.37,0.079
133.08,-36.30,0.079
133.10,-36.24,0.079
133.11,-36.17,0.079
133.12,-36.10,0.079
133.14,-36.04,0.079
133.15,-35.97,0.079
133.16,-35.90,0.080
133.18,-35.83,0.080
133.19,-35.77,0.080
133.20,-35.70,0.080
133.21,-35.64,0.080
133.23,-35.57,0.080
133.24,-35.50,0.080
133.25,-35.44,0.080
133.27,-35.37,0.080
133.28,-35.30,0.080
133.30,-35.23,0.080
133.31,-35.17,0.080
133.32,-35.10,0.080
133.34,-35.04,0.080
133.35,-34.97,0.080
133.36,-34.90,0.080
133.38,-34.84,0.080
133.39,-34.77,0.080
133.40,-34.70,0.080
133.41,-34.63,0.080
133.43,-34.57,0.080
133.44,-34.50,0.080
133.45,-34.43,0.080
133.47,-34.37,0.080
133.48,-34.30,0.080
133.50,-34.23,0.080
133.51,-34.17,0.080
133.52,-34.10,0.080
133.54,-34.03,0.080
133.55,-33.97,0.080
133.56,-33.90,0.080
133.58,-33.83,0.080
133.59,-33.77,0.080
133.60,-33.70,0.080
133.61,-33.63,0.080
133.63,-33.57,0.080
133.64,-33.50,0.080
133.65,-33.43,0.080
133.67,-33.37,0.080
133.68,-33.30,0.080
133.70,-33.23,0.080
133.71,-33.17,0.080
133.72,-33.10,0.080
133.74,-33.03,0.080
133.75,-32.97,0.080
133.76,-32.90,0.080
133.78,-32.83,0.080
133.79,-32.77,0.081
133.80,-32.70,0.081
133.81,-32.63,0.081
133.83,-32.57,0.081
133.84,-32.50,0.081
133.85,-32.43,0.081
133.87,-32.37,0.081
133.88,-32.30,0.081
133.90,-32.23,0.081
133.91,-32.17,0.081
133.92,-32.10,0.081
133.94,-32.03,0.081
133.95,-31.97,0.081
133.96,-31.90,0.081
133.98,-31.83,0.081
133.99,-31.77,0.081
134.00,-31.70,0.081
134.01,-31.63,0.081
134.03,-31.57,0.081
134.04,-31.50,0.081
134.05,-31.43,0.081
134.07,-31.36,0.081
134.08,-31.30,0.081
134.10,-31.23,0.081
134.11,-31.16,0.081
134.12,-31.10,0.081
134.14,-31.03,0.081
134.15,-30.97,0.081
134.16,-30.90,0.081
134.18,-30.83,0.081
134.19,-30.76,0.081
134.20,-30.70,0.082
134.21,-30.63,0.082
134.23,-30.56,0.082
134.24,-30.50,0.082
134.25,-30.43,0.082
134.27,-30.36,0.082
134.28,-30.30,0.082
134.30,-30.23,0.082
134.31,-30.17,0.082
134.32,-30.10,0.082
134.34,-30.03,0.082
134.35,-29.96,0.082
134.36,-29.90,0.082
134.38,-29.83,0.082
134.39,-29.76,0.082
134.40,-29.70,0.082
134.41,-29.63,0.082
134.43,-29.57,0.082
134.44,-29.50,0.082
134.45,-29.43,0.082
134.47,-29.36,0.082
134.48,-29.30,0.082
134.50,-29.23,0.083
134.51,-29.16,0.082
134.52,-29.10,0.083
134.54,-29.03,0.083
134.55,-28.96,0.083
134.56,-28.90,0.083
134.58,-28.83,0.083
134.59,-28.76,0.083
134.60,-28.70,0.083
134.61,-28.63,0.083
134.63,-28.56,0.083
134.64,-28.50,0.083
134.65,-28.43,0.083
134.67,-28.36,0.083
134.68,-28.30,0.083
134.70,-28.23,0.083
134.71,-28.16,0.083
134.72,-28.10,0.083
134.74,-28.03,0.083
134.75,-27.96,0.083
134.76,-27.90,0.083
134.78,-27.83,0.083
134.79,-27.76,0.083
134.80,-27.70,0.083
134.81,-27.63,0.083
134.83,-27.56,0.083
134.84,-27.50,0.084
134.85,-27.43,0.084
134.87,-27.36,0.084
134.88,-27.29,0.084
134.90,-27.23,0.084
134.91,-27.16,0.084
134.92,-27.10,0.084
134.94,-27.03,0.084
134.95,-26.96,0.084
134.96,-26.90,0.084
134.98,-26.83,0.084
134.99,-26.76,0.084
135.00,-26.70,0.084
135.01,-26.63,0.084
135.03,-26.56,0.084
135.04,-26.50,0.084
135.05,-26.43,0.084
135.07,-26.36,0.084
135.08,-26.29,0.085
135.10,-26.23,0.085
135.11,-26.16,0.085
135.12,-26.10,0.085
135.14,-26.03,0.085
135.15,-25.96,0.085
135.16,-25.89,0.085
135.18,-25.83,0.085
135.19,-25.76,0.085
135.20,-25.69,0.085
135.21,-25.63,0.085
135.23,-25.56,0.085
135.24,-25.49,0.085
135.25,-25.43,0.085
135.27,-25.36,0.086
135.28,-25.29,0.086
135.30,-25.23,0.086
135.31,-25.16,0.086
135.32,-25.10,0.086
135.34,-25.03,0.086
135.35,-24.96,0.086
135.36,-24.89,0.086
135.38,-24.83,0.086
135.39,-24.76,0.086
135.40,-24.69,0.086
135.41,-24.63,0.086
135.43,-24.56,0.087
135.44,-24.49,0.087
135.45,-24.43,0.087
135.47,-24.36,0.087
135.48,-24.29,0.087
135.50,-24.23,0.087
135.51,-24.16,0.087
135.52,-24.09,0.087
135.54,-24.03,0.087
135.55,-23.96,0.087
135.56,-23.89,0.088
135.58,-23.83,0.087
135.59,-23.76,0.088
135.60,-23.69,0.088
135.61,-23.63,0.088
135.63,-23.56,0.088
135.64,-23.49,0.088
135.65,-23.43,0.088
135.67,-23.36,0.088
135.68,-23.29,0.088
135.70,-23.23,0.088
135.71,-23.16,0.089
135.72,-23.09,0.089
135.74,-23.03,0.089
135.75,-22.96,0.089
135.76,-22.89,0.089
135.78,-22.83,0.089
135.79,-22.76,0.089
135.80,-22.69,0.089
135.81,-22.63,0.090
135.83,-22.56,0.090
135.84,-22.49,0.090
135.85,-22.43,0.090
135.87,-22.36,0.090
135.88,-22.29,0.090
135.90,-22.23,0.090
135.91,-22.16,0.091
135.92,-22.09,0.091
135.94,-22.03,0.091
135.95,-21.96,0.091
135.96,-21.89,0.091
135.98,-21.83,0.091
135.99,-21.76,0.092
136.00,-21.69,0.092
136.01,-21.63,0.092
136.03,-21.56,0.092
136.04,-21.49,0.092
136.05,-21.43,0.092
136.07,-21.36,0.093
136.08,-21.29,0.093
136.10,-21.23,0.093
136.11,-21.16,0.093
136.12,-21.09,0.093
136.14,-21.03,0.094
136.15,-20.96,0.094
136.16,-20.89,0.094
136.18,-20.83,0.094
136.19,-20.76,0.094
136.20,-20.69,0.095
136.21,-20.63,0.095
136.23,-20.56,0.095
136.24,-20.49,0.095
136.25,-20.43,0.096
136.27,-20.36,0.096
136.28,-20.29,0.096
136.30,-20.23,0.096
136.31,-20.16,0.096
136.32,-20.09,0.097
136.34,-20.03,0.097
136.35,-19.96,0.097
136.36,-19.89,0.097
136.38,-19.83,0.098
136.39,-19.76,0.098
136.40,-19.69,0.098
136.41,-19.63,0.098
136.43,-19.56,0.099
136.44,-19.49,0.099
136.45,-19.43,0.099
136.47,-19.36,0.100
136.48,-19.29,0.100
136.50,-19.23,0.100
136.51,-19.16,0.100
136.52,-19.09,0.101
136.53,-19.03,0.101
136.55,-18.96,0.101
136.56,-18.89,0.102
136.58,-18.83,0.102
136.59,-18.76,0.102
136.60,-18.69,0.103
136.62,-18.63,0.103
136.63,-18.56,0.104
136.64,-18.49,0.104
136.65,-18.43,0.104
136.67,-18.36,0.105
136.68,-18.29,0.105
136.70,-18.23,0.106
136.71,-18.16,0.106
136.72,-18.09,0.106
136.73,-18.03,0.107
136.75,-17.96,0.107
136.76,-17.90,0.108
136.78,-17.83,0.108
136.79,-17.76,0.109
136.80,-17.70,0.109
136.82,-17.63,0.109
136.83,-17.56,0.110
136.84,-17.50,0.110
136.85,-17.43,0.111
136.87,-17.36,0.111
136.88,-17.30,0.111
136.90,-17.23,0.112
136.91,-17.16,0.112
136.92,-17.10,0.113
136.93,-17.03,0.114
136.95,-16.96,0.114
136.96,-16.90,0.114
136.98,-16.83,0.115
136.99,-16.76,0.115
137.00,-16.70,0.116
137.02,-16.63,0.116
137.03,-16.56,0.117
137.04,-16.50,0.117
137.05,-16.43,0.118
137.07,-16.36,0.119
137.08,-16.30,0.119
137.10,-16.23,0.119
137.11,-16.16,0.120
137.12,-16.10,0.120
137.13,-16.03,0.121
137.15,-15.97,0.121
137.16,-15.90,0.121
137.18,-15.83,0.122
137.19,-15.76,0.122
137.20,-15.70,0.122
137.22,-15.63,0.123
137.23,-15.56,0.123
137.24,-15.50,0.123
137.25,-15.43,0.124
137.27,-15.36,0.124
137.28,-15.30,0.124
137.30,-15.23,0.125
137.31,-15.16,0.125
137.32,-15.10,0.125
137.33,-15.03,0.125
137.35,-14.96,0.126
137.36,-14.90,0.126
137.38,-14.83,0.126
137.39,-14.76,0.126
137.40,-14.70,0.126
137.42,-14.63,0.126
137.43,-14.56,0.127
137.44,-14.50,0.127
137.45,-14.43,0.127
137.47,-14.36,0.127
137.48,-14.30,0.127
137.50,-14.23,0.127
137.51,-14.16,0.127
137.52,-14.10,0.127
137.53,-14.03,0.127
137.55,-13.96,0.127
137.56,-13.90,0.127
137.58,-13.83,0.127
137.59,-13.76,0.127
137.60,-13.69,0.127
137.62,-13.63,0.127
137.63,-13.56,0.127
137.64,-13.49,0.127
137.65,-13.43,0.126
137.67,-13.36,0.126
137.68,-13.30,0.126
137.70,-13.23,0.126
137.71,-13.16,0.126
137.72,-13.09,0.126
137.73,-13.03,0.125
137.75,-12.96,0.125
137.76,-12.89,0.125
137.78,-12.83,0.125
137.79,-12.76,0.125
137.80,-12.69,0.125
137.82,-12.63,0.124
137.83,-12.56,0.124
137.84,-12.49,0.124
137.85,-12.43,0.124
137.87,-12.36,0.124
137.88,-12.29,0.124
137.90,-12.23,0.123
137.91,-12.16,0.123
137.92,-12.09,0.123
137.93,-12.03,0.123
137.95,-11.96,0.123
137.96,-11.89,0.123
137.98,-11.83,0.122
137.99,-11.76,0.122
138.00,-11.69,0.122
138.02,-11.63,0.122
138.03,-11.56,0.122
138.04,-11.49,0.122
138.05,-11.42,0.122
138.07,-11.36,0.121
138.08,-11.29,0.121
138.10,-11.22,0.121
138.11,-11.16,0.121
138.12,-11.09,0.121
138.13,-11.02,0.121
138.15,-10.96,0.121
138.16,-10.89,0.121
138.18,-10.82,0.121
138.19,-10.76,0.121
138.20,-10.69,0.120
138.22,-10.63,0.120
138.23,-10.56,0.120
138.24,-10.49,0.120
138.25,-10.42,0.120
138.27,-10.36,0.120
138.28,-10.29,0.120
138.30,-10.22,0.120
138.31,-10.16,0.120
138.32,-10.09,0.120
138.33,-10.02,0.120
138.35,-9.96,0.120
138.36,-9.89,0.119
138.38,-9.82,0.119
138.39,-9.76,0.119
138.40,-9.69,0.119
138.42,-9.62,0.119
138.43,-9.56,0.119
138.44,-9.49,0.119
138.45,-9.42,0.119
138.47,-9.36,0.119
138.48,-9.29,0.119
138.50,-9.22,0.119
138.51,-9.16,0.119
138.52,-9.09,0.119
138.53,-9.02,0.119
138.55,-8.96,0.119
138.56,-8.89,0.119
138.58,-8.82,0.119
138.59,-8.76,0.119
138.60,-8.69,0.119
138.62,-8.62,0.119
138.63,-8.56,0.119
138.64,-8.49,0.119
138.65,-8.42,0.119
138.67,-8.36,0.119
138.68,-8.29,0.119
138.70,-8.22,0.119
138.71,-8.16,0.119
138.72,-8.09,0.119
138.73,-8.02,0.119
138.75,-7.96,0.119
138.76,-7.89,0.119
138.78,-7.82,0.119
138.79,-7.75,0.119
138.80,-7.69,0.119
138.82,-7.62,0.119
138.83,-7.55,0.119
138.84,-7.49,0.119
138.85,-7.42,0.119
138.87,-7.35,0.119
138.88,-7.29,0.119
138.90,-7.22,0.119
138.91,-7.15,0.119
138.92,-7.09,0.119
138.93,-7.02,0.119
138.95,-6.95,0.119
138.96,-6.89,0.119
138.98,-6.82,0.119
138.99,-6.75,0.119
139.00,-6.69,0.119
139.02,-6.62,0.119
139.03,-6.55,0.119
139.04,-6.49,0.119
139.05,-6.42,0.119
139.07,-6.35,0.119
139.08,-6.29,0.119
139.10,-6.22,0.119
139.11,-6.15,0.119
139.12,-6.09,0.119
139.13,-6.02,0.119
139.15,-5.95,0.119
139.16,-5.88,0.119
139.18,-5.82,0.119
139.19,-5.75,0.119
139.20,-5.68,0.119
139.22,-5.62,0.119
139.23,-5.55,0.119
139.24,-5.48,0.119
139.25,-5.42,0.119
139.27,-5.35,0.119
139.28,-5.28,0.119
139.30,-5.22,0.119
139.31,-5.15,0.119
139.32,-5.08,0.119
139.33,-5.02,0.119
139.35,-4.95,0.119
139.36,-4.88,0.119
139.38,-4.82,0.119
139.39,-4.75,0.119
139.40,-4.68,0.119
139.42,-4.62,0.119
139.43,-4.55,0.119
139.44,-4.48,0.119
139.45,-4.42,0.119
139.47,-4.35,0.119
139.48,-4.28,0.119
139.50,-4.22,0.119
139.51,-4.15,0.119
139.52,-4.08,0.119
139.53,-4.02,0.119
139.55,-3.95,0.119
139.56,-3.88,0.119
139.58,-3.82,0.119
139.59,-3.75,0.119
139.60,-3.68,0.119
139.62,-3.62,0.119
139.63,-3.55,0.119
139.64,-3.48,0.119
139.65,-3.42,0.119
139.67,-3.35,0.119
139.68,-3.28,0.119
139.70,-3.22,0.119
139.71,-3.15,0.119
139.72,-3.08,0.119
139.73,-3.02,0.119
139.75,-2.95,0.119
139.76,-2.88,0.119
139.78,-2.82,0.119
139.79,-2.75,0.119
139.80,-2.68,0.119
139.82,-2.62,0.119
139.83,-2.55,0.119
139.84,-2.48,0.119
139.85,-2.42,0.119
139.87,-2.35,0.119
139.88,-2.28,0.119
139.90,-2.22,0.119
139.91,-2.15,0.119
139.92,-2.08,0.119
139.93,-2.02,0.119
139.95,-1.95,0.119
139.96,-1.88,0.119
139.98,-1.82,0.119
139.99,-1.75,0.119
140.00,-1.68,0.119
140.02,-1.62,0.119
140.03,-1.55,0.119
140.04,-1.48,0.119
140.05,-1.42,0.119
140.07,-1.35,0.119
140.08,-1.28,0.119
140.10,-1.22,0.119
140.11,-1.15,0.119
140.12,-1.08,0.119
140.13,-1.02,0.119
140.15,-0.95,0.119
140.16,-0.88,0.119
140.18,-0.81,0.119
140.19,-0.75,0.119
140.20,-0.68,0.119
140.22,-0.61,0.119
140.23,-0.55,0.119
140.24,-0.48,0.119
140.25,-0.41,0.119
140.27,-0.35,0.119
140.28,-0.28,0.119
140.30,-0.22,0.119
140.31,-0.15,0.119
140.32,-0.08,0.119
140.33,-0.02,0.119
140.35,0.05,0.119
140.36,0.12,0.119
140.38,0.19,0.119
140.39,0.25,0.119
140.40,0.32,0.119
140.42,0.38,0.119
140.43,0.45,0.119
140.44,0.52,0.119
140.45,0.59,0.120
140.47,0.65,0.119
140.48,0.72,0.119
140.50,0.78,0.120
140.51,0.85,0.119
140.52,0.92,0.119
140.53,0.99,0.119
140.55,1.05,0.119
140.56,1.12,0.119
140.58,1.18,0.119
140.59,1.25,0.119
140.60,1.32,0.120
140.62,1.38,0.119
140.63,1.45,0.119
140.64,1.52,0.120
140.65,1.59,0.120
140.67,1.65,0.120
140.68,1.72,0.120
140.70,1.78,0.120
140.71,1.85,0.120
140.72,1.92,0.120
140.73,1.99,0.120
140.75,2.05,0.120
140.76,2.12,0.120
140.78,2.19,0.120
140.79,2.25,0.120
140.80,2.32,0.120
140.82,2.39,0.120
140.83,2.45,0.120
140.84,2.52,0.120
140.85,2.59,0.120
140.87,2.65,0.120
140.88,2.72,0.120
140.90,2.79,0.120
140.91,2.85,0.120
140.92,2.92,0.120
140.93,2.99,0.120
140.95,3.05,0.120
140.96,3.12,0.120
140.98,3.19,0.120
140.99,3.25,0.120
141.00,3.32,0.120
141.02,3.39,0.120
141.03,3.45,0.120
141.04,3.52,0.120
141.05,3.59,0.120
141.07,3.65,0.120
141.08,3.72,0.120
141.10,3.79,0.120
141.11,3.85,0.120
141.12,3.92,0.120
141.13,3.99,0.120
141.15,4.05,0.120
141.16,4.12,0.120
141.18,4.19,0.120
141.19,4.25,0.120
141.20,4.32,0.120
141.22,4.39,0.120
141.23,4.45,0.120
141.24,4.52,0.120
141.25,4.59,0.120
141.27,4.65,0.120
141.28,4.72,0.120
141.30,4.79,0.120
141.31,4.85,0.120
141.32,4.92,0.120
141.33,4.99,0.120
141.35,5.05,0.120
141.36,5.12,0.120
141.38,5.19,0.120
141.39,5.25,0.120
141.40,5.32,0.120
141.42,5.39,0.120
141.43,5.45,0.120
141.44,5.52,0.120
141.45,5.59,0.120
141.47,5.65,0.120
141.48,5.72,0.120
141.50,5.79,0.120
141.51,5.86,0.120
141.52,5.92,0.120
141.53,5.99,0.121
141.55,6.05,0.121
141.56,6.12,0.121
141.58,6.19,0.121
141.59,6.25,0.121
141.60,6.32,0.121
141.62,6.39,0.121
141.63,6.46,0.121
141.64,6.52,0.121
141.65,6.59,0.121
141.67,6.65,0.121
141.68,6.72,0.121
141.70,6.79,0.121
141.71,6.86,0.121
141.72,6.92,0.121
141.73,6.99,0.121
141.75,7.06,0.121
141.76,7.12,0.121
141.78,7.19,0.121
141.79,7.26,0.121
141.80,7.32,0.121
141.82,7.39,0.121
141.83,7.46,0.121
141.84,7.52,0.121
141.85,7.59,0.121
141.87,7.66,0.121
141.88,7.72,0.121
141.90,7.79,0.121
141.91,7.86,0.121
141.92,7.92,0.121
141.93,7.99,0.121
141.95,8.06,0.121
141.96,8.12,0.121
141.98,8.19,0.121
141.99,8.26,0.121
142.00,8.32,0.121
142.02,8.39,0.121
142.03,8.46,0.121
142.04,8.52,0.121
142.05,8.59,0.121
142.07,8.66,0.121
142.08,8.72,0.121
142.10,8.79,0.121
142.11,8.86,0.121
142.12,8.92,0.121
142.13,8.99,0.121
142.15,9.06,0.121
142.16,9.12,0.121
142.18,9.19,0.121
142.19,9.26,0.121
142.20,9.32,0.121
142.22,9.39,0.121
142.23,9.46,0.121
142.24,9.52,0.121
142.25,9.59,0.121
142.27,9.66,0.121
142.28,9.73,0.121
142.30,9.79,0.121
142.31,9.86,0.121
142.32,9.92,0.121
142.33,9.99,0.121
142.35,10.06,0.121
142.36,10.12,0.121
142.38,10.19,0.121
142.39,10.26,0.121
142.40,10.33,0.121
142.42,10.39,0.121
142.43,10.46,0.121
142.44,10.52,0.121
142.45,10.59,0.121
142.47,10.66,0.121
142.48,10.72,0.122
142.50,10.79,0.122
142.51,10.86,0.122
142.52,10.93,0.122
142.53,10.99,0.122
142.55,11.06,0.122
142.56,11.13,0.122
142.58,11.19,0.122
142.59,11.26,0.122
142.60,11.33,0.122
142.62,11.39,0.122
142.63,11.46,0.122
142.64,11.53,0.122
142.65,11.59,0.122
142.67,11.66,0.122
142.68,11.73,0.122
142.70,11.79,0.122
142.71,11.86,0.122
142.72,11.93,0.122
142.73,11.99,0.122
142.75,12.06,0.122
142.76,12.13,0.122
142.78,12.19,0.122
142.79,12.26,0.122
142.80,12.33,0.122
142.82,12.39,0.122
142.83,12.46,0.122
142.84,12.53,0.122
142.85,12.59,0.122
142.87,12.66,0.122
142.88,12.73,0.122
142.90,12.79,0.122
142.91,12.86,0.122
142.92,12.93,0.122
142.93,12.99,0.122
142.95,13.06,0.122
142.96,13.13,0.122
142.98,13.19,0.122
142.99,13.26,0.122
143.00,13.33,0.122
143.02,13.39,0.122
143.03,13.46,0.122
143.04,13.53,0.122
143.05,13.59,0.122
143.07,13.66,0.122
143.08,13.73,0.122
143.10,13.79,0.122
143.11,13.86,0.122
143.12,13.93,0.122
143.13,13.99,0.122
143.15,14.06,0.122
143.16,14.13,0.122
143.18,14.19,0.122
143.19,14.26,0.122
143.20,14.33,0.122
143.22,14.40,0.122
143.23,14.46,0.122
143.24,14.53,0.122
143.25,14.60,0.122
143.27,14.66,0.122
143.28,14.73,0.122
143.30,14.80,0.122
143.31,14.86,0.122
143.32,14.93,0.122
143.33,15.00,0.122
143.35,15.06,0.122
143.36,15.13,0.122
143.38,15.20,0.122
143.39,15.26,0.122
143.40,15.33,0.122
143.42,15.40,0.122
143.43,15.46,0.122
143.44,15.53,0.122
143.45,15.60,0.122
143.47,15.66,0.122
143.48,15.73,0.122
143.50,15.80,0.122
143.51,15.86,0.122
143.52,15.93,0.122
143.53,16.00,0.122
143.55,16.06,0.122
143.56,16.13,0.122
143.58,16.20,0.122
143.59,16.26,0.122
143.60,16.33,0.122
143.62,16.40,0.122
143.63,16.46,0.122
143.64,16.53,0.122
143.65,16.60,0.122
143.67,16.66,0.122
143.68,16.73,0.122
143.70,16.80,0.122
143.71,16.86,0.122
143.72,16.93,0.122
143.73,17.00,0.122
143.75,17.06,0.122
143.76,17.13,0.123
143.78,17.20,0.123
143.79,17.26,0.123
143.80,17.33,0.123
143.82,17.40,0.123
143.83,17.46,0.123
143.84,17.53,0.123
143.85,17.60,0.123
143.87,17.66,0.123
143.88,17.73,0.123
143.90,17.80,0.123
143.91,17.86,0.123
143.92,17.93,0.123
143.93,18.00,0.123
143.95,18.06,0.123
143.96,18.13,0.123
143.98,18.20,0.123
143.99,18.26,0.123
144.00,18.33,0.123
144.02,18.40,0.123
144.03,18.47,0.123
144.04,18.53,0.123
144.05,18.60,0.123
144.07,18.67,0.123
144.08,18.73,0.123
144.10,18.80,0.123
144.11,18.86,0.123
144.12,18.93,0.123
144.13,19.00,0.123
144.15,19.06,0.123
144.16,19.13,0.123
144.18,19.20,0.123
144.19,19.26,0.123
144.20,19.33,0.124
144.22,19.40,0.124
144.23,19.47,0.124
144.24,19.53,0.124
144.25,19.60,0.124
144.27,19.67,0.124
144.28,19.73,0.124
144.30,19.80,0.124
144.31,19.87,0.124
144.32,19.93,0.124
144.33,20.00,0.124
144.35,20.07,0.124
144.36,20.13,0.124
144.38,20.20,0.124
144.39,20.27,0.124
144.40,20.33,0.124
144.42,20.40,0.124
144.43,20.47,0.124
144.44,20.53,0.124
144.45,20.60,0.124
144.47,20.67,0.124
144.48,20.73,0.124
144.50,20.80,0.124
144.51,20.87,0.124
144.52,20.93,0.124
144.53,21.00,0.124
144.55,21.07,0.124
144.56,21.13,0.124
144.58,21.20,0.124
144.59,21.27,0.124
144.60,21.33,0.124
144.62,21.40,0.124
144.63,21.47,0.124
144.64,21.53,0.124
144.65,21.60,0.124
144.67,21.67,0.124
144.68,21.73,0.124
144.70,21.80,0.124
144.71,21.87,0.124
144.72,21.93,0.124
144.73,22.00,0.124
144.75,22.07,0.124
144.76,22.13,0.124
144.78,22.20,0.124
144.79,22.27,0.124
144.80,22.33,0.124
144.82,22.40,0.124
144.83,22.47,0.124
144.84,22.53,0.124
144.85,22.60,0.124
144.87,22.67,0.124
144.88,22.73,0.125
144.90,22.80,0.125
144.91,22.87,0.125
144.92,22.93,0.125
144.93,23.00,0.125
144.95,23.07,0.125
144.96,23.14,0.125
144.98,23.20,0.125
144.99,23.27,0.125
145.00,23.33,0.125
145.02,23.40,0.125
145.03,23.47,0.125
145.04,23.53,0.125
145.05,23.60,0.125
145.07,23.67,0.125
145.08,23.73,0.125
145.10,23.80,0.125
145.11,23.87,0.125
145.12,23.93,0.125
145.13,24.00,0.125
145.15,24.07,0.125
145.16,24.14,0.125
145.18,24.20,0.125
145.19,24.27,0.125
145.20,24.34,0.125
145.22,24.40,0.125
145.23,24.47,0.125
145.24,24.54,0.125
145.25,24.60,0.125
145.27,24.67,0.125
145.28,24.74,0.125
145.30,24.80,0.125
145.31,24.87,0.125
145.32,24.94,0.125
145.33,25.00,0.125
145.35,25.07,0.125
145.36,25.14,0.125
145.38,25.20,0.125
145.39,25.27,0.125
145.40,25.34,0.125
145.42,25.40,0.125
145.43,25.47,0.125
145.44,25.54,0.125
145.45,25.60,0.125
145.47,25.67,0.125
145.48,25.74,0.125
145.50,25.80,0.125
145.51,25.87,0.125
145.52,25.94,0.126
145.53,26.00,0.126
145.55,26.07,0.126
145.56,26.14,0.126
145.58,26.20,0.126
145.59,26.27,0.126
145.60,26.34,0.126
145.62,26.40,0.126
145.63,26.47,0.126
145.64,26.54,0.126
145.65,26.60,0.126
145.67,26.67,0.126
145.68,26.74,0.126
145.70,26.80,0.126
145.71,26.87,0.126
145.72,26.94,0.126
145.73,27.00,0.126
145.75,27.07,0.126
145.76,27.14,0.126
145.78,27.20,0.126
145.79,27.27,0.126
145.80,27.34,0.126
145.82,27.40,0.126
145.83,27.47,0.126
145.84,27.54,0.126
145.85,27.60,0.126
145.87,27.67,0.126
145.88,27.74,0.126
145.90,27.81,0.126
145.91,27.87,0.126
145.92,27.94,0.126
145.93,28.00,0.126
145.95,28.07,0.126
145.96,28.14,0.126
145.98,28.21,0.126
145.99,28.27,0.126
146.00,28.34,0.126
146.02,28.41,0.126
146.03,28.47,0.126
146.04,28.54,0.126
146.05,28.60,0.126
146.07,28.67,0.126
146.08,28.74,0.127
146.10,28.81,0.127
146.11,28.87,0.127
146.12,28.94,0.127
146.13,29.01,0.127
146.15,29.07,
146.16,29.14,
146.18,29.21,
146.19,29.27,
146.20,,