File: DSC/2025_04_19_Sapphire_n60C_200C_5Cmin_x3.csv
Filename,2025_04_19_Sapphire_n60C_200C_5Cmin_x3
Instrument name,DSC2A-00468 (192.168.1.100)
Operator,Yarger
rundate,4/19/2025
Sample name,2025_04_19_Sapphire_n60C_200C_5Cmin_x3
proceduresegments,Data Off ; Equilibrate -60.00 °C; Data On ; Ramp 5.00 °C/min to 200.00 °C; Data Off ; Isothermal 0.1 min; Data On ; Ramp 10.00 °C/min to -60.00 °C; Data Off ; Isothermal 1.0 min; Data On ; Ramp 5.00 °C/min to 200.00 °C; Data Off ; Isothermal 0.1 min; Data On ; Ramp 10.00 °C/min to -60.00 °C; Data Off ; Isothermal 1.0 min; Data On ; Ramp 5.00 °C/min to 30.00 °C
[File Parameters]
Run date,4/19/2025 5:24:33 PM
Trios version,5.1.1.46572
Original File Name,
Current File Name,D:\DSC2500\JYarger\2025_04_19_Sapphire_n60C_200C_5Cmin_x3.tri
[Procedure]
Procedure Name,Sapphire_n60_200C_5Cmin_x3
Sample Name,2025_04_19_Sapphire_n60C_200C_5Cmin_x3
Sample Mass,23.5 mg
Reference Sample Mass,0 mg
Pan Mass,52.18 mg
Pan Number,2
Reference Pan Mass,53.66 mg
Reference Pan Number,46
Pan Type,Tzero Aluminum Hermetic
Comments,Hermetic Sealed Al DSC Consumables Pan/Lids.
Project Name,CA
Operator,Yarger
Test,Custom
Unload Max Temperature,30
Unload Min Temperature,30
Load Max Temperature,30
Load Min Temperature,30
Stop on Gas Flow Error,Yes
[Signal List]
Signal #1,Time (min)
Signal #2,Temperature (°C)
Signal #3,Heat Flow (mW)
Signal #4,Delta T (µV)
Signal #5,Delta Tzero (µV)
Signal #6,Tzero Temperature (°C)
Signal #7,Cell Purge (mL/min)
Signal #8,Heater Temp (°C)
Signal #9,Power Delivered (W)
Signal #10,Reference Junction Temperature (°C)
Signal #11,Flange Temperature (°C)
Signal #12,Heat Flow Phase (rad)
Signal #13,Total Heat Capacity (J/°C)
Signal #14,Heat Capacity (J/°C)
[Configuration]
Company Name,ASU
Instrument Name,DSC2A-00468
Instrument Type,DSC2500
Serial Number,DSC2A-00468
IP,192.168.1.100
Location of Instrument,MRRC
DisplayType,Unknown
Sample Interval ,0.1 s/pt
Selected Heat Flow,T4P
Exotherm Direction,Down
Cell Serial,DRC2-00792
Lid Type,Standard
Cooler,RCS 90
Leave Cooler on at End of Sequence,On
Gas 2,Nitrogen
Gas Selected,Channel 1
Flow Rate,50 mL/min
Secondary Purge,On
Licensed Heat Flow,Heat Flow T4P
Modulation Licensed,Yes
[Versions]
Common IDD Version,1
Cortex Version,VER 2.10.2.31
Driver,5.0.0.6
GDM Version,1.0.3.3
TouchscreenVersion,1.0.0.16145
FEP Version,1.2.1.21
FEP Bootloader,2.0.0.5
AutoSampler Version,2.1.1.26
Auto Sampler Bootloader,2.0.0.5
FCM Version,1.1.0.3
FCM Bootloader,2.0.0.5
[Experiment Logs]
Experiment Log Entry # 1,Air Cool is off.
Experiment Log Entry # 3,Data On set to 0
Experiment Log Entry # 5,Equilibrate Segment -60 (C) Started
Experiment Log Entry # 7,Data On set to 1
Experiment Log Entry # 9,Ramp Segment 5 C/min to 200 Started
Experiment Log Entry # 11,Data On set to 0
Experiment Log Entry # 13,Isothermal Segment 0.1 min started
Experiment Log Entry # 15,Data On set to 1
Experiment Log Entry # 17,Ramp Segment 10 C/min to -60 Started
Experiment Log Entry # 19,Data On set to 0
Experiment Log Entry # 21,Isothermal Segment 1 min started
Experiment Log Entry # 23,Data On set to 1
Experiment Log Entry # 25,Ramp Segment 5 C/min to 200 Started
Experiment Log Entry # 27,Data On set to 0
Experiment Log Entry # 29,Isothermal Segment 0.1 min started
Experiment Log Entry # 31,Data On set to 1
Experiment Log Entry # 33,Ramp Segment 10 C/min to -60 Started
Experiment Log Entry # 35,Data On set to 0
Experiment Log Entry # 37,Isothermal Segment 1 min started
Experiment Log Entry # 39,Data On set to 1
Experiment Log Entry # 41,Ramp Segment 5 C/min to 30 Started
[Method Log]
Method Log Entry # 1,Data Off
Method Log Entry # 2,Equilibrate -60 °C
Method Log Entry # 3,Data On
Method Log Entry # 4,(Ramp 360045) Ramp 5 °C/minute to 200 °C
Method Log Entry # 5,Data Off
Method Log Entry # 6,Isothermal 0.1 minutes
Method Log Entry # 7,Data On
Method Log Entry # 8,(Ramp 360049) Ramp 10 °C/minute to -60 °C
Method Log Entry # 9,Data Off
Method Log Entry # 10,Isothermal 1 minutes
Method Log Entry # 11,Data On
Method Log Entry # 12,(Ramp 360053) Ramp 5 °C/minute to 200 °C
Method Log Entry # 13,Data Off
Method Log Entry # 14,Isothermal 0.1 minutes
Method Log Entry # 15,Data On
Method Log Entry # 16,(Ramp 360057) Ramp 10 °C/minute to -60 °C
Method Log Entry # 17,Data Off
Method Log Entry # 18,Isothermal 1 minutes
Method Log Entry # 19,Data On
Method Log Entry # 20,(Ramp 360061) Ramp 5 °C/minute to 30 °C
Cell Serial,DRC2-00792
[T1 Calibration]
Slope,-0.008529666
Offset,9.636258
Initial Temperature,98.23
GUID,f8bfdadc-4977-4fdf-ba6d-0ba9134940c3
[TZero Calibration]
Date Applied,11/29/2022 4:06:13 PM
Description,From -89.059 °C to 396.009 °C at 20.000°C/min
Gas Type,Nitrogen
Pan Type,None
Source Files 1,C:\Users\yargerlab\Desktop\DSC Data\General\TZero_calibration_11_29_22_2nd(2).tri
Source Files 2,C:\Users\yargerlab\Desktop\DSC Data\General\TZero_calibration_11_29_22_2nd(3).tri
Delta T Offset,13.05235
Delta T Slope,-0.007271007
Delta T0 Offset,-13.69128
Delta T0 Slope,0.06063341
[Temperature Calibration]
Date Applied,11/29/2022 7:12:28 PM
Description,From 106.590 °C to 186.590 °C at 10.000°C/min
Gas Type,Nitrogen
Pan Type,Tzero Aluminum Hermetic
Source Files 1,C:\Users\yargerlab\Desktop\DSC Data\General\Indium(6).tri
Measured 1,157.391
Known 1,156.598
[Cell Constant Calibration]
Date Applied,11/29/2022 7:12:29 PM
Description,From 106.590 °C to 186.590 °C at 10.000°C/min
Gas Type,Nitrogen
Pan Type,Tzero Aluminum Hermetic
Source Files 1,C:\Users\yargerlab\Desktop\DSC Data\General\Indium(6).tri
T4P KCell,1.006051
Onset Slope,63.26126 mW/°C
[Direct Cp Calibration]
Date Applied,11/30/2022 11:04:51 AM
Description,From -79.983 °C to 298.409 °C at 10.000°C/min
Gas Type,Nitrogen
Pan Type,Tzero Aluminum Hermetic
Source Files 1,C:\Users\yargerlab\Desktop\DSC Data\General\Sapphire_Heat_Capacity_11_30_22.tri
[Rev Cp Calibration]
Date Applied,11/30/2022 1:58:51 PM
Description,From -79.996 °C to 292.812 °C at 3.000°C/min
Gas Type,Nitrogen
Pan Type,Tzero Aluminum Hermetic
Source Files 1,C:\Users\yargerlab\Desktop\DSC Data\General\Sapphire_MDSC_Calibration_11_30_22.tri
[step]
Ramp 5.00 °C/min to 200.00 °C
Time,Temperature,Heat Flow (Normalized)
min,°C,W/g
0.00,-59.67,-0.015
0.03,-59.69,-0.014
0.07,-59.69,-0.010
0.11,-59.65,-0.004
0.14,-59.57,0.003
0.18,-59.47,0.012
0.21,-59.34,0.019
0.24,-59.21,0.025
0.28,-59.06,0.029
0.31,-58.91,0.032
0.35,-58.76,0.034
0.39,-58.60,0.036
0.42,-58.44,0.037
0.45,-58.28,0.039
0.49,-58.11,0.039
0.53,-57.94,0.040
0.56,-57.78,0.040
0.60,-57.61,0.041
0.63,-57.44,0.041
0.67,-57.27,0.041
0.70,-57.10,0.041
0.73,-56.93,0.041
0.77,-56.76,0.041
0.80,-56.59,0.042
0.84,-56.41,0.042
0.88,-56.24,0.042
0.91,-56.07,0.042
0.95,-55.90,0.042
0.98,-55.73,0.042
1.02,-55.55,0.042
1.05,-55.38,0.042
1.08,-55.21,0.042
1.12,-55.03,0.042
1.16,-54.86,0.042
1.19,-54.69,0.043
1.23,-54.51,0.043
1.26,-54.34,0.043
1.29,-54.16,0.043
1.33,-53.99,0.043
1.37,-53.82,0.043
1.40,-53.64,0.043
1.43,-53.47,0.043
1.47,-53.29,0.043
1.51,-53.12,0.043
1.54,-52.95,0.043
1.58,-52.77,0.043
1.61,-52.60,0.043
1.64,-52.42,0.043
1.68,-52.25,0.043
1.72,-52.08,0.043
1.75,-51.90,0.043
1.78,-51.73,0.043
1.82,-51.55,0.043
1.86,-51.38,0.043
1.89,-51.20,0.043
1.93,-51.03,0.043
1.96,-50.85,0.043
1.99,-50.68,0.043
2.03,-50.50,0.043
2.07,-50.33,0.043
2.10,-50.16,0.043
2.14,-49.98,0.043
2.17,-49.80,0.043
2.21,-49.63,0.043
2.24,-49.46,0.043
2.28,-49.28,0.043
2.31,-49.11,0.043
2.34,-48.93,0.044
2.38,-48.76,0.044
2.41,-48.58,0.044
2.45,-48.41,0.044
2.49,-48.23,0.044
2.52,-48.06,0.044
2.56,-47.88,0.044
2.59,-47.71,0.044
2.63,-47.53,0.044
2.66,-47.36,0.044
2.69,-47.18,0.044
2.73,-47.01,0.044
2.76,-46.83,0.044
2.80,-46.66,0.044
2.84,-46.49,0.044
2.87,-46.31,0.044
2.91,-46.13,0.044
2.94,-45.96,0.044
2.98,-45.79,0.044
3.01,-45.61,0.044
3.04,-45.44,0.044
3.08,-45.26,0.044
3.11,-45.09,0.044
3.15,-44.91,0.044
3.19,-44.74,0.044
3.22,-44.56,0.044
3.26,-44.39,0.044
3.29,-44.21,0.044
3.33,-44.04,0.044
3.36,-43.86,0.044
3.39,-43.69,0.044
3.43,-43.51,0.044
3.46,-43.34,0.044
3.50,-43.16,0.044
3.54,-42.99,0.044
3.57,-42.81,0.044
3.61,-42.64,0.044
3.64,-42.46,0.044
3.68,-42.29,0.044
3.71,-42.11,0.044
3.74,-41.94,0.045
3.78,-41.76,0.045
3.81,-41.59,0.045
3.85,-41.41,0.045
3.89,-41.24,0.045
3.92,-41.06,0.045
3.96,-40.89,0.045
3.99,-40.71,0.045
4.03,-40.53,0.045
4.06,-40.36,0.045
4.09,-40.18,0.045
4.13,-40.01,0.045
4.16,-39.83,0.045
4.20,-39.66,0.045
4.24,-39.48,0.045
4.27,-39.31,0.045
4.30,-39.13,0.045
4.34,-38.96,0.045
4.38,-38.78,0.045
4.41,-38.61,0.045
4.45,-38.43,0.045
4.48,-38.26,0.045
4.51,-38.08,0.045
4.55,-37.91,0.045
4.59,-37.73,0.045
4.62,-37.56,0.045
4.65,-37.38,0.045
4.69,-37.21,0.045
4.73,-37.03,0.045
4.76,-36.86,0.045
4.80,-36.68,0.045
4.83,-36.51,0.045
4.86,-36.33,0.045
4.90,-36.16,0.045
4.94,-35.98,0.045
4.97,-35.80,0.046
5.00,-35.63,0.046
5.04,-35.46,0.046
5.08,-35.28,0.046
5.11,-35.10,0.046
5.15,-34.93,0.046
5.18,-34.75,0.046
5.21,-34.58,0.046
5.25,-34.41,0.046
5.29,-34.23,0.046
5.32,-34.05,0.046
5.35,-33.88,0.046
5.39,-33.70,0.046
5.43,-33.53,0.046
5.46,-33.35,0.046
5.50,-33.18,0.046
5.53,-33.00,0.046
5.56,-32.83,0.046
5.60,-32.65,0.046
5.64,-32.48,0.046
5.67,-32.30,0.046
5.70,-32.13,0.046
5.74,-31.95,0.046
5.78,-31.78,0.046
5.81,-31.60,0.046
5.85,-31.43,0.046
5.88,-31.25,0.046
5.91,-31.08,0.046
5.95,-30.90,0.046
5.99,-30.72,0.046
6.02,-30.55,0.046
6.05,-30.37,0.046
6.09,-30.20,0.047
6.13,-30.03,0.047
6.16,-29.85,0.047
6.20,-29.67,0.047
6.23,-29.50,0.047
6.26,-29.32,0.047
6.30,-29.15,0.047
6.34,-28.97,0.047
6.37,-28.80,0.047
6.40,-28.62,0.047
6.44,-28.45,0.047
6.48,-28.27,0.047
6.51,-28.10,0.047
6.55,-27.92,0.047
6.58,-27.75,0.047
6.61,-27.57,0.047
6.65,-27.40,0.047
6.69,-27.22,0.047
6.72,-27.05,0.047
6.75,-26.87,0.047
6.79,-26.70,0.047
6.83,-26.52,0.047
6.86,-26.35,0.047
6.90,-26.17,0.047
6.93,-26.00,0.047
6.96,-25.82,0.047
7.00,-25.65,0.047
7.04,-25.47,0.047
7.07,-25.30,0.047
7.10,-25.12,0.047
7.14,-24.94,0.047
7.18,-24.77,0.047
7.21,-24.59,0.047
7.25,-24.42,0.047
7.28,-24.24,0.047
7.31,-24.07,0.047
7.35,-23.89,0.048
7.39,-23.72,0.048
7.42,-23.54,0.048
7.45,-23.37,0.048
7.49,-23.20,0.048
7.53,-23.02,0.048
7.56,-22.84,0.048
7.60,-22.67,0.048
7.63,-22.49,0.048
7.66,-22.32,0.048
7.70,-22.14,0.048
7.74,-21.97,0.048
7.77,-21.79,0.048
7.80,-21.62,0.048
7.84,-21.44,0.048
7.88,-21.27,0.048
7.91,-21.09,0.048
7.95,-20.92,0.048
7.98,-20.74,0.048
8.01,-20.57,0.048
8.05,-20.39,0.048
8.09,-20.22,0.048
8.12,-20.04,0.048
8.15,-19.87,0.048
8.19,-19.69,0.048
8.23,-19.52,0.048
8.26,-19.34,0.048
8.30,-19.17,0.048
8.33,-18.99,0.048
8.36,-18.82,0.048
8.40,-18.64,0.048
8.44,-18.47,0.048
8.47,-18.29,0.048
8.50,-18.12,0.048
8.54,-17.94,0.048
8.58,-17.76,0.049
8.61,-17.59,0.049
8.65,-17.42,0.049
8.68,-17.24,0.049
8.72,-17.06,0.049
8.75,-16.89,0.049
8.78,-16.71,0.049
8.82,-16.54,0.049
8.85,-16.36,0.049
8.89,-16.19,0.049
8.93,-16.01,0.049
8.96,-15.84,0.049
9.00,-15.66,0.049
9.03,-15.49,0.049
9.07,-15.31,0.049
9.10,-15.14,0.049
9.13,-14.96,0.049
9.17,-14.79,0.049
9.20,-14.61,0.049
9.24,-14.44,0.049
9.28,-14.26,0.049
9.31,-14.09,0.049
9.35,-13.91,0.049
9.38,-13.74,0.049
9.42,-13.56,0.049
9.45,-13.39,0.049
9.48,-13.21,0.049
9.52,-13.04,0.049
9.55,-12.86,0.049
9.59,-12.69,0.049
9.63,-12.51,0.049
9.66,-12.34,0.049
9.70,-12.16,0.049
9.73,-11.99,0.049
9.77,-11.81,0.050
9.80,-11.64,0.050
9.83,-11.46,0.050
9.87,-11.29,0.050
9.90,-11.11,0.050
9.94,-10.94,0.050
9.98,-10.76,0.050
10.01,-10.58,0.050
10.05,-10.41,0.050
10.08,-10.24,0.050
10.12,-10.06,0.050
10.15,-9.88,0.050
10.18,-9.71,0.050
10.22,-9.54,0.050
10.25,-9.36,0.050
10.29,-9.18,0.050
10.33,-9.01,0.050
10.36,-8.83,0.050
10.40,-8.66,0.050
10.43,-8.48,0.050
10.47,-8.31,0.050
10.50,-8.13,0.050
10.53,-7.96,0.050
10.57,-7.78,0.050
10.60,-7.61,0.050
10.64,-7.43,0.050
10.68,-7.26,0.050
10.71,-7.08,0.050
10.75,-6.91,0.050
10.78,-6.73,0.050
10.82,-6.56,0.050
10.85,-6.38,0.050
10.88,-6.21,0.050
10.92,-6.03,0.051
10.95,-5.86,0.051
10.99,-5.68,0.051
11.03,-5.51,0.051
11.06,-5.33,0.051
11.10,-5.16,0.051
11.13,-4.98,0.051
11.17,-4.81,0.051
11.20,-4.63,0.051
11.23,-4.46,0.051
11.27,-4.28,0.051
11.30,-4.11,0.051
11.34,-3.93,0.051
11.38,-3.75,0.051
11.41,-3.58,0.051
11.45,-3.41,0.051
11.48,-3.23,0.051
11.52,-3.06,0.051
11.55,-2.88,0.051
11.58,-2.70,0.051
11.62,-2.53,0.051
11.65,-2.35,0.051
11.69,-2.18,0.051
11.73,-2.00,0.051
11.76,-1.83,0.051
11.80,-1.65,0.051
11.83,-1.48,0.051
11.87,-1.30,0.051
11.90,-1.13,0.051
11.93,-0.95,0.051
11.97,-0.78,0.051
12.00,-0.60,0.051
12.04,-0.43,0.051
12.08,-0.25,0.051
12.11,-0.08,0.051
12.15,0.10,0.052
12.18,0.27,0.052
12.22,0.45,0.052
12.25,0.62,0.052
12.28,0.80,0.052
12.32,0.97,0.052
12.35,1.15,0.052
12.39,1.32,0.052
12.43,1.50,0.052
12.46,1.67,0.052
12.50,1.85,0.052
12.53,2.02,0.052
12.57,2.20,0.052
12.60,2.37,0.052
12.63,2.55,0.052
12.67,2.72,0.052
12.70,2.90,0.052
12.74,3.07,0.052
12.78,3.25,0.052
12.81,3.42,0.052
12.85,3.60,0.052
12.88,3.77,0.052
12.92,3.95,0.052
12.95,4.12,0.052
12.98,4.30,0.052
13.02,4.47,0.052
13.05,4.65,0.052
13.09,4.82,0.052
13.13,5.00,0.052
13.16,5.17,0.052
13.20,5.35,0.052
13.23,5.53,0.052
13.27,5.70,0.052
13.30,5.88,0.053
13.33,6.05,0.053
13.37,6.23,0.053
13.40,6.40,0.053
13.44,6.58,0.053
13.48,6.75,0.053
13.51,6.93,0.053
13.55,7.10,0.053
13.58,7.28,0.053
13.62,7.45,0.053
13.65,7.63,0.053
13.68,7.80,0.053
13.72,7.98,0.053
13.75,8.15,0.053
13.79,8.33,0.053
13.83,8.50,0.053
13.86,8.68,0.053
13.90,8.85,0.053
13.93,9.03,0.053
13.97,9.20,0.053
14.00,9.38,0.053
14.03,9.55,0.053
14.07,9.73,0.053
14.10,9.90,0.053
14.14,10.08,0.053
14.18,10.25,0.053
14.21,10.43,0.053
14.25,10.60,0.053
14.28,10.78,0.053
14.32,10.95,0.053
14.35,11.13,0.053
14.38,11.30,0.053
14.42,11.48,0.053
14.45,11.65,0.053
14.49,11.83,0.054
14.53,12.01,0.054
14.56,12.18,0.054
14.60,12.36,0.054
14.63,12.53,0.054
14.67,12.70,0.054
14.70,12.88,0.054
14.73,13.05,0.054
14.77,13.23,0.054
14.80,13.41,0.054
14.84,13.58,0.054
14.88,13.76,0.054
14.91,13.93,0.054
14.95,14.11,0.054
14.98,14.28,0.054
15.02,14.46,0.054
15.05,14.63,0.054
15.08,14.80,0.054
15.12,14.98,0.054
15.15,15.16,0.054
15.19,15.33,0.054
15.23,15.51,0.054
15.26,15.68,0.054
15.30,15.86,0.054
15.33,16.03,0.054
15.37,16.21,0.054
15.40,16.38,0.054
15.43,16.56,0.054
15.47,16.73,0.054
15.50,16.91,0.054
15.54,17.08,0.054
15.58,17.26,0.054
15.61,17.43,0.054
15.65,17.61,0.054
15.68,17.78,0.054
15.72,17.96,0.054
15.75,18.13,0.054
15.78,18.31,0.055
15.82,18.48,0.055
15.85,18.66,0.055
15.89,18.83,0.055
15.93,19.01,0.055
15.96,19.18,0.055
16.00,19.36,0.055
16.03,19.54,0.055
16.07,19.71,0.055
16.10,19.89,0.055
16.13,20.06,0.055
16.17,20.24,0.055
16.20,20.41,0.055
16.24,20.59,0.055
16.28,20.76,0.055
16.31,20.94,0.055
16.35,21.11,0.055
16.38,21.29,0.055
16.42,21.46,0.055
16.45,21.64,0.055
16.48,21.81,0.055
16.52,21.99,0.055
16.55,22.16,0.055
16.59,22.34,0.055
16.63,22.51,0.055
16.66,22.69,0.055
16.70,22.86,0.055
16.73,23.04,0.055
16.77,23.21,0.055
16.80,23.39,0.055
16.83,23.56,0.055
16.87,23.74,0.055
16.90,23.91,0.055
16.94,24.09,0.055
16.98,24.26,0.056
17.01,24.44,0.056
17.05,24.61,0.056
17.08,24.79,0.056
17.12,24.96,0.056
17.15,25.14,0.056
17.18,25.31,0.056
17.22,25.49,0.056
17.26,25.66,0.056
17.29,25.84,0.056
17.33,26.01,0.056
17.36,26.19,0.056
17.39,26.36,0.056
17.43,26.54,0.056
17.47,26.71,0.056
17.50,26.89,0.056
17.53,27.06,0.056
17.57,27.24,0.056
17.61,27.41,0.056
17.64,27.59,0.056
17.68,27.76,0.056
17.71,27.94,0.056
17.74,28.12,0.056
17.78,28.29,0.056
17.82,28.47,0.056
17.85,28.64,0.056
17.88,28.82,0.056
17.92,28.99,0.056
17.96,29.17,0.056
17.99,29.34,0.056
18.03,29.52,0.056
18.06,29.69,0.056
18.09,29.87,0.056
18.13,30.04,0.056
18.17,30.21,0.056
18.20,30.39,0.056
18.23,30.57,0.056
18.27,30.74,0.057
18.31,30.92,0.057
18.34,31.09,0.057
18.38,31.27,0.057
18.41,31.44,0.057
18.44,31.62,0.057
18.48,31.79,0.057
18.52,31.97,0.057
18.55,32.14,0.057
18.58,32.32,0.057
18.62,32.49,0.057
18.66,32.67,0.057
18.69,32.84,0.057
18.73,33.02,0.057
18.76,33.19,0.057
18.79,33.37,0.057
18.83,33.54,0.057
18.87,33.72,0.057
18.90,33.89,0.057
18.93,34.07,0.057
18.97,34.24,0.057
19.01,34.42,0.057
19.04,34.59,0.057
19.08,34.77,0.057
19.11,34.94,0.057
19.14,35.12,0.057
19.18,35.29,0.057
19.22,35.47,0.057
19.25,35.65,0.057
19.28,35.82,0.057
19.32,36.00,0.057
19.36,36.17,0.057
19.39,36.35,0.057
19.43,36.52,0.057
19.46,36.70,0.057
19.49,36.87,0.057
19.53,37.04,0.057
19.57,37.22,0.057
19.60,37.40,0.058
19.63,37.57,0.058
19.67,37.75,0.058
19.71,37.92,0.058
19.74,38.10,0.058
19.78,38.27,0.058
19.81,38.45,0.058
19.84,38.62,0.058
19.88,38.80,0.058
19.92,38.97,0.058
19.95,39.15,0.058
19.98,39.32,0.058
20.02,39.50,0.058
20.06,39.67,0.058
20.09,39.85,0.058
20.13,40.02,0.058
20.16,40.20,0.058
20.19,40.37,0.058
20.23,40.55,0.058
20.27,40.72,0.058
20.30,40.90,0.058
20.33,41.07,0.058
20.37,41.25,0.058
20.41,41.42,0.058
20.44,41.60,0.058
20.48,41.78,0.058
20.51,41.95,0.058
20.54,42.12,0.058
20.58,42.30,0.058
20.62,42.48,0.058
20.65,42.65,0.058
20.68,42.82,0.058
20.72,43.00,0.058
20.76,43.17,0.058
20.79,43.35,0.058
20.83,43.53,0.058
20.86,43.70,0.058
20.89,43.87,0.058
20.93,44.05,0.058
20.97,44.22,0.059
21.00,44.40,0.059
21.03,44.58,0.059
21.07,44.75,0.059
21.11,44.92,0.059
21.14,45.10,0.059
21.18,45.27,0.059
21.21,45.45,0.059
21.24,45.63,0.059
21.28,45.80,0.059
21.32,45.97,0.059
21.35,46.15,0.059
21.38,46.33,0.059
21.42,46.50,0.059
21.46,46.68,0.059
21.49,46.85,0.059
21.53,47.02,0.059
21.56,47.20,0.059
21.59,47.38,0.059
21.63,47.55,0.059
21.67,47.73,0.059
21.70,47.90,0.059
21.73,48.08,0.059
21.77,48.25,0.059
21.81,48.43,0.059
21.84,48.60,0.059
21.88,48.77,0.059
21.91,48.95,0.059
21.94,49.13,0.059
21.98,49.30,0.059
22.02,49.48,0.059
22.05,49.65,0.059
22.08,49.83,0.059
22.12,50.00,0.059
22.16,50.18,0.059
22.19,50.35,0.059
22.23,50.53,0.059
22.26,50.70,0.059
22.29,50.88,0.059
22.33,51.05,0.059
22.37,51.23,0.059
22.40,51.40,0.059
22.43,51.58,0.060
22.47,51.75,0.060
22.51,51.93,0.060
22.54,52.10,0.060
22.58,52.28,0.060
22.61,52.45,0.060
22.64,52.63,0.060
22.68,52.80,0.060
22.72,52.98,0.060
22.75,53.15,0.060
22.78,53.33,0.060
22.82,53.50,0.060
22.86,53.68,0.060
22.89,53.85,0.060
22.93,54.03,0.060
22.96,54.20,0.060
22.99,54.38,0.060
23.03,54.55,0.060
23.07,54.73,0.060
23.10,54.90,0.060
23.13,55.08,0.060
23.17,55.25,0.060
23.21,55.43,0.060
23.24,55.61,0.060
23.28,55.78,0.060
23.31,55.96,0.060
23.34,56.13,0.060
23.38,56.31,0.060
23.42,56.48,0.060
23.45,56.66,0.060
23.48,56.83,0.060
23.52,57.00,0.060
23.56,57.18,0.060
23.59,57.36,0.060
23.63,57.53,0.060
23.66,57.71,0.060
23.69,57.88,0.060
23.73,58.06,0.060
23.77,58.23,0.060
23.80,58.41,0.060
23.83,58.58,0.060
23.87,58.76,0.060
23.91,58.93,0.060
23.94,59.11,0.060
23.98,59.28,0.060
24.01,59.46,0.060
24.04,59.63,0.060
24.08,59.81,0.060
24.12,59.98,0.061
24.15,60.16,0.061
24.18,60.33,0.061
24.22,60.51,0.061
24.26,60.68,0.061
24.29,60.86,0.061
24.33,61.03,0.061
24.36,61.21,0.061
24.39,61.38,0.061
24.43,61.56,0.061
24.47,61.73,0.061
24.50,61.91,0.061
24.53,62.08,0.061
24.57,62.26,0.061
24.61,62.43,0.061
24.64,62.61,0.061
24.68,62.78,0.061
24.71,62.96,0.061
24.74,63.13,0.061
24.78,63.31,0.061
24.82,63.48,0.061
24.85,63.66,0.061
24.88,63.84,0.061
24.92,64.01,0.061
24.96,64.18,0.061
24.99,64.36,0.061
25.03,64.54,0.061
25.06,64.71,0.061
25.09,64.89,0.061
25.13,65.06,0.061
25.17,65.24,0.061
25.20,65.41,0.061
25.23,65.59,0.061
25.27,65.76,0.061
25.31,65.94,0.061
25.34,66.11,0.061
25.38,66.29,0.061
25.41,66.46,0.061
25.44,66.64,0.061
25.48,66.81,0.061
25.52,66.99,0.061
25.55,67.16,0.061
25.58,67.34,0.061
25.62,67.51,0.061
25.66,67.69,0.061
25.69,67.86,0.061
25.73,68.04,0.061
25.76,68.21,0.062
25.79,68.39,0.062
25.83,68.56,0.062
25.87,68.74,0.062
25.90,68.91,0.062
25.93,69.09,0.062
25.97,69.26,0.062
26.01,69.44,0.062
26.04,69.61,0.062
26.08,69.79,0.062
26.11,69.96,0.062
26.14,70.14,0.062
26.18,70.31,0.062
26.22,70.49,0.062
26.25,70.66,0.062
26.28,70.84,0.062
26.32,71.01,0.062
26.36,71.19,0.062
26.39,71.36,0.062
26.43,71.54,0.062
26.46,71.71,0.062
26.49,71.89,0.062
26.53,72.06,0.062
26.57,72.24,0.062
26.60,72.42,0.062
26.63,72.59,0.062
26.67,72.76,0.062
26.71,72.94,0.062
26.74,73.12,0.062
26.78,73.29,0.062
26.81,73.46,0.062
26.84,73.64,0.062
26.88,73.81,0.062
26.92,73.99,0.062
26.95,74.16,0.062
26.98,74.34,0.062
27.02,74.52,0.062
27.06,74.69,0.062
27.09,74.87,0.062
27.13,75.04,0.062
27.16,75.22,0.062
27.19,75.39,0.062
27.23,75.57,0.062
27.27,75.74,0.062
27.30,75.92,0.062
27.33,76.09,0.062
27.37,76.27,0.062
27.41,76.44,0.062
27.44,76.62,0.063
27.48,76.79,0.063
27.51,76.97,0.063
27.54,77.14,0.063
27.58,77.32,0.063
27.62,77.49,0.063
27.65,77.67,0.063
27.68,77.84,0.063
27.72,78.02,0.063
27.76,78.19,0.063
27.79,78.37,0.063
27.83,78.54,0.063
27.86,78.72,0.063
27.89,78.89,0.063
27.93,79.07,0.063
27.97,79.24,0.063
28.00,79.42,0.063
28.03,79.59,0.063
28.07,79.77,0.063
28.11,79.94,0.063
28.14,80.12,0.063
28.18,80.29,0.063
28.21,80.47,0.063
28.24,80.64,0.063
28.28,80.82,0.063
28.32,80.99,0.063
28.35,81.17,0.063
28.38,81.34,0.063
28.42,81.52,0.063
28.46,81.69,0.063
28.49,81.87,0.063
28.53,82.04,0.063
28.56,82.22,0.063
28.59,82.40,0.063
28.63,82.57,0.063
28.67,82.75,0.063
28.70,82.92,0.063
28.73,83.10,0.063
28.77,83.27,0.063
28.81,83.45,0.063
28.84,83.62,0.063
28.88,83.80,0.063
28.91,83.97,0.063
28.94,84.14,0.063
28.98,84.32,0.063
29.02,84.50,0.063
29.05,84.67,0.063
29.08,84.85,0.063
29.12,85.02,0.063
29.16,85.20,0.063
29.19,85.37,0.063
29.23,85.55,0.063
29.26,85.72,0.063
29.29,85.90,0.063
29.33,86.07,0.063
29.37,86.25,0.063
29.40,86.42,0.063
29.43,86.60,0.063
29.47,86.77,0.063
29.51,86.95,0.063
29.54,87.12,0.064
29.58,87.30,0.064
29.61,87.47,0.064
29.64,87.65,0.064
29.68,87.82,0.064
29.72,88.00,0.064
29.75,88.17,0.064
29.78,88.35,0.064
29.82,88.52,0.064
29.86,88.70,0.064
29.89,88.87,0.064
29.93,89.05,0.064
29.96,89.22,0.064
29.99,89.40,0.064
30.03,89.57,0.064
30.07,89.75,0.064
30.10,89.92,0.064
30.13,90.10,0.064
30.17,90.28,0.064
30.21,90.45,0.064
30.24,90.62,0.064
30.28,90.80,0.064
30.31,90.97,0.064
30.34,91.15,0.064
30.38,91.32,0.064
30.42,91.50,0.064
30.45,91.67,0.064
30.48,91.85,0.064
30.52,92.02,0.064
30.56,92.20,0.064
30.59,92.38,0.064
30.63,92.55,0.064
30.66,92.72,0.064
30.69,92.90,0.064
30.73,93.07,0.064
30.77,93.25,0.064
30.80,93.43,0.064
30.83,93.60,0.064
30.87,93.77,0.064
30.91,93.95,0.064
30.94,94.13,0.064
30.98,94.30,0.064
31.01,94.48,0.064
31.04,94.65,0.064
31.08,94.82,0.064
31.12,95.00,0.064
31.15,95.18,0.064
31.18,95.35,0.064
31.22,95.53,0.064
31.26,95.70,0.064
31.29,95.88,0.065
31.33,96.05,0.065
31.36,96.23,0.065
31.39,96.40,0.065
31.43,96.58,0.065
31.47,96.75,0.065
31.50,96.93,0.065
31.53,97.10,0.065
31.57,97.28,0.065
31.61,97.45,0.065
31.64,97.63,0.065
31.68,97.80,0.065
31.71,97.98,0.065
31.74,98.15,0.065
31.78,98.33,0.065
31.82,98.50,0.065
31.85,98.68,0.065
31.88,98.85,0.065
31.92,99.03,0.065
31.96,99.20,0.065
31.99,99.38,0.065
32.03,99.55,0.065
32.06,99.73,0.065
32.09,99.90,0.065
32.13,100.08,0.065
32.17,100.25,0.065
32.20,100.43,0.065
32.23,100.60,0.065
32.27,100.78,0.065
32.31,100.95,0.065
32.34,101.13,0.065
32.38,101.30,0.065
32.41,101.48,0.065
32.44,101.65,0.065
32.48,101.83,0.065
32.52,102.00,0.065
32.55,102.18,0.065
32.58,102.36,0.065
32.62,102.53,0.065
32.66,102.71,0.065
32.69,102.88,0.065
32.73,103.06,0.065
32.76,103.23,0.065
32.79,103.41,0.065
32.83,103.58,0.065
32.87,103.76,0.065
32.90,103.93,0.065
32.93,104.11,0.065
32.97,104.28,0.065
33.01,104.46,0.065
33.04,104.63,0.065
33.08,104.81,0.065
33.11,104.98,0.065
33.14,105.16,0.065
33.18,105.33,0.065
33.22,105.51,0.065
33.25,105.68,0.065
33.28,105.86,0.065
33.32,106.03,0.065
33.36,106.21,0.065
33.39,106.38,0.065
33.43,106.56,0.065
33.46,106.73,0.065
33.49,106.91,0.065
33.53,107.08,0.065
33.57,107.26,0.065
33.60,107.43,0.066
33.63,107.61,0.066
33.67,107.78,0.066
33.71,107.96,0.066
33.74,108.13,0.066
33.78,108.31,0.066
33.81,108.48,0.066
33.84,108.66,0.066
33.88,108.83,0.066
33.92,109.01,0.066
33.95,109.18,0.066
33.98,109.36,0.066
34.02,109.53,0.066
34.06,109.71,0.066
34.09,109.88,0.066
34.13,110.06,0.066
34.16,110.23,0.066
34.19,110.41,0.066
34.23,110.58,0.066
34.26,110.76,0.066
34.30,110.93,0.066
34.34,111.11,0.066
34.37,111.28,0.066
34.41,111.46,0.066
34.44,111.63,0.066
34.48,111.81,0.066
34.51,111.98,0.066
34.54,112.16,0.066
34.58,112.33,0.066
34.61,112.51,0.066
34.65,112.68,0.066
34.69,112.86,0.066
34.72,113.03,0.066
34.76,113.21,0.066
34.79,113.38,0.066
34.83,113.56,0.066
34.86,113.73,0.066
34.89,113.91,0.066
34.93,114.09,0.066
34.96,114.26,0.066
35.00,114.44,0.066
35.04,114.61,0.066
35.07,114.78,0.066
35.11,114.96,0.066
35.14,115.13,0.066
35.18,115.31,0.066
35.21,115.48,0.066
35.24,115.66,0.066
35.28,115.83,0.066
35.31,116.01,0.066
35.35,116.18,0.066
35.39,116.36,0.066
35.42,116.53,0.066
35.46,116.71,0.066
35.49,116.88,0.066
35.53,117.06,0.066
35.56,117.23,0.066
35.59,117.41,0.066
35.63,117.58,0.066
35.66,117.76,0.066
35.70,117.93,0.066
35.74,118.11,0.066
35.77,118.28,0.066
35.81,118.46,0.066
35.84,118.64,0.066
35.88,118.81,0.067
35.91,118.99,0.067
35.94,119.16,0.067
35.98,119.33,0.067
36.01,119.51,0.067
36.05,119.69,0.067
36.09,119.86,0.067
36.12,120.04,0.067
36.16,120.21,0.067
36.19,120.39,0.067
36.23,120.56,0.067
36.26,120.74,0.067
36.29,120.91,0.067
36.33,121.09,0.067
36.36,121.26,0.067
36.40,121.44,0.067
36.44,121.61,0.067
36.47,121.79,0.067
36.51,121.96,0.067
36.54,122.14,0.067
36.58,122.31,0.067
36.61,122.49,0.067
36.64,122.66,0.067
36.68,122.84,0.067
36.71,123.01,0.067
36.75,123.19,0.067
36.79,123.36,0.067
36.82,123.54,0.067
36.86,123.71,0.067
36.89,123.89,0.067
36.93,124.06,0.067
36.96,124.24,0.067
36.99,124.41,0.067
37.03,124.59,0.067
37.06,124.76,0.067
37.10,124.94,0.067
37.14,125.11,0.067
37.17,125.29,0.067
37.21,125.46,0.067
37.24,125.64,0.067
37.28,125.81,0.067
37.31,125.99,0.067
37.34,126.16,0.067
37.38,126.34,0.067
37.41,126.51,0.067
37.45,126.69,0.067
37.49,126.86,0.067
37.52,127.04,0.067
37.56,127.21,0.067
37.59,127.39,0.067
37.63,127.56,0.067
37.66,127.74,0.067
37.69,127.91,0.067
37.73,128.09,0.067
37.76,128.26,0.067
37.80,128.44,0.067
37.84,128.61,0.067
37.87,128.79,0.067
37.91,128.96,0.067
37.94,129.14,0.067
37.98,129.31,0.067
38.01,129.49,0.067
38.04,129.66,0.067
38.08,129.84,0.067
38.11,130.02,0.067
38.15,130.19,0.067
38.19,130.36,0.067
38.22,130.54,0.067
38.26,130.72,0.068
38.29,130.89,0.068
38.33,131.07,0.068
38.36,131.24,0.068
38.39,131.41,0.068
38.43,131.59,0.068
38.46,131.76,0.068
38.50,131.94,0.068
38.54,132.12,0.068
38.57,132.29,0.068
38.61,132.47,0.068
38.64,132.64,0.068
38.68,132.81,0.068
38.71,132.99,0.068
38.74,133.17,0.068
38.78,133.34,0.068
38.81,133.52,0.068
38.85,133.69,0.068
38.89,133.86,0.068
38.92,134.04,0.068
38.96,134.21,0.068
38.99,134.39,0.068
39.03,134.57,0.068
39.06,134.74,0.068
39.09,134.92,0.068
39.13,135.09,0.068
39.16,135.27,0.068
39.20,135.44,0.068
39.24,135.62,0.068
39.27,135.79,0.068
39.31,135.97,0.068
39.34,136.14,0.068
39.38,136.32,0.068
39.41,136.49,0.068
39.44,136.67,0.068
39.48,136.84,0.068
39.51,137.02,0.068
39.55,137.19,0.068
39.59,137.37,0.068
39.62,137.54,0.068
39.66,137.72,0.068
39.69,137.89,0.068
39.73,138.07,0.068
39.76,138.24,0.068
39.79,138.42,0.068
39.83,138.59,0.068
39.86,138.77,0.068
39.90,138.94,0.068
39.94,139.12,0.068
39.97,139.29,0.068
40.01,139.47,0.068
40.04,139.64,0.068
40.08,139.82,0.068
40.11,139.99,0.068
40.14,140.17,0.068
40.18,140.34,0.068
40.21,140.52,0.068
40.25,140.69,0.068
40.29,140.87,0.068
40.32,141.05,0.068
40.36,141.22,0.068
40.39,141.40,0.068
40.43,141.57,0.068
40.46,141.74,0.068
40.49,141.92,0.068
40.53,142.10,0.068
40.56,142.27,0.068
40.60,142.45,0.068
40.64,142.62,0.068
40.67,142.79,0.068
40.71,142.97,0.068
40.74,143.14,0.068
40.78,143.32,0.069
40.81,143.49,0.069
40.84,143.67,0.069
40.88,143.84,0.069
40.91,144.02,0.069
40.95,144.19,0.069
40.99,144.37,0.069
41.02,144.54,0.069
41.06,144.72,0.069
41.09,144.89,0.069
41.13,145.07,0.069
41.16,145.24,0.069
41.19,145.42,0.069
41.23,145.59,0.069
41.26,145.77,0.069
41.30,145.95,0.069
41.34,146.12,0.069
41.37,146.30,0.069
41.41,146.47,0.069
41.44,146.65,0.069
41.48,146.82,0.069
41.51,147.00,0.069
41.54,147.17,0.069
41.58,147.34,0.069
41.61,147.52,0.069
41.65,147.69,0.069
41.69,147.87,0.069
41.72,148.05,0.069
41.76,148.22,0.069
41.79,148.40,0.069
41.83,148.57,0.069
41.86,148.75,0.069
41.89,148.92,0.069
41.93,149.10,0.069
41.96,149.27,0.069
42.00,149.45,0.069
42.04,149.62,0.069
42.07,149.80,0.069
42.11,149.97,0.069
42.14,150.15,0.069
42.18,150.32,0.069
42.21,150.50,0.069
42.24,150.67,0.069
42.28,150.85,0.069
42.31,151.02,0.069
42.35,151.20,0.069
42.39,151.37,0.069
42.42,151.55,0.069
42.46,151.72,0.069
42.49,151.90,0.069
42.53,152.07,0.069
42.56,152.25,0.069
42.59,152.42,0.069
42.63,152.60,0.069
42.66,152.77,0.069
42.70,152.95,0.069
42.74,153.12,0.069
42.77,153.30,0.069
42.81,153.47,0.069
42.84,153.65,0.069
42.88,153.82,0.069
42.91,154.00,0.070
42.94,154.17,0.070
42.98,154.35,0.070
43.01,154.52,0.070
43.05,154.70,0.070
43.09,154.87,0.070
43.12,155.05,0.070
43.16,155.22,0.070
43.19,155.40,0.070
43.23,155.57,0.070
43.26,155.75,0.070
43.29,155.92,0.070
43.33,156.10,0.070
43.36,156.27,0.070
43.40,156.45,0.070
43.44,156.62,0.070
43.47,156.80,0.070
43.51,156.97,0.070
43.54,157.15,0.070
43.58,157.32,0.070
43.61,157.50,0.070
43.64,157.67,0.070
43.68,157.85,0.070
43.71,158.02,0.070
43.75,158.20,0.070
43.79,158.37,0.070
43.82,158.55,0.070
43.86,158.72,0.070
43.89,158.90,0.070
43.93,159.07,0.070
43.96,159.25,0.070
43.99,159.42,0.070
44.03,159.60,0.070
44.06,159.77,0.070
44.10,159.95,0.070
44.14,160.12,0.070
44.17,160.30,0.070
44.21,160.47,0.070
44.24,160.65,0.070
44.28,160.82,0.070
44.31,161.00,0.070
44.34,161.17,0.070
44.38,161.35,0.070
44.41,161.52,0.070
44.45,161.70,0.070
44.49,161.87,0.070
44.52,162.05,0.070
44.56,162.22,0.070
44.59,162.40,0.070
44.63,162.57,0.070
44.66,162.75,0.070
44.69,162.92,0.070
44.73,163.10,0.070
44.76,163.27,0.070
44.80,163.45,0.070
44.84,163.62,0.070
44.87,163.80,0.070
44.91,163.97,0.070
44.94,164.15,0.070
44.98,164.32,0.070
45.01,164.50,0.070
45.04,164.67,0.070
45.08,164.85,0.070
45.11,165.03,0.070
45.15,165.20,0.070
45.19,165.37,0.070
45.22,165.55,0.070
45.26,165.73,0.070
45.29,165.90,0.070
45.33,166.08,0.070
45.36,166.25,0.070
45.39,166.43,0.070
45.43,166.60,0.070
45.46,166.78,0.070
45.50,166.95,0.070
45.54,167.13,0.070
45.57,167.30,0.070
45.61,167.48,0.070
45.64,167.65,0.070
45.68,167.83,0.070
45.71,168.00,0.070
45.74,168.18,0.070
45.78,168.35,0.070
45.81,168.53,0.070
45.85,168.70,0.070
45.89,168.88,0.070
45.92,169.05,0.070
45.96,169.23,0.070
45.99,169.40,0.070
46.03,169.57,0.070
46.06,169.75,0.070
46.09,169.93,0.070
46.13,170.10,0.071
46.16,170.27,0.071
46.20,170.45,0.071
46.24,170.63,0.071
46.27,170.80,0.071
46.31,170.98,0.071
46.34,171.15,0.071
46.38,171.33,0.071
46.41,171.50,0.071
46.44,171.68,0.071
46.48,171.85,0.071
46.51,172.03,0.071
46.55,172.20,0.071
46.59,172.38,0.071
46.62,172.55,0.071
46.66,172.73,0.071
46.69,172.90,0.071
46.73,173.08,0.071
46.76,173.25,0.071
46.79,173.43,0.071
46.83,173.60,0.071
46.86,173.77,0.071
46.90,173.95,0.071
46.94,174.13,0.071
46.97,174.30,0.071
47.01,174.48,0.071
47.04,174.65,0.071
47.08,174.83,0.071
47.11,175.00,0.071
47.14,175.18,0.071
47.18,175.35,0.071
47.21,175.53,0.071
47.25,175.70,0.071
47.29,175.88,0.071
47.32,176.05,0.071
47.36,176.23,0.071
47.39,176.40,0.071
47.43,176.58,0.071
47.46,176.75,0.071
47.49,176.93,0.071
47.53,177.10,0.071
47.56,177.28,0.071
47.60,177.45,0.071
47.64,177.63,0.071
47.67,177.80,0.071
47.71,177.98,0.071
47.74,178.15,0.071
47.78,178.33,0.071
47.81,178.50,0.071
47.84,178.68,0.071
47.88,178.85,0.071
47.91,179.03,0.071
47.95,179.20,0.071
47.99,179.38,0.071
48.02,179.55,0.071
48.06,179.73,0.071
48.09,179.90,0.071
48.13,180.08,0.071
48.16,180.25,0.071
48.19,180.43,0.071
48.23,180.60,0.071
48.26,180.78,0.071
48.30,180.95,0.071
48.34,181.13,0.071
48.37,181.30,0.071
48.41,181.48,0.071
48.44,181.65,0.071
48.48,181.83,0.071
48.51,182.00,0.071
48.54,182.18,0.071
48.58,182.35,0.071
48.61,182.53,0.071
48.65,182.70,0.071
48.69,182.88,0.071
48.72,183.05,0.071
48.76,183.23,0.072
48.79,183.40,0.071
48.83,183.58,0.071
48.86,183.75,0.071
48.89,183.93,0.071
48.93,184.10,0.071
48.96,184.28,0.071
49.00,184.45,0.071
49.04,184.63,0.071
49.07,184.80,0.071
49.11,184.98,0.072
49.14,185.15,0.072
49.18,185.33,0.072
49.21,185.50,0.072
49.24,185.68,0.072
49.28,185.85,0.072
49.31,186.03,0.072
49.35,186.20,0.072
49.39,186.38,0.072
49.42,186.55,0.072
49.46,186.73,0.072
49.49,186.90,0.072
49.53,187.08,0.072
49.56,187.25,0.072
49.59,187.43,0.072
49.63,187.60,0.072
49.66,187.78,0.072
49.70,187.95,0.072
49.74,188.13,0.072
49.77,188.30,0.072
49.81,188.48,0.072
49.84,188.65,0.072
49.88,188.83,0.072
49.91,189.00,0.072
49.94,189.18,0.072
49.98,189.36,0.072
50.01,189.53,0.072
50.05,189.70,0.072
50.09,189.88,0.072
50.12,190.06,0.072
50.16,190.23,0.072
50.19,190.40,0.072
50.23,190.58,0.072
50.26,190.75,0.072
50.29,190.93,0.072
50.33,191.10,0.072
50.36,191.28,0.072
50.40,191.45,0.072
50.44,191.63,0.072
50.47,191.80,0.072
50.51,191.98,0.072
50.54,192.15,0.072
50.58,192.33,0.072
50.61,192.50,0.072
50.64,192.68,0.072
50.68,192.85,0.072
50.71,193.03,0.072
50.75,193.21,0.072
50.79,193.38,0.072
50.82,193.55,0.072
50.86,193.73,0.072
50.89,193.90,0.072
50.93,194.08,0.072
50.96,194.25,0.072
50.99,194.43,0.072
51.03,194.61,0.072
51.06,194.78,0.072
51.10,194.95,0.072
51.14,195.13,0.072
51.17,195.30,0.072
51.21,195.48,0.072
51.24,195.65,0.072
51.28,195.83,0.072
51.31,196.00,0.072
51.34,196.18,0.072
51.38,196.35,0.072
51.41,196.53,0.072
51.45,196.70,0.072
51.49,196.88,0.072
51.52,197.05,0.072
51.56,197.23,0.072
51.59,197.40,0.072
51.63,197.58,0.072
51.66,197.75,0.072
51.69,197.93,0.072
51.73,198.10,0.072
51.76,198.28,0.073
51.80,198.46,0.073
51.84,198.63,0.073
51.87,198.81,0.073
51.91,198.98,0.073
51.94,199.16,
51.98,199.33,
51.99,,

[step]
Ramp 10.00 °C/min to -60.00 °C
Time,Temperature,Heat Flow (Normalized)
min,°C,W/g
52.09,199.84,0.063
52.11,199.90,0.058
52.12,199.95,0.051
52.14,199.98,0.043
52.16,200.00,0.032
52.18,200.00,0.018
52.20,199.98,-0.001
52.21,199.93,-0.022
52.23,199.86,-0.045
52.25,199.77,-0.067
52.27,199.66,-0.086
52.29,199.54,-0.103
52.31,199.41,-0.116
52.33,199.27,-0.127
52.34,199.12,-0.137
52.36,198.97,-0.144
52.38,198.81,-0.150
52.40,198.65,-0.156
52.42,198.49,-0.160
52.44,198.32,-0.164
52.45,198.15,-0.166
52.47,197.98,-0.169
52.49,197.81,-0.171
52.51,197.64,-0.173
52.53,197.46,-0.174
52.54,197.29,-0.175
52.56,197.11,-0.177
52.58,196.93,-0.177
52.60,196.75,-0.178
52.62,196.58,-0.179
52.64,196.40,-0.179
52.66,196.22,-0.180
52.67,196.04,-0.180
52.69,195.86,-0.180
52.71,195.68,-0.180
52.73,195.50,-0.180
52.75,195.32,-0.181
52.76,195.14,-0.181
52.78,194.96,-0.181
52.80,194.78,-0.181
52.82,194.59,-0.181
52.84,194.41,-0.181
52.86,194.23,-0.181
52.88,194.05,-0.181
52.89,193.87,-0.181
52.91,193.69,-0.182
52.93,193.51,-0.182
52.95,193.32,-0.182
52.97,193.14,-0.182
52.99,192.96,-0.182
53.00,192.78,-0.182
53.02,192.60,-0.182
53.04,192.42,-0.182
53.06,192.24,-0.182
53.08,192.05,-0.182
53.09,191.87,-0.182
53.11,191.69,-0.182
53.13,191.51,-0.182
53.15,191.32,-0.182
53.17,191.14,-0.182
53.19,190.96,-0.182
53.21,190.78,-0.182
53.22,190.60,-0.182
53.24,190.41,-0.182
53.26,190.23,-0.182
53.28,190.05,-0.182
53.30,189.87,-0.182
53.31,189.68,-0.182
53.33,189.50,-0.182
53.35,189.32,-0.182
53.37,189.14,-0.182
53.39,188.95,-0.182
53.41,188.77,-0.182
53.43,188.59,-0.182
53.44,188.41,-0.182
53.46,188.22,-0.182
53.48,188.04,-0.182
53.50,187.86,-0.182
53.52,187.67,-0.182
53.54,187.49,-0.182
53.55,187.31,-0.182
53.57,187.13,-0.182
53.59,186.94,-0.182
53.61,186.76,-0.182
53.63,186.58,-0.182
53.64,186.39,-0.182
53.66,186.21,-0.182
53.68,186.03,-0.182
53.70,185.85,-0.182
53.72,185.66,-0.182
53.74,185.48,-0.182
53.76,185.30,-0.182
53.77,185.11,-0.182
53.79,184.93,-0.182
53.81,184.75,-0.182
53.83,184.57,-0.182
53.85,184.38,-0.182
53.86,184.20,-0.182
53.88,184.02,-0.182
53.90,183.83,-0.182
53.92,183.65,-0.182
53.94,183.47,-0.182
53.96,183.29,-0.181
53.98,183.10,-0.181
53.99,182.92,-0.181
54.01,182.74,-0.181
54.03,182.55,-0.181
54.05,182.37,-0.181
54.07,182.19,-0.181
54.09,182.00,-0.181
54.10,181.82,-0.181
54.12,181.64,-0.181
54.14,181.46,-0.181
54.16,181.27,-0.181
54.18,181.09,-0.181
54.19,180.91,-0.181
54.21,180.72,-0.181
54.23,180.54,-0.181
54.25,180.36,-0.181
54.27,180.17,-0.181
54.29,179.99,-0.181
54.31,179.81,-0.181
54.32,179.63,-0.181
54.34,179.44,-0.181
54.36,179.26,-0.181
54.38,179.08,-0.181
54.40,178.89,-0.180
54.41,178.71,-0.180
54.43,178.53,-0.180
54.45,178.34,-0.180
54.47,178.16,-0.180
54.49,177.98,-0.180
54.51,177.79,-0.180
54.53,177.61,-0.180
54.54,177.43,-0.180
54.56,177.25,-0.180
54.58,177.06,-0.180
54.60,176.88,-0.180
54.62,176.70,-0.180
54.64,176.51,-0.180
54.65,176.33,-0.180
54.67,176.15,-0.180
54.69,175.96,-0.180
54.71,175.78,-0.180
54.73,175.60,-0.180
54.74,175.41,-0.180
54.76,175.23,-0.180
54.78,175.05,-0.180
54.80,174.87,-0.180
54.82,174.68,-0.180
54.84,174.50,-0.180
54.86,174.32,-0.180
54.87,174.13,-0.180
54.89,173.95,-0.180
54.91,173.77,-0.180
54.93,173.58,-0.180
54.95,173.40,-0.179
54.96,173.22,-0.179
54.98,173.03,-0.179
55.00,172.85,-0.179
55.02,172.67,-0.179
55.04,172.48,-0.179
55.06,172.30,-0.179
55.08,172.12,-0.179
55.09,171.94,-0.179
55.11,171.75,-0.179
55.13,171.57,-0.179
55.15,171.39,-0.179
55.17,171.20,-0.179
55.19,171.02,-0.179
55.20,170.84,-0.179
55.22,170.65,-0.179
55.24,170.47,-0.179
55.26,170.29,-0.179
55.28,170.10,-0.179
55.29,169.92,-0.179
55.31,169.74,-0.179
55.33,169.55,-0.179
55.35,169.37,-0.179
55.37,169.19,-0.178
55.39,169.01,-0.178
55.41,168.82,-0.178
55.42,168.64,-0.178
55.44,168.46,-0.178
55.46,168.27,-0.178
55.48,168.09,-0.178
55.50,167.91,-0.178
55.51,167.72,-0.178
55.53,167.54,-0.178
55.55,167.36,-0.178
55.57,167.17,-0.178
55.59,166.99,-0.178
55.61,166.81,-0.178
55.63,166.63,-0.178
55.64,166.44,-0.178
55.66,166.26,-0.178
55.68,166.08,-0.178
55.70,165.89,-0.178
55.72,165.71,-0.178
55.74,165.53,-0.178
55.75,165.34,-0.178
55.77,165.16,-0.178
55.79,164.98,-0.178
55.81,164.79,-0.177
55.83,164.61,-0.177
55.84,164.43,-0.177
55.86,164.25,-0.177
55.88,164.06,-0.177
55.90,163.88,-0.177
55.92,163.69,-0.177
55.94,163.51,-0.177
55.96,163.33,-0.177
55.97,163.15,-0.177
55.99,162.96,-0.177
56.01,162.78,-0.177
56.03,162.60,-0.177
56.05,162.41,-0.177
56.06,162.23,-0.177
56.08,162.05,-0.177
56.10,161.86,-0.177
56.12,161.68,-0.177
56.14,161.50,-0.177
56.16,161.32,-0.177
56.18,161.13,-0.177
56.19,160.95,-0.177
56.21,160.77,-0.177
56.23,160.58,-0.177
56.25,160.40,-0.177
56.27,160.22,-0.176
56.29,160.03,-0.176
56.30,159.85,-0.176
56.32,159.67,-0.176
56.34,159.48,-0.176
56.36,159.30,-0.176
56.38,159.12,-0.176
56.39,158.93,-0.176
56.41,158.75,-0.176
56.43,158.57,-0.176
56.45,158.38,-0.176
56.47,158.20,-0.176
56.49,158.02,-0.176
56.51,157.84,-0.176
56.52,157.65,-0.176
56.54,157.47,-0.176
56.56,157.29,-0.176
56.58,157.10,-0.176
56.60,156.92,-0.176
56.61,156.74,-0.176
56.63,156.55,-0.176
56.65,156.37,-0.176
56.67,156.19,-0.176
56.69,156.00,-0.176
56.71,155.82,-0.176
56.73,155.64,-0.176
56.74,155.45,-0.175
56.76,155.27,-0.175
56.78,155.09,-0.175
56.80,154.91,-0.175
56.82,154.72,-0.175
56.84,154.54,-0.175
56.85,154.36,-0.175
56.87,154.17,-0.175
56.89,153.99,-0.175
56.91,153.81,-0.175
56.93,153.62,-0.175
56.94,153.44,-0.175
56.96,153.26,-0.175
56.98,153.07,-0.175
57.00,152.89,-0.175
57.02,152.71,-0.175
57.04,152.52,-0.175
57.06,152.34,-0.175
57.07,152.16,-0.175
57.09,151.98,-0.175
57.11,151.79,-0.175
57.13,151.61,-0.175
57.15,151.43,-0.175
57.16,151.24,-0.174
57.18,151.06,-0.174
57.20,150.88,-0.174
57.22,150.69,-0.174
57.24,150.51,-0.174
57.26,150.33,-0.174
57.28,150.14,-0.174
57.29,149.96,-0.174
57.31,149.78,-0.174
57.33,149.59,-0.174
57.35,149.41,-0.174
57.37,149.23,-0.174
57.39,149.04,-0.174
57.40,148.86,-0.174
57.42,148.68,-0.174
57.44,148.50,-0.174
57.46,148.31,-0.174
57.48,148.13,-0.174
57.49,147.95,-0.174
57.51,147.76,-0.174
57.53,147.58,-0.174
57.55,147.40,-0.174
57.57,147.21,-0.174
57.59,147.03,-0.174
57.61,146.85,-0.173
57.62,146.66,-0.173
57.64,146.48,-0.173
57.66,146.30,-0.173
57.68,146.12,-0.173
57.70,145.93,-0.173
57.71,145.75,-0.173
57.73,145.57,-0.173
57.75,145.38,-0.173
57.77,145.20,-0.173
57.79,145.02,-0.173
57.81,144.83,-0.173
57.83,144.65,-0.173
57.84,144.47,-0.173
57.86,144.28,-0.173
57.88,144.10,-0.173
57.90,143.92,-0.173
57.92,143.73,-0.173
57.94,143.55,-0.173
57.95,143.37,-0.173
57.97,143.18,-0.173
57.99,143.00,-0.173
58.01,142.82,-0.172
58.03,142.64,-0.172
58.04,142.45,-0.172
[...]
162.38,-39.89,0.045
162.39,-39.82,0.045
162.40,-39.75,0.045
162.42,-39.69,0.045
162.43,-39.62,0.045
162.45,-39.55,0.045
162.46,-39.49,0.045
162.47,-39.42,0.045
162.48,-39.35,0.045
162.50,-39.29,0.045
162.51,-39.22,0.045
162.53,-39.15,0.045
162.54,-39.09,0.045
162.55,-39.02,0.045
162.57,-38.95,0.045
162.58,-38.89,0.045
162.59,-38.82,0.045
162.60,-38.75,0.045
162.62,-38.69,0.045
162.63,-38.62,0.045
162.65,-38.55,0.045
162.66,-38.48,0.045
162.67,-38.42,0.045
162.68,-38.35,0.045
162.70,-38.28,0.045
162.71,-38.22,0.045
162.73,-38.15,0.045
162.74,-38.08,0.045
162.75,-38.02,0.045
162.77,-37.95,0.045
162.78,-37.88,0.045
162.79,-37.82,0.045
162.80,-37.75,0.045
162.82,-37.68,0.045
162.83,-37.62,0.045
162.85,-37.55,0.045
162.86,-37.48,0.045
162.87,-37.41,0.045
162.88,-37.35,0.045
162.90,-37.28,0.045
162.91,-37.22,0.045
162.93,-37.15,0.045
162.94,-37.08,0.045
162.95,-37.02,0.045
162.97,-36.95,0.045
162.98,-36.88,0.045
162.99,-36.81,0.045
163.00,-36.75,0.045
163.02,-36.68,0.045
163.03,-36.61,0.045
163.05,-36.55,0.045
163.06,-36.48,0.045
163.07,-36.42,0.045
163.08,-36.35,0.045
163.10,-36.28,0.045
163.11,-36.21,0.045
163.13,-36.15,0.045
163.14,-36.08,0.045
163.15,-36.02,0.045
163.17,-35.95,0.045
163.18,-35.88,0.045
163.19,-35.81,0.045
163.20,-35.75,0.045
163.22,-35.68,0.045
163.23,-35.62,0.045
163.25,-35.55,0.045
163.26,-35.48,0.045
163.27,-35.41,0.045
163.28,-35.35,0.045
163.30,-35.28,0.045
163.31,-35.22,0.045
163.33,-35.15,0.045
163.34,-35.08,0.045
163.35,-35.01,0.045
163.37,-34.95,0.045
163.38,-34.88,0.045
163.39,-34.81,0.045
163.40,-34.75,0.045
163.42,-34.68,0.045
163.43,-34.61,0.045
163.45,-34.55,0.045
163.46,-34.48,0.045
163.47,-34.41,0.045
163.48,-34.35,0.045
163.50,-34.28,0.045
163.51,-34.21,0.046
163.53,-34.15,0.046
163.54,-34.08,0.046
163.55,-34.01,0.046
163.57,-33.95,0.046
163.58,-33.88,0.046
163.59,-33.81,0.046
163.60,-33.75,0.046
163.62,-33.68,0.046
163.63,-33.61,0.046
163.65,-33.55,0.046
163.66,-33.48,0.046
163.67,-33.41,0.046
163.68,-33.35,0.046
163.70,-33.28,0.046
163.71,-33.21,0.046
163.73,-33.15,0.046
163.74,-33.08,0.046
163.75,-33.01,0.046
163.77,-32.95,0.046
163.78,-32.88,0.046
163.79,-32.81,0.046
163.80,-32.75,0.046
163.82,-32.68,0.046
163.83,-32.61,0.046
163.85,-32.55,0.046
163.86,-32.48,0.046
163.87,-32.41,0.046
163.88,-32.35,0.046
163.90,-32.28,0.046
163.91,-32.21,0.046
163.93,-32.15,0.046
163.94,-32.08,0.046
163.95,-32.01,0.046
163.97,-31.95,0.046
163.98,-31.88,0.046
163.99,-31.81,0.046
164.00,-31.74,0.046
164.02,-31.68,0.046
164.03,-31.61,0.046
164.05,-31.54,0.046
164.06,-31.48,0.046
164.07,-31.41,0.046
164.08,-31.34,0.046
164.10,-31.28,0.046
164.11,-31.21,0.046
164.13,-31.15,0.046
164.14,-31.08,0.046
164.15,-31.01,0.046
164.17,-30.94,0.046
164.18,-30.88,0.046
164.19,-30.81,0.046
164.20,-30.75,0.046
164.22,-30.68,0.046
164.23,-30.61,0.046
164.25,-30.54,0.046
164.26,-30.48,0.046
164.27,-30.41,0.046
164.28,-30.34,0.046
164.30,-30.27,0.046
164.31,-30.21,0.046
164.33,-30.14,0.046
164.34,-30.08,0.046
164.35,-30.01,0.046
164.37,-29.94,0.046
164.38,-29.88,0.046
164.39,-29.81,0.046
164.40,-29.74,0.046
164.42,-29.68,0.046
164.43,-29.61,0.046
164.45,-29.54,0.046
164.46,-29.48,0.046
164.47,-29.41,0.046
164.48,-29.34,0.046
164.50,-29.28,0.046
164.51,-29.21,0.046
164.53,-29.14,0.046
164.54,-29.08,0.046
164.55,-29.01,0.046
164.57,-28.94,0.046
164.58,-28.88,0.046
164.59,-28.81,0.046
164.60,-28.74,0.046
164.62,-28.68,0.046
164.63,-28.61,0.046
164.65,-28.54,0.046
164.66,-28.48,0.046
164.67,-28.41,0.046
164.68,-28.34,0.046
164.70,-28.28,0.046
164.71,-28.21,0.046
164.73,-28.14,0.047
164.74,-28.08,0.047
164.75,-28.01,0.047
164.77,-27.94,0.047
164.78,-27.88,0.047
164.79,-27.81,0.047
164.80,-27.74,0.047
164.82,-27.68,0.047
164.83,-27.61,0.047
164.85,-27.54,0.047
164.86,-27.48,0.047
164.87,-27.41,0.047
164.88,-27.34,0.047
164.90,-27.28,0.047
164.91,-27.21,0.047
164.93,-27.14,0.047
164.94,-27.07,0.047
164.95,-27.01,0.047
164.97,-26.94,0.047
164.98,-26.88,0.047
164.99,-26.81,0.047
165.00,-26.74,0.047
165.02,-26.67,0.047
165.03,-26.61,0.047
165.05,-26.54,0.047
165.06,-26.47,0.047
165.07,-26.41,0.047
165.08,-26.34,0.047
165.10,-26.27,0.047
165.11,-26.21,0.047
165.13,-26.14,0.047
165.14,-26.07,0.047
165.15,-26.01,0.047
165.17,-25.94,0.047
165.18,-25.87,0.047
165.19,-25.81,0.047
165.20,-25.74,0.047
165.22,-25.67,0.047
165.23,-25.61,0.047
165.25,-25.54,0.047
165.26,-25.47,0.047
165.27,-25.41,0.047
165.28,-25.34,0.047
165.30,-25.27,0.047
165.31,-25.21,0.047
165.33,-25.14,0.047
165.34,-25.07,0.047
165.35,-25.01,0.047
165.37,-24.94,0.047
165.38,-24.87,0.047
165.39,-24.81,0.047
165.40,-24.74,0.047
165.42,-24.67,0.047
165.43,-24.61,0.047
165.45,-24.54,0.047
165.46,-24.47,0.047
165.47,-24.41,0.047
165.48,-24.34,0.047
165.50,-24.27,0.047
165.51,-24.21,0.047
165.53,-24.14,0.047
165.54,-24.07,0.047
165.55,-24.01,0.047
165.57,-23.94,0.047
165.58,-23.87,0.047
165.59,-23.81,0.047
165.60,-23.74,0.047
165.62,-23.67,0.047
165.63,-23.61,0.047
165.65,-23.54,0.047
165.66,-23.47,0.047
165.67,-23.41,0.047
165.68,-23.34,0.047
165.70,-23.27,0.047
165.71,-23.21,0.047
165.73,-23.14,0.047
165.74,-23.07,0.047
165.75,-23.01,0.047
165.77,-22.94,0.047
165.78,-22.87,0.047
165.79,-22.80,0.047
165.80,-22.74,0.047
165.82,-22.67,0.047
165.83,-22.60,0.048
165.85,-22.54,0.048
165.86,-22.47,0.048
165.87,-22.40,0.048
165.88,-22.34,0.048
165.90,-22.27,0.048
165.91,-22.20,0.048
165.93,-22.14,0.048
165.94,-22.07,0.048
165.95,-22.01,0.048
165.97,-21.94,0.048
165.98,-21.87,0.048
165.99,-21.80,0.048
166.00,-21.74,0.048
166.02,-21.67,0.048
166.03,-21.60,0.048
166.05,-21.54,0.048
166.06,-21.47,0.048
166.07,-21.40,0.048
166.08,-21.34,0.048
166.10,-21.27,0.048
166.11,-21.20,0.048
166.13,-21.14,0.048
166.14,-21.07,0.048
166.15,-21.00,0.048
166.17,-20.94,0.048
166.18,-20.87,0.048
166.19,-20.80,0.048
166.20,-20.74,0.048
166.22,-20.67,0.048
166.23,-20.60,0.048
166.25,-20.54,0.048
166.26,-20.47,0.048
166.27,-20.40,0.048
166.28,-20.34,0.048
166.30,-20.27,0.048
166.31,-20.20,0.048
166.33,-20.14,0.048
166.34,-20.07,0.048
166.35,-20.00,0.048
166.37,-19.94,0.048
166.38,-19.87,0.048
166.39,-19.80,0.048
166.40,-19.74,0.048
166.42,-19.67,0.048
166.43,-19.60,0.048
166.45,-19.54,0.048
166.46,-19.47,0.048
166.47,-19.40,0.048
166.48,-19.34,0.048
166.50,-19.27,0.048
166.51,-19.20,0.048
166.53,-19.14,0.048
166.54,-19.07,0.048
166.55,-19.00,0.048
166.57,-18.94,0.048
166.58,-18.87,0.048
166.59,-18.80,0.048
166.60,-18.74,0.048
166.62,-18.67,0.048
166.63,-18.60,0.048
166.65,-18.54,0.048
166.66,-18.47,0.048
166.67,-18.40,0.048
166.68,-18.33,0.048
166.70,-18.27,0.048
166.71,-18.20,0.048
166.73,-18.14,0.048
166.74,-18.07,0.048
166.75,-18.00,0.048
166.77,-17.94,0.048
166.78,-17.87,0.048
166.79,-17.80,0.048
166.80,-17.74,0.048
166.82,-17.67,0.048
166.83,-17.60,0.048
166.85,-17.54,0.048
166.86,-17.47,0.048
166.87,-17.40,0.048
166.88,-17.34,0.048
166.90,-17.27,0.048
166.91,-17.20,0.048
166.93,-17.14,0.048
166.94,-17.07,0.048
166.95,-17.00,0.048
166.97,-16.94,0.048
166.98,-16.87,0.048
166.99,-16.80,0.048
167.00,-16.73,0.048
167.02,-16.67,0.048
167.03,-16.60,0.048
167.05,-16.53,0.048
167.06,-16.47,0.048
167.07,-16.40,0.048
167.08,-16.33,0.048
167.10,-16.27,0.049
167.11,-16.20,0.049
167.13,-16.13,0.049
167.14,-16.07,0.049
167.15,-16.00,0.049
167.17,-15.93,0.049
167.18,-15.87,0.049
167.19,-15.80,0.049
167.20,-15.73,0.049
167.22,-15.67,0.049
167.23,-15.60,0.049
167.25,-15.53,0.049
167.26,-15.47,0.049
167.27,-15.40,0.049
167.28,-15.33,0.049
167.30,-15.27,0.049
167.31,-15.20,0.049
167.33,-15.13,0.049
167.34,-15.07,0.049
167.35,-15.00,0.049
167.37,-14.93,0.049
167.38,-14.87,0.049
167.39,-14.80,0.049
167.40,-14.73,0.049
167.42,-14.66,0.049
167.43,-14.60,0.049
167.45,-14.53,0.049
167.46,-14.47,0.049
167.47,-14.40,0.049
167.48,-14.33,0.049
167.50,-14.27,0.049
167.51,-14.20,0.049
167.53,-14.13,0.049
167.54,-14.07,0.049
167.55,-14.00,0.049
167.57,-13.93,0.049
167.58,-13.87,0.049
167.59,-13.80,0.049
167.60,-13.73,0.049
167.62,-13.67,0.049
167.63,-13.60,0.049
167.65,-13.53,0.049
167.66,-13.47,0.049
167.67,-13.40,0.049
167.68,-13.33,0.049
167.70,-13.27,0.049
167.71,-13.20,0.049
167.73,-13.13,0.049
167.74,-13.07,0.049
167.75,-13.00,0.049
167.77,-12.93,0.049
167.78,-12.87,0.049
167.79,-12.80,0.049
167.80,-12.73,0.049
167.82,-12.67,0.049
167.83,-12.60,0.049
167.85,-12.53,0.049
167.86,-12.47,0.049
167.87,-12.40,0.049
167.88,-12.33,0.049
167.90,-12.26,0.049
167.91,-12.20,0.049
167.93,-12.13,0.049
167.94,-12.07,0.049
167.95,-12.00,0.049
167.97,-11.93,0.049
167.98,-11.87,0.049
167.99,-11.80,0.049
168.00,-11.73,0.049
168.02,-11.67,0.049
168.03,-11.60,0.049
168.05,-11.53,0.049
168.06,-11.47,0.049
168.07,-11.40,0.049
168.08,-11.33,0.049
168.10,-11.26,0.049
168.11,-11.20,0.049
168.13,-11.13,0.049
168.14,-11.07,0.049
168.15,-11.00,0.049
168.17,-10.93,0.049
168.18,-10.86,0.049
168.19,-10.80,0.049
168.20,-10.73,0.049
168.22,-10.66,0.049
168.23,-10.60,0.049
168.25,-10.53,0.049
168.26,-10.46,0.049
168.27,-10.40,0.049
168.28,-10.33,0.050
168.30,-10.26,0.050
168.31,-10.20,0.050
168.33,-10.13,0.050
168.34,-10.07,0.050
168.35,-10.00,0.050
168.37,-9.93,0.050
168.38,-9.86,0.050
168.39,-9.80,0.050
168.40,-9.73,0.050
168.42,-9.66,0.050
168.43,-9.60,0.050
168.45,-9.53,0.050
168.46,-9.46,0.050
168.47,-9.40,0.050
168.48,-9.33,0.050
168.50,-9.26,0.050
168.51,-9.20,0.050
168.53,-9.13,0.050
168.54,-9.06,0.050
168.55,-9.00,0.050
168.57,-8.93,0.050
168.58,-8.86,0.050
168.59,-8.80,0.050
168.60,-8.73,0.050
168.62,-8.66,0.050
168.63,-8.60,0.050
168.65,-8.53,0.050
168.66,-8.46,0.050
168.67,-8.40,0.050
168.68,-8.33,0.050
168.70,-8.26,0.050
168.71,-8.20,0.050
168.73,-8.13,0.050
168.74,-8.06,0.050
168.75,-8.00,0.050
168.77,-7.93,0.050
168.78,-7.86,0.050
168.79,-7.79,0.050
168.80,-7.73,0.050
168.82,-7.66,0.050
168.83,-7.60,0.050
168.85,-7.53,0.050
168.86,-7.46,0.050
168.87,-7.40,0.050
168.88,-7.33,0.050
168.90,-7.26,0.050
168.91,-7.20,0.050
168.93,-7.13,0.050
168.94,-7.06,0.050
168.95,-7.00,0.050
168.97,-6.93,0.050
168.98,-6.86,0.050
168.99,-6.80,0.050
169.00,-6.73,0.050
169.02,-6.66,0.050
169.03,-6.60,0.050
169.05,-6.53,0.050
169.06,-6.46,0.050
169.07,-6.39,0.050
169.08,-6.33,0.050
169.10,-6.26,0.050
169.11,-6.19,0.050
169.13,-6.13,0.050
169.14,-6.06,0.050
169.15,-5.99,0.050
169.17,-5.93,0.050
169.18,-5.86,0.050
169.19,-5.79,0.050
169.20,-5.73,0.050
169.22,-5.66,0.050
169.23,-5.59,0.050
169.25,-5.53,0.050
169.26,-5.46,0.050
169.27,-5.39,0.050
169.28,-5.33,0.050
169.30,-5.26,0.050
169.31,-5.19,0.050
169.33,-5.13,0.050
169.34,-5.06,0.050
169.35,-4.99,0.050
169.37,-4.93,0.050
169.38,-4.86,0.051
169.39,-4.79,0.051
169.40,-4.73,0.051
169.42,-4.66,0.051
169.43,-4.59,0.051
169.45,-4.53,0.051
169.46,-4.46,0.051
169.47,-4.39,0.051
169.48,-4.33,0.051
169.50,-4.26,0.051
169.51,-4.19,0.051
169.53,-4.13,0.051
169.54,-4.06,0.051
169.55,-3.99,0.051
169.57,-3.93,0.051
169.58,-3.86,0.051
169.59,-3.79,0.051
169.60,-3.73,0.051
169.62,-3.66,0.051
169.63,-3.59,0.051
169.65,-3.52,0.051
169.66,-3.46,0.051
169.67,-3.39,0.051
169.68,-3.33,0.051
169.70,-3.26,0.051
169.71,-3.19,0.051
169.73,-3.13,0.051
169.74,-3.06,0.051
169.75,-2.99,0.051
169.77,-2.93,0.051
169.78,-2.86,0.051
169.79,-2.79,0.051
169.80,-2.73,0.051
169.82,-2.66,0.051
169.83,-2.59,0.051
169.85,-2.52,0.051
169.86,-2.46,0.051
169.87,-2.39,0.051
169.88,-2.33,0.051
169.90,-2.26,0.051
169.91,-2.19,0.051
169.93,-2.12,0.051
169.94,-2.06,0.051
169.95,-1.99,0.051
169.97,-1.92,0.051
169.98,-1.86,0.051
169.99,-1.79,0.051
170.00,-1.72,0.051
170.02,-1.66,0.051
170.03,-1.59,0.051
170.05,-1.52,0.051
170.06,-1.46,0.051
170.07,-1.39,0.051
170.08,-1.32,0.051
170.10,-1.26,0.051
170.11,-1.19,0.051
170.13,-1.12,0.051
170.14,-1.06,0.051
170.15,-0.99,0.051
170.17,-0.92,0.051
170.18,-0.86,0.051
170.19,-0.79,0.051
170.20,-0.72,0.051
170.22,-0.66,0.051
170.23,-0.59,0.051
170.25,-0.52,0.051
170.26,-0.46,0.051
170.27,-0.39,0.051
170.28,-0.32,0.051
170.30,-0.26,0.051
170.31,-0.19,0.051
170.33,-0.12,0.051
170.34,-0.06,0.051
170.35,0.01,0.051
170.37,0.08,0.051
170.38,0.14,0.051
170.39,0.21,0.051
170.40,0.28,0.051
170.42,0.34,0.051
170.43,0.41,0.051
170.45,0.48,0.051
170.46,0.54,0.051
170.47,0.61,0.051
170.48,0.68,0.051
170.50,0.74,0.051
170.51,0.81,0.051
170.53,0.88,0.051
170.54,0.94,0.051
170.55,1.01,0.051
170.57,1.08,0.051
170.58,1.14,0.051
170.59,1.21,0.051
170.60,1.28,0.051
170.62,1.34,0.051
170.63,1.41,0.051
170.65,1.48,0.051
170.66,1.54,0.051
170.67,1.61,0.052
170.68,1.68,0.052
170.70,1.74,0.052
170.71,1.81,0.052
170.73,1.88,0.052
170.74,1.94,0.052
170.75,2.01,0.052
170.77,2.08,0.052
170.78,2.15,0.052
170.79,2.21,0.052
170.80,2.28,0.052
170.82,2.35,0.052
170.83,2.41,0.052
170.85,2.48,0.052
170.86,2.55,0.052
170.87,2.61,0.052
170.88,2.68,0.052
170.90,2.74,0.052
170.91,2.81,0.052
170.93,2.88,0.052
170.94,2.95,0.052
170.95,3.01,0.052
170.97,3.08,0.052
170.98,3.15,0.052
170.99,3.21,0.052
171.00,3.28,0.052
171.02,3.35,0.052
171.03,3.41,0.052
171.05,3.48,0.052
171.06,3.54,0.052
171.07,3.61,0.052
171.08,3.68,0.052
171.10,3.75,0.052
171.11,3.81,0.052
171.13,3.88,0.052
171.14,3.95,0.052
171.15,4.01,0.052
171.17,4.08,0.052
171.18,4.15,0.052
171.19,4.21,0.052
171.20,4.28,0.052
171.22,4.35,0.052
171.23,4.41,0.052
171.25,4.48,0.052
171.26,4.55,0.052
171.27,4.61,0.052
171.28,4.68,0.052
171.30,4.75,0.052
171.31,4.81,0.052
171.33,4.88,0.052
171.34,4.95,0.052
171.35,5.01,0.052
171.37,5.08,0.052
171.38,5.15,0.052
171.39,5.21,0.052
171.40,5.28,0.052
171.42,5.35,0.052
171.43,5.41,0.052
171.45,5.48,0.052
171.46,5.55,0.052
171.47,5.61,0.052
171.48,5.68,0.052
171.50,5.75,0.052
171.51,5.81,0.052
171.53,5.88,0.052
171.54,5.95,0.052
171.55,6.01,0.052
171.57,6.08,0.052
171.58,6.15,0.052
171.59,6.21,0.052
171.60,6.28,0.052
171.62,6.35,0.052
171.63,6.41,0.052
171.65,6.48,0.052
171.66,6.55,0.052
171.67,6.61,0.052
171.68,6.68,0.052
171.70,6.75,0.052
171.71,6.81,0.052
171.73,6.88,0.052
171.74,6.95,0.052
171.75,7.01,0.052
171.77,7.08,0.052
171.78,7.15,0.052
171.79,7.22,0.052
171.80,7.28,0.052
171.82,7.35,0.053
171.83,7.41,0.053
171.85,7.48,0.053
171.86,7.55,0.053
171.87,7.61,0.053
171.88,7.68,0.053
171.90,7.75,0.053
171.91,7.82,0.053
171.93,7.88,0.053
171.94,7.95,0.053
171.95,8.01,0.053
171.97,8.08,0.053
171.98,8.15,0.053
171.99,8.21,0.053
172.00,8.28,0.053
172.02,8.35,0.053
172.03,8.42,0.053
172.05,8.48,0.053
172.06,8.55,0.053
172.07,8.62,0.053
172.08,8.68,0.053
172.10,8.75,0.053
172.11,8.82,0.053
172.13,8.88,0.053
172.14,8.95,0.053
172.15,9.02,0.053
172.17,9.08,0.053
172.18,9.15,0.053
172.19,9.22,0.053
172.20,9.28,0.053
172.22,9.35,0.053
172.23,9.42,0.053
172.25,9.48,0.053
172.26,9.55,0.053
172.27,9.62,0.053
172.28,9.68,0.053
172.30,9.75,0.053
172.31,9.82,0.053
172.33,9.88,0.053
172.34,9.95,0.053
172.35,10.02,0.053
172.37,10.08,0.053
172.38,10.15,0.053
172.39,10.22,0.053
172.40,10.28,0.053
172.42,10.35,0.053
172.43,10.42,0.053
172.45,10.48,0.053
172.46,10.55,0.053
172.47,10.62,0.053
172.48,10.68,0.053
172.50,10.75,0.053
172.51,10.82,0.053
172.53,10.88,0.053
172.54,10.95,0.053
172.55,11.02,0.053
172.57,11.08,0.053
172.58,11.15,0.053
172.59,11.22,0.053
172.60,11.28,0.053
172.62,11.35,0.053
172.63,11.42,0.053
172.65,11.48,0.053
172.66,11.55,0.053
172.67,11.62,0.053
172.68,11.68,0.053
172.70,11.75,0.053
172.71,11.82,0.053
172.73,11.88,0.053
172.74,11.95,0.053
172.75,12.02,0.053
172.77,12.08,0.053
172.78,12.15,0.053
172.79,12.22,0.053
172.80,12.28,0.053
172.82,12.35,0.053
172.83,12.42,0.053
172.85,12.48,0.053
172.86,12.55,0.053
172.87,12.62,0.053
172.88,12.68,0.053
172.90,12.75,0.053
172.91,12.82,0.053
172.93,12.88,0.053
172.94,12.95,0.053
172.95,13.02,0.053
172.97,13.08,0.053
172.98,13.15,0.053
172.99,13.22,0.053
173.00,13.28,0.053
173.02,13.35,0.053
173.03,13.42,0.054
173.05,13.48,0.054
173.06,13.55,0.054
173.07,13.62,0.054
173.08,13.68,0.054
173.10,13.75,0.054
173.11,13.82,0.054
173.13,13.88,0.054
173.14,13.95,0.054
173.15,14.02,0.054
173.17,14.08,0.054
173.18,14.15,0.054
173.19,14.22,0.054
173.20,14.28,0.054
173.22,14.35,0.054
173.23,14.42,0.054
173.25,14.49,0.054
173.26,14.55,0.054
173.27,14.62,0.054
173.28,14.69,0.054
173.30,14.75,0.054
173.31,14.82,0.054
173.33,14.89,0.054
173.34,14.95,0.054
173.35,15.02,0.054
173.37,15.09,0.054
173.38,15.15,0.054
173.39,15.22,0.054
173.40,15.29,0.054
173.42,15.35,0.054
173.43,15.42,0.054
173.45,15.49,0.054
173.46,15.55,0.054
173.47,15.62,0.054
173.48,15.69,0.054
173.50,15.75,0.054
173.51,15.82,0.054
173.53,15.89,0.054
173.54,15.95,0.054
173.55,16.02,0.054
173.57,16.09,0.054
173.58,16.15,0.054
173.59,16.22,0.054
173.60,16.29,0.054
173.62,16.35,0.054
173.63,16.42,0.054
173.65,16.49,0.054
173.66,16.55,0.054
173.67,16.62,0.054
173.68,16.69,0.054
173.70,16.76,0.054
173.71,16.82,0.054
173.73,16.89,0.054
173.74,16.95,0.054
173.75,17.02,0.054
173.77,17.09,0.054
173.78,17.15,0.054
173.79,17.22,0.054
173.80,17.29,0.054
173.82,17.35,0.054
173.83,17.42,0.054
173.85,17.49,0.054
173.86,17.55,0.054
173.87,17.62,0.054
173.88,17.69,0.054
173.90,17.75,0.054
173.91,17.82,0.054
173.93,17.89,0.054
173.94,17.95,0.054
173.95,18.02,0.054
173.97,18.09,0.054
173.98,18.15,0.054
173.99,18.22,0.054
174.00,18.29,0.054
174.02,18.35,0.054
174.03,18.42,0.054
174.05,18.49,0.054
174.06,18.55,0.054
174.07,18.62,0.054
174.08,18.69,0.054
174.10,18.76,0.054
174.11,18.82,0.054
174.13,18.89,0.054
174.14,18.95,0.054
174.15,19.02,0.054
174.17,19.09,0.054
174.18,19.15,0.054
174.19,19.22,0.054
174.20,19.29,0.054
174.22,19.36,0.054
174.23,19.42,0.054
174.25,19.49,0.054
174.26,19.56,0.054
174.27,19.62,0.055
174.28,19.69,0.055
174.30,19.75,0.055
174.31,19.82,0.055
174.33,19.89,0.055
174.34,19.95,0.055
174.35,20.02,0.055
174.37,20.09,0.055
174.38,20.15,0.055
174.39,20.22,0.055
174.40,20.29,0.055
174.42,20.36,0.055
174.43,20.42,0.055
174.45,20.49,0.055
174.46,20.56,0.055
174.47,20.62,0.055
174.48,20.69,0.055
174.50,20.76,0.055
174.51,20.82,0.055
174.53,20.89,0.055
174.54,20.96,0.055
174.55,21.02,0.055
174.57,21.09,0.055
174.58,21.16,0.055
174.59,21.22,0.055
174.60,21.29,0.055
174.62,21.36,0.055
174.63,21.42,0.055
174.65,21.49,0.055
174.66,21.56,0.055
174.67,21.62,0.055
174.68,21.69,0.055
174.70,21.76,0.055
174.71,21.82,0.055
174.73,21.89,0.055
174.74,21.96,0.055
174.75,22.02,0.055
174.77,22.09,0.055
174.78,22.16,0.055
174.79,22.22,0.055
174.80,22.29,0.055
174.82,22.36,0.055
174.83,22.42,0.055
174.85,22.49,0.055
174.86,22.56,0.055
174.87,22.62,0.055
174.88,22.69,0.055
174.90,22.76,0.055
174.91,22.82,0.055
174.93,22.89,0.055
174.94,22.96,0.055
174.95,23.02,0.055
174.97,23.09,0.055
174.98,23.16,0.055
174.99,23.22,0.055
175.00,23.29,0.055
175.02,23.36,0.055
175.03,23.42,0.055
175.05,23.49,0.055
175.06,23.56,0.055
175.07,23.62,0.055
175.08,23.69,0.055
175.10,23.76,0.055
175.11,23.82,0.055
175.13,23.89,0.055
175.14,23.96,0.055
175.15,24.02,0.055
175.17,24.09,0.055
175.18,24.16,0.055
175.19,24.22,0.055
175.20,24.29,0.055
175.22,24.36,0.055
175.23,24.43,0.055
175.25,24.49,0.055
175.26,24.56,0.055
175.27,24.62,0.055
175.28,24.69,0.055
175.30,24.76,0.055
175.31,24.83,0.055
175.33,24.89,0.055
175.34,24.96,0.055
175.35,25.03,0.055
175.37,25.09,0.055
175.38,25.16,0.055
175.39,25.23,0.055
175.40,25.29,0.055
175.42,25.36,0.055
175.43,25.43,0.055
175.45,25.49,0.055
175.46,25.56,0.056
175.47,25.63,0.056
175.48,25.69,0.056
175.50,25.76,0.056
175.51,25.83,0.056
175.53,25.89,0.056
175.54,25.96,0.056
175.55,26.03,0.056
175.57,26.09,0.056
175.58,26.16,0.056
175.59,26.23,0.056
175.60,26.29,0.056
175.62,26.36,0.056
175.63,26.43,0.056
175.65,26.49,0.056
175.66,26.56,0.056
175.67,26.63,0.056
175.68,26.69,0.056
175.70,26.76,0.056
175.71,26.83,0.056
175.73,26.89,0.056
175.74,26.96,0.056
175.75,27.03,0.056
175.77,27.09,0.056
175.78,27.16,0.056
175.79,27.23,0.056
175.80,27.29,0.056
175.82,27.36,0.056
175.83,27.43,0.056
175.85,27.49,0.056
175.86,27.56,0.056
175.87,27.63,0.056
175.88,27.69,0.056
175.90,27.76,0.056
175.91,27.83,0.056
175.93,27.89,0.056
175.94,27.96,0.056
175.95,28.03,0.056
175.97,28.09,0.056
175.98,28.16,0.056
175.99,28.23,0.056
176.00,28.29,0.056
176.02,28.36,0.056
176.03,28.43,0.056
176.05,28.49,0.056
176.06,28.56,0.056
176.07,28.63,0.056
176.08,28.70,0.056
176.10,28.76,0.056
176.11,28.83,0.056
176.13,28.89,0.056
176.14,28.96,0.056
176.15,29.03,
176.17,29.09,
176.18,29.16,
176.19,29.23,
176.20,,