File: DSC/2025_04_18_CBD_Pro_n60C_170C_5Cmin_x3.csv
Filename,2025_04_18_CBD_Pro_n60C_170C_5Cmin_x3
Instrument name,DSC2A-00468 (192.168.1.100)
Operator,Yarger
rundate,4/19/2025
Sample name,2025_04_18_CBD_Pro_n60C_170C_5Cmin_x3
proceduresegments,Data Off ; Equilibrate -60.00 °C; Data On ; Ramp 5.00 °C/min to 170.00 °C; Data Off ; Isothermal 0.1 min; Data On ; Ramp 10.00 °C/min to -60.00 °C; Data Off ; Isothermal 1.0 min; Data On ; Ramp 5.00 °C/min to 170.00 °C; Data Off ; Isothermal 0.1 min; Data On ; Ramp 10.00 °C/min to -60.00 °C; Data Off ; Isothermal 1.0 min; Data On ; Ramp 5.00 °C/min to 170.00 °C
[File Parameters]
Run date,4/19/2025 12:29:55 AM
Trios version,5.1.1.46572
Original File Name,
Current File Name,D:\DSC2500\JYarger\2025_04_18_CBD_Pro_n60C_170C_5Cmin_x3.tri
[Procedure]
Procedure Name,CBD_Pro_n60_170C_5Cmin_x3
Sample Name,2025_04_18_CBD_Pro_n60C_170C_5Cmin_x3
Sample Mass,2.48 mg
Reference Sample Mass,0 mg
Pan Mass,53.24 mg
Pan Number,25
Reference Pan Mass,53.66 mg
Reference Pan Number,46
Pan Type,Tzero Aluminum Hermetic
Comments,Hermetic Sealed Al DSC Consumables Pan/Lids.
Project Name,CA
Operator,Yarger
Test,Custom
Unload Max Temperature,30
Unload Min Temperature,30
Load Max Temperature,30
Load Min Temperature,30
Stop on Gas Flow Error,Yes
[Signal List]
Signal #1,Time (min)
Signal #2,Temperature (°C)
Signal #3,Heat Flow (mW)
Signal #4,Delta T (µV)
Signal #5,Delta Tzero (µV)
Signal #6,Tzero Temperature (°C)
Signal #7,Cell Purge (mL/min)
Signal #8,Heater Temp (°C)
Signal #9,Power Delivered (W)
Signal #10,Reference Junction Temperature (°C)
Signal #11,Flange Temperature (°C)
Signal #12,Heat Flow Phase (rad)
Signal #13,Total Heat Capacity (J/°C)
Signal #14,Heat Capacity (J/°C)
[Configuration]
Company Name,ASU
Instrument Name,DSC2A-00468
Instrument Type,DSC2500
Serial Number,DSC2A-00468
IP,192.168.1.100
Location of Instrument,MRRC
DisplayType,Unknown
Sample Interval ,0.1 s/pt
Selected Heat Flow,T4P
Exotherm Direction,Down
Cell Serial,DRC2-00792
Lid Type,Standard
Cooler,RCS 90
Leave Cooler on at End of Sequence,On
Gas 2,Nitrogen
Gas Selected,Channel 1
Flow Rate,50 mL/min
Secondary Purge,On
Licensed Heat Flow,Heat Flow T4P
Modulation Licensed,Yes
[Versions]
Common IDD Version,1
Cortex Version,VER 2.10.2.31
Driver,5.0.0.6
GDM Version,1.0.3.3
TouchscreenVersion,1.0.0.16145
FEP Version,1.2.1.21
FEP Bootloader,2.0.0.5
AutoSampler Version,2.1.1.26
Auto Sampler Bootloader,2.0.0.5
FCM Version,1.1.0.3
FCM Bootloader,2.0.0.5
[Experiment Logs]
Experiment Log Entry # 1,Data On set to 0
Experiment Log Entry # 3,Equilibrate Segment -60 (C) Started
Experiment Log Entry # 5,Air Cool is off.
Experiment Log Entry # 7,Data On set to 1
Experiment Log Entry # 9,Ramp Segment 5 C/min to 170 Started
Experiment Log Entry # 11,Data On set to 0
Experiment Log Entry # 13,Isothermal Segment 0.1 min started
Experiment Log Entry # 15,Data On set to 1
Experiment Log Entry # 17,Ramp Segment 10 C/min to -60 Started
Experiment Log Entry # 19,Data On set to 0
Experiment Log Entry # 21,Isothermal Segment 1 min started
Experiment Log Entry # 23,Data On set to 1
Experiment Log Entry # 25,Ramp Segment 5 C/min to 170 Started
Experiment Log Entry # 27,Data On set to 0
Experiment Log Entry # 29,Isothermal Segment 0.1 min started
Experiment Log Entry # 31,Data On set to 1
Experiment Log Entry # 33,Ramp Segment 10 C/min to -60 Started
Experiment Log Entry # 35,Data On set to 0
Experiment Log Entry # 37,Isothermal Segment 1 min started
Experiment Log Entry # 39,Data On set to 1
Experiment Log Entry # 41,Ramp Segment 5 C/min to 170 Started
[Method Log]
Method Log Entry # 1,Data Off
Method Log Entry # 2,Equilibrate -60 °C
Method Log Entry # 3,Data On
Method Log Entry # 4,(Ramp 142250) Ramp 5 °C/minute to 170 °C
Method Log Entry # 5,Data Off
Method Log Entry # 6,Isothermal 0.1 minutes
Method Log Entry # 7,Data On
Method Log Entry # 8,(Ramp 142254) Ramp 10 °C/minute to -60 °C
Method Log Entry # 9,Data Off
Method Log Entry # 10,Isothermal 1 minutes
Method Log Entry # 11,Data On
Method Log Entry # 12,(Ramp 142258) Ramp 5 °C/minute to 170 °C
Method Log Entry # 13,Data Off
Method Log Entry # 14,Isothermal 0.1 minutes
Method Log Entry # 15,Data On
Method Log Entry # 16,(Ramp 142262) Ramp 10 °C/minute to -60 °C
Method Log Entry # 17,Data Off
Method Log Entry # 18,Isothermal 1 minutes
Method Log Entry # 19,Data On
Method Log Entry # 20,(Ramp 142266) Ramp 5 °C/minute to 170 °C
Cell Serial,DRC2-00792
[T1 Calibration]
Slope,-0.008529666
Offset,9.636258
Initial Temperature,98.23
GUID,f8bfdadc-4977-4fdf-ba6d-0ba9134940c3
[TZero Calibration]
Date Applied,11/29/2022 4:06:13 PM
Description,From -89.059 °C to 396.009 °C at 20.000°C/min
Gas Type,Nitrogen
Pan Type,None
Source Files 1,C:\Users\yargerlab\Desktop\DSC Data\General\TZero_calibration_11_29_22_2nd(2).tri
Source Files 2,C:\Users\yargerlab\Desktop\DSC Data\General\TZero_calibration_11_29_22_2nd(3).tri
Delta T Offset,13.05235
Delta T Slope,-0.007271007
Delta T0 Offset,-13.69128
Delta T0 Slope,0.06063341
[Temperature Calibration]
Date Applied,11/29/2022 7:12:28 PM
Description,From 106.590 °C to 186.590 °C at 10.000°C/min
Gas Type,Nitrogen
Pan Type,Tzero Aluminum Hermetic
Source Files 1,C:\Users\yargerlab\Desktop\DSC Data\General\Indium(6).tri
Measured 1,157.391
Known 1,156.598
[Cell Constant Calibration]
Date Applied,11/29/2022 7:12:29 PM
Description,From 106.590 °C to 186.590 °C at 10.000°C/min
Gas Type,Nitrogen
Pan Type,Tzero Aluminum Hermetic
Source Files 1,C:\Users\yargerlab\Desktop\DSC Data\General\Indium(6).tri
T4P KCell,1.006051
Onset Slope,63.26126 mW/°C
[Direct Cp Calibration]
Date Applied,11/30/2022 11:04:51 AM
Description,From -79.983 °C to 298.409 °C at 10.000°C/min
Gas Type,Nitrogen
Pan Type,Tzero Aluminum Hermetic
Source Files 1,C:\Users\yargerlab\Desktop\DSC Data\General\Sapphire_Heat_Capacity_11_30_22.tri
[Rev Cp Calibration]
Date Applied,11/30/2022 1:58:51 PM
Description,From -79.996 °C to 292.812 °C at 3.000°C/min
Gas Type,Nitrogen
Pan Type,Tzero Aluminum Hermetic
Source Files 1,C:\Users\yargerlab\Desktop\DSC Data\General\Sapphire_MDSC_Calibration_11_30_22.tri
[step]
Ramp 5.00 °C/min to 170.00 °C
Time,Temperature,Heat Flow (Normalized)
min,°C,W/g
0.00,-59.69,-0.034
0.03,-59.71,-0.032
0.06,-59.71,-0.015
0.09,-59.68,0.019
0.13,-59.62,0.042
0.16,-59.52,0.062
0.19,-59.41,0.075
0.22,-59.28,0.084
0.25,-59.15,0.089
0.29,-59.01,0.094
0.32,-58.87,0.099
0.35,-58.73,0.103
0.38,-58.58,0.104
0.41,-58.43,0.105
0.44,-58.28,0.106
0.48,-58.13,0.107
0.51,-57.98,0.108
0.54,-57.82,0.109
0.57,-57.67,0.110
0.60,-57.52,0.110
0.63,-57.36,0.111
0.67,-57.21,0.111
0.70,-57.06,0.111
0.73,-56.90,0.111
0.76,-56.74,0.112
0.79,-56.59,0.112
0.82,-56.43,0.112
0.85,-56.28,0.111
0.89,-56.12,0.111
0.92,-55.97,0.111
0.95,-55.81,0.111
0.98,-55.65,0.111
1.01,-55.50,0.111
1.05,-55.34,0.110
1.08,-55.18,0.110
1.11,-55.03,0.110
1.14,-54.87,0.109
1.17,-54.71,0.109
1.20,-54.56,0.109
1.23,-54.40,0.109
1.27,-54.24,0.108
1.30,-54.08,0.108
1.33,-53.93,0.108
1.36,-53.77,0.107
1.39,-53.61,0.107
1.43,-53.46,0.107
1.46,-53.30,0.107
1.49,-53.14,0.107
1.52,-52.98,0.106
1.55,-52.82,0.106
1.58,-52.67,0.106
1.62,-52.51,0.106
1.65,-52.35,0.106
1.68,-52.19,0.105
1.71,-52.04,0.105
1.74,-51.88,0.105
1.77,-51.72,0.105
1.81,-51.56,0.105
1.84,-51.40,0.105
1.87,-51.24,0.104
1.90,-51.09,0.104
1.93,-50.93,0.104
1.96,-50.77,0.104
1.99,-50.61,0.104
2.03,-50.46,0.104
2.06,-50.30,0.103
2.09,-50.14,0.103
2.12,-49.98,0.103
2.15,-49.82,0.103
2.19,-49.67,0.103
2.22,-49.51,0.103
2.25,-49.35,0.103
2.28,-49.19,0.103
2.31,-49.03,0.102
2.34,-48.87,0.102
2.38,-48.72,0.102
2.41,-48.56,0.102
2.44,-48.40,0.102
2.47,-48.24,0.102
2.50,-48.08,0.102
2.53,-47.93,0.102
2.56,-47.77,0.102
2.60,-47.61,0.101
2.63,-47.45,0.101
2.66,-47.29,0.101
2.69,-47.13,0.101
2.72,-46.98,0.101
2.76,-46.82,0.101
2.79,-46.66,0.101
2.82,-46.50,0.101
2.85,-46.34,0.101
2.88,-46.18,0.101
2.91,-46.03,0.100
2.94,-45.87,0.100
2.98,-45.71,0.100
3.01,-45.55,0.100
3.04,-45.39,0.100
3.07,-45.23,0.100
3.10,-45.08,0.100
3.14,-44.92,0.100
3.17,-44.76,0.100
3.20,-44.60,0.100
3.23,-44.44,0.100
3.26,-44.29,0.100
3.29,-44.13,0.100
3.33,-43.97,0.099
3.36,-43.81,0.099
3.39,-43.65,0.100
3.42,-43.49,0.099
3.45,-43.34,0.099
3.48,-43.18,0.099
3.51,-43.02,0.099
3.55,-42.86,0.099
3.58,-42.70,0.099
3.61,-42.54,0.099
3.64,-42.39,0.099
3.67,-42.23,0.099
3.71,-42.07,0.099
3.74,-41.91,0.099
3.77,-41.75,0.099
3.80,-41.59,0.099
3.83,-41.44,0.098
3.86,-41.28,0.099
3.89,-41.12,0.099
3.93,-40.96,0.099
3.96,-40.80,0.099
3.99,-40.64,0.098
4.02,-40.48,0.099
4.05,-40.33,0.099
4.09,-40.17,0.098
4.12,-40.01,0.098
4.15,-39.85,0.098
4.18,-39.69,0.098
4.21,-39.53,0.098
4.24,-39.37,0.098
4.28,-39.22,0.098
4.31,-39.06,0.098
4.34,-38.90,0.098
4.37,-38.74,0.098
4.40,-38.58,0.098
4.43,-38.42,0.098
4.46,-38.26,0.098
4.50,-38.11,0.098
4.53,-37.95,0.098
4.56,-37.79,0.098
4.59,-37.63,0.098
4.62,-37.47,0.097
4.65,-37.31,0.097
4.69,-37.15,0.097
4.72,-36.99,0.097
4.75,-36.84,0.097
4.78,-36.68,0.097
4.81,-36.52,0.097
4.85,-36.36,0.097
4.88,-36.20,0.097
4.91,-36.04,0.097
4.94,-35.89,0.097
4.97,-35.73,0.097
5.00,-35.57,0.097
5.04,-35.41,0.097
5.07,-35.25,0.097
5.10,-35.09,0.097
5.13,-34.94,0.097
5.16,-34.77,0.097
5.19,-34.62,0.097
5.23,-34.46,0.097
5.26,-34.30,0.097
5.29,-34.14,0.097
5.32,-33.98,0.097
5.35,-33.83,0.097
5.38,-33.67,0.097
5.41,-33.51,0.097
5.45,-33.35,0.097
5.48,-33.19,0.097
5.51,-33.03,0.097
5.54,-32.87,0.097
5.57,-32.71,0.097
5.60,-32.56,0.097
5.64,-32.40,0.097
5.67,-32.24,0.097
5.70,-32.08,0.097
5.73,-31.92,0.097
5.76,-31.76,0.096
5.80,-31.61,0.096
5.83,-31.45,0.097
5.86,-31.29,0.096
5.89,-31.13,0.097
5.92,-30.97,0.096
5.95,-30.81,0.096
5.99,-30.65,0.096
6.02,-30.50,0.096
6.05,-30.34,0.096
6.08,-30.18,0.096
6.11,-30.02,0.096
6.14,-29.86,0.096
6.18,-29.70,0.096
6.21,-29.55,0.096
6.24,-29.39,0.096
6.27,-29.23,0.096
6.30,-29.07,0.096
6.33,-28.91,0.096
6.36,-28.75,0.096
6.40,-28.60,0.096
6.43,-28.44,0.096
6.46,-28.28,0.096
6.49,-28.12,0.096
6.52,-27.96,0.096
6.55,-27.81,0.096
6.59,-27.65,0.096
6.62,-27.49,0.096
6.65,-27.33,0.096
6.68,-27.17,0.096
6.71,-27.01,0.096
6.75,-26.86,0.096
6.78,-26.70,0.096
6.81,-26.54,0.096
6.84,-26.38,0.096
6.87,-26.22,0.096
6.90,-26.06,0.096
6.94,-25.90,0.096
6.97,-25.74,0.096
7.00,-25.59,0.096
7.03,-25.43,0.096
7.06,-25.27,0.096
7.09,-25.11,0.096
7.13,-24.95,0.096
7.16,-24.79,0.096
7.19,-24.64,0.096
7.22,-24.48,0.096
7.25,-24.32,0.096
7.28,-24.16,0.096
7.31,-24.00,0.096
7.35,-23.84,0.096
7.38,-23.68,0.096
7.41,-23.52,0.096
7.44,-23.37,0.096
7.47,-23.21,0.096
7.50,-23.05,0.096
7.54,-22.89,0.096
7.57,-22.73,0.096
7.60,-22.57,0.096
7.63,-22.42,0.096
7.66,-22.26,0.096
7.70,-22.10,0.096
7.73,-21.94,0.096
7.76,-21.78,0.096
7.79,-21.62,0.096
7.82,-21.46,0.096
7.85,-21.31,0.096
7.89,-21.15,0.096
7.92,-20.99,0.096
7.95,-20.83,0.096
7.98,-20.67,0.096
8.01,-20.51,0.096
8.04,-20.35,0.096
8.08,-20.20,0.096
8.11,-20.04,0.096
8.14,-19.88,0.096
8.17,-19.72,0.096
8.20,-19.56,0.096
8.23,-19.40,0.096
8.26,-19.24,0.096
8.30,-19.09,0.096
8.33,-18.93,0.096
8.36,-18.77,0.096
8.39,-18.61,0.096
8.42,-18.45,0.096
8.45,-18.30,0.096
8.49,-18.14,0.096
8.52,-17.98,0.096
8.55,-17.82,0.096
8.58,-17.66,0.096
8.61,-17.50,0.096
8.65,-17.34,0.096
8.68,-17.18,0.096
8.71,-17.03,0.096
8.74,-16.87,0.096
8.77,-16.71,0.096
8.80,-16.55,0.096
8.83,-16.39,0.096
8.87,-16.23,0.096
8.90,-16.08,0.096
8.93,-15.92,0.096
8.96,-15.76,0.096
8.99,-15.60,0.095
9.03,-15.44,0.096
9.06,-15.28,0.096
9.09,-15.12,0.096
9.12,-14.97,0.095
9.15,-14.81,0.095
9.18,-14.65,0.095
9.22,-14.49,0.096
9.25,-14.33,0.096
9.28,-14.17,0.095
9.31,-14.02,0.095
9.34,-13.86,0.095
9.37,-13.70,0.095
9.40,-13.54,0.096
9.44,-13.38,0.095
9.47,-13.22,0.096
9.50,-13.06,0.096
9.53,-12.90,0.096
9.56,-12.74,0.096
9.60,-12.59,0.096
9.63,-12.43,0.096
9.66,-12.27,0.096
9.69,-12.11,0.096
9.72,-11.95,0.096
9.75,-11.79,0.096
9.78,-11.64,0.095
9.82,-11.48,0.095
9.85,-11.32,0.095
9.88,-11.16,0.095
9.91,-11.01,0.095
9.94,-10.85,0.095
9.98,-10.69,0.095
10.01,-10.53,0.095
10.04,-10.37,0.095
10.07,-10.21,0.095
10.10,-10.06,0.096
10.13,-9.90,0.096
10.17,-9.74,0.096
10.20,-9.58,0.096
10.23,-9.42,0.096
10.26,-9.26,0.096
10.29,-9.10,0.096
10.32,-8.94,0.096
10.35,-8.78,0.096
10.39,-8.63,0.096
10.42,-8.47,0.096
10.45,-8.31,0.096
10.48,-8.15,0.096
10.51,-7.99,0.096
10.55,-7.83,0.096
10.58,-7.67,0.096
10.61,-7.52,0.096
10.64,-7.36,0.096
10.67,-7.20,0.096
10.70,-7.04,0.096
10.73,-6.88,0.096
10.77,-6.72,0.096
10.80,-6.57,0.096
10.83,-6.41,0.096
10.86,-6.25,0.096
10.89,-6.09,0.096
10.93,-5.93,0.096
10.96,-5.77,0.096
10.99,-5.62,0.096
11.02,-5.46,0.096
11.05,-5.30,0.096
11.08,-5.14,0.096
11.12,-4.98,0.096
11.15,-4.82,0.096
11.18,-4.67,0.096
11.21,-4.51,0.096
11.24,-4.35,0.096
11.27,-4.19,0.096
11.30,-4.03,0.096
11.34,-3.87,0.096
11.37,-3.71,0.096
11.40,-3.56,0.096
11.43,-3.40,0.096
11.46,-3.24,0.096
11.50,-3.08,0.096
11.53,-2.92,0.096
11.56,-2.77,0.096
11.59,-2.61,0.096
11.62,-2.45,0.097
11.65,-2.29,0.096
11.68,-2.13,0.096
11.72,-1.97,0.096
11.75,-1.81,0.096
11.78,-1.65,0.096
11.81,-1.50,0.096
11.84,-1.34,0.096
11.88,-1.18,0.096
11.91,-1.02,0.096
11.94,-0.86,0.096
11.97,-0.71,0.097
12.00,-0.55,0.097
12.03,-0.39,0.097
12.07,-0.23,0.097
12.10,-0.07,0.097
12.13,0.09,0.097
12.16,0.25,0.097
12.19,0.40,0.097
12.22,0.56,0.097
12.25,0.72,0.097
12.29,0.88,0.097
12.32,1.04,0.097
12.35,1.20,0.097
12.38,1.36,0.097
12.41,1.52,0.097
12.45,1.67,0.097
12.48,1.83,0.097
12.51,1.99,0.097
12.54,2.15,0.097
12.57,2.31,0.097
12.60,2.47,0.097
12.63,2.62,0.097
12.67,2.78,0.097
12.70,2.94,0.097
12.73,3.10,0.097
12.76,3.26,0.097
12.79,3.42,0.097
12.83,3.57,0.097
12.86,3.73,0.097
12.89,3.89,0.097
12.92,4.05,0.097
12.95,4.21,0.097
12.98,4.37,0.097
13.02,4.52,0.097
13.05,4.68,0.097
13.08,4.84,0.097
13.11,5.00,0.097
13.14,5.16,0.098
13.17,5.32,0.098
13.20,5.48,0.098
13.24,5.63,0.098
13.27,5.79,0.098
13.30,5.95,0.098
13.33,6.11,0.098
13.36,6.27,0.098
13.40,6.43,0.098
13.43,6.58,0.098
13.46,6.74,0.098
13.49,6.90,0.098
13.52,7.06,0.098
13.55,7.22,0.098
13.58,7.38,0.098
13.62,7.53,0.098
13.65,7.69,0.098
13.68,7.85,0.098
13.71,8.01,0.098
13.74,8.17,0.098
13.78,8.33,0.098
13.81,8.49,0.098
13.84,8.64,0.098
13.87,8.80,0.098
13.90,8.96,0.098
13.93,9.12,0.098
13.97,9.28,0.098
14.00,9.44,0.098
14.03,9.60,0.098
14.06,9.75,0.098
14.09,9.91,0.098
14.12,10.07,0.099
14.15,10.23,0.099
14.19,10.39,0.098
14.22,10.55,0.099
14.25,10.70,0.099
14.28,10.86,0.099
14.31,11.02,0.099
14.35,11.18,0.099
14.38,11.34,0.099
14.41,11.50,0.099
14.44,11.65,0.099
14.47,11.81,0.099
14.50,11.97,0.099
14.53,12.13,0.099
14.57,12.29,0.099
14.60,12.45,0.099
14.63,12.61,0.099
14.66,12.76,0.099
14.69,12.92,0.099
14.73,13.08,0.099
14.76,13.24,0.099
14.79,13.40,0.099
14.82,13.56,0.099
14.85,13.71,0.099
14.88,13.87,0.099
14.92,14.03,0.099
14.95,14.19,0.099
14.98,14.35,0.099
15.01,14.51,0.100
15.04,14.67,0.100
15.07,14.82,0.100
15.10,14.98,0.100
15.14,15.14,0.099
15.17,15.30,0.100
15.20,15.46,0.100
15.23,15.62,0.100
15.26,15.77,0.099
15.30,15.93,0.099
15.33,16.09,0.099
15.36,16.25,0.099
15.39,16.41,0.099
15.42,16.57,0.099
15.45,16.72,0.100
15.48,16.88,0.100
15.52,17.04,0.100
15.55,17.20,0.100
15.58,17.36,0.100
15.61,17.52,0.100
15.64,17.68,0.100
15.68,17.83,0.100
15.71,17.99,0.100
15.74,18.15,0.100
15.77,18.31,0.101
15.80,18.47,0.101
15.83,18.63,0.101
15.87,18.78,0.101
15.90,18.94,0.101
15.93,19.10,0.101
15.96,19.26,0.101
15.99,19.42,0.101
16.02,19.58,0.101
16.05,19.74,0.101
16.09,19.89,0.101
16.12,20.05,0.101
16.15,20.21,0.101
16.18,20.37,0.101
16.21,20.53,0.101
16.25,20.69,0.101
16.28,20.84,0.101
16.31,21.00,0.101
16.34,21.16,0.101
16.37,21.32,0.101
16.40,21.48,0.102
16.43,21.64,0.101
16.47,21.80,0.101
16.50,21.95,0.101
16.53,22.11,0.101
16.56,22.27,0.101
16.59,22.43,0.102
16.63,22.59,0.102
16.66,22.75,0.102
16.69,22.90,0.102
16.72,23.06,0.102
16.75,23.22,0.102
16.78,23.38,0.102
16.82,23.54,0.102
16.85,23.70,0.102
16.88,23.86,0.102
16.91,24.01,0.102
16.94,24.17,0.102
16.97,24.33,0.102
17.00,24.49,0.102
17.04,24.65,0.102
17.07,24.80,0.102
17.10,24.96,0.102
17.13,25.12,0.102
17.16,25.28,0.102
17.19,25.44,0.102
17.23,25.60,0.102
17.26,25.76,0.103
17.29,25.91,0.103
17.32,26.07,0.103
17.35,26.23,0.103
17.38,26.39,0.103
17.42,26.55,0.103
17.45,26.71,0.103
17.48,26.87,0.103
17.51,27.02,0.103
17.54,27.18,0.103
17.58,27.34,0.103
17.61,27.50,0.103
17.64,27.66,0.103
17.67,27.82,0.103
17.70,27.98,0.103
17.73,28.13,0.103
17.77,28.29,0.104
17.80,28.45,0.104
17.83,28.61,0.103
17.86,28.77,0.104
17.89,28.92,0.104
17.92,29.08,0.104
17.96,29.24,0.104
17.99,29.40,0.104
18.02,29.56,0.104
18.05,29.72,0.104
18.08,29.88,0.104
18.11,30.04,0.104
18.14,30.19,0.104
18.18,30.35,0.104
18.21,30.51,0.104
18.24,30.67,0.104
18.27,30.83,0.104
18.30,30.98,0.104
18.33,31.14,0.104
18.37,31.30,0.104
18.40,31.46,0.105
18.43,31.62,0.104
18.46,31.78,0.105
18.49,31.94,0.105
18.53,32.09,0.105
18.56,32.25,0.105
18.59,32.41,0.105
18.62,32.57,0.105
18.65,32.73,0.105
18.68,32.89,0.105
18.72,33.04,0.105
18.75,33.20,0.105
18.78,33.36,0.105
18.81,33.52,0.105
18.84,33.68,0.105
18.87,33.84,0.105
18.91,34.00,0.105
18.94,34.15,0.105
18.97,34.31,0.106
19.00,34.47,0.106
19.03,34.63,0.106
19.06,34.79,0.106
19.09,34.95,0.106
19.13,35.10,0.106
19.16,35.26,0.106
19.19,35.42,0.106
19.22,35.58,0.106
19.25,35.74,0.106
19.28,35.90,0.106
19.32,36.05,0.106
19.35,36.21,0.106
19.38,36.37,0.106
19.41,36.53,0.106
19.44,36.69,0.106
19.48,36.85,0.106
19.51,37.00,0.106
19.54,37.16,0.106
19.57,37.32,0.106
19.60,37.48,0.107
19.63,37.64,0.107
19.67,37.80,0.107
19.70,37.96,0.107
19.73,38.11,0.107
19.76,38.27,0.107
19.79,38.43,0.107
19.82,38.59,0.107
19.86,38.75,0.107
19.89,38.91,0.107
19.92,39.07,0.107
19.95,39.22,0.107
19.98,39.38,0.107
20.01,39.54,0.107
20.04,39.70,0.107
20.08,39.86,0.107
20.11,40.01,0.107
20.14,40.18,0.107
20.17,40.33,0.108
20.20,40.49,0.108
20.23,40.65,0.108
20.27,40.81,0.108
20.30,40.97,0.108
20.33,41.13,0.108
20.36,41.28,0.108
20.39,41.44,0.108
20.43,41.60,0.108
20.46,41.76,0.108
20.49,41.92,0.108
20.52,42.08,0.108
20.55,42.23,0.108
20.58,42.39,0.109
20.62,42.55,0.109
20.65,42.71,0.109
20.68,42.87,0.109
20.71,43.03,0.109
20.74,43.18,0.109
20.77,43.34,0.109
20.81,43.50,0.109
20.84,43.66,0.109
20.87,43.82,0.110
20.90,43.98,0.110
20.93,44.14,0.110
20.96,44.29,0.110
20.99,44.45,0.110
21.03,44.61,0.110
21.06,44.77,0.110
21.09,44.93,0.110
21.12,45.08,0.110
21.15,45.24,0.110
21.18,45.40,0.110
21.22,45.56,0.110
21.25,45.72,0.110
21.28,45.88,0.110
21.31,46.04,0.110
21.34,46.19,0.110
21.38,46.35,0.111
21.41,46.51,0.111
21.44,46.67,0.111
21.47,46.83,0.111
21.50,46.99,0.111
21.53,47.15,0.111
21.57,47.30,0.111
21.60,47.46,0.111
21.63,47.62,0.111
21.66,47.78,0.111
21.69,47.94,0.111
21.72,48.10,0.111
21.76,48.25,0.111
21.79,48.41,0.112
21.82,48.57,0.112
21.85,48.73,0.112
21.88,48.89,0.112
21.91,49.05,0.112
21.94,49.20,0.112
21.98,49.36,0.112
22.01,49.52,0.112
22.04,49.68,0.112
22.07,49.84,0.113
22.10,49.99,0.113
22.13,50.16,0.113
22.17,50.31,0.113
22.20,50.47,0.113
22.23,50.63,0.113
22.26,50.79,0.113
22.29,50.95,0.113
22.33,51.10,0.113
22.36,51.26,0.113
22.39,51.42,0.113
22.42,51.58,0.114
22.45,51.74,0.114
22.48,51.90,0.114
22.52,52.06,0.114
22.55,52.21,0.114
22.58,52.37,0.114
22.61,52.53,0.114
22.64,52.69,0.114
22.67,52.85,0.115
22.71,53.01,0.115
22.74,53.16,0.115
22.77,53.32,0.115
22.80,53.48,0.115
22.83,53.64,0.115
22.86,53.80,0.115
22.89,53.96,0.115
22.93,54.11,0.115
22.96,54.27,0.116
22.99,54.43,0.116
23.02,54.59,0.116
23.05,54.75,0.116
23.08,54.91,0.116
23.12,55.07,0.116
23.15,55.22,0.117
23.18,55.38,0.117
23.21,55.54,0.117
23.24,55.70,0.117
23.28,55.86,0.118
23.31,56.02,0.118
23.34,56.17,0.118
23.37,56.33,0.118
23.40,56.49,0.118
23.43,56.65,0.119
23.47,56.81,0.119
23.50,56.97,0.119
23.53,57.12,0.119
23.56,57.28,0.120
23.59,57.44,0.120
23.62,57.60,0.120
23.66,57.76,0.121
23.69,57.92,0.121
23.72,58.08,0.122
23.75,58.23,0.122
23.78,58.39,0.122
23.81,58.55,0.123
23.84,58.71,0.123
23.88,58.87,0.124
23.91,59.02,0.124
23.94,59.18,0.125
23.97,59.34,0.125
24.00,59.50,0.126
24.03,59.66,0.127
24.07,59.82,0.127
24.10,59.97,0.128
24.13,60.13,0.129
24.16,60.29,0.129
24.19,60.45,0.130
24.23,60.61,0.131
24.26,60.77,0.132
24.29,60.92,0.133
24.32,61.08,0.134
24.35,61.24,0.136
24.38,61.40,0.137
24.42,61.56,0.139
24.45,61.71,0.141
24.48,61.87,0.143
24.51,62.03,0.145
24.54,62.19,0.148
24.57,62.35,0.152
24.61,62.50,0.156
24.64,62.66,0.162
24.67,62.82,0.169
24.70,62.97,0.178
24.73,63.13,0.187
24.76,63.29,0.199
24.79,63.45,0.212
24.83,63.60,0.225
24.86,63.76,0.240
24.89,63.92,0.258
24.92,64.07,0.278
24.95,64.23,0.301
24.98,64.38,0.325
25.02,64.54,0.356
25.05,64.69,0.387
25.08,64.84,0.422
25.11,65.00,0.461
25.14,65.15,0.501
25.18,65.30,0.545
25.21,65.45,0.583
25.24,65.60,0.625
25.27,65.75,0.661
25.30,65.91,0.700
25.33,66.06,0.735
25.37,66.21,0.763
25.40,66.36,0.795
25.43,66.52,0.827
25.46,66.67,0.855
25.49,66.82,0.882
25.52,66.98,0.909
25.56,67.13,0.932
25.59,67.28,0.953
25.62,67.44,0.971
25.65,67.59,0.984
25.68,67.75,0.993
25.71,67.91,0.999
25.74,68.06,1.002
25.78,68.22,1.001
25.81,68.38,0.998
25.84,68.54,0.982
25.87,68.70,0.939
25.90,68.86,0.895
25.93,69.03,0.841
25.97,69.20,0.778
26.00,69.37,0.698
26.03,69.54,0.607
26.06,69.71,0.505
26.09,69.88,0.410
26.13,70.06,0.334
26.16,70.23,0.283
26.19,70.40,0.242
26.22,70.56,0.214
26.25,70.73,0.198
26.28,70.89,0.180
26.32,71.05,0.171
26.35,71.21,0.165
26.38,71.37,0.162
26.41,71.53,0.158
26.44,71.69,0.157
26.47,71.85,0.156
26.51,72.01,0.155
26.54,72.17,0.154
26.57,72.33,0.153
26.60,72.49,0.152
26.63,72.65,0.151
26.66,72.80,0.150
26.69,72.96,0.150
26.73,73.12,0.149
26.76,73.28,0.148
26.79,73.44,0.148
26.82,73.60,0.147
26.85,73.75,0.147
26.88,73.91,0.146
26.92,74.07,0.146
26.95,74.23,0.146
26.98,74.39,0.145
27.01,74.55,0.145
27.04,74.71,0.145
27.08,74.86,0.145
27.11,75.02,0.144
27.14,75.18,0.144
27.17,75.34,0.144
27.20,75.50,0.144
27.23,75.66,0.143
27.27,75.81,0.143
27.30,75.97,0.143
27.33,76.13,0.143
27.36,76.29,0.143
27.39,76.45,0.143
27.42,76.61,0.143
27.46,76.76,0.143
27.49,76.92,0.143
27.52,77.08,0.143
27.55,77.24,0.143
27.58,77.40,0.143
27.61,77.56,0.143
27.64,77.71,0.143
27.68,77.87,0.143
27.71,78.03,0.143
27.74,78.19,0.143
27.77,78.35,0.143
27.80,78.51,0.142
27.83,78.67,0.143
27.87,78.82,0.142
27.90,78.98,0.143
27.93,79.14,0.142
27.96,79.30,0.142
27.99,79.46,0.142
28.03,79.62,0.142
28.06,79.78,0.142
28.09,79.93,0.142
28.12,80.09,0.142
28.15,80.25,0.142
28.18,80.41,0.142
28.22,80.57,0.142
28.25,80.73,0.142
28.28,80.88,0.142
28.31,81.04,0.142
28.34,81.20,0.142
28.37,81.36,0.142
28.41,81.52,0.142
28.44,81.68,0.142
28.47,81.84,0.142
28.50,81.99,0.142
28.53,82.15,0.142
28.56,82.31,0.142
28.59,82.47,0.142
28.63,82.63,0.142
28.66,82.79,0.142
28.69,82.94,0.142
28.72,83.10,0.142
28.75,83.26,0.142
28.78,83.42,0.142
28.82,83.58,0.142
28.85,83.74,0.142
28.88,83.89,0.142
28.91,84.05,0.142
28.94,84.21,0.142
28.98,84.37,0.142
29.01,84.53,0.142
29.04,84.69,0.142
29.07,84.84,0.142
29.10,85.00,0.142
29.13,85.16,0.142
29.17,85.32,0.142
29.20,85.48,0.141
29.23,85.64,0.141
29.26,85.80,0.141
29.29,85.95,0.141
29.32,86.11,0.141
29.36,86.27,0.141
29.39,86.43,0.141
29.42,86.59,0.141
29.45,86.75,0.141
29.48,86.90,0.141
29.51,87.06,0.141
29.54,87.22,0.141
29.58,87.38,0.141
29.61,87.54,0.141
29.64,87.70,0.140
29.67,87.86,0.140
29.70,88.01,0.140
29.73,88.17,0.140
29.77,88.33,0.140
29.80,88.49,0.140
29.83,88.65,0.140
29.86,88.81,0.140
29.89,88.97,0.140
29.93,89.12,0.140
29.96,89.28,0.140
29.99,89.44,0.140
30.02,89.60,0.139
30.05,89.76,0.139
30.08,89.91,0.139
30.12,90.07,0.139
30.15,90.23,0.139
30.18,90.39,0.139
30.21,90.55,0.139
30.24,90.71,0.139
30.27,90.86,0.138
30.31,91.02,0.138
30.34,91.18,0.138
30.37,91.34,0.138
30.40,91.50,0.138
30.43,91.66,0.138
30.46,91.82,0.137
30.49,91.97,0.137
30.53,92.13,0.137
30.56,92.29,0.137
30.59,92.45,0.137
30.62,92.61,0.136
30.65,92.77,0.136
30.68,92.92,0.136
30.72,93.08,0.135
30.75,93.24,0.135
30.78,93.40,0.135
30.81,93.56,0.135
30.84,93.72,0.134
30.88,93.88,0.134
30.91,94.03,0.134
30.94,94.19,0.133
30.97,94.35,0.133
31.00,94.51,0.133
31.03,94.67,0.132
31.07,94.83,0.132
31.10,94.98,0.131
31.13,95.14,0.131
31.16,95.30,0.131
31.19,95.46,0.130
31.22,95.62,0.130
31.26,95.78,0.129
31.29,95.94,0.129
31.32,96.09,0.128
31.35,96.25,0.128
31.38,96.41,0.127
31.41,96.57,0.127
31.44,96.73,0.126
31.48,96.89,0.126
31.51,97.05,0.125
31.54,97.20,0.125
31.57,97.36,0.124
31.60,97.52,0.124
31.63,97.68,0.123
31.67,97.84,0.123
31.70,98.00,0.122
31.73,98.16,0.122
31.76,98.31,0.121
31.79,98.47,0.121
31.83,98.63,0.120
31.86,98.79,0.120
31.89,98.95,0.119
31.92,99.11,0.119
31.95,99.26,0.118
31.98,99.42,0.118
32.02,99.58,0.118
32.05,99.74,0.117
32.08,99.90,0.117
32.11,100.06,0.116
32.14,100.22,0.116
32.17,100.38,0.115
32.21,100.54,0.114
32.24,100.69,0.114
32.27,100.85,0.113
32.30,101.01,0.112
32.33,101.17,0.112
32.36,101.33,0.111
32.39,101.49,0.111
32.43,101.65,0.110
32.46,101.80,0.109
32.49,101.96,0.109
32.52,102.12,0.108
32.55,102.28,0.108
32.58,102.44,0.107
32.62,102.59,0.107
32.65,102.75,0.106
32.68,102.91,0.105
32.71,103.07,0.105
32.74,103.23,0.105
32.78,103.38,0.104
32.81,103.54,0.104
32.84,103.70,0.103
32.87,103.86,0.103
32.90,104.02,0.103
32.93,104.18,0.102
32.97,104.34,0.102
33.00,104.50,0.101
33.03,104.65,0.101
33.06,104.81,0.100
33.09,104.97,0.100
33.12,105.13,0.099
33.16,105.29,0.099
33.19,105.45,0.098
33.22,105.60,0.098
33.25,105.76,0.097
33.28,105.92,0.097
33.31,106.08,0.096
33.34,106.24,0.096
33.38,106.40,0.096
33.41,106.55,0.095
33.44,106.71,0.095
33.47,106.87,0.094
33.50,107.03,0.094
33.53,107.19,0.093
33.57,107.35,0.093
33.60,107.51,0.092
33.63,107.66,0.092
33.66,107.82,0.091
33.69,107.98,0.091
33.73,108.14,0.090
33.76,108.30,0.089
33.79,108.46,0.089
33.82,108.61,0.088
33.85,108.77,0.087
33.88,108.93,0.087
33.92,109.09,0.086
33.95,109.25,0.086
33.98,109.41,0.085
34.01,109.57,0.085
34.04,109.72,0.084
34.07,109.88,0.084
34.11,110.04,0.083
34.14,110.20,0.082
34.17,110.36,0.082
34.20,110.52,0.081
34.23,110.68,0.080
34.26,110.83,0.080
34.29,110.99,0.079
34.33,111.15,0.078
34.36,111.31,0.078
34.39,111.47,0.077
34.42,111.63,0.076
34.45,111.78,0.076
34.49,111.94,0.075
34.52,112.10,0.074
34.55,112.26,0.074
34.58,112.42,0.073
34.61,112.58,0.073
34.64,112.74,0.072
34.68,112.89,0.071
34.71,113.05,0.071
34.74,113.21,0.070
34.77,113.37,0.069
34.80,113.53,0.069
34.83,113.69,0.068
34.86,113.84,0.068
34.90,114.00,0.067
34.93,114.16,0.067
34.96,114.32,0.066
34.99,114.48,0.065
35.02,114.64,0.065
35.06,114.80,0.064
35.09,114.95,0.064
35.12,115.11,0.063
35.15,115.27,0.063
35.18,115.43,0.062
35.21,115.59,0.062
35.24,115.75,0.062
35.28,115.90,0.061
35.31,116.06,0.061
35.34,116.22,0.060
35.37,116.38,0.060
35.40,116.54,0.060
35.44,116.70,0.059
35.47,116.86,0.059
35.50,117.01,0.059
35.53,117.17,0.059
35.56,117.33,0.059
35.59,117.49,0.058
35.63,117.65,0.058
35.66,117.81,0.058
35.69,117.96,0.058
35.72,118.12,0.058
35.75,118.28,0.057
35.78,118.44,0.057
35.81,118.60,0.057
35.85,118.76,0.057
35.88,118.91,0.057
35.91,119.07,0.057
35.94,119.23,0.058
35.97,119.39,0.058
36.01,119.55,0.058
36.04,119.71,0.058
36.07,119.86,0.058
36.10,120.02,0.058
36.13,120.18,0.059
36.16,120.34,0.059
36.19,120.50,0.059
36.23,120.66,0.059
36.26,120.81,0.060
36.29,120.97,0.060
36.32,121.13,0.060
36.35,121.29,0.061
36.39,121.45,0.061
36.42,121.61,0.062
36.45,121.77,0.062
36.48,121.92,0.062
36.51,122.08,0.063
36.54,122.24,0.063
36.58,122.40,0.064
36.61,122.56,0.064
36.64,122.71,0.065
36.67,122.87,0.066
36.70,123.03,0.066
36.73,123.19,0.067
36.76,123.35,0.067
36.80,123.51,0.068
36.83,123.66,0.069
36.86,123.82,0.070
36.89,123.98,0.070
36.92,124.14,0.071
36.96,124.30,0.072
36.99,124.46,0.073
37.02,124.61,0.074
37.05,124.77,0.074
37.08,124.93,0.075
37.11,125.09,0.076
37.14,125.25,0.077
37.18,125.40,0.078
37.21,125.56,0.079
37.24,125.72,0.080
37.27,125.88,0.081
37.30,126.04,0.082
37.34,126.19,0.083
37.37,126.35,0.084
37.40,126.51,0.085
37.43,126.67,0.086
37.46,126.83,0.088
37.49,126.99,0.089
37.53,127.14,0.090
37.56,127.30,0.092
37.59,127.46,0.093
37.62,127.62,0.094
37.65,127.78,0.096
37.68,127.94,0.097
37.71,128.09,0.098
37.75,128.25,0.100
37.78,128.41,0.101
37.81,128.57,0.103
37.84,128.73,0.104
37.87,128.88,0.106
37.91,129.04,0.107
37.94,129.20,0.109
37.97,129.36,0.111
38.00,129.52,0.112
38.03,129.67,0.114
38.06,129.83,0.116
38.09,129.99,0.118
38.13,130.15,0.120
38.16,130.31,0.121
38.19,130.47,0.123
38.22,130.62,0.125
38.25,130.78,0.128
38.29,130.94,0.130
38.32,131.10,0.132
38.35,131.25,0.134
38.38,131.41,0.136
38.41,131.57,0.138
38.44,131.73,0.140
38.48,131.89,0.142
38.51,132.05,0.144
38.54,132.20,0.146
38.57,132.36,0.148
38.60,132.52,0.150
38.63,132.68,0.152
38.66,132.84,0.155
38.70,132.99,0.157
38.73,133.15,0.159
38.76,133.31,0.161
38.79,133.47,0.164
38.82,133.63,0.167
38.86,133.78,0.171
38.89,133.94,0.174
38.92,134.10,0.178
38.95,134.26,0.182
38.98,134.42,0.186
39.01,134.57,0.190
39.04,134.73,0.194
39.08,134.89,0.198
39.11,135.05,0.203
39.14,135.20,0.207
39.17,135.36,0.210
39.20,135.52,0.217
39.24,135.68,0.220
39.27,135.84,0.223
39.30,135.99,0.227
39.33,136.15,0.231
39.36,136.31,0.236
39.39,136.47,0.240
39.43,136.62,0.243
39.46,136.78,0.248
39.49,136.94,0.252
39.52,137.10,0.256
39.55,137.26,0.261
39.58,137.41,0.265
39.61,137.57,0.268
39.65,137.73,0.272
39.68,137.89,0.276
39.71,138.04,0.280
39.74,138.20,0.286
39.77,138.36,0.290
39.81,138.52,0.295
39.84,138.67,0.301
39.87,138.83,0.305
39.90,138.99,0.312
39.93,139.15,0.318
39.96,139.30,0.324
39.99,139.46,0.331
40.03,139.62,0.338
40.06,139.78,0.345
40.09,139.93,0.352
40.12,140.09,0.359
40.15,140.25,0.366
40.19,140.41,0.375
40.22,140.56,0.382
40.25,140.72,0.391
40.28,140.88,0.398
40.31,141.04,0.408
40.34,141.19,0.417
40.38,141.35,0.427
40.41,141.51,0.436
40.44,141.66,0.447
40.47,141.82,0.457
40.50,141.98,0.470
40.53,142.13,0.482
40.56,142.29,0.494
40.60,142.45,0.508
40.63,142.60,0.519
40.66,142.76,0.535
40.69,142.92,0.548
40.72,143.07,0.565
40.76,143.23,0.585
40.79,143.38,0.607
40.82,143.54,0.628
40.85,143.70,0.646
40.88,143.85,0.667
40.91,144.01,0.695
40.94,144.16,0.730
40.98,144.31,0.805
41.01,144.46,1.013
41.04,144.59,1.168
41.07,144.74,1.088
41.10,144.91,0.775
41.14,145.10,0.533
41.17,145.28,0.382
41.20,145.46,0.294
41.23,145.63,0.240
41.26,145.80,0.210
41.29,145.97,0.185
41.33,146.13,0.173
41.36,146.30,0.163
41.39,146.46,0.158
41.42,146.62,0.153
41.45,146.77,0.152
41.48,146.93,0.150
41.51,147.09,0.149
41.55,147.25,0.148
41.58,147.41,0.147
41.61,147.57,0.146
41.64,147.73,0.145
41.67,147.89,0.145
41.71,148.04,0.144
41.74,148.20,0.144
41.77,148.36,0.143
41.80,148.52,0.142
41.83,148.68,0.142
41.86,148.84,0.142
41.89,148.99,0.141
41.93,149.15,0.141
41.96,149.31,0.141
41.99,149.47,0.140
42.02,149.63,0.140
42.05,149.79,0.140
42.09,149.94,0.139
42.12,150.10,0.139
42.15,150.26,0.139
42.18,150.42,0.138
42.21,150.58,0.138
42.24,150.74,0.138
42.28,150.90,0.138
42.31,151.05,0.138
42.34,151.21,0.137
42.37,151.37,0.137
42.40,151.53,0.137
42.43,151.69,0.137
42.46,151.85,0.136
42.50,152.00,0.136
42.53,152.16,0.136
42.56,152.32,0.136
42.59,152.48,0.135
42.62,152.64,0.135
42.66,152.80,0.135
42.69,152.96,0.135
42.72,153.11,0.135
42.75,153.27,0.135
42.78,153.43,0.134
42.81,153.59,0.134
42.84,153.75,0.134
42.88,153.91,0.133
42.91,154.06,0.133
42.94,154.22,0.133
42.97,154.38,0.133
43.00,154.54,0.132
43.04,154.70,0.132
43.07,154.86,0.132
43.10,155.02,0.131
43.13,155.17,0.131
43.16,155.33,0.130
43.19,155.49,0.130
43.23,155.65,0.130
43.26,155.81,0.129
43.29,155.96,0.129
43.32,156.12,0.129
43.35,156.28,0.129
43.38,156.44,0.128
43.41,156.60,0.128
43.45,156.76,0.128
43.48,156.91,0.127
43.51,157.07,0.127
43.54,157.23,0.127
43.57,157.39,0.126
43.61,157.55,0.126
43.64,157.71,0.126
43.67,157.87,0.125
43.70,158.02,0.125
43.73,158.18,0.124
43.76,158.34,0.124
43.79,158.50,0.124
43.83,158.66,0.124
43.86,158.82,0.123
43.89,158.98,0.123
43.92,159.13,0.122
43.95,159.29,0.122
43.99,159.45,0.122
44.02,159.61,0.121
44.05,159.77,0.121
44.08,159.92,0.121
44.11,160.08,0.120
44.14,160.24,0.120
44.18,160.40,0.120
44.21,160.56,0.119
44.24,160.72,0.119
44.27,160.87,0.119
44.30,161.03,0.119
44.33,161.19,0.118
44.36,161.35,0.118
44.40,161.51,0.118
44.43,161.67,0.117
44.46,161.83,0.117
44.49,161.98,0.117
44.52,162.14,0.116
44.56,162.30,0.116
44.59,162.46,0.116
44.62,162.62,0.115
44.65,162.77,0.115
44.68,162.93,0.115
44.71,163.09,0.114
44.74,163.25,0.114
44.78,163.41,0.114
44.81,163.57,0.113
44.84,163.73,0.113
44.87,163.88,0.113
44.90,164.04,0.113
44.94,164.20,0.112
44.97,164.36,0.112
45.00,164.52,0.112
45.03,164.68,0.112
45.06,164.84,0.111
45.09,164.99,0.111
45.13,165.15,0.111
45.16,165.31,0.110
45.19,165.47,0.110
45.22,165.63,0.110
45.25,165.79,0.109
45.28,165.94,0.109
45.31,166.10,0.109
45.35,166.26,0.109
45.38,166.42,0.109
45.41,166.58,0.108
45.44,166.74,0.108
45.47,166.90,0.108
45.51,167.05,0.108
45.54,167.21,0.107
45.57,167.37,0.107
45.60,167.53,0.107
45.63,167.69,0.107
45.66,167.84,0.107
45.69,168.00,0.106
45.73,168.16,0.106
45.76,168.32,0.106
45.79,168.48,0.106
45.82,168.64,0.106
45.85,168.80,0.105
45.89,168.95,0.105
45.92,169.11,0.105
45.95,169.27,
45.98,,
45.98,,

[step]
Ramp 10.00 °C/min to -60.00 °C
Time,Temperature,Heat Flow (Normalized)
min,°C,W/g
46.09,169.90,0.047
46.10,169.96,0.026
46.12,170.00,0.000
46.14,170.03,-0.029
46.15,170.05,-0.069
46.17,170.05,-0.125
46.19,170.03,-0.194
46.20,169.99,-0.272
46.22,169.93,-0.343
46.24,169.85,-0.410
46.25,169.75,-0.465
46.27,169.64,-0.510
46.29,169.52,-0.539
46.30,169.39,-0.570
46.32,169.25,-0.586
46.34,169.11,-0.606
46.35,168.97,-0.618
46.37,168.82,-0.630
46.39,168.67,-0.638
46.40,168.52,-0.647
46.42,168.36,-0.649
46.44,168.21,-0.655
46.45,168.05,-0.661
46.47,167.89,-0.664
46.49,167.73,-0.665
46.50,167.57,-0.665
46.52,167.41,-0.669
46.54,167.25,-0.670
46.55,167.09,-0.670
46.57,166.92,-0.671
46.59,166.76,-0.671
46.60,166.60,-0.672
46.62,166.43,-0.672
46.64,166.27,-0.673
46.65,166.11,-0.673
46.67,165.94,-0.673
46.69,165.78,-0.673
46.70,165.62,-0.674
46.72,165.45,-0.674
46.74,165.29,-0.674
46.75,165.12,-0.674
46.77,164.96,-0.674
46.79,164.79,-0.674
46.80,164.63,-0.674
46.82,164.47,-0.674
46.84,164.30,-0.674
46.85,164.14,-0.674
46.87,163.97,-0.674
46.89,163.81,-0.674
46.90,163.64,-0.674
46.92,163.48,-0.674
46.94,163.31,-0.674
46.95,163.15,-0.673
46.97,162.98,-0.673
46.99,162.81,-0.673
47.00,162.65,-0.672
47.02,162.48,-0.672
47.04,162.32,-0.671
47.05,162.15,-0.671
47.07,161.99,-0.671
47.09,161.82,-0.670
47.10,161.66,-0.670
47.12,161.49,-0.670
47.14,161.32,-0.669
47.15,161.16,-0.669
47.17,160.99,-0.668
47.19,160.83,-0.668
47.20,160.66,-0.668
47.22,160.50,-0.667
47.24,160.33,-0.667
47.25,160.16,-0.667
47.27,160.00,-0.666
47.29,159.83,-0.666
47.30,159.66,-0.665
47.32,159.50,-0.665
47.34,159.33,-0.664
47.35,159.17,-0.663
47.37,159.00,-0.663
47.39,158.83,-0.662
47.40,158.67,-0.662
47.42,158.50,-0.661
47.44,158.34,-0.661
47.45,158.17,-0.660
47.47,158.00,-0.660
47.49,157.84,-0.659
47.50,157.67,-0.659
47.52,157.51,-0.658
47.54,157.34,-0.658
47.55,157.17,-0.657
47.57,157.01,-0.657
47.59,156.84,-0.656
47.60,156.68,-0.656
47.62,156.51,-0.655
47.64,156.34,-0.654
47.65,156.18,-0.654
47.67,156.01,-0.654
47.69,155.84,-0.653
47.70,155.68,-0.653
47.72,155.51,-0.652
47.74,155.35,-0.652
47.75,155.18,-0.652
47.77,155.01,-0.651
47.79,154.85,-0.650
47.80,154.68,-0.649
47.82,154.51,-0.649
47.84,154.35,-0.648
47.85,154.18,-0.648
47.87,154.01,-0.647
47.89,153.85,-0.647
47.90,153.68,-0.647
47.92,153.52,-0.646
47.94,153.35,-0.646
47.95,153.18,-0.645
47.97,153.02,-0.645
47.99,152.85,-0.644
48.00,152.68,-0.644
48.02,152.52,-0.643
48.04,152.35,-0.643
48.05,152.18,-0.643
48.07,152.02,-0.642
48.09,151.85,-0.642
48.10,151.69,-0.641
48.12,151.52,-0.641
48.14,151.35,-0.641
48.15,151.19,-0.640
48.17,151.02,-0.640
48.19,150.85,-0.639
48.20,150.69,-0.639
48.22,150.52,-0.638
48.24,150.35,-0.638
48.25,150.19,-0.637
48.27,150.02,-0.637
48.29,149.85,-0.636
48.30,149.69,-0.636
48.32,149.52,-0.635
48.34,149.35,-0.635
48.35,149.19,-0.635
48.37,149.02,-0.634
48.39,148.85,-0.634
48.40,148.69,-0.633
48.42,148.52,-0.632
48.44,148.36,-0.632
48.45,148.19,-0.631
48.47,148.02,-0.631
48.49,147.86,-0.630
48.50,147.69,-0.630
48.52,147.52,-0.629
48.54,147.36,-0.629
48.55,147.19,-0.629
48.57,147.02,-0.628
48.59,146.86,-0.627
48.60,146.69,-0.627
48.62,146.52,-0.627
48.64,146.36,-0.626
48.65,146.19,-0.626
48.67,146.02,-0.626
48.69,145.86,-0.625
48.70,145.69,-0.625
48.72,145.52,-0.624
48.74,145.36,-0.624
48.75,145.19,-0.624
48.77,145.03,-0.623
48.79,144.86,-0.623
48.80,144.69,-0.623
48.82,144.53,-0.622
48.84,144.36,-0.622
48.85,144.19,-0.621
48.87,144.03,-0.621
48.89,143.86,-0.621
48.90,143.69,-0.620
48.92,143.53,-0.620
48.94,143.36,-0.620
48.95,143.19,-0.619
48.97,143.03,-0.619
48.99,142.86,-0.618
49.00,142.70,-0.618
49.02,142.53,-0.617
49.04,142.36,-0.617
49.05,142.20,-0.617
49.07,142.03,-0.616
49.09,141.86,-0.616
49.10,141.70,-0.616
49.12,141.53,-0.615
49.14,141.36,-0.615
49.15,141.20,-0.615
49.17,141.03,-0.614
49.19,140.86,-0.614
49.20,140.70,-0.614
49.22,140.53,-0.613
49.24,140.36,-0.613
49.25,140.20,-0.613
49.27,140.03,-0.612
49.29,139.86,-0.612
49.30,139.70,-0.612
49.32,139.53,-0.611
49.34,139.36,-0.611
49.35,139.20,-0.611
49.37,139.03,-0.610
49.39,138.86,-0.610
49.40,138.70,-0.610
49.42,138.53,-0.609
49.44,138.36,-0.609
49.45,138.20,-0.608
49.47,138.03,-0.608
49.49,137.86,-0.608
49.50,137.70,-0.607
49.52,137.53,-0.607
49.54,137.36,-0.607
49.55,137.20,-0.606
49.57,137.03,-0.606
49.59,136.87,-0.606
49.60,136.70,-0.605
49.62,136.53,-0.605
49.64,136.37,-0.605
49.65,136.20,-0.604
49.67,136.03,-0.604
49.69,135.87,-0.603
49.70,135.70,-0.603
49.72,135.53,-0.603
49.74,135.37,-0.602
49.75,135.20,-0.602
49.77,135.03,-0.602
49.79,134.87,-0.601
49.80,134.70,-0.601
49.82,134.54,-0.600
49.84,134.37,-0.600
49.85,134.20,-0.600
49.87,134.04,-0.600
49.89,133.87,-0.599
49.90,133.70,-0.599
49.92,133.54,-0.599
49.94,133.37,-0.598
49.95,133.20,-0.598
49.97,133.04,-0.598
49.99,132.87,-0.598
50.00,132.71,-0.597
50.02,132.54,-0.597
50.04,132.37,-0.597
50.05,132.21,-0.597
50.07,132.04,-0.596
50.09,131.87,-0.596
50.10,131.70,-0.596
50.12,131.54,-0.596
50.14,131.37,-0.595
50.15,131.21,-0.595
50.17,131.04,-0.595
50.19,130.87,-0.595
50.20,130.71,-0.594
50.22,130.54,-0.594
50.24,130.37,-0.594
50.25,130.21,-0.594
50.27,130.04,-0.593
50.29,129.87,-0.593
50.30,129.71,-0.593
50.32,129.54,-0.593
50.34,129.37,-0.592
50.35,129.21,-0.592
50.37,129.04,-0.592
50.39,128.87,-0.592
50.40,128.71,-0.591
50.42,128.54,-0.591
50.44,128.37,-0.591
50.45,128.21,-0.591
50.47,128.04,-0.590
50.49,127.87,-0.590
50.50,127.71,-0.590
50.52,127.54,-0.590
50.54,127.38,-0.589
50.55,127.21,-0.589
50.57,127.04,-0.589
50.59,126.88,-0.589
50.60,126.71,-0.588
50.62,126.54,-0.588
50.64,126.38,-0.588
50.65,126.21,-0.588
50.67,126.04,-0.587
50.69,125.88,-0.587
50.70,125.71,-0.587
50.72,125.54,-0.587
50.74,125.38,-0.586
50.75,125.21,-0.586
50.77,125.04,-0.586
50.79,124.88,-0.586
50.80,124.71,-0.586
50.82,124.55,-0.585
50.84,124.38,-0.585
50.85,124.21,-0.585
50.87,124.05,-0.585
50.89,123.88,-0.584
50.90,123.71,-0.584
50.92,123.55,-0.584
50.94,123.38,-0.583
50.95,123.21,-0.583
50.97,123.05,-0.583
50.99,122.88,-0.583
51.00,122.72,-0.582
51.02,122.55,-0.582
51.04,122.38,-0.582
51.05,122.22,-0.582
51.07,122.05,-0.582
51.09,121.88,-0.581
51.10,121.72,-0.581
51.12,121.55,-0.581
51.14,121.38,-0.581
51.15,121.22,-0.580
51.17,121.05,-0.580
51.19,120.88,-0.580
51.20,120.72,-0.580
51.22,120.55,-0.579
51.24,120.38,-0.579
51.25,120.22,-0.579
51.27,120.05,-0.579
51.29,119.88,-0.579
51.30,119.72,-0.578
51.32,119.55,-0.578
51.34,119.39,-0.577
51.35,119.22,-0.577
51.37,119.05,-0.577
51.39,118.89,-0.577
51.40,118.72,-0.576
51.42,118.55,-0.576
51.44,118.39,-0.576
51.45,118.22,-0.576
51.47,118.05,-0.576
51.49,117.89,-0.575
51.50,117.72,-0.575
51.52,117.55,-0.575
51.54,117.39,-0.575
51.55,117.22,-0.575
51.57,117.05,-0.574
51.59,116.89,-0.574
51.60,116.72,-0.574
51.62,116.55,-0.574
51.64,116.39,-0.573
51.65,116.22,-0.573
51.67,116.06,-0.573
51.69,115.89,-0.573
51.70,115.72,-0.572
51.72,115.56,-0.572
51.74,115.39,-0.572
51.75,115.22,-0.572
51.77,115.06,-0.572
51.79,114.89,-0.572
51.80,114.72,-0.571
51.82,114.56,-0.571
51.84,114.39,-0.571
51.85,114.22,-0.571
51.87,114.06,-0.570
51.89,113.89,-0.570
51.90,113.72,-0.570
51.92,113.56,-0.570
51.94,113.39,-0.570
51.95,113.22,-0.569
51.97,113.06,-0.569
51.99,112.89,-0.569
52.00,112.72,-0.569
52.02,112.56,-0.569
52.04,112.39,-0.568
52.05,112.23,-0.568
52.07,112.06,-0.568
52.09,111.89,-0.568
52.10,111.73,-0.567
[...]
153.60,6.31,0.133
153.63,6.47,0.133
153.66,6.63,0.133
153.69,6.79,0.133
153.73,6.95,0.133
153.76,7.10,0.133
153.79,7.26,0.133
153.82,7.42,0.134
153.85,7.58,0.134
153.88,7.74,0.134
153.92,7.90,0.134
153.95,8.06,0.134
153.98,8.22,0.134
154.01,8.37,0.134
154.04,8.53,0.134
154.07,8.69,0.134
154.10,8.85,0.134
154.14,9.01,0.135
154.17,9.17,0.135
154.20,9.32,0.135
154.23,9.48,0.135
154.26,9.64,0.135
154.30,9.80,0.135
154.33,9.96,0.135
154.36,10.12,0.135
154.39,10.27,0.135
154.42,10.43,0.135
154.45,10.59,0.135
154.48,10.75,0.135
154.52,10.91,0.137
154.55,11.07,0.137
154.58,11.22,0.137
154.61,11.38,0.137
154.64,11.54,0.137
154.68,11.70,0.137
154.71,11.86,0.137
154.74,12.02,0.137
154.77,12.18,0.137
154.80,12.34,0.137
154.83,12.49,0.137
154.87,12.65,0.137
154.90,12.81,0.137
154.93,12.97,0.137
154.96,13.13,0.137
154.99,13.29,0.137
155.02,13.44,0.137
155.05,13.60,0.136
155.09,13.76,0.136
155.12,13.92,0.136
155.15,14.08,0.137
155.18,14.24,0.136
155.21,14.39,0.136
155.25,14.55,0.136
155.28,14.71,0.136
155.31,14.87,0.136
155.34,15.03,0.136
155.37,15.19,0.136
155.40,15.35,0.137
155.43,15.50,0.136
155.47,15.66,0.136
155.50,15.82,0.136
155.53,15.98,0.136
155.56,16.14,0.136
155.59,16.30,0.136
155.63,16.46,0.136
155.66,16.61,0.136
155.69,16.77,0.136
155.72,16.93,0.136
155.75,17.09,0.136
155.78,17.25,0.137
155.82,17.40,0.137
155.85,17.56,0.137
155.88,17.72,0.137
155.91,17.88,0.137
155.94,18.04,0.137
155.97,18.20,0.137
156.00,18.36,0.137
156.04,18.51,0.137
156.07,18.67,0.137
156.10,18.83,0.137
156.13,18.99,0.137
156.16,19.15,0.137
156.20,19.31,0.137
156.23,19.46,0.137
156.26,19.62,0.137
156.29,19.78,0.137
156.32,19.94,0.138
156.35,20.10,0.137
156.38,20.26,0.138
156.42,20.42,0.138
156.45,20.57,0.138
156.48,20.73,0.138
156.51,20.89,0.138
156.54,21.05,0.138
156.58,21.21,0.138
156.61,21.37,0.138
156.64,21.52,0.138
156.67,21.68,0.138
156.70,21.84,0.138
156.73,22.00,0.138
156.77,22.16,0.138
156.80,22.32,0.138
156.83,22.47,0.138
156.86,22.63,0.138
156.89,22.79,0.138
156.92,22.95,0.138
156.95,23.11,0.138
156.99,23.27,0.139
157.02,23.43,0.139
157.05,23.58,0.139
157.08,23.74,0.139
157.11,23.90,0.139
157.15,24.06,0.139
157.18,24.22,0.139
157.21,24.38,0.139
157.24,24.53,0.139
157.27,24.69,0.139
157.30,24.85,0.139
157.33,25.01,0.139
157.37,25.17,0.139
157.40,25.33,0.139
157.43,25.48,0.139
157.46,25.64,0.139
157.49,25.80,0.140
157.53,25.96,0.140
157.56,26.12,0.139
157.59,26.28,0.139
157.62,26.44,0.140
157.65,26.59,0.140
157.68,26.75,0.140
157.72,26.91,0.140
157.75,27.07,0.140
157.78,27.23,0.140
157.81,27.39,0.140
157.84,27.55,0.140
157.87,27.70,0.140
157.90,27.86,0.140
157.94,28.02,0.140
157.97,28.18,0.140
158.00,28.34,0.140
158.03,28.50,0.140
158.06,28.65,0.140
158.10,28.81,0.140
158.13,28.97,0.140
158.16,29.13,0.140
158.19,29.29,0.140
158.22,29.45,0.140
158.25,29.61,0.140
158.28,29.76,0.140
158.32,29.92,0.140
158.35,30.08,0.140
158.38,30.24,0.140
158.41,30.40,0.140
158.44,30.56,0.141
158.48,30.71,0.141
158.51,30.87,0.141
158.54,31.03,0.141
158.57,31.19,0.141
158.60,31.35,0.141
158.63,31.51,0.141
158.67,31.66,0.141
158.70,31.82,0.141
158.73,31.98,0.141
158.76,32.14,0.141
158.79,32.30,0.141
158.82,32.46,0.141
158.85,32.62,0.141
158.89,32.77,0.141
158.92,32.93,0.141
158.95,33.09,0.141
158.98,33.25,0.141
159.01,33.41,0.141
159.05,33.57,0.141
159.08,33.72,0.141
159.11,33.88,0.141
159.14,34.04,0.141
159.17,34.20,0.141
159.20,34.36,0.141
159.23,34.52,0.141
159.27,34.67,0.141
159.30,34.83,0.141
159.33,34.99,0.141
159.36,35.15,0.141
159.39,35.31,0.141
159.43,35.47,0.141
159.46,35.63,0.141
159.49,35.78,0.142
159.52,35.94,0.142
159.55,36.10,0.142
159.58,36.26,0.142
159.62,36.42,0.142
159.65,36.58,0.142
159.68,36.74,0.142
159.71,36.89,0.142
159.74,37.05,0.142
159.77,37.21,0.142
159.80,37.37,0.142
159.84,37.53,0.142
159.87,37.69,0.142
159.90,37.84,0.142
159.93,38.00,0.142
159.96,38.16,0.142
160.00,38.32,0.142
160.03,38.48,0.142
160.06,38.63,0.142
160.09,38.79,0.142
160.12,38.95,0.142
160.15,39.11,0.142
160.18,39.27,0.142
160.22,39.43,0.142
160.25,39.59,0.142
160.28,39.75,0.142
160.31,39.90,0.142
160.34,40.06,0.143
160.38,40.22,0.143
160.41,40.38,0.143
160.44,40.54,0.143
160.47,40.70,0.143
160.50,40.85,0.143
160.53,41.01,0.143
160.57,41.17,0.143
160.60,41.33,0.143
160.63,41.49,0.143
160.66,41.65,0.143
160.69,41.81,0.143
160.72,41.96,0.143
160.75,42.12,0.143
160.79,42.28,0.143
160.82,42.44,0.143
160.85,42.60,0.143
160.88,42.75,0.143
160.91,42.91,0.144
160.95,43.07,0.144
160.98,43.23,0.144
161.01,43.39,0.144
161.04,43.55,0.144
161.07,43.71,0.144
161.10,43.87,0.144
161.13,44.02,0.144
161.17,44.18,0.144
161.20,44.34,0.144
161.23,44.50,0.144
161.26,44.66,0.144
161.29,44.82,0.144
161.33,44.97,0.144
161.36,45.13,0.144
161.39,45.29,0.144
161.42,45.45,0.144
161.45,45.61,0.145
161.48,45.77,0.145
161.52,45.92,0.145
161.55,46.08,0.145
161.58,46.24,0.145
161.61,46.40,0.145
161.64,46.56,0.145
161.67,46.72,0.145
161.70,46.87,0.145
161.74,47.03,0.145
161.77,47.19,0.145
161.80,47.35,0.145
161.83,47.51,0.145
161.86,47.67,0.145
161.90,47.82,0.145
161.93,47.98,0.145
161.96,48.14,0.145
161.99,48.30,0.145
162.02,48.46,0.145
162.05,48.62,0.145
162.08,48.77,0.145
162.12,48.93,0.146
162.15,49.09,0.146
162.18,49.25,0.146
162.21,49.41,0.146
162.24,49.57,0.146
162.28,49.73,0.146
162.31,49.88,0.146
162.34,50.04,0.146
162.37,50.20,0.146
162.40,50.36,0.146
162.43,50.52,0.146
162.47,50.68,0.146
162.50,50.84,0.146
162.53,50.99,0.146
162.56,51.15,0.146
162.59,51.31,0.146
162.62,51.47,0.146
162.65,51.63,0.146
162.69,51.78,0.146
162.72,51.94,0.146
162.75,52.10,0.146
162.78,52.26,0.147
162.81,52.42,0.147
162.85,52.58,0.147
162.88,52.73,0.147
162.91,52.89,0.147
162.94,53.05,0.147
162.97,53.21,0.147
163.00,53.37,0.147
163.03,53.53,0.147
163.07,53.69,0.147
163.10,53.84,0.147
163.13,54.00,0.147
163.16,54.16,0.147
163.19,54.32,0.147
163.23,54.48,0.147
163.26,54.64,0.147
163.29,54.80,0.147
163.32,54.95,0.147
163.35,55.11,0.147
163.38,55.27,0.148
163.42,55.43,0.147
163.45,55.59,0.148
163.48,55.75,0.148
163.51,55.90,0.148
163.54,56.06,0.148
163.57,56.22,0.148
163.60,56.38,0.148
163.64,56.54,0.148
163.67,56.70,0.148
163.70,56.85,0.148
163.73,57.01,0.148
163.76,57.17,0.148
163.80,57.33,0.148
163.83,57.49,0.148
163.86,57.65,0.148
163.89,57.81,0.148
163.92,57.96,0.148
163.95,58.12,0.148
163.98,58.28,0.148
164.02,58.44,0.148
164.05,58.60,0.148
164.08,58.75,0.148
164.11,58.91,0.148
164.14,59.07,0.148
164.18,59.23,0.148
164.21,59.39,0.148
164.24,59.55,0.149
164.27,59.71,0.149
164.30,59.87,0.149
164.33,60.02,0.149
164.37,60.18,0.149
164.40,60.34,0.149
164.43,60.50,0.149
164.46,60.66,0.149
164.49,60.82,0.149
164.52,60.97,0.149
164.55,61.13,0.149
164.59,61.29,0.149
164.62,61.45,0.149
164.65,61.61,0.149
164.68,61.77,0.149
164.71,61.92,0.149
164.75,62.08,0.149
164.78,62.24,0.149
164.81,62.40,0.149
164.84,62.56,0.149
164.87,62.72,0.149
164.90,62.88,0.149
164.93,63.03,0.149
164.97,63.19,0.149
165.00,63.35,0.149
165.03,63.51,0.149
165.06,63.67,0.150
165.09,63.83,0.150
165.13,63.98,0.150
165.16,64.14,0.150
165.19,64.30,0.150
165.22,64.46,0.150
165.25,64.62,0.150
165.28,64.78,0.150
165.32,64.93,0.150
165.35,65.09,0.150
165.38,65.25,0.150
165.41,65.41,0.150
165.44,65.57,0.150
165.47,65.73,0.150
165.50,65.89,0.150
165.54,66.04,0.150
165.57,66.20,0.150
165.60,66.36,0.151
165.63,66.52,0.150
165.66,66.68,0.151
165.70,66.83,0.151
165.73,66.99,0.151
165.76,67.15,0.151
165.79,67.31,0.151
165.82,67.47,0.151
165.85,67.63,0.151
165.88,67.79,0.151
165.92,67.94,0.151
165.95,68.10,0.151
165.98,68.26,0.151
166.01,68.42,0.151
166.04,68.58,0.151
166.08,68.74,0.173
166.11,68.89,0.169
166.14,69.05,0.166
166.17,69.21,0.164
166.20,69.37,0.163
166.23,69.53,0.162
166.27,69.69,0.161
166.30,69.84,0.159
166.33,70.00,0.159
166.36,70.16,0.158
166.39,70.32,0.157
166.42,70.48,0.157
166.45,70.64,0.156
166.49,70.79,0.156
166.52,70.95,0.156
166.55,71.11,0.155
166.58,71.27,0.155
166.61,71.43,0.155
166.65,71.59,0.155
166.68,71.75,0.155
166.71,71.90,0.154
166.74,72.06,0.154
166.77,72.22,0.154
166.80,72.38,0.154
166.83,72.54,0.154
166.87,72.70,0.154
166.90,72.86,0.154
166.93,73.01,0.154
166.96,73.17,0.154
166.99,73.33,0.154
167.03,73.49,0.154
167.06,73.65,0.154
167.09,73.80,0.154
167.12,73.96,0.154
167.15,74.12,0.154
167.18,74.28,0.154
167.22,74.44,0.154
167.25,74.60,0.154
167.28,74.76,0.154
167.31,74.91,0.154
167.34,75.07,0.154
167.37,75.23,0.154
167.40,75.39,0.154
167.44,75.55,0.154
167.47,75.71,0.155
167.50,75.86,0.154
167.53,76.02,0.155
167.56,76.18,0.155
167.60,76.34,0.155
167.63,76.50,0.155
167.66,76.66,0.155
167.69,76.82,0.155
167.72,76.97,0.155
167.75,77.13,0.155
167.78,77.29,0.155
167.82,77.45,0.155
167.85,77.61,0.155
167.88,77.77,0.155
167.91,77.92,0.155
167.94,78.08,0.155
167.98,78.24,0.155
168.01,78.40,0.155
168.04,78.56,0.155
168.07,78.72,0.155
168.10,78.87,0.155
168.13,79.03,0.155
168.17,79.19,0.155
168.20,79.35,0.155
168.23,79.51,0.155
168.26,79.67,0.155
168.29,79.83,0.155
168.32,79.98,0.155
168.35,80.14,0.155
168.39,80.30,0.155
168.42,80.46,0.155
168.45,80.62,0.155
168.48,80.78,0.155
168.51,80.94,0.155
168.55,81.09,0.155
168.58,81.25,0.155
168.61,81.41,0.155
168.64,81.57,0.155
168.67,81.73,0.155
168.70,81.88,0.155
168.73,82.04,0.155
168.77,82.20,0.155
168.80,82.36,0.155
168.83,82.52,0.155
168.86,82.68,0.155
168.89,82.84,0.155
168.93,83.00,0.155
168.96,83.15,0.155
168.99,83.31,0.155
169.02,83.47,0.155
169.05,83.63,0.155
169.08,83.79,0.155
169.12,83.95,0.155
169.15,84.11,0.155
169.18,84.26,0.155
169.21,84.42,0.154
169.24,84.58,0.154
169.27,84.74,0.153
169.30,84.90,0.153
169.34,85.05,0.153
169.37,85.21,0.153
169.40,85.37,0.153
169.43,85.53,0.153
169.46,85.69,0.153
169.50,85.84,0.153
169.53,86.00,0.153
169.56,86.16,0.153
169.59,86.32,0.153
169.62,86.48,0.153
169.65,86.64,0.153
169.68,86.80,0.153
169.72,86.95,0.153
169.75,87.11,0.153
169.78,87.27,0.152
169.81,87.43,0.152
169.84,87.59,0.152
169.88,87.75,0.152
169.91,87.90,0.152
169.94,88.06,0.152
169.97,88.22,0.152
170.00,88.38,0.152
170.03,88.54,0.152
170.07,88.70,0.152
170.10,88.86,0.151
170.13,89.01,0.151
170.16,89.17,0.151
170.19,89.33,0.151
170.22,89.49,0.151
170.25,89.65,0.151
170.29,89.81,0.150
170.32,89.97,0.150
170.35,90.12,0.150
170.38,90.28,0.150
170.41,90.44,0.149
170.45,90.60,0.149
170.48,90.76,0.149
170.51,90.92,0.149
170.54,91.08,0.148
170.57,91.23,0.148
170.60,91.39,0.148
170.63,91.55,0.147
170.67,91.71,0.147
170.70,91.87,0.147
170.73,92.02,0.146
170.76,92.18,0.146
170.79,92.34,0.146
170.83,92.50,0.145
170.86,92.66,0.145
170.89,92.82,0.145
170.92,92.98,0.145
170.95,93.13,0.144
170.98,93.29,0.143
171.02,93.45,0.143
171.05,93.61,0.143
171.08,93.77,0.142
171.11,93.93,0.142
171.14,94.08,0.141
171.17,94.24,0.141
171.20,94.40,0.141
171.24,94.56,0.140
171.27,94.72,0.140
171.30,94.88,0.139
171.33,95.04,0.139
171.36,95.20,0.138
171.40,95.35,0.138
171.43,95.51,0.138
171.46,95.67,0.137
171.49,95.83,0.136
171.52,95.99,0.136
171.55,96.15,0.135
171.58,96.30,0.134
171.62,96.46,0.134
171.65,96.62,0.133
171.68,96.78,0.133
171.71,96.94,0.132
171.74,97.10,0.132
171.78,97.25,0.131
171.81,97.41,0.130
171.84,97.57,0.130
171.87,97.73,0.129
171.90,97.89,0.128
171.93,98.05,0.128
171.97,98.21,0.127
172.00,98.37,0.126
172.03,98.52,0.126
172.06,98.68,0.125
172.09,98.84,0.124
172.12,99.00,0.124
172.15,99.16,0.123
172.19,99.31,0.122
172.22,99.47,0.122
172.25,99.63,0.121
172.28,99.79,0.120
172.31,99.95,0.119
172.35,100.11,0.119
172.38,100.27,0.118
172.41,100.43,0.117
172.44,100.58,0.117
172.47,100.74,0.116
172.50,100.90,0.116
172.53,101.06,0.115
172.57,101.22,0.114
172.60,101.38,0.114
172.63,101.54,0.113
172.66,101.69,0.112
172.69,101.85,0.111
172.73,102.01,0.111
172.76,102.17,0.110
172.79,102.33,0.110
172.82,102.49,0.109
172.85,102.65,0.108
172.88,102.80,0.108
172.92,102.96,0.107
172.95,103.12,0.106
172.98,103.28,0.106
173.01,103.44,0.105
173.04,103.60,0.104
173.07,103.75,0.104
173.10,103.91,0.103
173.14,104.07,0.103
173.17,104.23,0.102
173.20,104.39,0.101
173.23,104.55,0.101
173.26,104.71,0.100
173.30,104.86,0.100
173.33,105.02,0.100
173.36,105.18,0.099
173.39,105.34,0.099
173.42,105.50,0.098
173.45,105.66,0.098
173.48,105.82,0.097
173.52,105.97,0.097
173.55,106.13,0.097
173.58,106.29,0.096
173.61,106.45,0.096
173.64,106.61,0.095
173.68,106.77,0.095
173.71,106.92,0.094
173.74,107.08,0.094
173.77,107.24,0.094
173.80,107.40,0.093
173.83,107.56,0.093
173.87,107.72,0.093
173.90,107.88,0.093
173.93,108.03,0.092
173.96,108.19,0.092
173.99,108.35,0.092
174.02,108.51,0.092
174.05,108.67,0.092
174.09,108.83,0.091
174.12,108.98,0.091
174.15,109.14,0.091
174.18,109.30,0.091
174.21,109.46,0.091
174.25,109.62,0.091
174.28,109.77,0.091
174.31,109.93,0.091
174.34,110.09,0.091
174.37,110.25,0.091
174.40,110.41,0.091
174.43,110.57,0.091
174.47,110.73,0.091
174.50,110.88,0.091
174.53,111.04,0.091
174.56,111.20,0.091
174.59,111.36,0.091
174.63,111.52,0.091
174.66,111.68,0.091
174.69,111.83,0.091
174.72,111.99,0.091
174.75,112.15,0.092
174.78,112.31,0.092
174.82,112.47,0.092
174.85,112.63,0.092
174.88,112.79,0.093
174.91,112.94,0.093
174.94,113.10,0.093
174.97,113.26,0.093
175.00,113.42,0.094
175.04,113.58,0.094
175.07,113.74,0.094
175.10,113.90,0.094
175.13,114.05,0.094
175.16,114.21,0.094
175.20,114.37,0.094
175.23,114.53,0.094
175.26,114.69,0.094
175.29,114.85,0.094
175.32,115.00,0.094
175.35,115.16,0.095
175.38,115.32,0.095
175.42,115.48,0.095
175.45,115.64,0.095
175.48,115.79,0.095
175.51,115.95,0.095
175.54,116.11,0.096
175.58,116.27,0.096
175.61,116.43,0.096
175.64,116.59,0.096
175.67,116.74,0.097
175.70,116.90,0.097
175.73,117.06,0.098
175.77,117.22,0.098
175.80,117.38,0.098
175.83,117.53,0.099
175.86,117.69,0.099
175.89,117.85,0.100
175.92,118.01,0.100
175.95,118.17,0.101
175.99,118.33,0.101
176.02,118.48,0.102
176.05,118.64,0.102
176.08,118.80,0.103
176.11,118.96,0.103
176.15,119.12,0.104
176.18,119.28,0.104
176.21,119.44,0.104
176.24,119.59,0.105
176.27,119.75,0.105
176.30,119.91,0.106
176.33,120.07,0.106
176.37,120.23,0.107
176.40,120.38,0.108
176.43,120.54,0.108
176.46,120.70,0.109
176.49,120.86,0.110
176.53,121.02,0.110
176.56,121.18,0.111
176.59,121.33,0.112
176.62,121.49,0.112
176.65,121.65,0.113
176.68,121.81,0.114
176.72,121.97,0.115
176.75,122.13,0.116
176.78,122.28,0.116
176.81,122.44,0.117
176.84,122.60,0.118
176.87,122.76,0.118
176.90,122.91,0.119
176.94,123.07,0.120
176.97,123.23,0.121
177.00,123.39,0.122
177.03,123.55,0.123
177.06,123.71,0.124
177.10,123.86,0.125
177.13,124.02,0.126
177.16,124.18,0.126
177.19,124.34,0.127
177.22,124.50,0.128
177.25,124.66,0.129
177.28,124.81,0.130
177.32,124.97,0.131
177.35,125.13,0.132
177.38,125.29,0.133
177.41,125.45,0.133
177.44,125.61,0.134
177.48,125.76,0.135
177.51,125.92,0.136
177.54,126.08,0.136
177.57,126.24,0.137
177.60,126.40,0.138
177.63,126.56,0.139
177.67,126.71,0.140
177.70,126.87,0.141
177.73,127.03,0.141
177.76,127.19,0.142
177.79,127.35,0.143
177.82,127.51,0.144
177.85,127.67,0.144
177.89,127.82,0.145
177.92,127.98,0.146
177.95,128.14,0.146
177.98,128.30,0.147
178.01,128.46,0.148
178.05,128.61,0.149
178.08,128.77,0.149
178.11,128.93,0.150
178.14,129.09,0.151
178.17,129.25,0.152
178.20,129.40,0.153
178.23,129.56,0.154
178.27,129.72,0.156
178.30,129.88,0.157
178.33,130.04,0.159
178.36,130.20,0.160
178.39,130.35,0.163
178.43,130.51,0.165
178.46,130.67,0.168
178.49,130.83,0.171
178.52,130.98,0.174
178.55,131.14,0.178
178.58,131.30,0.182
178.62,131.46,0.187
178.65,131.62,0.191
178.68,131.77,0.195
178.71,131.93,0.199
178.74,132.09,0.203
178.77,132.25,0.208
178.80,132.41,0.212
178.84,132.56,0.219
178.87,132.72,0.224
178.90,132.88,0.230
178.93,133.04,0.236
178.96,133.19,0.240
179.00,133.35,0.249
179.03,133.51,0.255
179.06,133.67,0.261
179.09,133.82,0.267
179.12,133.98,0.274
179.15,134.14,0.280
179.18,134.29,0.288
179.22,134.45,0.297
179.25,134.61,0.308
179.28,134.77,0.318
179.31,134.92,0.328
179.34,135.08,0.335
179.38,135.24,0.345
179.41,135.40,0.354
179.44,135.55,0.363
179.47,135.71,0.371
179.50,135.87,0.380
179.53,136.02,0.389
179.57,136.18,0.398
179.60,136.34,0.404
179.63,136.49,0.411
179.66,136.65,0.417
179.69,136.81,0.422
179.72,136.97,0.427
179.75,137.12,0.431
179.79,137.28,0.434
179.82,137.44,0.437
179.85,137.60,0.439
179.88,137.76,0.440
179.91,137.91,0.441
179.95,138.07,0.442
179.98,138.23,0.442
180.01,138.39,0.442
180.04,138.55,0.442
180.07,138.71,0.439
180.10,138.87,0.436
180.13,139.03,0.432
180.17,139.19,0.422
180.20,139.34,0.416
180.23,139.50,0.404
180.26,139.66,0.397
180.29,139.82,0.388
180.33,139.98,0.381
180.36,140.14,0.372
180.39,140.30,0.365
180.42,140.46,0.355
180.45,140.62,0.347
180.48,140.78,0.339
180.52,140.94,0.329
180.55,141.10,0.317
180.58,141.26,0.305
180.61,141.42,0.292
180.64,141.58,0.278
180.67,141.74,0.262
180.70,141.90,0.246
180.74,142.06,0.227
180.77,142.22,0.213
180.80,142.38,0.199
180.83,142.54,0.186
180.86,142.70,0.178
180.90,142.86,0.174
180.93,143.02,0.172
180.96,143.18,0.171
180.99,143.34,0.170
181.02,143.50,0.169
181.05,143.66,0.168
181.08,143.82,0.168
181.12,143.98,0.167
181.15,144.13,0.167
181.18,144.29,0.166
181.21,144.45,0.166
181.24,144.61,0.166
181.28,144.77,0.166
181.31,144.92,0.166
181.34,145.08,0.165
181.37,145.24,0.165
181.40,145.40,0.165
181.43,145.56,0.165
181.47,145.72,0.165
181.50,145.88,0.165
181.53,146.03,0.165
181.56,146.19,0.165
181.59,146.35,0.165
181.62,146.51,0.165
181.65,146.67,0.165
181.69,146.83,0.165
181.72,146.98,0.165
181.75,147.14,0.165
181.78,147.30,0.165
181.81,147.46,0.165
181.85,147.62,0.165
181.88,147.78,0.166
181.91,147.93,0.166
181.94,148.09,0.166
181.97,148.25,0.166
182.00,148.41,0.166
182.03,148.57,0.166
182.07,148.73,0.166
182.10,148.88,0.166
182.13,149.04,0.166
182.16,149.20,0.166
182.19,149.36,0.166
182.23,149.52,0.166
182.26,149.68,0.166
182.29,149.83,0.166
182.32,149.99,0.166
182.35,150.15,0.166
182.38,150.31,0.166
182.42,150.47,0.166
182.45,150.63,0.166
182.48,150.78,0.166
182.51,150.94,0.166
182.54,151.10,0.166
182.57,151.26,0.166
182.60,151.42,0.166
182.64,151.58,0.166
182.67,151.73,0.166
182.70,151.89,0.167
182.73,152.05,0.167
182.76,152.21,0.167
182.80,152.37,0.167
182.83,152.53,0.167
182.86,152.69,0.167
182.89,152.84,0.167
182.92,153.00,0.167
182.95,153.16,0.167
182.98,153.32,0.167
183.02,153.48,0.167
183.05,153.64,0.167
183.08,153.79,0.167
183.11,153.95,0.168
183.14,154.11,0.168
183.18,154.27,0.168
183.21,154.43,0.168
183.24,154.59,0.168
183.27,154.75,0.168
183.30,154.90,0.168
183.33,155.06,0.168
183.37,155.22,0.168
183.40,155.38,0.168
183.43,155.54,0.168
183.46,155.69,0.168
183.49,155.85,0.167
183.52,156.01,0.167
183.55,156.17,0.167
183.59,156.33,0.167
183.62,156.49,0.167
183.65,156.64,0.167
183.68,156.80,0.167
183.71,156.96,0.167
183.75,157.12,0.167
183.78,157.28,0.167
183.81,157.43,0.167
183.84,157.59,0.167
183.87,157.75,0.168
183.90,157.91,0.168
183.93,158.07,0.168
183.97,158.23,0.168
184.00,158.39,0.168
184.03,158.54,0.168
184.06,158.70,0.168
184.09,158.86,0.168
184.13,159.02,0.168
184.16,159.18,0.168
184.19,159.34,0.168
184.22,159.49,0.168
184.25,159.65,0.168
184.28,159.81,0.168
184.32,159.97,0.168
184.35,160.13,0.168
184.38,160.29,0.168
184.41,160.44,0.168
184.44,160.60,0.168
184.47,160.76,0.168
184.50,160.92,0.168
184.54,161.08,0.168
184.57,161.24,0.168
184.60,161.40,0.169
184.63,161.55,0.169
184.66,161.71,0.169
184.70,161.87,0.169
184.73,162.03,0.169
184.76,162.19,0.169
184.79,162.34,0.169
184.82,162.50,0.169
184.85,162.66,0.169
184.88,162.82,0.169
184.92,162.98,0.169
184.95,163.14,0.169
184.98,163.30,0.169
185.01,163.45,0.169
185.04,163.61,0.169
185.08,163.77,0.169
185.11,163.93,0.169
185.14,164.09,0.169
185.17,164.24,0.169
185.20,164.40,0.170
185.23,164.56,0.170
185.27,164.72,0.170
185.30,164.88,0.170
185.33,165.04,0.170
185.36,165.20,0.171
185.39,165.35,0.171
185.42,165.51,0.171
185.45,165.67,0.171
185.49,165.83,0.171
185.52,165.99,0.171
185.55,166.15,0.171
185.58,166.30,0.171
185.61,166.46,0.172
185.65,166.62,0.172
185.68,166.78,0.172
185.71,166.94,0.172
185.74,167.09,0.172
185.77,167.25,0.173
185.80,167.41,0.173
185.83,167.57,0.173
185.87,167.73,0.174
185.90,167.89,0.174
185.93,168.05,0.174
185.96,168.20,0.174
185.99,168.36,0.174
186.03,168.52,0.174
186.06,168.68,0.174
186.09,168.84,0.175
186.12,168.99,0.174
186.15,169.15,
186.18,169.31,
186.20,,