File: DSC/2025_04_13_L_Proline_n60C_200C_10Cmin_x3.csv
Filename,2025_04_13_L_Proline_n60C_200C_10Cmin_x3
Instrument name,DSC2A-00468 (192.168.1.100)
Operator,Yarger
rundate,4/13/2025
Sample name,2025_04_13_L_Proline_n60C_200C_10Cmin_x3
proceduresegments,Data Off ; Equilibrate -60.00 °C; Data On ; Ramp 10.00 °C/min to 200.00 °C; Data Off ; Isothermal 1.0 min; Data On ; Ramp 10.00 °C/min to -60.00 °C; Data Off ; Isothermal 1.0 min; Data On ; Ramp 10.00 °C/min to 200.00 °C; Data Off ; Isothermal 1.0 min; Data On ; Ramp 10.00 °C/min to -60.00 °C; Data Off ; Isothermal 1.0 min; Data On ; Ramp 10.00 °C/min to 200.00 °C
[File Parameters]
Run date,4/13/2025 6:28:42 AM
Trios version,5.1.1.46572
Original File Name,
Current File Name,D:\DSC2500\JYarger\2025_04_13_L_Proline_n60C_200C_10Cmin_x3.tri
[Procedure]
Procedure Name,Pro_n60_200C_10Cmin_x3
Sample Name,2025_04_13_L_Proline_n60C_200C_10Cmin_x3
Sample Mass,6.12 mg
Reference Sample Mass,0 mg
Pan Mass,53.39 mg
Pan Number,43
Reference Pan Mass,53.32 mg
Reference Pan Number,10
Pan Type,Tzero Aluminum Hermetic
Comments,Hermetic Sealed Al DSC Consumables Pan/Lids.
Project Name,CA
Operator,Yarger
Test,Custom
Unload Max Temperature,30
Unload Min Temperature,30
Load Max Temperature,30
Load Min Temperature,30
Stop on Gas Flow Error,Yes
[Signal List]
Signal #1,Time (min)
Signal #2,Temperature (°C)
Signal #3,Heat Flow (mW)
Signal #4,Delta T (µV)
Signal #5,Delta Tzero (µV)
Signal #6,Tzero Temperature (°C)
Signal #7,Cell Purge (mL/min)
Signal #8,Heater Temp (°C)
Signal #9,Power Delivered (W)
Signal #10,Reference Junction Temperature (°C)
Signal #11,Flange Temperature (°C)
Signal #12,Heat Flow Phase (rad)
Signal #13,Total Heat Capacity (J/°C)
Signal #14,Heat Capacity (J/°C)
[Configuration]
Company Name,ASU
Instrument Name,DSC2A-00468
Instrument Type,DSC2500
Serial Number,DSC2A-00468
IP,192.168.1.100
Location of Instrument,MRRC
DisplayType,Unknown
Sample Interval ,0.1 s/pt
Selected Heat Flow,T4P
Exotherm Direction,Down
Cell Serial,DRC2-00792
Lid Type,Standard
Cooler,RCS 90
Leave Cooler on at End of Sequence,On
Gas 2,Nitrogen
Gas Selected,Channel 1
Flow Rate,50 mL/min
Secondary Purge,On
Licensed Heat Flow,Heat Flow T4P
Modulation Licensed,Yes
[Versions]
Common IDD Version,1
Cortex Version,VER 2.10.2.31
Driver,5.0.0.6
GDM Version,1.0.3.3
TouchscreenVersion,1.0.0.16145
FEP Version,1.2.1.21
FEP Bootloader,2.0.0.5
AutoSampler Version,2.1.1.26
Auto Sampler Bootloader,2.0.0.5
FCM Version,1.1.0.3
FCM Bootloader,2.0.0.5
[Experiment Logs]
Experiment Log Entry # 1,Data On set to 0
Experiment Log Entry # 3,Equilibrate Segment -60 (C) Started
Experiment Log Entry # 5,Air Cool is off.
Experiment Log Entry # 7,Data On set to 1
Experiment Log Entry # 9,Ramp Segment 10 C/min to 200 Started
Experiment Log Entry # 11,Data On set to 0
Experiment Log Entry # 13,Isothermal Segment 1 min started
Experiment Log Entry # 15,Data On set to 1
Experiment Log Entry # 17,Ramp Segment 10 C/min to -60 Started
Experiment Log Entry # 19,Data On set to 0
Experiment Log Entry # 21,Isothermal Segment 1 min started
Experiment Log Entry # 23,Data On set to 1
Experiment Log Entry # 25,Ramp Segment 10 C/min to 200 Started
Experiment Log Entry # 27,Data On set to 0
Experiment Log Entry # 29,Isothermal Segment 1 min started
Experiment Log Entry # 31,Data On set to 1
Experiment Log Entry # 33,Ramp Segment 10 C/min to -60 Started
Experiment Log Entry # 35,Data On set to 0
Experiment Log Entry # 37,Isothermal Segment 1 min started
Experiment Log Entry # 39,Data On set to 1
Experiment Log Entry # 41,Ramp Segment 10 C/min to 200 Started
[Method Log]
Method Log Entry # 1,Data Off
Method Log Entry # 2,Equilibrate -60 °C
Method Log Entry # 3,Data On
Method Log Entry # 4,(Ramp 350993) Ramp 10 °C/minute to 200 °C
Method Log Entry # 5,Data Off
Method Log Entry # 6,Isothermal 1 minutes
Method Log Entry # 7,Data On
Method Log Entry # 8,(Ramp 350997) Ramp 10 °C/minute to -60 °C
Method Log Entry # 9,Data Off
Method Log Entry # 10,Isothermal 1 minutes
Method Log Entry # 11,Data On
Method Log Entry # 12,(Ramp 351001) Ramp 10 °C/minute to 200 °C
Method Log Entry # 13,Data Off
Method Log Entry # 14,Isothermal 1 minutes
Method Log Entry # 15,Data On
Method Log Entry # 16,(Ramp 351005) Ramp 10 °C/minute to -60 °C
Method Log Entry # 17,Data Off
Method Log Entry # 18,Isothermal 1 minutes
Method Log Entry # 19,Data On
Method Log Entry # 20,(Ramp 351009) Ramp 10 °C/minute to 200 °C
Cell Serial,DRC2-00792
[T1 Calibration]
Slope,-0.008529666
Offset,9.636258
Initial Temperature,98.23
GUID,f8bfdadc-4977-4fdf-ba6d-0ba9134940c3
[TZero Calibration]
Date Applied,11/29/2022 4:06:13 PM
Description,From -89.059 °C to 396.009 °C at 20.000°C/min
Gas Type,Nitrogen
Pan Type,None
Source Files 1,C:\Users\yargerlab\Desktop\DSC Data\General\TZero_calibration_11_29_22_2nd(2).tri
Source Files 2,C:\Users\yargerlab\Desktop\DSC Data\General\TZero_calibration_11_29_22_2nd(3).tri
Delta T Offset,13.05235
Delta T Slope,-0.007271007
Delta T0 Offset,-13.69128
Delta T0 Slope,0.06063341
[Temperature Calibration]
Date Applied,11/29/2022 7:12:28 PM
Description,From 106.590 °C to 186.590 °C at 10.000°C/min
Gas Type,Nitrogen
Pan Type,Tzero Aluminum Hermetic
Source Files 1,C:\Users\yargerlab\Desktop\DSC Data\General\Indium(6).tri
Measured 1,157.391
Known 1,156.598
[Cell Constant Calibration]
Date Applied,11/29/2022 7:12:29 PM
Description,From 106.590 °C to 186.590 °C at 10.000°C/min
Gas Type,Nitrogen
Pan Type,Tzero Aluminum Hermetic
Source Files 1,C:\Users\yargerlab\Desktop\DSC Data\General\Indium(6).tri
T4P KCell,1.006051
Onset Slope,63.26126 mW/°C
[Direct Cp Calibration]
Date Applied,11/30/2022 11:04:51 AM
Description,From -79.983 °C to 298.409 °C at 10.000°C/min
Gas Type,Nitrogen
Pan Type,Tzero Aluminum Hermetic
Source Files 1,C:\Users\yargerlab\Desktop\DSC Data\General\Sapphire_Heat_Capacity_11_30_22.tri
[Rev Cp Calibration]
Date Applied,11/30/2022 1:58:51 PM
Description,From -79.996 °C to 292.812 °C at 3.000°C/min
Gas Type,Nitrogen
Pan Type,Tzero Aluminum Hermetic
Source Files 1,C:\Users\yargerlab\Desktop\DSC Data\General\Sapphire_MDSC_Calibration_11_30_22.tri
[step]
Ramp 10.00 °C/min to 200.00 °C
Time,Temperature,Heat Flow (Normalized)
min,°C,W/g
0.00,-59.69,-0.031
0.02,-59.70,-0.030
0.04,-59.70,-0.026
0.05,-59.71,-0.022
0.07,-59.69,-0.019
0.09,-59.66,-0.016
0.11,-59.60,-0.011
0.13,-59.53,-0.001
0.15,-59.44,0.013
0.16,-59.33,0.027
0.18,-59.21,0.043
0.20,-59.08,0.059
0.22,-58.94,0.075
0.24,-58.80,0.088
0.26,-58.64,0.101
0.28,-58.48,0.109
0.29,-58.33,0.118
0.31,-58.16,0.126
0.33,-58.00,0.132
0.35,-57.83,0.137
0.37,-57.66,0.140
0.39,-57.49,0.143
0.40,-57.32,0.147
0.42,-57.15,0.150
0.44,-56.98,0.151
0.46,-56.80,0.152
0.48,-56.63,0.153
0.50,-56.45,0.154
0.51,-56.28,0.155
0.53,-56.10,0.156
0.55,-55.92,0.157
0.57,-55.75,0.158
0.59,-55.57,0.158
0.60,-55.39,0.158
0.62,-55.21,0.158
0.64,-55.03,0.159
0.66,-54.85,0.159
0.68,-54.67,0.159
0.70,-54.50,0.159
0.72,-54.31,0.160
0.73,-54.13,0.160
0.75,-53.95,0.160
0.77,-53.78,0.160
0.79,-53.59,0.160
0.81,-53.42,0.160
0.83,-53.24,0.161
0.84,-53.06,0.161
0.86,-52.87,0.161
0.88,-52.69,0.161
0.90,-52.51,0.161
0.92,-52.33,0.161
0.93,-52.15,0.161
0.95,-51.97,0.161
0.97,-51.79,0.162
0.99,-51.61,0.162
1.01,-51.43,0.162
1.03,-51.24,0.162
1.05,-51.06,0.162
1.06,-50.88,0.162
1.08,-50.70,0.162
1.10,-50.52,0.162
1.12,-50.34,0.162
1.14,-50.15,0.162
1.16,-49.97,0.162
1.17,-49.79,0.162
1.19,-49.61,0.162
1.21,-49.42,0.162
1.23,-49.24,0.162
1.25,-49.06,0.163
1.27,-48.88,0.163
1.28,-48.69,0.163
1.30,-48.51,0.163
1.32,-48.33,0.163
1.34,-48.15,0.163
1.36,-47.96,0.163
1.38,-47.78,0.163
1.39,-47.60,0.163
1.41,-47.41,0.163
1.43,-47.23,0.163
1.45,-47.05,0.163
1.47,-46.87,0.163
1.48,-46.68,0.163
1.50,-46.50,0.163
1.52,-46.32,0.163
1.54,-46.13,0.163
1.56,-45.95,0.163
1.58,-45.77,0.163
1.59,-45.59,0.163
1.61,-45.40,0.163
1.63,-45.22,0.163
1.65,-45.04,0.163
1.67,-44.85,0.163
1.69,-44.67,0.163
1.71,-44.49,0.163
1.72,-44.30,0.163
1.74,-44.12,0.163
1.76,-43.94,0.163
1.78,-43.75,0.163
1.80,-43.57,0.163
1.82,-43.39,0.163
1.83,-43.20,0.163
1.85,-43.02,0.163
1.87,-42.84,0.163
1.89,-42.65,0.163
1.91,-42.47,0.163
1.93,-42.29,0.163
1.94,-42.10,0.163
1.96,-41.92,0.163
1.98,-41.74,0.163
2.00,-41.55,0.163
2.02,-41.37,0.163
2.03,-41.19,0.163
2.05,-41.00,0.163
2.07,-40.82,0.163
2.09,-40.64,0.163
2.11,-40.45,0.163
2.13,-40.27,0.164
2.14,-40.09,0.164
2.16,-39.90,0.164
2.18,-39.72,0.164
2.20,-39.53,0.164
2.22,-39.35,0.164
2.24,-39.17,0.164
2.26,-38.98,0.164
2.27,-38.80,0.164
2.29,-38.62,0.164
2.31,-38.43,0.164
2.33,-38.25,0.164
2.35,-38.07,0.164
2.36,-37.88,0.164
2.38,-37.70,0.164
2.40,-37.51,0.164
2.42,-37.33,0.164
2.44,-37.15,0.164
2.46,-36.96,0.164
2.48,-36.78,0.164
2.49,-36.60,0.164
2.51,-36.42,0.164
2.53,-36.23,0.164
2.55,-36.05,0.164
2.57,-35.86,0.164
2.59,-35.68,0.164
2.60,-35.50,0.164
2.62,-35.31,0.164
2.64,-35.13,0.164
2.66,-34.95,0.164
2.68,-34.76,0.164
2.69,-34.58,0.164
2.71,-34.39,0.165
2.73,-34.21,0.165
2.75,-34.03,0.165
2.77,-33.85,0.165
2.79,-33.66,0.165
2.81,-33.48,0.165
2.82,-33.30,0.165
2.84,-33.11,0.165
2.86,-32.93,0.165
2.88,-32.74,0.165
2.90,-32.56,0.165
2.91,-32.38,0.165
2.93,-32.19,0.165
2.95,-32.01,0.165
2.97,-31.82,0.165
2.99,-31.64,0.165
3.01,-31.46,0.165
3.03,-31.28,0.165
3.04,-31.09,0.165
3.06,-30.91,0.165
3.08,-30.72,0.165
3.10,-30.54,0.165
3.12,-30.36,0.165
3.14,-30.17,0.165
3.15,-29.99,0.166
3.17,-29.81,0.166
3.19,-29.62,0.166
3.21,-29.44,0.166
3.23,-29.26,0.166
3.24,-29.07,0.166
3.26,-28.89,0.166
3.28,-28.71,0.166
3.30,-28.52,0.166
3.32,-28.34,0.166
3.34,-28.15,0.166
3.36,-27.97,0.166
3.37,-27.79,0.166
3.39,-27.60,0.166
3.41,-27.42,0.166
3.43,-27.24,0.166
3.45,-27.05,0.166
3.46,-26.87,0.166
3.48,-26.69,0.166
3.50,-26.50,0.166
3.52,-26.32,0.167
3.54,-26.14,0.167
3.56,-25.95,0.167
3.58,-25.77,0.167
3.59,-25.59,0.167
3.61,-25.40,0.167
3.63,-25.22,0.167
3.65,-25.04,0.167
3.67,-24.85,0.167
3.69,-24.67,0.167
3.70,-24.48,0.167
3.72,-24.30,0.167
3.74,-24.12,0.167
3.76,-23.93,0.167
3.78,-23.75,0.167
3.79,-23.57,0.167
3.81,-23.38,0.167
3.83,-23.20,0.167
3.85,-23.01,0.168
3.87,-22.83,0.168
3.89,-22.65,0.168
3.91,-22.46,0.168
3.92,-22.28,0.168
3.94,-22.10,0.168
3.96,-21.92,0.168
3.98,-21.73,0.168
4.00,-21.55,0.168
4.01,-21.36,0.168
4.03,-21.18,0.168
4.05,-21.00,0.168
4.07,-20.81,0.168
4.09,-20.63,0.168
4.11,-20.45,0.168
4.13,-20.26,0.168
4.14,-20.08,0.169
4.16,-19.90,0.169
4.18,-19.71,0.169
4.20,-19.53,0.169
4.22,-19.34,0.169
4.24,-19.16,0.169
4.25,-18.98,0.169
4.27,-18.79,0.169
4.29,-18.61,0.169
4.31,-18.43,0.169
4.33,-18.24,0.169
4.35,-18.06,0.169
4.36,-17.88,0.169
4.38,-17.69,0.169
4.40,-17.51,0.169
4.42,-17.33,0.170
4.44,-17.14,0.170
4.45,-16.96,0.170
4.47,-16.78,0.170
4.49,-16.59,0.170
4.51,-16.41,0.170
4.53,-16.22,0.170
4.55,-16.04,0.170
4.56,-15.86,0.170
4.58,-15.67,0.170
4.60,-15.49,0.170
4.62,-15.31,0.170
4.64,-15.12,0.170
4.66,-14.94,0.170
4.68,-14.75,0.171
4.69,-14.57,0.171
4.71,-14.39,0.171
4.73,-14.20,0.171
4.75,-14.02,0.171
4.77,-13.84,0.171
4.79,-13.65,0.171
4.80,-13.47,0.171
4.82,-13.29,0.171
4.84,-13.10,0.171
4.86,-12.92,0.171
4.88,-12.74,0.171
4.90,-12.55,0.171
4.91,-12.37,0.171
4.93,-12.19,0.172
4.95,-12.00,0.172
4.97,-11.82,0.172
4.99,-11.64,0.172
5.00,-11.45,0.172
5.02,-11.27,0.172
5.04,-11.09,0.172
5.06,-10.90,0.172
5.08,-10.72,0.172
5.10,-10.54,0.172
5.11,-10.35,0.172
5.13,-10.17,0.172
5.15,-9.99,0.172
5.17,-9.80,0.172
5.19,-9.62,0.173
5.21,-9.43,0.173
5.23,-9.25,0.173
5.24,-9.07,0.173
5.26,-8.88,0.173
5.28,-8.70,0.173
5.30,-8.52,0.173
5.32,-8.33,0.173
5.34,-8.15,0.173
5.35,-7.97,0.173
5.37,-7.78,0.173
5.39,-7.60,0.174
5.41,-7.41,0.174
5.43,-7.23,0.174
5.45,-7.05,0.174
5.46,-6.86,0.174
5.48,-6.68,0.174
5.50,-6.50,0.174
5.52,-6.31,0.174
5.54,-6.13,0.174
5.55,-5.95,0.174
5.57,-5.76,0.174
5.59,-5.58,0.175
5.61,-5.39,0.175
5.63,-5.21,0.175
5.65,-5.03,0.175
5.66,-4.84,0.175
5.68,-4.66,0.175
5.70,-4.48,0.175
5.72,-4.29,0.175
5.74,-4.11,0.175
5.76,-3.93,0.175
5.78,-3.74,0.175
5.79,-3.56,0.175
5.81,-3.38,0.176
5.83,-3.19,0.176
5.85,-3.01,0.176
5.87,-2.82,0.176
5.89,-2.64,0.176
5.90,-2.46,0.176
5.92,-2.27,0.176
5.94,-2.09,0.176
5.96,-1.91,0.176
5.98,-1.72,0.176
6.00,-1.54,0.176
6.01,-1.36,0.177
6.03,-1.17,0.177
6.05,-0.99,0.177
6.07,-0.81,0.177
6.09,-0.62,0.177
6.10,-0.44,0.177
6.12,-0.26,0.177
6.14,-0.07,0.177
6.16,0.11,0.177
6.18,0.29,0.177
6.20,0.48,0.177
6.21,0.66,0.177
6.23,0.84,0.178
6.25,1.03,0.178
6.27,1.21,0.178
6.29,1.39,0.178
6.31,1.58,0.178
6.33,1.76,0.178
6.34,1.95,0.178
6.36,2.13,0.178
6.38,2.31,0.178
6.40,2.50,0.178
6.42,2.68,0.179
6.44,2.86,0.179
6.45,3.05,0.179
6.47,3.23,0.179
6.49,3.41,0.179
6.51,3.60,0.179
6.53,3.78,0.179
6.55,3.97,0.179
6.56,4.15,0.179
6.58,4.33,0.179
6.60,4.52,0.179
6.62,4.70,0.180
6.64,4.88,0.180
6.65,5.07,0.180
6.67,5.25,0.180
6.69,5.43,0.180
6.71,5.62,0.180
6.73,5.80,0.180
6.75,5.98,0.180
6.76,6.17,0.180
6.78,6.35,0.181
6.80,6.53,0.181
6.82,6.72,0.181
6.84,6.90,0.181
6.86,7.09,0.181
6.88,7.27,0.181
6.89,7.45,0.181
6.91,7.64,0.181
6.93,7.82,0.181
6.95,8.00,0.182
6.97,8.19,0.182
6.99,8.37,0.182
7.00,8.55,0.182
7.02,8.74,0.182
7.04,8.92,0.182
7.06,9.10,0.182
7.08,9.29,0.182
7.10,9.47,0.182
7.11,9.66,0.183
7.13,9.84,0.183
7.15,10.02,0.183
7.17,10.21,0.183
7.19,10.39,0.183
7.20,10.57,0.183
7.22,10.76,0.183
7.24,10.94,0.183
7.26,11.12,0.184
7.28,11.31,0.184
7.30,11.49,0.184
7.31,11.67,0.184
7.33,11.86,0.184
7.35,12.04,0.184
7.37,12.23,0.184
7.39,12.41,0.184
7.41,12.59,0.185
7.43,12.78,0.185
7.44,12.96,0.185
7.46,13.14,0.185
7.48,13.33,0.185
7.50,13.51,0.185
7.52,13.69,0.185
7.54,13.88,0.185
7.55,14.06,0.185
7.57,14.24,0.185
7.59,14.43,0.186
7.61,14.61,0.186
7.63,14.79,0.186
7.65,14.98,0.186
7.66,15.16,0.186
7.68,15.35,0.186
7.70,15.53,0.186
7.72,15.71,0.186
7.74,15.90,0.186
7.75,16.08,0.187
7.77,16.26,0.187
7.79,16.45,0.187
7.81,16.63,0.187
7.83,16.81,0.187
7.85,17.00,0.187
7.86,17.18,0.187
7.88,17.36,0.187
7.90,17.55,0.187
7.92,17.73,0.188
7.94,17.91,0.188
7.96,18.10,0.188
7.98,18.28,0.188
7.99,18.46,0.188
8.01,18.65,0.188
8.03,18.83,0.188
8.05,19.02,0.188
8.07,19.20,0.188
8.09,19.38,0.188
8.10,19.57,0.189
8.12,19.75,0.189
8.14,19.93,0.189
8.16,20.12,0.189
8.18,20.30,0.189
8.20,20.48,0.189
8.21,20.67,0.189
8.23,20.85,0.190
8.25,21.03,0.190
8.27,21.22,0.190
8.29,21.40,0.190
8.30,21.59,0.190
8.32,21.77,0.190
8.34,21.95,0.190
8.36,22.13,0.190
8.38,22.32,0.191
8.40,22.50,0.191
8.41,22.69,0.191
8.43,22.87,0.191
8.45,23.05,0.191
8.47,23.24,0.191
8.49,23.42,0.191
8.51,23.60,0.191
8.53,23.79,0.192
8.54,23.97,0.192
8.56,24.15,0.192
8.58,24.34,0.192
8.60,24.52,0.192
8.62,24.70,0.192
8.63,24.89,0.192
8.65,25.07,0.192
8.67,25.25,0.192
8.69,25.44,0.192
8.71,25.62,0.193
8.73,25.80,0.193
8.75,25.99,0.193
8.76,26.17,0.193
8.78,26.35,0.193
8.80,26.54,0.193
8.82,26.72,0.193
8.84,26.91,0.193
8.85,27.09,0.194
8.87,27.27,0.194
8.89,27.46,0.194
8.91,27.64,0.194
8.93,27.82,0.194
8.95,28.01,0.194
8.97,28.19,0.194
8.98,28.37,0.195
9.00,28.56,0.195
9.02,28.74,0.195
9.04,28.92,0.195
9.06,29.11,0.195
9.08,29.29,0.195
9.09,29.48,0.195
9.11,29.66,0.195
9.13,29.84,0.196
9.15,30.03,0.196
9.17,30.21,0.196
9.18,30.39,0.196
9.20,30.58,0.196
9.22,30.76,0.196
9.24,30.94,0.196
9.26,31.13,0.196
9.28,31.31,0.197
9.30,31.49,0.197
9.31,31.68,0.197
9.33,31.86,0.197
9.35,32.04,0.197
9.37,32.23,0.197
9.39,32.41,0.197
9.40,32.59,0.198
9.42,32.78,0.198
9.44,32.96,0.198
9.46,33.15,0.198
9.48,33.33,0.198
9.50,33.51,0.198
9.52,33.70,0.198
9.53,33.88,0.198
9.55,34.06,0.198
9.57,34.25,0.199
9.59,34.43,0.199
9.61,34.61,0.199
9.63,34.80,0.199
9.64,34.98,0.199
9.66,35.16,0.199
9.68,35.35,0.199
9.70,35.53,0.199
9.72,35.71,0.200
9.73,35.90,0.200
9.75,36.08,0.200
9.77,36.26,0.200
9.79,36.45,0.200
9.81,36.63,0.200
9.83,36.82,0.200
9.85,37.00,0.200
9.86,37.18,0.200
9.88,37.37,0.201
9.90,37.55,0.201
9.92,37.73,0.201
9.94,37.92,0.201
9.95,38.10,0.201
9.97,38.28,0.201
9.99,38.47,0.201
10.01,38.65,0.202
10.03,38.83,0.202
10.05,39.02,0.202
10.07,39.20,0.202
10.08,39.38,0.202
10.10,39.57,0.202
10.12,39.75,0.202
10.14,39.93,0.202
10.16,40.12,0.202
10.18,40.30,0.202
10.19,40.49,0.203
10.21,40.67,0.203
10.23,40.85,0.203
10.25,41.04,0.203
10.27,41.22,0.203
10.28,41.40,0.203
10.30,41.59,0.203
10.32,41.77,0.203
10.34,41.95,0.204
10.36,42.14,0.204
10.38,42.32,0.204
10.40,42.50,0.204
10.41,42.69,0.204
10.43,42.87,0.204
10.45,43.06,0.204
10.47,43.24,0.205
10.49,43.42,0.205
10.50,43.60,0.205
10.52,43.79,0.205
10.54,43.97,0.205
10.56,44.16,0.205
10.58,44.34,0.205
10.60,44.52,0.205
10.62,44.71,0.206
10.63,44.89,0.206
10.65,45.07,0.206
10.67,45.26,0.206
10.69,45.44,0.206
10.71,45.63,0.206
10.73,45.81,0.207
10.74,45.99,0.207
10.76,46.17,0.207
10.78,46.36,0.207
10.80,46.54,0.207
10.82,46.72,0.207
10.83,46.91,0.207
10.85,47.09,0.207
10.87,47.28,0.208
10.89,47.46,0.208
10.91,47.64,0.208
10.93,47.83,0.208
10.95,48.01,0.208
10.96,48.19,0.208
10.98,48.38,0.208
11.00,48.56,0.209
11.02,48.74,0.209
11.04,48.93,0.209
11.05,49.11,0.209
11.07,49.30,0.209
11.09,49.48,0.209
11.11,49.66,0.209
11.13,49.85,0.210
11.15,50.03,0.210
11.17,50.21,0.210
11.18,50.40,0.210
11.20,50.58,0.210
11.22,50.76,0.210
11.24,50.95,0.210
11.26,51.13,0.211
11.28,51.31,0.211
11.29,51.50,0.211
11.31,51.68,0.211
11.33,51.86,0.211
11.35,52.05,0.211
11.37,52.23,0.211
11.38,52.41,0.211
11.40,52.60,0.212
11.42,52.78,0.212
11.44,52.96,0.212
11.46,53.15,0.212
11.48,53.33,0.212
11.50,53.52,0.212
11.51,53.70,0.212
11.53,53.88,0.213
11.55,54.06,0.213
11.57,54.25,0.213
11.59,54.43,0.213
11.60,54.61,0.213
11.62,54.80,0.213
11.64,54.98,0.213
11.66,55.17,0.214
11.68,55.35,0.214
11.70,55.53,0.214
11.72,55.72,0.214
11.73,55.90,0.214
11.75,56.08,0.214
11.77,56.27,0.215
11.79,56.45,0.215
11.81,56.63,0.215
11.83,56.82,0.215
11.84,57.00,0.215
11.86,57.18,0.215
11.88,57.37,0.215
11.90,57.55,0.216
11.92,57.73,0.216
11.93,57.92,0.216
11.95,58.10,0.216
11.97,58.28,0.216
11.99,58.47,0.216
12.01,58.65,0.217
12.03,58.84,0.217
12.05,59.02,0.217
12.06,59.20,0.217
12.08,59.39,0.217
12.10,59.57,0.217
12.12,59.75,0.217
12.14,59.94,0.218
12.15,60.12,0.218
12.17,60.31,0.218
12.19,60.49,0.218
12.21,60.67,0.218
12.23,60.85,0.218
12.25,61.04,0.218
12.27,61.22,0.219
12.28,61.41,0.219
12.30,61.59,0.219
12.32,61.77,0.219
12.34,61.96,0.219
12.36,62.14,0.219
12.38,62.32,0.219
12.39,62.51,0.220
12.41,62.69,0.220
12.43,62.87,0.220
12.45,63.06,0.220
12.47,63.24,0.220
12.48,63.42,0.220
12.50,63.61,0.220
12.52,63.79,0.221
12.54,63.98,0.221
12.56,64.16,0.221
12.58,64.34,0.221
12.60,64.53,0.221
12.61,64.71,0.221
12.63,64.89,0.221
12.65,65.08,0.221
12.67,65.26,0.222
12.69,65.44,0.222
12.70,65.63,0.222
12.72,65.81,0.222
12.74,65.99,0.222
12.76,66.18,0.222
12.78,66.36,0.223
12.80,66.54,0.223
12.82,66.73,0.223
12.83,66.91,0.223
12.85,67.09,0.223
12.87,67.28,0.223
12.89,67.46,0.223
12.91,67.64,0.224
12.93,67.83,0.224
12.94,68.01,0.224
12.96,68.19,0.224
12.98,68.38,0.224
13.00,68.56,0.224
13.02,68.74,0.225
13.03,68.93,0.225
13.05,69.11,0.225
13.07,69.29,0.225
13.09,69.48,0.225
13.11,69.66,0.225
13.13,69.85,0.225
13.15,70.03,0.225
13.16,70.21,0.226
13.18,70.40,0.226
13.20,70.58,0.226
13.22,70.76,0.226
13.24,70.95,0.226
13.25,71.13,0.226
13.27,71.31,0.226
13.29,71.50,0.226
13.31,71.68,0.226
13.33,71.86,0.226
13.35,72.05,0.227
13.37,72.23,0.227
13.38,72.41,0.227
13.40,72.60,0.227
13.42,72.78,0.227
13.44,72.97,0.227
13.46,73.15,0.227
13.48,73.33,0.227
13.49,73.52,0.227
13.51,73.70,0.227
13.53,73.88,0.227
13.55,74.07,0.228
13.57,74.25,0.228
13.58,74.43,0.228
13.60,74.62,0.228
13.62,74.80,0.228
13.64,74.98,0.228
13.66,75.17,0.228
13.68,75.35,0.228
13.70,75.53,0.228
13.71,75.72,0.228
13.73,75.90,0.228
13.75,76.08,0.229
13.77,76.27,0.229
13.79,76.45,0.229
13.80,76.63,0.229
13.82,76.82,0.229
13.84,77.00,0.229
13.86,77.19,0.229
13.88,77.37,0.230
13.90,77.55,0.230
13.92,77.74,0.230
13.93,77.92,0.230
13.95,78.10,0.230
13.97,78.29,0.230
13.99,78.47,0.230
14.01,78.65,0.230
14.03,78.84,0.231
14.04,79.02,0.231
14.06,79.20,0.231
14.08,79.39,0.231
14.10,79.57,0.231
14.12,79.75,0.231
14.13,79.94,0.231
14.15,80.12,0.232
14.17,80.30,0.232
14.19,80.49,0.232
14.21,80.67,0.232
14.23,80.86,0.232
14.25,81.04,0.232
14.26,81.22,0.232
14.28,81.40,0.233
14.30,81.59,0.233
14.32,81.77,0.233
14.34,81.96,0.233
14.35,82.14,0.233
14.37,82.32,0.233
14.39,82.50,0.233
14.41,82.69,0.233
14.43,82.87,0.233
14.45,83.06,0.234
14.47,83.24,0.234
14.48,83.42,0.234
14.50,83.61,0.234
14.52,83.79,0.234
14.54,83.97,0.234
14.56,84.16,0.234
14.58,84.34,0.234
14.59,84.52,0.234
14.61,84.71,0.235
14.63,84.89,0.235
14.65,85.07,0.235
14.67,85.26,0.235
14.68,85.44,0.235
14.70,85.62,0.235
14.72,85.81,0.235
14.74,85.99,0.235
14.76,86.18,0.236
14.78,86.36,0.236
14.80,86.54,0.236
14.81,86.73,0.236
14.83,86.91,0.236
14.85,87.09,0.236
14.87,87.28,0.236
14.89,87.46,0.237
14.90,87.64,0.237
14.92,87.83,0.237
14.94,88.01,0.237
14.96,88.19,0.237
14.98,88.38,0.237
15.00,88.56,0.237
15.02,88.74,0.237
15.03,88.93,0.238
15.05,89.11,0.238
15.07,89.29,0.238
15.09,89.48,0.238
15.11,89.66,0.238
15.13,89.84,0.238
15.14,90.03,0.239
15.16,90.21,0.239
15.18,90.40,0.239
15.20,90.58,0.239
15.22,90.76,0.239
15.23,90.95,0.239
15.25,91.13,0.239
15.27,91.31,0.240
15.29,91.50,0.240
15.31,91.68,0.240
15.33,91.86,0.240
15.35,92.05,0.240
15.36,92.23,0.240
15.38,92.41,0.241
15.40,92.60,0.241
15.42,92.78,0.241
15.44,92.96,0.241
15.45,93.15,0.241
15.47,93.33,0.241
15.49,93.51,0.242
15.51,93.70,0.242
15.53,93.88,0.242
15.55,94.06,0.242
15.57,94.25,0.242
15.58,94.43,0.242
15.60,94.61,0.242
15.62,94.80,0.243
15.64,94.98,0.243
15.66,95.17,0.243
15.68,95.35,0.243
15.69,95.53,0.243
15.71,95.72,0.243
15.73,95.90,0.243
15.75,96.08,0.244
15.77,96.27,0.244
15.78,96.45,0.244
15.80,96.63,0.244
15.82,96.82,0.244
15.84,97.00,0.244
15.86,97.18,0.245
15.88,97.37,0.245
15.90,97.55,0.245
15.91,97.73,0.245
15.93,97.92,0.245
15.95,98.10,0.245
15.97,98.28,0.246
15.99,98.47,0.246
16.00,98.65,0.246
16.02,98.84,0.246
16.04,99.02,0.246
16.06,99.20,0.246
16.08,99.39,0.247
16.10,99.57,0.247
16.12,99.75,0.247
16.13,99.93,0.247
16.15,100.12,0.247
16.17,100.30,0.247
16.19,100.49,0.247
16.21,100.67,0.248
16.23,100.85,0.248
16.24,101.04,0.248
16.26,101.22,0.248
16.28,101.40,0.248
16.30,101.59,0.248
16.32,101.77,0.249
16.33,101.95,0.249
16.35,102.14,0.249
16.37,102.32,0.249
16.39,102.50,0.249
16.41,102.69,0.249
16.43,102.87,0.250
16.45,103.05,0.250
16.46,103.24,0.250
16.48,103.42,0.250
16.50,103.61,0.250
16.52,103.79,0.250
16.54,103.97,0.251
16.55,104.16,0.251
16.57,104.34,0.251
16.59,104.52,0.251
16.61,104.71,0.251
16.63,104.89,0.251
16.65,105.07,0.252
16.67,105.26,0.252
16.68,105.44,0.252
16.70,105.62,0.252
16.72,105.81,0.252
16.74,105.99,0.252
16.76,106.17,0.252
16.78,106.36,0.253
16.79,106.54,0.253
16.81,106.72,0.253
16.83,106.91,0.253
16.85,107.09,0.253
16.87,107.27,0.253
16.88,107.46,0.253
16.90,107.64,0.254
16.92,107.82,0.254
16.94,108.01,0.254
16.96,108.19,0.254
16.98,108.37,0.254
17.00,108.56,0.254
17.01,108.74,0.254
17.03,108.92,0.255
17.05,109.11,0.255
17.07,109.29,0.255
17.09,109.47,0.255
17.11,109.66,0.255
17.12,109.84,0.255
17.14,110.02,0.255
17.16,110.21,0.256
17.18,110.39,0.256
17.20,110.58,0.256
17.22,110.76,0.256
17.23,110.94,0.256
17.25,111.13,0.256
17.27,111.31,0.256
17.29,111.49,0.257
17.31,111.68,0.257
17.33,111.86,0.257
17.34,112.04,0.257
17.36,112.23,0.257
17.38,112.41,0.257
17.40,112.59,0.258
17.42,112.78,0.258
17.43,112.96,0.258
17.45,113.14,0.258
17.47,113.33,0.258
17.49,113.51,0.258
17.51,113.69,0.258
17.53,113.88,0.258
17.54,114.06,0.259
17.56,114.24,0.259
17.58,114.43,0.259
17.60,114.61,0.259
17.62,114.80,0.259
17.64,114.98,0.259
17.66,115.16,0.259
17.67,115.35,0.260
17.69,115.53,0.260
17.71,115.71,0.260
17.73,115.90,0.260
17.75,116.08,0.260
17.77,116.26,0.260
17.78,116.45,0.260
17.80,116.63,0.260
17.82,116.81,0.261
17.84,117.00,0.261
17.86,117.18,0.261
17.88,117.36,0.261
17.89,117.55,0.261
17.91,117.73,0.261
17.93,117.91,0.261
17.95,118.10,0.261
17.97,118.28,0.262
17.98,118.46,0.262
18.00,118.65,0.262
18.02,118.83,0.262
18.04,119.01,0.262
18.06,119.20,0.262
18.08,119.38,0.262
18.09,119.56,0.262
18.11,119.75,0.263
18.13,119.93,0.263
18.15,120.12,0.263
18.17,120.30,0.263
18.19,120.48,0.263
18.21,120.67,0.263
18.22,120.85,0.263
18.24,121.03,0.263
18.26,121.22,0.264
18.28,121.40,0.264
18.30,121.58,0.264
18.32,121.77,0.264
18.33,121.95,0.264
18.35,122.13,0.264
18.37,122.32,0.265
18.39,122.50,0.265
18.41,122.69,0.265
18.43,122.87,0.265
18.44,123.05,0.265
18.46,123.23,0.265
18.48,123.42,0.265
18.50,123.60,0.265
18.52,123.78,0.266
18.53,123.97,0.266
18.55,124.15,0.266
18.57,124.33,0.266
18.59,124.52,0.266
18.61,124.70,0.266
18.63,124.88,0.266
18.64,125.07,0.266
18.66,125.25,0.266
18.68,125.43,0.267
18.70,125.62,0.267
18.72,125.80,0.267
18.74,125.99,0.267
18.76,126.17,0.267
18.77,126.35,0.267
18.79,126.54,0.267
18.81,126.72,0.268
18.83,126.90,0.268
18.85,127.09,0.268
18.87,127.27,0.268
18.88,127.45,0.268
18.90,127.64,0.268
18.92,127.82,0.268
18.94,128.00,0.268
18.96,128.19,0.269
18.98,128.37,0.269
18.99,128.55,0.269
19.01,128.74,0.269
19.03,128.92,0.269
19.05,129.10,0.269
19.07,129.29,0.269
19.08,129.47,0.269
19.10,129.65,0.269
19.12,129.84,0.270
19.14,130.02,0.270
19.16,130.20,0.270
19.18,130.39,0.270
19.19,130.57,0.270
19.21,130.75,0.270
19.23,130.94,0.270
19.25,131.12,0.270
19.27,131.30,0.270
19.29,131.49,0.271
19.31,131.67,0.271
19.32,131.86,0.271
19.34,132.04,0.271
19.36,132.22,0.271
19.38,132.41,0.271
19.40,132.59,0.271
19.42,132.77,0.271
19.43,132.96,0.271
19.45,133.14,0.272
19.47,133.32,0.272
19.49,133.51,0.272
19.51,133.69,0.272
19.53,133.87,0.272
19.54,134.06,0.272
19.56,134.24,0.272
19.58,134.42,0.272
19.60,134.61,0.272
19.62,134.79,0.272
19.63,134.98,0.273
19.65,135.16,0.273
19.67,135.34,0.273
19.69,135.53,0.273
19.71,135.71,0.273
19.73,135.89,0.273
19.74,136.08,0.273
19.76,136.26,0.273
19.78,136.44,0.273
19.80,136.63,0.273
19.82,136.81,0.273
19.84,136.99,0.274
19.86,137.18,0.274
19.87,137.36,0.274
19.89,137.54,0.274
19.91,137.73,0.274
19.93,137.91,0.274
19.95,138.09,0.274
19.97,138.28,0.274
19.98,138.46,0.274
20.00,138.64,0.274
20.02,138.83,0.274
20.04,139.01,0.274
20.06,139.19,0.275
20.08,139.38,0.275
20.09,139.56,0.275
20.11,139.74,0.275
20.13,139.93,0.275
20.15,140.11,0.275
20.17,140.29,0.275
20.18,140.48,0.275
20.20,140.66,0.276
20.22,140.84,0.276
20.24,141.03,0.276
20.26,141.21,0.276
20.28,141.39,0.276
20.29,141.58,0.276
20.31,141.76,0.276
20.33,141.94,0.276
20.35,142.13,0.276
20.37,142.31,0.276
20.39,142.50,0.277
20.41,142.68,0.277
20.42,142.86,0.277
20.44,143.05,0.277
20.46,143.23,0.277
20.48,143.41,0.277
20.50,143.60,0.277
20.52,143.78,0.277
20.53,143.96,0.277
20.55,144.15,0.277
20.57,144.33,0.277
20.59,144.51,0.278
20.61,144.70,0.278
20.63,144.88,0.278
20.64,145.06,0.278
20.66,145.25,0.278
20.68,145.43,0.278
20.70,145.62,0.278
20.72,145.80,0.278
20.73,145.98,0.278
20.75,146.16,0.278
20.77,146.35,0.278
20.79,146.53,0.278
20.81,146.72,0.278
20.83,146.90,0.279
20.84,147.08,0.279
20.86,147.27,0.279
20.88,147.45,0.279
20.90,147.63,0.279
20.92,147.82,0.279
20.94,148.00,0.279
20.96,148.18,0.279
20.97,148.37,0.279
20.99,148.55,0.279
21.01,148.73,0.280
21.03,148.92,0.280
21.05,149.10,0.280
21.07,149.28,0.280
21.08,149.47,0.280
21.10,149.65,0.280
21.12,149.84,0.280
21.14,150.02,0.280
21.16,150.20,0.280
21.18,150.38,0.280
21.19,150.57,0.280
21.21,150.75,0.281
21.23,150.93,0.281
21.25,151.12,0.281
21.27,151.30,0.281
21.28,151.48,0.281
21.30,151.67,0.281
21.32,151.85,0.281
21.34,152.03,0.281
21.36,152.22,0.281
21.38,152.40,0.281
21.39,152.58,0.281
21.41,152.77,0.282
21.43,152.95,0.282
21.45,153.14,0.282
21.47,153.32,0.282
21.49,153.50,0.282
21.51,153.69,0.282
21.52,153.87,0.282
21.54,154.05,0.282
21.56,154.24,0.282
21.58,154.42,0.282
21.60,154.60,0.283
21.62,154.79,0.283
21.63,154.97,0.283
21.65,155.15,0.283
21.67,155.34,0.283
21.69,155.52,0.283
21.71,155.70,0.283
21.73,155.89,0.283
21.74,156.07,0.283
21.76,156.25,0.283
21.78,156.44,0.283
21.80,156.62,0.283
21.82,156.80,0.284
21.83,156.99,0.284
21.85,157.17,0.284
21.87,157.35,0.284
21.89,157.54,0.284
21.91,157.72,0.284
21.93,157.90,0.284
21.94,158.09,0.284
21.96,158.27,0.284
21.98,158.45,0.284
22.00,158.64,0.284
22.02,158.82,0.284
22.04,159.01,0.284
22.06,159.19,0.284
22.07,159.37,0.285
22.09,159.56,0.285
22.11,159.74,0.285
22.13,159.92,0.285
22.15,160.11,0.285
22.17,160.29,0.285
22.18,160.47,0.285
22.20,160.66,0.285
22.22,160.84,0.285
22.24,161.02,0.285
22.26,161.21,0.285
22.28,161.39,0.286
22.29,161.57,0.286
22.31,161.76,0.286
22.33,161.94,0.286
22.35,162.12,0.286
22.37,162.31,0.286
22.38,162.49,0.286
22.40,162.67,0.286
22.42,162.86,0.286
22.44,163.04,0.286
22.46,163.22,0.286
22.48,163.41,0.287
22.49,163.59,0.287
22.51,163.77,0.287
22.53,163.96,0.287
22.55,164.14,0.287
22.57,164.32,0.287
22.59,164.51,0.287
22.61,164.69,0.287
22.62,164.87,0.287
22.64,165.06,0.287
22.66,165.24,0.287
22.68,165.43,0.287
22.70,165.61,0.288
22.72,165.79,0.288
22.73,165.97,0.288
22.75,166.16,0.288
22.77,166.34,0.288
22.79,166.53,0.288
22.81,166.71,0.288
22.83,166.89,0.288
22.84,167.08,0.288
22.86,167.26,0.288
22.88,167.44,0.289
22.90,167.63,0.289
22.92,167.81,0.289
22.93,167.99,0.289
22.95,168.18,0.289
22.97,168.36,0.289
22.99,168.54,0.289
23.01,168.73,0.289
23.03,168.91,0.289
23.04,169.09,0.289
23.06,169.28,0.289
23.08,169.46,0.289
23.10,169.64,0.289
23.12,169.83,0.290
23.14,170.01,0.290
23.16,170.19,0.290
23.17,170.38,0.290
23.19,170.56,0.290
23.21,170.75,0.290
23.23,170.93,0.290
23.25,171.11,0.290
23.27,171.30,0.290
23.28,171.48,0.290
23.30,171.66,0.290
23.32,171.85,0.291
23.34,172.03,0.291
23.36,172.21,0.291
23.38,172.40,0.291
23.39,172.58,0.291
23.41,172.76,0.291
23.43,172.95,0.291
23.45,173.13,0.291
23.47,173.31,0.291
23.48,173.50,0.291
23.50,173.68,0.292
23.52,173.86,0.292
23.54,174.05,0.292
23.56,174.23,0.292
23.58,174.42,0.292
23.59,174.60,0.292
23.61,174.78,0.292
23.63,174.96,0.292
23.65,175.15,0.292
23.67,175.33,0.292
23.69,175.52,0.292
23.71,175.70,0.293
23.72,175.88,0.293
23.74,176.07,0.293
23.76,176.25,0.293
23.78,176.43,0.293
23.80,176.61,0.293
23.82,176.80,0.293
23.83,176.98,0.293
23.85,177.17,0.293
23.87,177.35,0.293
23.89,177.53,0.293
23.91,177.72,0.293
23.93,177.90,0.294
23.94,178.08,0.294
23.96,178.27,0.294
23.98,178.45,0.294
24.00,178.63,0.294
24.02,178.82,0.294
24.03,179.00,0.294
24.05,179.18,0.294
24.07,179.37,0.294
24.09,179.55,0.295
24.11,179.73,0.295
24.13,179.92,0.295
24.14,180.10,0.295
24.16,180.28,0.295
24.18,180.47,0.295
24.20,180.65,0.295
24.22,180.83,0.295
24.24,181.02,0.295
24.26,181.20,0.296
24.27,181.38,0.296
24.29,181.57,0.296
24.31,181.75,0.296
24.33,181.93,0.296
24.35,182.12,0.296
24.37,182.30,0.296
24.38,182.48,0.296
24.40,182.67,0.297
24.42,182.85,0.297
24.44,183.03,0.297
24.46,183.22,0.297
24.48,183.40,0.297
24.49,183.59,0.297
24.51,183.77,0.297
24.53,183.95,0.298
24.55,184.13,0.298
24.57,184.32,0.298
24.58,184.50,0.298
24.60,184.68,0.298
24.62,184.87,0.298
24.64,185.05,0.298
24.66,185.23,0.298
24.68,185.42,0.299
24.69,185.60,0.299
24.71,185.79,0.299
24.73,185.97,0.299
24.75,186.15,0.299
24.77,186.34,0.299
24.79,186.52,0.299
24.81,186.70,0.300
24.82,186.89,0.300
24.84,187.07,0.300
24.86,187.25,0.300
24.88,187.44,0.300
24.90,187.62,0.300
24.92,187.80,0.300
24.93,187.99,0.301
24.95,188.17,0.301
24.97,188.35,0.301
24.99,188.54,0.301
25.01,188.72,0.301
25.03,188.90,0.301
25.04,189.09,0.301
25.06,189.27,0.301
25.08,189.45,0.302
25.10,189.64,0.302
25.12,189.82,0.302
25.13,190.00,0.302
25.15,190.19,0.302
25.17,190.37,0.302
25.19,190.55,0.302
25.21,190.74,0.302
25.23,190.92,0.302
25.24,191.10,0.303
25.26,191.29,0.303
25.28,191.47,0.303
25.30,191.65,0.303
25.32,191.84,0.303
25.34,192.02,0.303
25.36,192.20,0.303
25.37,192.39,0.303
25.39,192.57,0.303
25.41,192.75,0.304
25.43,192.94,0.304
25.45,193.12,0.304
25.47,193.30,0.304
25.48,193.49,0.304
25.50,193.67,0.304
25.52,193.85,0.304
25.54,194.04,0.304
25.56,194.22,0.304
25.58,194.40,0.305
25.59,194.59,0.305
25.61,194.77,0.305
25.63,194.96,0.305
25.65,195.14,0.305
25.67,195.32,0.305
25.68,195.51,0.305
25.70,195.69,0.305
25.72,195.87,0.306
25.74,196.06,0.306
25.76,196.24,0.306
25.78,196.42,0.306
25.79,196.61,0.306
25.81,196.79,0.306
25.83,196.97,0.306
25.85,197.16,0.306
25.87,197.34,0.306
25.89,197.52,0.306
25.91,197.71,0.307
25.92,197.89,0.307
25.94,198.07,
25.96,198.26,
25.98,198.44,
25.99,,

[step]
Ramp 10.00 °C/min to -60.00 °C
Time,Temperature,Heat Flow (Normalized)
min,°C,W/g
26.99,200.08,-0.046
27.01,200.08,-0.046
27.03,200.08,-0.046
27.05,200.07,-0.049
27.07,200.05,-0.063
27.08,200.01,-0.083
27.10,199.95,-0.109
27.12,199.87,-0.141
27.14,199.77,-0.176
27.16,199.65,-0.212
27.18,199.52,-0.244
27.19,199.37,-0.272
27.21,199.22,-0.295
27.23,199.07,-0.315
27.25,198.91,-0.330
27.27,198.74,-0.344
27.29,198.57,-0.354
27.31,198.40,-0.362
27.32,198.23,-0.368
27.34,198.06,-0.374
27.36,197.88,-0.378
27.38,197.71,-0.382
27.40,197.53,-0.384
27.42,197.36,-0.387
27.43,197.18,-0.390
27.45,197.00,-0.391
27.47,196.82,-0.392
27.49,196.64,-0.393
27.51,196.46,-0.394
27.53,196.28,-0.394
27.54,196.10,-0.395
27.56,195.92,-0.395
27.58,195.74,-0.396
27.60,195.56,-0.396
27.62,195.38,-0.396
27.63,195.20,-0.396
27.65,195.02,-0.396
27.67,194.84,-0.397
27.69,194.65,-0.397
27.71,194.47,-0.397
27.73,194.29,-0.397
27.74,194.11,-0.397
27.76,193.93,-0.397
27.78,193.75,-0.397
27.80,193.57,-0.398
27.82,193.38,-0.398
27.84,193.20,-0.398
27.86,193.02,-0.398
27.87,192.84,-0.398
27.89,192.66,-0.398
27.91,192.47,-0.398
27.93,192.29,-0.398
27.95,192.11,-0.398
27.97,191.93,-0.398
27.98,191.75,-0.398
28.00,191.56,-0.398
28.02,191.38,-0.398
28.04,191.20,-0.398
28.06,191.02,-0.398
28.08,190.84,-0.398
28.09,190.65,-0.398
28.11,190.47,-0.397
28.13,190.29,-0.397
28.15,190.11,-0.397
28.17,189.92,-0.397
28.18,189.74,-0.397
28.20,189.56,-0.397
28.22,189.37,-0.397
28.24,189.19,-0.397
28.26,189.01,-0.397
28.28,188.83,-0.397
28.29,188.64,-0.396
28.31,188.46,-0.396
28.33,188.28,-0.396
28.35,188.09,-0.396
28.37,187.91,-0.396
28.39,187.73,-0.396
28.41,187.55,-0.395
28.42,187.36,-0.395
28.44,187.18,-0.395
28.46,187.00,-0.395
28.48,186.81,-0.395
28.50,186.63,-0.395
28.52,186.45,-0.394
28.53,186.27,-0.394
28.55,186.08,-0.394
28.57,185.90,-0.394
28.59,185.72,-0.394
28.61,185.54,-0.394
28.63,185.35,-0.393
28.64,185.17,-0.393
28.66,184.99,-0.393
28.68,184.80,-0.393
28.70,184.62,-0.393
28.72,184.44,-0.392
28.73,184.25,-0.392
28.75,184.07,-0.392
28.77,183.89,-0.392
28.79,183.70,-0.392
28.81,183.52,-0.391
28.83,183.34,-0.391
28.84,183.16,-0.391
28.86,182.97,-0.391
28.88,182.79,-0.391
28.90,182.61,-0.390
28.92,182.42,-0.390
28.94,182.24,-0.390
28.96,182.06,-0.390
28.97,181.87,-0.390
28.99,181.69,-0.389
29.01,181.51,-0.389
29.03,181.32,-0.389
29.05,181.14,-0.389
29.07,180.96,-0.389
29.08,180.78,-0.388
29.10,180.59,-0.388
29.12,180.41,-0.388
29.14,180.23,-0.388
29.16,180.04,-0.388
29.18,179.86,-0.387
29.19,179.68,-0.387
29.21,179.49,-0.387
29.23,179.31,-0.387
29.25,179.13,-0.387
29.27,178.94,-0.386
29.28,178.76,-0.386
29.30,178.58,-0.386
29.32,178.40,-0.386
29.34,178.21,-0.386
29.36,178.03,-0.385
29.38,177.85,-0.385
29.39,177.66,-0.385
29.41,177.48,-0.385
29.43,177.30,-0.385
29.45,177.11,-0.384
29.47,176.93,-0.384
29.49,176.75,-0.384
29.51,176.56,-0.384
29.52,176.38,-0.384
29.54,176.20,-0.384
29.56,176.01,-0.383
29.58,175.83,-0.383
29.60,175.65,-0.383
29.62,175.46,-0.383
29.63,175.28,-0.382
29.65,175.10,-0.382
29.67,174.92,-0.382
29.69,174.73,-0.382
29.71,174.55,-0.381
29.73,174.37,-0.381
29.74,174.18,-0.381
29.76,174.00,-0.381
29.78,173.82,-0.381
29.80,173.63,-0.381
29.82,173.45,-0.380
29.83,173.27,-0.380
29.85,173.09,-0.380
29.87,172.90,-0.380
29.89,172.72,-0.380
29.91,172.53,-0.379
29.93,172.35,-0.379
29.94,172.17,-0.379
29.96,171.98,-0.379
29.98,171.80,-0.379
30.00,171.62,-0.379
30.02,171.43,-0.379
30.04,171.25,-0.378
30.06,171.07,-0.378
30.07,170.89,-0.378
30.09,170.70,-0.378
30.11,170.52,-0.378
30.13,170.34,-0.377
30.15,170.15,-0.377
30.17,169.97,-0.377
30.18,169.79,-0.377
30.20,169.61,-0.377
30.22,169.42,-0.376
30.24,169.24,-0.376
30.26,169.05,-0.376
30.28,168.87,-0.376
30.29,168.69,-0.376
30.31,168.51,-0.375
30.33,168.32,-0.375
30.35,168.14,-0.375
30.37,167.96,-0.375
30.38,167.77,-0.375
30.40,167.59,-0.375
30.42,167.41,-0.374
30.44,167.22,-0.374
30.46,167.04,-0.374
30.48,166.86,-0.374
30.49,166.67,-0.374
30.51,166.49,-0.374
30.53,166.31,-0.374
30.55,166.12,-0.373
30.57,165.94,-0.373
30.59,165.76,-0.373
30.61,165.58,-0.373
30.62,165.39,-0.372
30.64,165.21,-0.372
30.66,165.03,-0.372
30.68,164.84,-0.372
30.70,164.66,-0.372
30.72,164.48,-0.372
30.73,164.29,-0.372
30.75,164.11,-0.372
30.77,163.93,-0.371
30.79,163.74,-0.371
30.81,163.56,-0.371
30.83,163.38,-0.371
30.84,163.19,-0.371
30.86,163.01,-0.371
30.88,162.83,-0.371
30.90,162.65,-0.370
30.92,162.46,-0.370
30.93,162.28,-0.370
30.95,162.10,-0.370
30.97,161.91,-0.370
30.99,161.73,-0.370
31.01,161.55,-0.370
31.03,161.36,-0.369
31.04,161.18,-0.369
31.06,161.00,-0.369
31.08,160.81,-0.369
31.10,160.63,-0.369
31.12,160.45,-0.369
31.14,160.26,-0.368
31.16,160.08,-0.368
31.17,159.90,-0.368
31.19,159.71,-0.368
31.21,159.53,-0.368
31.23,159.35,-0.368
31.25,159.17,-0.368
31.27,158.98,-0.368
31.28,158.80,-0.367
31.30,158.62,-0.367
31.32,158.43,-0.367
31.34,158.25,-0.367
31.36,158.07,-0.367
31.38,157.88,-0.367
31.39,157.70,-0.367
31.41,157.52,-0.367
31.43,157.33,-0.366
31.45,157.15,-0.366
31.47,156.97,-0.366
31.48,156.78,-0.366
31.50,156.60,-0.366
31.52,156.42,-0.366
31.54,156.23,-0.366
31.56,156.05,-0.365
31.58,155.87,-0.365
31.59,155.69,-0.365
31.61,155.50,-0.365
31.63,155.32,-0.365
31.65,155.14,-0.365
31.67,154.95,-0.365
31.69,154.77,-0.365
31.71,154.59,-0.364
31.72,154.40,-0.364
31.74,154.22,-0.364
31.76,154.04,-0.364
31.78,153.85,-0.364
31.80,153.67,-0.364
31.82,153.49,-0.364
31.83,153.30,-0.364
31.85,153.12,-0.364
31.87,152.94,-0.363
31.89,152.76,-0.363
31.91,152.57,-0.363
31.93,152.39,-0.363
31.94,152.21,-0.363
31.96,152.02,-0.363
31.98,151.84,-0.363
32.00,151.66,-0.362
32.02,151.47,-0.362
32.03,151.29,-0.362
32.05,151.11,-0.362
32.07,150.92,-0.362
32.09,150.74,-0.362
32.11,150.56,-0.362
32.13,150.37,-0.362
32.14,150.19,-0.361
32.16,150.01,-0.361
32.18,149.82,-0.361
32.20,149.64,-0.361
32.22,149.46,-0.361
32.24,149.28,-0.361
32.26,149.09,-0.361
32.27,148.91,-0.360
32.29,148.73,-0.360
32.31,148.54,-0.360
32.33,148.36,-0.360
32.35,148.18,-0.360
32.37,147.99,-0.360
32.38,147.81,-0.360
32.40,147.63,-0.360
32.42,147.44,-0.359
32.44,147.26,-0.359
32.46,147.08,-0.359
32.48,146.90,-0.359
32.49,146.71,-0.359
32.51,146.53,-0.359
32.53,146.34,-0.359
32.55,146.16,-0.359
32.57,145.98,-0.358
32.58,145.80,-0.358
32.60,145.61,-0.358
32.62,145.43,-0.358
32.64,145.25,-0.358
32.66,145.06,-0.358
32.68,144.88,-0.358
32.69,144.70,-0.358
32.71,144.51,-0.357
32.73,144.33,-0.357
32.75,144.15,-0.357
32.77,143.96,-0.357
32.79,143.78,-0.357
32.81,143.60,-0.357
32.82,143.42,-0.357
32.84,143.23,-0.356
32.86,143.05,-0.356
32.88,142.87,-0.356
32.90,142.68,-0.356
32.92,142.50,-0.356
32.93,142.32,-0.356
32.95,142.13,-0.356
32.97,141.95,-0.356
32.99,141.77,-0.355
33.01,141.58,-0.355
33.03,141.40,-0.355
33.04,141.22,-0.355
33.06,141.03,-0.355
33.08,140.85,-0.355
33.10,140.67,-0.355
33.12,140.49,-0.355
33.13,140.30,-0.354
33.15,140.12,-0.354
33.17,139.94,-0.354
33.19,139.75,-0.354
33.21,139.57,-0.354
33.23,139.39,-0.354
33.24,139.20,-0.354
33.26,139.02,-0.353
33.28,138.84,-0.353
33.30,138.65,-0.353
33.32,138.47,-0.353
33.34,138.29,-0.353
33.36,138.10,-0.353
33.37,137.92,-0.353
33.39,137.74,-0.352
33.41,137.56,-0.352
33.43,137.37,-0.352
33.45,137.19,-0.352
33.47,137.01,-0.352
33.48,136.82,-0.352
33.50,136.64,-0.352
33.52,136.46,-0.352
33.54,136.27,-0.351
33.56,136.09,-0.351
33.58,135.91,-0.351
33.59,135.72,-0.351
33.61,135.54,-0.351
33.63,135.36,-0.351
33.65,135.17,-0.351
33.67,134.99,-0.351
33.68,134.81,-0.351
33.70,134.62,-0.351
33.72,134.44,-0.350
33.74,134.26,-0.350
33.76,134.08,-0.350
33.78,133.89,-0.350
33.79,133.71,-0.350
33.81,133.53,-0.350
33.83,133.34,-0.350
33.85,133.16,-0.350
33.87,132.98,-0.349
33.89,132.79,-0.349
33.91,132.61,-0.349
33.92,132.43,-0.349
33.94,132.24,-0.349
33.96,132.06,-0.349
33.98,131.88,-0.349
34.00,131.69,-0.348
34.02,131.51,-0.348
34.03,131.33,-0.348
34.05,131.14,-0.348
34.07,130.96,-0.348
34.09,130.78,-0.348
34.11,130.59,-0.348
34.13,130.41,-0.348
34.14,130.23,-0.347
34.16,130.05,-0.347
34.18,129.86,-0.347
34.20,129.68,-0.347
34.22,129.50,-0.347
34.24,129.31,-0.347
34.25,129.13,-0.347
34.27,128.95,-0.347
34.29,128.76,-0.346
34.31,128.58,-0.346
34.33,128.40,-0.346
[...]
115.21,10.64,0.197
115.23,10.82,0.197
115.25,11.00,0.197
115.27,11.19,0.198
115.29,11.37,0.198
115.31,11.56,0.198
115.33,11.74,0.198
115.34,11.92,0.198
115.36,12.11,0.198
115.38,12.29,0.198
115.40,12.47,0.198
115.42,12.66,0.198
115.44,12.84,0.199
115.45,13.02,0.199
115.47,13.21,0.199
115.49,13.39,0.199
115.51,13.57,0.199
115.53,13.76,0.199
115.55,13.94,0.199
115.56,14.12,0.199
115.58,14.31,0.200
115.60,14.49,0.200
115.62,14.67,0.200
115.64,14.86,0.200
115.65,15.04,0.200
115.67,15.23,0.200
115.69,15.41,0.200
115.71,15.59,0.201
115.73,15.78,0.201
115.75,15.96,0.201
115.76,16.14,0.201
115.78,16.33,0.201
115.80,16.51,0.201
115.82,16.69,0.201
115.84,16.88,0.202
115.86,17.06,0.202
115.88,17.24,0.202
115.89,17.43,0.202
115.91,17.61,0.202
115.93,17.79,0.202
115.95,17.98,0.202
115.97,18.16,0.202
115.99,18.35,0.202
116.00,18.53,0.203
116.02,18.71,0.203
116.04,18.90,0.203
116.06,19.08,0.203
116.08,19.26,0.203
116.10,19.45,0.203
116.11,19.63,0.203
116.13,19.81,0.203
116.15,20.00,0.204
116.17,20.18,0.204
116.19,20.36,0.204
116.20,20.55,0.204
116.22,20.73,0.204
116.24,20.91,0.205
116.26,21.10,0.205
116.28,21.28,0.205
116.30,21.46,0.205
116.31,21.65,0.205
116.33,21.83,0.205
116.35,22.02,0.205
116.37,22.20,0.205
116.39,22.38,0.206
116.41,22.57,0.206
116.43,22.75,0.206
116.44,22.93,0.206
116.46,23.12,0.206
116.48,23.30,0.206
116.50,23.48,0.206
116.52,23.67,0.207
116.54,23.85,0.207
116.55,24.03,0.207
116.57,24.22,0.207
116.59,24.40,0.207
116.61,24.58,0.207
116.63,24.77,0.207
116.65,24.95,0.207
116.66,25.13,0.208
116.68,25.32,0.208
116.70,25.50,0.208
116.72,25.69,0.208
116.74,25.87,0.208
116.75,26.05,0.208
116.77,26.24,0.208
116.79,26.42,0.209
116.81,26.60,0.209
116.83,26.79,0.209
116.85,26.97,0.209
116.86,27.15,0.209
116.88,27.34,0.209
116.90,27.52,0.210
116.92,27.70,0.210
116.94,27.89,0.210
116.96,28.07,0.210
116.98,28.25,0.210
116.99,28.44,0.210
117.01,28.62,0.210
117.03,28.80,0.211
117.05,28.99,0.211
117.07,29.17,0.211
117.09,29.36,0.211
117.10,29.54,0.211
117.12,29.72,0.211
117.14,29.91,0.212
117.16,30.09,0.212
117.18,30.27,0.212
117.20,30.46,0.212
117.21,30.64,0.212
117.23,30.82,0.212
117.25,31.01,0.212
117.27,31.19,0.213
117.29,31.37,0.213
117.30,31.56,0.213
117.32,31.74,0.213
117.34,31.93,0.213
117.36,32.11,0.213
117.38,32.29,0.213
117.40,32.48,0.214
117.41,32.66,0.214
117.43,32.84,0.214
117.45,33.03,0.214
117.47,33.21,0.214
117.49,33.39,0.214
117.51,33.58,0.215
117.53,33.76,0.215
117.54,33.94,0.215
117.56,34.13,0.215
117.58,34.31,0.215
117.60,34.49,0.215
117.62,34.68,0.215
117.64,34.86,0.216
117.65,35.04,0.216
117.67,35.23,0.216
117.69,35.41,0.216
117.71,35.59,0.216
117.73,35.78,0.216
117.75,35.96,0.216
117.76,36.15,0.217
117.78,36.33,0.217
117.80,36.51,0.217
117.82,36.70,0.217
117.84,36.88,0.217
117.85,37.06,0.217
117.87,37.25,0.218
117.89,37.43,0.218
117.91,37.61,0.218
117.93,37.80,0.218
117.95,37.98,0.218
117.96,38.16,0.218
117.98,38.35,0.218
118.00,38.53,0.219
118.02,38.71,0.219
118.04,38.90,0.219
118.06,39.08,0.219
118.08,39.26,0.219
118.09,39.45,0.219
118.11,39.63,0.219
118.13,39.82,0.220
118.15,40.00,0.220
118.17,40.18,0.220
118.19,40.37,0.220
118.20,40.55,0.220
118.22,40.73,0.220
118.24,40.92,0.221
118.26,41.10,0.221
118.28,41.28,0.221
118.30,41.47,0.221
118.31,41.65,0.221
118.33,41.83,0.221
118.35,42.02,0.222
118.37,42.20,0.222
118.39,42.38,0.222
118.40,42.57,0.222
118.42,42.75,0.222
118.44,42.94,0.222
118.46,43.12,0.223
118.48,43.30,0.223
118.50,43.49,0.223
118.51,43.67,0.223
118.53,43.85,0.223
118.55,44.04,0.223
118.57,44.22,0.223
118.59,44.40,0.224
118.61,44.59,0.224
118.63,44.77,0.224
118.64,44.95,0.224
118.66,45.14,0.224
118.68,45.32,0.224
118.70,45.50,0.224
118.72,45.69,0.225
118.74,45.87,0.225
118.75,46.05,0.225
118.77,46.24,0.225
118.79,46.42,0.225
118.81,46.60,0.226
118.83,46.79,0.226
118.85,46.97,0.226
118.86,47.16,0.226
118.88,47.34,0.226
118.90,47.52,0.226
118.92,47.71,0.227
118.94,47.89,0.227
118.95,48.07,0.227
118.97,48.26,0.227
118.99,48.44,0.227
119.01,48.62,0.227
119.03,48.81,0.227
119.05,48.99,0.228
119.06,49.17,0.228
119.08,49.36,0.228
119.10,49.54,0.228
119.12,49.73,0.228
119.14,49.91,0.228
119.16,50.09,0.229
119.18,50.28,0.229
119.19,50.46,0.229
119.21,50.64,0.229
119.23,50.83,0.229
119.25,51.01,0.229
119.27,51.19,0.229
119.29,51.38,0.230
119.30,51.56,0.230
119.32,51.74,0.230
119.34,51.93,0.230
119.36,52.11,0.230
119.38,52.29,0.230
119.40,52.48,0.230
119.41,52.66,0.231
119.43,52.84,0.231
119.45,53.03,0.231
119.47,53.21,0.231
119.49,53.39,0.231
119.50,53.58,0.231
119.52,53.76,0.232
119.54,53.95,0.232
119.56,54.13,0.232
119.58,54.31,0.232
119.60,54.50,0.232
119.61,54.68,0.232
119.63,54.86,0.232
119.65,55.05,0.233
119.67,55.23,0.233
119.69,55.41,0.233
119.71,55.60,0.233
119.73,55.78,0.233
119.74,55.96,0.233
119.76,56.15,0.233
119.78,56.33,0.234
119.80,56.51,0.234
119.82,56.70,0.234
119.84,56.88,0.234
119.85,57.06,0.234
119.87,57.25,0.234
119.89,57.43,0.235
119.91,57.62,0.235
119.93,57.80,0.235
119.95,57.98,0.235
119.96,58.17,0.235
119.98,58.35,0.235
120.00,58.53,0.235
120.02,58.72,0.236
120.04,58.90,0.236
120.05,59.08,0.236
120.07,59.27,0.236
120.09,59.45,0.236
120.11,59.63,0.236
120.13,59.82,0.237
120.15,60.00,0.237
120.16,60.18,0.237
120.18,60.37,0.237
120.20,60.55,0.237
120.22,60.74,0.237
120.24,60.92,0.237
120.26,61.10,0.238
120.28,61.28,0.238
120.29,61.47,0.238
120.31,61.65,0.238
120.33,61.84,0.238
120.35,62.02,0.238
120.37,62.20,0.238
120.39,62.39,0.239
120.40,62.57,0.239
120.42,62.75,0.239
120.44,62.94,0.239
120.46,63.12,0.239
120.48,63.30,0.239
120.50,63.49,0.240
120.51,63.67,0.240
120.53,63.85,0.240
120.55,64.04,0.240
120.57,64.22,0.240
120.59,64.40,0.240
120.60,64.59,0.240
120.62,64.77,0.241
120.64,64.95,0.241
120.66,65.14,0.241
120.68,65.32,0.241
120.70,65.51,0.241
120.71,65.69,0.241
120.73,65.87,0.242
120.75,66.05,0.242
120.77,66.24,0.242
120.79,66.42,0.242
120.81,66.61,0.242
120.83,66.79,0.242
120.84,66.97,0.243
120.86,67.16,0.243
120.88,67.34,0.243
120.90,67.52,0.243
120.92,67.71,0.243
120.94,67.89,0.243
120.95,68.07,0.243
120.97,68.26,0.244
120.99,68.44,0.244
121.01,68.62,0.244
121.03,68.81,0.244
121.05,68.99,0.244
121.06,69.17,0.244
121.08,69.36,0.245
121.10,69.54,0.245
121.12,69.73,0.245
121.14,69.91,0.245
121.15,70.09,0.245
121.17,70.27,0.245
121.19,70.46,0.245
121.21,70.64,0.246
121.23,70.83,0.246
121.25,71.01,0.246
121.26,71.19,0.246
121.28,71.37,0.246
121.30,71.56,0.247
121.32,71.74,0.247
121.34,71.93,0.247
121.36,72.11,0.247
121.38,72.29,0.247
121.39,72.48,0.247
121.41,72.66,0.248
121.43,72.84,0.248
121.45,73.03,0.248
121.47,73.21,0.248
121.49,73.40,0.248
121.50,73.58,0.248
121.52,73.76,0.249
121.54,73.95,0.249
121.56,74.13,0.249
121.58,74.31,0.249
121.60,74.49,0.249
121.61,74.68,0.249
121.63,74.86,0.249
121.65,75.05,0.250
121.67,75.23,0.250
121.69,75.41,0.250
121.70,75.60,0.250
121.72,75.78,0.250
121.74,75.96,0.250
121.76,76.15,0.251
121.78,76.33,0.251
121.80,76.51,0.251
121.81,76.70,0.251
121.83,76.88,0.251
121.85,77.06,0.251
121.87,77.25,0.252
121.89,77.43,0.252
121.91,77.61,0.252
121.93,77.80,0.252
121.94,77.98,0.252
121.96,78.16,0.252
121.98,78.35,0.252
122.00,78.53,0.253
122.02,78.71,0.253
122.04,78.90,0.253
122.05,79.08,0.253
122.07,79.27,0.253
122.09,79.45,0.253
122.11,79.63,0.254
122.13,79.82,0.254
122.15,80.00,0.254
122.16,80.18,0.254
122.18,80.37,0.254
122.20,80.55,0.254
122.22,80.73,0.254
122.24,80.92,0.254
122.25,81.10,0.255
122.27,81.28,0.255
122.29,81.47,0.255
122.31,81.65,0.255
122.33,81.83,0.255
122.35,82.02,0.255
122.36,82.20,0.255
122.38,82.39,0.256
122.40,82.57,0.256
122.42,82.75,0.256
122.44,82.94,0.256
122.46,83.12,0.256
122.48,83.30,0.256
122.49,83.49,0.256
122.51,83.67,0.257
122.53,83.86,0.257
122.55,84.04,0.257
122.57,84.22,0.257
122.59,84.41,0.257
122.60,84.59,0.257
122.62,84.77,0.257
122.64,84.96,0.257
122.66,85.14,0.257
122.68,85.32,0.258
122.70,85.51,0.258
122.71,85.69,0.258
122.73,85.87,0.258
122.75,86.06,0.258
122.77,86.24,0.258
122.79,86.42,0.258
122.80,86.61,0.258
122.82,86.79,0.258
122.84,86.98,0.258
122.86,87.16,0.258
122.88,87.34,0.258
122.90,87.53,0.258
122.91,87.71,0.259
122.93,87.89,0.259
122.95,88.08,0.259
122.97,88.26,0.259
122.99,88.44,0.259
123.01,88.62,0.259
123.03,88.81,0.259
123.04,88.99,0.259
123.06,89.17,0.259
123.08,89.36,0.259
123.10,89.54,0.260
123.12,89.72,0.260
123.14,89.91,0.260
123.15,90.09,0.260
123.17,90.27,0.260
123.19,90.46,0.260
123.21,90.64,0.260
123.23,90.82,0.260
123.25,91.01,0.261
123.26,91.19,0.261
123.28,91.38,0.261
123.30,91.56,0.261
123.32,91.74,0.261
123.34,91.93,0.261
123.35,92.11,0.261
123.37,92.29,0.262
123.39,92.48,0.262
123.41,92.66,0.262
123.43,92.84,0.262
123.45,93.03,0.262
123.46,93.21,0.262
123.48,93.39,0.263
123.50,93.58,0.263
123.52,93.76,0.263
123.54,93.94,0.263
123.56,94.13,0.263
123.58,94.31,0.263
123.59,94.50,0.263
123.61,94.68,0.264
123.63,94.86,0.264
123.65,95.05,0.264
123.67,95.23,0.264
123.69,95.41,0.264
123.70,95.60,0.264
123.72,95.78,0.264
123.74,95.96,0.264
123.76,96.15,0.265
123.78,96.33,0.265
123.80,96.51,0.265
123.81,96.70,0.265
123.83,96.88,0.265
123.85,97.06,0.265
123.87,97.25,0.265
123.89,97.43,0.265
123.90,97.62,0.265
123.92,97.80,0.266
123.94,97.98,0.266
123.96,98.16,0.266
123.98,98.35,0.266
124.00,98.53,0.266
124.01,98.71,0.266
124.03,98.90,0.266
124.05,99.08,0.266
124.07,99.26,0.266
124.09,99.45,0.266
124.11,99.63,0.267
124.13,99.81,0.267
124.14,100.00,0.267
124.16,100.18,0.267
124.18,100.37,0.267
124.20,100.55,0.267
124.22,100.73,0.267
124.24,100.92,0.267
124.25,101.10,0.267
124.27,101.28,0.268
124.29,101.47,0.268
124.31,101.65,0.268
124.33,101.84,0.268
124.35,102.02,0.268
124.36,102.20,0.268
124.38,102.39,0.268
124.40,102.57,0.268
124.42,102.75,0.269
124.44,102.94,0.269
124.45,103.12,0.269
124.47,103.30,0.269
124.49,103.49,0.269
124.51,103.67,0.269
124.53,103.85,0.269
124.55,104.04,0.269
124.56,104.22,0.269
124.58,104.40,0.269
124.60,104.59,0.270
124.62,104.77,0.270
124.64,104.95,0.270
124.66,105.14,0.270
124.68,105.32,0.270
124.69,105.50,0.270
124.71,105.69,0.270
124.73,105.87,0.270
124.75,106.06,0.270
124.77,106.24,0.270
124.79,106.42,0.270
124.80,106.60,0.271
124.82,106.79,0.271
124.84,106.97,0.271
124.86,107.15,0.271
124.88,107.34,0.271
124.90,107.52,0.271
124.91,107.71,0.271
124.93,107.89,0.271
124.95,108.07,0.271
124.97,108.26,0.271
124.99,108.44,0.271
125.00,108.62,0.272
125.02,108.81,0.272
125.04,108.99,0.272
125.06,109.17,0.272
125.08,109.36,0.272
125.10,109.54,0.272
125.11,109.72,0.272
125.13,109.91,0.272
125.15,110.09,0.272
125.17,110.28,0.273
125.19,110.46,0.273
125.21,110.64,0.273
125.23,110.82,0.273
125.24,111.01,0.273
125.26,111.19,0.273
125.28,111.37,0.273
125.30,111.56,0.273
125.32,111.74,0.273
125.34,111.92,0.273
125.35,112.11,0.273
125.37,112.29,0.274
125.39,112.48,0.274
125.41,112.66,0.274
125.43,112.84,0.274
125.45,113.03,0.274
125.46,113.21,0.274
125.48,113.39,0.274
125.50,113.58,0.274
125.52,113.76,0.274
125.54,113.94,0.274
125.55,114.13,0.275
125.57,114.31,0.275
125.59,114.49,0.275
125.61,114.68,0.275
125.63,114.86,0.275
125.65,115.04,0.275
125.66,115.23,0.275
125.68,115.41,0.275
125.70,115.59,0.275
125.72,115.78,0.275
125.74,115.96,0.275
125.76,116.14,0.275
125.78,116.33,0.276
125.79,116.51,0.276
125.81,116.70,0.276
125.83,116.88,0.276
125.85,117.06,0.276
125.87,117.25,0.276
125.89,117.43,0.276
125.90,117.61,0.276
125.92,117.80,0.276
125.94,117.98,0.276
125.96,118.16,0.276
125.98,118.35,0.276
126.00,118.53,0.277
126.01,118.71,0.277
126.03,118.90,0.277
126.05,119.08,0.277
126.07,119.26,0.277
126.09,119.45,0.277
126.10,119.63,0.277
126.12,119.82,0.277
126.14,120.00,0.277
126.16,120.18,0.277
126.18,120.37,0.278
126.20,120.55,0.278
126.21,120.73,0.278
126.23,120.92,0.278
126.25,121.10,0.278
126.27,121.28,0.278
126.29,121.47,0.278
126.31,121.65,0.278
126.33,121.83,0.278
126.34,122.02,0.278
126.36,122.20,0.278
126.38,122.38,0.278
126.40,122.57,0.279
126.42,122.75,0.279
126.44,122.93,0.279
126.45,123.12,0.279
126.47,123.30,0.279
126.49,123.48,0.279
126.51,123.67,0.279
126.53,123.85,0.279
126.55,124.03,0.279
126.56,124.22,0.279
126.58,124.40,0.279
126.60,124.58,0.279
126.62,124.77,0.280
126.64,124.95,0.280
126.65,125.13,0.280
126.67,125.32,0.280
126.69,125.50,0.280
126.71,125.69,0.280
126.73,125.87,0.280
126.75,126.05,0.280
126.76,126.24,0.280
126.78,126.42,0.280
126.80,126.60,0.280
126.82,126.79,0.281
126.84,126.97,0.281
126.86,127.15,0.281
126.88,127.34,0.281
126.89,127.52,0.281
126.91,127.70,0.281
126.93,127.89,0.281
126.95,128.07,0.281
126.97,128.25,0.281
126.99,128.44,0.281
127.00,128.62,0.281
127.02,128.80,0.281
127.04,128.99,0.281
127.06,129.17,0.282
127.08,129.35,0.282
127.10,129.54,0.282
127.11,129.72,0.282
127.13,129.90,0.282
127.15,130.09,0.282
127.17,130.27,0.282
127.19,130.46,0.282
127.20,130.64,0.282
127.22,130.82,0.282
127.24,131.01,0.283
127.26,131.19,0.283
127.28,131.37,0.283
127.30,131.56,0.283
127.31,131.74,0.283
127.33,131.92,0.283
127.35,132.11,0.283
127.37,132.29,0.283
127.39,132.47,0.283
127.41,132.66,0.283
127.43,132.84,0.283
127.44,133.02,0.283
127.46,133.21,0.283
127.48,133.39,0.283
127.50,133.58,0.284
127.52,133.76,0.284
127.54,133.94,0.284
127.55,134.12,0.284
127.57,134.31,0.284
127.59,134.49,0.284
127.61,134.68,0.284
127.63,134.86,0.284
127.65,135.04,0.284
127.66,135.23,0.284
127.68,135.41,0.284
127.70,135.59,0.284
127.72,135.78,0.284
127.74,135.96,0.284
127.75,136.14,0.284
127.77,136.33,0.285
127.79,136.51,0.285
127.81,136.69,0.285
127.83,136.88,0.285
127.85,137.06,0.285
127.86,137.24,0.285
127.88,137.43,0.285
127.90,137.61,0.285
127.92,137.79,0.285
127.94,137.98,0.285
127.96,138.16,0.285
127.98,138.34,0.285
127.99,138.53,0.285
128.01,138.71,0.285
128.03,138.89,0.285
128.05,139.08,0.286
128.07,139.26,0.286
128.09,139.45,0.286
128.10,139.63,0.286
128.12,139.81,0.286
128.14,139.99,0.286
128.16,140.18,0.286
128.18,140.36,0.286
128.20,140.54,0.286
128.21,140.73,0.286
128.23,140.91,0.286
128.25,141.09,0.286
128.27,141.28,0.286
128.29,141.46,0.286
128.30,141.65,0.287
128.32,141.83,0.287
128.34,142.01,0.287
128.36,142.20,0.287
128.38,142.38,0.287
128.40,142.56,0.287
128.41,142.75,0.287
128.43,142.93,0.287
128.45,143.11,0.287
128.47,143.30,0.287
128.49,143.48,0.287
128.51,143.66,0.287
128.53,143.85,0.287
128.54,144.03,0.287
128.56,144.21,0.287
128.58,144.40,0.288
128.60,144.58,0.288
128.62,144.76,0.288
128.64,144.95,0.288
128.65,145.13,0.288
128.67,145.32,0.288
128.69,145.50,0.288
128.71,145.68,0.288
128.73,145.87,0.288
128.75,146.05,0.288
128.76,146.23,0.288
128.78,146.42,0.288
128.80,146.60,0.288
128.82,146.78,0.289
128.84,146.97,0.289
128.85,147.15,0.289
128.87,147.33,0.289
128.89,147.52,0.289
128.91,147.70,0.289
128.93,147.88,0.289
128.95,148.07,0.289
128.96,148.25,0.289
128.98,148.43,0.289
129.00,148.62,0.289
129.02,148.80,0.289
129.04,148.98,0.289
129.06,149.17,0.289
129.08,149.35,0.289
129.09,149.54,0.290
129.11,149.72,0.290
129.13,149.90,0.290
129.15,150.09,0.290
129.17,150.27,0.290
129.19,150.45,0.290
129.20,150.64,0.290
129.22,150.82,0.290
129.24,151.00,0.290
129.26,151.19,0.290
129.28,151.37,0.290
129.30,151.55,0.290
129.31,151.74,0.290
129.33,151.92,0.290
129.35,152.10,0.291
129.37,152.29,0.291
129.39,152.47,0.291
129.40,152.65,0.291
129.42,152.84,0.291
129.44,153.02,0.291
129.46,153.20,0.291
129.48,153.39,0.291
129.50,153.57,0.291
129.51,153.75,0.291
129.53,153.94,0.291
129.55,154.12,0.291
129.57,154.30,0.291
129.59,154.49,0.291
129.61,154.67,0.291
129.63,154.85,0.291
129.64,155.04,0.291
129.66,155.22,0.291
129.68,155.40,0.292
129.70,155.59,0.292
129.72,155.77,0.292
129.74,155.96,0.292
129.75,156.14,0.292
129.77,156.32,0.292
129.79,156.51,0.292
129.81,156.69,0.292
129.83,156.87,0.292
129.85,157.06,0.292
129.86,157.24,0.292
129.88,157.42,0.292
129.90,157.61,0.292
129.92,157.79,0.292
129.94,157.97,0.292
129.95,158.16,0.293
129.97,158.34,0.293
129.99,158.52,0.293
130.01,158.71,0.293
130.03,158.89,0.293
130.05,159.08,0.293
130.06,159.26,0.293
130.08,159.44,0.293
130.10,159.63,0.293
130.12,159.81,0.293
130.14,159.99,0.293
130.16,160.17,0.293
130.18,160.36,0.293
130.19,160.54,0.293
130.21,160.73,0.293
130.23,160.91,0.293
130.25,161.09,0.293
130.27,161.28,0.294
130.29,161.46,0.294
130.30,161.64,0.294
130.32,161.83,0.294
130.34,162.01,0.294
130.36,162.19,0.294
130.38,162.38,0.294
130.40,162.56,0.294
130.41,162.74,0.294
130.43,162.93,0.294
130.45,163.11,0.294
130.47,163.29,0.294
130.49,163.47,0.294
130.50,163.66,0.294
130.52,163.84,0.294
130.54,164.03,0.294
130.56,164.21,0.294
130.58,164.39,0.294
130.60,164.58,0.295
130.61,164.76,0.295
130.63,164.94,0.295
130.65,165.13,0.295
130.67,165.31,0.295
130.69,165.50,0.295
130.71,165.68,0.295
130.73,165.86,0.295
130.74,166.05,0.295
130.76,166.23,0.295
130.78,166.41,0.295
130.80,166.60,0.295
130.82,166.78,0.295
130.84,166.96,0.295
130.85,167.15,0.295
130.87,167.33,0.295
130.89,167.51,0.295
130.91,167.70,0.295
130.93,167.88,0.296
130.95,168.06,0.296
130.96,168.25,0.296
130.98,168.43,0.296
131.00,168.61,0.296
131.02,168.80,0.296
131.04,168.98,0.296
131.05,169.16,0.296
131.07,169.35,0.296
131.09,169.53,0.296
131.11,169.71,0.296
131.13,169.90,0.296
131.15,170.08,0.296
131.16,170.27,0.296
131.18,170.45,0.296
131.20,170.63,0.296
131.22,170.82,0.296
131.24,171.00,0.296
131.26,171.18,0.297
131.28,171.37,0.297
131.29,171.55,0.297
131.31,171.73,0.297
131.33,171.92,0.297
131.35,172.10,0.297
131.37,172.28,0.297
131.39,172.47,0.297
131.40,172.65,0.297
131.42,172.83,0.297
131.44,173.02,0.297
131.46,173.20,0.297
131.48,173.38,0.297
131.50,173.57,0.297
131.51,173.75,0.297
131.53,173.93,0.297
131.55,174.12,0.297
131.57,174.30,0.297
131.59,174.48,0.297
131.60,174.67,0.297
131.62,174.85,0.298
131.64,175.03,0.298
131.66,175.22,0.298
131.68,175.40,0.298
131.70,175.58,0.298
131.71,175.77,0.298
131.73,175.95,0.298
131.75,176.13,0.298
131.77,176.32,0.298
131.79,176.50,0.298
131.81,176.68,0.298
131.83,176.87,0.298
131.84,177.05,0.298
131.86,177.23,0.298
131.88,177.42,0.298
131.90,177.60,0.298
131.92,177.79,0.298
131.94,177.97,0.298
131.95,178.15,0.299
131.97,178.34,0.299
131.99,178.52,0.299
132.01,178.70,0.299
132.03,178.89,0.299
132.05,179.07,0.299
132.06,179.25,0.299
132.08,179.44,0.299
132.10,179.62,0.299
132.12,179.80,0.299
132.14,179.99,0.299
132.15,180.17,0.299
132.17,180.35,0.299
132.19,180.54,0.299
132.21,180.72,0.299
132.23,180.91,0.299
132.25,181.09,0.299
132.26,181.27,0.299
132.28,181.46,0.299
132.30,181.64,0.299
132.32,181.82,0.299
132.34,182.01,0.299
132.36,182.19,0.299
132.38,182.37,0.299
132.39,182.56,0.299
132.41,182.74,0.299
132.43,182.92,0.300
132.45,183.10,0.300
132.47,183.29,0.300
132.49,183.47,0.300
132.50,183.66,0.300
132.52,183.84,0.300
132.54,184.02,0.300
132.56,184.20,0.300
132.58,184.39,0.300
132.60,184.57,0.300
132.61,184.76,0.300
132.63,184.94,0.300
132.65,185.12,0.300
132.67,185.31,0.300
132.69,185.49,0.300
132.70,185.68,0.300
132.72,185.86,0.300
132.74,186.04,0.301
132.76,186.23,0.301
132.78,186.41,0.301
132.80,186.59,0.301
132.81,186.77,0.301
132.83,186.96,0.301
132.85,187.14,0.301
132.87,187.32,0.301
132.89,187.51,0.301
132.91,187.69,0.301
132.93,187.87,0.301
132.94,188.06,0.301
132.96,188.24,0.301
132.98,188.42,0.301
133.00,188.61,0.301
133.02,188.79,0.301
133.04,188.98,0.301
133.05,189.16,0.301
133.07,189.34,0.301
133.09,189.53,0.301
133.11,189.71,0.302
133.13,189.89,0.302
133.15,190.08,0.302
133.16,190.26,0.302
133.18,190.44,0.302
133.20,190.63,0.302
133.22,190.81,0.302
133.24,190.99,0.302
133.25,191.18,0.302
133.27,191.36,0.302
133.29,191.54,0.302
133.31,191.73,0.302
133.33,191.91,0.302
133.35,192.09,0.302
133.36,192.28,0.302
133.38,192.46,0.302
133.40,192.64,0.302
133.42,192.83,0.303
133.44,193.01,0.303
133.46,193.19,0.303
133.48,193.38,0.303
133.49,193.56,0.303
133.51,193.74,0.303
133.53,193.93,0.303
133.55,194.11,0.303
133.57,194.30,0.303
133.59,194.48,0.303
133.60,194.66,0.303
133.62,194.85,0.303
133.64,195.03,0.303
133.66,195.21,0.303
133.68,195.40,0.303
133.70,195.58,0.303
133.71,195.76,0.303
133.73,195.95,0.303
133.75,196.13,0.303
133.77,196.31,0.303
133.79,196.50,0.303
133.80,196.68,0.303
133.82,196.86,0.304
133.84,197.05,0.304
133.86,197.23,0.304
133.88,197.41,0.304
133.90,197.60,0.304
133.91,197.78,0.304
133.93,197.96,
133.95,198.15,
133.97,198.33,
133.99,,