File: DSC/2025_04_18_THCa_n60C_170C_10Cmin_x3.csv
Filename,2025_04_18_THCa_n60C_170C_10Cmin_x3
Instrument name,DSC2A-00468 (192.168.1.100)
Operator,Yarger
rundate,4/19/2025
Sample name,2025_04_18_THCa_n60C_170C_10Cmin_x3
proceduresegments,Data Off ; Equilibrate -60.00 °C; Data On ; Ramp 10.00 °C/min to 170.00 °C; Data Off ; Isothermal 0.1 min; Data On ; Ramp 10.00 °C/min to -60.00 °C; Data Off ; Isothermal 1.0 min; Data On ; Ramp 10.00 °C/min to 170.00 °C; Data Off ; Isothermal 0.1 min; Data On ; Ramp 10.00 °C/min to -60.00 °C; Data Off ; Isothermal 1.0 min; Data On ; Ramp 10.00 °C/min to 30.00 °C
[File Parameters]
Run date,4/19/2025 5:35:33 AM
Trios version,5.1.1.46572
Original File Name,
Current File Name,D:\DSC2500\JYarger\2025_04_18_THCa_n60C_170C_10Cmin_x3.tri
[Procedure]
Procedure Name,THCa_n60_170C_10Cmin_x3
Sample Name,2025_04_18_THCa_n60C_170C_10Cmin_x3
Sample Mass,10.6 mg
Reference Sample Mass,0 mg
Pan Mass,53.05 mg
Pan Number,6
Reference Pan Mass,53.66 mg
Reference Pan Number,46
Pan Type,Tzero Aluminum Hermetic
Comments,Hermetic Sealed Al DSC Consumables Pan/Lids.
Project Name,CA
Operator,Yarger
Test,Custom
Unload Max Temperature,30
Unload Min Temperature,30
Load Max Temperature,30
Load Min Temperature,30
Stop on Gas Flow Error,Yes
[Signal List]
Signal #1,Time (min)
Signal #2,Temperature (°C)
Signal #3,Heat Flow (mW)
Signal #4,Delta T (µV)
Signal #5,Delta Tzero (µV)
Signal #6,Tzero Temperature (°C)
Signal #7,Cell Purge (mL/min)
Signal #8,Heater Temp (°C)
Signal #9,Power Delivered (W)
Signal #10,Reference Junction Temperature (°C)
Signal #11,Flange Temperature (°C)
Signal #12,Heat Flow Phase (rad)
Signal #13,Total Heat Capacity (J/°C)
Signal #14,Heat Capacity (J/°C)
[Configuration]
Company Name,ASU
Instrument Name,DSC2A-00468
Instrument Type,DSC2500
Serial Number,DSC2A-00468
IP,192.168.1.100
Location of Instrument,MRRC
DisplayType,Unknown
Sample Interval ,0.1 s/pt
Selected Heat Flow,T4P
Exotherm Direction,Down
Cell Serial,DRC2-00792
Lid Type,Standard
Cooler,RCS 90
Leave Cooler on at End of Sequence,On
Gas 2,Nitrogen
Gas Selected,Channel 1
Flow Rate,50 mL/min
Secondary Purge,On
Licensed Heat Flow,Heat Flow T4P
Modulation Licensed,Yes
[Versions]
Common IDD Version,1
Cortex Version,VER 2.10.2.31
Driver,5.0.0.6
GDM Version,1.0.3.3
TouchscreenVersion,1.0.0.16145
FEP Version,1.2.1.21
FEP Bootloader,2.0.0.5
AutoSampler Version,2.1.1.26
Auto Sampler Bootloader,2.0.0.5
FCM Version,1.1.0.3
FCM Bootloader,2.0.0.5
[Experiment Logs]
Experiment Log Entry # 1,Data On set to 0
Experiment Log Entry # 3,Equilibrate Segment -60 (C) Started
Experiment Log Entry # 5,Air Cool is off.
Experiment Log Entry # 7,Data On set to 1
Experiment Log Entry # 9,Ramp Segment 10 C/min to 170 Started
Experiment Log Entry # 11,Data On set to 0
Experiment Log Entry # 13,Isothermal Segment 0.1 min started
Experiment Log Entry # 15,Data On set to 1
Experiment Log Entry # 17,Ramp Segment 10 C/min to -60 Started
Experiment Log Entry # 19,Data On set to 0
Experiment Log Entry # 21,Isothermal Segment 1 min started
Experiment Log Entry # 23,Data On set to 1
Experiment Log Entry # 25,Ramp Segment 10 C/min to 170 Started
Experiment Log Entry # 27,Data On set to 0
Experiment Log Entry # 29,Isothermal Segment 0.1 min started
Experiment Log Entry # 31,Data On set to 1
Experiment Log Entry # 33,Ramp Segment 10 C/min to -60 Started
Experiment Log Entry # 35,Data On set to 0
Experiment Log Entry # 37,Isothermal Segment 1 min started
Experiment Log Entry # 39,Data On set to 1
Experiment Log Entry # 41,Ramp Segment 10 C/min to 30 Started
[Method Log]
Method Log Entry # 1,Data Off
Method Log Entry # 2,Equilibrate -60 °C
Method Log Entry # 3,Data On
Method Log Entry # 4,(Ramp 207604) Ramp 10 °C/minute to 170 °C
Method Log Entry # 5,Data Off
Method Log Entry # 6,Isothermal 0.1 minutes
Method Log Entry # 7,Data On
Method Log Entry # 8,(Ramp 207608) Ramp 10 °C/minute to -60 °C
Method Log Entry # 9,Data Off
Method Log Entry # 10,Isothermal 1 minutes
Method Log Entry # 11,Data On
Method Log Entry # 12,(Ramp 207612) Ramp 10 °C/minute to 170 °C
Method Log Entry # 13,Data Off
Method Log Entry # 14,Isothermal 0.1 minutes
Method Log Entry # 15,Data On
Method Log Entry # 16,(Ramp 207616) Ramp 10 °C/minute to -60 °C
Method Log Entry # 17,Data Off
Method Log Entry # 18,Isothermal 1 minutes
Method Log Entry # 19,Data On
Method Log Entry # 20,(Ramp 207620) Ramp 10 °C/minute to 30 °C
Cell Serial,DRC2-00792
[T1 Calibration]
Slope,-0.008529666
Offset,9.636258
Initial Temperature,98.23
GUID,f8bfdadc-4977-4fdf-ba6d-0ba9134940c3
[TZero Calibration]
Date Applied,11/29/2022 4:06:13 PM
Description,From -89.059 °C to 396.009 °C at 20.000°C/min
Gas Type,Nitrogen
Pan Type,None
Source Files 1,C:\Users\yargerlab\Desktop\DSC Data\General\TZero_calibration_11_29_22_2nd(2).tri
Source Files 2,C:\Users\yargerlab\Desktop\DSC Data\General\TZero_calibration_11_29_22_2nd(3).tri
Delta T Offset,13.05235
Delta T Slope,-0.007271007
Delta T0 Offset,-13.69128
Delta T0 Slope,0.06063341
[Temperature Calibration]
Date Applied,11/29/2022 7:12:28 PM
Description,From 106.590 °C to 186.590 °C at 10.000°C/min
Gas Type,Nitrogen
Pan Type,Tzero Aluminum Hermetic
Source Files 1,C:\Users\yargerlab\Desktop\DSC Data\General\Indium(6).tri
Measured 1,157.391
Known 1,156.598
[Cell Constant Calibration]
Date Applied,11/29/2022 7:12:29 PM
Description,From 106.590 °C to 186.590 °C at 10.000°C/min
Gas Type,Nitrogen
Pan Type,Tzero Aluminum Hermetic
Source Files 1,C:\Users\yargerlab\Desktop\DSC Data\General\Indium(6).tri
T4P KCell,1.006051
Onset Slope,63.26126 mW/°C
[Direct Cp Calibration]
Date Applied,11/30/2022 11:04:51 AM
Description,From -79.983 °C to 298.409 °C at 10.000°C/min
Gas Type,Nitrogen
Pan Type,Tzero Aluminum Hermetic
Source Files 1,C:\Users\yargerlab\Desktop\DSC Data\General\Sapphire_Heat_Capacity_11_30_22.tri
[Rev Cp Calibration]
Date Applied,11/30/2022 1:58:51 PM
Description,From -79.996 °C to 292.812 °C at 3.000°C/min
Gas Type,Nitrogen
Pan Type,Tzero Aluminum Hermetic
Source Files 1,C:\Users\yargerlab\Desktop\DSC Data\General\Sapphire_MDSC_Calibration_11_30_22.tri
[step]
Ramp 10.00 °C/min to 170.00 °C
Time,Temperature,Heat Flow (Normalized)
min,°C,W/g
0.00,-59.65,-0.046
0.02,-59.66,-0.045
0.03,-59.67,-0.041
0.05,-59.68,-0.037
0.07,-59.67,-0.031
0.08,-59.65,-0.025
0.10,-59.61,-0.017
0.12,-59.56,-0.007
0.13,-59.49,0.005
0.15,-59.41,0.018
0.17,-59.31,0.032
0.18,-59.20,0.046
0.20,-59.09,0.061
0.22,-58.97,0.073
0.23,-58.84,0.086
0.25,-58.71,0.097
0.27,-58.58,0.107
0.28,-58.44,0.116
0.30,-58.30,0.125
0.32,-58.15,0.131
0.33,-58.01,0.137
0.35,-57.86,0.143
0.37,-57.71,0.148
0.38,-57.56,0.152
0.40,-57.41,0.157
0.42,-57.25,0.160
0.43,-57.10,0.163
0.45,-56.94,0.166
0.47,-56.79,0.168
0.48,-56.63,0.171
0.50,-56.47,0.172
0.52,-56.31,0.173
0.53,-56.15,0.176
0.55,-56.00,0.177
0.57,-55.83,0.178
0.58,-55.68,0.179
0.60,-55.51,0.180
0.62,-55.35,0.181
0.63,-55.19,0.182
0.65,-55.03,0.182
0.67,-54.87,0.183
0.68,-54.71,0.184
0.70,-54.54,0.184
0.72,-54.38,0.184
0.73,-54.22,0.185
0.75,-54.06,0.185
0.77,-53.89,0.186
0.78,-53.73,0.186
0.80,-53.57,0.186
0.82,-53.40,0.186
0.83,-53.24,0.187
0.85,-53.07,0.187
0.87,-52.91,0.187
0.88,-52.75,0.187
0.90,-52.58,0.187
0.92,-52.42,0.188
0.93,-52.26,0.188
0.95,-52.09,0.188
0.97,-51.93,0.188
0.98,-51.76,0.188
1.00,-51.60,0.189
1.02,-51.43,0.189
1.03,-51.27,0.189
1.05,-51.10,0.189
1.07,-50.94,0.189
1.08,-50.77,0.190
1.10,-50.61,0.190
1.12,-50.44,0.190
1.13,-50.28,0.190
1.15,-50.11,0.190
1.17,-49.95,0.191
1.18,-49.78,0.191
1.20,-49.61,0.191
1.22,-49.45,0.191
1.23,-49.28,0.191
1.25,-49.12,0.191
1.27,-48.95,0.191
1.28,-48.79,0.192
1.30,-48.62,0.192
1.32,-48.45,0.192
1.33,-48.29,0.192
1.35,-48.12,0.192
1.37,-47.96,0.192
1.38,-47.79,0.192
1.40,-47.62,0.193
1.42,-47.46,0.193
1.43,-47.29,0.193
1.45,-47.13,0.193
1.47,-46.96,0.193
1.48,-46.79,0.193
1.50,-46.63,0.193
1.52,-46.46,0.193
1.53,-46.29,0.194
1.55,-46.13,0.194
1.57,-45.96,0.194
1.58,-45.80,0.194
1.60,-45.63,0.194
1.62,-45.46,0.194
1.63,-45.29,0.194
1.65,-45.13,0.194
1.67,-44.96,0.194
1.68,-44.80,0.195
1.70,-44.63,0.195
1.72,-44.46,0.195
1.73,-44.30,0.195
1.75,-44.13,0.195
1.77,-43.96,0.195
1.78,-43.80,0.195
1.80,-43.63,0.195
1.82,-43.46,0.195
1.83,-43.30,0.195
1.85,-43.13,0.195
1.87,-42.96,0.195
1.88,-42.80,0.196
1.90,-42.63,0.196
1.92,-42.46,0.196
1.93,-42.30,0.196
1.95,-42.13,0.196
1.97,-41.96,0.196
1.98,-41.80,0.196
2.00,-41.63,0.196
2.02,-41.46,0.196
2.03,-41.30,0.196
2.05,-41.13,0.196
2.07,-40.96,0.196
2.08,-40.79,0.197
2.10,-40.63,0.197
2.12,-40.46,0.197
2.13,-40.30,0.197
2.15,-40.13,0.197
2.17,-39.96,0.197
2.18,-39.79,0.197
2.20,-39.63,0.197
2.22,-39.46,0.197
2.23,-39.30,0.197
2.25,-39.13,0.197
2.27,-38.96,0.197
2.28,-38.79,0.197
2.30,-38.63,0.197
2.32,-38.46,0.197
2.33,-38.30,0.198
2.35,-38.13,0.198
2.37,-37.96,0.198
2.38,-37.80,0.198
2.40,-37.63,0.198
2.42,-37.47,0.198
2.43,-37.30,0.198
2.45,-37.13,0.198
2.47,-36.96,0.198
2.48,-36.80,0.198
2.50,-36.63,0.198
2.52,-36.46,0.198
2.53,-36.30,0.198
2.55,-36.13,0.198
2.57,-35.96,0.198
2.58,-35.80,0.199
2.60,-35.63,0.199
2.62,-35.46,0.199
2.63,-35.30,0.199
2.65,-35.13,0.199
2.67,-34.96,0.199
2.68,-34.79,0.199
2.70,-34.63,0.199
2.72,-34.46,0.199
2.73,-34.29,0.199
2.75,-34.13,0.200
2.77,-33.96,0.200
2.78,-33.79,0.200
2.80,-33.62,0.200
2.82,-33.46,0.200
2.83,-33.29,0.200
2.85,-33.12,0.200
2.87,-32.96,0.200
2.88,-32.79,0.200
2.90,-32.62,0.200
2.92,-32.46,0.201
2.93,-32.29,0.201
2.95,-32.12,0.201
2.97,-31.96,0.201
2.98,-31.79,0.201
3.00,-31.62,0.201
3.02,-31.46,0.201
3.03,-31.29,0.201
3.05,-31.12,0.201
3.07,-30.96,0.201
3.08,-30.79,0.201
3.10,-30.62,0.201
3.12,-30.45,0.201
3.13,-30.29,0.202
3.15,-30.12,0.202
3.17,-29.95,0.202
3.18,-29.79,0.202
3.20,-29.62,0.202
3.22,-29.45,0.202
3.23,-29.29,0.202
3.25,-29.12,0.202
3.27,-28.95,0.202
3.28,-28.78,0.202
3.30,-28.62,0.202
3.32,-28.45,0.202
3.33,-28.28,0.203
3.35,-28.12,0.203
3.37,-27.95,0.203
3.38,-27.78,0.203
3.40,-27.62,0.203
3.42,-27.45,0.203
3.43,-27.28,0.203
3.45,-27.12,0.203
3.47,-26.95,0.203
3.48,-26.78,0.203
3.50,-26.61,0.203
3.52,-26.45,0.203
3.53,-26.28,0.204
3.55,-26.11,0.204
3.57,-25.95,0.204
3.58,-25.78,0.204
3.60,-25.61,0.204
3.62,-25.45,0.204
3.63,-25.28,0.204
3.65,-25.11,0.204
3.67,-24.95,0.204
3.68,-24.78,0.204
3.70,-24.61,0.204
3.72,-24.44,0.205
3.73,-24.28,0.205
3.75,-24.11,0.205
3.77,-23.94,0.205
3.78,-23.78,0.205
3.80,-23.61,0.205
3.82,-23.44,0.205
3.83,-23.28,0.205
3.85,-23.11,0.205
3.87,-22.94,0.205
3.88,-22.78,0.205
3.90,-22.61,0.206
3.92,-22.44,0.206
3.93,-22.27,0.206
3.95,-22.11,0.206
3.97,-21.94,0.206
3.98,-21.77,0.206
4.00,-21.61,0.206
4.02,-21.44,0.206
4.03,-21.27,0.206
4.05,-21.11,0.206
4.07,-20.94,0.207
4.08,-20.77,0.207
4.10,-20.61,0.207
4.12,-20.44,0.207
4.13,-20.27,0.207
4.15,-20.11,0.207
4.17,-19.94,0.207
4.18,-19.77,0.207
4.20,-19.61,0.207
4.22,-19.44,0.207
4.23,-19.27,0.207
4.25,-19.10,0.208
4.27,-18.94,0.208
4.28,-18.77,0.208
4.30,-18.60,0.208
4.32,-18.43,0.208
4.33,-18.27,0.208
4.35,-18.10,0.208
4.37,-17.93,0.208
4.38,-17.77,0.208
4.40,-17.60,0.209
4.42,-17.43,0.209
4.43,-17.27,0.209
4.45,-17.10,0.209
4.47,-16.93,0.209
4.48,-16.77,0.209
4.50,-16.60,0.209
4.52,-16.43,0.209
4.53,-16.27,0.209
4.55,-16.10,0.209
4.57,-15.93,0.210
4.58,-15.76,0.210
4.60,-15.60,0.210
4.62,-15.43,0.210
4.63,-15.27,0.210
4.65,-15.10,0.210
4.67,-14.93,0.210
4.68,-14.76,0.210
4.70,-14.60,0.210
4.72,-14.43,0.210
4.73,-14.27,0.211
4.75,-14.10,0.211
4.77,-13.93,0.211
4.78,-13.76,0.211
4.80,-13.60,0.211
4.82,-13.43,0.211
4.83,-13.26,0.211
4.85,-13.10,0.211
4.87,-12.93,0.211
4.88,-12.76,0.211
4.90,-12.60,0.212
4.92,-12.43,0.212
4.93,-12.26,0.212
4.95,-12.10,0.212
4.97,-11.93,0.212
4.98,-11.76,0.212
5.00,-11.60,0.212
5.02,-11.43,0.212
5.03,-11.26,0.212
5.05,-11.10,0.212
5.07,-10.93,0.212
5.08,-10.76,0.213
5.10,-10.60,0.213
5.12,-10.43,0.213
5.13,-10.26,0.213
5.15,-10.10,0.213
5.17,-9.93,0.213
5.18,-9.76,0.213
5.20,-9.59,0.213
5.22,-9.43,0.213
5.23,-9.26,0.214
5.25,-9.09,0.214
5.27,-8.93,0.214
5.28,-8.76,0.214
5.30,-8.59,0.214
5.32,-8.43,0.214
5.33,-8.26,0.214
5.35,-8.09,0.214
5.37,-7.93,0.214
5.38,-7.76,0.214
5.40,-7.59,0.215
5.42,-7.43,0.215
5.43,-7.26,0.215
5.45,-7.09,0.215
5.47,-6.93,0.215
5.48,-6.76,0.215
5.50,-6.59,0.215
5.52,-6.43,0.215
5.53,-6.26,0.215
5.55,-6.09,0.216
5.57,-5.93,0.216
5.58,-5.76,0.216
5.60,-5.59,0.216
5.62,-5.43,0.216
5.63,-5.26,0.216
5.65,-5.09,0.216
5.67,-4.93,0.216
5.68,-4.76,0.217
5.70,-4.59,0.217
5.72,-4.42,0.217
5.73,-4.26,0.217
5.75,-4.09,0.217
5.77,-3.92,0.217
5.78,-3.76,0.217
5.80,-3.59,0.217
5.82,-3.42,0.218
5.83,-3.26,0.218
5.85,-3.09,0.218
5.87,-2.92,0.218
5.88,-2.76,0.218
5.90,-2.59,0.218
5.92,-2.42,0.218
5.93,-2.25,0.218
5.95,-2.09,0.219
5.97,-1.92,0.219
5.98,-1.75,0.219
6.00,-1.59,0.219
6.02,-1.42,0.219
6.03,-1.25,0.219
6.05,-1.09,0.219
6.07,-0.92,0.219
6.08,-0.75,0.219
6.10,-0.59,0.219
6.12,-0.42,0.220
6.13,-0.25,0.220
6.15,-0.09,0.220
6.17,0.08,0.220
6.18,0.25,0.220
6.20,0.42,0.220
6.22,0.58,0.220
6.23,0.75,0.221
6.25,0.92,0.221
6.27,1.08,0.221
6.28,1.25,0.221
6.30,1.42,0.221
6.32,1.58,0.221
6.33,1.75,0.221
6.35,1.92,0.221
6.37,2.08,0.221
6.38,2.25,0.222
6.40,2.42,0.222
6.42,2.58,0.222
6.43,2.75,0.222
6.45,2.92,0.222
6.47,3.08,0.222
6.48,3.25,0.222
6.50,3.42,0.222
6.52,3.58,0.223
6.53,3.75,0.223
6.55,3.92,0.223
6.57,4.09,0.223
6.58,4.25,0.223
6.60,4.42,0.223
6.62,4.59,0.223
6.63,4.75,0.223
6.65,4.92,0.224
6.67,5.09,0.224
6.68,5.25,0.224
6.70,5.42,0.224
6.72,5.59,0.224
6.73,5.75,0.224
6.75,5.92,0.224
6.77,6.09,0.224
6.78,6.25,0.225
6.80,6.42,0.225
6.82,6.59,0.225
6.83,6.75,0.225
6.85,6.92,0.225
6.87,7.09,0.225
6.88,7.25,0.225
6.90,7.42,0.225
6.92,7.59,0.226
6.93,7.76,0.226
6.95,7.92,0.226
6.97,8.09,0.226
6.98,8.26,0.226
7.00,8.42,0.226
7.02,8.59,0.226
7.03,8.76,0.227
7.05,8.92,0.227
7.07,9.09,0.227
7.08,9.26,0.227
7.10,9.42,0.227
7.12,9.59,0.227
7.13,9.76,0.227
7.15,9.92,0.228
7.17,10.09,0.228
7.18,10.26,0.228
7.20,10.43,0.228
7.22,10.59,0.228
7.23,10.76,0.228
7.25,10.92,0.228
7.27,11.09,0.229
7.28,11.26,0.229
7.30,11.43,0.229
7.32,11.59,0.229
7.33,11.76,0.229
7.35,11.93,0.229
7.37,12.09,0.229
7.38,12.26,0.229
7.40,12.43,0.230
7.42,12.59,0.230
7.43,12.76,0.230
7.45,12.93,0.230
7.47,13.09,0.230
7.48,13.26,0.230
7.50,13.43,0.230
7.52,13.59,0.230
7.53,13.76,0.231
7.55,13.93,0.231
7.57,14.10,0.231
7.58,14.26,0.231
7.60,14.43,0.231
7.62,14.60,0.231
7.63,14.76,0.231
7.65,14.93,0.231
7.67,15.10,0.231
7.68,15.26,0.232
7.70,15.43,0.232
7.72,15.60,0.232
7.73,15.76,0.232
7.75,15.93,0.232
7.77,16.10,0.232
7.78,16.26,0.232
7.80,16.43,0.232
7.82,16.60,0.233
7.83,16.76,0.233
7.85,16.93,0.233
7.87,17.10,0.233
7.88,17.27,0.233
7.90,17.43,0.233
7.92,17.60,0.233
7.93,17.77,0.234
7.95,17.93,0.234
7.97,18.10,0.234
7.98,18.27,0.234
8.00,18.43,0.234
8.02,18.60,0.234
8.03,18.77,0.234
8.05,18.93,0.235
8.07,19.10,0.235
8.08,19.27,0.235
8.10,19.43,0.235
8.12,19.60,0.235
8.13,19.77,0.235
8.15,19.93,0.235
8.17,20.10,0.235
8.18,20.27,0.236
8.20,20.43,0.236
8.22,20.60,0.236
8.23,20.77,0.236
8.25,20.93,0.236
8.27,21.10,0.236
8.28,21.27,0.236
8.30,21.43,0.236
8.32,21.60,0.237
8.33,21.77,0.237
8.35,21.94,0.237
8.37,22.10,0.237
8.38,22.27,0.237
8.40,22.44,0.237
8.42,22.60,0.237
8.43,22.77,0.238
8.45,22.94,0.238
8.47,23.10,0.238
8.48,23.27,0.238
8.50,23.44,0.238
8.52,23.60,0.238
8.53,23.77,0.238
8.55,23.94,0.239
8.57,24.10,0.239
8.58,24.27,0.239
8.60,24.44,0.239
8.62,24.60,0.239
8.63,24.77,0.239
8.65,24.94,0.239
8.67,25.10,0.240
8.68,25.27,0.240
8.70,25.44,0.240
8.72,25.60,0.240
8.73,25.77,0.240
8.75,25.94,0.240
8.77,26.10,0.240
8.78,26.27,0.240
8.80,26.44,0.241
8.82,26.61,0.241
8.83,26.77,0.241
8.85,26.94,0.241
8.87,27.11,0.241
8.88,27.27,0.241
8.90,27.44,0.241
8.92,27.61,0.242
8.93,27.77,0.242
8.95,27.94,0.242
8.97,28.11,0.242
8.98,28.27,0.242
9.00,28.44,0.242
9.02,28.61,0.242
9.03,28.77,0.242
9.05,28.94,0.243
9.07,29.11,0.243
9.08,29.28,0.243
9.10,29.44,0.243
9.12,29.61,0.243
9.13,29.78,0.243
9.15,29.94,0.243
9.17,30.11,0.243
9.18,30.28,0.244
9.20,30.44,0.244
9.22,30.61,0.244
9.23,30.78,0.244
9.25,30.94,0.244
9.27,31.11,0.244
9.28,31.28,0.244
9.30,31.45,0.245
9.32,31.61,0.245
9.33,31.78,0.245
9.35,31.94,0.245
9.37,32.11,0.245
9.38,32.28,0.245
9.40,32.45,0.245
9.42,32.61,0.245
9.43,32.78,0.245
9.45,32.94,0.246
9.47,33.11,0.246
9.48,33.28,0.246
9.50,33.45,0.246
9.52,33.61,0.246
9.53,33.78,0.246
9.55,33.95,0.246
9.57,34.11,0.246
9.58,34.28,0.247
9.60,34.45,0.247
9.62,34.61,0.247
9.63,34.78,0.247
9.65,34.95,0.247
9.67,35.11,0.247
9.68,35.28,0.247
9.70,35.45,0.247
9.72,35.62,0.248
9.73,35.78,0.248
9.75,35.95,0.248
9.77,36.11,0.248
9.78,36.28,0.248
9.80,36.45,0.248
9.82,36.62,0.248
9.83,36.78,0.248
9.85,36.95,0.249
9.87,37.12,0.249
9.88,37.28,0.249
9.90,37.45,0.249
9.92,37.62,0.249
9.93,37.78,0.249
9.95,37.95,0.249
9.97,38.12,0.249
9.98,38.28,0.249
10.00,38.45,0.250
10.02,38.62,0.250
10.03,38.79,0.250
10.05,38.95,0.250
10.07,39.12,0.250
10.08,39.29,0.250
10.10,39.45,0.250
10.12,39.62,0.250
10.13,39.79,0.251
10.15,39.95,0.251
10.17,40.12,0.251
10.18,40.29,0.251
10.20,40.45,0.251
10.22,40.62,0.251
10.23,40.79,0.251
10.25,40.95,0.251
10.27,41.12,0.252
10.28,41.29,0.252
10.30,41.45,0.252
10.32,41.62,0.252
10.33,41.79,0.252
10.35,41.95,0.252
10.37,42.12,0.252
10.38,42.29,0.252
10.40,42.45,0.253
10.42,42.62,0.253
10.43,42.79,0.253
10.45,42.96,0.253
10.47,43.12,0.253
10.48,43.29,0.253
10.50,43.46,0.254
10.52,43.62,0.254
10.53,43.79,0.254
10.55,43.96,0.254
10.57,44.12,0.254
10.58,44.29,0.254
10.60,44.46,0.254
10.62,44.62,0.254
10.63,44.79,0.254
10.65,44.96,0.255
10.67,45.12,0.255
10.68,45.29,0.255
10.70,45.46,0.255
10.72,45.62,0.255
10.73,45.79,0.255
10.75,45.96,0.255
10.77,46.13,0.255
10.78,46.29,0.256
10.80,46.46,0.256
10.82,46.62,0.256
10.83,46.79,0.256
10.85,46.96,0.256
10.87,47.13,0.256
10.88,47.29,0.256
10.90,47.46,0.256
10.92,47.63,0.257
10.93,47.79,0.257
10.95,47.96,0.257
10.97,48.13,0.257
10.98,48.29,0.257
11.00,48.46,0.257
11.02,48.63,0.257
11.03,48.79,0.257
11.05,48.96,0.257
11.07,49.13,0.258
11.08,49.30,0.258
11.10,49.46,0.258
11.12,49.63,0.258
11.13,49.80,0.258
11.15,49.96,0.258
11.17,50.13,0.258
11.18,50.30,0.259
11.20,50.46,0.259
11.22,50.63,0.259
11.23,50.80,0.259
11.25,50.96,0.259
11.27,51.13,0.259
11.28,51.30,0.259
11.30,51.46,0.259
11.32,51.63,0.260
11.33,51.80,0.260
11.35,51.96,0.260
11.37,52.13,0.260
11.38,52.30,0.260
11.40,52.46,0.260
11.42,52.63,0.260
11.43,52.80,0.260
11.45,52.97,0.260
11.47,53.13,0.261
11.48,53.30,0.261
11.50,53.46,0.261
11.52,53.63,0.261
11.53,53.80,0.261
11.55,53.97,0.261
11.57,54.13,0.261
11.58,54.30,0.261
11.60,54.47,0.262
11.62,54.63,0.262
11.63,54.80,0.262
11.65,54.97,0.262
11.67,55.13,0.262
11.68,55.30,0.262
11.70,55.47,0.262
11.72,55.64,0.262
11.73,55.80,0.263
11.75,55.97,0.263
11.77,56.13,0.263
11.78,56.30,0.263
11.80,56.47,0.263
11.82,56.64,0.263
11.83,56.80,0.263
11.85,56.97,0.263
11.87,57.14,0.264
11.88,57.30,0.264
11.90,57.47,0.264
11.92,57.64,0.264
11.93,57.80,0.264
11.95,57.97,0.264
11.97,58.14,0.264
11.98,58.30,0.264
12.00,58.47,0.264
12.02,58.64,0.265
12.03,58.80,0.265
12.05,58.97,0.265
12.07,59.14,0.265
12.08,59.30,0.265
12.10,59.47,0.265
12.12,59.64,0.265
12.13,59.81,0.265
12.15,59.97,0.265
12.17,60.14,0.266
12.18,60.30,0.266
12.20,60.47,0.266
12.22,60.64,0.266
12.23,60.80,0.266
12.25,60.97,0.266
12.27,61.14,0.266
12.28,61.31,0.266
12.30,61.47,0.266
12.32,61.64,0.267
12.33,61.81,0.267
12.35,61.97,0.267
12.37,62.14,0.267
12.38,62.31,0.267
12.40,62.47,0.267
12.42,62.64,0.267
12.43,62.81,0.267
12.45,62.97,0.268
12.47,63.14,0.268
12.48,63.31,0.268
12.50,63.47,0.268
12.52,63.64,0.268
12.53,63.81,0.268
12.55,63.97,0.268
12.57,64.14,0.268
12.58,64.31,0.268
12.60,64.47,0.269
12.62,64.64,0.269
12.63,64.81,0.269
12.65,64.97,0.269
12.67,65.14,0.269
12.68,65.31,0.269
12.70,65.47,0.269
12.72,65.64,0.269
12.73,65.81,0.270
12.75,65.97,0.270
12.77,66.14,0.270
12.78,66.31,0.270
12.80,66.47,0.270
12.82,66.64,0.270
12.83,66.81,0.270
12.85,66.98,0.270
12.87,67.14,0.270
12.88,67.31,0.271
12.90,67.48,0.271
12.92,67.64,0.271
12.93,67.81,0.271
12.95,67.98,0.271
12.97,68.14,0.271
12.98,68.31,0.271
13.00,68.48,0.271
13.02,68.64,0.272
13.03,68.81,0.272
13.05,68.98,0.272
13.07,69.14,0.272
13.08,69.31,0.272
13.10,69.48,0.272
13.12,69.64,0.272
13.13,69.81,0.272
13.15,69.98,0.273
13.17,70.15,0.273
13.18,70.31,0.273
13.20,70.48,0.273
13.22,70.65,0.273
13.23,70.81,0.273
13.25,70.98,0.273
13.27,71.15,0.273
13.28,71.31,0.273
13.30,71.48,0.274
13.32,71.65,0.274
13.33,71.81,0.274
13.35,71.98,0.274
13.37,72.15,0.274
13.38,72.31,0.274
13.40,72.48,0.274
13.42,72.65,0.274
13.43,72.81,0.274
13.45,72.98,0.275
13.47,73.15,0.275
13.48,73.31,0.275
13.50,73.48,0.275
13.52,73.65,0.275
13.53,73.82,0.275
13.55,73.98,0.275
13.57,74.15,0.275
13.58,74.32,0.275
13.60,74.48,0.276
13.62,74.65,0.276
13.63,74.82,0.276
13.65,74.98,0.276
13.67,75.15,0.276
13.68,75.32,0.276
13.70,75.48,0.276
13.72,75.65,0.276
13.73,75.82,0.276
13.75,75.98,0.277
13.77,76.15,0.277
13.78,76.32,0.277
13.80,76.48,0.277
13.82,76.65,0.277
13.83,76.82,0.277
13.85,76.98,0.277
13.87,77.15,0.277
13.88,77.32,0.277
13.90,77.49,0.278
13.92,77.65,0.278
13.93,77.82,0.278
13.95,77.99,0.278
13.97,78.15,0.278
13.98,78.32,0.278
14.00,78.49,0.278
14.02,78.65,0.278
14.03,78.82,0.278
14.05,78.99,0.279
14.07,79.15,0.279
14.08,79.32,0.279
14.10,79.49,0.279
14.12,79.65,0.279
14.13,79.82,0.279
14.15,79.99,0.279
14.17,80.15,0.279
14.18,80.32,0.279
14.20,80.49,0.280
14.22,80.65,0.280
14.23,80.82,0.280
14.25,80.99,0.280
14.27,81.16,0.280
14.28,81.32,0.280
14.30,81.49,0.280
14.32,81.66,0.280
14.33,81.82,0.280
14.35,81.99,0.281
14.37,82.15,0.281
14.38,82.32,0.281
14.40,82.49,0.281
14.42,82.66,0.281
14.43,82.82,0.281
14.45,82.99,0.281
14.47,83.16,0.281
14.48,83.32,0.281
14.50,83.49,0.281
14.52,83.66,0.282
14.53,83.82,0.282
14.55,83.99,0.282
14.57,84.16,0.282
14.58,84.32,0.282
14.60,84.49,0.282
14.62,84.66,0.282
14.63,84.82,0.282
14.65,84.99,0.282
14.67,85.16,0.282
14.68,85.33,0.283
14.70,85.49,0.283
14.72,85.66,0.283
14.73,85.83,0.283
14.75,85.99,0.283
14.77,86.16,0.283
14.78,86.33,0.283
14.80,86.49,0.283
14.82,86.66,0.283
14.83,86.83,0.283
14.85,86.99,0.284
14.87,87.16,0.284
14.88,87.33,0.284
14.90,87.49,0.284
14.92,87.66,0.284
14.93,87.83,0.284
14.95,88.00,0.284
14.97,88.16,0.284
14.98,88.33,0.284
15.00,88.49,0.284
15.02,88.66,0.285
15.03,88.83,0.285
15.05,89.00,0.285
15.07,89.16,0.285
15.08,89.33,0.285
15.10,89.50,0.285
15.12,89.66,0.285
15.13,89.83,0.285
15.15,90.00,0.286
15.17,90.16,0.286
15.18,90.33,0.286
15.20,90.49,0.286
15.22,90.66,0.286
15.23,90.83,0.286
15.25,91.00,0.286
15.27,91.16,0.286
15.28,91.33,0.286
15.30,91.50,0.287
15.32,91.66,0.287
15.33,91.83,0.287
15.35,92.00,0.287
15.37,92.16,0.287
15.38,92.33,0.287
15.40,92.50,0.287
15.42,92.66,0.288
15.43,92.83,0.288
15.45,93.00,0.288
15.47,93.16,0.288
15.48,93.33,0.288
15.50,93.50,0.288
15.52,93.66,0.288
15.53,93.83,0.288
15.55,94.00,0.289
15.57,94.16,0.289
15.58,94.33,0.289
15.60,94.50,0.289
15.62,94.67,0.289
15.63,94.83,0.289
15.65,95.00,0.289
15.67,95.17,0.289
15.68,95.33,0.289
15.70,95.50,0.290
15.72,95.67,0.290
15.73,95.83,0.290
15.75,96.00,0.290
15.77,96.17,0.290
15.78,96.33,0.290
15.80,96.50,0.290
15.82,96.67,0.290
15.83,96.83,0.291
15.85,97.00,0.291
15.87,97.17,0.291
15.88,97.34,0.291
15.90,97.50,0.291
15.92,97.67,0.291
15.93,97.84,0.291
15.95,98.00,0.291
15.97,98.17,0.291
15.98,98.33,0.292
16.00,98.50,0.292
16.02,98.67,0.292
16.03,98.84,0.292
16.05,99.00,0.292
16.07,99.17,0.292
16.08,99.34,0.292
16.10,99.50,0.292
16.12,99.67,0.293
16.13,99.84,0.293
16.15,100.00,0.293
16.17,100.17,0.293
16.18,100.34,0.293
16.20,100.50,0.293
16.22,100.67,0.293
16.23,100.84,0.293
16.25,101.00,0.293
16.27,101.17,0.294
16.28,101.34,0.294
16.30,101.50,0.294
16.32,101.67,0.294
16.33,101.84,0.294
16.35,102.00,0.294
16.37,102.17,0.294
16.38,102.34,0.294
16.40,102.51,0.295
16.42,102.67,0.295
16.43,102.84,0.295
16.45,103.00,0.295
16.47,103.17,0.295
16.48,103.34,0.295
16.50,103.50,0.295
16.52,103.67,0.295
16.53,103.84,0.295
16.55,104.01,0.296
16.57,104.17,0.296
16.58,104.34,0.296
16.60,104.51,0.296
16.62,104.67,0.296
16.63,104.84,0.296
16.65,105.01,0.296
16.67,105.17,0.296
16.68,105.34,0.296
16.70,105.51,0.297
16.72,105.67,0.297
16.73,105.84,0.297
16.75,106.01,0.297
16.77,106.17,0.297
16.78,106.34,0.297
16.80,106.51,0.297
16.82,106.67,0.297
16.83,106.84,0.297
16.85,107.01,0.298
16.87,107.17,0.298
16.88,107.34,0.298
16.90,107.51,0.298
16.92,107.68,0.298
16.93,107.84,0.298
16.95,108.01,0.298
16.97,108.18,0.298
16.98,108.34,0.299
17.00,108.51,0.299
17.02,108.68,0.299
17.03,108.84,0.299
17.05,109.01,0.299
17.07,109.18,0.299
17.08,109.34,0.299
17.10,109.51,0.299
17.12,109.68,0.299
17.13,109.84,0.300
17.15,110.01,0.300
17.17,110.18,0.300
17.18,110.34,0.300
17.20,110.51,0.300
17.22,110.68,0.300
17.23,110.84,0.300
17.25,111.01,0.300
17.27,111.18,0.300
17.28,111.35,0.301
17.30,111.51,0.301
17.32,111.68,0.301
17.33,111.85,0.301
17.35,112.01,0.301
17.37,112.18,0.301
17.38,112.34,0.301
17.40,112.51,0.301
17.42,112.68,0.301
17.43,112.84,0.302
17.45,113.01,0.302
17.47,113.18,0.302
17.48,113.35,0.302
17.50,113.51,0.302
17.52,113.68,0.302
17.53,113.85,0.302
17.55,114.01,0.302
17.57,114.18,0.303
17.58,114.35,0.303
17.60,114.51,0.303
17.62,114.68,0.303
17.63,114.85,0.303
17.65,115.01,0.303
17.67,115.18,0.303
17.68,115.35,0.303
17.70,115.51,0.304
17.72,115.68,0.304
17.73,115.85,0.304
17.75,116.01,0.304
17.77,116.18,0.304
17.78,116.35,0.304
17.80,116.51,0.304
17.82,116.68,0.304
17.83,116.85,0.304
17.85,117.01,0.305
17.87,117.18,0.305
17.88,117.35,0.305
17.90,117.51,0.305
17.92,117.68,0.305
17.93,117.85,0.305
17.95,118.02,0.305
17.97,118.18,0.305
17.98,118.35,0.306
18.00,118.52,0.306
18.02,118.68,0.306
18.03,118.85,0.306
18.05,119.02,0.306
18.07,119.18,0.306
18.08,119.35,0.306
18.10,119.52,0.306
18.12,119.68,0.306
18.13,119.85,0.307
18.15,120.02,0.307
18.17,120.18,0.307
18.18,120.35,0.307
18.20,120.52,0.307
18.22,120.68,0.307
18.23,120.85,0.307
18.25,121.02,0.307
18.27,121.18,0.308
18.28,121.35,0.308
18.30,121.52,0.308
18.32,121.69,0.308
18.33,121.85,0.308
18.35,122.02,0.308
18.37,122.18,0.308
18.38,122.35,0.308
18.40,122.52,0.309
18.42,122.69,0.309
18.43,122.85,0.309
18.45,123.02,0.309
18.47,123.19,0.309
18.48,123.35,0.309
18.50,123.52,0.309
18.52,123.68,0.309
18.53,123.85,0.310
18.55,124.02,0.310
18.57,124.19,0.310
18.58,124.35,0.310
18.60,124.52,0.310
18.62,124.68,0.310
18.63,124.85,0.310
18.65,125.02,0.311
18.67,125.19,0.311
18.68,125.35,0.311
18.70,125.52,0.311
18.72,125.69,0.311
18.73,125.85,0.311
18.75,126.02,0.311
18.77,126.19,0.312
18.78,126.35,0.312
18.80,126.52,0.312
18.82,126.69,0.312
18.83,126.85,0.312
18.85,127.02,0.312
18.87,127.19,0.313
18.88,127.35,0.313
18.90,127.52,0.313
18.92,127.69,0.313
18.93,127.85,0.313
18.95,128.02,0.314
18.97,128.19,0.314
18.98,128.35,0.314
19.00,128.52,0.314
19.02,128.69,0.314
19.03,128.85,0.315
19.05,129.02,0.315
19.07,129.19,0.315
19.08,129.35,0.315
19.10,129.52,0.315
19.12,129.69,0.316
19.13,129.85,0.316
19.15,130.02,0.316
19.17,130.19,0.317
19.18,130.35,0.317
19.20,130.52,0.317
19.22,130.69,0.317
19.23,130.85,0.317
19.25,131.02,0.318
19.27,131.19,0.318
19.28,131.35,0.318
19.30,131.52,0.319
19.32,131.69,0.319
19.33,131.85,0.319
19.35,132.02,0.320
19.37,132.19,0.320
19.38,132.35,0.321
19.40,132.52,0.321
19.42,132.69,0.321
19.43,132.85,0.322
19.45,133.02,0.323
19.47,133.19,0.324
19.48,133.35,0.325
19.50,133.52,0.325
19.52,133.68,0.326
19.53,133.85,0.327
19.55,134.02,0.328
19.57,134.18,0.329
19.58,134.35,0.330
19.60,134.52,0.331
19.62,134.68,0.332
19.63,134.85,0.333
19.65,135.02,0.335
19.67,135.18,0.337
19.68,135.35,0.339
19.70,135.51,0.340
19.72,135.68,0.342
19.73,135.85,0.344
19.75,136.01,0.347
19.77,136.18,0.349
19.78,136.34,0.351
19.80,136.51,0.355
19.82,136.67,0.357
19.83,136.84,0.361
19.85,137.00,0.365
19.87,137.17,0.370
19.88,137.33,0.374
19.90,137.50,0.380
19.92,137.66,0.384
19.93,137.82,0.393
19.95,137.99,0.399
19.97,138.15,0.408
19.98,138.31,0.418
20.00,138.47,0.428
20.02,138.63,0.441
20.03,138.80,0.454
20.05,138.95,0.470
20.07,139.11,0.488
20.08,139.27,0.508
20.10,139.43,0.531
20.12,139.58,0.557
20.13,139.73,0.586
20.15,139.88,0.617
20.17,140.03,0.652
20.18,140.18,0.692
20.20,140.33,0.734
20.22,140.47,0.777
20.23,140.61,0.826
20.25,140.75,0.875
20.27,140.89,0.925
20.28,141.03,0.977
20.30,141.17,1.029
20.32,141.30,1.084
20.33,141.43,1.138
20.35,141.57,1.193
20.37,141.70,1.249
20.38,141.83,1.301
20.40,141.97,1.351
20.42,142.10,1.403
20.43,142.23,1.448
20.45,142.37,1.503
20.47,142.50,1.560
20.48,142.63,1.607
20.50,142.77,1.650
20.52,142.90,1.691
20.53,143.04,1.728
20.55,143.18,1.759
20.57,143.32,1.785
20.58,143.47,1.810
20.60,143.62,1.819
20.62,143.77,1.812
20.63,143.93,1.794
20.65,144.09,1.770
20.67,144.27,1.743
20.68,144.44,1.705
20.70,144.62,1.663
20.72,144.81,1.614
20.73,145.00,1.558
20.75,145.19,1.495
20.77,145.39,1.429
20.78,145.59,1.360
20.80,145.79,1.290
20.82,146.00,1.220
20.83,146.21,1.151
20.85,146.42,1.086
20.87,146.63,1.025
20.88,146.83,0.967
20.90,147.04,0.910
20.92,147.24,0.857
20.93,147.45,0.811
20.95,147.65,0.769
20.97,147.85,0.730
20.98,148.04,0.697
21.00,148.24,0.666
21.02,148.43,0.639
21.03,148.62,0.614
21.05,148.80,0.593
21.07,148.99,0.578
21.08,149.17,0.558
21.10,149.35,0.541
21.12,149.53,0.531
21.13,149.71,0.522
21.15,149.89,0.514
21.17,150.06,0.507
21.18,150.23,0.502
21.20,150.41,0.496
21.22,150.58,0.490
21.23,150.75,0.489
21.25,150.92,0.485
21.27,151.09,0.483
21.28,151.26,0.483
21.30,151.43,0.483
21.32,151.60,0.482
21.33,151.77,0.480
21.35,151.94,0.481
21.37,152.10,0.482
21.38,152.27,0.481
21.40,152.44,0.480
21.42,152.61,0.479
21.43,152.77,0.478
21.45,152.94,0.478
21.47,153.11,0.481
21.48,153.27,0.487
21.50,153.44,0.486
21.52,153.61,0.484
21.53,153.77,0.482
21.55,153.94,0.482
21.57,154.11,0.482
21.58,154.27,0.482
21.60,154.44,0.482
21.62,154.61,0.483
21.63,154.77,0.492
21.65,154.94,0.492
21.67,155.10,0.491
21.68,155.27,0.490
21.70,155.44,0.489
21.72,155.60,0.489
21.73,155.77,0.489
21.75,155.94,0.489
21.77,156.10,0.489
21.78,156.27,0.490
21.80,156.44,0.494
21.82,156.60,0.498
21.83,156.77,0.503
21.85,156.93,0.507
21.87,157.10,0.518
21.88,157.26,0.528
21.90,157.42,0.531
21.92,157.59,0.526
21.93,157.75,0.530
21.95,157.92,0.529
21.97,158.08,0.528
21.98,158.25,0.528
22.00,158.41,0.529
22.02,158.58,0.532
22.03,158.75,0.532
22.05,158.91,0.537
22.07,159.08,0.539
22.08,159.24,0.538
22.10,159.41,0.538
22.12,159.58,0.539
22.13,159.74,0.541
22.15,159.91,0.541
22.17,160.08,0.540
22.18,160.24,0.540
22.20,160.41,0.542
22.22,160.58,0.547
22.23,160.74,0.546
22.25,160.91,0.548
22.27,161.07,0.547
22.28,161.24,0.547
22.30,161.41,0.547
22.32,161.57,0.547
22.33,161.74,0.548
22.35,161.91,0.548
22.37,162.07,0.548
22.38,162.24,0.551
22.40,162.41,0.554
22.42,162.57,0.556
22.43,162.74,0.555
22.45,162.90,0.552
22.47,163.07,0.552
22.48,163.24,0.552
22.50,163.41,0.552
22.52,163.57,0.551
22.53,163.74,0.551
22.55,163.91,0.550
22.57,164.07,0.550
22.58,164.24,0.550
22.60,164.40,0.555
22.62,164.57,0.555
22.63,164.74,0.552
22.65,164.91,0.550
22.67,165.07,0.547
22.68,165.24,0.544
22.70,165.41,0.542
22.72,165.58,0.539
22.73,165.75,0.537
22.75,165.91,0.534
22.77,166.08,0.533
22.78,166.25,0.529
22.80,166.42,0.523
22.82,166.59,0.525
22.83,166.76,0.518
22.85,166.93,0.517
22.87,167.09,0.516
22.88,167.26,0.512
22.90,167.43,0.508
22.92,167.60,0.503
22.93,167.77,0.500
22.95,167.94,
22.97,168.11,
22.98,168.28,
22.99,,

[step]
Ramp 10.00 °C/min to -60.00 °C
Time,Temperature,Heat Flow (Normalized)
min,°C,W/g
23.09,169.28,0.470
23.11,169.38,0.469
23.13,169.46,0.469
23.14,169.52,0.465
23.16,169.56,0.455
23.18,169.58,0.450
23.19,169.57,0.444
23.21,169.53,0.434
23.23,169.47,0.415
23.24,169.40,0.386
23.26,169.31,0.348
23.28,169.21,0.306
23.29,169.11,0.263
23.31,169.00,0.223
23.33,168.88,0.187
23.34,168.76,0.155
23.36,168.63,0.125
23.38,168.50,0.099
23.39,168.36,0.075
23.41,168.23,0.053
23.43,168.09,0.034
23.44,167.94,0.016
23.46,167.80,0.000
23.48,167.65,-0.015
23.49,167.50,-0.028
23.51,167.35,-0.040
23.53,167.20,-0.050
23.54,167.05,-0.061
23.56,166.89,-0.070
23.58,166.74,-0.070
23.59,166.58,-0.055
23.61,166.42,-0.029
23.63,166.25,-0.010
23.64,166.08,-0.002
23.66,165.91,0.000
23.68,165.75,-0.002
23.69,165.58,-0.005
23.71,165.42,-0.009
23.73,165.26,-0.017
23.74,165.09,-0.024
23.76,164.93,-0.032
23.78,164.77,-0.038
23.79,164.61,-0.046
23.81,164.45,-0.053
23.83,164.29,-0.060
23.84,164.13,-0.067
23.86,163.97,-0.075
23.88,163.80,-0.080
23.89,163.65,-0.087
23.91,163.48,-0.094
23.93,163.32,-0.099
23.94,163.16,-0.106
23.96,163.00,-0.113
23.98,162.84,-0.119
23.99,162.68,-0.124
24.01,162.52,-0.130
24.03,162.36,-0.135
24.04,162.19,-0.140
24.06,162.03,-0.144
24.08,161.87,-0.148
24.09,161.71,-0.151
24.11,161.55,-0.156
24.13,161.38,-0.159
24.14,161.22,-0.162
24.16,161.06,-0.165
24.18,160.89,-0.169
24.19,160.73,-0.171
24.21,160.57,-0.177
24.23,160.40,-0.179
24.24,160.24,-0.183
24.26,160.08,-0.186
24.28,159.91,-0.188
24.29,159.75,-0.191
24.31,159.59,-0.193
24.33,159.42,-0.196
24.34,159.26,-0.198
24.36,159.09,-0.201
24.38,158.93,-0.203
24.39,158.76,-0.205
24.41,158.60,-0.206
24.43,158.43,-0.209
24.44,158.27,-0.212
24.46,158.11,-0.214
24.48,157.94,-0.216
24.49,157.78,-0.218
24.51,157.61,-0.219
24.53,157.45,-0.221
24.54,157.28,-0.222
24.56,157.12,-0.224
24.58,156.95,-0.225
24.59,156.79,-0.226
24.61,156.62,-0.227
24.63,156.46,-0.228
24.64,156.29,-0.229
24.66,156.13,-0.230
24.68,155.96,-0.232
24.69,155.80,-0.233
24.71,155.63,-0.234
24.73,155.47,-0.235
24.74,155.30,-0.237
24.76,155.14,-0.238
24.78,154.97,-0.239
24.79,154.80,-0.240
24.81,154.64,-0.241
24.83,154.47,-0.242
24.84,154.31,-0.242
24.86,154.14,-0.244
24.88,153.98,-0.245
24.89,153.81,-0.245
24.91,153.64,-0.246
24.93,153.48,-0.246
24.94,153.31,-0.248
24.96,153.15,-0.250
24.98,152.98,-0.250
24.99,152.82,-0.251
25.01,152.65,-0.251
25.03,152.48,-0.251
25.04,152.32,-0.252
25.06,152.15,-0.252
25.08,151.99,-0.253
25.09,151.82,-0.254
25.11,151.66,-0.254
25.13,151.49,-0.255
25.14,151.32,-0.256
25.16,151.16,-0.256
25.18,150.99,-0.257
25.19,150.83,-0.257
25.21,150.66,-0.257
25.23,150.49,-0.258
25.24,150.33,-0.259
25.26,150.16,-0.259
25.28,150.00,-0.260
25.29,149.83,-0.260
25.31,149.66,-0.261
25.33,149.50,-0.262
25.34,149.33,-0.262
25.36,149.17,-0.262
25.38,149.00,-0.263
25.39,148.83,-0.264
25.41,148.67,-0.264
25.43,148.50,-0.264
25.44,148.33,-0.264
25.46,148.17,-0.265
25.48,148.00,-0.265
25.49,147.84,-0.266
25.51,147.67,-0.267
25.53,147.51,-0.267
25.54,147.34,-0.268
25.56,147.17,-0.268
25.58,147.01,-0.269
25.59,146.84,-0.269
25.61,146.67,-0.269
25.63,146.51,-0.269
25.64,146.34,-0.269
25.66,146.18,-0.270
25.68,146.01,-0.270
25.69,145.84,-0.270
25.71,145.68,-0.270
25.73,145.51,-0.271
25.74,145.35,-0.271
25.76,145.18,-0.271
25.78,145.01,-0.271
25.79,144.85,-0.272
25.81,144.68,-0.272
25.83,144.51,-0.272
25.84,144.35,-0.272
25.86,144.18,-0.273
25.88,144.01,-0.273
25.89,143.85,-0.274
25.91,143.68,-0.274
25.93,143.52,-0.274
25.94,143.35,-0.274
25.96,143.18,-0.275
25.98,143.02,-0.275
25.99,142.85,-0.275
26.01,142.68,-0.276
26.03,142.52,-0.276
26.04,142.35,-0.276
26.06,142.19,-0.276
26.08,142.02,-0.277
26.09,141.85,-0.277
26.11,141.69,-0.277
26.13,141.52,-0.277
26.14,141.36,-0.277
26.16,141.19,-0.278
26.18,141.02,-0.278
26.19,140.86,-0.278
26.21,140.69,-0.278
26.23,140.52,-0.279
26.24,140.36,-0.279
26.26,140.19,-0.279
26.28,140.02,-0.279
26.29,139.86,-0.279
26.31,139.69,-0.280
26.33,139.52,-0.280
26.34,139.36,-0.280
26.36,139.19,-0.280
26.38,139.03,-0.280
26.39,138.86,-0.281
26.41,138.69,-0.281
26.43,138.53,-0.281
26.44,138.36,-0.281
26.46,138.20,-0.281
26.48,138.03,-0.282
26.49,137.86,-0.282
26.51,137.70,-0.282
26.53,137.53,-0.282
26.54,137.36,-0.282
26.56,137.20,-0.282
26.58,137.03,-0.283
26.59,136.86,-0.283
26.61,136.70,-0.283
26.63,136.53,-0.283
26.64,136.37,-0.283
26.66,136.20,-0.283
26.68,136.03,-0.283
26.69,135.87,-0.283
26.71,135.70,-0.283
26.73,135.53,-0.284
26.74,135.37,-0.284
26.76,135.20,-0.284
26.78,135.03,-0.284
26.79,134.87,-0.284
26.81,134.70,-0.284
26.83,134.54,-0.284
26.84,134.37,-0.284
26.86,134.20,-0.284
26.88,134.04,-0.285
26.89,133.87,-0.285
26.91,133.71,-0.285
26.93,133.54,-0.285
26.94,133.37,-0.285
26.96,133.21,-0.285
26.98,133.04,-0.285
26.99,132.87,-0.286
27.01,132.71,-0.286
27.03,132.54,-0.286
27.04,132.37,-0.286
27.06,132.21,-0.286
27.08,132.04,-0.286
27.09,131.87,-0.286
27.11,131.71,-0.286
27.13,131.54,-0.287
27.14,131.38,-0.287
27.16,131.21,-0.287
27.18,131.04,-0.287
27.19,130.88,-0.287
27.21,130.71,-0.287
27.23,130.54,-0.287
27.24,130.38,-0.287
27.26,130.21,-0.287
27.28,130.04,-0.287
27.29,129.88,-0.287
27.31,129.71,-0.287
27.33,129.54,-0.287
27.34,129.38,-0.287
27.36,129.21,-0.287
27.38,129.05,-0.288
27.39,128.88,-0.288
27.41,128.71,-0.288
27.43,128.55,-0.288
27.44,128.38,-0.288
27.46,128.21,-0.288
27.48,128.05,-0.288
27.49,127.88,-0.288
27.51,127.72,-0.288
27.53,127.55,-0.288
27.54,127.38,-0.288
27.56,127.22,-0.288
27.58,127.05,-0.288
27.59,126.88,-0.288
27.61,126.72,-0.288
27.63,126.55,-0.288
27.64,126.38,-0.289
27.66,126.22,-0.289
27.68,126.05,-0.289
27.69,125.88,-0.289
27.71,125.72,-0.289
27.73,125.55,-0.289
27.74,125.39,-0.289
27.76,125.22,-0.289
27.78,125.05,-0.289
27.79,124.89,-0.289
27.81,124.72,-0.289
27.83,124.55,-0.289
27.84,124.39,-0.289
27.86,124.22,-0.289
27.88,124.05,-0.289
27.89,123.89,-0.289
27.91,123.72,-0.289
27.93,123.55,-0.289
27.94,123.39,-0.289
27.96,123.22,-0.289
27.98,123.06,-0.289
27.99,122.89,-0.289
28.01,122.72,-0.289
28.03,122.56,-0.289
28.04,122.39,-0.289
28.06,122.22,-0.289
28.08,122.06,-0.289
28.09,121.89,-0.289
28.11,121.72,-0.289
28.13,121.56,-0.289
28.14,121.39,-0.289
28.16,121.22,-0.289
28.18,121.06,-0.290
28.19,120.89,-0.290
28.21,120.72,-0.290
28.23,120.56,-0.290
28.24,120.39,-0.290
28.26,120.22,-0.290
28.28,120.06,-0.290
28.29,119.89,-0.290
28.31,119.73,-0.290
28.33,119.56,-0.290
28.34,119.39,-0.290
28.36,119.23,-0.290
28.38,119.06,-0.290
28.39,118.89,-0.290
28.41,118.73,-0.290
28.43,118.56,-0.290
28.44,118.40,-0.290
28.46,118.23,-0.290
28.48,118.06,-0.290
28.49,117.90,-0.290
28.51,117.73,-0.290
28.53,117.56,-0.290
28.54,117.40,-0.290
28.56,117.23,-0.290
28.58,117.06,-0.290
28.59,116.90,-0.290
28.61,116.73,-0.290
28.63,116.56,-0.290
28.64,116.40,-0.290
28.66,116.23,-0.290
28.68,116.07,-0.290
28.69,115.90,-0.290
28.71,115.73,-0.290
28.73,115.57,-0.290
28.74,115.40,-0.290
28.76,115.23,-0.290
28.78,115.07,-0.290
28.79,114.90,-0.290
28.81,114.73,-0.290
28.83,114.57,-0.290
28.84,114.40,-0.290
28.86,114.23,-0.290
28.88,114.07,-0.290
28.89,113.90,-0.289
28.91,113.74,-0.289
28.93,113.57,-0.289
28.94,113.40,-0.289
28.96,113.24,-0.289
28.98,113.07,-0.289
28.99,112.90,-0.289
29.01,112.74,-0.289
29.03,112.57,-0.289
29.04,112.40,-0.289
29.06,112.24,-0.289
29.08,112.07,-0.289
29.09,111.90,-0.289
29.11,111.74,-0.289
29.13,111.57,-0.289
29.14,111.40,-0.289
29.16,111.24,-0.289
29.18,111.07,-0.289
29.19,110.90,-0.289
29.21,110.74,-0.289
29.23,110.57,-0.289
29.24,110.41,-0.289
29.26,110.24,-0.289
29.28,110.07,-0.289
29.29,109.90,-0.289
29.31,109.74,-0.289
29.33,109.57,-0.289
29.34,109.41,-0.289
29.36,109.24,-0.289
29.38,109.07,-0.289
29.39,108.91,-0.289
29.41,108.74,-0.289
29.43,108.57,-0.289
29.44,108.41,-0.289
29.46,108.24,-0.289
29.48,108.07,-0.289
29.49,107.91,-0.289
29.51,107.74,-0.289
29.53,107.57,-0.289
29.54,107.41,-0.289
29.56,107.24,-0.289
29.58,107.08,-0.289
29.59,106.91,-0.289
29.61,106.74,-0.288
29.63,106.58,-0.288
29.64,106.41,-0.288
29.66,106.24,-0.288
29.68,106.08,-0.288
29.69,105.91,-0.288
29.71,105.74,-0.288
29.73,105.58,-0.288
29.74,105.41,-0.288
29.76,105.25,-0.288
29.78,105.08,-0.288
29.79,104.91,-0.288
29.81,104.75,-0.288
29.83,104.58,-0.288
29.84,104.41,-0.288
29.86,104.25,-0.288
29.88,104.08,-0.288
29.89,103.92,-0.288
29.91,103.75,-0.288
29.93,103.58,-0.287
29.94,103.41,-0.287
29.96,103.25,-0.287
29.98,103.08,-0.287
29.99,102.92,-0.287
30.01,102.75,-0.287
30.03,102.58,-0.287
30.04,102.41,-0.287
30.06,102.25,-0.287
30.08,102.08,-0.287
30.09,101.92,-0.287
30.11,101.75,-0.287
30.13,101.58,-0.287
30.14,101.42,-0.287
30.16,101.25,-0.287
30.18,101.08,-0.287
30.19,100.92,-0.287
30.21,100.75,-0.287
30.23,100.59,-0.287
30.24,100.42,-0.287
30.26,100.25,-0.287
30.28,100.09,-0.287
30.29,99.92,-0.286
30.31,99.75,-0.286
30.33,99.59,-0.286
30.34,99.42,-0.286
30.36,99.25,-0.286
30.38,99.09,-0.286
30.39,98.92,-0.286
30.41,98.75,-0.286
30.43,98.59,-0.286
30.44,98.42,-0.286
30.46,98.26,-0.286
30.48,98.09,-0.286
30.49,97.92,-0.286
30.51,97.76,-0.286
[...]
96.09,-42.83,0.121
96.10,-42.76,0.121
96.11,-42.69,0.121
96.11,-42.63,0.121
96.12,-42.56,0.121
96.13,-42.49,0.121
96.13,-42.43,0.121
96.14,-42.36,0.121
96.15,-42.29,0.121
96.15,-42.23,0.121
96.16,-42.16,0.121
96.17,-42.09,0.121
96.17,-42.03,0.121
96.18,-41.96,0.122
96.19,-41.89,0.122
96.19,-41.83,0.122
96.20,-41.76,0.122
96.21,-41.69,0.122
96.21,-41.63,0.122
96.22,-41.56,0.122
96.23,-41.49,0.122
96.23,-41.42,0.122
96.24,-41.36,0.122
96.25,-41.29,0.122
96.25,-41.23,0.122
96.26,-41.16,0.122
96.27,-41.09,0.122
96.27,-41.03,0.122
96.28,-40.96,0.122
96.29,-40.89,0.123
96.29,-40.83,0.123
96.30,-40.76,0.123
96.31,-40.69,0.123
96.31,-40.62,0.123
96.32,-40.56,0.123
96.33,-40.49,0.123
96.33,-40.43,0.123
96.34,-40.36,0.123
96.35,-40.29,0.123
96.35,-40.23,0.123
96.36,-40.16,0.123
96.37,-40.09,0.123
96.37,-40.02,0.123
96.38,-39.96,0.123
96.39,-39.89,0.123
96.39,-39.83,0.123
96.40,-39.76,0.123
96.41,-39.69,0.124
96.41,-39.63,0.124
96.42,-39.56,0.124
96.43,-39.49,0.124
96.43,-39.42,0.124
96.44,-39.36,0.124
96.45,-39.29,0.124
96.45,-39.23,0.124
96.46,-39.16,0.124
96.47,-39.09,0.124
96.47,-39.02,0.124
96.48,-38.96,0.124
96.49,-38.89,0.124
96.49,-38.82,0.124
96.50,-38.76,0.124
96.51,-38.69,0.124
96.51,-38.63,0.124
96.52,-38.56,0.124
96.53,-38.49,0.124
96.53,-38.42,0.124
96.54,-38.36,0.124
96.55,-38.29,0.124
96.55,-38.22,0.125
96.56,-38.16,0.125
96.57,-38.09,0.125
96.57,-38.02,0.125
96.58,-37.96,0.125
96.59,-37.89,0.125
96.59,-37.82,0.125
96.60,-37.76,0.125
96.61,-37.69,0.125
96.61,-37.62,0.125
96.62,-37.56,0.125
96.63,-37.49,0.125
96.63,-37.42,0.125
96.64,-37.36,0.125
96.65,-37.29,0.125
96.65,-37.22,0.125
96.66,-37.16,0.125
96.67,-37.09,0.125
96.67,-37.02,0.125
96.68,-36.96,0.125
96.69,-36.89,0.125
96.69,-36.82,0.125
96.70,-36.76,0.125
96.71,-36.69,0.125
96.71,-36.62,0.125
96.72,-36.56,0.125
96.73,-36.49,0.126
96.73,-36.42,0.126
96.74,-36.36,0.126
96.75,-36.29,0.126
96.75,-36.22,0.126
96.76,-36.16,0.126
96.77,-36.09,0.126
96.77,-36.02,0.126
96.78,-35.96,0.126
96.79,-35.89,0.126
96.79,-35.82,0.126
96.80,-35.76,0.126
96.81,-35.69,0.126
96.81,-35.62,0.126
96.82,-35.55,0.126
96.83,-35.49,0.126
96.83,-35.42,0.126
96.84,-35.36,0.126
96.85,-35.29,0.126
96.85,-35.22,0.126
96.86,-35.16,0.126
96.87,-35.09,0.126
96.87,-35.02,0.127
96.88,-34.96,0.127
96.89,-34.89,0.127
96.89,-34.82,0.127
96.90,-34.76,0.127
96.91,-34.69,0.127
96.91,-34.62,0.127
96.92,-34.56,0.127
96.93,-34.49,0.127
96.93,-34.42,0.127
96.94,-34.35,0.127
96.95,-34.29,0.127
96.95,-34.22,0.127
96.96,-34.16,0.127
96.97,-34.09,0.127
96.97,-34.02,0.127
96.98,-33.95,0.127
96.99,-33.89,0.127
96.99,-33.82,0.127
97.00,-33.75,0.127
97.01,-33.69,0.127
97.01,-33.62,0.127
97.02,-33.55,0.127
97.03,-33.49,0.127
97.03,-33.42,0.127
97.04,-33.35,0.127
97.05,-33.29,0.127
97.05,-33.22,0.127
97.06,-33.15,0.128
97.07,-33.09,0.128
97.07,-33.02,0.128
97.08,-32.95,0.128
97.09,-32.89,0.128
97.09,-32.82,0.128
97.10,-32.75,0.128
97.11,-32.69,0.128
97.11,-32.62,0.128
97.12,-32.55,0.128
97.13,-32.49,0.128
97.13,-32.42,0.128
97.14,-32.35,0.128
97.15,-32.29,0.128
97.15,-32.22,0.128
97.16,-32.15,0.128
97.17,-32.09,0.128
97.17,-32.02,0.128
97.18,-31.95,0.128
97.19,-31.89,0.128
97.19,-31.82,0.128
97.20,-31.75,0.128
97.21,-31.69,0.129
97.21,-31.62,0.129
97.22,-31.55,0.129
97.23,-31.49,0.129
97.23,-31.42,0.129
97.24,-31.35,0.129
97.25,-31.29,0.129
97.25,-31.22,0.129
97.26,-31.15,0.129
97.27,-31.08,0.129
97.27,-31.02,0.129
97.28,-30.95,0.129
97.29,-30.88,0.129
97.29,-30.82,0.129
97.30,-30.75,0.129
97.31,-30.68,0.129
97.31,-30.62,0.129
97.32,-30.55,0.129
97.33,-30.48,0.129
97.33,-30.42,0.129
97.34,-30.35,0.129
97.35,-30.28,0.129
97.35,-30.22,0.129
97.36,-30.15,0.129
97.37,-30.08,0.129
97.37,-30.02,0.129
97.38,-29.95,0.129
97.39,-29.89,0.130
97.39,-29.82,0.130
97.40,-29.75,0.130
97.41,-29.68,0.130
97.41,-29.62,0.130
97.42,-29.55,0.130
97.43,-29.48,0.130
97.43,-29.42,0.130
97.44,-29.35,0.130
97.45,-29.28,0.130
97.45,-29.22,0.130
97.46,-29.15,0.130
97.47,-29.08,0.130
97.47,-29.02,0.130
97.48,-28.95,0.130
97.49,-28.88,0.130
97.49,-28.82,0.130
97.50,-28.75,0.130
97.51,-28.68,0.130
97.51,-28.62,0.130
97.52,-28.55,0.130
97.53,-28.48,0.130
97.53,-28.42,0.130
97.54,-28.35,0.130
97.55,-28.28,0.130
97.55,-28.22,0.131
97.56,-28.15,0.131
97.57,-28.08,0.131
97.57,-28.01,0.131
97.58,-27.95,0.131
97.59,-27.88,0.131
97.59,-27.81,0.131
97.60,-27.75,0.131
97.61,-27.68,0.131
97.61,-27.62,0.131
97.62,-27.55,0.131
97.63,-27.48,0.131
97.63,-27.41,0.131
97.64,-27.35,0.131
97.65,-27.28,0.131
97.65,-27.22,0.131
97.66,-27.15,0.131
97.67,-27.08,0.131
97.67,-27.02,0.131
97.68,-26.95,0.131
97.69,-26.88,0.131
97.69,-26.81,0.131
97.70,-26.75,0.131
97.71,-26.68,0.131
97.71,-26.61,0.131
97.72,-26.55,0.132
97.73,-26.48,0.132
97.73,-26.41,0.132
97.74,-26.35,0.132
97.75,-26.28,0.132
97.75,-26.21,0.132
97.76,-26.15,0.132
97.77,-26.08,0.132
97.77,-26.01,0.132
97.78,-25.95,0.132
97.79,-25.88,0.132
97.79,-25.81,0.132
97.80,-25.75,0.132
97.81,-25.68,0.132
97.81,-25.61,0.132
97.82,-25.54,0.132
97.83,-25.48,0.132
97.83,-25.41,0.132
97.84,-25.35,0.132
97.85,-25.28,0.132
97.85,-25.21,0.132
97.86,-25.15,0.132
97.87,-25.08,0.132
97.87,-25.01,0.132
97.88,-24.95,0.132
97.89,-24.88,0.132
97.89,-24.81,0.132
97.90,-24.74,0.133
97.91,-24.68,0.133
97.91,-24.61,0.133
97.92,-24.54,0.133
97.93,-24.48,0.133
97.93,-24.41,0.133
97.94,-24.34,0.133
97.95,-24.28,0.133
97.95,-24.21,0.133
97.96,-24.14,0.133
97.97,-24.08,0.133
97.97,-24.01,0.133
97.98,-23.95,0.133
97.99,-23.88,0.133
97.99,-23.81,0.133
98.00,-23.74,0.133
98.01,-23.68,0.133
98.01,-23.61,0.133
98.02,-23.54,0.133
98.03,-23.48,0.133
98.03,-23.41,0.133
98.04,-23.34,0.133
98.05,-23.28,0.133
98.05,-23.21,0.133
98.06,-23.14,0.134
98.07,-23.08,0.134
98.07,-23.01,0.134
98.08,-22.94,0.134
98.09,-22.88,0.134
98.09,-22.81,0.134
98.10,-22.74,0.134
98.11,-22.68,0.134
98.11,-22.61,0.134
98.12,-22.54,0.134
98.13,-22.48,0.134
98.13,-22.41,0.134
98.14,-22.34,0.134
98.15,-22.28,0.134
98.15,-22.21,0.134
98.16,-22.14,0.134
98.17,-22.08,0.134
98.17,-22.01,0.134
98.18,-21.94,0.134
98.19,-21.88,0.134
98.19,-21.81,0.134
98.20,-21.74,0.134
98.21,-21.68,0.134
98.21,-21.61,0.134
98.22,-21.54,0.134
98.23,-21.48,0.134
98.23,-21.41,0.134
98.24,-21.34,0.134
98.25,-21.28,0.135
98.25,-21.21,0.135
98.26,-21.14,0.135
98.27,-21.08,0.135
98.27,-21.01,0.135
98.28,-20.94,0.135
98.29,-20.87,0.135
98.29,-20.81,0.135
98.30,-20.74,0.135
98.31,-20.68,0.135
98.31,-20.61,0.135
98.32,-20.54,0.135
98.33,-20.47,0.135
98.33,-20.41,0.135
98.34,-20.34,0.135
98.35,-20.27,0.135
98.35,-20.21,0.135
98.36,-20.14,0.135
98.37,-20.07,0.135
98.37,-20.01,0.135
98.38,-19.94,0.135
98.39,-19.87,0.136
98.39,-19.81,0.136
98.40,-19.74,0.136
98.41,-19.67,0.136
98.41,-19.61,0.136
98.42,-19.54,0.136
98.43,-19.47,0.136
98.43,-19.41,0.136
98.44,-19.34,0.136
98.45,-19.27,0.136
98.45,-19.21,0.136
98.46,-19.14,0.136
98.47,-19.07,0.136
98.47,-19.01,0.136
98.48,-18.94,0.136
98.49,-18.87,0.136
98.49,-18.81,0.136
98.50,-18.74,0.136
98.51,-18.67,0.136
98.51,-18.61,0.136
98.52,-18.54,0.136
98.53,-18.47,0.136
98.53,-18.41,0.136
98.54,-18.34,0.136
98.55,-18.27,0.136
98.55,-18.21,0.136
98.56,-18.14,0.136
98.57,-18.07,0.136
98.57,-18.01,0.136
98.58,-17.94,0.136
98.59,-17.87,0.137
98.59,-17.81,0.137
98.60,-17.74,0.137
98.61,-17.67,0.137
98.61,-17.61,0.137
98.62,-17.54,0.137
98.63,-17.47,0.137
98.63,-17.40,0.137
98.64,-17.34,0.137
98.65,-17.27,0.137
98.65,-17.21,0.137
98.66,-17.14,0.137
98.67,-17.07,0.137
98.67,-17.01,0.137
98.68,-16.94,0.137
98.69,-16.87,0.137
98.69,-16.80,0.137
98.70,-16.74,0.137
98.71,-16.67,0.137
98.71,-16.60,0.137
98.72,-16.54,0.137
98.73,-16.47,0.137
98.73,-16.41,0.137
98.74,-16.34,0.137
98.75,-16.27,0.137
98.75,-16.20,0.137
98.76,-16.14,0.137
98.77,-16.07,0.138
98.77,-16.00,0.138
98.78,-15.94,0.138
98.79,-15.87,0.138
98.79,-15.80,0.138
98.80,-15.74,0.138
98.81,-15.67,0.138
98.81,-15.60,0.138
98.82,-15.54,0.138
98.83,-15.47,0.138
98.83,-15.40,0.138
98.84,-15.34,0.138
98.85,-15.27,0.138
98.85,-15.20,0.138
98.86,-15.14,0.138
98.87,-15.07,0.138
98.87,-15.00,0.138
98.88,-14.94,0.138
98.89,-14.87,0.138
98.89,-14.80,0.138
98.90,-14.74,0.138
98.91,-14.67,0.138
98.91,-14.60,0.138
98.92,-14.54,0.138
98.93,-14.47,0.139
98.93,-14.40,0.139
98.94,-14.34,0.139
98.95,-14.27,0.139
98.95,-14.20,0.139
98.96,-14.14,0.139
98.97,-14.07,0.139
98.97,-14.00,0.139
98.98,-13.94,0.139
98.99,-13.87,0.139
98.99,-13.80,0.139
99.00,-13.73,0.139
99.01,-13.67,0.139
99.01,-13.60,0.139
99.02,-13.53,0.139
99.03,-13.47,0.139
99.03,-13.40,0.139
99.04,-13.34,0.139
99.05,-13.27,0.139
99.05,-13.20,0.139
99.06,-13.13,0.139
99.07,-13.07,0.139
99.07,-13.00,0.139
99.08,-12.93,0.139
99.09,-12.87,0.139
99.09,-12.80,0.140
99.10,-12.73,0.140
99.11,-12.67,0.140
99.11,-12.60,0.140
99.12,-12.53,0.140
99.13,-12.47,0.140
99.13,-12.40,0.140
99.14,-12.33,0.140
99.15,-12.27,0.140
99.15,-12.20,0.140
99.16,-12.13,0.140
99.17,-12.07,0.140
99.17,-12.00,0.140
99.18,-11.93,0.140
99.19,-11.87,0.140
99.19,-11.80,0.140
99.20,-11.73,0.140
99.21,-11.67,0.140
99.21,-11.60,0.140
99.22,-11.53,0.140
99.23,-11.47,0.140
99.23,-11.40,0.140
99.24,-11.33,0.140
99.25,-11.27,0.140
99.25,-11.20,0.140
99.26,-11.13,0.140
99.27,-11.07,0.141
99.27,-11.00,0.141
99.28,-10.93,0.141
99.29,-10.87,0.141
99.29,-10.80,0.141
99.30,-10.73,0.141
99.31,-10.67,0.141
99.31,-10.60,0.141
99.32,-10.53,0.141
99.33,-10.47,0.141
99.33,-10.40,0.141
99.34,-10.33,0.141
99.35,-10.27,0.141
99.35,-10.20,0.141
99.36,-10.13,0.141
99.37,-10.07,0.141
99.37,-10.00,0.141
99.38,-9.93,0.141
99.39,-9.87,0.141
99.39,-9.80,0.141
99.40,-9.73,0.141
99.41,-9.67,0.141
99.41,-9.60,0.141
99.42,-9.53,0.141
99.43,-9.47,0.142
99.43,-9.40,0.142
99.44,-9.33,0.142
99.45,-9.27,0.142
99.45,-9.20,0.142
99.46,-9.13,0.142
99.47,-9.07,0.142
99.47,-9.00,0.142
99.48,-8.93,0.142
99.49,-8.86,0.142
99.49,-8.80,0.142
99.50,-8.73,0.142
99.51,-8.66,0.142
99.51,-8.60,0.142
99.52,-8.53,0.142
99.53,-8.46,0.142
99.53,-8.40,0.142
99.54,-8.33,0.142
99.55,-8.27,0.142
99.55,-8.20,0.142
99.56,-8.13,0.142
99.57,-8.06,0.142
99.57,-8.00,0.142
99.58,-7.93,0.142
99.59,-7.87,0.143
99.59,-7.80,0.143
99.60,-7.73,0.143
99.61,-7.66,0.143
99.61,-7.60,0.143
99.62,-7.53,0.143
99.63,-7.46,0.143
99.63,-7.40,0.143
99.64,-7.33,0.143
99.65,-7.26,0.143
99.65,-7.20,0.143
99.66,-7.13,0.143
99.67,-7.06,0.143
99.67,-7.00,0.143
99.68,-6.93,0.143
99.69,-6.86,0.143
99.69,-6.80,0.143
99.70,-6.73,0.143
99.71,-6.66,0.143
99.71,-6.60,0.144
99.72,-6.53,0.144
99.73,-6.46,0.144
99.73,-6.40,0.144
99.74,-6.33,0.144
99.75,-6.26,0.144
99.75,-6.20,0.144
99.76,-6.13,0.144
99.77,-6.06,0.144
99.77,-6.00,0.144
99.78,-5.93,0.144
99.79,-5.86,0.144
99.79,-5.80,0.144
99.80,-5.73,0.144
99.81,-5.66,0.144
99.81,-5.59,0.144
99.82,-5.53,0.144
99.83,-5.46,0.144
99.83,-5.40,0.144
99.84,-5.33,0.144
99.85,-5.26,0.144
99.85,-5.20,0.144
99.86,-5.13,0.145
99.87,-5.06,0.145
99.87,-4.99,0.145
99.88,-4.93,0.145
99.89,-4.86,0.145
99.89,-4.80,0.145
99.90,-4.73,0.145
99.91,-4.66,0.145
99.91,-4.59,0.145
99.92,-4.53,0.145
99.93,-4.46,0.145
99.93,-4.39,0.145
99.94,-4.33,0.145
99.95,-4.26,0.145
99.95,-4.19,0.145
99.96,-4.13,0.145
99.97,-4.06,0.145
99.97,-3.99,0.145
99.98,-3.93,0.145
99.99,-3.86,0.145
99.99,-3.79,0.145
100.00,-3.72,0.145
100.01,-3.66,0.145
100.01,-3.59,0.145
100.02,-3.52,0.145
100.03,-3.45,0.145
100.03,-3.39,0.145
100.04,-3.32,0.145
100.05,-3.25,0.146
100.05,-3.19,0.146
100.06,-3.12,0.146
100.07,-3.05,0.147
100.07,-2.99,0.147
100.08,-2.92,0.147
100.09,-2.85,0.148
100.09,-2.79,0.148
100.10,-2.72,0.149
100.11,-2.65,0.149
100.11,-2.59,0.149
100.12,-2.52,0.149
100.13,-2.45,0.149
100.13,-2.39,0.149
100.14,-2.32,0.149
100.15,-2.25,0.149
100.15,-2.19,0.149
100.16,-2.12,0.149
100.17,-2.05,0.149
100.17,-1.99,0.149
100.18,-1.92,0.149
100.19,-1.85,0.149
100.19,-1.78,0.149
100.20,-1.72,0.149
100.21,-1.65,0.149
100.21,-1.59,0.149
100.22,-1.52,0.149
100.23,-1.45,0.149
100.23,-1.38,0.149
100.24,-1.32,0.149
100.25,-1.25,0.149
100.25,-1.19,0.149
100.26,-1.12,0.149
100.27,-1.05,0.149
100.27,-0.99,0.149
100.28,-0.92,0.149
100.29,-0.85,0.150
100.29,-0.79,0.150
100.30,-0.72,0.150
100.31,-0.65,0.150
100.31,-0.59,0.150
100.32,-0.52,0.150
100.33,-0.45,0.150
100.33,-0.39,0.150
100.34,-0.32,0.150
100.35,-0.25,0.150
100.35,-0.19,0.150
100.36,-0.12,0.150
100.37,-0.05,0.150
100.37,0.01,0.150
100.38,0.08,0.150
100.39,0.15,0.150
100.39,0.21,0.150
100.40,0.28,0.150
100.41,0.35,0.150
100.41,0.41,0.150
100.42,0.48,0.150
100.43,0.55,0.150
100.43,0.61,0.150
100.44,0.68,0.150
100.45,0.75,0.150
100.45,0.82,0.150
100.46,0.88,0.150
100.47,0.95,0.150
100.47,1.01,0.150
100.48,1.08,0.150
100.49,1.15,0.150
100.49,1.21,0.151
100.50,1.28,0.151
100.51,1.35,0.151
100.51,1.41,0.151
100.52,1.48,0.151
100.53,1.55,0.151
100.53,1.61,0.151
100.54,1.68,0.151
100.55,1.75,0.151
100.55,1.81,0.151
100.56,1.88,0.151
100.57,1.95,0.151
100.57,2.01,0.151
100.58,2.08,0.151
100.59,2.15,0.151
100.59,2.21,0.151
100.60,2.28,0.151
100.61,2.35,0.152
100.61,2.41,0.152
100.62,2.48,0.152
100.63,2.55,0.152
100.63,2.61,0.152
100.64,2.68,0.152
100.65,2.75,0.152
100.65,2.81,0.152
100.66,2.88,0.152
100.67,2.95,0.152
100.67,3.01,0.152
100.68,3.08,0.152
100.69,3.15,0.152
100.69,3.21,0.152
100.70,3.28,0.152
100.71,3.35,0.153
100.71,3.41,0.153
100.72,3.48,0.153
100.73,3.55,0.153
100.73,3.62,0.153
100.74,3.68,0.153
100.75,3.75,0.153
100.75,3.81,0.153
100.76,3.88,0.153
100.77,3.95,0.153
100.77,4.01,0.153
100.78,4.08,0.154
100.79,4.15,0.154
100.79,4.21,0.154
100.80,4.28,0.154
100.81,4.35,0.154
100.81,4.41,0.154
100.82,4.48,0.154
100.83,4.55,0.155
100.83,4.61,0.155
100.84,4.68,0.155
100.85,4.75,0.155
100.85,4.81,0.155
100.86,4.88,0.155
100.87,4.95,0.156
100.87,5.01,0.156
100.88,5.08,0.156
100.89,5.15,0.156
100.89,5.21,0.156
100.90,5.28,0.156
100.91,5.35,0.156
100.91,5.41,0.156
100.92,5.48,0.156
100.93,5.55,0.157
100.93,5.61,0.157
100.94,5.68,0.157
100.95,5.75,0.157
100.95,5.81,0.157
100.96,5.88,0.157
100.97,5.95,0.158
100.97,6.01,0.158
100.98,6.08,0.158
100.99,6.15,0.158
100.99,6.21,0.158
101.00,6.28,0.158
101.01,6.35,0.158
101.01,6.41,0.158
101.02,6.48,0.159
101.03,6.55,0.159
101.03,6.61,0.159
101.04,6.68,0.160
101.05,6.75,0.160
101.05,6.81,0.160
101.06,6.88,0.160
101.07,6.94,0.160
101.07,7.01,0.161
101.08,7.08,0.161
101.09,7.14,0.161
101.09,7.21,0.161
101.10,7.28,0.162
101.11,7.34,0.162
101.11,7.41,0.162
101.12,7.48,0.162
101.13,7.54,0.163
101.13,7.61,0.163
101.14,7.68,0.163
101.15,7.75,0.163
101.15,7.81,0.164
101.16,7.88,0.164
101.17,7.94,0.164
101.17,8.01,0.165
101.18,8.08,0.165
101.19,8.14,0.165
101.19,8.21,0.165
101.20,8.28,0.166
101.21,8.34,0.166
101.21,8.41,0.166
101.22,8.48,0.167
101.23,8.54,0.167
101.23,8.61,0.167
101.24,8.67,0.167
101.25,8.74,0.168
101.25,8.81,0.168
101.26,8.87,0.168
101.27,8.94,0.169
101.27,9.01,0.169
101.28,9.07,0.169
101.29,9.14,0.170
101.29,9.21,0.170
101.30,9.27,0.171
101.31,9.34,0.171
101.31,9.41,0.171
101.32,9.47,0.172
101.33,9.54,0.173
101.33,9.61,0.173
101.34,9.67,0.173
101.35,9.74,0.174
101.35,9.81,0.175
101.36,9.87,0.175
101.37,9.94,0.175
101.37,10.01,0.176
101.38,10.07,0.176
101.39,10.14,0.176
101.39,10.21,0.177
101.40,10.27,0.178
101.41,10.34,0.178
101.41,10.40,0.179
101.42,10.47,0.179
101.43,10.54,0.180
101.43,10.60,0.180
101.44,10.67,0.181
101.45,10.74,0.181
101.45,10.80,0.182
101.46,10.87,0.182
101.47,10.94,0.182
101.47,11.00,0.183
101.48,11.07,0.184
101.49,11.13,0.184
101.49,11.20,0.185
101.50,11.27,0.185
101.51,11.33,0.186
101.51,11.40,0.187
101.52,11.47,0.187
101.53,11.53,0.188
101.53,11.60,0.188
101.54,11.66,0.189
101.55,11.73,0.191
101.55,11.80,0.191
101.56,11.86,0.192
101.57,11.93,0.193
101.57,12.00,0.193
101.58,12.06,0.194
101.59,12.13,0.195
101.59,12.19,0.195
101.60,12.26,0.196
101.61,12.33,0.196
101.61,12.39,0.197
101.62,12.46,0.198
101.63,12.53,0.198
101.63,12.59,0.200
101.64,12.66,0.201
101.65,12.72,0.201
101.65,12.79,0.202
101.66,12.86,0.203
101.67,12.92,0.205
101.67,12.99,0.205
101.68,13.06,0.205
101.69,13.12,0.206
101.69,13.19,0.208
101.70,13.26,0.209
101.71,13.32,0.209
101.71,13.39,0.210
101.72,13.45,0.211
101.73,13.52,0.211
101.73,13.59,0.212
101.74,13.65,0.213
101.75,13.72,0.214
101.75,13.78,0.215
101.76,13.85,0.216
101.77,13.92,0.217
101.77,13.98,0.218
101.78,14.05,0.218
101.79,14.11,0.219
101.79,14.18,0.220
101.80,14.25,0.221
101.81,14.31,0.222
101.81,14.38,0.222
101.82,14.44,0.224
101.83,14.51,0.224
101.83,14.58,0.225
101.84,14.64,0.225
101.85,14.71,0.226
101.85,14.78,0.227
101.86,14.84,0.228
101.87,14.91,0.229
101.87,14.97,0.229
101.88,15.04,0.230
101.89,15.11,0.230
101.89,15.17,0.231
101.90,15.24,0.231
101.91,15.30,0.232
101.91,15.37,0.233
101.92,15.44,0.233
101.93,15.50,0.234
101.93,15.57,0.234
101.94,15.64,0.235
101.95,15.70,0.235
101.95,15.77,0.235
101.96,15.83,0.235
101.97,15.90,0.236
101.97,15.97,0.236
101.98,16.03,0.236
101.99,16.10,0.236
101.99,16.17,0.237
102.00,16.23,0.237
102.01,16.30,0.237
102.01,16.37,0.237
102.02,16.43,0.237
102.03,16.50,0.237
102.03,16.57,0.237
102.04,16.63,0.237
102.05,16.70,0.237
102.05,16.77,0.237
102.06,16.83,0.238
102.07,16.90,0.238
102.07,16.97,0.238
102.08,17.03,0.238
102.09,17.10,0.238
102.09,17.17,0.238
102.10,17.23,0.238
102.11,17.30,0.238
102.11,17.36,0.238
102.12,17.43,0.238
102.13,17.50,0.238
102.13,17.57,0.238
102.14,17.63,0.237
102.15,17.70,0.237
102.15,17.77,0.237
102.16,17.83,0.237
102.17,17.90,0.236
102.17,17.97,0.236
102.18,18.03,0.236
102.19,18.10,0.235
102.19,18.17,0.235
102.20,18.24,0.234
102.21,18.30,0.234
102.21,18.37,0.234
102.22,18.43,0.234
102.23,18.50,0.234
102.23,18.57,0.234
102.24,18.64,0.234
102.25,18.70,0.233
102.25,18.77,0.233
102.26,18.84,0.233
102.27,18.91,0.233
102.27,18.97,0.233
102.28,19.04,0.233
102.29,19.11,0.232
102.29,19.17,0.232
102.30,19.24,0.232
102.31,19.31,0.232
102.31,19.37,0.231
102.32,19.44,0.231
102.33,19.51,0.231
102.33,19.57,0.230
102.34,19.64,0.230
102.35,19.71,0.230
102.35,19.78,0.230
102.36,19.84,0.230
102.37,19.91,0.230
102.37,19.98,0.229
102.38,20.04,0.229
102.39,20.11,0.229
102.39,20.18,0.229
102.40,20.24,0.229
102.41,20.31,0.229
102.41,20.38,0.229
102.42,20.44,0.229
102.43,20.51,0.229
102.43,20.58,0.229
102.44,20.64,0.229
102.45,20.71,0.228
102.45,20.78,0.228
102.46,20.84,0.228
102.47,20.91,0.228
102.47,20.98,0.228
102.48,21.05,0.228
102.49,21.11,0.228
102.49,21.18,0.228
102.50,21.25,0.228
102.51,21.31,0.228
102.51,21.38,0.228
102.52,21.45,0.228
102.53,21.51,0.228
102.53,21.58,0.228
102.54,21.65,0.228
102.55,21.71,0.227
102.55,21.78,0.227
102.56,21.85,0.227
102.57,21.91,0.227
102.57,21.98,0.227
102.58,22.05,0.227
102.59,22.11,0.227
102.59,22.18,0.227
102.60,22.25,0.227
102.61,22.31,0.227
102.61,22.38,0.227
102.62,22.45,0.227
102.63,22.51,0.227
102.63,22.58,0.227
102.64,22.65,0.227
102.65,22.72,0.227
102.65,22.78,0.227
102.66,22.85,0.227
102.67,22.92,0.226
102.67,22.98,0.226
102.68,23.05,0.226
102.69,23.12,0.226
102.69,23.18,0.226
102.70,23.25,0.226
102.71,23.32,0.226
102.71,23.38,0.226
102.72,23.45,0.226
102.73,23.52,0.226
102.73,23.58,0.226
102.74,23.65,0.226
102.75,23.72,0.226
102.75,23.79,0.226
102.76,23.85,0.226
102.77,23.92,0.226
102.77,23.99,0.226
102.78,24.05,0.226
102.79,24.12,0.226
102.79,24.19,0.226
102.80,24.25,0.226
102.81,24.32,0.226
102.81,24.39,0.226
102.82,24.45,0.226
102.83,24.52,0.226
102.83,24.59,0.226
102.84,24.65,0.226
102.85,24.72,0.226
102.85,24.79,0.226
102.86,24.85,0.226
102.87,24.92,0.226
102.87,24.99,0.226
102.88,25.05,0.226
102.89,25.12,0.226
102.89,25.18,0.226
102.90,25.25,0.226
102.91,25.32,0.226
102.91,25.39,0.226
102.92,25.45,0.226
102.93,25.52,0.226
102.93,25.59,0.226
102.94,25.65,0.226
102.95,25.72,0.226
102.95,25.79,0.226
102.96,25.85,0.226
102.97,25.92,0.226
102.97,25.99,0.226
102.98,26.05,0.226
102.99,26.12,0.226
102.99,26.19,0.226
103.00,26.25,0.226
103.01,26.32,0.226
103.01,26.39,0.226
103.02,26.45,0.226
103.03,26.52,0.226
103.03,26.59,0.226
103.04,26.66,0.226
103.05,26.72,0.226
103.05,26.79,0.226
103.06,26.86,0.226
103.07,26.92,0.226
103.07,26.99,0.226
103.08,27.06,0.226
103.09,27.12,0.226
103.09,27.19,0.226
103.10,27.26,0.226
103.11,27.32,0.226
103.11,27.39,0.226
103.12,27.46,0.226
103.13,27.52,0.226
103.13,27.59,0.226
103.14,27.66,0.226
103.15,27.72,0.226
103.15,27.79,
103.16,27.86,
103.17,27.92,
103.17,27.99,
103.18,28.06,
103.19,28.12,
103.19,28.19,
103.20,,
103.20,,