File: DSC/2025_04_13_THC_Pro_Slurry_Heptane_n60C_150C_10Cmin_x3.csv
Filename,2025_04_13_THC_Pro_Slurry_Heptane_n60C_150C_10Cmin_x3
Instrument name,DSC2A-00468 (192.168.1.100)
Operator,Yarger
rundate,4/13/2025
Sample name,2025_04_13_THC_Pro_Slurry_Heptane_n60C_150C_10Cmin_x3
proceduresegments,Data Off ; Equilibrate -60.00 °C; Data On ; Ramp 10.00 °C/min to 150.00 °C; Data Off ; Isothermal 1.0 min; Data On ; Ramp 10.00 °C/min to -60.00 °C; Data Off ; Isothermal 1.0 min; Data On ; Ramp 10.00 °C/min to 150.00 °C; Data Off ; Isothermal 1.0 min; Data On ; Ramp 10.00 °C/min to -60.00 °C; Data Off ; Isothermal 1.0 min; Data On ; Ramp 10.00 °C/min to 150.00 °C
[File Parameters]
Run date,4/13/2025 3:08:52 PM
Trios version,5.1.1.46572
Original File Name,D:\DSC2500\JYarger\2025_04_13_THC_Pro_Slurry_Heptane_n60C_150C_10Cmin_x3.tri
Current File Name,Y:\Files\Data\DSC\DSC2500\JYarger\2025_04_13_THC_Pro_Slurry_Heptane_n60C_150C_10Cmin_x3.tri
[Procedure]
Procedure Name,THC_Pro_n60_150C_10Cmin_x3
Sample Name,2025_04_13_THC_Pro_Slurry_Heptane_n60C_150C_10Cmin_x3
Sample Mass,2.81 mg
Reference Sample Mass,0 mg
Pan Mass,53.4 mg
Pan Number,48
Reference Pan Mass,53.32 mg
Reference Pan Number,10
Pan Type,Tzero Aluminum Hermetic
Comments,Hermetic Sealed Al DSC Consumables Pan/Lids.
Project Name,CA
Operator,Yarger
Test,Custom
Unload Max Temperature,30
Unload Min Temperature,30
Load Max Temperature,30
Load Min Temperature,30
Stop on Gas Flow Error,Yes
[Signal List]
Signal #1,Time (min)
Signal #2,Temperature (°C)
Signal #3,Heat Flow (mW)
Signal #4,Delta T (µV)
Signal #5,Delta Tzero (µV)
Signal #6,Tzero Temperature (°C)
Signal #7,Cell Purge (mL/min)
Signal #8,Heater Temp (°C)
Signal #9,Power Delivered (W)
Signal #10,Reference Junction Temperature (°C)
Signal #11,Flange Temperature (°C)
Signal #12,Heat Flow Phase (rad)
Signal #13,Total Heat Capacity (J/°C)
Signal #14,Heat Capacity (J/°C)
[Configuration]
Company Name,ASU
Instrument Name,DSC2A-00468
Instrument Type,DSC2500
Serial Number,DSC2A-00468
IP,192.168.1.100
Location of Instrument,MRRC
DisplayType,Unknown
Sample Interval ,0.1 s/pt
Selected Heat Flow,T4P
Exotherm Direction,Down
Cell Serial,DRC2-00792
Lid Type,Standard
Cooler,RCS 90
Leave Cooler on at End of Sequence,On
Gas 2,Nitrogen
Gas Selected,Channel 1
Flow Rate,50 mL/min
Secondary Purge,On
Licensed Heat Flow,Heat Flow T4P
Modulation Licensed,Yes
[Versions]
Common IDD Version,1
Cortex Version,VER 2.10.2.31
Driver,5.0.0.6
GDM Version,1.0.3.3
TouchscreenVersion,1.0.0.16145
FEP Version,1.2.1.21
FEP Bootloader,2.0.0.5
AutoSampler Version,2.1.1.26
Auto Sampler Bootloader,2.0.0.5
FCM Version,1.1.0.3
FCM Bootloader,2.0.0.5
[Experiment Logs]
Experiment Log Entry # 1,Data On set to 0
Experiment Log Entry # 3,Air Cool is off.
Experiment Log Entry # 5,Equilibrate Segment -60 (C) Started
Experiment Log Entry # 7,Data On set to 1
Experiment Log Entry # 9,Ramp Segment 10 C/min to 150 Started
Experiment Log Entry # 11,Data On set to 0
Experiment Log Entry # 13,Isothermal Segment 1 min started
Experiment Log Entry # 15,Data On set to 1
Experiment Log Entry # 17,Ramp Segment 10 C/min to -60 Started
Experiment Log Entry # 19,Data On set to 0
Experiment Log Entry # 21,Isothermal Segment 1 min started
Experiment Log Entry # 23,Data On set to 1
Experiment Log Entry # 25,Ramp Segment 10 C/min to 150 Started
Experiment Log Entry # 27,Data On set to 0
Experiment Log Entry # 29,Isothermal Segment 1 min started
Experiment Log Entry # 31,Data On set to 1
Experiment Log Entry # 33,Ramp Segment 10 C/min to -60 Started
Experiment Log Entry # 35,Data On set to 0
Experiment Log Entry # 37,Isothermal Segment 1 min started
Experiment Log Entry # 39,Data On set to 1
Experiment Log Entry # 41,Ramp Segment 10 C/min to 150 Started
[Method Log]
Method Log Entry # 1,Data Off
Method Log Entry # 2,Equilibrate -60 °C
Method Log Entry # 3,Data On
Method Log Entry # 4,(Ramp 463841) Ramp 10 °C/minute to 150 °C
Method Log Entry # 5,Data Off
Method Log Entry # 6,Isothermal 1 minutes
Method Log Entry # 7,Data On
Method Log Entry # 8,(Ramp 463845) Ramp 10 °C/minute to -60 °C
Method Log Entry # 9,Data Off
Method Log Entry # 10,Isothermal 1 minutes
Method Log Entry # 11,Data On
Method Log Entry # 12,(Ramp 463849) Ramp 10 °C/minute to 150 °C
Method Log Entry # 13,Data Off
Method Log Entry # 14,Isothermal 1 minutes
Method Log Entry # 15,Data On
Method Log Entry # 16,(Ramp 463853) Ramp 10 °C/minute to -60 °C
Method Log Entry # 17,Data Off
Method Log Entry # 18,Isothermal 1 minutes
Method Log Entry # 19,Data On
Method Log Entry # 20,(Ramp 463857) Ramp 10 °C/minute to 150 °C
Cell Serial,DRC2-00792
[T1 Calibration]
Slope,-0.008529666
Offset,9.636258
Initial Temperature,98.23
GUID,f8bfdadc-4977-4fdf-ba6d-0ba9134940c3
[TZero Calibration]
Date Applied,11/29/2022 4:06:13 PM
Description,From -89.059 °C to 396.009 °C at 20.000°C/min
Gas Type,Nitrogen
Pan Type,None
Source Files 1,C:\Users\yargerlab\Desktop\DSC Data\General\TZero_calibration_11_29_22_2nd(2).tri
Source Files 2,C:\Users\yargerlab\Desktop\DSC Data\General\TZero_calibration_11_29_22_2nd(3).tri
Delta T Offset,13.05235
Delta T Slope,-0.007271007
Delta T0 Offset,-13.69128
Delta T0 Slope,0.06063341
[Temperature Calibration]
Date Applied,11/29/2022 7:12:28 PM
Description,From 106.590 °C to 186.590 °C at 10.000°C/min
Gas Type,Nitrogen
Pan Type,Tzero Aluminum Hermetic
Source Files 1,C:\Users\yargerlab\Desktop\DSC Data\General\Indium(6).tri
Measured 1,157.391
Known 1,156.598
[Cell Constant Calibration]
Date Applied,11/29/2022 7:12:29 PM
Description,From 106.590 °C to 186.590 °C at 10.000°C/min
Gas Type,Nitrogen
Pan Type,Tzero Aluminum Hermetic
Source Files 1,C:\Users\yargerlab\Desktop\DSC Data\General\Indium(6).tri
T4P KCell,1.006051
Onset Slope,63.26126 mW/°C
[Direct Cp Calibration]
Date Applied,11/30/2022 11:04:51 AM
Description,From -79.983 °C to 298.409 °C at 10.000°C/min
Gas Type,Nitrogen
Pan Type,Tzero Aluminum Hermetic
Source Files 1,C:\Users\yargerlab\Desktop\DSC Data\General\Sapphire_Heat_Capacity_11_30_22.tri
[Rev Cp Calibration]
Date Applied,11/30/2022 1:58:51 PM
Description,From -79.996 °C to 292.812 °C at 3.000°C/min
Gas Type,Nitrogen
Pan Type,Tzero Aluminum Hermetic
Source Files 1,C:\Users\yargerlab\Desktop\DSC Data\General\Sapphire_MDSC_Calibration_11_30_22.tri
[step]
Ramp 10.00 °C/min to 150.00 °C
Time,Temperature,Heat Flow (Normalized)
min,°C,W/g
0.00,-59.69,-0.059
0.01,-59.70,-0.058
0.03,-59.71,-0.054
0.05,-59.71,-0.050
0.06,-59.70,-0.048
0.08,-59.69,-0.049
0.09,-59.66,-0.050
0.11,-59.62,-0.053
0.12,-59.56,-0.054
0.14,-59.49,-0.055
0.15,-59.41,-0.051
0.16,-59.32,-0.030
0.18,-59.22,-0.006
0.19,-59.11,0.014
0.21,-59.00,0.037
0.23,-58.88,0.060
0.24,-58.76,0.078
0.26,-58.63,0.094
0.27,-58.50,0.111
0.29,-58.37,0.124
0.30,-58.24,0.138
0.31,-58.10,0.146
0.33,-57.97,0.153
0.35,-57.83,0.162
0.36,-57.69,0.167
0.38,-57.56,0.173
0.39,-57.41,0.177
0.40,-57.27,0.181
0.42,-57.13,0.183
0.44,-56.99,0.186
0.45,-56.85,0.191
0.46,-56.71,0.193
0.48,-56.56,0.194
0.50,-56.42,0.195
0.51,-56.28,0.196
0.53,-56.13,0.198
0.54,-55.99,0.198
0.55,-55.84,0.200
0.57,-55.70,0.201
0.58,-55.55,0.201
0.60,-55.40,0.202
0.62,-55.26,0.202
0.63,-55.11,0.202
0.65,-54.97,0.203
0.66,-54.82,0.204
0.68,-54.68,0.204
0.69,-54.53,0.205
0.70,-54.38,0.205
0.72,-54.23,0.205
0.73,-54.09,0.206
0.75,-53.94,0.206
0.77,-53.79,0.207
0.78,-53.65,0.207
0.80,-53.50,0.207
0.81,-53.35,0.208
0.83,-53.20,0.208
0.84,-53.06,0.208
0.85,-52.91,0.209
0.87,-52.76,0.209
0.88,-52.61,0.209
0.90,-52.47,0.209
0.92,-52.32,0.210
0.93,-52.17,0.210
0.95,-52.02,0.210
0.96,-51.87,0.210
0.98,-51.72,0.210
0.99,-51.58,0.211
1.00,-51.43,0.211
1.02,-51.28,0.211
1.03,-51.13,0.211
1.05,-50.98,0.212
1.07,-50.83,0.212
1.08,-50.68,0.212
1.09,-50.54,0.212
1.11,-50.39,0.212
1.13,-50.24,0.212
1.14,-50.09,0.212
1.16,-49.94,0.212
1.17,-49.79,0.213
1.18,-49.64,0.213
1.20,-49.49,0.213
1.22,-49.34,0.213
1.23,-49.19,0.213
1.24,-49.05,0.213
1.26,-48.90,0.213
1.28,-48.75,0.213
1.29,-48.60,0.213
1.31,-48.45,0.213
1.32,-48.30,0.213
1.33,-48.15,0.214
1.35,-48.00,0.214
1.37,-47.85,0.214
1.38,-47.70,0.214
1.39,-47.55,0.214
1.41,-47.40,0.214
1.43,-47.25,0.214
1.44,-47.10,0.214
1.46,-46.95,0.214
1.47,-46.81,0.214
1.48,-46.65,0.214
1.50,-46.50,0.214
1.52,-46.35,0.214
1.53,-46.20,0.214
1.54,-46.06,0.214
1.56,-45.91,0.214
1.58,-45.76,0.214
1.59,-45.61,0.214
1.61,-45.46,0.214
1.62,-45.31,0.214
1.63,-45.16,0.214
1.65,-45.01,0.214
1.67,-44.86,0.214
1.68,-44.71,0.214
1.69,-44.56,0.214
1.71,-44.41,0.214
1.73,-44.26,0.214
1.74,-44.11,0.214
1.76,-43.96,0.214
1.77,-43.81,0.214
1.78,-43.66,0.214
1.80,-43.51,0.214
1.82,-43.36,0.214
1.83,-43.21,0.214
1.84,-43.06,0.214
1.86,-42.91,0.214
1.88,-42.76,0.214
1.89,-42.61,0.214
1.91,-42.46,0.214
1.92,-42.31,0.214
1.93,-42.16,0.214
1.95,-42.01,0.214
1.97,-41.86,0.214
1.98,-41.71,0.214
1.99,-41.56,0.214
2.01,-41.41,0.214
2.03,-41.26,0.214
2.04,-41.11,0.214
2.06,-40.96,0.214
2.07,-40.81,0.214
2.08,-40.66,0.214
2.10,-40.51,0.214
2.12,-40.36,0.214
2.13,-40.21,0.214
2.14,-40.06,0.214
2.16,-39.91,0.214
2.18,-39.76,0.214
2.19,-39.61,0.214
2.21,-39.46,0.214
2.22,-39.31,0.214
2.24,-39.16,0.214
2.25,-39.01,0.214
2.26,-38.86,0.214
2.28,-38.71,0.214
2.29,-38.56,0.214
2.31,-38.41,0.214
2.33,-38.26,0.214
2.34,-38.11,0.214
2.36,-37.96,0.214
2.37,-37.81,0.214
2.39,-37.65,0.214
2.40,-37.50,0.214
2.41,-37.35,0.214
2.43,-37.20,0.214
2.44,-37.05,0.214
2.46,-36.90,0.214
2.48,-36.76,0.214
2.49,-36.60,0.214
2.51,-36.45,0.214
2.52,-36.30,0.214
2.54,-36.15,0.214
2.55,-36.00,0.214
2.56,-35.85,0.214
2.58,-35.70,0.214
2.59,-35.55,0.214
2.61,-35.40,0.214
2.63,-35.25,0.214
2.64,-35.10,0.214
2.66,-34.95,0.214
2.67,-34.80,0.214
2.69,-34.65,0.214
2.70,-34.50,0.214
2.71,-34.35,0.214
2.73,-34.20,0.214
2.74,-34.05,0.214
2.76,-33.90,0.214
2.78,-33.75,0.214
2.79,-33.60,0.214
2.81,-33.45,0.214
2.82,-33.30,0.214
2.84,-33.15,0.214
2.85,-33.00,0.214
2.86,-32.85,0.214
2.88,-32.70,0.214
2.89,-32.55,0.214
2.91,-32.40,0.214
2.93,-32.25,0.214
2.94,-32.10,0.214
2.96,-31.95,0.214
2.97,-31.80,0.214
2.99,-31.65,0.214
3.00,-31.50,0.214
3.01,-31.35,0.214
3.03,-31.20,0.214
3.04,-31.05,0.214
3.06,-30.90,0.214
3.08,-30.75,0.214
3.09,-30.60,0.214
3.11,-30.45,0.214
3.12,-30.30,0.214
3.14,-30.15,0.214
3.15,-30.00,0.214
3.16,-29.85,0.214
3.18,-29.70,0.213
3.19,-29.55,0.214
3.21,-29.40,0.214
3.23,-29.25,0.214
3.24,-29.10,0.214
3.26,-28.95,0.214
3.27,-28.79,0.214
3.29,-28.64,0.214
3.30,-28.50,0.214
3.31,-28.34,0.214
3.33,-28.19,0.214
3.34,-28.04,0.214
3.36,-27.89,0.214
3.38,-27.74,0.214
3.39,-27.59,0.214
3.41,-27.44,0.214
3.42,-27.29,0.214
3.44,-27.14,0.214
3.45,-26.99,0.214
3.46,-26.84,0.214
3.48,-26.69,0.214
3.49,-26.54,0.214
3.51,-26.39,0.214
3.53,-26.24,0.214
3.54,-26.09,0.214
3.56,-25.94,0.214
3.57,-25.79,0.214
3.59,-25.64,0.214
3.60,-25.49,0.214
3.61,-25.34,0.214
3.63,-25.19,0.214
3.64,-25.04,0.214
3.66,-24.89,0.214
3.68,-24.74,0.214
3.69,-24.59,0.214
3.71,-24.44,0.214
3.72,-24.29,0.214
3.74,-24.14,0.214
3.75,-23.99,0.214
3.76,-23.84,0.214
3.78,-23.69,0.214
3.79,-23.54,0.214
3.81,-23.39,0.214
3.83,-23.24,0.214
3.84,-23.09,0.214
3.86,-22.94,0.214
3.87,-22.79,0.214
3.89,-22.64,0.214
3.90,-22.49,0.214
3.91,-22.34,0.214
3.93,-22.19,0.214
3.94,-22.04,0.214
3.96,-21.89,0.215
3.98,-21.74,0.215
3.99,-21.59,0.215
4.01,-21.44,0.215
4.02,-21.28,0.215
4.04,-21.14,0.215
4.05,-20.99,0.215
4.06,-20.84,0.215
4.08,-20.69,0.215
4.09,-20.53,0.215
4.11,-20.38,0.215
4.13,-20.23,0.215
4.14,-20.08,0.215
4.16,-19.93,0.215
4.17,-19.78,0.215
4.19,-19.63,0.215
4.20,-19.48,0.215
4.21,-19.33,0.215
4.23,-19.18,0.215
4.24,-19.03,0.215
4.26,-18.88,0.215
4.28,-18.73,0.215
4.29,-18.58,0.215
4.30,-18.43,0.215
4.32,-18.28,0.215
4.34,-18.13,0.215
4.35,-17.98,0.215
4.36,-17.83,0.215
4.38,-17.68,0.215
4.40,-17.53,0.215
4.41,-17.38,0.216
4.43,-17.23,0.216
4.44,-17.08,0.216
4.45,-16.93,0.216
4.47,-16.78,0.216
4.49,-16.63,0.216
4.50,-16.48,0.216
4.51,-16.33,0.216
4.53,-16.18,0.216
4.55,-16.03,0.216
4.56,-15.88,0.216
4.58,-15.73,0.216
4.59,-15.58,0.216
4.60,-15.43,0.216
4.62,-15.28,0.216
4.64,-15.13,0.216
4.65,-14.98,0.216
4.66,-14.83,0.216
4.68,-14.68,0.216
4.70,-14.53,0.216
4.71,-14.38,0.216
4.73,-14.23,0.216
4.74,-14.08,0.217
4.75,-13.93,0.216
4.77,-13.78,0.217
4.79,-13.63,0.217
4.80,-13.48,0.217
4.81,-13.33,0.217
4.83,-13.18,0.217
4.85,-13.03,0.217
4.86,-12.88,0.217
4.88,-12.73,0.217
4.89,-12.58,0.217
4.90,-12.43,0.217
4.92,-12.27,0.217
4.94,-12.12,0.217
4.95,-11.97,0.217
4.96,-11.83,0.217
4.98,-11.67,0.217
5.00,-11.52,0.217
5.01,-11.37,0.217
5.03,-11.22,0.217
5.04,-11.07,0.217
5.05,-10.92,0.217
5.07,-10.77,0.217
5.09,-10.62,0.217
5.10,-10.47,0.218
5.11,-10.32,0.218
5.13,-10.17,0.218
5.15,-10.02,0.218
5.16,-9.87,0.218
5.18,-9.72,0.218
5.19,-9.57,0.218
5.20,-9.42,0.218
5.22,-9.27,0.218
5.24,-9.12,0.218
5.25,-8.97,0.218
5.26,-8.82,0.218
5.28,-8.67,0.218
5.30,-8.52,0.218
5.31,-8.37,0.219
5.33,-8.22,0.218
5.34,-8.07,0.219
5.35,-7.92,0.219
5.37,-7.77,0.219
5.39,-7.62,0.219
5.40,-7.47,0.219
5.41,-7.32,0.219
5.43,-7.17,0.219
5.45,-7.02,0.219
5.46,-6.87,0.219
5.48,-6.72,0.219
5.49,-6.57,0.219
5.50,-6.42,0.219
5.52,-6.27,0.219
5.54,-6.12,0.220
5.55,-5.97,0.220
5.56,-5.82,0.220
5.58,-5.67,0.220
5.60,-5.52,0.220
5.61,-5.37,0.220
5.63,-5.22,0.220
5.64,-5.07,0.220
5.65,-4.92,0.220
5.67,-4.77,0.220
5.69,-4.62,0.220
5.70,-4.47,0.220
5.71,-4.32,0.221
5.73,-4.17,0.221
5.75,-4.02,0.221
5.76,-3.87,0.221
5.78,-3.72,0.221
5.79,-3.57,0.221
5.80,-3.42,0.221
5.82,-3.27,0.221
5.84,-3.12,0.221
5.85,-2.96,0.221
5.86,-2.81,0.221
5.88,-2.66,0.221
5.90,-2.51,0.221
5.91,-2.36,0.221
5.93,-2.21,0.221
5.94,-2.06,0.221
5.95,-1.91,0.222
5.97,-1.76,0.222
5.99,-1.61,0.222
6.00,-1.46,0.222
6.01,-1.31,0.222
6.03,-1.16,0.222
6.05,-1.01,0.222
6.06,-0.86,0.222
6.08,-0.71,0.222
6.09,-0.56,0.222
6.10,-0.41,0.222
6.12,-0.26,0.223
6.14,-0.11,0.223
6.15,0.04,0.223
6.16,0.19,0.223
6.18,0.34,0.223
6.20,0.49,0.223
6.21,0.64,0.223
6.23,0.79,0.223
6.24,0.94,0.223
6.25,1.09,0.223
6.27,1.24,0.223
6.29,1.39,0.223
6.30,1.54,0.223
6.31,1.69,0.224
6.33,1.84,0.224
6.35,1.99,0.224
6.36,2.14,0.224
6.38,2.29,0.224
6.39,2.44,0.224
6.40,2.59,0.224
6.42,2.74,0.224
6.44,2.89,0.224
6.45,3.04,0.224
6.46,3.19,0.224
6.48,3.34,0.224
6.50,3.49,0.224
6.51,3.64,0.224
6.53,3.79,0.225
6.54,3.95,0.225
6.55,4.10,0.225
6.57,4.25,0.225
6.59,4.39,0.225
6.60,4.54,0.225
6.61,4.69,0.225
6.63,4.85,0.225
6.65,4.99,0.225
6.66,5.15,0.225
6.68,5.30,0.225
6.69,5.44,0.225
6.70,5.60,0.226
6.72,5.75,0.226
6.74,5.90,0.226
6.75,6.05,0.226
6.76,6.20,0.226
6.78,6.35,0.226
6.80,6.50,0.226
6.81,6.65,0.226
6.83,6.80,0.226
6.84,6.95,0.226
6.85,7.10,0.227
6.87,7.25,0.227
6.89,7.40,0.227
6.90,7.55,0.227
6.91,7.70,0.227
6.93,7.85,0.227
6.95,8.00,0.227
6.96,8.15,0.227
6.98,8.30,0.227
6.99,8.45,0.227
7.00,8.60,0.227
7.02,8.75,0.228
7.04,8.90,0.228
7.05,9.05,0.228
7.06,9.20,0.228
7.08,9.35,0.228
7.10,9.50,0.228
7.11,9.65,0.228
7.13,9.80,0.228
7.14,9.95,0.228
7.15,10.10,0.228
7.17,10.25,0.228
7.19,10.40,0.229
7.20,10.55,0.229
7.21,10.70,0.229
7.23,10.85,0.229
7.25,11.00,0.229
7.26,11.15,0.229
7.28,11.30,0.229
7.29,11.45,0.230
7.30,11.60,0.230
7.32,11.75,0.230
7.34,11.90,0.230
7.35,12.05,0.230
7.36,12.20,0.230
7.38,12.35,0.230
7.40,12.50,0.230
7.41,12.65,0.230
7.43,12.80,0.230
7.44,12.95,0.231
7.45,13.10,0.231
7.47,13.26,0.231
7.49,13.40,0.231
7.50,13.56,0.231
7.51,13.70,0.231
7.53,13.85,0.231
7.55,14.01,0.231
7.56,14.16,0.232
7.58,14.30,0.232
7.59,14.46,0.232
7.60,14.61,0.232
7.62,14.76,0.232
7.64,14.91,0.232
7.65,15.06,0.232
7.66,15.21,0.232
7.68,15.36,0.232
7.70,15.51,0.233
7.71,15.66,0.233
7.73,15.81,0.233
7.74,15.96,0.233
7.75,16.11,0.233
7.77,16.26,0.233
7.79,16.41,0.233
7.80,16.56,0.233
7.81,16.71,0.233
7.83,16.86,0.233
7.85,17.01,0.234
7.86,17.16,0.234
7.88,17.31,0.234
7.89,17.46,0.234
7.90,17.61,0.234
7.92,17.76,0.234
7.94,17.91,0.234
7.95,18.06,0.234
7.96,18.21,0.234
7.98,18.36,0.234
8.00,18.51,0.234
8.01,18.66,0.234
8.03,18.81,0.234
8.04,18.96,0.234
8.05,19.11,0.234
8.07,19.26,0.235
8.09,19.41,0.235
8.10,19.56,0.235
8.11,19.71,0.235
8.13,19.86,0.235
8.15,20.01,0.235
8.16,20.16,0.235
8.18,20.31,0.236
8.19,20.46,0.236
8.20,20.61,0.236
8.22,20.76,0.236
8.24,20.91,0.236
8.25,21.06,0.236
8.26,21.21,0.237
8.28,21.36,0.237
8.30,21.51,0.237
8.31,21.66,0.237
8.33,21.81,0.237
8.34,21.96,0.237
8.35,22.11,0.237
8.37,22.26,0.237
8.39,22.41,0.238
8.40,22.56,0.238
8.41,22.71,0.238
8.43,22.86,0.238
8.45,23.01,0.238
8.46,23.16,0.238
8.48,23.31,0.238
8.49,23.46,0.238
8.50,23.62,0.238
8.52,23.77,0.239
8.53,23.92,0.239
8.55,24.07,0.239
8.57,24.22,0.239
8.58,24.36,0.239
8.60,24.52,0.239
8.61,24.67,0.239
8.63,24.82,0.239
8.64,24.97,0.240
8.65,25.11,0.240
8.67,25.27,0.240
8.68,25.42,0.240
8.70,25.57,0.240
8.72,25.72,0.241
8.73,25.87,0.241
8.75,26.02,0.241
8.76,26.17,0.241
8.78,26.32,0.241
8.79,26.47,0.241
8.80,26.62,0.241
8.82,26.77,0.241
8.83,26.92,0.242
8.85,27.07,0.242
8.87,27.22,0.242
8.88,27.37,0.242
8.90,27.52,0.242
8.91,27.67,0.243
8.93,27.82,0.243
8.94,27.97,0.243
8.95,28.12,0.243
8.97,28.27,0.243
8.98,28.42,0.243
9.00,28.57,0.243
9.02,28.72,0.243
9.03,28.87,0.244
9.05,29.02,0.244
9.06,29.17,0.244
9.08,29.32,0.244
9.09,29.47,0.244
9.10,29.62,0.244
9.12,29.77,0.245
9.13,29.92,0.245
9.15,30.07,0.245
9.17,30.22,0.245
9.18,30.37,0.245
9.20,30.52,0.245
9.21,30.67,0.245
9.23,30.82,0.246
9.24,30.97,0.246
9.25,31.12,0.246
9.27,31.27,0.246
9.28,31.42,0.246
9.30,31.57,0.246
9.32,31.72,0.246
9.33,31.87,0.246
9.35,32.02,0.247
9.36,32.17,0.247
9.38,32.32,0.247
9.39,32.47,0.247
9.40,32.62,0.247
9.42,32.77,0.247
9.43,32.92,0.248
9.45,33.07,0.248
9.47,33.22,0.248
9.48,33.37,0.248
9.50,33.52,0.248
9.51,33.67,0.248
9.53,33.83,0.248
9.54,33.98,0.248
9.55,34.13,0.249
9.57,34.28,0.249
9.58,34.43,0.249
9.60,34.58,0.249
9.62,34.73,0.249
9.63,34.88,0.249
9.65,35.03,0.250
9.66,35.18,0.250
9.68,35.33,0.250
9.69,35.48,0.250
9.70,35.63,0.250
9.72,35.78,0.250
9.73,35.93,0.250
9.75,36.08,0.250
9.77,36.23,0.251
9.78,36.38,0.251
9.80,36.53,0.251
9.81,36.68,0.251
9.83,36.83,0.251
9.84,36.98,0.251
9.85,37.13,0.251
9.87,37.28,0.252
9.88,37.43,0.252
9.90,37.58,0.252
9.92,37.73,0.252
9.93,37.88,0.252
9.95,38.03,0.252
9.96,38.18,0.253
9.98,38.33,0.253
9.99,38.48,0.253
10.00,38.63,0.253
10.02,38.78,0.253
10.03,38.93,0.253
10.05,39.08,0.253
10.07,39.23,0.253
10.08,39.38,0.254
10.10,39.53,0.254
10.11,39.68,0.254
10.13,39.83,0.254
10.14,39.98,0.254
10.15,40.13,0.254
10.17,40.28,0.255
10.18,40.43,0.255
10.20,40.58,0.255
10.22,40.73,0.255
10.23,40.88,0.255
10.25,41.03,0.255
10.26,41.18,0.255
10.28,41.33,0.256
10.29,41.48,0.256
10.30,41.63,0.256
10.32,41.78,0.256
10.33,41.93,0.256
10.35,42.08,0.256
10.37,42.23,0.256
10.38,42.38,0.256
10.40,42.54,0.257
10.41,42.68,0.257
10.43,42.84,0.257
10.44,42.99,0.257
10.45,43.14,0.257
10.47,43.28,0.257
10.48,43.43,0.257
10.50,43.59,0.258
10.52,43.74,0.258
10.53,43.88,0.258
10.55,44.04,0.258
10.56,44.19,0.258
10.58,44.34,0.259
10.59,44.49,0.259
10.60,44.64,0.259
10.62,44.79,0.259
10.63,44.94,0.259
10.65,45.09,0.259
10.67,45.24,0.259
10.68,45.39,0.260
10.70,45.54,0.260
10.71,45.69,0.260
10.73,45.84,0.260
10.74,45.99,0.260
10.75,46.14,0.260
10.77,46.29,0.260
10.78,46.44,0.260
10.80,46.59,0.261
10.82,46.74,0.261
10.83,46.89,0.261
10.85,47.04,0.261
10.86,47.19,0.261
10.88,47.34,0.261
10.89,47.49,0.261
10.90,47.64,0.262
10.92,47.79,0.262
10.93,47.94,0.262
10.95,48.09,0.262
10.97,48.24,0.262
10.98,48.39,0.262
11.00,48.54,0.263
11.01,48.69,0.263
11.03,48.84,0.263
11.04,48.99,0.263
11.05,49.14,0.263
11.07,49.29,0.263
11.08,49.44,0.264
11.10,49.59,0.264
11.12,49.74,0.264
11.13,49.89,0.264
11.15,50.04,0.264
11.16,50.19,0.264
11.18,50.34,0.264
11.19,50.49,0.265
11.20,50.64,0.265
11.22,50.79,0.265
11.23,50.94,0.265
11.25,51.09,0.265
11.27,51.24,0.265
11.28,51.39,0.266
11.30,51.54,0.266
11.31,51.69,0.266
11.33,51.84,0.266
11.34,51.99,0.266
11.35,52.14,0.266
11.37,52.29,0.266
11.38,52.44,0.267
11.40,52.59,0.267
11.42,52.74,0.267
11.43,52.89,0.267
11.45,53.04,0.267
11.46,53.19,0.267
11.48,53.34,0.268
11.49,53.49,0.268
11.50,53.64,0.268
11.52,53.79,0.268
11.53,53.94,0.268
11.55,54.10,0.268
11.57,54.24,0.269
11.58,54.40,0.269
11.60,54.55,0.269
11.61,54.69,0.269
11.63,54.85,0.269
11.64,55.00,0.269
11.65,55.15,0.269
11.67,55.30,0.270
11.68,55.45,0.270
11.70,55.60,0.270
11.72,55.75,0.270
11.73,55.90,0.270
11.75,56.05,0.270
11.76,56.20,0.271
11.78,56.35,0.271
11.79,56.50,0.271
11.80,56.65,0.271
11.82,56.80,0.271
11.83,56.95,0.271
11.85,57.10,0.271
11.87,57.25,0.272
11.88,57.40,0.272
11.90,57.55,0.272
11.91,57.70,0.272
11.93,57.85,0.272
11.94,58.00,0.272
11.95,58.15,0.272
11.97,58.30,0.273
11.98,58.45,0.273
12.00,58.60,0.273
12.02,58.75,0.273
12.03,58.90,0.273
12.05,59.05,0.273
12.06,59.20,0.274
12.08,59.35,0.274
12.09,59.50,0.274
12.10,59.65,0.274
12.12,59.80,0.274
12.13,59.95,0.274
12.15,60.10,0.274
12.17,60.25,0.274
12.18,60.40,0.275
12.20,60.55,0.275
12.21,60.70,0.275
12.23,60.85,0.275
12.24,61.00,0.276
12.25,61.15,0.276
12.27,61.30,0.276
12.28,61.45,0.276
12.30,61.60,0.276
12.32,61.75,0.276
12.33,61.90,0.276
12.35,62.05,0.276
12.36,62.20,0.277
12.38,62.35,0.277
12.39,62.50,0.277
12.40,62.65,0.277
12.42,62.80,0.277
12.43,62.95,0.278
12.45,63.10,0.278
12.47,63.25,0.278
12.48,63.40,0.278
12.50,63.55,0.278
12.51,63.70,0.278
12.53,63.85,0.279
12.54,64.00,0.279
12.55,64.15,0.279
12.57,64.30,0.279
12.58,64.46,0.279
12.60,64.60,0.279
12.62,64.76,0.280
12.63,64.90,0.280
12.65,65.06,0.280
12.66,65.21,0.280
12.68,65.36,0.280
12.69,65.51,0.280
12.70,65.66,0.281
12.72,65.81,0.281
12.73,65.96,0.281
12.75,66.11,0.281
12.77,66.26,0.281
12.78,66.41,0.281
12.80,66.56,0.282
12.81,66.71,0.282
12.83,66.86,0.282
12.84,67.01,0.282
12.85,67.16,0.282
12.87,67.31,0.283
12.88,67.46,0.283
12.90,67.61,0.283
12.92,67.76,0.283
12.93,67.91,0.283
12.95,68.06,0.283
12.96,68.21,0.284
12.98,68.36,0.284
12.99,68.51,0.284
13.00,68.66,0.284
13.02,68.81,0.284
13.03,68.96,0.284
13.05,69.11,0.285
13.07,69.26,0.285
13.08,69.41,0.285
13.10,69.56,0.285
13.11,69.71,0.285
13.13,69.86,0.285
13.14,70.01,0.286
13.15,70.16,0.286
13.17,70.31,0.286
13.18,70.46,0.286
13.20,70.61,0.286
13.22,70.76,0.286
13.23,70.91,0.287
13.25,71.06,0.287
13.26,71.21,0.287
13.28,71.36,0.287
13.29,71.51,0.287
13.30,71.66,0.288
13.32,71.81,0.288
13.33,71.96,0.288
13.35,72.11,0.288
13.37,72.26,0.288
13.38,72.41,0.289
13.40,72.56,0.289
13.41,72.71,0.289
13.43,72.86,0.289
13.44,73.01,0.290
13.45,73.16,0.290
13.47,73.31,0.290
13.48,73.46,0.290
13.50,73.61,0.290
13.52,73.76,0.291
13.53,73.91,0.291
13.55,74.06,0.291
13.56,74.21,0.291
13.58,74.36,0.291
13.59,74.51,0.291
13.60,74.66,0.291
13.62,74.81,0.292
13.63,74.96,0.292
13.65,75.11,0.292
13.67,75.26,0.292
13.68,75.41,0.292
13.70,75.56,0.293
13.71,75.71,0.293
13.73,75.86,0.293
13.74,76.01,0.293
13.75,76.16,0.293
13.77,76.31,0.293
13.78,76.46,0.294
13.80,76.61,0.294
13.82,76.76,0.294
13.83,76.91,0.294
13.85,77.06,0.294
13.86,77.21,0.295
13.88,77.36,0.295
13.89,77.51,0.295
13.90,77.66,0.295
13.92,77.81,0.296
13.93,77.96,0.296
13.95,78.11,0.296
13.97,78.26,0.296
13.98,78.42,0.297
14.00,78.56,0.297
14.01,78.71,0.297
14.03,78.87,0.297
14.04,79.01,0.297
14.05,79.16,0.297
14.07,79.31,0.298
14.08,79.46,0.298
14.10,79.62,0.298
14.12,79.77,0.298
14.13,79.92,0.299
14.15,80.07,0.299
14.16,80.22,0.299
14.18,80.37,0.299
14.19,80.52,0.299
14.20,80.67,0.300
14.22,80.82,0.300
14.23,80.97,0.300
14.25,81.12,0.301
14.27,81.27,0.301
14.28,81.42,0.301
14.30,81.57,0.301
14.31,81.72,0.301
14.33,81.87,0.302
14.34,82.02,0.302
14.35,82.17,0.302
14.37,82.32,0.302
14.38,82.46,0.303
14.40,82.61,0.303
14.42,82.76,0.303
14.43,82.91,0.303
14.45,83.06,0.303
14.46,83.21,0.303
14.48,83.37,0.304
14.49,83.52,0.304
14.50,83.67,0.304
14.52,83.82,0.304
14.53,83.97,0.305
14.55,84.12,0.305
14.57,84.27,0.305
14.58,84.42,0.305
14.60,84.57,0.306
14.61,84.72,0.306
14.63,84.87,0.306
14.64,85.02,0.306
14.65,85.17,0.307
14.67,85.32,0.307
14.68,85.47,0.307
14.70,85.62,0.307
14.72,85.77,0.308
14.73,85.92,0.308
14.75,86.07,0.308
14.76,86.22,0.308
14.78,86.37,0.309
14.79,86.52,0.309
14.80,86.67,0.309
14.82,86.82,0.309
14.83,86.97,0.310
14.85,87.12,0.310
14.87,87.27,0.310
14.88,87.42,0.311
14.90,87.57,0.311
14.91,87.72,0.311
14.93,87.87,0.312
14.94,88.02,0.312
14.95,88.17,0.312
14.97,88.32,0.313
14.98,88.47,0.313
15.00,88.62,0.313
15.02,88.77,0.314
15.03,88.92,0.314
15.05,89.07,0.314
15.06,89.22,0.315
15.08,89.37,0.315
15.09,89.52,0.315
15.10,89.67,0.316
15.12,89.82,0.316
15.13,89.97,0.317
15.15,90.12,0.317
15.17,90.27,0.317
15.18,90.42,0.318
15.20,90.57,0.318
15.21,90.72,0.319
15.23,90.87,0.319
15.24,91.02,0.319
15.25,91.17,0.320
15.27,91.32,0.321
15.28,91.47,0.321
15.30,91.62,0.322
15.32,91.77,0.322
15.33,91.92,0.323
15.35,92.07,0.323
15.36,92.22,0.324
15.38,92.37,0.324
15.39,92.52,0.325
15.40,92.67,0.325
15.42,92.83,0.326
15.43,92.97,0.326
15.45,93.12,0.327
15.47,93.27,0.328
15.48,93.43,0.328
15.50,93.57,0.329
15.51,93.73,0.329
15.53,93.87,0.330
15.54,94.02,0.330
15.55,94.17,0.331
15.57,94.32,0.331
15.58,94.47,0.332
15.60,94.63,0.333
15.62,94.77,0.333
15.63,94.92,0.334
15.65,95.08,0.334
15.66,95.22,0.335
15.68,95.37,0.336
15.69,95.53,0.336
15.70,95.68,0.337
15.72,95.82,0.338
15.73,95.98,0.338
15.75,96.13,0.339
15.77,96.27,0.340
15.78,96.43,0.341
15.80,96.57,0.341
15.81,96.73,0.342
15.83,96.87,0.343
15.84,97.02,0.344
15.85,97.18,0.345
15.87,97.32,0.345
15.88,97.48,0.346
15.90,97.62,0.347
15.92,97.77,0.348
15.93,97.93,0.348
15.95,98.07,0.349
15.96,98.22,0.351
15.98,98.37,0.352
15.99,98.52,0.352
16.00,98.67,0.354
16.02,98.82,0.355
16.03,98.97,0.355
16.05,99.12,0.356
16.07,99.27,0.358
16.08,99.42,0.359
16.10,99.57,0.360
16.11,99.72,0.361
16.13,99.87,0.361
16.14,100.02,0.363
16.15,100.17,0.364
16.17,100.32,0.365
16.18,100.47,0.366
16.20,100.62,0.368
16.22,100.77,0.368
16.23,100.92,0.369
16.25,101.07,0.372
16.26,101.22,0.373
16.28,101.37,0.373
16.29,101.52,0.374
16.30,101.67,0.376
16.32,101.82,0.377
16.33,101.97,0.378
16.35,102.12,0.380
16.37,102.27,0.381
16.38,102.42,0.383
16.40,102.57,0.386
16.41,102.72,0.387
16.43,102.87,0.388
16.44,103.02,0.390
16.45,103.17,0.392
16.47,103.32,0.393
16.48,103.47,0.394
16.50,103.62,0.395
16.52,103.77,0.397
16.53,103.92,0.399
16.55,104.07,0.400
16.56,104.22,0.402
16.58,104.37,0.405
16.59,104.52,0.406
16.60,104.67,0.409
16.62,104.82,0.410
16.63,104.97,0.412
16.65,105.12,0.415
16.67,105.27,0.416
16.68,105.42,0.418
16.70,105.57,0.419
16.71,105.72,0.422
16.73,105.87,0.424
16.74,106.02,0.425
16.75,106.17,0.428
16.77,106.32,0.430
16.78,106.47,0.432
16.80,106.62,0.435
16.82,106.77,0.438
16.83,106.92,0.440
16.85,107.07,0.442
16.86,107.22,0.444
16.88,107.37,0.446
16.89,107.52,0.451
16.90,107.66,0.452
16.92,107.81,0.455
16.93,107.96,0.457
16.95,108.11,0.460
16.97,108.26,0.462
16.98,108.41,0.465
17.00,108.56,0.467
17.01,108.71,0.471
17.03,108.86,0.475
17.04,109.01,0.478
17.05,109.16,0.479
17.07,109.31,0.482
17.08,109.46,0.486
17.10,109.61,0.488
17.12,109.76,0.491
17.13,109.91,0.494
17.14,110.06,0.496
17.16,110.21,0.500
17.18,110.36,0.503
17.19,110.51,0.506
17.21,110.66,0.509
17.22,110.81,0.513
17.23,110.96,0.516
17.25,111.11,0.519
17.27,111.26,0.522
17.28,111.41,0.526
17.29,111.55,0.530
17.31,111.70,0.534
17.33,111.85,0.538
17.34,112.00,0.541
17.36,112.15,0.546
17.37,112.30,0.549
17.38,112.45,0.554
17.40,112.60,0.558
17.42,112.75,0.562
17.43,112.90,0.564
17.44,113.05,0.570
17.46,113.20,0.574
17.48,113.35,0.578
17.49,113.50,0.583
17.51,113.65,0.588
17.52,113.80,0.590
17.53,113.95,0.596
17.55,114.10,0.600
17.57,114.24,0.606
17.58,114.40,0.608
17.59,114.54,0.614
17.61,114.69,0.619
17.63,114.84,0.624
17.64,114.99,0.629
17.66,115.14,0.633
17.67,115.29,0.639
17.68,115.44,0.643
17.70,115.59,0.651
17.72,115.74,0.654
17.73,115.89,0.661
17.74,116.04,0.666
17.76,116.19,0.671
17.78,116.34,0.677
17.79,116.48,0.684
17.81,116.63,0.691
17.82,116.78,0.696
17.83,116.93,0.701
17.85,117.08,0.709
17.87,117.23,0.719
17.88,117.38,0.724
17.89,117.53,0.730
17.91,117.68,0.739
17.93,117.82,0.744
17.94,117.97,0.749
17.96,118.12,0.756
17.97,118.27,0.765
17.98,118.42,0.773
18.00,118.57,0.780
18.02,118.72,0.786
18.03,118.87,0.795
18.04,119.02,0.806
18.06,119.17,0.813
18.08,119.31,0.820
18.09,119.46,0.828
18.11,119.61,0.837
18.12,119.76,0.842
18.13,119.91,0.851
18.15,120.06,0.856
18.17,120.21,0.865
18.18,120.36,0.872
18.19,120.51,0.878
18.21,120.65,0.884
18.23,120.80,0.890
18.24,120.95,0.899
18.26,121.10,0.908
18.27,121.25,0.920
18.28,121.40,0.936
18.30,121.55,0.962
18.32,121.69,0.975
18.33,121.84,0.989
18.34,121.99,0.998
18.36,122.14,1.008
18.38,122.28,1.022
18.39,122.43,1.037
18.41,122.58,1.078
18.42,122.73,1.084
18.43,122.87,1.073
18.45,123.02,1.056
18.47,123.18,1.027
18.48,123.33,1.004
18.49,123.48,0.986
18.51,123.63,0.962
18.53,123.78,0.933
18.54,123.94,0.897
18.56,124.09,0.854
18.57,124.25,0.829
18.58,124.40,0.789
18.60,124.56,0.697
18.62,124.72,0.614
18.63,124.88,0.548
18.64,125.04,0.502
18.66,125.20,0.471
18.68,125.36,0.447
18.69,125.51,0.429
18.71,125.67,0.418
18.72,125.82,0.404
18.73,125.98,0.398
18.75,126.13,0.391
18.77,126.28,0.383
18.78,126.44,0.380
18.79,126.59,0.376
18.81,126.74,0.372
18.83,126.89,0.370
18.84,127.04,0.368
18.86,127.19,0.367
18.87,127.34,0.366
18.88,127.50,0.365
18.90,127.65,0.364
18.92,127.80,0.363
18.93,127.95,0.362
18.94,128.10,0.362
18.96,128.25,0.362
18.98,128.40,0.361
18.99,128.55,0.361
19.01,128.70,0.361
19.02,128.85,0.360
19.03,129.00,0.360
19.05,129.15,0.360
19.07,129.30,0.360
19.08,129.45,0.359
19.09,129.60,0.359
19.11,129.75,0.359
19.13,129.90,0.358
19.14,130.05,0.358
19.16,130.20,0.358
19.17,130.35,0.358
19.18,130.50,0.357
19.20,130.65,0.357
19.22,130.80,0.357
19.23,130.95,0.357
19.24,131.10,0.356
19.26,131.25,0.356
19.28,131.40,0.356
19.29,131.55,0.356
19.31,131.70,0.355
19.32,131.85,0.355
19.33,132.00,0.355
19.35,132.15,0.354
19.37,132.30,0.354
19.38,132.45,0.354
19.39,132.60,0.354
19.41,132.75,0.354
19.43,132.90,0.353
19.44,133.06,0.353
19.46,133.21,0.353
19.47,133.36,0.353
19.48,133.51,0.353
19.50,133.66,0.352
19.52,133.81,0.352
19.53,133.96,0.352
19.54,134.11,0.352
19.56,134.26,0.351
19.58,134.41,0.351
19.59,134.56,0.351
19.61,134.71,0.351
19.62,134.86,0.350
19.63,135.01,0.350
19.65,135.16,0.350
19.67,135.31,0.349
19.68,135.46,0.349
19.69,135.61,0.349
19.71,135.76,0.349
19.73,135.91,0.348
19.74,136.06,0.348
19.76,136.21,0.348
19.77,136.36,0.348
19.78,136.51,0.347
19.80,136.66,0.347
19.82,136.81,0.347
19.83,136.96,0.347
19.84,137.11,0.347
19.86,137.26,0.346
19.88,137.41,0.346
19.89,137.56,0.346
19.91,137.71,0.346
19.92,137.86,0.345
19.93,138.01,0.345
19.95,138.16,0.345
19.97,138.31,0.345
19.98,138.46,0.344
19.99,138.61,0.344
20.01,138.76,0.344
20.03,138.91,0.344
20.04,139.06,0.344
20.06,139.21,0.343
20.07,139.36,0.343
20.08,139.51,0.343
20.10,139.66,0.343
20.12,139.81,0.342
20.13,139.96,0.342
20.14,140.11,0.342
20.16,140.26,0.342
20.18,140.41,0.342
20.19,140.56,0.341
20.21,140.71,0.341
20.22,140.86,0.341
20.23,141.01,0.341
20.25,141.16,0.341
20.27,141.31,0.340
20.28,141.46,0.340
20.29,141.61,0.340
20.31,141.76,0.340
20.33,141.91,0.339
20.34,142.06,0.339
20.36,142.21,0.339
20.37,142.36,0.339
20.38,142.51,0.338
20.40,142.66,0.338
20.42,142.81,0.338
20.43,142.96,0.338
20.44,143.11,0.337
20.46,143.26,0.337
20.48,143.41,0.337
20.49,143.56,0.337
20.51,143.71,0.336
20.52,143.86,0.336
20.53,144.01,0.336
20.55,144.17,0.336
20.57,144.32,0.335
20.58,144.46,0.335
20.59,144.62,0.335
20.61,144.77,0.334
20.63,144.92,0.334
20.64,145.06,0.334
20.66,145.22,0.334
20.67,145.37,0.333
20.68,145.52,0.333
20.70,145.67,0.333
20.72,145.82,0.332
20.73,145.97,0.332
20.74,146.12,0.332
20.76,146.27,0.331
20.78,146.42,0.331
20.79,146.57,0.331
20.81,146.72,0.330
20.82,146.87,0.330
20.83,147.02,0.330
20.85,147.17,0.329
20.87,147.32,0.329
20.88,147.47,0.329
20.89,147.62,0.328
20.91,147.77,0.328
20.93,147.92,0.328
20.94,148.07,
20.96,148.22,
20.97,148.37,
20.98,,
20.99,,

[step]
Ramp 10.00 °C/min to -60.00 °C
Time,Temperature,Heat Flow (Normalized)
min,°C,W/g
21.99,150.10,-0.144
22.01,150.10,-0.145
22.02,150.10,-0.145
22.04,150.10,-0.145
22.05,150.08,-0.145
22.07,150.06,-0.145
22.08,150.02,-0.144
22.10,149.97,-0.150
22.11,149.91,-0.188
22.13,149.83,-0.229
22.14,149.73,-0.275
22.16,149.63,-0.321
22.17,149.52,-0.362
22.19,149.40,-0.401
22.20,149.28,-0.431
22.22,149.16,-0.456
22.23,149.03,-0.475
22.25,148.90,-0.493
22.26,148.76,-0.508
22.28,148.63,-0.517
22.29,148.49,-0.531
22.31,148.35,-0.539
22.32,148.21,-0.549
22.34,148.07,-0.555
22.35,147.93,-0.558
22.37,147.79,-0.562
22.38,147.64,-0.568
22.40,147.50,-0.570
22.41,147.35,-0.573
22.43,147.21,-0.574
22.44,147.06,-0.577
22.46,146.91,-0.580
22.47,146.77,-0.581
22.49,146.62,-0.582
22.50,146.47,-0.582
22.52,146.33,-0.583
22.53,146.18,-0.584
22.55,146.03,-0.584
22.56,145.89,-0.584
22.58,145.74,-0.584
22.59,145.59,-0.584
22.61,145.44,-0.585
22.62,145.29,-0.585
22.64,145.14,-0.585
22.65,145.00,-0.585
22.67,144.85,-0.586
22.68,144.70,-0.586
22.70,144.55,-0.586
22.71,144.40,-0.586
22.73,144.25,-0.586
22.74,144.11,-0.586
22.76,143.96,-0.586
22.77,143.81,-0.586
22.79,143.66,-0.586
22.80,143.51,-0.586
22.82,143.36,-0.586
22.83,143.22,-0.586
22.85,143.06,-0.586
22.86,142.92,-0.586
22.88,142.77,-0.586
22.89,142.62,-0.585
22.91,142.47,-0.585
22.92,142.32,-0.585
22.94,142.17,-0.585
22.95,142.02,-0.584
22.97,141.87,-0.584
22.98,141.73,-0.584
23.00,141.58,-0.584
23.01,141.43,-0.583
23.03,141.28,-0.583
23.04,141.13,-0.583
23.06,140.98,-0.582
23.07,140.83,-0.582
23.09,140.68,-0.582
23.10,140.53,-0.582
23.12,140.38,-0.581
23.13,140.23,-0.581
23.15,140.08,-0.580
23.16,139.93,-0.580
23.18,139.78,-0.580
23.19,139.63,-0.579
23.21,139.48,-0.579
23.22,139.34,-0.579
23.24,139.19,-0.578
23.25,139.04,-0.578
23.27,138.89,-0.578
23.28,138.74,-0.577
23.30,138.59,-0.577
23.31,138.44,-0.576
23.33,138.29,-0.576
23.34,138.14,-0.575
23.36,137.99,-0.575
23.37,137.84,-0.574
23.39,137.69,-0.574
23.40,137.54,-0.574
23.42,137.39,-0.573
23.43,137.24,-0.572
23.45,137.09,-0.572
23.46,136.94,-0.572
23.48,136.79,-0.571
23.49,136.64,-0.571
23.51,136.49,-0.571
23.52,136.34,-0.570
23.54,136.19,-0.570
23.55,136.05,-0.569
23.57,135.90,-0.569
23.58,135.75,-0.569
23.60,135.60,-0.568
23.61,135.45,-0.568
23.63,135.30,-0.567
23.64,135.15,-0.567
23.66,135.00,-0.566
23.67,134.85,-0.566
23.69,134.70,-0.565
23.70,134.55,-0.565
23.72,134.40,-0.564
23.73,134.25,-0.564
23.75,134.10,-0.564
23.76,133.95,-0.563
23.78,133.80,-0.563
23.79,133.65,-0.562
23.81,133.50,-0.562
23.82,133.35,-0.561
23.84,133.20,-0.561
23.85,133.05,-0.561
23.87,132.90,-0.560
23.88,132.75,-0.560
23.90,132.60,-0.559
23.91,132.45,-0.559
23.93,132.30,-0.558
23.94,132.15,-0.558
23.96,132.00,-0.558
23.97,131.85,-0.557
23.99,131.70,-0.557
24.00,131.55,-0.556
24.02,131.40,-0.556
24.03,131.25,-0.555
24.05,131.10,-0.555
24.06,130.95,-0.555
24.08,130.80,-0.554
24.09,130.65,-0.554
24.11,130.50,-0.553
24.12,130.35,-0.553
24.14,130.20,-0.553
24.15,130.05,-0.552
24.17,129.90,-0.552
24.18,129.75,-0.551
24.20,129.60,-0.551
24.21,129.45,-0.550
24.23,129.30,-0.550
24.24,129.15,-0.549
24.26,129.01,-0.549
24.27,128.85,-0.549
24.29,128.71,-0.548
24.30,128.55,-0.548
24.32,128.41,-0.547
24.33,128.26,-0.547
24.35,128.11,-0.547
24.36,127.96,-0.546
24.38,127.81,-0.545
24.39,127.66,-0.545
24.41,127.51,-0.545
24.42,127.36,-0.544
24.44,127.21,-0.544
24.45,127.06,-0.544
24.47,126.91,-0.543
24.48,126.76,-0.543
24.50,126.61,-0.543
24.51,126.46,-0.542
24.53,126.31,-0.542
24.54,126.16,-0.542
24.56,126.01,-0.541
24.57,125.86,-0.541
24.59,125.71,-0.541
24.60,125.56,-0.540
24.62,125.41,-0.540
24.63,125.26,-0.539
24.65,125.11,-0.539
24.66,124.96,-0.539
24.68,124.81,-0.538
24.69,124.66,-0.538
24.71,124.51,-0.538
24.72,124.36,-0.537
24.74,124.21,-0.537
24.75,124.06,-0.536
24.77,123.91,-0.536
24.78,123.76,-0.536
24.80,123.61,-0.536
24.81,123.46,-0.535
24.83,123.31,-0.535
24.84,123.16,-0.535
24.86,123.01,-0.534
24.87,122.86,-0.534
24.89,122.71,-0.533
24.90,122.56,-0.533
24.92,122.41,-0.533
24.93,122.26,-0.532
24.95,122.11,-0.532
24.96,121.96,-0.532
24.98,121.81,-0.531
24.99,121.66,-0.531
25.01,121.51,-0.531
25.02,121.36,-0.530
25.04,121.21,-0.530
25.05,121.06,-0.530
25.07,120.91,-0.530
25.08,120.76,-0.529
25.10,120.61,-0.529
25.11,120.46,-0.528
25.13,120.31,-0.528
25.14,120.16,-0.528
25.16,120.01,-0.528
25.17,119.86,-0.527
25.19,119.71,-0.527
25.20,119.56,-0.527
25.22,119.41,-0.527
25.23,119.26,-0.526
25.25,119.11,-0.526
25.26,118.96,-0.525
25.28,118.82,-0.525
25.29,118.67,-0.525
25.31,118.52,-0.524
25.32,118.37,-0.524
25.34,118.21,-0.524
25.35,118.07,-0.524
25.37,117.92,-0.523
25.38,117.77,-0.523
25.40,117.62,-0.523
25.41,117.46,-0.523
25.43,117.32,-0.522
25.44,117.17,-0.522
25.46,117.02,-0.522
25.47,116.87,-0.521
25.49,116.72,-0.521
25.50,116.57,-0.521
25.52,116.42,-0.520
25.53,116.27,-0.520
25.55,116.12,-0.520
25.56,115.97,-0.519
25.58,115.82,-0.519
25.59,115.67,-0.519
25.61,115.52,-0.518
25.62,115.37,-0.518
25.64,115.22,-0.518
25.65,115.07,-0.518
25.67,114.92,-0.517
25.68,114.77,-0.517
25.70,114.62,-0.517
25.71,114.47,-0.517
25.73,114.32,-0.516
25.74,114.17,-0.516
25.76,114.02,-0.516
25.77,113.87,-0.515
25.79,113.72,-0.515
25.80,113.57,-0.515
25.82,113.42,-0.515
25.83,113.27,-0.514
25.85,113.12,-0.514
25.86,112.97,-0.514
25.88,112.82,-0.514
25.89,112.67,-0.513
25.91,112.52,-0.513
25.92,112.37,-0.513
25.94,112.22,-0.513
25.95,112.07,-0.512
25.97,111.92,-0.512
25.98,111.77,-0.512
26.00,111.62,-0.512
26.01,111.47,-0.511
26.03,111.32,-0.511
26.04,111.17,-0.511
26.06,111.02,-0.510
26.07,110.87,-0.510
26.09,110.72,-0.510
26.10,110.57,-0.509
26.12,110.42,-0.509
26.13,110.27,-0.509
26.15,110.12,-0.509
26.16,109.97,-0.509
26.18,109.82,-0.508
26.19,109.67,-0.508
26.21,109.52,-0.507
26.22,109.37,-0.507
26.24,109.22,-0.507
26.25,109.07,-0.507
26.27,108.92,-0.506
26.28,108.77,-0.506
26.30,108.62,-0.506
26.31,108.47,-0.506
26.33,108.33,-0.506
26.34,108.18,-0.505
26.36,108.02,-0.505
26.37,107.87,-0.505
26.39,107.73,-0.505
26.40,107.58,-0.505
26.42,107.43,-0.504
26.43,107.28,-0.504
26.45,107.13,-0.504
26.46,106.98,-0.504
26.48,106.82,-0.503
26.49,106.68,-0.503
26.51,106.53,-0.503
26.52,106.38,-0.503
26.54,106.23,-0.503
26.55,106.08,-0.502
26.57,105.93,-0.502
26.58,105.78,-0.502
26.60,105.63,-0.502
26.61,105.48,-0.502
26.63,105.33,-0.501
26.64,105.18,-0.501
26.66,105.03,-0.501
26.67,104.88,-0.501
26.69,104.73,-0.500
26.70,104.58,-0.500
26.72,104.43,-0.500
26.73,104.28,-0.500
26.75,104.13,-0.499
26.76,103.98,-0.499
26.78,103.83,-0.499
26.79,103.68,-0.498
26.81,103.53,-0.498
26.82,103.38,-0.498
26.84,103.23,-0.498
26.85,103.08,-0.498
26.87,102.93,-0.498
26.88,102.78,-0.497
26.90,102.63,-0.497
26.91,102.48,-0.497
26.93,102.33,-0.497
26.94,102.18,-0.497
26.96,102.03,-0.496
26.97,101.88,-0.496
26.99,101.73,-0.496
27.00,101.58,-0.496
27.02,101.43,-0.495
27.03,101.28,-0.495
27.05,101.13,-0.495
27.06,100.98,-0.495
27.08,100.83,-0.495
27.09,100.68,-0.494
27.11,100.53,-0.494
27.12,100.38,-0.494
27.14,100.23,-0.494
27.15,100.08,-0.494
27.17,99.93,-0.493
27.18,99.78,-0.493
27.20,99.63,-0.493
27.21,99.48,-0.493
27.23,99.33,-0.493
27.24,99.18,-0.492
27.26,99.03,-0.492
27.27,98.88,-0.492
27.29,98.73,-0.492
27.30,98.58,-0.492
27.32,98.43,-0.491
27.33,98.28,-0.491
27.35,98.13,-0.491
27.36,97.98,-0.491
27.38,97.83,-0.491
27.39,97.68,-0.491
27.41,97.53,-0.491
27.42,97.38,-0.490
27.44,97.24,-0.490
27.45,97.09,-0.490
27.47,96.94,-0.490
27.48,96.79,-0.490
27.50,96.64,-0.489
27.51,96.49,-0.489
27.53,96.33,-0.489
27.54,96.19,-0.489
27.56,96.04,-0.489
27.57,95.89,-0.489
27.59,95.74,-0.488
27.60,95.59,-0.488
27.62,95.44,-0.488
27.63,95.29,-0.488
27.65,95.14,-0.487
27.66,94.99,-0.487
27.68,94.84,-0.487
27.69,94.69,-0.487
27.71,94.54,-0.486
27.72,94.39,-0.486
27.74,94.24,-0.486
27.75,94.09,-0.486
27.77,93.94,-0.486
27.78,93.79,-0.485
27.80,93.64,-0.485
27.81,93.49,-0.485
27.83,93.34,-0.485
27.84,93.19,-0.485
27.86,93.04,-0.484
27.87,92.89,-0.484
27.89,92.74,-0.484
27.90,92.59,-0.483
27.92,92.44,-0.483
27.93,92.29,-0.483
27.95,92.14,-0.483
27.96,91.99,-0.483
27.98,91.84,-0.482
27.99,91.69,-0.482
28.01,91.54,-0.482
28.02,91.39,-0.482
28.04,91.24,-0.482
28.05,91.09,-0.481
28.07,90.94,-0.481
28.08,90.79,-0.481
28.10,90.64,-0.481
28.11,90.49,-0.480
28.13,90.34,-0.480
28.14,90.19,-0.480
28.16,90.04,-0.480
28.17,89.89,-0.479
28.19,89.74,-0.479
28.20,89.59,-0.479
28.22,89.44,-0.479
28.23,89.29,-0.478
28.25,89.14,-0.478
28.26,88.99,-0.478
28.28,88.84,-0.478
28.29,88.69,-0.478
28.31,88.55,-0.477
28.32,88.39,-0.477
28.34,88.25,-0.477
28.35,88.09,-0.477
28.37,87.94,-0.476
28.38,87.80,-0.476
28.40,87.65,-0.476
28.41,87.49,-0.476
[...]
93.05,-11.05,0.280
93.06,-10.90,0.280
93.08,-10.75,0.281
93.09,-10.60,0.281
93.11,-10.45,0.282
93.12,-10.30,0.282
93.14,-10.15,0.282
93.15,-10.00,0.283
93.17,-9.85,0.283
93.18,-9.70,0.283
93.20,-9.55,0.284
93.21,-9.40,0.284
93.23,-9.25,0.284
93.24,-9.10,0.284
93.26,-8.95,0.285
93.27,-8.80,0.285
93.29,-8.65,0.285
93.30,-8.50,0.286
93.32,-8.35,0.286
93.33,-8.20,0.286
93.35,-8.05,0.287
93.36,-7.90,0.287
93.38,-7.75,0.287
93.39,-7.60,0.287
93.41,-7.45,0.288
93.42,-7.30,0.288
93.44,-7.15,0.288
93.45,-7.00,0.289
93.47,-6.85,0.289
93.48,-6.70,0.289
93.50,-6.55,0.289
93.51,-6.40,0.290
93.53,-6.25,0.290
93.54,-6.10,0.290
93.56,-5.95,0.290
93.57,-5.80,0.290
93.59,-5.65,0.290
93.60,-5.49,0.290
93.62,-5.34,0.291
93.63,-5.19,0.291
93.65,-5.05,0.291
93.66,-4.90,0.291
93.68,-4.74,0.291
93.69,-4.59,0.291
93.71,-4.44,0.291
93.72,-4.29,0.291
93.74,-4.15,0.292
93.75,-3.99,0.292
93.77,-3.84,0.292
93.78,-3.69,0.292
93.80,-3.54,0.292
93.81,-3.39,0.292
93.83,-3.24,0.292
93.84,-3.09,0.292
93.86,-2.94,0.292
93.87,-2.79,0.292
93.89,-2.64,0.293
93.90,-2.49,0.293
93.92,-2.34,0.293
93.93,-2.19,0.293
93.95,-2.04,0.293
93.96,-1.89,0.293
93.98,-1.74,0.293
93.99,-1.59,0.293
94.01,-1.44,0.293
94.02,-1.29,0.293
94.04,-1.14,0.293
94.05,-0.99,0.293
94.07,-0.84,0.293
94.08,-0.69,0.293
94.10,-0.54,0.293
94.11,-0.39,0.293
94.13,-0.24,0.293
94.14,-0.09,0.293
94.16,0.06,0.293
94.17,0.21,0.294
94.19,0.36,0.294
94.20,0.51,0.294
94.22,0.66,0.294
94.23,0.81,0.294
94.25,0.96,0.294
94.26,1.11,0.294
94.28,1.26,0.294
94.29,1.41,0.294
94.31,1.56,0.294
94.32,1.71,0.294
94.34,1.86,0.295
94.35,2.02,0.295
94.37,2.17,0.295
94.38,2.32,0.295
94.40,2.47,0.295
94.41,2.62,0.295
94.43,2.76,0.295
94.44,2.91,0.295
94.46,3.07,0.295
94.47,3.22,0.295
94.49,3.37,0.296
94.50,3.52,0.296
94.52,3.67,0.296
94.53,3.82,0.296
94.55,3.97,0.296
94.56,4.12,0.296
94.58,4.27,0.296
94.59,4.42,0.296
94.61,4.57,0.296
94.62,4.72,0.296
94.64,4.87,0.296
94.65,5.02,0.297
94.67,5.17,0.297
94.68,5.32,0.297
94.70,5.47,0.297
94.71,5.62,0.297
94.73,5.77,0.297
94.74,5.92,0.297
94.76,6.07,0.297
94.77,6.22,0.297
94.79,6.37,0.297
94.80,6.52,0.297
94.82,6.67,0.298
94.83,6.82,0.298
94.85,6.97,0.298
94.86,7.12,0.298
94.88,7.27,0.298
94.89,7.42,0.298
94.91,7.57,0.298
94.92,7.72,0.298
94.94,7.87,0.298
94.95,8.02,0.298
94.97,8.17,0.298
94.98,8.32,0.298
95.00,8.47,0.299
95.01,8.62,0.299
95.03,8.77,0.299
95.04,8.92,0.299
95.06,9.07,0.299
95.07,9.22,0.299
95.09,9.37,0.299
95.10,9.52,0.299
95.12,9.67,0.299
95.13,9.82,0.299
95.15,9.97,0.300
95.16,10.12,0.300
95.18,10.27,0.300
95.19,10.42,0.300
95.21,10.57,0.300
95.22,10.72,0.300
95.24,10.87,0.300
95.25,11.02,0.300
95.27,11.17,0.300
95.28,11.32,0.300
95.30,11.48,0.301
95.31,11.63,0.301
95.33,11.77,0.301
95.34,11.93,0.301
95.36,12.08,0.301
95.37,12.22,0.301
95.39,12.38,0.301
95.40,12.53,0.301
95.42,12.68,0.302
95.43,12.83,0.302
95.45,12.98,0.302
95.46,13.13,0.302
95.48,13.28,0.302
95.49,13.43,0.302
95.51,13.58,0.302
95.52,13.73,0.302
95.54,13.88,0.302
95.55,14.03,0.303
95.57,14.18,0.303
95.58,14.33,0.303
95.60,14.48,0.303
95.61,14.63,0.303
95.63,14.78,0.303
95.64,14.93,0.303
95.66,15.08,0.303
95.67,15.23,0.303
95.69,15.38,0.303
95.70,15.53,0.304
95.72,15.68,0.304
95.73,15.83,0.304
95.75,15.98,0.304
95.76,16.13,0.304
95.78,16.28,0.304
95.79,16.43,0.304
95.81,16.58,0.304
95.82,16.73,0.304
95.84,16.88,0.305
95.85,17.03,0.305
95.87,17.18,0.305
95.88,17.33,0.305
95.90,17.48,0.305
95.91,17.63,0.305
95.93,17.78,0.305
95.94,17.93,0.305
95.96,18.08,0.305
95.97,18.23,0.305
95.99,18.38,0.305
96.00,18.53,0.305
96.02,18.68,0.305
96.03,18.83,0.305
96.05,18.98,0.306
96.06,19.13,0.306
96.08,19.28,0.306
96.09,19.43,0.306
96.11,19.58,0.306
96.12,19.73,0.306
96.14,19.88,0.307
96.15,20.03,0.307
96.17,20.18,0.307
96.18,20.33,0.307
96.20,20.49,0.307
96.21,20.64,0.307
96.23,20.79,0.307
96.24,20.94,0.308
96.26,21.09,0.308
96.27,21.24,0.308
96.29,21.39,0.308
96.30,21.54,0.308
96.32,21.69,0.308
96.33,21.84,0.308
96.35,21.99,0.309
96.36,22.14,0.309
96.38,22.29,0.309
96.39,22.44,0.309
96.41,22.59,0.309
96.42,22.74,0.309
96.44,22.89,0.309
96.45,23.04,0.309
96.47,23.19,0.310
96.48,23.34,0.310
96.50,23.49,0.310
96.51,23.64,0.310
96.53,23.79,0.310
96.54,23.94,0.310
96.56,24.09,0.310
96.57,24.24,0.310
96.59,24.39,0.310
96.60,24.54,0.311
96.62,24.69,0.311
96.63,24.84,0.311
96.65,24.99,0.311
96.66,25.14,0.311
96.68,25.29,0.311
96.69,25.44,0.311
96.71,25.59,0.311
96.72,25.74,0.312
96.74,25.89,0.312
96.75,26.04,0.312
96.77,26.19,0.312
96.78,26.34,0.312
96.80,26.49,0.312
96.81,26.64,0.312
96.83,26.79,0.313
96.84,26.94,0.313
96.86,27.09,0.313
96.87,27.24,0.313
96.89,27.39,0.313
96.90,27.54,0.313
96.92,27.69,0.313
96.93,27.84,0.314
96.95,27.99,0.314
96.96,28.14,0.314
96.98,28.29,0.314
96.99,28.44,0.314
97.01,28.59,0.314
97.02,28.74,0.315
97.04,28.89,0.315
97.05,29.04,0.315
97.07,29.19,0.315
97.08,29.35,0.315
97.10,29.49,0.315
97.11,29.65,0.316
97.13,29.79,0.316
97.14,29.95,0.316
97.16,30.10,0.316
97.17,30.25,0.316
97.19,30.40,0.316
97.20,30.55,0.316
97.22,30.70,0.316
97.23,30.85,0.317
97.25,31.00,0.317
97.26,31.15,0.317
97.28,31.30,0.317
97.29,31.45,0.317
97.31,31.60,0.317
97.32,31.75,0.317
97.34,31.90,0.318
97.35,32.05,0.318
97.37,32.20,0.318
97.38,32.35,0.318
97.40,32.50,0.318
97.41,32.65,0.318
97.43,32.80,0.318
97.44,32.95,0.318
97.46,33.10,0.319
97.47,33.25,0.319
97.49,33.40,0.319
97.50,33.55,0.319
97.52,33.70,0.319
97.53,33.85,0.319
97.55,34.00,0.319
97.56,34.15,0.319
97.58,34.30,0.320
97.59,34.45,0.320
97.61,34.60,0.320
97.62,34.75,0.320
97.64,34.90,0.320
97.65,35.05,0.320
97.67,35.20,0.321
97.68,35.35,0.321
97.70,35.50,0.321
97.71,35.65,0.321
97.73,35.80,0.321
97.74,35.95,0.321
97.76,36.10,0.321
97.77,36.25,0.321
97.79,36.40,0.322
97.80,36.55,0.322
97.82,36.70,0.322
97.83,36.85,0.322
97.85,37.00,0.322
97.86,37.15,0.322
97.88,37.30,0.322
97.89,37.45,0.322
97.91,37.60,0.323
97.92,37.75,0.323
97.94,37.90,0.323
97.95,38.06,0.323
97.97,38.20,0.323
97.98,38.35,0.323
98.00,38.51,0.323
98.01,38.66,0.323
98.03,38.81,0.324
98.04,38.96,0.324
98.06,39.11,0.324
98.07,39.26,0.324
98.09,39.41,0.324
98.10,39.56,0.324
98.12,39.71,0.324
98.13,39.86,0.324
98.15,40.01,0.324
98.16,40.16,0.325
98.18,40.31,0.325
98.19,40.46,0.325
98.21,40.61,0.325
98.22,40.76,0.325
98.24,40.91,0.325
98.25,41.06,0.325
98.27,41.21,0.325
98.28,41.36,0.325
98.30,41.51,0.326
98.31,41.66,0.326
98.33,41.81,0.326
98.34,41.96,0.326
98.36,42.11,0.326
98.37,42.26,0.326
98.39,42.41,0.326
98.40,42.56,0.326
98.42,42.71,0.326
98.43,42.86,0.327
98.45,43.01,0.327
98.46,43.16,0.327
98.48,43.31,0.327
98.49,43.46,0.327
98.51,43.61,0.327
98.52,43.76,0.327
98.54,43.91,0.327
98.55,44.06,0.328
98.57,44.21,0.328
98.58,44.36,0.328
98.60,44.51,0.328
98.61,44.66,0.328
98.63,44.81,0.328
98.64,44.96,0.328
98.66,45.11,0.329
98.67,45.26,0.329
98.69,45.41,0.329
98.70,45.56,0.329
98.72,45.71,0.329
98.73,45.86,0.329
98.75,46.01,0.330
98.76,46.16,0.330
98.78,46.31,0.330
98.79,46.46,0.330
98.81,46.61,0.330
98.82,46.76,0.330
98.84,46.91,0.330
98.85,47.06,0.330
98.87,47.21,0.331
98.88,47.37,0.331
98.90,47.51,0.331
98.91,47.66,0.331
98.93,47.81,0.331
98.94,47.97,0.331
98.96,48.11,0.331
98.97,48.26,0.332
98.99,48.41,0.332
99.00,48.56,0.332
99.02,48.72,0.332
99.03,48.86,0.332
99.05,49.01,0.332
99.06,49.17,0.332
99.08,49.32,0.332
99.09,49.46,0.332
99.11,49.62,0.332
99.12,49.77,0.333
99.14,49.92,0.333
99.15,50.07,0.333
99.17,50.22,0.333
99.18,50.37,0.333
99.20,50.52,0.333
99.21,50.67,0.333
99.23,50.82,0.334
99.24,50.97,0.334
99.26,51.12,0.334
99.27,51.27,0.334
99.29,51.42,0.334
99.30,51.57,0.334
99.32,51.72,0.334
99.33,51.87,0.334
99.35,52.02,0.334
99.36,52.17,0.334
99.38,52.32,0.335
99.39,52.47,0.335
99.41,52.62,0.335
99.42,52.77,0.335
99.44,52.92,0.335
99.45,53.07,0.335
99.47,53.22,0.335
99.48,53.37,0.336
99.50,53.52,0.336
99.51,53.67,0.336
99.53,53.82,0.336
99.54,53.97,0.336
99.56,54.12,0.336
99.57,54.27,0.336
99.59,54.42,0.336
99.60,54.57,0.336
99.62,54.72,0.337
99.63,54.87,0.337
99.65,55.02,0.337
99.66,55.17,0.337
99.68,55.32,0.337
99.69,55.47,0.337
99.71,55.62,0.337
99.72,55.77,0.337
99.74,55.92,0.338
99.75,56.07,0.338
99.77,56.22,0.338
99.78,56.37,0.338
99.80,56.52,0.338
99.81,56.67,0.338
99.83,56.82,0.339
99.84,56.97,0.339
99.86,57.12,0.339
99.87,57.27,0.339
99.89,57.42,0.339
99.90,57.57,0.339
99.92,57.72,0.339
99.93,57.87,0.340
99.95,58.02,0.340
99.96,58.17,0.340
99.98,58.32,0.340
99.99,58.48,0.340
100.01,58.63,0.340
100.02,58.78,0.340
100.04,58.93,0.340
100.05,59.08,0.341
100.07,59.23,0.341
100.08,59.38,0.341
100.10,59.53,0.341
100.11,59.68,0.341
100.13,59.83,0.341
100.14,59.98,0.341
100.16,60.13,0.341
100.17,60.28,0.341
100.19,60.43,0.342
100.20,60.58,0.342
100.22,60.73,0.342
100.23,60.88,0.342
100.25,61.03,0.342
100.26,61.18,0.342
100.28,61.33,0.342
100.29,61.48,0.342
100.31,61.63,0.342
100.32,61.78,0.342
100.34,61.93,0.343
100.35,62.08,0.343
100.37,62.23,0.343
100.38,62.38,0.343
100.40,62.53,0.343
100.41,62.68,0.343
100.43,62.83,0.343
100.44,62.98,0.343
100.46,63.13,0.343
100.47,63.28,0.343
100.49,63.43,0.343
100.50,63.58,0.344
100.52,63.73,0.344
100.53,63.88,0.344
100.55,64.03,0.344
100.56,64.18,0.344
100.58,64.33,0.344
100.59,64.48,0.345
100.61,64.63,0.345
100.62,64.78,0.345
100.64,64.93,0.345
100.65,65.08,0.345
100.67,65.23,0.345
100.68,65.38,0.345
100.70,65.53,0.345
100.71,65.68,0.345
100.73,65.83,0.345
100.74,65.98,0.345
100.76,66.13,0.345
100.77,66.28,0.346
100.79,66.43,0.346
100.80,66.58,0.346
100.82,66.73,0.346
100.83,66.88,0.346
100.85,67.03,0.346
100.86,67.18,0.346
100.88,67.33,0.346
100.89,67.48,0.346
100.91,67.63,0.347
100.92,67.78,0.347
100.94,67.93,0.347
100.95,68.08,0.347
100.97,68.23,0.347
100.98,68.38,0.347
101.00,68.53,0.347
101.01,68.68,0.347
101.03,68.83,0.348
101.04,68.98,0.348
101.06,69.13,0.348
101.07,69.28,0.348
101.09,69.43,0.348
101.10,69.58,0.348
101.12,69.73,0.348
101.13,69.88,0.349
101.15,70.03,0.349
101.16,70.18,0.349
101.18,70.33,0.349
101.19,70.48,0.349
101.21,70.63,0.349
101.22,70.78,0.349
101.24,70.93,0.350
101.25,71.09,0.350
101.27,71.23,0.350
101.28,71.38,0.350
101.30,71.54,0.350
101.31,71.68,0.350
101.33,71.84,0.350
101.34,71.99,0.350
101.36,72.14,0.351
101.37,72.29,0.351
101.39,72.44,0.351
101.40,72.59,0.351
101.42,72.74,0.351
101.43,72.89,0.351
101.45,73.04,0.351
101.46,73.19,0.352
101.48,73.34,0.352
101.49,73.49,0.352
101.51,73.64,0.352
101.52,73.79,0.352
101.54,73.94,0.352
101.55,74.09,0.352
101.57,74.24,0.352
101.58,74.39,0.352
101.60,74.54,0.353
101.61,74.69,0.353
101.63,74.84,0.353
101.64,74.99,0.353
101.66,75.14,0.353
101.67,75.29,0.353
101.69,75.44,0.353
101.70,75.59,0.353
101.72,75.74,0.354
101.73,75.89,0.354
101.75,76.04,0.354
101.76,76.19,0.354
101.78,76.34,0.354
101.79,76.49,0.354
101.81,76.64,0.354
101.82,76.79,0.354
101.84,76.94,0.354
101.85,77.09,0.355
101.87,77.24,0.355
101.88,77.39,0.355
101.90,77.54,0.355
101.91,77.69,0.355
101.93,77.84,0.355
101.94,77.99,0.355
101.96,78.14,0.355
101.97,78.29,0.355
101.99,78.44,0.356
102.00,78.59,0.356
102.02,78.74,0.356
102.03,78.89,0.356
102.05,79.04,0.356
102.06,79.19,0.356
102.08,79.34,0.356
102.09,79.49,0.356
102.11,79.64,0.356
102.12,79.79,0.356
102.14,79.94,0.357
102.15,80.09,0.357
102.17,80.24,0.357
102.18,80.39,0.357
102.20,80.54,0.357
102.21,80.69,0.357
102.23,80.84,0.357
102.24,80.99,0.357
102.26,81.14,0.357
102.27,81.30,0.358
102.29,81.44,0.358
102.30,81.59,0.358
102.32,81.75,0.358
102.33,81.90,0.358
102.35,82.05,0.358
102.36,82.20,0.358
102.38,82.35,0.358
102.39,82.50,0.358
102.41,82.65,0.358
102.42,82.80,0.358
102.44,82.95,0.359
102.45,83.10,0.359
102.47,83.25,0.359
102.48,83.40,0.359
102.50,83.55,0.359
102.51,83.70,0.359
102.53,83.85,0.359
102.54,84.00,0.359
102.56,84.15,0.359
102.57,84.30,0.359
102.59,84.45,0.359
102.60,84.60,0.359
102.62,84.75,0.359
102.63,84.90,0.359
102.65,85.05,0.360
102.66,85.20,0.360
102.68,85.35,0.360
102.69,85.50,0.360
102.71,85.65,0.360
102.72,85.80,0.360
102.74,85.95,0.360
102.75,86.10,0.360
102.77,86.25,0.360
102.78,86.40,0.360
102.80,86.55,0.360
102.81,86.70,0.360
102.83,86.85,0.360
102.84,87.00,0.360
102.86,87.15,0.360
102.87,87.30,0.361
102.89,87.45,0.361
102.90,87.60,0.361
102.92,87.75,0.361
102.93,87.90,0.361
102.95,88.05,0.361
102.96,88.20,0.361
102.98,88.35,0.361
102.99,88.50,0.361
103.01,88.65,0.361
103.02,88.80,0.362
103.04,88.95,0.362
103.05,89.10,0.362
103.07,89.25,0.362
103.08,89.40,0.362
103.10,89.55,0.362
103.11,89.70,0.362
103.13,89.85,0.362
103.14,90.00,0.362
103.16,90.15,0.363
103.17,90.30,0.363
103.19,90.45,0.363
103.20,90.60,0.363
103.22,90.75,0.363
103.23,90.90,0.363
103.25,91.05,0.364
103.26,91.20,0.364
103.28,91.35,0.364
103.29,91.50,0.364
103.31,91.65,0.364
103.32,91.80,0.364
103.34,91.95,0.364
103.35,92.11,0.364
103.37,92.26,0.365
103.38,92.41,0.365
103.40,92.55,0.365
103.41,92.70,0.365
103.43,92.85,0.365
103.44,93.01,0.365
103.46,93.16,0.366
103.47,93.30,0.366
103.49,93.46,0.366
103.50,93.61,0.366
103.52,93.76,0.366
103.53,93.91,0.366
103.55,94.05,0.366
103.56,94.21,0.366
103.58,94.36,0.367
103.59,94.50,0.367
103.61,94.66,0.367
103.62,94.80,0.367
103.64,94.96,0.367
103.65,95.10,0.367
103.67,95.25,0.367
103.68,95.40,0.368
103.70,95.55,0.368
103.71,95.70,0.368
103.73,95.86,0.368
103.74,96.01,0.368
103.76,96.16,0.368
103.77,96.31,0.369
103.79,96.46,0.369
103.80,96.61,0.369
103.82,96.76,0.369
103.83,96.91,0.370
103.85,97.06,0.370
103.86,97.21,0.370
103.88,97.36,0.370
103.89,97.51,0.370
103.91,97.66,0.370
103.92,97.81,0.370
103.94,97.96,0.370
103.95,98.11,0.371
103.97,98.26,0.371
103.98,98.41,0.371
104.00,98.56,0.371
104.01,98.71,0.371
104.03,98.86,0.371
104.04,99.01,0.371
104.06,99.16,0.371
104.07,99.31,0.371
104.09,99.46,0.371
104.10,99.61,0.372
104.12,99.76,0.372
104.13,99.91,0.372
104.15,100.06,0.372
104.16,100.21,0.372
104.18,100.36,0.372
104.19,100.51,0.372
104.21,100.66,0.372
104.22,100.81,0.372
104.24,100.96,0.372
104.25,101.11,0.372
104.27,101.26,0.372
104.28,101.41,0.373
104.30,101.56,0.373
104.31,101.71,0.373
104.33,101.86,0.373
104.34,102.01,0.373
104.36,102.16,0.373
104.37,102.31,0.373
104.39,102.46,0.373
104.40,102.61,0.373
104.42,102.76,0.373
104.43,102.91,0.373
104.45,103.06,0.373
104.46,103.21,0.373
104.48,103.37,0.374
104.49,103.51,0.374
104.51,103.66,0.374
104.52,103.82,0.374
104.54,103.97,0.374
104.55,104.12,0.374
104.57,104.27,0.374
104.58,104.42,0.374
104.60,104.57,0.374
104.61,104.72,0.375
104.63,104.87,0.375
104.64,105.02,0.375
104.66,105.17,0.375
104.67,105.32,0.375
104.69,105.47,0.375
104.70,105.62,0.375
104.72,105.77,0.375
104.73,105.92,0.375
104.75,106.07,0.375
104.76,106.22,0.375
104.78,106.37,0.375
104.79,106.52,0.375
104.81,106.67,0.375
104.82,106.82,0.375
104.84,106.97,0.376
104.85,107.12,0.376
104.87,107.27,0.376
104.88,107.42,0.376
104.90,107.57,0.376
104.91,107.72,0.376
104.93,107.87,0.376
104.94,108.02,0.376
104.96,108.17,0.376
104.97,108.32,0.376
104.99,108.47,0.376
105.00,108.62,0.376
105.02,108.77,0.377
105.03,108.92,0.377
105.05,109.07,0.377
105.06,109.22,0.377
105.08,109.37,0.377
105.09,109.52,0.377
105.11,109.67,0.377
105.12,109.82,0.377
105.14,109.97,0.377
105.15,110.12,0.378
105.17,110.27,0.378
105.18,110.42,0.378
105.20,110.57,0.378
105.21,110.72,0.378
105.23,110.87,0.378
105.24,111.02,0.378
105.26,111.17,0.378
105.27,111.32,0.378
105.29,111.47,0.378
105.30,111.62,0.378
105.32,111.77,0.378
105.33,111.92,0.378
105.35,112.07,0.378
105.36,112.22,0.379
105.38,112.37,0.379
105.39,112.52,0.379
105.41,112.67,0.379
105.42,112.82,0.379
105.44,112.97,0.379
105.45,113.12,0.379
105.47,113.27,0.379
105.48,113.42,0.379
105.50,113.57,0.379
105.51,113.72,0.380
105.53,113.87,0.380
105.54,114.02,0.380
105.56,114.17,0.380
105.57,114.32,0.380
105.59,114.47,0.380
105.60,114.62,0.380
105.62,114.77,0.380
105.63,114.92,0.380
105.65,115.07,0.380
105.66,115.22,0.380
105.68,115.37,0.380
105.69,115.52,0.381
105.71,115.67,0.381
105.72,115.82,0.381
105.74,115.97,0.381
105.75,116.12,0.381
105.77,116.27,0.381
105.78,116.42,0.381
105.80,116.57,0.381
105.81,116.72,0.381
105.83,116.87,0.381
105.84,117.02,0.381
105.86,117.18,0.381
105.87,117.32,0.381
105.89,117.47,0.381
105.90,117.62,0.381
105.92,117.77,0.382
105.93,117.92,0.382
105.95,118.07,0.382
105.96,118.23,0.382
105.98,118.38,0.382
105.99,118.53,0.382
106.01,118.68,0.382
106.02,118.83,0.382
106.04,118.98,0.382
106.05,119.13,0.382
106.07,119.28,0.382
106.08,119.43,0.382
106.10,119.58,0.382
106.11,119.73,0.382
106.13,119.88,0.383
106.14,120.03,0.383
106.16,120.18,0.383
106.17,120.33,0.383
106.19,120.48,0.383
106.20,120.63,0.383
106.22,120.78,0.383
106.23,120.93,0.383
106.25,121.08,0.383
106.26,121.23,0.383
106.28,121.38,0.383
106.29,121.53,0.383
106.31,121.68,0.383
106.32,121.83,0.383
106.34,121.98,0.383
106.35,122.13,0.383
106.37,122.28,0.384
106.38,122.43,0.384
106.40,122.58,0.384
106.41,122.73,0.384
106.43,122.88,0.384
106.44,123.03,0.384
106.46,123.18,0.384
106.47,123.33,0.384
106.49,123.48,0.384
106.50,123.63,0.384
106.52,123.78,0.384
106.53,123.93,0.384
106.55,124.08,0.384
106.56,124.23,0.384
106.58,124.38,0.384
106.59,124.53,0.384
106.61,124.68,0.384
106.62,124.83,0.384
106.64,124.98,0.385
106.65,125.13,0.385
106.67,125.28,0.385
106.68,125.43,0.385
106.70,125.58,0.385
106.71,125.73,0.385
106.73,125.88,0.385
106.74,126.03,0.385
106.76,126.18,0.385
106.77,126.33,0.385
106.79,126.48,0.385
106.80,126.63,0.385
106.82,126.78,0.385
106.83,126.93,0.385
106.85,127.08,0.386
106.86,127.23,0.386
106.88,127.38,0.386
106.89,127.53,0.386
106.91,127.68,0.386
106.92,127.83,0.386
106.94,127.98,0.386
106.95,128.13,0.386
106.97,128.28,0.386
106.98,128.43,0.386
107.00,128.58,0.386
107.01,128.74,0.386
107.03,128.89,0.386
107.04,129.04,0.387
107.06,129.18,0.387
107.07,129.33,0.387
107.09,129.48,0.387
107.10,129.63,0.387
107.12,129.79,0.387
107.13,129.94,0.387
107.15,130.09,0.387
107.16,130.24,0.387
107.18,130.38,0.387
107.19,130.54,0.387
107.21,130.69,0.387
107.22,130.84,0.387
107.24,130.99,0.387
107.25,131.14,0.387
107.27,131.29,0.387
107.28,131.44,0.387
107.30,131.59,0.388
107.31,131.74,0.388
107.33,131.89,0.388
107.34,132.04,0.388
107.36,132.19,0.388
107.37,132.34,0.388
107.39,132.49,0.388
107.40,132.64,0.388
107.42,132.79,0.388
107.43,132.94,0.388
107.45,133.09,0.388
107.46,133.24,0.388
107.48,133.39,0.388
107.49,133.54,0.388
107.51,133.69,0.389
107.52,133.84,0.389
107.54,133.99,0.389
107.55,134.14,0.389
107.57,134.29,0.389
107.58,134.44,0.389
107.60,134.59,0.389
107.61,134.74,0.389
107.63,134.89,0.389
107.64,135.04,0.389
107.66,135.19,0.389
107.67,135.34,0.389
107.69,135.49,0.389
107.70,135.64,0.389
107.72,135.79,0.389
107.73,135.94,0.390
107.75,136.09,0.390
107.76,136.24,0.390
107.78,136.39,0.390
107.79,136.54,0.390
107.81,136.69,0.390
107.82,136.84,0.390
107.84,136.99,0.390
107.85,137.14,0.390
107.87,137.29,0.390
107.88,137.44,0.390
107.90,137.59,0.390
107.91,137.74,0.390
107.93,137.89,0.391
107.94,138.04,0.391
107.96,138.19,0.391
107.97,138.34,0.391
107.99,138.49,0.391
108.00,138.64,0.391
108.02,138.79,0.391
108.03,138.94,0.391
108.05,139.09,0.391
108.06,139.24,0.391
108.08,139.39,0.391
108.09,139.54,0.391
108.11,139.69,0.391
108.12,139.84,0.392
108.14,139.99,0.392
108.15,140.14,0.392
108.17,140.29,0.392
108.18,140.44,0.392
108.20,140.59,0.392
108.21,140.74,0.392
108.23,140.89,0.393
108.24,141.04,0.393
108.26,141.19,0.393
108.27,141.34,0.393
108.29,141.49,0.393
108.30,141.64,0.393
108.32,141.79,0.393
108.33,141.94,0.393
108.35,142.09,0.393
108.36,142.24,0.393
108.38,142.39,0.393
108.39,142.54,0.393
108.41,142.69,0.394
108.42,142.84,0.394
108.44,142.99,0.394
108.45,143.14,0.394
108.47,143.29,0.394
108.48,143.44,0.394
108.50,143.59,0.394
108.51,143.74,0.394
108.53,143.89,0.394
108.54,144.04,0.394
108.56,144.19,0.394
108.57,144.34,0.394
108.59,144.49,0.395
108.60,144.64,0.395
108.62,144.79,0.395
108.63,144.95,0.395
108.65,145.09,0.395
108.66,145.25,0.395
108.68,145.40,0.395
108.69,145.54,0.395
108.71,145.69,0.395
108.72,145.84,0.395
108.74,146.00,0.395
108.75,146.15,0.395
108.77,146.30,0.395
108.78,146.45,0.396
108.80,146.60,0.396
108.81,146.75,0.396
108.83,146.90,0.396
108.84,147.05,0.396
108.86,147.20,0.396
108.87,147.35,0.396
108.89,147.50,0.396
108.90,147.65,0.396
108.92,147.80,0.397
108.93,147.95,0.397
108.95,148.10,
108.96,148.25,
108.98,148.40,
108.99,,