File: DSC/2025_04_19_Sapphire_n60C_200C_10Cmin_x3.csv
Filename,2025_04_19_Sapphire_n60C_200C_10Cmin_x3
Instrument name,DSC2A-00468 (192.168.1.100)
Operator,Yarger
rundate,4/19/2025
Sample name,2025_04_19_Sapphire_n60C_200C_10Cmin_x3
proceduresegments,Data Off ; Equilibrate -60.00 °C; Data On ; Ramp 10.00 °C/min to 200.00 °C; Data Off ; Isothermal 0.1 min; Data On ; Ramp 10.00 °C/min to -60.00 °C; Data Off ; Isothermal 1.0 min; Data On ; Ramp 10.00 °C/min to 200.00 °C; Data Off ; Isothermal 0.1 min; Data On ; Ramp 10.00 °C/min to -60.00 °C; Data Off ; Isothermal 1.0 min; Data On ; Ramp 10.00 °C/min to 30.00 °C
[File Parameters]
Run date,4/19/2025 8:27:12 PM
Trios version,5.1.1.46572
Original File Name,
Current File Name,D:\DSC2500\JYarger\2025_04_19_Sapphire_n60C_200C_10Cmin_x3.tri
[Procedure]
Procedure Name,Sapphire_n60_200C_10Cmin_x3
Sample Name,2025_04_19_Sapphire_n60C_200C_10Cmin_x3
Sample Mass,23.5 mg
Reference Sample Mass,0 mg
Pan Mass,52.18 mg
Pan Number,2
Reference Pan Mass,53.66 mg
Reference Pan Number,46
Pan Type,Tzero Aluminum Hermetic
Comments,Hermetic Sealed Al DSC Consumables Pan/Lids.
Project Name,CA
Operator,Yarger
Test,Custom
Unload Max Temperature,30
Unload Min Temperature,30
Load Max Temperature,30
Load Min Temperature,30
Stop on Gas Flow Error,Yes
[Signal List]
Signal #1,Time (min)
Signal #2,Temperature (°C)
Signal #3,Heat Flow (mW)
Signal #4,Delta T (µV)
Signal #5,Delta Tzero (µV)
Signal #6,Tzero Temperature (°C)
Signal #7,Cell Purge (mL/min)
Signal #8,Heater Temp (°C)
Signal #9,Power Delivered (W)
Signal #10,Reference Junction Temperature (°C)
Signal #11,Flange Temperature (°C)
Signal #12,Heat Flow Phase (rad)
Signal #13,Total Heat Capacity (J/°C)
Signal #14,Heat Capacity (J/°C)
[Configuration]
Company Name,ASU
Instrument Name,DSC2A-00468
Instrument Type,DSC2500
Serial Number,DSC2A-00468
IP,192.168.1.100
Location of Instrument,MRRC
DisplayType,Unknown
Sample Interval ,0.1 s/pt
Selected Heat Flow,T4P
Exotherm Direction,Down
Cell Serial,DRC2-00792
Lid Type,Standard
Cooler,RCS 90
Leave Cooler on at End of Sequence,On
Gas 2,Nitrogen
Gas Selected,Channel 1
Flow Rate,50 mL/min
Secondary Purge,On
Licensed Heat Flow,Heat Flow T4P
Modulation Licensed,Yes
[Versions]
Common IDD Version,1
Cortex Version,VER 2.10.2.31
Driver,5.0.0.6
GDM Version,1.0.3.3
TouchscreenVersion,1.0.0.16145
FEP Version,1.2.1.21
FEP Bootloader,2.0.0.5
AutoSampler Version,2.1.1.26
Auto Sampler Bootloader,2.0.0.5
FCM Version,1.1.0.3
FCM Bootloader,2.0.0.5
[Experiment Logs]
Experiment Log Entry # 1,Data On set to 0
Experiment Log Entry # 3,Equilibrate Segment -60 (C) Started
Experiment Log Entry # 5,Data On set to 1
Experiment Log Entry # 7,Ramp Segment 10 C/min to 200 Started
Experiment Log Entry # 9,Data On set to 0
Experiment Log Entry # 11,Isothermal Segment 0.1 min started
Experiment Log Entry # 13,Data On set to 1
Experiment Log Entry # 15,Ramp Segment 10 C/min to -60 Started
Experiment Log Entry # 17,Data On set to 0
Experiment Log Entry # 19,Isothermal Segment 1 min started
Experiment Log Entry # 21,Data On set to 1
Experiment Log Entry # 23,Ramp Segment 10 C/min to 200 Started
Experiment Log Entry # 25,Data On set to 0
Experiment Log Entry # 27,Isothermal Segment 0.1 min started
Experiment Log Entry # 29,Data On set to 1
Experiment Log Entry # 31,Ramp Segment 10 C/min to -60 Started
Experiment Log Entry # 33,Data On set to 0
Experiment Log Entry # 35,Isothermal Segment 1 min started
Experiment Log Entry # 37,Data On set to 1
Experiment Log Entry # 39,Ramp Segment 10 C/min to 30 Started
[Method Log]
Method Log Entry # 1,Data Off
Method Log Entry # 2,Equilibrate -60 °C
Method Log Entry # 3,Data On
Method Log Entry # 4,(Ramp 399322) Ramp 10 °C/minute to 200 °C
Method Log Entry # 5,Data Off
Method Log Entry # 6,Isothermal 0.1 minutes
Method Log Entry # 7,Data On
Method Log Entry # 8,(Ramp 399326) Ramp 10 °C/minute to -60 °C
Method Log Entry # 9,Data Off
Method Log Entry # 10,Isothermal 1 minutes
Method Log Entry # 11,Data On
Method Log Entry # 12,(Ramp 399330) Ramp 10 °C/minute to 200 °C
Method Log Entry # 13,Data Off
Method Log Entry # 14,Isothermal 0.1 minutes
Method Log Entry # 15,Data On
Method Log Entry # 16,(Ramp 399334) Ramp 10 °C/minute to -60 °C
Method Log Entry # 17,Data Off
Method Log Entry # 18,Isothermal 1 minutes
Method Log Entry # 19,Data On
Method Log Entry # 20,(Ramp 399338) Ramp 10 °C/minute to 30 °C
Cell Serial,DRC2-00792
[T1 Calibration]
Slope,-0.008529666
Offset,9.636258
Initial Temperature,98.23
GUID,f8bfdadc-4977-4fdf-ba6d-0ba9134940c3
[TZero Calibration]
Date Applied,11/29/2022 4:06:13 PM
Description,From -89.059 °C to 396.009 °C at 20.000°C/min
Gas Type,Nitrogen
Pan Type,None
Source Files 1,C:\Users\yargerlab\Desktop\DSC Data\General\TZero_calibration_11_29_22_2nd(2).tri
Source Files 2,C:\Users\yargerlab\Desktop\DSC Data\General\TZero_calibration_11_29_22_2nd(3).tri
Delta T Offset,13.05235
Delta T Slope,-0.007271007
Delta T0 Offset,-13.69128
Delta T0 Slope,0.06063341
[Temperature Calibration]
Date Applied,11/29/2022 7:12:28 PM
Description,From 106.590 °C to 186.590 °C at 10.000°C/min
Gas Type,Nitrogen
Pan Type,Tzero Aluminum Hermetic
Source Files 1,C:\Users\yargerlab\Desktop\DSC Data\General\Indium(6).tri
Measured 1,157.391
Known 1,156.598
[Cell Constant Calibration]
Date Applied,11/29/2022 7:12:29 PM
Description,From 106.590 °C to 186.590 °C at 10.000°C/min
Gas Type,Nitrogen
Pan Type,Tzero Aluminum Hermetic
Source Files 1,C:\Users\yargerlab\Desktop\DSC Data\General\Indium(6).tri
T4P KCell,1.006051
Onset Slope,63.26126 mW/°C
[Direct Cp Calibration]
Date Applied,11/30/2022 11:04:51 AM
Description,From -79.983 °C to 298.409 °C at 10.000°C/min
Gas Type,Nitrogen
Pan Type,Tzero Aluminum Hermetic
Source Files 1,C:\Users\yargerlab\Desktop\DSC Data\General\Sapphire_Heat_Capacity_11_30_22.tri
[Rev Cp Calibration]
Date Applied,11/30/2022 1:58:51 PM
Description,From -79.996 °C to 292.812 °C at 3.000°C/min
Gas Type,Nitrogen
Pan Type,Tzero Aluminum Hermetic
Source Files 1,C:\Users\yargerlab\Desktop\DSC Data\General\Sapphire_MDSC_Calibration_11_30_22.tri
[step]
Ramp 10.00 °C/min to 200.00 °C
Time,Temperature,Heat Flow (Normalized)
min,°C,W/g
0.00,-59.68,-0.014
0.02,-59.69,-0.014
0.04,-59.70,-0.012
0.05,-59.70,-0.010
0.07,-59.69,-0.007
0.09,-59.66,-0.002
0.11,-59.61,0.003
0.13,-59.54,0.010
0.15,-59.46,0.018
0.16,-59.35,0.025
0.18,-59.24,0.033
0.20,-59.12,0.040
0.22,-58.98,0.046
0.24,-58.84,0.052
0.26,-58.69,0.057
0.28,-58.54,0.061
0.29,-58.39,0.064
0.31,-58.23,0.068
0.33,-58.07,0.070
0.35,-57.90,0.072
0.37,-57.74,0.074
0.39,-57.57,0.076
0.40,-57.40,0.077
0.42,-57.23,0.078
0.44,-57.06,0.079
0.46,-56.89,0.080
0.48,-56.71,0.081
0.50,-56.54,0.082
0.51,-56.36,0.082
0.53,-56.19,0.083
0.55,-56.01,0.083
0.57,-55.84,0.084
0.59,-55.66,0.084
0.60,-55.48,0.084
0.62,-55.31,0.085
0.64,-55.13,0.085
0.66,-54.95,0.085
0.68,-54.77,0.085
0.70,-54.59,0.086
0.72,-54.41,0.086
0.73,-54.23,0.086
0.75,-54.05,0.086
0.77,-53.87,0.086
0.79,-53.69,0.086
0.81,-53.52,0.086
0.83,-53.33,0.087
0.84,-53.15,0.087
0.86,-52.97,0.087
0.88,-52.79,0.087
0.90,-52.61,0.087
0.92,-52.43,0.087
0.93,-52.25,0.087
0.95,-52.07,0.087
0.97,-51.89,0.088
0.99,-51.71,0.088
1.01,-51.53,0.088
1.03,-51.34,0.088
1.05,-51.16,0.088
1.06,-50.98,0.088
1.08,-50.80,0.088
1.10,-50.62,0.088
1.12,-50.43,0.088
1.14,-50.25,0.088
1.16,-50.07,0.088
1.17,-49.89,0.089
1.19,-49.71,0.089
1.21,-49.52,0.089
1.23,-49.34,0.089
1.25,-49.16,0.089
1.27,-48.98,0.089
1.28,-48.80,0.089
1.30,-48.61,0.089
1.32,-48.43,0.089
1.34,-48.25,0.089
1.36,-48.07,0.090
1.38,-47.88,0.090
1.39,-47.70,0.090
1.41,-47.52,0.090
1.43,-47.34,0.090
1.45,-47.15,0.090
1.47,-46.97,0.090
1.48,-46.79,0.090
1.50,-46.60,0.090
1.52,-46.42,0.090
1.54,-46.24,0.090
1.56,-46.06,0.090
1.58,-45.87,0.090
1.59,-45.69,0.090
1.61,-45.51,0.091
1.63,-45.32,0.091
1.65,-45.14,0.091
1.67,-44.96,0.091
1.69,-44.77,0.091
1.71,-44.59,0.091
1.72,-44.41,0.091
1.74,-44.23,0.091
1.76,-44.04,0.091
1.78,-43.86,0.091
1.80,-43.68,0.091
1.82,-43.49,0.091
1.83,-43.31,0.092
1.85,-43.13,0.092
1.87,-42.94,0.092
1.89,-42.76,0.092
1.91,-42.58,0.092
1.93,-42.39,0.092
1.94,-42.21,0.092
1.96,-42.03,0.092
1.98,-41.84,0.092
2.00,-41.66,0.092
2.02,-41.48,0.092
2.03,-41.29,0.092
2.05,-41.11,0.092
2.07,-40.93,0.092
2.09,-40.74,0.093
2.11,-40.56,0.093
2.13,-40.38,0.093
2.14,-40.19,0.093
2.16,-40.01,0.093
2.18,-39.83,0.093
2.20,-39.64,0.093
2.22,-39.46,0.093
2.24,-39.28,0.093
2.26,-39.09,0.093
2.27,-38.91,0.093
2.29,-38.73,0.093
2.31,-38.54,0.093
2.33,-38.36,0.093
2.35,-38.18,0.094
2.36,-37.99,0.094
2.38,-37.81,0.094
2.40,-37.63,0.094
2.42,-37.44,0.094
2.44,-37.26,0.094
2.46,-37.07,0.094
2.48,-36.89,0.094
2.49,-36.71,0.094
2.51,-36.52,0.094
2.53,-36.34,0.094
2.55,-36.16,0.094
2.57,-35.97,0.094
2.59,-35.79,0.094
2.60,-35.61,0.095
2.62,-35.42,0.095
2.64,-35.24,0.095
2.66,-35.06,0.095
2.68,-34.87,0.095
2.69,-34.69,0.095
2.71,-34.51,0.095
2.73,-34.32,0.095
2.75,-34.14,0.095
2.77,-33.96,0.095
2.79,-33.77,0.095
2.81,-33.59,0.095
2.82,-33.40,0.095
2.84,-33.22,0.095
2.86,-33.04,0.095
2.88,-32.86,0.096
2.90,-32.67,0.096
2.91,-32.49,0.096
2.93,-32.30,0.096
2.95,-32.12,0.096
2.97,-31.94,0.096
2.99,-31.75,0.096
3.01,-31.57,0.096
3.03,-31.39,0.096
3.04,-31.20,0.096
3.06,-31.02,0.096
3.08,-30.83,0.096
3.10,-30.65,0.096
3.12,-30.47,0.096
3.14,-30.29,0.097
3.15,-30.10,0.097
3.17,-29.92,0.097
3.19,-29.73,0.097
3.21,-29.55,0.097
3.23,-29.37,0.097
3.24,-29.18,0.097
3.26,-29.00,0.097
3.28,-28.82,0.097
3.30,-28.63,0.097
3.32,-28.45,0.097
3.34,-28.27,0.097
3.36,-28.08,0.097
3.37,-27.90,0.097
3.39,-27.72,0.097
3.41,-27.53,0.098
3.43,-27.35,0.098
3.45,-27.17,0.098
3.46,-26.98,0.098
3.48,-26.80,0.098
3.50,-26.61,0.098
3.52,-26.43,0.098
3.54,-26.25,0.098
3.56,-26.06,0.098
3.58,-25.88,0.098
3.59,-25.70,0.098
3.61,-25.51,0.098
3.63,-25.33,0.098
3.65,-25.15,0.099
3.67,-24.96,0.099
3.69,-24.78,0.099
3.70,-24.60,0.099
3.72,-24.41,0.099
3.74,-24.23,0.099
3.76,-24.05,0.099
3.78,-23.86,0.099
3.79,-23.68,0.099
3.81,-23.49,0.099
3.83,-23.31,0.099
3.85,-23.13,0.099
3.87,-22.94,0.099
3.89,-22.76,0.099
3.91,-22.58,0.100
3.92,-22.40,0.100
3.94,-22.21,0.100
3.96,-22.03,0.100
3.98,-21.84,0.100
4.00,-21.66,0.100
4.01,-21.48,0.100
4.03,-21.29,0.100
4.05,-21.11,0.100
4.07,-20.93,0.100
4.09,-20.74,0.100
4.11,-20.56,0.100
4.13,-20.38,0.100
4.14,-20.19,0.100
4.16,-20.01,0.101
4.18,-19.82,0.101
4.20,-19.64,0.101
4.22,-19.46,0.101
4.24,-19.27,0.101
4.25,-19.09,0.101
4.27,-18.91,0.101
4.29,-18.72,0.101
4.31,-18.54,0.101
4.33,-18.36,0.101
4.35,-18.17,0.101
4.36,-17.99,0.101
4.38,-17.81,0.101
4.40,-17.62,0.101
4.42,-17.44,0.102
4.44,-17.26,0.102
4.45,-17.07,0.102
4.47,-16.89,0.102
4.49,-16.70,0.102
4.51,-16.52,0.102
4.53,-16.34,0.102
4.55,-16.16,0.102
4.56,-15.97,0.102
4.58,-15.79,0.102
4.60,-15.61,0.102
4.62,-15.42,0.102
4.64,-15.24,0.102
4.66,-15.05,0.102
4.68,-14.87,0.102
4.69,-14.69,0.102
4.71,-14.50,0.103
4.73,-14.32,0.103
4.75,-14.14,0.103
4.77,-13.95,0.103
4.79,-13.77,0.103
4.80,-13.59,0.103
4.82,-13.40,0.103
4.84,-13.22,0.103
4.86,-13.04,0.103
4.88,-12.85,0.103
4.90,-12.67,0.103
4.91,-12.49,0.103
4.93,-12.30,0.103
4.95,-12.12,0.103
4.97,-11.94,0.104
4.99,-11.75,0.104
5.00,-11.57,0.104
5.02,-11.38,0.104
5.04,-11.20,0.104
5.06,-11.02,0.104
5.08,-10.83,0.104
5.10,-10.65,0.104
5.11,-10.47,0.104
5.13,-10.28,0.104
5.15,-10.10,0.104
5.17,-9.92,0.104
5.19,-9.73,0.104
5.21,-9.55,0.104
5.23,-9.37,0.104
5.24,-9.18,0.105
5.26,-9.00,0.105
5.28,-8.82,0.105
5.30,-8.63,0.105
5.32,-8.45,0.105
5.34,-8.27,0.105
5.35,-8.08,0.105
5.37,-7.90,0.105
5.39,-7.72,0.105
5.41,-7.53,0.105
5.43,-7.35,0.105
5.45,-7.16,0.105
5.46,-6.98,0.105
5.48,-6.80,0.106
5.50,-6.61,0.106
5.52,-6.43,0.106
5.54,-6.25,0.106
5.55,-6.06,0.106
5.57,-5.88,0.106
5.59,-5.70,0.106
5.61,-5.51,0.106
5.63,-5.33,0.106
5.65,-5.15,0.106
5.66,-4.96,0.106
5.68,-4.78,0.106
5.70,-4.59,0.106
5.72,-4.41,0.107
5.74,-4.23,0.107
5.76,-4.04,0.107
5.78,-3.86,0.107
5.79,-3.68,0.107
5.81,-3.49,0.107
5.83,-3.31,0.107
5.85,-3.13,0.107
5.87,-2.94,0.107
5.89,-2.76,0.107
5.90,-2.58,0.107
5.92,-2.39,0.107
5.94,-2.21,0.107
5.96,-2.03,0.107
5.98,-1.84,0.108
6.00,-1.66,0.108
6.01,-1.48,0.108
6.03,-1.29,0.108
6.05,-1.11,0.108
6.07,-0.93,0.108
6.09,-0.74,0.108
6.10,-0.56,0.108
6.12,-0.38,0.108
6.14,-0.19,0.108
6.16,-0.01,0.108
6.18,0.17,0.108
6.20,0.36,0.108
6.21,0.54,0.108
6.23,0.73,0.108
6.25,0.91,0.109
6.27,1.09,0.109
6.29,1.28,0.109
6.31,1.46,0.109
6.33,1.64,0.109
6.34,1.83,0.109
6.36,2.01,0.109
6.38,2.19,0.109
6.40,2.38,0.109
6.42,2.56,0.109
6.44,2.75,0.109
6.45,2.93,0.109
6.47,3.11,0.109
6.49,3.30,0.110
6.51,3.48,0.110
6.53,3.66,0.110
6.55,3.85,0.110
6.56,4.03,0.110
6.58,4.21,0.110
6.60,4.40,0.110
6.62,4.58,0.110
6.64,4.76,0.110
6.65,4.95,0.110
6.67,5.13,0.110
6.69,5.31,0.110
6.71,5.50,0.110
6.73,5.68,0.111
6.75,5.86,0.111
6.76,6.05,0.111
6.78,6.23,0.111
6.80,6.41,0.111
6.82,6.60,0.111
6.84,6.78,0.111
6.86,6.97,0.111
6.88,7.15,0.111
6.89,7.33,0.111
6.91,7.52,0.111
6.93,7.70,0.111
6.95,7.88,0.111
6.97,8.07,0.111
6.99,8.25,0.111
7.00,8.43,0.112
7.02,8.62,0.112
7.04,8.80,0.112
7.06,8.98,0.112
7.08,9.17,0.112
7.10,9.35,0.112
7.11,9.53,0.112
7.13,9.72,0.112
7.15,9.90,0.112
7.17,10.09,0.112
7.19,10.27,0.112
7.20,10.45,0.112
7.22,10.64,0.112
7.24,10.82,0.112
7.26,11.00,0.113
7.28,11.19,0.113
7.30,11.37,0.113
7.31,11.55,0.113
7.33,11.74,0.113
7.35,11.92,0.113
7.37,12.10,0.113
7.39,12.29,0.113
7.41,12.47,0.113
7.43,12.66,0.113
7.44,12.84,0.113
7.46,13.02,0.113
7.48,13.21,0.113
7.50,13.39,0.113
7.52,13.57,0.113
7.54,13.76,0.114
7.55,13.94,0.114
7.57,14.12,0.114
7.59,14.31,0.114
7.61,14.49,0.114
7.63,14.67,0.114
7.65,14.86,0.114
7.66,15.04,0.114
7.68,15.22,0.114
7.70,15.41,0.114
7.72,15.59,0.114
7.74,15.77,0.114
7.75,15.96,0.114
7.77,16.14,0.114
7.79,16.33,0.114
7.81,16.51,0.115
7.83,16.69,0.115
7.85,16.88,0.115
7.86,17.06,0.115
7.88,17.24,0.115
7.90,17.43,0.115
7.92,17.61,0.115
7.94,17.79,0.115
7.96,17.98,0.115
7.98,18.16,0.115
7.99,18.34,0.115
8.01,18.53,0.115
8.03,18.71,0.115
8.05,18.89,0.116
8.07,19.08,0.116
8.09,19.26,0.116
8.10,19.44,0.116
8.12,19.63,0.116
8.14,19.81,0.116
8.16,19.99,0.116
8.18,20.18,0.116
8.20,20.36,0.116
8.21,20.55,0.116
8.23,20.73,0.116
8.25,20.91,0.116
8.27,21.10,0.116
8.29,21.28,0.116
8.30,21.46,0.116
8.32,21.65,0.116
8.34,21.83,0.117
8.36,22.01,0.117
8.38,22.20,0.117
8.40,22.38,0.117
8.41,22.56,0.117
8.43,22.75,0.117
8.45,22.93,0.117
8.47,23.11,0.117
8.49,23.30,0.117
8.51,23.48,0.117
8.53,23.66,0.117
8.54,23.85,0.117
8.56,24.03,0.117
8.58,24.22,0.117
8.60,24.40,0.117
8.62,24.58,0.118
8.63,24.77,0.118
8.65,24.95,0.118
8.67,25.13,0.118
8.69,25.32,0.118
8.71,25.50,0.118
8.73,25.68,0.118
8.75,25.87,0.118
8.76,26.05,0.118
8.78,26.23,0.118
8.80,26.42,0.118
8.82,26.60,0.118
8.84,26.79,0.118
8.85,26.97,0.118
8.87,27.15,0.119
8.89,27.34,0.119
8.91,27.52,0.119
8.93,27.70,0.119
8.95,27.88,0.119
8.97,28.07,0.119
8.98,28.25,0.119
9.00,28.44,0.119
9.02,28.62,0.119
9.04,28.80,0.119
9.06,28.99,0.119
9.08,29.17,0.119
9.09,29.35,0.119
9.11,29.54,0.119
9.13,29.72,0.119
9.15,29.90,0.120
9.17,30.09,0.120
9.18,30.27,0.120
9.20,30.45,0.120
9.22,30.64,0.120
9.24,30.82,0.120
9.26,31.01,0.120
9.28,31.19,0.120
9.30,31.37,0.120
9.31,31.56,0.120
9.33,31.74,0.120
9.35,31.92,0.120
9.37,32.11,0.120
9.39,32.29,0.120
9.40,32.47,0.120
9.42,32.66,0.120
9.44,32.84,0.121
9.46,33.02,0.121
9.48,33.21,0.121
9.50,33.39,0.121
9.52,33.57,0.121
9.53,33.76,0.121
9.55,33.94,0.121
9.57,34.12,0.121
9.59,34.31,0.121
9.61,34.49,0.121
9.63,34.67,0.121
9.64,34.86,0.121
9.66,35.04,0.121
9.68,35.23,0.121
9.70,35.41,0.121
9.72,35.59,0.121
9.73,35.78,0.122
9.75,35.96,0.122
9.77,36.14,0.122
9.79,36.33,0.122
9.81,36.51,0.122
9.83,36.69,0.122
9.85,36.88,0.122
9.86,37.06,0.122
9.88,37.24,0.122
9.90,37.43,0.122
9.92,37.61,0.122
9.94,37.80,0.122
9.95,37.98,0.122
9.97,38.16,0.122
9.99,38.35,0.122
10.01,38.53,0.122
10.03,38.71,0.122
10.05,38.90,0.123
10.07,39.08,0.123
10.08,39.26,0.123
10.10,39.45,0.123
10.12,39.63,0.123
10.14,39.81,0.123
10.16,40.00,0.123
10.18,40.18,0.123
10.19,40.36,0.123
10.21,40.55,0.123
10.23,40.73,0.123
10.25,40.92,0.123
10.27,41.10,0.123
10.28,41.28,0.123
10.30,41.47,0.123
10.32,41.65,0.123
10.34,41.83,0.123
10.36,42.02,0.123
10.38,42.20,0.124
10.40,42.38,0.124
10.41,42.57,0.124
10.43,42.75,0.124
10.45,42.93,0.124
10.47,43.12,0.124
10.49,43.30,0.124
10.50,43.48,0.124
10.52,43.67,0.124
10.54,43.85,0.124
10.56,44.03,0.124
10.58,44.22,0.124
10.60,44.40,0.124
10.62,44.58,0.124
10.63,44.77,0.125
10.65,44.95,0.125
10.67,45.14,0.125
10.69,45.32,0.125
10.71,45.50,0.125
10.73,45.69,0.125
10.74,45.87,0.125
10.76,46.05,0.125
10.78,46.24,0.125
10.80,46.42,0.125
10.82,46.60,0.125
10.83,46.79,0.125
10.85,46.97,0.125
10.87,47.16,0.125
10.89,47.34,0.125
10.91,47.52,0.125
10.93,47.71,0.125
10.95,47.89,0.126
10.96,48.07,0.126
10.98,48.26,0.126
11.00,48.44,0.126
11.02,48.62,0.126
11.04,48.81,0.126
11.05,48.99,0.126
11.07,49.17,0.126
11.09,49.36,0.126
11.11,49.54,0.126
11.13,49.72,0.126
11.15,49.91,0.126
11.17,50.09,0.126
11.18,50.28,0.126
11.20,50.46,0.126
11.22,50.64,0.126
11.24,50.83,0.126
11.26,51.01,0.126
11.28,51.19,0.127
11.29,51.38,0.127
11.31,51.56,0.127
11.33,51.74,0.127
11.35,51.93,0.127
11.37,52.11,0.127
11.38,52.29,0.127
11.40,52.48,0.127
11.42,52.66,0.127
11.44,52.85,0.127
11.46,53.03,0.127
11.48,53.21,0.127
11.50,53.40,0.127
11.51,53.58,0.127
11.53,53.76,0.127
11.55,53.95,0.127
11.57,54.13,0.127
11.59,54.31,0.127
11.60,54.50,0.128
11.62,54.68,0.128
11.64,54.86,0.128
11.66,55.05,0.128
11.68,55.23,0.128
11.70,55.41,0.128
11.72,55.60,0.128
11.73,55.78,0.128
11.75,55.97,0.128
11.77,56.15,0.128
11.79,56.33,0.128
11.81,56.51,0.128
11.83,56.70,0.128
11.84,56.88,0.128
11.86,57.07,0.128
11.88,57.25,0.128
11.90,57.43,0.128
11.92,57.62,0.128
11.93,57.80,0.128
11.95,57.98,0.128
11.97,58.16,0.129
11.99,58.35,0.129
12.01,58.53,0.129
12.03,58.72,0.129
12.05,58.90,0.129
12.06,59.08,0.129
12.08,59.27,0.129
12.10,59.45,0.129
12.12,59.63,0.129
12.14,59.82,0.129
12.15,60.00,0.129
12.17,60.18,0.129
12.19,60.37,0.129
12.21,60.55,0.129
12.23,60.73,0.129
12.25,60.92,0.129
12.27,61.10,0.129
12.28,61.28,0.129
12.30,61.47,0.130
12.32,61.65,0.130
12.34,61.84,0.130
12.36,62.02,0.130
12.38,62.20,0.130
12.39,62.39,0.130
12.41,62.57,0.130
12.43,62.75,0.130
12.45,62.94,0.130
12.47,63.12,0.130
12.48,63.30,0.130
12.50,63.49,0.130
12.52,63.67,0.130
12.54,63.85,0.130
12.56,64.04,0.130
12.58,64.22,0.130
12.60,64.40,0.130
12.61,64.59,0.130
12.63,64.77,0.130
12.65,64.95,0.131
12.67,65.14,0.131
12.69,65.32,0.131
12.70,65.50,0.131
12.72,65.69,0.131
12.74,65.87,0.131
12.76,66.06,0.131
12.78,66.24,0.131
12.80,66.42,0.131
12.82,66.61,0.131
12.83,66.79,0.131
12.85,66.97,0.131
12.87,67.16,0.131
12.89,67.34,0.131
12.91,67.52,0.131
12.93,67.71,0.131
12.94,67.89,0.131
12.96,68.07,0.131
12.98,68.26,0.131
13.00,68.44,0.132
13.02,68.62,0.132
13.03,68.81,0.132
13.05,68.99,0.132
13.07,69.17,0.132
13.09,69.36,0.132
13.11,69.54,0.132
13.13,69.72,0.132
13.15,69.91,0.132
13.16,70.09,0.132
13.18,70.28,0.132
13.20,70.46,0.132
13.22,70.64,0.132
13.24,70.83,0.132
13.25,71.01,0.132
13.27,71.19,0.132
13.29,71.38,0.132
13.31,71.56,0.132
13.33,71.74,0.132
13.35,71.93,0.132
13.37,72.11,0.133
13.38,72.30,0.133
13.40,72.48,0.133
13.42,72.66,0.133
13.44,72.84,0.133
13.46,73.03,0.133
13.48,73.21,0.133
13.49,73.40,0.133
13.51,73.58,0.133
13.53,73.76,0.133
13.55,73.95,0.133
13.57,74.13,0.133
13.58,74.31,0.133
13.60,74.50,0.133
13.62,74.68,0.133
13.64,74.86,0.133
13.66,75.05,0.133
13.68,75.23,0.133
13.70,75.42,0.133
13.71,75.60,0.134
13.73,75.78,0.134
13.75,75.97,0.134
13.77,76.15,0.134
13.79,76.33,0.134
13.80,76.52,0.134
13.82,76.70,0.134
13.84,76.88,0.134
13.86,77.07,0.134
13.88,77.25,0.134
13.90,77.43,0.134
13.92,77.62,0.134
13.93,77.80,0.134
13.95,77.98,0.134
13.97,78.17,0.134
13.99,78.35,0.134
14.01,78.53,0.134
14.03,78.72,0.134
14.04,78.90,0.134
14.06,79.08,0.134
14.08,79.27,0.134
14.10,79.45,0.135
14.12,79.64,0.135
14.13,79.82,0.135
14.15,80.00,0.135
14.17,80.19,0.135
14.19,80.37,0.135
14.21,80.55,0.135
14.23,80.74,0.135
14.25,80.92,0.135
14.26,81.10,0.135
14.28,81.29,0.135
14.30,81.47,0.135
14.32,81.65,0.135
14.34,81.84,0.135
14.35,82.02,0.135
14.37,82.20,0.135
14.39,82.39,0.135
14.41,82.57,0.135
14.43,82.75,0.135
14.45,82.94,0.135
14.47,83.12,0.135
14.48,83.31,0.136
14.50,83.49,0.136
14.52,83.67,0.136
14.54,83.86,0.136
14.56,84.04,0.136
14.58,84.22,0.136
14.59,84.41,0.136
14.61,84.59,0.136
14.63,84.77,0.136
14.65,84.96,0.136
14.67,85.14,0.136
14.68,85.32,0.136
14.70,85.51,0.136
14.72,85.69,0.136
14.74,85.87,0.136
14.76,86.06,0.136
14.78,86.24,0.136
14.80,86.42,0.136
14.81,86.61,0.136
14.83,86.79,0.136
14.85,86.98,0.136
14.87,87.16,0.136
14.89,87.34,0.136
14.90,87.53,0.136
14.92,87.71,0.137
14.94,87.90,0.137
14.96,88.08,0.137
14.98,88.26,0.137
15.00,88.45,0.137
15.02,88.63,0.137
15.03,88.81,0.137
15.05,89.00,0.137
15.07,89.18,0.137
15.09,89.36,0.137
15.11,89.55,0.137
15.13,89.73,0.137
15.14,89.91,0.137
15.16,90.10,0.137
15.18,90.28,0.137
15.20,90.46,0.137
15.22,90.65,0.137
15.23,90.83,0.137
15.25,91.02,0.137
15.27,91.20,0.137
15.29,91.38,0.137
15.31,91.56,0.137
15.33,91.75,0.137
15.35,91.93,0.137
15.36,92.11,0.137
15.38,92.30,0.137
15.40,92.48,0.138
15.42,92.66,0.138
15.44,92.85,0.138
15.45,93.03,0.138
15.47,93.22,0.138
15.49,93.40,0.138
15.51,93.58,0.138
15.53,93.77,0.138
15.55,93.95,0.138
15.57,94.13,0.138
15.58,94.32,0.138
15.60,94.50,0.138
15.62,94.68,0.138
15.64,94.87,0.138
15.66,95.05,0.138
15.68,95.23,0.138
15.69,95.42,0.138
15.71,95.60,0.138
15.73,95.79,0.138
15.75,95.97,0.138
15.77,96.15,0.138
15.78,96.33,0.138
15.80,96.52,0.138
15.82,96.70,0.139
15.84,96.89,0.139
15.86,97.07,0.139
15.88,97.25,0.139
15.90,97.44,0.139
15.91,97.62,0.139
15.93,97.80,0.139
15.95,97.99,0.139
15.97,98.17,0.139
15.99,98.35,0.139
16.00,98.54,0.139
16.02,98.72,0.139
16.04,98.90,0.139
16.06,99.09,0.139
16.08,99.27,0.139
16.10,99.45,0.139
16.12,99.64,0.139
16.13,99.82,0.139
16.15,100.00,0.139
16.17,100.19,0.139
16.19,100.37,0.139
16.21,100.55,0.139
16.23,100.74,0.139
16.24,100.92,0.140
16.26,101.11,0.140
16.28,101.29,0.140
16.30,101.47,0.140
16.32,101.66,0.140
16.33,101.84,0.140
16.35,102.02,0.140
16.37,102.21,0.140
16.39,102.39,0.140
16.41,102.57,0.140
16.43,102.76,0.140
16.45,102.94,0.140
16.46,103.12,0.140
16.48,103.31,0.140
16.50,103.49,0.140
16.52,103.67,0.140
16.54,103.86,0.140
16.55,104.04,0.140
16.57,104.22,0.140
16.59,104.41,0.140
16.61,104.59,0.140
16.63,104.77,0.140
16.65,104.96,0.140
16.67,105.14,0.140
16.68,105.33,0.140
16.70,105.51,0.141
16.72,105.69,0.141
16.74,105.88,0.141
16.76,106.06,0.141
16.78,106.24,0.141
16.79,106.43,0.141
16.81,106.61,0.141
16.83,106.79,0.141
16.85,106.98,0.141
16.87,107.16,0.141
16.88,107.34,0.141
16.90,107.53,0.141
16.92,107.71,0.141
16.94,107.90,0.141
16.96,108.08,0.141
16.98,108.26,0.141
17.00,108.45,0.141
17.01,108.63,0.141
17.03,108.81,0.141
17.05,109.00,0.141
17.07,109.18,0.141
17.09,109.36,0.141
17.11,109.55,0.142
17.12,109.73,0.142
17.14,109.91,0.142
17.16,110.10,0.142
17.18,110.28,0.142
17.20,110.46,0.142
17.22,110.65,0.142
17.23,110.83,0.142
17.25,111.01,0.142
17.27,111.20,0.142
17.29,111.38,0.142
17.31,111.56,0.142
17.33,111.75,0.142
17.34,111.93,0.142
17.36,112.11,0.142
17.38,112.30,0.142
17.40,112.48,0.142
17.42,112.66,0.142
17.43,112.85,0.142
17.45,113.03,0.142
17.47,113.21,0.142
17.49,113.40,0.142
17.51,113.58,0.142
17.53,113.76,0.142
17.54,113.95,0.143
17.56,114.13,0.143
17.58,114.32,0.143
17.60,114.50,0.143
17.62,114.68,0.143
17.64,114.87,0.143
17.66,115.05,0.143
17.67,115.23,0.143
17.69,115.42,0.143
17.71,115.60,0.143
17.73,115.78,0.143
17.75,115.97,0.143
17.77,116.15,0.143
17.78,116.33,0.143
17.80,116.52,0.143
17.82,116.70,0.143
17.84,116.88,0.143
17.86,117.07,0.143
17.88,117.25,0.143
17.89,117.44,0.143
17.91,117.62,0.143
17.93,117.80,0.143
17.95,117.99,0.143
17.97,118.17,0.143
17.98,118.35,0.143
18.00,118.54,0.144
18.02,118.72,0.144
18.04,118.90,0.144
18.06,119.09,0.144
18.08,119.27,0.144
18.09,119.45,0.144
18.11,119.64,0.144
18.13,119.82,0.144
18.15,120.01,0.144
18.17,120.19,0.144
18.19,120.37,0.144
18.21,120.56,0.144
18.22,120.74,0.144
18.24,120.92,0.144
18.26,121.10,0.144
18.28,121.29,0.144
18.30,121.47,0.144
18.32,121.66,0.144
18.33,121.84,0.144
18.35,122.02,0.144
18.37,122.21,0.144
18.39,122.39,0.144
18.41,122.57,0.144
18.43,122.76,0.144
18.44,122.94,0.144
18.46,123.12,0.144
18.48,123.31,0.144
18.50,123.49,0.145
18.52,123.67,0.145
18.53,123.86,0.145
18.55,124.04,0.145
18.57,124.22,0.145
18.59,124.41,0.145
18.61,124.59,0.145
18.63,124.77,0.145
18.64,124.96,0.145
18.66,125.14,0.145
18.68,125.32,0.145
18.70,125.51,0.145
18.72,125.69,0.145
18.74,125.87,0.145
18.76,126.06,0.145
18.77,126.24,0.145
18.79,126.43,0.145
18.81,126.61,0.145
18.83,126.79,0.145
18.85,126.98,0.145
18.87,127.16,0.145
18.88,127.34,0.145
18.90,127.53,0.145
18.92,127.71,0.145
18.94,127.89,0.145
18.96,128.08,0.145
18.98,128.26,0.146
18.99,128.44,0.146
19.01,128.63,0.146
19.03,128.81,0.146
19.05,128.99,0.146
19.07,129.18,0.146
19.08,129.36,0.146
19.10,129.54,0.146
19.12,129.73,0.146
19.14,129.91,0.146
19.16,130.09,0.146
19.18,130.28,0.146
19.19,130.46,0.146
19.21,130.64,0.146
19.23,130.83,0.146
19.25,131.01,0.146
19.27,131.19,0.146
19.29,131.38,0.146
19.31,131.56,0.146
19.32,131.74,0.146
19.34,131.93,0.146
19.36,132.11,0.146
19.38,132.30,0.146
19.40,132.48,0.146
19.42,132.66,0.146
19.43,132.85,0.146
19.45,133.03,0.146
19.47,133.21,0.147
19.49,133.40,0.147
19.51,133.58,0.147
19.53,133.76,0.147
19.54,133.95,0.147
19.56,134.13,0.147
19.58,134.31,0.147
19.60,134.50,0.147
19.62,134.68,0.147
19.63,134.86,0.147
19.65,135.05,0.147
19.67,135.23,0.147
19.69,135.42,0.147
19.71,135.60,0.147
19.73,135.78,0.147
19.74,135.97,0.147
19.76,136.15,0.147
19.78,136.33,0.147
19.80,136.52,0.147
19.82,136.70,0.147
19.84,136.88,0.147
19.86,137.07,0.147
19.87,137.25,0.147
19.89,137.43,0.147
19.91,137.62,0.147
19.93,137.80,0.147
19.95,137.98,0.147
19.97,138.17,0.147
19.98,138.35,0.147
20.00,138.53,0.148
20.02,138.72,0.148
20.04,138.90,0.148
20.06,139.08,0.148
20.08,139.27,0.148
20.09,139.45,0.148
20.11,139.63,0.148
20.13,139.82,0.148
20.15,140.00,0.148
20.17,140.18,0.148
20.18,140.37,0.148
20.20,140.55,0.148
20.22,140.74,0.148
20.24,140.92,0.148
20.26,141.10,0.148
20.28,141.29,0.148
20.29,141.47,0.148
20.31,141.65,0.148
20.33,141.84,0.148
20.35,142.02,0.148
20.37,142.20,0.148
20.39,142.39,0.148
20.41,142.57,0.148
20.42,142.75,0.148
20.44,142.94,0.148
20.46,143.12,0.148
20.48,143.30,0.148
20.50,143.49,0.148
20.52,143.67,0.149
20.53,143.85,0.149
20.55,144.04,0.149
20.57,144.22,0.149
20.59,144.41,0.149
20.61,144.59,0.149
20.63,144.77,0.149
20.64,144.95,0.149
20.66,145.14,0.149
20.68,145.32,0.149
20.70,145.51,0.149
20.72,145.69,0.149
20.73,145.87,0.149
20.75,146.06,0.149
20.77,146.24,0.149
20.79,146.42,0.149
20.81,146.61,0.149
20.83,146.79,0.149
20.84,146.97,0.149
20.86,147.16,0.149
20.88,147.34,0.149
20.90,147.52,0.149
20.92,147.71,0.149
20.94,147.89,0.149
20.96,148.07,0.149
20.97,148.26,0.149
20.99,148.44,0.149
21.01,148.63,0.149
21.03,148.81,0.149
21.05,148.99,0.149
21.07,149.17,0.149
21.08,149.36,0.149
21.10,149.54,0.150
21.12,149.73,0.150
21.14,149.91,0.150
21.16,150.09,0.150
21.18,150.27,0.150
21.19,150.46,0.150
21.21,150.64,0.150
21.23,150.83,0.150
21.25,151.01,0.150
21.27,151.19,0.150
21.28,151.38,0.150
21.30,151.56,0.150
21.32,151.74,0.150
21.34,151.93,0.150
21.36,152.11,0.150
21.38,152.29,0.150
21.39,152.48,0.150
21.41,152.66,0.150
21.43,152.84,0.150
21.45,153.03,0.150
21.47,153.21,0.150
21.49,153.40,0.150
21.51,153.58,0.150
21.52,153.76,0.150
21.54,153.94,0.150
21.56,154.13,0.150
21.58,154.31,0.150
21.60,154.49,0.150
21.62,154.68,0.150
21.63,154.86,0.150
21.65,155.05,0.150
21.67,155.23,0.151
21.69,155.41,0.151
21.71,155.60,0.151
21.73,155.78,0.151
21.74,155.96,0.151
21.76,156.15,0.151
21.78,156.33,0.151
21.80,156.51,0.151
21.82,156.70,0.151
21.83,156.88,0.151
21.85,157.06,0.151
21.87,157.25,0.151
21.89,157.43,0.151
21.91,157.61,0.151
21.93,157.80,0.151
21.94,157.98,0.151
21.96,158.16,0.151
21.98,158.35,0.151
22.00,158.53,0.151
22.02,158.71,0.151
22.04,158.90,0.151
22.06,159.08,0.151
22.07,159.26,0.151
22.09,159.45,0.151
22.11,159.63,0.151
22.13,159.81,0.151
22.15,160.00,0.151
22.17,160.18,0.151
22.18,160.37,0.151
22.20,160.55,0.151
22.22,160.73,0.151
22.24,160.92,0.152
22.26,161.10,0.152
22.28,161.28,0.152
22.29,161.47,0.152
22.31,161.65,0.152
22.33,161.83,0.152
22.35,162.02,0.152
22.37,162.20,0.152
22.38,162.38,0.152
22.40,162.57,0.152
22.42,162.75,0.152
22.44,162.93,0.152
22.46,163.12,0.152
22.48,163.30,0.152
22.49,163.48,0.152
22.51,163.67,0.152
22.53,163.85,0.152
22.55,164.03,0.152
22.57,164.22,0.152
22.59,164.40,0.152
22.61,164.58,0.152
22.62,164.77,0.152
22.64,164.95,0.152
22.66,165.14,0.152
22.68,165.32,0.152
22.70,165.50,0.152
22.72,165.69,0.152
22.73,165.87,0.152
22.75,166.05,0.152
22.77,166.24,0.152
22.79,166.42,0.153
22.81,166.60,0.153
22.83,166.79,0.153
22.84,166.97,0.153
22.86,167.15,0.153
22.88,167.34,0.153
22.90,167.52,0.153
22.92,167.70,0.153
22.93,167.89,0.153
22.95,168.07,0.153
22.97,168.25,0.153
22.99,168.44,0.153
23.01,168.62,0.153
23.03,168.80,0.153
23.04,168.99,0.153
23.06,169.17,0.153
23.08,169.36,0.153
23.10,169.54,0.153
23.12,169.72,0.153
23.14,169.90,0.153
23.16,170.09,0.153
23.17,170.27,0.153
23.19,170.46,0.153
23.21,170.64,0.153
23.23,170.82,0.153
23.25,171.01,0.153
23.27,171.19,0.153
23.28,171.37,0.153
23.30,171.56,0.153
23.32,171.74,0.153
23.34,171.92,0.153
23.36,172.11,0.153
23.38,172.29,0.153
23.39,172.47,0.153
23.41,172.66,0.153
23.43,172.84,0.153
23.45,173.02,0.153
23.47,173.21,0.154
23.48,173.39,0.154
23.50,173.57,0.154
23.52,173.76,0.154
23.54,173.94,0.154
23.56,174.12,0.154
23.58,174.31,0.154
23.59,174.49,0.154
23.61,174.68,0.154
23.63,174.86,0.154
23.65,175.04,0.154
23.67,175.23,0.154
23.69,175.41,0.154
23.71,175.59,0.154
23.72,175.78,0.154
23.74,175.96,0.154
23.76,176.14,0.154
23.78,176.33,0.154
23.80,176.51,0.154
23.82,176.69,0.154
23.83,176.88,0.154
23.85,177.06,0.154
23.87,177.24,0.154
23.89,177.43,0.154
23.91,177.61,0.154
23.93,177.79,0.154
23.94,177.98,0.154
23.96,178.16,0.154
23.98,178.34,0.154
24.00,178.53,0.154
24.02,178.71,0.154
24.03,178.89,0.154
24.05,179.08,0.154
24.07,179.26,0.154
24.09,179.44,0.155
24.11,179.63,0.155
24.13,179.81,0.155
24.14,180.00,0.155
24.16,180.18,0.155
24.18,180.36,0.155
24.20,180.54,0.155
24.22,180.73,0.155
24.24,180.91,0.155
24.26,181.10,0.155
24.27,181.28,0.155
24.29,181.46,0.155
24.31,181.65,0.155
24.33,181.83,0.155
24.35,182.01,0.155
24.37,182.20,0.155
24.38,182.38,0.155
24.40,182.56,0.155
24.42,182.75,0.155
24.44,182.93,0.155
24.46,183.11,0.155
24.48,183.30,0.155
24.49,183.48,0.155
24.51,183.66,0.155
24.53,183.85,0.155
24.55,184.03,0.155
24.57,184.21,0.155
24.58,184.40,0.155
24.60,184.58,0.155
24.62,184.77,0.155
24.64,184.95,0.155
24.66,185.13,0.155
24.68,185.31,0.155
24.69,185.50,0.155
24.71,185.68,0.155
24.73,185.86,0.156
24.75,186.05,0.156
24.77,186.23,0.156
24.79,186.42,0.156
24.81,186.60,0.156
24.82,186.78,0.156
24.84,186.97,0.156
24.86,187.15,0.156
24.88,187.33,0.156
24.90,187.52,0.156
24.92,187.70,0.156
24.93,187.88,0.156
24.95,188.07,0.156
24.97,188.25,0.156
24.99,188.43,0.156
25.01,188.62,0.156
25.03,188.80,0.156
25.04,188.99,0.156
25.06,189.17,0.156
25.08,189.35,0.156
25.10,189.54,0.156
25.12,189.72,0.156
25.13,189.90,0.156
25.15,190.08,0.156
25.17,190.27,0.156
25.19,190.45,0.156
25.21,190.64,0.156
25.23,190.82,0.156
25.24,191.00,0.156
25.26,191.19,0.156
25.28,191.37,0.156
25.30,191.55,0.156
25.32,191.74,0.156
25.34,191.92,0.156
25.36,192.10,0.156
25.37,192.29,0.156
25.39,192.47,0.157
25.41,192.65,0.157
25.43,192.84,0.157
25.45,193.02,0.157
25.47,193.20,0.157
25.48,193.39,0.157
25.50,193.57,0.157
25.52,193.75,0.157
25.54,193.94,0.157
25.56,194.12,0.157
25.58,194.30,0.157
25.59,194.49,0.157
25.61,194.67,0.157
25.63,194.85,0.157
25.65,195.04,0.157
25.67,195.22,0.157
25.68,195.40,0.157
25.70,195.59,0.157
25.72,195.77,0.157
25.74,195.95,0.157
25.76,196.14,0.157
25.78,196.32,0.157
25.79,196.50,0.157
25.81,196.69,0.157
25.83,196.87,0.157
25.85,197.05,0.157
25.87,197.24,0.157
25.89,197.42,0.157
25.91,197.60,0.157
25.92,197.79,0.157
25.94,197.97,
25.96,198.15,
25.98,198.34,
25.99,,

[step]
Ramp 10.00 °C/min to -60.00 °C
Time,Temperature,Heat Flow (Normalized)
min,°C,W/g
26.09,199.40,0.139
26.11,199.52,0.135
26.13,199.62,0.122
26.15,199.69,0.105
26.17,199.75,0.086
26.18,199.77,0.062
26.20,199.77,0.036
26.22,199.73,0.007
26.24,199.68,-0.021
26.26,199.59,-0.047
26.28,199.50,-0.070
26.29,199.38,-0.090
26.31,199.26,-0.106
26.33,199.12,-0.119
26.35,198.98,-0.129
26.37,198.83,-0.138
26.39,198.68,-0.145
26.41,198.52,-0.151
26.42,198.36,-0.156
26.44,198.19,-0.160
26.46,198.03,-0.164
26.48,197.86,-0.167
26.50,197.69,-0.169
26.52,197.51,-0.172
26.53,197.34,-0.173
26.55,197.17,-0.175
26.57,196.99,-0.176
26.59,196.81,-0.177
26.61,196.64,-0.177
26.63,196.46,-0.178
26.64,196.28,-0.179
26.66,196.10,-0.179
26.68,195.92,-0.180
26.70,195.74,-0.180
26.72,195.56,-0.180
26.73,195.38,-0.180
26.75,195.21,-0.181
26.77,195.02,-0.181
26.79,194.84,-0.181
26.81,194.66,-0.181
26.83,194.48,-0.181
26.84,194.30,-0.181
26.86,194.12,-0.182
26.88,193.94,-0.182
26.90,193.76,-0.182
26.92,193.58,-0.182
26.94,193.40,-0.182
26.96,193.22,-0.182
26.97,193.03,-0.182
26.99,192.85,-0.182
27.01,192.67,-0.182
27.03,192.49,-0.182
27.05,192.31,-0.182
27.07,192.13,-0.182
27.08,191.94,-0.182
27.10,191.76,-0.182
27.12,191.58,-0.182
27.14,191.40,-0.182
27.16,191.22,-0.182
27.18,191.04,-0.182
27.19,190.85,-0.182
27.21,190.67,-0.182
27.23,190.49,-0.182
27.25,190.31,-0.182
27.27,190.12,-0.182
27.28,189.94,-0.182
27.30,189.76,-0.182
27.32,189.58,-0.182
27.34,189.39,-0.182
27.36,189.21,-0.182
27.38,189.03,-0.182
27.39,188.85,-0.182
27.41,188.66,-0.182
27.43,188.48,-0.182
27.45,188.30,-0.182
27.47,188.12,-0.182
27.49,187.93,-0.182
27.51,187.75,-0.182
27.52,187.57,-0.182
27.54,187.39,-0.182
27.56,187.20,-0.182
27.58,187.02,-0.182
27.60,186.84,-0.182
27.62,186.65,-0.182
27.63,186.47,-0.182
27.65,186.29,-0.182
27.67,186.11,-0.182
27.69,185.93,-0.182
27.71,185.74,-0.182
27.73,185.56,-0.182
27.74,185.38,-0.182
27.76,185.19,-0.182
27.78,185.01,-0.182
27.80,184.83,-0.182
27.82,184.65,-0.182
27.83,184.46,-0.182
27.85,184.28,-0.182
27.87,184.10,-0.182
27.89,183.91,-0.182
27.91,183.73,-0.182
27.93,183.55,-0.182
27.94,183.36,-0.182
27.96,183.18,-0.182
27.98,183.00,-0.182
28.00,182.81,-0.182
28.02,182.63,-0.182
28.04,182.45,-0.182
28.06,182.27,-0.182
28.07,182.08,-0.182
28.09,181.90,-0.182
28.11,181.72,-0.182
28.13,181.53,-0.181
28.15,181.35,-0.181
28.17,181.17,-0.181
28.18,180.98,-0.181
28.20,180.80,-0.181
28.22,180.62,-0.181
28.24,180.44,-0.181
28.26,180.25,-0.181
28.28,180.07,-0.181
28.29,179.89,-0.181
28.31,179.70,-0.181
28.33,179.52,-0.181
28.35,179.34,-0.181
28.37,179.15,-0.181
28.38,178.97,-0.181
28.40,178.79,-0.181
28.42,178.61,-0.181
28.44,178.42,-0.181
28.46,178.24,-0.181
28.48,178.06,-0.181
28.49,177.87,-0.181
28.51,177.69,-0.181
28.53,177.51,-0.181
28.55,177.33,-0.180
28.57,177.14,-0.180
28.59,176.96,-0.180
28.61,176.78,-0.180
28.62,176.59,-0.180
28.64,176.41,-0.180
28.66,176.23,-0.180
28.68,176.04,-0.180
28.70,175.86,-0.180
28.72,175.68,-0.180
28.73,175.49,-0.180
28.75,175.31,-0.180
28.77,175.13,-0.180
28.79,174.94,-0.180
28.81,174.76,-0.180
28.83,174.58,-0.180
28.84,174.40,-0.180
28.86,174.21,-0.180
28.88,174.03,-0.180
28.90,173.85,-0.180
28.92,173.66,-0.180
28.93,173.48,-0.180
28.95,173.30,-0.180
28.97,173.11,-0.180
28.99,172.93,-0.180
29.01,172.75,-0.179
29.03,172.57,-0.179
29.04,172.38,-0.179
29.06,172.20,-0.179
29.08,172.02,-0.179
29.10,171.83,-0.179
29.12,171.65,-0.179
29.14,171.47,-0.179
29.16,171.28,-0.179
29.17,171.10,-0.179
29.19,170.92,-0.179
29.21,170.73,-0.179
29.23,170.55,-0.179
29.25,170.37,-0.179
29.27,170.18,-0.179
29.28,170.00,-0.179
29.30,169.82,-0.179
29.32,169.63,-0.179
29.34,169.45,-0.179
29.36,169.27,-0.179
29.38,169.08,-0.179
29.39,168.90,-0.179
29.41,168.72,-0.179
29.43,168.54,-0.178
29.45,168.35,-0.178
29.47,168.17,-0.178
29.48,167.99,-0.178
29.50,167.80,-0.178
29.52,167.62,-0.178
29.54,167.44,-0.178
29.56,167.25,-0.178
29.58,167.07,-0.178
29.59,166.89,-0.178
29.61,166.70,-0.178
29.63,166.52,-0.178
29.65,166.34,-0.178
29.67,166.16,-0.178
29.69,165.97,-0.178
29.71,165.79,-0.178
29.72,165.61,-0.178
29.74,165.42,-0.178
29.76,165.24,-0.178
29.78,165.06,-0.178
29.80,164.87,-0.178
29.82,164.69,-0.178
29.83,164.51,-0.177
29.85,164.32,-0.177
29.87,164.14,-0.177
29.89,163.96,-0.177
29.91,163.78,-0.177
29.93,163.59,-0.177
29.94,163.41,-0.177
29.96,163.23,-0.177
29.98,163.04,-0.177
30.00,162.86,-0.177
30.02,162.68,-0.177
30.03,162.49,-0.177
30.05,162.31,-0.177
30.07,162.13,-0.177
30.09,161.94,-0.177
30.11,161.76,-0.177
30.13,161.58,-0.177
30.14,161.39,-0.177
30.16,161.21,-0.177
30.18,161.03,-0.177
30.20,160.85,-0.177
30.22,160.66,-0.177
30.24,160.48,-0.177
30.26,160.30,-0.176
30.27,160.11,-0.176
30.29,159.93,-0.176
30.31,159.75,-0.176
30.33,159.56,-0.176
30.35,159.38,-0.176
30.37,159.20,-0.176
30.38,159.01,-0.176
30.40,158.83,-0.176
30.42,158.65,-0.176
30.44,158.46,-0.176
30.46,158.28,-0.176
30.48,158.10,-0.176
30.49,157.92,-0.176
30.51,157.73,-0.176
30.53,157.55,-0.176
30.55,157.37,-0.176
30.57,157.18,-0.176
30.58,157.00,-0.176
30.60,156.82,-0.176
30.62,156.63,-0.176
30.64,156.45,-0.176
30.66,156.27,-0.176
30.68,156.08,-0.176
30.69,155.90,-0.176
30.71,155.72,-0.176
30.73,155.54,-0.175
30.75,155.35,-0.175
30.77,155.17,-0.175
30.79,154.99,-0.175
30.81,154.80,-0.175
30.82,154.62,-0.175
30.84,154.44,-0.175
30.86,154.25,-0.175
30.88,154.07,-0.175
30.90,153.89,-0.175
30.92,153.70,-0.175
30.93,153.52,-0.175
30.95,153.34,-0.175
30.97,153.15,-0.175
30.99,152.97,-0.175
31.01,152.79,-0.175
31.03,152.60,-0.175
31.04,152.42,-0.175
31.06,152.24,-0.175
31.08,152.05,-0.175
31.10,151.87,-0.175
31.12,151.69,-0.175
31.13,151.51,-0.175
31.15,151.32,-0.175
31.17,151.14,-0.175
31.19,150.96,-0.174
31.21,150.77,-0.174
31.23,150.59,-0.174
31.24,150.41,-0.174
31.26,150.22,-0.174
31.28,150.04,-0.174
31.30,149.86,-0.174
31.32,149.67,-0.174
31.34,149.49,-0.174
31.36,149.31,-0.174
31.37,149.13,-0.174
31.39,148.94,-0.174
31.41,148.76,-0.174
31.43,148.57,-0.174
31.45,148.39,-0.174
31.47,148.21,-0.174
31.48,148.03,-0.174
31.50,147.84,-0.174
31.52,147.66,-0.174
31.54,147.48,-0.174
31.56,147.29,-0.174
31.58,147.11,-0.174
31.59,146.93,-0.174
31.61,146.74,-0.173
31.63,146.56,-0.173
31.65,146.38,-0.173
31.67,146.19,-0.173
31.68,146.01,-0.173
31.70,145.83,-0.173
31.72,145.64,-0.173
31.74,145.46,-0.173
31.76,145.28,-0.173
31.78,145.10,-0.173
31.79,144.91,-0.173
31.81,144.73,-0.173
31.83,144.55,-0.173
31.85,144.36,-0.173
31.87,144.18,-0.173
31.89,144.00,-0.173
31.91,143.81,-0.173
31.92,143.63,-0.173
31.94,143.45,-0.173
31.96,143.26,-0.173
31.98,143.08,-0.172
32.00,142.90,-0.172
32.02,142.71,-0.172
32.03,142.53,-0.172
32.05,142.35,-0.172
32.07,142.16,-0.172
32.09,141.98,-0.172
32.11,141.80,-0.172
32.13,141.62,-0.172
32.14,141.43,-0.172
32.16,141.25,-0.172
32.18,141.07,-0.172
32.20,140.88,-0.172
32.22,140.70,-0.172
32.23,140.52,-0.172
32.25,140.33,-0.172
32.27,140.15,-0.172
32.29,139.97,-0.172
32.31,139.78,-0.172
32.33,139.60,-0.172
32.34,139.42,-0.172
32.36,139.24,-0.172
32.38,139.05,-0.171
32.40,138.87,-0.171
32.42,138.69,-0.171
32.44,138.50,-0.171
32.46,138.32,-0.171
32.47,138.14,-0.171
32.49,137.95,-0.171
32.51,137.77,-0.171
32.53,137.59,-0.171
32.55,137.40,-0.171
32.57,137.22,-0.171
32.58,137.04,-0.171
32.60,136.85,-0.171
32.62,136.67,-0.171
32.64,136.49,-0.171
32.66,136.31,-0.171
32.68,136.12,-0.171
32.69,135.94,-0.171
32.71,135.76,-0.171
32.73,135.57,-0.171
32.75,135.39,-0.171
32.77,135.21,-0.171
32.78,135.02,-0.170
32.80,134.84,-0.170
32.82,134.66,-0.170
32.84,134.47,-0.170
32.86,134.29,-0.170
32.88,134.11,-0.170
32.89,133.92,-0.170
32.91,133.74,-0.170
32.93,133.56,-0.170
32.95,133.38,-0.170
32.97,133.19,-0.170
32.99,133.01,-0.170
33.01,132.83,-0.170
33.02,132.64,-0.170
33.04,132.46,-0.170
33.06,132.28,-0.170
33.08,132.09,-0.170
33.10,131.91,-0.170
33.12,131.73,-0.170
33.13,131.54,-0.170
33.15,131.36,-0.170
33.17,131.18,-0.170
33.19,130.99,-0.169
33.21,130.81,-0.169
33.23,130.63,-0.169
33.24,130.45,-0.169
33.26,130.26,-0.169
33.28,130.08,-0.169
33.30,129.90,-0.169
33.32,129.71,-0.169
33.33,129.53,-0.169
33.35,129.35,-0.169
33.37,129.16,-0.169
33.39,128.98,-0.169
33.41,128.80,-0.169
33.43,128.62,-0.169
33.44,128.43,-0.169
33.46,128.25,-0.169
[...]
108.29,-40.94,0.092
108.30,-40.87,0.092
108.30,-40.81,0.092
108.31,-40.74,0.092
108.31,-40.67,0.092
108.32,-40.61,0.092
108.33,-40.54,0.092
108.34,-40.47,0.092
108.34,-40.41,0.092
108.35,-40.34,0.092
108.35,-40.27,0.092
108.36,-40.21,0.092
108.37,-40.14,0.092
108.38,-40.07,0.093
108.38,-40.01,0.093
108.39,-39.94,0.093
108.40,-39.87,0.093
108.40,-39.81,0.093
108.41,-39.74,0.093
108.41,-39.67,0.093
108.42,-39.61,0.093
108.43,-39.54,0.093
108.44,-39.47,0.093
108.44,-39.41,0.093
108.45,-39.34,0.093
108.45,-39.27,0.093
108.46,-39.21,0.093
108.47,-39.14,0.093
108.48,-39.07,0.093
108.48,-39.01,0.093
108.49,-38.94,0.093
108.50,-38.87,0.093
108.50,-38.81,0.093
108.51,-38.74,0.093
108.51,-38.67,0.093
108.52,-38.61,0.093
108.53,-38.54,0.093
108.54,-38.47,0.093
108.54,-38.41,0.093
108.55,-38.34,0.093
108.55,-38.27,0.093
108.56,-38.21,0.093
108.57,-38.14,0.093
108.58,-38.07,0.093
108.58,-38.00,0.093
108.59,-37.94,0.093
108.60,-37.87,0.093
108.60,-37.81,0.093
108.61,-37.74,0.093
108.61,-37.67,0.093
108.62,-37.60,0.093
108.63,-37.54,0.093
108.64,-37.47,0.094
108.64,-37.40,0.094
108.65,-37.34,0.094
108.65,-37.27,0.094
108.66,-37.21,0.094
108.67,-37.14,0.094
108.68,-37.07,0.094
108.68,-37.00,0.094
108.69,-36.94,0.094
108.70,-36.87,0.094
108.70,-36.80,0.094
108.71,-36.74,0.094
108.71,-36.67,0.094
108.72,-36.60,0.094
108.73,-36.54,0.094
108.74,-36.47,0.094
108.74,-36.40,0.094
108.75,-36.34,0.094
108.75,-36.27,0.094
108.76,-36.20,0.094
108.77,-36.14,0.094
108.78,-36.07,0.094
108.78,-36.01,0.094
108.79,-35.94,0.094
108.80,-35.87,0.094
108.80,-35.80,0.094
108.81,-35.74,0.094
108.81,-35.67,0.094
108.82,-35.60,0.094
108.83,-35.54,0.094
108.84,-35.47,0.094
108.84,-35.40,0.094
108.85,-35.34,0.094
108.85,-35.27,0.094
108.86,-35.20,0.094
108.87,-35.14,0.094
108.88,-35.07,0.094
108.88,-35.00,0.094
108.89,-34.94,0.094
108.90,-34.87,0.095
108.90,-34.80,0.095
108.91,-34.74,0.095
108.91,-34.67,0.095
108.92,-34.60,0.095
108.93,-34.54,0.095
108.94,-34.47,0.095
108.94,-34.40,0.095
108.95,-34.34,0.095
108.95,-34.27,0.095
108.96,-34.20,0.095
108.97,-34.14,0.095
108.98,-34.07,0.095
108.98,-34.00,0.095
108.99,-33.94,0.095
109.00,-33.87,0.095
109.00,-33.80,0.095
109.01,-33.73,0.095
109.01,-33.67,0.095
109.02,-33.60,0.095
109.03,-33.54,0.095
109.04,-33.47,0.095
109.04,-33.40,0.095
109.05,-33.33,0.095
109.05,-33.27,0.095
109.06,-33.20,0.095
109.07,-33.14,0.095
109.08,-33.07,0.095
109.08,-33.00,0.095
109.09,-32.94,0.095
109.10,-32.87,0.095
109.10,-32.80,0.095
109.11,-32.74,0.095
109.11,-32.67,0.095
109.12,-32.60,0.095
109.13,-32.54,0.095
109.14,-32.47,0.095
109.14,-32.40,0.095
109.15,-32.33,0.095
109.15,-32.27,0.096
109.16,-32.20,0.096
109.17,-32.13,0.096
109.18,-32.07,0.096
109.18,-32.00,0.096
109.19,-31.93,0.096
109.20,-31.87,0.096
109.20,-31.80,0.096
109.21,-31.73,0.096
109.21,-31.67,0.096
109.22,-31.60,0.096
109.23,-31.53,0.096
109.24,-31.47,0.096
109.24,-31.40,0.096
109.25,-31.33,0.096
109.25,-31.27,0.096
109.26,-31.20,0.096
109.27,-31.13,0.096
109.28,-31.07,0.096
109.28,-31.00,0.096
109.29,-30.93,0.096
109.30,-30.87,0.096
109.30,-30.80,0.096
109.31,-30.73,0.096
109.31,-30.67,0.096
109.32,-30.60,0.096
109.33,-30.53,0.096
109.34,-30.46,0.096
109.34,-30.40,0.096
109.35,-30.33,0.096
109.35,-30.26,0.096
109.36,-30.20,0.096
109.37,-30.13,0.096
109.38,-30.06,0.096
109.38,-30.00,0.096
109.39,-29.93,0.096
109.40,-29.87,0.097
109.40,-29.80,0.097
109.41,-29.73,0.097
109.41,-29.67,0.097
109.42,-29.60,0.097
109.43,-29.53,0.097
109.44,-29.46,0.097
109.44,-29.40,0.097
109.45,-29.33,0.097
109.45,-29.26,0.097
109.46,-29.20,0.097
109.47,-29.13,0.097
109.48,-29.06,0.097
109.48,-29.00,0.097
109.49,-28.93,0.097
109.50,-28.86,0.097
109.50,-28.80,0.097
109.51,-28.73,0.097
109.51,-28.66,0.097
109.52,-28.60,0.097
109.53,-28.53,0.097
109.54,-28.46,0.097
109.54,-28.40,0.097
109.55,-28.33,0.097
109.55,-28.26,0.097
109.56,-28.20,0.097
109.57,-28.13,0.097
109.58,-28.06,0.097
109.58,-28.00,0.097
109.59,-27.93,0.097
109.60,-27.86,0.097
109.60,-27.80,0.097
109.61,-27.73,0.097
109.61,-27.66,0.097
109.62,-27.60,0.097
109.63,-27.53,0.097
109.64,-27.46,0.097
109.64,-27.40,0.097
109.65,-27.33,0.097
109.65,-27.26,0.098
109.66,-27.20,0.098
109.67,-27.13,0.098
109.68,-27.06,0.098
109.68,-27.00,0.098
109.69,-26.93,0.098
109.70,-26.86,0.098
109.70,-26.79,0.098
109.71,-26.73,0.098
109.71,-26.66,0.098
109.72,-26.60,0.098
109.73,-26.53,0.098
109.74,-26.46,0.098
109.74,-26.40,0.098
109.75,-26.33,0.098
109.75,-26.26,0.098
109.76,-26.19,0.098
109.77,-26.13,0.098
109.78,-26.06,0.098
109.78,-26.00,0.098
109.79,-25.93,0.098
109.80,-25.86,0.098
109.80,-25.79,0.098
109.81,-25.73,0.098
109.81,-25.66,0.098
109.82,-25.59,0.098
109.83,-25.53,0.098
109.84,-25.46,0.098
109.84,-25.39,0.098
109.85,-25.33,0.098
109.85,-25.26,0.098
109.86,-25.19,0.098
109.87,-25.13,0.098
109.88,-25.06,0.098
109.88,-24.99,0.098
109.89,-24.93,0.098
109.90,-24.86,0.098
109.90,-24.79,0.098
109.91,-24.73,0.098
109.91,-24.66,0.099
109.92,-24.59,0.099
109.93,-24.53,0.099
109.94,-24.46,0.099
109.94,-24.39,0.099
109.95,-24.33,0.099
109.95,-24.26,0.099
109.96,-24.19,0.099
109.97,-24.13,0.099
109.98,-24.06,0.099
109.98,-23.99,0.099
109.99,-23.93,0.099
110.00,-23.86,0.099
110.00,-23.79,0.099
110.01,-23.73,0.099
110.01,-23.66,0.099
110.02,-23.59,0.099
110.03,-23.53,0.099
110.04,-23.46,0.099
110.04,-23.39,0.099
110.05,-23.33,0.099
110.05,-23.26,0.099
110.06,-23.19,0.099
110.07,-23.13,0.099
110.08,-23.06,0.099
110.08,-22.99,0.099
110.09,-22.93,0.099
110.10,-22.86,0.099
110.10,-22.79,0.099
110.11,-22.72,0.099
110.11,-22.66,0.099
110.12,-22.59,0.099
110.13,-22.52,0.099
110.14,-22.46,0.099
110.14,-22.39,0.099
110.15,-22.32,0.099
110.15,-22.26,0.099
110.16,-22.19,0.099
110.17,-22.12,0.100
110.18,-22.06,0.100
110.18,-21.99,0.100
110.19,-21.92,0.100
110.20,-21.86,0.100
110.20,-21.79,0.100
110.21,-21.72,0.100
110.21,-21.66,0.100
110.22,-21.59,0.100
110.23,-21.52,0.100
110.24,-21.46,0.100
110.24,-21.39,0.100
110.25,-21.33,0.100
110.25,-21.26,0.100
110.26,-21.19,0.100
110.27,-21.12,0.100
110.28,-21.06,0.100
110.28,-20.99,0.100
110.29,-20.92,0.100
110.30,-20.86,0.100
110.30,-20.79,0.100
110.31,-20.72,0.100
110.31,-20.66,0.100
110.32,-20.59,0.100
110.33,-20.52,0.100
110.34,-20.46,0.100
110.34,-20.39,0.100
110.35,-20.32,0.100
110.35,-20.25,0.100
110.36,-20.19,0.100
110.37,-20.12,0.100
110.38,-20.06,0.100
110.38,-19.99,0.100
110.39,-19.92,0.100
110.40,-19.86,0.100
110.40,-19.79,0.100
110.41,-19.72,0.100
110.41,-19.66,0.100
110.42,-19.59,0.100
110.43,-19.52,0.101
110.44,-19.45,0.101
110.44,-19.39,0.101
110.45,-19.32,0.101
110.45,-19.26,0.101
110.46,-19.19,0.101
110.47,-19.12,0.101
110.48,-19.05,0.101
110.48,-18.99,0.101
110.49,-18.92,0.101
110.50,-18.86,0.101
110.50,-18.79,0.101
110.51,-18.72,0.101
110.51,-18.65,0.101
110.52,-18.59,0.101
110.53,-18.52,0.101
110.54,-18.45,0.101
110.54,-18.39,0.101
110.55,-18.32,0.101
110.55,-18.25,0.101
110.56,-18.19,0.101
110.57,-18.12,0.101
110.58,-18.05,0.101
110.58,-17.99,0.101
110.59,-17.92,0.101
110.60,-17.85,0.101
110.60,-17.79,0.101
110.61,-17.72,0.101
110.61,-17.65,0.101
110.62,-17.59,0.101
110.63,-17.52,0.101
110.64,-17.45,0.101
110.64,-17.39,0.101
110.65,-17.32,0.101
110.65,-17.25,0.102
110.66,-17.19,0.102
110.67,-17.12,0.102
110.68,-17.05,0.102
110.68,-16.99,0.102
110.69,-16.92,0.102
110.70,-16.85,0.102
110.70,-16.79,0.102
110.71,-16.72,0.102
110.71,-16.65,0.102
110.72,-16.59,0.102
110.73,-16.52,0.102
110.74,-16.45,0.102
110.74,-16.39,0.102
110.75,-16.32,0.102
110.75,-16.25,0.102
110.76,-16.19,0.102
110.77,-16.12,0.102
110.78,-16.05,0.102
110.78,-15.99,0.102
110.79,-15.92,0.102
110.80,-15.85,0.102
110.80,-15.79,0.102
110.81,-15.72,0.102
110.81,-15.65,0.102
110.82,-15.59,0.102
110.83,-15.52,0.102
110.84,-15.45,0.102
110.84,-15.39,0.102
110.85,-15.32,0.102
110.85,-15.25,0.102
110.86,-15.19,0.102
110.87,-15.12,0.102
110.88,-15.05,0.102
110.88,-14.98,0.102
110.89,-14.92,0.102
110.90,-14.85,0.102
110.90,-14.78,0.102
110.91,-14.72,0.102
110.91,-14.65,0.102
110.92,-14.59,0.102
110.93,-14.52,0.102
110.94,-14.45,0.102
110.94,-14.38,0.102
110.95,-14.32,0.102
110.95,-14.25,0.103
110.96,-14.18,0.103
110.97,-14.12,0.103
110.98,-14.05,0.103
110.98,-13.98,0.103
110.99,-13.92,0.103
111.00,-13.85,0.103
111.00,-13.79,0.103
111.01,-13.72,0.103
111.01,-13.65,0.103
111.02,-13.59,0.103
111.03,-13.52,0.103
111.04,-13.45,0.103
111.04,-13.39,0.103
111.05,-13.32,0.103
111.05,-13.25,0.103
111.06,-13.19,0.103
111.07,-13.12,0.103
111.08,-13.05,0.103
111.08,-12.99,0.103
111.09,-12.92,0.103
111.10,-12.85,0.103
111.10,-12.78,0.103
111.11,-12.72,0.103
111.11,-12.65,0.103
111.12,-12.59,0.103
111.13,-12.52,0.103
111.14,-12.45,0.103
111.14,-12.38,0.103
111.15,-12.32,0.103
111.15,-12.25,0.103
111.16,-12.18,0.103
111.17,-12.12,0.103
111.18,-12.05,0.103
111.18,-11.98,0.103
111.19,-11.92,0.103
111.20,-11.85,0.103
111.20,-11.78,0.103
111.21,-11.72,0.103
111.21,-11.65,0.103
111.22,-11.58,0.104
111.23,-11.52,0.104
111.24,-11.45,0.104
111.24,-11.38,0.104
111.25,-11.32,0.104
111.25,-11.25,0.104
111.26,-11.18,0.104
111.27,-11.12,0.104
111.28,-11.05,0.104
111.28,-10.98,0.104
111.29,-10.92,0.104
111.30,-10.85,0.104
111.30,-10.78,0.104
111.31,-10.72,0.104
111.31,-10.65,0.104
111.32,-10.58,0.104
111.33,-10.52,0.104
111.34,-10.45,0.104
111.34,-10.38,0.104
111.35,-10.32,0.104
111.35,-10.25,0.104
111.36,-10.18,0.104
111.37,-10.12,0.104
111.38,-10.05,0.104
111.38,-9.98,0.104
111.39,-9.91,0.104
111.40,-9.85,0.104
111.40,-9.78,0.104
111.41,-9.72,0.104
111.41,-9.65,0.104
111.42,-9.58,0.104
111.43,-9.51,0.104
111.44,-9.45,0.104
111.44,-9.38,0.104
111.45,-9.31,0.104
111.45,-9.25,0.104
111.46,-9.18,0.104
111.47,-9.12,0.104
111.48,-9.05,0.105
111.48,-8.98,0.105
111.49,-8.91,0.105
111.50,-8.85,0.105
111.50,-8.78,0.105
111.51,-8.72,0.105
111.51,-8.65,0.105
111.52,-8.58,0.105
111.53,-8.51,0.105
111.54,-8.45,0.105
111.54,-8.38,0.105
111.55,-8.31,0.105
111.55,-8.25,0.105
111.56,-8.18,0.105
111.57,-8.11,0.105
111.58,-8.05,0.105
111.58,-7.98,0.105
111.59,-7.91,0.105
111.60,-7.85,0.105
111.60,-7.78,0.105
111.61,-7.71,0.105
111.61,-7.65,0.105
111.62,-7.58,0.105
111.63,-7.51,0.105
111.64,-7.45,0.105
111.64,-7.38,0.105
111.65,-7.31,0.105
111.65,-7.25,0.105
111.66,-7.18,0.105
111.67,-7.11,0.105
111.68,-7.05,0.105
111.68,-6.98,0.105
111.69,-6.91,0.105
111.70,-6.85,0.105
111.70,-6.78,0.105
111.71,-6.71,0.105
111.71,-6.65,0.106
111.72,-6.58,0.106
111.73,-6.51,0.106
111.74,-6.45,0.106
111.74,-6.38,0.106
111.75,-6.31,0.106
111.75,-6.24,0.106
111.76,-6.18,0.106
111.77,-6.11,0.106
111.78,-6.04,0.106
111.78,-5.98,0.106
111.79,-5.91,0.106
111.80,-5.84,0.106
111.80,-5.78,0.106
111.81,-5.71,0.106
111.81,-5.64,0.106
111.82,-5.58,0.106
111.83,-5.51,0.106
111.84,-5.44,0.106
111.84,-5.38,0.106
111.85,-5.31,0.106
111.85,-5.24,0.106
111.86,-5.18,0.106
111.87,-5.11,0.106
111.88,-5.04,0.106
111.88,-4.98,0.106
111.89,-4.91,0.106
111.90,-4.84,0.106
111.90,-4.78,0.106
111.91,-4.71,0.106
111.91,-4.64,0.106
111.92,-4.58,0.106
111.93,-4.51,0.106
111.94,-4.44,0.106
111.94,-4.38,0.106
111.95,-4.31,0.106
111.95,-4.24,0.106
111.96,-4.18,0.106
111.97,-4.11,0.106
111.98,-4.04,0.106
111.98,-3.98,0.107
111.99,-3.91,0.107
112.00,-3.84,0.107
112.00,-3.78,0.107
112.01,-3.71,0.107
112.01,-3.64,0.107
112.02,-3.58,0.107
112.03,-3.51,0.107
112.04,-3.44,0.107
112.04,-3.38,0.107
112.05,-3.31,0.107
112.05,-3.24,0.107
112.06,-3.18,0.107
112.07,-3.11,0.107
112.08,-3.04,0.107
112.08,-2.98,0.107
112.09,-2.91,0.107
112.10,-2.84,0.107
112.10,-2.78,0.107
112.11,-2.71,0.107
112.11,-2.64,0.107
112.12,-2.58,0.107
112.13,-2.51,0.107
112.14,-2.44,0.107
112.14,-2.38,0.107
112.15,-2.31,0.107
112.15,-2.24,0.107
112.16,-2.17,0.107
112.17,-2.11,0.107
112.18,-2.04,0.107
112.18,-1.97,0.107
112.19,-1.91,0.107
112.20,-1.84,0.107
112.20,-1.77,0.107
112.21,-1.71,0.107
112.21,-1.64,0.107
112.22,-1.57,0.107
112.23,-1.51,0.107
112.24,-1.44,0.108
112.24,-1.37,0.108
112.25,-1.31,0.108
112.25,-1.24,0.108
112.26,-1.17,0.108
112.27,-1.11,0.108
112.28,-1.04,0.108
112.28,-0.97,0.108
112.29,-0.91,0.108
112.30,-0.84,0.108
112.30,-0.77,0.108
112.31,-0.71,0.108
112.31,-0.64,0.108
112.32,-0.57,0.108
112.33,-0.51,0.108
112.34,-0.44,0.108
112.34,-0.37,0.108
112.35,-0.30,0.108
112.35,-0.24,0.108
112.36,-0.17,0.108
112.37,-0.11,0.108
112.38,-0.04,0.108
112.38,0.03,0.108
112.39,0.09,0.108
112.40,0.16,0.108
112.40,0.23,0.108
112.41,0.30,0.108
112.41,0.36,0.108
112.42,0.43,0.108
112.43,0.49,0.108
112.44,0.56,0.108
112.44,0.63,0.108
112.45,0.69,0.108
112.45,0.76,0.108
112.46,0.83,0.108
112.47,0.90,0.108
112.48,0.96,0.108
112.48,1.03,0.108
112.49,1.10,0.108
112.50,1.16,0.108
112.50,1.23,0.108
112.51,1.30,0.108
112.51,1.36,0.108
112.52,1.43,0.109
112.53,1.50,0.109
112.54,1.56,0.109
112.54,1.63,0.109
112.55,1.70,0.109
112.55,1.76,0.109
112.56,1.83,0.109
112.57,1.90,0.109
112.58,1.96,0.109
112.58,2.03,0.109
112.59,2.10,0.109
112.60,2.16,0.109
112.60,2.23,0.109
112.61,2.30,0.109
112.61,2.36,0.109
112.62,2.43,0.109
112.63,2.50,0.109
112.64,2.56,0.109
112.64,2.63,0.109
112.65,2.70,0.109
112.65,2.76,0.109
112.66,2.83,0.109
112.67,2.90,0.109
112.68,2.96,0.109
112.68,3.03,0.109
112.69,3.10,0.109
112.70,3.17,0.109
112.70,3.23,0.109
112.71,3.30,0.109
112.71,3.36,0.109
112.72,3.43,0.109
112.73,3.50,0.109
112.74,3.57,0.109
112.74,3.63,0.109
112.75,3.70,0.109
112.75,3.76,0.109
112.76,3.83,0.109
112.77,3.90,0.110
112.78,3.97,0.110
112.78,4.03,0.110
112.79,4.10,0.110
112.80,4.17,0.110
112.80,4.23,0.110
112.81,4.30,0.110
112.81,4.37,0.110
112.82,4.43,0.110
112.83,4.50,0.110
112.84,4.57,0.110
112.84,4.63,0.110
112.85,4.70,0.110
112.85,4.77,0.110
112.86,4.83,0.110
112.87,4.90,0.110
112.88,4.97,0.110
112.88,5.03,0.110
112.89,5.10,0.110
112.90,5.17,0.110
112.90,5.23,0.110
112.91,5.30,0.110
112.91,5.37,0.110
112.92,5.43,0.110
112.93,5.50,0.110
112.94,5.57,0.110
112.94,5.63,0.110
112.95,5.70,0.110
112.95,5.77,0.110
112.96,5.83,0.110
112.97,5.90,0.110
112.98,5.97,0.110
112.98,6.03,0.110
112.99,6.10,0.110
113.00,6.17,0.110
113.00,6.23,0.110
113.01,6.30,0.110
113.01,6.37,0.110
113.02,6.43,0.110
113.03,6.50,0.111
113.04,6.57,0.111
113.04,6.63,0.111
113.05,6.70,0.111
113.05,6.77,0.111
113.06,6.83,0.111
113.07,6.90,0.111
113.08,6.97,0.111
113.08,7.03,0.111
113.09,7.10,0.111
113.10,7.17,0.111
113.10,7.24,0.111
113.11,7.30,0.111
113.11,7.37,0.111
113.12,7.43,0.111
113.13,7.50,0.111
113.14,7.57,0.111
113.14,7.64,0.111
113.15,7.70,0.111
113.15,7.77,0.111
113.16,7.84,0.111
113.17,7.90,0.111
113.18,7.97,0.111
113.18,8.04,0.111
113.19,8.10,0.111
113.20,8.17,0.111
113.20,8.24,0.111
113.21,8.30,0.111
113.21,8.37,0.111
113.22,8.44,0.111
113.23,8.50,0.111
113.24,8.57,0.111
113.24,8.64,0.111
113.25,8.70,0.111
113.25,8.77,0.111
113.26,8.84,0.111
113.27,8.91,0.112
113.28,8.97,0.112
113.28,9.04,0.112
113.29,9.10,0.112
113.30,9.17,0.112
113.30,9.24,0.112
113.31,9.30,0.112
113.31,9.37,0.112
113.32,9.44,0.112
113.33,9.51,0.112
113.34,9.57,0.112
113.34,9.64,0.112
113.35,9.71,0.112
113.35,9.77,0.112
113.36,9.84,0.112
113.37,9.91,0.112
113.38,9.97,0.112
113.38,10.04,0.112
113.39,10.11,0.112
113.40,10.17,0.112
113.40,10.24,0.112
113.41,10.31,0.112
113.41,10.37,0.112
113.42,10.44,0.112
113.43,10.51,0.112
113.44,10.57,0.112
113.44,10.64,0.112
113.45,10.71,0.112
113.45,10.77,0.112
113.46,10.84,0.112
113.47,10.91,0.112
113.48,10.97,0.112
113.48,11.04,0.112
113.49,11.11,0.112
113.50,11.17,0.112
113.50,11.24,0.112
113.51,11.30,0.113
113.51,11.37,0.113
113.52,11.44,0.113
113.53,11.51,0.113
113.54,11.57,0.113
113.54,11.64,0.113
113.55,11.71,0.113
113.55,11.77,0.113
113.56,11.84,0.113
113.57,11.91,0.113
113.58,11.97,0.113
113.58,12.04,0.113
113.59,12.11,0.113
113.60,12.17,0.113
113.60,12.24,0.113
113.61,12.31,0.113
113.61,12.37,0.113
113.62,12.44,0.113
113.63,12.51,0.113
113.64,12.57,0.113
113.64,12.64,0.113
113.65,12.71,0.113
113.65,12.77,0.113
113.66,12.84,0.113
113.67,12.91,0.113
113.68,12.97,0.113
113.68,13.04,0.113
113.69,13.11,0.113
113.70,13.17,0.113
113.70,13.24,0.113
113.71,13.31,0.113
113.71,13.37,0.113
113.72,13.44,0.113
113.73,13.51,0.113
113.74,13.57,0.113
113.74,13.64,0.113
113.75,13.71,0.113
113.75,13.77,0.113
113.76,13.84,0.113
113.77,13.91,0.113
113.78,13.97,0.113
113.78,14.04,0.114
113.79,14.11,0.114
113.80,14.17,0.114
113.80,14.24,0.114
113.81,14.31,0.114
113.81,14.38,0.114
113.82,14.44,0.114
113.83,14.51,0.114
113.84,14.58,0.114
113.84,14.64,0.114
113.85,14.71,0.114
113.85,14.78,0.114
113.86,14.84,0.114
113.87,14.91,0.114
113.88,14.98,0.114
113.88,15.04,0.114
113.89,15.11,0.114
113.90,15.18,0.114
113.90,15.24,0.114
113.91,15.31,0.114
113.91,15.38,0.114
113.92,15.44,0.114
113.93,15.51,0.114
113.94,15.58,0.114
113.94,15.64,0.114
113.95,15.71,0.114
113.95,15.78,0.114
113.96,15.84,0.114
113.97,15.91,0.114
113.98,15.98,0.114
113.98,16.04,0.114
113.99,16.11,0.114
114.00,16.18,0.114
114.00,16.24,0.114
114.01,16.31,0.114
114.01,16.38,0.114
114.02,16.44,0.114
114.03,16.51,0.114
114.04,16.58,0.114
114.04,16.64,0.114
114.05,16.71,0.114
114.05,16.78,0.114
114.06,16.84,0.114
114.07,16.91,0.114
114.08,16.98,0.114
114.08,17.04,0.114
114.09,17.11,0.115
114.10,17.18,0.115
114.10,17.24,0.115
114.11,17.31,0.115
114.11,17.38,0.115
114.12,17.44,0.115
114.13,17.51,0.115
114.14,17.58,0.115
114.14,17.64,0.115
114.15,17.71,0.115
114.15,17.78,0.115
114.16,17.84,0.115
114.17,17.91,0.115
114.18,17.98,0.115
114.18,18.04,0.115
114.19,18.11,0.115
114.20,18.18,0.115
114.20,18.24,0.115
114.21,18.31,0.115
114.21,18.38,0.115
114.22,18.45,0.115
114.23,18.51,0.115
114.24,18.58,0.115
114.24,18.64,0.115
114.25,18.71,0.115
114.25,18.78,0.115
114.26,18.84,0.115
114.27,18.91,0.115
114.28,18.98,0.115
114.28,19.04,0.115
114.29,19.11,0.115
114.30,19.18,0.115
114.30,19.25,0.115
114.31,19.31,0.115
114.31,19.38,0.115
114.32,19.45,0.115
114.33,19.51,0.115
114.34,19.58,0.115
114.34,19.65,0.115
114.35,19.71,0.116
114.35,19.78,0.116
114.36,19.85,0.116
114.37,19.91,0.116
114.38,19.98,0.116
114.38,20.05,0.116
114.39,20.11,0.116
114.40,20.18,0.116
114.40,20.25,0.116
114.41,20.31,0.116
114.41,20.38,0.116
114.42,20.45,0.116
114.43,20.51,0.116
114.44,20.58,0.116
114.44,20.65,0.116
114.45,20.72,0.116
114.45,20.78,0.116
114.46,20.85,0.116
114.47,20.91,0.116
114.48,20.98,0.116
114.48,21.05,0.116
114.49,21.12,0.116
114.50,21.18,0.116
114.50,21.25,0.116
114.51,21.32,0.116
114.51,21.38,0.116
114.52,21.45,0.116
114.53,21.52,0.116
114.54,21.58,0.116
114.54,21.65,0.116
114.55,21.72,0.116
114.55,21.78,0.116
114.56,21.85,0.116
114.57,21.91,0.116
114.58,21.98,0.116
114.58,22.05,0.116
114.59,22.12,0.116
114.60,22.18,0.117
114.60,22.25,0.117
114.61,22.32,0.117
114.61,22.38,0.117
114.62,22.45,0.117
114.63,22.52,0.117
114.64,22.58,0.117
114.64,22.65,0.117
114.65,22.72,0.117
114.65,22.78,0.117
114.66,22.85,0.117
114.67,22.92,0.117
114.68,22.98,0.117
114.68,23.05,0.117
114.69,23.12,0.117
114.70,23.18,0.117
114.70,23.25,0.117
114.71,23.32,0.117
114.71,23.38,0.117
114.72,23.45,0.117
114.73,23.52,0.117
114.74,23.58,0.117
114.74,23.65,0.117
114.75,23.72,0.117
114.75,23.78,0.117
114.76,23.85,0.117
114.77,23.92,0.117
114.78,23.98,0.117
114.78,24.05,0.117
114.79,24.12,0.117
114.80,24.18,0.117
114.80,24.25,0.117
114.81,24.32,0.117
114.81,24.38,0.117
114.82,24.45,0.117
114.83,24.52,0.117
114.84,24.58,0.117
114.84,24.65,0.117
114.85,24.72,0.117
114.85,24.78,0.117
114.86,24.85,0.118
114.87,24.92,0.118
114.88,24.98,0.118
114.88,25.05,0.118
114.89,25.12,0.118
114.90,25.19,0.118
114.90,25.25,0.118
114.91,25.32,0.118
114.91,25.39,0.118
114.92,25.45,0.118
114.93,25.52,0.118
114.94,25.59,0.118
114.94,25.65,0.118
114.95,25.72,0.118
114.95,25.79,0.118
114.96,25.85,0.118
114.97,25.92,0.118
114.98,25.99,0.118
114.98,26.05,0.118
114.99,26.12,0.118
115.00,26.19,0.118
115.00,26.25,0.118
115.01,26.32,0.118
115.01,26.39,0.118
115.02,26.45,0.118
115.03,26.52,0.118
115.04,26.59,0.118
115.04,26.65,0.118
115.05,26.72,0.118
115.05,26.79,0.118
115.06,26.85,0.118
115.07,26.92,0.118
115.08,26.99,0.118
115.08,27.05,0.118
115.09,27.12,0.118
115.10,27.19,0.118
115.10,27.25,0.118
115.11,27.32,0.118
115.11,27.39,0.118
115.12,27.45,0.118
115.13,27.52,0.118
115.14,27.59,0.119
115.14,27.66,0.119
115.15,27.72,0.119
115.15,27.79,
115.16,27.86,
115.17,27.92,
115.18,27.99,
115.18,28.05,
115.19,28.12,
115.20,28.19,
115.20,,
115.21,,