File: DSC/2025_04_13_CBN_Powder_n60C_150C_10Cmin_x3.csv
Filename,2025_04_13_CBN_Powder_n60C_150C_10Cmin_x3
Instrument name,DSC2A-00468 (192.168.1.100)
Operator,Yarger
rundate,4/13/2025
Sample name,2025_04_13_CBN_Powder_n60C_150C_10Cmin_x3
proceduresegments,Data Off ; Equilibrate -60.00 °C; Data On ; Ramp 10.00 °C/min to 150.00 °C; Data Off ; Isothermal 1.0 min; Data On ; Ramp 10.00 °C/min to -60.00 °C; Data Off ; Isothermal 1.0 min; Data On ; Ramp 10.00 °C/min to 150.00 °C; Data Off ; Isothermal 1.0 min; Data On ; Ramp 10.00 °C/min to -60.00 °C; Data Off ; Isothermal 1.0 min; Data On ; Ramp 10.00 °C/min to 150.00 °C
[File Parameters]
Run date,4/13/2025 7:44:57 PM
Trios version,5.1.1.46572
Original File Name,D:\DSC2500\JYarger\2025_04_13_CBN_Powder_n60C_150C_10Cmin_x3.tri
Current File Name,D:\DSC2500\JYarger\2025_04_13_CBN_Powder_n60C_150C_10Cmin_x3.tri
[Procedure]
Procedure Name,CBN_n60_150C_10Cmin_x3
Sample Name,2025_04_13_CBN_Powder_n60C_150C_10Cmin_x3
Sample Mass,8.81 mg
Reference Sample Mass,0 mg
Pan Mass,54.25 mg
Pan Number,53
Reference Pan Mass,53.32 mg
Reference Pan Number,10
Pan Type,Tzero Aluminum Hermetic
Comments,Hermetic Sealed Al DSC Consumables Pan/Lids.
Project Name,CA
Operator,Yarger
Test,Custom
Unload Max Temperature,30
Unload Min Temperature,30
Load Max Temperature,30
Load Min Temperature,30
Stop on Gas Flow Error,Yes
[Signal List]
Signal #1,Time (min)
Signal #2,Temperature (°C)
Signal #3,Heat Flow (mW)
Signal #4,Delta T (µV)
Signal #5,Delta Tzero (µV)
Signal #6,Tzero Temperature (°C)
Signal #7,Cell Purge (mL/min)
Signal #8,Heater Temp (°C)
Signal #9,Power Delivered (W)
Signal #10,Reference Junction Temperature (°C)
Signal #11,Flange Temperature (°C)
Signal #12,Heat Flow Phase (rad)
Signal #13,Total Heat Capacity (J/°C)
Signal #14,Heat Capacity (J/°C)
[Configuration]
Company Name,ASU
Instrument Name,DSC2A-00468
Instrument Type,DSC2500
Serial Number,DSC2A-00468
IP,192.168.1.100
Location of Instrument,MRRC
DisplayType,Unknown
Sample Interval ,0.1 s/pt
Selected Heat Flow,T4P
Exotherm Direction,Down
Cell Serial,DRC2-00792
Lid Type,Standard
Cooler,RCS 90
Leave Cooler on at End of Sequence,On
Gas 2,Nitrogen
Gas Selected,Channel 1
Flow Rate,50 mL/min
Secondary Purge,On
Licensed Heat Flow,Heat Flow T4P
Modulation Licensed,Yes
[Versions]
Common IDD Version,1
Cortex Version,VER 2.10.2.31
Driver,5.0.0.6
GDM Version,1.0.3.3
TouchscreenVersion,1.0.0.16145
FEP Version,1.2.1.21
FEP Bootloader,2.0.0.5
AutoSampler Version,2.1.1.26
Auto Sampler Bootloader,2.0.0.5
FCM Version,1.1.0.3
FCM Bootloader,2.0.0.5
[Experiment Logs]
Experiment Log Entry # 1,Air Cool is off.
Experiment Log Entry # 3,Data On set to 0
Experiment Log Entry # 5,Equilibrate Segment -60 (C) Started
Experiment Log Entry # 7,Data On set to 1
Experiment Log Entry # 9,Ramp Segment 10 C/min to 150 Started
Experiment Log Entry # 11,Data On set to 0
Experiment Log Entry # 13,Isothermal Segment 1 min started
Experiment Log Entry # 15,Data On set to 1
Experiment Log Entry # 17,Ramp Segment 10 C/min to -60 Started
Experiment Log Entry # 19,Data On set to 0
Experiment Log Entry # 21,Isothermal Segment 1 min started
Experiment Log Entry # 23,Data On set to 1
Experiment Log Entry # 25,Ramp Segment 10 C/min to 150 Started
Experiment Log Entry # 27,Data On set to 0
Experiment Log Entry # 29,Isothermal Segment 1 min started
Experiment Log Entry # 31,Data On set to 1
Experiment Log Entry # 33,Ramp Segment 10 C/min to -60 Started
Experiment Log Entry # 35,Data On set to 0
Experiment Log Entry # 37,Isothermal Segment 1 min started
Experiment Log Entry # 39,Data On set to 1
Experiment Log Entry # 41,Ramp Segment 10 C/min to 150 Started
[Method Log]
Method Log Entry # 1,Data Off
Method Log Entry # 2,Equilibrate -60 °C
Method Log Entry # 3,Data On
Method Log Entry # 4,(Ramp 512891) Ramp 10 °C/minute to 150 °C
Method Log Entry # 5,Data Off
Method Log Entry # 6,Isothermal 1 minutes
Method Log Entry # 7,Data On
Method Log Entry # 8,(Ramp 512895) Ramp 10 °C/minute to -60 °C
Method Log Entry # 9,Data Off
Method Log Entry # 10,Isothermal 1 minutes
Method Log Entry # 11,Data On
Method Log Entry # 12,(Ramp 512899) Ramp 10 °C/minute to 150 °C
Method Log Entry # 13,Data Off
Method Log Entry # 14,Isothermal 1 minutes
Method Log Entry # 15,Data On
Method Log Entry # 16,(Ramp 512903) Ramp 10 °C/minute to -60 °C
Method Log Entry # 17,Data Off
Method Log Entry # 18,Isothermal 1 minutes
Method Log Entry # 19,Data On
Method Log Entry # 20,(Ramp 512907) Ramp 10 °C/minute to 150 °C
Cell Serial,DRC2-00792
[T1 Calibration]
Slope,-0.008529666
Offset,9.636258
Initial Temperature,98.23
GUID,f8bfdadc-4977-4fdf-ba6d-0ba9134940c3
[TZero Calibration]
Date Applied,11/29/2022 4:06:13 PM
Description,From -89.059 °C to 396.009 °C at 20.000°C/min
Gas Type,Nitrogen
Pan Type,None
Source Files 1,C:\Users\yargerlab\Desktop\DSC Data\General\TZero_calibration_11_29_22_2nd(2).tri
Source Files 2,C:\Users\yargerlab\Desktop\DSC Data\General\TZero_calibration_11_29_22_2nd(3).tri
Delta T Offset,13.05235
Delta T Slope,-0.007271007
Delta T0 Offset,-13.69128
Delta T0 Slope,0.06063341
[Temperature Calibration]
Date Applied,11/29/2022 7:12:28 PM
Description,From 106.590 °C to 186.590 °C at 10.000°C/min
Gas Type,Nitrogen
Pan Type,Tzero Aluminum Hermetic
Source Files 1,C:\Users\yargerlab\Desktop\DSC Data\General\Indium(6).tri
Measured 1,157.391
Known 1,156.598
[Cell Constant Calibration]
Date Applied,11/29/2022 7:12:29 PM
Description,From 106.590 °C to 186.590 °C at 10.000°C/min
Gas Type,Nitrogen
Pan Type,Tzero Aluminum Hermetic
Source Files 1,C:\Users\yargerlab\Desktop\DSC Data\General\Indium(6).tri
T4P KCell,1.006051
Onset Slope,63.26126 mW/°C
[Direct Cp Calibration]
Date Applied,11/30/2022 11:04:51 AM
Description,From -79.983 °C to 298.409 °C at 10.000°C/min
Gas Type,Nitrogen
Pan Type,Tzero Aluminum Hermetic
Source Files 1,C:\Users\yargerlab\Desktop\DSC Data\General\Sapphire_Heat_Capacity_11_30_22.tri
[Rev Cp Calibration]
Date Applied,11/30/2022 1:58:51 PM
Description,From -79.996 °C to 292.812 °C at 3.000°C/min
Gas Type,Nitrogen
Pan Type,Tzero Aluminum Hermetic
Source Files 1,C:\Users\yargerlab\Desktop\DSC Data\General\Sapphire_MDSC_Calibration_11_30_22.tri
[step]
Ramp 10.00 °C/min to 150.00 °C
Time,Temperature,Heat Flow (Normalized)
min,°C,W/g
0.00,-59.66,-0.053
0.01,-59.67,-0.053
0.03,-59.68,-0.048
0.05,-59.68,-0.045
0.06,-59.68,-0.047
0.08,-59.66,-0.049
0.09,-59.63,-0.057
0.11,-59.59,-0.063
0.12,-59.53,-0.067
0.14,-59.46,-0.066
0.15,-59.38,-0.065
0.16,-59.29,-0.055
0.18,-59.19,-0.041
0.19,-59.08,-0.027
0.21,-58.98,-0.013
0.23,-58.86,0.001
0.24,-58.74,0.016
0.26,-58.62,0.028
0.27,-58.50,0.041
0.29,-58.37,0.052
0.30,-58.25,0.062
0.31,-58.12,0.070
0.33,-57.99,0.078
0.35,-57.85,0.086
0.36,-57.72,0.093
0.38,-57.59,0.097
0.39,-57.45,0.103
0.40,-57.31,0.107
0.42,-57.18,0.112
0.44,-57.03,0.116
0.45,-56.90,0.118
0.46,-56.76,0.122
0.48,-56.61,0.125
0.50,-56.47,0.127
0.51,-56.33,0.130
0.53,-56.19,0.132
0.54,-56.05,0.133
0.55,-55.90,0.135
0.57,-55.76,0.137
0.58,-55.61,0.138
0.60,-55.47,0.139
0.62,-55.33,0.140
0.63,-55.18,0.141
0.65,-55.04,0.142
0.66,-54.89,0.143
0.68,-54.75,0.144
0.69,-54.60,0.144
0.70,-54.45,0.145
0.72,-54.31,0.145
0.73,-54.16,0.146
0.75,-54.01,0.146
0.77,-53.87,0.146
0.78,-53.72,0.148
0.80,-53.57,0.148
0.81,-53.43,0.148
0.83,-53.28,0.148
0.84,-53.13,0.149
0.85,-52.98,0.149
0.87,-52.84,0.150
0.88,-52.69,0.150
0.90,-52.54,0.150
0.92,-52.39,0.150
0.93,-52.25,0.150
0.95,-52.10,0.150
0.96,-51.95,0.151
0.98,-51.80,0.151
0.99,-51.65,0.151
1.00,-51.51,0.151
1.02,-51.36,0.151
1.03,-51.21,0.151
1.05,-51.06,0.152
1.07,-50.91,0.152
1.08,-50.76,0.152
1.09,-50.62,0.152
1.11,-50.47,0.152
1.13,-50.32,0.152
1.14,-50.17,0.152
1.16,-50.02,0.153
1.17,-49.87,0.153
1.18,-49.72,0.153
1.20,-49.57,0.153
1.22,-49.42,0.153
1.23,-49.27,0.153
1.24,-49.13,0.154
1.26,-48.98,0.154
1.28,-48.83,0.154
1.29,-48.68,0.154
1.31,-48.53,0.154
1.32,-48.38,0.154
1.33,-48.23,0.154
1.35,-48.08,0.155
1.37,-47.93,0.155
1.38,-47.78,0.155
1.39,-47.63,0.155
1.41,-47.48,0.155
1.43,-47.33,0.155
1.44,-47.18,0.155
1.46,-47.03,0.155
1.47,-46.88,0.156
1.48,-46.74,0.156
1.50,-46.59,0.156
1.52,-46.44,0.156
1.53,-46.29,0.156
1.54,-46.14,0.156
1.56,-45.99,0.156
1.58,-45.84,0.156
1.59,-45.69,0.156
1.61,-45.54,0.157
1.62,-45.39,0.157
1.63,-45.24,0.157
1.65,-45.09,0.157
1.67,-44.94,0.157
1.68,-44.79,0.157
1.69,-44.64,0.157
1.71,-44.49,0.157
1.73,-44.34,0.157
1.74,-44.19,0.157
1.76,-44.04,0.157
1.77,-43.89,0.158
1.78,-43.74,0.158
1.80,-43.59,0.158
1.82,-43.44,0.158
1.83,-43.29,0.158
1.84,-43.14,0.158
1.86,-42.99,0.158
1.88,-42.84,0.158
1.89,-42.69,0.158
1.91,-42.54,0.158
1.92,-42.39,0.158
1.93,-42.24,0.159
1.95,-42.09,0.159
1.97,-41.94,0.159
1.98,-41.79,0.159
1.99,-41.64,0.159
2.01,-41.49,0.159
2.03,-41.34,0.159
2.04,-41.19,0.159
2.06,-41.04,0.159
2.07,-40.89,0.159
2.08,-40.74,0.159
2.10,-40.59,0.159
2.12,-40.44,0.160
2.13,-40.29,0.160
2.14,-40.14,0.160
2.16,-39.99,0.160
2.18,-39.84,0.160
2.19,-39.69,0.160
2.21,-39.54,0.160
2.22,-39.39,0.160
2.24,-39.24,0.160
2.25,-39.09,0.160
2.26,-38.94,0.160
2.28,-38.79,0.160
2.29,-38.64,0.160
2.31,-38.49,0.161
2.33,-38.34,0.161
2.34,-38.19,0.161
2.36,-38.04,0.161
2.37,-37.89,0.161
2.39,-37.74,0.161
2.40,-37.59,0.161
2.41,-37.44,0.161
2.43,-37.29,0.161
2.44,-37.14,0.161
2.46,-36.99,0.161
2.48,-36.84,0.161
2.49,-36.69,0.162
2.51,-36.54,0.162
2.52,-36.39,0.162
2.54,-36.24,0.162
2.55,-36.09,0.162
2.56,-35.94,0.162
2.58,-35.79,0.162
2.59,-35.64,0.162
2.61,-35.48,0.162
2.63,-35.33,0.162
2.64,-35.18,0.162
2.66,-35.03,0.162
2.67,-34.88,0.162
2.69,-34.73,0.163
2.70,-34.58,0.163
2.71,-34.43,0.163
2.73,-34.28,0.163
2.74,-34.13,0.163
2.76,-33.98,0.163
2.78,-33.83,0.163
2.79,-33.68,0.163
2.81,-33.53,0.163
2.82,-33.38,0.163
2.84,-33.23,0.163
2.85,-33.08,0.163
2.86,-32.93,0.163
2.88,-32.78,0.163
2.89,-32.63,0.164
2.91,-32.48,0.164
2.93,-32.33,0.164
2.94,-32.18,0.164
2.96,-32.03,0.164
2.97,-31.88,0.164
2.99,-31.73,0.164
3.00,-31.58,0.164
3.01,-31.43,0.164
3.03,-31.28,0.164
3.04,-31.13,0.164
3.06,-30.98,0.164
3.08,-30.83,0.164
3.09,-30.68,0.164
3.11,-30.53,0.165
3.12,-30.38,0.165
3.14,-30.23,0.165
3.15,-30.08,0.165
3.16,-29.93,0.165
3.18,-29.78,0.165
3.19,-29.63,0.165
3.21,-29.48,0.165
3.23,-29.33,0.165
3.24,-29.18,0.165
3.26,-29.03,0.165
3.27,-28.88,0.165
3.29,-28.73,0.166
3.30,-28.58,0.166
3.31,-28.43,0.166
3.33,-28.28,0.166
3.34,-28.13,0.166
3.36,-27.98,0.166
3.38,-27.83,0.166
3.39,-27.68,0.166
3.41,-27.53,0.166
3.42,-27.38,0.166
3.44,-27.23,0.166
3.45,-27.08,0.166
3.46,-26.93,0.166
3.48,-26.77,0.167
3.49,-26.63,0.167
3.51,-26.47,0.167
3.53,-26.33,0.167
3.54,-26.17,0.167
3.56,-26.02,0.167
3.57,-25.88,0.167
3.59,-25.72,0.167
3.60,-25.57,0.167
3.61,-25.42,0.167
3.63,-25.27,0.167
3.64,-25.12,0.168
3.66,-24.97,0.168
3.68,-24.82,0.168
3.69,-24.67,0.168
3.71,-24.52,0.168
3.72,-24.37,0.168
3.74,-24.22,0.168
3.75,-24.07,0.168
3.76,-23.92,0.168
3.78,-23.77,0.168
3.79,-23.62,0.169
3.81,-23.47,0.169
3.83,-23.32,0.169
3.84,-23.17,0.169
3.86,-23.02,0.169
3.87,-22.87,0.169
3.89,-22.72,0.169
3.90,-22.57,0.169
3.91,-22.42,0.169
3.93,-22.27,0.169
3.94,-22.12,0.169
3.96,-21.97,0.169
3.98,-21.82,0.169
3.99,-21.67,0.170
4.01,-21.52,0.170
4.02,-21.37,0.170
4.04,-21.22,0.170
4.05,-21.07,0.170
4.06,-20.92,0.170
4.08,-20.77,0.170
4.09,-20.62,0.170
4.11,-20.47,0.170
4.13,-20.32,0.170
4.14,-20.17,0.170
4.16,-20.02,0.170
4.17,-19.87,0.171
4.19,-19.72,0.171
4.20,-19.57,0.171
4.21,-19.42,0.171
4.23,-19.27,0.171
4.24,-19.12,0.171
4.26,-18.97,0.171
4.28,-18.82,0.171
4.29,-18.67,0.171
4.30,-18.52,0.171
4.32,-18.37,0.171
4.34,-18.22,0.172
4.35,-18.07,0.172
4.36,-17.92,0.172
4.38,-17.77,0.172
4.40,-17.62,0.172
4.41,-17.46,0.172
4.43,-17.32,0.172
4.44,-17.16,0.172
4.45,-17.02,0.172
4.47,-16.86,0.173
4.49,-16.72,0.173
4.50,-16.56,0.173
4.51,-16.41,0.173
4.53,-16.26,0.173
4.55,-16.11,0.173
4.56,-15.97,0.173
4.58,-15.81,0.173
4.59,-15.66,0.173
4.60,-15.51,0.173
4.62,-15.36,0.173
4.64,-15.21,0.173
4.65,-15.06,0.173
4.66,-14.91,0.174
4.68,-14.76,0.174
4.70,-14.61,0.174
4.71,-14.46,0.174
4.73,-14.31,0.174
4.74,-14.16,0.174
4.75,-14.01,0.174
4.77,-13.86,0.174
4.79,-13.71,0.174
4.80,-13.56,0.174
4.81,-13.41,0.175
4.83,-13.26,0.175
4.85,-13.11,0.175
4.86,-12.96,0.175
4.88,-12.81,0.175
4.89,-12.66,0.175
4.90,-12.51,0.175
4.92,-12.36,0.175
4.94,-12.21,0.175
4.95,-12.06,0.175
4.96,-11.91,0.175
4.98,-11.76,0.176
5.00,-11.61,0.176
5.01,-11.46,0.176
5.03,-11.31,0.176
5.04,-11.16,0.176
5.05,-11.01,0.176
5.07,-10.86,0.176
5.09,-10.71,0.176
5.10,-10.56,0.176
5.11,-10.41,0.177
5.13,-10.26,0.177
5.15,-10.11,0.177
5.16,-9.96,0.177
5.18,-9.81,0.177
5.19,-9.66,0.177
5.20,-9.51,0.177
5.22,-9.36,0.177
5.24,-9.21,0.177
5.25,-9.06,0.177
5.26,-8.91,0.178
5.28,-8.76,0.178
5.30,-8.61,0.178
5.31,-8.46,0.178
5.33,-8.31,0.178
5.34,-8.16,0.178
5.35,-8.01,0.178
5.37,-7.86,0.178
5.39,-7.71,0.178
5.40,-7.56,0.178
5.41,-7.41,0.179
5.43,-7.26,0.179
5.45,-7.11,0.179
5.46,-6.95,0.179
5.48,-6.81,0.179
5.49,-6.66,0.179
5.50,-6.51,0.179
5.52,-6.36,0.179
5.54,-6.21,0.179
5.55,-6.06,0.180
5.56,-5.90,0.180
5.58,-5.75,0.180
5.60,-5.60,0.180
5.61,-5.45,0.180
5.63,-5.30,0.180
5.64,-5.15,0.180
5.65,-5.00,0.181
5.67,-4.85,0.181
5.69,-4.70,0.181
5.70,-4.55,0.181
5.71,-4.40,0.181
5.73,-4.25,0.181
5.75,-4.10,0.181
5.76,-3.95,0.181
5.78,-3.80,0.181
5.79,-3.65,0.182
5.80,-3.50,0.182
5.82,-3.35,0.182
5.84,-3.20,0.182
5.85,-3.05,0.182
5.86,-2.90,0.182
5.88,-2.75,0.182
5.90,-2.60,0.182
5.91,-2.45,0.183
5.93,-2.30,0.183
5.94,-2.15,0.183
5.95,-2.00,0.183
5.97,-1.85,0.183
5.99,-1.70,0.183
6.00,-1.55,0.183
6.01,-1.40,0.183
6.03,-1.25,0.183
6.05,-1.10,0.184
6.06,-0.95,0.184
6.08,-0.80,0.184
6.09,-0.65,0.184
6.10,-0.50,0.184
6.12,-0.35,0.184
6.14,-0.20,0.184
6.15,-0.05,0.185
6.16,0.10,0.185
6.18,0.25,0.185
6.20,0.40,0.185
6.21,0.55,0.185
6.23,0.70,0.185
6.24,0.85,0.185
6.25,1.00,0.185
6.27,1.15,0.185
6.29,1.30,0.185
6.30,1.45,0.186
6.31,1.60,0.186
6.33,1.75,0.186
6.35,1.90,0.186
6.36,2.05,0.186
6.38,2.20,0.186
6.39,2.35,0.186
6.40,2.50,0.186
6.42,2.65,0.186
6.44,2.80,0.187
6.45,2.95,0.187
6.46,3.11,0.187
6.48,3.26,0.187
6.50,3.41,0.187
6.51,3.55,0.187
6.53,3.71,0.187
6.54,3.85,0.188
6.55,4.01,0.188
6.57,4.16,0.188
6.59,4.30,0.188
6.60,4.46,0.188
6.61,4.61,0.188
6.63,4.76,0.188
6.65,4.91,0.188
6.66,5.06,0.189
6.68,5.21,0.189
6.69,5.35,0.189
6.70,5.51,0.189
6.72,5.66,0.189
6.74,5.81,0.189
6.75,5.96,0.189
6.76,6.11,0.189
6.78,6.26,0.190
6.80,6.41,0.190
6.81,6.56,0.190
6.83,6.71,0.190
6.84,6.86,0.190
6.85,7.01,0.190
6.87,7.16,0.190
6.89,7.31,0.191
6.90,7.46,0.191
6.91,7.61,0.191
6.93,7.76,0.191
6.95,7.91,0.191
6.96,8.06,0.191
6.98,8.21,0.191
6.99,8.36,0.191
7.00,8.51,0.191
7.02,8.66,0.192
7.04,8.81,0.192
7.05,8.96,0.192
7.06,9.11,0.192
7.08,9.26,0.192
7.10,9.41,0.192
7.11,9.56,0.192
7.13,9.71,0.192
7.14,9.86,0.193
7.15,10.01,0.193
7.17,10.16,0.193
7.19,10.31,0.193
7.20,10.46,0.193
7.21,10.61,0.193
7.23,10.76,0.193
7.25,10.91,0.193
7.26,11.06,0.194
7.28,11.21,0.194
7.29,11.36,0.194
7.30,11.51,0.194
7.32,11.66,0.194
7.34,11.81,0.194
7.35,11.96,0.194
7.36,12.11,0.194
7.38,12.26,0.195
7.40,12.41,0.195
7.41,12.56,0.195
7.43,12.71,0.195
7.44,12.87,0.195
7.45,13.01,0.195
7.47,13.16,0.195
7.49,13.31,0.195
7.50,13.46,0.196
7.51,13.62,0.196
7.53,13.77,0.196
7.55,13.92,0.196
7.56,14.06,0.196
7.58,14.21,0.196
7.59,14.36,0.196
7.60,14.51,0.196
7.62,14.66,0.197
7.64,14.82,0.197
7.65,14.97,0.197
7.66,15.11,0.197
7.68,15.27,0.197
7.70,15.42,0.197
7.71,15.57,0.197
7.73,15.72,0.197
7.74,15.87,0.198
7.75,16.01,0.198
7.77,16.17,0.198
7.79,16.32,0.198
7.80,16.47,0.198
7.81,16.62,0.198
7.83,16.77,0.198
7.85,16.92,0.199
7.86,17.07,0.199
7.88,17.22,0.199
7.89,17.37,0.199
7.90,17.52,0.199
7.92,17.67,0.199
7.94,17.82,0.199
7.95,17.97,0.199
7.96,18.12,0.200
7.98,18.27,0.200
8.00,18.42,0.200
8.01,18.57,0.200
8.03,18.72,0.200
8.04,18.87,0.200
8.05,19.02,0.200
8.07,19.17,0.200
8.09,19.32,0.201
8.10,19.47,0.201
8.11,19.62,0.201
8.13,19.77,0.201
8.15,19.92,0.201
8.16,20.07,0.201
8.18,20.22,0.202
8.19,20.37,0.202
8.20,20.52,0.202
8.22,20.67,0.202
8.24,20.82,0.202
8.25,20.97,0.202
8.26,21.12,0.202
8.28,21.27,0.202
8.30,21.42,0.203
8.31,21.57,0.203
8.33,21.72,0.203
8.34,21.87,0.203
8.35,22.02,0.203
8.37,22.17,0.203
8.39,22.32,0.203
8.40,22.47,0.203
8.41,22.62,0.204
8.43,22.77,0.204
8.45,22.92,0.204
8.46,23.07,0.204
8.48,23.22,0.204
8.49,23.37,0.204
8.50,23.52,0.204
8.52,23.67,0.204
8.53,23.82,0.205
8.55,23.97,0.205
8.57,24.12,0.205
8.58,24.27,0.205
8.60,24.42,0.205
8.61,24.57,0.205
8.63,24.72,0.205
8.64,24.87,0.205
8.65,25.02,0.206
8.67,25.17,0.206
8.68,25.32,0.206
8.70,25.47,0.206
8.72,25.62,0.206
8.73,25.77,0.206
8.75,25.92,0.207
8.76,26.07,0.207
8.78,26.22,0.207
8.79,26.37,0.207
8.80,26.53,0.207
8.82,26.68,0.207
8.83,26.83,0.207
8.85,26.98,0.207
8.87,27.13,0.208
8.88,27.28,0.208
8.90,27.43,0.208
8.91,27.58,0.208
8.93,27.73,0.208
8.94,27.88,0.208
8.95,28.03,0.208
8.97,28.18,0.208
8.98,28.33,0.209
9.00,28.48,0.209
9.02,28.63,0.209
9.03,28.78,0.209
9.05,28.93,0.209
9.06,29.08,0.209
9.08,29.23,0.209
9.09,29.38,0.210
9.10,29.53,0.210
9.12,29.68,0.210
9.13,29.83,0.210
9.15,29.98,0.210
9.17,30.13,0.210
9.18,30.28,0.210
9.20,30.43,0.211
9.21,30.58,0.211
9.23,30.73,0.211
9.24,30.88,0.211
9.25,31.03,0.211
9.27,31.18,0.211
9.28,31.33,0.211
9.30,31.48,0.211
9.32,31.63,0.212
9.33,31.78,0.212
9.35,31.93,0.212
9.36,32.08,0.212
9.38,32.23,0.212
9.39,32.38,0.212
9.40,32.53,0.212
9.42,32.68,0.212
9.43,32.83,0.213
9.45,32.98,0.213
9.47,33.13,0.213
9.48,33.28,0.213
9.50,33.43,0.213
9.51,33.58,0.213
9.53,33.73,0.213
9.54,33.88,0.213
9.55,34.03,0.214
9.57,34.18,0.214
9.58,34.33,0.214
9.60,34.48,0.214
9.62,34.63,0.214
9.63,34.78,0.214
9.65,34.93,0.214
9.66,35.08,0.214
9.68,35.23,0.215
9.69,35.38,0.215
9.70,35.53,0.215
9.72,35.68,0.215
9.73,35.83,0.215
9.75,35.98,0.215
9.77,36.13,0.216
9.78,36.28,0.216
9.80,36.43,0.216
9.81,36.58,0.216
9.83,36.73,0.216
9.84,36.88,0.216
9.85,37.03,0.216
9.87,37.18,0.216
9.88,37.33,0.217
9.90,37.48,0.217
9.92,37.63,0.217
9.93,37.78,0.217
9.95,37.93,0.217
9.96,38.09,0.217
9.98,38.23,0.217
9.99,38.39,0.218
10.00,38.54,0.218
10.02,38.68,0.218
10.03,38.83,0.218
10.05,38.99,0.218
10.07,39.13,0.218
10.08,39.29,0.218
10.10,39.43,0.219
10.11,39.59,0.219
10.13,39.74,0.219
10.14,39.89,0.219
10.15,40.04,0.219
10.17,40.19,0.219
10.18,40.34,0.219
10.20,40.49,0.220
10.22,40.64,0.220
10.23,40.79,0.220
10.25,40.93,0.220
10.26,41.09,0.220
10.28,41.24,0.220
10.29,41.39,0.220
10.30,41.54,0.221
10.32,41.69,0.221
10.33,41.84,0.221
10.35,41.99,0.221
10.37,42.14,0.221
10.38,42.29,0.222
10.40,42.44,0.222
10.41,42.59,0.222
10.43,42.74,0.222
10.44,42.89,0.222
10.45,43.04,0.222
10.47,43.19,0.222
10.48,43.34,0.223
10.50,43.49,0.223
10.52,43.64,0.223
10.53,43.79,0.223
10.55,43.94,0.223
10.56,44.09,0.223
10.58,44.24,0.224
10.59,44.39,0.224
10.60,44.54,0.224
10.62,44.69,0.224
10.63,44.84,0.224
10.65,44.99,0.224
10.67,45.14,0.225
10.68,45.29,0.225
10.70,45.44,0.225
10.71,45.59,0.225
10.73,45.74,0.225
10.74,45.89,0.225
10.75,46.04,0.225
10.77,46.19,0.226
10.78,46.34,0.226
10.80,46.49,0.226
10.82,46.64,0.226
10.83,46.79,0.226
10.85,46.94,0.226
10.86,47.09,0.227
10.88,47.24,0.227
10.89,47.39,0.227
10.90,47.54,0.227
10.92,47.69,0.227
10.93,47.84,0.227
10.95,47.99,0.228
10.97,48.14,0.228
10.98,48.29,0.228
11.00,48.44,0.228
11.01,48.59,0.228
11.03,48.74,0.228
11.04,48.89,0.228
11.05,49.04,0.229
11.07,49.19,0.229
11.08,49.34,0.229
11.10,49.49,0.229
11.12,49.64,0.229
11.13,49.79,0.229
11.15,49.94,0.230
11.16,50.09,0.230
11.18,50.24,0.230
11.19,50.39,0.230
11.20,50.54,0.230
11.22,50.69,0.230
11.23,50.84,0.231
11.25,50.99,0.231
11.27,51.14,0.231
11.28,51.29,0.231
11.30,51.44,0.231
11.31,51.59,0.231
11.33,51.74,0.232
11.34,51.89,0.232
11.35,52.04,0.232
11.37,52.19,0.232
11.38,52.34,0.232
11.40,52.49,0.232
11.42,52.64,0.232
11.43,52.79,0.233
11.45,52.94,0.233
11.46,53.09,0.233
11.48,53.25,0.233
11.49,53.39,0.233
11.50,53.55,0.233
11.52,53.70,0.233
11.53,53.85,0.234
11.55,54.00,0.234
11.57,54.15,0.234
11.58,54.30,0.234
11.60,54.45,0.234
11.61,54.60,0.235
11.63,54.75,0.235
11.64,54.90,0.235
11.65,55.05,0.235
11.67,55.20,0.235
11.68,55.35,0.235
11.70,55.50,0.236
11.72,55.65,0.236
11.73,55.80,0.236
11.75,55.95,0.236
11.76,56.10,0.236
11.78,56.25,0.237
11.79,56.40,0.237
11.80,56.55,0.237
11.82,56.70,0.237
11.83,56.85,0.237
11.85,57.00,0.238
11.87,57.15,0.238
11.88,57.30,0.238
11.90,57.45,0.238
11.91,57.60,0.239
11.93,57.75,0.239
11.94,57.90,0.239
11.95,58.05,0.239
11.97,58.20,0.240
11.98,58.35,0.240
12.00,58.50,0.240
12.02,58.65,0.240
12.03,58.80,0.240
12.05,58.95,0.241
12.06,59.10,0.241
12.08,59.25,0.241
12.09,59.40,0.242
12.10,59.55,0.242
12.12,59.70,0.242
12.13,59.85,0.242
12.15,60.00,0.243
12.17,60.15,0.243
12.18,60.30,0.243
12.20,60.45,0.243
12.21,60.60,0.244
12.23,60.75,0.244
12.24,60.90,0.244
12.25,61.05,0.245
12.27,61.20,0.245
12.28,61.35,0.246
12.30,61.50,0.246
12.32,61.65,0.246
12.33,61.80,0.247
12.35,61.95,0.247
12.36,62.10,0.247
12.38,62.25,0.248
12.39,62.40,0.248
12.40,62.55,0.249
12.42,62.70,0.249
12.43,62.85,0.250
12.45,63.00,0.251
12.47,63.15,0.251
12.48,63.30,0.251
12.50,63.45,0.251
12.51,63.60,0.253
12.53,63.75,0.253
12.54,63.90,0.253
12.55,64.05,0.255
12.57,64.20,0.255
12.58,64.35,0.256
12.60,64.50,0.257
12.62,64.65,0.257
12.63,64.80,0.258
12.65,64.95,0.259
12.66,65.10,0.260
12.68,65.25,0.261
12.69,65.40,0.262
12.70,65.54,0.263
12.72,65.69,0.264
12.73,65.84,0.265
12.75,65.99,0.266
12.77,66.14,0.267
12.78,66.29,0.268
12.80,66.44,0.270
12.81,66.59,0.271
12.83,66.74,0.272
12.84,66.89,0.273
12.85,67.04,0.275
12.87,67.19,0.276
12.88,67.34,0.278
12.90,67.49,0.280
12.92,67.64,0.282
12.93,67.79,0.283
12.95,67.94,0.285
12.96,68.09,0.287
12.98,68.23,0.289
12.99,68.38,0.291
13.00,68.53,0.293
13.02,68.68,0.295
13.03,68.83,0.298
13.05,68.98,0.300
13.07,69.13,0.303
13.08,69.28,0.307
13.10,69.42,0.310
13.11,69.57,0.312
13.13,69.72,0.316
13.14,69.87,0.320
13.15,70.02,0.323
13.17,70.17,0.328
13.18,70.31,0.332
13.20,70.46,0.337
13.22,70.61,0.343
13.23,70.76,0.348
13.25,70.91,0.354
13.26,71.05,0.360
13.28,71.20,0.366
13.29,71.35,0.373
13.30,71.49,0.381
13.32,71.64,0.389
13.33,71.79,0.397
13.35,71.93,0.406
13.37,72.08,0.417
13.38,72.22,0.428
13.40,72.37,0.440
13.41,72.51,0.452
13.43,72.65,0.467
13.44,72.80,0.481
13.45,72.94,0.497
13.47,73.08,0.515
13.48,73.22,0.533
13.50,73.36,0.555
13.52,73.50,0.576
13.53,73.64,0.601
13.55,73.78,0.628
13.56,73.92,0.657
13.58,74.05,0.690
13.59,74.19,0.724
13.60,74.32,0.762
13.62,74.45,0.809
13.63,74.58,0.861
13.65,74.71,0.914
13.67,74.83,0.977
13.68,74.95,1.044
13.70,75.07,1.117
13.71,75.18,1.194
13.73,75.29,1.279
13.74,75.40,1.371
13.75,75.50,1.471
13.77,75.61,1.565
13.78,75.71,1.657
13.80,75.81,1.743
13.82,75.90,1.838
13.83,76.00,1.942
13.85,76.10,2.029
13.86,76.19,2.108
13.88,76.29,2.209
13.89,76.38,2.330
13.90,76.47,2.434
13.92,76.57,2.469
13.93,76.68,2.468
13.95,76.80,2.452
13.97,76.93,2.432
13.98,77.06,2.408
14.00,77.21,2.388
14.01,77.35,2.378
14.03,77.50,2.363
14.04,77.65,2.341
14.05,77.81,2.307
14.07,77.97,2.261
14.08,78.13,2.204
14.10,78.31,2.133
14.12,78.48,2.047
14.13,78.67,1.966
14.15,78.85,1.902
14.16,79.03,1.837
14.18,79.22,1.748
14.19,79.42,1.632
14.20,79.62,1.504
14.22,79.83,1.377
14.23,80.04,1.253
14.25,80.25,1.135
14.27,80.47,1.021
14.28,80.68,0.916
14.30,80.90,0.823
14.31,81.11,0.745
14.33,81.31,0.683
14.34,81.51,0.633
14.35,81.71,0.591
14.37,81.90,0.556
14.38,82.08,0.527
14.40,82.26,0.494
14.42,82.44,0.478
14.43,82.62,0.453
14.45,82.79,0.435
14.46,82.96,0.419
14.48,83.12,0.405
14.49,83.29,0.392
14.50,83.45,0.381
14.52,83.61,0.371
14.53,83.77,0.363
14.55,83.93,0.355
14.57,84.09,0.349
14.58,84.25,0.343
14.60,84.40,0.337
14.61,84.56,0.333
14.63,84.71,0.330
14.64,84.87,0.325
14.65,85.02,0.323
14.67,85.17,0.321
14.68,85.32,0.318
14.70,85.48,0.316
14.72,85.63,0.315
14.73,85.78,0.312
14.75,85.93,0.311
14.76,86.09,0.310
14.78,86.24,0.309
14.79,86.39,0.309
14.80,86.54,0.308
14.82,86.69,0.307
14.83,86.84,0.307
14.85,86.99,0.307
14.87,87.14,0.306
14.88,87.30,0.306
14.90,87.45,0.305
14.91,87.60,0.305
14.93,87.75,0.305
14.94,87.90,0.305
14.95,88.05,0.305
14.97,88.20,0.305
14.98,88.35,0.304
15.00,88.50,0.304
15.02,88.65,0.304
15.03,88.80,0.304
15.05,88.95,0.304
15.06,89.10,0.304
15.08,89.25,0.304
15.09,89.40,0.304
15.10,89.55,0.303
15.12,89.70,0.303
15.13,89.85,0.303
15.15,90.00,0.303
15.17,90.15,0.303
15.18,90.30,0.303
15.20,90.45,0.303
15.21,90.60,0.303
15.23,90.75,0.303
15.24,90.90,0.303
15.25,91.05,0.303
15.27,91.20,0.303
15.28,91.35,0.303
15.30,91.50,0.303
15.32,91.65,0.303
15.33,91.80,0.303
15.35,91.95,0.303
15.36,92.10,0.303
15.38,92.25,0.303
15.39,92.40,0.303
15.40,92.55,0.303
15.42,92.70,0.303
15.43,92.85,0.303
15.45,93.00,0.303
15.47,93.15,0.303
15.48,93.30,0.303
15.50,93.45,0.303
15.51,93.60,0.303
15.53,93.75,0.303
15.54,93.91,0.303
15.55,94.05,0.303
15.57,94.20,0.303
15.58,94.35,0.303
15.60,94.50,0.303
15.62,94.66,0.303
15.63,94.81,0.303
15.65,94.96,0.303
15.66,95.11,0.303
15.68,95.26,0.304
15.69,95.41,0.304
15.70,95.56,0.304
15.72,95.71,0.304
15.73,95.86,0.304
15.75,96.01,0.304
15.77,96.16,0.304
15.78,96.31,0.304
15.80,96.46,0.304
15.81,96.61,0.304
15.83,96.76,0.304
15.84,96.91,0.304
15.85,97.06,0.304
15.87,97.21,0.304
15.88,97.36,0.304
15.90,97.51,0.304
15.92,97.66,0.304
15.93,97.81,0.304
15.95,97.96,0.304
15.96,98.11,0.304
15.98,98.26,0.304
15.99,98.41,0.304
16.00,98.56,0.305
16.02,98.71,0.305
16.03,98.86,0.305
16.05,99.01,0.305
16.07,99.16,0.305
16.08,99.31,0.305
16.10,99.46,0.305
16.11,99.61,0.305
16.13,99.76,0.305
16.14,99.91,0.305
16.15,100.06,0.305
16.17,100.21,0.305
16.18,100.36,0.305
16.20,100.51,0.305
16.22,100.66,0.305
16.23,100.81,0.305
16.25,100.96,0.306
16.26,101.11,0.306
16.28,101.26,0.306
16.29,101.41,0.306
16.30,101.56,0.306
16.32,101.71,0.306
16.33,101.86,0.306
16.35,102.01,0.306
16.37,102.16,0.306
16.38,102.31,0.306
16.40,102.46,0.306
16.41,102.61,0.306
16.43,102.76,0.306
16.44,102.91,0.306
16.45,103.06,0.307
16.47,103.21,0.307
16.48,103.36,0.307
16.50,103.51,0.307
16.52,103.67,0.307
16.53,103.81,0.307
16.55,103.96,0.307
16.56,104.12,0.307
16.58,104.27,0.307
16.59,104.41,0.307
16.60,104.57,0.307
16.62,104.71,0.307
16.63,104.86,0.307
16.65,105.02,0.307
16.67,105.17,0.307
16.68,105.32,0.307
16.70,105.46,0.307
16.71,105.61,0.307
16.73,105.77,0.307
16.74,105.91,0.307
16.75,106.06,0.307
16.77,106.21,0.307
16.78,106.37,0.307
16.80,106.51,0.307
16.82,106.67,0.308
16.83,106.82,0.308
16.85,106.96,0.308
16.86,107.11,0.308
16.88,107.26,0.308
16.89,107.42,0.308
16.90,107.57,0.308
16.92,107.72,0.308
16.93,107.87,0.308
16.95,108.02,0.308
16.97,108.17,0.308
16.98,108.32,0.308
17.00,108.47,0.308
17.01,108.62,0.308
17.03,108.77,0.308
17.04,108.92,0.308
17.05,109.07,0.308
17.07,109.22,0.308
17.08,109.37,0.309
17.10,109.52,0.309
17.12,109.67,0.309
17.13,109.82,0.309
17.14,109.97,0.309
17.16,110.12,0.309
17.18,110.27,0.309
17.19,110.42,0.309
17.21,110.57,0.309
17.22,110.72,0.309
17.23,110.87,0.309
17.25,111.02,0.309
17.27,111.17,0.309
17.28,111.32,0.309
17.29,111.47,0.309
17.31,111.62,0.309
17.33,111.77,0.309
17.34,111.92,0.310
17.36,112.07,0.310
17.37,112.22,0.310
17.38,112.37,0.310
17.40,112.52,0.310
17.42,112.67,0.310
17.43,112.82,0.310
17.44,112.97,0.310
17.46,113.12,0.310
17.48,113.27,0.310
17.49,113.42,0.310
17.51,113.57,0.310
17.52,113.72,0.310
17.53,113.87,0.310
17.55,114.02,0.310
17.57,114.17,0.310
17.58,114.32,0.310
17.59,114.47,0.310
17.61,114.62,0.311
17.63,114.77,0.311
17.64,114.92,0.311
17.66,115.07,0.311
17.67,115.22,0.311
17.68,115.38,0.311
17.70,115.52,0.311
17.72,115.67,0.311
17.73,115.82,0.311
17.74,115.97,0.311
17.76,116.13,0.311
17.78,116.28,0.311
17.79,116.43,0.311
17.81,116.57,0.311
17.82,116.72,0.311
17.83,116.87,0.311
17.85,117.02,0.311
17.87,117.17,0.311
17.88,117.33,0.311
17.89,117.47,0.311
17.91,117.63,0.311
17.93,117.77,0.312
17.94,117.93,0.312
17.96,118.08,0.312
17.97,118.23,0.312
17.98,118.38,0.312
18.00,118.53,0.312
18.02,118.68,0.312
18.03,118.83,0.312
18.04,118.98,0.312
18.06,119.13,0.312
18.08,119.28,0.312
18.09,119.43,0.312
18.11,119.58,0.312
18.12,119.73,0.312
18.13,119.88,0.312
18.15,120.03,0.312
18.17,120.18,0.312
18.18,120.33,0.312
18.19,120.48,0.312
18.21,120.63,0.312
18.23,120.78,0.313
18.24,120.93,0.313
18.26,121.08,0.313
18.27,121.23,0.313
18.28,121.38,0.313
18.30,121.53,0.313
18.32,121.68,0.313
18.33,121.83,0.313
18.34,121.98,0.313
18.36,122.13,0.313
18.38,122.28,0.313
18.39,122.43,0.313
18.41,122.58,0.313
18.42,122.73,0.313
18.43,122.88,0.313
18.45,123.03,0.314
18.47,123.18,0.314
18.48,123.33,0.314
18.49,123.48,0.314
18.51,123.63,0.314
18.53,123.78,0.314
18.54,123.93,0.314
18.56,124.08,0.314
18.57,124.23,0.314
18.58,124.38,0.314
18.60,124.53,0.314
18.62,124.68,0.314
18.63,124.83,0.314
18.64,124.98,0.314
18.66,125.13,0.314
18.68,125.28,0.314
18.69,125.43,0.314
18.71,125.58,0.314
18.72,125.73,0.314
18.73,125.88,0.314
18.75,126.03,0.314
18.77,126.18,0.315
18.78,126.33,0.315
18.79,126.48,0.315
18.81,126.63,0.315
18.83,126.78,0.315
18.84,126.93,0.315
18.86,127.08,0.315
18.87,127.23,0.315
18.88,127.38,0.315
18.90,127.53,0.315
18.92,127.68,0.315
18.93,127.83,0.315
18.94,127.98,0.315
18.96,128.13,0.315
18.98,128.29,0.315
18.99,128.43,0.315
19.01,128.58,0.316
19.02,128.74,0.316
19.03,128.89,0.316
19.05,129.04,0.316
19.07,129.18,0.316
19.08,129.34,0.316
19.09,129.49,0.316
19.11,129.64,0.316
19.13,129.79,0.316
19.14,129.94,0.316
19.16,130.09,0.316
19.17,130.24,0.316
19.18,130.39,0.316
19.20,130.54,0.316
19.22,130.69,0.316
19.23,130.84,0.316
19.24,130.99,0.316
19.26,131.14,0.316
19.28,131.29,0.316
19.29,131.44,0.316
19.31,131.59,0.316
19.32,131.74,0.316
19.33,131.89,0.316
19.35,132.04,0.316
19.37,132.19,0.317
19.38,132.34,0.317
19.39,132.49,0.317
19.41,132.64,0.317
19.43,132.79,0.317
19.44,132.94,0.317
19.46,133.09,0.317
19.47,133.24,0.317
19.48,133.39,0.317
19.50,133.54,0.317
19.52,133.69,0.317
19.53,133.84,0.317
19.54,133.99,0.317
19.56,134.14,0.318
19.58,134.29,0.318
19.59,134.44,0.318
19.61,134.59,0.318
19.62,134.74,0.318
19.63,134.89,0.318
19.65,135.04,0.318
19.67,135.19,0.318
19.68,135.34,0.318
19.69,135.49,0.318
19.71,135.64,0.318
19.73,135.79,0.318
19.74,135.94,0.318
19.76,136.09,0.318
19.77,136.24,0.318
19.78,136.39,0.318
19.80,136.54,0.318
19.82,136.69,0.318
19.83,136.84,0.318
19.84,136.99,0.318
19.86,137.14,0.318
19.88,137.29,0.318
19.89,137.44,0.318
19.91,137.59,0.318
19.92,137.74,0.319
19.93,137.89,0.319
19.95,138.04,0.319
19.97,138.19,0.319
19.98,138.34,0.319
19.99,138.49,0.319
20.01,138.64,0.319
20.03,138.79,0.319
20.04,138.94,0.319
20.06,139.09,0.319
20.07,139.24,0.319
20.08,139.39,0.319
20.10,139.54,0.319
20.12,139.69,0.319
20.13,139.84,0.320
20.14,139.99,0.320
20.16,140.14,0.320
20.18,140.29,0.320
20.19,140.44,0.320
20.21,140.59,0.320
20.22,140.74,0.320
20.23,140.89,0.320
20.25,141.04,0.320
20.27,141.19,0.320
20.28,141.34,0.320
20.29,141.49,0.320
20.31,141.64,0.320
20.33,141.80,0.321
20.34,141.95,0.321
20.36,142.10,0.321
20.37,142.25,0.321
20.38,142.40,0.321
20.40,142.55,0.321
20.42,142.70,0.321
20.43,142.85,0.321
20.44,143.00,0.321
20.46,143.14,0.322
20.48,143.30,0.322
20.49,143.45,0.322
20.51,143.60,0.322
20.52,143.75,0.322
20.53,143.90,0.322
20.55,144.05,0.322
20.57,144.20,0.322
20.58,144.35,0.322
20.59,144.50,0.322
20.61,144.65,0.322
20.63,144.80,0.322
20.64,144.95,0.322
20.66,145.10,0.322
20.67,145.25,0.322
20.68,145.40,0.323
20.70,145.55,0.323
20.72,145.70,0.323
20.73,145.85,0.323
20.74,146.00,0.323
20.76,146.15,0.323
20.78,146.30,0.323
20.79,146.45,0.323
20.81,146.60,0.323
20.82,146.75,0.323
20.83,146.90,0.323
20.85,147.05,0.323
20.87,147.20,0.323
20.88,147.35,0.324
20.89,147.50,0.324
20.91,147.65,0.324
20.93,147.80,0.324
20.94,147.95,
20.96,148.10,
20.97,148.25,
20.98,,
20.99,,

[step]
Ramp 10.00 °C/min to -60.00 °C
Time,Temperature,Heat Flow (Normalized)
min,°C,W/g
21.99,150.09,-0.020
22.01,150.09,-0.020
22.02,150.09,-0.021
22.04,150.08,-0.021
22.05,150.07,-0.017
22.07,150.05,-0.008
22.08,150.01,-0.004
22.10,149.96,-0.007
22.11,149.89,-0.023
22.13,149.81,-0.047
22.14,149.72,-0.077
22.16,149.63,-0.110
22.17,149.52,-0.141
22.19,149.41,-0.169
22.20,149.30,-0.195
22.22,149.18,-0.217
22.23,149.06,-0.236
22.25,148.93,-0.252
22.26,148.81,-0.266
22.28,148.68,-0.279
22.29,148.55,-0.290
22.31,148.41,-0.299
22.32,148.28,-0.310
22.34,148.14,-0.316
22.35,148.00,-0.323
22.37,147.86,-0.329
22.38,147.72,-0.334
22.40,147.58,-0.339
22.41,147.44,-0.342
22.43,147.29,-0.346
22.44,147.15,-0.349
22.46,147.00,-0.352
22.47,146.86,-0.354
22.49,146.72,-0.357
22.50,146.57,-0.357
22.52,146.42,-0.360
22.53,146.28,-0.360
22.55,146.13,-0.362
22.56,145.99,-0.363
22.58,145.84,-0.363
22.59,145.69,-0.364
22.61,145.54,-0.365
22.62,145.40,-0.366
22.64,145.25,-0.366
22.65,145.10,-0.366
22.67,144.96,-0.367
22.68,144.81,-0.367
22.70,144.66,-0.367
22.71,144.51,-0.368
22.73,144.37,-0.368
22.74,144.22,-0.368
22.76,144.07,-0.368
22.77,143.92,-0.368
22.79,143.77,-0.369
22.80,143.62,-0.369
22.82,143.47,-0.369
22.83,143.32,-0.369
22.85,143.18,-0.369
22.86,143.03,-0.369
22.88,142.88,-0.370
22.89,142.73,-0.370
22.91,142.58,-0.370
22.92,142.43,-0.370
22.94,142.28,-0.370
22.95,142.14,-0.370
22.97,141.99,-0.370
22.98,141.84,-0.370
23.00,141.69,-0.371
23.01,141.54,-0.371
23.03,141.39,-0.371
23.04,141.24,-0.371
23.06,141.09,-0.371
23.07,140.94,-0.371
23.09,140.79,-0.371
23.10,140.64,-0.371
23.12,140.49,-0.371
23.13,140.34,-0.371
23.15,140.19,-0.371
23.16,140.05,-0.371
23.18,139.90,-0.371
23.19,139.75,-0.371
23.21,139.60,-0.371
23.22,139.45,-0.371
23.24,139.30,-0.371
23.25,139.15,-0.371
23.27,139.00,-0.371
23.28,138.85,-0.371
23.30,138.70,-0.371
23.31,138.55,-0.371
23.33,138.40,-0.371
23.34,138.25,-0.371
23.36,138.10,-0.371
23.37,137.95,-0.371
23.39,137.80,-0.371
23.40,137.65,-0.371
23.42,137.51,-0.371
23.43,137.35,-0.371
23.45,137.21,-0.371
23.46,137.05,-0.371
23.48,136.91,-0.371
23.49,136.76,-0.371
23.51,136.61,-0.371
23.52,136.46,-0.371
23.54,136.31,-0.371
23.55,136.16,-0.371
23.57,136.01,-0.370
23.58,135.86,-0.370
23.60,135.71,-0.370
23.61,135.56,-0.370
23.63,135.41,-0.370
23.64,135.26,-0.370
23.66,135.11,-0.370
23.67,134.96,-0.370
23.69,134.81,-0.370
23.70,134.66,-0.370
23.72,134.51,-0.370
23.73,134.36,-0.370
23.75,134.21,-0.370
23.76,134.06,-0.370
23.78,133.91,-0.369
23.79,133.76,-0.369
23.81,133.61,-0.369
23.82,133.46,-0.369
23.84,133.31,-0.369
23.85,133.16,-0.369
23.87,133.01,-0.369
23.88,132.87,-0.369
23.90,132.72,-0.369
23.91,132.57,-0.369
23.93,132.42,-0.369
23.94,132.27,-0.369
23.96,132.12,-0.368
23.97,131.97,-0.368
23.99,131.82,-0.368
24.00,131.67,-0.368
24.02,131.52,-0.368
24.03,131.37,-0.368
24.05,131.22,-0.368
24.06,131.07,-0.368
24.08,130.92,-0.368
24.09,130.77,-0.368
24.11,130.62,-0.368
24.12,130.47,-0.368
24.14,130.32,-0.368
24.15,130.17,-0.368
24.17,130.02,-0.367
24.18,129.87,-0.367
24.20,129.72,-0.367
24.21,129.57,-0.367
24.23,129.42,-0.367
24.24,129.27,-0.367
24.26,129.12,-0.367
24.27,128.97,-0.367
24.29,128.82,-0.367
24.30,128.67,-0.367
24.32,128.52,-0.367
24.33,128.37,-0.367
24.35,128.22,-0.366
24.36,128.07,-0.366
24.38,127.92,-0.366
24.39,127.77,-0.366
24.41,127.62,-0.366
24.42,127.47,-0.366
24.44,127.32,-0.366
24.45,127.17,-0.366
24.47,127.02,-0.366
24.48,126.87,-0.366
24.50,126.72,-0.366
24.51,126.57,-0.366
24.53,126.42,-0.365
24.54,126.27,-0.365
24.56,126.12,-0.365
24.57,125.98,-0.365
24.59,125.83,-0.365
24.60,125.67,-0.365
24.62,125.53,-0.365
24.63,125.38,-0.365
24.65,125.23,-0.365
24.66,125.08,-0.365
24.68,124.93,-0.365
24.69,124.78,-0.365
24.71,124.63,-0.365
24.72,124.48,-0.364
24.74,124.33,-0.364
24.75,124.18,-0.364
24.77,124.03,-0.364
24.78,123.88,-0.364
24.80,123.73,-0.364
24.81,123.58,-0.364
24.83,123.43,-0.364
24.84,123.28,-0.364
24.86,123.13,-0.364
24.87,122.98,-0.364
24.89,122.83,-0.364
24.90,122.68,-0.363
24.92,122.53,-0.363
24.93,122.38,-0.363
24.95,122.23,-0.363
24.96,122.08,-0.363
24.98,121.93,-0.363
24.99,121.78,-0.363
25.01,121.63,-0.363
25.02,121.48,-0.363
25.04,121.33,-0.363
25.05,121.18,-0.363
25.07,121.03,-0.362
25.08,120.88,-0.362
25.10,120.73,-0.362
25.11,120.58,-0.362
25.13,120.43,-0.362
25.14,120.28,-0.362
25.16,120.13,-0.362
25.17,119.98,-0.362
25.19,119.83,-0.362
25.20,119.68,-0.362
25.22,119.53,-0.362
25.23,119.38,-0.362
25.25,119.23,-0.362
25.26,119.08,-0.361
25.28,118.93,-0.361
25.29,118.78,-0.361
25.31,118.63,-0.361
25.32,118.48,-0.361
25.34,118.33,-0.361
25.35,118.18,-0.361
25.37,118.03,-0.361
25.38,117.88,-0.361
25.40,117.73,-0.361
25.41,117.58,-0.361
25.43,117.43,-0.361
25.44,117.28,-0.361
25.46,117.13,-0.360
25.47,116.98,-0.360
25.49,116.83,-0.360
25.50,116.68,-0.360
25.52,116.53,-0.360
25.53,116.39,-0.360
25.55,116.24,-0.360
25.56,116.09,-0.360
25.58,115.94,-0.360
25.59,115.79,-0.360
25.61,115.64,-0.360
25.62,115.49,-0.360
25.64,115.34,-0.359
25.65,115.19,-0.359
25.67,115.04,-0.359
25.68,114.89,-0.359
25.70,114.74,-0.359
25.71,114.59,-0.359
25.73,114.44,-0.359
25.74,114.29,-0.359
25.76,114.14,-0.359
25.77,113.99,-0.359
25.79,113.84,-0.359
25.80,113.69,-0.359
25.82,113.54,-0.359
25.83,113.39,-0.358
25.85,113.24,-0.358
25.86,113.09,-0.358
25.88,112.94,-0.358
25.89,112.79,-0.358
25.91,112.64,-0.358
25.92,112.49,-0.358
25.94,112.34,-0.358
25.95,112.19,-0.358
25.97,112.04,-0.358
25.98,111.89,-0.358
26.00,111.74,-0.358
26.01,111.59,-0.358
26.03,111.44,-0.357
26.04,111.29,-0.357
26.06,111.14,-0.357
26.07,110.99,-0.357
26.09,110.84,-0.357
26.10,110.69,-0.357
26.12,110.54,-0.357
26.13,110.39,-0.357
26.15,110.24,-0.357
26.16,110.09,-0.357
26.18,109.94,-0.357
26.19,109.79,-0.357
26.21,109.64,-0.356
26.22,109.49,-0.356
26.24,109.34,-0.356
26.25,109.19,-0.356
26.27,109.04,-0.356
26.28,108.89,-0.356
26.30,108.74,-0.356
26.31,108.59,-0.356
26.33,108.44,-0.356
26.34,108.30,-0.356
26.36,108.14,-0.356
26.37,108.00,-0.356
26.39,107.84,-0.356
26.40,107.70,-0.356
26.42,107.55,-0.356
26.43,107.40,-0.355
26.45,107.25,-0.355
26.46,107.10,-0.355
26.48,106.95,-0.355
26.49,106.80,-0.355
26.51,106.65,-0.355
26.52,106.50,-0.355
26.54,106.35,-0.355
26.55,106.20,-0.355
26.57,106.05,-0.355
26.58,105.90,-0.355
26.60,105.75,-0.355
26.61,105.60,-0.355
26.63,105.45,-0.355
26.64,105.30,-0.354
26.66,105.15,-0.354
26.67,105.00,-0.354
26.69,104.85,-0.354
26.70,104.70,-0.354
26.72,104.55,-0.354
26.73,104.40,-0.354
26.75,104.25,-0.354
26.76,104.10,-0.354
26.78,103.95,-0.354
26.79,103.80,-0.354
26.81,103.65,-0.354
26.82,103.50,-0.353
26.84,103.35,-0.353
26.85,103.20,-0.353
26.87,103.05,-0.353
26.88,102.90,-0.353
26.90,102.75,-0.353
26.91,102.60,-0.353
26.93,102.45,-0.353
26.94,102.30,-0.353
26.96,102.15,-0.353
26.97,102.00,-0.353
26.99,101.85,-0.352
27.00,101.70,-0.352
27.02,101.55,-0.352
27.03,101.40,-0.352
27.05,101.25,-0.352
27.06,101.10,-0.352
27.08,100.95,-0.352
27.09,100.80,-0.352
27.11,100.65,-0.352
27.12,100.50,-0.352
27.14,100.36,-0.352
27.15,100.20,-0.352
27.17,100.05,-0.352
27.18,99.90,-0.351
27.20,99.76,-0.351
27.21,99.61,-0.351
27.23,99.45,-0.351
27.24,99.31,-0.351
27.26,99.16,-0.351
27.27,99.01,-0.351
27.29,98.86,-0.351
27.30,98.71,-0.351
27.32,98.56,-0.351
27.33,98.41,-0.351
27.35,98.26,-0.351
27.36,98.11,-0.351
27.38,97.96,-0.351
27.39,97.81,-0.351
27.41,97.66,-0.350
27.42,97.51,-0.350
27.44,97.36,-0.350
27.45,97.21,-0.350
27.47,97.06,-0.350
27.48,96.91,-0.350
27.50,96.76,-0.350
27.51,96.61,-0.350
27.53,96.46,-0.350
27.54,96.31,-0.350
27.56,96.16,-0.350
27.57,96.01,-0.350
27.59,95.86,-0.350
27.60,95.71,-0.349
27.62,95.56,-0.349
27.63,95.41,-0.349
27.65,95.26,-0.349
27.66,95.11,-0.349
27.68,94.96,-0.349
27.69,94.81,-0.349
27.71,94.66,-0.349
27.72,94.51,-0.349
27.74,94.36,-0.349
27.75,94.21,-0.349
27.77,94.06,-0.349
27.78,93.91,-0.349
27.80,93.76,-0.349
27.81,93.61,-0.348
27.83,93.46,-0.348
27.84,93.31,-0.348
27.86,93.16,-0.348
27.87,93.01,-0.348
27.89,92.86,-0.348
27.90,92.71,-0.348
27.92,92.56,-0.348
27.93,92.41,-0.348
27.95,92.26,-0.348
27.96,92.11,-0.348
27.98,91.96,-0.348
27.99,91.81,-0.347
28.01,91.67,-0.347
28.02,91.51,-0.347
28.04,91.36,-0.347
28.05,91.22,-0.347
28.07,91.07,-0.347
28.08,90.92,-0.347
28.10,90.77,-0.347
28.11,90.62,-0.347
28.13,90.47,-0.347
28.14,90.32,-0.347
28.16,90.17,-0.347
28.17,90.02,-0.346
28.19,89.87,-0.346
28.20,89.72,-0.346
28.22,89.57,-0.346
28.23,89.42,-0.346
28.25,89.27,-0.346
28.26,89.12,-0.346
28.28,88.97,-0.346
28.29,88.82,-0.346
28.31,88.67,-0.346
28.32,88.52,-0.346
28.34,88.37,-0.345
28.35,88.22,-0.345
28.37,88.07,-0.345
28.38,87.92,-0.345
28.40,87.77,-0.345
28.41,87.62,-0.345
28.43,87.47,-0.345
28.44,87.32,-0.345
28.46,87.17,-0.345
28.47,87.02,-0.345
[...]
93.05,-11.13,0.178
93.06,-10.98,0.178
93.08,-10.83,0.178
93.09,-10.68,0.178
93.11,-10.53,0.178
93.12,-10.38,0.179
93.14,-10.23,0.179
93.15,-10.08,0.179
93.17,-9.93,0.179
93.18,-9.78,0.179
93.20,-9.63,0.180
93.21,-9.48,0.180
93.23,-9.33,0.180
93.24,-9.18,0.180
93.26,-9.03,0.180
93.27,-8.88,0.181
93.29,-8.73,0.181
93.30,-8.58,0.181
93.32,-8.43,0.181
93.33,-8.28,0.181
93.35,-8.13,0.182
93.36,-7.98,0.182
93.38,-7.83,0.182
93.39,-7.68,0.182
93.41,-7.53,0.183
93.42,-7.38,0.183
93.44,-7.23,0.183
93.45,-7.08,0.184
93.47,-6.93,0.184
93.48,-6.78,0.184
93.50,-6.63,0.185
93.51,-6.48,0.185
93.53,-6.33,0.186
93.54,-6.18,0.186
93.56,-6.03,0.186
93.57,-5.88,0.187
93.59,-5.73,0.187
93.60,-5.58,0.188
93.62,-5.43,0.188
93.63,-5.28,0.189
93.65,-5.13,0.189
93.66,-4.98,0.190
93.68,-4.83,0.190
93.69,-4.68,0.191
93.71,-4.53,0.192
93.72,-4.38,0.192
93.74,-4.23,0.193
93.75,-4.08,0.194
93.77,-3.93,0.195
93.78,-3.78,0.196
93.80,-3.63,0.196
93.81,-3.48,0.197
93.83,-3.33,0.198
93.84,-3.18,0.200
93.86,-3.03,0.200
93.87,-2.88,0.203
93.89,-2.73,0.204
93.90,-2.58,0.205
93.92,-2.43,0.206
93.93,-2.28,0.206
93.95,-2.13,0.208
93.96,-1.98,0.209
93.98,-1.83,0.211
93.99,-1.69,0.213
94.01,-1.53,0.214
94.02,-1.39,0.216
94.04,-1.24,0.217
94.05,-1.09,0.219
94.07,-0.94,0.221
94.08,-0.79,0.222
94.10,-0.64,0.225
94.11,-0.49,0.226
94.13,-0.34,0.229
94.14,-0.19,0.230
94.16,-0.04,0.233
94.17,0.10,0.235
94.19,0.25,0.238
94.20,0.40,0.241
94.22,0.55,0.242
94.23,0.70,0.246
94.25,0.85,0.247
94.26,1.00,0.250
94.28,1.14,0.253
94.29,1.29,0.256
94.31,1.44,0.258
94.32,1.59,0.263
94.34,1.74,0.264
94.35,1.89,0.268
94.37,2.04,0.271
94.38,2.18,0.273
94.40,2.33,0.276
94.41,2.48,0.278
94.43,2.63,0.280
94.44,2.78,0.282
94.46,2.93,0.284
94.47,3.07,0.285
94.49,3.22,0.286
94.50,3.37,0.288
94.52,3.52,0.288
94.53,3.67,0.288
94.55,3.82,0.289
94.56,3.97,0.289
94.58,4.12,0.289
94.59,4.27,0.288
94.61,4.42,0.288
94.62,4.57,0.287
94.64,4.72,0.286
94.65,4.87,0.284
94.67,5.02,0.282
94.68,5.17,0.279
94.70,5.33,0.278
94.71,5.48,0.276
94.73,5.63,0.274
94.74,5.78,0.273
94.76,5.93,0.271
94.77,6.08,0.271
94.79,6.23,0.270
94.80,6.38,0.270
94.82,6.54,0.268
94.83,6.68,0.268
94.85,6.84,0.267
94.86,6.99,0.267
94.88,7.14,0.267
94.89,7.29,0.266
94.91,7.44,0.266
94.92,7.59,0.266
94.94,7.74,0.266
94.95,7.89,0.266
94.97,8.04,0.265
94.98,8.19,0.265
95.00,8.34,0.265
95.01,8.49,0.265
95.03,8.64,0.265
95.04,8.79,0.265
95.06,8.94,0.264
95.07,9.09,0.264
95.09,9.25,0.264
95.10,9.40,0.264
95.12,9.55,0.264
95.13,9.69,0.264
95.15,9.85,0.264
95.16,10.00,0.264
95.18,10.15,0.263
95.19,10.30,0.263
95.21,10.45,0.263
95.22,10.60,0.263
95.24,10.75,0.263
95.25,10.90,0.263
95.27,11.05,0.263
95.28,11.20,0.263
95.30,11.35,0.263
95.31,11.50,0.263
95.33,11.65,0.263
95.34,11.80,0.263
95.36,11.95,0.263
95.37,12.10,0.263
95.39,12.25,0.263
95.40,12.40,0.263
95.42,12.55,0.263
95.43,12.70,0.263
95.45,12.85,0.263
95.46,13.00,0.263
95.48,13.15,0.263
95.49,13.30,0.263
95.51,13.45,0.263
95.52,13.60,0.263
95.54,13.75,0.263
95.55,13.90,0.263
95.57,14.05,0.263
95.58,14.20,0.263
95.60,14.35,0.263
95.61,14.50,0.263
95.63,14.65,0.263
95.64,14.80,0.263
95.66,14.95,0.263
95.67,15.10,0.263
95.69,15.25,0.264
95.70,15.40,0.264
95.72,15.55,0.264
95.73,15.70,0.264
95.75,15.85,0.264
95.76,16.00,0.264
95.78,16.15,0.264
95.79,16.30,0.264
95.81,16.45,0.264
95.82,16.60,0.264
95.84,16.75,0.264
95.85,16.90,0.264
95.87,17.05,0.264
95.88,17.20,0.264
95.90,17.36,0.264
95.91,17.51,0.265
95.93,17.66,0.265
95.94,17.80,0.265
95.96,17.96,0.265
95.97,18.11,0.265
95.99,18.26,0.265
96.00,18.41,0.265
96.02,18.56,0.265
96.03,18.71,0.265
96.05,18.86,0.265
96.06,19.01,0.265
96.08,19.16,0.265
96.09,19.31,0.265
96.11,19.46,0.265
96.12,19.61,0.266
96.14,19.76,0.266
96.15,19.91,0.266
96.17,20.06,0.266
96.18,20.21,0.266
96.20,20.36,0.266
96.21,20.51,0.266
96.23,20.66,0.266
96.24,20.81,0.266
96.26,20.96,0.266
96.27,21.11,0.266
96.29,21.26,0.267
96.30,21.41,0.267
96.32,21.56,0.267
96.33,21.71,0.267
96.35,21.86,0.267
96.36,22.01,0.267
96.38,22.16,0.267
96.39,22.31,0.267
96.41,22.46,0.267
96.42,22.61,0.267
96.44,22.76,0.268
96.45,22.91,0.268
96.47,23.06,0.268
96.48,23.21,0.268
96.50,23.36,0.268
96.51,23.51,0.268
96.53,23.66,0.268
96.54,23.81,0.268
96.56,23.96,0.268
96.57,24.11,0.268
96.59,24.26,0.268
96.60,24.41,0.269
96.62,24.56,0.269
96.63,24.71,0.269
96.65,24.86,0.269
96.66,25.01,0.269
96.68,25.16,0.269
96.69,25.31,0.269
96.71,25.46,0.269
96.72,25.61,0.269
96.74,25.76,0.269
96.75,25.91,0.270
96.77,26.07,0.270
96.78,26.21,0.270
96.80,26.37,0.270
96.81,26.52,0.270
96.83,26.66,0.270
96.84,26.82,0.270
96.86,26.96,0.270
96.87,27.12,0.270
96.89,27.27,0.270
96.90,27.42,0.270
96.92,27.57,0.271
96.93,27.72,0.271
96.95,27.87,0.271
96.96,28.02,0.271
96.98,28.17,0.271
96.99,28.32,0.271
97.01,28.47,0.271
97.02,28.62,0.271
97.04,28.77,0.271
97.05,28.92,0.271
97.07,29.07,0.272
97.08,29.22,0.272
97.10,29.37,0.272
97.11,29.52,0.272
97.13,29.67,0.272
97.14,29.82,0.272
97.16,29.97,0.272
97.17,30.12,0.272
97.19,30.27,0.272
97.20,30.42,0.272
97.22,30.57,0.272
97.23,30.72,0.273
97.25,30.87,0.273
97.26,31.02,0.273
97.28,31.17,0.273
97.29,31.32,0.273
97.31,31.47,0.273
97.32,31.62,0.273
97.34,31.77,0.273
97.35,31.92,0.273
97.37,32.07,0.273
97.38,32.22,0.273
97.40,32.37,0.274
97.41,32.52,0.274
97.43,32.67,0.274
97.44,32.82,0.274
97.46,32.97,0.274
97.47,33.12,0.274
97.49,33.27,0.274
97.50,33.42,0.274
97.52,33.57,0.274
97.53,33.72,0.274
97.55,33.87,0.274
97.56,34.02,0.274
97.58,34.17,0.275
97.59,34.32,0.275
97.61,34.47,0.275
97.62,34.62,0.275
97.64,34.77,0.275
97.65,34.92,0.275
97.67,35.07,0.275
97.68,35.22,0.275
97.70,35.37,0.275
97.71,35.52,0.275
97.73,35.67,0.275
97.74,35.82,0.275
97.76,35.97,0.275
97.77,36.13,0.276
97.79,36.28,0.276
97.80,36.43,0.276
97.82,36.58,0.276
97.83,36.73,0.276
97.85,36.88,0.276
97.86,37.03,0.276
97.88,37.18,0.276
97.89,37.33,0.276
97.91,37.48,0.276
97.92,37.63,0.276
97.94,37.78,0.276
97.95,37.93,0.277
97.97,38.08,0.277
97.98,38.23,0.277
98.00,38.38,0.277
98.01,38.53,0.277
98.03,38.68,0.277
98.04,38.83,0.277
98.06,38.98,0.277
98.07,39.13,0.277
98.09,39.28,0.277
98.10,39.43,0.277
98.12,39.58,0.278
98.13,39.73,0.278
98.15,39.88,0.278
98.16,40.03,0.278
98.18,40.18,0.278
98.19,40.33,0.278
98.21,40.48,0.278
98.22,40.63,0.278
98.24,40.78,0.278
98.25,40.93,0.278
98.27,41.08,0.278
98.28,41.23,0.278
98.30,41.38,0.279
98.31,41.53,0.279
98.33,41.68,0.279
98.34,41.83,0.279
98.36,41.98,0.279
98.37,42.13,0.279
98.39,42.28,0.279
98.40,42.43,0.279
98.42,42.58,0.279
98.43,42.73,0.279
98.45,42.88,0.279
98.46,43.03,0.279
98.48,43.18,0.279
98.49,43.33,0.280
98.51,43.48,0.280
98.52,43.63,0.280
98.54,43.78,0.280
98.55,43.93,0.280
98.57,44.08,0.280
98.58,44.23,0.280
98.60,44.38,0.280
98.61,44.53,0.280
98.63,44.69,0.280
98.64,44.83,0.280
98.66,44.99,0.280
98.67,45.14,0.280
98.69,45.29,0.281
98.70,45.44,0.281
98.72,45.59,0.281
98.73,45.74,0.281
98.75,45.89,0.281
98.76,46.04,0.281
98.78,46.19,0.281
98.79,46.34,0.281
98.81,46.49,0.281
98.82,46.64,0.281
98.84,46.79,0.281
98.85,46.94,0.281
98.87,47.09,0.282
98.88,47.24,0.282
98.90,47.39,0.282
98.91,47.54,0.282
98.93,47.69,0.282
98.94,47.84,0.282
98.96,47.99,0.282
98.97,48.14,0.282
98.99,48.29,0.282
99.00,48.44,0.282
99.02,48.59,0.282
99.03,48.74,0.282
99.05,48.89,0.282
99.06,49.04,0.283
99.08,49.19,0.283
99.09,49.34,0.283
99.11,49.49,0.283
99.12,49.64,0.283
99.14,49.79,0.283
99.15,49.94,0.283
99.17,50.09,0.283
99.18,50.24,0.283
99.20,50.39,0.283
99.21,50.54,0.283
99.23,50.69,0.283
99.24,50.84,0.284
99.26,50.99,0.284
99.27,51.14,0.284
99.29,51.29,0.284
99.30,51.44,0.284
99.32,51.59,0.284
99.33,51.74,0.284
99.35,51.89,0.284
99.36,52.04,0.284
99.38,52.19,0.284
99.39,52.34,0.284
99.41,52.49,0.284
99.42,52.65,0.284
99.44,52.80,0.284
99.45,52.95,0.285
99.47,53.10,0.285
99.48,53.24,0.285
99.50,53.40,0.285
99.51,53.55,0.285
99.53,53.70,0.285
99.54,53.85,0.285
99.56,54.00,0.285
99.57,54.15,0.285
99.59,54.30,0.285
99.60,54.45,0.285
99.62,54.60,0.285
99.63,54.75,0.286
99.65,54.90,0.286
99.66,55.05,0.286
99.68,55.20,0.286
99.69,55.35,0.286
99.71,55.50,0.286
99.72,55.65,0.286
99.74,55.80,0.286
99.75,55.95,0.286
99.77,56.10,0.286
99.78,56.25,0.286
99.80,56.40,0.286
99.81,56.55,0.286
99.83,56.70,0.286
99.84,56.85,0.286
99.86,57.00,0.287
99.87,57.15,0.287
99.89,57.30,0.287
99.90,57.45,0.287
99.92,57.60,0.287
99.93,57.75,0.287
99.95,57.90,0.287
99.96,58.05,0.287
99.98,58.20,0.287
99.99,58.35,0.287
100.01,58.50,0.287
100.02,58.65,0.287
100.04,58.80,0.287
100.05,58.95,0.287
100.07,59.10,0.287
100.08,59.25,0.288
100.10,59.40,0.288
100.11,59.55,0.288
100.13,59.70,0.288
100.14,59.85,0.288
100.16,60.00,0.288
100.17,60.15,0.288
100.19,60.30,0.288
100.20,60.45,0.288
100.22,60.60,0.288
100.23,60.75,0.288
100.25,60.90,0.288
100.26,61.05,0.288
100.28,61.20,0.288
100.29,61.35,0.288
100.31,61.51,0.288
100.32,61.65,0.289
100.34,61.81,0.289
100.35,61.96,0.289
100.37,62.11,0.289
100.38,62.26,0.289
100.40,62.41,0.289
100.41,62.56,0.289
100.43,62.71,0.289
100.44,62.86,0.289
100.46,63.01,0.289
100.47,63.16,0.289
100.49,63.31,0.289
100.50,63.46,0.289
100.52,63.61,0.289
100.53,63.76,0.289
100.55,63.91,0.290
100.56,64.06,0.290
100.58,64.21,0.290
100.59,64.36,0.290
100.61,64.51,0.290
100.62,64.66,0.290
100.64,64.81,0.290
100.65,64.96,0.290
100.67,65.11,0.290
100.68,65.26,0.290
100.70,65.41,0.290
100.71,65.56,0.290
100.73,65.71,0.290
100.74,65.86,0.290
100.76,66.01,0.291
100.77,66.16,0.291
100.79,66.31,0.291
100.80,66.46,0.291
100.82,66.61,0.291
100.83,66.76,0.291
100.85,66.91,0.291
100.86,67.06,0.291
100.88,67.21,0.291
100.89,67.36,0.291
100.91,67.51,0.291
100.92,67.66,0.291
100.94,67.81,0.291
100.95,67.96,0.291
100.97,68.11,0.291
100.98,68.26,0.291
101.00,68.41,0.292
101.01,68.56,0.292
101.03,68.71,0.292
101.04,68.86,0.292
101.06,69.01,0.292
101.07,69.16,0.292
101.09,69.31,0.292
101.10,69.46,0.292
101.12,69.61,0.292
101.13,69.76,0.292
101.15,69.91,0.292
101.16,70.06,0.292
101.18,70.21,0.292
101.19,70.36,0.293
101.21,70.51,0.293
101.22,70.66,0.293
101.24,70.81,0.293
101.25,70.96,0.293
101.27,71.11,0.293
101.28,71.27,0.293
101.30,71.42,0.293
101.31,71.56,0.293
101.33,71.71,0.293
101.34,71.87,0.293
101.36,72.02,0.293
101.37,72.17,0.293
101.39,72.32,0.293
101.40,72.47,0.294
101.42,72.62,0.294
101.43,72.77,0.294
101.45,72.92,0.294
101.46,73.07,0.294
101.48,73.22,0.294
101.49,73.37,0.294
101.51,73.52,0.294
101.52,73.67,0.294
101.54,73.82,0.294
101.55,73.97,0.294
101.57,74.12,0.294
101.58,74.27,0.294
101.60,74.42,0.294
101.61,74.57,0.294
101.63,74.72,0.294
101.64,74.87,0.294
101.66,75.02,0.295
101.67,75.17,0.295
101.69,75.32,0.295
101.70,75.47,0.295
101.72,75.62,0.295
101.73,75.77,0.295
101.75,75.92,0.295
101.76,76.07,0.295
101.78,76.22,0.295
101.79,76.37,0.295
101.81,76.52,0.295
101.82,76.67,0.295
101.84,76.82,0.295
101.85,76.97,0.295
101.87,77.12,0.296
101.88,77.27,0.296
101.90,77.42,0.296
101.91,77.57,0.296
101.93,77.72,0.296
101.94,77.87,0.296
101.96,78.02,0.296
101.97,78.17,0.296
101.99,78.32,0.296
102.00,78.47,0.296
102.02,78.62,0.296
102.03,78.77,0.296
102.05,78.92,0.296
102.06,79.07,0.296
102.08,79.22,0.296
102.09,79.37,0.296
102.11,79.52,0.297
102.12,79.67,0.297
102.14,79.82,0.297
102.15,79.97,0.297
102.17,80.12,0.297
102.18,80.27,0.297
102.20,80.42,0.297
102.21,80.57,0.297
102.23,80.72,0.297
102.24,80.87,0.297
102.26,81.02,0.297
102.27,81.17,0.297
102.29,81.32,0.297
102.30,81.47,0.297
102.32,81.62,0.297
102.33,81.77,0.297
102.35,81.92,0.297
102.36,82.07,0.297
102.38,82.22,0.298
102.39,82.37,0.298
102.41,82.53,0.298
102.42,82.68,0.298
102.44,82.83,0.298
102.45,82.98,0.298
102.47,83.13,0.298
102.48,83.28,0.298
102.50,83.43,0.298
102.51,83.58,0.298
102.53,83.73,0.298
102.54,83.88,0.298
102.56,84.03,0.298
102.57,84.18,0.298
102.59,84.33,0.298
102.60,84.48,0.298
102.62,84.63,0.298
102.63,84.78,0.298
102.65,84.93,0.298
102.66,85.08,0.298
102.68,85.23,0.298
102.69,85.38,0.298
102.71,85.53,0.298
102.72,85.68,0.299
102.74,85.83,0.299
102.75,85.98,0.299
102.77,86.13,0.299
102.78,86.28,0.299
102.80,86.43,0.299
102.81,86.58,0.299
102.83,86.73,0.299
102.84,86.88,0.299
102.86,87.03,0.299
102.87,87.18,0.299
102.89,87.33,0.299
102.90,87.48,0.299
102.92,87.63,0.299
102.93,87.78,0.299
102.95,87.93,0.299
102.96,88.08,0.299
102.98,88.23,0.299
102.99,88.38,0.300
103.01,88.53,0.300
103.02,88.68,0.300
103.04,88.83,0.300
103.05,88.98,0.300
103.07,89.13,0.300
103.08,89.28,0.300
103.10,89.43,0.300
103.11,89.58,0.300
103.13,89.73,0.300
103.14,89.88,0.300
103.16,90.03,0.300
103.17,90.18,0.300
103.19,90.33,0.300
103.20,90.48,0.300
103.22,90.63,0.300
103.23,90.78,0.301
103.25,90.93,0.301
103.26,91.08,0.301
103.28,91.23,0.301
103.29,91.38,0.301
103.31,91.53,0.301
103.32,91.69,0.301
103.34,91.84,0.301
103.35,91.99,0.301
103.37,92.13,0.301
103.38,92.29,0.301
103.40,92.44,0.301
103.41,92.58,0.301
103.43,92.74,0.301
103.44,92.89,0.301
103.46,93.04,0.302
103.47,93.19,0.302
103.49,93.34,0.302
103.50,93.49,0.302
103.52,93.64,0.302
103.53,93.79,0.302
103.55,93.94,0.302
103.56,94.09,0.302
103.58,94.24,0.302
103.59,94.39,0.302
103.61,94.54,0.302
103.62,94.69,0.302
103.64,94.84,0.302
103.65,94.99,0.302
103.67,95.14,0.302
103.68,95.29,0.302
103.70,95.44,0.303
103.71,95.59,0.303
103.73,95.74,0.303
103.74,95.89,0.303
103.76,96.04,0.303
103.77,96.19,0.303
103.79,96.34,0.303
103.80,96.49,0.303
103.82,96.64,0.303
103.83,96.79,0.303
103.85,96.94,0.303
103.86,97.09,0.303
103.88,97.24,0.303
103.89,97.39,0.303
103.91,97.54,0.303
103.92,97.69,0.304
103.94,97.84,0.304
103.95,97.99,0.304
103.97,98.14,0.304
103.98,98.29,0.304
104.00,98.44,0.304
104.01,98.59,0.304
104.03,98.74,0.304
104.04,98.89,0.304
104.06,99.04,0.304
104.07,99.19,0.304
104.09,99.34,0.304
104.10,99.49,0.305
104.12,99.64,0.305
104.13,99.79,0.305
104.15,99.94,0.305
104.16,100.09,0.305
104.18,100.24,0.305
104.19,100.39,0.305
104.21,100.54,0.305
104.22,100.69,0.305
104.24,100.84,0.305
104.25,100.99,0.305
104.27,101.14,0.305
104.28,101.29,0.305
104.30,101.45,0.305
104.31,101.59,0.305
104.33,101.74,0.306
104.34,101.89,0.306
104.36,102.05,0.306
104.37,102.19,0.306
104.39,102.34,0.306
104.40,102.49,0.306
104.42,102.64,0.306
104.43,102.79,0.306
104.45,102.94,0.306
104.46,103.09,0.306
104.48,103.24,0.306
104.49,103.39,0.306
104.51,103.54,0.306
104.52,103.69,0.306
104.54,103.84,0.306
104.55,103.99,0.306
104.57,104.14,0.306
104.58,104.29,0.306
104.60,104.45,0.306
104.61,104.60,0.306
104.63,104.75,0.306
104.64,104.90,0.307
104.66,105.05,0.307
104.67,105.20,0.307
104.69,105.35,0.307
104.70,105.50,0.307
104.72,105.65,0.307
104.73,105.80,0.307
104.75,105.95,0.307
104.76,106.10,0.307
104.78,106.25,0.307
104.79,106.40,0.307
104.81,106.55,0.307
104.82,106.70,0.308
104.84,106.85,0.308
104.85,107.00,0.308
104.87,107.15,0.308
104.88,107.30,0.308
104.90,107.45,0.308
104.91,107.60,0.308
104.93,107.75,0.308
104.94,107.90,0.308
104.96,108.05,0.308
104.97,108.20,0.308
104.99,108.35,0.308
105.00,108.50,0.308
105.02,108.65,0.309
105.03,108.80,0.309
105.05,108.95,0.309
105.06,109.10,0.309
105.08,109.25,0.309
105.09,109.40,0.309
105.11,109.55,0.309
105.12,109.70,0.309
105.14,109.85,0.309
105.15,110.00,0.309
105.17,110.15,0.309
105.18,110.30,0.309
105.20,110.45,0.309
105.21,110.60,0.309
105.23,110.75,0.309
105.24,110.90,0.309
105.26,111.05,0.309
105.27,111.20,0.310
105.29,111.35,0.310
105.30,111.50,0.310
105.32,111.65,0.310
105.33,111.80,0.310
105.35,111.95,0.310
105.36,112.10,0.310
105.38,112.25,0.310
105.39,112.40,0.310
105.41,112.55,0.310
105.42,112.70,0.310
105.44,112.85,0.310
105.45,113.00,0.310
105.47,113.15,0.310
105.48,113.30,0.310
105.50,113.45,0.310
105.51,113.60,0.311
105.53,113.75,0.311
105.54,113.90,0.311
105.56,114.05,0.311
105.57,114.20,0.311
105.59,114.35,0.311
105.60,114.50,0.311
105.62,114.66,0.311
105.63,114.80,0.311
105.65,114.95,0.311
105.66,115.10,0.311
105.68,115.25,0.311
105.69,115.40,0.311
105.71,115.55,0.311
105.72,115.71,0.311
105.74,115.85,0.311
105.75,116.01,0.311
105.77,116.16,0.311
105.78,116.31,0.312
105.80,116.46,0.312
105.81,116.61,0.312
105.83,116.76,0.312
105.84,116.91,0.312
105.86,117.06,0.312
105.87,117.21,0.312
105.89,117.36,0.312
105.90,117.51,0.312
105.92,117.66,0.312
105.93,117.81,0.312
105.95,117.96,0.312
105.96,118.11,0.313
105.98,118.26,0.313
105.99,118.41,0.313
106.01,118.56,0.313
106.02,118.71,0.313
106.04,118.86,0.313
106.05,119.01,0.313
106.07,119.16,0.313
106.08,119.31,0.313
106.10,119.46,0.313
106.11,119.61,0.313
106.13,119.76,0.313
106.14,119.91,0.313
106.16,120.06,0.313
106.17,120.21,0.313
106.19,120.36,0.313
106.20,120.51,0.313
106.22,120.66,0.313
106.23,120.81,0.313
106.25,120.96,0.314
106.26,121.11,0.314
106.28,121.26,0.314
106.29,121.41,0.314
106.31,121.56,0.314
106.32,121.71,0.314
106.34,121.86,0.314
106.35,122.01,0.314
106.37,122.16,0.314
106.38,122.31,0.314
106.40,122.46,0.314
106.41,122.61,0.314
106.43,122.76,0.314
106.44,122.91,0.314
106.46,123.06,0.314
106.47,123.21,0.315
106.49,123.36,0.315
106.50,123.51,0.315
106.52,123.66,0.315
106.53,123.81,0.315
106.55,123.96,0.315
106.56,124.11,0.315
106.58,124.26,0.315
106.59,124.41,0.315
106.61,124.56,0.315
106.62,124.71,0.315
106.64,124.86,0.315
106.65,125.01,0.315
106.67,125.16,0.315
106.68,125.31,0.315
106.70,125.46,0.315
106.71,125.61,0.315
106.73,125.76,0.315
106.74,125.91,0.315
106.76,126.07,0.315
106.77,126.22,0.316
106.79,126.37,0.316
106.80,126.51,0.316
106.82,126.67,0.316
106.83,126.81,0.316
106.85,126.96,0.316
106.86,127.12,0.316
106.88,127.26,0.316
106.89,127.42,0.316
106.91,127.56,0.316
106.92,127.72,0.316
106.94,127.86,0.316
106.95,128.02,0.316
106.97,128.17,0.316
106.98,128.32,0.316
107.00,128.47,0.316
107.01,128.62,0.316
107.03,128.77,0.316
107.04,128.92,0.317
107.06,129.07,0.317
107.07,129.22,0.317
107.09,129.37,0.317
107.10,129.52,0.317
107.12,129.67,0.317
107.13,129.82,0.317
107.15,129.97,0.317
107.16,130.12,0.317
107.18,130.27,0.317
107.19,130.42,0.317
107.21,130.57,0.317
107.22,130.72,0.317
107.24,130.87,0.317
107.25,131.02,0.317
107.27,131.17,0.317
107.28,131.32,0.317
107.30,131.47,0.317
107.31,131.62,0.318
107.33,131.77,0.318
107.34,131.92,0.318
107.36,132.07,0.318
107.37,132.22,0.318
107.39,132.37,0.318
107.40,132.52,0.318
107.42,132.67,0.318
107.43,132.82,0.318
107.45,132.97,0.318
107.46,133.12,0.318
107.48,133.27,0.318
107.49,133.42,0.318
107.51,133.57,0.318
107.52,133.72,0.318
107.54,133.87,0.319
107.55,134.02,0.319
107.57,134.17,0.319
107.58,134.32,0.319
107.60,134.47,0.319
107.61,134.62,0.319
107.63,134.77,0.319
107.64,134.92,0.319
107.66,135.07,0.319
107.67,135.22,0.319
107.69,135.37,0.319
107.70,135.52,0.319
107.72,135.67,0.319
107.73,135.82,0.319
107.75,135.97,0.319
107.76,136.12,0.319
107.78,136.27,0.320
107.79,136.43,0.320
107.81,136.57,0.320
107.82,136.72,0.320
107.84,136.87,0.320
107.85,137.02,0.320
107.87,137.17,0.320
107.88,137.32,0.320
107.90,137.48,0.320
107.91,137.62,0.320
107.93,137.77,0.320
107.94,137.92,0.320
107.96,138.07,0.320
107.97,138.22,0.320
107.99,138.37,0.320
108.00,138.53,0.320
108.02,138.67,0.320
108.03,138.82,0.320
108.05,138.97,0.320
108.06,139.13,0.320
108.08,139.28,0.320
108.09,139.43,0.320
108.11,139.58,0.320
108.12,139.73,0.320
108.14,139.88,0.321
108.15,140.03,0.321
108.17,140.18,0.321
108.18,140.33,0.321
108.20,140.48,0.321
108.21,140.63,0.321
108.23,140.78,0.321
108.24,140.93,0.321
108.26,141.08,0.321
108.27,141.23,0.321
108.29,141.38,0.321
108.30,141.53,0.321
108.32,141.68,0.321
108.33,141.83,0.321
108.35,141.98,0.321
108.36,142.13,0.321
108.38,142.28,0.321
108.39,142.43,0.321
108.41,142.58,0.321
108.42,142.73,0.321
108.44,142.88,0.322
108.45,143.03,0.322
108.47,143.18,0.322
108.48,143.33,0.322
108.50,143.48,0.322
108.51,143.63,0.322
108.53,143.78,0.322
108.54,143.93,0.322
108.56,144.08,0.322
108.57,144.23,0.322
108.59,144.38,0.322
108.60,144.53,0.322
108.62,144.68,0.322
108.63,144.83,0.322
108.65,144.98,0.322
108.66,145.13,0.322
108.68,145.28,0.322
108.69,145.43,0.322
108.71,145.58,0.322
108.72,145.73,0.322
108.74,145.88,0.323
108.75,146.03,0.323
108.77,146.18,0.323
108.78,146.33,0.323
108.80,146.48,0.323
108.81,146.63,0.323
108.83,146.78,0.323
108.84,146.93,0.323
108.86,147.08,0.323
108.87,147.23,0.323
108.89,147.38,0.323
108.90,147.53,0.323
108.92,147.68,0.323
108.93,147.83,0.324
108.95,147.98,
108.96,148.13,
108.98,148.28,
108.99,,