File: DSC/2025_04_11_Empty_Pans_Std_10Cmin_n60C_200C.csv
Filename,2025_04_11_Empty_Pans_Std_10Cmin_n60C_200C
Instrument name,DSC2A-00468 (192.168.1.100)
Operator,Yarger
rundate,4/11/2025
Sample name,2025_04_11_Empty_Pans_Std_10Cmin_n60C_200C
proceduresegments,Data Off ; Equilibrate -60.00 °C; Data On ; Ramp 10.00 °C/min to 200.00 °C; Data Off ; Isothermal 1.0 min; Data On ; Ramp 10.00 °C/min to -60.00 °C; Data Off ; Isothermal 1.0 min; Data On ; Ramp 10.00 °C/min to 200.00 °C; Data Off ; Isothermal 1.0 min; Data On ; Ramp 10.00 °C/min to -60.00 °C; Data Off ; Isothermal 1.0 min; Data On ; Ramp 10.00 °C/min to 200.00 °C
[File Parameters]
Run date,4/11/2025 10:15:15 PM
Trios version,5.1.1.46572
Original File Name,
Current File Name,D:\DSC2500\JYarger\2025_04_11_Empty_Pans_Std_10Cmin_n60C_200C.tri
[Procedure]
Procedure Name,Empty_Pans_n60_200C_10Cmin_x3
Sample Name,2025_04_11_Empty_Pans_Std_10Cmin_n60C_200C
Sample Mass,0 mg
Reference Sample Mass,0 mg
Pan Mass,54.47 mg
Pan Number,11
Reference Pan Mass,53.32 mg
Reference Pan Number,10
Pan Type,Tzero Aluminum Hermetic
Comments,Hermetic Sealed Al DSC Consumables Pan/Lids.
Project Name,CA
Operator,Yarger
Test,Custom
Unload Max Temperature,30
Unload Min Temperature,30
Load Max Temperature,30
Load Min Temperature,30
Stop on Gas Flow Error,Yes
[Signal List]
Signal #1,Time (min)
Signal #2,Temperature (°C)
Signal #3,Heat Flow (mW)
Signal #4,Delta T (µV)
Signal #5,Delta Tzero (µV)
Signal #6,Tzero Temperature (°C)
Signal #7,Cell Purge (mL/min)
Signal #8,Heater Temp (°C)
Signal #9,Power Delivered (W)
Signal #10,Reference Junction Temperature (°C)
Signal #11,Flange Temperature (°C)
Signal #12,Heat Flow Phase (rad)
Signal #13,Total Heat Capacity (J/°C)
Signal #14,Heat Capacity (J/°C)
[Configuration]
Company Name,ASU
Instrument Name,DSC2A-00468
Instrument Type,DSC2500
Serial Number,DSC2A-00468
IP,192.168.1.100
Location of Instrument,MRRC
DisplayType,Unknown
Sample Interval ,0.1 s/pt
Selected Heat Flow,T4P
Exotherm Direction,Down
Cell Serial,DRC2-00792
Lid Type,Standard
Cooler,RCS 90
Leave Cooler on at End of Sequence,On
Gas 2,Nitrogen
Gas Selected,Channel 1
Flow Rate,50 mL/min
Secondary Purge,On
Licensed Heat Flow,Heat Flow T4P
Modulation Licensed,Yes
[Versions]
Common IDD Version,1
Cortex Version,VER 2.10.2.31
Driver,5.0.0.6
GDM Version,1.0.3.3
TouchscreenVersion,1.0.0.16145
FEP Version,1.2.1.21
FEP Bootloader,2.0.0.5
AutoSampler Version,2.1.1.26
Auto Sampler Bootloader,2.0.0.5
FCM Version,1.1.0.3
FCM Bootloader,2.0.0.5
[Experiment Logs]
Experiment Log Entry # 1,Data On set to 0
Experiment Log Entry # 3,Equilibrate Segment -60 (C) Started
Experiment Log Entry # 5,Air Cool is off.
Experiment Log Entry # 7,Data On set to 1
Experiment Log Entry # 9,Ramp Segment 10 C/min to 200 Started
Experiment Log Entry # 11,Data On set to 0
Experiment Log Entry # 13,Isothermal Segment 1 min started
Experiment Log Entry # 15,Data On set to 1
Experiment Log Entry # 17,Ramp Segment 10 C/min to -60 Started
Experiment Log Entry # 19,Data On set to 0
Experiment Log Entry # 21,Isothermal Segment 1 min started
Experiment Log Entry # 23,Data On set to 1
Experiment Log Entry # 25,Ramp Segment 10 C/min to 200 Started
Experiment Log Entry # 27,Data On set to 0
Experiment Log Entry # 29,Isothermal Segment 1 min started
Experiment Log Entry # 31,Data On set to 1
Experiment Log Entry # 33,Ramp Segment 10 C/min to -60 Started
Experiment Log Entry # 35,Data On set to 0
Experiment Log Entry # 37,Isothermal Segment 1 min started
Experiment Log Entry # 39,Data On set to 1
Experiment Log Entry # 41,Ramp Segment 10 C/min to 200 Started
[Method Log]
Method Log Entry # 1,Data Off
Method Log Entry # 2,Equilibrate -60 °C
Method Log Entry # 3,Data On
Method Log Entry # 4,(Ramp 71791) Ramp 10 °C/minute to 200 °C
Method Log Entry # 5,Data Off
Method Log Entry # 6,Isothermal 1 minutes
Method Log Entry # 7,Data On
Method Log Entry # 8,(Ramp 71795) Ramp 10 °C/minute to -60 °C
Method Log Entry # 9,Data Off
Method Log Entry # 10,Isothermal 1 minutes
Method Log Entry # 11,Data On
Method Log Entry # 12,(Ramp 71799) Ramp 10 °C/minute to 200 °C
Method Log Entry # 13,Data Off
Method Log Entry # 14,Isothermal 1 minutes
Method Log Entry # 15,Data On
Method Log Entry # 16,(Ramp 71803) Ramp 10 °C/minute to -60 °C
Method Log Entry # 17,Data Off
Method Log Entry # 18,Isothermal 1 minutes
Method Log Entry # 19,Data On
Method Log Entry # 20,(Ramp 71807) Ramp 10 °C/minute to 200 °C
Cell Serial,DRC2-00792
[T1 Calibration]
Slope,-0.008529666
Offset,9.636258
Initial Temperature,98.23
GUID,f8bfdadc-4977-4fdf-ba6d-0ba9134940c3
[TZero Calibration]
Date Applied,11/29/2022 4:06:13 PM
Description,From -89.059 °C to 396.009 °C at 20.000°C/min
Gas Type,Nitrogen
Pan Type,None
Source Files 1,C:\Users\yargerlab\Desktop\DSC Data\General\TZero_calibration_11_29_22_2nd(2).tri
Source Files 2,C:\Users\yargerlab\Desktop\DSC Data\General\TZero_calibration_11_29_22_2nd(3).tri
Delta T Offset,13.05235
Delta T Slope,-0.007271007
Delta T0 Offset,-13.69128
Delta T0 Slope,0.06063341
[Temperature Calibration]
Date Applied,11/29/2022 7:12:28 PM
Description,From 106.590 °C to 186.590 °C at 10.000°C/min
Gas Type,Nitrogen
Pan Type,Tzero Aluminum Hermetic
Source Files 1,C:\Users\yargerlab\Desktop\DSC Data\General\Indium(6).tri
Measured 1,157.391
Known 1,156.598
[Cell Constant Calibration]
Date Applied,11/29/2022 7:12:29 PM
Description,From 106.590 °C to 186.590 °C at 10.000°C/min
Gas Type,Nitrogen
Pan Type,Tzero Aluminum Hermetic
Source Files 1,C:\Users\yargerlab\Desktop\DSC Data\General\Indium(6).tri
T4P KCell,1.006051
Onset Slope,63.26126 mW/°C
[Direct Cp Calibration]
Date Applied,11/30/2022 11:04:51 AM
Description,From -79.983 °C to 298.409 °C at 10.000°C/min
Gas Type,Nitrogen
Pan Type,Tzero Aluminum Hermetic
Source Files 1,C:\Users\yargerlab\Desktop\DSC Data\General\Sapphire_Heat_Capacity_11_30_22.tri
[Rev Cp Calibration]
Date Applied,11/30/2022 1:58:51 PM
Description,From -79.996 °C to 292.812 °C at 3.000°C/min
Gas Type,Nitrogen
Pan Type,Tzero Aluminum Hermetic
Source Files 1,C:\Users\yargerlab\Desktop\DSC Data\General\Sapphire_MDSC_Calibration_11_30_22.tri
[step]
Ramp 10.00 °C/min to 200.00 °C
Time,Temperature,Heat Flow (Normalized)
min,°C,W/g
0.00,-59.72,
0.02,-59.72,
0.04,-59.73,
0.05,-59.73,
0.07,-59.71,
0.09,-59.68,
0.11,-59.63,
0.13,-59.55,
0.15,-59.46,
0.16,-59.35,
0.18,-59.22,
0.20,-59.09,
0.22,-58.94,
0.24,-58.79,
0.26,-58.63,
0.28,-58.47,
0.29,-58.31,
0.31,-58.14,
0.33,-57.97,
0.35,-57.80,
0.37,-57.63,
0.39,-57.46,
0.40,-57.29,
0.42,-57.11,
0.44,-56.94,
0.46,-56.76,
0.48,-56.59,
0.50,-56.41,
0.51,-56.23,
0.53,-56.06,
0.55,-55.88,
0.57,-55.70,
0.59,-55.52,
0.60,-55.34,
0.62,-55.16,
0.64,-54.98,
0.66,-54.81,
0.68,-54.63,
0.70,-54.45,
0.72,-54.27,
0.73,-54.09,
0.75,-53.91,
0.77,-53.73,
0.79,-53.55,
0.81,-53.37,
0.83,-53.19,
0.84,-53.01,
0.86,-52.83,
0.88,-52.64,
0.90,-52.46,
0.92,-52.28,
0.93,-52.10,
0.95,-51.92,
0.97,-51.74,
0.99,-51.56,
1.01,-51.38,
1.03,-51.20,
1.05,-51.01,
1.06,-50.83,
1.08,-50.65,
1.10,-50.47,
1.12,-50.28,
1.14,-50.10,
1.16,-49.92,
1.17,-49.74,
1.19,-49.56,
1.21,-49.37,
1.23,-49.19,
1.25,-49.01,
1.27,-48.83,
1.28,-48.64,
1.30,-48.46,
1.32,-48.28,
1.34,-48.10,
1.36,-47.91,
1.38,-47.73,
1.39,-47.55,
1.41,-47.37,
1.43,-47.18,
1.45,-47.00,
1.47,-46.82,
1.48,-46.63,
1.50,-46.45,
1.52,-46.27,
1.54,-46.08,
1.56,-45.90,
1.58,-45.72,
1.59,-45.54,
1.61,-45.35,
1.63,-45.17,
1.65,-44.99,
1.67,-44.80,
1.69,-44.62,
1.71,-44.44,
1.72,-44.25,
1.74,-44.07,
1.76,-43.89,
1.78,-43.70,
1.80,-43.52,
1.82,-43.34,
1.83,-43.15,
1.85,-42.97,
1.87,-42.79,
1.89,-42.60,
1.91,-42.42,
1.93,-42.24,
1.94,-42.05,
1.96,-41.87,
1.98,-41.69,
2.00,-41.50,
2.02,-41.32,
2.03,-41.14,
2.05,-40.95,
2.07,-40.77,
2.09,-40.58,
2.11,-40.40,
2.13,-40.22,
2.14,-40.04,
2.16,-39.85,
2.18,-39.67,
2.20,-39.48,
2.22,-39.30,
2.24,-39.12,
2.26,-38.93,
2.27,-38.75,
2.29,-38.57,
2.31,-38.38,
2.33,-38.20,
2.35,-38.01,
2.36,-37.83,
2.38,-37.65,
2.40,-37.46,
2.42,-37.28,
2.44,-37.10,
2.46,-36.91,
2.48,-36.73,
2.49,-36.55,
2.51,-36.36,
2.53,-36.18,
2.55,-36.00,
2.57,-35.81,
2.59,-35.63,
2.60,-35.44,
2.62,-35.26,
2.64,-35.08,
2.66,-34.90,
2.68,-34.71,
2.69,-34.53,
2.71,-34.34,
2.73,-34.16,
2.75,-33.98,
2.77,-33.79,
2.79,-33.61,
2.81,-33.43,
2.82,-33.24,
2.84,-33.06,
2.86,-32.88,
2.88,-32.69,
2.90,-32.51,
2.91,-32.32,
2.93,-32.14,
2.95,-31.96,
2.97,-31.77,
2.99,-31.59,
3.01,-31.41,
3.03,-31.22,
3.04,-31.04,
3.06,-30.86,
3.08,-30.67,
3.10,-30.49,
3.12,-30.30,
3.14,-30.12,
3.15,-29.94,
3.17,-29.75,
3.19,-29.57,
3.21,-29.39,
3.23,-29.20,
3.24,-29.02,
3.26,-28.84,
3.28,-28.65,
3.30,-28.47,
3.32,-28.29,
3.34,-28.10,
3.36,-27.92,
3.37,-27.73,
3.39,-27.55,
3.41,-27.37,
3.43,-27.18,
3.45,-27.00,
3.46,-26.82,
3.48,-26.63,
3.50,-26.45,
3.52,-26.26,
3.54,-26.08,
3.56,-25.90,
3.58,-25.72,
3.59,-25.53,
3.61,-25.35,
3.63,-25.17,
3.65,-24.98,
3.67,-24.80,
3.69,-24.61,
3.70,-24.43,
3.72,-24.24,
3.74,-24.06,
3.76,-23.88,
3.78,-23.70,
3.79,-23.51,
3.81,-23.33,
3.83,-23.14,
3.85,-22.96,
3.87,-22.78,
3.89,-22.59,
3.91,-22.41,
3.92,-22.23,
3.94,-22.04,
3.96,-21.86,
3.98,-21.68,
4.00,-21.49,
4.01,-21.31,
4.03,-21.12,
4.05,-20.94,
4.07,-20.76,
4.09,-20.57,
4.11,-20.39,
4.13,-20.21,
4.14,-20.02,
4.16,-19.84,
4.18,-19.66,
4.20,-19.47,
4.22,-19.29,
4.24,-19.11,
4.25,-18.92,
4.27,-18.74,
4.29,-18.56,
4.31,-18.37,
4.33,-18.19,
4.35,-18.00,
4.36,-17.82,
4.38,-17.64,
4.40,-17.45,
4.42,-17.27,
4.44,-17.09,
4.45,-16.90,
4.47,-16.72,
4.49,-16.54,
4.51,-16.35,
4.53,-16.17,
4.55,-15.99,
4.56,-15.80,
4.58,-15.62,
4.60,-15.43,
4.62,-15.25,
4.64,-15.07,
4.66,-14.88,
4.68,-14.70,
4.69,-14.52,
4.71,-14.33,
4.73,-14.15,
4.75,-13.97,
4.77,-13.78,
4.79,-13.60,
4.80,-13.41,
4.82,-13.23,
4.84,-13.05,
4.86,-12.86,
4.88,-12.68,
4.90,-12.50,
4.91,-12.31,
4.93,-12.13,
4.95,-11.95,
4.97,-11.76,
4.99,-11.58,
5.00,-11.40,
5.02,-11.21,
5.04,-11.03,
5.06,-10.85,
5.08,-10.66,
5.10,-10.48,
5.11,-10.30,
5.13,-10.11,
5.15,-9.93,
5.17,-9.74,
5.19,-9.56,
5.21,-9.38,
5.23,-9.19,
5.24,-9.01,
5.26,-8.83,
5.28,-8.64,
5.30,-8.46,
5.32,-8.28,
5.34,-8.09,
5.35,-7.91,
5.37,-7.73,
5.39,-7.54,
5.41,-7.36,
5.43,-7.17,
5.45,-6.99,
5.46,-6.81,
5.48,-6.62,
5.50,-6.44,
5.52,-6.26,
5.54,-6.07,
5.55,-5.89,
5.57,-5.71,
5.59,-5.52,
5.61,-5.34,
5.63,-5.16,
5.65,-4.97,
5.66,-4.79,
5.68,-4.60,
5.70,-4.42,
5.72,-4.24,
5.74,-4.05,
5.76,-3.87,
5.78,-3.69,
5.79,-3.50,
5.81,-3.32,
5.83,-3.14,
5.85,-2.95,
5.87,-2.77,
5.89,-2.59,
5.90,-2.40,
5.92,-2.22,
5.94,-2.03,
5.96,-1.85,
5.98,-1.67,
6.00,-1.48,
6.01,-1.30,
6.03,-1.12,
6.05,-0.93,
6.07,-0.75,
6.09,-0.57,
6.10,-0.38,
6.12,-0.20,
6.14,-0.02,
6.16,0.17,
6.18,0.35,
6.20,0.54,
6.21,0.72,
6.23,0.90,
6.25,1.09,
6.27,1.27,
6.29,1.45,
6.31,1.64,
6.33,1.82,
6.34,2.00,
6.36,2.19,
6.38,2.37,
6.40,2.56,
6.42,2.74,
6.44,2.92,
6.45,3.10,
6.47,3.29,
6.49,3.47,
6.51,3.66,
6.53,3.84,
6.55,4.02,
6.56,4.21,
6.58,4.39,
6.60,4.57,
6.62,4.76,
6.64,4.94,
6.65,5.12,
6.67,5.31,
6.69,5.49,
6.71,5.67,
6.73,5.86,
6.75,6.04,
6.76,6.23,
6.78,6.41,
6.80,6.59,
6.82,6.78,
6.84,6.96,
6.86,7.14,
6.88,7.33,
6.89,7.51,
6.91,7.70,
6.93,7.88,
6.95,8.06,
6.97,8.25,
6.99,8.43,
7.00,8.61,
7.02,8.80,
7.04,8.98,
7.06,9.16,
7.08,9.35,
7.10,9.53,
7.11,9.71,
7.13,9.90,
7.15,10.08,
7.17,10.26,
7.19,10.45,
7.20,10.63,
7.22,10.82,
7.24,11.00,
7.26,11.18,
7.28,11.36,
7.30,11.55,
7.31,11.73,
7.33,11.92,
7.35,12.10,
7.37,12.29,
7.39,12.47,
7.41,12.65,
7.43,12.83,
7.44,13.02,
7.46,13.20,
7.48,13.39,
7.50,13.57,
7.52,13.75,
7.54,13.94,
7.55,14.12,
7.57,14.30,
7.59,14.49,
7.61,14.67,
7.63,14.85,
7.65,15.04,
7.66,15.22,
7.68,15.41,
7.70,15.59,
7.72,15.77,
7.74,15.95,
7.75,16.14,
7.77,16.32,
7.79,16.51,
7.81,16.69,
7.83,16.87,
7.85,17.06,
7.86,17.24,
7.88,17.42,
7.90,17.61,
7.92,17.79,
7.94,17.97,
7.96,18.16,
7.98,18.34,
7.99,18.52,
8.01,18.71,
8.03,18.89,
8.05,19.08,
8.07,19.26,
8.09,19.44,
8.10,19.63,
8.12,19.81,
8.14,19.99,
8.16,20.18,
8.18,20.36,
8.20,20.54,
8.21,20.73,
8.23,20.91,
8.25,21.09,
8.27,21.28,
8.29,21.46,
8.30,21.64,
8.32,21.83,
8.34,22.01,
8.36,22.20,
8.38,22.38,
8.40,22.56,
8.41,22.75,
8.43,22.93,
8.45,23.11,
8.47,23.30,
8.49,23.48,
8.51,23.66,
8.53,23.85,
8.54,24.03,
8.56,24.21,
8.58,24.40,
8.60,24.58,
8.62,24.76,
8.63,24.95,
8.65,25.13,
8.67,25.32,
8.69,25.50,
8.71,25.68,
8.73,25.87,
8.75,26.05,
8.76,26.23,
8.78,26.42,
8.80,26.60,
8.82,26.78,
8.84,26.97,
8.85,27.15,
8.87,27.33,
8.89,27.52,
8.91,27.70,
8.93,27.89,
8.95,28.07,
8.97,28.25,
8.98,28.44,
9.00,28.62,
9.02,28.80,
9.04,28.99,
9.06,29.17,
9.08,29.35,
9.09,29.54,
9.11,29.72,
9.13,29.90,
9.15,30.09,
9.17,30.27,
9.18,30.45,
9.20,30.64,
9.22,30.82,
9.24,31.00,
9.26,31.19,
9.28,31.37,
9.30,31.56,
9.31,31.74,
9.33,31.92,
9.35,32.11,
9.37,32.29,
9.39,32.47,
9.40,32.66,
9.42,32.84,
9.44,33.02,
9.46,33.21,
9.48,33.39,
9.50,33.58,
9.52,33.76,
9.53,33.94,
9.55,34.13,
9.57,34.31,
9.59,34.49,
9.61,34.68,
9.63,34.86,
9.64,35.04,
9.66,35.23,
9.68,35.41,
9.70,35.59,
9.72,35.78,
9.73,35.96,
9.75,36.14,
9.77,36.33,
9.79,36.51,
9.81,36.69,
9.83,36.88,
9.85,37.06,
9.86,37.25,
9.88,37.43,
9.90,37.61,
9.92,37.80,
9.94,37.98,
9.95,38.16,
9.97,38.35,
9.99,38.53,
10.01,38.71,
10.03,38.90,
10.05,39.08,
10.07,39.26,
10.08,39.45,
10.10,39.63,
10.12,39.82,
10.14,40.00,
10.16,40.18,
10.18,40.37,
10.19,40.55,
10.21,40.73,
10.23,40.92,
10.25,41.10,
10.27,41.28,
10.28,41.47,
10.30,41.65,
10.32,41.83,
10.34,42.02,
10.36,42.20,
10.38,42.39,
10.40,42.57,
10.41,42.75,
10.43,42.94,
10.45,43.12,
10.47,43.30,
10.49,43.49,
10.50,43.67,
10.52,43.85,
10.54,44.04,
10.56,44.22,
10.58,44.40,
10.60,44.59,
10.62,44.77,
10.63,44.95,
10.65,45.14,
10.67,45.32,
10.69,45.50,
10.71,45.69,
10.73,45.87,
10.74,46.05,
10.76,46.24,
10.78,46.42,
10.80,46.61,
10.82,46.79,
10.83,46.97,
10.85,47.16,
10.87,47.34,
10.89,47.52,
10.91,47.71,
10.93,47.89,
10.95,48.07,
10.96,48.26,
10.98,48.44,
11.00,48.62,
11.02,48.81,
11.04,48.99,
11.05,49.17,
11.07,49.36,
11.09,49.54,
11.11,49.73,
11.13,49.91,
11.15,50.09,
11.17,50.28,
11.18,50.46,
11.20,50.64,
11.22,50.83,
11.24,51.01,
11.26,51.19,
11.28,51.38,
11.29,51.56,
11.31,51.75,
11.33,51.93,
11.35,52.11,
11.37,52.29,
11.38,52.48,
11.40,52.66,
11.42,52.85,
11.44,53.03,
11.46,53.21,
11.48,53.40,
11.50,53.58,
11.51,53.76,
11.53,53.95,
11.55,54.13,
11.57,54.31,
11.59,54.50,
11.60,54.68,
11.62,54.86,
11.64,55.05,
11.66,55.23,
11.68,55.42,
11.70,55.60,
11.72,55.78,
11.73,55.97,
11.75,56.15,
11.77,56.33,
11.79,56.52,
11.81,56.70,
11.83,56.89,
11.84,57.07,
11.86,57.25,
11.88,57.43,
11.90,57.62,
11.92,57.80,
11.93,57.99,
11.95,58.17,
11.97,58.35,
11.99,58.54,
12.01,58.72,
12.03,58.90,
12.05,59.09,
12.06,59.27,
12.08,59.45,
12.10,59.64,
12.12,59.82,
12.14,60.00,
12.15,60.19,
12.17,60.37,
12.19,60.56,
12.21,60.74,
12.23,60.92,
12.25,61.11,
12.27,61.29,
12.28,61.47,
12.30,61.66,
12.32,61.84,
12.34,62.02,
12.36,62.21,
12.38,62.39,
12.39,62.57,
12.41,62.76,
12.43,62.94,
12.45,63.12,
12.47,63.31,
12.48,63.49,
12.50,63.67,
12.52,63.86,
12.54,64.04,
12.56,64.22,
12.58,64.41,
12.60,64.59,
12.61,64.78,
12.63,64.96,
12.65,65.14,
12.67,65.33,
12.69,65.51,
12.70,65.69,
12.72,65.88,
12.74,66.06,
12.76,66.24,
12.78,66.43,
12.80,66.61,
12.82,66.80,
12.83,66.98,
12.85,67.16,
12.87,67.35,
12.89,67.53,
12.91,67.71,
12.93,67.90,
12.94,68.08,
12.96,68.26,
12.98,68.44,
13.00,68.63,
13.02,68.81,
13.03,69.00,
13.05,69.18,
13.07,69.36,
13.09,69.55,
13.11,69.73,
13.13,69.91,
13.15,70.10,
13.16,70.28,
13.18,70.46,
13.20,70.65,
13.22,70.83,
13.24,71.01,
13.25,71.20,
13.27,71.38,
13.29,71.56,
13.31,71.75,
13.33,71.93,
13.35,72.12,
13.37,72.30,
13.38,72.48,
13.40,72.67,
13.42,72.85,
13.44,73.03,
13.46,73.22,
13.48,73.40,
13.49,73.58,
13.51,73.77,
13.53,73.95,
13.55,74.13,
13.57,74.32,
13.58,74.50,
13.60,74.68,
13.62,74.87,
13.64,75.05,
13.66,75.24,
13.68,75.42,
13.70,75.60,
13.71,75.79,
13.73,75.97,
13.75,76.15,
13.77,76.34,
13.79,76.52,
13.80,76.70,
13.82,76.89,
13.84,77.07,
13.86,77.25,
13.88,77.44,
13.90,77.62,
13.92,77.81,
13.93,77.99,
13.95,78.17,
13.97,78.36,
13.99,78.54,
14.01,78.72,
14.03,78.91,
14.04,79.09,
14.06,79.27,
14.08,79.46,
14.10,79.64,
14.12,79.82,
14.13,80.01,
14.15,80.19,
14.17,80.37,
14.19,80.56,
14.21,80.74,
14.23,80.92,
14.25,81.11,
14.26,81.29,
14.28,81.47,
14.30,81.66,
14.32,81.84,
14.34,82.02,
14.35,82.21,
14.37,82.39,
14.39,82.58,
14.41,82.76,
14.43,82.94,
14.45,83.13,
14.47,83.31,
14.48,83.49,
14.50,83.68,
14.52,83.86,
14.54,84.05,
14.56,84.23,
14.58,84.41,
14.59,84.60,
14.61,84.78,
14.63,84.96,
14.65,85.15,
14.67,85.33,
14.68,85.51,
14.70,85.70,
14.72,85.88,
14.74,86.06,
14.76,86.25,
14.78,86.43,
14.80,86.61,
14.81,86.80,
14.83,86.98,
14.85,87.16,
14.87,87.35,
14.89,87.53,
14.90,87.71,
14.92,87.90,
14.94,88.08,
14.96,88.26,
14.98,88.45,
15.00,88.63,
15.02,88.82,
15.03,89.00,
15.05,89.18,
15.07,89.37,
15.09,89.55,
15.11,89.73,
15.13,89.92,
15.14,90.10,
15.16,90.28,
15.18,90.47,
15.20,90.65,
15.22,90.83,
15.23,91.02,
15.25,91.20,
15.27,91.38,
15.29,91.57,
15.31,91.75,
15.33,91.93,
15.35,92.12,
15.36,92.30,
15.38,92.48,
15.40,92.67,
15.42,92.85,
15.44,93.04,
15.45,93.22,
15.47,93.40,
15.49,93.59,
15.51,93.77,
15.53,93.95,
15.55,94.14,
15.57,94.32,
15.58,94.50,
15.60,94.69,
15.62,94.87,
15.64,95.05,
15.66,95.24,
15.68,95.42,
15.69,95.60,
15.71,95.79,
15.73,95.97,
15.75,96.15,
15.77,96.34,
15.78,96.52,
15.80,96.71,
15.82,96.89,
15.84,97.07,
15.86,97.26,
15.88,97.44,
15.90,97.62,
15.91,97.81,
15.93,97.99,
15.95,98.17,
15.97,98.36,
15.99,98.54,
16.00,98.72,
16.02,98.91,
16.04,99.09,
16.06,99.28,
16.08,99.46,
16.10,99.64,
16.12,99.82,
16.13,100.01,
16.15,100.19,
16.17,100.37,
16.19,100.56,
16.21,100.74,
16.23,100.93,
16.24,101.11,
16.26,101.29,
16.28,101.48,
16.30,101.66,
16.32,101.84,
16.33,102.02,
16.35,102.21,
16.37,102.39,
16.39,102.58,
16.41,102.76,
16.43,102.94,
16.45,103.13,
16.46,103.31,
16.48,103.49,
16.50,103.68,
16.52,103.86,
16.54,104.04,
16.55,104.23,
16.57,104.41,
16.59,104.60,
16.61,104.78,
16.63,104.96,
16.65,105.15,
16.67,105.33,
16.68,105.51,
16.70,105.70,
16.72,105.88,
16.74,106.06,
16.76,106.25,
16.78,106.43,
16.79,106.61,
16.81,106.80,
16.83,106.98,
16.85,107.16,
16.87,107.35,
16.88,107.53,
16.90,107.71,
16.92,107.90,
16.94,108.08,
16.96,108.26,
16.98,108.45,
17.00,108.63,
17.01,108.81,
17.03,109.00,
17.05,109.18,
17.07,109.37,
17.09,109.55,
17.11,109.73,
17.12,109.92,
17.14,110.10,
17.16,110.28,
17.18,110.47,
17.20,110.65,
17.22,110.83,
17.23,111.02,
17.25,111.20,
17.27,111.38,
17.29,111.57,
17.31,111.75,
17.33,111.93,
17.34,112.12,
17.36,112.30,
17.38,112.48,
17.40,112.67,
17.42,112.85,
17.43,113.03,
17.45,113.22,
17.47,113.40,
17.49,113.58,
17.51,113.77,
17.53,113.95,
17.54,114.14,
17.56,114.32,
17.58,114.50,
17.60,114.69,
17.62,114.87,
17.64,115.05,
17.66,115.24,
17.67,115.42,
17.69,115.60,
17.71,115.79,
17.73,115.97,
17.75,116.15,
17.77,116.34,
17.78,116.52,
17.80,116.70,
17.82,116.89,
17.84,117.07,
17.86,117.25,
17.88,117.44,
17.89,117.62,
17.91,117.81,
17.93,117.99,
17.95,118.17,
17.97,118.36,
17.98,118.54,
18.00,118.72,
18.02,118.91,
18.04,119.09,
18.06,119.27,
18.08,119.46,
18.09,119.64,
18.11,119.82,
18.13,120.01,
18.15,120.19,
18.17,120.37,
18.19,120.56,
18.21,120.74,
18.22,120.92,
18.24,121.11,
18.26,121.29,
18.28,121.48,
18.30,121.66,
18.32,121.84,
18.33,122.03,
18.35,122.21,
18.37,122.39,
18.39,122.58,
18.41,122.76,
18.43,122.94,
18.44,123.13,
18.46,123.31,
18.48,123.49,
18.50,123.68,
18.52,123.86,
18.53,124.04,
18.55,124.23,
18.57,124.41,
18.59,124.60,
18.61,124.78,
18.63,124.96,
18.64,125.14,
18.66,125.33,
18.68,125.51,
18.70,125.69,
18.72,125.88,
18.74,126.06,
18.76,126.25,
18.77,126.43,
18.79,126.61,
18.81,126.79,
18.83,126.98,
18.85,127.16,
18.87,127.35,
18.88,127.53,
18.90,127.71,
18.92,127.90,
18.94,128.08,
18.96,128.26,
18.98,128.45,
18.99,128.63,
19.01,128.82,
19.03,129.00,
19.05,129.18,
19.07,129.36,
19.08,129.55,
19.10,129.73,
19.12,129.91,
19.14,130.10,
19.16,130.28,
19.18,130.46,
19.19,130.65,
19.21,130.83,
19.23,131.02,
19.25,131.20,
19.27,131.38,
19.29,131.57,
19.31,131.75,
19.32,131.93,
19.34,132.12,
19.36,132.30,
19.38,132.48,
19.40,132.66,
19.42,132.85,
19.43,133.03,
19.45,133.22,
19.47,133.40,
19.49,133.58,
19.51,133.77,
19.53,133.95,
19.54,134.13,
19.56,134.32,
19.58,134.50,
19.60,134.68,
19.62,134.87,
19.63,135.05,
19.65,135.23,
19.67,135.42,
19.69,135.60,
19.71,135.79,
19.73,135.97,
19.74,136.15,
19.76,136.34,
19.78,136.52,
19.80,136.70,
19.82,136.89,
19.84,137.07,
19.86,137.25,
19.87,137.44,
19.89,137.62,
19.91,137.80,
19.93,137.99,
19.95,138.17,
19.97,138.35,
19.98,138.54,
20.00,138.72,
20.02,138.90,
20.04,139.09,
20.06,139.27,
20.08,139.45,
20.09,139.64,
20.11,139.82,
20.13,140.00,
20.15,140.19,
20.17,140.37,
20.18,140.56,
20.20,140.74,
20.22,140.92,
20.24,141.10,
20.26,141.29,
20.28,141.47,
20.29,141.65,
20.31,141.84,
20.33,142.02,
20.35,142.20,
20.37,142.39,
20.39,142.57,
20.41,142.76,
20.42,142.94,
20.44,143.12,
20.46,143.31,
20.48,143.49,
20.50,143.67,
20.52,143.86,
20.53,144.04,
20.55,144.22,
20.57,144.41,
20.59,144.59,
20.61,144.77,
20.63,144.96,
20.64,145.14,
20.66,145.33,
20.68,145.51,
20.70,145.69,
20.72,145.88,
20.73,146.06,
20.75,146.24,
20.77,146.43,
20.79,146.61,
20.81,146.79,
20.83,146.98,
20.84,147.16,
20.86,147.34,
20.88,147.53,
20.90,147.71,
20.92,147.89,
20.94,148.08,
20.96,148.26,
20.97,148.44,
20.99,148.63,
21.01,148.81,
21.03,149.00,
21.05,149.18,
21.07,149.36,
21.08,149.54,
21.10,149.73,
21.12,149.91,
21.14,150.09,
21.16,150.28,
21.18,150.46,
21.19,150.64,
21.21,150.83,
21.23,151.01,
21.25,151.20,
21.27,151.38,
21.28,151.56,
21.30,151.75,
21.32,151.93,
21.34,152.11,
21.36,152.29,
21.38,152.48,
21.39,152.66,
21.41,152.85,
21.43,153.03,
21.45,153.21,
21.47,153.40,
21.49,153.58,
21.51,153.76,
21.52,153.95,
21.54,154.13,
21.56,154.31,
21.58,154.50,
21.60,154.68,
21.62,154.86,
21.63,155.05,
21.65,155.23,
21.67,155.41,
21.69,155.60,
21.71,155.78,
21.73,155.97,
21.74,156.15,
21.76,156.33,
21.78,156.51,
21.80,156.70,
21.82,156.88,
21.83,157.07,
21.85,157.25,
21.87,157.43,
21.89,157.62,
21.91,157.80,
21.93,157.98,
21.94,158.17,
21.96,158.35,
21.98,158.53,
22.00,158.71,
22.02,158.90,
22.04,159.08,
22.06,159.27,
22.07,159.45,
22.09,159.63,
22.11,159.81,
22.13,160.00,
22.15,160.18,
22.17,160.37,
22.18,160.55,
22.20,160.73,
22.22,160.92,
22.24,161.10,
22.26,161.29,
22.28,161.47,
22.29,161.65,
22.31,161.83,
22.33,162.02,
22.35,162.20,
22.37,162.38,
22.38,162.57,
22.40,162.75,
22.42,162.93,
22.44,163.12,
22.46,163.30,
22.48,163.49,
22.49,163.67,
22.51,163.85,
22.53,164.04,
22.55,164.22,
22.57,164.40,
22.59,164.59,
22.61,164.77,
22.62,164.95,
22.64,165.14,
22.66,165.32,
22.68,165.50,
22.70,165.69,
22.72,165.87,
22.73,166.05,
22.75,166.24,
22.77,166.42,
22.79,166.60,
22.81,166.79,
22.83,166.97,
22.84,167.15,
22.86,167.34,
22.88,167.52,
22.90,167.70,
22.92,167.89,
22.93,168.07,
22.95,168.26,
22.97,168.44,
22.99,168.62,
23.01,168.81,
23.03,168.99,
23.04,169.17,
23.06,169.36,
23.08,169.54,
23.10,169.72,
23.12,169.91,
23.14,170.09,
23.16,170.27,
23.17,170.46,
23.19,170.64,
23.21,170.82,
23.23,171.01,
23.25,171.19,
23.27,171.37,
23.28,171.56,
23.30,171.74,
23.32,171.92,
23.34,172.11,
23.36,172.29,
23.38,172.47,
23.39,172.66,
23.41,172.84,
23.43,173.02,
23.45,173.21,
23.47,173.39,
23.48,173.57,
23.50,173.76,
23.52,173.94,
23.54,174.12,
23.56,174.31,
23.58,174.49,
23.59,174.67,
23.61,174.86,
23.63,175.04,
23.65,175.22,
23.67,175.41,
23.69,175.59,
23.71,175.78,
23.72,175.96,
23.74,176.14,
23.76,176.33,
23.78,176.51,
23.80,176.69,
23.82,176.88,
23.83,177.06,
23.85,177.24,
23.87,177.43,
23.89,177.61,
23.91,177.79,
23.93,177.98,
23.94,178.16,
23.96,178.34,
23.98,178.53,
24.00,178.71,
24.02,178.89,
24.03,179.08,
24.05,179.26,
24.07,179.44,
24.09,179.63,
24.11,179.81,
24.13,179.99,
24.14,180.18,
24.16,180.36,
24.18,180.54,
24.20,180.73,
24.22,180.91,
24.24,181.09,
24.26,181.28,
24.27,181.46,
24.29,181.64,
24.31,181.83,
24.33,182.01,
24.35,182.19,
24.37,182.38,
24.38,182.56,
24.40,182.74,
24.42,182.93,
24.44,183.11,
24.46,183.29,
24.48,183.48,
24.49,183.66,
24.51,183.84,
24.53,184.03,
24.55,184.21,
24.57,184.39,
24.58,184.58,
24.60,184.76,
24.62,184.95,
24.64,185.13,
24.66,185.31,
24.68,185.49,
24.69,185.68,
24.71,185.86,
24.73,186.05,
24.75,186.23,
24.77,186.41,
24.79,186.60,
24.81,186.78,
24.82,186.96,
24.84,187.15,
24.86,187.33,
24.88,187.51,
24.90,187.70,
24.92,187.88,
24.93,188.06,
24.95,188.25,
24.97,188.43,
24.99,188.61,
25.01,188.80,
25.03,188.98,
25.04,189.16,
25.06,189.35,
25.08,189.53,
25.10,189.71,
25.12,189.90,
25.13,190.08,
25.15,190.26,
25.17,190.45,
25.19,190.63,
25.21,190.82,
25.23,191.00,
25.24,191.18,
25.26,191.37,
25.28,191.55,
25.30,191.73,
25.32,191.92,
25.34,192.10,
25.36,192.28,
25.37,192.47,
25.39,192.65,
25.41,192.83,
25.43,193.02,
25.45,193.20,
25.47,193.38,
25.48,193.57,
25.50,193.75,
25.52,193.93,
25.54,194.11,
25.56,194.30,
25.58,194.48,
25.59,194.67,
25.61,194.85,
25.63,195.03,
25.65,195.22,
25.67,195.40,
25.68,195.58,
25.70,195.77,
25.72,195.95,
25.74,196.13,
25.76,196.32,
25.78,196.50,
25.79,196.68,
25.81,196.87,
25.83,197.05,
25.85,197.23,
25.87,197.42,
25.89,197.60,
25.91,197.79,
25.92,197.97,
25.94,198.15,
25.96,198.33,
25.98,198.52,
25.99,,

[step]
Ramp 10.00 °C/min to -60.00 °C
Time,Temperature,Heat Flow (Normalized)
min,°C,W/g
26.99,200.07,
27.01,200.07,
27.03,200.06,
27.05,200.05,
27.07,200.03,
27.08,199.99,
27.10,199.93,
27.12,199.84,
27.14,199.74,
27.16,199.61,
27.18,199.47,
27.19,199.32,
27.21,199.16,
27.23,199.00,
27.25,198.83,
27.27,198.66,
27.29,198.49,
27.31,198.32,
27.32,198.14,
27.34,197.96,
27.36,197.79,
27.38,197.61,
27.40,197.43,
27.42,197.25,
27.43,197.07,
27.45,196.89,
27.47,196.71,
27.49,196.53,
27.51,196.35,
27.53,196.17,
27.54,195.99,
27.56,195.81,
27.58,195.63,
27.60,195.45,
27.62,195.27,
27.63,195.09,
27.65,194.91,
27.67,194.72,
27.69,194.54,
27.71,194.36,
27.73,194.18,
27.74,194.00,
27.76,193.82,
27.78,193.64,
27.80,193.45,
27.82,193.27,
27.84,193.09,
27.86,192.91,
27.87,192.73,
27.89,192.54,
27.91,192.36,
27.93,192.18,
27.95,192.00,
27.97,191.81,
27.98,191.63,
28.00,191.45,
28.02,191.27,
28.04,191.09,
28.06,190.90,
28.08,190.72,
28.09,190.54,
28.11,190.36,
28.13,190.17,
28.15,189.99,
28.17,189.81,
28.18,189.62,
28.20,189.44,
28.22,189.26,
28.24,189.08,
28.26,188.89,
28.28,188.71,
28.29,188.53,
28.31,188.35,
28.33,188.16,
28.35,187.98,
28.37,187.80,
28.39,187.62,
28.41,187.43,
28.42,187.25,
28.44,187.07,
28.46,186.88,
28.48,186.70,
28.50,186.52,
28.52,186.34,
28.53,186.15,
28.55,185.97,
28.57,185.79,
28.59,185.60,
28.61,185.42,
28.63,185.24,
28.64,185.06,
28.66,184.87,
28.68,184.69,
28.70,184.51,
28.72,184.32,
28.73,184.14,
28.75,183.96,
28.77,183.77,
28.79,183.59,
28.81,183.41,
28.83,183.23,
28.84,183.04,
28.86,182.86,
28.88,182.68,
28.90,182.49,
28.92,182.31,
28.94,182.13,
28.96,181.94,
28.97,181.76,
28.99,181.58,
29.01,181.40,
29.03,181.21,
29.05,181.03,
29.07,180.85,
29.08,180.66,
29.10,180.48,
29.12,180.30,
29.14,180.11,
29.16,179.93,
29.18,179.75,
29.19,179.57,
29.21,179.38,
29.23,179.20,
29.25,179.02,
29.27,178.83,
29.28,178.65,
29.30,178.47,
29.32,178.28,
29.34,178.10,
29.36,177.92,
29.38,177.73,
29.39,177.55,
29.41,177.37,
29.43,177.18,
29.45,177.00,
29.47,176.82,
29.49,176.63,
29.51,176.45,
29.52,176.27,
29.54,176.09,
29.56,175.90,
29.58,175.72,
29.60,175.54,
29.62,175.35,
29.63,175.17,
29.65,174.99,
29.67,174.80,
29.69,174.62,
29.71,174.44,
29.73,174.25,
29.74,174.07,
29.76,173.89,
29.78,173.71,
29.80,173.52,
29.82,173.34,
29.83,173.16,
29.85,172.97,
29.87,172.79,
29.89,172.61,
29.91,172.42,
29.93,172.24,
29.94,172.06,
29.96,171.87,
29.98,171.69,
30.00,171.51,
30.02,171.32,
30.04,171.14,
30.06,170.96,
30.07,170.78,
30.09,170.59,
30.11,170.41,
30.13,170.23,
30.15,170.04,
30.17,169.86,
30.18,169.68,
30.20,169.50,
30.22,169.31,
30.24,169.13,
30.26,168.95,
30.28,168.76,
30.29,168.58,
30.31,168.40,
30.33,168.21,
30.35,168.03,
30.37,167.85,
30.38,167.66,
30.40,167.48,
30.42,167.30,
30.44,167.12,
30.46,166.93,
30.48,166.75,
30.49,166.56,
30.51,166.38,
30.53,166.20,
30.55,166.02,
30.57,165.83,
30.59,165.65,
30.61,165.47,
30.62,165.28,
30.64,165.10,
30.66,164.92,
30.68,164.73,
30.70,164.55,
30.72,164.37,
30.73,164.18,
30.75,164.00,
30.77,163.82,
30.79,163.63,
30.81,163.45,
30.83,163.27,
30.84,163.09,
30.86,162.90,
30.88,162.72,
30.90,162.54,
30.92,162.35,
30.93,162.17,
30.95,161.99,
30.97,161.80,
30.99,161.62,
31.01,161.44,
31.03,161.25,
31.04,161.07,
31.06,160.89,
31.08,160.70,
31.10,160.52,
31.12,160.34,
31.14,160.15,
31.16,159.97,
31.17,159.79,
31.19,159.61,
31.21,159.42,
31.23,159.24,
31.25,159.06,
31.27,158.87,
31.28,158.69,
31.30,158.51,
31.32,158.32,
31.34,158.14,
31.36,157.96,
31.38,157.77,
31.39,157.59,
31.41,157.41,
31.43,157.23,
31.45,157.04,
31.47,156.86,
31.48,156.68,
31.50,156.49,
31.52,156.31,
31.54,156.13,
31.56,155.94,
31.58,155.76,
31.59,155.58,
31.61,155.39,
31.63,155.21,
31.65,155.03,
31.67,154.85,
31.69,154.66,
31.71,154.48,
31.72,154.29,
31.74,154.11,
31.76,153.93,
31.78,153.74,
31.80,153.56,
31.82,153.38,
31.83,153.20,
31.85,153.01,
31.87,152.83,
31.89,152.65,
31.91,152.46,
31.93,152.28,
31.94,152.10,
31.96,151.91,
31.98,151.73,
32.00,151.55,
32.02,151.36,
32.03,151.18,
32.05,151.00,
32.07,150.82,
32.09,150.63,
32.11,150.45,
32.13,150.27,
32.14,150.08,
32.16,149.90,
32.18,149.72,
32.20,149.53,
32.22,149.35,
32.24,149.17,
32.26,148.98,
32.27,148.80,
32.29,148.62,
32.31,148.44,
32.33,148.25,
32.35,148.07,
32.37,147.89,
32.38,147.70,
32.40,147.52,
32.42,147.34,
32.44,147.15,
32.46,146.97,
32.48,146.79,
32.49,146.60,
32.51,146.42,
32.53,146.24,
32.55,146.05,
32.57,145.87,
32.58,145.69,
32.60,145.50,
32.62,145.32,
32.64,145.14,
32.66,144.95,
32.68,144.77,
32.69,144.59,
32.71,144.41,
32.73,144.22,
32.75,144.04,
32.77,143.86,
32.79,143.67,
32.81,143.49,
32.82,143.31,
32.84,143.12,
32.86,142.94,
32.88,142.76,
32.90,142.57,
32.92,142.39,
32.93,142.21,
32.95,142.02,
32.97,141.84,
32.99,141.66,
33.01,141.48,
33.03,141.29,
33.04,141.11,
33.06,140.93,
33.08,140.74,
33.10,140.56,
33.12,140.38,
33.13,140.19,
33.15,140.01,
33.17,139.83,
33.19,139.64,
33.21,139.46,
33.23,139.28,
33.24,139.09,
33.26,138.91,
33.28,138.73,
33.30,138.54,
33.32,138.36,
33.34,138.18,
33.36,138.00,
33.37,137.81,
33.39,137.63,
33.41,137.45,
33.43,137.26,
33.45,137.08,
33.47,136.90,
33.48,136.71,
33.50,136.53,
33.52,136.35,
33.54,136.16,
33.56,135.98,
33.58,135.80,
33.59,135.61,
33.61,135.43,
33.63,135.25,
33.65,135.07,
33.67,134.88,
33.68,134.70,
33.70,134.52,
33.72,134.33,
33.74,134.15,
33.76,133.97,
33.78,133.78,
33.79,133.60,
33.81,133.42,
33.83,133.24,
33.85,133.05,
33.87,132.87,
33.89,132.68,
33.91,132.50,
33.92,132.32,
33.94,132.14,
33.96,131.95,
33.98,131.77,
34.00,131.59,
34.02,131.40,
34.03,131.22,
34.05,131.04,
34.07,130.85,
34.09,130.67,
34.11,130.49,
34.13,130.30,
34.14,130.12,
34.16,129.94,
34.18,129.75,
34.20,129.57,
34.22,129.39,
34.24,129.21,
34.25,129.02,
34.27,128.84,
34.29,128.66,
34.31,128.47,
34.33,128.29,
34.34,128.11,
34.36,127.92,
34.38,127.74,
34.40,127.56,
34.42,127.37,
34.44,127.19,
34.46,127.01,
34.47,126.82,
34.49,126.64,
34.51,126.46,
34.53,126.27,
34.55,126.09,
34.56,125.91,
34.58,125.73,
34.60,125.54,
34.62,125.36,
34.64,125.18,
34.66,124.99,
34.68,124.81,
34.69,124.63,
34.71,124.44,
34.73,124.26,
34.75,124.08,
34.77,123.89,
34.79,123.71,
34.80,123.53,
34.82,123.35,
34.84,123.16,
34.86,122.98,
34.88,122.80,
34.89,122.61,
34.91,122.43,
34.93,122.25,
34.95,122.06,
34.97,121.88,
34.99,121.70,
35.01,121.51,
35.02,121.33,
35.04,121.15,
35.06,120.96,
35.08,120.78,
35.10,120.60,
35.11,120.41,
35.13,120.23,
35.15,120.05,
35.17,119.87,
35.19,119.68,
35.21,119.50,
35.23,119.32,
35.24,119.13,
35.26,118.95,
35.28,118.77,
35.30,118.58,
35.32,118.40,
35.34,118.22,
35.35,118.03,
35.37,117.85,
35.39,117.67,
35.41,117.48,
35.43,117.30,
35.44,117.12,
35.46,116.93,
35.48,116.75,
35.50,116.57,
35.52,116.39,
35.54,116.20,
35.56,116.02,
35.57,115.83,
35.59,115.65,
35.61,115.47,
35.63,115.29,
35.65,115.10,
35.66,114.92,
35.68,114.74,
35.70,114.55,
35.72,114.37,
35.74,114.19,
35.76,114.00,
35.78,113.82,
35.79,113.64,
35.81,113.45,
35.83,113.27,
35.85,113.09,
35.87,112.91,
35.89,112.72,
35.90,112.54,
35.92,112.36,
35.94,112.17,
35.96,111.99,
35.98,111.81,
35.99,111.62,
36.01,111.44,
36.03,111.26,
36.05,111.07,
36.07,110.89,
36.09,110.71,
36.11,110.52,
36.12,110.34,
36.14,110.16,
36.16,109.97,
36.18,109.79,
36.20,109.61,
36.21,109.43,
36.23,109.24,
36.25,109.06,
36.27,108.88,
36.29,108.69,
36.31,108.51,
36.33,108.33,
36.34,108.14,
36.36,107.96,
36.38,107.78,
36.40,107.59,
36.42,107.41,
36.44,107.23,
36.45,107.05,
36.47,106.86,
36.49,106.68,
36.51,106.50,
36.53,106.31,
36.54,106.13,
36.56,105.95,
36.58,105.76,
36.60,105.58,
36.62,105.40,
36.64,105.21,
36.66,105.03,
36.67,104.85,
36.69,104.66,
36.71,104.48,
36.73,104.30,
36.75,104.11,
36.76,103.93,
36.78,103.75,
36.80,103.56,
36.82,103.38,
36.84,103.20,
36.86,103.02,
36.88,102.83,
36.89,102.65,
36.91,102.47,
36.93,102.28,
36.95,102.10,
36.97,101.92,
36.99,101.73,
37.00,101.55,
37.02,101.37,
37.04,101.18,
37.06,101.00,
37.08,100.82,
37.09,100.63,
37.11,100.45,
37.13,100.27,
37.15,100.08,
37.17,99.90,
37.19,99.72,
37.21,99.54,
37.22,99.35,
37.24,99.17,
37.26,98.99,
37.28,98.80,
37.30,98.62,
37.31,98.44,
37.33,98.25,
37.35,98.07,
37.37,97.89,
37.39,97.71,
37.41,97.52,
37.43,97.34,
37.44,97.15,
37.46,96.97,
37.48,96.79,
37.50,96.61,
37.52,96.42,
37.54,96.24,
37.55,96.06,
37.57,95.87,
37.59,95.69,
37.61,95.51,
37.63,95.32,
37.64,95.14,
37.66,94.96,
37.68,94.77,
37.70,94.59,
37.72,94.41,
37.74,94.22,
37.76,94.04,
37.77,93.86,
37.79,93.67,
37.81,93.49,
37.83,93.31,
37.85,93.13,
37.86,92.94,
37.88,92.76,
37.90,92.58,
37.92,92.39,
37.94,92.21,
37.96,92.03,
37.98,91.84,
37.99,91.66,
38.01,91.48,
38.03,91.29,
38.05,91.11,
38.07,90.93,
38.09,90.74,
38.10,90.56,
38.12,90.38,
38.14,90.20,
38.16,90.01,
38.18,89.83,
38.19,89.65,
38.21,89.46,
38.23,89.28,
38.25,89.10,
38.27,88.91,
38.29,88.73,
38.31,88.55,
38.32,88.36,
38.34,88.18,
38.36,88.00,
38.38,87.81,
38.40,87.63,
38.41,87.45,
38.43,87.27,
38.45,87.08,
38.47,86.90,
38.49,86.72,
38.51,86.53,
38.53,86.35,
38.54,86.17,
38.56,85.98,
38.58,85.80,
38.60,85.62,
38.62,85.43,
38.64,85.25,
38.65,85.07,
38.67,84.88,
38.69,84.70,
38.71,84.52,
38.73,84.34,
38.74,84.15,
38.76,83.97,
38.78,83.79,
38.80,83.60,
38.82,83.42,
38.84,83.24,
38.86,83.05,
38.87,82.87,
38.89,82.69,
38.91,82.50,
38.93,82.32,
38.95,82.14,
38.96,81.95,
38.98,81.77,
39.00,81.59,
39.02,81.41,
39.04,81.22,
39.06,81.04,
39.08,80.86,
39.09,80.67,
39.11,80.49,
39.13,80.31,
39.15,80.12,
39.17,79.94,
39.19,79.76,
39.20,79.57,
39.22,79.39,
39.24,79.21,
39.26,79.02,
39.28,78.84,
39.29,78.66,
39.31,78.48,
39.33,78.29,
39.35,78.11,
39.37,77.92,
39.39,77.74,
39.41,77.56,
39.42,77.38,
39.44,77.19,
39.46,77.01,
39.48,76.83,
39.50,76.64,
39.51,76.46,
39.53,76.28,
39.55,76.09,
39.57,75.91,
39.59,75.73,
39.61,75.54,
39.63,75.36,
39.64,75.18,
39.66,74.99,
39.68,74.81,
39.70,74.63,
39.72,74.45,
39.74,74.26,
39.75,74.08,
39.77,73.90,
39.79,73.71,
39.81,73.53,
39.83,73.35,
39.84,73.16,
39.86,72.98,
39.88,72.80,
39.90,72.61,
39.92,72.43,
39.94,72.25,
39.96,72.07,
39.97,71.88,
39.99,71.70,
40.01,71.52,
40.03,71.33,
40.05,71.15,
40.06,70.97,
40.08,70.78,
40.10,70.60,
40.12,70.42,
40.14,70.23,
40.16,70.05,
40.18,69.87,
40.19,69.68,
40.21,69.50,
40.23,69.32,
40.25,69.13,
40.27,68.95,
40.29,68.77,
40.30,68.58,
40.32,68.40,
40.34,68.22,
40.36,68.04,
40.38,67.85,
40.39,67.67,
40.41,67.49,
40.43,67.30,
40.45,67.12,
40.47,66.94,
40.49,66.75,
40.51,66.57,
40.52,66.39,
40.54,66.20,
40.56,66.02,
40.58,65.84,
40.60,65.65,
40.61,65.47,
40.63,65.29,
40.65,65.11,
40.67,64.92,
40.69,64.74,
40.71,64.56,
40.73,64.37,
40.74,64.19,
40.76,64.01,
40.78,63.82,
40.80,63.64,
40.82,63.46,
40.84,63.27,
40.85,63.09,
40.87,62.91,
40.89,62.72,
40.91,62.54,
40.93,62.36,
40.94,62.18,
40.96,61.99,
40.98,61.81,
41.00,61.63,
41.02,61.44,
41.04,61.26,
41.06,61.08,
41.07,60.89,
41.09,60.71,
41.11,60.53,
41.13,60.34,
41.15,60.16,
41.16,59.98,
41.18,59.79,
41.20,59.61,
41.22,59.43,
41.24,59.24,
41.26,59.06,
41.28,58.88,
41.29,58.70,
41.31,58.51,
41.33,58.33,
41.35,58.14,
41.37,57.96,
41.39,57.78,
41.40,57.60,
41.42,57.41,
41.44,57.23,
41.46,57.05,
41.48,56.86,
41.49,56.68,
41.51,56.50,
41.53,56.31,
41.55,56.13,
41.57,55.95,
41.59,55.77,
41.61,55.58,
41.62,55.40,
41.64,55.22,
41.66,55.03,
41.68,54.85,
41.70,54.66,
41.71,54.48,
41.73,54.30,
41.75,54.12,
41.77,53.93,
41.79,53.75,
41.81,53.57,
41.83,53.38,
41.84,53.20,
41.86,53.02,
41.88,52.83,
41.90,52.65,
41.92,52.47,
41.94,52.28,
41.95,52.10,
41.97,51.92,
41.99,51.73,
42.01,51.55,
42.03,51.37,
42.04,51.19,
42.06,51.00,
42.08,50.82,
42.10,50.64,
42.12,50.45,
42.14,50.27,
42.16,50.09,
42.17,49.90,
42.19,49.72,
42.21,49.54,
42.23,49.36,
42.25,49.17,
42.26,48.99,
42.28,48.80,
42.30,48.62,
42.32,48.44,
42.34,48.26,
42.36,48.07,
42.38,47.89,
42.39,47.71,
42.41,47.52,
42.43,47.34,
42.45,47.16,
42.47,46.97,
42.49,46.79,
42.50,46.61,
42.52,46.42,
42.54,46.24,
42.56,46.06,
42.58,45.88,
42.59,45.69,
42.61,45.51,
42.63,45.33,
42.65,45.14,
42.67,44.96,
42.69,44.78,
42.71,44.59,
42.72,44.41,
42.74,44.23,
42.76,44.04,
42.78,43.86,
42.80,43.68,
42.81,43.49,
42.83,43.31,
42.85,43.13,
42.87,42.95,
42.89,42.76,
42.91,42.58,
42.93,42.40,
42.94,42.21,
42.96,42.03,
42.98,41.85,
43.00,41.66,
43.02,41.48,
43.04,41.30,
43.05,41.12,
43.07,40.93,
43.09,40.75,
43.11,40.56,
43.13,40.38,
43.14,40.20,
43.16,40.01,
43.18,39.83,
43.20,39.65,
43.22,39.47,
43.24,39.28,
43.26,39.10,
43.27,38.92,
43.29,38.73,
43.31,38.55,
43.33,38.37,
43.35,38.18,
43.36,38.00,
43.38,37.82,
43.40,37.63,
43.42,37.45,
43.44,37.27,
43.46,37.09,
43.48,36.90,
43.49,36.72,
43.51,36.54,
43.53,36.35,
43.55,36.17,
43.57,35.99,
43.59,35.80,
43.60,35.62,
43.62,35.44,
43.64,35.25,
43.66,35.07,
43.68,34.89,
43.69,34.71,
43.71,34.52,
43.73,34.34,
43.75,34.16,
43.77,33.97,
43.79,33.79,
43.81,33.61,
43.82,33.42,
43.84,33.24,
43.86,33.06,
43.88,32.87,
43.90,32.69,
43.91,32.51,
43.93,32.32,
43.95,32.14,
43.97,31.96,
43.99,31.77,
44.01,31.59,
44.03,31.41,
44.04,31.23,
44.06,31.04,
44.08,30.86,
44.10,30.68,
44.12,30.49,
44.14,30.31,
44.15,30.13,
44.17,29.94,
44.19,29.76,
44.21,29.58,
44.23,29.39,
44.24,29.21,
44.26,29.03,
44.28,28.84,
44.30,28.66,
44.32,28.48,
44.34,28.29,
44.36,28.11,
44.37,27.93,
44.39,27.75,
44.41,27.56,
44.43,27.38,
44.45,27.20,
44.46,27.01,
44.48,26.83,
44.50,26.65,
44.52,26.46,
44.54,26.28,
44.56,26.10,
44.58,25.91,
44.59,25.73,
44.61,25.55,
44.63,25.36,
44.65,25.18,
44.67,25.00,
44.69,24.81,
44.70,24.63,
44.72,24.45,
44.74,24.27,
44.76,24.08,
44.78,23.90,
44.79,23.71,
44.81,23.53,
44.83,23.35,
44.85,23.16,
44.87,22.98,
44.89,22.80,
44.91,22.61,
44.92,22.43,
44.94,22.25,
44.96,22.06,
44.98,21.88,
45.00,21.70,
45.01,21.52,
45.03,21.33,
45.05,21.15,
45.07,20.97,
45.09,20.78,
45.11,20.60,
45.13,20.42,
45.14,20.24,
45.16,20.05,
45.18,19.87,
45.20,19.69,
45.22,19.50,
45.24,19.32,
45.25,19.14,
45.27,18.96,
45.29,18.77,
45.31,18.59,
45.33,18.41,
45.34,18.22,
45.36,18.04,
45.38,17.86,
45.40,17.68,
45.42,17.49,
45.44,17.31,
45.46,17.13,
45.47,16.94,
45.49,16.76,
45.51,16.58,
45.53,16.39,
45.55,16.21,
45.56,16.03,
45.58,15.84,
45.60,15.66,
45.62,15.48,
45.64,15.30,
45.66,15.11,
45.68,14.93,
45.69,14.74,
45.71,14.56,
45.73,14.38,
45.75,14.20,
45.77,14.01,
45.79,13.83,
45.80,13.65,
45.82,13.46,
45.84,13.28,
45.86,13.10,
45.88,12.92,
45.89,12.73,
45.91,12.55,
45.93,12.37,
45.95,12.18,
45.97,12.00,
45.99,11.82,
46.01,11.63,
46.02,11.45,
46.04,11.27,
46.06,11.09,
46.08,10.90,
46.10,10.72,
46.11,10.54,
46.13,10.35,
46.15,10.17,
46.17,9.99,
46.19,9.80,
46.21,9.62,
46.23,9.44,
46.24,9.26,
46.26,9.07,
46.28,8.89,
46.30,8.71,
46.32,8.53,
46.34,8.34,
46.35,8.16,
46.37,7.98,
46.39,7.79,
46.41,7.61,
46.43,7.43,
46.44,7.24,
46.46,7.06,
46.48,6.88,
46.50,6.69,
46.52,6.51,
46.54,6.33,
46.56,6.14,
46.57,5.96,
46.59,5.78,
46.61,5.60,
46.63,5.41,
46.65,5.23,
46.66,5.05,
46.68,4.86,
46.70,4.68,
46.72,4.50,
46.74,4.31,
46.76,4.13,
46.78,3.95,
46.79,3.76,
46.81,3.58,
46.83,3.40,
46.85,3.21,
46.87,3.03,
46.89,2.85,
46.90,2.66,
46.92,2.48,
46.94,2.30,
46.96,2.11,
46.98,1.93,
46.99,1.75,
47.01,1.56,
47.03,1.38,
47.05,1.20,
47.07,1.01,
47.09,0.83,
47.11,0.65,
47.12,0.46,
47.14,0.28,
47.16,0.09,
47.18,-0.09,
47.20,-0.27,
47.21,-0.46,
47.23,-0.64,
47.25,-0.82,
47.27,-1.01,
47.29,-1.19,
47.31,-1.37,
47.33,-1.56,
47.34,-1.74,
47.36,-1.92,
47.38,-2.11,
47.40,-2.29,
47.42,-2.48,
47.44,-2.66,
47.45,-2.84,
47.47,-3.02,
47.49,-3.21,
47.51,-3.39,
47.53,-3.58,
47.54,-3.76,
47.56,-3.94,
[...]
116.15,20.07,,0.155
116.17,20.25,,0.155
116.19,20.43,,0.155
116.20,20.62,,0.155
116.22,20.80,,0.156
116.24,20.99,,0.156
116.26,21.17,,0.156
116.28,21.35,,0.156
116.30,21.54,,0.156
116.31,21.72,,0.156
116.33,21.90,,0.158
116.35,22.09,,0.158
116.37,22.27,,0.158
116.39,22.45,,0.159
116.41,22.64,,0.159
116.43,22.82,,0.158
116.44,23.00,,0.159
116.46,23.19,,0.159
116.48,23.37,,0.158
116.50,23.56,,0.158
116.52,23.74,,0.158
116.54,23.92,,0.158
116.55,24.11,,0.158
116.57,24.29,,0.158
116.59,24.47,,0.158
116.61,24.66,,0.157
116.63,24.84,,0.158
116.65,25.02,,0.158
116.66,25.21,,0.157
116.68,25.39,,0.158
116.70,25.57,,0.158
116.72,25.76,,0.158
116.74,25.94,,0.159
116.75,26.13,,0.159
116.77,26.31,,0.159
116.79,26.49,,0.159
116.81,26.68,,0.160
116.83,26.86,,0.160
116.85,27.04,,0.160
116.86,27.23,,0.160
116.88,27.41,,0.161
116.90,27.59,,0.161
116.92,27.78,,0.161
116.94,27.96,,0.161
116.96,28.14,,0.161
116.98,28.33,,0.161
116.99,28.51,,0.161
117.01,28.69,,0.162
117.03,28.88,,0.162
117.05,29.06,,0.162
117.07,29.25,,0.162
117.09,29.43,,0.163
117.10,29.61,,0.163
117.12,29.80,,0.162
117.14,29.98,,0.163
117.16,30.16,,0.163
117.18,30.35,,0.163
117.20,30.53,,0.163
117.21,30.71,,0.163
117.23,30.90,,0.163
117.25,31.08,,0.163
117.27,31.26,,0.163
117.29,31.45,,0.163
117.30,31.63,,0.163
117.32,31.82,,0.163
117.34,32.00,,0.164
117.36,32.18,,0.164
117.38,32.37,,0.164
117.40,32.55,,0.164
117.41,32.73,,0.164
117.43,32.92,,0.164
117.45,33.10,,0.164
117.47,33.28,,0.164
117.49,33.47,,0.164
117.51,33.65,,0.164
117.53,33.83,,0.164
117.54,34.02,,0.164
117.56,34.20,,0.165
117.58,34.39,,0.165
117.60,34.57,,0.165
117.62,34.75,,0.165
117.64,34.93,,0.165
117.65,35.12,,0.165
117.67,35.30,,0.166
117.69,35.49,,0.166
117.71,35.67,,0.166
117.73,35.85,,0.166
117.75,36.04,,0.166
117.76,36.22,,0.166
117.78,36.40,,0.166
117.80,36.59,,0.166
117.82,36.77,,0.167
117.84,36.95,,0.167
117.85,37.14,,0.167
117.87,37.32,,0.167
117.89,37.50,,0.167
117.91,37.69,,0.167
117.93,37.87,,0.168
117.95,38.06,,0.168
117.96,38.24,,0.168
117.98,38.42,,0.168
118.00,38.61,,0.168
118.02,38.79,,0.168
118.04,38.97,,0.169
118.06,39.16,,0.168
118.08,39.34,,0.169
118.09,39.52,,0.169
118.11,39.71,,0.169
118.13,39.89,,0.169
118.15,40.07,,0.169
118.17,40.26,,0.169
118.19,40.44,,0.169
118.20,40.62,,0.170
118.22,40.81,,0.170
118.24,40.99,,0.170
118.26,41.18,,0.170
118.28,41.36,,0.171
118.30,41.54,,0.170
118.31,41.73,,0.171
118.33,41.91,,0.171
118.35,42.09,,0.171
118.37,42.28,,0.171
118.39,42.46,,0.172
118.40,42.64,,0.172
118.42,42.83,,0.172
118.44,43.01,,0.172
118.46,43.19,,0.172
118.48,43.38,,0.172
118.50,43.56,,0.172
118.51,43.74,,0.172
118.53,43.93,,0.173
118.55,44.11,,0.173
118.57,44.30,,0.173
118.59,44.48,,0.173
118.61,44.66,,0.173
118.63,44.85,,0.174
118.64,45.03,,0.174
118.66,45.21,,0.174
118.68,45.40,,0.175
118.70,45.58,,0.175
118.72,45.76,,0.174
118.74,45.95,,0.175
118.75,46.13,,0.175
118.77,46.31,,0.175
118.79,46.50,,0.175
118.81,46.68,,0.175
118.83,46.86,,0.176
118.85,47.05,,0.176
118.86,47.23,,0.176
118.88,47.42,,0.176
118.90,47.60,,0.177
118.92,47.78,,0.177
118.94,47.97,,0.177
118.95,48.15,,0.177
118.97,48.33,,0.177
118.99,48.52,,0.177
119.01,48.70,,0.178
119.03,48.88,,0.178
119.05,49.07,,0.178
119.06,49.25,,0.178
119.08,49.44,,0.178
119.10,49.62,,0.179
119.12,49.80,,0.179
119.14,49.99,,0.179
119.16,50.17,,0.179
119.18,50.35,,0.179
119.19,50.54,,0.179
119.21,50.72,,0.179
119.23,50.90,,0.180
119.25,51.09,,0.180
119.27,51.27,,0.180
119.29,51.45,,0.180
119.30,51.64,,0.180
119.32,51.82,,0.181
119.34,52.00,,0.181
119.36,52.19,,0.181
119.38,52.37,,0.181
119.40,52.56,,0.182
119.41,52.74,,0.182
119.43,52.92,,0.182
119.45,53.11,,0.182
119.47,53.29,,0.182
119.49,53.47,,0.183
119.50,53.66,,0.183
119.52,53.84,,0.183
119.54,54.02,,0.183
119.56,54.21,,0.183
119.58,54.39,,0.183
119.60,54.57,,0.184
119.61,54.76,,0.184
119.63,54.94,,0.184
119.65,55.12,,0.184
119.67,55.31,,0.185
119.69,55.49,,0.185
119.71,55.67,,0.185
119.73,55.86,,0.186
119.74,56.04,,0.186
119.76,56.23,,0.186
119.78,56.41,,0.186
119.80,56.59,,0.186
119.82,56.78,,0.186
119.84,56.96,,0.186
119.85,57.14,,0.186
119.87,57.33,,0.187
119.89,57.51,,0.187
119.91,57.69,,0.187
119.93,57.88,,0.187
119.95,58.06,,0.187
119.96,58.24,,0.188
119.98,58.43,,0.188
120.00,58.61,,0.188
120.02,58.79,,0.188
120.04,58.98,,0.188
120.05,59.16,,0.189
120.07,59.35,,0.189
120.09,59.53,,0.189
120.11,59.71,,0.189
120.13,59.90,,0.189
120.15,60.08,,0.190
120.16,60.26,,0.190
120.18,60.45,,0.190
120.20,60.63,,0.190
120.22,60.81,,0.190
120.24,61.00,,0.191
120.26,61.18,,0.191
120.28,61.37,,0.191
120.29,61.55,,0.191
120.31,61.73,,0.192
120.33,61.91,,0.192
120.35,62.10,,0.192
120.37,62.28,,0.192
120.39,62.46,,0.193
120.40,62.65,,0.193
120.42,62.83,,0.193
120.44,63.02,,0.193
120.46,63.20,,0.193
120.48,63.38,,0.193
120.50,63.57,,0.194
120.51,63.75,,0.194
120.53,63.93,,0.194
120.55,64.12,,0.194
120.57,64.30,,0.195
120.59,64.49,,0.195
120.60,64.67,,0.195
120.62,64.85,,0.195
120.64,65.04,,0.195
120.66,65.22,,0.196
120.68,65.40,,0.196
120.70,65.59,,0.196
120.71,65.77,,0.196
120.73,65.96,,0.196
120.75,66.14,,0.196
120.77,66.32,,0.197
120.79,66.51,,0.197
120.81,66.69,,0.197
120.83,66.87,,0.197
120.84,67.06,,0.197
120.86,67.24,,0.198
120.88,67.42,,0.198
120.90,67.61,,0.198
120.92,67.79,,0.198
120.94,67.97,,0.199
120.95,68.16,,0.199
120.97,68.34,,0.199
120.99,68.52,,0.199
121.01,68.71,,0.199
121.03,68.89,,0.200
121.05,69.07,,0.200
121.06,69.26,,0.200
121.08,69.44,,0.200
121.10,69.62,,0.200
121.12,69.81,,0.200
121.14,69.99,,0.201
121.15,70.17,,0.201
121.17,70.36,,0.201
121.19,70.54,,0.201
121.21,70.72,,0.202
121.23,70.91,,0.202
121.25,71.09,,0.202
121.26,71.27,,0.202
121.28,71.46,,0.202
121.30,71.64,,0.203
121.32,71.82,,0.203
121.34,72.01,,0.203
121.36,72.19,,0.203
121.38,72.38,,0.203
121.39,72.56,,0.204
121.41,72.74,,0.204
121.43,72.93,,0.204
121.45,73.11,,0.204
121.47,73.29,,0.204
121.49,73.48,,0.205
121.50,73.66,,0.205
121.52,73.84,,0.205
121.54,74.03,,0.205
121.56,74.21,,0.205
121.58,74.39,,0.205
121.60,74.58,,0.206
121.61,74.76,,0.206
121.63,74.94,,0.206
121.65,75.13,,0.206
121.67,75.31,,0.207
121.69,75.49,,0.207
121.70,75.68,,0.207
121.72,75.86,,0.207
121.74,76.05,,0.208
121.76,76.23,,0.208
121.78,76.41,,0.208
121.80,76.60,,0.208
121.81,76.78,,0.209
121.83,76.96,,0.209
121.85,77.15,,0.209
121.87,77.33,,0.209
121.89,77.51,,0.210
121.91,77.70,,0.210
121.93,77.88,,0.210
121.94,78.06,,0.211
121.96,78.25,,0.211
121.98,78.43,,0.211
122.00,78.61,,0.211
122.02,78.80,,0.211
122.04,78.98,,0.212
122.05,79.16,,0.212
122.07,79.35,,0.212
122.09,79.53,,0.212
122.11,79.71,,0.212
122.13,79.90,,0.212
122.15,80.08,,0.212
122.16,80.27,,0.213
122.18,80.45,,0.213
122.20,80.63,,0.213
122.22,80.82,,0.213
122.24,81.00,,0.214
122.25,81.18,,0.214
122.27,81.37,,0.214
122.29,81.55,,0.214
122.31,81.73,,0.214
122.33,81.92,,0.214
122.35,82.10,,0.214
122.36,82.28,,0.214
122.38,82.47,,0.215
122.40,82.65,,0.215
122.42,82.83,,0.215
122.44,83.02,,0.215
122.46,83.20,,0.215
122.48,83.39,,0.215
122.49,83.57,,0.215
122.51,83.75,,0.216
122.53,83.94,,0.216
122.55,84.12,,0.215
122.57,84.30,,0.216
122.59,84.49,,0.216
122.60,84.67,,0.216
122.62,84.85,,0.216
122.64,85.04,,0.216
122.66,85.22,,0.216
122.68,85.41,,0.216
122.70,85.59,,0.216
122.71,85.77,,0.216
122.73,85.95,,0.216
122.75,86.14,,0.216
122.77,86.32,,0.216
122.79,86.50,,0.217
122.80,86.69,,0.217
122.82,86.87,,0.217
122.84,87.06,,0.218
122.86,87.24,,0.218
122.88,87.42,,0.218
122.90,87.61,,0.218
122.91,87.79,,0.218
122.93,87.97,,0.218
122.95,88.16,,0.218
122.97,88.34,,0.218
122.99,88.52,,0.219
123.01,88.71,,0.219
123.03,88.89,,0.220
123.04,89.07,,0.220
123.06,89.26,,0.220
123.08,89.44,,0.220
123.10,89.62,,0.221
123.12,89.81,,0.221
123.14,89.99,,0.222
123.15,90.17,,0.222
123.17,90.36,,0.222
123.19,90.54,,0.222
123.21,90.73,,0.223
123.23,90.91,,0.223
123.25,91.09,,0.224
123.26,91.28,,0.224
123.28,91.46,,0.225
123.30,91.64,,0.225
123.32,91.83,,0.225
123.34,92.01,,0.225
123.35,92.19,,0.226
123.37,92.38,,0.226
123.39,92.56,,0.226
123.41,92.74,,0.227
123.43,92.93,,0.227
123.45,93.11,,0.228
123.46,93.30,,0.228
123.48,93.48,,0.228
123.50,93.66,,0.228
123.52,93.84,,0.229
123.54,94.03,,0.229
123.56,94.21,,0.229
123.58,94.40,,0.230
123.59,94.58,,0.230
123.61,94.76,,0.231
123.63,94.95,,0.231
123.65,95.13,,0.231
123.67,95.31,,0.231
123.69,95.50,,0.232
123.70,95.68,,0.232
123.72,95.86,,0.232
123.74,96.05,,0.233
123.76,96.23,,0.233
123.78,96.41,,0.233
123.80,96.60,,0.233
123.81,96.78,,0.234
123.83,96.96,,0.234
123.85,97.15,,0.234
123.87,97.33,,0.235
123.89,97.51,,0.235
123.90,97.70,,0.235
123.92,97.88,,0.235
123.94,98.06,,0.236
123.96,98.25,,0.236
123.98,98.43,,0.236
124.00,98.62,,0.236
124.01,98.80,,0.237
124.03,98.98,,0.237
124.05,99.17,,0.237
124.07,99.35,,0.237
124.09,99.53,,0.238
124.11,99.72,,0.238
124.13,99.90,,0.238
124.14,100.08,,0.238
124.16,100.27,,0.239
124.18,100.45,,0.239
124.20,100.64,,0.240
124.22,100.82,,0.240
124.24,101.00,,0.240
124.25,101.18,,0.240
124.27,101.37,,0.240
124.29,101.55,,0.241
124.31,101.74,,0.241
124.33,101.92,,0.241
124.35,102.10,,0.242
124.36,102.29,,0.242
124.38,102.47,,0.242
124.40,102.65,,0.242
124.42,102.84,,0.243
124.44,103.02,,0.243
124.45,103.20,,0.243
124.47,103.39,,0.243
124.49,103.57,,0.244
124.51,103.75,,0.244
124.53,103.94,,0.244
124.55,104.12,,0.245
124.56,104.31,,0.245
124.58,104.49,,0.245
124.60,104.67,,0.245
124.62,104.86,,0.246
124.64,105.04,,0.246
124.66,105.22,,0.246
124.68,105.41,,0.247
124.69,105.59,,0.247
124.71,105.77,,0.247
124.73,105.96,,0.248
124.75,106.14,,0.248
124.77,106.32,,0.248
124.79,106.51,,0.249
124.80,106.69,,0.249
124.82,106.87,,0.249
124.84,107.06,,0.249
124.86,107.24,,0.249
124.88,107.42,,0.250
124.90,107.61,,0.250
124.91,107.79,,0.250
124.93,107.97,,0.251
124.95,108.16,,0.251
124.97,108.34,,0.251
124.99,108.52,,0.251
125.00,108.71,,0.252
125.02,108.89,,0.252
125.04,109.07,,0.252
125.06,109.26,,0.253
125.08,109.44,,0.253
125.10,109.63,,0.253
125.11,109.81,,0.254
125.13,109.99,,0.254
125.15,110.17,,0.254
125.17,110.36,,0.254
125.19,110.54,,0.254
125.21,110.73,,0.255
125.23,110.91,,0.255
125.24,111.09,,0.255
125.26,111.28,,0.255
125.28,111.46,,0.255
125.30,111.64,,0.256
125.32,111.83,,0.256
125.34,112.01,,0.256
125.35,112.19,,0.256
125.37,112.38,,0.256
125.39,112.56,,0.256
125.41,112.74,,0.256
125.43,112.93,,0.257
125.45,113.11,,0.257
125.46,113.30,,0.257
125.48,113.48,,0.257
125.50,113.66,,0.258
125.52,113.85,,0.258
125.54,114.03,,0.258
125.55,114.21,,0.259
125.57,114.39,,0.259
125.59,114.58,,0.259
125.61,114.76,,0.259
125.63,114.95,,0.260
125.65,115.13,,0.260
125.66,115.31,,0.260
125.68,115.50,,0.260
125.70,115.68,,0.261
125.72,115.86,,0.261
125.74,116.05,,0.261
125.76,116.23,,0.262
125.78,116.41,,0.262
125.79,116.60,,0.262
125.81,116.78,,0.263
125.83,116.96,,0.263
125.85,117.15,,0.263
125.87,117.33,,0.264
125.89,117.52,,0.264
125.90,117.70,,0.264
125.92,117.88,,0.264
125.94,118.07,,0.265
125.96,118.25,,0.265
125.98,118.43,,0.265
126.00,118.61,,0.265
126.01,118.80,,0.266
126.03,118.98,,0.266
126.05,119.17,,0.266
126.07,119.35,,0.267
126.09,119.53,,0.267
126.10,119.72,,0.267
126.12,119.90,,0.267
126.14,120.08,,0.268
126.16,120.27,,0.268
126.18,120.45,,0.268
126.20,120.63,,0.268
126.21,120.82,,0.268
126.23,121.00,,0.269
126.25,121.18,,0.269
126.27,121.37,,0.269
126.29,121.55,,0.270
126.31,121.73,,0.270
126.33,121.92,,0.270
126.34,122.10,,0.271
126.36,122.29,,0.271
126.38,122.47,,0.271
126.40,122.65,,0.271
126.42,122.83,,0.272
126.44,123.02,,0.272
126.45,123.20,,0.272
126.47,123.39,,0.272
126.49,123.57,,0.273
126.51,123.75,,0.273
126.53,123.94,,0.274
126.55,124.12,,0.274
126.56,124.30,,0.274
126.58,124.49,,0.274
126.60,124.67,,0.274
126.62,124.85,,0.275
126.64,125.04,,0.275
126.65,125.22,,0.276
126.67,125.40,,0.276
126.69,125.59,,0.276
126.71,125.77,,0.277
126.73,125.95,,0.277
126.75,126.14,,0.277
126.76,126.32,,0.277
126.78,126.51,,0.277
126.80,126.69,,0.278
126.82,126.87,,0.278
126.84,127.06,,0.278
126.86,127.24,,0.278
126.88,127.42,,0.279
126.89,127.61,,0.279
126.91,127.79,,0.279
126.93,127.97,,0.279
126.95,128.16,,0.280
126.97,128.34,,0.280
126.99,128.52,,0.280
127.00,128.71,,0.281
127.02,128.89,,0.281
127.04,129.07,,0.281
127.06,129.26,,0.281
127.08,129.44,,0.281
127.10,129.62,,0.281
127.11,129.81,,0.282
127.13,129.99,,0.282
127.15,130.17,,0.282
127.17,130.36,,0.283
127.19,130.54,,0.283
127.20,130.72,,0.284
127.22,130.91,,0.284
127.24,131.09,,0.284
127.26,131.28,,0.284
127.28,131.46,,0.284
127.30,131.64,,0.284
127.31,131.83,,0.285
127.33,132.01,,0.284
127.35,132.19,,0.285
127.37,132.38,,0.285
127.39,132.56,,0.285
127.41,132.74,,0.286
127.43,132.93,,0.286
127.44,133.11,,0.286
127.46,133.29,,0.287
127.48,133.48,,0.287
127.50,133.66,,0.287
127.52,133.84,,0.288
127.54,134.03,,0.288
127.55,134.21,,0.288
127.57,134.39,,0.289
127.59,134.58,,0.289
127.61,134.76,,0.289
127.63,134.94,,0.289
127.65,135.13,,0.290
127.66,135.31,,0.290
127.68,135.49,,0.290
127.70,135.68,,0.290
127.72,135.86,,0.291
127.74,136.04,,0.291
127.75,136.23,,0.292
127.77,136.41,,0.292
127.79,136.59,,0.292
127.81,136.78,,0.292
127.83,136.96,,0.292
127.85,137.14,,0.292
127.86,137.33,,0.293
127.88,137.51,,0.293
127.90,137.69,,0.293
127.92,137.88,,0.294
127.94,138.06,,0.294
127.96,138.25,,0.294
127.98,138.43,,0.294
127.99,138.61,,0.295
128.01,138.80,,0.295
128.03,138.98,,0.295
128.05,139.16,,0.295
128.07,139.35,,0.296
128.09,139.53,,0.296
128.10,139.71,,0.297
128.12,139.90,,0.297
128.14,140.08,,0.297
128.16,140.26,,0.298
128.18,140.45,,0.298
128.20,140.63,,0.299
128.21,140.81,,0.299
128.23,141.00,,0.299
128.25,141.18,,0.299
128.27,141.36,,0.299
128.29,141.55,,0.299
128.30,141.73,,0.300
128.32,141.91,,0.300
128.34,142.10,,0.300
128.36,142.28,,0.300
128.38,142.46,,0.301
128.40,142.65,,0.301
128.41,142.83,,0.302
128.43,143.02,,0.302
128.45,143.20,,0.302
128.47,143.38,,0.303
128.49,143.57,,0.302
128.51,143.75,,0.303
128.53,143.93,,0.303
128.54,144.12,,0.303
128.56,144.30,,0.303
128.58,144.48,,0.304
128.60,144.67,,0.304
128.62,144.85,,0.304
128.64,145.03,,0.305
128.65,145.22,,0.305
128.67,145.40,,0.306
128.69,145.59,,0.306
128.71,145.77,,0.306
128.73,145.95,,0.306
128.75,146.14,,0.307
128.76,146.32,,0.307
128.78,146.50,,0.307
128.80,146.69,,0.307
128.82,146.87,,0.307
128.84,147.05,,0.308
128.85,147.24,,0.308
128.87,147.42,,0.308
128.89,147.60,,0.309
128.91,147.79,,0.309
128.93,147.97,,0.309
128.95,148.15,,0.309
128.96,148.33,,0.309
128.98,148.52,,0.309
129.00,148.70,,0.309
129.02,148.88,,0.309
129.04,149.07,,0.310
129.06,149.25,,0.310
129.08,149.43,,0.311
129.09,149.62,,0.311
129.11,149.80,,0.311
129.13,149.99,,0.311
129.15,150.17,,0.312
129.17,150.35,,0.312
129.19,150.54,,0.312
129.20,150.72,,0.312
129.22,150.90,,0.313
129.24,151.09,,0.313
129.26,151.27,,0.313
129.28,151.45,,0.313
129.30,151.64,,0.313
129.31,151.82,,0.314
129.33,152.01,,0.314
129.35,152.19,,0.314
129.37,152.37,,0.315
129.39,152.56,,0.315
129.40,152.74,,0.315
129.42,152.92,,0.315
129.44,153.11,,0.315
129.46,153.29,,0.315
129.48,153.47,,0.316
129.50,153.66,,0.316
129.51,153.84,,0.316
129.53,154.02,,0.316
129.55,154.21,,0.317
129.57,154.39,,0.317
129.59,154.57,,0.317
129.61,154.76,,0.318
129.63,154.94,,0.318
129.64,155.12,,0.318
129.66,155.31,,0.319
129.68,155.49,,0.319
129.70,155.68,,0.319
129.72,155.86,,0.319
129.74,156.04,,0.319
129.75,156.23,,0.319
129.77,156.41,,0.319
129.79,156.59,,0.319
129.81,156.77,,0.320
129.83,156.96,,0.320
129.85,157.14,,0.321
129.86,157.32,,0.321
129.88,157.51,,0.321
129.90,157.69,,0.321
129.92,157.87,,0.322
129.94,158.06,,0.322
129.95,158.24,,0.322
129.97,158.42,,0.323
129.99,158.61,,0.323
130.01,158.79,,0.323
130.03,158.97,,0.324
130.05,159.16,,0.324
130.06,159.34,,0.324
130.08,159.52,,0.325
130.10,159.71,,0.325
130.12,159.89,,0.325
130.14,160.07,,0.326
130.16,160.26,,0.326
130.18,160.44,,0.326
130.19,160.62,,0.327
130.21,160.81,,0.327
130.23,160.99,,0.328
130.25,161.18,,0.328
130.27,161.36,,0.328
130.29,161.54,,0.329
130.30,161.73,,0.329
130.32,161.91,,0.329
130.34,162.09,,0.330
130.36,162.28,,0.330
130.38,162.46,,0.330
130.40,162.64,,0.330
130.41,162.83,,0.331
130.43,163.01,,0.331
130.45,163.20,,0.331
130.47,163.38,,0.331
130.49,163.56,,0.332
130.50,163.74,,0.332
130.52,163.93,,0.332
130.54,164.11,,0.332
130.56,164.29,,0.332
130.58,164.48,,0.332
130.60,164.66,,0.333
130.61,164.84,,0.333
130.63,165.03,,0.334
130.65,165.21,,0.334
130.67,165.39,,0.334
130.69,165.58,,0.335
130.71,165.76,,0.335
130.73,165.94,,0.336
130.74,166.13,,0.336
130.76,166.31,,0.337
130.78,166.49,,0.337
130.80,166.68,,0.337
130.82,166.86,,0.337
130.84,167.05,,0.338
130.85,167.23,,0.338
130.87,167.41,,0.338
130.89,167.60,,0.339
130.91,167.78,,0.339
130.93,167.96,,0.339
130.95,168.15,,0.339
130.96,168.33,,0.339
130.98,168.52,,0.339
131.00,168.70,,0.339
131.02,168.88,,0.339
131.04,169.06,,0.339
131.05,169.25,,0.339
131.07,169.43,,0.340
131.09,169.61,,0.340
131.11,169.80,,0.340
131.13,169.98,,0.340
131.15,170.16,,0.341
131.16,170.35,,0.341
131.18,170.53,,0.341
131.20,170.71,,0.342
131.22,170.90,,0.342
131.24,171.08,,0.342
131.26,171.27,,0.342
131.28,171.45,,0.343
131.29,171.63,,0.343
131.31,171.82,,0.343
131.33,172.00,,0.343
131.35,172.18,,0.344
131.37,172.37,,0.344
131.39,172.55,,0.344
131.40,172.73,,0.345
131.42,172.92,,0.345
131.44,173.10,,0.345
131.46,173.28,,0.346
131.48,173.47,,0.346
131.50,173.65,,0.346
131.51,173.83,,0.346
131.53,174.02,,0.347
131.55,174.20,,0.347
131.57,174.38,,0.347
131.59,174.57,,0.348
131.60,174.75,,0.348
131.62,174.93,,0.348
131.64,175.12,,0.349
131.66,175.30,,0.349
131.68,175.48,,0.349
131.70,175.67,,0.349
131.71,175.85,,0.349
131.73,176.03,,0.350
131.75,176.22,,0.350
131.77,176.40,,0.351
131.79,176.58,,0.351
131.81,176.77,,0.352
131.83,176.95,,0.352
131.84,177.14,,0.352
131.86,177.32,,0.352
131.88,177.50,,0.353
131.90,177.69,,0.353
131.92,177.87,,0.353
131.94,178.05,,0.353
131.95,178.24,,0.353
131.97,178.42,,0.354
131.99,178.60,,0.354
132.01,178.79,,0.354
132.03,178.97,,0.354
132.05,179.15,,0.354
132.06,179.34,,0.355
132.08,179.52,,0.355
132.10,179.70,,0.355
132.12,179.89,,0.356
132.14,180.07,,0.356
132.15,180.25,,0.357
132.17,180.44,,0.357
132.19,180.62,,0.358
132.21,180.80,,0.358
132.23,180.99,,0.359
132.25,181.17,,0.359
132.26,181.35,,0.360
132.28,181.54,,0.360
132.30,181.72,,0.361
132.32,181.90,,0.361
132.34,182.09,,0.361
132.36,182.27,,0.361
132.38,182.45,,0.362
132.39,182.64,,0.362
132.41,182.82,,0.362
132.43,183.01,,0.362
132.45,183.19,,0.363
132.47,183.37,,0.363
132.49,183.56,,0.363
132.50,183.74,,0.364
132.52,183.92,,0.364
132.54,184.11,,0.364
132.56,184.29,,0.365
132.58,184.47,,0.364
132.60,184.65,,0.365
132.61,184.84,,0.365
132.63,185.02,,0.366
132.65,185.20,,0.366
132.67,185.39,,0.367
132.69,185.57,,0.367
132.70,185.75,,0.368
132.72,185.94,,0.368
132.74,186.12,,0.368
132.76,186.31,,0.368
132.78,186.49,,0.368
132.80,186.67,,0.369
132.81,186.86,,0.369
132.83,187.04,,0.368
132.85,187.22,,0.369
132.87,187.41,,0.369
132.89,187.59,,0.369
132.91,187.77,,0.369
132.93,187.96,,0.370
132.94,188.14,,0.370
132.96,188.32,,0.370
132.98,188.51,,0.371
133.00,188.69,,0.371
133.02,188.88,,0.371
133.04,189.06,,0.371
133.05,189.24,,0.372
133.07,189.42,,0.372
133.09,189.61,,0.373
133.11,189.79,,0.373
133.13,189.97,,0.373
133.15,190.16,,0.373
133.16,190.34,,0.374
133.18,190.52,,0.374
133.20,190.71,,0.374
133.22,190.89,,0.374
133.24,191.08,,0.375
133.25,191.26,,0.375
133.27,191.44,,0.375
133.29,191.63,,0.375
133.31,191.81,,0.375
133.33,191.99,,0.376
133.35,192.18,,0.376
133.36,192.36,,0.376
133.38,192.54,,0.377
133.40,192.73,,0.377
133.42,192.91,,0.377
133.44,193.09,,0.377
133.46,193.28,,0.378
133.48,193.46,,0.378
133.49,193.64,,0.378
133.51,193.83,,0.378
133.53,194.01,,0.378
133.55,194.19,,0.379
133.57,194.38,,0.379
133.59,194.56,,0.379
133.60,194.74,,0.379
133.62,194.93,,0.380
133.64,195.11,,0.380
133.66,195.29,,0.381
133.68,195.48,,0.381
133.70,195.66,,0.382
133.71,195.84,,0.382
133.73,196.03,,0.382
133.75,196.21,,0.383
133.77,196.40,,0.383
133.79,196.58,,0.383
133.80,196.76,,0.384
133.82,196.95,,0.384
133.84,197.13,,0.384
133.86,197.31,,0.384
133.88,197.49,,0.385
133.90,197.68,,0.385
133.91,197.86,,0.385
133.93,198.05,,
133.95,198.23,,
133.97,198.41,,
133.99,,,