File: DSC/2025_04_12_CBD_Pro_MechanoChem_15min_2.csv
Filename,2025_04_12_CBD_Pro_MechanoChem_15min_2
Instrument name,DSC2A-00468 (192.168.1.100)
Operator,Yarger
rundate,4/12/2025
Sample name,2025_04_12_CBD_Pro_MechanoChem_15min_2
proceduresegments,Data Off ; Equilibrate -60.00 °C; Data On ; Ramp 10.00 °C/min to 200.00 °C; Data Off ; Isothermal 1.0 min; Data On ; Ramp 10.00 °C/min to -60.00 °C; Data Off ; Isothermal 1.0 min; Data On ; Ramp 10.00 °C/min to 200.00 °C; Data Off ; Isothermal 1.0 min; Data On ; Ramp 10.00 °C/min to -60.00 °C; Data Off ; Isothermal 1.0 min; Data On ; Ramp 10.00 °C/min to 200.00 °C
[File Parameters]
Run date,4/12/2025 4:36:30 AM
Trios version,5.1.1.46572
Original File Name,
Current File Name,D:\DSC2500\JYarger\2025_04_12_CBD_Pro_MechanoChem_15min_2.tri
[Procedure]
Procedure Name,CBD_Pro_n60_200C_10Cmin_x3
Sample Name,2025_04_12_CBD_Pro_MechanoChem_15min_2
Sample Mass,6.95 mg
Reference Sample Mass,0 mg
Pan Mass,53.94 mg
Pan Number,16
Reference Pan Mass,53.32 mg
Reference Pan Number,10
Pan Type,Tzero Aluminum Hermetic
Comments,Hermetic Sealed Al DSC Consumables Pan/Lids.  Re-run CBD-Pro after -60-150C run 6 hr earlier. re-wt after 1st run - 60.89 mg.
Project Name,CA
Operator,Yarger
Test,Custom
Unload Max Temperature,30
Unload Min Temperature,30
Load Max Temperature,30
Load Min Temperature,30
Stop on Gas Flow Error,Yes
[Signal List]
Signal #1,Time (min)
Signal #2,Temperature (°C)
Signal #3,Heat Flow (mW)
Signal #4,Delta T (µV)
Signal #5,Delta Tzero (µV)
Signal #6,Tzero Temperature (°C)
Signal #7,Cell Purge (mL/min)
Signal #8,Heater Temp (°C)
Signal #9,Power Delivered (W)
Signal #10,Reference Junction Temperature (°C)
Signal #11,Flange Temperature (°C)
Signal #12,Heat Flow Phase (rad)
Signal #13,Total Heat Capacity (J/°C)
Signal #14,Heat Capacity (J/°C)
[Configuration]
Company Name,ASU
Instrument Name,DSC2A-00468
Instrument Type,DSC2500
Serial Number,DSC2A-00468
IP,192.168.1.100
Location of Instrument,MRRC
DisplayType,Unknown
Sample Interval ,0.1 s/pt
Selected Heat Flow,T4P
Exotherm Direction,Down
Cell Serial,DRC2-00792
Lid Type,Standard
Cooler,RCS 90
Leave Cooler on at End of Sequence,On
Gas 2,Nitrogen
Gas Selected,Channel 1
Flow Rate,50 mL/min
Secondary Purge,On
Licensed Heat Flow,Heat Flow T4P
Modulation Licensed,Yes
[Versions]
Common IDD Version,1
Cortex Version,VER 2.10.2.31
Driver,5.0.0.6
GDM Version,1.0.3.3
TouchscreenVersion,1.0.0.16145
FEP Version,1.2.1.21
FEP Bootloader,2.0.0.5
AutoSampler Version,2.1.1.26
Auto Sampler Bootloader,2.0.0.5
FCM Version,1.1.0.3
FCM Bootloader,2.0.0.5
[Experiment Logs]
Experiment Log Entry # 1,Air Cool is off.
Experiment Log Entry # 3,Data On set to 0
Experiment Log Entry # 5,Equilibrate Segment -60 (C) Started
Experiment Log Entry # 7,Data On set to 1
Experiment Log Entry # 9,Ramp Segment 10 C/min to 200 Started
Experiment Log Entry # 11,Data On set to 0
Experiment Log Entry # 13,Isothermal Segment 1 min started
Experiment Log Entry # 15,Data On set to 1
Experiment Log Entry # 17,Ramp Segment 10 C/min to -60 Started
Experiment Log Entry # 19,Data On set to 0
Experiment Log Entry # 21,Isothermal Segment 1 min started
Experiment Log Entry # 23,Data On set to 1
Experiment Log Entry # 25,Ramp Segment 10 C/min to 200 Started
Experiment Log Entry # 27,Data On set to 0
Experiment Log Entry # 29,Isothermal Segment 1 min started
Experiment Log Entry # 31,Data On set to 1
Experiment Log Entry # 33,Ramp Segment 10 C/min to -60 Started
Experiment Log Entry # 35,Data On set to 0
Experiment Log Entry # 37,Isothermal Segment 1 min started
Experiment Log Entry # 39,Data On set to 1
Experiment Log Entry # 41,Ramp Segment 10 C/min to 200 Started
[Method Log]
Method Log Entry # 1,Data Off
Method Log Entry # 2,Equilibrate -60 °C
Method Log Entry # 3,Data On
Method Log Entry # 4,(Ramp 154102) Ramp 10 °C/minute to 200 °C
Method Log Entry # 5,Data Off
Method Log Entry # 6,Isothermal 1 minutes
Method Log Entry # 7,Data On
Method Log Entry # 8,(Ramp 154106) Ramp 10 °C/minute to -60 °C
Method Log Entry # 9,Data Off
Method Log Entry # 10,Isothermal 1 minutes
Method Log Entry # 11,Data On
Method Log Entry # 12,(Ramp 154110) Ramp 10 °C/minute to 200 °C
Method Log Entry # 13,Data Off
Method Log Entry # 14,Isothermal 1 minutes
Method Log Entry # 15,Data On
Method Log Entry # 16,(Ramp 154114) Ramp 10 °C/minute to -60 °C
Method Log Entry # 17,Data Off
Method Log Entry # 18,Isothermal 1 minutes
Method Log Entry # 19,Data On
Method Log Entry # 20,(Ramp 154118) Ramp 10 °C/minute to 200 °C
Cell Serial,DRC2-00792
[T1 Calibration]
Slope,-0.008529666
Offset,9.636258
Initial Temperature,98.23
GUID,f8bfdadc-4977-4fdf-ba6d-0ba9134940c3
[TZero Calibration]
Date Applied,11/29/2022 4:06:13 PM
Description,From -89.059 °C to 396.009 °C at 20.000°C/min
Gas Type,Nitrogen
Pan Type,None
Source Files 1,C:\Users\yargerlab\Desktop\DSC Data\General\TZero_calibration_11_29_22_2nd(2).tri
Source Files 2,C:\Users\yargerlab\Desktop\DSC Data\General\TZero_calibration_11_29_22_2nd(3).tri
Delta T Offset,13.05235
Delta T Slope,-0.007271007
Delta T0 Offset,-13.69128
Delta T0 Slope,0.06063341
[Temperature Calibration]
Date Applied,11/29/2022 7:12:28 PM
Description,From 106.590 °C to 186.590 °C at 10.000°C/min
Gas Type,Nitrogen
Pan Type,Tzero Aluminum Hermetic
Source Files 1,C:\Users\yargerlab\Desktop\DSC Data\General\Indium(6).tri
Measured 1,157.391
Known 1,156.598
[Cell Constant Calibration]
Date Applied,11/29/2022 7:12:29 PM
Description,From 106.590 °C to 186.590 °C at 10.000°C/min
Gas Type,Nitrogen
Pan Type,Tzero Aluminum Hermetic
Source Files 1,C:\Users\yargerlab\Desktop\DSC Data\General\Indium(6).tri
T4P KCell,1.006051
Onset Slope,63.26126 mW/°C
[Direct Cp Calibration]
Date Applied,11/30/2022 11:04:51 AM
Description,From -79.983 °C to 298.409 °C at 10.000°C/min
Gas Type,Nitrogen
Pan Type,Tzero Aluminum Hermetic
Source Files 1,C:\Users\yargerlab\Desktop\DSC Data\General\Sapphire_Heat_Capacity_11_30_22.tri
[Rev Cp Calibration]
Date Applied,11/30/2022 1:58:51 PM
Description,From -79.996 °C to 292.812 °C at 3.000°C/min
Gas Type,Nitrogen
Pan Type,Tzero Aluminum Hermetic
Source Files 1,C:\Users\yargerlab\Desktop\DSC Data\General\Sapphire_MDSC_Calibration_11_30_22.tri
[step]
Ramp 10.00 °C/min to 200.00 °C
Time,Temperature,Heat Flow (Normalized)
min,°C,W/g
0.00,-59.69,-0.034
0.02,-59.70,-0.033
0.04,-59.71,-0.028
0.05,-59.71,-0.023
0.07,-59.69,-0.018
0.09,-59.66,-0.010
0.11,-59.61,0.000
0.13,-59.54,0.013
0.15,-59.45,0.029
0.16,-59.34,0.045
0.18,-59.22,0.063
0.20,-59.09,0.079
0.22,-58.96,0.095
0.24,-58.81,0.108
0.26,-58.66,0.121
0.28,-58.51,0.130
0.29,-58.35,0.138
0.31,-58.19,0.146
0.33,-58.03,0.152
0.35,-57.86,0.157
0.37,-57.69,0.162
0.39,-57.53,0.165
0.40,-57.36,0.168
0.42,-57.18,0.172
0.44,-57.01,0.174
0.46,-56.84,0.176
0.48,-56.66,0.177
0.50,-56.49,0.179
0.51,-56.31,0.181
0.53,-56.14,0.182
0.55,-55.96,0.182
0.57,-55.79,0.183
0.59,-55.61,0.184
0.60,-55.43,0.184
0.62,-55.25,0.185
0.64,-55.07,0.186
0.66,-54.89,0.186
0.68,-54.72,0.186
0.70,-54.54,0.187
0.72,-54.36,0.187
0.73,-54.18,0.187
0.75,-54.00,0.188
0.77,-53.82,0.188
0.79,-53.64,0.188
0.81,-53.46,0.189
0.83,-53.28,0.189
0.84,-53.10,0.189
0.86,-52.92,0.189
0.88,-52.74,0.190
0.90,-52.56,0.190
0.92,-52.38,0.190
0.93,-52.20,0.190
0.95,-52.01,0.190
0.97,-51.83,0.191
0.99,-51.65,0.191
1.01,-51.47,0.191
1.03,-51.29,0.191
1.05,-51.11,0.192
1.06,-50.93,0.192
1.08,-50.74,0.192
1.10,-50.56,0.192
1.12,-50.38,0.192
1.14,-50.20,0.193
1.16,-50.02,0.193
1.17,-49.84,0.193
1.19,-49.65,0.193
1.21,-49.47,0.193
1.23,-49.29,0.193
1.25,-49.11,0.194
1.27,-48.92,0.194
1.28,-48.74,0.194
1.30,-48.56,0.194
1.32,-48.38,0.194
1.34,-48.19,0.194
1.36,-48.01,0.194
1.38,-47.83,0.195
1.39,-47.64,0.195
1.41,-47.46,0.195
1.43,-47.28,0.195
1.45,-47.10,0.195
1.47,-46.91,0.195
1.48,-46.73,0.195
1.50,-46.55,0.195
1.52,-46.37,0.196
1.54,-46.18,0.196
1.56,-46.00,0.196
1.58,-45.82,0.196
1.59,-45.63,0.196
1.61,-45.45,0.196
1.63,-45.27,0.196
1.65,-45.08,0.196
1.67,-44.90,0.196
1.69,-44.72,0.196
1.71,-44.53,0.196
1.72,-44.35,0.197
1.74,-44.17,0.197
1.76,-43.99,0.197
1.78,-43.80,0.197
1.80,-43.62,0.197
1.82,-43.44,0.197
1.83,-43.25,0.197
1.85,-43.07,0.197
1.87,-42.89,0.198
1.89,-42.70,0.198
1.91,-42.52,0.198
1.93,-42.34,0.198
1.94,-42.15,0.198
1.96,-41.97,0.198
1.98,-41.79,0.198
2.00,-41.60,0.198
2.02,-41.42,0.198
2.03,-41.23,0.198
2.05,-41.05,0.198
2.07,-40.87,0.198
2.09,-40.68,0.198
2.11,-40.50,0.199
2.13,-40.32,0.199
2.14,-40.13,0.199
2.16,-39.95,0.199
2.18,-39.77,0.199
2.20,-39.58,0.199
2.22,-39.40,0.199
2.24,-39.22,0.199
2.26,-39.03,0.199
2.27,-38.85,0.199
2.29,-38.67,0.199
2.31,-38.48,0.199
2.33,-38.30,0.199
2.35,-38.12,0.200
2.36,-37.93,0.200
2.38,-37.75,0.200
2.40,-37.56,0.200
2.42,-37.38,0.200
2.44,-37.20,0.200
2.46,-37.02,0.200
2.48,-36.83,0.200
2.49,-36.65,0.200
2.51,-36.46,0.200
2.53,-36.28,0.200
2.55,-36.10,0.201
2.57,-35.91,0.201
2.59,-35.73,0.201
2.60,-35.55,0.201
2.62,-35.36,0.201
2.64,-35.18,0.201
2.66,-35.00,0.201
2.68,-34.81,0.201
2.69,-34.63,0.201
2.71,-34.45,0.201
2.73,-34.26,0.201
2.75,-34.08,0.201
2.77,-33.89,0.201
2.79,-33.71,0.201
2.81,-33.53,0.202
2.82,-33.34,0.202
2.84,-33.16,0.202
2.86,-32.98,0.202
2.88,-32.79,0.202
2.90,-32.61,0.202
2.91,-32.42,0.202
2.93,-32.24,0.202
2.95,-32.06,0.202
2.97,-31.87,0.202
2.99,-31.69,0.202
3.01,-31.51,0.202
3.03,-31.32,0.203
3.04,-31.14,0.203
3.06,-30.96,0.203
3.08,-30.77,0.203
3.10,-30.59,0.203
3.12,-30.41,0.203
3.14,-30.22,0.203
3.15,-30.04,0.203
3.17,-29.86,0.203
3.19,-29.67,0.203
3.21,-29.49,0.203
3.23,-29.30,0.203
3.24,-29.12,0.204
3.26,-28.94,0.204
3.28,-28.75,0.204
3.30,-28.57,0.204
3.32,-28.39,0.204
3.34,-28.20,0.204
3.36,-28.02,0.204
3.37,-27.83,0.204
3.39,-27.65,0.204
3.41,-27.47,0.204
3.43,-27.29,0.205
3.45,-27.10,0.205
3.46,-26.92,0.205
3.48,-26.73,0.205
3.50,-26.55,0.205
3.52,-26.37,0.205
3.54,-26.18,0.205
3.56,-26.00,0.205
3.58,-25.82,0.205
3.59,-25.63,0.205
3.61,-25.45,0.206
3.63,-25.27,0.206
3.65,-25.08,0.206
3.67,-24.90,0.206
3.69,-24.72,0.206
3.70,-24.53,0.206
3.72,-24.35,0.206
3.74,-24.17,0.206
3.76,-23.98,0.206
3.78,-23.80,0.207
3.79,-23.61,0.207
3.81,-23.43,0.207
3.83,-23.25,0.207
3.85,-23.06,0.207
3.87,-22.88,0.207
3.89,-22.70,0.207
3.91,-22.51,0.207
3.92,-22.33,0.207
3.94,-22.15,0.207
3.96,-21.96,0.208
3.98,-21.78,0.208
4.00,-21.60,0.208
4.01,-21.41,0.208
4.03,-21.23,0.208
4.05,-21.04,0.208
4.07,-20.86,0.208
4.09,-20.68,0.208
4.11,-20.49,0.208
4.13,-20.31,0.209
4.14,-20.13,0.209
4.16,-19.94,0.209
4.18,-19.76,0.209
4.20,-19.58,0.209
4.22,-19.39,0.209
4.24,-19.21,0.209
4.25,-19.03,0.209
4.27,-18.84,0.210
4.29,-18.66,0.210
4.31,-18.48,0.210
4.33,-18.29,0.210
4.35,-18.11,0.210
4.36,-17.92,0.210
4.38,-17.74,0.210
4.40,-17.56,0.211
4.42,-17.38,0.211
4.44,-17.19,0.211
4.45,-17.01,0.211
4.47,-16.82,0.211
4.49,-16.64,0.212
4.51,-16.46,0.212
4.53,-16.27,0.212
4.55,-16.09,0.212
4.56,-15.90,0.212
4.58,-15.72,0.212
4.60,-15.54,0.213
4.62,-15.36,0.213
4.64,-15.17,0.213
4.66,-14.99,0.213
4.68,-14.80,0.213
4.69,-14.62,0.214
4.71,-14.44,0.214
4.73,-14.26,0.214
4.75,-14.07,0.215
4.77,-13.89,0.215
4.79,-13.71,0.215
4.80,-13.52,0.215
4.82,-13.34,0.216
4.84,-13.15,0.216
4.86,-12.97,0.216
4.88,-12.79,0.216
4.90,-12.60,0.217
4.91,-12.42,0.217
4.93,-12.24,0.217
4.95,-12.05,0.218
4.97,-11.87,0.218
4.99,-11.69,0.219
5.00,-11.50,0.219
5.02,-11.32,0.219
5.04,-11.14,0.220
5.06,-10.95,0.220
5.08,-10.77,0.221
5.10,-10.59,0.221
5.11,-10.40,0.221
5.13,-10.22,0.222
5.15,-10.04,0.223
5.17,-9.86,0.224
5.19,-9.67,0.224
5.21,-9.49,0.225
5.23,-9.31,0.225
5.24,-9.12,0.226
5.26,-8.94,0.227
5.28,-8.76,0.228
5.30,-8.57,0.229
5.32,-8.39,0.230
5.34,-8.21,0.231
5.35,-8.02,0.232
5.37,-7.84,0.233
5.39,-7.66,0.234
5.41,-7.47,0.235
5.43,-7.29,0.237
5.45,-7.11,0.238
5.46,-6.93,0.239
5.48,-6.74,0.240
5.50,-6.56,0.242
5.52,-6.38,0.243
5.54,-6.19,0.245
5.55,-6.01,0.246
5.57,-5.83,0.247
5.59,-5.64,0.250
5.61,-5.46,0.251
5.63,-5.28,0.253
5.65,-5.10,0.254
5.66,-4.91,0.255
5.68,-4.73,0.256
5.70,-4.55,0.258
5.72,-4.36,0.259
5.74,-4.18,0.260
5.76,-4.00,0.261
5.78,-3.82,0.262
5.79,-3.63,0.264
5.81,-3.45,0.264
5.83,-3.27,0.265
5.85,-3.08,0.266
5.87,-2.90,0.267
5.89,-2.72,0.268
5.90,-2.53,0.269
5.92,-2.35,0.269
5.94,-2.17,0.270
5.96,-1.98,0.270
5.98,-1.80,0.271
6.00,-1.62,0.271
6.01,-1.43,0.272
6.03,-1.25,0.272
6.05,-1.07,0.272
6.07,-0.88,0.273
6.09,-0.70,0.274
6.10,-0.52,0.274
6.12,-0.33,0.274
6.14,-0.15,0.274
6.16,0.03,0.274
6.18,0.22,0.275
6.20,0.40,0.275
6.21,0.58,0.275
6.23,0.77,0.275
6.25,0.95,0.275
6.27,1.13,0.275
6.29,1.32,0.275
6.31,1.50,0.275
6.33,1.68,0.276
6.34,1.87,0.276
6.36,2.05,0.276
6.38,2.24,0.276
6.40,2.42,0.276
6.42,2.60,0.276
6.44,2.79,0.276
6.45,2.97,0.276
6.47,3.15,0.276
6.49,3.34,0.276
6.51,3.52,0.276
6.53,3.71,0.276
6.55,3.89,0.276
6.56,4.07,0.276
6.58,4.26,0.276
6.60,4.44,0.276
6.62,4.62,0.276
6.64,4.81,0.276
6.65,4.99,0.276
6.67,5.17,0.276
6.69,5.36,0.276
6.71,5.54,0.276
6.73,5.73,0.276
6.75,5.91,0.276
6.76,6.09,0.276
6.78,6.28,0.276
6.80,6.46,0.276
6.82,6.64,0.276
6.84,6.83,0.276
6.86,7.01,0.276
6.88,7.19,0.277
6.89,7.38,0.277
6.91,7.56,0.277
6.93,7.75,0.277
6.95,7.93,0.277
6.97,8.11,0.277
6.99,8.30,0.277
7.00,8.48,0.277
7.02,8.66,0.277
7.04,8.85,0.277
7.06,9.03,0.277
7.08,9.21,0.277
7.10,9.40,0.277
7.11,9.58,0.278
7.13,9.76,0.278
7.15,9.95,0.278
7.17,10.13,0.278
7.19,10.31,0.278
7.20,10.50,0.278
7.22,10.68,0.278
7.24,10.87,0.279
7.26,11.05,0.279
7.28,11.23,0.279
7.30,11.42,0.279
7.31,11.60,0.279
7.33,11.78,0.279
7.35,11.96,0.280
7.37,12.15,0.280
7.39,12.33,0.280
7.41,12.52,0.280
7.43,12.70,0.280
7.44,12.88,0.281
7.46,13.07,0.281
7.48,13.25,0.281
7.50,13.43,0.281
7.52,13.62,0.281
7.54,13.80,0.282
7.55,13.98,0.282
7.57,14.17,0.282
7.59,14.35,0.282
7.61,14.53,0.282
7.63,14.72,0.283
7.65,14.90,0.283
7.66,15.08,0.283
7.68,15.27,0.283
7.70,15.45,0.283
7.72,15.64,0.284
7.74,15.82,0.284
7.75,16.00,0.284
7.77,16.19,0.284
7.79,16.37,0.284
7.81,16.55,0.284
7.83,16.74,0.285
7.85,16.92,0.285
7.86,17.10,0.285
7.88,17.29,0.285
7.90,17.47,0.285
7.92,17.65,0.285
7.94,17.84,0.285
7.96,18.02,0.286
7.98,18.20,0.286
7.99,18.39,0.286
8.01,18.57,0.286
8.03,18.75,0.286
8.05,18.94,0.286
8.07,19.12,0.286
8.09,19.31,0.287
8.10,19.49,0.287
8.12,19.67,0.287
8.14,19.86,0.287
8.16,20.04,0.287
8.18,20.23,0.287
8.20,20.41,0.287
8.21,20.59,0.287
8.23,20.78,0.288
8.25,20.96,0.288
8.27,21.14,0.288
8.29,21.33,0.288
8.30,21.51,0.288
8.32,21.69,0.288
8.34,21.88,0.288
8.36,22.06,0.288
8.38,22.24,0.288
8.40,22.43,0.288
8.41,22.61,0.289
8.43,22.79,0.289
8.45,22.98,0.289
8.47,23.16,0.289
8.49,23.34,0.289
8.51,23.53,0.289
8.53,23.71,0.289
8.54,23.89,0.289
8.56,24.08,0.289
8.58,24.26,0.290
8.60,24.45,0.290
8.62,24.63,0.290
8.63,24.81,0.290
8.65,25.00,0.290
8.67,25.18,0.290
8.69,25.36,0.290
8.71,25.55,0.290
8.73,25.73,0.291
8.75,25.91,0.291
8.76,26.10,0.291
8.78,26.28,0.291
8.80,26.46,0.291
8.82,26.65,0.291
8.84,26.83,0.291
8.85,27.02,0.292
8.87,27.20,0.292
8.89,27.38,0.292
8.91,27.57,0.292
8.93,27.75,0.292
8.95,27.93,0.292
8.97,28.12,0.292
8.98,28.30,0.292
9.00,28.48,0.293
9.02,28.67,0.293
9.04,28.85,0.293
9.06,29.03,0.293
9.08,29.22,0.293
9.09,29.40,0.293
9.11,29.58,0.293
9.13,29.77,0.293
9.15,29.95,0.294
9.17,30.14,0.294
9.18,30.32,0.294
9.20,30.50,0.294
9.22,30.69,0.294
9.24,30.87,0.294
9.26,31.05,0.294
9.28,31.24,0.295
9.30,31.42,0.295
9.31,31.60,0.295
9.33,31.79,0.295
9.35,31.97,0.295
9.37,32.15,0.295
9.39,32.34,0.295
9.40,32.52,0.295
9.42,32.70,0.296
9.44,32.89,0.296
9.46,33.07,0.296
9.48,33.25,0.296
9.50,33.44,0.296
9.52,33.62,0.296
9.53,33.81,0.296
9.55,33.99,0.296
9.57,34.17,0.297
9.59,34.36,0.297
9.61,34.54,0.297
9.63,34.72,0.297
9.64,34.91,0.297
9.66,35.09,0.297
9.68,35.27,0.297
9.70,35.46,0.297
9.72,35.64,0.297
9.73,35.83,0.298
9.75,36.01,0.298
9.77,36.19,0.298
9.79,36.38,0.298
9.81,36.56,0.298
9.83,36.74,0.298
9.85,36.93,0.298
9.86,37.11,0.298
9.88,37.29,0.298
9.90,37.48,0.299
9.92,37.66,0.299
9.94,37.84,0.299
9.95,38.03,0.299
9.97,38.21,0.299
9.99,38.40,0.299
10.01,38.58,0.299
10.03,38.76,0.299
10.05,38.95,0.300
10.07,39.13,0.300
10.08,39.31,0.300
10.10,39.50,0.300
10.12,39.68,0.300
10.14,39.86,0.300
10.16,40.05,0.300
10.18,40.23,0.300
10.19,40.41,0.301
10.21,40.60,0.301
10.23,40.78,0.301
10.25,40.96,0.301
10.27,41.15,0.301
10.28,41.33,0.301
10.30,41.52,0.301
10.32,41.70,0.301
10.34,41.88,0.302
10.36,42.06,0.302
10.38,42.25,0.302
10.40,42.43,0.302
10.41,42.62,0.302
10.43,42.80,0.302
10.45,42.98,0.302
10.47,43.17,0.303
10.49,43.35,0.303
10.50,43.53,0.303
10.52,43.72,0.303
10.54,43.90,0.303
10.56,44.08,0.303
10.58,44.27,0.303
10.60,44.45,0.303
10.62,44.63,0.304
10.63,44.82,0.304
10.65,45.00,0.304
10.67,45.19,0.304
10.69,45.37,0.304
10.71,45.55,0.304
10.73,45.74,0.304
10.74,45.92,0.304
10.76,46.10,0.305
10.78,46.29,0.305
10.80,46.47,0.305
10.82,46.65,0.305
10.83,46.84,0.305
10.85,47.02,0.305
10.87,47.20,0.305
10.89,47.39,0.306
10.91,47.57,0.306
10.93,47.76,0.306
10.95,47.94,0.306
10.96,48.12,0.306
10.98,48.31,0.306
11.00,48.49,0.306
11.02,48.67,0.306
11.04,48.86,0.307
11.05,49.04,0.307
11.07,49.22,0.307
11.09,49.41,0.307
11.11,49.59,0.307
11.13,49.77,0.307
11.15,49.96,0.307
11.17,50.14,0.307
11.18,50.33,0.308
11.20,50.51,0.308
11.22,50.69,0.308
11.24,50.88,0.308
11.26,51.06,0.308
11.28,51.24,0.308
11.29,51.43,0.308
11.31,51.61,0.308
11.33,51.79,0.309
11.35,51.98,0.309
11.37,52.16,0.309
11.38,52.34,0.309
11.40,52.53,0.309
11.42,52.71,0.309
11.44,52.89,0.309
11.46,53.08,0.310
11.48,53.26,0.310
11.50,53.45,0.310
11.51,53.63,0.310
11.53,53.81,0.310
11.55,54.00,0.310
11.57,54.18,0.310
11.59,54.36,0.310
11.60,54.55,0.311
11.62,54.73,0.311
11.64,54.91,0.311
11.66,55.10,0.311
11.68,55.28,0.311
11.70,55.46,0.311
11.72,55.65,0.311
11.73,55.83,0.311
11.75,56.01,0.311
11.77,56.20,0.312
11.79,56.38,0.312
11.81,56.57,0.312
11.83,56.75,0.312
11.84,56.93,0.312
11.86,57.12,0.312
11.88,57.30,0.312
11.90,57.48,0.313
11.92,57.67,0.313
11.93,57.85,0.313
11.95,58.03,0.313
11.97,58.22,0.313
11.99,58.40,0.313
12.01,58.58,0.313
12.03,58.77,0.314
12.05,58.95,0.314
12.06,59.13,0.314
12.08,59.32,0.314
12.10,59.50,0.314
12.12,59.69,0.314
12.14,59.87,0.314
12.15,60.05,0.314
12.17,60.24,0.315
12.19,60.42,0.315
12.21,60.60,0.315
12.23,60.79,0.315
12.25,60.97,0.315
12.27,61.15,0.315
12.28,61.34,0.315
12.30,61.52,0.316
12.32,61.70,0.316
12.34,61.89,0.316
12.36,62.07,0.316
12.38,62.25,0.316
12.39,62.44,0.316
12.41,62.62,0.316
12.43,62.80,0.316
12.45,62.99,0.316
12.47,63.17,0.317
12.48,63.36,0.317
12.50,63.54,0.317
12.52,63.72,0.317
12.54,63.91,0.317
12.56,64.09,0.317
12.58,64.27,0.317
12.60,64.46,0.317
12.61,64.64,0.318
12.63,64.82,0.318
12.65,65.01,0.318
12.67,65.19,0.318
12.69,65.37,0.318
12.70,65.56,0.318
12.72,65.74,0.318
12.74,65.92,0.318
12.76,66.11,0.318
12.78,66.29,0.319
12.80,66.47,0.319
12.82,66.66,0.319
12.83,66.84,0.319
12.85,67.02,0.319
12.87,67.21,0.319
12.89,67.39,0.319
12.91,67.58,0.319
12.93,67.76,0.319
12.94,67.94,0.320
12.96,68.13,0.320
12.98,68.31,0.320
13.00,68.49,0.320
13.02,68.68,0.320
13.03,68.86,0.320
13.05,69.04,0.320
13.07,69.23,0.321
13.09,69.41,0.321
13.11,69.59,0.321
13.13,69.78,0.321
13.15,69.96,0.321
13.16,70.14,0.321
13.18,70.33,0.321
13.20,70.51,0.321
13.22,70.70,0.322
13.24,70.88,0.322
13.25,71.06,0.322
13.27,71.25,0.322
13.29,71.43,0.322
13.31,71.61,0.322
13.33,71.80,0.322
13.35,71.98,0.322
13.37,72.16,0.323
13.38,72.35,0.323
13.40,72.53,0.323
13.42,72.71,0.323
13.44,72.90,0.323
13.46,73.08,0.323
13.48,73.26,0.323
13.49,73.45,0.324
13.51,73.63,0.324
13.53,73.81,0.324
13.55,74.00,0.324
13.57,74.18,0.324
13.58,74.37,0.324
13.60,74.55,0.324
13.62,74.73,0.325
13.64,74.92,0.325
13.66,75.10,0.325
13.68,75.28,0.325
13.70,75.47,0.325
13.71,75.65,0.325
13.73,75.83,0.325
13.75,76.02,0.325
13.77,76.20,0.326
13.79,76.38,0.326
13.80,76.57,0.326
13.82,76.75,0.326
13.84,76.93,0.326
13.86,77.12,0.326
13.88,77.30,0.326
13.90,77.49,0.326
13.92,77.67,0.327
13.93,77.85,0.327
13.95,78.04,0.327
13.97,78.22,0.327
13.99,78.40,0.327
14.01,78.59,0.327
14.03,78.77,0.327
14.04,78.95,0.327
14.06,79.14,0.327
14.08,79.32,0.328
14.10,79.50,0.328
14.12,79.69,0.328
14.13,79.87,0.328
14.15,80.05,0.328
14.17,80.24,0.328
14.19,80.42,0.328
14.21,80.60,0.328
14.23,80.79,0.328
14.25,80.97,0.329
14.26,81.15,0.329
14.28,81.34,0.329
14.30,81.52,0.329
14.32,81.70,0.329
14.34,81.89,0.329
14.35,82.07,0.329
14.37,82.25,0.329
14.39,82.44,0.329
14.41,82.62,0.329
14.43,82.81,0.330
14.45,82.99,0.330
14.47,83.17,0.330
14.48,83.36,0.330
14.50,83.54,0.330
14.52,83.72,0.330
14.54,83.91,0.330
14.56,84.09,0.330
14.58,84.27,0.330
14.59,84.46,0.330
14.61,84.64,0.330
14.63,84.82,0.330
14.65,85.01,0.331
14.67,85.19,0.331
14.68,85.38,0.331
14.70,85.56,0.331
14.72,85.74,0.331
14.74,85.93,0.331
14.76,86.11,0.331
14.78,86.29,0.331
14.80,86.48,0.331
14.81,86.66,0.331
14.83,86.84,0.331
14.85,87.03,0.331
14.87,87.21,0.332
14.89,87.39,0.332
14.90,87.58,0.332
14.92,87.76,0.332
14.94,87.94,0.332
14.96,88.13,0.332
14.98,88.31,0.332
15.00,88.49,0.332
15.02,88.68,0.332
15.03,88.86,0.332
15.05,89.05,0.332
15.07,89.23,0.332
15.09,89.41,0.332
15.11,89.60,0.333
15.13,89.78,0.333
15.14,89.96,0.333
15.16,90.15,0.333
15.18,90.33,0.333
15.20,90.51,0.333
15.22,90.70,0.333
15.23,90.88,0.333
15.25,91.07,0.333
15.27,91.25,0.333
15.29,91.43,0.333
15.31,91.62,0.333
15.33,91.80,0.333
15.35,91.98,0.334
15.36,92.17,0.334
15.38,92.35,0.334
15.40,92.53,0.334
15.42,92.72,0.334
15.44,92.90,0.334
15.45,93.08,0.334
15.47,93.27,0.334
15.49,93.45,0.334
15.51,93.63,0.334
15.53,93.82,0.334
15.55,94.00,0.334
15.57,94.18,0.334
15.58,94.37,0.334
15.60,94.55,0.334
15.62,94.74,0.334
15.64,94.92,0.334
15.66,95.10,0.334
15.68,95.29,0.334
15.69,95.47,0.334
15.71,95.65,0.334
15.73,95.84,0.334
15.75,96.02,0.334
15.77,96.21,0.334
15.78,96.39,0.334
15.80,96.57,0.334
15.82,96.75,0.334
15.84,96.94,0.334
15.86,97.12,0.334
15.88,97.31,0.334
15.90,97.49,0.334
15.91,97.67,0.334
15.93,97.85,0.334
15.95,98.04,0.334
15.97,98.22,0.334
15.99,98.41,0.334
16.00,98.59,0.334
16.02,98.77,0.334
16.04,98.96,0.333
16.06,99.14,0.333
16.08,99.33,0.333
16.10,99.51,0.333
16.12,99.69,0.333
16.13,99.88,0.333
16.15,100.06,0.333
16.17,100.24,0.333
16.19,100.43,0.333
16.21,100.61,0.332
16.23,100.79,0.332
16.24,100.98,0.332
16.26,101.16,0.332
16.28,101.35,0.332
16.30,101.53,0.332
16.32,101.71,0.332
16.33,101.90,0.331
16.35,102.08,0.331
16.37,102.26,0.331
16.39,102.45,0.331
16.41,102.63,0.331
16.43,102.82,0.330
16.45,103.00,0.330
16.46,103.18,0.330
16.48,103.37,0.330
16.50,103.55,0.329
16.52,103.73,0.329
16.54,103.92,0.329
16.55,104.10,0.329
16.57,104.28,0.329
16.59,104.47,0.329
16.61,104.65,0.328
16.63,104.84,0.328
16.65,105.02,0.328
16.67,105.20,0.328
16.68,105.39,0.327
16.70,105.57,0.327
16.72,105.75,0.327
16.74,105.94,0.327
16.76,106.12,0.327
16.78,106.31,0.326
16.79,106.49,0.326
16.81,106.67,0.326
16.83,106.86,0.326
16.85,107.04,0.325
16.87,107.22,0.325
16.88,107.41,0.325
16.90,107.59,0.324
16.92,107.78,0.324
16.94,107.96,0.324
16.96,108.14,0.324
16.98,108.33,0.323
17.00,108.51,0.323
17.01,108.69,0.323
17.03,108.88,0.322
17.05,109.06,0.322
17.07,109.24,0.322
17.09,109.43,0.322
17.11,109.61,0.321
17.12,109.79,0.321
17.14,109.98,0.321
17.16,110.16,0.320
17.18,110.34,0.320
17.20,110.53,0.320
17.22,110.71,0.320
17.23,110.89,0.319
17.25,111.08,0.319
17.27,111.26,0.319
17.29,111.45,0.319
17.31,111.63,0.319
17.33,111.81,0.318
17.34,112.00,0.318
17.36,112.18,0.318
17.38,112.36,0.318
17.40,112.55,0.317
17.42,112.73,0.317
17.43,112.92,0.317
17.45,113.10,0.317
17.47,113.28,0.317
17.49,113.47,0.316
17.51,113.65,0.316
17.53,113.83,0.316
17.54,114.02,0.316
17.56,114.20,0.315
17.58,114.38,0.315
17.60,114.57,0.315
17.62,114.75,0.315
17.64,114.94,0.315
17.66,115.12,0.314
17.67,115.30,0.314
17.69,115.49,0.314
17.71,115.67,0.314
17.73,115.85,0.314
17.75,116.04,0.313
17.77,116.22,0.313
17.78,116.40,0.313
17.80,116.59,0.313
17.82,116.77,0.313
17.84,116.95,0.313
17.86,117.14,0.312
17.88,117.32,0.312
17.89,117.50,0.312
17.91,117.69,0.312
17.93,117.87,0.312
17.95,118.06,0.312
17.97,118.24,0.312
17.98,118.42,0.312
18.00,118.61,0.311
18.02,118.79,0.311
18.04,118.97,0.311
18.06,119.16,0.311
18.08,119.34,0.311
18.09,119.52,0.311
18.11,119.71,0.311
18.13,119.89,0.311
18.15,120.07,0.311
18.17,120.26,0.311
18.19,120.44,0.312
18.21,120.63,0.312
18.22,120.81,0.312
18.24,120.99,0.312
18.26,121.18,0.312
18.28,121.36,0.312
18.30,121.54,0.312
18.32,121.73,0.312
18.33,121.91,0.313
18.35,122.09,0.313
18.37,122.28,0.313
18.39,122.46,0.313
18.41,122.64,0.313
18.43,122.83,0.314
18.44,123.01,0.314
18.46,123.19,0.314
18.48,123.38,0.314
18.50,123.56,0.314
18.52,123.74,0.315
18.53,123.93,0.315
18.55,124.11,0.316
18.57,124.29,0.316
18.59,124.48,0.316
18.61,124.66,0.316
18.63,124.84,0.316
18.64,125.03,0.317
18.66,125.21,0.317
18.68,125.39,0.318
18.70,125.58,0.318
18.72,125.76,0.318
18.74,125.94,0.319
18.76,126.13,0.319
18.77,126.31,0.319
18.79,126.49,0.320
18.81,126.68,0.320
18.83,126.86,0.321
18.85,127.04,0.321
18.87,127.23,0.321
18.88,127.41,0.322
18.90,127.59,0.322
18.92,127.78,0.323
18.94,127.96,0.323
18.96,128.14,0.323
18.98,128.33,0.324
18.99,128.51,0.324
19.01,128.69,0.325
19.03,128.88,0.325
19.05,129.06,0.326
19.07,129.24,0.326
19.08,129.43,0.327
19.10,129.61,0.328
19.12,129.79,0.328
19.14,129.97,0.328
19.16,130.16,0.329
19.18,130.34,0.330
19.19,130.53,0.330
19.21,130.71,0.330
19.23,130.89,0.331
19.25,131.07,0.331
19.27,131.26,0.332
19.29,131.44,0.332
19.31,131.62,0.333
19.32,131.80,0.333
19.34,131.99,0.335
19.36,132.17,0.335
19.38,132.36,0.336
19.40,132.54,0.336
19.42,132.72,0.337
19.43,132.91,0.338
19.45,133.09,0.340
19.47,133.27,0.341
19.49,133.46,0.343
19.51,133.64,0.344
19.53,133.82,0.345
19.54,134.01,0.345
19.56,134.19,0.346
19.58,134.37,0.346
19.60,134.56,0.346
19.62,134.74,0.347
19.63,134.92,0.347
19.65,135.11,0.347
19.67,135.29,0.347
19.69,135.47,0.347
19.71,135.66,0.347
19.73,135.84,0.348
19.74,136.02,0.348
19.76,136.21,0.348
19.78,136.39,0.349
19.80,136.58,0.349
19.82,136.76,0.349
19.84,136.94,0.350
19.86,137.13,0.350
19.87,137.31,0.350
19.89,137.49,0.351
19.91,137.68,0.351
19.93,137.86,0.352
19.95,138.04,0.352
19.97,138.23,0.354
19.98,138.41,0.356
20.00,138.59,0.359
20.02,138.77,0.362
20.04,138.96,0.368
20.06,139.14,0.373
20.08,139.32,0.381
20.09,139.50,0.388
20.11,139.68,0.399
20.13,139.86,0.411
20.15,140.04,0.429
20.17,140.22,0.450
20.18,140.40,0.475
20.20,140.57,0.506
20.22,140.74,0.540
20.24,140.92,0.577
20.26,141.09,0.614
20.28,141.26,0.645
20.29,141.43,0.674
20.31,141.60,0.697
20.33,141.77,0.715
20.35,141.94,0.725
20.37,142.12,0.727
20.39,142.30,0.726
20.41,142.48,0.712
20.42,142.66,0.692
20.44,142.85,0.663
20.46,143.04,0.628
20.48,143.23,0.588
20.50,143.43,0.549
20.52,143.63,0.513
20.53,143.82,0.482
20.55,144.02,0.458
20.57,144.21,0.439
20.59,144.41,0.424
20.61,144.60,0.414
20.63,144.79,0.405
20.64,144.98,0.398
20.66,145.17,0.393
20.68,145.36,0.388
20.70,145.54,0.384
20.72,145.73,0.381
20.73,145.92,0.379
20.75,146.10,0.377
20.77,146.29,0.375
20.79,146.47,0.373
20.81,146.66,0.372
20.83,146.84,0.371
20.84,147.02,0.371
20.86,147.21,0.370
20.88,147.39,0.370
20.90,147.58,0.370
20.92,147.76,0.369
20.94,147.94,0.369
20.96,148.13,0.369
20.97,148.31,0.369
20.99,148.49,0.369
21.01,148.68,0.369
21.03,148.86,0.368
21.05,149.05,0.368
21.07,149.23,0.368
21.08,149.41,0.368
21.10,149.60,0.368
21.12,149.78,0.368
21.14,149.96,0.368
21.16,150.15,0.368
21.18,150.33,0.368
21.19,150.51,0.368
21.21,150.70,0.368
21.23,150.88,0.368
21.25,151.07,0.368
21.27,151.25,0.368
21.28,151.43,0.368
21.30,151.61,0.368
21.32,151.80,0.368
21.34,151.98,0.368
21.36,152.16,0.368
21.38,152.35,0.368
21.39,152.53,0.368
21.41,152.71,0.368
21.43,152.90,0.368
21.45,153.08,0.368
21.47,153.26,0.368
21.49,153.45,0.369
21.51,153.63,0.369
21.52,153.81,0.369
21.54,154.00,0.369
21.56,154.18,0.369
21.58,154.37,0.369
21.60,154.55,0.369
21.62,154.73,0.369
21.63,154.91,0.369
21.65,155.10,0.370
21.67,155.28,0.370
21.69,155.47,0.370
21.71,155.65,0.370
21.73,155.83,0.370
21.74,156.01,0.370
21.76,156.20,0.370
21.78,156.38,0.371
21.80,156.57,0.371
21.82,156.75,0.371
21.83,156.93,0.371
21.85,157.12,0.371
21.87,157.30,0.371
21.89,157.48,0.371
21.91,157.67,0.372
21.93,157.85,0.372
21.94,158.03,0.372
21.96,158.22,0.372
21.98,158.40,0.372
22.00,158.58,0.372
22.02,158.77,0.372
22.04,158.95,0.372
22.06,159.13,0.373
22.07,159.32,0.373
22.09,159.50,0.373
22.11,159.68,0.373
22.13,159.87,0.373
22.15,160.05,0.373
22.17,160.24,0.373
22.18,160.42,0.373
22.20,160.60,0.373
22.22,160.79,0.374
22.24,160.97,0.374
22.26,161.15,0.374
22.28,161.34,0.374
22.29,161.52,0.374
22.31,161.70,0.374
22.33,161.89,0.374
22.35,162.07,0.375
22.37,162.25,0.375
22.38,162.44,0.375
22.40,162.62,0.375
22.42,162.80,0.375
22.44,162.99,0.375
22.46,163.17,0.375
22.48,163.35,0.376
22.49,163.54,0.376
22.51,163.72,0.376
22.53,163.90,0.376
22.55,164.09,0.376
22.57,164.27,0.376
22.59,164.45,0.376
22.61,164.64,0.376
22.62,164.82,0.376
22.64,165.00,0.377
22.66,165.19,0.377
22.68,165.37,0.377
22.70,165.55,0.377
22.72,165.74,0.377
22.73,165.92,0.377
22.75,166.10,0.377
22.77,166.29,0.378
22.79,166.47,0.378
22.81,166.65,0.378
22.83,166.84,0.378
22.84,167.02,0.378
22.86,167.21,0.378
22.88,167.39,0.378
22.90,167.57,0.378
22.92,167.76,0.379
22.93,167.94,0.379
22.95,168.12,0.379
22.97,168.31,0.379
22.99,168.49,0.379
23.01,168.67,0.380
23.03,168.86,0.380
23.04,169.04,0.380
23.06,169.22,0.380
23.08,169.41,0.380
23.10,169.59,0.380
23.12,169.77,0.380
23.14,169.96,0.381
23.16,170.14,0.381
23.17,170.32,0.381
23.19,170.51,0.381
23.21,170.69,0.381
23.23,170.87,0.382
23.25,171.06,0.382
23.27,171.24,0.382
23.28,171.42,0.382
23.30,171.61,0.383
23.32,171.79,0.383
23.34,171.97,0.383
23.36,172.16,0.383
23.38,172.34,0.383
23.39,172.52,0.384
23.41,172.71,0.384
23.43,172.89,0.384
23.45,173.07,0.384
23.47,173.26,0.384
23.48,173.44,0.385
23.50,173.62,0.385
23.52,173.81,0.385
23.54,173.99,0.386
23.56,174.17,0.386
23.58,174.36,0.386
23.59,174.54,0.387
23.61,174.72,0.387
23.63,174.91,0.388
23.65,175.09,0.388
23.67,175.27,0.388
23.69,175.46,0.389
23.71,175.64,0.389
23.72,175.82,0.390
23.74,176.01,0.390
23.76,176.19,0.390
23.78,176.37,0.391
23.80,176.56,0.391
23.82,176.74,0.392
23.83,176.92,0.392
23.85,177.11,0.393
23.87,177.29,0.393
23.89,177.47,0.394
23.91,177.66,0.394
23.93,177.84,0.395
23.94,178.02,0.395
23.96,178.21,0.396
23.98,178.39,0.397
24.00,178.57,0.397
24.02,178.76,0.397
24.03,178.94,0.398
24.05,179.12,0.399
24.07,179.30,0.399
24.09,179.49,0.400
24.11,179.67,0.400
24.13,179.85,0.401
24.14,180.04,0.402
24.16,180.22,0.402
24.18,180.41,0.403
24.20,180.59,0.404
24.22,180.77,0.405
24.24,180.96,0.405
24.26,181.14,0.406
24.27,181.32,0.406
24.29,181.51,0.407
24.31,181.69,0.407
24.33,181.87,0.408
24.35,182.05,0.409
24.37,182.24,0.410
24.38,182.42,0.411
24.40,182.60,0.411
24.42,182.79,0.413
24.44,182.97,0.413
24.46,183.15,0.414
24.48,183.34,0.415
24.49,183.52,0.416
24.51,183.70,0.417
24.53,183.89,0.417
24.55,184.07,0.418
24.57,184.25,0.419
24.58,184.43,0.420
24.60,184.62,0.422
24.62,184.80,0.422
24.64,184.99,0.424
24.66,185.17,0.425
24.68,185.35,0.426
24.69,185.53,0.427
24.71,185.72,0.428
24.73,185.90,0.430
24.75,186.09,0.431
24.77,186.27,0.432
24.79,186.45,0.433
24.81,186.63,0.434
24.82,186.82,0.435
24.84,187.00,0.437
24.86,187.18,0.437
24.88,187.36,0.438
24.90,187.55,0.439
24.92,187.73,0.441
24.93,187.91,0.442
24.95,188.10,0.443
24.97,188.28,0.445
24.99,188.46,0.446
25.01,188.65,0.448
25.03,188.83,0.449
25.04,189.01,0.450
25.06,189.19,0.451
25.08,189.38,0.452
25.10,189.56,0.452
25.12,189.74,0.454
25.13,189.93,0.455
25.15,190.11,0.456
25.17,190.29,0.456
25.19,190.48,0.457
25.21,190.66,0.458
25.23,190.84,0.458
25.24,191.03,0.459
25.26,191.21,0.460
25.28,191.39,0.460
25.30,191.57,0.460
25.32,191.76,0.461
25.34,191.94,0.461
25.36,192.12,0.462
25.37,192.31,0.462
25.39,192.49,0.463
25.41,192.67,0.464
25.43,192.86,0.465
25.45,193.04,0.466
25.47,193.22,0.468
25.48,193.41,0.468
25.50,193.59,0.470
25.52,193.77,0.471
25.54,193.96,0.472
25.56,194.14,0.474
25.58,194.32,0.475
25.59,194.50,0.477
25.61,194.69,0.477
25.63,194.87,0.479
25.65,195.05,0.481
25.67,195.24,0.482
25.68,195.42,0.484
25.70,195.60,0.486
25.72,195.79,0.487
25.74,195.97,0.488
25.76,196.15,0.490
25.78,196.33,0.492
25.79,196.52,0.493
25.81,196.70,0.494
25.83,196.88,0.496
25.85,197.07,0.497
25.87,197.25,0.499
25.89,197.43,0.500
25.91,197.61,0.503
25.92,197.80,0.504
25.94,197.98,
25.96,198.16,
25.98,198.35,
25.99,,

[step]
Ramp 10.00 °C/min to -60.00 °C
Time,Temperature,Heat Flow (Normalized)
min,°C,W/g
26.99,200.04,0.067
27.01,200.04,0.067
27.03,200.04,0.066
27.05,200.03,0.061
27.07,200.00,0.044
27.08,199.96,0.022
27.10,199.90,-0.009
27.12,199.82,-0.051
27.14,199.72,-0.097
27.16,199.60,-0.142
27.18,199.48,-0.185
27.19,199.34,-0.223
27.21,199.19,-0.254
27.23,199.04,-0.280
27.25,198.89,-0.302
27.27,198.73,-0.321
27.29,198.56,-0.336
27.31,198.40,-0.350
27.32,198.23,-0.361
27.34,198.06,-0.370
27.36,197.89,-0.379
27.38,197.72,-0.387
27.40,197.54,-0.393
27.42,197.37,-0.398
27.43,197.19,-0.402
27.45,197.01,-0.408
27.47,196.84,-0.410
27.49,196.66,-0.413
27.51,196.48,-0.416
27.53,196.30,-0.419
27.54,196.12,-0.420
27.56,195.94,-0.423
27.58,195.76,-0.424
27.60,195.58,-0.425
27.62,195.40,-0.427
27.63,195.22,-0.429
27.65,195.04,-0.429
27.67,194.86,-0.430
27.69,194.68,-0.432
27.71,194.50,-0.432
27.73,194.32,-0.433
27.74,194.14,-0.434
27.76,193.96,-0.435
27.78,193.78,-0.436
27.80,193.60,-0.437
27.82,193.42,-0.437
27.84,193.23,-0.438
27.86,193.05,-0.438
27.87,192.87,-0.439
27.89,192.69,-0.440
27.91,192.51,-0.440
27.93,192.33,-0.441
27.95,192.14,-0.441
27.97,191.96,-0.442
27.98,191.78,-0.442
28.00,191.60,-0.443
28.02,191.41,-0.443
28.04,191.23,-0.444
28.06,191.05,-0.444
28.08,190.87,-0.444
28.09,190.69,-0.445
28.11,190.50,-0.445
28.13,190.32,-0.446
28.15,190.14,-0.446
28.17,189.96,-0.446
28.18,189.78,-0.447
28.20,189.59,-0.447
28.22,189.41,-0.447
28.24,189.23,-0.448
28.26,189.05,-0.448
28.28,188.86,-0.449
28.29,188.68,-0.449
28.31,188.50,-0.449
28.33,188.32,-0.449
28.35,188.13,-0.450
28.37,187.95,-0.450
28.39,187.77,-0.450
28.41,187.59,-0.451
28.42,187.40,-0.451
28.44,187.22,-0.451
28.46,187.04,-0.451
28.48,186.85,-0.452
28.50,186.67,-0.452
28.52,186.49,-0.452
28.53,186.31,-0.452
28.55,186.12,-0.453
28.57,185.94,-0.453
28.59,185.76,-0.453
28.61,185.58,-0.453
28.63,185.39,-0.453
28.64,185.21,-0.453
28.66,185.03,-0.454
28.68,184.85,-0.454
28.70,184.66,-0.454
28.72,184.48,-0.454
28.73,184.30,-0.454
28.75,184.11,-0.455
28.77,183.93,-0.455
28.79,183.75,-0.455
28.81,183.56,-0.455
28.83,183.38,-0.455
28.84,183.20,-0.455
28.86,183.02,-0.455
28.88,182.83,-0.455
28.90,182.65,-0.456
28.92,182.47,-0.456
28.94,182.28,-0.456
28.96,182.10,-0.456
28.97,181.92,-0.456
28.99,181.74,-0.456
29.01,181.55,-0.456
29.03,181.37,-0.456
29.05,181.19,-0.456
29.07,181.00,-0.456
29.08,180.82,-0.457
29.10,180.64,-0.457
29.12,180.45,-0.457
29.14,180.27,-0.457
29.16,180.09,-0.457
29.18,179.90,-0.457
29.19,179.72,-0.457
29.21,179.54,-0.457
29.23,179.36,-0.457
29.25,179.17,-0.457
29.27,178.99,-0.457
29.28,178.81,-0.457
29.30,178.62,-0.457
29.32,178.44,-0.457
29.34,178.26,-0.457
29.36,178.07,-0.457
29.38,177.89,-0.457
29.39,177.71,-0.457
29.41,177.53,-0.457
29.43,177.34,-0.457
29.45,177.16,-0.457
29.47,176.98,-0.457
29.49,176.79,-0.457
29.51,176.61,-0.457
29.52,176.43,-0.457
29.54,176.24,-0.457
29.56,176.06,-0.457
29.58,175.88,-0.457
29.60,175.69,-0.457
29.62,175.51,-0.457
29.63,175.33,-0.457
29.65,175.15,-0.457
29.67,174.96,-0.457
29.69,174.78,-0.456
29.71,174.60,-0.456
29.73,174.41,-0.456
29.74,174.23,-0.456
29.76,174.05,-0.456
29.78,173.86,-0.456
29.80,173.68,-0.456
29.82,173.50,-0.456
29.83,173.31,-0.456
29.85,173.13,-0.456
29.87,172.95,-0.456
29.89,172.77,-0.456
29.91,172.58,-0.456
29.93,172.40,-0.456
29.94,172.21,-0.456
29.96,172.03,-0.456
29.98,171.85,-0.456
30.00,171.66,-0.456
30.02,171.48,-0.456
30.04,171.30,-0.456
30.06,171.11,-0.456
30.07,170.93,-0.456
30.09,170.75,-0.455
30.11,170.57,-0.455
30.13,170.38,-0.455
30.15,170.20,-0.455
30.17,170.02,-0.455
30.18,169.83,-0.455
30.20,169.65,-0.455
30.22,169.47,-0.455
30.24,169.29,-0.455
30.26,169.10,-0.454
30.28,168.92,-0.454
30.29,168.74,-0.454
30.31,168.55,-0.454
30.33,168.37,-0.454
30.35,168.19,-0.454
30.37,168.00,-0.454
30.38,167.82,-0.454
30.40,167.64,-0.454
30.42,167.45,-0.454
30.44,167.27,-0.453
30.46,167.09,-0.453
30.48,166.91,-0.453
30.49,166.72,-0.453
30.51,166.54,-0.453
30.53,166.36,-0.453
30.55,166.17,-0.453
30.57,165.99,-0.453
30.59,165.81,-0.453
30.61,165.62,-0.453
30.62,165.44,-0.452
30.64,165.26,-0.452
30.66,165.07,-0.452
30.68,164.89,-0.452
30.70,164.71,-0.452
30.72,164.53,-0.452
30.73,164.34,-0.452
30.75,164.16,-0.452
30.77,163.98,-0.452
30.79,163.79,-0.451
30.81,163.61,-0.451
30.83,163.43,-0.451
30.84,163.24,-0.451
30.86,163.06,-0.451
30.88,162.88,-0.451
30.90,162.70,-0.451
30.92,162.51,-0.451
30.93,162.33,-0.451
30.95,162.14,-0.451
30.97,161.96,-0.450
30.99,161.78,-0.450
31.01,161.60,-0.450
31.03,161.41,-0.450
31.04,161.23,-0.450
31.06,161.05,-0.450
31.08,160.86,-0.450
31.10,160.68,-0.450
31.12,160.50,-0.450
31.14,160.31,-0.449
31.16,160.13,-0.449
31.17,159.95,-0.449
31.19,159.76,-0.449
31.21,159.58,-0.449
31.23,159.40,-0.449
31.25,159.22,-0.449
31.27,159.03,-0.449
31.28,158.85,-0.449
31.30,158.67,-0.449
31.32,158.48,-0.448
31.34,158.30,-0.448
31.36,158.12,-0.448
31.38,157.93,-0.448
31.39,157.75,-0.448
31.41,157.57,-0.448
31.43,157.38,-0.448
31.45,157.20,-0.448
31.47,157.02,-0.448
31.48,156.83,-0.447
31.50,156.65,-0.447
31.52,156.47,-0.447
31.54,156.28,-0.447
31.56,156.10,-0.447
31.58,155.92,-0.447
31.59,155.74,-0.447
31.61,155.55,-0.447
31.63,155.37,-0.446
31.65,155.19,-0.446
31.67,155.00,-0.446
31.69,154.82,-0.446
31.71,154.64,-0.446
31.72,154.45,-0.446
31.74,154.27,-0.446
31.76,154.09,-0.446
31.78,153.91,-0.445
31.80,153.72,-0.445
31.82,153.54,-0.445
31.83,153.36,-0.445
31.85,153.17,-0.445
31.87,152.99,-0.445
31.89,152.81,-0.445
31.91,152.62,-0.445
31.93,152.44,-0.445
31.94,152.26,-0.444
31.96,152.07,-0.444
31.98,151.89,-0.444
32.00,151.71,-0.444
32.02,151.52,-0.444
32.03,151.34,-0.444
32.05,151.16,-0.444
32.07,150.97,-0.444
32.09,150.79,-0.443
32.11,150.61,-0.443
32.13,150.43,-0.443
32.14,150.24,-0.443
32.16,150.06,-0.443
32.18,149.87,-0.443
32.20,149.69,-0.443
32.22,149.51,-0.443
32.24,149.33,-0.442
32.26,149.14,-0.442
32.27,148.96,-0.442
32.29,148.78,-0.442
32.31,148.59,-0.442
32.33,148.41,-0.442
32.35,148.23,-0.441
32.37,148.04,-0.441
32.38,147.86,-0.441
32.40,147.68,-0.441
32.42,147.50,-0.441
32.44,147.31,-0.441
32.46,147.13,-0.441
32.48,146.95,-0.441
32.49,146.76,-0.441
32.51,146.58,-0.440
32.53,146.40,-0.440
32.55,146.21,-0.440
32.57,146.03,-0.440
32.58,145.85,-0.440
32.60,145.66,-0.440
32.62,145.48,-0.440
32.64,145.30,-0.440
32.66,145.12,-0.439
32.68,144.93,-0.439
32.69,144.75,-0.439
32.71,144.57,-0.439
32.73,144.38,-0.439
32.75,144.20,-0.439
32.77,144.02,-0.439
32.79,143.83,-0.439
32.81,143.65,-0.439
32.82,143.47,-0.438
32.84,143.28,-0.438
32.86,143.10,-0.438
32.88,142.92,-0.438
32.90,142.73,-0.438
32.92,142.55,-0.438
32.93,142.37,-0.438
32.95,142.18,-0.438
32.97,142.00,-0.437
32.99,141.82,-0.437
33.01,141.63,-0.437
33.03,141.45,-0.437
33.04,141.27,-0.437
33.06,141.09,-0.437
33.08,140.90,-0.437
33.10,140.72,-0.437
33.12,140.54,-0.436
33.13,140.35,-0.436
33.15,140.17,-0.436
33.17,139.99,-0.436
33.19,139.80,-0.436
33.21,139.62,-0.436
33.23,139.44,-0.436
33.24,139.25,-0.436
33.26,139.07,-0.435
33.28,138.89,-0.435
33.30,138.70,-0.435
33.32,138.52,-0.435
33.34,138.34,-0.435
33.36,138.15,-0.435
33.37,137.97,-0.435
33.39,137.79,-0.435
33.41,137.61,-0.435
33.43,137.42,-0.434
33.45,137.24,-0.434
33.47,137.06,-0.434
33.48,136.87,-0.434
33.50,136.69,-0.434
33.52,136.51,-0.434
33.54,136.32,-0.434
33.56,136.14,-0.434
33.58,135.96,-0.433
33.59,135.77,-0.433
33.61,135.59,-0.433
33.63,135.41,-0.433
33.65,135.22,-0.433
33.67,135.04,-0.433
33.68,134.86,-0.433
33.70,134.68,-0.432
33.72,134.49,-0.432
33.74,134.31,-0.432
33.76,134.13,-0.432
33.78,133.94,-0.432
33.79,133.76,-0.432
33.81,133.58,-0.432
33.83,133.39,-0.432
33.85,133.21,-0.432
33.87,133.03,-0.432
33.89,132.84,-0.431
33.91,132.66,-0.431
33.92,132.48,-0.431
33.94,132.29,-0.431
33.96,132.11,-0.431
33.98,131.93,-0.431
34.00,131.75,-0.431
34.02,131.56,-0.431
34.03,131.38,-0.431
34.05,131.20,-0.430
34.07,131.01,-0.430
34.09,130.83,-0.430
34.11,130.65,-0.430
34.13,130.46,-0.430
34.14,130.28,-0.430
34.16,130.10,-0.430
34.18,129.91,-0.430
34.20,129.73,-0.429
34.22,129.55,-0.429
34.24,129.36,-0.429
34.25,129.18,-0.429
34.27,129.00,-0.429
[...]
115.21,10.57,0.291
115.23,10.75,0.292
115.25,10.94,0.293
115.27,11.12,0.294
115.29,11.30,0.295
115.31,11.49,0.296
115.33,11.67,0.297
115.34,11.85,0.298
115.36,12.03,0.299
115.38,12.22,0.300
115.40,12.40,0.301
115.42,12.58,0.302
115.44,12.77,0.302
115.45,12.95,0.303
115.47,13.13,0.304
115.49,13.31,0.305
115.51,13.50,0.305
115.53,13.68,0.306
115.55,13.87,0.307
115.56,14.05,0.308
115.58,14.23,0.308
115.60,14.42,0.308
115.62,14.60,0.309
115.64,14.78,0.309
115.65,14.97,0.310
115.67,15.15,0.310
115.69,15.33,0.311
115.71,15.52,0.311
115.73,15.70,0.311
115.75,15.88,0.312
115.76,16.07,0.312
115.78,16.25,0.312
115.80,16.43,0.312
115.82,16.62,0.313
115.84,16.80,0.313
115.86,16.98,0.313
115.88,17.17,0.313
115.89,17.35,0.313
115.91,17.53,0.313
115.93,17.72,0.313
115.95,17.90,0.313
115.97,18.09,0.314
115.99,18.27,0.314
116.00,18.45,0.314
116.02,18.64,0.314
116.04,18.82,0.314
116.06,19.00,0.314
116.08,19.19,0.314
116.10,19.37,0.314
116.11,19.55,0.314
116.13,19.74,0.314
116.15,19.92,0.314
116.17,20.10,0.314
116.19,20.29,0.314
116.20,20.47,0.314
116.22,20.66,0.314
116.24,20.84,0.314
116.26,21.02,0.314
116.28,21.21,0.314
116.30,21.39,0.314
116.31,21.57,0.314
116.33,21.76,0.314
116.35,21.94,0.314
116.37,22.12,0.314
116.39,22.31,0.315
116.41,22.49,0.315
116.43,22.68,0.315
116.44,22.86,0.315
116.46,23.04,0.315
116.48,23.23,0.315
116.50,23.41,0.315
116.52,23.59,0.315
116.54,23.78,0.315
116.55,23.96,0.315
116.57,24.14,0.315
116.59,24.33,0.315
116.61,24.51,0.315
116.63,24.69,0.315
116.65,24.88,0.315
116.66,25.06,0.316
116.68,25.25,0.316
116.70,25.43,0.316
116.72,25.61,0.316
116.74,25.80,0.316
116.75,25.98,0.316
116.77,26.16,0.316
116.79,26.35,0.316
116.81,26.53,0.316
116.83,26.71,0.316
116.85,26.90,0.317
116.86,27.08,0.317
116.88,27.26,0.317
116.90,27.45,0.317
116.92,27.63,0.317
116.94,27.82,0.317
116.96,28.00,0.317
116.98,28.18,0.317
116.99,28.37,0.318
117.01,28.55,0.318
117.03,28.73,0.318
117.05,28.92,0.318
117.07,29.10,0.318
117.09,29.28,0.318
117.10,29.47,0.319
117.12,29.65,0.319
117.14,29.83,0.319
117.16,30.02,0.319
117.18,30.20,0.319
117.20,30.38,0.319
117.21,30.57,0.319
117.23,30.75,0.319
117.25,30.93,0.320
117.27,31.12,0.320
117.29,31.30,0.320
117.30,31.49,0.320
117.32,31.67,0.320
117.34,31.85,0.320
117.36,32.04,0.320
117.38,32.22,0.321
117.40,32.40,0.321
117.41,32.59,0.321
117.43,32.77,0.321
117.45,32.95,0.321
117.47,33.14,0.321
117.49,33.32,0.321
117.51,33.50,0.322
117.53,33.69,0.322
117.54,33.87,0.322
117.56,34.06,0.322
117.58,34.24,0.322
117.60,34.42,0.322
117.62,34.61,0.323
117.64,34.79,0.323
117.65,34.97,0.323
117.67,35.16,0.323
117.69,35.34,0.323
117.71,35.52,0.323
117.73,35.71,0.323
117.75,35.89,0.323
117.76,36.07,0.324
117.78,36.26,0.324
117.80,36.44,0.324
117.82,36.63,0.324
117.84,36.81,0.324
117.85,36.99,0.324
117.87,37.18,0.324
117.89,37.36,0.325
117.91,37.54,0.325
117.93,37.73,0.325
117.95,37.91,0.325
117.96,38.09,0.325
117.98,38.28,0.325
118.00,38.46,0.325
118.02,38.64,0.325
118.04,38.83,0.326
118.06,39.01,0.326
118.08,39.19,0.326
118.09,39.38,0.326
118.11,39.56,0.326
118.13,39.74,0.326
118.15,39.93,0.326
118.17,40.11,0.327
118.19,40.30,0.327
118.20,40.48,0.327
118.22,40.66,0.327
118.24,40.85,0.327
118.26,41.03,0.327
118.28,41.21,0.327
118.30,41.40,0.328
118.31,41.58,0.328
118.33,41.76,0.328
118.35,41.95,0.328
118.37,42.13,0.328
118.39,42.31,0.328
118.40,42.50,0.328
118.42,42.68,0.329
118.44,42.87,0.329
118.46,43.05,0.329
118.48,43.23,0.329
118.50,43.42,0.329
118.51,43.60,0.329
118.53,43.78,0.330
118.55,43.97,0.330
118.57,44.15,0.330
118.59,44.33,0.330
118.61,44.52,0.330
118.63,44.70,0.330
118.64,44.88,0.330
118.66,45.07,0.331
118.68,45.25,0.331
118.70,45.43,0.331
118.72,45.62,0.331
118.74,45.80,0.331
118.75,45.99,0.331
118.77,46.17,0.331
118.79,46.35,0.332
118.81,46.53,0.332
118.83,46.72,0.332
118.85,46.90,0.332
118.86,47.09,0.332
118.88,47.27,0.332
118.90,47.45,0.333
118.92,47.64,0.333
118.94,47.82,0.333
118.95,48.00,0.333
118.97,48.19,0.333
118.99,48.37,0.333
119.01,48.55,0.333
119.03,48.74,0.334
119.05,48.92,0.334
119.06,49.10,0.334
119.08,49.29,0.334
119.10,49.47,0.334
119.12,49.65,0.334
119.14,49.84,0.335
119.16,50.02,0.335
119.18,50.21,0.335
119.19,50.39,0.335
119.21,50.57,0.335
119.23,50.76,0.335
119.25,50.94,0.335
119.27,51.12,0.336
119.29,51.31,0.336
119.30,51.49,0.336
119.32,51.67,0.336
119.34,51.86,0.336
119.36,52.04,0.336
119.38,52.22,0.336
119.40,52.41,0.336
119.41,52.59,0.337
119.43,52.78,0.337
119.45,52.96,0.337
119.47,53.14,0.337
119.49,53.33,0.337
119.50,53.51,0.337
119.52,53.69,0.338
119.54,53.88,0.338
119.56,54.06,0.338
119.58,54.24,0.338
119.60,54.43,0.338
119.61,54.61,0.338
119.63,54.79,0.338
119.65,54.98,0.338
119.67,55.16,0.339
119.69,55.34,0.339
119.71,55.53,0.339
119.73,55.71,0.339
119.74,55.90,0.339
119.76,56.08,0.339
119.78,56.26,0.340
119.80,56.45,0.340
119.82,56.63,0.340
119.84,56.81,0.340
119.85,57.00,0.340
119.87,57.18,0.340
119.89,57.36,0.340
119.91,57.55,0.341
119.93,57.73,0.341
119.95,57.91,0.341
119.96,58.10,0.341
119.98,58.28,0.341
120.00,58.47,0.341
120.02,58.65,0.341
120.04,58.83,0.342
120.05,59.02,0.342
120.07,59.20,0.342
120.09,59.39,0.342
120.11,59.57,0.342
120.13,59.75,0.342
120.15,59.94,0.342
120.16,60.12,0.343
120.18,60.30,0.343
120.20,60.49,0.343
120.22,60.67,0.343
120.24,60.85,0.343
120.26,61.04,0.343
120.28,61.22,0.343
120.29,61.40,0.343
120.31,61.59,0.343
120.33,61.77,0.344
120.35,61.95,0.344
120.37,62.14,0.344
120.39,62.32,0.344
120.40,62.50,0.344
120.42,62.69,0.344
120.44,62.87,0.344
120.46,63.05,0.344
120.48,63.24,0.345
120.50,63.42,0.345
120.51,63.61,0.345
120.53,63.79,0.345
120.55,63.97,0.346
120.57,64.16,0.346
120.59,64.34,0.346
120.60,64.52,0.346
120.62,64.71,0.346
120.64,64.89,0.346
120.66,65.07,0.346
120.68,65.26,0.347
120.70,65.44,0.347
120.71,65.62,0.347
120.73,65.81,0.347
120.75,65.99,0.347
120.77,66.18,0.347
120.79,66.36,0.347
120.81,66.54,0.347
120.83,66.72,0.347
120.84,66.91,0.348
120.86,67.09,0.348
120.88,67.28,0.348
120.90,67.46,0.348
120.92,67.64,0.348
120.94,67.83,0.348
120.95,68.01,0.348
120.97,68.19,0.349
120.99,68.38,0.349
121.01,68.56,0.349
121.03,68.74,0.349
121.05,68.93,0.349
121.06,69.11,0.349
121.08,69.29,0.349
121.10,69.48,0.349
121.12,69.66,0.350
121.14,69.84,0.350
121.15,70.03,0.350
121.17,70.21,0.350
121.19,70.39,0.350
121.21,70.58,0.350
121.23,70.76,0.350
121.25,70.94,0.350
121.26,71.13,0.351
121.28,71.31,0.351
121.30,71.49,0.351
121.32,71.68,0.351
121.34,71.86,0.351
121.36,72.04,0.351
121.38,72.23,0.351
121.39,72.41,0.351
121.41,72.59,0.352
121.43,72.78,0.352
121.45,72.96,0.352
121.47,73.15,0.352
121.49,73.33,0.352
121.50,73.51,0.352
121.52,73.70,0.352
121.54,73.88,0.353
121.56,74.06,0.353
121.58,74.25,0.353
121.60,74.43,0.353
121.61,74.61,0.353
121.63,74.80,0.353
121.65,74.98,0.354
121.67,75.16,0.354
121.69,75.35,0.354
121.70,75.53,0.354
121.72,75.72,0.354
121.74,75.90,0.354
121.76,76.08,0.354
121.78,76.27,0.354
121.80,76.45,0.355
121.81,76.63,0.355
121.83,76.82,0.355
121.85,77.00,0.355
121.87,77.18,0.355
121.89,77.37,0.355
121.91,77.55,0.355
121.93,77.73,0.355
121.94,77.92,0.356
121.96,78.10,0.356
121.98,78.28,0.356
122.00,78.47,0.356
122.02,78.65,0.356
122.04,78.84,0.356
122.05,79.02,0.356
122.07,79.20,0.356
122.09,79.38,0.357
122.11,79.57,0.357
122.13,79.75,0.357
122.15,79.94,0.357
122.16,80.12,0.357
122.18,80.30,0.357
122.20,80.49,0.357
122.22,80.67,0.357
122.24,80.85,0.358
122.25,81.04,0.358
122.27,81.22,0.358
122.29,81.40,0.358
122.31,81.59,0.358
122.33,81.77,0.358
122.35,81.95,0.358
122.36,82.14,0.358
122.38,82.32,0.358
122.40,82.50,0.359
122.42,82.69,0.359
122.44,82.87,0.359
122.46,83.05,0.359
122.48,83.24,0.359
122.49,83.42,0.359
122.51,83.60,0.359
122.53,83.79,0.359
122.55,83.97,0.360
122.57,84.15,0.360
122.59,84.34,0.360
122.60,84.52,0.360
122.62,84.70,0.360
122.64,84.89,0.360
122.66,85.07,0.360
122.68,85.25,0.361
122.70,85.44,0.361
122.71,85.62,0.361
122.73,85.80,0.361
122.75,85.99,0.361
122.77,86.17,0.361
122.79,86.36,0.362
122.80,86.54,0.362
122.82,86.72,0.362
122.84,86.91,0.362
122.86,87.09,0.362
122.88,87.27,0.362
122.90,87.46,0.362
122.91,87.64,0.363
122.93,87.83,0.363
122.95,88.01,0.363
122.97,88.19,0.363
122.99,88.38,0.363
123.01,88.56,0.363
123.03,88.74,0.363
123.04,88.93,0.363
123.06,89.11,0.364
123.08,89.29,0.364
123.10,89.48,0.364
123.12,89.66,0.364
123.14,89.84,0.364
123.15,90.03,0.364
123.17,90.21,0.364
123.19,90.39,0.365
123.21,90.58,0.365
123.23,90.76,0.365
123.25,90.95,0.365
123.26,91.13,0.365
123.28,91.31,0.365
123.30,91.50,0.365
123.32,91.68,0.366
123.34,91.86,0.366
123.35,92.05,0.366
123.37,92.23,0.366
123.39,92.41,0.366
123.41,92.60,0.366
123.43,92.78,0.366
123.45,92.96,0.366
123.46,93.15,0.367
123.48,93.33,0.367
123.50,93.51,0.367
123.52,93.70,0.367
123.54,93.88,0.367
123.56,94.06,0.367
123.58,94.25,0.367
123.59,94.43,0.368
123.61,94.62,0.368
123.63,94.80,0.368
123.65,94.98,0.368
123.67,95.17,0.368
123.69,95.35,0.368
123.70,95.53,0.368
123.72,95.72,0.369
123.74,95.90,0.369
123.76,96.08,0.369
123.78,96.27,0.369
123.80,96.45,0.369
123.81,96.63,0.369
123.83,96.82,0.369
123.85,97.00,0.370
123.87,97.18,0.370
123.89,97.37,0.370
123.90,97.55,0.370
123.92,97.73,0.370
123.94,97.92,0.370
123.96,98.10,0.370
123.98,98.29,0.371
124.00,98.47,0.371
124.01,98.65,0.371
124.03,98.84,0.371
124.05,99.02,0.371
124.07,99.20,0.372
124.09,99.39,0.372
124.11,99.57,0.372
124.13,99.75,0.372
124.14,99.94,0.372
124.16,100.12,0.372
124.18,100.30,0.372
124.20,100.49,0.372
124.22,100.67,0.373
124.24,100.85,0.373
124.25,101.04,0.373
124.27,101.22,0.373
124.29,101.41,0.373
124.31,101.59,0.373
124.33,101.77,0.373
124.35,101.96,0.373
124.36,102.14,0.373
124.38,102.32,0.373
124.40,102.50,0.374
124.42,102.69,0.374
124.44,102.87,0.374
124.45,103.06,0.374
124.47,103.24,0.374
124.49,103.42,0.374
124.51,103.61,0.374
124.53,103.79,0.374
124.55,103.97,0.375
124.56,104.16,0.375
124.58,104.34,0.375
124.60,104.52,0.375
124.62,104.71,0.375
124.64,104.89,0.375
124.66,105.08,0.375
124.68,105.26,0.376
124.69,105.44,0.376
124.71,105.63,0.376
124.73,105.81,0.376
124.75,105.99,0.376
124.77,106.18,0.376
124.79,106.36,0.376
124.80,106.54,0.376
124.82,106.73,0.377
124.84,106.91,0.377
124.86,107.09,0.377
124.88,107.28,0.377
124.90,107.46,0.377
124.91,107.64,0.377
124.93,107.83,0.377
124.95,108.01,0.377
124.97,108.19,0.378
124.99,108.38,0.378
125.00,108.56,0.378
125.02,108.75,0.378
125.04,108.93,0.378
125.06,109.11,0.378
125.08,109.30,0.378
125.10,109.48,0.379
125.11,109.66,0.379
125.13,109.85,0.379
125.15,110.03,0.379
125.17,110.21,0.379
125.19,110.40,0.379
125.21,110.58,0.379
125.23,110.76,0.379
125.24,110.95,0.380
125.26,111.13,0.380
125.28,111.31,0.380
125.30,111.50,0.380
125.32,111.68,0.380
125.34,111.86,0.380
125.35,112.05,0.380
125.37,112.23,0.380
125.39,112.41,0.381
125.41,112.60,0.381
125.43,112.78,0.381
125.45,112.97,0.381
125.46,113.15,0.381
125.48,113.33,0.382
125.50,113.52,0.382
125.52,113.70,0.382
125.54,113.89,0.382
125.55,114.07,0.382
125.57,114.25,0.382
125.59,114.44,0.383
125.61,114.62,0.383
125.63,114.80,0.383
125.65,114.99,0.383
125.66,115.17,0.383
125.68,115.35,0.383
125.70,115.54,0.383
125.72,115.72,0.383
125.74,115.90,0.383
125.76,116.09,0.383
125.78,116.27,0.383
125.79,116.45,0.383
125.81,116.64,0.384
125.83,116.82,0.384
125.85,117.00,0.384
125.87,117.19,0.384
125.89,117.37,0.384
125.90,117.55,0.384
125.92,117.74,0.384
125.94,117.92,0.384
125.96,118.10,0.384
125.98,118.29,0.384
126.00,118.47,0.384
126.01,118.65,0.385
126.03,118.84,0.385
126.05,119.02,0.385
126.07,119.20,0.385
126.09,119.39,0.385
126.10,119.57,0.385
126.12,119.75,0.386
126.14,119.94,0.386
126.16,120.12,0.386
126.18,120.31,0.386
126.20,120.49,0.386
126.21,120.67,0.386
126.23,120.86,0.386
126.25,121.04,0.387
126.27,121.22,0.387
126.29,121.41,0.387
126.31,121.59,0.387
126.33,121.77,0.387
126.34,121.96,0.387
126.36,122.14,0.387
126.38,122.32,0.388
126.40,122.51,0.388
126.42,122.69,0.388
126.44,122.87,0.388
126.45,123.06,0.388
126.47,123.24,0.388
126.49,123.42,0.388
126.51,123.61,0.389
126.53,123.79,0.389
126.55,123.97,0.389
126.56,124.16,0.389
126.58,124.34,0.389
126.60,124.52,0.389
126.62,124.71,0.389
126.64,124.89,0.390
126.65,125.07,0.390
126.67,125.26,0.390
126.69,125.44,0.390
126.71,125.62,0.390
126.73,125.81,0.390
126.75,125.99,0.391
126.76,126.17,0.391
126.78,126.36,0.391
126.80,126.54,0.391
126.82,126.72,0.391
126.84,126.91,0.391
126.86,127.09,0.391
126.88,127.27,0.392
126.89,127.46,0.392
126.91,127.64,0.392
126.93,127.83,0.392
126.95,128.01,0.392
126.97,128.19,0.392
126.99,128.38,0.392
127.00,128.56,0.393
127.02,128.74,0.393
127.04,128.93,0.393
127.06,129.11,0.393
127.08,129.29,0.393
127.10,129.48,0.393
127.11,129.66,0.393
127.13,129.84,0.394
127.15,130.03,0.394
127.17,130.21,0.394
127.19,130.39,0.394
127.20,130.58,0.394
127.22,130.76,0.394
127.24,130.94,0.394
127.26,131.13,0.394
127.28,131.31,0.395
127.30,131.49,0.395
127.31,131.68,0.395
127.33,131.86,0.395
127.35,132.04,0.395
127.37,132.23,0.395
127.39,132.41,0.396
127.41,132.59,0.396
127.43,132.78,0.396
127.44,132.96,0.396
127.46,133.15,0.396
127.48,133.33,0.396
127.50,133.51,0.396
127.52,133.70,0.397
127.54,133.88,0.397
127.55,134.06,0.397
127.57,134.25,0.397
127.59,134.43,0.397
127.61,134.61,0.397
127.63,134.80,0.397
127.65,134.98,0.398
127.66,135.16,0.398
127.68,135.35,0.398
127.70,135.53,0.398
127.72,135.71,0.398
127.74,135.90,0.398
127.75,136.08,0.398
127.77,136.26,0.399
127.79,136.45,0.399
127.81,136.63,0.399
127.83,136.81,0.399
127.85,137.00,0.399
127.86,137.18,0.399
127.88,137.36,0.399
127.90,137.55,0.400
127.92,137.73,0.400
127.94,137.91,0.400
127.96,138.10,0.400
127.98,138.28,0.400
127.99,138.47,0.400
128.01,138.65,0.401
128.03,138.83,0.401
128.05,139.02,0.401
128.07,139.20,0.401
128.09,139.38,0.401
128.10,139.57,0.401
128.12,139.75,0.401
128.14,139.93,0.402
128.16,140.12,0.402
128.18,140.30,0.402
128.20,140.48,0.402
128.21,140.67,0.402
128.23,140.85,0.402
128.25,141.03,0.403
128.27,141.22,0.403
128.29,141.40,0.403
128.30,141.58,0.403
128.32,141.77,0.403
128.34,141.95,0.403
128.36,142.13,0.404
128.38,142.32,0.404
128.40,142.50,0.404
128.41,142.68,0.404
128.43,142.87,0.404
128.45,143.05,0.404
128.47,143.24,0.405
128.49,143.42,0.405
128.51,143.60,0.405
128.53,143.78,0.405
128.54,143.97,0.405
128.56,144.15,0.405
128.58,144.33,0.405
128.60,144.52,0.406
128.62,144.70,0.406
128.64,144.89,0.406
128.65,145.07,0.406
128.67,145.25,0.406
128.69,145.44,0.406
128.71,145.62,0.407
128.73,145.80,0.407
128.75,145.99,0.407
128.76,146.17,0.407
128.78,146.35,0.407
128.80,146.54,0.407
128.82,146.72,0.407
128.84,146.90,0.408
128.85,147.09,0.408
128.87,147.27,0.408
128.89,147.46,0.408
128.91,147.64,0.408
128.93,147.82,0.408
128.95,148.01,0.408
128.96,148.19,0.409
128.98,148.37,0.409
129.00,148.56,0.409
129.02,148.74,0.409
129.04,148.92,0.409
129.06,149.11,0.409
129.08,149.29,0.409
129.09,149.47,0.410
129.11,149.66,0.410
129.13,149.84,0.410
129.15,150.02,0.410
129.17,150.21,0.410
129.19,150.39,0.410
129.20,150.57,0.411
129.22,150.76,0.411
129.24,150.94,0.411
129.26,151.12,0.411
129.28,151.31,0.411
129.30,151.49,0.411
129.31,151.67,0.411
129.33,151.86,0.412
129.35,152.04,0.412
129.37,152.22,0.412
129.39,152.41,0.412
129.40,152.59,0.412
129.42,152.78,0.412
129.44,152.96,0.412
129.46,153.14,0.413
129.48,153.33,0.413
129.50,153.51,0.413
129.51,153.69,0.413
129.53,153.88,0.413
129.55,154.06,0.413
129.57,154.24,0.414
129.59,154.43,0.414
129.61,154.61,0.414
129.63,154.79,0.414
129.64,154.98,0.414
129.66,155.16,0.414
129.68,155.34,0.414
129.70,155.53,0.414
129.72,155.71,0.415
129.74,155.89,0.415
129.75,156.08,0.415
129.77,156.26,0.415
129.79,156.44,0.415
129.81,156.63,0.415
129.83,156.81,0.415
129.85,156.99,0.416
129.86,157.18,0.416
129.88,157.36,0.416
129.90,157.54,0.416
129.92,157.73,0.416
129.94,157.91,0.416
129.95,158.09,0.416
129.97,158.28,0.417
129.99,158.46,0.417
130.01,158.65,0.417
130.03,158.83,0.417
130.05,159.01,0.417
130.06,159.19,0.417
130.08,159.38,0.417
130.10,159.56,0.418
130.12,159.74,0.418
130.14,159.93,0.418
130.16,160.11,0.418
130.18,160.29,0.418
130.19,160.48,0.418
130.21,160.66,0.418
130.23,160.85,0.419
130.25,161.03,0.419
130.27,161.21,0.419
130.29,161.40,0.419
130.30,161.58,0.419
130.32,161.76,0.419
130.34,161.95,0.420
130.36,162.13,0.420
130.38,162.31,0.420
130.40,162.50,0.420
130.41,162.68,0.420
130.43,162.86,0.420
130.45,163.05,0.421
130.47,163.23,0.421
130.49,163.41,0.421
130.50,163.60,0.421
130.52,163.78,0.421
130.54,163.96,0.421
130.56,164.15,0.422
130.58,164.33,0.422
130.60,164.51,0.422
130.61,164.70,0.422
130.63,164.88,0.422
130.65,165.06,0.422
130.67,165.25,0.422
130.69,165.43,0.423
130.71,165.61,0.423
130.73,165.80,0.423
130.74,165.98,0.423
130.76,166.16,0.423
130.78,166.35,0.423
130.80,166.53,0.423
130.82,166.71,0.424
130.84,166.90,0.424
130.85,167.08,0.424
130.87,167.26,0.424
130.89,167.45,0.424
130.91,167.63,0.425
130.93,167.82,0.425
130.95,168.00,0.425
130.96,168.18,0.425
130.98,168.37,0.425
131.00,168.55,0.425
131.02,168.73,0.425
131.04,168.92,0.426
131.05,169.10,0.426
131.07,169.28,0.426
131.09,169.47,0.426
131.11,169.65,0.426
131.13,169.83,0.426
131.15,170.02,0.427
131.16,170.20,0.427
131.18,170.38,0.427
131.20,170.57,0.427
131.22,170.75,0.427
131.24,170.93,0.428
131.26,171.12,0.428
131.28,171.30,0.428
131.29,171.48,0.428
131.31,171.67,0.428
131.33,171.85,0.429
131.35,172.03,0.429
131.37,172.22,0.429
131.39,172.40,0.429
131.40,172.58,0.430
131.42,172.77,0.430
131.44,172.95,0.430
131.46,173.13,0.430
131.48,173.32,0.431
131.50,173.50,0.431
131.51,173.68,0.431
131.53,173.87,0.431
131.55,174.05,0.432
131.57,174.23,0.432
131.59,174.42,0.432
131.60,174.60,0.432
131.62,174.79,0.432
131.64,174.97,0.432
131.66,175.15,0.433
131.68,175.34,0.433
131.70,175.52,0.433
131.71,175.70,0.433
131.73,175.89,0.433
131.75,176.07,0.433
131.77,176.25,0.433
131.79,176.44,0.433
131.81,176.62,0.434
131.83,176.80,0.434
131.84,176.99,0.434
131.86,177.17,0.434
131.88,177.35,0.434
131.90,177.54,0.434
131.92,177.72,0.434
131.94,177.90,0.434
131.95,178.09,0.435
131.97,178.27,0.435
131.99,178.45,0.435
132.01,178.64,0.435
132.03,178.82,0.435
132.05,179.00,0.435
132.06,179.19,0.435
132.08,179.37,0.435
132.10,179.56,0.436
132.12,179.74,0.436
132.14,179.92,0.436
132.15,180.10,0.436
132.17,180.29,0.436
132.19,180.47,0.436
132.21,180.65,0.436
132.23,180.84,0.437
132.25,181.02,0.437
132.26,181.21,0.437
132.28,181.39,0.437
132.30,181.57,0.437
132.32,181.75,0.437
132.34,181.94,0.438
132.36,182.12,0.438
132.38,182.30,0.438
132.39,182.49,0.438
132.41,182.67,0.438
132.43,182.85,0.439
132.45,183.04,0.439
132.47,183.22,0.439
132.49,183.40,0.439
132.50,183.59,0.439
132.52,183.77,0.440
132.54,183.96,0.440
132.56,184.14,0.440
132.58,184.32,0.440
132.60,184.51,0.440
132.61,184.69,0.440
132.63,184.87,0.441
132.65,185.06,0.441
132.67,185.24,0.441
132.69,185.42,0.441
132.70,185.61,0.441
132.72,185.79,0.442
132.74,185.97,0.442
132.76,186.16,0.442
132.78,186.34,0.442
132.80,186.52,0.442
132.81,186.71,0.443
132.83,186.89,0.443
132.85,187.07,0.443
132.87,187.26,0.443
132.89,187.44,0.443
132.91,187.62,0.443
132.93,187.81,0.443
132.94,187.99,0.444
132.96,188.17,0.444
132.98,188.36,0.444
133.00,188.54,0.444
133.02,188.72,0.444
133.04,188.91,0.445
133.05,189.09,0.445
133.07,189.27,0.445
133.09,189.46,0.445
133.11,189.64,0.445
133.13,189.82,0.445
133.15,190.01,0.446
133.16,190.19,0.446
133.18,190.38,0.446
133.20,190.56,0.446
133.22,190.74,0.446
133.24,190.93,0.447
133.25,191.11,0.447
133.27,191.29,0.447
133.29,191.47,0.447
133.31,191.66,0.447
133.33,191.84,0.447
133.35,192.02,0.448
133.36,192.21,0.448
133.38,192.39,0.448
133.40,192.57,0.448
133.42,192.76,0.449
133.44,192.94,0.449
133.46,193.12,0.449
133.48,193.31,0.449
133.49,193.49,0.450
133.51,193.67,0.450
133.53,193.86,0.450
133.55,194.04,0.451
133.57,194.22,0.451
133.59,194.41,0.451
133.60,194.59,0.451
133.62,194.77,0.452
133.64,194.96,0.452
133.66,195.14,0.452
133.68,195.32,0.453
133.70,195.51,0.453
133.71,195.69,0.453
133.73,195.87,0.453
133.75,196.06,0.454
133.77,196.24,0.454
133.79,196.42,0.455
133.80,196.61,0.455
133.82,196.79,0.455
133.84,196.98,0.456
133.86,197.16,0.456
133.88,197.34,0.456
133.90,197.52,0.456
133.91,197.71,0.457
133.93,197.89,
133.95,198.08,
133.97,198.26,
133.99,,