File: DSC/2025_04_12_CBD_Pro_MechanoChem_15min_n60C_200C_10Cmin.csv
Filename,2025_04_12_CBD_Pro_MechanoChem_15min_n60C_200C_10Cmin
Instrument name,DSC2A-00468 (192.168.1.100)
Operator,Yarger
rundate,4/12/2025
Sample name,2025_04_12_CBD_Pro_MechanoChem_15min_n60C_200C_10Cmin
proceduresegments,Data Off ; Equilibrate -60.00 °C; Data On ; Ramp 10.00 °C/min to 200.00 °C; Data Off ; Isothermal 1.0 min; Data On ; Ramp 10.00 °C/min to -60.00 °C; Data Off ; Isothermal 1.0 min; Data On ; Ramp 10.00 °C/min to 200.00 °C; Data Off ; Isothermal 1.0 min; Data On ; Ramp 10.00 °C/min to -60.00 °C; Data Off ; Isothermal 1.0 min; Data On ; Ramp 10.00 °C/min to 200.00 °C
[File Parameters]
Run date,4/12/2025 5:46:07 PM
Trios version,5.1.1.46572
Original File Name,
Current File Name,D:\DSC2500\JYarger\2025_04_12_CBD_Pro_MechanoChem_15min_n60C_200C_10Cmin.tri
[Procedure]
Procedure Name,CBD_Pro_n60_200C_10Cmin_x3
Sample Name,2025_04_12_CBD_Pro_MechanoChem_15min_n60C_200C_10Cmin
Sample Mass,6.52 mg
Reference Sample Mass,0 mg
Pan Mass,53.46 mg
Pan Number,21
Reference Pan Mass,53.32 mg
Reference Pan Number,10
Pan Type,Tzero Aluminum Hermetic
Comments,Hermetic Sealed Al DSC Consumables Pan/Lids.
Project Name,CA
Operator,Yarger
Test,Custom
Unload Max Temperature,30
Unload Min Temperature,30
Load Max Temperature,30
Load Min Temperature,30
Stop on Gas Flow Error,Yes
[Signal List]
Signal #1,Time (min)
Signal #2,Temperature (°C)
Signal #3,Heat Flow (mW)
Signal #4,Delta T (µV)
Signal #5,Delta Tzero (µV)
Signal #6,Tzero Temperature (°C)
Signal #7,Cell Purge (mL/min)
Signal #8,Heater Temp (°C)
Signal #9,Power Delivered (W)
Signal #10,Reference Junction Temperature (°C)
Signal #11,Flange Temperature (°C)
Signal #12,Heat Flow Phase (rad)
Signal #13,Total Heat Capacity (J/°C)
Signal #14,Heat Capacity (J/°C)
[Configuration]
Company Name,ASU
Instrument Name,DSC2A-00468
Instrument Type,DSC2500
Serial Number,DSC2A-00468
IP,192.168.1.100
Location of Instrument,MRRC
DisplayType,Unknown
Sample Interval ,0.1 s/pt
Selected Heat Flow,T4P
Exotherm Direction,Down
Cell Serial,DRC2-00792
Lid Type,Standard
Cooler,RCS 90
Leave Cooler on at End of Sequence,On
Gas 2,Nitrogen
Gas Selected,Channel 1
Flow Rate,50 mL/min
Secondary Purge,On
Licensed Heat Flow,Heat Flow T4P
Modulation Licensed,Yes
[Versions]
Common IDD Version,1
Cortex Version,VER 2.10.2.31
Driver,5.0.0.6
GDM Version,1.0.3.3
TouchscreenVersion,1.0.0.16145
FEP Version,1.2.1.21
FEP Bootloader,2.0.0.5
AutoSampler Version,2.1.1.26
Auto Sampler Bootloader,2.0.0.5
FCM Version,1.1.0.3
FCM Bootloader,2.0.0.5
[Experiment Logs]
Experiment Log Entry # 1,Air Cool is off.
Experiment Log Entry # 3,Data On set to 0
Experiment Log Entry # 5,Equilibrate Segment -60 (C) Started
Experiment Log Entry # 7,Data On set to 1
Experiment Log Entry # 9,Ramp Segment 10 C/min to 200 Started
Experiment Log Entry # 11,Data On set to 0
Experiment Log Entry # 13,Isothermal Segment 1 min started
Experiment Log Entry # 15,Data On set to 1
Experiment Log Entry # 17,Ramp Segment 10 C/min to -60 Started
Experiment Log Entry # 19,Data On set to 0
Experiment Log Entry # 21,Isothermal Segment 1 min started
Experiment Log Entry # 23,Data On set to 1
Experiment Log Entry # 25,Ramp Segment 10 C/min to 200 Started
Experiment Log Entry # 27,Data On set to 0
Experiment Log Entry # 29,Isothermal Segment 1 min started
Experiment Log Entry # 31,Data On set to 1
Experiment Log Entry # 33,Ramp Segment 10 C/min to -60 Started
Experiment Log Entry # 35,Data On set to 0
Experiment Log Entry # 37,Isothermal Segment 1 min started
Experiment Log Entry # 39,Data On set to 1
Experiment Log Entry # 41,Ramp Segment 10 C/min to 200 Started
[Method Log]
Method Log Entry # 1,Data Off
Method Log Entry # 2,Equilibrate -60 °C
Method Log Entry # 3,Data On
Method Log Entry # 4,(Ramp 186035) Ramp 10 °C/minute to 200 °C
Method Log Entry # 5,Data Off
Method Log Entry # 6,Isothermal 1 minutes
Method Log Entry # 7,Data On
Method Log Entry # 8,(Ramp 186039) Ramp 10 °C/minute to -60 °C
Method Log Entry # 9,Data Off
Method Log Entry # 10,Isothermal 1 minutes
Method Log Entry # 11,Data On
Method Log Entry # 12,(Ramp 186043) Ramp 10 °C/minute to 200 °C
Method Log Entry # 13,Data Off
Method Log Entry # 14,Isothermal 1 minutes
Method Log Entry # 15,Data On
Method Log Entry # 16,(Ramp 186047) Ramp 10 °C/minute to -60 °C
Method Log Entry # 17,Data Off
Method Log Entry # 18,Isothermal 1 minutes
Method Log Entry # 19,Data On
Method Log Entry # 20,(Ramp 186051) Ramp 10 °C/minute to 200 °C
Cell Serial,DRC2-00792
[T1 Calibration]
Slope,-0.008529666
Offset,9.636258
Initial Temperature,98.23
GUID,f8bfdadc-4977-4fdf-ba6d-0ba9134940c3
[TZero Calibration]
Date Applied,11/29/2022 4:06:13 PM
Description,From -89.059 °C to 396.009 °C at 20.000°C/min
Gas Type,Nitrogen
Pan Type,None
Source Files 1,C:\Users\yargerlab\Desktop\DSC Data\General\TZero_calibration_11_29_22_2nd(2).tri
Source Files 2,C:\Users\yargerlab\Desktop\DSC Data\General\TZero_calibration_11_29_22_2nd(3).tri
Delta T Offset,13.05235
Delta T Slope,-0.007271007
Delta T0 Offset,-13.69128
Delta T0 Slope,0.06063341
[Temperature Calibration]
Date Applied,11/29/2022 7:12:28 PM
Description,From 106.590 °C to 186.590 °C at 10.000°C/min
Gas Type,Nitrogen
Pan Type,Tzero Aluminum Hermetic
Source Files 1,C:\Users\yargerlab\Desktop\DSC Data\General\Indium(6).tri
Measured 1,157.391
Known 1,156.598
[Cell Constant Calibration]
Date Applied,11/29/2022 7:12:29 PM
Description,From 106.590 °C to 186.590 °C at 10.000°C/min
Gas Type,Nitrogen
Pan Type,Tzero Aluminum Hermetic
Source Files 1,C:\Users\yargerlab\Desktop\DSC Data\General\Indium(6).tri
T4P KCell,1.006051
Onset Slope,63.26126 mW/°C
[Direct Cp Calibration]
Date Applied,11/30/2022 11:04:51 AM
Description,From -79.983 °C to 298.409 °C at 10.000°C/min
Gas Type,Nitrogen
Pan Type,Tzero Aluminum Hermetic
Source Files 1,C:\Users\yargerlab\Desktop\DSC Data\General\Sapphire_Heat_Capacity_11_30_22.tri
[Rev Cp Calibration]
Date Applied,11/30/2022 1:58:51 PM
Description,From -79.996 °C to 292.812 °C at 3.000°C/min
Gas Type,Nitrogen
Pan Type,Tzero Aluminum Hermetic
Source Files 1,C:\Users\yargerlab\Desktop\DSC Data\General\Sapphire_MDSC_Calibration_11_30_22.tri
[step]
Ramp 10.00 °C/min to 200.00 °C
Time,Temperature,Heat Flow (Normalized)
min,°C,W/g
0.00,-59.68,-0.044
0.02,-59.69,-0.043
0.04,-59.70,-0.038
0.05,-59.70,-0.030
0.07,-59.69,-0.019
0.09,-59.66,-0.007
0.11,-59.61,0.006
0.13,-59.54,0.020
0.15,-59.45,0.035
0.16,-59.35,0.050
0.18,-59.22,0.065
0.20,-59.09,0.080
0.22,-58.95,0.093
0.24,-58.81,0.106
0.26,-58.66,0.117
0.28,-58.50,0.128
0.29,-58.34,0.138
0.31,-58.18,0.145
0.33,-58.02,0.154
0.35,-57.85,0.159
0.37,-57.68,0.166
0.39,-57.51,0.170
0.40,-57.34,0.175
0.42,-57.17,0.179
0.44,-57.00,0.182
0.46,-56.83,0.185
0.48,-56.66,0.188
0.50,-56.48,0.189
0.51,-56.31,0.192
0.53,-56.13,0.193
0.55,-55.95,0.195
0.57,-55.78,0.196
0.59,-55.60,0.197
0.60,-55.42,0.198
0.62,-55.25,0.199
0.64,-55.07,0.199
0.66,-54.89,0.200
0.68,-54.71,0.200
0.70,-54.53,0.200
0.72,-54.35,0.201
0.73,-54.17,0.201
0.75,-54.00,0.202
0.77,-53.82,0.202
0.79,-53.64,0.202
0.81,-53.46,0.203
0.83,-53.28,0.203
0.84,-53.10,0.203
0.86,-52.92,0.203
0.88,-52.74,0.204
0.90,-52.55,0.204
0.92,-52.37,0.204
0.93,-52.19,0.204
0.95,-52.01,0.205
0.97,-51.83,0.205
0.99,-51.65,0.205
1.01,-51.47,0.206
1.03,-51.29,0.206
1.05,-51.11,0.206
1.06,-50.92,0.206
1.08,-50.74,0.206
1.10,-50.56,0.207
1.12,-50.38,0.207
1.14,-50.20,0.207
1.16,-50.02,0.207
1.17,-49.83,0.207
1.19,-49.65,0.207
1.21,-49.47,0.208
1.23,-49.29,0.208
1.25,-49.10,0.208
1.27,-48.92,0.208
1.28,-48.74,0.208
1.30,-48.56,0.208
1.32,-48.38,0.208
1.34,-48.19,0.209
1.36,-48.01,0.209
1.38,-47.83,0.209
1.39,-47.64,0.209
1.41,-47.46,0.209
1.43,-47.28,0.209
1.45,-47.10,0.209
1.47,-46.91,0.209
1.48,-46.73,0.209
1.50,-46.55,0.210
1.52,-46.37,0.210
1.54,-46.18,0.210
1.56,-46.00,0.210
1.58,-45.82,0.210
1.59,-45.63,0.210
1.61,-45.45,0.210
1.63,-45.27,0.210
1.65,-45.08,0.210
1.67,-44.90,0.211
1.69,-44.72,0.211
1.71,-44.54,0.211
1.72,-44.35,0.211
1.74,-44.17,0.211
1.76,-43.98,0.211
1.78,-43.80,0.211
1.80,-43.62,0.211
1.82,-43.44,0.211
1.83,-43.25,0.211
1.85,-43.07,0.211
1.87,-42.89,0.211
1.89,-42.70,0.212
1.91,-42.52,0.212
1.93,-42.33,0.212
1.94,-42.15,0.212
1.96,-41.97,0.212
1.98,-41.79,0.212
2.00,-41.60,0.212
2.02,-41.42,0.212
2.03,-41.24,0.212
2.05,-41.05,0.212
2.07,-40.87,0.212
2.09,-40.69,0.212
2.11,-40.50,0.212
2.13,-40.32,0.213
2.14,-40.13,0.213
2.16,-39.95,0.213
2.18,-39.77,0.213
2.20,-39.58,0.213
2.22,-39.40,0.213
2.24,-39.22,0.213
2.26,-39.03,0.213
2.27,-38.85,0.213
2.29,-38.67,0.213
2.31,-38.48,0.214
2.33,-38.30,0.214
2.35,-38.12,0.214
2.36,-37.93,0.214
2.38,-37.75,0.214
2.40,-37.56,0.214
2.42,-37.38,0.214
2.44,-37.20,0.214
2.46,-37.02,0.214
2.48,-36.83,0.214
2.49,-36.65,0.214
2.51,-36.46,0.214
2.53,-36.28,0.215
2.55,-36.10,0.215
2.57,-35.92,0.215
2.59,-35.73,0.215
2.60,-35.55,0.215
2.62,-35.36,0.215
2.64,-35.18,0.215
2.66,-35.00,0.215
2.68,-34.81,0.215
2.69,-34.63,0.215
2.71,-34.44,0.215
2.73,-34.26,0.215
2.75,-34.08,0.216
2.77,-33.90,0.216
2.79,-33.71,0.216
2.81,-33.53,0.216
2.82,-33.34,0.216
2.84,-33.16,0.216
2.86,-32.98,0.216
2.88,-32.79,0.216
2.90,-32.61,0.216
2.91,-32.43,0.216
2.93,-32.24,0.217
2.95,-32.06,0.217
2.97,-31.88,0.217
2.99,-31.69,0.217
3.01,-31.51,0.217
3.03,-31.32,0.217
3.04,-31.14,0.217
3.06,-30.96,0.217
3.08,-30.78,0.217
3.10,-30.59,0.217
3.12,-30.41,0.217
3.14,-30.22,0.218
3.15,-30.04,0.218
3.17,-29.86,0.218
3.19,-29.67,0.218
3.21,-29.49,0.218
3.23,-29.31,0.218
3.24,-29.12,0.218
3.26,-28.94,0.218
3.28,-28.76,0.218
3.30,-28.57,0.218
3.32,-28.39,0.219
3.34,-28.20,0.219
3.36,-28.02,0.219
3.37,-27.84,0.219
3.39,-27.65,0.219
3.41,-27.47,0.219
3.43,-27.29,0.219
3.45,-27.10,0.219
3.46,-26.92,0.219
3.48,-26.73,0.219
3.50,-26.55,0.219
3.52,-26.37,0.220
3.54,-26.19,0.220
3.56,-26.00,0.220
3.58,-25.82,0.220
3.59,-25.64,0.220
3.61,-25.45,0.220
3.63,-25.27,0.220
3.65,-25.08,0.220
3.67,-24.90,0.220
3.69,-24.72,0.220
3.70,-24.53,0.221
3.72,-24.35,0.221
3.74,-24.17,0.221
3.76,-23.98,0.221
3.78,-23.80,0.221
3.79,-23.61,0.221
3.81,-23.43,0.221
3.83,-23.25,0.221
3.85,-23.06,0.221
3.87,-22.88,0.221
3.89,-22.70,0.221
3.91,-22.51,0.222
3.92,-22.33,0.222
3.94,-22.15,0.222
3.96,-21.96,0.222
3.98,-21.78,0.222
4.00,-21.60,0.222
4.01,-21.41,0.222
4.03,-21.23,0.222
4.05,-21.05,0.222
4.07,-20.86,0.222
4.09,-20.68,0.223
4.11,-20.49,0.223
4.13,-20.31,0.223
4.14,-20.13,0.223
4.16,-19.94,0.223
4.18,-19.76,0.223
4.20,-19.58,0.223
4.22,-19.39,0.223
4.24,-19.21,0.223
4.25,-19.02,0.224
4.27,-18.84,0.224
4.29,-18.66,0.224
4.31,-18.47,0.224
4.33,-18.29,0.224
4.35,-18.11,0.224
4.36,-17.93,0.224
4.38,-17.74,0.224
4.40,-17.56,0.224
4.42,-17.37,0.224
4.44,-17.19,0.224
4.45,-17.01,0.224
4.47,-16.82,0.225
4.49,-16.64,0.225
4.51,-16.46,0.225
4.53,-16.27,0.225
4.55,-16.09,0.225
4.56,-15.90,0.225
4.58,-15.72,0.225
4.60,-15.54,0.225
4.62,-15.35,0.225
4.64,-15.17,0.226
4.66,-14.99,0.226
4.68,-14.80,0.226
4.69,-14.62,0.226
4.71,-14.44,0.226
4.73,-14.25,0.226
4.75,-14.07,0.226
4.77,-13.89,0.226
4.79,-13.70,0.227
4.80,-13.52,0.227
4.82,-13.34,0.227
4.84,-13.15,0.227
4.86,-12.97,0.227
4.88,-12.79,0.227
4.90,-12.60,0.227
4.91,-12.42,0.227
4.93,-12.24,0.228
4.95,-12.05,0.228
4.97,-11.87,0.228
4.99,-11.68,0.228
5.00,-11.50,0.228
5.02,-11.32,0.228
5.04,-11.13,0.228
5.06,-10.95,0.228
5.08,-10.77,0.228
5.10,-10.58,0.229
5.11,-10.40,0.229
5.13,-10.22,0.229
5.15,-10.03,0.229
5.17,-9.85,0.229
5.19,-9.67,0.229
5.21,-9.48,0.229
5.23,-9.30,0.230
5.24,-9.12,0.230
5.26,-8.93,0.230
5.28,-8.75,0.230
5.30,-8.56,0.230
5.32,-8.38,0.230
5.34,-8.20,0.230
5.35,-8.01,0.231
5.37,-7.83,0.231
5.39,-7.65,0.231
5.41,-7.46,0.231
5.43,-7.28,0.231
5.45,-7.10,0.231
5.46,-6.91,0.231
5.48,-6.73,0.232
5.50,-6.55,0.232
5.52,-6.36,0.232
5.54,-6.18,0.232
5.55,-6.00,0.232
5.57,-5.81,0.232
5.59,-5.63,0.232
5.61,-5.45,0.232
5.63,-5.26,0.233
5.65,-5.08,0.233
5.66,-4.89,0.233
5.68,-4.71,0.233
5.70,-4.53,0.233
5.72,-4.34,0.233
5.74,-4.16,0.233
5.76,-3.98,0.233
5.78,-3.79,0.234
5.79,-3.61,0.234
5.81,-3.43,0.234
5.83,-3.24,0.234
5.85,-3.06,0.234
5.87,-2.88,0.234
5.89,-2.69,0.234
5.90,-2.51,0.234
5.92,-2.32,0.235
5.94,-2.14,0.235
5.96,-1.96,0.235
5.98,-1.77,0.235
6.00,-1.59,0.235
6.01,-1.41,0.235
6.03,-1.22,0.235
6.05,-1.04,0.235
6.07,-0.86,0.235
6.09,-0.67,0.236
6.10,-0.49,0.236
6.12,-0.31,0.236
6.14,-0.12,0.236
6.16,0.06,0.236
6.18,0.25,0.236
6.20,0.43,0.236
6.21,0.61,0.236
6.23,0.80,0.236
6.25,0.98,0.237
6.27,1.16,0.237
6.29,1.35,0.237
6.31,1.53,0.237
6.33,1.71,0.237
6.34,1.90,0.237
6.36,2.08,0.237
6.38,2.26,0.237
6.40,2.45,0.238
6.42,2.63,0.238
6.44,2.82,0.238
6.45,3.00,0.238
6.47,3.18,0.238
6.49,3.37,0.238
6.51,3.55,0.238
6.53,3.73,0.238
6.55,3.92,0.239
6.56,4.10,0.239
6.58,4.28,0.239
6.60,4.47,0.239
6.62,4.65,0.239
6.64,4.83,0.239
6.65,5.02,0.239
6.67,5.20,0.239
6.69,5.38,0.240
6.71,5.57,0.240
6.73,5.75,0.240
6.75,5.94,0.240
6.76,6.12,0.240
6.78,6.30,0.240
6.80,6.49,0.240
6.82,6.67,0.241
6.84,6.85,0.241
6.86,7.04,0.241
6.88,7.22,0.241
6.89,7.40,0.241
6.91,7.59,0.241
6.93,7.77,0.241
6.95,7.95,0.242
6.97,8.14,0.242
6.99,8.32,0.242
7.00,8.51,0.242
7.02,8.69,0.242
7.04,8.87,0.242
7.06,9.06,0.242
7.08,9.24,0.242
7.10,9.42,0.243
7.11,9.61,0.243
7.13,9.79,0.243
7.15,9.97,0.243
7.17,10.16,0.243
7.19,10.34,0.244
7.20,10.52,0.244
7.22,10.71,0.244
7.24,10.89,0.244
7.26,11.07,0.244
7.28,11.26,0.244
7.30,11.44,0.244
7.31,11.63,0.244
7.33,11.81,0.245
7.35,11.99,0.245
7.37,12.18,0.245
7.39,12.36,0.245
7.41,12.54,0.245
7.43,12.73,0.245
7.44,12.91,0.245
7.46,13.09,0.246
7.48,13.28,0.246
7.50,13.46,0.246
7.52,13.64,0.246
7.54,13.83,0.246
7.55,14.01,0.246
7.57,14.19,0.246
7.59,14.38,0.246
7.61,14.56,0.247
7.63,14.74,0.247
7.65,14.93,0.247
7.66,15.11,0.247
7.68,15.29,0.247
7.70,15.48,0.247
7.72,15.66,0.247
7.74,15.84,0.248
7.75,16.03,0.248
7.77,16.21,0.248
7.79,16.40,0.248
7.81,16.58,0.248
7.83,16.76,0.248
7.85,16.95,0.249
7.86,17.13,0.249
7.88,17.31,0.249
7.90,17.50,0.249
7.92,17.68,0.249
7.94,17.86,0.249
7.96,18.05,0.249
7.98,18.23,0.249
7.99,18.42,0.250
8.01,18.60,0.250
8.03,18.78,0.250
8.05,18.97,0.250
8.07,19.15,0.250
8.09,19.33,0.250
8.10,19.52,0.251
8.12,19.70,0.251
8.14,19.88,0.251
8.16,20.07,0.251
8.18,20.25,0.251
8.20,20.43,0.251
8.21,20.62,0.252
8.23,20.80,0.252
8.25,20.98,0.252
8.27,21.17,0.252
8.29,21.35,0.252
8.30,21.53,0.252
8.32,21.72,0.253
8.34,21.90,0.253
8.36,22.08,0.253
8.38,22.27,0.253
8.40,22.45,0.253
8.41,22.64,0.253
8.43,22.82,0.253
8.45,23.00,0.254
8.47,23.19,0.254
8.49,23.37,0.254
8.51,23.55,0.254
8.53,23.74,0.254
8.54,23.92,0.254
8.56,24.10,0.254
8.58,24.29,0.254
8.60,24.47,0.255
8.62,24.65,0.255
8.63,24.84,0.255
8.65,25.02,0.255
8.67,25.20,0.255
8.69,25.39,0.255
8.71,25.57,0.255
8.73,25.76,0.256
8.75,25.94,0.256
8.76,26.12,0.256
8.78,26.31,0.256
8.80,26.49,0.256
8.82,26.67,0.256
8.84,26.86,0.257
8.85,27.04,0.257
8.87,27.22,0.257
8.89,27.41,0.257
8.91,27.59,0.257
8.93,27.77,0.257
8.95,27.96,0.257
8.97,28.14,0.258
8.98,28.32,0.258
9.00,28.51,0.258
9.02,28.69,0.258
9.04,28.88,0.258
9.06,29.06,0.258
9.08,29.24,0.258
9.09,29.43,0.259
9.11,29.61,0.259
9.13,29.79,0.259
9.15,29.98,0.259
9.17,30.16,0.259
9.18,30.34,0.259
9.20,30.53,0.259
9.22,30.71,0.260
9.24,30.89,0.260
9.26,31.08,0.260
9.28,31.26,0.260
9.30,31.44,0.260
9.31,31.63,0.260
9.33,31.81,0.260
9.35,32.00,0.261
9.37,32.18,0.261
9.39,32.36,0.261
9.40,32.54,0.261
9.42,32.73,0.261
9.44,32.91,0.261
9.46,33.10,0.261
9.48,33.28,0.262
9.50,33.46,0.262
9.52,33.65,0.262
9.53,33.83,0.262
9.55,34.01,0.262
9.57,34.20,0.262
9.59,34.38,0.262
9.61,34.57,0.263
9.63,34.75,0.263
9.64,34.93,0.263
9.66,35.12,0.263
9.68,35.30,0.263
9.70,35.48,0.263
9.72,35.67,0.263
9.73,35.85,0.263
9.75,36.03,0.264
9.77,36.22,0.264
9.79,36.40,0.264
9.81,36.58,0.264
9.83,36.77,0.264
9.85,36.95,0.264
9.86,37.13,0.264
9.88,37.32,0.265
9.90,37.50,0.265
9.92,37.68,0.265
9.94,37.87,0.265
9.95,38.05,0.265
9.97,38.23,0.265
9.99,38.42,0.266
10.01,38.60,0.266
10.03,38.78,0.266
10.05,38.97,0.266
10.07,39.15,0.266
10.08,39.34,0.266
10.10,39.52,0.266
10.12,39.70,0.267
10.14,39.89,0.267
10.16,40.07,0.267
10.18,40.25,0.267
10.19,40.44,0.267
10.21,40.62,0.267
10.23,40.80,0.268
10.25,40.99,0.268
10.27,41.17,0.268
10.28,41.35,0.268
10.30,41.54,0.268
10.32,41.72,0.268
10.34,41.90,0.268
10.36,42.09,0.269
10.38,42.27,0.269
10.40,42.45,0.269
10.41,42.64,0.269
10.43,42.82,0.269
10.45,43.01,0.270
10.47,43.19,0.270
10.49,43.37,0.270
10.50,43.56,0.270
10.52,43.74,0.270
10.54,43.92,0.270
10.56,44.11,0.271
10.58,44.29,0.271
10.60,44.47,0.271
10.62,44.66,0.271
10.63,44.84,0.271
10.65,45.02,0.271
10.67,45.21,0.271
10.69,45.39,0.272
10.71,45.57,0.272
10.73,45.76,0.272
10.74,45.94,0.272
10.76,46.12,0.272
10.78,46.31,0.272
10.80,46.49,0.273
10.82,46.67,0.273
10.83,46.86,0.273
10.85,47.04,0.273
10.87,47.22,0.273
10.89,47.41,0.274
10.91,47.59,0.274
10.93,47.77,0.274
10.95,47.96,0.274
10.96,48.14,0.274
10.98,48.32,0.274
11.00,48.51,0.275
11.02,48.69,0.275
11.04,48.88,0.275
11.05,49.06,0.275
11.07,49.24,0.275
11.09,49.43,0.276
11.11,49.61,0.276
11.13,49.79,0.276
11.15,49.98,0.276
11.17,50.16,0.277
11.18,50.34,0.277
11.20,50.53,0.277
11.22,50.71,0.277
11.24,50.89,0.277
11.26,51.08,0.278
11.28,51.26,0.278
11.29,51.44,0.278
11.31,51.63,0.278
11.33,51.81,0.278
11.35,51.99,0.278
11.37,52.18,0.279
11.38,52.36,0.279
11.40,52.54,0.279
11.42,52.73,0.279
11.44,52.91,0.280
11.46,53.10,0.280
11.48,53.28,0.280
11.50,53.46,0.280
11.51,53.65,0.281
11.53,53.83,0.281
11.55,54.01,0.281
11.57,54.20,0.281
11.59,54.38,0.281
11.60,54.56,0.282
11.62,54.75,0.282
11.64,54.93,0.282
11.66,55.11,0.282
11.68,55.30,0.282
11.70,55.48,0.283
11.72,55.66,0.283
11.73,55.85,0.283
11.75,56.03,0.284
11.77,56.22,0.284
11.79,56.40,0.284
11.81,56.58,0.285
11.83,56.77,0.285
11.84,56.95,0.285
11.86,57.13,0.285
11.88,57.32,0.286
11.90,57.50,0.286
11.92,57.68,0.286
11.93,57.87,0.287
11.95,58.05,0.287
11.97,58.23,0.287
11.99,58.42,0.288
12.01,58.60,0.288
12.03,58.78,0.288
12.05,58.97,0.289
12.06,59.15,0.289
12.08,59.33,0.290
12.10,59.52,0.290
12.12,59.70,0.291
12.14,59.88,0.291
12.15,60.07,0.292
12.17,60.25,0.293
12.19,60.43,0.293
12.21,60.62,0.294
12.23,60.80,0.295
12.25,60.98,0.296
12.27,61.17,0.297
12.28,61.35,0.298
12.30,61.53,0.300
12.32,61.72,0.301
12.34,61.90,0.304
12.36,62.08,0.305
12.38,62.26,0.307
12.39,62.45,0.310
12.41,62.63,0.313
12.43,62.81,0.316
12.45,62.99,0.319
12.47,63.18,0.324
12.48,63.36,0.329
12.50,63.54,0.333
12.52,63.72,0.341
12.54,63.90,0.349
12.56,64.08,0.360
12.58,64.26,0.370
12.60,64.44,0.383
12.61,64.62,0.398
12.63,64.80,0.416
12.65,64.98,0.435
12.67,65.16,0.458
12.69,65.33,0.480
12.70,65.51,0.505
12.72,65.68,0.531
12.74,65.85,0.558
12.76,66.03,0.585
12.78,66.20,0.613
12.80,66.37,0.640
12.82,66.54,0.668
12.83,66.71,0.698
12.85,66.88,0.726
12.87,67.06,0.754
12.89,67.23,0.782
12.91,67.40,0.808
12.93,67.57,0.834
12.94,67.74,0.860
12.96,67.91,0.885
12.98,68.08,0.908
13.00,68.26,0.929
13.02,68.43,0.948
13.03,68.60,0.967
13.05,68.78,0.986
13.07,68.95,1.004
13.09,69.13,1.020
13.11,69.30,1.034
13.13,69.48,1.045
13.15,69.66,1.054
13.16,69.83,1.062
13.18,70.01,1.065
13.20,70.19,1.069
13.22,70.37,1.072
13.24,70.55,1.072
13.25,70.74,1.069
13.27,70.92,1.066
13.29,71.10,1.058
13.31,71.29,1.046
13.33,71.47,1.034
13.35,71.66,1.020
13.37,71.85,1.004
13.38,72.04,0.984
13.40,72.23,0.959
13.42,72.42,0.929
13.44,72.61,0.899
13.46,72.81,0.863
13.48,73.00,0.827
13.49,73.20,0.787
13.51,73.40,0.743
13.53,73.60,0.700
13.55,73.80,0.661
13.57,74.00,0.625
13.58,74.20,0.591
13.60,74.40,0.560
13.62,74.60,0.533
13.64,74.80,0.509
13.66,74.99,0.488
13.68,75.19,0.468
13.70,75.38,0.452
13.71,75.58,0.437
13.73,75.77,0.424
13.75,75.96,0.413
13.77,76.15,0.402
13.79,76.34,0.394
13.80,76.53,0.385
13.82,76.72,0.379
13.84,76.90,0.373
13.86,77.09,0.367
13.88,77.28,0.363
13.90,77.46,0.359
13.92,77.65,0.356
13.93,77.84,0.353
13.95,78.02,0.350
13.97,78.21,0.347
13.99,78.39,0.346
14.01,78.58,0.344
14.03,78.76,0.343
14.04,78.95,0.341
14.06,79.13,0.340
14.08,79.32,0.339
14.10,79.50,0.339
14.12,79.69,0.338
14.13,79.87,0.337
14.15,80.05,0.337
14.17,80.24,0.336
14.19,80.42,0.336
14.21,80.60,0.335
14.23,80.79,0.335
14.25,80.97,0.335
14.26,81.16,0.334
14.28,81.34,0.334
14.30,81.52,0.334
14.32,81.71,0.334
14.34,81.89,0.333
14.35,82.07,0.333
14.37,82.26,0.333
14.39,82.44,0.333
14.41,82.63,0.332
14.43,82.81,0.332
14.45,82.99,0.332
14.47,83.18,0.332
14.48,83.36,0.332
14.50,83.54,0.332
14.52,83.73,0.332
14.54,83.91,0.331
14.56,84.09,0.331
14.58,84.28,0.331
14.59,84.46,0.331
14.61,84.65,0.331
14.63,84.83,0.331
14.65,85.01,0.331
14.67,85.20,0.330
14.68,85.38,0.330
14.70,85.56,0.330
14.72,85.75,0.330
14.74,85.93,0.330
14.76,86.11,0.330
14.78,86.30,0.330
14.80,86.48,0.330
14.81,86.66,0.330
14.83,86.85,0.330
14.85,87.03,0.330
14.87,87.22,0.330
14.89,87.40,0.330
14.90,87.58,0.329
14.92,87.77,0.329
14.94,87.95,0.329
14.96,88.13,0.329
14.98,88.32,0.329
15.00,88.50,0.329
15.02,88.68,0.329
15.03,88.87,0.329
15.05,89.05,0.329
15.07,89.23,0.329
15.09,89.42,0.329
15.11,89.60,0.329
15.13,89.79,0.329
15.14,89.97,0.329
15.16,90.15,0.329
15.18,90.34,0.329
15.20,90.52,0.329
15.22,90.70,0.329
15.23,90.89,0.328
15.25,91.07,0.328
15.27,91.26,0.328
15.29,91.44,0.328
15.31,91.62,0.328
15.33,91.81,0.328
15.35,91.99,0.328
15.36,92.17,0.328
15.38,92.36,0.327
15.40,92.54,0.327
15.42,92.72,0.327
15.44,92.91,0.327
15.45,93.09,0.327
15.47,93.27,0.326
15.49,93.46,0.326
15.51,93.64,0.326
15.53,93.83,0.325
15.55,94.01,0.325
15.57,94.19,0.325
15.58,94.38,0.324
15.60,94.56,0.324
15.62,94.74,0.323
15.64,94.93,0.323
15.66,95.11,0.323
15.68,95.30,0.322
15.69,95.48,0.321
15.71,95.66,0.321
15.73,95.85,0.320
15.75,96.03,0.320
15.77,96.21,0.319
15.78,96.40,0.318
15.80,96.58,0.317
15.82,96.77,0.316
15.84,96.95,0.315
15.86,97.14,0.313
15.88,97.32,0.313
15.90,97.50,0.312
15.91,97.69,0.310
15.93,97.87,0.309
15.95,98.06,0.307
15.97,98.24,0.306
15.99,98.43,0.303
16.00,98.61,0.302
16.02,98.79,0.301
16.04,98.98,0.298
16.06,99.16,0.297
16.08,99.35,0.295
16.10,99.53,0.294
16.12,99.71,0.292
16.13,99.90,0.290
16.15,100.08,0.288
16.17,100.27,0.287
16.19,100.45,0.284
16.21,100.64,0.282
16.23,100.82,0.279
16.24,101.00,0.277
16.26,101.19,0.275
16.28,101.37,0.273
16.30,101.56,0.271
16.32,101.74,0.269
16.33,101.92,0.266
16.35,102.11,0.264
16.37,102.29,0.261
16.39,102.48,0.259
16.41,102.66,0.256
16.43,102.85,0.254
16.45,103.03,0.252
16.46,103.22,0.249
16.48,103.40,0.246
16.50,103.59,0.244
16.52,103.77,0.240
16.54,103.96,0.236
16.55,104.14,0.235
16.57,104.32,0.232
16.59,104.51,0.230
16.61,104.69,0.227
16.63,104.88,0.223
16.65,105.06,0.221
16.67,105.25,0.218
16.68,105.43,0.216
16.70,105.62,0.212
16.72,105.80,0.210
16.74,105.99,0.206
16.76,106.17,0.205
16.78,106.36,0.202
16.79,106.54,0.199
16.81,106.72,0.197
16.83,106.91,0.195
16.85,107.09,0.193
16.87,107.28,0.190
16.88,107.46,0.188
16.90,107.65,0.186
16.92,107.83,0.185
16.94,108.02,0.182
16.96,108.20,0.181
16.98,108.38,0.179
17.00,108.57,0.178
17.01,108.75,0.176
17.03,108.94,0.175
17.05,109.12,0.174
17.07,109.30,0.173
17.09,109.49,0.172
17.11,109.67,0.171
17.12,109.86,0.170
17.14,110.04,0.170
17.16,110.22,0.169
17.18,110.41,0.168
17.20,110.59,0.168
17.22,110.77,0.168
17.23,110.96,0.168
17.25,111.14,0.167
17.27,111.33,0.167
17.29,111.51,0.167
17.31,111.69,0.167
17.33,111.88,0.167
17.34,112.06,0.167
17.36,112.24,0.167
17.38,112.43,0.167
17.40,112.61,0.167
17.42,112.79,0.167
17.43,112.98,0.167
17.45,113.16,0.167
17.47,113.34,0.168
17.49,113.53,0.168
17.51,113.71,0.168
17.53,113.89,0.169
17.54,114.08,0.169
17.56,114.26,0.171
17.58,114.44,0.171
17.60,114.63,0.172
17.62,114.81,0.173
17.64,114.99,0.175
17.66,115.18,0.176
17.67,115.36,0.177
17.69,115.54,0.179
17.71,115.73,0.180
17.73,115.91,0.182
17.75,116.09,0.184
17.77,116.27,0.185
17.78,116.46,0.186
17.80,116.64,0.187
17.82,116.82,0.189
17.84,117.01,0.190
17.86,117.19,0.193
17.88,117.37,0.194
17.89,117.55,0.196
17.91,117.74,0.198
17.93,117.92,0.199
17.95,118.10,0.201
17.97,118.29,0.203
17.98,118.47,0.204
18.00,118.65,0.206
18.02,118.83,0.208
18.04,119.02,0.209
18.06,119.20,0.211
18.08,119.38,0.213
18.09,119.56,0.215
18.11,119.75,0.217
18.13,119.93,0.219
18.15,120.11,0.220
18.17,120.30,0.222
18.19,120.48,0.225
18.21,120.66,0.226
18.22,120.84,0.228
18.24,121.03,0.229
18.26,121.21,0.232
18.28,121.39,0.234
18.30,121.57,0.236
18.32,121.76,0.238
18.33,121.94,0.240
18.35,122.12,0.241
18.37,122.31,0.243
18.39,122.49,0.246
18.41,122.67,0.247
18.43,122.85,0.250
18.44,123.04,0.251
18.46,123.22,0.253
18.48,123.40,0.256
18.50,123.58,0.258
18.52,123.77,0.260
18.53,123.95,0.262
18.55,124.13,0.264
18.57,124.32,0.266
18.59,124.50,0.268
18.61,124.68,0.271
18.63,124.86,0.273
18.64,125.05,0.275
18.66,125.23,0.277
18.68,125.41,0.279
18.70,125.59,0.282
18.72,125.78,0.284
18.74,125.96,0.287
18.76,126.14,0.289
18.77,126.32,0.291
18.79,126.51,0.294
18.81,126.69,0.297
18.83,126.87,0.299
18.85,127.05,0.301
18.87,127.24,0.304
18.88,127.42,0.306
18.90,127.60,0.308
18.92,127.78,0.311
18.94,127.97,0.314
18.96,128.15,0.317
18.98,128.33,0.319
18.99,128.51,0.323
19.01,128.69,0.325
19.03,128.88,0.329
19.05,129.06,0.332
19.07,129.24,0.334
19.08,129.42,0.337
19.10,129.61,0.341
19.12,129.79,0.345
19.14,129.97,0.347
19.16,130.15,0.350
19.18,130.33,0.354
19.19,130.52,0.357
19.21,130.70,0.362
19.23,130.88,0.365
19.25,131.06,0.369
19.27,131.25,0.373
19.29,131.43,0.377
19.31,131.61,0.381
19.32,131.79,0.384
19.34,131.97,0.388
19.36,132.16,0.393
19.38,132.34,0.396
19.40,132.52,0.402
19.42,132.70,0.405
19.43,132.88,0.409
19.45,133.07,0.413
19.47,133.25,0.418
19.49,133.43,0.422
19.51,133.61,0.426
19.53,133.79,0.430
19.54,133.98,0.434
19.56,134.16,0.440
19.58,134.34,0.442
19.60,134.52,0.449
19.62,134.70,0.453
19.63,134.88,0.457
19.65,135.07,0.463
19.67,135.25,0.468
19.69,135.43,0.471
19.71,135.61,0.477
19.73,135.79,0.482
19.74,135.97,0.487
19.76,136.15,0.493
19.78,136.34,0.498
19.80,136.52,0.503
19.82,136.70,0.509
19.84,136.88,0.514
19.86,137.06,0.520
19.87,137.24,0.526
19.89,137.42,0.532
19.91,137.60,0.537
19.93,137.79,0.545
19.95,137.97,0.551
19.97,138.15,0.559
19.98,138.33,0.564
20.00,138.51,0.572
20.02,138.69,0.580
20.04,138.87,0.587
20.06,139.05,0.595
20.08,139.23,0.603
20.09,139.41,0.611
20.11,139.59,0.621
20.13,139.77,0.629
20.15,139.95,0.638
20.17,140.13,0.647
20.18,140.31,0.657
20.20,140.49,0.666
20.22,140.67,0.676
20.24,140.85,0.688
20.26,141.03,0.698
20.28,141.21,0.709
20.29,141.39,0.720
20.31,141.57,0.732
20.33,141.75,0.745
20.35,141.93,0.756
20.37,142.11,0.770
20.39,142.28,0.784
20.41,142.46,0.798
20.42,142.64,0.815
20.44,142.82,0.830
20.46,143.00,0.849
20.48,143.17,0.869
20.50,143.35,0.891
20.52,143.53,0.918
20.53,143.70,0.960
20.55,143.87,1.002
20.57,144.04,1.044
20.59,144.21,1.090
20.61,144.38,1.165
20.63,144.53,1.313
20.64,144.68,1.464
20.66,144.82,1.601
20.68,144.96,1.781
20.70,145.08,1.966
20.72,145.21,2.181
20.73,145.32,2.403
20.75,145.45,2.316
20.77,145.60,2.286
20.79,145.76,2.272
20.81,145.94,2.160
20.83,146.14,2.011
20.84,146.35,1.787
20.86,146.59,1.399
20.88,146.86,1.053
20.90,147.14,0.854
20.92,147.40,0.745
20.94,147.65,0.671
20.96,147.89,0.609
20.97,148.12,0.569
20.99,148.34,0.524
21.01,148.55,0.494
21.03,148.76,0.469
21.05,148.96,0.447
21.07,149.16,0.430
21.08,149.36,0.416
21.10,149.55,0.405
21.12,149.74,0.396
21.14,149.93,0.388
21.16,150.12,0.383
21.18,150.31,0.377
21.19,150.50,0.374
21.21,150.68,0.370
21.23,150.87,0.368
21.25,151.06,0.366
21.27,151.24,0.365
21.28,151.43,0.364
21.30,151.61,0.363
21.32,151.79,0.362
21.34,151.98,0.362
21.36,152.16,0.361
21.38,152.35,0.361
21.39,152.53,0.361
21.41,152.71,0.361
21.43,152.90,0.361
21.45,153.08,0.360
21.47,153.27,0.360
21.49,153.45,0.360
21.51,153.63,0.360
21.52,153.82,0.360
21.54,154.00,0.360
21.56,154.18,0.360
21.58,154.37,0.360
21.60,154.55,0.359
21.62,154.73,0.359
21.63,154.92,0.359
21.65,155.10,0.359
21.67,155.28,0.359
21.69,155.47,0.359
21.71,155.65,0.359
21.73,155.84,0.359
21.74,156.02,0.359
21.76,156.20,0.359
21.78,156.39,0.359
21.80,156.57,0.359
21.82,156.75,0.359
21.83,156.94,0.359
21.85,157.12,0.359
21.87,157.30,0.359
21.89,157.49,0.359
21.91,157.67,0.359
21.93,157.85,0.359
21.94,158.04,0.359
21.96,158.22,0.359
21.98,158.40,0.359
22.00,158.59,0.359
22.02,158.77,0.359
22.04,158.95,0.358
22.06,159.14,0.358
22.07,159.32,0.358
22.09,159.50,0.358
22.11,159.69,0.358
22.13,159.87,0.358
22.15,160.05,0.358
22.17,160.24,0.358
22.18,160.42,0.358
22.20,160.60,0.358
22.22,160.79,0.358
22.24,160.97,0.358
22.26,161.16,0.358
22.28,161.34,0.358
22.29,161.52,0.358
22.31,161.71,0.358
22.33,161.89,0.358
22.35,162.07,0.357
22.37,162.26,0.357
22.38,162.44,0.357
22.40,162.62,0.357
22.42,162.81,0.357
22.44,162.99,0.357
22.46,163.17,0.357
22.48,163.36,0.357
22.49,163.54,0.357
22.51,163.73,0.357
22.53,163.91,0.357
22.55,164.09,0.357
22.57,164.28,0.356
22.59,164.46,0.356
22.61,164.64,0.356
22.62,164.83,0.356
22.64,165.01,0.356
22.66,165.19,0.356
22.68,165.38,0.356
22.70,165.56,0.356
22.72,165.74,0.356
22.73,165.93,0.356
22.75,166.11,0.355
22.77,166.29,0.355
22.79,166.48,0.355
22.81,166.66,0.355
22.83,166.85,0.355
22.84,167.03,0.355
22.86,167.21,0.355
22.88,167.40,0.355
22.90,167.58,0.355
22.92,167.76,0.355
22.93,167.95,0.355
22.95,168.13,0.355
22.97,168.31,0.354
22.99,168.50,0.354
23.01,168.68,0.354
23.03,168.86,0.354
23.04,169.05,0.354
23.06,169.23,0.354
23.08,169.41,0.354
23.10,169.60,0.354
23.12,169.78,0.354
23.14,169.96,0.354
23.16,170.15,0.354
23.17,170.33,0.354
23.19,170.51,0.354
23.21,170.70,0.354
23.23,170.88,0.353
23.25,171.06,0.353
23.27,171.25,0.353
23.28,171.43,0.353
23.30,171.61,0.353
23.32,171.80,0.353
23.34,171.98,0.353
23.36,172.17,0.353
23.38,172.35,0.353
23.39,172.53,0.353
23.41,172.72,0.353
23.43,172.90,0.353
23.45,173.08,0.353
23.47,173.27,0.353
23.48,173.45,0.353
23.50,173.63,0.353
23.52,173.82,0.353
23.54,174.00,0.353
23.56,174.18,0.353
23.58,174.37,0.353
23.59,174.55,0.353
23.61,174.73,0.353
23.63,174.92,0.353
23.65,175.10,0.353
23.67,175.28,0.353
23.69,175.47,0.353
23.71,175.65,0.353
23.72,175.83,0.353
23.74,176.02,0.353
23.76,176.20,0.353
23.78,176.38,0.353
23.80,176.57,0.353
23.82,176.75,0.353
23.83,176.94,0.353
23.85,177.12,0.353
23.87,177.30,0.353
23.89,177.49,0.353
23.91,177.67,0.353
23.93,177.85,0.354
23.94,178.04,0.354
23.96,178.22,0.354
23.98,178.40,0.354
24.00,178.59,0.354
24.02,178.77,0.354
24.03,178.95,0.354
24.05,179.14,0.354
24.07,179.32,0.354
24.09,179.50,0.355
24.11,179.69,0.355
24.13,179.87,0.355
24.14,180.05,0.355
24.16,180.24,0.356
24.18,180.42,0.356
24.20,180.60,0.357
24.22,180.79,0.357
24.24,180.97,0.358
24.26,181.15,0.358
24.27,181.34,0.359
24.29,181.52,0.360
24.31,181.70,0.361
24.33,181.89,0.362
24.35,182.07,0.364
24.37,182.25,0.365
24.38,182.43,0.367
24.40,182.62,0.368
24.42,182.80,0.369
24.44,182.98,0.371
24.46,183.17,0.372
24.48,183.35,0.374
24.49,183.53,0.376
24.51,183.71,0.377
24.53,183.90,0.378
24.55,184.08,0.379
24.57,184.26,0.381
24.58,184.45,0.382
24.60,184.63,0.383
24.62,184.81,0.384
24.64,185.00,0.386
24.66,185.18,0.387
24.68,185.36,0.389
24.69,185.54,0.389
24.71,185.73,0.390
24.73,185.91,0.391
24.75,186.09,0.393
24.77,186.28,0.393
24.79,186.46,0.394
24.81,186.64,0.396
24.82,186.82,0.397
24.84,187.01,0.397
24.86,187.19,0.398
24.88,187.37,0.400
24.90,187.56,0.402
24.92,187.74,0.403
24.93,187.92,0.404
24.95,188.11,0.405
24.97,188.29,0.407
24.99,188.47,0.408
25.01,188.65,0.409
25.03,188.84,0.410
25.04,189.02,0.412
25.06,189.20,0.413
25.08,189.39,0.414
25.10,189.57,0.415
25.12,189.75,0.416
25.13,189.93,0.418
25.15,190.12,0.419
25.17,190.30,0.420
25.19,190.48,0.421
25.21,190.67,0.422
25.23,190.85,0.423
25.24,191.03,0.426
25.26,191.22,0.427
25.28,191.40,0.428
25.30,191.58,0.430
25.32,191.77,0.432
25.34,191.95,0.433
25.36,192.13,0.435
25.37,192.31,0.436
25.39,192.50,0.437
25.41,192.68,0.439
25.43,192.86,0.441
25.45,193.05,0.442
25.47,193.23,0.443
25.48,193.41,0.445
25.50,193.60,0.446
25.52,193.78,0.448
25.54,193.96,0.449
25.56,194.14,0.451
25.58,194.33,0.452
25.59,194.51,0.453
25.61,194.69,0.455
25.63,194.88,0.458
25.65,195.06,0.459
25.67,195.24,0.460
25.68,195.43,0.461
25.70,195.61,0.464
25.72,195.79,0.465
25.74,195.97,0.467
25.76,196.16,0.469
25.78,196.34,0.470
25.79,196.52,0.472
25.81,196.71,0.473
25.83,196.89,0.476
25.85,197.07,0.477
25.87,197.25,0.479
25.89,197.44,0.481
25.91,197.62,0.482
25.92,197.80,0.484
25.94,197.98,
25.96,198.17,
25.98,198.35,
25.99,,

[step]
Ramp 10.00 °C/min to -60.00 °C
Time,Temperature,Heat Flow (Normalized)
min,°C,W/g
26.99,200.04,0.041
27.01,200.04,0.040
27.03,200.04,0.040
27.05,200.03,0.038
27.07,200.01,0.021
27.08,199.97,-0.003
27.10,199.91,-0.040
27.12,199.83,-0.085
27.14,199.74,-0.136
27.16,199.62,-0.185
27.18,199.49,-0.231
27.19,199.35,-0.267
27.21,199.21,-0.300
27.23,199.06,-0.324
27.25,198.90,-0.346
27.27,198.74,-0.363
27.29,198.57,-0.376
27.31,198.41,-0.388
27.32,198.24,-0.398
27.34,198.07,-0.406
27.36,197.89,-0.414
27.38,197.72,-0.420
27.40,197.54,-0.426
27.42,197.37,-0.429
27.43,197.19,-0.433
27.45,197.01,-0.436
27.47,196.84,-0.440
27.49,196.66,-0.442
27.51,196.48,-0.444
27.53,196.30,-0.446
27.54,196.12,-0.447
27.56,195.94,-0.449
27.58,195.76,-0.452
27.60,195.58,-0.453
27.62,195.40,-0.453
27.63,195.22,-0.455
27.65,195.04,-0.456
27.67,194.86,-0.457
27.69,194.68,-0.458
27.71,194.50,-0.458
27.73,194.32,-0.459
27.74,194.13,-0.459
27.76,193.95,-0.460
27.78,193.77,-0.460
27.80,193.59,-0.460
27.82,193.41,-0.461
27.84,193.23,-0.462
27.86,193.05,-0.462
27.87,192.87,-0.463
27.89,192.68,-0.463
27.91,192.50,-0.464
27.93,192.32,-0.464
27.95,192.14,-0.465
27.97,191.96,-0.465
27.98,191.77,-0.466
28.00,191.59,-0.467
28.02,191.41,-0.467
28.04,191.23,-0.467
28.06,191.05,-0.468
28.08,190.87,-0.468
28.09,190.68,-0.468
28.11,190.50,-0.469
28.13,190.32,-0.469
28.15,190.14,-0.469
28.17,189.95,-0.470
28.18,189.77,-0.470
28.20,189.59,-0.471
28.22,189.40,-0.471
28.24,189.22,-0.472
28.26,189.04,-0.472
28.28,188.85,-0.472
28.29,188.67,-0.472
28.31,188.49,-0.473
28.33,188.31,-0.473
28.35,188.13,-0.473
28.37,187.94,-0.473
28.39,187.76,-0.473
28.41,187.58,-0.473
28.42,187.40,-0.473
28.44,187.21,-0.473
28.46,187.03,-0.474
28.48,186.85,-0.474
28.50,186.67,-0.474
28.52,186.49,-0.474
28.53,186.30,-0.474
28.55,186.12,-0.474
28.57,185.94,-0.475
28.59,185.76,-0.475
28.61,185.57,-0.475
28.63,185.39,-0.475
28.64,185.21,-0.475
28.66,185.02,-0.476
28.68,184.84,-0.476
28.70,184.66,-0.476
28.72,184.48,-0.476
28.73,184.29,-0.476
28.75,184.11,-0.477
28.77,183.93,-0.477
28.79,183.74,-0.477
28.81,183.56,-0.477
28.83,183.38,-0.477
28.84,183.19,-0.477
28.86,183.01,-0.477
28.88,182.83,-0.477
28.90,182.65,-0.478
28.92,182.46,-0.478
28.94,182.28,-0.478
28.96,182.10,-0.478
28.97,181.91,-0.478
28.99,181.73,-0.478
29.01,181.55,-0.478
29.03,181.36,-0.478
29.05,181.18,-0.478
29.07,181.00,-0.478
29.08,180.81,-0.478
29.10,180.63,-0.478
29.12,180.45,-0.478
29.14,180.27,-0.478
29.16,180.08,-0.478
29.18,179.90,-0.478
29.19,179.72,-0.478
29.21,179.53,-0.478
29.23,179.35,-0.478
29.25,179.17,-0.478
29.27,178.98,-0.478
29.28,178.80,-0.478
29.30,178.62,-0.478
29.32,178.44,-0.478
29.34,178.25,-0.478
29.36,178.07,-0.478
29.38,177.89,-0.478
29.39,177.70,-0.478
29.41,177.52,-0.478
29.43,177.34,-0.478
29.45,177.15,-0.478
29.47,176.97,-0.478
29.49,176.79,-0.478
29.51,176.61,-0.478
29.52,176.42,-0.478
29.54,176.24,-0.478
29.56,176.06,-0.478
29.58,175.87,-0.478
29.60,175.69,-0.478
29.62,175.51,-0.478
29.63,175.32,-0.478
29.65,175.14,-0.478
29.67,174.96,-0.478
29.69,174.78,-0.478
29.71,174.59,-0.477
29.73,174.41,-0.477
29.74,174.22,-0.477
29.76,174.04,-0.477
29.78,173.86,-0.477
29.80,173.68,-0.477
29.82,173.49,-0.477
29.83,173.31,-0.477
29.85,173.13,-0.477
29.87,172.94,-0.477
29.89,172.76,-0.477
29.91,172.58,-0.477
29.93,172.39,-0.477
29.94,172.21,-0.477
29.96,172.03,-0.477
29.98,171.84,-0.477
30.00,171.66,-0.476
30.02,171.48,-0.476
30.04,171.30,-0.476
30.06,171.11,-0.476
30.07,170.93,-0.476
30.09,170.75,-0.476
30.11,170.56,-0.476
30.13,170.38,-0.476
30.15,170.20,-0.476
30.17,170.01,-0.476
30.18,169.83,-0.475
30.20,169.65,-0.475
30.22,169.46,-0.475
30.24,169.28,-0.475
30.26,169.10,-0.475
30.28,168.91,-0.475
30.29,168.73,-0.475
30.31,168.55,-0.475
30.33,168.36,-0.475
30.35,168.18,-0.474
30.37,168.00,-0.474
30.38,167.82,-0.474
30.40,167.63,-0.474
30.42,167.45,-0.474
30.44,167.27,-0.474
30.46,167.08,-0.474
30.48,166.90,-0.474
30.49,166.72,-0.474
30.51,166.53,-0.474
30.53,166.35,-0.473
30.55,166.17,-0.473
30.57,165.99,-0.473
30.59,165.80,-0.473
30.61,165.62,-0.473
30.62,165.44,-0.473
30.64,165.25,-0.473
30.66,165.07,-0.473
30.68,164.89,-0.473
30.70,164.70,-0.472
30.72,164.52,-0.472
30.73,164.34,-0.472
30.75,164.15,-0.472
30.77,163.97,-0.472
30.79,163.79,-0.472
30.81,163.61,-0.472
30.83,163.42,-0.472
30.84,163.24,-0.472
30.86,163.06,-0.471
30.88,162.87,-0.471
30.90,162.69,-0.471
30.92,162.51,-0.471
30.93,162.32,-0.471
30.95,162.14,-0.471
30.97,161.96,-0.471
30.99,161.77,-0.471
31.01,161.59,-0.470
31.03,161.41,-0.470
31.04,161.23,-0.470
31.06,161.04,-0.470
31.08,160.86,-0.470
31.10,160.68,-0.470
31.12,160.49,-0.470
31.14,160.31,-0.470
31.16,160.13,-0.470
31.17,159.94,-0.469
31.19,159.76,-0.469
31.21,159.58,-0.469
31.23,159.39,-0.469
31.25,159.21,-0.469
31.27,159.03,-0.469
31.28,158.84,-0.469
31.30,158.66,-0.469
31.32,158.48,-0.468
31.34,158.29,-0.468
31.36,158.11,-0.468
31.38,157.93,-0.468
31.39,157.74,-0.468
31.41,157.56,-0.468
31.43,157.38,-0.468
31.45,157.20,-0.467
31.47,157.01,-0.467
31.48,156.83,-0.467
31.50,156.65,-0.467
31.52,156.46,-0.467
31.54,156.28,-0.467
31.56,156.10,-0.467
31.58,155.91,-0.467
31.59,155.73,-0.466
31.61,155.55,-0.466
31.63,155.36,-0.466
31.65,155.18,-0.466
31.67,155.00,-0.466
31.69,154.82,-0.466
31.71,154.63,-0.466
31.72,154.45,-0.466
31.74,154.27,-0.465
31.76,154.08,-0.465
31.78,153.90,-0.465
31.80,153.71,-0.465
31.82,153.53,-0.465
31.83,153.35,-0.465
31.85,153.17,-0.465
31.87,152.98,-0.465
31.89,152.80,-0.464
31.91,152.62,-0.464
31.93,152.43,-0.464
31.94,152.25,-0.464
31.96,152.07,-0.464
31.98,151.88,-0.464
32.00,151.70,-0.464
32.02,151.52,-0.463
32.03,151.34,-0.463
32.05,151.15,-0.463
32.07,150.97,-0.463
32.09,150.79,-0.463
32.11,150.60,-0.463
32.13,150.42,-0.462
32.14,150.24,-0.462
32.16,150.05,-0.462
32.18,149.87,-0.462
32.20,149.69,-0.462
32.22,149.50,-0.462
32.24,149.32,-0.462
32.26,149.14,-0.462
32.27,148.95,-0.461
32.29,148.77,-0.461
32.31,148.59,-0.461
32.33,148.40,-0.461
32.35,148.22,-0.461
32.37,148.04,-0.461
32.38,147.86,-0.461
32.40,147.67,-0.461
32.42,147.49,-0.461
32.44,147.31,-0.460
32.46,147.12,-0.460
32.48,146.94,-0.460
32.49,146.76,-0.460
32.51,146.57,-0.460
32.53,146.39,-0.460
32.55,146.21,-0.459
32.57,146.02,-0.459
32.58,145.84,-0.459
32.60,145.66,-0.459
32.62,145.48,-0.459
32.64,145.29,-0.459
32.66,145.11,-0.458
32.68,144.93,-0.458
32.69,144.74,-0.458
32.71,144.56,-0.458
32.73,144.38,-0.458
32.75,144.19,-0.458
32.77,144.01,-0.458
32.79,143.83,-0.457
32.81,143.64,-0.457
32.82,143.46,-0.457
32.84,143.28,-0.457
32.86,143.10,-0.457
32.88,142.91,-0.457
32.90,142.73,-0.457
32.92,142.55,-0.457
32.93,142.36,-0.457
32.95,142.18,-0.456
32.97,142.00,-0.456
32.99,141.81,-0.456
33.01,141.63,-0.456
33.03,141.45,-0.456
33.04,141.26,-0.456
33.06,141.08,-0.456
33.08,140.90,-0.456
33.10,140.71,-0.455
33.12,140.53,-0.455
33.13,140.35,-0.455
33.15,140.17,-0.455
33.17,139.98,-0.455
33.19,139.80,-0.455
33.21,139.62,-0.455
33.23,139.43,-0.455
33.24,139.25,-0.455
33.26,139.07,-0.454
33.28,138.88,-0.454
33.30,138.70,-0.454
33.32,138.52,-0.454
33.34,138.33,-0.454
33.36,138.15,-0.454
33.37,137.97,-0.453
33.39,137.78,-0.453
33.41,137.60,-0.453
33.43,137.42,-0.453
33.45,137.23,-0.453
33.47,137.05,-0.453
33.48,136.87,-0.453
33.50,136.68,-0.453
33.52,136.50,-0.453
33.54,136.32,-0.452
33.56,136.14,-0.452
33.58,135.95,-0.452
33.59,135.77,-0.452
33.61,135.59,-0.452
33.63,135.40,-0.452
33.65,135.22,-0.452
33.67,135.04,-0.452
33.68,134.85,-0.451
33.70,134.67,-0.451
33.72,134.49,-0.451
33.74,134.30,-0.451
33.76,134.12,-0.451
33.78,133.94,-0.451
33.79,133.75,-0.450
33.81,133.57,-0.450
33.83,133.39,-0.450
33.85,133.21,-0.450
33.87,133.02,-0.450
33.89,132.84,-0.450
33.91,132.66,-0.450
33.92,132.47,-0.450
33.94,132.29,-0.449
33.96,132.11,-0.449
33.98,131.92,-0.449
34.00,131.74,-0.449
34.02,131.56,-0.449
34.03,131.38,-0.449
34.05,131.19,-0.449
34.07,131.01,-0.449
34.09,130.83,-0.448
34.11,130.64,-0.448
34.13,130.46,-0.448
34.14,130.28,-0.448
34.16,130.09,-0.448
34.18,129.91,-0.448
34.20,129.73,-0.448
34.22,129.54,-0.448
34.24,129.36,-0.447
34.25,129.18,-0.447
34.27,128.99,-0.447
34.29,128.81,-0.447
[...]
115.21,10.57,0.307
115.23,10.75,0.307
115.25,10.94,0.309
115.27,11.12,0.310
115.29,11.30,0.311
115.31,11.48,0.312
115.33,11.67,0.313
115.34,11.85,0.314
115.36,12.04,0.315
115.38,12.22,0.315
115.40,12.40,0.316
115.42,12.58,0.316
115.44,12.77,0.316
115.45,12.95,0.317
115.47,13.14,0.317
115.49,13.32,0.318
115.51,13.50,0.318
115.53,13.69,0.318
115.55,13.87,0.319
115.56,14.05,0.319
115.58,14.24,0.319
115.60,14.42,0.319
115.62,14.60,0.320
115.64,14.79,0.320
115.65,14.97,0.320
115.67,15.15,0.320
115.69,15.34,0.320
115.71,15.52,0.321
115.73,15.70,0.321
115.75,15.89,0.321
115.76,16.07,0.321
115.78,16.25,0.321
115.80,16.44,0.321
115.82,16.62,0.321
115.84,16.81,0.321
115.86,16.99,0.322
115.88,17.17,0.322
115.89,17.36,0.322
115.91,17.54,0.322
115.93,17.72,0.322
115.95,17.91,0.322
115.97,18.09,0.322
115.99,18.27,0.322
116.00,18.46,0.322
116.02,18.64,0.322
116.04,18.83,0.322
116.06,19.01,0.322
116.08,19.19,0.322
116.10,19.38,0.322
116.11,19.56,0.322
116.13,19.74,0.322
116.15,19.93,0.322
116.17,20.11,0.322
116.19,20.29,0.322
116.20,20.48,0.322
116.22,20.66,0.322
116.24,20.84,0.322
116.26,21.03,0.322
116.28,21.21,0.322
116.30,21.40,0.322
116.31,21.58,0.322
116.33,21.76,0.322
116.35,21.95,0.322
116.37,22.13,0.322
116.39,22.31,0.322
116.41,22.50,0.322
116.43,22.68,0.322
116.44,22.86,0.322
116.46,23.05,0.322
116.48,23.23,0.322
116.50,23.41,0.322
116.52,23.60,0.322
116.54,23.78,0.322
116.55,23.96,0.322
116.57,24.15,0.322
116.59,24.33,0.322
116.61,24.51,0.322
116.63,24.70,0.322
116.65,24.88,0.323
116.66,25.07,0.323
116.68,25.25,0.323
116.70,25.43,0.323
116.72,25.62,0.323
116.74,25.80,0.323
116.75,25.98,0.323
116.77,26.17,0.323
116.79,26.35,0.323
116.81,26.53,0.323
116.83,26.72,0.324
116.85,26.90,0.324
116.86,27.09,0.324
116.88,27.27,0.324
116.90,27.45,0.324
116.92,27.64,0.324
116.94,27.82,0.324
116.96,28.00,0.324
116.98,28.19,0.324
116.99,28.37,0.325
117.01,28.55,0.325
117.03,28.74,0.325
117.05,28.92,0.325
117.07,29.10,0.325
117.09,29.29,0.325
117.10,29.47,0.325
117.12,29.65,0.325
117.14,29.84,0.326
117.16,30.02,0.326
117.18,30.21,0.326
117.20,30.39,0.326
117.21,30.57,0.326
117.23,30.76,0.326
117.25,30.94,0.326
117.27,31.12,0.327
117.29,31.31,0.327
117.30,31.49,0.327
117.32,31.68,0.327
117.34,31.86,0.327
117.36,32.04,0.327
117.38,32.23,0.327
117.40,32.41,0.327
117.41,32.59,0.328
117.43,32.78,0.328
117.45,32.96,0.328
117.47,33.14,0.328
117.49,33.33,0.328
117.51,33.51,0.328
117.53,33.69,0.328
117.54,33.88,0.328
117.56,34.06,0.329
117.58,34.24,0.329
117.60,34.43,0.329
117.62,34.61,0.329
117.64,34.79,0.329
117.65,34.98,0.329
117.67,35.16,0.329
117.69,35.34,0.329
117.71,35.53,0.330
117.73,35.71,0.330
117.75,35.89,0.330
117.76,36.08,0.330
117.78,36.26,0.330
117.80,36.45,0.330
117.82,36.63,0.330
117.84,36.81,0.331
117.85,37.00,0.331
117.87,37.18,0.331
117.89,37.36,0.331
117.91,37.55,0.331
117.93,37.73,0.331
117.95,37.91,0.331
117.96,38.10,0.331
117.98,38.28,0.332
118.00,38.46,0.332
118.02,38.65,0.332
118.04,38.83,0.332
118.06,39.01,0.332
118.08,39.20,0.332
118.09,39.38,0.332
118.11,39.56,0.333
118.13,39.75,0.333
118.15,39.93,0.333
118.17,40.12,0.333
118.19,40.30,0.333
118.20,40.48,0.333
118.22,40.67,0.333
118.24,40.85,0.333
118.26,41.03,0.334
118.28,41.22,0.334
118.30,41.40,0.334
118.31,41.58,0.334
118.33,41.77,0.334
118.35,41.95,0.334
118.37,42.13,0.335
118.39,42.32,0.335
118.40,42.50,0.335
118.42,42.68,0.335
118.44,42.87,0.335
118.46,43.05,0.335
118.48,43.24,0.335
118.50,43.42,0.336
118.51,43.60,0.336
118.53,43.79,0.336
118.55,43.97,0.336
118.57,44.15,0.336
118.59,44.34,0.336
118.61,44.52,0.336
118.63,44.70,0.337
118.64,44.89,0.337
118.66,45.07,0.337
118.68,45.25,0.337
118.70,45.44,0.337
118.72,45.62,0.337
118.74,45.80,0.337
118.75,45.99,0.338
118.77,46.17,0.338
118.79,46.36,0.338
118.81,46.54,0.338
118.83,46.72,0.338
118.85,46.91,0.338
118.86,47.09,0.339
118.88,47.27,0.339
118.90,47.46,0.339
118.92,47.64,0.339
118.94,47.83,0.339
118.95,48.01,0.339
118.97,48.19,0.339
118.99,48.37,0.340
119.01,48.56,0.340
119.03,48.74,0.340
119.05,48.92,0.340
119.06,49.11,0.340
119.08,49.29,0.340
119.10,49.48,0.340
119.12,49.66,0.341
119.14,49.84,0.341
119.16,50.03,0.341
119.18,50.21,0.341
119.19,50.39,0.341
119.21,50.58,0.341
119.23,50.76,0.342
119.25,50.94,0.342
119.27,51.13,0.342
119.29,51.31,0.342
119.30,51.50,0.342
119.32,51.68,0.342
119.34,51.86,0.342
119.36,52.04,0.342
119.38,52.23,0.343
119.40,52.41,0.343
119.41,52.59,0.343
119.43,52.78,0.343
119.45,52.96,0.343
119.47,53.14,0.344
119.49,53.33,0.344
119.50,53.51,0.344
119.52,53.70,0.344
119.54,53.88,0.344
119.56,54.06,0.344
119.58,54.25,0.345
119.60,54.43,0.345
119.61,54.61,0.345
119.63,54.80,0.345
119.65,54.98,0.345
119.67,55.16,0.345
119.69,55.35,0.345
119.71,55.53,0.345
119.73,55.72,0.346
119.74,55.90,0.346
119.76,56.08,0.346
119.78,56.27,0.346
119.80,56.45,0.346
119.82,56.63,0.346
119.84,56.82,0.346
119.85,57.00,0.347
119.87,57.18,0.347
119.89,57.37,0.347
119.91,57.55,0.347
119.93,57.73,0.347
119.95,57.92,0.347
119.96,58.10,0.347
119.98,58.29,0.347
120.00,58.47,0.348
120.02,58.65,0.348
120.04,58.84,0.348
120.05,59.02,0.348
120.07,59.20,0.348
120.09,59.39,0.348
120.11,59.57,0.348
120.13,59.75,0.349
120.15,59.94,0.349
120.16,60.12,0.349
120.18,60.30,0.349
120.20,60.49,0.349
120.22,60.67,0.349
120.24,60.85,0.349
120.26,61.04,0.350
120.28,61.22,0.350
120.29,61.41,0.350
120.31,61.59,0.350
120.33,61.77,0.350
120.35,61.96,0.350
120.37,62.14,0.350
120.39,62.32,0.350
120.40,62.51,0.351
120.42,62.69,0.351
120.44,62.87,0.351
120.46,63.06,0.351
120.48,63.24,0.351
120.50,63.42,0.351
120.51,63.61,0.351
120.53,63.79,0.352
120.55,63.97,0.352
120.57,64.16,0.352
120.59,64.34,0.352
120.60,64.52,0.352
120.62,64.71,0.352
120.64,64.89,0.352
120.66,65.07,0.353
120.68,65.26,0.353
120.70,65.44,0.353
120.71,65.62,0.353
120.73,65.81,0.353
120.75,65.99,0.353
120.77,66.17,0.353
120.79,66.36,0.354
120.81,66.54,0.354
120.83,66.73,0.354
120.84,66.91,0.354
120.86,67.09,0.354
120.88,67.28,0.354
120.90,67.46,0.354
120.92,67.64,0.355
120.94,67.83,0.355
120.95,68.01,0.355
120.97,68.19,0.355
120.99,68.38,0.355
121.01,68.56,0.355
121.03,68.74,0.355
121.05,68.93,0.355
121.06,69.11,0.355
121.08,69.29,0.356
121.10,69.48,0.356
121.12,69.66,0.356
121.14,69.84,0.356
121.15,70.03,0.356
121.17,70.21,0.356
121.19,70.39,0.356
121.21,70.58,0.357
121.23,70.76,0.357
121.25,70.94,0.357
121.26,71.13,0.357
121.28,71.31,0.357
121.30,71.50,0.357
121.32,71.68,0.357
121.34,71.86,0.357
121.36,72.05,0.358
121.38,72.23,0.358
121.39,72.41,0.358
121.41,72.60,0.358
121.43,72.78,0.358
121.45,72.96,0.358
121.47,73.15,0.358
121.49,73.33,0.359
121.50,73.51,0.359
121.52,73.70,0.359
121.54,73.88,0.359
121.56,74.07,0.359
121.58,74.25,0.359
121.60,74.43,0.360
121.61,74.62,0.360
121.63,74.80,0.360
121.65,74.98,0.360
121.67,75.17,0.360
121.69,75.35,0.360
121.70,75.53,0.360
121.72,75.72,0.360
121.74,75.90,0.361
121.76,76.08,0.361
121.78,76.27,0.361
121.80,76.45,0.361
121.81,76.63,0.361
121.83,76.82,0.361
121.85,77.00,0.361
121.87,77.18,0.361
121.89,77.37,0.361
121.91,77.55,0.362
121.93,77.74,0.362
121.94,77.92,0.362
121.96,78.10,0.362
121.98,78.29,0.362
122.00,78.47,0.362
122.02,78.65,0.362
122.04,78.84,0.362
122.05,79.02,0.362
122.07,79.20,0.362
122.09,79.39,0.363
122.11,79.57,0.363
122.13,79.75,0.363
122.15,79.94,0.363
122.16,80.12,0.363
122.18,80.30,0.363
122.20,80.49,0.363
122.22,80.67,0.363
122.24,80.85,0.363
122.25,81.04,0.364
122.27,81.22,0.364
122.29,81.40,0.364
122.31,81.59,0.364
122.33,81.77,0.364
122.35,81.96,0.364
122.36,82.14,0.364
122.38,82.32,0.364
122.40,82.51,0.364
122.42,82.69,0.364
122.44,82.87,0.364
122.46,83.06,0.365
122.48,83.24,0.365
122.49,83.42,0.365
122.51,83.61,0.365
122.53,83.79,0.365
122.55,83.97,0.365
122.57,84.16,0.365
122.59,84.34,0.365
122.60,84.52,0.365
122.62,84.71,0.365
122.64,84.89,0.366
122.66,85.08,0.366
122.68,85.26,0.366
122.70,85.44,0.366
122.71,85.62,0.366
122.73,85.81,0.366
122.75,85.99,0.366
122.77,86.17,0.366
122.79,86.36,0.366
122.80,86.54,0.366
122.82,86.73,0.366
122.84,86.91,0.366
122.86,87.09,0.367
122.88,87.28,0.367
122.90,87.46,0.367
122.91,87.64,0.367
122.93,87.83,0.367
122.95,88.01,0.367
122.97,88.19,0.367
122.99,88.38,0.367
123.01,88.56,0.367
123.03,88.75,0.367
123.04,88.93,0.368
123.06,89.11,0.368
123.08,89.30,0.368
123.10,89.48,0.368
123.12,89.66,0.368
123.14,89.85,0.368
123.15,90.03,0.368
123.17,90.21,0.368
123.19,90.40,0.369
123.21,90.58,0.369
123.23,90.76,0.369
123.25,90.95,0.369
123.26,91.13,0.369
123.28,91.31,0.369
123.30,91.50,0.369
123.32,91.68,0.370
123.34,91.87,0.370
123.35,92.05,0.370
123.37,92.23,0.370
123.39,92.42,0.370
123.41,92.60,0.370
123.43,92.78,0.370
123.45,92.97,0.370
123.46,93.15,0.370
123.48,93.33,0.371
123.50,93.52,0.371
123.52,93.70,0.371
123.54,93.88,0.371
123.56,94.07,0.371
123.58,94.25,0.371
123.59,94.44,0.371
123.61,94.62,0.371
123.63,94.80,0.371
123.65,94.99,0.372
123.67,95.17,0.372
123.69,95.35,0.372
123.70,95.54,0.372
123.72,95.72,0.372
123.74,95.90,0.372
123.76,96.09,0.372
123.78,96.27,0.372
123.80,96.45,0.372
123.81,96.64,0.372
123.83,96.82,0.373
123.85,97.00,0.373
123.87,97.19,0.373
123.89,97.37,0.373
123.90,97.55,0.373
123.92,97.74,0.373
123.94,97.92,0.373
123.96,98.10,0.373
123.98,98.29,0.373
124.00,98.47,0.374
124.01,98.65,0.374
124.03,98.84,0.374
124.05,99.02,0.374
124.07,99.21,0.374
124.09,99.39,0.374
124.11,99.57,0.374
124.13,99.75,0.374
124.14,99.94,0.374
124.16,100.12,0.374
124.18,100.31,0.375
124.20,100.49,0.375
124.22,100.67,0.375
124.24,100.86,0.375
124.25,101.04,0.375
124.27,101.22,0.375
124.29,101.41,0.375
124.31,101.59,0.375
124.33,101.77,0.376
124.35,101.96,0.376
124.36,102.14,0.376
124.38,102.32,0.376
124.40,102.51,0.376
124.42,102.69,0.376
124.44,102.87,0.376
124.45,103.06,0.376
124.47,103.24,0.376
124.49,103.43,0.376
124.51,103.61,0.377
124.53,103.79,0.377
124.55,103.98,0.377
124.56,104.16,0.377
124.58,104.34,0.377
124.60,104.53,0.377
124.62,104.71,0.377
124.64,104.89,0.377
124.66,105.08,0.377
124.68,105.26,0.378
124.69,105.44,0.378
124.71,105.63,0.378
124.73,105.81,0.378
124.75,105.99,0.378
124.77,106.18,0.378
124.79,106.36,0.378
124.80,106.54,0.378
124.82,106.73,0.378
124.84,106.91,0.378
124.86,107.09,0.378
124.88,107.28,0.379
124.90,107.46,0.379
124.91,107.65,0.379
124.93,107.83,0.379
124.95,108.01,0.379
124.97,108.20,0.379
124.99,108.38,0.379
125.00,108.56,0.379
125.02,108.75,0.379
125.04,108.93,0.380
125.06,109.11,0.380
125.08,109.30,0.380
125.10,109.48,0.380
125.11,109.67,0.380
125.13,109.85,0.380
125.15,110.03,0.380
125.17,110.22,0.380
125.19,110.40,0.380
125.21,110.58,0.381
125.23,110.77,0.381
125.24,110.95,0.381
125.26,111.13,0.381
125.28,111.32,0.381
125.30,111.50,0.381
125.32,111.68,0.381
125.34,111.87,0.381
125.35,112.05,0.381
125.37,112.23,0.381
125.39,112.42,0.382
125.41,112.60,0.382
125.43,112.78,0.382
125.45,112.97,0.382
125.46,113.15,0.382
125.48,113.33,0.382
125.50,113.52,0.382
125.52,113.70,0.382
125.54,113.88,0.382
125.55,114.07,0.383
125.57,114.25,0.383
125.59,114.43,0.383
125.61,114.62,0.383
125.63,114.80,0.383
125.65,114.99,0.383
125.66,115.17,0.383
125.68,115.35,0.383
125.70,115.54,0.383
125.72,115.72,0.383
125.74,115.90,0.384
125.76,116.09,0.384
125.78,116.27,0.384
125.79,116.45,0.384
125.81,116.63,0.384
125.83,116.82,0.384
125.85,117.00,0.384
125.87,117.19,0.384
125.89,117.37,0.385
125.90,117.55,0.385
125.92,117.74,0.385
125.94,117.92,0.385
125.96,118.10,0.385
125.98,118.29,0.385
126.00,118.47,0.385
126.01,118.65,0.385
126.03,118.84,0.385
126.05,119.02,0.386
126.07,119.20,0.386
126.09,119.39,0.386
126.10,119.57,0.386
126.12,119.75,0.386
126.14,119.94,0.386
126.16,120.12,0.386
126.18,120.30,0.386
126.20,120.49,0.386
126.21,120.67,0.387
126.23,120.86,0.387
126.25,121.04,0.387
126.27,121.22,0.387
126.29,121.40,0.387
126.31,121.59,0.387
126.33,121.77,0.387
126.34,121.96,0.387
126.36,122.14,0.387
126.38,122.32,0.388
126.40,122.51,0.388
126.42,122.69,0.388
126.44,122.87,0.388
126.45,123.06,0.388
126.47,123.24,0.388
126.49,123.42,0.388
126.51,123.61,0.388
126.53,123.79,0.389
126.55,123.97,0.389
126.56,124.16,0.389
126.58,124.34,0.389
126.60,124.52,0.389
126.62,124.71,0.389
126.64,124.89,0.389
126.65,125.07,0.389
126.67,125.26,0.389
126.69,125.44,0.390
126.71,125.63,0.390
126.73,125.81,0.390
126.75,125.99,0.390
126.76,126.18,0.390
126.78,126.36,0.390
126.80,126.54,0.390
126.82,126.73,0.390
126.84,126.91,0.391
126.86,127.09,0.391
126.88,127.28,0.391
126.89,127.46,0.391
126.91,127.64,0.391
126.93,127.83,0.391
126.95,128.01,0.391
126.97,128.19,0.391
126.99,128.38,0.392
127.00,128.56,0.392
127.02,128.74,0.392
127.04,128.93,0.392
127.06,129.11,0.392
127.08,129.29,0.392
127.10,129.48,0.392
127.11,129.66,0.392
127.13,129.85,0.392
127.15,130.03,0.393
127.17,130.21,0.393
127.19,130.40,0.393
127.20,130.58,0.393
127.22,130.76,0.393
127.24,130.95,0.393
127.26,131.13,0.393
127.28,131.31,0.394
127.30,131.50,0.394
127.31,131.68,0.394
127.33,131.86,0.394
127.35,132.05,0.394
127.37,132.23,0.394
127.39,132.41,0.394
127.41,132.60,0.394
127.43,132.78,0.394
127.44,132.97,0.395
127.46,133.15,0.395
127.48,133.33,0.395
127.50,133.51,0.395
127.52,133.70,0.395
127.54,133.88,0.395
127.55,134.07,0.395
127.57,134.25,0.395
127.59,134.43,0.395
127.61,134.62,0.396
127.63,134.80,0.396
127.65,134.98,0.396
127.66,135.17,0.396
127.68,135.35,0.396
127.70,135.53,0.396
127.72,135.72,0.396
127.74,135.90,0.396
127.75,136.08,0.397
127.77,136.27,0.397
127.79,136.45,0.397
127.81,136.63,0.397
127.83,136.82,0.397
127.85,137.00,0.397
127.86,137.18,0.397
127.88,137.37,0.397
127.90,137.55,0.398
127.92,137.73,0.398
127.94,137.92,0.398
127.96,138.10,0.398
127.98,138.28,0.398
127.99,138.47,0.398
128.01,138.65,0.398
128.03,138.83,0.398
128.05,139.02,0.399
128.07,139.20,0.399
128.09,139.38,0.399
128.10,139.57,0.399
128.12,139.75,0.399
128.14,139.93,0.399
128.16,140.12,0.399
128.18,140.30,0.399
128.20,140.48,0.400
128.21,140.67,0.400
128.23,140.85,0.400
128.25,141.04,0.400
128.27,141.22,0.400
128.29,141.40,0.400
128.30,141.59,0.400
128.32,141.77,0.400
128.34,141.95,0.401
128.36,142.14,0.401
128.38,142.32,0.401
128.40,142.50,0.401
128.41,142.69,0.401
128.43,142.87,0.401
128.45,143.05,0.401
128.47,143.24,0.402
128.49,143.42,0.402
128.51,143.60,0.402
128.53,143.79,0.402
128.54,143.97,0.402
128.56,144.15,0.402
128.58,144.34,0.402
128.60,144.52,0.402
128.62,144.70,0.403
128.64,144.89,0.403
128.65,145.07,0.403
128.67,145.25,0.403
128.69,145.44,0.403
128.71,145.62,0.403
128.73,145.80,0.404
128.75,145.99,0.404
128.76,146.17,0.404
128.78,146.35,0.404
128.80,146.54,0.404
128.82,146.72,0.404
128.84,146.91,0.404
128.85,147.09,0.405
128.87,147.27,0.405
128.89,147.46,0.405
128.91,147.64,0.405
128.93,147.82,0.405
128.95,148.01,0.405
128.96,148.19,0.405
128.98,148.37,0.406
129.00,148.56,0.406
129.02,148.74,0.406
129.04,148.92,0.406
129.06,149.11,0.406
129.08,149.29,0.406
129.09,149.47,0.406
129.11,149.66,0.407
129.13,149.84,0.407
129.15,150.02,0.407
129.17,150.21,0.407
129.19,150.39,0.407
129.20,150.57,0.407
129.22,150.76,0.408
129.24,150.94,0.408
129.26,151.12,0.408
129.28,151.31,0.408
129.30,151.49,0.408
129.31,151.67,0.408
129.33,151.86,0.408
129.35,152.04,0.408
129.37,152.23,0.409
129.39,152.41,0.409
129.40,152.59,0.409
129.42,152.78,0.409
129.44,152.96,0.409
129.46,153.14,0.409
129.48,153.33,0.410
129.50,153.51,0.410
129.51,153.69,0.410
129.53,153.88,0.410
129.55,154.06,0.410
129.57,154.24,0.410
129.59,154.43,0.410
129.61,154.61,0.411
129.63,154.79,0.411
129.64,154.98,0.411
129.66,155.16,0.411
129.68,155.34,0.411
129.70,155.53,0.411
129.72,155.71,0.411
129.74,155.89,0.412
129.75,156.08,0.412
129.77,156.26,0.412
129.79,156.45,0.412
129.81,156.63,0.412
129.83,156.81,0.412
129.85,157.00,0.412
129.86,157.18,0.412
129.88,157.36,0.412
129.90,157.55,0.413
129.92,157.73,0.413
129.94,157.91,0.413
129.95,158.10,0.413
129.97,158.28,0.413
129.99,158.46,0.413
130.01,158.65,0.413
130.03,158.83,0.413
130.05,159.01,0.414
130.06,159.19,0.414
130.08,159.38,0.414
130.10,159.56,0.414
130.12,159.75,0.414
130.14,159.93,0.414
130.16,160.11,0.414
130.18,160.30,0.414
130.19,160.48,0.415
130.21,160.66,0.415
130.23,160.85,0.415
130.25,161.03,0.415
130.27,161.21,0.415
130.29,161.40,0.415
130.30,161.58,0.415
130.32,161.77,0.416
130.34,161.95,0.416
130.36,162.13,0.416
130.38,162.31,0.416
130.40,162.50,0.416
130.41,162.68,0.416
130.43,162.86,0.416
130.45,163.05,0.416
130.47,163.23,0.416
130.49,163.41,0.417
130.50,163.60,0.417
130.52,163.78,0.417
130.54,163.97,0.417
130.56,164.15,0.417
130.58,164.33,0.417
130.60,164.52,0.417
130.61,164.70,0.417
130.63,164.88,0.418
130.65,165.07,0.418
130.67,165.25,0.418
130.69,165.43,0.418
130.71,165.62,0.418
130.73,165.80,0.418
130.74,165.98,0.418
130.76,166.17,0.419
130.78,166.35,0.419
130.80,166.53,0.419
130.82,166.72,0.419
130.84,166.90,0.419
130.85,167.08,0.419
130.87,167.27,0.420
130.89,167.45,0.420
130.91,167.63,0.420
130.93,167.82,0.420
130.95,168.00,0.420
130.96,168.19,0.420
130.98,168.37,0.421
131.00,168.55,0.421
131.02,168.73,0.421
131.04,168.92,0.421
131.05,169.10,0.421
131.07,169.28,0.421
131.09,169.47,0.421
131.11,169.65,0.421
131.13,169.83,0.421
131.15,170.02,0.422
131.16,170.20,0.422
131.18,170.38,0.422
131.20,170.57,0.422
131.22,170.75,0.422
131.24,170.94,0.422
131.26,171.12,0.422
131.28,171.30,0.423
131.29,171.49,0.423
131.31,171.67,0.423
131.33,171.85,0.423
131.35,172.04,0.423
131.37,172.22,0.423
131.39,172.40,0.424
131.40,172.59,0.424
131.42,172.77,0.424
131.44,172.95,0.424
131.46,173.14,0.424
131.48,173.32,0.424
131.50,173.50,0.424
131.51,173.69,0.424
131.53,173.87,0.425
131.55,174.05,0.425
131.57,174.24,0.425
131.59,174.42,0.425
131.60,174.60,0.425
131.62,174.79,0.426
131.64,174.97,0.426
131.66,175.15,0.426
131.68,175.34,0.426
131.70,175.52,0.426
131.71,175.70,0.426
131.73,175.89,0.427
131.75,176.07,0.427
131.77,176.25,0.427
131.79,176.44,0.427
131.81,176.62,0.427
131.83,176.81,0.427
131.84,176.99,0.428
131.86,177.17,0.428
131.88,177.36,0.428
131.90,177.54,0.428
131.92,177.72,0.428
131.94,177.90,0.429
131.95,178.09,0.429
131.97,178.27,0.429
131.99,178.46,0.429
132.01,178.64,0.429
132.03,178.82,0.430
132.05,179.01,0.430
132.06,179.19,0.430
132.08,179.37,0.430
132.10,179.56,0.430
132.12,179.74,0.430
132.14,179.92,0.431
132.15,180.11,0.431
132.17,180.29,0.431
132.19,180.47,0.431
132.21,180.66,0.431
132.23,180.84,0.432
132.25,181.02,0.432
132.26,181.20,0.432
132.28,181.39,0.432
132.30,181.57,0.432
132.32,181.75,0.433
132.34,181.94,0.433
132.36,182.12,0.433
132.38,182.31,0.434
132.39,182.49,0.434
132.41,182.67,0.434
132.43,182.86,0.435
132.45,183.04,0.435
132.47,183.22,0.435
132.49,183.41,0.435
132.50,183.59,0.436
132.52,183.77,0.436
132.54,183.96,0.437
132.56,184.14,0.437
132.58,184.32,0.437
132.60,184.50,0.438
132.61,184.69,0.438
132.63,184.87,0.439
132.65,185.05,0.439
132.67,185.24,0.440
132.69,185.42,0.441
132.70,185.60,0.442
132.72,185.79,0.442
132.74,185.97,0.443
132.76,186.16,0.444
132.78,186.34,0.444
132.80,186.52,0.445
132.81,186.70,0.445
132.83,186.89,0.446
132.85,187.07,0.446
132.87,187.25,0.446
132.89,187.44,0.447
132.91,187.62,0.447
132.93,187.80,0.448
132.94,187.99,0.448
132.96,188.17,0.449
132.98,188.35,0.449
133.00,188.54,0.450
133.02,188.72,0.450
133.04,188.90,0.451
133.05,189.08,0.452
133.07,189.27,0.452
133.09,189.45,0.453
133.11,189.64,0.453
133.13,189.82,0.454
133.15,190.00,0.455
133.16,190.19,0.455
133.18,190.37,0.456
133.20,190.55,0.456
133.22,190.74,0.457
133.24,190.92,0.457
133.25,191.10,0.458
133.27,191.28,0.458
133.29,191.47,0.459
133.31,191.65,0.460
133.33,191.84,0.461
133.35,192.02,0.461
133.36,192.20,0.462
133.38,192.38,0.462
133.40,192.57,0.463
133.42,192.75,0.463
133.44,192.93,0.464
133.46,193.12,0.465
133.48,193.30,0.465
133.49,193.48,0.466
133.51,193.67,0.466
133.53,193.85,0.467
133.55,194.03,0.468
133.57,194.22,0.468
133.59,194.40,0.469
133.60,194.58,0.469
133.62,194.77,0.470
133.64,194.95,0.471
133.66,195.13,0.471
133.68,195.32,0.472
133.70,195.50,0.473
133.71,195.68,0.474
133.73,195.87,0.474
133.75,196.05,0.475
133.77,196.23,0.476
133.79,196.42,0.476
133.80,196.60,0.477
133.82,196.78,0.478
133.84,196.97,0.479
133.86,197.15,0.479
133.88,197.33,0.480
133.90,197.52,0.481
133.91,197.70,0.481
133.93,197.88,
133.95,198.07,
133.97,198.25,
133.99,,