File: DSC/2025_04_11_Indium_Std_2.csv
Filename,2025_04_11_Indium_Std_2
Instrument name,DSC2A-00468 (192.168.1.100)
Operator,Yarger
rundate,4/11/2025
Sample name,2025_04_11_Indium_Std_2
proceduresegments,Data Off ; Equilibrate 30.00 °C; Data On ; Ramp 5.00 °C/min to 200.00 °C
[File Parameters]
Run date,4/11/2025 4:29:39 PM
Trios version,5.1.1.46572
Original File Name,
Current File Name,D:\DSC2500\JYarger\2025_04_11_Indium_Std_2.tri
[Procedure]
Procedure Name,Indium
Sample Name,2025_04_11_Indium_Std_2
Sample Mass,3.36 mg
Reference Sample Mass,0 mg
Pan Mass,53.42 mg
Pan Number,9
Reference Pan Mass,53.32 mg
Reference Pan Number,10
Pan Type,Tzero Aluminum Hermetic
Comments,Hermetic Sealed Al Tzero Pan/Lids.  Indium Wire.
Project Name,CA
Operator,Yarger
Test,Custom
Unload Max Temperature,30
Unload Min Temperature,30
Load Max Temperature,30
Load Min Temperature,30
Stop on Gas Flow Error,Yes
[Signal List]
Signal #1,Time (min)
Signal #2,Temperature (°C)
Signal #3,Heat Flow (mW)
Signal #4,Delta T (µV)
Signal #5,Delta Tzero (µV)
Signal #6,Tzero Temperature (°C)
Signal #7,Cell Purge (mL/min)
Signal #8,Heater Temp (°C)
Signal #9,Power Delivered (W)
Signal #10,Reference Junction Temperature (°C)
Signal #11,Flange Temperature (°C)
Signal #12,Heat Flow Phase (rad)
Signal #13,Total Heat Capacity (J/°C)
Signal #14,Heat Capacity (J/°C)
[Configuration]
Company Name,ASU
Instrument Name,DSC2A-00468
Instrument Type,DSC2500
Serial Number,DSC2A-00468
IP,192.168.1.100
Location of Instrument,MRRC
DisplayType,Unknown
Sample Interval ,0.1 s/pt
Selected Heat Flow,T4P
Exotherm Direction,Down
Cell Serial,DRC2-00792
Lid Type,Standard
Cooler,RCS 90
Leave Cooler on at End of Sequence,On
Gas 2,Nitrogen
Gas Selected,Channel 1
Flow Rate,50 mL/min
Secondary Purge,On
Licensed Heat Flow,Heat Flow T4P
Modulation Licensed,Yes
[Versions]
Common IDD Version,1
Cortex Version,VER 2.10.2.31
Driver,5.0.0.6
GDM Version,1.0.3.3
TouchscreenVersion,1.0.0.16145
FEP Version,1.2.1.21
FEP Bootloader,2.0.0.5
AutoSampler Version,2.1.1.26
Auto Sampler Bootloader,2.0.0.5
FCM Version,1.1.0.3
FCM Bootloader,2.0.0.5
[Experiment Logs]
Experiment Log Entry # 1,Data On set to 0
Experiment Log Entry # 3,Equilibrate Segment 30 (C) Started
Experiment Log Entry # 5,Air Cool is off.
Experiment Log Entry # 7,Data On set to 1
Experiment Log Entry # 9,Ramp Segment 5 C/min to 200 Started
[Method Log]
Method Log Entry # 1,Data Off
Method Log Entry # 2,Equilibrate 30 °C
Method Log Entry # 3,Data On
Method Log Entry # 4,(Ramp 2098) Ramp 5 °C/minute to 200 °C
Cell Serial,DRC2-00792
[T1 Calibration]
Slope,-0.008529666
Offset,9.636258
Initial Temperature,98.23
GUID,f8bfdadc-4977-4fdf-ba6d-0ba9134940c3
[TZero Calibration]
Date Applied,11/29/2022 4:06:13 PM
Description,From -89.059 °C to 396.009 °C at 20.000°C/min
Gas Type,Nitrogen
Pan Type,None
Source Files 1,C:\Users\yargerlab\Desktop\DSC Data\General\TZero_calibration_11_29_22_2nd(2).tri
Source Files 2,C:\Users\yargerlab\Desktop\DSC Data\General\TZero_calibration_11_29_22_2nd(3).tri
Delta T Offset,13.05235
Delta T Slope,-0.007271007
Delta T0 Offset,-13.69128
Delta T0 Slope,0.06063341
[Temperature Calibration]
Date Applied,11/29/2022 7:12:28 PM
Description,From 106.590 °C to 186.590 °C at 10.000°C/min
Gas Type,Nitrogen
Pan Type,Tzero Aluminum Hermetic
Source Files 1,C:\Users\yargerlab\Desktop\DSC Data\General\Indium(6).tri
Measured 1,157.391
Known 1,156.598
[Cell Constant Calibration]
Date Applied,11/29/2022 7:12:29 PM
Description,From 106.590 °C to 186.590 °C at 10.000°C/min
Gas Type,Nitrogen
Pan Type,Tzero Aluminum Hermetic
Source Files 1,C:\Users\yargerlab\Desktop\DSC Data\General\Indium(6).tri
T4P KCell,1.006051
Onset Slope,63.26126 mW/°C
[Direct Cp Calibration]
Date Applied,11/30/2022 11:04:51 AM
Description,From -79.983 °C to 298.409 °C at 10.000°C/min
Gas Type,Nitrogen
Pan Type,Tzero Aluminum Hermetic
Source Files 1,C:\Users\yargerlab\Desktop\DSC Data\General\Sapphire_Heat_Capacity_11_30_22.tri
[Rev Cp Calibration]
Date Applied,11/30/2022 1:58:51 PM
Description,From -79.996 °C to 292.812 °C at 3.000°C/min
Gas Type,Nitrogen
Pan Type,Tzero Aluminum Hermetic
Source Files 1,C:\Users\yargerlab\Desktop\DSC Data\General\Sapphire_MDSC_Calibration_11_30_22.tri
[step]
Ramp 5.00 °C/min to 200.00 °C
Time,Temperature,Heat Flow (Normalized)
min,°C,W/g
0.00,29.85,-0.048
0.02,29.87,-0.028
0.05,29.89,-0.023
0.07,29.92,-0.019
0.09,29.97,-0.014
0.12,30.04,-0.008
0.14,30.12,0.002
0.16,30.22,0.010
0.19,30.32,0.019
0.21,30.42,0.022
0.23,30.53,0.025
0.26,30.64,0.028
0.28,30.75,0.030
0.30,30.87,0.031
0.33,30.99,0.032
0.35,31.10,0.033
0.37,31.22,0.033
0.40,31.34,0.034
0.42,31.46,0.034
0.44,31.58,0.035
0.47,31.70,0.035
0.49,31.81,0.035
0.51,31.93,0.035
0.54,32.05,0.036
0.56,32.17,0.036
0.58,32.29,0.036
0.61,32.41,0.036
0.63,32.52,0.036
0.65,32.64,0.036
0.68,32.76,0.036
0.70,32.88,0.036
0.72,33.00,0.036
0.75,33.11,0.036
0.77,33.23,0.036
0.79,33.35,0.036
0.82,33.47,0.036
0.84,33.58,0.036
0.86,33.70,0.036
0.89,33.82,0.036
0.91,33.94,0.036
0.93,34.05,0.036
0.96,34.17,0.036
0.98,34.29,0.035
1.00,34.40,0.035
1.03,34.52,0.035
1.05,34.64,0.035
1.07,34.75,0.035
1.10,34.87,0.035
1.12,34.99,0.035
1.14,35.10,0.035
1.17,35.22,0.035
1.19,35.34,0.034
1.21,35.46,0.034
1.24,35.57,0.034
1.26,35.69,0.034
1.28,35.80,0.034
1.31,35.92,0.034
1.33,36.04,0.034
1.35,36.16,0.034
1.38,36.27,0.034
1.40,36.39,0.034
1.42,36.50,0.034
1.45,36.62,0.034
1.47,36.74,0.034
1.49,36.86,0.034
1.52,36.97,0.034
1.54,37.09,0.033
1.56,37.21,0.033
1.59,37.32,0.033
1.61,37.44,0.033
1.63,37.56,0.033
1.66,37.67,0.033
1.68,37.79,0.033
1.70,37.91,0.033
1.73,38.02,0.033
1.75,38.14,0.033
1.77,38.26,0.033
1.80,38.37,0.033
1.82,38.49,0.033
1.84,38.61,0.033
1.87,38.72,0.033
1.89,38.84,0.033
1.91,38.96,0.033
1.94,39.07,0.033
1.96,39.19,0.033
1.98,39.31,0.033
2.01,39.42,0.032
2.03,39.54,0.032
2.05,39.66,0.032
2.08,39.77,0.032
2.10,39.89,0.032
2.12,40.01,0.032
2.15,40.13,0.032
2.17,40.24,0.032
2.19,40.36,0.032
2.22,40.48,0.032
2.24,40.59,0.032
2.26,40.71,0.032
2.29,40.82,0.032
2.31,40.94,0.032
2.33,41.06,0.032
2.36,41.17,0.032
2.38,41.29,0.032
2.40,41.41,0.032
2.43,41.52,0.032
2.45,41.64,0.032
2.47,41.76,0.032
2.50,41.88,0.032
2.52,41.99,0.032
2.54,42.11,0.032
2.57,42.23,0.032
2.59,42.34,0.032
2.61,42.46,0.032
2.64,42.58,0.032
2.66,42.69,0.032
2.68,42.81,0.032
2.71,42.93,0.032
2.73,43.04,0.032
2.75,43.16,0.032
2.78,43.28,0.032
2.80,43.39,0.032
2.82,43.51,0.032
2.85,43.63,0.032
2.87,43.74,0.032
2.89,43.86,0.032
2.92,43.98,0.032
2.94,44.09,0.032
2.96,44.21,0.032
2.99,44.33,0.032
3.01,44.44,0.032
3.03,44.56,0.032
3.06,44.68,0.032
3.08,44.79,0.032
3.10,44.91,0.032
3.13,45.03,0.032
3.15,45.14,0.032
3.17,45.26,0.032
3.20,45.38,0.032
3.22,45.49,0.032
3.24,45.61,0.032
3.27,45.73,0.032
3.29,45.85,0.032
3.31,45.96,0.032
3.34,46.08,0.032
3.36,46.20,0.032
3.38,46.31,0.032
3.41,46.43,0.032
3.43,46.55,0.031
3.45,46.66,0.031
3.48,46.78,0.032
3.50,46.89,0.032
3.52,47.01,0.032
3.55,47.13,0.032
3.57,47.25,0.032
3.59,47.36,0.032
3.62,47.48,0.032
3.64,47.60,0.032
3.66,47.71,0.032
3.69,47.83,0.032
3.71,47.95,0.031
3.73,48.06,0.031
3.76,48.18,0.031
3.78,48.30,0.031
3.80,48.41,0.031
3.83,48.53,0.031
3.85,48.65,0.031
3.87,48.76,0.031
3.90,48.88,0.031
3.92,49.00,0.031
3.94,49.12,0.031
3.97,49.23,0.031
3.99,49.35,0.032
4.01,49.46,0.032
4.04,49.58,0.032
4.06,49.70,0.031
4.08,49.81,0.031
4.11,49.93,0.031
4.13,50.05,0.031
4.15,50.17,0.031
4.18,50.28,0.031
4.20,50.40,0.031
4.22,50.51,0.031
4.25,50.63,0.031
4.27,50.75,0.031
4.29,50.86,0.031
4.32,50.98,0.031
4.34,51.10,0.031
4.36,51.22,0.031
4.39,51.33,0.031
4.41,51.45,0.031
4.43,51.57,0.031
4.46,51.68,0.031
4.48,51.80,0.031
4.50,51.92,0.031
4.53,52.03,0.032
4.55,52.15,0.031
4.57,52.27,0.032
4.60,52.38,0.032
4.62,52.50,0.032
4.64,52.62,0.032
4.67,52.73,0.032
4.69,52.85,0.032
4.71,52.97,0.032
4.74,53.08,0.032
4.76,53.20,0.032
4.78,53.32,0.031
4.81,53.43,0.031
4.83,53.55,0.032
4.85,53.67,0.032
4.88,53.78,0.032
4.90,53.90,0.032
4.92,54.02,0.032
4.95,54.13,0.032
4.97,54.25,0.032
4.99,54.37,0.032
5.02,54.48,0.032
5.04,54.60,0.032
5.06,54.72,0.032
5.09,54.83,0.032
5.11,54.95,0.032
5.13,55.07,0.032
5.16,55.18,0.032
5.18,55.30,0.032
5.20,55.42,0.032
5.23,55.53,0.032
5.25,55.65,0.032
5.27,55.77,0.032
5.30,55.88,0.032
5.32,56.00,0.032
5.34,56.12,0.032
5.37,56.23,0.032
5.39,56.35,0.032
5.41,56.47,0.032
5.44,56.59,0.032
5.46,56.70,0.032
5.48,56.82,0.032
5.51,56.93,0.032
5.53,57.05,0.032
5.55,57.17,0.032
5.58,57.29,0.032
5.60,57.40,0.032
5.62,57.52,0.032
5.65,57.64,0.032
5.67,57.75,0.032
5.69,57.87,0.032
5.72,57.99,0.032
5.74,58.10,0.032
5.76,58.22,0.032
5.79,58.34,0.032
5.81,58.45,0.032
5.83,58.57,0.032
5.86,58.69,0.032
5.88,58.80,0.032
5.90,58.92,0.032
5.93,59.04,0.032
5.95,59.15,0.032
5.97,59.27,0.032
6.00,59.39,0.032
6.02,59.50,0.032
6.04,59.62,0.032
6.07,59.74,0.032
6.09,59.85,0.032
6.11,59.97,0.032
6.14,60.09,0.032
6.16,60.20,0.032
6.18,60.32,0.032
6.21,60.44,0.032
6.23,60.55,0.032
6.25,60.67,0.032
6.28,60.79,0.032
6.30,60.90,0.032
6.32,61.02,0.032
6.35,61.14,0.032
6.37,61.25,0.032
6.39,61.37,0.032
6.42,61.49,0.032
6.44,61.61,0.032
6.46,61.72,0.032
6.49,61.84,0.032
6.51,61.96,0.032
6.53,62.07,0.032
6.56,62.19,0.032
6.58,62.31,0.032
6.60,62.42,0.032
6.63,62.54,0.032
6.65,62.66,0.032
6.67,62.77,0.032
6.70,62.89,0.032
6.72,63.01,0.032
6.74,63.12,0.032
6.77,63.24,0.032
6.79,63.35,0.032
6.81,63.47,0.032
6.84,63.59,0.032
6.86,63.71,0.032
6.88,63.82,0.032
6.91,63.94,0.032
6.93,64.06,0.032
6.95,64.17,0.032
6.98,64.29,0.032
7.00,64.41,0.032
7.02,64.52,0.032
7.05,64.64,0.032
7.07,64.76,0.032
7.09,64.87,0.032
7.12,64.99,0.032
7.14,65.11,0.032
7.16,65.22,0.032
7.19,65.34,0.032
7.21,65.46,0.032
7.23,65.58,0.032
7.26,65.69,0.032
7.28,65.81,0.032
7.30,65.92,0.032
7.33,66.04,0.032
7.35,66.16,0.032
7.37,66.27,0.032
7.40,66.39,0.032
7.42,66.51,0.032
7.44,66.63,0.032
7.47,66.74,0.032
7.49,66.86,0.032
7.51,66.97,0.032
7.54,67.09,0.032
7.56,67.21,0.032
7.58,67.32,0.032
7.61,67.44,0.032
7.63,67.56,0.032
7.65,67.67,0.032
7.68,67.79,0.032
7.70,67.91,0.032
7.72,68.02,0.032
7.75,68.14,0.032
7.77,68.26,0.032
7.79,68.37,0.032
7.82,68.49,0.032
7.84,68.61,0.032
7.86,68.72,0.032
7.89,68.84,0.032
7.91,68.96,0.032
7.93,69.08,0.032
7.96,69.19,0.032
7.98,69.31,0.032
8.00,69.43,0.032
8.03,69.54,0.033
8.05,69.66,0.033
8.07,69.78,0.033
8.10,69.89,0.033
8.12,70.01,0.033
8.14,70.13,0.033
8.17,70.24,0.033
8.19,70.36,0.033
8.21,70.48,0.033
8.24,70.59,0.033
8.26,70.71,0.033
8.28,70.83,0.033
8.31,70.94,0.033
8.33,71.06,0.033
8.35,71.18,0.033
8.38,71.29,0.033
8.40,71.41,0.033
8.42,71.53,0.033
8.45,71.64,0.033
8.47,71.76,0.033
8.49,71.88,0.033
8.52,71.99,0.033
8.54,72.11,0.033
8.56,72.23,0.033
8.59,72.34,0.033
8.61,72.46,0.033
8.63,72.58,0.033
8.66,72.69,0.033
8.68,72.81,0.033
8.70,72.93,0.033
8.73,73.04,0.033
8.75,73.16,0.033
8.77,73.28,0.033
8.80,73.39,0.033
8.82,73.51,0.033
8.84,73.63,0.033
8.87,73.75,0.033
8.89,73.86,0.033
8.91,73.98,0.033
8.94,74.10,0.033
8.96,74.21,0.033
8.98,74.33,0.033
9.01,74.44,0.033
9.03,74.56,0.033
9.05,74.68,0.033
9.08,74.79,0.033
9.10,74.91,0.033
9.12,75.03,0.033
9.15,75.15,0.033
9.17,75.26,0.033
9.19,75.38,0.033
9.22,75.50,0.033
9.24,75.61,0.033
9.26,75.73,0.033
9.29,75.85,0.033
9.31,75.96,0.033
9.33,76.08,0.033
9.36,76.20,0.033
9.38,76.31,0.033
9.40,76.43,0.033
9.43,76.55,0.033
9.45,76.66,0.033
9.47,76.78,0.033
9.50,76.90,0.033
9.52,77.01,0.033
9.54,77.13,0.033
9.57,77.25,0.033
9.59,77.36,0.033
9.61,77.48,0.033
9.64,77.60,0.033
9.66,77.71,0.033
9.68,77.83,0.033
9.71,77.95,0.033
9.73,78.06,0.033
9.75,78.18,0.033
9.78,78.30,0.033
9.80,78.41,0.033
9.82,78.53,0.033
9.85,78.65,0.033
9.87,78.77,0.033
9.89,78.88,0.033
9.92,79.00,0.033
9.94,79.11,0.033
9.96,79.23,0.033
9.99,79.35,0.033
10.01,79.46,0.033
10.03,79.58,0.033
10.06,79.70,0.033
10.08,79.81,0.033
10.10,79.93,0.033
10.13,80.05,0.033
10.15,80.16,0.034
10.17,80.28,0.034
10.20,80.40,0.034
10.22,80.52,0.034
10.24,80.63,0.034
10.27,80.75,0.034
10.29,80.87,0.034
10.31,80.98,0.034
10.34,81.10,0.034
10.36,81.22,0.034
10.38,81.33,0.034
10.41,81.45,0.033
10.43,81.57,0.033
10.45,81.68,0.033
10.48,81.80,0.033
10.50,81.92,0.033
10.52,82.03,0.033
10.55,82.15,0.033
10.57,82.27,0.033
10.59,82.38,0.033
10.62,82.50,0.033
10.64,82.62,0.033
10.66,82.73,0.033
10.69,82.85,0.034
10.71,82.97,0.034
10.73,83.08,0.034
10.76,83.20,0.033
10.78,83.32,0.033
10.80,83.43,0.033
10.83,83.55,0.033
10.85,83.67,0.034
10.87,83.78,0.033
10.90,83.90,0.033
10.92,84.02,0.033
10.94,84.13,0.033
10.97,84.25,0.033
10.99,84.37,0.034
11.01,84.48,0.034
11.04,84.60,0.034
11.06,84.72,0.034
11.08,84.83,0.033
11.11,84.95,0.034
11.13,85.07,0.034
11.15,85.18,0.033
11.18,85.30,0.033
11.20,85.42,0.034
11.22,85.53,0.034
11.25,85.65,0.034
11.27,85.77,0.034
11.29,85.88,0.034
11.32,86.00,0.033
11.34,86.12,0.034
11.36,86.23,0.034
11.39,86.35,0.034
11.41,86.47,0.034
11.43,86.59,0.034
11.46,86.70,0.034
11.48,86.82,0.034
11.50,86.93,0.034
11.53,87.05,0.033
11.55,87.17,0.034
11.57,87.29,0.034
11.60,87.40,0.034
11.62,87.52,0.034
11.64,87.63,0.034
11.67,87.75,0.034
11.69,87.87,0.034
11.71,87.99,0.034
11.74,88.10,0.034
11.76,88.22,0.034
11.78,88.34,0.034
11.81,88.45,0.034
11.83,88.57,0.034
11.85,88.69,0.034
11.88,88.80,0.034
11.90,88.92,0.034
11.92,89.04,0.034
11.95,89.15,0.034
11.97,89.27,0.034
11.99,89.39,0.034
12.02,89.50,0.034
12.04,89.62,0.034
12.06,89.74,0.034
12.09,89.85,0.034
12.11,89.97,0.034
12.13,90.09,0.034
12.16,90.20,0.034
12.18,90.32,0.034
12.20,90.44,0.034
12.23,90.55,0.034
12.25,90.67,0.034
12.27,90.79,0.034
12.30,90.90,0.034
12.32,91.02,0.034
12.34,91.14,0.034
12.37,91.25,0.034
12.39,91.37,0.034
12.41,91.49,0.034
12.44,91.60,0.034
12.46,91.72,0.034
12.48,91.84,0.034
12.51,91.95,0.034
12.53,92.07,0.034
12.55,92.19,0.034
12.58,92.30,0.034
12.60,92.42,0.034
12.62,92.54,0.034
12.65,92.65,0.034
12.67,92.77,0.034
12.69,92.89,0.034
12.72,93.01,0.034
12.74,93.12,0.034
12.76,93.24,0.034
12.79,93.36,0.034
12.81,93.47,0.034
12.83,93.59,0.034
12.86,93.71,0.034
12.88,93.82,0.034
12.90,93.94,0.034
12.93,94.06,0.034
12.95,94.17,0.034
12.97,94.29,0.034
13.00,94.41,0.034
13.02,94.52,0.034
13.04,94.64,0.035
13.07,94.76,0.034
13.09,94.87,0.034
13.11,94.99,0.034
13.14,95.10,0.034
13.16,95.22,0.034
13.18,95.34,0.035
13.21,95.46,0.035
13.23,95.57,0.035
13.25,95.69,0.035
13.28,95.81,0.035
13.30,95.92,0.035
13.32,96.04,0.035
13.35,96.16,0.035
13.37,96.27,0.035
13.39,96.39,0.035
13.42,96.51,0.035
13.44,96.62,0.035
13.46,96.74,0.035
13.49,96.86,0.035
13.51,96.97,0.035
13.53,97.09,0.035
13.56,97.21,0.035
13.58,97.32,0.035
13.60,97.44,0.035
13.63,97.56,0.035
13.65,97.67,0.035
13.67,97.79,0.035
13.70,97.91,0.035
13.72,98.02,0.035
13.74,98.14,0.035
13.77,98.26,0.035
13.79,98.37,0.035
13.81,98.49,0.035
13.84,98.61,0.035
13.86,98.72,0.035
13.88,98.84,0.035
13.91,98.96,0.035
13.93,99.07,0.035
13.95,99.19,0.035
13.98,99.31,0.035
14.00,99.42,0.035
14.02,99.54,0.035
14.05,99.66,0.035
14.07,99.77,0.035
14.09,99.89,0.035
14.12,100.01,0.035
14.14,100.12,0.035
14.16,100.24,0.035
14.19,100.36,0.035
14.21,100.47,0.035
14.23,100.59,0.035
14.26,100.71,0.035
14.28,100.83,0.035
14.30,100.94,0.035
14.33,101.06,0.035
14.35,101.17,0.035
14.37,101.29,0.035
14.40,101.41,0.035
14.42,101.52,0.035
14.44,101.64,0.035
14.47,101.76,0.035
14.49,101.88,0.035
14.51,101.99,0.035
14.54,102.11,0.035
14.56,102.23,0.035
14.58,102.34,0.035
14.61,102.46,0.035
14.63,102.58,0.035
14.65,102.69,0.035
14.68,102.81,0.035
14.70,102.92,0.035
14.72,103.04,0.035
14.75,103.16,0.035
14.77,103.28,0.035
14.79,103.39,0.035
14.82,103.51,0.035
14.84,103.63,0.035
14.86,103.74,0.035
14.89,103.86,0.035
14.91,103.98,0.035
14.93,104.09,0.035
14.96,104.21,0.036
14.98,104.32,0.035
15.00,104.44,0.036
15.03,104.56,0.036
15.05,104.68,0.036
15.07,104.79,0.036
15.10,104.91,0.036
15.12,105.03,0.036
15.14,105.14,0.036
15.17,105.26,0.036
15.19,105.38,0.036
15.21,105.49,0.036
15.24,105.61,0.036
15.26,105.73,0.036
15.28,105.84,0.036
15.31,105.96,0.036
15.33,106.07,0.036
15.35,106.19,0.036
15.38,106.31,0.035
15.40,106.43,0.035
15.42,106.54,0.036
15.45,106.66,0.036
15.47,106.78,0.036
15.49,106.89,0.036
15.52,107.01,0.036
15.54,107.13,0.036
15.56,107.24,0.036
15.59,107.36,0.036
15.61,107.48,0.036
15.63,107.59,0.036
15.66,107.71,0.036
15.68,107.83,0.036
15.70,107.94,0.036
15.73,108.06,0.036
15.75,108.18,0.036
15.77,108.29,0.036
15.80,108.41,0.036
15.82,108.53,0.036
15.84,108.64,0.036
15.87,108.76,0.036
15.89,108.88,0.036
15.91,109.00,0.036
15.94,109.11,0.036
15.96,109.23,0.036
15.98,109.35,0.036
16.01,109.46,0.036
16.03,109.58,0.036
16.05,109.69,0.036
16.08,109.81,0.036
16.10,109.93,0.036
16.12,110.04,0.036
16.15,110.16,0.036
16.17,110.28,0.036
16.19,110.40,0.036
16.22,110.51,0.036
16.24,110.63,0.036
16.26,110.75,0.036
16.29,110.86,0.036
16.31,110.98,0.036
16.33,111.10,0.036
16.36,111.21,0.036
16.38,111.33,0.036
16.40,111.44,0.036
16.43,111.56,0.036
16.45,111.68,0.036
16.47,111.79,0.036
16.50,111.91,0.036
16.52,112.03,0.036
16.54,112.15,0.036
16.57,112.26,0.036
16.59,112.38,0.036
16.61,112.50,0.036
16.64,112.61,0.036
16.66,112.73,0.036
16.68,112.85,0.036
16.71,112.96,0.036
16.73,113.08,0.036
16.75,113.20,0.036
16.78,113.31,0.036
16.80,113.43,0.036
16.82,113.55,0.036
16.85,113.66,0.036
16.87,113.78,0.036
16.89,113.90,0.036
16.92,114.01,0.036
16.94,114.13,0.036
16.96,114.25,0.036
16.99,114.36,0.036
17.01,114.48,0.036
17.03,114.60,0.036
17.06,114.71,0.036
17.08,114.83,0.036
17.10,114.95,0.036
17.13,115.06,0.036
17.15,115.18,0.036
17.17,115.30,0.036
17.20,115.41,0.036
17.22,115.53,0.036
17.24,115.65,0.036
17.27,115.77,0.036
17.29,115.88,0.036
17.31,116.00,0.036
17.34,116.12,0.036
17.36,116.23,0.036
17.38,116.35,0.036
17.41,116.46,0.036
17.43,116.58,0.036
17.45,116.70,0.036
17.48,116.82,0.036
17.50,116.93,0.036
17.52,117.05,0.036
17.55,117.17,0.036
17.57,117.28,0.036
17.59,117.40,0.036
17.62,117.51,0.036
17.64,117.63,0.036
17.66,117.75,0.037
17.69,117.86,0.037
17.71,117.98,0.037
17.73,118.10,0.037
17.76,118.22,0.037
17.78,118.33,0.037
17.80,118.45,0.037
17.83,118.57,0.037
17.85,118.68,0.037
17.87,118.80,0.037
17.90,118.92,0.037
17.92,119.03,0.037
17.94,119.15,0.037
17.97,119.27,0.037
17.99,119.38,0.037
18.01,119.50,0.037
18.04,119.62,0.037
18.06,119.73,0.037
18.08,119.85,0.037
18.11,119.97,0.037
18.13,120.08,0.037
18.15,120.20,0.037
18.18,120.32,0.037
18.20,120.43,0.037
18.22,120.55,0.037
18.25,120.67,0.037
18.27,120.78,0.037
18.29,120.90,0.037
18.32,121.02,0.037
18.34,121.13,0.037
18.36,121.25,0.037
18.39,121.37,0.037
18.41,121.48,0.037
18.43,121.60,0.037
18.46,121.72,0.037
18.48,121.83,0.037
18.50,121.95,0.037
18.53,122.07,0.037
18.55,122.18,0.037
18.57,122.30,0.037
18.60,122.42,0.037
18.62,122.53,0.037
18.64,122.65,0.037
18.67,122.77,0.037
18.69,122.88,0.037
18.71,123.00,0.037
18.74,123.12,0.037
18.76,123.23,0.037
18.78,123.35,0.037
18.81,123.47,0.037
18.83,123.58,0.037
18.85,123.70,0.037
18.88,123.82,0.037
18.90,123.93,0.037
18.92,124.05,0.037
18.95,124.17,0.037
18.97,124.28,0.038
18.99,124.40,0.038
19.02,124.52,0.038
19.04,124.63,0.037
19.06,124.75,0.038
19.09,124.87,0.038
19.11,124.98,0.038
19.13,125.10,0.038
19.16,125.22,0.038
19.18,125.33,0.038
19.20,125.45,0.038
19.23,125.57,0.038
19.25,125.68,0.038
19.27,125.80,0.038
19.30,125.92,0.038
19.32,126.03,0.038
19.34,126.15,0.038
19.37,126.27,0.038
19.39,126.38,0.038
19.41,126.50,0.038
19.44,126.62,0.038
19.46,126.74,0.038
19.48,126.85,0.038
19.51,126.97,0.038
19.53,127.08,0.038
19.55,127.20,0.038
19.58,127.32,0.038
19.60,127.43,0.038
19.62,127.55,0.038
19.65,127.67,0.038
19.67,127.78,0.038
19.69,127.90,0.038
19.72,128.02,0.038
19.74,128.13,0.038
19.76,128.25,0.038
19.79,128.37,0.038
19.81,128.48,0.038
19.83,128.60,0.038
19.86,128.72,0.038
19.88,128.83,0.038
19.90,128.95,0.038
19.93,129.07,0.038
19.95,129.19,0.038
19.97,129.30,0.038
20.00,129.42,0.038
20.02,129.54,0.038
20.04,129.65,0.038
20.07,129.77,0.038
20.09,129.89,0.038
20.11,130.00,0.038
20.14,130.12,0.038
20.16,130.24,0.038
20.18,130.35,0.038
20.21,130.47,0.038
20.23,130.59,0.038
20.25,130.70,0.038
20.28,130.82,0.038
20.30,130.93,0.038
20.32,131.05,0.038
20.35,131.17,0.038
20.37,131.29,0.038
20.39,131.40,0.038
20.42,131.52,0.038
20.44,131.63,0.038
20.46,131.75,0.038
20.49,131.87,0.038
20.51,131.98,0.038
20.53,132.10,0.038
20.56,132.22,0.039
20.58,132.34,0.038
20.60,132.45,0.039
20.63,132.57,0.038
20.65,132.69,0.039
20.67,132.80,0.039
20.70,132.92,0.039
20.72,133.04,0.039
20.74,133.15,0.038
20.77,133.27,0.039
20.79,133.39,0.038
20.81,133.50,0.038
20.84,133.62,0.038
20.86,133.74,0.039
20.88,133.85,0.039
20.91,133.97,0.039
20.93,134.09,0.039
20.95,134.20,0.039
20.98,134.32,0.039
21.00,134.44,0.039
21.02,134.55,0.039
21.05,134.67,0.039
21.07,134.79,0.039
21.09,134.90,0.039
21.12,135.02,0.039
21.14,135.14,0.039
21.16,135.25,0.039
21.19,135.37,0.039
21.21,135.49,0.039
21.23,135.60,0.039
21.26,135.72,0.039
21.28,135.84,0.039
21.30,135.95,0.039
21.33,136.07,0.039
21.35,136.19,0.039
21.37,136.30,0.039
21.40,136.42,0.039
21.42,136.54,0.039
21.44,136.65,0.039
21.47,136.77,0.039
21.49,136.89,0.039
21.51,137.00,0.039
21.54,137.12,0.039
21.56,137.24,0.039
21.58,137.35,0.039
21.61,137.47,0.039
21.63,137.59,0.039
21.65,137.70,0.039
21.68,137.82,0.039
21.70,137.94,0.039
21.72,138.05,0.039
21.75,138.17,0.039
21.77,138.29,0.039
21.79,138.41,0.039
21.82,138.52,0.039
21.84,138.64,0.039
21.86,138.75,0.039
21.89,138.87,0.039
21.91,138.99,0.039
21.93,139.10,0.039
21.96,139.22,0.039
21.98,139.34,0.039
22.00,139.46,0.039
22.03,139.57,0.039
22.05,139.69,0.039
22.07,139.81,0.040
22.10,139.92,0.040
22.12,140.04,0.040
22.14,140.15,0.040
22.17,140.27,0.040
22.19,140.39,0.040
22.21,140.50,0.040
22.24,140.62,0.040
22.26,140.74,0.040
22.28,140.85,0.040
22.31,140.97,0.040
22.33,141.09,0.040
22.35,141.21,0.040
22.38,141.32,0.040
22.40,141.44,0.040
22.42,141.55,0.040
22.45,141.67,0.040
22.47,141.79,0.040
22.49,141.91,0.040
22.52,142.02,0.040
22.54,142.14,0.040
22.56,142.26,0.040
22.59,142.37,0.040
22.61,142.49,0.040
22.63,142.60,0.040
22.66,142.72,0.040
22.68,142.84,0.040
22.70,142.96,0.040
22.73,143.07,0.040
22.75,143.19,0.040
22.77,143.31,0.040
22.80,143.42,0.040
22.82,143.54,0.040
22.84,143.66,0.040
22.87,143.77,0.040
22.89,143.89,0.040
22.91,144.01,0.040
22.94,144.12,0.040
22.96,144.24,0.040
22.98,144.35,0.040
23.01,144.47,0.040
23.03,144.59,0.040
23.05,144.71,0.040
23.08,144.82,0.040
23.10,144.94,0.040
23.12,145.06,0.040
23.15,145.17,0.040
23.17,145.29,0.041
23.19,145.41,0.041
23.22,145.52,0.041
23.24,145.64,0.041
23.26,145.76,0.041
23.29,145.87,0.041
23.31,145.99,0.041
23.33,146.11,0.041
23.36,146.22,0.041
23.38,146.34,0.041
23.40,146.46,0.041
23.43,146.57,0.041
23.45,146.69,0.041
23.47,146.81,0.041
23.50,146.92,0.041
23.52,147.04,0.041
23.54,147.16,0.041
23.57,147.27,0.041
23.59,147.39,0.041
23.61,147.51,0.041
23.64,147.62,0.041
23.66,147.74,0.041
23.68,147.86,0.041
23.71,147.97,0.041
23.73,148.09,0.041
23.75,148.21,0.041
23.78,148.32,0.041
23.80,148.44,0.041
23.82,148.56,0.041
23.85,148.67,0.041
23.87,148.79,0.041
23.89,148.91,0.041
23.92,149.02,0.041
23.94,149.14,0.041
23.96,149.26,0.041
23.99,149.37,0.041
24.01,149.49,0.041
24.03,149.61,0.041
24.06,149.72,0.041
24.08,149.84,0.041
24.10,149.96,0.041
24.13,150.07,0.041
24.15,150.19,0.041
24.17,150.31,0.041
24.20,150.42,0.041
24.22,150.54,0.041
24.24,150.66,0.041
24.27,150.77,0.041
24.29,150.89,0.041
24.31,151.01,0.041
24.34,151.12,0.041
24.36,151.24,0.041
24.38,151.36,0.041
24.41,151.47,0.041
24.43,151.59,0.041
24.45,151.71,0.041
24.48,151.82,0.041
24.50,151.94,0.041
24.52,152.06,0.041
24.55,152.17,0.041
24.57,152.29,0.041
24.59,152.41,0.041
24.62,152.52,0.041
24.64,152.64,0.041
24.66,152.76,0.042
24.69,152.87,0.042
24.71,152.99,0.042
24.73,153.11,0.042
24.76,153.22,0.042
24.78,153.34,0.042
24.80,153.46,0.042
24.83,153.57,0.042
24.85,153.69,0.042
24.87,153.81,0.042
24.90,153.92,0.042
24.92,154.04,0.042
24.94,154.16,0.042
24.97,154.27,0.042
24.99,154.39,0.042
25.01,154.51,0.042
25.04,154.62,0.042
25.06,154.74,0.042
25.08,154.86,0.042
25.11,154.97,0.042
25.13,155.09,0.042
25.15,155.21,0.042
25.18,155.32,0.042
25.20,155.44,0.042
25.22,155.56,0.042
25.25,155.67,0.042
25.27,155.79,0.042
25.29,155.91,0.042
25.32,156.03,0.043
25.34,156.14,0.043
25.36,156.26,0.043
25.39,156.38,0.043
25.41,156.49,0.044
25.43,156.61,0.061
25.46,156.72,0.146
25.48,156.82,0.290
25.50,156.92,0.444
25.53,157.01,0.600
25.55,157.10,0.746
25.57,157.19,0.883
25.60,157.28,1.027
25.62,157.37,1.174
25.64,157.46,1.325
25.67,157.54,1.451
25.69,157.64,1.597
25.71,157.72,1.718
25.74,157.81,1.854
25.76,157.91,1.925
25.78,158.00,1.964
25.81,158.11,1.654
25.83,158.31,0.662
25.85,158.50,0.474
25.88,158.67,0.360
25.90,158.83,0.277
25.92,158.97,0.215
25.95,159.11,0.173
25.97,159.24,0.140
25.99,159.37,0.114
26.02,159.50,0.096
26.04,159.62,0.080
26.06,159.74,0.072
26.09,159.86,0.065
26.11,159.98,0.061
26.13,160.10,0.055
26.16,160.22,0.054
26.18,160.34,0.052
26.20,160.46,0.051
26.23,160.57,0.050
26.25,160.69,0.049
26.27,160.81,0.049
26.30,160.93,0.048
26.32,161.04,0.048
26.34,161.16,0.048
26.37,161.27,0.047
26.39,161.39,0.047
26.41,161.51,0.047
26.44,161.62,0.046
26.46,161.74,0.046
26.48,161.86,0.046
26.51,161.97,0.045
26.53,162.09,0.045
26.55,162.21,0.045
26.58,162.32,0.045
26.60,162.44,0.045
26.62,162.56,0.045
26.65,162.67,0.045
26.67,162.79,0.045
26.69,162.91,0.045
26.72,163.02,0.045
26.74,163.14,0.045
26.76,163.26,0.045
26.79,163.37,0.045
26.81,163.49,0.045
26.83,163.61,0.045
26.86,163.73,0.045
26.88,163.84,0.045
26.90,163.96,0.045
26.93,164.08,0.045
26.95,164.19,0.045
26.97,164.31,0.045
27.00,164.43,0.045
27.02,164.54,0.045
27.04,164.66,0.045
27.07,164.78,0.045
27.09,164.89,0.045
27.11,165.01,0.045
27.14,165.13,0.045
27.16,165.24,0.045
27.18,165.36,0.045
27.21,165.48,0.045
27.23,165.59,0.045
27.25,165.71,0.045
27.28,165.83,0.045
27.30,165.94,0.045
27.32,166.06,0.045
27.35,166.17,0.045
27.37,166.29,0.045
27.39,166.41,0.045
27.42,166.52,0.045
27.44,166.64,0.045
27.46,166.76,0.045
27.49,166.88,0.045
27.51,166.99,0.045
27.53,167.11,0.045
27.56,167.23,0.045
27.58,167.34,0.045
27.60,167.46,0.045
27.63,167.58,0.045
27.65,167.69,0.045
27.67,167.81,0.045
27.70,167.93,0.045
27.72,168.04,0.045
27.74,168.16,0.045
27.77,168.28,0.045
27.79,168.39,0.045
27.81,168.51,0.045
27.84,168.63,0.045
27.86,168.74,0.046
27.88,168.86,0.046
27.91,168.98,0.046
27.93,169.09,0.046
27.95,169.21,0.046
27.98,169.33,0.046
28.00,169.44,0.046
28.02,169.56,0.046
28.05,169.68,0.046
28.07,169.79,0.046
28.09,169.91,0.046
28.12,170.03,0.046
28.14,170.14,0.046
28.16,170.26,0.046
28.19,170.38,0.046
28.21,170.49,0.046
28.23,170.61,0.046
28.26,170.73,0.046
28.28,170.84,0.046
28.30,170.96,0.046
28.33,171.08,0.046
28.35,171.19,0.046
28.37,171.31,0.046
28.40,171.43,0.046
28.42,171.54,0.046
28.44,171.66,0.046
28.47,171.78,0.046
28.49,171.89,0.046
28.51,172.01,0.046
28.54,172.13,0.046
28.56,172.24,0.046
28.58,172.36,0.046
28.61,172.48,0.046
28.63,172.59,0.046
28.65,172.71,0.046
28.68,172.83,0.046
28.70,172.94,0.046
28.72,173.06,0.046
28.75,173.18,0.046
28.77,173.29,0.046
28.79,173.41,0.046
28.82,173.53,0.046
28.84,173.64,0.046
28.86,173.76,0.047
28.89,173.88,0.047
28.91,173.99,0.047
28.93,174.11,0.047
28.96,174.23,0.047
28.98,174.34,0.047
29.00,174.46,0.047
29.03,174.58,0.047
29.05,174.69,0.047
29.07,174.81,0.047
29.10,174.93,0.047
29.12,175.04,0.047
29.14,175.16,0.047
29.17,175.28,0.047
29.19,175.39,0.047
29.21,175.51,0.047
29.24,175.63,0.047
29.26,175.74,0.047
29.28,175.86,0.047
29.31,175.98,0.047
29.33,176.09,0.047
29.35,176.21,0.047
29.38,176.33,0.047
29.40,176.44,0.047
29.42,176.56,0.047
29.45,176.68,0.047
29.47,176.79,0.048
29.49,176.91,0.048
29.52,177.03,0.048
29.54,177.15,0.048
29.56,177.26,0.048
29.59,177.38,0.048
29.61,177.49,0.048
29.63,177.61,0.048
29.66,177.73,0.048
29.68,177.84,0.048
29.70,177.96,0.048
29.73,178.08,0.048
29.75,178.19,0.048
29.77,178.31,0.048
29.80,178.43,0.048
29.82,178.54,0.048
29.84,178.66,0.048
29.87,178.78,0.048
29.89,178.90,0.048
29.91,179.01,0.048
29.94,179.13,0.048
29.96,179.25,0.048
29.98,179.36,0.048
30.01,179.48,0.048
30.03,179.60,0.048
30.05,179.71,0.048
30.08,179.83,0.048
30.10,179.95,0.048
30.12,180.06,0.048
30.15,180.18,0.048
30.17,180.30,0.048
30.19,180.41,0.048
30.22,180.53,0.048
30.24,180.65,0.048
30.26,180.76,0.048
30.29,180.88,0.048
30.31,181.00,0.048
30.33,181.11,0.048
30.36,181.23,0.048
30.38,181.35,0.048
30.40,181.46,0.048
30.43,181.58,0.048
30.45,181.70,0.048
30.47,181.81,0.048
30.50,181.93,0.048
30.52,182.05,0.048
30.54,182.16,0.048
30.57,182.28,0.048
30.59,182.40,0.048
30.61,182.51,0.048
30.64,182.63,0.048
30.66,182.75,0.048
30.68,182.86,0.048
30.71,182.98,0.048
30.73,183.10,0.048
30.75,183.21,0.048
30.78,183.33,0.048
30.80,183.45,0.048
30.82,183.56,0.048
30.85,183.68,0.048
30.87,183.79,0.048
30.89,183.91,0.048
30.92,184.03,0.048
30.94,184.14,0.048
30.96,184.26,0.048
30.99,184.38,0.048
31.01,184.49,0.048
31.03,184.61,0.048
31.06,184.73,0.048
31.08,184.85,0.048
31.10,184.96,0.048
31.13,185.08,0.048
31.15,185.19,0.048
31.17,185.31,0.049
31.20,185.43,0.048
31.22,185.54,0.049
31.24,185.66,0.049
31.27,185.78,0.049
31.29,185.90,0.049
31.31,186.01,0.049
31.34,186.13,0.049
31.36,186.25,0.049
31.38,186.36,0.049
31.41,186.48,0.049
31.43,186.60,0.049
31.45,186.71,0.049
31.48,186.83,0.049
31.50,186.95,0.049
31.52,187.06,0.049
31.55,187.18,0.049
31.57,187.30,0.049
31.59,187.41,0.049
31.62,187.53,0.049
31.64,187.65,0.049
31.66,187.76,0.049
31.69,187.88,0.050
31.71,188.00,0.050
31.73,188.11,0.050
31.76,188.23,0.050
31.78,188.35,0.050
31.80,188.46,0.050
31.83,188.58,0.050
31.85,188.69,0.050
31.87,188.81,0.050
31.90,188.93,0.050
31.92,189.04,0.050
31.94,189.16,0.050
31.97,189.28,0.050
31.99,189.40,0.050
32.01,189.51,0.050
32.04,189.63,0.050
32.06,189.74,0.050
32.08,189.86,0.050
32.11,189.98,0.050
32.13,190.09,0.050
32.15,190.21,0.050
32.18,190.33,0.050
32.20,190.44,0.050
32.22,190.56,0.050
32.25,190.68,0.050
32.27,190.79,0.050
32.29,190.91,0.051
32.32,191.03,0.051
32.34,191.15,0.051
32.36,191.26,0.051
32.39,191.38,0.051
32.41,191.50,0.051
32.43,191.61,0.051
32.46,191.73,0.051
32.48,191.84,0.051
32.50,191.96,0.051
32.53,192.08,0.051
32.55,192.19,0.051
32.57,192.31,0.051
32.60,192.43,0.051
32.62,192.55,0.051
32.64,192.66,0.051
32.67,192.78,0.051
32.69,192.89,0.051
32.71,193.01,0.052
32.74,193.13,0.052
32.76,193.24,0.052
32.78,193.36,0.052
32.81,193.48,0.052
32.83,193.59,0.052
32.85,193.71,0.052
32.88,193.83,0.052
32.90,193.94,0.052
32.92,194.06,0.052
32.95,194.18,0.052
32.97,194.30,0.052
32.99,194.41,0.052
33.02,194.53,0.052
33.04,194.65,0.052
33.06,194.76,0.052
33.09,194.88,0.052
33.11,195.00,0.052
33.13,195.11,0.052
33.16,195.23,0.052
33.18,195.35,0.052
33.20,195.46,0.052
33.23,195.58,0.052
33.25,195.70,0.052
33.27,195.81,0.052
33.30,195.93,0.052
33.32,196.05,0.052
33.34,196.16,0.052
33.37,196.28,0.052
33.39,196.40,0.052
33.41,196.51,0.052
33.44,196.63,0.052
33.46,196.75,0.052
33.48,196.86,0.052
33.51,196.98,0.052
33.53,197.10,0.052
33.55,197.21,0.052
33.58,197.33,0.052
33.60,197.45,0.052
33.62,197.56,0.052
33.65,197.68,0.052
33.67,197.80,0.052
33.69,197.91,0.052
33.72,198.03,0.052
33.74,198.15,0.052
33.76,198.26,0.052
33.79,198.38,0.052
33.81,198.50,0.052
33.83,198.61,0.052
33.86,198.73,0.052
33.88,198.85,0.052
33.90,198.96,0.052
33.93,199.08,0.053
33.95,199.20,
33.97,199.31,
33.99,,