File: DSC/2025_04_13_CBN_Pro_Slurry_Heptane_n60C_130C_10Cmin_x3.csv
Filename,2025_04_13_CBN_Pro_Slurry_Heptane_n60C_130C_10Cmin_x3
Instrument name,DSC2A-00468 (192.168.1.100)
Operator,Yarger
rundate,4/13/2025
Sample name,2025_04_13_CBN_Pro_Slurry_Heptane_n60C_130C_10Cmin_x3
proceduresegments,Data Off ; Equilibrate -60.00 °C; Data On ; Ramp 10.00 °C/min to 130.00 °C; Data Off ; Isothermal 1.0 min; Data On ; Ramp 10.00 °C/min to -60.00 °C; Data Off ; Isothermal 1.0 min; Data On ; Ramp 10.00 °C/min to 130.00 °C; Data Off ; Isothermal 1.0 min; Data On ; Ramp 10.00 °C/min to -60.00 °C; Data Off ; Isothermal 1.0 min; Data On ; Ramp 10.00 °C/min to 130.00 °C
[File Parameters]
Run date,4/13/2025 5:07:23 PM
Trios version,5.1.1.46572
Original File Name,
Current File Name,D:\DSC2500\JYarger\2025_04_13_CBN_Pro_Slurry_Heptane_n60C_130C_10Cmin_x3.tri
[Procedure]
Procedure Name,CBN_Pro_n60_130C_10Cmin_x3
Sample Name,2025_04_13_CBN_Pro_Slurry_Heptane_n60C_130C_10Cmin_x3
Sample Mass,2.75 mg
Reference Sample Mass,0 mg
Pan Mass,53.7 mg
Pan Number,27
Reference Pan Mass,53.32 mg
Reference Pan Number,10
Pan Type,Tzero Aluminum Hermetic
Comments,Hermetic Sealed Al DSC Consumables Pan/Lids.
Project Name,CA
Operator,Yarger
Test,Custom
Unload Max Temperature,30
Unload Min Temperature,30
Load Max Temperature,30
Load Min Temperature,30
Stop on Gas Flow Error,Yes
[Signal List]
Signal #1,Time (min)
Signal #2,Temperature (°C)
Signal #3,Heat Flow (mW)
Signal #4,Delta T (µV)
Signal #5,Delta Tzero (µV)
Signal #6,Tzero Temperature (°C)
Signal #7,Cell Purge (mL/min)
Signal #8,Heater Temp (°C)
Signal #9,Power Delivered (W)
Signal #10,Reference Junction Temperature (°C)
Signal #11,Flange Temperature (°C)
Signal #12,Heat Flow Phase (rad)
Signal #13,Total Heat Capacity (J/°C)
Signal #14,Heat Capacity (J/°C)
[Configuration]
Company Name,ASU
Instrument Name,DSC2A-00468
Instrument Type,DSC2500
Serial Number,DSC2A-00468
IP,192.168.1.100
Location of Instrument,MRRC
DisplayType,Unknown
Sample Interval ,0.1 s/pt
Selected Heat Flow,T4P
Exotherm Direction,Down
Cell Serial,DRC2-00792
Lid Type,Standard
Cooler,RCS 90
Leave Cooler on at End of Sequence,On
Gas 2,Nitrogen
Gas Selected,Channel 1
Flow Rate,50 mL/min
Secondary Purge,On
Licensed Heat Flow,Heat Flow T4P
Modulation Licensed,Yes
[Versions]
Common IDD Version,1
Cortex Version,VER 2.10.2.31
Driver,5.0.0.6
GDM Version,1.0.3.3
TouchscreenVersion,1.0.0.16145
FEP Version,1.2.1.21
FEP Bootloader,2.0.0.5
AutoSampler Version,2.1.1.26
Auto Sampler Bootloader,2.0.0.5
FCM Version,1.1.0.3
FCM Bootloader,2.0.0.5
[Experiment Logs]
Experiment Log Entry # 1,Data On set to 0
Experiment Log Entry # 3,Equilibrate Segment -60 (C) Started
Experiment Log Entry # 5,Air Cool is off.
Experiment Log Entry # 7,Data On set to 1
Experiment Log Entry # 9,Ramp Segment 10 C/min to 130 Started
Experiment Log Entry # 11,Data On set to 0
Experiment Log Entry # 13,Isothermal Segment 1 min started
Experiment Log Entry # 15,Data On set to 1
Experiment Log Entry # 17,Ramp Segment 10 C/min to -60 Started
Experiment Log Entry # 19,Data On set to 0
Experiment Log Entry # 21,Isothermal Segment 1 min started
Experiment Log Entry # 23,Data On set to 1
Experiment Log Entry # 25,Ramp Segment 10 C/min to 130 Started
Experiment Log Entry # 27,Data On set to 0
Experiment Log Entry # 29,Isothermal Segment 1 min started
Experiment Log Entry # 31,Data On set to 1
Experiment Log Entry # 33,Ramp Segment 10 C/min to -60 Started
Experiment Log Entry # 35,Data On set to 0
Experiment Log Entry # 37,Isothermal Segment 1 min started
Experiment Log Entry # 39,Data On set to 1
Experiment Log Entry # 41,Ramp Segment 10 C/min to 130 Started
[Method Log]
Method Log Entry # 1,Data Off
Method Log Entry # 2,Equilibrate -60 °C
Method Log Entry # 3,Data On
Method Log Entry # 4,(Ramp 489490) Ramp 10 °C/minute to 130 °C
Method Log Entry # 5,Data Off
Method Log Entry # 6,Isothermal 1 minutes
Method Log Entry # 7,Data On
Method Log Entry # 8,(Ramp 489494) Ramp 10 °C/minute to -60 °C
Method Log Entry # 9,Data Off
Method Log Entry # 10,Isothermal 1 minutes
Method Log Entry # 11,Data On
Method Log Entry # 12,(Ramp 489498) Ramp 10 °C/minute to 130 °C
Method Log Entry # 13,Data Off
Method Log Entry # 14,Isothermal 1 minutes
Method Log Entry # 15,Data On
Method Log Entry # 16,(Ramp 489502) Ramp 10 °C/minute to -60 °C
Method Log Entry # 17,Data Off
Method Log Entry # 18,Isothermal 1 minutes
Method Log Entry # 19,Data On
Method Log Entry # 20,(Ramp 489506) Ramp 10 °C/minute to 130 °C
Cell Serial,DRC2-00792
[T1 Calibration]
Slope,-0.008529666
Offset,9.636258
Initial Temperature,98.23
GUID,f8bfdadc-4977-4fdf-ba6d-0ba9134940c3
[TZero Calibration]
Date Applied,11/29/2022 4:06:13 PM
Description,From -89.059 °C to 396.009 °C at 20.000°C/min
Gas Type,Nitrogen
Pan Type,None
Source Files 1,C:\Users\yargerlab\Desktop\DSC Data\General\TZero_calibration_11_29_22_2nd(2).tri
Source Files 2,C:\Users\yargerlab\Desktop\DSC Data\General\TZero_calibration_11_29_22_2nd(3).tri
Delta T Offset,13.05235
Delta T Slope,-0.007271007
Delta T0 Offset,-13.69128
Delta T0 Slope,0.06063341
[Temperature Calibration]
Date Applied,11/29/2022 7:12:28 PM
Description,From 106.590 °C to 186.590 °C at 10.000°C/min
Gas Type,Nitrogen
Pan Type,Tzero Aluminum Hermetic
Source Files 1,C:\Users\yargerlab\Desktop\DSC Data\General\Indium(6).tri
Measured 1,157.391
Known 1,156.598
[Cell Constant Calibration]
Date Applied,11/29/2022 7:12:29 PM
Description,From 106.590 °C to 186.590 °C at 10.000°C/min
Gas Type,Nitrogen
Pan Type,Tzero Aluminum Hermetic
Source Files 1,C:\Users\yargerlab\Desktop\DSC Data\General\Indium(6).tri
T4P KCell,1.006051
Onset Slope,63.26126 mW/°C
[Direct Cp Calibration]
Date Applied,11/30/2022 11:04:51 AM
Description,From -79.983 °C to 298.409 °C at 10.000°C/min
Gas Type,Nitrogen
Pan Type,Tzero Aluminum Hermetic
Source Files 1,C:\Users\yargerlab\Desktop\DSC Data\General\Sapphire_Heat_Capacity_11_30_22.tri
[Rev Cp Calibration]
Date Applied,11/30/2022 1:58:51 PM
Description,From -79.996 °C to 292.812 °C at 3.000°C/min
Gas Type,Nitrogen
Pan Type,Tzero Aluminum Hermetic
Source Files 1,C:\Users\yargerlab\Desktop\DSC Data\General\Sapphire_MDSC_Calibration_11_30_22.tri
[step]
Ramp 10.00 °C/min to 130.00 °C
Time,Temperature,Heat Flow (Normalized)
min,°C,W/g
0.00,-59.70,-0.046
0.01,-59.71,-0.045
0.03,-59.71,-0.041
0.04,-59.72,-0.037
0.05,-59.71,-0.035
0.07,-59.70,-0.035
0.08,-59.68,-0.040
0.09,-59.66,-0.056
0.11,-59.61,-0.071
0.12,-59.56,-0.081
0.13,-59.50,-0.086
0.15,-59.43,-0.085
0.16,-59.35,-0.083
0.17,-59.26,-0.077
0.19,-59.17,-0.056
0.20,-59.07,-0.036
0.21,-58.97,-0.016
0.23,-58.86,0.003
0.24,-58.75,0.017
0.25,-58.64,0.035
0.27,-58.52,0.047
0.28,-58.41,0.063
0.29,-58.29,0.076
0.31,-58.17,0.083
0.32,-58.05,0.093
0.33,-57.93,0.102
0.35,-57.81,0.111
0.36,-57.69,0.113
0.37,-57.56,0.119
0.39,-57.44,0.126
0.40,-57.31,0.128
0.41,-57.19,0.132
0.43,-57.06,0.138
0.44,-56.94,0.139
0.45,-56.81,0.142
0.47,-56.68,0.144
0.48,-56.56,0.145
0.49,-56.43,0.147
0.51,-56.30,0.148
0.52,-56.17,0.149
0.53,-56.04,0.151
0.55,-55.92,0.152
0.56,-55.79,0.152
0.57,-55.66,0.153
0.59,-55.53,0.154
0.60,-55.40,0.154
0.61,-55.27,0.155
0.63,-55.14,0.155
0.64,-55.01,0.156
0.65,-54.88,0.156
0.67,-54.75,0.156
0.68,-54.62,0.157
0.69,-54.49,0.157
0.71,-54.36,0.157
0.72,-54.23,0.158
0.73,-54.10,0.158
0.75,-53.97,0.158
0.76,-53.84,0.159
0.77,-53.71,0.159
0.79,-53.57,0.159
0.80,-53.44,0.159
0.81,-53.31,0.160
0.83,-53.18,0.160
0.84,-53.05,0.160
0.85,-52.92,0.160
0.87,-52.79,0.160
0.88,-52.65,0.160
0.89,-52.52,0.161
0.91,-52.39,0.161
0.92,-52.26,0.161
0.93,-52.13,0.161
0.95,-52.00,0.161
0.96,-51.86,0.161
0.97,-51.73,0.161
0.99,-51.60,0.161
1.00,-51.47,0.161
1.01,-51.34,0.161
1.03,-51.20,0.162
1.04,-51.07,0.162
1.05,-50.94,0.162
1.07,-50.81,0.162
1.08,-50.68,0.162
1.09,-50.54,0.162
1.11,-50.41,0.162
1.12,-50.28,0.162
1.13,-50.15,0.161
1.15,-50.01,0.161
1.16,-49.88,0.162
1.17,-49.75,0.161
1.19,-49.62,0.161
1.20,-49.48,0.161
1.21,-49.35,0.161
1.23,-49.22,0.161
1.24,-49.09,0.161
1.25,-48.95,0.161
1.27,-48.82,0.161
1.28,-48.69,0.161
1.29,-48.56,0.161
1.31,-48.42,0.161
1.32,-48.29,0.161
1.33,-48.16,0.161
1.35,-48.02,0.161
1.36,-47.89,0.161
1.37,-47.76,0.161
1.39,-47.62,0.161
1.40,-47.49,0.161
1.41,-47.36,0.161
1.43,-47.23,0.161
1.44,-47.09,0.161
1.45,-46.96,0.160
1.47,-46.83,0.160
1.48,-46.69,0.160
1.49,-46.56,0.160
1.51,-46.43,0.160
1.52,-46.30,0.160
1.53,-46.16,0.160
1.55,-46.03,0.160
1.56,-45.90,0.160
1.57,-45.76,0.160
1.59,-45.63,0.160
1.60,-45.50,0.160
1.61,-45.36,0.160
1.63,-45.23,0.160
1.64,-45.10,0.159
1.65,-44.96,0.159
1.67,-44.83,0.159
1.68,-44.70,0.159
1.69,-44.57,0.159
1.71,-44.43,0.159
1.72,-44.30,0.159
1.73,-44.17,0.159
1.75,-44.03,0.159
1.76,-43.90,0.159
1.77,-43.77,0.159
1.79,-43.63,0.159
1.80,-43.50,0.159
1.81,-43.37,0.159
1.83,-43.23,0.159
1.84,-43.10,0.159
1.85,-42.97,0.159
1.87,-42.83,0.159
1.88,-42.70,0.159
1.89,-42.57,0.159
1.91,-42.43,0.158
1.92,-42.30,0.158
1.93,-42.17,0.158
1.95,-42.03,0.158
1.96,-41.90,0.158
1.97,-41.77,0.158
1.99,-41.63,0.158
2.00,-41.50,0.158
2.01,-41.36,0.158
2.03,-41.23,0.158
2.04,-41.10,0.158
2.05,-40.97,0.158
2.07,-40.83,0.158
2.08,-40.70,0.158
2.09,-40.56,0.157
2.11,-40.43,0.157
2.12,-40.30,0.157
2.13,-40.17,0.157
2.15,-40.03,0.157
2.16,-39.90,0.157
2.17,-39.76,0.157
2.19,-39.63,0.157
2.20,-39.50,0.157
2.21,-39.36,0.157
2.23,-39.23,0.157
2.24,-39.10,0.157
2.25,-38.96,0.157
2.27,-38.83,0.157
2.28,-38.70,0.157
2.29,-38.56,0.157
2.31,-38.43,0.156
2.32,-38.30,0.156
2.33,-38.16,0.156
2.35,-38.03,0.156
2.36,-37.89,0.156
2.37,-37.76,0.156
2.39,-37.63,0.156
2.40,-37.49,0.156
2.41,-37.36,0.156
2.43,-37.23,0.156
2.44,-37.09,0.156
2.45,-36.96,0.156
2.47,-36.83,0.156
2.48,-36.69,0.156
2.49,-36.56,0.156
2.51,-36.43,0.156
2.52,-36.29,0.156
2.53,-36.16,0.156
2.55,-36.03,0.156
2.56,-35.89,0.156
2.57,-35.76,0.156
2.59,-35.62,0.156
2.60,-35.49,0.156
2.61,-35.36,0.155
2.63,-35.23,0.155
2.64,-35.09,0.155
2.65,-34.96,0.155
2.67,-34.82,0.155
2.68,-34.69,0.155
2.69,-34.56,0.155
2.71,-34.42,0.155
2.72,-34.29,0.155
2.73,-34.16,0.155
2.75,-34.02,0.155
2.76,-33.89,0.155
2.77,-33.76,0.155
2.79,-33.62,0.155
2.80,-33.49,0.155
2.81,-33.36,0.155
2.83,-33.22,0.155
2.84,-33.09,0.155
2.85,-32.95,0.155
2.87,-32.82,0.155
2.88,-32.69,0.155
2.89,-32.55,0.155
2.91,-32.42,0.155
2.92,-32.29,0.155
2.93,-32.15,0.155
2.95,-32.02,0.155
2.96,-31.89,0.155
2.97,-31.75,0.155
2.99,-31.62,0.154
3.00,-31.49,0.154
3.01,-31.35,0.154
3.03,-31.22,0.154
3.04,-31.09,0.154
3.05,-30.95,0.154
3.07,-30.82,0.154
3.08,-30.69,0.154
3.09,-30.55,0.154
3.11,-30.42,0.154
3.12,-30.28,0.154
3.13,-30.15,0.154
3.15,-30.02,0.154
3.16,-29.89,0.154
3.17,-29.75,0.154
3.19,-29.62,0.154
3.20,-29.48,0.154
3.21,-29.35,0.154
3.23,-29.22,0.154
3.24,-29.08,0.154
3.25,-28.95,0.154
3.27,-28.81,0.154
3.28,-28.68,0.154
3.29,-28.55,0.154
3.31,-28.42,0.154
3.32,-28.28,0.154
3.33,-28.15,0.154
3.35,-28.02,0.154
3.36,-27.88,0.154
3.37,-27.75,0.154
3.39,-27.61,0.154
3.40,-27.48,0.154
3.41,-27.35,0.154
3.43,-27.21,0.154
3.44,-27.08,0.154
3.45,-26.95,0.154
3.47,-26.81,0.154
3.48,-26.68,0.153
3.49,-26.55,0.154
3.51,-26.41,0.154
3.52,-26.28,0.154
3.53,-26.15,0.153
3.55,-26.01,0.153
3.56,-25.88,0.153
3.57,-25.75,0.153
3.59,-25.61,0.153
3.60,-25.48,0.153
3.61,-25.34,0.153
3.63,-25.21,0.153
3.64,-25.08,0.153
3.65,-24.95,0.153
3.67,-24.81,0.153
3.68,-24.68,0.153
3.69,-24.54,0.153
3.71,-24.41,0.153
3.72,-24.28,0.153
3.73,-24.14,0.153
3.75,-24.01,0.153
3.76,-23.88,0.153
3.77,-23.74,0.153
3.79,-23.61,0.153
3.80,-23.47,0.153
3.81,-23.34,0.153
3.83,-23.21,0.153
3.84,-23.08,0.153
3.85,-22.94,0.153
3.87,-22.81,0.153
3.88,-22.68,0.153
3.89,-22.54,0.153
3.91,-22.41,0.153
3.92,-22.28,0.153
3.93,-22.14,0.153
3.95,-22.01,0.153
3.96,-21.87,0.153
3.97,-21.74,0.153
3.99,-21.61,0.153
4.00,-21.47,0.153
4.01,-21.34,0.153
4.03,-21.21,0.153
4.04,-21.07,0.153
4.05,-20.94,0.153
4.07,-20.81,0.153
4.08,-20.67,0.153
4.09,-20.54,0.153
4.11,-20.41,0.153
4.12,-20.27,0.153
4.13,-20.14,0.153
4.15,-20.01,0.153
4.16,-19.87,0.153
4.17,-19.74,0.153
4.19,-19.61,0.153
4.20,-19.47,0.153
4.21,-19.34,0.153
4.23,-19.20,0.153
4.24,-19.07,0.153
4.25,-18.94,0.153
4.27,-18.80,0.153
4.28,-18.67,0.153
4.29,-18.54,0.153
4.31,-18.40,0.153
4.32,-18.27,0.153
4.33,-18.14,0.153
4.35,-18.00,0.153
4.36,-17.87,0.153
4.37,-17.74,0.153
4.39,-17.60,0.153
4.40,-17.47,0.153
4.41,-17.33,0.153
4.43,-17.20,0.153
4.44,-17.07,0.153
4.45,-16.93,0.153
4.47,-16.80,0.153
4.48,-16.67,0.153
4.49,-16.53,0.153
4.51,-16.40,0.153
4.52,-16.27,0.153
4.53,-16.13,0.153
4.55,-16.00,0.153
4.56,-15.87,0.153
4.57,-15.73,0.153
4.59,-15.60,0.153
4.60,-15.47,0.153
4.61,-15.33,0.153
4.63,-15.20,0.153
4.64,-15.07,0.153
4.65,-14.93,0.153
4.67,-14.80,0.153
4.68,-14.67,0.153
4.69,-14.53,0.153
4.71,-14.40,0.153
4.72,-14.26,0.153
4.73,-14.13,0.153
4.75,-14.00,0.153
4.76,-13.86,0.153
4.77,-13.73,0.153
4.79,-13.60,0.153
4.80,-13.47,0.153
4.81,-13.33,0.153
4.83,-13.20,0.153
4.84,-13.06,0.153
4.85,-12.93,0.153
4.87,-12.80,0.153
4.88,-12.66,0.153
4.89,-12.53,0.153
4.91,-12.40,0.153
4.92,-12.26,0.153
4.93,-12.13,0.153
4.95,-11.99,0.153
4.96,-11.86,0.153
4.97,-11.73,0.153
4.99,-11.60,0.153
5.00,-11.46,0.153
5.01,-11.33,0.153
5.03,-11.20,0.153
5.04,-11.06,0.153
5.05,-10.93,0.153
5.07,-10.79,0.153
5.08,-10.66,0.153
5.09,-10.53,0.153
5.11,-10.39,0.153
5.12,-10.26,0.153
5.13,-10.13,0.153
5.15,-9.99,0.153
5.16,-9.86,0.153
5.17,-9.73,0.153
5.19,-9.59,0.153
5.20,-9.46,0.153
5.21,-9.33,0.153
5.23,-9.19,0.153
5.24,-9.06,0.153
5.25,-8.93,0.153
5.27,-8.79,0.153
5.28,-8.66,0.153
5.29,-8.53,0.153
5.31,-8.39,0.153
5.32,-8.26,0.153
5.33,-8.13,0.153
5.35,-7.99,0.153
5.36,-7.86,0.154
5.37,-7.73,0.154
5.39,-7.59,0.154
5.40,-7.46,0.154
5.41,-7.32,0.154
5.43,-7.19,0.154
5.44,-7.06,0.154
5.45,-6.92,0.154
5.47,-6.79,0.154
5.48,-6.66,0.154
5.49,-6.52,0.154
5.51,-6.39,0.154
5.52,-6.26,0.154
5.53,-6.12,0.154
5.55,-5.99,0.154
5.56,-5.85,0.154
5.57,-5.72,0.154
5.59,-5.59,0.154
5.60,-5.46,0.154
5.61,-5.32,0.154
5.63,-5.19,0.154
5.64,-5.05,0.154
5.65,-4.92,0.154
5.67,-4.79,0.154
5.68,-4.65,0.154
5.69,-4.52,0.154
5.71,-4.39,0.155
5.72,-4.25,0.155
5.73,-4.12,0.155
5.75,-3.99,0.155
5.76,-3.85,0.155
5.77,-3.72,0.155
5.79,-3.59,0.155
5.80,-3.45,0.155
5.81,-3.32,0.155
5.83,-3.18,0.155
5.84,-3.05,0.155
5.85,-2.92,0.155
5.87,-2.78,0.155
5.88,-2.65,0.155
5.89,-2.52,0.155
5.91,-2.38,0.155
5.92,-2.25,0.155
5.93,-2.12,0.155
5.95,-1.98,0.155
5.96,-1.85,0.155
5.97,-1.71,0.155
5.99,-1.58,0.155
6.00,-1.45,0.155
6.01,-1.32,0.155
6.03,-1.18,0.156
6.04,-1.05,0.156
6.05,-0.92,0.156
6.07,-0.78,0.156
6.08,-0.65,0.156
6.09,-0.51,0.156
6.11,-0.38,0.156
6.12,-0.25,0.156
6.13,-0.11,0.156
6.15,0.02,0.156
6.16,0.15,0.156
6.17,0.29,0.156
6.19,0.42,0.156
6.20,0.55,0.156
6.21,0.69,0.156
6.23,0.82,0.156
6.24,0.95,0.156
6.25,1.09,0.156
6.27,1.22,0.156
6.28,1.35,0.156
6.29,1.49,0.156
6.31,1.62,0.156
6.32,1.75,0.156
6.33,1.89,0.156
6.35,2.02,0.156
6.36,2.16,0.156
6.37,2.29,0.156
6.39,2.42,0.156
6.40,2.55,0.156
6.41,2.69,0.156
6.43,2.82,0.157
6.44,2.95,0.157
6.45,3.09,0.157
6.47,3.22,0.157
6.48,3.35,0.157
6.49,3.49,0.157
6.51,3.62,0.157
6.52,3.76,0.157
6.53,3.89,0.157
6.55,4.02,0.157
6.56,4.16,0.157
6.57,4.29,0.157
6.59,4.42,0.157
6.60,4.56,0.157
6.61,4.69,0.157
6.63,4.82,0.157
6.64,4.96,0.157
6.65,5.09,0.157
6.67,5.23,0.158
6.68,5.36,0.158
6.69,5.49,0.158
6.71,5.63,0.158
6.72,5.76,0.158
6.73,5.89,0.158
6.75,6.03,0.158
6.76,6.16,0.158
6.77,6.29,0.158
6.79,6.43,0.158
6.80,6.56,0.158
6.81,6.69,0.158
6.83,6.83,0.158
6.84,6.96,0.158
6.85,7.09,0.158
6.87,7.23,0.158
6.88,7.36,0.158
6.89,7.50,0.158
6.91,7.63,0.158
6.92,7.76,0.159
6.93,7.89,0.159
6.95,8.03,0.159
6.96,8.16,0.159
6.97,8.30,0.159
6.99,8.43,0.159
7.00,8.56,0.159
7.01,8.70,0.159
7.03,8.83,0.159
7.04,8.96,0.159
7.05,9.10,0.159
7.07,9.23,0.159
7.08,9.36,0.159
7.09,9.50,0.159
7.11,9.63,0.159
7.12,9.76,0.159
7.13,9.90,0.159
7.15,10.03,0.160
7.16,10.17,0.160
7.17,10.30,0.160
7.19,10.43,0.160
7.20,10.56,0.160
7.21,10.70,0.160
7.23,10.83,0.160
7.24,10.96,0.160
7.25,11.10,0.160
7.27,11.23,0.160
7.28,11.37,0.160
7.29,11.50,0.160
7.31,11.63,0.160
7.32,11.77,0.160
7.33,11.90,0.160
7.35,12.03,0.160
7.36,12.17,0.161
7.37,12.30,0.161
7.39,12.43,0.161
7.40,12.57,0.161
7.41,12.70,0.161
7.43,12.83,0.161
7.44,12.97,0.161
7.45,13.10,0.161
7.47,13.23,0.161
7.48,13.37,0.161
7.49,13.50,0.161
7.51,13.64,0.161
7.52,13.77,0.162
7.53,13.90,0.162
7.55,14.03,0.162
7.56,14.17,0.162
7.57,14.30,0.162
7.59,14.43,0.162
7.60,14.57,0.162
7.61,14.70,0.162
7.63,14.84,0.162
7.64,14.97,0.162
7.65,15.10,0.162
7.67,15.24,0.162
7.68,15.37,0.162
7.69,15.50,0.162
7.71,15.64,0.162
7.72,15.77,0.162
7.73,15.91,0.162
7.75,16.04,0.162
7.76,16.17,0.162
7.77,16.31,0.163
7.79,16.44,0.163
7.80,16.57,0.163
7.81,16.70,0.163
7.83,16.84,0.163
7.84,16.97,0.163
7.85,17.11,0.163
7.87,17.24,0.163
7.88,17.37,0.163
7.89,17.51,0.163
7.91,17.64,0.163
7.92,17.77,0.163
7.93,17.91,0.163
7.95,18.04,0.163
7.96,18.17,0.163
7.97,18.31,0.163
7.99,18.44,0.163
8.00,18.58,0.163
8.01,18.71,0.163
8.03,18.84,0.163
8.04,18.98,0.163
8.05,19.11,0.164
8.07,19.24,0.164
8.08,19.38,0.164
8.09,19.51,0.164
8.11,19.64,0.164
8.12,19.78,0.164
8.13,19.91,0.164
8.15,20.04,0.164
8.16,20.18,0.164
8.17,20.31,0.165
8.19,20.44,0.165
8.20,20.58,0.165
8.21,20.71,0.165
8.23,20.84,0.165
8.24,20.98,0.165
8.25,21.11,0.165
8.27,21.24,0.165
8.28,21.38,0.165
8.29,21.51,0.165
8.31,21.64,0.166
8.32,21.78,0.166
8.33,21.91,0.166
8.35,22.04,0.166
8.36,22.18,0.166
8.37,22.31,0.166
8.39,22.44,0.166
8.40,22.58,0.166
8.41,22.71,0.166
8.43,22.84,0.166
8.44,22.98,0.166
8.45,23.11,0.166
8.47,23.24,0.166
8.48,23.38,0.167
8.49,23.51,0.167
8.51,23.64,0.167
8.52,23.78,0.167
8.53,23.91,0.167
8.55,24.05,0.167
8.56,24.18,0.167
8.57,24.31,0.167
8.59,24.45,0.167
8.60,24.58,0.167
8.61,24.71,0.167
8.63,24.85,0.168
8.64,24.98,0.168
8.65,25.11,0.168
8.67,25.25,0.168
8.68,25.38,0.168
8.69,25.51,0.168
8.71,25.65,0.168
8.72,25.78,0.168
8.73,25.91,0.168
8.75,26.05,0.168
8.76,26.18,0.168
8.77,26.31,0.168
8.79,26.45,0.169
8.80,26.58,0.169
8.81,26.71,0.169
8.83,26.85,0.169
8.84,26.98,0.169
8.85,27.12,0.169
8.87,27.25,0.170
8.88,27.38,0.170
8.89,27.51,0.170
8.91,27.65,0.170
8.92,27.78,0.170
8.93,27.91,0.170
8.95,28.05,0.170
8.96,28.18,0.170
8.97,28.31,0.170
8.99,28.45,0.170
9.00,28.58,0.170
9.01,28.72,0.170
9.03,28.85,0.171
9.04,28.98,0.171
9.05,29.12,0.171
9.07,29.25,0.171
9.08,29.38,0.171
9.09,29.52,0.171
9.11,29.65,0.172
9.12,29.79,0.172
9.13,29.92,0.172
9.15,30.05,0.172
9.16,30.19,0.172
9.17,30.32,0.172
9.19,30.45,0.172
9.20,30.59,0.172
9.21,30.72,0.173
9.23,30.85,0.173
9.24,30.99,0.173
9.25,31.12,0.173
9.27,31.25,0.173
9.28,31.39,0.173
9.29,31.52,0.173
9.31,31.65,0.173
9.32,31.79,0.173
9.33,31.92,0.174
9.35,32.05,0.174
9.36,32.19,0.174
9.37,32.32,0.174
9.39,32.45,0.174
9.40,32.59,0.174
9.41,32.72,0.174
9.43,32.86,0.174
9.44,32.99,0.174
9.45,33.12,0.175
9.47,33.26,0.175
9.48,33.39,0.175
9.49,33.52,0.175
9.51,33.66,0.175
9.52,33.79,0.175
9.53,33.92,0.175
9.55,34.06,0.176
9.56,34.19,0.176
9.57,34.32,0.176
9.59,34.46,0.176
9.60,34.59,0.176
9.61,34.72,0.176
9.63,34.86,0.176
9.64,34.99,0.176
9.65,35.12,0.176
9.67,35.26,0.176
9.68,35.39,0.177
9.69,35.52,0.177
9.71,35.66,0.177
9.72,35.79,0.177
9.73,35.92,0.177
9.75,36.06,0.177
9.76,36.19,0.177
9.77,36.32,0.177
9.79,36.46,0.177
9.80,36.59,0.178
9.81,36.72,0.178
9.83,36.86,0.178
9.84,36.99,0.178
9.85,37.12,0.178
9.87,37.26,0.178
9.88,37.39,0.178
9.89,37.52,0.178
9.91,37.66,0.179
9.92,37.79,0.179
9.93,37.93,0.179
9.95,38.06,0.179
9.96,38.19,0.179
9.97,38.33,0.179
9.99,38.46,0.179
10.00,38.59,0.180
10.01,38.73,0.180
10.03,38.86,0.180
10.04,38.99,0.180
10.05,39.13,0.180
10.07,39.26,0.180
10.08,39.39,0.180
10.09,39.53,0.181
10.11,39.66,0.181
10.12,39.79,0.181
10.13,39.93,0.181
10.15,40.06,0.181
10.16,40.19,0.182
10.17,40.33,0.182
10.19,40.46,0.182
10.20,40.60,0.182
10.21,40.73,0.182
10.23,40.86,0.182
10.24,41.00,0.182
10.25,41.13,0.182
10.27,41.26,0.183
10.28,41.40,0.183
10.29,41.53,0.183
10.31,41.66,0.183
10.32,41.80,0.183
10.33,41.93,0.183
10.35,42.06,0.184
10.36,42.20,0.184
10.37,42.33,0.184
10.39,42.46,0.184
10.40,42.60,0.184
10.41,42.73,0.184
10.43,42.86,0.185
10.44,43.00,0.185
10.45,43.13,0.185
10.47,43.27,0.185
10.48,43.40,0.185
10.49,43.53,0.185
10.51,43.66,0.185
10.52,43.80,0.186
10.53,43.93,0.186
10.55,44.06,0.186
10.56,44.20,0.186
10.57,44.33,0.186
10.59,44.46,0.186
10.60,44.60,0.187
10.61,44.73,0.187
10.63,44.87,0.187
10.64,45.00,0.187
10.65,45.13,0.187
10.67,45.27,0.187
10.68,45.40,0.187
10.69,45.53,0.188
10.71,45.67,0.188
10.72,45.80,0.188
10.73,45.93,0.188
10.75,46.07,0.188
10.76,46.20,0.188
10.77,46.33,0.189
10.79,46.47,0.189
10.80,46.60,0.189
10.81,46.73,0.189
10.83,46.87,0.189
10.84,47.00,0.189
10.85,47.13,0.190
10.87,47.27,0.190
10.88,47.40,0.190
10.89,47.54,0.190
10.91,47.67,0.190
10.92,47.80,0.190
10.93,47.94,0.190
10.95,48.07,0.191
10.96,48.20,0.191
10.97,48.34,0.191
10.99,48.47,0.191
11.00,48.60,0.191
11.01,48.74,0.191
11.03,48.87,0.191
11.04,49.00,0.192
11.05,49.14,0.192
11.07,49.27,0.192
11.08,49.41,0.192
11.09,49.54,0.192
11.11,49.67,0.192
11.12,49.81,0.193
11.13,49.94,0.193
11.15,50.07,0.193
11.16,50.20,0.193
11.17,50.34,0.193
11.19,50.47,0.193
11.20,50.61,0.193
11.21,50.74,0.193
11.23,50.87,0.193
11.24,51.01,0.194
11.25,51.14,0.194
11.27,51.27,0.194
11.28,51.41,0.194
11.29,51.54,0.194
11.31,51.67,0.194
11.32,51.81,0.194
11.33,51.94,0.194
11.35,52.07,0.194
11.36,52.21,0.195
11.37,52.34,0.195
11.39,52.47,0.195
11.40,52.61,0.195
11.41,52.74,0.195
11.43,52.87,0.195
11.44,53.01,0.195
11.45,53.14,0.196
11.47,53.28,0.196
11.48,53.41,0.196
11.49,53.54,0.196
11.51,53.67,0.196
11.52,53.81,0.196
11.53,53.94,0.196
11.55,54.07,0.197
11.56,54.21,0.197
11.57,54.34,0.197
11.59,54.48,0.197
11.60,54.61,0.197
11.61,54.74,0.198
11.63,54.88,0.198
11.64,55.01,0.198
11.65,55.14,0.198
11.67,55.28,0.199
11.68,55.41,0.199
11.69,55.54,0.199
11.71,55.67,0.199
11.72,55.81,0.200
11.73,55.94,0.200
11.75,56.08,0.200
11.76,56.21,0.200
11.77,56.34,0.201
11.79,56.48,0.201
11.80,56.61,0.201
11.81,56.74,0.201
11.83,56.88,0.202
11.84,57.01,0.202
11.85,57.14,0.202
11.87,57.28,0.202
11.88,57.41,0.202
11.89,57.54,0.203
11.91,57.68,0.203
11.92,57.81,0.203
11.93,57.94,0.203
11.95,58.08,0.204
11.96,58.21,0.204
11.97,58.34,0.204
11.99,58.48,0.204
12.00,58.61,0.204
12.01,58.74,0.204
12.03,58.88,0.205
12.04,59.01,0.205
12.05,59.14,0.205
12.07,59.28,0.205
12.08,59.41,0.205
12.09,59.55,0.205
12.11,59.68,0.205
12.12,59.81,0.205
12.13,59.95,0.206
12.15,60.08,0.206
12.16,60.21,0.206
12.17,60.35,0.206
12.19,60.48,0.206
12.20,60.61,0.206
12.21,60.75,0.206
12.23,60.88,0.206
12.24,61.01,0.207
12.25,61.15,0.207
12.27,61.28,0.207
12.28,61.41,0.207
12.29,61.55,0.207
12.31,61.68,0.207
12.32,61.82,0.207
12.33,61.95,0.207
12.35,62.08,0.208
12.36,62.22,0.208
12.37,62.35,0.208
12.39,62.48,0.208
12.40,62.62,0.208
12.41,62.75,0.208
12.43,62.88,0.208
12.44,63.02,0.208
12.45,63.15,0.209
12.47,63.28,0.209
12.48,63.42,0.209
12.49,63.55,0.209
12.51,63.68,0.209
12.52,63.82,0.210
12.53,63.95,0.210
12.55,64.08,0.210
12.56,64.22,0.210
12.57,64.35,0.210
12.59,64.48,0.211
12.60,64.62,0.211
12.61,64.75,0.211
12.63,64.88,0.212
12.64,65.02,0.212
12.65,65.15,0.212
12.67,65.29,0.212
12.68,65.42,0.212
12.69,65.55,0.212
12.71,65.69,0.213
12.72,65.82,0.213
12.73,65.95,0.213
12.75,66.09,0.213
12.76,66.22,0.214
12.77,66.35,0.214
12.79,66.49,0.214
12.80,66.62,0.214
12.81,66.75,0.214
12.83,66.88,0.215
12.84,67.02,0.215
12.85,67.15,0.215
12.87,67.29,0.215
12.88,67.42,0.216
12.89,67.55,0.216
12.91,67.69,0.216
12.92,67.82,0.217
12.93,67.95,0.217
12.95,68.08,0.217
12.96,68.22,0.217
12.97,68.35,0.218
12.99,68.48,0.218
13.00,68.62,0.218
13.01,68.75,0.218
13.03,68.88,0.219
13.04,69.02,0.219
13.05,69.15,0.219
13.07,69.29,0.219
13.08,69.42,0.220
13.09,69.55,0.220
13.11,69.69,0.221
13.12,69.82,0.221
13.13,69.95,0.221
13.15,70.09,0.222
13.16,70.22,0.222
13.17,70.35,0.222
13.19,70.49,0.223
13.20,70.62,0.223
13.21,70.75,0.223
13.23,70.89,0.224
13.24,71.02,0.224
13.25,71.15,0.224
13.27,71.29,0.225
13.28,71.42,0.225
13.29,71.55,0.225
13.31,71.69,0.225
13.32,71.82,0.226
13.33,71.95,0.226
13.35,72.09,0.227
13.36,72.22,0.227
13.37,72.35,0.228
13.39,72.49,0.228
13.40,72.62,0.228
13.41,72.75,0.229
13.43,72.89,0.229
13.44,73.02,0.229
13.45,73.15,0.230
13.47,73.29,0.231
13.48,73.42,0.231
13.49,73.55,0.231
13.51,73.69,0.232
13.52,73.82,0.232
13.53,73.95,0.232
13.55,74.09,0.233
13.56,74.22,0.233
13.57,74.35,0.233
13.59,74.49,0.234
13.60,74.62,0.234
13.61,74.76,0.234
13.63,74.89,0.235
13.64,75.02,0.235
13.65,75.16,0.236
13.67,75.29,0.236
13.68,75.42,0.236
13.69,75.56,0.237
13.71,75.69,0.237
13.72,75.82,0.238
13.73,75.96,0.239
13.75,76.09,0.240
13.76,76.22,0.240
13.77,76.36,0.241
13.79,76.49,0.241
13.80,76.62,0.242
13.81,76.76,0.242
13.83,76.89,0.242
13.84,77.02,0.243
13.85,77.16,0.244
13.87,77.29,0.244
13.88,77.42,0.245
13.89,77.56,0.246
13.91,77.69,0.246
13.92,77.82,0.247
13.93,77.96,0.247
13.95,78.09,0.249
13.96,78.22,0.249
13.97,78.36,0.251
13.99,78.49,0.251
14.00,78.62,0.252
14.01,78.76,0.252
14.03,78.89,0.254
14.04,79.02,0.255
14.05,79.16,0.255
14.07,79.29,0.256
14.08,79.42,0.257
14.09,79.56,0.258
14.11,79.69,0.259
14.12,79.82,0.260
14.13,79.95,0.262
14.15,80.09,0.263
14.16,80.22,0.263
14.17,80.36,0.264
14.19,80.49,0.267
14.20,80.62,0.267
14.21,80.75,0.268
14.23,80.89,0.269
14.24,81.02,0.270
14.25,81.16,0.272
14.27,81.29,0.274
14.28,81.42,0.275
14.29,81.55,0.277
14.31,81.69,0.279
14.32,81.82,0.280
14.33,81.95,0.280
14.35,82.09,0.283
14.36,82.22,0.283
14.37,82.35,0.286
14.39,82.49,0.287
14.40,82.62,0.289
14.41,82.75,0.291
14.43,82.89,0.293
14.44,83.02,0.294
14.45,83.15,0.297
14.47,83.28,0.301
14.48,83.42,0.302
14.49,83.55,0.304
14.51,83.68,0.306
14.52,83.82,0.307
14.53,83.95,0.310
14.55,84.08,0.313
14.56,84.22,0.314
14.57,84.35,0.317
14.59,84.48,0.318
14.60,84.62,0.323
14.61,84.75,0.325
14.63,84.88,0.328
14.64,85.01,0.331
14.65,85.15,0.335
14.67,85.28,0.337
14.68,85.41,0.340
14.69,85.54,0.343
14.71,85.68,0.346
14.72,85.81,0.348
14.73,85.94,0.351
14.75,86.08,0.354
14.76,86.21,0.358
14.77,86.34,0.362
14.79,86.48,0.364
14.80,86.61,0.367
14.81,86.74,0.373
14.83,86.88,0.375
14.84,87.01,0.384
14.85,87.14,0.385
14.87,87.27,0.387
14.88,87.41,0.392
14.89,87.54,0.397
14.91,87.67,0.401
14.92,87.81,0.404
14.93,87.94,0.409
14.95,88.07,0.412
14.96,88.20,0.417
14.97,88.34,0.422
14.99,88.47,0.427
15.00,88.60,0.431
15.01,88.73,0.433
15.03,88.87,0.439
15.04,89.00,0.442
15.05,89.13,0.448
15.07,89.27,0.453
15.08,89.40,0.459
15.09,89.53,0.466
15.11,89.66,0.469
15.12,89.79,0.476
15.13,89.93,0.480
15.15,90.06,0.485
15.16,90.19,0.493
15.17,90.33,0.498
15.19,90.46,0.502
15.20,90.59,0.508
15.21,90.72,0.517
15.23,90.86,0.523
15.24,90.99,0.528
15.25,91.12,0.536
15.27,91.25,0.543
15.28,91.39,0.550
15.29,91.52,0.557
15.31,91.65,0.566
15.32,91.78,0.571
15.33,91.92,0.582
15.35,92.05,0.590
15.36,92.18,0.599
15.37,92.31,0.605
15.39,92.44,0.617
15.40,92.58,0.625
15.41,92.71,0.631
15.43,92.84,0.642
15.44,92.97,0.649
15.45,93.10,0.660
15.47,93.24,0.669
15.48,93.37,0.678
15.49,93.50,0.691
15.51,93.63,0.705
15.52,93.76,0.717
15.53,93.90,0.738
15.55,94.03,0.752
15.56,94.16,0.776
15.57,94.29,0.802
15.59,94.42,0.831
15.60,94.55,0.869
15.61,94.68,0.919
15.63,94.80,0.966
15.64,94.93,1.014
15.65,95.06,1.080
15.67,95.18,1.108
15.68,95.31,1.111
15.69,95.44,1.086
15.71,95.57,1.063
15.72,95.70,1.037
15.73,95.84,1.009
15.75,95.97,0.986
15.76,96.11,0.958
15.77,96.24,0.931
15.79,96.38,0.894
15.80,96.52,0.852
15.81,96.65,0.809
15.83,96.79,0.757
15.84,96.93,0.694
15.85,97.08,0.630
15.87,97.22,0.561
15.88,97.36,0.502
15.89,97.50,0.455
15.91,97.64,0.416
15.92,97.79,0.386
15.93,97.93,0.365
15.95,98.07,0.344
15.96,98.21,0.330
15.97,98.34,0.318
15.99,98.48,0.307
16.00,98.62,0.300
16.01,98.75,0.293
16.03,98.89,0.288
16.04,99.03,0.283
16.05,99.16,0.277
16.07,99.30,0.275
16.08,99.43,0.272
16.09,99.57,0.269
16.11,99.70,0.268
16.12,99.84,0.267
16.13,99.97,0.264
16.15,100.11,0.263
16.16,100.24,0.262
16.17,100.37,0.261
16.19,100.51,0.260
16.20,100.64,0.260
16.21,100.77,0.259
16.23,100.91,0.259
16.24,101.04,0.258
16.25,101.18,0.258
16.27,101.31,0.258
16.28,101.44,0.258
16.29,101.58,0.257
16.31,101.71,0.257
16.32,101.84,0.257
16.33,101.98,0.257
16.35,102.11,0.257
16.36,102.25,0.256
16.37,102.38,0.256
16.39,102.51,0.256
16.40,102.65,0.256
16.41,102.78,0.256
16.43,102.91,0.256
16.44,103.05,0.256
16.45,103.18,0.255
16.47,103.31,0.255
16.48,103.45,0.255
16.49,103.58,0.255
16.51,103.71,0.255
16.52,103.85,0.255
16.53,103.98,0.255
16.55,104.11,0.255
16.56,104.25,0.255
16.57,104.38,0.255
16.59,104.51,0.255
16.60,104.65,0.255
16.61,104.78,0.255
16.63,104.91,0.255
16.64,105.05,0.255
16.65,105.18,0.255
16.67,105.31,0.255
16.68,105.45,0.255
16.69,105.58,0.255
16.71,105.71,0.255
16.72,105.85,0.255
16.73,105.98,0.255
16.75,106.12,0.255
16.76,106.25,0.256
16.77,106.38,0.256
16.79,106.52,0.256
16.80,106.65,0.256
16.81,106.78,0.256
16.83,106.92,0.256
16.84,107.05,0.256
16.85,107.18,0.256
16.87,107.32,0.256
16.88,107.45,0.256
16.89,107.58,0.256
16.91,107.72,0.256
16.92,107.85,0.256
16.93,107.98,0.257
16.95,108.12,0.257
16.96,108.25,0.257
16.97,108.38,0.257
16.99,108.52,0.257
17.00,108.65,0.257
17.01,108.79,0.257
17.03,108.92,0.257
17.04,109.05,0.257
17.05,109.19,0.257
17.07,109.32,0.257
17.08,109.45,0.257
17.09,109.59,0.257
17.11,109.72,0.257
17.12,109.85,0.257
17.13,109.99,0.257
17.15,110.12,0.257
17.16,110.25,0.257
17.17,110.39,0.257
17.19,110.52,0.257
17.20,110.66,0.258
17.21,110.79,0.257
17.23,110.92,0.257
17.24,111.06,0.257
17.25,111.19,0.258
17.27,111.32,0.257
17.28,111.46,0.258
17.29,111.59,0.257
17.31,111.72,0.258
17.32,111.86,0.258
17.33,111.99,0.258
17.35,112.12,0.258
17.36,112.26,0.258
17.37,112.39,0.258
17.39,112.52,0.258
17.40,112.66,0.258
17.41,112.79,0.258
17.43,112.93,0.258
17.44,113.06,0.258
17.45,113.19,0.258
17.47,113.33,0.258
17.48,113.46,0.258
17.49,113.59,0.258
17.51,113.73,0.258
17.52,113.86,0.258
17.53,113.99,0.258
17.55,114.13,0.258
17.56,114.26,0.258
17.57,114.39,0.258
17.59,114.52,0.258
17.60,114.66,0.258
17.61,114.79,0.258
17.63,114.92,0.258
17.64,115.06,0.258
17.65,115.19,0.258
17.67,115.32,0.258
17.68,115.46,0.258
17.69,115.59,0.258
17.71,115.73,0.258
17.72,115.86,0.258
17.73,115.99,0.258
17.75,116.13,0.258
17.76,116.26,0.258
17.77,116.39,0.258
17.79,116.53,0.258
17.80,116.66,0.258
17.81,116.79,0.258
17.83,116.93,0.258
17.84,117.06,0.258
17.85,117.19,0.258
17.87,117.33,0.258
17.88,117.46,0.258
17.89,117.59,0.258
17.91,117.73,0.258
17.92,117.86,0.258
17.93,117.99,0.258
17.95,118.13,0.258
17.96,118.26,0.258
17.97,118.39,0.258
17.99,118.53,0.258
18.00,118.66,0.258
18.01,118.79,0.258
18.03,118.93,0.258
18.04,119.06,0.258
18.05,119.20,0.258
18.07,119.33,0.258
18.08,119.46,0.258
18.09,119.60,0.258
18.11,119.73,0.258
18.12,119.86,0.258
18.13,120.00,0.258
18.15,120.13,0.258
18.16,120.26,0.258
18.17,120.40,0.258
18.19,120.53,0.258
18.20,120.66,0.258
18.21,120.80,0.258
18.23,120.93,0.258
18.24,121.06,0.258
18.25,121.20,0.258
18.27,121.33,0.258
18.28,121.46,0.258
18.29,121.60,0.258
18.31,121.73,0.258
18.32,121.86,0.258
18.33,122.00,0.258
18.35,122.13,0.258
18.36,122.26,0.258
18.37,122.40,0.258
18.39,122.53,0.258
18.40,122.66,0.258
18.41,122.80,0.258
18.43,122.93,0.259
18.44,123.06,0.258
18.45,123.20,0.258
18.47,123.33,0.259
18.48,123.46,0.259
18.49,123.60,0.259
18.51,123.73,0.259
18.52,123.86,0.259
18.53,124.00,0.259
18.55,124.13,0.259
18.56,124.26,0.259
18.57,124.40,0.259
18.59,124.53,0.259
18.60,124.66,0.259
18.61,124.80,0.259
18.63,124.93,0.259
18.64,125.07,0.259
18.65,125.20,0.259
18.67,125.33,0.259
18.68,125.47,0.259
18.69,125.60,0.259
18.71,125.73,0.259
18.72,125.87,0.259
18.73,126.00,0.259
18.75,126.13,0.259
18.76,126.27,0.259
18.77,126.40,0.259
18.79,126.53,0.260
18.80,126.67,0.260
18.81,126.80,0.260
18.83,126.93,0.260
18.84,127.07,0.260
18.85,127.20,0.260
18.87,127.33,0.260
18.88,127.47,0.260
18.89,127.60,0.260
18.91,127.73,0.260
18.92,127.87,0.260
18.93,128.00,0.260
18.95,128.13,
18.96,128.27,
18.97,128.40,
18.99,,
18.99,,

[step]
Ramp 10.00 °C/min to -60.00 °C
Time,Temperature,Heat Flow (Normalized)
min,°C,W/g
19.99,130.10,-0.092
20.01,130.10,-0.092
20.02,130.10,-0.092
20.03,130.09,-0.092
20.05,130.08,-0.091
20.06,130.07,-0.076
20.07,130.04,-0.057
20.09,130.00,-0.046
20.10,129.95,-0.044
20.11,129.89,-0.050
20.13,129.82,-0.085
20.14,129.73,-0.124
20.15,129.64,-0.161
20.17,129.55,-0.200
20.18,129.45,-0.233
20.19,129.34,-0.260
20.21,129.23,-0.287
20.22,129.12,-0.306
20.23,129.01,-0.326
20.25,128.89,-0.339
20.26,128.77,-0.353
20.27,128.65,-0.362
20.29,128.53,-0.373
20.30,128.41,-0.380
20.31,128.28,-0.390
20.33,128.16,-0.398
20.34,128.03,-0.403
20.35,127.91,-0.411
20.37,127.78,-0.412
20.38,127.65,-0.417
20.39,127.52,-0.419
20.41,127.40,-0.421
20.42,127.27,-0.422
20.43,127.14,-0.424
20.45,127.01,-0.425
20.46,126.88,-0.426
20.47,126.75,-0.426
20.49,126.62,-0.427
20.50,126.49,-0.428
20.51,126.36,-0.428
20.53,126.23,-0.429
20.54,126.09,-0.430
20.55,125.96,-0.430
20.57,125.83,-0.431
20.58,125.70,-0.431
20.59,125.57,-0.431
20.61,125.44,-0.432
20.62,125.31,-0.432
20.63,125.17,-0.432
20.65,125.04,-0.432
20.66,124.91,-0.433
20.67,124.78,-0.433
20.69,124.65,-0.433
20.70,124.52,-0.433
20.71,124.38,-0.433
20.73,124.25,-0.434
20.74,124.12,-0.434
20.75,123.99,-0.434
20.77,123.86,-0.434
20.78,123.72,-0.434
20.79,123.59,-0.434
20.81,123.46,-0.434
20.82,123.33,-0.435
20.83,123.20,-0.434
20.85,123.06,-0.434
20.86,122.93,-0.434
20.87,122.80,-0.434
20.89,122.67,-0.434
20.90,122.53,-0.434
20.91,122.40,-0.434
20.93,122.27,-0.434
20.94,122.14,-0.434
20.95,122.00,-0.434
20.97,121.87,-0.434
20.98,121.74,-0.434
20.99,121.61,-0.434
21.01,121.47,-0.434
21.02,121.34,-0.434
21.03,121.21,-0.433
21.05,121.08,-0.433
21.06,120.94,-0.433
21.07,120.81,-0.433
21.09,120.68,-0.433
21.10,120.54,-0.433
21.11,120.41,-0.433
21.13,120.28,-0.432
21.14,120.15,-0.432
21.15,120.01,-0.432
21.17,119.88,-0.432
21.18,119.75,-0.432
21.19,119.62,-0.431
21.21,119.48,-0.431
21.22,119.35,-0.431
21.23,119.22,-0.431
21.25,119.08,-0.431
21.26,118.95,-0.431
21.27,118.82,-0.430
21.29,118.69,-0.430
21.30,118.55,-0.430
21.31,118.42,-0.430
21.33,118.29,-0.430
21.34,118.15,-0.429
21.35,118.02,-0.429
21.37,117.89,-0.429
21.38,117.75,-0.429
21.39,117.62,-0.428
21.41,117.49,-0.428
21.42,117.36,-0.428
21.43,117.22,-0.428
21.45,117.09,-0.428
21.46,116.96,-0.427
21.47,116.82,-0.427
21.49,116.69,-0.427
21.50,116.56,-0.427
21.51,116.42,-0.426
21.53,116.29,-0.426
21.54,116.16,-0.426
21.55,116.03,-0.426
21.57,115.89,-0.425
21.58,115.76,-0.425
21.59,115.63,-0.425
21.61,115.49,-0.425
21.62,115.36,-0.424
21.63,115.22,-0.424
21.65,115.09,-0.424
21.66,114.96,-0.424
21.67,114.83,-0.424
21.69,114.69,-0.423
21.70,114.56,-0.423
21.71,114.43,-0.423
21.73,114.29,-0.423
21.74,114.16,-0.422
21.75,114.03,-0.422
21.77,113.89,-0.422
21.78,113.76,-0.422
21.79,113.63,-0.422
21.81,113.49,-0.421
21.82,113.36,-0.421
21.83,113.23,-0.421
21.85,113.10,-0.420
21.86,112.96,-0.420
21.87,112.83,-0.420
21.89,112.70,-0.420
21.90,112.56,-0.420
21.91,112.43,-0.419
21.93,112.30,-0.419
21.94,112.16,-0.419
21.95,112.03,-0.419
21.97,111.90,-0.419
21.98,111.77,-0.418
21.99,111.63,-0.418
22.01,111.50,-0.418
22.02,111.36,-0.417
22.03,111.23,-0.417
22.05,111.10,-0.417
22.06,110.97,-0.417
22.07,110.83,-0.417
22.09,110.70,-0.416
22.10,110.57,-0.416
22.11,110.43,-0.416
22.13,110.30,-0.416
22.14,110.17,-0.415
22.15,110.03,-0.415
22.17,109.90,-0.415
22.18,109.77,-0.415
22.19,109.63,-0.415
22.21,109.50,-0.414
22.22,109.37,-0.414
22.23,109.23,-0.414
22.25,109.10,-0.414
22.26,108.97,-0.414
22.27,108.83,-0.413
22.29,108.70,-0.413
22.30,108.57,-0.413
22.31,108.44,-0.413
22.33,108.30,-0.412
22.34,108.17,-0.412
22.35,108.03,-0.412
22.37,107.90,-0.412
22.38,107.77,-0.412
22.39,107.64,-0.411
22.41,107.50,-0.411
22.42,107.37,-0.411
22.43,107.24,-0.411
22.45,107.10,-0.410
22.46,106.97,-0.410
22.47,106.84,-0.410
22.49,106.70,-0.410
22.50,106.57,-0.409
22.51,106.44,-0.409
22.53,106.30,-0.409
22.54,106.17,-0.409
22.55,106.04,-0.409
22.57,105.90,-0.408
22.58,105.77,-0.408
22.59,105.64,-0.408
22.61,105.51,-0.408
22.62,105.37,-0.407
22.63,105.24,-0.407
22.65,105.11,-0.407
22.66,104.97,-0.406
22.67,104.84,-0.406
22.69,104.71,-0.406
22.70,104.57,-0.406
22.71,104.44,-0.406
22.73,104.31,-0.406
22.74,104.17,-0.405
22.75,104.04,-0.405
22.77,103.91,-0.405
22.78,103.77,-0.405
22.79,103.64,-0.405
22.81,103.51,-0.405
22.82,103.37,-0.404
22.83,103.24,-0.404
22.85,103.11,-0.404
22.86,102.97,-0.404
22.87,102.84,-0.404
22.89,102.71,-0.403
22.90,102.57,-0.403
22.91,102.44,-0.403
22.93,102.31,-0.403
22.94,102.18,-0.403
22.95,102.04,-0.402
22.97,101.91,-0.402
22.98,101.78,-0.402
22.99,101.64,-0.402
23.01,101.51,-0.402
23.02,101.38,-0.401
23.03,101.24,-0.401
23.05,101.11,-0.401
23.06,100.97,-0.401
23.07,100.84,-0.401
23.09,100.71,-0.401
23.10,100.57,-0.401
23.11,100.44,-0.400
23.13,100.31,-0.400
23.14,100.17,-0.400
23.15,100.04,-0.400
23.17,99.91,-0.400
23.18,99.78,-0.399
23.19,99.64,-0.399
23.21,99.51,-0.399
23.22,99.38,-0.399
23.23,99.24,-0.398
23.25,99.11,-0.398
23.26,98.98,-0.398
23.27,98.84,-0.398
23.29,98.71,-0.398
23.30,98.58,-0.397
23.31,98.44,-0.397
23.33,98.31,-0.397
23.34,98.18,-0.396
23.35,98.04,-0.396
23.37,97.91,-0.396
23.38,97.78,-0.396
23.39,97.65,-0.396
23.41,97.51,-0.396
23.42,97.38,-0.396
23.43,97.25,-0.395
23.45,97.11,-0.395
23.46,96.98,-0.395
23.47,96.85,-0.395
23.49,96.71,-0.395
23.50,96.58,-0.394
23.51,96.45,-0.394
23.53,96.31,-0.394
23.54,96.18,-0.394
23.55,96.05,-0.393
23.57,95.91,-0.393
23.58,95.78,-0.393
23.59,95.65,-0.393
23.61,95.52,-0.393
23.62,95.38,-0.393
23.63,95.25,-0.392
23.65,95.12,-0.392
23.66,94.98,-0.392
23.67,94.85,-0.392
23.69,94.72,-0.392
23.70,94.58,-0.392
23.71,94.45,-0.391
23.73,94.32,-0.391
23.74,94.18,-0.391
23.75,94.05,-0.391
23.77,93.92,-0.391
23.78,93.78,-0.391
23.79,93.65,-0.390
23.81,93.52,-0.390
23.82,93.38,-0.390
23.83,93.25,-0.390
23.85,93.12,-0.390
23.86,92.98,-0.390
23.87,92.85,-0.389
23.89,92.72,-0.389
23.90,92.58,-0.389
23.91,92.45,-0.389
23.93,92.32,-0.389
23.94,92.18,-0.388
23.95,92.05,-0.388
23.97,91.92,-0.388
23.98,91.79,-0.388
23.99,91.65,-0.388
24.01,91.52,-0.388
24.02,91.39,-0.387
24.03,91.25,-0.387
24.05,91.12,-0.387
24.06,90.99,-0.387
24.07,90.85,-0.386
24.09,90.72,-0.386
24.10,90.59,-0.386
24.11,90.45,-0.386
24.13,90.32,-0.385
24.14,90.19,-0.385
24.15,90.05,-0.385
24.17,89.92,-0.385
24.18,89.79,-0.385
24.19,89.66,-0.385
24.21,89.52,-0.384
24.22,89.39,-0.384
24.23,89.26,-0.384
24.25,89.12,-0.384
24.26,88.99,-0.384
24.27,88.86,-0.383
24.29,88.72,-0.383
24.30,88.59,-0.383
24.31,88.46,-0.383
24.33,88.32,-0.383
24.34,88.19,-0.382
24.35,88.06,-0.382
24.37,87.92,-0.382
24.38,87.79,-0.382
24.39,87.66,-0.382
24.41,87.52,-0.382
24.42,87.39,-0.381
24.43,87.26,-0.381
24.45,87.12,-0.381
24.46,86.99,-0.381
24.47,86.86,-0.381
24.49,86.72,-0.381
24.50,86.59,-0.380
24.51,86.46,-0.380
24.53,86.32,-0.380
24.54,86.19,-0.380
24.55,86.06,-0.380
24.57,85.93,-0.379
24.58,85.79,-0.379
24.59,85.66,-0.379
24.61,85.53,-0.379
24.62,85.39,-0.379
24.63,85.26,-0.379
24.65,85.13,-0.379
24.66,84.99,-0.378
24.67,84.86,-0.378
24.69,84.73,-0.378
24.70,84.59,-0.378
24.71,84.46,-0.378
24.73,84.33,-0.378
24.74,84.19,-0.378
24.75,84.06,-0.378
24.77,83.93,-0.378
24.78,83.79,-0.377
24.79,83.66,-0.377
24.81,83.53,-0.377
24.82,83.39,-0.377
24.83,83.26,-0.377
24.85,83.13,-0.377
24.86,82.99,-0.377
24.87,82.86,-0.377
24.89,82.73,-0.377
24.90,82.60,-0.376
24.91,82.46,-0.376
24.93,82.33,-0.376
24.94,82.20,-0.376
24.95,82.06,-0.376
24.97,81.93,-0.376
24.98,81.80,-0.376
24.99,81.66,-0.376
25.01,81.53,-0.376
25.02,81.40,-0.375
25.03,81.26,-0.375
25.05,81.13,-0.375
25.06,81.00,-0.375
25.07,80.86,-0.375
25.09,80.73,-0.375
25.10,80.60,-0.375
25.11,80.46,-0.375
25.13,80.33,-0.375
25.14,80.20,-0.375
25.15,80.06,-0.375
25.17,79.93,-0.375
25.18,79.80,-0.374
25.19,79.67,-0.374
25.21,79.53,-0.374
25.22,79.40,-0.374
25.23,79.27,-0.374
25.25,79.13,-0.374
25.26,79.00,-0.374
25.27,78.87,-0.374
25.29,78.73,-0.373
25.30,78.60,-0.373
25.31,78.47,-0.373
25.33,78.33,-0.373
25.34,78.20,-0.373
25.35,78.07,-0.373
25.37,77.93,-0.373
25.38,77.80,-0.373
25.39,77.67,-0.373
25.41,77.53,-0.372
25.42,77.40,-0.372
25.43,77.27,-0.372
25.45,77.13,-0.372
25.46,77.00,-0.372
25.47,76.87,-0.372
25.49,76.73,-0.372
25.50,76.60,-0.372
25.51,76.47,-0.372
25.53,76.34,-0.371
25.54,76.20,-0.371
25.55,76.07,-0.371
25.57,75.93,-0.371
25.58,75.80,-0.371
25.59,75.67,-0.371
25.61,75.54,-0.370
25.62,75.40,-0.370
25.63,75.27,-0.370
[...]
84.33,-18.25,0.160
84.34,-18.12,0.160
84.35,-17.98,0.160
84.37,-17.85,0.160
84.38,-17.72,0.160
84.39,-17.58,0.160
84.41,-17.45,0.160
84.42,-17.32,0.160
84.43,-17.18,0.160
84.45,-17.05,0.160
84.46,-16.91,0.160
84.47,-16.78,0.160
84.49,-16.65,0.160
84.50,-16.52,0.160
84.51,-16.38,0.160
84.53,-16.25,0.160
84.54,-16.11,0.160
84.55,-15.98,0.160
84.57,-15.85,0.160
84.58,-15.71,0.160
84.59,-15.58,0.160
84.61,-15.45,0.160
84.62,-15.31,0.160
84.63,-15.18,0.160
84.65,-15.05,0.160
84.66,-14.91,0.160
84.67,-14.78,0.160
84.69,-14.64,0.160
84.70,-14.51,0.160
84.71,-14.38,0.160
84.73,-14.24,0.160
84.74,-14.11,0.160
84.75,-13.98,0.160
84.77,-13.85,0.160
84.78,-13.71,0.160
84.79,-13.58,0.160
84.81,-13.45,0.160
84.82,-13.31,0.160
84.83,-13.18,0.160
84.85,-13.05,0.160
84.86,-12.91,0.160
84.87,-12.78,0.160
84.89,-12.65,0.160
84.90,-12.51,0.160
84.91,-12.38,0.160
84.93,-12.24,0.160
84.94,-12.11,0.160
84.95,-11.98,0.160
84.97,-11.84,0.160
84.98,-11.71,0.160
84.99,-11.58,0.160
85.01,-11.44,0.160
85.02,-11.31,0.160
85.03,-11.18,0.160
85.05,-11.04,0.160
85.06,-10.91,0.161
85.07,-10.77,0.160
85.09,-10.64,0.161
85.10,-10.51,0.161
85.11,-10.37,0.161
85.13,-10.24,0.161
85.14,-10.11,0.161
85.15,-9.97,0.161
85.17,-9.84,0.161
85.18,-9.71,0.161
85.19,-9.57,0.161
85.21,-9.44,0.161
85.22,-9.31,0.161
85.23,-9.17,0.161
85.25,-9.04,0.161
85.26,-8.91,0.161
85.27,-8.77,0.161
85.29,-8.64,0.161
85.30,-8.51,0.161
85.31,-8.37,0.161
85.33,-8.24,0.161
85.34,-8.11,0.161
85.35,-7.97,0.161
85.37,-7.84,0.161
85.38,-7.71,0.162
85.39,-7.57,0.162
85.41,-7.44,0.162
85.42,-7.31,0.162
85.43,-7.17,0.162
85.45,-7.04,0.162
85.46,-6.91,0.162
85.47,-6.77,0.162
85.49,-6.64,0.162
85.50,-6.50,0.162
85.51,-6.37,0.162
85.53,-6.24,0.162
85.54,-6.11,0.162
85.55,-5.97,0.162
85.57,-5.84,0.162
85.58,-5.70,0.162
85.59,-5.57,0.162
85.61,-5.44,0.162
85.62,-5.30,0.163
85.63,-5.17,0.163
85.65,-5.04,0.163
85.66,-4.90,0.163
85.67,-4.77,0.163
85.69,-4.64,0.163
85.70,-4.50,0.163
85.71,-4.37,0.163
85.73,-4.24,0.163
85.74,-4.10,0.163
85.75,-3.97,0.163
85.77,-3.83,0.163
85.78,-3.70,0.163
85.79,-3.57,0.163
85.81,-3.43,0.163
85.82,-3.30,0.163
85.83,-3.17,0.164
85.85,-3.03,0.163
85.86,-2.90,0.164
85.87,-2.77,0.164
85.89,-2.63,0.164
85.90,-2.50,0.164
85.91,-2.37,0.164
85.93,-2.23,0.164
85.94,-2.10,0.164
85.95,-1.97,0.164
85.97,-1.83,0.164
85.98,-1.70,0.164
85.99,-1.56,0.164
86.01,-1.43,0.164
86.02,-1.30,0.164
86.03,-1.16,0.164
86.05,-1.03,0.165
86.06,-0.90,0.165
86.07,-0.76,0.165
86.09,-0.63,0.165
86.10,-0.50,0.165
86.11,-0.36,0.165
86.13,-0.23,0.165
86.14,-0.10,0.165
86.15,0.04,0.165
86.17,0.17,0.165
86.18,0.30,0.165
86.19,0.44,0.165
86.21,0.57,0.165
86.22,0.71,0.165
86.23,0.84,0.166
86.25,0.97,0.166
86.26,1.10,0.166
86.27,1.24,0.166
86.29,1.37,0.166
86.30,1.51,0.166
86.31,1.64,0.166
86.33,1.77,0.166
86.34,1.91,0.166
86.35,2.04,0.166
86.37,2.17,0.166
86.38,2.31,0.167
86.39,2.44,0.167
86.41,2.57,0.167
86.42,2.71,0.167
86.43,2.84,0.167
86.45,2.98,0.167
86.46,3.11,0.167
86.47,3.24,0.167
86.49,3.38,0.167
86.50,3.51,0.168
86.51,3.64,0.168
86.53,3.78,0.168
86.54,3.91,0.168
86.55,4.04,0.168
86.57,4.18,0.168
86.58,4.31,0.168
86.59,4.44,0.168
86.61,4.58,0.168
86.62,4.71,0.169
86.63,4.84,0.169
86.65,4.98,0.169
86.66,5.11,0.169
86.67,5.24,0.169
86.69,5.38,0.169
86.70,5.51,0.170
86.71,5.64,0.170
86.73,5.78,0.170
86.74,5.91,0.170
86.75,6.04,0.170
86.77,6.18,0.170
86.78,6.31,0.171
86.79,6.44,0.171
86.81,6.58,0.171
86.82,6.71,0.171
86.83,6.84,0.171
86.85,6.98,0.172
86.86,7.11,0.172
86.87,7.25,0.172
86.89,7.38,0.172
86.90,7.51,0.172
86.91,7.65,0.173
86.93,7.78,0.173
86.94,7.91,0.173
86.95,8.04,0.173
86.97,8.18,0.174
86.98,8.31,0.174
86.99,8.45,0.174
87.01,8.58,0.175
87.02,8.71,0.175
87.03,8.84,0.175
87.05,8.98,0.175
87.06,9.11,0.175
87.07,9.25,0.176
87.09,9.38,0.176
87.10,9.51,0.176
87.11,9.65,0.177
87.13,9.78,0.177
87.14,9.91,0.177
87.15,10.05,0.178
87.17,10.18,0.178
87.18,10.31,0.178
87.19,10.45,0.179
87.21,10.58,0.179
87.22,10.71,0.180
87.23,10.85,0.180
87.25,10.98,0.180
87.26,11.11,0.181
87.27,11.25,0.181
87.29,11.38,0.182
87.30,11.51,0.182
87.31,11.65,0.182
87.33,11.78,0.183
87.34,11.91,0.183
87.35,12.05,0.184
87.37,12.18,0.185
87.38,12.31,0.185
87.39,12.45,0.186
87.41,12.58,0.186
87.42,12.71,0.187
87.43,12.85,0.187
87.45,12.98,0.188
87.46,13.12,0.188
87.47,13.25,0.189
87.49,13.38,0.190
87.50,13.52,0.190
87.51,13.65,0.191
87.53,13.78,0.192
87.54,13.92,0.193
87.55,14.05,0.194
87.57,14.18,0.194
87.58,14.31,0.195
87.59,14.45,0.196
87.61,14.58,0.197
87.62,14.71,0.198
87.63,14.85,0.199
87.65,14.98,0.200
87.66,15.11,0.201
87.67,15.25,0.202
87.69,15.38,0.203
87.70,15.51,0.204
87.71,15.65,0.205
87.73,15.78,0.205
87.74,15.91,0.207
87.75,16.05,0.208
87.77,16.18,0.209
87.78,16.31,0.209
87.79,16.45,0.210
87.81,16.58,0.211
87.82,16.71,0.212
87.83,16.85,0.213
87.85,16.98,0.215
87.86,17.11,0.215
87.87,17.25,0.217
87.89,17.38,0.218
87.90,17.51,0.218
87.91,17.65,0.219
87.93,17.78,0.220
87.94,17.91,0.220
87.95,18.05,0.221
87.97,18.18,0.221
87.98,18.31,0.222
87.99,18.45,0.223
88.01,18.58,0.224
88.02,18.71,0.224
88.03,18.85,0.225
88.05,18.98,0.226
88.06,19.11,0.227
88.07,19.25,0.227
88.09,19.38,0.228
88.10,19.51,0.228
88.11,19.65,0.228
88.13,19.78,0.229
88.14,19.91,0.229
88.15,20.05,0.230
88.17,20.18,0.230
88.18,20.31,0.230
88.19,20.45,0.231
88.21,20.58,0.231
88.22,20.72,0.231
88.23,20.85,0.232
88.25,20.98,0.232
88.26,21.12,0.232
88.27,21.25,0.232
88.29,21.38,0.233
88.30,21.52,0.233
88.31,21.65,0.233
88.33,21.78,0.233
88.34,21.92,0.233
88.35,22.05,0.233
88.37,22.18,0.233
88.38,22.32,0.233
88.39,22.45,0.233
88.41,22.58,0.233
88.42,22.72,0.233
88.43,22.85,0.233
88.45,22.99,0.233
88.46,23.12,0.233
88.47,23.25,0.232
88.49,23.39,0.232
88.50,23.52,0.232
88.51,23.65,0.232
88.53,23.78,0.232
88.54,23.92,0.232
88.55,24.05,0.232
88.57,24.19,0.232
88.58,24.32,0.231
88.59,24.45,0.231
88.61,24.59,0.231
88.62,24.72,0.231
88.63,24.85,0.231
88.65,24.99,0.231
88.66,25.12,0.231
88.67,25.25,0.231
88.69,25.39,0.231
88.70,25.52,0.230
88.71,25.65,0.230
88.73,25.79,0.230
88.74,25.92,0.230
88.75,26.05,0.230
88.77,26.19,0.230
88.78,26.32,0.230
88.79,26.46,0.230
88.81,26.59,0.230
88.82,26.72,0.230
88.83,26.86,0.230
88.85,26.99,0.230
88.86,27.12,0.230
88.87,27.26,0.230
88.89,27.39,0.230
88.90,27.52,0.230
88.91,27.66,0.230
88.93,27.79,0.230
88.94,27.92,0.230
88.95,28.06,0.230
88.97,28.19,0.230
88.98,28.32,0.230
88.99,28.46,0.230
89.01,28.59,0.230
89.02,28.73,0.230
89.03,28.86,0.230
89.05,28.99,0.230
89.06,29.12,0.230
89.07,29.26,0.230
89.09,29.39,0.230
89.10,29.52,0.230
89.11,29.66,0.230
89.13,29.79,0.230
89.14,29.93,0.230
89.15,30.06,0.230
89.17,30.19,0.230
89.18,30.33,0.230
89.19,30.46,0.231
89.21,30.60,0.230
89.22,30.73,0.231
89.23,30.86,0.231
89.25,31.00,0.231
89.26,31.13,0.231
89.27,31.26,0.231
89.29,31.40,0.231
89.30,31.53,0.231
89.31,31.66,0.231
89.33,31.80,0.231
89.34,31.93,0.231
89.35,32.06,0.231
89.37,32.20,0.231
89.38,32.33,0.231
89.39,32.46,0.231
89.41,32.60,0.231
89.42,32.73,0.231
89.43,32.86,0.231
89.45,33.00,0.231
89.46,33.13,0.232
89.47,33.26,0.232
89.49,33.40,0.232
89.50,33.53,0.232
89.51,33.66,0.232
89.53,33.80,0.232
89.54,33.93,0.232
89.55,34.06,0.232
89.57,34.20,0.232
89.58,34.33,0.232
89.59,34.46,0.232
89.61,34.60,0.232
89.62,34.73,0.232
89.63,34.87,0.232
89.65,35.00,0.232
89.66,35.13,0.232
89.67,35.27,0.232
89.69,35.40,0.232
89.70,35.53,0.232
89.71,35.67,0.232
89.73,35.80,0.232
89.74,35.93,0.232
89.75,36.07,0.232
89.77,36.20,0.232
89.78,36.33,0.232
89.79,36.47,0.232
89.81,36.60,0.233
89.82,36.73,0.233
89.83,36.87,0.233
89.85,37.00,0.233
89.86,37.13,0.233
89.87,37.27,0.233
89.89,37.40,0.233
89.90,37.53,0.233
89.91,37.67,0.233
89.93,37.80,0.233
89.94,37.94,0.233
89.95,38.07,0.233
89.97,38.20,0.233
89.98,38.34,0.233
89.99,38.47,0.233
90.01,38.60,0.233
90.02,38.74,0.233
90.03,38.87,0.233
90.05,39.00,0.233
90.06,39.14,0.233
90.07,39.27,0.234
90.09,39.40,0.234
90.10,39.54,0.234
90.11,39.67,0.234
90.13,39.81,0.234
90.14,39.94,0.234
90.15,40.07,0.234
90.17,40.21,0.234
90.18,40.34,0.234
90.19,40.47,0.234
90.21,40.61,0.234
90.22,40.74,0.234
90.23,40.87,0.234
90.25,41.01,0.234
90.26,41.14,0.234
90.27,41.27,0.235
90.29,41.41,0.235
90.30,41.54,0.235
90.31,41.67,0.235
90.33,41.81,0.235
90.34,41.94,0.235
90.35,42.07,0.235
90.37,42.21,0.235
90.38,42.34,0.235
90.39,42.47,0.235
90.41,42.61,0.235
90.42,42.74,0.235
90.43,42.87,0.235
90.45,43.01,0.235
90.46,43.14,0.235
90.47,43.28,0.235
90.49,43.41,0.235
90.50,43.54,0.235
90.51,43.68,0.235
90.53,43.81,0.236
90.54,43.94,0.236
90.55,44.08,0.236
90.57,44.21,0.236
90.58,44.34,0.236
90.59,44.48,0.236
90.61,44.61,0.236
90.62,44.74,0.236
90.63,44.88,0.236
90.65,45.01,0.236
90.66,45.14,0.236
90.67,45.28,0.236
90.69,45.41,0.236
90.70,45.54,0.237
90.71,45.68,0.237
90.73,45.81,0.237
90.74,45.95,0.237
90.75,46.08,0.237
90.77,46.21,0.237
90.78,46.34,0.237
90.79,46.48,0.237
90.81,46.61,0.237
90.82,46.74,0.237
90.83,46.88,0.237
90.85,47.01,0.237
90.86,47.15,0.237
90.87,47.28,0.237
90.89,47.41,0.237
90.90,47.55,0.237
90.91,47.68,0.237
90.93,47.81,0.237
90.94,47.95,0.237
90.95,48.08,0.237
90.97,48.21,0.237
90.98,48.35,0.237
90.99,48.48,0.237
91.01,48.61,0.237
91.02,48.75,0.237
91.03,48.88,0.237
91.05,49.01,0.237
91.06,49.15,0.237
91.07,49.28,0.237
91.09,49.41,0.237
91.10,49.55,0.237
91.11,49.68,0.237
91.13,49.82,0.237
91.14,49.95,0.238
91.15,50.08,0.237
91.17,50.22,0.237
91.18,50.35,0.237
91.19,50.48,0.237
91.21,50.62,0.237
91.22,50.75,0.237
91.23,50.88,0.237
91.25,51.02,0.237
91.26,51.15,0.237
91.27,51.29,0.237
91.29,51.42,0.237
91.30,51.55,0.237
91.31,51.69,0.237
91.33,51.82,0.236
91.34,51.95,0.236
91.35,52.09,0.236
91.37,52.22,0.236
91.38,52.35,0.236
91.39,52.49,0.236
91.41,52.62,0.236
91.42,52.75,0.235
91.43,52.89,0.235
91.45,53.02,0.235
91.46,53.15,0.235
91.47,53.29,0.234
91.49,53.42,0.234
91.50,53.55,0.233
91.51,53.69,0.233
91.53,53.82,0.233
91.54,53.95,0.233
91.55,54.09,0.232
91.57,54.22,0.232
91.58,54.36,0.232
91.59,54.49,0.231
91.61,54.62,0.231
91.62,54.76,0.230
91.63,54.89,0.230
91.65,55.02,0.229
91.66,55.16,0.229
91.67,55.29,0.229
91.69,55.43,0.228
91.70,55.56,0.227
91.71,55.69,0.227
91.73,55.83,0.226
91.74,55.96,0.226
91.75,56.09,0.225
91.77,56.23,0.225
91.78,56.36,0.224
91.79,56.49,0.224
91.81,56.63,0.223
91.82,56.76,0.223
91.83,56.90,0.222
91.85,57.03,0.221
91.86,57.16,0.221
91.87,57.30,0.220
91.89,57.43,0.219
91.90,57.56,0.218
91.91,57.70,0.218
91.93,57.83,0.217
91.94,57.96,0.217
91.95,58.10,0.216
91.97,58.23,0.216
91.98,58.36,0.215
91.99,58.50,0.214
92.01,58.63,0.213
92.02,58.76,0.213
92.03,58.90,0.212
92.05,59.03,0.212
92.06,59.17,0.211
92.07,59.30,0.210
92.09,59.43,0.209
92.10,59.57,0.209
92.11,59.70,0.208
92.13,59.84,0.208
92.14,59.97,0.207
92.15,60.10,0.206
92.17,60.24,0.206
92.18,60.37,0.205
92.19,60.50,0.205
92.21,60.64,0.205
92.22,60.77,0.204
92.23,60.90,0.204
92.25,61.04,0.203
92.26,61.17,0.203
92.27,61.30,0.203
92.29,61.44,0.202
92.30,61.57,0.202
92.31,61.71,0.202
92.33,61.84,0.202
92.34,61.97,0.201
92.35,62.11,0.201
92.37,62.24,0.201
92.38,62.37,0.201
92.39,62.51,0.201
92.41,62.64,0.201
92.42,62.77,0.201
92.43,62.91,0.201
92.45,63.04,0.201
92.46,63.17,0.201
92.47,63.31,0.201
92.49,63.44,0.201
92.50,63.57,0.201
92.51,63.71,0.201
92.53,63.84,0.201
92.54,63.97,0.202
92.55,64.11,0.202
92.57,64.24,0.202
92.58,64.37,0.202
92.59,64.51,0.203
92.61,64.64,0.203
92.62,64.77,0.203
92.63,64.91,0.204
92.65,65.04,0.204
92.66,65.17,0.204
92.67,65.31,0.205
92.69,65.44,0.205
92.70,65.57,0.206
92.71,65.71,0.206
92.73,65.84,0.207
92.74,65.97,0.208
92.75,66.11,0.209
92.77,66.24,0.209
92.78,66.37,0.210
92.79,66.50,0.211
92.81,66.64,0.211
92.82,66.77,0.212
92.83,66.91,0.213
92.85,67.04,0.213
92.86,67.17,0.214
92.87,67.31,0.214
92.89,67.44,0.215
92.90,67.57,0.216
92.91,67.71,0.216
92.93,67.84,0.217
92.94,67.97,0.218
92.95,68.11,0.218
92.97,68.24,0.219
92.98,68.37,0.219
92.99,68.50,0.220
93.01,68.64,0.220
93.02,68.77,0.222
93.03,68.90,0.222
93.05,69.04,0.223
93.06,69.17,0.224
93.07,69.30,0.224
93.09,69.44,0.225
93.10,69.57,0.225
93.11,69.70,0.226
93.13,69.84,0.227
93.14,69.97,0.227
93.15,70.10,0.228
93.17,70.24,0.229
93.18,70.37,0.229
93.19,70.51,0.230
93.21,70.64,0.231
93.22,70.77,0.231
93.23,70.90,0.232
93.25,71.04,0.232
93.26,71.17,0.233
93.27,71.30,0.233
93.29,71.44,0.234
93.30,71.57,0.234
93.31,71.71,0.235
93.33,71.84,0.236
93.34,71.97,0.236
93.35,72.11,0.237
93.37,72.24,0.237
93.38,72.37,0.238
93.39,72.51,0.239
93.41,72.64,0.239
93.42,72.77,0.240
93.43,72.91,0.240
93.45,73.04,0.241
93.46,73.17,0.241
93.47,73.31,0.242
93.49,73.44,0.242
93.50,73.57,0.243
93.51,73.71,0.243
93.53,73.84,0.244
93.54,73.97,0.244
93.55,74.11,0.245
93.57,74.24,0.246
93.58,74.37,0.246
93.59,74.51,0.247
93.61,74.64,0.247
93.62,74.77,0.248
93.63,74.91,0.249
93.65,75.04,0.249
93.66,75.17,0.250
93.67,75.31,0.250
93.69,75.44,0.251
93.70,75.57,0.251
93.71,75.71,0.252
93.73,75.84,0.252
93.74,75.97,0.253
93.75,76.11,0.253
93.77,76.24,0.254
93.78,76.37,0.254
93.79,76.51,0.255
93.81,76.64,0.256
93.82,76.77,0.256
93.83,76.91,0.257
93.85,77.04,0.257
93.86,77.17,0.258
93.87,77.31,0.259
93.89,77.44,0.260
93.90,77.57,0.260
93.91,77.71,0.261
93.93,77.84,0.262
93.94,77.97,0.263
93.95,78.11,0.263
93.97,78.24,0.264
93.98,78.37,0.266
93.99,78.51,0.267
94.01,78.64,0.268
94.02,78.77,0.268
94.03,78.91,0.269
94.05,79.04,0.270
94.06,79.17,0.272
94.07,79.31,0.273
94.09,79.44,0.276
94.10,79.57,0.278
94.11,79.70,0.279
94.13,79.84,0.281
94.14,79.97,0.282
94.15,80.10,0.284
94.17,80.24,0.285
94.18,80.37,0.287
94.19,80.50,0.288
94.21,80.64,0.290
94.22,80.77,0.290
94.23,80.90,0.291
94.25,81.04,0.293
94.26,81.17,0.294
94.27,81.30,0.295
94.29,81.44,0.296
94.30,81.57,0.298
94.31,81.70,0.299
94.33,81.84,0.300
94.34,81.97,0.302
94.35,82.10,0.303
94.37,82.24,0.303
94.38,82.37,0.304
94.39,82.50,0.305
94.41,82.64,0.305
94.42,82.77,0.306
94.43,82.90,0.307
94.45,83.04,0.308
94.46,83.17,0.309
94.47,83.30,0.310
94.49,83.44,0.311
94.50,83.57,0.312
94.51,83.70,0.312
94.53,83.84,0.313
94.54,83.97,0.314
94.55,84.10,0.315
94.57,84.24,0.316
94.58,84.37,0.317
94.59,84.50,0.317
94.61,84.64,0.319
94.62,84.77,0.320
94.63,84.90,0.321
94.65,85.04,0.323
94.66,85.17,0.324
94.67,85.30,0.326
94.69,85.44,0.328
94.70,85.57,0.329
94.71,85.70,0.330
94.73,85.83,0.331
94.74,85.97,0.332
94.75,86.10,0.333
94.77,86.23,0.333
94.78,86.37,0.334
94.79,86.50,0.334
94.81,86.64,0.335
94.82,86.77,0.335
94.83,86.90,0.336
94.85,87.04,0.335
94.86,87.17,0.335
94.87,87.30,0.332
94.89,87.44,0.328
94.90,87.57,0.320
94.91,87.71,0.311
94.93,87.84,0.307
94.94,87.98,0.301
94.95,88.11,0.295
94.97,88.24,0.287
94.98,88.38,0.284
94.99,88.51,0.279
95.01,88.65,0.277
95.02,88.78,0.276
95.03,88.91,0.274
95.05,89.05,0.273
95.06,89.18,0.272
95.07,89.32,0.270
95.09,89.45,0.270
95.10,89.58,0.269
95.11,89.72,0.268
95.13,89.85,0.268
95.14,89.99,0.268
95.15,90.12,0.268
95.17,90.25,0.267
95.18,90.39,0.267
95.19,90.52,0.267
95.21,90.65,0.267
95.22,90.79,0.267
95.23,90.92,0.266
95.25,91.05,0.266
95.26,91.19,0.266
95.27,91.32,0.266
95.29,91.45,0.266
95.30,91.59,0.265
95.31,91.72,0.265
95.33,91.85,0.265
95.34,91.99,0.265
95.35,92.12,0.265
95.37,92.26,0.265
95.38,92.39,0.265
95.39,92.52,0.265
95.41,92.66,0.265
95.42,92.79,0.265
95.43,92.92,0.265
95.45,93.06,0.265
95.46,93.19,0.265
95.47,93.32,0.265
95.49,93.46,0.265
95.50,93.59,0.265
95.51,93.72,0.265
95.53,93.86,0.265
95.54,93.99,0.265
95.55,94.12,0.265
95.57,94.26,0.265
95.58,94.39,0.264
95.59,94.52,0.265
95.61,94.66,0.265
95.62,94.79,0.265
95.63,94.93,0.265
95.65,95.06,0.265
95.66,95.19,0.265
95.67,95.32,0.265
95.69,95.46,0.265
95.70,95.59,0.265
95.71,95.72,0.265
95.73,95.86,0.265
95.74,95.99,0.265
95.75,96.13,0.265
95.77,96.26,0.265
95.78,96.39,0.265
95.79,96.53,0.265
95.81,96.66,0.265
95.82,96.79,0.266
95.83,96.93,0.266
95.85,97.06,0.266
95.86,97.19,0.266
95.87,97.33,0.266
95.89,97.46,0.266
95.90,97.59,0.266
95.91,97.73,0.266
95.93,97.86,0.266
95.94,97.99,0.266
95.95,98.13,0.266
95.97,98.26,0.266
95.98,98.39,0.266
95.99,98.53,0.266
96.01,98.66,0.266
96.02,98.79,0.266
96.03,98.93,0.266
96.05,99.06,0.266
96.06,99.19,0.267
96.07,99.33,0.267
96.09,99.46,0.267
96.10,99.59,0.267
96.11,99.73,0.267
96.13,99.86,0.267
96.14,99.99,0.267
96.15,100.13,0.267
96.17,100.26,0.267
96.18,100.40,0.267
96.19,100.53,0.267
96.21,100.66,0.267
96.22,100.80,0.267
96.23,100.93,0.267
96.25,101.06,0.267
96.26,101.20,0.267
96.27,101.33,0.267
96.29,101.47,0.268
96.30,101.60,0.268
96.31,101.73,0.268
96.33,101.87,0.268
96.34,102.00,0.268
96.35,102.13,0.268
96.37,102.27,0.268
96.38,102.40,0.268
96.39,102.53,0.269
96.41,102.67,0.269
96.42,102.80,0.269
96.43,102.93,0.269
96.45,103.07,0.269
96.46,103.20,0.269
96.47,103.33,0.269
96.49,103.47,0.269
96.50,103.60,0.269
96.51,103.73,0.269
96.53,103.87,0.269
96.54,104.00,0.269
96.55,104.13,0.269
96.57,104.27,0.269
96.58,104.40,0.269
96.59,104.53,0.269
96.61,104.67,0.269
96.62,104.80,0.269
96.63,104.93,0.270
96.65,105.07,0.269
96.66,105.20,0.270
96.67,105.33,0.270
96.69,105.47,0.270
96.70,105.60,0.270
96.71,105.73,0.270
96.73,105.87,0.270
96.74,106.00,0.270
96.75,106.13,0.270
96.77,106.27,0.270
96.78,106.40,0.270
96.79,106.53,0.270
96.81,106.67,0.270
96.82,106.80,0.270
96.83,106.93,0.270
96.85,107.07,0.270
96.86,107.20,0.270
96.87,107.34,0.270
96.89,107.47,0.271
96.90,107.60,0.271
96.91,107.73,0.271
96.93,107.87,0.271
96.94,108.00,0.271
96.95,108.13,0.271
96.97,108.27,0.271
96.98,108.40,0.271
96.99,108.54,0.271
97.01,108.67,0.271
97.02,108.80,0.271
97.03,108.94,0.271
97.05,109.07,0.271
97.06,109.20,0.272
97.07,109.34,0.272
97.09,109.47,0.272
97.10,109.60,0.272
97.11,109.74,0.272
97.13,109.87,0.272
97.14,110.00,0.272
97.15,110.14,0.272
97.17,110.27,0.272
97.18,110.40,0.272
97.19,110.54,0.272
97.21,110.67,0.272
97.22,110.80,0.272
97.23,110.94,0.272
97.25,111.07,0.272
97.26,111.20,0.272
97.27,111.34,0.272
97.29,111.47,0.273
97.30,111.60,0.273
97.31,111.74,0.273
97.33,111.87,0.273
97.34,112.01,0.273
97.35,112.14,0.273
97.37,112.27,0.273
97.38,112.41,0.273
97.39,112.54,0.273
97.41,112.67,0.273
97.42,112.81,0.273
97.43,112.94,0.273
97.45,113.07,0.273
97.46,113.21,0.273
97.47,113.34,0.273
97.49,113.47,0.273
97.50,113.61,0.273
97.51,113.74,0.274
97.53,113.88,0.274
97.54,114.01,0.274
97.55,114.14,0.274
97.57,114.28,0.274
97.58,114.41,0.274
97.59,114.54,0.274
97.61,114.68,0.274
97.62,114.81,0.274
97.63,114.94,0.274
97.65,115.07,0.274
97.66,115.21,0.274
97.67,115.34,0.274
97.69,115.47,0.274
97.70,115.61,0.274
97.71,115.74,0.274
97.73,115.87,0.274
97.74,116.01,0.274
97.75,116.14,0.274
97.77,116.27,0.274
97.78,116.41,0.275
97.79,116.54,0.274
97.81,116.67,0.274
97.82,116.81,0.274
97.83,116.94,0.274
97.85,117.07,0.274
97.86,117.21,0.275
97.87,117.34,0.275
97.89,117.48,0.274
97.90,117.61,0.275
97.91,117.74,0.275
97.93,117.88,0.275
97.94,118.01,0.275
97.95,118.14,0.275
97.97,118.28,0.275
97.98,118.41,0.275
97.99,118.54,0.275
98.01,118.68,0.275
98.02,118.81,0.275
98.03,118.94,0.275
98.05,119.08,0.275
98.06,119.21,0.275
98.07,119.34,0.275
98.09,119.48,0.275
98.10,119.61,0.275
98.11,119.74,0.275
98.13,119.88,0.275
98.14,120.01,0.275
98.15,120.14,0.275
98.17,120.28,0.275
98.18,120.41,0.275
98.19,120.55,0.275
98.21,120.68,0.275
98.22,120.81,0.275
98.23,120.94,0.275
98.25,121.08,0.276
98.26,121.21,0.275
98.27,121.35,0.276
98.29,121.48,0.276
98.30,121.61,0.276
98.31,121.75,0.276
98.33,121.88,0.276
98.34,122.01,0.276
98.35,122.15,0.276
98.37,122.28,0.276
98.38,122.41,0.276
98.39,122.55,0.276
98.41,122.68,0.276
98.42,122.81,0.276
98.43,122.95,0.276
98.45,123.08,0.276
98.46,123.21,0.276
98.47,123.35,0.276
98.49,123.48,0.276
98.50,123.61,0.276
98.51,123.75,0.276
98.53,123.88,0.276
98.54,124.01,0.276
98.55,124.15,0.276
98.57,124.28,0.276
98.58,124.41,0.276
98.59,124.55,0.276
98.61,124.68,0.276
98.62,124.81,0.276
98.63,124.95,0.276
98.65,125.08,0.276
98.66,125.22,0.277
98.67,125.35,0.277
98.69,125.48,0.277
98.70,125.61,0.277
98.71,125.75,0.277
98.73,125.88,0.277
98.74,126.02,0.277
98.75,126.15,0.277
98.77,126.28,0.277
98.78,126.42,0.277
98.79,126.55,0.277
98.81,126.68,0.277
98.82,126.82,0.277
98.83,126.95,0.277
98.85,127.08,0.277
98.86,127.22,0.277
98.87,127.35,0.277
98.89,127.48,0.277
98.90,127.62,0.277
98.91,127.75,0.277
98.93,127.88,0.277
98.94,128.02,
98.95,128.15,
98.97,128.28,
98.98,128.42,
98.99,,