File: DSC/2025_04_20_PVP10_n60C_160C_10Cmin_x3.csv
Filename,2025_04_20_PVP10_n60C_160C_10Cmin_x3
Instrument name,DSC2A-00468 (192.168.1.100)
Operator,Yarger
rundate,4/20/2025
Sample name,2025_04_20_PVP10_n60C_160C_10Cmin_x3
proceduresegments,Data Off ; Equilibrate -60.00 °C; Data On ; Ramp 10.00 °C/min to 200.00 °C; Data Off ; Isothermal 1.0 min; Data On ; Ramp 10.00 °C/min to -60.00 °C; Data Off ; Isothermal 1.0 min; Data On ; Ramp 10.00 °C/min to 200.00 °C; Data Off ; Isothermal 1.0 min; Data On ; Ramp 10.00 °C/min to -60.00 °C; Data Off ; Isothermal 1.0 min; Data On ; Ramp 10.00 °C/min to 200.00 °C
[File Parameters]
Run date,4/20/2025 2:19:59 PM
Trios version,5.1.1.46572
Original File Name,
Current File Name,D:\DSC2500\JYarger\2025_04_20_PVP10_n60C_160C_10Cmin_x3.tri
[Procedure]
Procedure Name,PVP10_n60_160C_10Cmin_x3
Sample Name,2025_04_20_PVP10_n60C_160C_10Cmin_x3
Sample Mass,3.22 mg
Reference Sample Mass,0 mg
Pan Mass,25.77 mg
Pan Number,33
Reference Pan Mass,25.8 mg
Reference Pan Number,28
Pan Type,Tzero Aluminum
Comments,"Al Pan/Lid, Not sealed."
Project Name,CA
Operator,Yarger
Test,Custom
Unload Max Temperature,30
Unload Min Temperature,30
Load Max Temperature,30
Load Min Temperature,30
Stop on Gas Flow Error,Yes
[Signal List]
Signal #1,Time (min)
Signal #2,Temperature (°C)
Signal #3,Heat Flow (mW)
Signal #4,Delta T (µV)
Signal #5,Delta Tzero (µV)
Signal #6,Tzero Temperature (°C)
Signal #7,Cell Purge (mL/min)
Signal #8,Heater Temp (°C)
Signal #9,Power Delivered (W)
Signal #10,Reference Junction Temperature (°C)
Signal #11,Flange Temperature (°C)
Signal #12,Heat Flow Phase (rad)
Signal #13,Total Heat Capacity (J/°C)
Signal #14,Heat Capacity (J/°C)
[Configuration]
Company Name,ASU
Instrument Name,DSC2A-00468
Instrument Type,DSC2500
Serial Number,DSC2A-00468
IP,192.168.1.100
Location of Instrument,MRRC
DisplayType,Unknown
Sample Interval ,0.1 s/pt
Selected Heat Flow,T4P
Exotherm Direction,Down
Cell Serial,DRC2-00792
Lid Type,Standard
Cooler,RCS 90
Leave Cooler on at End of Sequence,On
Gas 2,Nitrogen
Gas Selected,Channel 1
Flow Rate,50 mL/min
Secondary Purge,On
Licensed Heat Flow,Heat Flow T4P
Modulation Licensed,Yes
[Versions]
Common IDD Version,1
Cortex Version,VER 2.10.2.31
Driver,5.0.0.6
GDM Version,1.0.3.3
TouchscreenVersion,1.0.0.16145
FEP Version,1.2.1.21
FEP Bootloader,2.0.0.5
AutoSampler Version,2.1.1.26
Auto Sampler Bootloader,2.0.0.5
FCM Version,1.1.0.3
FCM Bootloader,2.0.0.5
[Experiment Logs]
Experiment Log Entry # 1,Data On set to 0
Experiment Log Entry # 3,Equilibrate Segment -60 (C) Started
Experiment Log Entry # 5,Air Cool is off.
Experiment Log Entry # 7,Data On set to 1
Experiment Log Entry # 9,Ramp Segment 10 C/min to 200 Started
Experiment Log Entry # 11,Data On set to 0
Experiment Log Entry # 13,Isothermal Segment 1 min started
Experiment Log Entry # 15,Data On set to 1
Experiment Log Entry # 17,Ramp Segment 10 C/min to -60 Started
Experiment Log Entry # 19,Data On set to 0
Experiment Log Entry # 21,Isothermal Segment 1 min started
Experiment Log Entry # 23,Data On set to 1
Experiment Log Entry # 25,Ramp Segment 10 C/min to 200 Started
Experiment Log Entry # 27,Data On set to 0
Experiment Log Entry # 29,Isothermal Segment 1 min started
Experiment Log Entry # 31,Data On set to 1
Experiment Log Entry # 33,Ramp Segment 10 C/min to -60 Started
Experiment Log Entry # 35,Data On set to 0
Experiment Log Entry # 37,Isothermal Segment 1 min started
Experiment Log Entry # 39,Data On set to 1
Experiment Log Entry # 41,Ramp Segment 10 C/min to 200 Started
Experiment Log Entry # 43,Auto sampler has detected that FCM has gone offline
[Method Log]
Method Log Entry # 1,Data Off
Method Log Entry # 2,Equilibrate -60 °C
Method Log Entry # 3,Data On
Method Log Entry # 4,(Ramp 535917) Ramp 10 °C/minute to 200 °C
Method Log Entry # 5,Data Off
Method Log Entry # 6,Isothermal 1 minutes
Method Log Entry # 7,Data On
Method Log Entry # 8,(Ramp 535921) Ramp 10 °C/minute to -60 °C
Method Log Entry # 9,Data Off
Method Log Entry # 10,Isothermal 1 minutes
Method Log Entry # 11,Data On
Method Log Entry # 12,(Ramp 535925) Ramp 10 °C/minute to 200 °C
Method Log Entry # 13,Data Off
Method Log Entry # 14,Isothermal 1 minutes
Method Log Entry # 15,Data On
Method Log Entry # 16,(Ramp 535929) Ramp 10 °C/minute to -60 °C
Method Log Entry # 17,Data Off
Method Log Entry # 18,Isothermal 1 minutes
Method Log Entry # 19,Data On
Method Log Entry # 20,(Ramp 535933) Ramp 10 °C/minute to 200 °C
Cell Serial,DRC2-00792
[T1 Calibration]
Slope,-0.008529666
Offset,9.636258
Initial Temperature,98.23
GUID,f8bfdadc-4977-4fdf-ba6d-0ba9134940c3
[TZero Calibration]
Date Applied,11/29/2022 4:06:13 PM
Description,From -89.059 °C to 396.009 °C at 20.000°C/min
Gas Type,Nitrogen
Pan Type,None
Source Files 1,C:\Users\yargerlab\Desktop\DSC Data\General\TZero_calibration_11_29_22_2nd(2).tri
Source Files 2,C:\Users\yargerlab\Desktop\DSC Data\General\TZero_calibration_11_29_22_2nd(3).tri
Delta T Offset,13.05235
Delta T Slope,-0.007271007
Delta T0 Offset,-13.69128
Delta T0 Slope,0.06063341
[Temperature Calibration]
Date Applied,11/29/2022 7:12:28 PM
Description,From 106.590 °C to 186.590 °C at 10.000°C/min
Gas Type,Nitrogen
Pan Type,Tzero Aluminum Hermetic
Source Files 1,C:\Users\yargerlab\Desktop\DSC Data\General\Indium(6).tri
Measured 1,157.391
Known 1,156.598
[Cell Constant Calibration]
Date Applied,11/29/2022 7:12:29 PM
Description,From 106.590 °C to 186.590 °C at 10.000°C/min
Gas Type,Nitrogen
Pan Type,Tzero Aluminum Hermetic
Source Files 1,C:\Users\yargerlab\Desktop\DSC Data\General\Indium(6).tri
T4P KCell,1.006051
Onset Slope,63.26126 mW/°C
[Direct Cp Calibration]
Date Applied,11/30/2022 11:04:51 AM
Description,From -79.983 °C to 298.409 °C at 10.000°C/min
Gas Type,Nitrogen
Pan Type,Tzero Aluminum Hermetic
Source Files 1,C:\Users\yargerlab\Desktop\DSC Data\General\Sapphire_Heat_Capacity_11_30_22.tri
[Rev Cp Calibration]
Date Applied,11/30/2022 1:58:51 PM
Description,From -79.996 °C to 292.812 °C at 3.000°C/min
Gas Type,Nitrogen
Pan Type,Tzero Aluminum Hermetic
Source Files 1,C:\Users\yargerlab\Desktop\DSC Data\General\Sapphire_MDSC_Calibration_11_30_22.tri
[step]
Ramp 10.00 °C/min to 200.00 °C
Time,Temperature,Heat Flow (Normalized)
min,°C,W/g
0.00,-59.81,-0.048
0.02,-59.81,-0.047
0.04,-59.81,-0.044
0.05,-59.80,-0.035
0.07,-59.77,-0.017
0.09,-59.71,0.009
0.11,-59.63,0.036
0.13,-59.53,0.067
0.15,-59.41,0.095
0.16,-59.26,0.123
0.18,-59.11,0.146
0.20,-58.95,0.166
0.22,-58.78,0.182
0.24,-58.61,0.193
0.26,-58.43,0.201
0.28,-58.26,0.208
0.29,-58.08,0.212
0.31,-57.90,0.214
0.33,-57.73,0.217
0.35,-57.55,0.219
0.37,-57.37,0.221
0.39,-57.19,0.221
0.40,-57.01,0.222
0.42,-56.83,0.222
0.44,-56.65,0.223
0.46,-56.47,0.224
0.48,-56.29,0.224
0.50,-56.11,0.225
0.51,-55.93,0.225
0.53,-55.75,0.226
0.55,-55.57,0.226
0.57,-55.39,0.227
0.59,-55.21,0.227
0.60,-55.03,0.228
0.62,-54.85,0.228
0.64,-54.67,0.229
0.66,-54.49,0.229
0.68,-54.31,0.230
0.70,-54.13,0.230
0.72,-53.95,0.230
0.73,-53.77,0.231
0.75,-53.59,0.231
0.77,-53.41,0.232
0.79,-53.22,0.232
0.81,-53.04,0.232
0.83,-52.86,0.233
0.84,-52.68,0.233
0.86,-52.50,0.233
0.88,-52.32,0.234
0.90,-52.13,0.234
0.92,-51.95,0.234
0.93,-51.77,0.235
0.95,-51.59,0.235
0.97,-51.41,0.235
0.99,-51.23,0.236
1.01,-51.04,0.236
1.03,-50.86,0.236
1.05,-50.68,0.236
1.06,-50.50,0.237
1.08,-50.31,0.237
1.10,-50.13,0.237
1.12,-49.95,0.237
1.14,-49.77,0.238
1.16,-49.58,0.238
1.17,-49.40,0.238
1.19,-49.22,0.238
1.21,-49.04,0.239
1.23,-48.85,0.239
1.25,-48.67,0.239
1.27,-48.49,0.239
1.28,-48.31,0.239
1.30,-48.12,0.239
1.32,-47.94,0.240
1.34,-47.76,0.240
1.36,-47.57,0.240
1.38,-47.39,0.240
1.39,-47.21,0.240
1.41,-47.02,0.240
1.43,-46.84,0.240
1.45,-46.66,0.240
1.47,-46.47,0.241
1.48,-46.29,0.241
1.50,-46.11,0.241
1.52,-45.92,0.241
1.54,-45.74,0.241
1.56,-45.56,0.241
1.58,-45.38,0.241
1.59,-45.19,0.241
1.61,-45.01,0.241
1.63,-44.83,0.241
1.65,-44.64,0.242
1.67,-44.46,0.242
1.69,-44.28,0.242
1.71,-44.09,0.242
1.72,-43.91,0.242
1.74,-43.73,0.242
1.76,-43.54,0.242
1.78,-43.36,0.242
1.80,-43.18,0.242
1.82,-42.99,0.242
1.83,-42.81,0.242
1.85,-42.63,0.242
1.87,-42.44,0.242
1.89,-42.26,0.243
1.91,-42.08,0.243
1.93,-41.89,0.243
1.94,-41.71,0.243
1.96,-41.52,0.243
1.98,-41.34,0.243
2.00,-41.16,0.243
2.02,-40.98,0.243
2.03,-40.79,0.243
2.05,-40.61,0.243
2.07,-40.43,0.243
2.09,-40.24,0.243
2.11,-40.06,0.243
2.13,-39.87,0.243
2.14,-39.69,0.243
2.16,-39.51,0.243
2.18,-39.32,0.243
2.20,-39.14,0.243
2.22,-38.96,0.243
2.24,-38.77,0.244
2.26,-38.59,0.244
2.27,-38.41,0.244
2.29,-38.22,0.244
2.31,-38.04,0.244
2.33,-37.85,0.244
2.35,-37.67,0.244
2.36,-37.49,0.244
2.38,-37.31,0.244
2.40,-37.12,0.244
2.42,-36.94,0.244
2.44,-36.75,0.244
2.46,-36.57,0.244
2.48,-36.39,0.244
2.49,-36.20,0.244
2.51,-36.02,0.244
2.53,-35.84,0.244
2.55,-35.65,0.244
2.57,-35.47,0.245
2.59,-35.29,0.245
2.60,-35.10,0.245
2.62,-34.92,0.245
2.64,-34.74,0.245
2.66,-34.55,0.245
2.68,-34.37,0.245
2.69,-34.19,0.245
2.71,-34.00,0.245
2.73,-33.82,0.245
2.75,-33.64,0.245
2.77,-33.45,0.245
2.79,-33.27,0.245
2.81,-33.08,0.245
2.82,-32.90,0.245
2.84,-32.72,0.245
2.86,-32.53,0.245
2.88,-32.35,0.246
2.90,-32.17,0.246
2.91,-31.98,0.246
2.93,-31.80,0.246
2.95,-31.61,0.246
2.97,-31.43,0.246
2.99,-31.25,0.246
3.01,-31.06,0.246
3.03,-30.88,0.246
3.04,-30.70,0.246
3.06,-30.51,0.246
3.08,-30.33,0.246
3.10,-30.15,0.246
3.12,-29.96,0.246
3.14,-29.78,0.246
3.15,-29.60,0.246
3.17,-29.41,0.247
3.19,-29.23,0.247
3.21,-29.05,0.247
3.23,-28.86,0.247
3.24,-28.68,0.247
3.26,-28.50,0.247
3.28,-28.31,0.247
3.30,-28.13,0.247
3.32,-27.95,0.247
3.34,-27.76,0.247
3.36,-27.58,0.247
3.37,-27.39,0.248
3.39,-27.21,0.248
3.41,-27.03,0.248
3.43,-26.84,0.248
3.45,-26.66,0.248
3.46,-26.48,0.248
3.48,-26.29,0.248
3.50,-26.11,0.248
3.52,-25.93,0.248
3.54,-25.74,0.248
3.56,-25.56,0.249
3.58,-25.38,0.249
3.59,-25.19,0.249
3.61,-25.01,0.249
3.63,-24.82,0.249
3.65,-24.64,0.249
3.67,-24.46,0.249
3.69,-24.27,0.249
3.70,-24.09,0.249
3.72,-23.91,0.249
3.74,-23.72,0.250
3.76,-23.54,0.250
3.78,-23.36,0.250
3.79,-23.17,0.250
3.81,-22.99,0.250
3.83,-22.81,0.250
3.85,-22.62,0.250
3.87,-22.44,0.250
3.89,-22.25,0.250
3.91,-22.07,0.251
3.92,-21.89,0.251
3.94,-21.70,0.251
3.96,-21.52,0.251
3.98,-21.34,0.251
4.00,-21.15,0.251
4.01,-20.97,0.251
4.03,-20.79,0.251
4.05,-20.60,0.251
4.07,-20.42,0.251
4.09,-20.24,0.251
4.11,-20.05,0.252
4.13,-19.87,0.252
4.14,-19.69,0.252
4.16,-19.50,0.252
4.18,-19.32,0.252
4.20,-19.14,0.252
4.22,-18.95,0.252
4.24,-18.77,0.252
4.25,-18.59,0.253
4.27,-18.40,0.253
4.29,-18.22,0.253
4.31,-18.03,0.253
4.33,-17.85,0.253
4.35,-17.67,0.253
4.36,-17.48,0.253
4.38,-17.30,0.254
4.40,-17.12,0.254
4.42,-16.93,0.254
4.44,-16.75,0.254
4.45,-16.57,0.254
4.47,-16.38,0.254
4.49,-16.20,0.254
4.51,-16.02,0.254
4.53,-15.83,0.255
4.55,-15.65,0.255
4.56,-15.46,0.255
4.58,-15.28,0.255
4.60,-15.10,0.255
4.62,-14.92,0.255
4.64,-14.73,0.256
4.66,-14.55,0.256
4.68,-14.36,0.256
4.69,-14.18,0.256
4.71,-14.00,0.256
4.73,-13.81,0.256
4.75,-13.63,0.257
4.77,-13.45,0.257
4.79,-13.26,0.257
4.80,-13.08,0.257
4.82,-12.90,0.257
4.84,-12.71,0.257
4.86,-12.53,0.258
4.88,-12.35,0.258
4.90,-12.16,0.258
4.91,-11.98,0.258
4.93,-11.80,0.258
4.95,-11.61,0.259
4.97,-11.43,0.259
4.99,-11.24,0.259
5.00,-11.06,0.259
5.02,-10.88,0.259
5.04,-10.70,0.260
5.06,-10.51,0.260
5.08,-10.33,0.260
5.10,-10.14,0.260
5.11,-9.96,0.260
5.13,-9.78,0.261
5.15,-9.59,0.261
5.17,-9.41,0.261
5.19,-9.23,0.261
5.21,-9.04,0.261
5.23,-8.86,0.262
5.24,-8.68,0.262
5.26,-8.49,0.262
5.28,-8.31,0.262
5.30,-8.13,0.262
5.32,-7.94,0.263
5.34,-7.76,0.263
5.35,-7.57,0.263
5.37,-7.39,0.263
5.39,-7.21,0.264
5.41,-7.03,0.264
5.43,-6.84,0.264
5.45,-6.66,0.264
5.46,-6.48,0.265
5.48,-6.29,0.265
5.50,-6.11,0.265
5.52,-5.92,0.265
5.54,-5.74,0.266
5.55,-5.56,0.266
5.57,-5.37,0.266
5.59,-5.19,0.266
5.61,-5.01,0.267
5.63,-4.82,0.267
5.65,-4.64,0.267
5.66,-4.46,0.267
5.68,-4.27,0.268
5.70,-4.09,0.268
5.72,-3.91,0.268
5.74,-3.72,0.269
5.76,-3.54,0.269
5.78,-3.36,0.269
5.79,-3.17,0.269
5.81,-2.99,0.270
5.83,-2.81,0.270
5.85,-2.62,0.270
5.87,-2.44,0.271
5.89,-2.25,0.271
5.90,-2.07,0.271
5.92,-1.89,0.271
5.94,-1.70,0.272
5.96,-1.52,0.272
5.98,-1.34,0.272
6.00,-1.15,0.273
6.01,-0.97,0.273
6.03,-0.79,0.273
6.05,-0.60,0.273
6.07,-0.42,0.274
6.09,-0.24,0.274
6.10,-0.05,0.275
6.12,0.13,0.275
6.14,0.31,0.275
6.16,0.50,0.275
6.18,0.68,0.276
6.20,0.87,0.276
6.21,1.05,0.277
6.23,1.23,0.277
6.25,1.41,0.277
6.27,1.60,0.278
6.29,1.78,0.278
6.31,1.97,0.278
6.33,2.15,0.279
6.34,2.33,0.279
6.36,2.51,0.279
6.38,2.70,0.280
6.40,2.88,0.280
6.42,3.07,0.281
6.44,3.25,0.281
6.45,3.43,0.281
6.47,3.62,0.282
6.49,3.80,0.282
6.51,3.98,0.283
6.53,4.17,0.283
6.55,4.35,0.284
6.56,4.53,0.284
6.58,4.72,0.284
6.60,4.90,0.285
6.62,5.08,0.285
6.64,5.27,0.286
6.65,5.45,0.286
6.67,5.63,0.287
6.69,5.82,0.287
6.71,6.00,0.288
6.73,6.18,0.288
6.75,6.37,0.289
6.76,6.55,0.289
6.78,6.73,0.290
6.80,6.92,0.290
6.82,7.10,0.290
6.84,7.28,0.291
6.86,7.47,0.291
6.88,7.65,0.292
6.89,7.83,0.292
6.91,8.02,0.293
6.93,8.20,0.293
6.95,8.38,0.294
6.97,8.57,0.294
6.99,8.75,0.295
7.00,8.93,0.295
7.02,9.12,0.296
7.04,9.30,0.296
7.06,9.48,0.297
7.08,9.67,0.297
7.10,9.85,0.298
7.11,10.04,0.298
7.13,10.22,0.299
7.15,10.40,0.300
7.17,10.59,0.300
7.19,10.77,0.301
7.20,10.95,0.301
7.22,11.14,0.302
7.24,11.32,0.302
7.26,11.50,0.303
7.28,11.69,0.304
7.30,11.87,0.304
7.31,12.05,0.305
7.33,12.24,0.305
7.35,12.42,0.306
7.37,12.60,0.307
7.39,12.79,0.307
7.41,12.97,0.308
7.43,13.16,0.309
7.44,13.34,0.309
7.46,13.52,0.310
7.48,13.71,0.311
7.50,13.89,0.311
7.52,14.07,0.312
7.54,14.26,0.313
7.55,14.44,0.313
7.57,14.62,0.314
7.59,14.80,0.315
7.61,14.99,0.315
7.63,15.17,0.316
7.65,15.35,0.317
7.66,15.54,0.317
7.68,15.72,0.318
7.70,15.90,0.319
7.72,16.09,0.320
7.74,16.27,0.320
7.75,16.45,0.321
7.77,16.64,0.322
7.79,16.82,0.323
7.81,17.00,0.323
7.83,17.19,0.324
7.85,17.37,0.325
7.86,17.55,0.326
7.88,17.74,0.327
7.90,17.92,0.328
7.92,18.10,0.329
7.94,18.29,0.329
7.96,18.47,0.330
7.98,18.66,0.331
7.99,18.84,0.332
8.01,19.02,0.333
8.03,19.20,0.334
8.05,19.39,0.334
8.07,19.57,0.335
8.09,19.75,0.336
8.10,19.94,0.337
8.12,20.12,0.338
8.14,20.30,0.339
8.16,20.49,0.340
8.18,20.67,0.341
8.20,20.85,0.342
8.21,21.04,0.343
8.23,21.22,0.344
8.25,21.41,0.345
8.27,21.59,0.346
8.29,21.77,0.346
8.30,21.95,0.347
8.32,22.14,0.348
8.34,22.32,0.349
8.36,22.50,0.350
8.38,22.69,0.351
8.40,22.87,0.353
8.41,23.06,0.354
8.43,23.24,0.355
8.45,23.42,0.356
8.47,23.60,0.357
8.49,23.79,0.358
8.51,23.97,0.359
8.53,24.15,0.361
8.54,24.34,0.362
8.56,24.52,0.363
8.58,24.70,0.365
8.60,24.89,0.366
8.62,25.07,0.367
8.63,25.25,0.368
8.65,25.43,0.369
8.67,25.62,0.370
8.69,25.80,0.372
8.71,25.99,0.373
8.73,26.17,0.374
8.75,26.35,0.375
8.76,26.54,0.377
8.78,26.72,0.378
8.80,26.90,0.380
8.82,27.09,0.382
8.84,27.27,0.383
8.85,27.45,0.384
8.87,27.64,0.385
8.89,27.82,0.386
8.91,28.00,0.387
8.93,28.19,0.390
8.95,28.37,0.391
8.97,28.55,0.392
8.98,28.74,0.393
9.00,28.92,0.395
9.02,29.10,0.397
9.04,29.28,0.398
9.06,29.47,0.399
9.08,29.65,0.401
9.09,29.83,0.402
9.11,30.02,0.404
9.13,30.20,0.406
9.15,30.38,0.407
9.17,30.57,0.409
9.18,30.75,0.410
9.20,30.93,0.412
9.22,31.12,0.414
9.24,31.30,0.415
9.26,31.48,0.418
9.28,31.67,0.419
9.30,31.85,0.421
9.31,32.03,0.424
9.33,32.22,0.425
9.35,32.40,0.427
9.37,32.58,0.429
9.39,32.77,0.430
9.40,32.95,0.432
9.42,33.13,0.433
9.44,33.32,0.435
9.46,33.50,0.437
9.48,33.68,0.439
9.50,33.86,0.440
9.52,34.05,0.442
9.53,34.23,0.444
9.55,34.41,0.446
9.57,34.60,0.448
9.59,34.78,0.450
9.61,34.96,0.452
9.63,35.15,0.453
9.64,35.33,0.456
9.66,35.51,0.457
9.68,35.69,0.459
9.70,35.88,0.462
9.72,36.06,0.464
9.73,36.24,0.466
9.75,36.43,0.468
9.77,36.61,0.470
9.79,36.79,0.472
9.81,36.98,0.474
9.83,37.16,0.476
9.85,37.34,0.478
9.86,37.53,0.480
9.88,37.71,0.484
9.90,37.89,0.486
9.92,38.08,0.487
9.94,38.26,0.489
9.95,38.44,0.492
9.97,38.62,0.494
9.99,38.81,0.496
10.01,38.99,0.498
10.03,39.17,0.500
10.05,39.36,0.502
10.07,39.54,0.505
10.08,39.72,0.507
10.10,39.91,0.510
10.12,40.09,0.512
10.14,40.27,0.514
10.16,40.45,0.517
10.18,40.64,0.519
10.19,40.82,0.522
10.21,41.00,0.524
10.23,41.19,0.526
10.25,41.37,0.529
10.27,41.55,0.532
10.28,41.74,0.533
10.30,41.92,0.537
10.32,42.10,0.539
10.34,42.28,0.542
10.36,42.47,0.544
10.38,42.65,0.547
10.40,42.83,0.550
10.41,43.02,0.552
10.43,43.20,0.554
10.45,43.38,0.557
10.47,43.57,0.560
10.49,43.75,0.562
10.50,43.93,0.565
10.52,44.11,0.567
10.54,44.30,0.571
10.56,44.48,0.573
10.58,44.66,0.577
10.60,44.85,0.579
10.62,45.03,0.582
10.63,45.21,0.585
10.65,45.39,0.587
10.67,45.58,0.591
10.69,45.76,0.593
10.71,45.94,0.595
10.73,46.13,0.598
10.74,46.31,0.602
10.76,46.49,0.604
10.78,46.68,0.607
10.80,46.86,0.610
10.82,47.04,0.615
10.83,47.22,0.618
10.85,47.41,0.620
10.87,47.59,0.623
10.89,47.77,0.627
10.91,47.96,0.629
10.93,48.14,0.631
10.95,48.32,0.635
10.96,48.50,0.638
10.98,48.69,0.642
11.00,48.87,0.644
11.02,49.05,0.647
11.04,49.24,0.651
11.05,49.42,0.654
11.07,49.60,0.657
11.09,49.79,0.660
11.11,49.97,0.664
11.13,50.15,0.666
11.15,50.33,0.670
11.17,50.52,0.673
11.18,50.70,0.676
11.20,50.88,0.681
11.22,51.06,0.684
11.24,51.25,0.688
11.26,51.43,0.691
11.28,51.61,0.695
11.29,51.80,0.697
11.31,51.98,0.702
11.33,52.16,0.705
11.35,52.34,0.709
11.37,52.53,0.711
11.38,52.71,0.715
11.40,52.89,0.719
11.42,53.08,0.723
11.44,53.26,0.726
11.46,53.44,0.730
11.48,53.62,0.734
11.50,53.81,0.737
11.51,53.99,0.741
11.53,54.17,0.745
11.55,54.35,0.748
11.57,54.54,0.752
11.59,54.72,0.756
11.60,54.90,0.760
11.62,55.08,0.764
11.64,55.27,0.768
11.66,55.45,0.772
11.68,55.63,0.775
11.70,55.82,0.780
11.72,56.00,0.784
11.73,56.18,0.787
11.75,56.37,0.793
11.77,56.55,0.796
11.79,56.73,0.801
11.81,56.91,0.804
11.83,57.10,0.809
11.84,57.28,0.813
11.86,57.46,0.818
11.88,57.64,0.821
11.90,57.83,0.826
11.92,58.01,0.831
11.93,58.19,0.836
11.95,58.37,0.841
11.97,58.56,0.845
11.99,58.74,0.851
12.01,58.92,0.856
12.03,59.11,0.860
12.05,59.29,0.866
12.06,59.47,0.871
12.08,59.65,0.876
12.10,59.83,0.881
12.12,60.02,0.888
12.14,60.20,0.892
12.15,60.38,0.900
12.17,60.56,0.906
12.19,60.75,0.913
12.21,60.93,0.919
12.23,61.11,0.926
12.25,61.29,0.933
12.27,61.48,0.943
12.28,61.66,0.948
12.30,61.84,0.957
12.32,62.02,0.965
12.34,62.20,0.971
12.36,62.38,0.978
12.38,62.57,0.984
12.39,62.75,0.989
12.41,62.93,0.995
12.43,63.11,1.001
12.45,63.30,1.005
12.47,63.48,1.009
12.48,63.66,1.012
12.50,63.84,1.015
12.52,64.03,1.019
12.54,64.21,1.021
12.56,64.39,1.023
12.58,64.57,1.026
12.60,64.76,1.028
12.61,64.94,1.029
12.63,65.12,1.031
12.65,65.31,1.032
12.67,65.49,1.034
12.69,65.67,1.036
12.70,65.86,1.037
12.72,66.04,1.039
12.74,66.22,1.040
12.76,66.40,1.043
12.78,66.59,1.045
12.80,66.77,1.047
12.82,66.95,1.050
12.83,67.14,1.053
12.85,67.32,1.057
12.87,67.50,1.059
12.89,67.69,1.062
12.91,67.87,1.064
12.93,68.05,1.067
12.94,68.23,1.070
12.96,68.42,1.074
12.98,68.60,1.077
13.00,68.78,1.080
13.02,68.97,1.083
13.03,69.15,1.087
13.05,69.33,1.090
13.07,69.52,1.093
13.09,69.70,1.097
13.11,69.88,1.100
13.13,70.06,1.103
13.15,70.25,1.106
13.16,70.43,1.109
13.18,70.61,1.112
13.20,70.80,1.115
13.22,70.98,1.119
13.24,71.16,1.122
13.25,71.34,1.124
13.27,71.53,1.129
13.29,71.71,1.131
13.31,71.89,1.133
13.33,72.08,1.136
13.35,72.26,1.139
13.37,72.44,1.143
13.38,72.62,1.145
13.40,72.81,1.148
13.42,72.99,1.151
13.44,73.17,1.153
13.46,73.35,1.156
13.48,73.54,1.157
13.49,73.72,1.161
13.51,73.91,1.163
13.53,74.09,1.166
13.55,74.27,1.167
13.57,74.45,1.170
13.58,74.64,1.172
13.60,74.82,1.174
13.62,75.00,1.176
13.64,75.19,1.178
13.66,75.37,1.179
13.68,75.55,1.181
13.70,75.74,1.183
13.71,75.92,1.184
13.73,76.10,1.186
13.75,76.29,1.188
13.77,76.47,1.189
13.79,76.65,1.191
13.80,76.83,1.193
13.82,77.02,1.195
13.84,77.20,1.196
13.86,77.38,1.198
13.88,77.57,1.200
13.90,77.75,1.201
13.92,77.93,1.202
13.93,78.12,1.203
13.95,78.30,1.205
13.97,78.48,1.206
13.99,78.67,1.207
14.01,78.85,1.208
14.03,79.03,1.209
14.04,79.22,1.210
14.06,79.40,1.211
14.08,79.58,1.211
14.10,79.77,1.212
14.12,79.95,1.213
14.13,80.13,1.214
14.15,80.32,1.215
14.17,80.50,1.215
14.19,80.68,1.216
14.21,80.87,1.217
14.23,81.05,1.218
14.25,81.23,1.218
14.26,81.42,1.219
14.28,81.60,1.219
14.30,81.78,1.220
14.32,81.97,1.220
14.34,82.15,1.221
14.35,82.34,1.221
14.37,82.52,1.222
14.39,82.70,1.222
14.41,82.89,1.222
14.43,83.07,1.223
14.45,83.25,1.223
14.47,83.44,1.223
14.48,83.62,1.223
14.50,83.81,1.223
14.52,83.99,1.223
14.54,84.17,1.222
14.56,84.36,1.222
14.58,84.54,1.222
14.59,84.72,1.222
14.61,84.91,1.221
14.63,85.09,1.221
14.65,85.27,1.220
14.67,85.46,1.219
14.68,85.64,1.219
14.70,85.83,1.218
14.72,86.01,1.217
14.74,86.19,1.216
14.76,86.38,1.215
14.78,86.56,1.214
14.80,86.75,1.212
14.81,86.93,1.210
14.83,87.11,1.208
14.85,87.30,1.206
14.87,87.48,1.205
14.89,87.66,1.202
14.90,87.85,1.201
14.92,88.03,1.198
14.94,88.22,1.195
14.96,88.40,1.193
14.98,88.58,1.190
15.00,88.77,1.188
15.02,88.95,1.185
15.03,89.14,1.182
15.05,89.32,1.179
15.07,89.50,1.176
15.09,89.69,1.173
15.11,89.87,1.169
15.13,90.06,1.167
15.14,90.24,1.163
15.16,90.42,1.160
15.18,90.61,1.156
15.20,90.79,1.153
15.22,90.98,1.150
15.23,91.16,1.145
15.25,91.35,1.142
15.27,91.53,1.140
15.29,91.72,1.136
15.31,91.90,1.133
15.33,92.08,1.129
15.35,92.27,1.126
15.36,92.45,1.121
15.38,92.64,1.117
15.40,92.82,1.114
15.42,93.00,1.109
15.44,93.19,1.105
15.45,93.37,1.101
15.47,93.56,1.097
15.49,93.74,1.093
15.51,93.93,1.088
15.53,94.11,1.085
15.55,94.29,1.081
15.57,94.48,1.078
15.58,94.66,1.073
15.60,94.85,1.069
15.62,95.03,1.064
15.64,95.22,1.059
15.66,95.40,1.055
15.68,95.59,1.050
15.69,95.77,1.046
15.71,95.96,1.042
15.73,96.14,1.037
15.75,96.32,1.032
15.77,96.51,1.027
15.78,96.69,1.023
15.80,96.88,1.019
15.82,97.06,1.014
15.84,97.25,1.010
15.86,97.43,1.005
15.88,97.61,1.000
15.90,97.80,0.996
15.91,97.98,0.991
15.93,98.17,0.986
15.95,98.35,0.983
15.97,98.54,0.977
15.99,98.72,0.973
16.00,98.91,0.968
16.02,99.09,0.964
16.04,99.27,0.959
16.06,99.46,0.954
16.08,99.65,0.949
16.10,99.83,0.944
16.12,100.01,0.939
16.13,100.20,0.934
16.15,100.38,0.929
16.17,100.57,0.924
16.19,100.75,0.920
16.21,100.94,0.916
16.23,101.12,0.910
16.24,101.31,0.906
16.26,101.49,0.900
16.28,101.67,0.896
16.30,101.86,0.892
16.32,102.04,0.887
16.33,102.23,0.882
16.35,102.41,0.877
16.37,102.60,0.872
16.39,102.78,0.868
16.41,102.97,0.862
16.43,103.15,0.858
16.45,103.33,0.854
16.46,103.52,0.849
16.48,103.70,0.844
16.50,103.89,0.839
16.52,104.07,0.833
16.54,104.26,0.829
16.55,104.44,0.824
16.57,104.63,0.819
16.59,104.81,0.815
16.61,104.99,0.810
16.63,105.18,0.806
16.65,105.36,0.801
16.67,105.55,0.797
16.68,105.73,0.793
16.70,105.92,0.787
16.72,106.10,0.783
16.74,106.29,0.779
16.76,106.47,0.775
16.78,106.65,0.771
16.79,106.84,0.765
16.81,107.02,0.760
16.83,107.21,0.756
16.85,107.39,0.752
16.87,107.58,0.747
16.88,107.76,0.744
16.90,107.94,0.739
16.92,108.13,0.735
16.94,108.31,0.730
16.96,108.50,0.726
16.98,108.68,0.721
17.00,108.87,0.718
17.01,109.05,0.713
17.03,109.24,0.709
17.05,109.42,0.704
17.07,109.61,0.700
17.09,109.79,0.695
17.11,109.97,0.692
17.12,110.16,0.688
17.14,110.34,0.684
17.16,110.53,0.680
17.18,110.71,0.676
17.20,110.89,0.671
17.22,111.08,0.668
17.23,111.26,0.663
17.25,111.45,0.659
17.27,111.63,0.656
17.29,111.81,0.651
17.31,112.00,0.647
17.33,112.18,0.645
17.34,112.37,0.641
17.36,112.55,0.637
17.38,112.74,0.633
17.40,112.92,0.630
17.42,113.11,0.625
17.43,113.29,0.622
17.45,113.48,0.617
17.47,113.66,0.613
17.49,113.84,0.611
17.51,114.03,0.606
17.53,114.21,0.603
17.54,114.39,0.600
17.56,114.58,0.596
17.58,114.76,0.592
17.60,114.95,0.588
17.62,115.13,0.586
17.64,115.32,0.582
17.66,115.50,0.579
17.67,115.68,0.576
17.69,115.87,0.572
17.71,116.05,0.569
17.73,116.24,0.566
17.75,116.42,0.562
17.77,116.61,0.558
17.78,116.79,0.555
17.80,116.97,0.552
17.82,117.16,0.549
17.84,117.34,0.545
17.86,117.52,0.543
17.88,117.71,0.540
17.89,117.89,0.537
17.91,118.08,0.534
17.93,118.26,0.531
17.95,118.45,0.528
17.97,118.63,0.525
17.98,118.82,0.522
18.00,119.00,0.519
18.02,119.18,0.517
18.04,119.37,0.513
18.06,119.55,0.510
18.08,119.74,0.508
18.09,119.92,0.505
18.11,120.10,0.502
18.13,120.29,0.500
18.15,120.47,0.496
18.17,120.66,0.494
18.19,120.84,0.491
18.21,121.02,0.489
18.22,121.21,0.486
18.24,121.39,0.483
18.26,121.58,0.481
18.28,121.76,0.479
18.30,121.94,0.477
18.32,122.13,0.474
18.33,122.31,0.471
18.35,122.50,0.469
18.37,122.68,0.467
18.39,122.86,0.464
18.41,123.05,0.462
18.43,123.23,0.460
18.44,123.41,0.458
18.46,123.60,0.455
18.48,123.78,0.453
18.50,123.97,0.451
18.52,124.15,0.449
18.53,124.33,0.448
18.55,124.52,0.446
18.57,124.70,0.444
18.59,124.89,0.442
18.61,125.07,0.439
18.63,125.25,0.437
18.64,125.44,0.435
18.66,125.62,0.434
18.68,125.80,0.432
18.70,125.99,0.429
18.72,126.17,0.428
18.74,126.36,0.426
18.76,126.54,0.425
18.77,126.72,0.423
18.79,126.91,0.422
18.81,127.09,0.420
18.83,127.28,0.418
18.85,127.46,0.417
18.87,127.64,0.415
18.88,127.83,0.413
18.90,128.01,0.412
18.92,128.19,0.410
18.94,128.38,0.408
18.96,128.56,0.407
18.98,128.75,0.406
18.99,128.93,0.405
19.01,129.11,0.403
19.03,129.30,0.402
19.05,129.48,0.401
19.07,129.67,0.400
19.08,129.85,0.399
19.10,130.03,0.397
19.12,130.22,0.396
19.14,130.40,0.395
19.16,130.58,0.393
19.18,130.77,0.391
19.19,130.95,0.390
19.21,131.13,0.389
19.23,131.32,0.388
19.25,131.50,0.387
19.27,131.69,0.386
19.29,131.87,0.385
19.31,132.05,0.384
19.32,132.24,0.383
19.34,132.42,0.382
19.36,132.60,0.381
19.38,132.79,0.380
19.40,132.97,0.379
19.42,133.16,0.378
19.43,133.34,0.377
19.45,133.52,0.376
19.47,133.71,0.375
19.49,133.89,0.375
19.51,134.07,0.374
19.53,134.26,0.373
19.54,134.44,0.372
19.56,134.62,0.371
19.58,134.81,0.370
19.60,134.99,0.369
19.62,135.18,0.369
19.63,135.36,0.368
19.65,135.54,0.367
19.67,135.73,0.366
19.69,135.91,0.366
19.71,136.09,0.365
19.73,136.28,0.364
19.74,136.46,0.364
19.76,136.64,0.363
19.78,136.83,0.362
19.80,137.01,0.362
19.82,137.19,0.361
19.84,137.38,0.361
19.86,137.56,0.360
19.87,137.74,0.360
19.89,137.93,0.359
19.91,138.11,0.359
19.93,138.29,0.358
19.95,138.48,0.358
19.97,138.66,0.358
19.98,138.85,0.357
20.00,139.03,0.357
20.02,139.21,0.357
20.04,139.40,0.356
20.06,139.58,0.356
20.08,139.76,0.356
20.09,139.95,0.356
20.11,140.13,0.356
20.13,140.31,0.356
20.15,140.50,0.355
20.17,140.68,0.355
20.18,140.86,0.355
20.20,141.05,0.355
20.22,141.23,0.355
20.24,141.41,0.355
20.26,141.60,0.355
20.28,141.78,0.355
20.29,141.96,0.355
20.31,142.15,0.355
20.33,142.33,0.355
20.35,142.52,0.355
20.37,142.70,0.355
20.39,142.88,0.355
20.41,143.06,0.355
20.42,143.25,0.355
20.44,143.43,0.355
20.46,143.62,0.355
20.48,143.80,0.355
20.50,143.98,0.355
20.52,144.17,0.355
20.53,144.35,0.355
20.55,144.53,0.355
20.57,144.72,0.355
20.59,144.90,0.355
20.61,145.08,0.355
20.63,145.27,0.355
20.64,145.45,0.355
20.66,145.63,0.355
20.68,145.82,0.355
20.70,146.00,0.355
20.72,146.18,0.355
20.73,146.37,0.355
20.75,146.55,0.354
20.77,146.74,0.354
20.79,146.92,0.354
20.81,147.10,0.354
20.83,147.29,0.354
20.84,147.47,0.354
20.86,147.65,0.354
20.88,147.84,0.354
20.90,148.02,0.353
20.92,148.20,0.353
20.94,148.39,0.353
20.96,148.57,0.353
20.97,148.75,0.353
20.99,148.94,0.352
21.01,149.12,0.352
21.03,149.30,0.352
21.05,149.49,0.352
21.07,149.67,0.352
21.08,149.85,0.351
21.10,150.04,0.351
21.12,150.22,0.351
21.14,150.41,0.350
21.16,150.59,0.350
21.18,150.77,0.350
21.19,150.96,0.350
21.21,151.14,0.349
21.23,151.32,0.349
21.25,151.51,0.349
21.27,151.69,0.349
21.28,151.87,0.348
21.30,152.06,0.348
21.32,152.24,0.348
21.34,152.42,0.348
21.36,152.61,0.348
21.38,152.79,0.348
21.39,152.97,0.347
21.41,153.16,0.347
21.43,153.34,0.347
21.45,153.52,0.347
21.47,153.71,0.347
21.49,153.89,0.346
21.51,154.07,0.346
21.52,154.26,0.346
21.54,154.44,0.346
21.56,154.62,0.346
21.58,154.81,0.346
21.60,154.99,0.345
21.62,155.17,0.345
21.63,155.36,0.345
21.65,155.54,0.345
21.67,155.73,0.345
21.69,155.91,0.345
21.71,156.09,0.345
21.73,156.28,0.345
21.74,156.46,0.345
21.76,156.64,0.345
21.78,156.83,0.345
21.80,157.01,0.345
21.82,157.19,0.345
21.83,157.38,0.344
21.85,157.56,0.344
21.87,157.75,0.344
21.89,157.93,0.344
21.91,158.11,0.344
21.93,158.29,0.344
21.94,158.48,0.344
21.96,158.66,0.344
21.98,158.84,0.344
22.00,159.03,0.344
22.02,159.21,0.344
22.04,159.39,0.344
22.06,159.58,0.344
22.07,159.76,0.344
22.09,159.95,0.344
22.11,160.13,0.344
22.13,160.31,0.344
22.15,160.50,0.344
22.17,160.68,0.344
22.18,160.86,0.344
22.20,161.05,0.344
22.22,161.23,0.344
22.24,161.41,0.344
22.26,161.60,0.344
22.28,161.78,0.344
22.29,161.96,0.344
22.31,162.15,0.344
22.33,162.33,0.344
22.35,162.51,0.344
22.37,162.70,0.344
22.38,162.88,0.344
22.40,163.06,0.344
22.42,163.25,0.344
22.44,163.43,0.344
22.46,163.61,0.344
22.48,163.80,0.344
22.49,163.98,0.344
22.51,164.16,0.344
22.53,164.35,0.344
22.55,164.53,0.344
22.57,164.71,0.344
22.59,164.90,0.344
22.61,165.08,0.344
22.62,165.27,0.344
22.64,165.45,0.344
22.66,165.63,0.344
22.68,165.82,0.344
22.70,166.00,0.344
22.72,166.18,0.344
22.73,166.37,0.344
22.75,166.55,0.344
22.77,166.73,0.344
22.79,166.92,0.344
22.81,167.10,0.344
22.83,167.28,0.344
22.84,167.47,0.344
22.86,167.65,0.344
22.88,167.83,0.344
22.90,168.02,0.344
22.92,168.20,0.344
22.93,168.38,0.344
22.95,168.57,0.344
22.97,168.75,0.345
22.99,168.93,0.345
23.01,169.12,0.345
23.03,169.30,0.345
23.04,169.48,0.345
23.06,169.67,0.345
23.08,169.85,0.345
23.10,170.03,0.345
23.12,170.22,0.345
23.14,170.40,0.345
23.16,170.58,0.345
23.17,170.77,0.345
23.19,170.95,0.345
23.21,171.14,0.345
23.23,171.32,0.345
23.25,171.50,0.345
23.27,171.69,0.345
23.28,171.87,0.345
23.30,172.05,0.345
23.32,172.24,0.345
23.34,172.42,0.345
23.36,172.60,0.345
23.38,172.79,0.345
23.39,172.97,0.345
23.41,173.15,0.345
23.43,173.34,0.346
23.45,173.52,0.346
23.47,173.70,0.346
23.48,173.89,0.346
23.50,174.07,0.346
23.52,174.25,0.346
23.54,174.44,0.346
23.56,174.62,0.346
23.58,174.80,0.346
23.59,174.99,0.346
23.61,175.17,0.346
23.63,175.35,0.346
23.65,175.54,0.346
23.67,175.72,0.346
23.69,175.91,0.346
23.71,176.09,0.347
23.72,176.27,0.347
23.74,176.45,0.347
23.76,176.64,0.347
23.78,176.82,0.347
23.80,177.01,0.347
23.82,177.19,0.347
23.83,177.37,0.347
23.85,177.56,0.347
23.87,177.74,0.347
23.89,177.92,0.347
23.91,178.10,0.347
23.93,178.29,0.347
23.94,178.47,0.348
23.96,178.66,0.348
23.98,178.84,0.348
24.00,179.02,0.348
24.02,179.21,0.348
24.03,179.39,0.348
24.05,179.57,0.349
24.07,179.76,0.349
24.09,179.94,0.349
24.11,180.12,0.349
24.13,180.31,0.349
24.14,180.49,0.349
24.16,180.67,0.349
24.18,180.86,0.349
24.20,181.04,0.349
24.22,181.22,0.350
24.24,181.41,0.350
24.26,181.59,0.350
24.27,181.77,0.350
24.29,181.96,0.350
24.31,182.14,0.350
24.33,182.32,0.350
24.35,182.51,0.350
24.37,182.69,0.351
24.38,182.87,0.351
24.40,183.06,0.351
24.42,183.24,0.351
24.44,183.42,0.351
24.46,183.61,0.351
24.48,183.79,0.352
24.49,183.98,0.352
24.51,184.16,0.352
24.53,184.34,0.352
24.55,184.53,0.352
24.57,184.71,0.352
24.58,184.89,0.353
24.60,185.08,0.353
24.62,185.26,0.353
24.64,185.44,0.353
24.66,185.63,0.353
24.68,185.81,0.353
24.69,185.99,0.354
24.71,186.18,0.354
24.73,186.36,0.354
24.75,186.54,0.354
24.77,186.73,0.354
24.79,186.91,0.354
24.81,187.09,0.355
24.82,187.28,0.355
24.84,187.46,0.355
24.86,187.64,0.355
24.88,187.83,0.355
24.90,188.01,0.355
24.92,188.19,0.356
24.93,188.38,0.356
24.95,188.56,0.356
24.97,188.75,0.356
24.99,188.93,0.357
25.01,189.11,0.357
25.03,189.30,0.357
25.04,189.48,0.357
25.06,189.66,0.357
25.08,189.84,0.358
25.10,190.03,0.358
25.12,190.21,0.358
25.13,190.39,0.358
25.15,190.58,0.358
25.17,190.76,0.358
25.19,190.95,0.359
25.21,191.13,0.359
25.23,191.31,0.359
25.24,191.49,0.359
25.26,191.68,0.359
25.28,191.86,0.359
25.30,192.05,0.360
25.32,192.23,0.360
25.34,192.41,0.360
25.36,192.60,0.360
25.37,192.78,0.360
25.39,192.96,0.360
25.41,193.14,0.360
25.43,193.33,0.361
25.45,193.51,0.361
25.47,193.70,0.361
25.48,193.88,0.361
25.50,194.06,0.361
25.52,194.25,0.362
25.54,194.43,0.362
25.56,194.61,0.362
25.58,194.80,0.362
25.59,194.98,0.362
25.61,195.16,0.363
25.63,195.35,0.363
25.65,195.53,0.363
25.67,195.71,0.363
25.68,195.90,0.363
25.70,196.08,0.364
25.72,196.26,0.364
25.74,196.45,0.364
25.76,196.63,0.364
25.78,196.82,0.364
25.79,197.00,0.364
25.81,197.18,0.365
25.83,197.37,0.365
25.85,197.55,0.365
25.87,197.73,0.365
25.89,197.92,0.365
25.91,198.10,0.365
25.92,198.28,0.365
25.94,198.46,
25.96,198.65,
25.98,198.83,
25.99,,

[step]
Ramp 10.00 °C/min to -60.00 °C
Time,Temperature,Heat Flow (Normalized)
min,°C,W/g
26.99,200.14,-0.053
27.01,200.14,-0.053
27.03,200.14,-0.053
27.05,200.12,-0.059
27.07,200.09,-0.092
27.08,200.04,-0.134
27.10,199.96,-0.190
27.12,199.85,-0.250
27.14,199.72,-0.305
27.16,199.57,-0.351
27.18,199.41,-0.388
27.19,199.24,-0.412
27.21,199.07,-0.432
27.23,198.90,-0.441
27.25,198.72,-0.447
27.27,198.54,-0.452
27.29,198.36,-0.455
27.31,198.18,-0.458
27.32,198.00,-0.459
27.34,197.82,-0.461
27.36,197.64,-0.462
27.38,197.46,-0.463
27.40,197.28,-0.464
27.42,197.10,-0.465
27.43,196.92,-0.465
27.45,196.74,-0.465
27.47,196.55,-0.465
27.49,196.37,-0.466
27.51,196.19,-0.466
27.53,196.01,-0.466
27.54,195.83,-0.466
27.56,195.65,-0.467
27.58,195.46,-0.467
27.60,195.28,-0.467
27.62,195.10,-0.467
27.63,194.92,-0.468
27.65,194.74,-0.468
27.67,194.55,-0.468
27.69,194.37,-0.468
27.71,194.19,-0.468
27.73,194.01,-0.469
27.74,193.83,-0.469
27.76,193.64,-0.469
27.78,193.46,-0.469
27.80,193.28,-0.469
27.82,193.10,-0.469
27.84,192.91,-0.469
27.86,192.73,-0.469
27.87,192.55,-0.469
27.89,192.37,-0.470
27.91,192.19,-0.470
27.93,192.00,-0.470
27.95,191.82,-0.470
27.97,191.64,-0.470
27.98,191.46,-0.470
28.00,191.27,-0.470
28.02,191.09,-0.470
28.04,190.91,-0.470
28.06,190.72,-0.470
28.08,190.54,-0.470
28.09,190.36,-0.470
28.11,190.18,-0.470
28.13,189.99,-0.470
28.15,189.81,-0.470
28.17,189.63,-0.470
28.18,189.45,-0.469
28.20,189.26,-0.469
28.22,189.08,-0.469
28.24,188.90,-0.469
28.26,188.71,-0.469
28.28,188.53,-0.469
28.29,188.35,-0.469
28.31,188.17,-0.469
28.33,187.98,-0.469
28.35,187.80,-0.469
28.37,187.62,-0.469
28.39,187.43,-0.468
28.41,187.25,-0.468
28.42,187.07,-0.468
28.44,186.89,-0.468
28.46,186.70,-0.468
28.48,186.52,-0.468
28.50,186.34,-0.468
28.52,186.15,-0.468
28.53,185.97,-0.468
28.55,185.79,-0.468
28.57,185.60,-0.468
28.59,185.42,-0.467
28.61,185.24,-0.467
28.63,185.05,-0.467
28.64,184.87,-0.467
28.66,184.69,-0.467
28.68,184.50,-0.467
28.70,184.32,-0.467
28.72,184.14,-0.467
28.73,183.95,-0.466
28.75,183.77,-0.466
28.77,183.59,-0.466
28.79,183.40,-0.466
28.81,183.22,-0.466
28.83,183.04,-0.466
28.84,182.85,-0.466
28.86,182.67,-0.466
28.88,182.49,-0.465
28.90,182.30,-0.465
28.92,182.12,-0.465
28.94,181.94,-0.465
28.96,181.76,-0.465
28.97,181.57,-0.465
28.99,181.39,-0.464
29.01,181.21,-0.464
29.03,181.02,-0.464
29.05,180.84,-0.464
29.07,180.66,-0.464
29.08,180.47,-0.464
29.10,180.29,-0.464
29.12,180.11,-0.463
29.14,179.92,-0.463
29.16,179.74,-0.463
29.18,179.56,-0.463
29.19,179.37,-0.463
29.21,179.19,-0.463
29.23,179.01,-0.463
29.25,178.82,-0.462
29.27,178.64,-0.462
29.28,178.46,-0.462
29.30,178.27,-0.462
29.32,178.09,-0.462
29.34,177.91,-0.462
29.36,177.72,-0.462
29.38,177.54,-0.462
29.39,177.36,-0.461
29.41,177.17,-0.461
29.43,176.99,-0.461
29.45,176.81,-0.461
29.47,176.63,-0.461
29.49,176.44,-0.461
29.51,176.26,-0.461
29.52,176.08,-0.460
29.54,175.89,-0.460
29.56,175.71,-0.460
29.58,175.52,-0.460
29.60,175.34,-0.460
29.62,175.16,-0.460
29.63,174.98,-0.460
29.65,174.79,-0.460
29.67,174.61,-0.459
29.69,174.43,-0.459
29.71,174.24,-0.459
29.73,174.06,-0.459
29.74,173.88,-0.459
29.76,173.69,-0.459
29.78,173.51,-0.459
29.80,173.33,-0.458
29.82,173.14,-0.458
29.83,172.96,-0.458
29.85,172.78,-0.458
29.87,172.59,-0.458
29.89,172.41,-0.458
29.91,172.23,-0.457
29.93,172.04,-0.457
29.94,171.86,-0.457
29.96,171.68,-0.457
29.98,171.49,-0.457
30.00,171.31,-0.457
30.02,171.13,-0.457
30.04,170.95,-0.456
30.06,170.76,-0.456
30.07,170.58,-0.456
30.09,170.39,-0.456
30.11,170.21,-0.456
30.13,170.03,-0.456
30.15,169.84,-0.456
30.17,169.66,-0.456
30.18,169.48,-0.456
30.20,169.29,-0.456
30.22,169.11,-0.456
30.24,168.93,-0.455
30.26,168.74,-0.455
30.28,168.56,-0.455
30.29,168.38,-0.455
30.31,168.20,-0.455
30.33,168.01,-0.455
30.35,167.83,-0.455
30.37,167.64,-0.455
30.38,167.46,-0.455
30.40,167.28,-0.454
30.42,167.10,-0.454
30.44,166.91,-0.454
30.46,166.73,-0.454
30.48,166.55,-0.454
30.49,166.36,-0.454
30.51,166.18,-0.454
30.53,166.00,-0.454
30.55,165.81,-0.454
30.57,165.63,-0.454
30.59,165.45,-0.453
30.61,165.26,-0.453
30.62,165.08,-0.453
30.64,164.90,-0.453
30.66,164.71,-0.453
30.68,164.53,-0.453
30.70,164.35,-0.453
30.72,164.16,-0.453
30.73,163.98,-0.453
30.75,163.80,-0.452
30.77,163.61,-0.452
30.79,163.43,-0.452
30.81,163.25,-0.452
30.83,163.06,-0.452
30.84,162.88,-0.452
30.86,162.70,-0.452
30.88,162.52,-0.452
30.90,162.33,-0.452
30.92,162.15,-0.452
30.93,161.96,-0.451
30.95,161.78,-0.451
30.97,161.60,-0.451
30.99,161.41,-0.451
31.01,161.23,-0.451
31.03,161.05,-0.451
31.04,160.87,-0.451
31.06,160.68,-0.451
31.08,160.50,-0.451
31.10,160.31,-0.450
31.12,160.13,-0.450
31.14,159.95,-0.450
31.16,159.76,-0.450
31.17,159.58,-0.450
31.19,159.40,-0.450
31.21,159.21,-0.450
31.23,159.03,-0.450
31.25,158.85,-0.450
31.27,158.66,-0.450
31.28,158.48,-0.449
31.30,158.30,-0.449
31.32,158.11,-0.449
31.34,157.93,-0.449
31.36,157.75,-0.449
31.38,157.57,-0.449
31.39,157.38,-0.449
31.41,157.20,-0.449
31.43,157.01,-0.448
31.45,156.83,-0.448
31.47,156.65,-0.448
31.48,156.47,-0.448
31.50,156.28,-0.448
31.52,156.10,-0.448
31.54,155.92,-0.448
31.56,155.73,-0.448
31.58,155.55,-0.448
31.59,155.37,-0.448
31.61,155.18,-0.447
31.63,155.00,-0.447
31.65,154.82,-0.447
31.67,154.63,-0.447
31.69,154.45,-0.447
31.71,154.26,-0.447
31.72,154.08,-0.447
31.74,153.90,-0.446
31.76,153.72,-0.446
31.78,153.53,-0.446
31.80,153.35,-0.446
31.82,153.17,-0.446
31.83,152.98,-0.446
31.85,152.80,-0.446
31.87,152.62,-0.446
31.89,152.43,-0.446
31.91,152.25,-0.445
31.93,152.07,-0.445
31.94,151.88,-0.445
31.96,151.70,-0.445
31.98,151.52,-0.445
32.00,151.33,-0.445
32.02,151.15,-0.445
32.03,150.97,-0.445
32.05,150.78,-0.445
32.07,150.60,-0.445
32.09,150.42,-0.444
32.11,150.23,-0.444
32.13,150.05,-0.444
32.14,149.87,-0.444
32.16,149.68,-0.444
32.18,149.50,-0.444
32.20,149.32,-0.443
32.22,149.13,-0.443
32.24,148.95,-0.443
32.26,148.77,-0.443
32.27,148.58,-0.443
32.29,148.40,-0.442
32.31,148.22,-0.442
32.33,148.03,-0.442
32.35,147.85,-0.442
32.37,147.67,-0.442
32.38,147.49,-0.441
32.40,147.30,-0.441
32.42,147.12,-0.441
32.44,146.93,-0.441
32.46,146.75,-0.441
32.48,146.57,-0.441
32.49,146.38,-0.441
32.51,146.20,-0.440
32.53,146.02,-0.440
32.55,145.84,-0.440
32.57,145.65,-0.440
32.58,145.47,-0.439
32.60,145.28,-0.439
32.62,145.10,-0.439
32.64,144.92,-0.439
32.66,144.73,-0.439
32.68,144.55,-0.438
32.69,144.37,-0.438
32.71,144.18,-0.438
32.73,144.00,-0.438
32.75,143.82,-0.437
32.77,143.63,-0.437
32.79,143.45,-0.437
32.81,143.27,-0.436
32.82,143.09,-0.436
32.84,142.90,-0.436
32.86,142.72,-0.436
32.88,142.53,-0.435
32.90,142.35,-0.435
32.92,142.17,-0.435
32.93,141.98,-0.434
32.95,141.80,-0.434
32.97,141.62,-0.434
32.99,141.43,-0.433
33.01,141.25,-0.433
33.03,141.07,-0.433
33.04,140.88,-0.432
33.06,140.70,-0.432
33.08,140.52,-0.431
33.10,140.34,-0.431
33.12,140.15,-0.431
33.13,139.97,-0.430
33.15,139.78,-0.430
33.17,139.60,-0.430
33.19,139.42,-0.429
33.21,139.23,-0.429
33.23,139.05,-0.428
33.24,138.87,-0.428
33.26,138.69,-0.427
33.28,138.50,-0.427
33.30,138.32,-0.426
33.32,138.13,-0.426
33.34,137.95,-0.426
33.36,137.77,-0.425
33.37,137.58,-0.425
33.39,137.40,-0.424
33.41,137.22,-0.424
33.43,137.04,-0.423
33.45,136.85,-0.423
33.47,136.67,-0.423
33.48,136.49,-0.422
33.50,136.30,-0.422
33.52,136.12,-0.421
33.54,135.93,-0.421
33.56,135.75,-0.420
33.58,135.57,-0.420
33.59,135.38,-0.420
33.61,135.20,-0.419
33.63,135.02,-0.419
33.65,134.83,-0.418
33.67,134.65,-0.418
33.68,134.47,-0.417
33.70,134.28,-0.417
33.72,134.10,-0.416
33.74,133.92,-0.416
33.76,133.73,-0.415
33.78,133.55,-0.415
33.79,133.37,-0.414
33.81,133.18,-0.414
33.83,133.00,-0.413
33.85,132.82,-0.413
33.87,132.63,-0.412
33.89,132.45,-0.412
33.91,132.27,-0.411
33.92,132.08,-0.411
33.94,131.90,-0.411
33.96,131.71,-0.410
33.98,131.53,-0.410
34.00,131.35,-0.409
34.02,131.17,-0.409
34.03,130.98,-0.408
34.05,130.80,-0.408
34.07,130.62,-0.407
34.09,130.43,-0.407
34.11,130.25,-0.406
34.13,130.07,-0.406
34.14,129.88,-0.406
34.16,129.70,-0.405
34.18,129.52,-0.405
34.20,129.33,-0.404
34.22,129.15,-0.404
34.24,128.97,-0.404
34.25,128.78,-0.403
34.27,128.60,-0.403
34.29,128.42,-0.402
[...]
115.21,11.05,0.211
115.23,11.23,0.211
115.25,11.41,0.211
115.27,11.60,0.211
115.29,11.78,0.211
115.31,11.97,0.211
115.33,12.15,0.211
115.34,12.33,0.211
115.36,12.52,0.211
115.38,12.70,0.211
115.40,12.88,0.212
115.42,13.06,0.212
115.44,13.25,0.212
115.45,13.43,0.212
115.47,13.61,0.212
115.49,13.80,0.212
115.51,13.98,0.212
115.53,14.17,0.212
115.55,14.35,0.212
115.56,14.53,0.212
115.58,14.72,0.212
115.60,14.90,0.213
115.62,15.08,0.213
115.64,15.27,0.213
115.65,15.45,0.213
115.67,15.63,0.213
115.69,15.82,0.213
115.71,16.00,0.213
115.73,16.19,0.213
115.75,16.37,0.213
115.76,16.55,0.214
115.78,16.74,0.214
115.80,16.92,0.214
115.82,17.10,0.214
115.84,17.29,0.214
115.86,17.47,0.214
115.88,17.65,0.214
115.89,17.84,0.214
115.91,18.02,0.214
115.93,18.20,0.214
115.95,18.39,0.215
115.97,18.57,0.215
115.99,18.75,0.215
116.00,18.94,0.215
116.02,19.12,0.215
116.04,19.30,0.215
116.06,19.49,0.215
116.08,19.67,0.215
116.10,19.85,0.215
116.11,20.04,0.215
116.13,20.22,0.216
116.15,20.40,0.216
116.17,20.59,0.216
116.19,20.77,0.216
116.20,20.96,0.216
116.22,21.14,0.216
116.24,21.32,0.216
116.26,21.51,0.216
116.28,21.69,0.216
116.30,21.87,0.217
116.31,22.06,0.217
116.33,22.24,0.217
116.35,22.42,0.217
116.37,22.61,0.217
116.39,22.79,0.217
116.41,22.97,0.217
116.43,23.16,0.217
116.44,23.34,0.217
116.46,23.52,0.217
116.48,23.71,0.217
116.50,23.89,0.218
116.52,24.07,0.218
116.54,24.26,0.218
116.55,24.44,0.218
116.57,24.63,0.218
116.59,24.81,0.218
116.61,24.99,0.218
116.63,25.18,0.218
116.65,25.36,0.219
116.66,25.54,0.219
116.68,25.73,0.219
116.70,25.91,0.219
116.72,26.09,0.219
116.74,26.28,0.219
116.75,26.46,0.219
116.77,26.64,0.219
116.79,26.83,0.219
116.81,27.01,0.219
116.83,27.20,0.220
116.85,27.38,0.220
116.86,27.56,0.220
116.88,27.75,0.220
116.90,27.93,0.220
116.92,28.11,0.220
116.94,28.30,0.220
116.96,28.48,0.220
116.98,28.66,0.220
116.99,28.85,0.220
117.01,29.03,0.221
117.03,29.21,0.221
117.05,29.40,0.221
117.07,29.58,0.221
117.09,29.76,0.221
117.10,29.95,0.221
117.12,30.13,0.221
117.14,30.31,0.221
117.16,30.50,0.221
117.18,30.68,0.222
117.20,30.86,0.222
117.21,31.05,0.222
117.23,31.23,0.222
117.25,31.41,0.222
117.27,31.60,0.222
117.29,31.78,0.222
117.30,31.96,0.222
117.32,32.15,0.222
117.34,32.33,0.223
117.36,32.52,0.223
117.38,32.70,0.223
117.40,32.88,0.223
117.41,33.07,0.223
117.43,33.25,0.223
117.45,33.43,0.223
117.47,33.62,0.223
117.49,33.80,0.223
117.51,33.98,0.223
117.53,34.17,0.223
117.54,34.35,0.224
117.56,34.53,0.224
117.58,34.72,0.224
117.60,34.90,0.224
117.62,35.08,0.224
117.64,35.27,0.224
117.65,35.45,0.224
117.67,35.64,0.224
117.69,35.82,0.224
117.71,36.00,0.225
117.73,36.19,0.225
117.75,36.37,0.225
117.76,36.55,0.225
117.78,36.74,0.225
117.80,36.92,0.225
117.82,37.10,0.225
117.84,37.29,0.225
117.85,37.47,0.225
117.87,37.66,0.226
117.89,37.84,0.226
117.91,38.02,0.226
117.93,38.21,0.226
117.95,38.39,0.226
117.96,38.57,0.226
117.98,38.75,0.226
118.00,38.94,0.226
118.02,39.12,0.226
118.04,39.31,0.227
118.06,39.49,0.227
118.08,39.67,0.227
118.09,39.86,0.227
118.11,40.04,0.227
118.13,40.22,0.227
118.15,40.41,0.227
118.17,40.59,0.227
118.19,40.77,0.227
118.20,40.96,0.228
118.22,41.14,0.228
118.24,41.32,0.228
118.26,41.51,0.228
118.28,41.69,0.228
118.30,41.88,0.228
118.31,42.06,0.228
118.33,42.24,0.228
118.35,42.43,0.228
118.37,42.61,0.228
118.39,42.79,0.229
118.40,42.98,0.229
118.42,43.16,0.229
118.44,43.34,0.229
118.46,43.53,0.229
118.48,43.71,0.229
118.50,43.89,0.229
118.51,44.08,0.229
118.53,44.26,0.230
118.55,44.44,0.230
118.57,44.63,0.230
118.59,44.81,0.230
118.61,44.99,0.230
118.63,45.18,0.230
118.64,45.36,0.230
118.66,45.54,0.230
118.68,45.73,0.230
118.70,45.91,0.231
118.72,46.10,0.231
118.74,46.28,0.231
118.75,46.46,0.231
118.77,46.65,0.231
118.79,46.83,0.231
118.81,47.01,0.231
118.83,47.20,0.231
118.85,47.38,0.231
118.86,47.56,0.232
118.88,47.75,0.232
118.90,47.93,0.232
118.92,48.11,0.232
118.94,48.30,0.232
118.95,48.48,0.232
118.97,48.66,0.232
118.99,48.85,0.232
119.01,49.03,0.233
119.03,49.21,0.233
119.05,49.40,0.233
119.06,49.58,0.233
119.08,49.77,0.233
119.10,49.95,0.233
119.12,50.13,0.233
119.14,50.31,0.233
119.16,50.50,0.234
119.18,50.68,0.234
119.19,50.87,0.234
119.21,51.05,0.234
119.23,51.23,0.234
119.25,51.42,0.234
119.27,51.60,0.234
119.29,51.78,0.235
119.30,51.97,0.235
119.32,52.15,0.235
119.34,52.33,0.235
119.36,52.52,0.235
119.38,52.70,0.235
119.40,52.88,0.235
119.41,53.07,0.235
119.43,53.25,0.235
119.45,53.43,0.236
119.47,53.62,0.236
119.49,53.80,0.236
119.50,53.99,0.236
119.52,54.17,0.236
119.54,54.35,0.236
119.56,54.54,0.236
119.58,54.72,0.236
119.60,54.90,0.236
119.61,55.09,0.236
119.63,55.27,0.237
119.65,55.45,0.237
119.67,55.64,0.237
119.69,55.82,0.237
119.71,56.00,0.237
119.73,56.19,0.237
119.74,56.37,0.237
119.76,56.55,0.237
119.78,56.74,0.237
119.80,56.92,0.237
119.82,57.10,0.238
119.84,57.29,0.238
119.85,57.47,0.238
119.87,57.66,0.238
119.89,57.84,0.238
119.91,58.02,0.238
119.93,58.21,0.238
119.95,58.39,0.238
119.96,58.57,0.239
119.98,58.76,0.239
120.00,58.94,0.239
120.02,59.12,0.239
120.04,59.31,0.239
120.05,59.49,0.239
120.07,59.67,0.239
120.09,59.86,0.239
120.11,60.04,0.239
120.13,60.23,0.239
120.15,60.41,0.240
120.16,60.59,0.240
120.18,60.78,0.240
120.20,60.96,0.240
120.22,61.14,0.240
120.24,61.33,0.240
120.26,61.51,0.240
120.28,61.69,0.240
120.29,61.88,0.240
120.31,62.06,0.241
120.33,62.24,0.241
120.35,62.43,0.241
120.37,62.61,0.241
120.39,62.79,0.241
120.40,62.98,0.241
120.42,63.16,0.241
120.44,63.34,0.241
120.46,63.53,0.242
120.48,63.71,0.242
120.50,63.89,0.242
120.51,64.08,0.242
120.53,64.26,0.242
120.55,64.44,0.242
120.57,64.63,0.242
120.59,64.81,0.242
120.60,64.99,0.242
120.62,65.18,0.242
120.64,65.36,0.243
120.66,65.54,0.243
120.68,65.73,0.243
120.70,65.91,0.243
120.71,66.09,0.243
120.73,66.28,0.243
120.75,66.46,0.243
120.77,66.65,0.243
120.79,66.83,0.243
120.81,67.01,0.244
120.83,67.20,0.244
120.84,67.38,0.244
120.86,67.56,0.244
120.88,67.75,0.244
120.90,67.93,0.244
120.92,68.11,0.244
120.94,68.30,0.244
120.95,68.48,0.244
120.97,68.66,0.244
120.99,68.85,0.245
121.01,69.03,0.245
121.03,69.21,0.245
121.05,69.40,0.245
121.06,69.58,0.245
121.08,69.76,0.245
121.10,69.95,0.245
121.12,70.13,0.245
121.14,70.32,0.245
121.15,70.50,0.246
121.17,70.68,0.246
121.19,70.87,0.246
121.21,71.05,0.246
121.23,71.23,0.246
121.25,71.42,0.246
121.26,71.60,0.246
121.28,71.78,0.246
121.30,71.97,0.247
121.32,72.15,0.247
121.34,72.33,0.247
121.36,72.52,0.247
121.38,72.70,0.247
121.39,72.88,0.247
121.41,73.07,0.247
121.43,73.25,0.247
121.45,73.43,0.248
121.47,73.62,0.248
121.49,73.80,0.248
121.50,73.98,0.248
121.52,74.17,0.248
121.54,74.35,0.248
121.56,74.54,0.248
121.58,74.72,0.249
121.60,74.90,0.249
121.61,75.09,0.249
121.63,75.27,0.249
121.65,75.45,0.249
121.67,75.64,0.249
121.69,75.82,0.249
121.70,76.00,0.249
121.72,76.19,0.250
121.74,76.37,0.250
121.76,76.55,0.250
121.78,76.74,0.250
121.80,76.92,0.250
121.81,77.10,0.250
121.83,77.29,0.250
121.85,77.47,0.250
121.87,77.65,0.250
121.89,77.84,0.251
121.91,78.02,0.251
121.93,78.20,0.251
121.94,78.39,0.251
121.96,78.57,0.251
121.98,78.75,0.251
122.00,78.94,0.251
122.02,79.12,0.251
122.04,79.30,0.252
122.05,79.49,0.252
122.07,79.67,0.252
122.09,79.86,0.252
122.11,80.04,0.252
122.13,80.22,0.252
122.15,80.41,0.252
122.16,80.59,0.252
122.18,80.77,0.252
122.20,80.96,0.253
122.22,81.14,0.253
122.24,81.32,0.253
122.25,81.51,0.253
122.27,81.69,0.253
122.29,81.87,0.253
122.31,82.06,0.253
122.33,82.24,0.253
122.35,82.42,0.253
122.36,82.61,0.253
122.38,82.79,0.254
122.40,82.97,0.254
122.42,83.16,0.254
122.44,83.34,0.254
122.46,83.53,0.254
122.48,83.71,0.254
122.49,83.89,0.254
122.51,84.08,0.254
122.53,84.26,0.254
122.55,84.44,0.255
122.57,84.63,0.255
122.59,84.81,0.255
122.60,84.99,0.255
122.62,85.18,0.255
122.64,85.36,0.255
122.66,85.54,0.255
122.68,85.73,0.255
122.70,85.91,0.255
122.71,86.09,0.255
122.73,86.28,0.256
122.75,86.46,0.256
122.77,86.64,0.256
122.79,86.83,0.256
122.80,87.01,0.256
122.82,87.19,0.256
122.84,87.38,0.256
122.86,87.56,0.256
122.88,87.75,0.256
122.90,87.93,0.256
122.91,88.11,0.256
122.93,88.30,0.257
122.95,88.48,0.257
122.97,88.66,0.257
122.99,88.85,0.257
123.01,89.03,0.257
123.03,89.21,0.257
123.04,89.40,0.257
123.06,89.58,0.257
123.08,89.76,0.258
123.10,89.95,0.258
123.12,90.13,0.258
123.14,90.31,0.258
123.15,90.50,0.258
123.17,90.68,0.258
123.19,90.86,0.258
123.21,91.05,0.258
123.23,91.23,0.259
123.25,91.42,0.259
123.26,91.60,0.259
123.28,91.78,0.259
123.30,91.96,0.259
123.32,92.15,0.259
123.34,92.33,0.259
123.35,92.51,0.259
123.37,92.70,0.259
123.39,92.88,0.260
123.41,93.06,0.260
123.43,93.25,0.260
123.45,93.43,0.260
123.46,93.62,0.260
123.48,93.80,0.260
123.50,93.98,0.260
123.52,94.17,0.260
123.54,94.35,0.261
123.56,94.53,0.261
123.58,94.72,0.261
123.59,94.90,0.261
123.61,95.09,0.261
123.63,95.27,0.261
123.65,95.45,0.262
123.67,95.64,0.262
123.69,95.82,0.262
123.70,96.00,0.262
123.72,96.19,0.262
123.74,96.37,0.262
123.76,96.55,0.262
123.78,96.74,0.262
123.80,96.92,0.263
123.81,97.11,0.263
123.83,97.29,0.263
123.85,97.47,0.263
123.87,97.66,0.263
123.89,97.84,0.263
123.90,98.02,0.263
123.92,98.21,0.263
123.94,98.39,0.263
123.96,98.57,0.263
123.98,98.76,0.263
124.00,98.94,0.263
124.01,99.12,0.263
124.03,99.31,0.263
124.05,99.49,0.264
124.07,99.67,0.264
124.09,99.86,0.264
124.11,100.04,0.264
124.13,100.22,0.264
124.14,100.41,0.264
124.16,100.59,0.264
124.18,100.77,0.264
124.20,100.96,0.264
124.22,101.14,0.264
124.24,101.32,0.264
124.25,101.51,0.264
124.27,101.69,0.265
124.29,101.88,0.265
124.31,102.06,0.265
124.33,102.24,0.265
124.35,102.42,0.265
124.36,102.61,0.265
124.38,102.79,0.265
124.40,102.97,0.265
124.42,103.16,0.265
124.44,103.34,0.265
124.45,103.52,0.266
124.47,103.71,0.266
124.49,103.89,0.266
124.51,104.07,0.266
124.53,104.26,0.266
124.55,104.44,0.266
124.56,104.62,0.266
124.58,104.81,0.266
124.60,104.99,0.267
124.62,105.18,0.267
124.64,105.36,0.267
124.66,105.54,0.267
124.68,105.73,0.267
124.69,105.91,0.267
124.71,106.09,0.267
124.73,106.28,0.268
124.75,106.46,0.268
124.77,106.64,0.268
124.79,106.83,0.268
124.80,107.01,0.268
124.82,107.19,0.268
124.84,107.38,0.268
124.86,107.56,0.268
124.88,107.74,0.269
124.90,107.93,0.269
124.91,108.11,0.269
124.93,108.30,0.269
124.95,108.48,0.269
124.97,108.66,0.269
124.99,108.85,0.269
125.00,109.03,0.270
125.02,109.21,0.270
125.04,109.40,0.270
125.06,109.58,0.270
125.08,109.76,0.270
125.10,109.95,0.270
125.11,110.13,0.270
125.13,110.31,0.270
125.15,110.50,0.271
125.17,110.68,0.271
125.19,110.86,0.271
125.21,111.05,0.271
125.23,111.23,0.271
125.24,111.41,0.271
125.26,111.59,0.271
125.28,111.78,0.271
125.30,111.96,0.272
125.32,112.14,0.272
125.34,112.33,0.272
125.35,112.51,0.272
125.37,112.70,0.272
125.39,112.88,0.272
125.41,113.06,0.272
125.43,113.25,0.273
125.45,113.43,0.273
125.46,113.61,0.273
125.48,113.80,0.273
125.50,113.98,0.273
125.52,114.16,0.273
125.54,114.35,0.273
125.55,114.53,0.274
125.57,114.72,0.274
125.59,114.90,0.274
125.61,115.08,0.274
125.63,115.27,0.274
125.65,115.45,0.274
125.66,115.63,0.274
125.68,115.82,0.274
125.70,116.00,0.275
125.72,116.18,0.275
125.74,116.37,0.275
125.76,116.55,0.275
125.78,116.73,0.275
125.79,116.92,0.276
125.81,117.10,0.276
125.83,117.28,0.276
125.85,117.47,0.276
125.87,117.65,0.276
125.89,117.83,0.276
125.90,118.02,0.276
125.92,118.20,0.277
125.94,118.38,0.277
125.96,118.57,0.277
125.98,118.75,0.277
126.00,118.93,0.277
126.01,119.12,0.278
126.03,119.30,0.278
126.05,119.48,0.278
126.07,119.67,0.278
126.09,119.85,0.278
126.10,120.03,0.278
126.12,120.22,0.279
126.14,120.40,0.279
126.16,120.59,0.279
126.18,120.77,0.279
126.20,120.95,0.279
126.21,121.14,0.279
126.23,121.32,0.280
126.25,121.50,0.280
126.27,121.69,0.280
126.29,121.87,0.280
126.31,122.05,0.280
126.33,122.24,0.281
126.34,122.42,0.281
126.36,122.60,0.281
126.38,122.79,0.281
126.40,122.97,0.281
126.42,123.15,0.282
126.44,123.34,0.282
126.45,123.52,0.282
126.47,123.70,0.282
126.49,123.89,0.282
126.51,124.07,0.283
126.53,124.25,0.283
126.55,124.44,0.283
126.56,124.62,0.283
126.58,124.80,0.283
126.60,124.99,0.284
126.62,125.17,0.284
126.64,125.35,0.284
126.65,125.54,0.284
126.67,125.72,0.285
126.69,125.90,0.285
126.71,126.09,0.285
126.73,126.27,0.285
126.75,126.45,0.285
126.76,126.64,0.286
126.78,126.82,0.286
126.80,127.00,0.286
126.82,127.19,0.286
126.84,127.37,0.286
126.86,127.55,0.287
126.88,127.74,0.287
126.89,127.92,0.287
126.91,128.10,0.287
126.93,128.29,0.288
126.95,128.47,0.288
126.97,128.65,0.288
126.99,128.84,0.288
127.00,129.02,0.289
127.02,129.21,0.289
127.04,129.39,0.289
127.06,129.57,0.290
127.08,129.76,0.290
127.10,129.94,0.290
127.11,130.12,0.291
127.13,130.31,0.291
127.15,130.49,0.291
127.17,130.67,0.291
127.19,130.86,0.292
127.20,131.04,0.292
127.22,131.22,0.292
127.24,131.41,0.293
127.26,131.59,0.293
127.28,131.77,0.293
127.30,131.96,0.294
127.31,132.14,0.294
127.33,132.32,0.294
127.35,132.51,0.295
127.37,132.69,0.295
127.39,132.87,0.295
127.41,133.06,0.296
127.43,133.24,0.296
127.44,133.42,0.297
127.46,133.61,0.297
127.48,133.79,0.298
127.50,133.97,0.298
127.52,134.16,0.299
127.54,134.34,0.299
127.55,134.52,0.300
127.57,134.71,0.300
127.59,134.89,0.300
127.61,135.07,0.301
127.63,135.26,0.302
127.65,135.44,0.302
127.66,135.62,0.303
127.68,135.81,0.303
127.70,135.99,0.304
127.72,136.17,0.304
127.74,136.36,0.305
127.75,136.54,0.305
127.77,136.72,0.306
127.79,136.91,0.307
127.81,137.09,0.307
127.83,137.27,0.308
127.85,137.46,0.309
127.86,137.64,0.309
127.88,137.82,0.310
127.90,138.01,0.311
127.92,138.19,0.311
127.94,138.37,0.312
127.96,138.56,0.313
127.98,138.74,0.314
127.99,138.92,0.314
128.01,139.11,0.315
128.03,139.29,0.316
128.05,139.47,0.317
128.07,139.66,0.317
128.09,139.84,0.318
128.10,140.02,0.319
128.12,140.21,0.320
128.14,140.39,0.320
128.16,140.57,0.321
128.18,140.76,0.322
128.20,140.94,0.323
128.21,141.12,0.324
128.23,141.31,0.325
128.25,141.49,0.325
128.27,141.67,0.326
128.29,141.86,0.327
128.30,142.04,0.328
128.32,142.22,0.329
128.34,142.41,0.329
128.36,142.59,0.330
128.38,142.77,0.331
128.40,142.95,0.331
128.41,143.14,0.332
128.43,143.32,0.333
128.45,143.51,0.334
128.47,143.69,0.335
128.49,143.87,0.335
128.51,144.06,0.336
128.53,144.24,0.337
128.54,144.42,0.337
128.56,144.61,0.338
128.58,144.79,0.338
128.60,144.97,0.339
128.62,145.15,0.339
128.64,145.34,0.340
128.65,145.52,0.340
128.67,145.71,0.341
128.69,145.89,0.341
128.71,146.07,0.342
128.73,146.26,0.342
128.75,146.44,0.343
128.76,146.62,0.343
128.78,146.81,0.343
128.80,146.99,0.343
128.82,147.17,0.344
128.84,147.36,0.344
128.85,147.54,0.344
128.87,147.72,0.344
128.89,147.91,0.345
128.91,148.09,0.345
128.93,148.27,0.345
128.95,148.46,0.345
128.96,148.64,0.345
128.98,148.83,0.345
129.00,149.01,0.345
129.02,149.19,0.345
129.04,149.38,0.345
129.06,149.56,0.345
129.08,149.74,0.345
129.09,149.93,0.345
129.11,150.11,0.345
129.13,150.29,0.345
129.15,150.48,0.345
129.17,150.66,0.345
129.19,150.84,0.345
129.20,151.03,0.345
129.22,151.21,0.345
129.24,151.39,0.345
129.26,151.58,0.346
129.28,151.76,0.346
129.30,151.95,0.346
129.31,152.13,0.346
129.33,152.31,0.346
129.35,152.50,0.346
129.37,152.68,0.345
129.39,152.86,0.345
129.40,153.04,0.345
129.42,153.23,0.345
129.44,153.41,0.345
129.46,153.59,0.345
129.48,153.78,0.345
129.50,153.96,0.345
129.51,154.14,0.345
129.53,154.33,0.345
129.55,154.51,0.345
129.57,154.69,0.345
129.59,154.88,0.345
129.61,155.06,0.346
129.63,155.25,0.346
129.64,155.43,0.346
129.66,155.61,0.346
129.68,155.80,0.346
129.70,155.98,0.346
129.72,156.16,0.346
129.74,156.35,0.346
129.75,156.53,0.346
129.77,156.71,0.346
129.79,156.90,0.346
129.81,157.08,0.346
129.83,157.26,0.346
129.85,157.45,0.346
129.86,157.63,0.346
129.88,157.81,0.346
129.90,158.00,0.346
129.92,158.18,0.346
129.94,158.36,0.346
129.95,158.55,0.346
129.97,158.73,0.346
129.99,158.92,0.346
130.01,159.10,0.346
130.03,159.28,0.347
130.05,159.47,0.347
130.06,159.65,0.347
130.08,159.83,0.347
130.10,160.02,0.347
130.12,160.20,0.347
130.14,160.38,0.347
130.16,160.57,0.347
130.18,160.75,0.347
130.19,160.93,0.347
130.21,161.12,0.347
130.23,161.30,0.347
130.25,161.48,0.347
130.27,161.67,0.347
130.29,161.85,0.347
130.30,162.03,0.347
130.32,162.22,0.348
130.34,162.40,0.348
130.36,162.58,0.348
130.38,162.77,0.348
130.40,162.95,0.348
130.41,163.13,0.348
130.43,163.32,0.348
130.45,163.50,0.348
130.47,163.69,0.349
130.49,163.87,0.349
130.50,164.05,0.349
130.52,164.24,0.349
130.54,164.42,0.349
130.56,164.60,0.349
130.58,164.78,0.349
130.60,164.97,0.349
130.61,165.15,0.349
130.63,165.34,0.349
130.65,165.52,0.349
130.67,165.70,0.349
130.69,165.89,0.349
130.71,166.07,0.349
130.73,166.25,0.350
130.74,166.44,0.350
130.76,166.62,0.350
130.78,166.80,0.350
130.80,166.99,0.350
130.82,167.17,0.350
130.84,167.35,0.350
130.85,167.54,0.350
130.87,167.72,0.350
130.89,167.90,0.350
130.91,168.09,0.350
130.93,168.27,0.350
130.95,168.45,0.351
130.96,168.64,0.351
130.98,168.82,0.351
131.00,169.00,0.351
131.02,169.19,0.351
131.04,169.37,0.351
131.05,169.55,0.351
131.07,169.74,0.351
131.09,169.92,0.351
131.11,170.10,0.351
131.13,170.29,0.352
131.15,170.47,0.352
131.16,170.65,0.352
131.18,170.84,0.352
131.20,171.02,0.352
131.22,171.21,0.352
131.24,171.39,0.352
131.26,171.57,0.352
131.28,171.76,0.352
131.29,171.94,0.353
131.31,172.12,0.353
131.33,172.31,0.353
131.35,172.49,0.353
131.37,172.67,0.353
131.39,172.86,0.353
131.40,173.04,0.353
131.42,173.22,0.353
131.44,173.41,0.353
131.46,173.59,0.353
131.48,173.77,0.354
131.50,173.96,0.354
131.51,174.14,0.354
131.53,174.32,0.354
131.55,174.51,0.354
131.57,174.69,0.354
131.59,174.87,0.354
131.60,175.06,0.354
131.62,175.24,0.354
131.64,175.43,0.355
131.66,175.61,0.355
131.68,175.79,0.355
131.70,175.97,0.355
131.71,176.16,0.355
131.73,176.34,0.355
131.75,176.52,0.355
131.77,176.71,0.355
131.79,176.89,0.355
131.81,177.07,0.355
131.83,177.26,0.355
131.84,177.44,0.356
131.86,177.63,0.356
131.88,177.81,0.356
131.90,177.99,0.356
131.92,178.18,0.356
131.94,178.36,0.356
131.95,178.54,0.356
131.97,178.73,0.356
131.99,178.91,0.356
132.01,179.09,0.356
132.03,179.28,0.356
132.05,179.46,0.357
132.06,179.64,0.357
132.08,179.83,0.357
132.10,180.01,0.357
132.12,180.19,0.357
132.14,180.38,0.357
132.15,180.56,0.357
132.17,180.74,0.357
132.19,180.93,0.357
132.21,181.11,0.357
132.23,181.29,0.357
132.25,181.48,0.357
132.26,181.66,0.357
132.28,181.84,0.358
132.30,182.03,0.358
132.32,182.21,0.358
132.34,182.39,0.358
132.36,182.58,0.358
132.38,182.76,0.358
132.39,182.95,0.358
132.41,183.13,0.358
132.43,183.31,0.358
132.45,183.49,0.358
132.47,183.68,0.358
132.49,183.86,0.358
132.50,184.05,0.359
132.52,184.23,0.359
132.54,184.42,0.359
132.56,184.60,0.359
132.58,184.78,0.359
132.60,184.96,0.359
132.61,185.15,0.359
132.63,185.33,0.360
132.65,185.51,0.360
132.67,185.70,0.360
132.69,185.88,0.360
132.70,186.06,0.360
132.72,186.25,0.360
132.74,186.43,0.360
132.76,186.61,0.360
132.78,186.80,0.360
132.80,186.98,0.360
132.81,187.16,0.360
132.83,187.34,0.360
132.85,187.53,0.360
132.87,187.71,0.360
132.89,187.90,0.361
132.91,188.08,0.361
132.93,188.26,0.361
132.94,188.45,0.361
132.96,188.63,0.361
132.98,188.81,0.361
133.00,189.00,0.361
133.02,189.18,0.362
133.04,189.37,0.362
133.05,189.55,0.362
133.07,189.73,0.362
133.09,189.92,0.362
133.11,190.10,0.362
133.13,190.28,0.362
133.15,190.47,0.362
133.16,190.65,0.363
133.18,190.83,0.363
133.20,191.02,0.363
133.22,191.20,0.363
133.24,191.38,0.363
133.25,191.57,0.363
133.27,191.75,0.363
133.29,191.93,0.363
133.31,192.12,0.363
133.33,192.30,0.363
133.35,192.48,0.364
133.36,192.67,0.364
133.38,192.85,0.364
133.40,193.03,0.364
133.42,193.22,0.364
133.44,193.40,0.364
133.46,193.58,0.364
133.48,193.77,0.364
133.49,193.95,0.364
133.51,194.13,0.365
133.53,194.32,0.365
133.55,194.50,0.365
133.57,194.68,0.365
133.59,194.87,0.365
133.60,195.05,0.365
133.62,195.23,0.365
133.64,195.42,0.365
133.66,195.60,0.365
133.68,195.78,0.365
133.70,195.97,0.366
133.71,196.15,0.366
133.73,196.34,0.366
133.75,196.52,0.366
133.77,196.70,0.366
133.79,196.88,0.366
133.80,197.07,0.366
133.82,197.25,0.366
133.84,197.44,0.366
133.86,197.62,0.366
133.88,197.80,0.366
133.90,197.99,0.366
133.91,198.17,0.367
133.93,198.35,
133.95,198.54,
133.97,198.72,
133.99,,