File: DSC/2025_04_12_Benzoic_Acid_n60C_150C_10Cmin_x3.csv
Filename,2025_04_12_Benzoic_Acid_n60C_150C_10Cmin_x3
Instrument name,DSC2A-00468 (192.168.1.100)
Operator,Yarger
rundate,4/12/2025
Sample name,2025_04_12_Benzoic_Acid_n60C_150C_10Cmin_x3
proceduresegments,Data Off ; Equilibrate -60.00 °C; Data On ; Ramp 10.00 °C/min to 150.00 °C; Data Off ; Isothermal 1.0 min; Data On ; Ramp 10.00 °C/min to -60.00 °C; Data Off ; Isothermal 1.0 min; Data On ; Ramp 10.00 °C/min to 150.00 °C; Data Off ; Isothermal 1.0 min; Data On ; Ramp 10.00 °C/min to -60.00 °C; Data Off ; Isothermal 1.0 min; Data On ; Ramp 10.00 °C/min to 150.00 °C
[File Parameters]
Run date,4/12/2025 10:08:58 PM
Trios version,5.1.1.46572
Original File Name,
Current File Name,D:\DSC2500\JYarger\2025_04_12_Benzoic_Acid_n60C_150C_10Cmin_x3.tri
[Procedure]
Procedure Name,BA_n60_150C_10Cmin_x3
Sample Name,2025_04_12_Benzoic_Acid_n60C_150C_10Cmin_x3
Sample Mass,2.94 mg
Reference Sample Mass,0 mg
Pan Mass,54.23 mg
Pan Number,20
Reference Pan Mass,53.32 mg
Reference Pan Number,10
Pan Type,Tzero Aluminum Hermetic
Comments,Hermetic Sealed Al DSC Consumables Pan/Lids.
Project Name,CA
Operator,Yarger
Test,Custom
Unload Max Temperature,30
Unload Min Temperature,30
Load Max Temperature,30
Load Min Temperature,30
Stop on Gas Flow Error,Yes
[Signal List]
Signal #1,Time (min)
Signal #2,Temperature (°C)
Signal #3,Heat Flow (mW)
Signal #4,Delta T (µV)
Signal #5,Delta Tzero (µV)
Signal #6,Tzero Temperature (°C)
Signal #7,Cell Purge (mL/min)
Signal #8,Heater Temp (°C)
Signal #9,Power Delivered (W)
Signal #10,Reference Junction Temperature (°C)
Signal #11,Flange Temperature (°C)
Signal #12,Heat Flow Phase (rad)
Signal #13,Total Heat Capacity (J/°C)
Signal #14,Heat Capacity (J/°C)
[Configuration]
Company Name,ASU
Instrument Name,DSC2A-00468
Instrument Type,DSC2500
Serial Number,DSC2A-00468
IP,192.168.1.100
Location of Instrument,MRRC
DisplayType,Unknown
Sample Interval ,0.1 s/pt
Selected Heat Flow,T4P
Exotherm Direction,Down
Cell Serial,DRC2-00792
Lid Type,Standard
Cooler,RCS 90
Leave Cooler on at End of Sequence,On
Gas 2,Nitrogen
Gas Selected,Channel 1
Flow Rate,50 mL/min
Secondary Purge,On
Licensed Heat Flow,Heat Flow T4P
Modulation Licensed,Yes
[Versions]
Common IDD Version,1
Cortex Version,VER 2.10.2.31
Driver,5.0.0.6
GDM Version,1.0.3.3
TouchscreenVersion,1.0.0.16145
FEP Version,1.2.1.21
FEP Bootloader,2.0.0.5
AutoSampler Version,2.1.1.26
Auto Sampler Bootloader,2.0.0.5
FCM Version,1.1.0.3
FCM Bootloader,2.0.0.5
[Experiment Logs]
Experiment Log Entry # 1,Data On set to 0
Experiment Log Entry # 3,Equilibrate Segment -60 (C) Started
Experiment Log Entry # 5,Data On set to 1
Experiment Log Entry # 7,Ramp Segment 10 C/min to 150 Started
Experiment Log Entry # 9,Data On set to 0
Experiment Log Entry # 11,Isothermal Segment 1 min started
Experiment Log Entry # 13,Data On set to 1
Experiment Log Entry # 15,Ramp Segment 10 C/min to -60 Started
Experiment Log Entry # 17,Data On set to 0
Experiment Log Entry # 19,Isothermal Segment 1 min started
Experiment Log Entry # 21,Data On set to 1
Experiment Log Entry # 23,Ramp Segment 10 C/min to 150 Started
Experiment Log Entry # 25,Data On set to 0
Experiment Log Entry # 27,Isothermal Segment 1 min started
Experiment Log Entry # 29,Data On set to 1
Experiment Log Entry # 31,Ramp Segment 10 C/min to -60 Started
Experiment Log Entry # 33,Data On set to 0
Experiment Log Entry # 35,Isothermal Segment 1 min started
Experiment Log Entry # 37,Data On set to 1
Experiment Log Entry # 39,Ramp Segment 10 C/min to 150 Started
[Method Log]
Method Log Entry # 1,Data Off
Method Log Entry # 2,Equilibrate -60 °C
Method Log Entry # 3,Data On
Method Log Entry # 4,(Ramp 242577) Ramp 10 °C/minute to 150 °C
Method Log Entry # 5,Data Off
Method Log Entry # 6,Isothermal 1 minutes
Method Log Entry # 7,Data On
Method Log Entry # 8,(Ramp 242581) Ramp 10 °C/minute to -60 °C
Method Log Entry # 9,Data Off
Method Log Entry # 10,Isothermal 1 minutes
Method Log Entry # 11,Data On
Method Log Entry # 12,(Ramp 242585) Ramp 10 °C/minute to 150 °C
Method Log Entry # 13,Data Off
Method Log Entry # 14,Isothermal 1 minutes
Method Log Entry # 15,Data On
Method Log Entry # 16,(Ramp 242589) Ramp 10 °C/minute to -60 °C
Method Log Entry # 17,Data Off
Method Log Entry # 18,Isothermal 1 minutes
Method Log Entry # 19,Data On
Method Log Entry # 20,(Ramp 242593) Ramp 10 °C/minute to 150 °C
Cell Serial,DRC2-00792
[T1 Calibration]
Slope,-0.008529666
Offset,9.636258
Initial Temperature,98.23
GUID,f8bfdadc-4977-4fdf-ba6d-0ba9134940c3
[TZero Calibration]
Date Applied,11/29/2022 4:06:13 PM
Description,From -89.059 °C to 396.009 °C at 20.000°C/min
Gas Type,Nitrogen
Pan Type,None
Source Files 1,C:\Users\yargerlab\Desktop\DSC Data\General\TZero_calibration_11_29_22_2nd(2).tri
Source Files 2,C:\Users\yargerlab\Desktop\DSC Data\General\TZero_calibration_11_29_22_2nd(3).tri
Delta T Offset,13.05235
Delta T Slope,-0.007271007
Delta T0 Offset,-13.69128
Delta T0 Slope,0.06063341
[Temperature Calibration]
Date Applied,11/29/2022 7:12:28 PM
Description,From 106.590 °C to 186.590 °C at 10.000°C/min
Gas Type,Nitrogen
Pan Type,Tzero Aluminum Hermetic
Source Files 1,C:\Users\yargerlab\Desktop\DSC Data\General\Indium(6).tri
Measured 1,157.391
Known 1,156.598
[Cell Constant Calibration]
Date Applied,11/29/2022 7:12:29 PM
Description,From 106.590 °C to 186.590 °C at 10.000°C/min
Gas Type,Nitrogen
Pan Type,Tzero Aluminum Hermetic
Source Files 1,C:\Users\yargerlab\Desktop\DSC Data\General\Indium(6).tri
T4P KCell,1.006051
Onset Slope,63.26126 mW/°C
[Direct Cp Calibration]
Date Applied,11/30/2022 11:04:51 AM
Description,From -79.983 °C to 298.409 °C at 10.000°C/min
Gas Type,Nitrogen
Pan Type,Tzero Aluminum Hermetic
Source Files 1,C:\Users\yargerlab\Desktop\DSC Data\General\Sapphire_Heat_Capacity_11_30_22.tri
[Rev Cp Calibration]
Date Applied,11/30/2022 1:58:51 PM
Description,From -79.996 °C to 292.812 °C at 3.000°C/min
Gas Type,Nitrogen
Pan Type,Tzero Aluminum Hermetic
Source Files 1,C:\Users\yargerlab\Desktop\DSC Data\General\Sapphire_MDSC_Calibration_11_30_22.tri
[step]
Ramp 10.00 °C/min to 150.00 °C
Time,Temperature,Heat Flow (Normalized)
min,°C,W/g
0.00,-59.70,-0.042
0.01,-59.71,-0.040
0.03,-59.71,-0.035
0.05,-59.71,-0.031
0.06,-59.71,-0.031
0.08,-59.69,-0.039
0.09,-59.66,-0.065
0.11,-59.62,-0.083
0.12,-59.56,-0.095
0.14,-59.49,-0.100
0.15,-59.41,-0.099
0.16,-59.31,-0.094
0.18,-59.21,-0.083
0.19,-59.10,-0.054
0.21,-58.99,-0.036
0.23,-58.87,-0.013
0.24,-58.75,0.004
0.26,-58.62,0.021
0.27,-58.50,0.036
0.29,-58.37,0.049
0.30,-58.23,0.060
0.31,-58.10,0.071
0.33,-57.96,0.079
0.35,-57.83,0.086
0.36,-57.69,0.091
0.38,-57.55,0.098
0.39,-57.41,0.101
0.40,-57.27,0.104
0.42,-57.13,0.107
0.44,-56.99,0.111
0.45,-56.85,0.113
0.46,-56.70,0.115
0.48,-56.56,0.116
0.50,-56.42,0.117
0.51,-56.27,0.119
0.53,-56.13,0.120
0.54,-55.98,0.121
0.55,-55.84,0.121
0.57,-55.69,0.122
0.58,-55.55,0.122
0.60,-55.40,0.123
0.62,-55.26,0.123
0.63,-55.11,0.124
0.65,-54.96,0.124
0.66,-54.82,0.125
0.68,-54.67,0.125
0.69,-54.52,0.125
0.70,-54.38,0.126
0.72,-54.23,0.126
0.73,-54.08,0.126
0.75,-53.93,0.126
0.77,-53.79,0.126
0.78,-53.64,0.127
0.80,-53.49,0.127
0.81,-53.35,0.127
0.83,-53.20,0.127
0.84,-53.05,0.127
0.85,-52.90,0.128
0.87,-52.76,0.128
0.88,-52.61,0.128
0.90,-52.46,0.128
0.92,-52.31,0.128
0.93,-52.16,0.128
0.95,-52.01,0.128
0.96,-51.87,0.128
0.98,-51.72,0.128
0.99,-51.57,0.128
1.00,-51.42,0.128
1.02,-51.27,0.128
1.03,-51.12,0.128
1.05,-50.98,0.128
1.07,-50.83,0.128
1.08,-50.68,0.128
1.09,-50.53,0.128
1.11,-50.38,0.128
1.13,-50.23,0.128
1.14,-50.08,0.128
1.16,-49.94,0.128
1.17,-49.79,0.128
1.18,-49.64,0.128
1.20,-49.49,0.128
1.22,-49.34,0.128
1.23,-49.19,0.128
1.24,-49.04,0.128
1.26,-48.89,0.128
1.28,-48.74,0.128
1.29,-48.59,0.128
1.31,-48.44,0.127
1.32,-48.29,0.128
1.33,-48.14,0.128
1.35,-47.99,0.127
1.37,-47.84,0.127
1.38,-47.70,0.127
1.39,-47.55,0.127
1.41,-47.40,0.127
1.43,-47.25,0.127
1.44,-47.10,0.127
1.46,-46.95,0.127
1.47,-46.80,0.127
1.48,-46.65,0.126
1.50,-46.50,0.126
1.52,-46.35,0.126
1.53,-46.20,0.126
1.54,-46.05,0.126
1.56,-45.90,0.126
1.58,-45.75,0.126
1.59,-45.60,0.126
1.61,-45.45,0.126
1.62,-45.30,0.126
1.63,-45.15,0.126
1.65,-45.00,0.126
1.67,-44.85,0.126
1.68,-44.70,0.126
1.69,-44.55,0.125
1.71,-44.40,0.125
1.73,-44.25,0.125
1.74,-44.10,0.125
1.76,-43.95,0.125
1.77,-43.80,0.125
1.78,-43.65,0.125
1.80,-43.50,0.125
1.82,-43.35,0.125
1.83,-43.20,0.125
1.84,-43.05,0.125
1.86,-42.90,0.125
1.88,-42.75,0.125
1.89,-42.60,0.125
1.91,-42.45,0.125
1.92,-42.30,0.124
1.93,-42.15,0.124
1.95,-42.00,0.124
1.97,-41.85,0.124
1.98,-41.70,0.124
1.99,-41.55,0.124
2.01,-41.40,0.124
2.03,-41.25,0.124
2.04,-41.10,0.124
2.06,-40.95,0.124
2.07,-40.80,0.124
2.08,-40.65,0.124
2.10,-40.50,0.124
2.12,-40.35,0.123
2.13,-40.20,0.123
2.14,-40.05,0.123
2.16,-39.90,0.123
2.18,-39.75,0.123
2.19,-39.60,0.123
2.21,-39.45,0.123
2.22,-39.30,0.123
2.24,-39.15,0.123
2.25,-39.00,0.123
2.26,-38.85,0.122
2.28,-38.70,0.122
2.29,-38.55,0.122
2.31,-38.40,0.122
2.33,-38.25,0.122
2.34,-38.10,0.122
2.36,-37.95,0.122
2.37,-37.80,0.122
2.39,-37.65,0.122
2.40,-37.50,0.122
2.41,-37.35,0.122
2.43,-37.20,0.122
2.44,-37.05,0.122
2.46,-36.90,0.122
2.48,-36.75,0.122
2.49,-36.60,0.122
2.51,-36.45,0.122
2.52,-36.30,0.122
2.54,-36.14,0.122
2.55,-36.00,0.121
2.56,-35.84,0.121
2.58,-35.69,0.121
2.59,-35.55,0.121
2.61,-35.40,0.121
2.63,-35.24,0.121
2.64,-35.09,0.121
2.66,-34.94,0.121
2.67,-34.79,0.121
2.69,-34.64,0.121
2.70,-34.49,0.121
2.71,-34.34,0.121
2.73,-34.19,0.120
2.74,-34.04,0.120
2.76,-33.89,0.120
2.78,-33.74,0.120
2.79,-33.59,0.120
2.81,-33.44,0.120
2.82,-33.29,0.120
2.84,-33.14,0.120
2.85,-32.99,0.120
2.86,-32.84,0.120
2.88,-32.69,0.120
2.89,-32.54,0.120
2.91,-32.39,0.120
2.93,-32.24,0.120
2.94,-32.09,0.120
2.96,-31.94,0.120
2.97,-31.79,0.120
2.99,-31.64,0.119
3.00,-31.49,0.119
3.01,-31.34,0.119
3.03,-31.19,0.119
3.04,-31.04,0.119
3.06,-30.89,0.119
3.08,-30.74,0.119
3.09,-30.59,0.119
3.11,-30.44,0.119
3.12,-30.29,0.119
3.14,-30.14,0.119
3.15,-29.99,0.119
3.16,-29.84,0.119
3.18,-29.69,0.119
3.19,-29.54,0.119
3.21,-29.39,0.119
3.23,-29.24,0.119
3.24,-29.09,0.119
3.26,-28.94,0.119
3.27,-28.79,0.119
3.29,-28.64,0.119
3.30,-28.49,0.119
3.31,-28.34,0.118
3.33,-28.19,0.118
3.34,-28.04,0.118
3.36,-27.89,0.118
3.38,-27.73,0.118
3.39,-27.58,0.118
3.41,-27.44,0.118
3.42,-27.28,0.118
3.44,-27.13,0.118
3.45,-26.98,0.118
3.46,-26.83,0.118
3.48,-26.68,0.118
3.49,-26.53,0.118
3.51,-26.38,0.118
3.53,-26.23,0.118
3.54,-26.08,0.118
3.56,-25.93,0.118
3.57,-25.78,0.118
3.59,-25.63,0.118
3.60,-25.48,0.118
3.61,-25.33,0.118
3.63,-25.18,0.118
3.64,-25.03,0.118
3.66,-24.88,0.118
3.68,-24.73,0.117
3.69,-24.58,0.117
3.71,-24.43,0.117
3.72,-24.28,0.117
3.74,-24.13,0.117
3.75,-23.98,0.117
3.76,-23.83,0.117
3.78,-23.68,0.117
3.79,-23.53,0.117
3.81,-23.38,0.117
3.83,-23.23,0.117
3.84,-23.08,0.117
3.86,-22.93,0.117
3.87,-22.78,0.117
3.89,-22.63,0.117
3.90,-22.48,0.117
3.91,-22.33,0.117
3.93,-22.18,0.117
3.94,-22.03,0.117
3.96,-21.88,0.117
3.98,-21.73,0.117
3.99,-21.58,0.117
4.01,-21.43,0.117
4.02,-21.28,0.117
4.04,-21.13,0.117
4.05,-20.97,0.117
4.06,-20.83,0.117
4.08,-20.67,0.117
4.09,-20.53,0.116
4.11,-20.38,0.116
4.13,-20.22,0.116
4.14,-20.07,0.116
4.16,-19.92,0.116
4.17,-19.77,0.116
4.19,-19.62,0.116
4.20,-19.47,0.116
4.21,-19.32,0.116
4.23,-19.17,0.116
4.24,-19.02,0.116
4.26,-18.87,0.116
4.28,-18.72,0.116
4.29,-18.57,0.116
4.30,-18.42,0.116
4.32,-18.27,0.116
4.34,-18.12,0.116
4.35,-17.97,0.116
4.36,-17.82,0.116
4.38,-17.67,0.116
4.40,-17.52,0.116
4.41,-17.37,0.116
4.43,-17.22,0.116
4.44,-17.07,0.116
4.45,-16.92,0.116
4.47,-16.77,0.116
4.49,-16.62,0.116
4.50,-16.47,0.116
4.51,-16.32,0.116
4.53,-16.17,0.116
4.55,-16.02,0.116
4.56,-15.87,0.116
4.58,-15.72,0.116
4.59,-15.57,0.116
4.60,-15.42,0.116
4.62,-15.27,0.115
4.64,-15.12,0.115
4.65,-14.97,0.115
4.66,-14.82,0.115
4.68,-14.67,0.115
4.70,-14.52,0.115
4.71,-14.37,0.115
4.73,-14.22,0.115
4.74,-14.07,0.115
4.75,-13.92,0.115
4.77,-13.77,0.115
4.79,-13.62,0.115
4.80,-13.47,0.115
4.81,-13.31,0.115
4.83,-13.16,0.115
4.85,-13.02,0.115
4.86,-12.87,0.115
4.88,-12.72,0.115
4.89,-12.57,0.115
4.90,-12.42,0.115
4.92,-12.27,0.115
4.94,-12.11,0.115
4.95,-11.97,0.115
4.96,-11.81,0.115
4.98,-11.66,0.115
5.00,-11.52,0.115
5.01,-11.36,0.115
5.03,-11.21,0.115
5.04,-11.06,0.115
5.05,-10.91,0.115
5.07,-10.76,0.115
5.09,-10.61,0.115
5.10,-10.46,0.115
5.11,-10.31,0.115
5.13,-10.16,0.115
5.15,-10.01,0.115
5.16,-9.86,0.115
5.18,-9.71,0.115
5.19,-9.56,0.115
5.20,-9.41,0.115
5.22,-9.26,0.115
5.24,-9.11,0.115
5.25,-8.96,0.115
5.26,-8.81,0.115
5.28,-8.66,0.115
5.30,-8.51,0.115
5.31,-8.36,0.115
5.33,-8.21,0.115
5.34,-8.06,0.115
5.35,-7.91,0.115
5.37,-7.76,0.115
5.39,-7.61,0.115
5.40,-7.46,0.115
5.41,-7.31,0.115
5.43,-7.16,0.115
5.45,-7.01,0.115
5.46,-6.86,0.115
5.48,-6.71,0.115
5.49,-6.56,0.115
5.50,-6.41,0.115
5.52,-6.26,0.115
5.54,-6.11,0.115
5.55,-5.96,0.115
5.56,-5.81,0.115
5.58,-5.66,0.115
5.60,-5.51,0.115
5.61,-5.36,0.115
5.63,-5.21,0.115
5.64,-5.06,0.115
5.65,-4.91,0.115
5.67,-4.76,0.115
5.69,-4.61,0.115
5.70,-4.45,0.115
5.71,-4.30,0.115
5.73,-4.15,0.115
5.75,-4.00,0.115
5.76,-3.85,0.115
5.78,-3.70,0.115
5.79,-3.55,0.115
5.80,-3.40,0.115
5.82,-3.25,0.115
5.84,-3.10,0.115
5.85,-2.95,0.115
5.86,-2.80,0.115
5.88,-2.65,0.115
5.90,-2.50,0.115
5.91,-2.35,0.115
5.93,-2.20,0.115
5.94,-2.05,0.115
5.95,-1.90,0.115
5.97,-1.75,0.115
5.99,-1.60,0.115
6.00,-1.45,0.115
6.01,-1.30,0.115
6.03,-1.15,0.115
6.05,-1.00,0.115
6.06,-0.85,0.115
6.08,-0.70,0.115
6.09,-0.55,0.115
6.10,-0.40,0.115
6.12,-0.25,0.115
6.14,-0.10,0.115
6.15,0.05,0.115
6.16,0.20,0.115
6.18,0.35,0.115
6.20,0.50,0.115
6.21,0.65,0.115
6.23,0.80,0.115
6.24,0.95,0.115
6.25,1.10,0.115
6.27,1.25,0.115
6.29,1.40,0.115
6.30,1.55,0.115
6.31,1.70,0.115
6.33,1.85,0.115
6.35,2.00,0.115
6.36,2.15,0.115
6.38,2.30,0.115
6.39,2.45,0.115
6.40,2.60,0.115
6.42,2.75,0.115
6.44,2.91,0.115
6.45,3.06,0.115
6.46,3.20,0.115
6.48,3.35,0.115
6.50,3.51,0.115
6.51,3.66,0.115
6.53,3.81,0.115
6.54,3.96,0.115
6.55,4.11,0.115
6.57,4.26,0.115
6.59,4.41,0.115
6.60,4.56,0.115
6.61,4.71,0.115
6.63,4.86,0.115
6.65,5.01,0.115
6.66,5.16,0.115
6.68,5.31,0.115
6.69,5.46,0.115
6.70,5.61,0.116
6.72,5.76,0.116
6.74,5.91,0.116
6.75,6.06,0.116
6.76,6.21,0.116
6.78,6.36,0.116
6.80,6.51,0.116
6.81,6.66,0.116
6.83,6.81,0.116
6.84,6.96,0.116
6.85,7.11,0.116
6.87,7.26,0.116
6.89,7.41,0.116
6.90,7.56,0.116
6.91,7.71,0.116
6.93,7.86,0.116
6.95,8.01,0.116
6.96,8.16,0.116
6.98,8.31,0.116
6.99,8.46,0.116
7.00,8.61,0.116
7.02,8.76,0.116
7.04,8.91,0.116
7.05,9.06,0.117
7.06,9.21,0.116
7.08,9.36,0.116
7.10,9.51,0.116
7.11,9.66,0.116
7.13,9.81,0.116
7.14,9.96,0.117
7.15,10.11,0.117
7.17,10.26,0.117
7.19,10.41,0.117
7.20,10.56,0.117
7.21,10.71,0.117
7.23,10.86,0.117
7.25,11.01,0.117
7.26,11.16,0.117
7.28,11.31,0.117
7.29,11.46,0.117
7.30,11.61,0.117
7.32,11.76,0.117
7.34,11.91,0.117
7.35,12.07,0.117
7.36,12.22,0.117
7.38,12.37,0.117
7.40,12.52,0.117
7.41,12.67,0.117
7.43,12.82,0.117
7.44,12.97,0.117
7.45,13.12,0.117
7.47,13.27,0.117
7.49,13.42,0.117
7.50,13.57,0.117
7.51,13.72,0.117
7.53,13.87,0.117
7.55,14.02,0.117
7.56,14.17,0.117
7.58,14.32,0.117
7.59,14.47,0.117
7.60,14.62,0.117
7.62,14.77,0.117
7.64,14.92,0.117
7.65,15.07,0.117
7.66,15.22,0.117
7.68,15.37,0.117
7.70,15.52,0.117
7.71,15.67,0.117
7.73,15.82,0.117
7.74,15.97,0.117
7.75,16.12,0.117
7.77,16.27,0.117
7.79,16.42,0.117
7.80,16.57,0.117
7.81,16.72,0.117
7.83,16.87,0.117
7.85,17.02,0.117
7.86,17.17,0.117
7.88,17.32,0.117
7.89,17.47,0.117
7.90,17.62,0.117
7.92,17.77,0.117
7.94,17.92,0.117
7.95,18.07,0.117
7.96,18.22,0.117
7.98,18.37,0.117
8.00,18.52,0.117
8.01,18.67,0.117
8.03,18.82,0.117
8.04,18.97,0.117
8.05,19.12,0.117
8.07,19.27,0.117
8.09,19.42,0.117
8.10,19.57,0.117
8.11,19.72,0.117
8.13,19.87,0.117
8.15,20.02,0.117
8.16,20.17,0.117
8.18,20.32,0.117
8.19,20.47,0.117
8.20,20.62,0.117
8.22,20.77,0.117
8.24,20.92,0.117
8.25,21.07,0.117
8.26,21.22,0.117
8.28,21.38,0.117
8.30,21.52,0.117
8.31,21.68,0.118
8.33,21.83,0.118
8.34,21.98,0.118
8.35,22.13,0.118
8.37,22.28,0.118
8.39,22.43,0.118
8.40,22.58,0.118
8.41,22.73,0.118
8.43,22.88,0.118
8.45,23.03,0.118
8.46,23.18,0.118
8.48,23.33,0.118
8.49,23.48,0.118
8.50,23.63,0.118
8.52,23.78,0.118
8.53,23.93,0.118
8.55,24.08,0.118
8.57,24.23,0.118
8.58,24.38,0.118
8.60,24.53,0.118
8.61,24.68,0.118
8.63,24.83,0.118
8.64,24.98,0.118
8.65,25.13,0.118
8.67,25.28,0.118
8.68,25.43,0.118
8.70,25.58,0.118
8.72,25.73,0.118
8.73,25.88,0.118
8.75,26.03,0.118
8.76,26.18,0.118
8.78,26.33,0.118
8.79,26.48,0.119
8.80,26.63,0.119
8.82,26.78,0.119
8.83,26.93,0.119
8.85,27.08,0.119
8.87,27.23,0.119
8.88,27.38,0.119
8.90,27.53,0.119
8.91,27.68,0.119
8.93,27.83,0.119
8.94,27.98,0.119
8.95,28.13,0.119
8.97,28.28,0.119
8.98,28.43,0.119
9.00,28.58,0.119
9.02,28.73,0.119
9.03,28.88,0.119
9.05,29.04,0.119
9.06,29.18,0.120
9.08,29.33,0.120
9.09,29.48,0.120
9.10,29.63,0.120
9.12,29.79,0.120
9.13,29.93,0.120
9.15,30.09,0.120
9.17,30.24,0.120
9.18,30.39,0.120
9.20,30.54,0.120
9.21,30.69,0.120
9.23,30.84,0.120
9.24,30.99,0.120
9.25,31.14,0.120
9.27,31.29,0.120
9.28,31.44,0.120
9.30,31.59,0.120
9.32,31.74,0.120
9.33,31.89,0.120
9.35,32.04,0.120
9.36,32.19,0.120
9.38,32.34,0.120
9.39,32.49,0.120
9.40,32.64,0.121
9.42,32.79,0.121
9.43,32.94,0.121
9.45,33.09,0.121
9.47,33.24,0.121
9.48,33.39,0.121
9.50,33.54,0.121
9.51,33.69,0.121
9.53,33.84,0.121
9.54,33.99,0.121
9.55,34.14,0.121
9.57,34.29,0.121
9.58,34.44,0.121
9.60,34.59,0.121
9.62,34.74,0.121
9.63,34.89,0.121
9.65,35.04,0.121
9.66,35.19,0.122
9.68,35.34,0.122
9.69,35.49,0.122
9.70,35.64,0.122
9.72,35.79,0.122
9.73,35.94,0.122
9.75,36.09,0.122
9.77,36.24,0.122
9.78,36.39,0.122
9.80,36.54,0.122
9.81,36.69,0.122
9.83,36.84,0.122
9.84,36.99,0.122
9.85,37.14,0.122
9.87,37.29,0.122
9.88,37.44,0.122
9.90,37.59,0.122
9.92,37.74,0.122
9.93,37.90,0.123
9.95,38.04,0.123
9.96,38.20,0.122
9.98,38.35,0.123
9.99,38.50,0.123
10.00,38.65,0.123
10.02,38.80,0.123
10.03,38.95,0.123
10.05,39.10,0.123
10.07,39.25,0.123
10.08,39.40,0.123
10.10,39.55,0.123
10.11,39.70,0.123
10.13,39.85,0.123
10.14,40.00,0.123
10.15,40.15,0.123
10.17,40.30,0.123
10.18,40.45,0.123
10.20,40.60,0.123
10.22,40.75,0.123
10.23,40.90,0.123
10.25,41.05,0.123
10.26,41.20,0.123
10.28,41.35,0.123
10.29,41.50,0.123
10.30,41.65,0.124
10.32,41.80,0.124
10.33,41.95,0.123
10.35,42.10,0.123
10.37,42.25,0.124
10.38,42.40,0.124
10.40,42.55,0.124
10.41,42.70,0.124
10.43,42.85,0.124
10.44,43.00,0.124
10.45,43.15,0.124
10.47,43.30,0.124
10.48,43.45,0.124
10.50,43.60,0.124
10.52,43.75,0.124
10.53,43.90,0.124
10.55,44.05,0.124
10.56,44.20,0.124
10.58,44.35,0.125
10.59,44.50,0.125
10.60,44.65,0.125
10.62,44.80,0.125
10.63,44.95,0.125
10.65,45.10,0.125
10.67,45.25,0.125
10.68,45.40,0.125
10.70,45.55,0.125
10.71,45.70,0.125
10.73,45.85,0.125
10.74,46.00,0.125
10.75,46.15,0.125
10.77,46.30,0.125
10.78,46.45,0.125
10.80,46.60,0.125
10.82,46.75,0.126
10.83,46.90,0.126
10.85,47.05,0.126
10.86,47.20,0.126
10.88,47.35,0.126
10.89,47.51,0.126
10.90,47.66,0.126
10.92,47.80,0.126
10.93,47.96,0.126
10.95,48.11,0.126
10.97,48.26,0.126
10.98,48.40,0.126
11.00,48.56,0.126
11.01,48.71,0.127
11.03,48.86,0.126
11.04,49.01,0.127
11.05,49.16,0.127
11.07,49.31,0.127
11.08,49.46,0.127
11.10,49.61,0.127
11.12,49.76,0.127
11.13,49.91,0.127
11.15,50.06,0.127
11.16,50.21,0.127
11.18,50.36,0.127
11.19,50.51,0.127
11.20,50.66,0.127
11.22,50.81,0.127
11.23,50.96,0.127
11.25,51.11,0.128
11.27,51.26,0.128
11.28,51.41,0.128
11.30,51.56,0.128
11.31,51.71,0.128
11.33,51.86,0.128
11.34,52.01,0.128
11.35,52.16,0.128
11.37,52.31,0.128
11.38,52.46,0.128
11.40,52.61,0.128
11.42,52.76,0.128
11.43,52.91,0.128
11.45,53.06,0.128
11.46,53.21,0.128
11.48,53.36,0.128
11.49,53.51,0.128
11.50,53.66,0.128
11.52,53.81,0.128
11.53,53.96,0.128
11.55,54.11,0.128
11.57,54.26,0.128
11.58,54.41,0.129
11.60,54.56,0.129
11.61,54.71,0.129
11.63,54.86,0.129
11.64,55.01,0.129
11.65,55.16,0.129
11.67,55.31,0.129
11.68,55.46,0.129
11.70,55.61,0.129
11.72,55.76,0.129
11.73,55.91,0.129
11.75,56.06,0.129
11.76,56.21,0.129
11.78,56.36,0.129
11.79,56.51,0.129
11.80,56.66,0.130
11.82,56.81,0.130
11.83,56.96,0.130
11.85,57.12,0.130
11.87,57.26,0.130
11.88,57.41,0.130
11.90,57.56,0.130
11.91,57.72,0.130
11.93,57.87,0.130
11.94,58.02,0.130
11.95,58.17,0.130
11.97,58.31,0.130
11.98,58.47,0.130
12.00,58.62,0.130
12.02,58.77,0.130
12.03,58.92,0.130
12.05,59.07,0.131
12.06,59.22,0.131
12.08,59.37,0.131
12.09,59.52,0.131
12.10,59.67,0.131
12.12,59.82,0.131
12.13,59.97,0.131
12.15,60.12,0.131
12.17,60.27,0.131
12.18,60.42,0.131
12.20,60.57,0.131
12.21,60.72,0.131
12.23,60.87,0.131
12.24,61.02,0.132
12.25,61.17,0.132
12.27,61.32,0.132
12.28,61.47,0.132
12.30,61.62,0.132
12.32,61.77,0.132
12.33,61.92,0.132
12.35,62.07,0.132
12.36,62.22,0.132
12.38,62.37,0.132
12.39,62.52,0.132
12.40,62.67,0.132
12.42,62.82,0.132
12.43,62.97,0.132
12.45,63.12,0.132
12.47,63.27,0.133
12.48,63.42,0.133
12.50,63.57,0.133
12.51,63.72,0.133
12.53,63.87,0.133
12.54,64.02,0.133
12.55,64.17,0.133
12.57,64.32,0.133
12.58,64.47,0.133
12.60,64.62,0.133
12.62,64.77,0.133
12.63,64.92,0.134
12.65,65.07,0.134
12.66,65.22,0.134
12.68,65.37,0.134
12.69,65.52,0.134
12.70,65.67,0.134
12.72,65.82,0.134
12.73,65.97,0.134
12.75,66.12,0.134
12.77,66.27,0.134
12.78,66.42,0.134
12.80,66.57,0.134
12.81,66.72,0.134
12.83,66.87,0.135
12.84,67.02,0.135
12.85,67.18,0.135
12.87,67.33,0.135
12.88,67.47,0.135
12.90,67.62,0.135
12.92,67.77,0.135
12.93,67.92,0.135
12.95,68.08,0.135
12.96,68.23,0.135
12.98,68.38,0.135
12.99,68.53,0.135
13.00,68.68,0.135
13.02,68.83,0.135
13.03,68.98,0.135
13.05,69.13,0.136
13.07,69.28,0.136
13.08,69.43,0.136
13.10,69.58,0.136
13.11,69.73,0.136
13.13,69.88,0.136
13.14,70.03,0.136
13.15,70.18,0.136
13.17,70.33,0.136
13.18,70.48,0.136
13.20,70.63,0.136
13.22,70.78,0.136
13.23,70.93,0.136
13.25,71.08,0.137
13.26,71.23,0.137
13.28,71.38,0.137
13.29,71.53,0.137
13.30,71.68,0.137
13.32,71.83,0.137
13.33,71.98,0.137
13.35,72.13,0.137
13.37,72.28,0.137
13.38,72.43,0.137
13.40,72.58,0.137
13.41,72.73,0.138
13.43,72.88,0.138
13.44,73.03,0.138
13.45,73.18,0.138
13.47,73.33,0.138
13.48,73.48,0.138
13.50,73.63,0.138
13.52,73.78,0.138
13.53,73.93,0.138
13.55,74.08,0.138
13.56,74.23,0.138
13.58,74.38,0.138
13.59,74.53,0.138
13.60,74.68,0.139
13.62,74.83,0.139
13.63,74.98,0.139
13.65,75.13,0.139
13.67,75.28,0.139
13.68,75.43,0.139
13.70,75.58,0.139
13.71,75.73,0.139
13.73,75.88,0.139
13.74,76.03,0.139
13.75,76.18,0.139
13.77,76.33,0.139
13.78,76.48,0.140
13.80,76.63,0.140
13.82,76.78,0.140
13.83,76.93,0.140
13.85,77.08,0.140
13.86,77.23,0.140
13.88,77.38,0.140
13.89,77.53,0.140
13.90,77.68,0.140
13.92,77.83,0.140
13.93,77.98,0.140
13.95,78.14,0.140
13.97,78.28,0.141
13.98,78.43,0.141
14.00,78.58,0.141
14.01,78.73,0.141
14.03,78.88,0.141
14.04,79.03,0.141
14.05,79.18,0.141
14.07,79.33,0.141
14.08,79.49,0.141
14.10,79.64,0.141
14.12,79.78,0.141
14.13,79.94,0.141
14.15,80.09,0.141
14.16,80.24,0.141
14.18,80.39,0.141
14.19,80.54,0.141
14.20,80.69,0.141
14.22,80.84,0.142
14.23,80.99,0.142
14.25,81.14,0.142
14.27,81.29,0.142
14.28,81.44,0.142
14.30,81.59,0.142
14.31,81.74,0.142
14.33,81.89,0.142
14.34,82.04,0.142
14.35,82.19,0.142
14.37,82.34,0.142
14.38,82.49,0.142
14.40,82.64,0.142
14.42,82.79,0.142
14.43,82.94,0.142
14.45,83.09,0.142
14.46,83.24,0.142
14.48,83.39,0.142
14.49,83.54,0.142
14.50,83.69,0.143
14.52,83.84,0.143
14.53,83.99,0.143
14.55,84.14,0.143
14.57,84.29,0.143
14.58,84.44,0.143
14.60,84.59,0.143
14.61,84.74,0.143
14.63,84.89,0.143
14.64,85.04,0.143
14.65,85.19,0.143
14.67,85.34,0.143
14.68,85.49,0.143
14.70,85.64,0.143
14.72,85.79,0.143
14.73,85.94,0.143
14.75,86.09,0.143
14.76,86.24,0.143
14.78,86.39,0.143
14.79,86.54,0.144
14.80,86.69,0.144
14.82,86.84,0.144
14.83,86.99,0.144
14.85,87.14,0.144
14.87,87.29,0.144
14.88,87.44,0.144
14.90,87.59,0.144
14.91,87.74,0.144
14.93,87.89,0.144
14.94,88.04,0.144
14.95,88.19,0.144
14.97,88.34,0.144
14.98,88.49,0.144
15.00,88.64,0.145
15.02,88.79,0.145
15.03,88.94,0.145
15.05,89.09,0.145
15.06,89.24,0.145
15.08,89.39,0.145
15.09,89.54,0.145
15.10,89.69,0.145
15.12,89.85,0.145
15.13,89.99,0.145
15.15,90.15,0.145
15.17,90.30,0.146
15.18,90.45,0.146
15.20,90.60,0.146
15.21,90.75,0.146
15.23,90.90,0.146
15.24,91.05,0.146
15.25,91.20,0.146
15.27,91.35,0.146
15.28,91.50,0.146
15.30,91.65,0.147
15.32,91.80,0.147
15.33,91.95,0.147
15.35,92.10,0.147
15.36,92.25,0.147
15.38,92.40,0.147
15.39,92.55,0.147
15.40,92.70,0.147
15.42,92.85,0.147
15.43,93.00,0.148
15.45,93.15,0.148
15.47,93.30,0.148
15.48,93.45,0.148
15.50,93.60,0.148
15.51,93.75,0.148
15.53,93.90,0.148
15.54,94.05,0.148
15.55,94.20,0.148
15.57,94.35,0.148
15.58,94.50,0.149
15.60,94.65,0.149
15.62,94.80,0.149
15.63,94.95,0.149
15.65,95.10,0.149
15.66,95.25,0.149
15.68,95.40,0.149
15.69,95.55,0.149
15.70,95.70,0.149
15.72,95.85,0.150
15.73,96.00,0.150
15.75,96.15,0.150
15.77,96.30,0.150
15.78,96.45,0.150
15.80,96.60,0.150
15.81,96.75,0.150
15.83,96.90,0.150
15.84,97.05,0.150
15.85,97.20,0.151
15.87,97.35,0.151
15.88,97.50,0.151
15.90,97.65,0.151
15.92,97.80,0.151
15.93,97.95,0.151
15.95,98.10,0.151
15.96,98.25,0.151
15.98,98.40,0.151
15.99,98.55,0.152
16.00,98.70,0.152
16.02,98.85,0.152
16.03,99.00,0.152
16.05,99.15,0.152
16.07,99.30,0.152
16.08,99.45,0.152
16.10,99.60,0.153
16.11,99.75,0.153
16.13,99.90,0.153
16.14,100.05,0.153
16.15,100.20,0.153
16.17,100.35,0.153
16.18,100.50,0.153
16.20,100.65,0.153
16.22,100.80,0.153
16.23,100.96,0.153
16.25,101.11,0.153
16.26,101.26,0.153
16.28,101.40,0.154
16.29,101.56,0.154
16.30,101.71,0.154
16.32,101.86,0.154
16.33,102.01,0.154
16.35,102.16,0.154
16.37,102.31,0.154
16.38,102.46,0.154
16.40,102.61,0.155
16.41,102.76,0.155
16.43,102.91,0.155
16.44,103.05,0.155
16.45,103.21,0.155
16.47,103.36,0.155
16.48,103.51,0.155
16.50,103.66,0.155
16.52,103.81,0.155
16.53,103.96,0.155
16.55,104.11,0.155
16.56,104.26,0.155
16.58,104.41,0.156
16.59,104.56,0.156
16.60,104.71,0.156
16.62,104.86,0.156
16.63,105.01,0.156
16.65,105.16,0.156
16.67,105.31,0.156
16.68,105.46,0.156
16.70,105.61,0.156
16.71,105.76,0.156
16.73,105.91,0.156
16.74,106.06,0.157
16.75,106.21,0.157
16.77,106.36,0.157
16.78,106.51,0.157
16.80,106.66,0.157
16.82,106.81,0.157
16.83,106.96,0.157
16.85,107.11,0.158
16.86,107.26,0.158
16.88,107.41,0.158
16.89,107.56,0.158
16.90,107.71,0.158
16.92,107.86,0.158
16.93,108.01,0.158
16.95,108.16,0.159
16.97,108.31,0.159
16.98,108.46,0.159
17.00,108.61,0.159
17.01,108.76,0.159
17.03,108.91,0.159
17.04,109.06,0.159
17.05,109.21,0.159
17.07,109.36,0.159
17.08,109.51,0.159
17.10,109.66,0.160
17.12,109.81,0.160
17.13,109.96,0.160
17.14,110.11,0.160
17.16,110.26,0.160
17.18,110.41,0.160
17.19,110.56,0.161
17.21,110.71,0.161
17.22,110.86,0.161
17.23,111.01,0.161
17.25,111.16,0.161
17.27,111.31,0.161
17.28,111.46,0.161
17.29,111.61,0.161
17.31,111.76,0.161
17.33,111.91,0.162
17.34,112.06,0.162
17.36,112.21,0.162
17.37,112.36,0.162
17.38,112.51,0.162
17.40,112.66,0.162
17.42,112.81,0.163
17.43,112.96,0.163
17.44,113.11,0.163
17.46,113.26,0.163
17.48,113.41,0.163
17.49,113.56,0.164
17.51,113.71,0.164
17.52,113.86,0.164
17.53,114.01,0.164
17.55,114.16,0.165
17.57,114.31,0.165
17.58,114.46,0.165
17.59,114.61,0.165
17.61,114.76,0.165
17.63,114.91,0.166
17.64,115.06,0.166
17.66,115.21,0.166
17.67,115.36,0.166
17.68,115.51,0.167
17.70,115.66,0.167
17.72,115.81,0.167
17.73,115.96,0.167
17.74,116.11,0.168
17.76,116.26,0.168
17.78,116.41,0.168
17.79,116.56,0.169
17.81,116.71,0.169
17.82,116.87,0.169
17.83,117.01,0.170
17.85,117.16,0.170
17.87,117.31,0.171
17.88,117.46,0.171
17.89,117.61,0.172
17.91,117.76,0.172
17.93,117.91,0.173
17.94,118.06,0.173
17.96,118.21,0.174
17.97,118.37,0.175
17.98,118.51,0.176
18.00,118.66,0.178
18.02,118.82,0.179
18.03,118.97,0.181
18.04,119.11,0.183
18.06,119.27,0.185
18.08,119.42,0.189
18.09,119.56,0.192
18.11,119.71,0.196
18.12,119.86,0.204
18.13,120.01,0.212
18.15,120.16,0.220
18.17,120.31,0.228
18.18,120.46,0.245
18.19,120.61,0.257
18.21,120.76,0.280
18.23,120.90,0.302
18.24,121.05,0.339
18.26,121.20,0.386
18.27,121.34,0.457
18.28,121.48,0.563
18.30,121.62,0.721
18.32,121.75,0.957
18.33,121.87,1.289
18.34,121.98,1.711
18.36,122.08,2.146
18.38,122.18,2.569
18.39,122.27,3.061
18.41,122.34,3.616
18.42,122.42,4.147
18.43,122.48,4.635
18.45,122.55,5.092
18.47,122.62,5.519
18.48,122.69,5.767
18.49,122.77,6.016
18.51,122.86,6.241
18.53,122.95,6.432
18.54,123.05,6.540
18.56,123.16,6.589
18.57,123.27,6.595
18.58,123.40,6.614
18.60,123.53,6.642
18.62,123.66,6.648
18.63,123.80,6.615
18.64,123.95,6.503
18.66,124.10,6.412
18.68,124.25,6.383
18.69,124.41,6.287
18.71,124.57,5.967
18.72,124.75,5.431
18.73,124.98,3.517
18.75,125.27,2.301
18.77,125.56,1.867
18.78,125.82,1.598
18.79,126.07,1.384
18.81,126.30,1.214
18.83,126.52,1.072
18.84,126.73,0.938
18.86,126.93,0.842
18.87,127.12,0.752
18.88,127.31,0.675
18.90,127.49,0.611
18.92,127.67,0.555
18.93,127.84,0.507
18.94,128.01,0.468
18.96,128.17,0.436
18.98,128.33,0.407
18.99,128.50,0.381
19.01,128.66,0.362
19.02,128.82,0.346
19.03,128.97,0.328
19.05,129.13,0.319
19.07,129.28,0.307
19.08,129.44,0.301
19.09,129.59,0.289
19.11,129.74,0.286
19.13,129.90,0.283
19.14,130.05,0.276
19.16,130.20,0.272
19.17,130.35,0.269
19.18,130.50,0.267
19.20,130.65,0.266
19.22,130.81,0.264
19.23,130.96,0.263
19.24,131.11,0.262
19.26,131.26,0.261
19.28,131.41,0.261
19.29,131.56,0.260
19.31,131.71,0.260
19.32,131.86,0.259
19.33,132.01,0.259
19.35,132.16,0.259
19.37,132.31,0.258
19.38,132.46,0.258
19.39,132.61,0.258
19.41,132.76,0.257
19.43,132.91,0.257
19.44,133.06,0.257
19.46,133.21,0.257
19.47,133.36,0.256
19.48,133.51,0.256
19.50,133.66,0.256
19.52,133.81,0.256
19.53,133.96,0.256
19.54,134.11,0.255
19.56,134.26,0.255
19.58,134.41,0.255
19.59,134.56,0.255
19.61,134.72,0.255
19.62,134.86,0.255
19.63,135.01,0.255
19.65,135.16,0.255
19.67,135.32,0.255
19.68,135.46,0.254
19.69,135.61,0.254
19.71,135.77,0.254
19.73,135.91,0.254
19.74,136.06,0.254
19.76,136.21,0.254
19.77,136.37,0.254
19.78,136.52,0.254
19.80,136.67,0.254
19.82,136.82,0.255
19.83,136.97,0.255
19.84,137.12,0.255
19.86,137.27,0.255
19.88,137.42,0.255
19.89,137.57,0.255
19.91,137.72,0.255
19.92,137.87,0.255
19.93,138.02,0.255
19.95,138.17,0.255
19.97,138.32,0.255
19.98,138.47,0.255
19.99,138.62,0.255
20.01,138.77,0.255
20.03,138.92,0.255
20.04,139.07,0.256
20.06,139.22,0.256
20.07,139.37,0.256
20.08,139.52,0.256
20.10,139.67,0.256
20.12,139.82,0.256
20.13,139.97,0.256
20.14,140.12,0.257
20.16,140.27,0.257
20.18,140.42,0.257
20.19,140.57,0.257
20.21,140.72,0.257
20.22,140.87,0.257
20.23,141.02,0.257
20.25,141.17,0.257
20.27,141.32,0.258
20.28,141.47,0.258
20.29,141.62,0.258
20.31,141.77,0.258
20.33,141.92,0.258
20.34,142.07,0.258
20.36,142.22,0.258
20.37,142.37,0.258
20.38,142.52,0.258
20.40,142.67,0.259
20.42,142.82,0.259
20.43,142.97,0.259
20.44,143.12,0.259
20.46,143.27,0.259
20.48,143.42,0.259
20.49,143.57,0.259
20.51,143.72,0.259
20.52,143.87,0.260
20.53,144.02,0.260
20.55,144.17,0.260
20.57,144.32,0.260
20.58,144.47,0.260
20.59,144.62,0.260
20.61,144.77,0.260
20.63,144.92,0.261
20.64,145.07,0.261
20.66,145.22,0.261
20.67,145.37,0.261
20.68,145.52,0.261
20.70,145.67,0.261
20.72,145.82,0.261
20.73,145.97,0.261
20.74,146.12,0.262
20.76,146.27,0.262
20.78,146.42,0.262
20.79,146.57,0.262
20.81,146.72,0.262
20.82,146.87,0.262
20.83,147.02,0.262
20.85,147.17,0.262
20.87,147.32,0.262
20.88,147.47,0.263
20.89,147.62,0.263
20.91,147.77,0.263
20.93,147.92,0.263
20.94,148.07,
20.96,148.22,
20.97,148.37,
20.98,,
20.99,,

[step]
Ramp 10.00 °C/min to -60.00 °C
Time,Temperature,Heat Flow (Normalized)
min,°C,W/g
21.99,150.09,-0.061
22.01,150.09,-0.061
22.02,150.09,-0.061
22.04,150.08,-0.061
22.05,150.07,-0.046
22.07,150.04,-0.011
22.08,150.01,0.015
22.10,149.95,0.032
22.11,149.88,0.026
22.13,149.80,0.013
22.14,149.70,-0.035
22.16,149.60,-0.079
22.17,149.49,-0.122
22.19,149.37,-0.164
22.20,149.25,-0.197
22.22,149.13,-0.228
22.23,149.00,-0.250
22.25,148.87,-0.265
22.26,148.73,-0.287
22.28,148.60,-0.298
22.29,148.46,-0.312
22.31,148.32,-0.323
22.32,148.18,-0.335
22.34,148.04,-0.338
22.35,147.90,-0.348
22.37,147.76,-0.351
22.38,147.61,-0.357
22.40,147.47,-0.362
22.41,147.33,-0.364
22.43,147.18,-0.367
22.44,147.04,-0.369
22.46,146.89,-0.371
22.47,146.74,-0.373
22.49,146.60,-0.375
22.50,146.45,-0.375
22.52,146.30,-0.376
22.53,146.16,-0.377
22.55,146.01,-0.377
22.56,145.86,-0.378
22.58,145.71,-0.378
22.59,145.57,-0.378
22.61,145.42,-0.379
22.62,145.27,-0.379
22.64,145.12,-0.380
22.65,144.98,-0.380
22.67,144.83,-0.380
22.68,144.68,-0.381
22.70,144.53,-0.381
22.71,144.38,-0.381
22.73,144.23,-0.382
22.74,144.08,-0.382
22.76,143.94,-0.382
22.77,143.79,-0.382
22.79,143.64,-0.383
22.80,143.49,-0.383
22.82,143.34,-0.383
22.83,143.19,-0.383
22.85,143.04,-0.383
22.86,142.90,-0.384
22.88,142.75,-0.384
22.89,142.60,-0.384
22.91,142.45,-0.384
22.92,142.30,-0.384
22.94,142.15,-0.384
22.95,142.00,-0.384
22.97,141.85,-0.384
22.98,141.70,-0.384
23.00,141.55,-0.384
23.01,141.41,-0.384
23.03,141.26,-0.384
23.04,141.11,-0.384
23.06,140.96,-0.384
23.07,140.81,-0.384
23.09,140.66,-0.384
23.10,140.51,-0.384
23.12,140.36,-0.384
23.13,140.21,-0.383
23.15,140.06,-0.383
23.16,139.91,-0.383
23.18,139.76,-0.383
23.19,139.61,-0.383
23.21,139.46,-0.383
23.22,139.31,-0.383
23.24,139.17,-0.383
23.25,139.02,-0.382
23.27,138.87,-0.382
23.28,138.72,-0.382
23.30,138.57,-0.382
23.31,138.42,-0.382
23.33,138.27,-0.382
23.34,138.12,-0.382
23.36,137.97,-0.381
23.37,137.82,-0.381
23.39,137.67,-0.381
23.40,137.52,-0.381
23.42,137.37,-0.381
23.43,137.22,-0.381
23.45,137.07,-0.380
23.46,136.92,-0.380
23.48,136.77,-0.380
23.49,136.62,-0.380
23.51,136.47,-0.380
23.52,136.32,-0.379
23.54,136.17,-0.379
23.55,136.02,-0.379
23.57,135.87,-0.379
23.58,135.72,-0.379
23.60,135.57,-0.379
23.61,135.42,-0.378
23.63,135.27,-0.378
23.64,135.13,-0.378
23.66,134.97,-0.378
23.67,134.82,-0.377
23.69,134.68,-0.377
23.70,134.53,-0.377
23.72,134.38,-0.377
23.73,134.23,-0.376
23.75,134.08,-0.376
23.76,133.93,-0.376
23.78,133.78,-0.376
23.79,133.63,-0.375
23.81,133.48,-0.375
23.82,133.33,-0.375
23.84,133.18,-0.375
23.85,133.03,-0.375
23.87,132.88,-0.375
23.88,132.73,-0.374
23.90,132.58,-0.374
23.91,132.43,-0.374
23.93,132.28,-0.374
23.94,132.13,-0.373
23.96,131.98,-0.373
23.97,131.83,-0.373
23.99,131.68,-0.372
24.00,131.53,-0.372
24.02,131.38,-0.372
24.03,131.23,-0.371
24.05,131.08,-0.371
24.06,130.93,-0.371
24.08,130.78,-0.371
24.09,130.63,-0.371
24.11,130.48,-0.371
24.12,130.33,-0.370
24.14,130.18,-0.370
24.15,130.03,-0.370
24.17,129.88,-0.370
24.18,129.73,-0.369
24.20,129.58,-0.369
24.21,129.43,-0.369
24.23,129.28,-0.369
24.24,129.13,-0.369
24.26,128.98,-0.368
24.27,128.83,-0.368
24.29,128.68,-0.368
24.30,128.53,-0.368
24.32,128.38,-0.368
24.33,128.23,-0.367
24.35,128.09,-0.367
24.36,127.93,-0.367
24.38,127.79,-0.367
24.39,127.64,-0.366
24.41,127.48,-0.366
24.42,127.34,-0.366
24.44,127.19,-0.366
24.45,127.04,-0.366
24.47,126.89,-0.365
24.48,126.74,-0.365
24.50,126.59,-0.365
24.51,126.44,-0.365
24.53,126.29,-0.365
24.54,126.14,-0.365
24.56,125.99,-0.364
24.57,125.84,-0.364
24.59,125.69,-0.364
24.60,125.54,-0.364
24.62,125.39,-0.363
24.63,125.24,-0.363
24.65,125.09,-0.363
24.66,124.94,-0.363
24.68,124.79,-0.363
24.69,124.64,-0.362
24.71,124.49,-0.362
24.72,124.34,-0.362
24.74,124.19,-0.362
24.75,124.04,-0.361
24.77,123.89,-0.361
24.78,123.74,-0.361
24.80,123.59,-0.361
24.81,123.44,-0.361
24.83,123.29,-0.360
24.84,123.14,-0.360
24.86,122.99,-0.360
24.87,122.84,-0.360
24.89,122.69,-0.360
24.90,122.54,-0.359
24.92,122.39,-0.359
24.93,122.24,-0.359
24.95,122.09,-0.359
24.96,121.94,-0.359
24.98,121.79,-0.358
24.99,121.64,-0.358
25.01,121.49,-0.358
25.02,121.34,-0.358
25.04,121.19,-0.357
25.05,121.04,-0.357
25.07,120.89,-0.357
25.08,120.74,-0.357
25.10,120.59,-0.357
25.11,120.44,-0.357
25.13,120.29,-0.356
25.14,120.14,-0.356
25.16,119.99,-0.356
25.17,119.84,-0.355
25.19,119.69,-0.355
25.20,119.54,-0.355
25.22,119.39,-0.355
25.23,119.24,-0.355
25.25,119.09,-0.355
25.26,118.94,-0.354
25.28,118.79,-0.354
25.29,118.64,-0.354
25.31,118.49,-0.354
25.32,118.34,-0.353
25.34,118.19,-0.353
25.35,118.04,-0.353
25.37,117.89,-0.353
25.38,117.74,-0.353
25.40,117.60,-0.352
25.41,117.45,-0.352
25.43,117.29,-0.352
25.44,117.15,-0.352
25.46,117.00,-0.352
25.47,116.84,-0.352
25.49,116.70,-0.351
25.50,116.55,-0.351
25.52,116.40,-0.351
25.53,116.25,-0.351
25.55,116.10,-0.351
25.56,115.95,-0.351
25.58,115.80,-0.350
25.59,115.65,-0.350
25.61,115.50,-0.350
25.62,115.35,-0.350
25.64,115.20,-0.350
25.65,115.05,-0.350
25.67,114.90,-0.349
25.68,114.75,-0.349
25.70,114.60,-0.349
25.71,114.45,-0.349
25.73,114.30,-0.348
25.74,114.15,-0.348
25.76,114.00,-0.348
25.77,113.85,-0.348
25.79,113.70,-0.348
25.80,113.55,-0.347
25.82,113.40,-0.347
25.83,113.25,-0.347
25.85,113.10,-0.347
25.86,112.95,-0.347
25.88,112.80,-0.346
25.89,112.65,-0.346
25.91,112.50,-0.346
25.92,112.35,-0.346
25.94,112.20,-0.346
25.95,112.05,-0.346
25.97,111.90,-0.346
25.98,111.75,-0.345
26.00,111.60,-0.345
26.01,111.45,-0.345
26.03,111.30,-0.345
26.04,111.15,-0.344
26.06,111.00,-0.344
26.07,110.85,-0.344
26.09,110.70,-0.344
26.10,110.55,-0.344
26.12,110.40,-0.344
26.13,110.25,-0.343
26.15,110.10,-0.343
26.16,109.95,-0.343
26.18,109.80,-0.343
26.19,109.65,-0.343
26.21,109.50,-0.343
26.22,109.35,-0.342
26.24,109.20,-0.342
26.25,109.05,-0.342
26.27,108.90,-0.342
26.28,108.75,-0.342
26.30,108.60,-0.341
26.31,108.45,-0.341
26.33,108.30,-0.341
26.34,108.16,-0.341
26.36,108.01,-0.341
26.37,107.86,-0.341
26.39,107.71,-0.340
26.40,107.55,-0.340
26.42,107.40,-0.340
26.43,107.26,-0.340
26.45,107.11,-0.340
26.46,106.96,-0.339
26.48,106.81,-0.339
26.49,106.66,-0.339
26.51,106.51,-0.339
26.52,106.36,-0.339
26.54,106.21,-0.339
26.55,106.06,-0.339
26.57,105.91,-0.338
26.58,105.76,-0.338
26.60,105.61,-0.338
26.61,105.46,-0.338
26.63,105.31,-0.338
26.64,105.16,-0.337
26.66,105.01,-0.337
26.67,104.86,-0.337
26.69,104.71,-0.337
26.70,104.56,-0.336
26.72,104.41,-0.336
26.73,104.26,-0.336
26.75,104.11,-0.336
26.76,103.96,-0.336
26.78,103.81,-0.336
26.79,103.66,-0.335
26.81,103.51,-0.335
26.82,103.36,-0.335
26.84,103.21,-0.335
26.85,103.06,-0.335
26.87,102.91,-0.335
26.88,102.76,-0.334
26.90,102.61,-0.334
26.91,102.46,-0.334
26.93,102.31,-0.334
26.94,102.19,-11.752
26.96,104.84,-83.863
26.97,105.55,-21.163
26.99,105.00,-7.431
27.00,104.39,-4.389
27.02,103.81,-3.171
27.03,103.30,-2.645
27.05,102.83,-2.267
27.06,102.42,-1.964
27.08,102.05,-1.722
27.09,101.71,-1.512
27.11,101.40,-1.335
27.12,101.11,-1.175
27.14,100.84,-1.042
27.15,100.60,-0.925
27.17,100.36,-0.827
27.18,100.14,-0.738
27.20,99.94,-0.671
27.21,99.73,-0.610
27.23,99.54,-0.555
27.24,99.36,-0.510
27.26,99.17,-0.477
27.27,99.00,-0.444
27.29,98.82,-0.414
27.30,98.66,-0.389
27.32,98.49,-0.371
27.33,98.33,-0.354
27.35,98.17,-0.340
27.36,98.01,-0.325
27.38,97.85,-0.316
27.39,97.69,-0.304
27.41,97.53,-0.301
27.42,97.38,-0.291
27.44,97.23,-0.291
27.45,97.07,-0.284
27.47,96.92,-0.278
27.48,96.77,-0.276
27.50,96.61,-0.273
27.51,96.46,-0.270
27.53,96.31,-0.269
27.54,96.16,-0.266
27.56,96.01,-0.265
27.57,95.86,-0.265
27.59,95.71,-0.264
27.60,95.56,-0.262
27.62,95.41,-0.261
27.63,95.26,-0.261
27.65,95.11,-0.260
27.66,94.96,-0.260
27.68,94.81,-0.260
27.69,94.66,-0.260
27.71,94.51,-0.259
27.72,94.36,-0.258
27.74,94.21,-0.258
27.75,94.06,-0.258
27.77,93.91,-0.257
27.78,93.76,-0.257
27.80,93.61,-0.256
27.81,93.46,-0.256
27.83,93.31,-0.256
27.84,93.16,-0.255
27.86,93.01,-0.255
27.87,92.86,-0.255
27.89,92.71,-0.255
27.90,92.56,-0.254
27.92,92.41,-0.254
27.93,92.26,-0.254
27.95,92.11,-0.254
27.96,91.96,-0.253
27.98,91.81,-0.253
27.99,91.66,-0.253
28.01,91.51,-0.253
28.02,91.36,-0.252
28.04,91.21,-0.252
28.05,91.06,-0.252
28.07,90.91,-0.251
28.08,90.76,-0.251
28.10,90.61,-0.251
28.11,90.46,-0.251
28.13,90.31,-0.251
28.14,90.16,-0.251
28.16,90.01,-0.251
28.17,89.86,-0.250
28.19,89.71,-0.250
28.20,89.56,-0.250
28.22,89.41,-0.250
28.23,89.26,-0.249
28.25,89.11,-0.249
28.26,88.96,-0.249
28.28,88.81,-0.249
28.29,88.66,-0.249
28.31,88.51,-0.249
28.32,88.36,-0.248
28.34,88.21,-0.248
28.35,88.06,-0.248
28.37,87.91,-0.248
28.38,87.76,-0.247
28.40,87.61,-0.247
28.41,87.46,-0.247
28.43,87.31,-0.247
28.44,87.16,-0.246
28.46,87.01,-0.246
28.47,86.86,-0.246
28.49,86.71,-0.246
28.50,86.56,-0.246
28.52,86.41,-0.246
28.53,86.26,-0.245
28.55,86.11,-0.245
[...]
93.05,-11.03,0.117
93.06,-10.88,0.117
93.08,-10.72,0.117
93.09,-10.57,0.117
93.11,-10.42,0.117
93.12,-10.28,0.117
93.14,-10.13,0.118
93.15,-9.98,0.117
93.17,-9.82,0.117
93.18,-9.67,0.117
93.20,-9.52,0.117
93.21,-9.37,0.117
93.23,-9.22,0.117
93.24,-9.07,0.117
93.26,-8.93,0.117
93.27,-8.77,0.117
93.29,-8.62,0.117
93.30,-8.47,0.118
93.32,-8.32,0.117
93.33,-8.17,0.117
93.35,-8.02,0.118
93.36,-7.87,0.117
93.38,-7.72,0.118
93.39,-7.57,0.118
93.41,-7.42,0.118
93.42,-7.27,0.118
93.44,-7.12,0.118
93.45,-6.97,0.118
93.47,-6.82,0.118
93.48,-6.67,0.118
93.50,-6.52,0.118
93.51,-6.37,0.118
93.53,-6.22,0.118
93.54,-6.07,0.118
93.56,-5.92,0.118
93.57,-5.77,0.118
93.59,-5.62,0.118
93.60,-5.47,0.118
93.62,-5.32,0.118
93.63,-5.17,0.118
93.65,-5.02,0.118
93.66,-4.87,0.118
93.68,-4.72,0.118
93.69,-4.57,0.118
93.71,-4.42,0.118
93.72,-4.27,0.118
93.74,-4.12,0.118
93.75,-3.97,0.118
93.77,-3.82,0.118
93.78,-3.67,0.118
93.80,-3.52,0.118
93.81,-3.37,0.118
93.83,-3.22,0.118
93.84,-3.07,0.118
93.86,-2.91,0.118
93.87,-2.77,0.118
93.89,-2.61,0.118
93.90,-2.46,0.117
93.92,-2.31,0.117
93.93,-2.16,0.117
93.95,-2.01,0.118
93.96,-1.86,0.117
93.98,-1.71,0.118
93.99,-1.56,0.118
94.01,-1.41,0.118
94.02,-1.26,0.118
94.04,-1.11,0.118
94.05,-0.96,0.118
94.07,-0.81,0.118
94.08,-0.66,0.118
94.10,-0.51,0.118
94.11,-0.36,0.118
94.13,-0.21,0.118
94.14,-0.06,0.118
94.16,0.09,0.118
94.17,0.24,0.118
94.19,0.39,0.118
94.20,0.54,0.118
94.22,0.69,0.118
94.23,0.84,0.118
94.25,0.99,0.118
94.26,1.14,0.118
94.28,1.29,0.118
94.29,1.44,0.118
94.31,1.59,0.118
94.32,1.74,0.118
94.34,1.89,0.118
94.35,2.04,0.118
94.37,2.19,0.118
94.38,2.34,0.118
94.40,2.49,0.118
94.41,2.64,0.118
94.43,2.79,0.118
94.44,2.94,0.118
94.46,3.09,0.118
94.47,3.24,0.118
94.49,3.39,0.118
94.50,3.54,0.118
94.52,3.69,0.118
94.53,3.84,0.118
94.55,3.99,0.118
94.56,4.14,0.118
94.58,4.29,0.118
94.59,4.44,0.118
94.61,4.59,0.118
94.62,4.74,0.118
94.64,4.89,0.119
94.65,5.04,0.118
94.67,5.20,0.119
94.68,5.34,0.118
94.70,5.50,0.118
94.71,5.65,0.118
94.73,5.80,0.118
94.74,5.95,0.119
94.76,6.10,0.119
94.77,6.25,0.119
94.79,6.40,0.119
94.80,6.55,0.119
94.82,6.70,0.119
94.83,6.85,0.119
94.85,7.00,0.119
94.86,7.15,0.119
94.88,7.30,0.119
94.89,7.45,0.119
94.91,7.60,0.119
94.92,7.75,0.119
94.94,7.90,0.119
94.95,8.05,0.119
94.97,8.20,0.119
94.98,8.35,0.119
95.00,8.50,0.119
95.01,8.65,0.119
95.03,8.80,0.119
95.04,8.95,0.119
95.06,9.10,0.119
95.07,9.25,0.119
95.09,9.40,0.119
95.10,9.55,0.119
95.12,9.70,0.119
95.13,9.85,0.120
95.15,10.00,0.120
95.16,10.15,0.120
95.18,10.30,0.120
95.19,10.45,0.120
95.21,10.60,0.120
95.22,10.75,0.120
95.24,10.90,0.120
95.25,11.05,0.120
95.27,11.20,0.120
95.28,11.35,0.120
95.30,11.50,0.120
95.31,11.66,0.120
95.33,11.81,0.120
95.34,11.95,0.120
95.36,12.10,0.120
95.37,12.26,0.120
95.39,12.41,0.120
95.40,12.55,0.120
95.42,12.71,0.120
95.43,12.85,0.120
95.45,13.01,0.120
95.46,13.16,0.120
95.48,13.31,0.120
95.49,13.46,0.120
95.51,13.61,0.120
95.52,13.76,0.120
95.54,13.91,0.120
95.55,14.06,0.120
95.57,14.21,0.120
95.58,14.36,0.120
95.60,14.51,0.120
95.61,14.66,0.120
95.63,14.81,0.120
95.64,14.96,0.120
95.66,15.11,0.120
95.67,15.26,0.120
95.69,15.41,0.120
95.70,15.56,0.120
95.72,15.71,0.120
95.73,15.86,0.120
95.75,16.01,0.120
95.76,16.16,0.120
95.78,16.31,0.120
95.79,16.46,0.120
95.81,16.61,0.120
95.82,16.76,0.120
95.84,16.91,0.120
95.85,17.06,0.120
95.87,17.21,0.120
95.88,17.36,0.121
95.90,17.51,0.120
95.91,17.66,0.120
95.93,17.81,0.120
95.94,17.96,0.120
95.96,18.11,0.120
95.97,18.26,0.120
95.99,18.41,0.120
96.00,18.56,0.120
96.02,18.71,0.120
96.03,18.86,0.120
96.05,19.01,0.120
96.06,19.16,0.120
96.08,19.31,0.120
96.09,19.46,0.120
96.11,19.61,0.121
96.12,19.76,0.121
96.14,19.91,0.121
96.15,20.06,0.121
96.17,20.21,0.121
96.18,20.36,0.121
96.20,20.51,0.121
96.21,20.66,0.121
96.23,20.81,0.121
96.24,20.96,0.121
96.26,21.11,0.121
96.27,21.26,0.121
96.29,21.41,0.121
96.30,21.56,0.121
96.32,21.72,0.121
96.33,21.86,0.122
96.35,22.01,0.122
96.36,22.17,0.122
96.38,22.31,0.122
96.39,22.47,0.122
96.41,22.62,0.122
96.42,22.77,0.122
96.44,22.92,0.122
96.45,23.07,0.122
96.47,23.22,0.122
96.48,23.37,0.122
96.50,23.52,0.122
96.51,23.67,0.122
96.53,23.82,0.122
96.54,23.97,0.122
96.56,24.12,0.122
96.57,24.27,0.122
96.59,24.42,0.122
96.60,24.57,0.122
96.62,24.72,0.122
96.63,24.87,0.122
96.65,25.02,0.122
96.66,25.17,0.122
96.68,25.32,0.122
96.69,25.47,0.122
96.71,25.62,0.122
96.72,25.77,0.122
96.74,25.92,0.122
96.75,26.07,0.122
96.77,26.22,0.122
96.78,26.37,0.122
96.80,26.52,0.122
96.81,26.67,0.122
96.83,26.82,0.122
96.84,26.97,0.122
96.86,27.12,0.123
96.87,27.27,0.123
96.89,27.42,0.123
96.90,27.57,0.123
96.92,27.72,0.123
96.93,27.87,0.123
96.95,28.02,0.123
96.96,28.17,0.123
96.98,28.32,0.123
96.99,28.47,0.123
97.01,28.62,0.123
97.02,28.77,0.123
97.04,28.92,0.123
97.05,29.07,0.123
97.07,29.22,0.123
97.08,29.37,0.123
97.10,29.52,0.123
97.11,29.67,0.123
97.13,29.82,0.123
97.14,29.97,0.123
97.16,30.12,0.123
97.17,30.27,0.123
97.19,30.42,0.123
97.20,30.57,0.123
97.22,30.72,0.123
97.23,30.87,0.124
97.25,31.02,0.124
97.26,31.18,0.124
97.28,31.33,0.124
97.29,31.48,0.124
97.31,31.63,0.124
97.32,31.78,0.124
97.34,31.93,0.124
97.35,32.08,0.124
97.37,32.23,0.124
97.38,32.38,0.124
97.40,32.53,0.124
97.41,32.68,0.124
97.43,32.83,0.124
97.44,32.98,0.124
97.46,33.13,0.125
97.47,33.28,0.124
97.49,33.43,0.125
97.50,33.58,0.125
97.52,33.73,0.125
97.53,33.88,0.125
97.55,34.03,0.125
97.56,34.18,0.125
97.58,34.33,0.125
97.59,34.48,0.125
97.61,34.63,0.125
97.62,34.78,0.125
97.64,34.93,0.125
97.65,35.08,0.125
97.67,35.23,0.125
97.68,35.38,0.125
97.70,35.53,0.125
97.71,35.68,0.125
97.73,35.83,0.125
97.74,35.98,0.125
97.76,36.13,0.125
97.77,36.28,0.125
97.79,36.43,0.125
97.80,36.58,0.125
97.82,36.73,0.125
97.83,36.88,0.126
97.85,37.03,0.126
97.86,37.18,0.126
97.88,37.33,0.126
97.89,37.48,0.126
97.91,37.63,0.126
97.92,37.78,0.126
97.94,37.93,0.126
97.95,38.08,0.126
97.97,38.23,0.126
97.98,38.38,0.126
98.00,38.53,0.126
98.01,38.68,0.126
98.03,38.83,0.126
98.04,38.98,0.126
98.06,39.13,0.126
98.07,39.28,0.126
98.09,39.43,0.126
98.10,39.58,0.126
98.12,39.73,0.126
98.13,39.89,0.126
98.15,40.04,0.126
98.16,40.18,0.126
98.18,40.33,0.127
98.19,40.49,0.127
98.21,40.63,0.127
98.22,40.79,0.127
98.24,40.94,0.127
98.25,41.09,0.127
98.27,41.24,0.127
98.28,41.39,0.127
98.30,41.54,0.127
98.31,41.69,0.127
98.33,41.84,0.127
98.34,41.99,0.127
98.36,42.14,0.127
98.37,42.29,0.127
98.39,42.44,0.127
98.40,42.59,0.127
98.42,42.74,0.127
98.43,42.89,0.127
98.45,43.04,0.127
98.46,43.19,0.127
98.48,43.34,0.128
98.49,43.49,0.128
98.51,43.64,0.128
98.52,43.79,0.128
98.54,43.94,0.128
98.55,44.09,0.128
98.57,44.24,0.128
98.58,44.39,0.128
98.60,44.54,0.128
98.61,44.69,0.128
98.63,44.84,0.128
98.64,44.99,0.128
98.66,45.14,0.128
98.67,45.29,0.128
98.69,45.44,0.128
98.70,45.59,0.128
98.72,45.74,0.128
98.73,45.89,0.128
98.75,46.04,0.129
98.76,46.19,0.129
98.78,46.34,0.129
98.79,46.49,0.129
98.81,46.64,0.129
98.82,46.79,0.129
98.84,46.94,0.129
98.85,47.09,0.129
98.87,47.24,0.129
98.88,47.40,0.129
98.90,47.54,0.129
98.91,47.69,0.129
98.93,47.84,0.129
98.94,47.99,0.129
98.96,48.14,0.129
98.97,48.29,0.129
98.99,48.44,0.129
99.00,48.59,0.129
99.02,48.74,0.129
99.03,48.89,0.129
99.05,49.04,0.129
99.06,49.19,0.129
99.08,49.35,0.130
99.09,49.49,0.130
99.11,49.64,0.130
99.12,49.79,0.130
99.14,49.95,0.130
99.15,50.09,0.130
99.17,50.25,0.130
99.18,50.40,0.130
99.20,50.55,0.130
99.21,50.70,0.130
99.23,50.85,0.130
99.24,51.00,0.130
99.26,51.15,0.130
99.27,51.30,0.130
99.29,51.45,0.130
99.30,51.60,0.131
99.32,51.75,0.131
99.33,51.90,0.131
99.35,52.05,0.131
99.36,52.20,0.131
99.38,52.35,0.131
99.39,52.50,0.131
99.41,52.65,0.131
99.42,52.80,0.131
99.44,52.95,0.131
99.45,53.10,0.131
99.47,53.25,0.131
99.48,53.40,0.131
99.50,53.55,0.131
99.51,53.70,0.131
99.53,53.85,0.131
99.54,54.00,0.131
99.56,54.15,0.132
99.57,54.30,0.131
99.59,54.45,0.132
99.60,54.60,0.132
99.62,54.75,0.132
99.63,54.90,0.132
99.65,55.05,0.132
99.66,55.20,0.132
99.68,55.35,0.132
99.69,55.50,0.132
99.71,55.65,0.132
99.72,55.80,0.132
99.74,55.95,0.132
99.75,56.10,0.132
99.77,56.25,0.132
99.78,56.40,0.132
99.80,56.55,0.132
99.81,56.70,0.132
99.83,56.85,0.132
99.84,57.00,0.132
99.86,57.15,0.133
99.87,57.30,0.133
99.89,57.45,0.133
99.90,57.60,0.133
99.92,57.75,0.133
99.93,57.90,0.133
99.95,58.05,0.133
99.96,58.20,0.133
99.98,58.36,0.133
99.99,58.50,0.133
100.01,58.66,0.133
100.02,58.81,0.133
100.04,58.95,0.133
100.05,59.11,0.133
100.07,59.26,0.133
100.08,59.41,0.134
100.10,59.56,0.134
100.11,59.71,0.134
100.13,59.86,0.134
100.14,60.01,0.134
100.16,60.16,0.134
100.17,60.31,0.134
100.19,60.46,0.134
100.20,60.61,0.134
100.22,60.76,0.134
100.23,60.91,0.134
100.25,61.06,0.134
100.26,61.21,0.134
100.28,61.36,0.134
100.29,61.51,0.134
100.31,61.66,0.134
100.32,61.81,0.135
100.34,61.96,0.135
100.35,62.11,0.135
100.37,62.26,0.135
100.38,62.41,0.135
100.40,62.56,0.135
100.41,62.71,0.135
100.43,62.86,0.135
100.44,63.01,0.135
100.46,63.16,0.135
100.47,63.31,0.135
100.49,63.46,0.135
100.50,63.61,0.135
100.52,63.76,0.135
100.53,63.91,0.135
100.55,64.06,0.135
100.56,64.21,0.135
100.58,64.36,0.135
100.59,64.51,0.135
100.61,64.66,0.135
100.62,64.81,0.135
100.64,64.96,0.136
100.65,65.11,0.136
100.67,65.26,0.136
100.68,65.41,0.136
100.70,65.56,0.136
100.71,65.71,0.136
100.73,65.86,0.136
100.74,66.01,0.136
100.76,66.16,0.136
100.77,66.31,0.136
100.79,66.46,0.136
100.80,66.61,0.137
100.82,66.76,0.137
100.83,66.91,0.137
100.85,67.06,0.137
100.86,67.21,0.137
100.88,67.36,0.137
100.89,67.51,0.137
100.91,67.66,0.137
100.92,67.81,0.137
100.94,67.96,0.137
100.95,68.11,0.137
100.97,68.26,0.137
100.98,68.41,0.137
101.00,68.56,0.137
101.01,68.71,0.137
101.03,68.86,0.138
101.04,69.01,0.138
101.06,69.16,0.138
101.07,69.31,0.138
101.09,69.46,0.138
101.10,69.61,0.138
101.12,69.76,0.138
101.13,69.92,0.138
101.15,70.06,0.138
101.16,70.22,0.138
101.18,70.37,0.138
101.19,70.52,0.138
101.21,70.67,0.138
101.22,70.82,0.138
101.24,70.97,0.138
101.25,71.12,0.139
101.27,71.27,0.139
101.28,71.42,0.139
101.30,71.57,0.139
101.31,71.72,0.139
101.33,71.87,0.139
101.34,72.02,0.139
101.36,72.17,0.139
101.37,72.32,0.139
101.39,72.47,0.139
101.40,72.62,0.139
101.42,72.77,0.139
101.43,72.92,0.140
101.45,73.07,0.140
101.46,73.22,0.140
101.48,73.37,0.140
101.49,73.52,0.140
101.51,73.67,0.140
101.52,73.82,0.140
101.54,73.97,0.140
101.55,74.12,0.140
101.57,74.27,0.140
101.58,74.42,0.140
101.60,74.57,0.141
101.61,74.72,0.141
101.63,74.87,0.141
101.64,75.02,0.141
101.66,75.17,0.141
101.67,75.32,0.141
101.69,75.47,0.141
101.70,75.62,0.141
101.72,75.77,0.141
101.73,75.92,0.141
101.75,76.07,0.141
101.76,76.22,0.141
101.78,76.37,0.141
101.79,76.52,0.142
101.81,76.67,0.142
101.82,76.82,0.142
101.84,76.97,0.142
101.85,77.12,0.142
101.87,77.27,0.142
101.88,77.42,0.142
101.90,77.57,0.142
101.91,77.72,0.142
101.93,77.87,0.142
101.94,78.02,0.142
101.96,78.17,0.143
101.97,78.32,0.143
101.99,78.47,0.143
102.00,78.62,0.143
102.02,78.77,0.143
102.03,78.92,0.143
102.05,79.07,0.143
102.06,79.22,0.143
102.08,79.37,0.143
102.09,79.52,0.143
102.11,79.67,0.143
102.12,79.82,0.143
102.14,79.97,0.143
102.15,80.12,0.143
102.17,80.27,0.143
102.18,80.42,0.144
102.20,80.57,0.144
102.21,80.72,0.144
102.23,80.87,0.144
102.24,81.02,0.144
102.26,81.18,0.144
102.27,81.33,0.144
102.29,81.48,0.144
102.30,81.63,0.144
102.32,81.78,0.144
102.33,81.93,0.144
102.35,82.07,0.144
102.36,82.23,0.144
102.38,82.38,0.144
102.39,82.53,0.144
102.41,82.68,0.144
102.42,82.83,0.144
102.44,82.98,0.144
102.45,83.13,0.144
102.47,83.28,0.144
102.48,83.43,0.144
102.50,83.58,0.145
102.51,83.73,0.145
102.53,83.88,0.145
102.54,84.03,0.145
102.56,84.18,0.145
102.57,84.33,0.145
102.59,84.48,0.145
102.60,84.63,0.145
102.62,84.78,0.145
102.63,84.93,0.145
102.65,85.08,0.145
102.66,85.23,0.145
102.68,85.38,0.145
102.69,85.53,0.145
102.71,85.68,0.145
102.72,85.83,0.145
102.74,85.98,0.145
102.75,86.13,0.145
102.77,86.28,0.145
102.78,86.43,0.146
102.80,86.58,0.145
102.81,86.73,0.146
102.83,86.88,0.146
102.84,87.03,0.146
102.86,87.18,0.146
102.87,87.33,0.146
102.89,87.48,0.146
102.90,87.63,0.146
102.92,87.78,0.146
102.93,87.93,0.146
102.95,88.08,0.146
102.96,88.23,0.146
102.98,88.38,0.146
102.99,88.53,0.146
103.01,88.68,0.147
103.02,88.83,0.147
103.04,88.98,0.147
103.05,89.13,0.147
103.07,89.28,0.147
103.08,89.43,0.147
103.10,89.58,0.147
103.11,89.73,0.147
103.13,89.88,0.147
103.14,90.03,0.147
103.16,90.18,0.148
103.17,90.33,0.148
103.19,90.48,0.148
103.20,90.63,0.148
103.22,90.78,0.148
103.23,90.93,0.148
103.25,91.08,0.148
103.26,91.23,0.148
103.28,91.38,0.149
103.29,91.53,0.149
103.31,91.69,0.149
103.32,91.84,0.149
103.34,91.99,0.149
103.35,92.14,0.149
103.37,92.29,0.149
103.38,92.43,0.149
103.40,92.59,0.149
103.41,92.74,0.149
103.43,92.89,0.150
103.44,93.04,0.150
103.46,93.19,0.150
103.47,93.34,0.150
103.49,93.49,0.150
103.50,93.64,0.150
103.52,93.79,0.150
103.53,93.94,0.150
103.55,94.09,0.150
103.56,94.24,0.151
103.58,94.39,0.151
103.59,94.54,0.151
103.61,94.69,0.151
103.62,94.84,0.151
103.64,94.99,0.151
103.65,95.14,0.151
103.67,95.29,0.151
103.68,95.44,0.151
103.70,95.59,0.152
103.71,95.74,0.152
103.73,95.89,0.152
103.74,96.04,0.152
103.76,96.19,0.152
103.77,96.34,0.152
103.79,96.49,0.152
103.80,96.64,0.152
103.82,96.79,0.152
103.83,96.94,0.152
103.85,97.09,0.152
103.86,97.24,0.152
103.88,97.39,0.153
103.89,97.54,0.153
103.91,97.69,0.153
103.92,97.84,0.153
103.94,97.99,0.153
103.95,98.14,0.153
103.97,98.29,0.153
103.98,98.44,0.153
104.00,98.59,0.153
104.01,98.74,0.153
104.03,98.89,0.154
104.04,99.04,0.154
104.06,99.19,0.154
104.07,99.34,0.154
104.09,99.49,0.154
104.10,99.64,0.154
104.12,99.79,0.154
104.13,99.94,0.154
104.15,100.09,0.154
104.16,100.24,0.155
104.18,100.39,0.155
104.19,100.54,0.155
104.21,100.69,0.155
104.22,100.84,0.155
104.24,100.99,0.155
104.25,101.14,0.155
104.27,101.29,0.155
104.28,101.44,0.155
104.30,101.59,0.155
104.31,101.74,0.156
104.33,101.89,0.156
104.34,102.04,0.156
104.36,102.19,0.156
104.37,102.34,0.156
104.39,102.49,0.156
104.40,102.64,0.156
104.42,102.79,0.156
104.43,102.94,0.156
104.45,103.09,0.157
104.46,103.25,0.157
104.48,103.39,0.157
104.49,103.54,0.157
104.51,103.70,0.157
104.52,103.84,0.157
104.54,103.99,0.157
104.55,104.14,0.157
104.57,104.29,0.157
104.58,104.44,0.158
104.60,104.60,0.158
104.61,104.75,0.158
104.63,104.90,0.158
104.64,105.05,0.158
104.66,105.20,0.158
104.67,105.35,0.158
104.69,105.50,0.158
104.70,105.65,0.158
104.72,105.80,0.158
104.73,105.95,0.159
104.75,106.10,0.159
104.76,106.25,0.159
104.78,106.40,0.159
104.79,106.55,0.159
104.81,106.70,0.159
104.82,106.85,0.159
104.84,107.00,0.159
104.85,107.15,0.160
104.87,107.30,0.160
104.88,107.45,0.160
104.90,107.60,0.160
104.91,107.75,0.160
104.93,107.90,0.160
104.94,108.05,0.160
104.96,108.20,0.160
104.97,108.35,0.160
104.99,108.50,0.161
105.00,108.65,0.161
105.02,108.80,0.161
105.03,108.95,0.161
105.05,109.10,0.161
105.06,109.25,0.161
105.08,109.40,0.161
105.09,109.55,0.161
105.11,109.70,0.161
105.12,109.85,0.162
105.14,110.00,0.162
105.15,110.15,0.162
105.17,110.30,0.162
105.18,110.45,0.162
105.20,110.60,0.163
105.21,110.75,0.163
105.23,110.90,0.163
105.24,111.05,0.163
105.26,111.20,0.163
105.27,111.35,0.163
105.29,111.50,0.163
105.30,111.65,0.163
105.32,111.80,0.163
105.33,111.95,0.163
105.35,112.10,0.164
105.36,112.25,0.164
105.38,112.40,0.164
105.39,112.55,0.164
105.41,112.70,0.164
105.42,112.85,0.164
105.44,113.00,0.165
105.45,113.15,0.165
105.47,113.30,0.165
105.48,113.45,0.165
105.50,113.60,0.165
105.51,113.75,0.165
105.53,113.90,0.166
105.54,114.05,0.166
105.56,114.20,0.166
105.57,114.35,0.166
105.59,114.50,0.166
105.60,114.65,0.167
105.62,114.80,0.167
105.63,114.95,0.167
105.65,115.10,0.167
105.66,115.25,0.167
105.68,115.40,0.168
105.69,115.55,0.168
105.71,115.70,0.168
105.72,115.85,0.169
105.74,116.00,0.169
105.75,116.15,0.169
105.77,116.30,0.170
105.78,116.45,0.170
105.80,116.60,0.170
105.81,116.75,0.171
105.83,116.90,0.171
105.84,117.05,0.171
105.86,117.20,0.172
105.87,117.35,0.172
105.89,117.50,0.173
105.90,117.65,0.174
105.92,117.80,0.175
105.93,117.95,0.175
105.95,118.10,0.177
105.96,118.25,0.178
105.98,118.40,0.179
105.99,118.55,0.181
106.01,118.70,0.182
106.02,118.85,0.184
106.04,119.00,0.186
106.05,119.15,0.189
106.07,119.30,0.196
106.08,119.45,0.198
106.10,119.60,0.206
106.11,119.75,0.212
106.13,119.90,0.221
106.14,120.05,0.229
106.16,120.20,0.238
106.17,120.35,0.251
106.19,120.49,0.267
106.20,120.64,0.287
106.22,120.79,0.314
106.23,120.94,0.344
106.25,121.08,0.391
106.26,121.23,0.452
106.28,121.37,0.540
106.29,121.51,0.670
106.31,121.64,0.857
106.32,121.77,1.122
106.34,121.89,1.489
106.35,122.00,1.951
106.37,122.09,2.433
106.38,122.18,2.873
106.40,122.26,3.312
106.41,122.34,3.831
106.43,122.41,4.349
106.44,122.48,4.802
106.46,122.55,5.184
106.47,122.62,5.526
106.49,122.70,5.771
106.50,122.79,6.103
106.52,122.87,6.357
106.53,122.97,6.555
106.55,123.07,6.630
106.56,123.18,6.652
106.58,123.30,6.626
106.59,123.42,6.625
106.61,123.56,6.567
106.62,123.70,6.536
106.64,123.85,6.497
106.65,123.99,6.494
106.67,124.14,6.455
106.68,124.29,6.534
106.70,124.43,6.615
106.71,124.59,5.939
106.73,124.81,4.149
106.74,125.10,2.581
106.76,125.39,2.008
106.77,125.66,1.697
106.79,125.91,1.470
106.80,126.15,1.281
106.82,126.38,1.128
106.83,126.59,0.994
106.85,126.80,0.890
106.86,126.99,0.782
106.88,127.18,0.706
106.89,127.37,0.636
106.91,127.54,0.577
106.92,127.72,0.526
106.94,127.89,0.485
106.95,128.06,0.449
106.97,128.22,0.418
106.98,128.38,0.391
107.00,128.54,0.372
107.01,128.70,0.349
107.03,128.86,0.340
107.04,129.01,0.322
107.06,129.17,0.311
107.07,129.33,0.305
107.09,129.48,0.293
107.10,129.63,0.287
107.12,129.79,0.282
107.13,129.94,0.278
107.15,130.09,0.273
107.16,130.24,0.271
107.18,130.39,0.268
107.19,130.54,0.267
107.21,130.70,0.265
107.22,130.85,0.265
107.24,131.00,0.263
107.25,131.15,0.263
107.27,131.30,0.262
107.28,131.45,0.261
107.30,131.60,0.260
107.31,131.75,0.260
107.33,131.90,0.260
107.34,132.05,0.259
107.36,132.20,0.259
107.37,132.35,0.258
107.39,132.50,0.258
107.40,132.65,0.258
107.42,132.80,0.257
107.43,132.95,0.257
107.45,133.10,0.257
107.46,133.25,0.257
107.48,133.40,0.257
107.49,133.55,0.256
107.51,133.70,0.256
107.52,133.85,0.256
107.54,134.00,0.256
107.55,134.15,0.256
107.57,134.30,0.256
107.58,134.45,0.255
107.60,134.60,0.255
107.61,134.75,0.255
107.63,134.90,0.255
107.64,135.05,0.255
107.66,135.20,0.255
107.67,135.35,0.255
107.69,135.50,0.255
107.70,135.65,0.255
107.72,135.80,0.255
107.73,135.95,0.255
107.75,136.10,0.255
107.76,136.25,0.255
107.78,136.40,0.255
107.79,136.55,0.255
107.81,136.70,0.255
107.82,136.85,0.255
107.84,137.00,0.255
107.85,137.15,0.255
107.87,137.30,0.255
107.88,137.45,0.255
107.90,137.60,0.255
107.91,137.75,0.255
107.93,137.90,0.255
107.94,138.05,0.255
107.96,138.20,0.255
107.97,138.35,0.256
107.99,138.51,0.256
108.00,138.65,0.256
108.02,138.80,0.256
108.03,138.95,0.256
108.05,139.11,0.256
108.06,139.26,0.256
108.08,139.40,0.256
108.09,139.56,0.256
108.11,139.70,0.256
108.12,139.85,0.256
108.14,140.00,0.256
108.15,140.16,0.257
108.17,140.31,0.257
108.18,140.46,0.257
108.20,140.61,0.257
108.21,140.76,0.257
108.23,140.91,0.257
108.24,141.06,0.257
108.26,141.21,0.257
108.27,141.36,0.258
108.29,141.51,0.258
108.30,141.66,0.258
108.32,141.81,0.258
108.33,141.96,0.258
108.35,142.11,0.258
108.36,142.26,0.258
108.38,142.41,0.258
108.39,142.56,0.258
108.41,142.71,0.259
108.42,142.86,0.259
108.44,143.01,0.259
108.45,143.16,0.259
108.47,143.31,0.259
108.48,143.46,0.259
108.50,143.61,0.259
108.51,143.76,0.260
108.53,143.91,0.260
108.54,144.06,0.260
108.56,144.21,0.260
108.57,144.36,0.260
108.59,144.51,0.260
108.60,144.66,0.260
108.62,144.81,0.261
108.63,144.96,0.261
108.65,145.11,0.261
108.66,145.26,0.261
108.68,145.41,0.261
108.69,145.56,0.261
108.71,145.71,0.262
108.72,145.86,0.262
108.74,146.01,0.262
108.75,146.16,0.262
108.77,146.31,0.262
108.78,146.46,0.262
108.80,146.61,0.262
108.81,146.76,0.262
108.83,146.91,0.262
108.84,147.06,0.263
108.86,147.21,0.263
108.87,147.36,0.263
108.89,147.51,0.263
108.90,147.66,0.263
108.92,147.81,0.263
108.93,147.96,0.263
108.95,148.11,
108.96,148.26,
108.98,148.41,
108.99,,