File: DSC/2025_04_11_Indium_Std_10Cmin_n60C_200C.csv
Filename,2025_04_11_Indium_Std_10Cmin_n60C_200C
Instrument name,DSC2A-00468 (192.168.1.100)
Operator,Yarger
rundate,4/11/2025
Sample name,2025_04_11_Indium_Std_10Cmin_n60C_200C
proceduresegments,Data Off ; Equilibrate -60.00 °C; Data On ; Ramp 10.00 °C/min to 200.00 °C; Data Off ; Isothermal 1.0 min; Data On ; Ramp 10.00 °C/min to -60.00 °C; Data Off ; Isothermal 1.0 min; Data On ; Ramp 10.00 °C/min to 200.00 °C; Data Off ; Isothermal 1.0 min; Data On ; Ramp 10.00 °C/min to -60.00 °C; Data Off ; Isothermal 1.0 min; Data On ; Ramp 10.00 °C/min to 200.00 °C
[File Parameters]
Run date,4/11/2025 7:50:54 PM
Trios version,5.1.1.46572
Original File Name,
Current File Name,D:\DSC2500\JYarger\2025_04_11_Indium_Std_10Cmin_n60C_200C.tri
[Procedure]
Procedure Name,Indium_n60_200C_10Cmin_x3
Sample Name,2025_04_11_Indium_Std_10Cmin_n60C_200C
Sample Mass,3.36 mg
Reference Sample Mass,0 mg
Pan Mass,53.42 mg
Pan Number,9
Reference Pan Mass,53.32 mg
Reference Pan Number,10
Pan Type,Tzero Aluminum Hermetic
Comments,Hermetic Sealed Al DSC Consumables Pan/Lids.
Project Name,CA
Operator,Yarger
Test,Custom
Unload Max Temperature,30
Unload Min Temperature,30
Load Max Temperature,30
Load Min Temperature,30
Stop on Gas Flow Error,Yes
[Signal List]
Signal #1,Time (min)
Signal #2,Temperature (°C)
Signal #3,Heat Flow (mW)
Signal #4,Delta T (µV)
Signal #5,Delta Tzero (µV)
Signal #6,Tzero Temperature (°C)
Signal #7,Cell Purge (mL/min)
Signal #8,Heater Temp (°C)
Signal #9,Power Delivered (W)
Signal #10,Reference Junction Temperature (°C)
Signal #11,Flange Temperature (°C)
Signal #12,Heat Flow Phase (rad)
Signal #13,Total Heat Capacity (J/°C)
Signal #14,Heat Capacity (J/°C)
[Configuration]
Company Name,ASU
Instrument Name,DSC2A-00468
Instrument Type,DSC2500
Serial Number,DSC2A-00468
IP,192.168.1.100
Location of Instrument,MRRC
DisplayType,Unknown
Sample Interval ,0.1 s/pt
Selected Heat Flow,T4P
Exotherm Direction,Down
Cell Serial,DRC2-00792
Lid Type,Standard
Cooler,RCS 90
Leave Cooler on at End of Sequence,On
Gas 2,Nitrogen
Gas Selected,Channel 1
Flow Rate,50 mL/min
Secondary Purge,On
Licensed Heat Flow,Heat Flow T4P
Modulation Licensed,Yes
[Versions]
Common IDD Version,1
Cortex Version,VER 2.10.2.31
Driver,5.0.0.6
GDM Version,1.0.3.3
TouchscreenVersion,1.0.0.16145
FEP Version,1.2.1.21
FEP Bootloader,2.0.0.5
AutoSampler Version,2.1.1.26
Auto Sampler Bootloader,2.0.0.5
FCM Version,1.1.0.3
FCM Bootloader,2.0.0.5
[Experiment Logs]
Experiment Log Entry # 1,Data On set to 0
Experiment Log Entry # 3,Equilibrate Segment -60 (C) Started
Experiment Log Entry # 5,Data On set to 1
Experiment Log Entry # 7,Ramp Segment 10 C/min to 200 Started
Experiment Log Entry # 9,Data On set to 0
Experiment Log Entry # 11,Isothermal Segment 1 min started
Experiment Log Entry # 13,Data On set to 1
Experiment Log Entry # 15,Ramp Segment 10 C/min to -60 Started
Experiment Log Entry # 17,Data On set to 0
Experiment Log Entry # 19,Isothermal Segment 1 min started
Experiment Log Entry # 21,Data On set to 1
Experiment Log Entry # 23,Ramp Segment 10 C/min to 200 Started
Experiment Log Entry # 25,Data On set to 0
Experiment Log Entry # 27,Isothermal Segment 1 min started
Experiment Log Entry # 29,Data On set to 1
Experiment Log Entry # 31,Ramp Segment 10 C/min to -60 Started
Experiment Log Entry # 33,Data On set to 0
Experiment Log Entry # 35,Isothermal Segment 1 min started
Experiment Log Entry # 37,Data On set to 1
Experiment Log Entry # 39,Ramp Segment 10 C/min to 200 Started
[Method Log]
Method Log Entry # 1,Data Off
Method Log Entry # 2,Equilibrate -60 °C
Method Log Entry # 3,Data On
Method Log Entry # 4,(Ramp 39942) Ramp 10 °C/minute to 200 °C
Method Log Entry # 5,Data Off
Method Log Entry # 6,Isothermal 1 minutes
Method Log Entry # 7,Data On
Method Log Entry # 8,(Ramp 39946) Ramp 10 °C/minute to -60 °C
Method Log Entry # 9,Data Off
Method Log Entry # 10,Isothermal 1 minutes
Method Log Entry # 11,Data On
Method Log Entry # 12,(Ramp 39950) Ramp 10 °C/minute to 200 °C
Method Log Entry # 13,Data Off
Method Log Entry # 14,Isothermal 1 minutes
Method Log Entry # 15,Data On
Method Log Entry # 16,(Ramp 39954) Ramp 10 °C/minute to -60 °C
Method Log Entry # 17,Data Off
Method Log Entry # 18,Isothermal 1 minutes
Method Log Entry # 19,Data On
Method Log Entry # 20,(Ramp 39958) Ramp 10 °C/minute to 200 °C
Cell Serial,DRC2-00792
[T1 Calibration]
Slope,-0.008529666
Offset,9.636258
Initial Temperature,98.23
GUID,f8bfdadc-4977-4fdf-ba6d-0ba9134940c3
[TZero Calibration]
Date Applied,11/29/2022 4:06:13 PM
Description,From -89.059 °C to 396.009 °C at 20.000°C/min
Gas Type,Nitrogen
Pan Type,None
Source Files 1,C:\Users\yargerlab\Desktop\DSC Data\General\TZero_calibration_11_29_22_2nd(2).tri
Source Files 2,C:\Users\yargerlab\Desktop\DSC Data\General\TZero_calibration_11_29_22_2nd(3).tri
Delta T Offset,13.05235
Delta T Slope,-0.007271007
Delta T0 Offset,-13.69128
Delta T0 Slope,0.06063341
[Temperature Calibration]
Date Applied,11/29/2022 7:12:28 PM
Description,From 106.590 °C to 186.590 °C at 10.000°C/min
Gas Type,Nitrogen
Pan Type,Tzero Aluminum Hermetic
Source Files 1,C:\Users\yargerlab\Desktop\DSC Data\General\Indium(6).tri
Measured 1,157.391
Known 1,156.598
[Cell Constant Calibration]
Date Applied,11/29/2022 7:12:29 PM
Description,From 106.590 °C to 186.590 °C at 10.000°C/min
Gas Type,Nitrogen
Pan Type,Tzero Aluminum Hermetic
Source Files 1,C:\Users\yargerlab\Desktop\DSC Data\General\Indium(6).tri
T4P KCell,1.006051
Onset Slope,63.26126 mW/°C
[Direct Cp Calibration]
Date Applied,11/30/2022 11:04:51 AM
Description,From -79.983 °C to 298.409 °C at 10.000°C/min
Gas Type,Nitrogen
Pan Type,Tzero Aluminum Hermetic
Source Files 1,C:\Users\yargerlab\Desktop\DSC Data\General\Sapphire_Heat_Capacity_11_30_22.tri
[Rev Cp Calibration]
Date Applied,11/30/2022 1:58:51 PM
Description,From -79.996 °C to 292.812 °C at 3.000°C/min
Gas Type,Nitrogen
Pan Type,Tzero Aluminum Hermetic
Source Files 1,C:\Users\yargerlab\Desktop\DSC Data\General\Sapphire_MDSC_Calibration_11_30_22.tri
[step]
Ramp 10.00 °C/min to 200.00 °C
Time,Temperature,Heat Flow (Normalized)
min,°C,W/g
0.00,-59.71,-0.030
0.02,-59.72,-0.029
0.04,-59.73,-0.027
0.05,-59.73,-0.021
0.07,-59.71,-0.011
0.09,-59.67,0.000
0.11,-59.62,0.013
0.13,-59.54,0.025
0.15,-59.45,0.036
0.16,-59.34,0.048
0.18,-59.21,0.056
0.20,-59.08,0.066
0.22,-58.93,0.074
0.24,-58.78,0.078
0.26,-58.63,0.084
0.28,-58.47,0.089
0.29,-58.30,0.092
0.31,-58.14,0.094
0.33,-57.97,0.096
0.35,-57.80,0.098
0.37,-57.63,0.099
0.39,-57.46,0.100
0.40,-57.29,0.101
0.42,-57.11,0.102
0.44,-56.94,0.103
0.46,-56.77,0.103
0.48,-56.59,0.104
0.50,-56.41,0.105
0.51,-56.24,0.105
0.53,-56.06,0.106
0.55,-55.88,0.106
0.57,-55.71,0.106
0.59,-55.53,0.107
0.60,-55.35,0.107
0.62,-55.17,0.107
0.64,-54.99,0.108
0.66,-54.81,0.108
0.68,-54.63,0.108
0.70,-54.45,0.108
0.72,-54.28,0.109
0.73,-54.09,0.109
0.75,-53.91,0.109
0.77,-53.74,0.109
0.79,-53.56,0.109
0.81,-53.37,0.109
0.83,-53.19,0.110
0.84,-53.01,0.110
0.86,-52.83,0.110
0.88,-52.65,0.110
0.90,-52.47,0.110
0.92,-52.29,0.110
0.93,-52.11,0.110
0.95,-51.93,0.110
0.97,-51.75,0.110
0.99,-51.57,0.110
1.01,-51.38,0.110
1.03,-51.20,0.110
1.05,-51.02,0.110
1.06,-50.84,0.110
1.08,-50.66,0.110
1.10,-50.48,0.110
1.12,-50.29,0.110
1.14,-50.11,0.110
1.16,-49.93,0.110
1.17,-49.75,0.110
1.19,-49.56,0.110
1.21,-49.38,0.110
1.23,-49.20,0.110
1.25,-49.01,0.110
1.27,-48.83,0.110
1.28,-48.65,0.110
1.30,-48.47,0.110
1.32,-48.29,0.110
1.34,-48.10,0.110
1.36,-47.92,0.110
1.38,-47.74,0.109
1.39,-47.56,0.109
1.41,-47.37,0.109
1.43,-47.19,0.109
1.45,-47.01,0.109
1.47,-46.82,0.109
1.48,-46.64,0.109
1.50,-46.46,0.109
1.52,-46.28,0.109
1.54,-46.09,0.109
1.56,-45.91,0.109
1.58,-45.73,0.109
1.59,-45.54,0.109
1.61,-45.36,0.108
1.63,-45.18,0.108
1.65,-45.00,0.108
1.67,-44.81,0.108
1.69,-44.63,0.108
1.71,-44.44,0.108
1.72,-44.26,0.108
1.74,-44.08,0.108
1.76,-43.89,0.108
1.78,-43.71,0.108
1.80,-43.53,0.108
1.82,-43.35,0.107
1.83,-43.16,0.107
1.85,-42.98,0.107
1.87,-42.80,0.107
1.89,-42.61,0.107
1.91,-42.43,0.107
1.93,-42.24,0.107
1.94,-42.06,0.107
1.96,-41.88,0.107
1.98,-41.69,0.107
2.00,-41.51,0.107
2.02,-41.33,0.107
2.03,-41.14,0.106
2.05,-40.96,0.106
2.07,-40.78,0.106
2.09,-40.59,0.106
2.11,-40.41,0.106
2.13,-40.23,0.106
2.14,-40.04,0.106
2.16,-39.86,0.106
2.18,-39.68,0.106
2.20,-39.49,0.106
2.22,-39.31,0.106
2.24,-39.12,0.106
2.26,-38.94,0.106
2.27,-38.76,0.105
2.29,-38.57,0.105
2.31,-38.39,0.105
2.33,-38.21,0.105
2.35,-38.02,0.105
2.36,-37.84,0.105
2.38,-37.66,0.105
2.40,-37.47,0.105
2.42,-37.29,0.105
2.44,-37.11,0.105
2.46,-36.92,0.105
2.48,-36.74,0.104
2.49,-36.55,0.104
2.51,-36.37,0.104
2.53,-36.19,0.104
2.55,-36.00,0.104
2.57,-35.82,0.104
2.59,-35.64,0.104
2.60,-35.45,0.104
2.62,-35.27,0.104
2.64,-35.09,0.104
2.66,-34.90,0.104
2.68,-34.72,0.104
2.69,-34.54,0.103
2.71,-34.35,0.103
2.73,-34.17,0.103
2.75,-33.98,0.103
2.77,-33.80,0.103
2.79,-33.62,0.103
2.81,-33.43,0.103
2.82,-33.25,0.103
2.84,-33.07,0.103
2.86,-32.88,0.103
2.88,-32.70,0.103
2.90,-32.51,0.103
2.91,-32.33,0.103
2.93,-32.15,0.103
2.95,-31.97,0.103
2.97,-31.78,0.102
2.99,-31.60,0.102
3.01,-31.41,0.102
3.03,-31.23,0.102
3.04,-31.05,0.102
3.06,-30.86,0.102
3.08,-30.68,0.102
3.10,-30.50,0.102
3.12,-30.31,0.102
3.14,-30.13,0.102
3.15,-29.95,0.102
3.17,-29.76,0.102
3.19,-29.58,0.102
3.21,-29.39,0.102
3.23,-29.21,0.102
3.24,-29.03,0.102
3.26,-28.84,0.101
3.28,-28.66,0.101
3.30,-28.48,0.102
3.32,-28.29,0.101
3.34,-28.11,0.101
3.36,-27.93,0.101
3.37,-27.74,0.101
3.39,-27.56,0.101
3.41,-27.38,0.101
3.43,-27.19,0.101
3.45,-27.01,0.101
3.46,-26.82,0.101
3.48,-26.64,0.101
3.50,-26.46,0.101
3.52,-26.27,0.101
3.54,-26.09,0.101
3.56,-25.91,0.101
3.58,-25.72,0.101
3.59,-25.54,0.101
3.61,-25.36,0.101
3.63,-25.17,0.101
3.65,-24.99,0.101
3.67,-24.81,0.100
3.69,-24.62,0.100
3.70,-24.44,0.100
3.72,-24.25,0.100
3.74,-24.07,0.100
3.76,-23.89,0.100
3.78,-23.70,0.100
3.79,-23.52,0.100
3.81,-23.34,0.100
3.83,-23.15,0.100
3.85,-22.97,0.100
3.87,-22.79,0.100
3.89,-22.60,0.100
3.91,-22.42,0.100
3.92,-22.24,0.099
3.94,-22.05,0.099
3.96,-21.87,0.099
3.98,-21.69,0.099
4.00,-21.50,0.099
4.01,-21.32,0.099
4.03,-21.14,0.099
4.05,-20.95,0.099
4.07,-20.77,0.099
4.09,-20.59,0.099
4.11,-20.40,0.099
4.13,-20.22,0.099
4.14,-20.03,0.099
4.16,-19.85,0.098
4.18,-19.67,0.098
4.20,-19.48,0.098
4.22,-19.30,0.098
4.24,-19.12,0.098
4.25,-18.93,0.098
4.27,-18.75,0.098
4.29,-18.56,0.098
4.31,-18.38,0.098
4.33,-18.20,0.098
4.35,-18.01,0.098
4.36,-17.83,0.098
4.38,-17.64,0.098
4.40,-17.46,0.098
4.42,-17.28,0.098
4.44,-17.09,0.098
4.45,-16.91,0.098
4.47,-16.73,0.098
4.49,-16.54,0.098
4.51,-16.36,0.097
4.53,-16.18,0.097
4.55,-15.99,0.097
4.56,-15.81,0.097
4.58,-15.62,0.097
4.60,-15.44,0.097
4.62,-15.26,0.097
4.64,-15.07,0.097
4.66,-14.89,0.097
4.68,-14.71,0.097
4.69,-14.52,0.097
4.71,-14.34,0.097
4.73,-14.16,0.097
4.75,-13.97,0.097
4.77,-13.79,0.097
4.79,-13.60,0.097
4.80,-13.42,0.097
4.82,-13.24,0.097
4.84,-13.06,0.097
4.86,-12.87,0.097
4.88,-12.69,0.097
4.90,-12.50,0.097
4.91,-12.32,0.097
4.93,-12.14,0.096
4.95,-11.95,0.096
4.97,-11.77,0.096
4.99,-11.59,0.096
5.00,-11.40,0.096
5.02,-11.22,0.096
5.04,-11.04,0.096
5.06,-10.85,0.096
5.08,-10.67,0.096
5.10,-10.49,0.096
5.11,-10.30,0.096
5.13,-10.12,0.096
5.15,-9.94,0.096
5.17,-9.75,0.096
5.19,-9.57,0.096
5.21,-9.38,0.096
5.23,-9.20,0.096
5.24,-9.02,0.096
5.26,-8.83,0.096
5.28,-8.65,0.096
5.30,-8.47,0.096
5.32,-8.28,0.096
5.34,-8.10,0.096
5.35,-7.92,0.096
5.37,-7.73,0.096
5.39,-7.55,0.096
5.41,-7.36,0.096
5.43,-7.18,0.096
5.45,-7.00,0.096
5.46,-6.81,0.096
5.48,-6.63,0.096
5.50,-6.45,0.096
5.52,-6.26,0.096
5.54,-6.08,0.096
5.55,-5.90,0.096
5.57,-5.71,0.096
5.59,-5.53,0.096
5.61,-5.35,0.096
5.63,-5.16,0.096
5.65,-4.98,0.096
5.66,-4.79,0.096
5.68,-4.61,0.096
5.70,-4.43,0.096
5.72,-4.24,0.096
5.74,-4.06,0.096
5.76,-3.88,0.096
5.78,-3.69,0.096
5.79,-3.51,0.096
5.81,-3.33,0.096
5.83,-3.14,0.096
5.85,-2.96,0.096
5.87,-2.77,0.096
5.89,-2.59,0.096
5.90,-2.41,0.096
5.92,-2.22,0.096
5.94,-2.04,0.096
5.96,-1.86,0.096
5.98,-1.67,0.096
6.00,-1.49,0.096
6.01,-1.31,0.096
6.03,-1.12,0.096
6.05,-0.94,0.096
6.07,-0.76,0.096
6.09,-0.57,0.095
6.10,-0.39,0.096
6.12,-0.21,0.095
6.14,-0.02,0.095
6.16,0.16,0.095
6.18,0.34,0.095
6.20,0.53,0.095
6.21,0.71,0.095
6.23,0.89,0.095
6.25,1.08,0.095
6.27,1.26,0.095
6.29,1.45,0.095
6.31,1.63,0.095
6.33,1.81,0.095
6.34,2.00,0.095
6.36,2.18,0.095
6.38,2.36,0.095
6.40,2.55,0.095
6.42,2.73,0.095
6.44,2.92,0.095
6.45,3.10,0.095
6.47,3.28,0.095
6.49,3.47,0.095
6.51,3.65,0.095
6.53,3.83,0.095
6.55,4.02,0.095
6.56,4.20,0.095
6.58,4.38,0.095
6.60,4.57,0.095
6.62,4.75,0.095
6.64,4.94,0.096
6.65,5.12,0.096
6.67,5.30,0.096
6.69,5.48,0.096
6.71,5.67,0.096
6.73,5.85,0.096
6.75,6.04,0.096
6.76,6.22,0.096
6.78,6.41,0.096
6.80,6.59,0.096
6.82,6.77,0.096
6.84,6.95,0.096
6.86,7.14,0.096
6.88,7.32,0.096
6.89,7.50,0.096
6.91,7.69,0.096
6.93,7.87,0.096
6.95,8.06,0.096
6.97,8.24,0.096
6.99,8.42,0.096
7.00,8.61,0.096
7.02,8.79,0.096
7.04,8.97,0.096
7.06,9.16,0.096
7.08,9.34,0.096
7.10,9.52,0.096
7.11,9.71,0.096
7.13,9.89,0.096
7.15,10.07,0.096
7.17,10.26,0.096
7.19,10.44,0.096
7.20,10.63,0.096
7.22,10.81,0.096
7.24,10.99,0.096
7.26,11.18,0.096
7.28,11.36,0.096
7.30,11.54,0.096
7.31,11.73,0.096
7.33,11.91,0.096
7.35,12.09,0.096
7.37,12.28,0.096
7.39,12.46,0.096
7.41,12.65,0.096
7.43,12.83,0.096
7.44,13.01,0.096
7.46,13.20,0.096
7.48,13.38,0.096
7.50,13.56,0.096
7.52,13.75,0.096
7.54,13.93,0.096
7.55,14.11,0.096
7.57,14.30,0.097
7.59,14.48,0.097
7.61,14.66,0.097
7.63,14.85,0.097
7.65,15.03,0.097
7.66,15.22,0.097
7.68,15.40,0.097
7.70,15.58,0.097
7.72,15.77,0.097
7.74,15.95,0.097
7.75,16.13,0.097
7.77,16.32,0.097
7.79,16.50,0.097
7.81,16.68,0.097
7.83,16.87,0.097
7.85,17.05,0.097
7.86,17.23,0.097
7.88,17.42,0.097
7.90,17.60,0.097
7.92,17.79,0.097
7.94,17.97,0.097
7.96,18.15,0.097
7.98,18.34,0.097
7.99,18.52,0.097
8.01,18.70,0.097
8.03,18.89,0.097
8.05,19.07,0.097
8.07,19.25,0.097
8.09,19.44,0.097
8.10,19.62,0.097
8.12,19.80,0.097
8.14,19.99,0.097
8.16,20.17,0.097
8.18,20.35,0.097
8.20,20.54,0.097
8.21,20.72,0.097
8.23,20.90,0.097
8.25,21.09,0.097
8.27,21.27,0.097
8.29,21.45,0.097
8.30,21.64,0.097
8.32,21.82,0.097
8.34,22.00,0.097
8.36,22.19,0.097
8.38,22.37,0.097
8.40,22.56,0.097
8.41,22.74,0.097
8.43,22.92,0.097
8.45,23.11,0.097
8.47,23.29,0.097
8.49,23.47,0.097
8.51,23.66,0.097
8.53,23.84,0.097
8.54,24.02,0.097
8.56,24.21,0.097
8.58,24.39,0.097
8.60,24.58,0.097
8.62,24.76,0.097
8.63,24.94,0.097
8.65,25.13,0.097
8.67,25.31,0.097
8.69,25.49,0.097
8.71,25.68,0.097
8.73,25.86,0.097
8.75,26.05,0.097
8.76,26.23,0.097
8.78,26.41,0.097
8.80,26.60,0.097
8.82,26.78,0.097
8.84,26.96,0.097
8.85,27.15,0.097
8.87,27.33,0.097
8.89,27.51,0.097
8.91,27.70,0.097
8.93,27.88,0.097
8.95,28.06,0.097
8.97,28.25,0.098
8.98,28.43,0.098
9.00,28.61,0.098
9.02,28.80,0.098
9.04,28.98,0.098
9.06,29.16,0.098
9.08,29.35,0.098
9.09,29.53,0.098
9.11,29.72,0.098
9.13,29.90,0.098
9.15,30.08,0.098
9.17,30.26,0.098
9.18,30.45,0.098
9.20,30.63,0.098
9.22,30.82,0.098
9.24,31.00,0.098
9.26,31.18,0.098
9.28,31.37,0.098
9.30,31.55,0.098
9.31,31.73,0.098
9.33,31.92,0.098
9.35,32.10,0.098
9.37,32.28,0.098
9.39,32.47,0.098
9.40,32.65,0.098
9.42,32.84,0.098
9.44,33.02,0.098
9.46,33.20,0.098
9.48,33.39,0.098
9.50,33.57,0.098
9.52,33.75,0.098
9.53,33.94,0.098
9.55,34.12,0.098
9.57,34.30,0.098
9.59,34.49,0.098
9.61,34.67,0.098
9.63,34.86,0.098
9.64,35.04,0.098
9.66,35.22,0.098
9.68,35.40,0.098
9.70,35.59,0.098
9.72,35.77,0.098
9.73,35.95,0.098
9.75,36.14,0.098
9.77,36.32,0.098
9.79,36.50,0.098
9.81,36.69,0.098
9.83,36.87,0.098
9.85,37.06,0.098
9.86,37.24,0.098
9.88,37.42,0.098
9.90,37.61,0.098
9.92,37.79,0.098
9.94,37.98,0.098
9.95,38.16,0.098
9.97,38.34,0.098
9.99,38.53,0.098
10.01,38.71,0.098
10.03,38.89,0.099
10.05,39.08,0.098
10.07,39.26,0.098
10.08,39.44,0.098
10.10,39.63,0.098
10.12,39.81,0.098
10.14,39.99,0.098
10.16,40.18,0.099
10.18,40.36,0.099
10.19,40.54,0.099
10.21,40.73,0.099
10.23,40.91,0.099
10.25,41.09,0.099
10.27,41.28,0.099
10.28,41.46,0.099
10.30,41.65,0.099
10.32,41.83,0.099
10.34,42.01,0.099
10.36,42.20,0.099
10.38,42.38,0.099
10.40,42.56,0.099
10.41,42.75,0.099
10.43,42.93,0.099
10.45,43.11,0.099
10.47,43.30,0.099
10.49,43.48,0.099
10.50,43.66,0.099
10.52,43.85,0.099
10.54,44.03,0.099
10.56,44.21,0.099
10.58,44.40,0.099
10.60,44.58,0.099
10.62,44.77,0.099
10.63,44.95,0.099
10.65,45.13,0.099
10.67,45.32,0.099
10.69,45.50,0.099
10.71,45.68,0.099
10.73,45.87,0.099
10.74,46.05,0.099
10.76,46.23,0.099
10.78,46.42,0.099
10.80,46.60,0.099
10.82,46.78,0.099
10.83,46.97,0.099
10.85,47.15,0.099
10.87,47.33,0.099
10.89,47.52,0.099
10.91,47.70,0.100
10.93,47.89,0.099
10.95,48.07,0.100
10.96,48.25,0.100
10.98,48.43,0.100
11.00,48.62,0.100
11.02,48.80,0.100
11.04,48.99,0.100
11.05,49.17,0.100
11.07,49.35,0.100
11.09,49.54,0.100
11.11,49.72,0.100
11.13,49.90,0.100
11.15,50.09,0.100
11.17,50.27,0.100
11.18,50.46,0.100
11.20,50.64,0.100
11.22,50.82,0.100
11.24,51.01,0.100
11.26,51.19,0.100
11.28,51.37,0.100
11.29,51.56,0.100
11.31,51.74,0.100
11.33,51.92,0.100
11.35,52.11,0.100
11.37,52.29,0.100
11.38,52.47,0.100
11.40,52.66,0.100
11.42,52.84,0.100
11.44,53.02,0.100
11.46,53.21,0.101
11.48,53.39,0.100
11.50,53.58,0.100
11.51,53.76,0.101
11.53,53.94,0.101
11.55,54.13,0.100
11.57,54.31,0.101
11.59,54.49,0.101
11.60,54.68,0.101
11.62,54.86,0.101
11.64,55.04,0.101
11.66,55.23,0.101
11.68,55.41,0.101
11.70,55.59,0.101
11.72,55.78,0.101
11.73,55.96,0.101
11.75,56.15,0.101
11.77,56.33,0.101
11.79,56.51,0.101
11.81,56.70,0.101
11.83,56.88,0.101
11.84,57.06,0.101
11.86,57.25,0.101
11.88,57.43,0.101
11.90,57.61,0.101
11.92,57.80,0.101
11.93,57.98,0.101
11.95,58.16,0.101
11.97,58.35,0.101
11.99,58.53,0.101
12.01,58.72,0.101
12.03,58.90,0.101
12.05,59.08,0.101
12.06,59.27,0.101
12.08,59.45,0.101
12.10,59.63,0.101
12.12,59.82,0.101
12.14,60.00,0.102
12.15,60.18,0.102
12.17,60.37,0.102
12.19,60.55,0.102
12.21,60.73,0.102
12.23,60.92,0.102
12.25,61.10,0.102
12.27,61.29,0.102
12.28,61.47,0.102
12.30,61.65,0.102
12.32,61.84,0.102
12.34,62.02,0.102
12.36,62.20,0.102
12.38,62.39,0.102
12.39,62.57,0.102
12.41,62.75,0.102
12.43,62.94,0.102
12.45,63.12,0.102
12.47,63.30,0.102
12.48,63.49,0.102
12.50,63.67,0.102
12.52,63.85,0.102
12.54,64.04,0.102
12.56,64.22,0.102
12.58,64.40,0.102
12.60,64.59,0.103
12.61,64.77,0.103
12.63,64.96,0.102
12.65,65.14,0.102
12.67,65.32,0.103
12.69,65.51,0.103
12.70,65.69,0.103
12.72,65.87,0.103
12.74,66.06,0.103
12.76,66.24,0.103
12.78,66.42,0.103
12.80,66.61,0.103
12.82,66.79,0.103
12.83,66.97,0.103
12.85,67.16,0.103
12.87,67.34,0.103
12.89,67.52,0.103
12.91,67.71,0.103
12.93,67.89,0.103
12.94,68.07,0.103
12.96,68.26,0.103
12.98,68.44,0.103
13.00,68.62,0.103
13.02,68.81,0.103
13.03,68.99,0.103
13.05,69.18,0.103
13.07,69.36,0.103
13.09,69.54,0.103
13.11,69.73,0.103
13.13,69.91,0.103
13.15,70.09,0.103
13.16,70.28,0.104
13.18,70.46,0.104
13.20,70.64,0.103
13.22,70.83,0.104
13.24,71.01,0.104
13.25,71.19,0.104
13.27,71.38,0.104
13.29,71.56,0.104
13.31,71.74,0.104
13.33,71.93,0.104
13.35,72.11,0.104
13.37,72.29,0.104
13.38,72.48,0.104
13.40,72.66,0.104
13.42,72.85,0.104
13.44,73.03,0.104
13.46,73.21,0.104
13.48,73.40,0.104
13.49,73.58,0.104
13.51,73.76,0.104
13.53,73.95,0.104
13.55,74.13,0.104
13.57,74.31,0.104
13.58,74.50,0.104
13.60,74.68,0.104
13.62,74.86,0.104
13.64,75.05,0.104
13.66,75.23,0.104
13.68,75.41,0.104
13.70,75.60,0.105
13.71,75.78,0.105
13.73,75.96,0.105
13.75,76.15,0.105
13.77,76.33,0.105
13.79,76.51,0.105
13.80,76.70,0.105
13.82,76.88,0.105
13.84,77.07,0.105
13.86,77.25,0.105
13.88,77.43,0.105
13.90,77.62,0.105
13.92,77.80,0.105
13.93,77.98,0.105
13.95,78.17,0.105
13.97,78.35,0.105
13.99,78.54,0.105
14.01,78.72,0.105
14.03,78.90,0.105
14.04,79.08,0.105
14.06,79.27,0.105
14.08,79.45,0.105
14.10,79.63,0.105
14.12,79.82,0.105
14.13,80.00,0.105
14.15,80.19,0.105
14.17,80.37,0.105
14.19,80.55,0.105
14.21,80.74,0.105
14.23,80.92,0.105
14.25,81.10,0.105
14.26,81.29,0.105
14.28,81.47,0.106
14.30,81.65,0.105
14.32,81.84,0.106
14.34,82.02,0.105
14.35,82.20,0.105
14.37,82.39,0.106
14.39,82.57,0.105
14.41,82.75,0.105
14.43,82.94,0.105
14.45,83.12,0.105
14.47,83.31,0.105
14.48,83.49,0.105
14.50,83.67,0.105
14.52,83.86,0.105
14.54,84.04,0.105
14.56,84.22,0.105
14.58,84.41,0.105
14.59,84.59,0.105
14.61,84.77,0.105
14.63,84.96,0.105
14.65,85.14,0.105
14.67,85.32,0.105
14.68,85.51,0.105
14.70,85.69,0.105
14.72,85.87,0.105
14.74,86.06,0.105
14.76,86.24,0.105
14.78,86.43,0.105
14.80,86.61,0.105
14.81,86.79,0.105
14.83,86.98,0.105
14.85,87.16,0.105
14.87,87.34,0.105
14.89,87.53,0.105
14.90,87.71,0.106
14.92,87.89,0.106
14.94,88.08,0.106
14.96,88.26,0.106
14.98,88.44,0.106
15.00,88.63,0.106
15.02,88.81,0.106
15.03,88.99,0.106
15.05,89.18,0.106
15.07,89.36,0.106
15.09,89.55,0.106
15.11,89.73,0.106
15.13,89.91,0.106
15.14,90.10,0.106
15.16,90.28,0.106
15.18,90.46,0.106
15.20,90.65,0.106
15.22,90.83,0.107
15.23,91.01,0.107
15.25,91.20,0.107
15.27,91.38,0.107
15.29,91.56,0.107
15.31,91.74,0.107
15.33,91.93,0.107
15.35,92.11,0.107
15.36,92.30,0.107
15.38,92.48,0.107
15.40,92.66,0.107
15.42,92.85,0.107
15.44,93.03,0.107
15.45,93.21,0.108
15.47,93.40,0.108
15.49,93.58,0.108
15.51,93.76,0.108
15.53,93.95,0.108
15.55,94.13,0.108
15.57,94.32,0.108
15.58,94.50,0.108
15.60,94.68,0.108
15.62,94.87,0.108
15.64,95.05,0.108
15.66,95.23,0.108
15.68,95.42,0.108
15.69,95.60,0.109
15.71,95.78,0.109
15.73,95.97,0.109
15.75,96.15,0.109
15.77,96.33,0.109
15.78,96.52,0.109
15.80,96.70,0.109
15.82,96.89,0.109
15.84,97.07,0.109
15.86,97.25,0.109
15.88,97.44,0.109
15.90,97.62,0.109
15.91,97.80,0.109
15.93,97.99,0.110
15.95,98.17,0.110
15.97,98.35,0.110
15.99,98.54,0.110
16.00,98.72,0.110
16.02,98.90,0.110
16.04,99.09,0.110
16.06,99.27,0.110
16.08,99.45,0.110
16.10,99.64,0.110
16.12,99.82,0.110
16.13,100.00,0.110
16.15,100.19,0.110
16.17,100.37,0.111
16.19,100.55,0.111
16.21,100.74,0.111
16.23,100.92,0.111
16.24,101.11,0.111
16.26,101.29,0.111
16.28,101.47,0.111
16.30,101.66,0.111
16.32,101.84,0.111
16.33,102.02,0.111
16.35,102.21,0.111
16.37,102.39,0.111
16.39,102.57,0.111
16.41,102.76,0.112
16.43,102.94,0.112
16.45,103.12,0.112
16.46,103.31,0.112
16.48,103.49,0.112
16.50,103.67,0.112
16.52,103.86,0.112
16.54,104.04,0.112
16.55,104.22,0.112
16.57,104.41,0.112
16.59,104.59,0.112
16.61,104.78,0.112
16.63,104.96,0.112
16.65,105.14,0.112
16.67,105.33,0.112
16.68,105.51,0.112
16.70,105.69,0.112
16.72,105.88,0.112
16.74,106.06,0.112
16.76,106.24,0.113
16.78,106.43,0.113
16.79,106.61,0.113
16.81,106.79,0.113
16.83,106.98,0.113
16.85,107.16,0.113
16.87,107.34,0.113
16.88,107.53,0.113
16.90,107.71,0.113
16.92,107.89,0.113
16.94,108.08,0.113
16.96,108.26,0.113
16.98,108.44,0.113
17.00,108.63,0.113
17.01,108.81,0.113
17.03,108.99,0.113
17.05,109.18,0.114
17.07,109.36,0.114
17.09,109.55,0.114
17.11,109.73,0.114
17.12,109.91,0.114
17.14,110.10,0.114
17.16,110.28,0.114
17.18,110.46,0.114
17.20,110.65,0.114
17.22,110.83,0.114
17.23,111.01,0.114
17.25,111.20,0.114
17.27,111.38,0.114
17.29,111.56,0.114
17.31,111.75,0.114
17.33,111.93,0.114
17.34,112.11,0.114
17.36,112.30,0.114
17.38,112.48,0.115
17.40,112.66,0.115
17.42,112.85,0.115
17.43,113.03,0.115
17.45,113.22,0.115
17.47,113.40,0.115
17.49,113.58,0.115
17.51,113.76,0.115
17.53,113.95,0.115
17.54,114.13,0.115
17.56,114.32,0.115
17.58,114.50,0.115
17.60,114.68,0.115
17.62,114.87,0.115
17.64,115.05,0.115
17.66,115.23,0.115
17.67,115.42,0.115
17.69,115.60,0.115
17.71,115.78,0.116
17.73,115.97,0.116
17.75,116.15,0.116
17.77,116.34,0.116
17.78,116.52,0.116
17.80,116.70,0.116
17.82,116.88,0.116
17.84,117.07,0.116
17.86,117.25,0.116
17.88,117.44,0.116
17.89,117.62,0.116
17.91,117.80,0.116
17.93,117.99,0.116
17.95,118.17,0.116
17.97,118.35,0.116
17.98,118.54,0.116
18.00,118.72,0.117
18.02,118.90,0.117
18.04,119.09,0.117
18.06,119.27,0.117
18.08,119.45,0.117
18.09,119.64,0.117
18.11,119.82,0.117
18.13,120.00,0.117
18.15,120.19,0.117
18.17,120.37,0.117
18.19,120.55,0.117
18.21,120.74,0.117
18.22,120.92,0.117
18.24,121.11,0.117
18.26,121.29,0.117
18.28,121.47,0.117
18.30,121.66,0.117
18.32,121.84,0.117
18.33,122.02,0.117
18.35,122.21,0.117
18.37,122.39,0.118
18.39,122.57,0.118
18.41,122.76,0.118
18.43,122.94,0.118
18.44,123.12,0.118
18.46,123.31,0.118
18.48,123.49,0.118
18.50,123.67,0.118
18.52,123.86,0.118
18.53,124.04,0.118
18.55,124.23,0.118
18.57,124.41,0.118
18.59,124.59,0.118
18.61,124.78,0.118
18.63,124.96,0.118
18.64,125.14,0.118
18.66,125.33,0.118
18.68,125.51,0.118
18.70,125.69,0.118
18.72,125.88,0.118
18.74,126.06,0.118
18.76,126.24,0.118
18.77,126.43,0.119
18.79,126.61,0.119
18.81,126.79,0.119
18.83,126.98,0.119
18.85,127.16,0.119
18.87,127.34,0.119
18.88,127.53,0.119
18.90,127.71,0.119
18.92,127.89,0.119
18.94,128.08,0.119
18.96,128.26,0.119
18.98,128.44,0.119
18.99,128.63,0.119
19.01,128.81,0.119
19.03,128.99,0.119
19.05,129.18,0.119
19.07,129.36,0.119
19.08,129.54,0.119
19.10,129.73,0.119
19.12,129.91,0.120
19.14,130.10,0.120
19.16,130.28,0.120
19.18,130.46,0.120
19.19,130.65,0.120
19.21,130.83,0.120
19.23,131.01,0.120
19.25,131.20,0.120
19.27,131.38,0.120
19.29,131.56,0.120
19.31,131.75,0.120
19.32,131.93,0.120
19.34,132.11,0.120
19.36,132.30,0.120
19.38,132.48,0.120
19.40,132.66,0.120
19.42,132.85,0.120
19.43,133.03,0.120
19.45,133.22,0.120
19.47,133.40,0.121
19.49,133.58,0.121
19.51,133.77,0.121
19.53,133.95,0.121
19.54,134.13,0.121
19.56,134.32,0.121
19.58,134.50,0.121
19.60,134.68,0.121
19.62,134.87,0.121
19.63,135.05,0.121
19.65,135.23,0.121
19.67,135.42,0.121
19.69,135.60,0.121
19.71,135.78,0.121
19.73,135.96,0.121
19.74,136.15,0.121
19.76,136.33,0.121
19.78,136.52,0.121
19.80,136.70,0.121
19.82,136.88,0.121
19.84,137.07,0.121
19.86,137.25,0.122
19.87,137.43,0.122
19.89,137.62,0.122
19.91,137.80,0.122
19.93,137.98,0.122
19.95,138.17,0.122
19.97,138.35,0.122
19.98,138.53,0.122
20.00,138.72,0.122
20.02,138.90,0.122
20.04,139.08,0.122
20.06,139.27,0.122
20.08,139.45,0.122
20.09,139.63,0.122
20.11,139.82,0.123
20.13,140.00,0.123
20.15,140.18,0.123
20.17,140.37,0.123
20.18,140.55,0.123
20.20,140.73,0.123
20.22,140.92,0.123
20.24,141.10,0.123
20.26,141.28,0.123
20.28,141.47,0.123
20.29,141.65,0.123
20.31,141.84,0.123
20.33,142.02,0.123
20.35,142.20,0.123
20.37,142.39,0.123
20.39,142.57,0.123
20.41,142.75,0.123
20.42,142.94,0.124
20.44,143.12,0.124
20.46,143.30,0.124
20.48,143.49,0.124
20.50,143.67,0.124
20.52,143.86,0.124
20.53,144.04,0.124
20.55,144.22,0.124
20.57,144.40,0.124
20.59,144.59,0.124
20.61,144.77,0.124
20.63,144.96,0.124
20.64,145.14,0.124
20.66,145.32,0.124
20.68,145.51,0.124
20.70,145.69,0.125
20.72,145.87,0.125
20.73,146.06,0.125
20.75,146.24,0.125
20.77,146.42,0.125
20.79,146.61,0.125
20.81,146.79,0.125
20.83,146.97,0.125
20.84,147.16,0.125
20.86,147.34,0.125
20.88,147.52,0.125
20.90,147.71,0.125
20.92,147.89,0.126
20.94,148.07,0.126
20.96,148.26,0.126
20.97,148.44,0.126
20.99,148.63,0.126
21.01,148.81,0.126
21.03,148.99,0.126
21.05,149.18,0.126
21.07,149.36,0.126
21.08,149.54,0.126
21.10,149.73,0.126
21.12,149.91,0.126
21.14,150.09,0.126
21.16,150.28,0.127
21.18,150.46,0.127
21.19,150.64,0.127
21.21,150.83,0.127
21.23,151.01,0.127
21.25,151.19,0.127
21.27,151.37,0.127
21.28,151.56,0.127
21.30,151.74,0.127
21.32,151.93,0.127
21.34,152.11,0.127
21.36,152.29,0.128
21.38,152.47,0.128
21.39,152.66,0.128
21.41,152.84,0.128
21.43,153.02,0.128
21.45,153.21,0.128
21.47,153.39,0.128
21.49,153.58,0.128
21.51,153.76,0.128
21.52,153.94,0.128
21.54,154.13,0.128
21.56,154.31,0.128
21.58,154.49,0.128
21.60,154.68,0.128
21.62,154.86,0.128
21.63,155.04,0.129
21.65,155.23,0.129
21.67,155.41,0.129
21.69,155.59,0.129
21.71,155.78,0.129
21.73,155.96,0.129
21.74,156.14,0.129
21.76,156.33,0.129
21.78,156.51,0.130
21.80,156.69,0.133
21.82,156.88,0.181
21.83,157.06,0.254
21.85,157.23,0.344
21.87,157.40,0.444
21.89,157.57,0.547
21.91,157.74,0.653
21.93,157.90,0.767
21.94,158.07,0.887
21.96,158.23,0.998
21.98,158.39,1.106
22.00,158.56,1.212
22.02,158.72,1.318
22.04,158.88,1.424
22.06,159.04,1.532
22.07,159.21,1.640
22.09,159.37,1.745
22.11,159.53,1.859
22.13,159.69,1.955
22.15,159.85,2.036
22.17,160.02,2.115
22.18,160.19,1.915
22.20,160.39,1.474
22.22,160.63,0.732
22.24,160.87,0.536
22.26,161.10,0.440
22.28,161.32,0.378
22.29,161.54,0.326
22.31,161.75,0.286
22.33,161.95,0.252
22.35,162.15,0.230
22.37,162.34,0.207
22.38,162.53,0.191
22.40,162.72,0.179
22.42,162.91,0.170
22.44,163.10,0.162
22.46,163.29,0.156
22.48,163.47,0.152
22.49,163.66,0.149
22.51,163.84,0.146
22.53,164.03,0.144
22.55,164.21,0.142
22.57,164.40,0.142
22.59,164.58,0.141
22.61,164.77,0.140
22.62,164.95,0.140
22.64,165.13,0.140
22.66,165.32,0.139
22.68,165.50,0.139
22.70,165.68,0.138
22.72,165.87,0.138
22.73,166.05,0.138
22.75,166.23,0.137
22.77,166.42,0.137
22.79,166.60,0.137
22.81,166.79,0.137
22.83,166.97,0.137
22.84,167.15,0.136
22.86,167.34,0.136
22.88,167.52,0.136
22.90,167.70,0.136
22.92,167.89,0.136
22.93,168.07,0.136
22.95,168.25,0.136
22.97,168.44,0.136
22.99,168.62,0.136
23.01,168.80,0.136
23.03,168.99,0.136
23.04,169.17,0.136
23.06,169.35,0.136
23.08,169.54,0.136
23.10,169.72,0.136
23.12,169.90,0.136
23.14,170.09,0.136
23.16,170.27,0.136
23.17,170.45,0.136
23.19,170.64,0.136
23.21,170.82,0.136
23.23,171.00,0.136
23.25,171.19,0.136
23.27,171.37,0.136
23.28,171.55,0.136
23.30,171.74,0.136
23.32,171.92,0.136
23.34,172.10,0.136
23.36,172.29,0.136
23.38,172.47,0.137
23.39,172.66,0.137
23.41,172.84,0.137
23.43,173.02,0.137
23.45,173.20,0.137
23.47,173.39,0.137
23.48,173.57,0.137
23.50,173.75,0.137
23.52,173.94,0.137
23.54,174.12,0.137
23.56,174.31,0.137
23.58,174.49,0.137
23.59,174.67,0.138
23.61,174.86,0.138
23.63,175.04,0.138
23.65,175.22,0.138
23.67,175.41,0.138
23.69,175.59,0.138
23.71,175.77,0.138
23.72,175.96,0.138
23.74,176.14,0.138
23.76,176.32,0.139
23.78,176.51,0.139
23.80,176.69,0.139
23.82,176.87,0.139
23.83,177.06,0.139
23.85,177.24,0.139
23.87,177.42,0.139
23.89,177.61,0.139
23.91,177.79,0.139
23.93,177.97,0.139
23.94,178.16,0.140
23.96,178.34,0.140
23.98,178.52,0.140
24.00,178.71,0.140
24.02,178.89,0.140
24.03,179.07,0.140
24.05,179.26,0.140
24.07,179.44,0.140
24.09,179.63,0.140
24.11,179.81,0.141
24.13,179.99,0.141
24.14,180.18,0.141
24.16,180.36,0.141
24.18,180.54,0.141
24.20,180.73,0.141
24.22,180.91,0.141
24.24,181.09,0.141
24.26,181.28,0.141
24.27,181.46,0.141
24.29,181.64,0.141
24.31,181.83,0.142
24.33,182.01,0.142
24.35,182.19,0.142
24.37,182.38,0.142
24.38,182.56,0.142
24.40,182.74,0.142
24.42,182.93,0.142
24.44,183.11,0.142
24.46,183.29,0.143
24.48,183.48,0.143
24.49,183.66,0.143
24.51,183.84,0.143
24.53,184.03,0.143
24.55,184.21,0.143
24.57,184.39,0.143
24.58,184.58,0.144
24.60,184.76,0.144
24.62,184.94,0.144
24.64,185.13,0.144
24.66,185.31,0.144
24.68,185.49,0.144
24.69,185.68,0.144
24.71,185.86,0.145
24.73,186.04,0.145
24.75,186.23,0.145
24.77,186.41,0.145
24.79,186.60,0.145
24.81,186.78,0.145
24.82,186.96,0.145
24.84,187.15,0.146
24.86,187.33,0.146
24.88,187.51,0.146
24.90,187.70,0.146
24.92,187.88,0.146
24.93,188.06,0.146
24.95,188.25,0.146
24.97,188.43,0.146
24.99,188.61,0.147
25.01,188.80,0.147
25.03,188.98,0.147
25.04,189.16,0.147
25.06,189.35,0.147
25.08,189.53,0.147
25.10,189.71,0.148
25.12,189.90,0.148
25.13,190.08,0.148
25.15,190.26,0.148
25.17,190.45,0.148
25.19,190.63,0.148
25.21,190.81,0.149
25.23,191.00,0.149
25.24,191.18,0.149
25.26,191.36,0.149
25.28,191.55,0.149
25.30,191.73,0.149
25.32,191.91,0.149
25.34,192.10,0.149
25.36,192.28,0.149
25.37,192.46,0.150
25.39,192.65,0.150
25.41,192.83,0.150
25.43,193.01,0.150
25.45,193.20,0.150
25.47,193.38,0.150
25.48,193.57,0.150
25.50,193.75,0.150
25.52,193.93,0.151
25.54,194.12,0.151
25.56,194.30,0.151
25.58,194.48,0.151
25.59,194.67,0.151
25.61,194.85,0.151
25.63,195.03,0.151
25.65,195.22,0.151
25.67,195.40,0.151
25.68,195.58,0.151
25.70,195.77,0.152
25.72,195.95,0.152
25.74,196.13,0.152
25.76,196.32,0.152
25.78,196.50,0.152
25.79,196.68,0.152
25.81,196.87,0.152
25.83,197.05,0.153
25.85,197.23,0.153
25.87,197.42,0.153
25.89,197.60,0.153
25.91,197.78,0.153
25.92,197.97,0.153
25.94,198.15,
25.96,198.33,
25.98,198.52,
25.99,,

[step]
Ramp 10.00 °C/min to -60.00 °C
Time,Temperature,Heat Flow (Normalized)
min,°C,W/g
26.99,200.07,-0.034
27.01,200.07,-0.034
27.03,200.06,-0.034
27.05,200.05,-0.038
27.07,200.03,-0.058
27.08,199.99,-0.083
27.10,199.92,-0.106
27.12,199.83,-0.130
27.14,199.72,-0.150
27.16,199.60,-0.165
27.18,199.46,-0.176
27.19,199.31,-0.186
27.21,199.15,-0.193
27.23,198.99,-0.198
27.25,198.82,-0.200
27.27,198.65,-0.203
27.29,198.48,-0.206
27.31,198.31,-0.208
27.32,198.14,-0.210
27.34,197.96,-0.211
27.36,197.78,-0.212
27.38,197.61,-0.214
27.40,197.43,-0.215
27.42,197.25,-0.215
27.43,197.07,-0.216
27.45,196.89,-0.216
27.47,196.71,-0.217
27.49,196.53,-0.217
27.51,196.35,-0.218
27.53,196.17,-0.218
27.54,195.99,-0.218
27.56,195.81,-0.219
27.58,195.63,-0.219
27.60,195.45,-0.219
27.62,195.27,-0.220
27.63,195.09,-0.220
27.65,194.91,-0.221
27.67,194.72,-0.221
27.69,194.54,-0.221
27.71,194.36,-0.222
27.73,194.18,-0.222
27.74,194.00,-0.222
27.76,193.82,-0.222
27.78,193.64,-0.223
27.80,193.45,-0.223
27.82,193.27,-0.223
27.84,193.09,-0.223
27.86,192.91,-0.223
27.87,192.73,-0.223
27.89,192.54,-0.224
27.91,192.36,-0.224
27.93,192.18,-0.224
27.95,192.00,-0.224
27.97,191.82,-0.224
27.98,191.63,-0.224
28.00,191.45,-0.224
28.02,191.27,-0.224
28.04,191.09,-0.224
28.06,190.90,-0.224
28.08,190.72,-0.225
28.09,190.54,-0.224
28.11,190.36,-0.224
28.13,190.18,-0.224
28.15,189.99,-0.224
28.17,189.81,-0.224
28.18,189.63,-0.224
28.20,189.45,-0.224
28.22,189.26,-0.224
28.24,189.08,-0.224
28.26,188.90,-0.224
28.28,188.71,-0.224
28.29,188.53,-0.224
28.31,188.35,-0.224
28.33,188.17,-0.224
28.35,187.98,-0.224
28.37,187.80,-0.224
28.39,187.62,-0.224
28.41,187.43,-0.224
28.42,187.25,-0.224
28.44,187.07,-0.224
28.46,186.89,-0.224
28.48,186.70,-0.224
28.50,186.52,-0.224
28.52,186.34,-0.224
28.53,186.15,-0.223
28.55,185.97,-0.223
28.57,185.79,-0.223
28.59,185.60,-0.223
28.61,185.42,-0.223
28.63,185.24,-0.223
28.64,185.06,-0.223
28.66,184.87,-0.223
28.68,184.69,-0.223
28.70,184.51,-0.223
28.72,184.32,-0.223
28.73,184.14,-0.223
28.75,183.96,-0.223
28.77,183.78,-0.222
28.79,183.59,-0.222
28.81,183.41,-0.222
28.83,183.23,-0.222
28.84,183.04,-0.222
28.86,182.86,-0.222
28.88,182.68,-0.222
28.90,182.49,-0.222
28.92,182.31,-0.222
28.94,182.13,-0.222
28.96,181.95,-0.222
28.97,181.76,-0.222
28.99,181.58,-0.221
29.01,181.40,-0.221
29.03,181.21,-0.221
29.05,181.03,-0.221
29.07,180.85,-0.221
29.08,180.66,-0.221
29.10,180.48,-0.221
29.12,180.30,-0.221
29.14,180.12,-0.221
29.16,179.93,-0.221
29.18,179.75,-0.221
29.19,179.57,-0.221
29.21,179.38,-0.221
29.23,179.20,-0.221
29.25,179.02,-0.221
29.27,178.84,-0.220
29.28,178.65,-0.220
29.30,178.47,-0.220
29.32,178.29,-0.220
29.34,178.10,-0.220
29.36,177.92,-0.220
29.38,177.74,-0.220
29.39,177.55,-0.220
29.41,177.37,-0.220
29.43,177.19,-0.220
29.45,177.00,-0.220
29.47,176.82,-0.220
29.49,176.64,-0.220
29.51,176.45,-0.220
29.52,176.27,-0.220
29.54,176.09,-0.219
29.56,175.90,-0.219
29.58,175.72,-0.219
29.60,175.54,-0.219
29.62,175.36,-0.219
29.63,175.17,-0.219
29.65,174.99,-0.219
29.67,174.81,-0.219
29.69,174.62,-0.219
29.71,174.44,-0.219
29.73,174.26,-0.219
29.74,174.07,-0.219
29.76,173.89,-0.219
29.78,173.71,-0.219
29.80,173.53,-0.219
29.82,173.34,-0.218
29.83,173.16,-0.219
29.85,172.98,-0.218
29.87,172.79,-0.218
29.89,172.61,-0.218
29.91,172.43,-0.218
29.93,172.24,-0.218
29.94,172.06,-0.218
29.96,171.88,-0.218
29.98,171.69,-0.218
30.00,171.51,-0.218
30.02,171.33,-0.218
30.04,171.15,-0.218
30.06,170.96,-0.218
30.07,170.78,-0.218
30.09,170.59,-0.218
30.11,170.41,-0.218
30.13,170.23,-0.218
30.15,170.05,-0.218
30.17,169.86,-0.217
30.18,169.68,-0.217
30.20,169.50,-0.217
30.22,169.31,-0.217
30.24,169.13,-0.217
30.26,168.95,-0.217
30.28,168.76,-0.217
30.29,168.58,-0.217
30.31,168.40,-0.217
30.33,168.21,-0.217
30.35,168.03,-0.217
30.37,167.85,-0.217
30.38,167.67,-0.217
30.40,167.48,-0.217
30.42,167.30,-0.217
30.44,167.12,-0.217
30.46,166.93,-0.217
30.48,166.75,-0.217
30.49,166.57,-0.217
30.51,166.38,-0.217
30.53,166.20,-0.217
30.55,166.02,-0.216
30.57,165.83,-0.216
30.59,165.65,-0.216
30.61,165.47,-0.216
30.62,165.29,-0.216
30.64,165.10,-0.216
30.66,164.92,-0.216
30.68,164.74,-0.216
30.70,164.55,-0.216
30.72,164.37,-0.216
30.73,164.19,-0.216
30.75,164.00,-0.216
30.77,163.82,-0.216
30.79,163.64,-0.216
30.81,163.45,-0.216
30.83,163.27,-0.216
30.84,163.09,-0.216
30.86,162.90,-0.216
30.88,162.72,-0.216
30.90,162.54,-0.216
30.92,162.36,-0.216
30.93,162.17,-0.216
30.95,161.99,-0.216
30.97,161.81,-0.216
30.99,161.62,-0.216
31.01,161.44,-0.216
31.03,161.26,-0.216
31.04,161.07,-0.216
31.06,160.89,-0.216
31.08,160.71,-0.216
31.10,160.52,-0.216
31.12,160.34,-0.216
31.14,160.16,-0.216
31.16,159.98,-0.216
31.17,159.79,-0.216
31.19,159.61,-0.216
31.21,159.43,-0.216
31.23,159.24,-0.216
31.25,159.06,-0.216
31.27,158.88,-0.216
31.28,158.69,-0.216
31.30,158.51,-0.216
31.32,158.33,-0.215
31.34,158.14,-0.215
31.36,157.96,-0.215
31.38,157.78,-0.215
31.39,157.59,-0.215
31.41,157.41,-0.215
31.43,157.23,-0.215
31.45,157.04,-0.215
31.47,156.86,-0.215
31.48,156.68,-0.215
31.50,156.49,-0.215
31.52,156.31,-0.215
31.54,156.13,-0.215
31.56,155.95,-0.215
31.58,155.76,-0.215
31.59,155.58,-0.215
31.61,155.40,-0.215
31.63,155.21,-0.215
31.65,155.03,-0.215
31.67,154.85,-0.215
31.69,154.66,-0.215
31.71,154.48,-0.215
31.72,154.30,-0.215
31.74,154.11,-0.215
31.76,153.94,-0.832
31.78,153.82,-1.729
31.80,153.71,-1.929
31.82,153.58,-2.055
31.83,153.45,-2.179
31.85,153.30,-2.291
31.87,153.16,-2.404
31.89,153.01,-2.513
31.91,152.85,-2.614
31.93,152.70,-2.705
31.94,152.54,-2.599
31.96,152.36,-2.408
31.98,152.14,-1.116
32.00,151.88,-0.584
32.02,151.63,-0.472
32.03,151.39,-0.416
32.05,151.16,-0.374
32.07,150.95,-0.341
32.09,150.74,-0.314
32.11,150.53,-0.295
32.13,150.33,-0.275
32.14,150.14,-0.263
32.16,149.94,-0.251
32.18,149.75,-0.244
32.20,149.56,-0.238
32.22,149.37,-0.235
32.24,149.19,-0.231
32.26,149.00,-0.226
32.27,148.81,-0.225
32.29,148.63,-0.224
32.31,148.44,-0.222
32.33,148.26,-0.222
32.35,148.07,-0.221
32.37,147.89,-0.220
32.38,147.71,-0.219
32.40,147.52,-0.219
32.42,147.34,-0.218
32.44,147.16,-0.218
32.46,146.97,-0.217
32.48,146.79,-0.217
32.49,146.61,-0.217
32.51,146.42,-0.217
32.53,146.24,-0.217
32.55,146.06,-0.216
32.57,145.87,-0.216
32.58,145.69,-0.216
32.60,145.51,-0.216
32.62,145.32,-0.215
32.64,145.14,-0.215
32.66,144.96,-0.215
32.68,144.77,-0.215
32.69,144.59,-0.215
32.71,144.41,-0.215
32.73,144.23,-0.214
32.75,144.04,-0.214
32.77,143.86,-0.214
32.79,143.68,-0.214
32.81,143.49,-0.214
32.82,143.31,-0.214
32.84,143.13,-0.214
32.86,142.94,-0.214
32.88,142.76,-0.213
32.90,142.58,-0.213
32.92,142.39,-0.213
32.93,142.21,-0.213
32.95,142.03,-0.213
32.97,141.85,-0.213
32.99,141.66,-0.213
33.01,141.48,-0.213
33.03,141.30,-0.213
33.04,141.11,-0.213
33.06,140.93,-0.213
33.08,140.75,-0.213
33.10,140.56,-0.213
33.12,140.38,-0.213
33.13,140.20,-0.213
33.15,140.01,-0.212
33.17,139.83,-0.212
33.19,139.65,-0.212
33.21,139.46,-0.212
33.23,139.28,-0.212
33.24,139.10,-0.212
33.26,138.91,-0.212
33.28,138.73,-0.212
33.30,138.55,-0.212
33.32,138.37,-0.212
33.34,138.18,-0.212
33.36,138.00,-0.212
33.37,137.82,-0.212
33.39,137.63,-0.212
33.41,137.45,-0.212
33.43,137.27,-0.211
33.45,137.08,-0.211
33.47,136.90,-0.211
33.48,136.72,-0.211
33.50,136.53,-0.211
33.52,136.35,-0.211
33.54,136.17,-0.211
33.56,135.98,-0.211
33.58,135.80,-0.211
33.59,135.62,-0.211
33.61,135.43,-0.211
33.63,135.25,-0.211
33.65,135.07,-0.211
33.67,134.88,-0.211
33.68,134.70,-0.211
33.70,134.52,-0.211
33.72,134.34,-0.211
33.74,134.15,-0.211
33.76,133.97,-0.211
33.78,133.79,-0.211
33.79,133.60,-0.211
33.81,133.42,-0.210
33.83,133.24,-0.210
33.85,133.05,-0.210
33.87,132.87,-0.210
33.89,132.69,-0.210
33.91,132.50,-0.210
33.92,132.32,-0.210
33.94,132.14,-0.210
33.96,131.96,-0.210
33.98,131.77,-0.210
34.00,131.59,-0.210
34.02,131.41,-0.210
34.03,131.22,-0.210
34.05,131.04,-0.210
34.07,130.86,-0.210
34.09,130.67,-0.210
34.11,130.49,-0.210
34.13,130.31,-0.210
34.14,130.12,-0.210
34.16,129.94,-0.210
34.18,129.76,-0.210
34.20,129.57,-0.210
34.22,129.39,-0.209
34.24,129.21,-0.209
34.25,129.03,-0.209
34.27,128.84,-0.209
34.29,128.66,-0.209
34.31,128.48,-0.209
34.33,128.29,-0.209
34.34,128.11,-0.209
34.36,127.93,-0.209
34.38,127.74,-0.209
[...]
115.21,10.69,0.107
115.23,10.88,0.107
115.25,11.06,0.107
115.27,11.25,0.107
115.29,11.43,0.107
115.31,11.61,0.107
115.33,11.79,0.107
115.34,11.98,0.107
115.36,12.16,0.107
115.38,12.34,0.107
115.40,12.53,0.107
115.42,12.71,0.107
115.44,12.90,0.107
115.45,13.08,0.107
115.47,13.27,0.107
115.49,13.45,0.107
115.51,13.63,0.107
115.53,13.82,0.107
115.55,14.00,0.107
115.56,14.18,0.107
115.58,14.37,0.107
115.60,14.55,0.107
115.62,14.73,0.107
115.64,14.92,0.107
115.65,15.10,0.107
115.67,15.28,0.107
115.69,15.47,0.107
115.71,15.65,0.108
115.73,15.83,0.108
115.75,16.02,0.108
115.76,16.20,0.108
115.78,16.39,0.108
115.80,16.57,0.108
115.82,16.75,0.108
115.84,16.94,0.108
115.86,17.12,0.108
115.88,17.30,0.108
115.89,17.49,0.108
115.91,17.67,0.108
115.93,17.85,0.108
115.95,18.04,0.108
115.97,18.22,0.108
115.99,18.40,0.108
116.00,18.59,0.108
116.02,18.77,0.108
116.04,18.95,0.108
116.06,19.14,0.108
116.08,19.32,0.108
116.10,19.50,0.108
116.11,19.69,0.108
116.13,19.87,0.108
116.15,20.06,0.109
116.17,20.24,0.109
116.19,20.42,0.109
116.20,20.61,0.109
116.22,20.79,0.109
116.24,20.97,0.109
116.26,21.16,0.109
116.28,21.34,0.109
116.30,21.52,0.109
116.31,21.71,0.109
116.33,21.89,0.109
116.35,22.07,0.109
116.37,22.26,0.109
116.39,22.44,0.109
116.41,22.63,0.109
116.43,22.81,0.109
116.44,22.99,0.109
116.46,23.18,0.109
116.48,23.36,0.109
116.50,23.54,0.109
116.52,23.73,0.109
116.54,23.91,0.109
116.55,24.09,0.109
116.57,24.28,0.109
116.59,24.46,0.109
116.61,24.65,0.109
116.63,24.83,0.109
116.65,25.01,0.109
116.66,25.19,0.110
116.68,25.38,0.110
116.70,25.56,0.110
116.72,25.75,0.110
116.74,25.93,0.110
116.75,26.11,0.110
116.77,26.30,0.110
116.79,26.48,0.110
116.81,26.66,0.110
116.83,26.85,0.110
116.85,27.03,0.110
116.86,27.21,0.110
116.88,27.40,0.110
116.90,27.58,0.110
116.92,27.76,0.110
116.94,27.95,0.110
116.96,28.13,0.110
116.98,28.32,0.110
116.99,28.50,0.110
117.01,28.68,0.110
117.03,28.87,0.110
117.05,29.05,0.110
117.07,29.23,0.110
117.09,29.42,0.110
117.10,29.60,0.110
117.12,29.78,0.110
117.14,29.97,0.110
117.16,30.15,0.110
117.18,30.33,0.110
117.20,30.52,0.110
117.21,30.70,0.110
117.23,30.89,0.110
117.25,31.07,0.110
117.27,31.25,0.110
117.29,31.44,0.110
117.30,31.62,0.110
117.32,31.80,0.110
117.34,31.99,0.110
117.36,32.17,0.110
117.38,32.35,0.111
117.40,32.54,0.111
117.41,32.72,0.111
117.43,32.90,0.111
117.45,33.09,0.111
117.47,33.27,0.111
117.49,33.45,0.111
117.51,33.64,0.111
117.53,33.82,0.111
117.54,34.00,0.111
117.56,34.19,0.111
117.58,34.37,0.111
117.60,34.55,0.111
117.62,34.74,0.111
117.64,34.92,0.111
117.65,35.11,0.111
117.67,35.29,0.111
117.69,35.47,0.111
117.71,35.66,0.111
117.73,35.84,0.111
117.75,36.02,0.111
117.76,36.21,0.111
117.78,36.39,0.111
117.80,36.57,0.111
117.82,36.76,0.111
117.84,36.94,0.111
117.85,37.13,0.111
117.87,37.31,0.111
117.89,37.49,0.111
117.91,37.68,0.111
117.93,37.86,0.111
117.95,38.04,0.111
117.96,38.23,0.111
117.98,38.41,0.111
118.00,38.59,0.111
118.02,38.78,0.111
118.04,38.96,0.111
118.06,39.14,0.111
118.08,39.33,0.111
118.09,39.51,0.111
118.11,39.70,0.111
118.13,39.88,0.111
118.15,40.06,0.111
118.17,40.25,0.111
118.19,40.43,0.111
118.20,40.61,0.111
118.22,40.80,0.111
118.24,40.98,0.111
118.26,41.17,0.111
118.28,41.35,0.111
118.30,41.53,0.111
118.31,41.71,0.111
118.33,41.90,0.111
118.35,42.08,0.111
118.37,42.27,0.111
118.39,42.45,0.111
118.40,42.63,0.111
118.42,42.82,0.111
118.44,43.00,0.111
118.46,43.18,0.111
118.48,43.37,0.111
118.50,43.55,0.111
118.51,43.73,0.111
118.53,43.92,0.112
118.55,44.10,0.111
118.57,44.28,0.112
118.59,44.47,0.112
118.61,44.65,0.112
118.63,44.84,0.112
118.64,45.02,0.112
118.66,45.20,0.112
118.68,45.39,0.112
118.70,45.57,0.112
118.72,45.75,0.112
118.74,45.94,0.112
118.75,46.12,0.112
118.77,46.30,0.112
118.79,46.49,0.112
118.81,46.67,0.112
118.83,46.85,0.112
118.85,47.04,0.112
118.86,47.22,0.112
118.88,47.40,0.112
118.90,47.59,0.112
118.92,47.77,0.112
118.94,47.96,0.112
118.95,48.14,0.112
118.97,48.32,0.113
118.99,48.50,0.113
119.01,48.69,0.113
119.03,48.87,0.113
119.05,49.06,0.113
119.06,49.24,0.113
119.08,49.42,0.113
119.10,49.61,0.113
119.12,49.79,0.113
119.14,49.97,0.113
119.16,50.16,0.113
119.18,50.34,0.113
119.19,50.53,0.113
119.21,50.71,0.113
119.23,50.89,0.113
119.25,51.07,0.113
119.27,51.26,0.113
119.29,51.44,0.113
119.30,51.63,0.113
119.32,51.81,0.113
119.34,51.99,0.114
119.36,52.18,0.114
119.38,52.36,0.114
119.40,52.54,0.114
119.41,52.73,0.114
119.43,52.91,0.114
119.45,53.09,0.114
119.47,53.28,0.114
119.49,53.46,0.114
119.50,53.65,0.114
119.52,53.83,0.114
119.54,54.01,0.114
119.56,54.20,0.114
119.58,54.38,0.114
119.60,54.56,0.114
119.61,54.75,0.114
119.63,54.93,0.114
119.65,55.11,0.114
119.67,55.30,0.114
119.69,55.48,0.114
119.71,55.66,0.114
119.73,55.85,0.114
119.74,56.03,0.114
119.76,56.22,0.114
119.78,56.40,0.114
119.80,56.58,0.114
119.82,56.76,0.114
119.84,56.95,0.114
119.85,57.13,0.114
119.87,57.32,0.115
119.89,57.50,0.115
119.91,57.68,0.115
119.93,57.87,0.115
119.95,58.05,0.115
119.96,58.23,0.115
119.98,58.42,0.115
120.00,58.60,0.115
120.02,58.78,0.115
120.04,58.97,0.115
120.05,59.15,0.115
120.07,59.33,0.115
120.09,59.52,0.115
120.11,59.70,0.115
120.13,59.88,0.115
120.15,60.07,0.115
120.16,60.25,0.115
120.18,60.44,0.115
120.20,60.62,0.115
120.22,60.80,0.115
120.24,60.99,0.115
120.26,61.17,0.115
120.28,61.35,0.115
120.29,61.54,0.116
120.31,61.72,0.116
120.33,61.90,0.116
120.35,62.09,0.116
120.37,62.27,0.116
120.39,62.46,0.116
120.40,62.64,0.116
120.42,62.82,0.116
120.44,63.01,0.116
120.46,63.19,0.116
120.48,63.37,0.116
120.50,63.56,0.116
120.51,63.74,0.116
120.53,63.92,0.116
120.55,64.11,0.116
120.57,64.29,0.116
120.59,64.47,0.117
120.60,64.66,0.117
120.62,64.84,0.117
120.64,65.03,0.117
120.66,65.21,0.117
120.68,65.39,0.117
120.70,65.58,0.117
120.71,65.76,0.117
120.73,65.94,0.117
120.75,66.13,0.117
120.77,66.31,0.117
120.79,66.49,0.117
120.81,66.68,0.117
120.83,66.86,0.117
120.84,67.04,0.117
120.86,67.23,0.117
120.88,67.41,0.117
120.90,67.59,0.117
120.92,67.78,0.117
120.94,67.96,0.117
120.95,68.15,0.118
120.97,68.33,0.118
120.99,68.51,0.118
121.01,68.70,0.118
121.03,68.88,0.118
121.05,69.06,0.118
121.06,69.24,0.118
121.08,69.43,0.118
121.10,69.61,0.118
121.12,69.79,0.118
121.14,69.98,0.118
121.15,70.16,0.118
121.17,70.35,0.118
121.19,70.53,0.118
121.21,70.71,0.118
121.23,70.89,0.118
121.25,71.08,0.118
121.26,71.26,0.118
121.28,71.45,0.118
121.30,71.63,0.118
121.32,71.81,0.118
121.34,72.00,0.119
121.36,72.18,0.119
121.38,72.36,0.119
121.39,72.55,0.119
121.41,72.73,0.119
121.43,72.91,0.119
121.45,73.10,0.119
121.47,73.28,0.119
121.49,73.47,0.119
121.50,73.65,0.119
121.52,73.83,0.119
121.54,74.01,0.119
121.56,74.20,0.119
121.58,74.38,0.119
121.60,74.57,0.119
121.61,74.75,0.119
121.63,74.93,0.119
121.65,75.12,0.119
121.67,75.30,0.119
121.69,75.48,0.119
121.70,75.67,0.120
121.72,75.85,0.120
121.74,76.04,0.120
121.76,76.22,0.120
121.78,76.40,0.120
121.80,76.59,0.120
121.81,76.77,0.120
121.83,76.95,0.120
121.85,77.14,0.120
121.87,77.32,0.120
121.89,77.50,0.120
121.91,77.69,0.120
121.93,77.87,0.120
121.94,78.05,0.120
121.96,78.24,0.120
121.98,78.42,0.120
122.00,78.60,0.120
122.02,78.79,0.120
122.04,78.97,0.120
122.05,79.15,0.120
122.07,79.34,0.120
122.09,79.52,0.120
122.11,79.71,0.120
122.13,79.89,0.120
122.15,80.07,0.120
122.16,80.25,0.120
122.18,80.44,0.120
122.20,80.62,0.121
122.22,80.81,0.121
122.24,80.99,0.121
122.25,81.17,0.121
122.27,81.36,0.121
122.29,81.54,0.121
122.31,81.72,0.121
122.33,81.91,0.121
122.35,82.09,0.121
122.36,82.27,0.121
122.38,82.46,0.121
122.40,82.64,0.121
122.42,82.82,0.121
122.44,83.01,0.121
122.46,83.19,0.121
122.48,83.38,0.121
122.49,83.56,0.121
122.51,83.74,0.121
122.53,83.93,0.121
122.55,84.11,0.121
122.57,84.29,0.121
122.59,84.48,0.121
122.60,84.66,0.120
122.62,84.84,0.120
122.64,85.03,0.120
122.66,85.21,0.120
122.68,85.39,0.120
122.70,85.58,0.120
122.71,85.76,0.120
122.73,85.94,0.120
122.75,86.13,0.120
122.77,86.31,0.120
122.79,86.50,0.120
122.80,86.68,0.121
122.82,86.86,0.120
122.84,87.05,0.121
122.86,87.23,0.121
122.88,87.41,0.121
122.90,87.60,0.121
122.91,87.78,0.121
122.93,87.96,0.121
122.95,88.15,0.121
122.97,88.33,0.121
122.99,88.51,0.121
123.01,88.70,0.121
123.03,88.88,0.121
123.04,89.06,0.121
123.06,89.25,0.121
123.08,89.43,0.121
123.10,89.61,0.121
123.12,89.80,0.121
123.14,89.98,0.122
123.15,90.17,0.122
123.17,90.35,0.122
123.19,90.53,0.122
123.21,90.71,0.122
123.23,90.90,0.122
123.25,91.08,0.122
123.26,91.26,0.122
123.28,91.45,0.122
123.30,91.63,0.122
123.32,91.82,0.122
123.34,92.00,0.123
123.35,92.18,0.123
123.37,92.37,0.123
123.39,92.55,0.123
123.41,92.73,0.123
123.43,92.92,0.123
123.45,93.10,0.123
123.46,93.28,0.123
123.48,93.47,0.123
123.50,93.65,0.123
123.52,93.83,0.123
123.54,94.02,0.123
123.56,94.20,0.123
123.58,94.39,0.123
123.59,94.57,0.123
123.61,94.75,0.124
123.63,94.93,0.124
123.65,95.12,0.124
123.67,95.30,0.124
123.69,95.48,0.124
123.70,95.67,0.124
123.72,95.85,0.124
123.74,96.04,0.124
123.76,96.22,0.124
123.78,96.40,0.124
123.80,96.59,0.124
123.81,96.77,0.124
123.83,96.95,0.124
123.85,97.14,0.125
123.87,97.32,0.125
123.89,97.50,0.125
123.90,97.69,0.125
123.92,97.87,0.125
123.94,98.05,0.125
123.96,98.24,0.125
123.98,98.42,0.125
124.00,98.60,0.125
124.01,98.79,0.125
124.03,98.97,0.125
124.05,99.16,0.125
124.07,99.34,0.125
124.09,99.52,0.125
124.11,99.71,0.126
124.13,99.89,0.126
124.14,100.07,0.126
124.16,100.26,0.126
124.18,100.44,0.126
124.20,100.62,0.126
124.22,100.81,0.126
124.24,100.99,0.126
124.25,101.17,0.126
124.27,101.36,0.126
124.29,101.54,0.126
124.31,101.72,0.126
124.33,101.91,0.126
124.35,102.09,0.126
124.36,102.27,0.126
124.38,102.46,0.126
124.40,102.64,0.126
124.42,102.83,0.127
124.44,103.01,0.127
124.45,103.19,0.127
124.47,103.38,0.127
124.49,103.56,0.127
124.51,103.74,0.127
124.53,103.93,0.127
124.55,104.11,0.127
124.56,104.29,0.127
124.58,104.48,0.127
124.60,104.66,0.127
124.62,104.84,0.127
124.64,105.03,0.127
124.66,105.21,0.127
124.68,105.39,0.127
124.69,105.58,0.127
124.71,105.76,0.127
124.73,105.95,0.128
124.75,106.13,0.128
124.77,106.31,0.128
124.79,106.49,0.128
124.80,106.68,0.128
124.82,106.86,0.128
124.84,107.04,0.128
124.86,107.23,0.128
124.88,107.41,0.128
124.90,107.60,0.128
124.91,107.78,0.128
124.93,107.96,0.128
124.95,108.15,0.129
124.97,108.33,0.129
124.99,108.51,0.129
125.00,108.70,0.129
125.02,108.88,0.129
125.04,109.06,0.129
125.06,109.25,0.129
125.08,109.43,0.129
125.10,109.62,0.129
125.11,109.80,0.129
125.13,109.98,0.129
125.15,110.16,0.129
125.17,110.35,0.129
125.19,110.53,0.129
125.21,110.72,0.130
125.23,110.90,0.130
125.24,111.08,0.130
125.26,111.27,0.130
125.28,111.45,0.130
125.30,111.63,0.130
125.32,111.82,0.130
125.34,112.00,0.130
125.35,112.18,0.130
125.37,112.37,0.130
125.39,112.55,0.130
125.41,112.73,0.130
125.43,112.92,0.130
125.45,113.10,0.130
125.46,113.28,0.131
125.48,113.47,0.131
125.50,113.65,0.131
125.52,113.84,0.131
125.54,114.02,0.131
125.55,114.20,0.131
125.57,114.39,0.131
125.59,114.57,0.131
125.61,114.75,0.131
125.63,114.94,0.131
125.65,115.12,0.131
125.66,115.30,0.131
125.68,115.49,0.131
125.70,115.67,0.131
125.72,115.85,0.131
125.74,116.04,0.131
125.76,116.22,0.131
125.78,116.40,0.132
125.79,116.59,0.132
125.81,116.77,0.132
125.83,116.95,0.132
125.85,117.14,0.132
125.87,117.32,0.132
125.89,117.50,0.132
125.90,117.69,0.132
125.92,117.87,0.132
125.94,118.05,0.132
125.96,118.24,0.132
125.98,118.42,0.132
126.00,118.60,0.132
126.01,118.79,0.132
126.03,118.97,0.133
126.05,119.15,0.133
126.07,119.34,0.133
126.09,119.52,0.133
126.10,119.71,0.133
126.12,119.89,0.133
126.14,120.07,0.133
126.16,120.26,0.133
126.18,120.44,0.133
126.20,120.62,0.133
126.21,120.81,0.133
126.23,120.99,0.133
126.25,121.18,0.133
126.27,121.36,0.133
126.29,121.54,0.133
126.31,121.73,0.133
126.33,121.91,0.133
126.34,122.09,0.133
126.36,122.28,0.133
126.38,122.46,0.133
126.40,122.64,0.133
126.42,122.83,0.133
126.44,123.01,0.133
126.45,123.20,0.133
126.47,123.38,0.134
126.49,123.56,0.134
126.51,123.74,0.134
126.53,123.93,0.134
126.55,124.11,0.134
126.56,124.29,0.134
126.58,124.48,0.134
126.60,124.66,0.134
126.62,124.85,0.134
126.64,125.03,0.134
126.65,125.21,0.134
126.67,125.39,0.134
126.69,125.58,0.134
126.71,125.76,0.134
126.73,125.95,0.134
126.75,126.13,0.134
126.76,126.31,0.134
126.78,126.50,0.134
126.80,126.68,0.135
126.82,126.86,0.135
126.84,127.05,0.135
126.86,127.23,0.135
126.88,127.41,0.135
126.89,127.60,0.135
126.91,127.78,0.135
126.93,127.96,0.135
126.95,128.15,0.135
126.97,128.33,0.135
126.99,128.51,0.135
127.00,128.70,0.135
127.02,128.88,0.135
127.04,129.06,0.135
127.06,129.25,0.135
127.08,129.43,0.135
127.10,129.61,0.135
127.11,129.80,0.136
127.13,129.98,0.136
127.15,130.16,0.136
127.17,130.35,0.136
127.19,130.53,0.136
127.20,130.71,0.136
127.22,130.90,0.136
127.24,131.08,0.136
127.26,131.27,0.136
127.28,131.45,0.136
127.30,131.63,0.136
127.31,131.82,0.136
127.33,132.00,0.136
127.35,132.18,0.136
127.37,132.36,0.136
127.39,132.55,0.136
127.41,132.73,0.136
127.43,132.92,0.137
127.44,133.10,0.137
127.46,133.28,0.137
127.48,133.47,0.137
127.50,133.65,0.137
127.52,133.83,0.137
127.54,134.02,0.137
127.55,134.20,0.137
127.57,134.38,0.137
127.59,134.57,0.137
127.61,134.75,0.137
127.63,134.93,0.137
127.65,135.12,0.138
127.66,135.30,0.138
127.68,135.48,0.138
127.70,135.67,0.138
127.72,135.85,0.138
127.74,136.04,0.138
127.75,136.22,0.138
127.77,136.40,0.138
127.79,136.58,0.138
127.81,136.77,0.138
127.83,136.95,0.138
127.85,137.14,0.138
127.86,137.32,0.138
127.88,137.50,0.138
127.90,137.69,0.138
127.92,137.87,0.138
127.94,138.05,0.139
127.96,138.24,0.139
127.98,138.42,0.139
127.99,138.60,0.139
128.01,138.79,0.139
128.03,138.97,0.139
128.05,139.15,0.139
128.07,139.34,0.139
128.09,139.52,0.139
128.10,139.70,0.139
128.12,139.89,0.139
128.14,140.07,0.139
128.16,140.25,0.139
128.18,140.44,0.139
128.20,140.62,0.139
128.21,140.81,0.139
128.23,140.99,0.140
128.25,141.17,0.140
128.27,141.36,0.140
128.29,141.54,0.140
128.30,141.72,0.140
128.32,141.91,0.140
128.34,142.09,0.140
128.36,142.27,0.140
128.38,142.46,0.140
128.40,142.64,0.140
128.41,142.82,0.140
128.43,143.01,0.140
128.45,143.19,0.140
128.47,143.37,0.140
128.49,143.56,0.140
128.51,143.74,0.140
128.53,143.92,0.140
128.54,144.11,0.140
128.56,144.29,0.141
128.58,144.47,0.141
128.60,144.66,0.141
128.62,144.84,0.141
128.64,145.02,0.141
128.65,145.21,0.141
128.67,145.39,0.141
128.69,145.57,0.141
128.71,145.76,0.141
128.73,145.94,0.141
128.75,146.12,0.141
128.76,146.31,0.141
128.78,146.49,0.141
128.80,146.68,0.141
128.82,146.86,0.141
128.84,147.04,0.142
128.85,147.23,0.142
128.87,147.41,0.142
128.89,147.59,0.142
128.91,147.78,0.142
128.93,147.96,0.142
128.95,148.14,0.142
128.96,148.33,0.142
128.98,148.51,0.142
129.00,148.69,0.142
129.02,148.88,0.142
129.04,149.06,0.142
129.06,149.25,0.142
129.08,149.43,0.143
129.09,149.61,0.143
129.11,149.80,0.143
129.13,149.98,0.143
129.15,150.16,0.143
129.17,150.35,0.143
129.19,150.53,0.143
129.20,150.71,0.143
129.22,150.90,0.143
129.24,151.08,0.143
129.26,151.26,0.143
129.28,151.45,0.143
129.30,151.63,0.143
129.31,151.81,0.143
129.33,152.00,0.143
129.35,152.18,0.143
129.37,152.36,0.143
129.39,152.55,0.143
129.40,152.73,0.144
129.42,152.91,0.144
129.44,153.10,0.144
129.46,153.28,0.144
129.48,153.46,0.144
129.50,153.65,0.144
129.51,153.83,0.144
129.53,154.02,0.144
129.55,154.20,0.144
129.57,154.38,0.144
129.59,154.56,0.144
129.61,154.75,0.144
129.63,154.93,0.144
129.64,155.12,0.144
129.66,155.30,0.144
129.68,155.48,0.145
129.70,155.66,0.145
129.72,155.85,0.145
129.74,156.03,0.145
129.75,156.21,0.145
129.77,156.40,0.145
129.79,156.58,0.146
129.81,156.76,0.185
129.83,156.94,0.263
129.85,157.12,0.372
129.86,157.29,0.484
129.88,157.45,0.601
129.90,157.62,0.718
129.92,157.78,0.839
129.94,157.94,0.960
129.95,158.11,1.082
129.97,158.27,1.206
129.99,158.43,1.331
130.01,158.59,1.456
130.03,158.75,1.578
130.05,158.90,1.694
130.06,159.07,1.808
130.08,159.22,1.926
130.10,159.38,2.027
130.12,159.55,2.131
130.14,159.71,2.220
130.16,159.88,1.996
130.18,160.07,1.690
130.19,160.31,0.810
130.21,160.56,0.570
130.23,160.79,0.472
130.25,161.02,0.402
130.27,161.23,0.348
130.29,161.44,0.304
130.30,161.65,0.272
130.32,161.85,0.245
130.34,162.04,0.224
130.36,162.23,0.207
130.38,162.42,0.194
130.40,162.61,0.184
130.41,162.80,0.178
130.43,162.99,0.171
130.45,163.18,0.167
130.47,163.36,0.164
130.49,163.55,0.160
130.50,163.73,0.159
130.52,163.92,0.157
130.54,164.10,0.156
130.56,164.28,0.155
130.58,164.47,0.155
130.60,164.65,0.154
130.61,164.84,0.153
130.63,165.02,0.153
130.65,165.20,0.153
130.67,165.39,0.153
130.69,165.57,0.152
130.71,165.75,0.152
130.73,165.94,0.152
130.74,166.12,0.152
130.76,166.30,0.151
130.78,166.49,0.151
130.80,166.67,0.151
130.82,166.85,0.151
130.84,167.04,0.151
130.85,167.22,0.150
130.87,167.40,0.150
130.89,167.59,0.150
130.91,167.77,0.150
130.93,167.95,0.150
130.95,168.14,0.150
130.96,168.32,0.150
130.98,168.50,0.150
131.00,168.69,0.150
131.02,168.87,0.150
131.04,169.06,0.149
131.05,169.24,0.149
131.07,169.42,0.149
131.09,169.61,0.149
131.11,169.79,0.149
131.13,169.97,0.149
131.15,170.15,0.149
131.16,170.34,0.149
131.18,170.52,0.149
131.20,170.71,0.149
131.22,170.89,0.149
131.24,171.07,0.149
131.26,171.26,0.149
131.28,171.44,0.149
131.29,171.62,0.150
131.31,171.81,0.150
131.33,171.99,0.150
131.35,172.17,0.150
131.37,172.36,0.150
131.39,172.54,0.150
131.40,172.72,0.150
131.42,172.91,0.150
131.44,173.09,0.150
131.46,173.27,0.150
131.48,173.46,0.150
131.50,173.64,0.150
131.51,173.82,0.150
131.53,174.01,0.150
131.55,174.19,0.150
131.57,174.37,0.150
131.59,174.56,0.150
131.60,174.74,0.150
131.62,174.92,0.150
131.64,175.11,0.150
131.66,175.29,0.150
131.68,175.48,0.150
131.70,175.66,0.151
131.71,175.84,0.151
131.73,176.03,0.151
131.75,176.21,0.151
131.77,176.39,0.151
131.79,176.58,0.151
131.81,176.76,0.151
131.83,176.94,0.151
131.84,177.13,0.151
131.86,177.31,0.151
131.88,177.49,0.151
131.90,177.68,0.151
131.92,177.86,0.151
131.94,178.04,0.151
131.95,178.23,0.151
131.97,178.41,0.151
131.99,178.60,0.151
132.01,178.78,0.151
132.03,178.96,0.151
132.05,179.15,0.151
132.06,179.33,0.151
132.08,179.51,0.151
132.10,179.70,0.151
132.12,179.88,0.151
132.14,180.06,0.151
132.15,180.24,0.152
132.17,180.43,0.152
132.19,180.61,0.152
132.21,180.79,0.152
132.23,180.98,0.152
132.25,181.16,0.152
132.26,181.34,0.152
132.28,181.53,0.152
132.30,181.71,0.152
132.32,181.89,0.152
132.34,182.08,0.152
132.36,182.26,0.152
132.38,182.44,0.152
132.39,182.63,0.152
132.41,182.81,0.152
132.43,182.99,0.152
132.45,183.18,0.152
132.47,183.36,0.153
132.49,183.55,0.153
132.50,183.73,0.153
132.52,183.91,0.153
132.54,184.10,0.153
132.56,184.28,0.153
132.58,184.46,0.153
132.60,184.65,0.153
132.61,184.83,0.153
132.63,185.01,0.153
132.65,185.19,0.153
132.67,185.38,0.153
132.69,185.56,0.153
132.70,185.75,0.153
132.72,185.93,0.153
132.74,186.11,0.153
132.76,186.30,0.154
132.78,186.48,0.154
132.80,186.66,0.154
132.81,186.85,0.154
132.83,187.03,0.154
132.85,187.22,0.154
132.87,187.40,0.154
132.89,187.58,0.154
132.91,187.77,0.154
132.93,187.95,0.154
132.94,188.13,0.154
132.96,188.32,0.154
132.98,188.50,0.154
133.00,188.68,0.154
133.02,188.87,0.154
133.04,189.05,0.154
133.05,189.23,0.154
133.07,189.42,0.154
133.09,189.60,0.155
133.11,189.78,0.155
133.13,189.97,0.155
133.15,190.15,0.155
133.16,190.33,0.155
133.18,190.52,0.155
133.20,190.70,0.155
133.22,190.88,0.155
133.24,191.07,0.155
133.25,191.25,0.155
133.27,191.44,0.155
133.29,191.62,0.155
133.31,191.80,0.155
133.33,191.99,0.155
133.35,192.17,0.155
133.36,192.35,0.155
133.38,192.54,0.155
133.40,192.72,0.156
133.42,192.90,0.156
133.44,193.09,0.156
133.46,193.27,0.156
133.48,193.45,0.156
133.49,193.64,0.156
133.51,193.82,0.156
133.53,194.00,0.156
133.55,194.18,0.156
133.57,194.37,0.156
133.59,194.55,0.156
133.60,194.73,0.156
133.62,194.92,0.156
133.64,195.10,0.156
133.66,195.28,0.156
133.68,195.47,0.156
133.70,195.65,0.157
133.71,195.84,0.157
133.73,196.02,0.157
133.75,196.20,0.157
133.77,196.39,0.157
133.79,196.57,0.157
133.80,196.75,0.157
133.82,196.94,0.157
133.84,197.12,0.157
133.86,197.30,0.157
133.88,197.49,0.157
133.90,197.67,0.157
133.91,197.85,0.157
133.93,198.04,
133.95,198.22,
133.97,198.40,
133.99,,