File: DSC/2025_04_13_CBD_Pro_MechanoChem_2min_n60C_200C_10Cmin.csv
Filename,2025_04_13_CBD_Pro_MechanoChem_2min_n60C_200C_10Cmin
Instrument name,DSC2A-00468 (192.168.1.100)
Operator,Yarger
rundate,4/13/2025
Sample name,2025_04_13_CBD_Pro_MechanoChem_2min_n60C_200C_10Cmin
proceduresegments,Data Off ; Equilibrate -60.00 °C; Data On ; Ramp 10.00 °C/min to 200.00 °C; Data Off ; Isothermal 1.0 min; Data On ; Ramp 10.00 °C/min to -60.00 °C; Data Off ; Isothermal 1.0 min; Data On ; Ramp 10.00 °C/min to 200.00 °C; Data Off ; Isothermal 1.0 min; Data On ; Ramp 10.00 °C/min to -60.00 °C; Data Off ; Isothermal 1.0 min; Data On ; Ramp 10.00 °C/min to 200.00 °C
[File Parameters]
Run date,4/13/2025 4:04:26 AM
Trios version,5.1.1.46572
Original File Name,
Current File Name,D:\DSC2500\JYarger\2025_04_13_CBD_Pro_MechanoChem_2min_n60C_200C_10Cmin.tri
[Procedure]
Procedure Name,CBD_n60_150C_10Cmin_x3
Sample Name,2025_04_13_CBD_Pro_MechanoChem_2min_n60C_200C_10Cmin
Sample Mass,3.44 mg
Reference Sample Mass,0 mg
Pan Mass,53.8 mg
Pan Number,23
Reference Pan Mass,53.32 mg
Reference Pan Number,10
Pan Type,Tzero Aluminum Hermetic
Comments,Hermetic Sealed Al DSC Consumables Pan/Lids.
Project Name,CA
Operator,Yarger
Test,Custom
Unload Max Temperature,30
Unload Min Temperature,30
Load Max Temperature,30
Load Min Temperature,30
Stop on Gas Flow Error,Yes
[Signal List]
Signal #1,Time (min)
Signal #2,Temperature (°C)
Signal #3,Heat Flow (mW)
Signal #4,Delta T (µV)
Signal #5,Delta Tzero (µV)
Signal #6,Tzero Temperature (°C)
Signal #7,Cell Purge (mL/min)
Signal #8,Heater Temp (°C)
Signal #9,Power Delivered (W)
Signal #10,Reference Junction Temperature (°C)
Signal #11,Flange Temperature (°C)
Signal #12,Heat Flow Phase (rad)
Signal #13,Total Heat Capacity (J/°C)
Signal #14,Heat Capacity (J/°C)
[Configuration]
Company Name,ASU
Instrument Name,DSC2A-00468
Instrument Type,DSC2500
Serial Number,DSC2A-00468
IP,192.168.1.100
Location of Instrument,MRRC
DisplayType,Unknown
Sample Interval ,0.1 s/pt
Selected Heat Flow,T4P
Exotherm Direction,Down
Cell Serial,DRC2-00792
Lid Type,Standard
Cooler,RCS 90
Leave Cooler on at End of Sequence,On
Gas 2,Nitrogen
Gas Selected,Channel 1
Flow Rate,50 mL/min
Secondary Purge,On
Licensed Heat Flow,Heat Flow T4P
Modulation Licensed,Yes
[Versions]
Common IDD Version,1
Cortex Version,VER 2.10.2.31
Driver,5.0.0.6
GDM Version,1.0.3.3
TouchscreenVersion,1.0.0.16145
FEP Version,1.2.1.21
FEP Bootloader,2.0.0.5
AutoSampler Version,2.1.1.26
Auto Sampler Bootloader,2.0.0.5
FCM Version,1.1.0.3
FCM Bootloader,2.0.0.5
[Experiment Logs]
Experiment Log Entry # 1,Data On set to 0
Experiment Log Entry # 3,Equilibrate Segment -60 (C) Started
Experiment Log Entry # 5,Air Cool is off.
Experiment Log Entry # 7,Data On set to 1
Experiment Log Entry # 9,Ramp Segment 10 C/min to 200 Started
Experiment Log Entry # 11,Data On set to 0
Experiment Log Entry # 13,Isothermal Segment 1 min started
Experiment Log Entry # 15,Data On set to 1
Experiment Log Entry # 17,Ramp Segment 10 C/min to -60 Started
Experiment Log Entry # 19,Data On set to 0
Experiment Log Entry # 21,Isothermal Segment 1 min started
Experiment Log Entry # 23,Data On set to 1
Experiment Log Entry # 25,Ramp Segment 10 C/min to 200 Started
Experiment Log Entry # 27,Data On set to 0
Experiment Log Entry # 29,Isothermal Segment 1 min started
Experiment Log Entry # 31,Data On set to 1
Experiment Log Entry # 33,Ramp Segment 10 C/min to -60 Started
Experiment Log Entry # 35,Data On set to 0
Experiment Log Entry # 37,Isothermal Segment 1 min started
Experiment Log Entry # 39,Data On set to 1
Experiment Log Entry # 41,Ramp Segment 10 C/min to 200 Started
[Method Log]
Method Log Entry # 1,Data Off
Method Log Entry # 2,Equilibrate -60 °C
Method Log Entry # 3,Data On
Method Log Entry # 4,(Ramp 320224) Ramp 10 °C/minute to 200 °C
Method Log Entry # 5,Data Off
Method Log Entry # 6,Isothermal 1 minutes
Method Log Entry # 7,Data On
Method Log Entry # 8,(Ramp 320228) Ramp 10 °C/minute to -60 °C
Method Log Entry # 9,Data Off
Method Log Entry # 10,Isothermal 1 minutes
Method Log Entry # 11,Data On
Method Log Entry # 12,(Ramp 320232) Ramp 10 °C/minute to 200 °C
Method Log Entry # 13,Data Off
Method Log Entry # 14,Isothermal 1 minutes
Method Log Entry # 15,Data On
Method Log Entry # 16,(Ramp 320236) Ramp 10 °C/minute to -60 °C
Method Log Entry # 17,Data Off
Method Log Entry # 18,Isothermal 1 minutes
Method Log Entry # 19,Data On
Method Log Entry # 20,(Ramp 320240) Ramp 10 °C/minute to 200 °C
Cell Serial,DRC2-00792
[T1 Calibration]
Slope,-0.008529666
Offset,9.636258
Initial Temperature,98.23
GUID,f8bfdadc-4977-4fdf-ba6d-0ba9134940c3
[TZero Calibration]
Date Applied,11/29/2022 4:06:13 PM
Description,From -89.059 °C to 396.009 °C at 20.000°C/min
Gas Type,Nitrogen
Pan Type,None
Source Files 1,C:\Users\yargerlab\Desktop\DSC Data\General\TZero_calibration_11_29_22_2nd(2).tri
Source Files 2,C:\Users\yargerlab\Desktop\DSC Data\General\TZero_calibration_11_29_22_2nd(3).tri
Delta T Offset,13.05235
Delta T Slope,-0.007271007
Delta T0 Offset,-13.69128
Delta T0 Slope,0.06063341
[Temperature Calibration]
Date Applied,11/29/2022 7:12:28 PM
Description,From 106.590 °C to 186.590 °C at 10.000°C/min
Gas Type,Nitrogen
Pan Type,Tzero Aluminum Hermetic
Source Files 1,C:\Users\yargerlab\Desktop\DSC Data\General\Indium(6).tri
Measured 1,157.391
Known 1,156.598
[Cell Constant Calibration]
Date Applied,11/29/2022 7:12:29 PM
Description,From 106.590 °C to 186.590 °C at 10.000°C/min
Gas Type,Nitrogen
Pan Type,Tzero Aluminum Hermetic
Source Files 1,C:\Users\yargerlab\Desktop\DSC Data\General\Indium(6).tri
T4P KCell,1.006051
Onset Slope,63.26126 mW/°C
[Direct Cp Calibration]
Date Applied,11/30/2022 11:04:51 AM
Description,From -79.983 °C to 298.409 °C at 10.000°C/min
Gas Type,Nitrogen
Pan Type,Tzero Aluminum Hermetic
Source Files 1,C:\Users\yargerlab\Desktop\DSC Data\General\Sapphire_Heat_Capacity_11_30_22.tri
[Rev Cp Calibration]
Date Applied,11/30/2022 1:58:51 PM
Description,From -79.996 °C to 292.812 °C at 3.000°C/min
Gas Type,Nitrogen
Pan Type,Tzero Aluminum Hermetic
Source Files 1,C:\Users\yargerlab\Desktop\DSC Data\General\Sapphire_MDSC_Calibration_11_30_22.tri
[step]
Ramp 10.00 °C/min to 200.00 °C
Time,Temperature,Heat Flow (Normalized)
min,°C,W/g
0.00,-59.70,-0.055
0.02,-59.71,-0.053
0.04,-59.72,-0.047
0.05,-59.71,-0.040
0.07,-59.70,-0.037
0.09,-59.67,-0.033
0.11,-59.61,-0.027
0.13,-59.54,-0.015
0.15,-59.45,0.001
0.16,-59.34,0.021
0.18,-59.22,0.042
0.20,-59.08,0.065
0.22,-58.94,0.086
0.24,-58.79,0.103
0.26,-58.64,0.122
0.28,-58.48,0.138
0.29,-58.32,0.153
0.31,-58.16,0.164
0.33,-57.99,0.172
0.35,-57.83,0.182
0.37,-57.66,0.190
0.39,-57.49,0.195
0.40,-57.32,0.200
0.42,-57.14,0.205
0.44,-56.97,0.210
0.46,-56.80,0.212
0.48,-56.62,0.215
0.50,-56.45,0.216
0.51,-56.27,0.218
0.53,-56.10,0.220
0.55,-55.92,0.221
0.57,-55.74,0.222
0.59,-55.56,0.224
0.60,-55.39,0.224
0.62,-55.21,0.225
0.64,-55.03,0.225
0.66,-54.85,0.227
0.68,-54.67,0.227
0.70,-54.49,0.227
0.72,-54.31,0.228
0.73,-54.13,0.228
0.75,-53.96,0.229
0.77,-53.77,0.229
0.79,-53.59,0.230
0.81,-53.41,0.230
0.83,-53.23,0.230
0.84,-53.05,0.231
0.86,-52.87,0.231
0.88,-52.69,0.231
0.90,-52.51,0.232
0.92,-52.33,0.232
0.93,-52.15,0.232
0.95,-51.97,0.232
0.97,-51.79,0.233
0.99,-51.60,0.233
1.01,-51.42,0.233
1.03,-51.24,0.233
1.05,-51.06,0.233
1.06,-50.88,0.234
1.08,-50.70,0.234
1.10,-50.51,0.234
1.12,-50.33,0.234
1.14,-50.15,0.234
1.16,-49.97,0.234
1.17,-49.79,0.234
1.19,-49.60,0.234
1.21,-49.42,0.234
1.23,-49.24,0.234
1.25,-49.06,0.234
1.27,-48.87,0.235
1.28,-48.69,0.235
1.30,-48.51,0.235
1.32,-48.33,0.235
1.34,-48.15,0.235
1.36,-47.96,0.235
1.38,-47.78,0.235
1.39,-47.60,0.235
1.41,-47.41,0.235
1.43,-47.23,0.235
1.45,-47.05,0.235
1.47,-46.87,0.235
1.48,-46.68,0.235
1.50,-46.50,0.235
1.52,-46.32,0.235
1.54,-46.13,0.235
1.56,-45.95,0.235
1.58,-45.77,0.235
1.59,-45.58,0.235
1.61,-45.40,0.235
1.63,-45.22,0.235
1.65,-45.03,0.235
1.67,-44.85,0.235
1.69,-44.67,0.235
1.71,-44.49,0.235
1.72,-44.30,0.235
1.74,-44.12,0.235
1.76,-43.94,0.235
1.78,-43.75,0.235
1.80,-43.57,0.235
1.82,-43.38,0.235
1.83,-43.20,0.235
1.85,-43.02,0.235
1.87,-42.84,0.235
1.89,-42.65,0.235
1.91,-42.47,0.235
1.93,-42.29,0.235
1.94,-42.10,0.235
1.96,-41.92,0.235
1.98,-41.74,0.235
2.00,-41.55,0.235
2.02,-41.37,0.235
2.03,-41.19,0.235
2.05,-41.00,0.235
2.07,-40.82,0.235
2.09,-40.63,0.235
2.11,-40.45,0.235
2.13,-40.27,0.235
2.14,-40.08,0.235
2.16,-39.90,0.235
2.18,-39.72,0.235
2.20,-39.53,0.235
2.22,-39.35,0.235
2.24,-39.17,0.235
2.26,-38.98,0.235
2.27,-38.80,0.235
2.29,-38.62,0.235
2.31,-38.43,0.235
2.33,-38.25,0.235
2.35,-38.06,0.235
2.36,-37.88,0.235
2.38,-37.70,0.235
2.40,-37.51,0.235
2.42,-37.33,0.235
2.44,-37.15,0.235
2.46,-36.96,0.235
2.48,-36.78,0.235
2.49,-36.60,0.235
2.51,-36.42,0.235
2.53,-36.23,0.235
2.55,-36.05,0.235
2.57,-35.86,0.235
2.59,-35.68,0.235
2.60,-35.50,0.235
2.62,-35.31,0.235
2.64,-35.13,0.235
2.66,-34.95,0.235
2.68,-34.76,0.235
2.69,-34.58,0.235
2.71,-34.39,0.235
2.73,-34.21,0.235
2.75,-34.03,0.235
2.77,-33.84,0.235
2.79,-33.66,0.235
2.81,-33.48,0.235
2.82,-33.29,0.235
2.84,-33.11,0.235
2.86,-32.93,0.235
2.88,-32.74,0.235
2.90,-32.56,0.235
2.91,-32.38,0.235
2.93,-32.19,0.235
2.95,-32.01,0.235
2.97,-31.82,0.235
2.99,-31.64,0.235
3.01,-31.46,0.236
3.03,-31.27,0.235
3.04,-31.09,0.235
3.06,-30.91,0.236
3.08,-30.72,0.236
3.10,-30.54,0.236
3.12,-30.35,0.236
3.14,-30.17,0.236
3.15,-29.99,0.236
3.17,-29.80,0.236
3.19,-29.62,0.236
3.21,-29.44,0.236
3.23,-29.25,0.236
3.24,-29.07,0.236
3.26,-28.88,0.236
3.28,-28.70,0.236
3.30,-28.52,0.236
3.32,-28.33,0.236
3.34,-28.15,0.236
3.36,-27.97,0.236
3.37,-27.78,0.236
3.39,-27.60,0.236
3.41,-27.42,0.236
3.43,-27.23,0.236
3.45,-27.05,0.236
3.46,-26.87,0.236
3.48,-26.68,0.236
3.50,-26.50,0.236
3.52,-26.32,0.236
3.54,-26.13,0.236
3.56,-25.95,0.236
3.58,-25.77,0.236
3.59,-25.58,0.236
3.61,-25.40,0.236
3.63,-25.21,0.236
3.65,-25.03,0.236
3.67,-24.85,0.236
3.69,-24.66,0.236
3.70,-24.48,0.236
3.72,-24.30,0.236
3.74,-24.11,0.236
3.76,-23.93,0.236
3.78,-23.75,0.236
3.79,-23.56,0.236
3.81,-23.38,0.236
3.83,-23.19,0.236
3.85,-23.01,0.236
3.87,-22.83,0.236
3.89,-22.64,0.236
3.91,-22.46,0.236
3.92,-22.28,0.236
3.94,-22.09,0.236
3.96,-21.91,0.236
3.98,-21.73,0.236
4.00,-21.54,0.236
4.01,-21.36,0.236
4.03,-21.18,0.236
4.05,-20.99,0.237
4.07,-20.81,0.237
4.09,-20.62,0.237
4.11,-20.44,0.237
4.13,-20.26,0.237
4.14,-20.07,0.237
4.16,-19.89,0.237
4.18,-19.71,0.237
4.20,-19.52,0.237
4.22,-19.34,0.237
4.24,-19.16,0.237
4.25,-18.97,0.237
4.27,-18.79,0.237
4.29,-18.60,0.237
4.31,-18.42,0.237
4.33,-18.24,0.237
4.35,-18.05,0.237
4.36,-17.87,0.237
4.38,-17.69,0.237
4.40,-17.50,0.237
4.42,-17.32,0.237
4.44,-17.14,0.237
4.45,-16.95,0.237
4.47,-16.77,0.237
4.49,-16.59,0.237
4.51,-16.40,0.237
4.53,-16.22,0.237
4.55,-16.03,0.237
4.56,-15.85,0.237
4.58,-15.67,0.237
4.60,-15.48,0.237
4.62,-15.30,0.237
4.64,-15.12,0.237
4.66,-14.93,0.238
4.68,-14.75,0.238
4.69,-14.57,0.238
4.71,-14.38,0.238
4.73,-14.20,0.238
4.75,-14.02,0.238
4.77,-13.83,0.238
4.79,-13.65,0.238
4.80,-13.47,0.238
4.82,-13.28,0.238
4.84,-13.10,0.238
4.86,-12.92,0.238
4.88,-12.73,0.238
4.90,-12.55,0.238
4.91,-12.36,0.238
4.93,-12.18,0.238
4.95,-12.00,0.238
4.97,-11.82,0.238
4.99,-11.63,0.238
5.00,-11.45,0.238
5.02,-11.26,0.238
5.04,-11.08,0.238
5.06,-10.90,0.238
5.08,-10.71,0.238
5.10,-10.53,0.238
5.11,-10.35,0.238
5.13,-10.16,0.238
5.15,-9.98,0.238
5.17,-9.79,0.239
5.19,-9.61,0.239
5.21,-9.43,0.239
5.23,-9.25,0.239
5.24,-9.06,0.239
5.26,-8.88,0.239
5.28,-8.69,0.239
5.30,-8.51,0.239
5.32,-8.33,0.239
5.34,-8.14,0.239
5.35,-7.96,0.239
5.37,-7.78,0.239
5.39,-7.59,0.239
5.41,-7.41,0.240
5.43,-7.23,0.240
5.45,-7.04,0.240
5.46,-6.86,0.240
5.48,-6.67,0.240
5.50,-6.49,0.240
5.52,-6.31,0.240
5.54,-6.12,0.240
5.55,-5.94,0.240
5.57,-5.76,0.240
5.59,-5.57,0.240
5.61,-5.39,0.240
5.63,-5.21,0.240
5.65,-5.02,0.240
5.66,-4.84,0.240
5.68,-4.65,0.241
5.70,-4.47,0.241
5.72,-4.29,0.241
5.74,-4.10,0.241
5.76,-3.92,0.241
5.78,-3.74,0.241
5.79,-3.56,0.241
5.81,-3.37,0.241
5.83,-3.19,0.241
5.85,-3.00,0.241
5.87,-2.82,0.241
5.89,-2.64,0.241
5.90,-2.45,0.241
5.92,-2.27,0.241
5.94,-2.09,0.241
5.96,-1.90,0.241
5.98,-1.72,0.242
6.00,-1.54,0.241
6.01,-1.35,0.242
6.03,-1.17,0.242
6.05,-0.99,0.242
6.07,-0.80,0.242
6.09,-0.62,0.242
6.10,-0.43,0.242
6.12,-0.25,0.242
6.14,-0.07,0.242
6.16,0.12,0.242
6.18,0.30,0.242
6.20,0.48,0.242
6.21,0.67,0.242
6.23,0.85,0.242
6.25,1.03,0.242
6.27,1.22,0.242
6.29,1.40,0.243
6.31,1.58,0.243
6.33,1.77,0.243
6.34,1.95,0.243
6.36,2.14,0.243
6.38,2.32,0.243
6.40,2.50,0.243
6.42,2.69,0.243
6.44,2.87,0.243
6.45,3.05,0.243
6.47,3.24,0.243
6.49,3.42,0.243
6.51,3.60,0.243
6.53,3.79,0.244
6.55,3.97,0.244
6.56,4.16,0.244
6.58,4.34,0.244
6.60,4.52,0.244
6.62,4.70,0.244
6.64,4.89,0.244
6.65,5.07,0.244
6.67,5.26,0.244
6.69,5.44,0.244
6.71,5.62,0.244
6.73,5.81,0.244
6.75,5.99,0.245
6.76,6.18,0.245
6.78,6.36,0.245
6.80,6.54,0.245
6.82,6.72,0.245
6.84,6.91,0.245
6.86,7.09,0.245
6.88,7.28,0.245
6.89,7.46,0.245
6.91,7.64,0.245
6.93,7.83,0.245
6.95,8.01,0.245
6.97,8.19,0.246
6.99,8.38,0.246
7.00,8.56,0.246
7.02,8.74,0.246
7.04,8.93,0.246
7.06,9.11,0.246
7.08,9.29,0.246
7.10,9.48,0.246
7.11,9.66,0.246
7.13,9.85,0.246
7.15,10.03,0.246
7.17,10.21,0.246
7.19,10.40,0.247
7.20,10.58,0.247
7.22,10.76,0.247
7.24,10.95,0.247
7.26,11.13,0.247
7.28,11.31,0.247
7.30,11.50,0.247
7.31,11.68,0.247
7.33,11.87,0.247
7.35,12.05,0.247
7.37,12.23,0.248
7.39,12.42,0.248
7.41,12.60,0.248
7.43,12.78,0.248
7.44,12.97,0.248
7.46,13.15,0.248
7.48,13.34,0.248
7.50,13.52,0.248
7.52,13.70,0.248
7.54,13.88,0.249
7.55,14.07,0.249
7.57,14.25,0.249
7.59,14.44,0.249
7.61,14.62,0.249
7.63,14.80,0.249
7.65,14.99,0.249
7.66,15.17,0.249
7.68,15.35,0.249
7.70,15.54,0.249
7.72,15.72,0.249
7.74,15.90,0.250
7.75,16.09,0.250
7.77,16.27,0.250
7.79,16.45,0.250
7.81,16.64,0.250
7.83,16.82,0.250
7.85,17.00,0.250
7.86,17.19,0.250
7.88,17.37,0.250
7.90,17.55,0.250
7.92,17.74,0.250
7.94,17.92,0.250
7.96,18.11,0.250
7.98,18.29,0.251
7.99,18.47,0.251
8.01,18.66,0.251
8.03,18.84,0.251
8.05,19.02,0.251
8.07,19.21,0.251
8.09,19.39,0.251
8.10,19.57,0.251
8.12,19.76,0.252
8.14,19.94,0.252
8.16,20.12,0.252
8.18,20.31,0.252
8.20,20.49,0.252
8.21,20.67,0.252
8.23,20.86,0.252
8.25,21.04,0.252
8.27,21.22,0.253
8.29,21.41,0.253
8.30,21.59,0.253
8.32,21.77,0.253
8.34,21.96,0.253
8.36,22.14,0.253
8.38,22.33,0.253
8.40,22.51,0.253
8.41,22.69,0.254
8.43,22.88,0.254
8.45,23.06,0.254
8.47,23.24,0.254
8.49,23.43,0.254
8.51,23.61,0.254
8.53,23.79,0.254
8.54,23.98,0.254
8.56,24.16,0.254
8.58,24.34,0.254
8.60,24.53,0.255
8.62,24.71,0.255
8.63,24.90,0.255
8.65,25.08,0.255
8.67,25.26,0.255
8.69,25.45,0.255
8.71,25.63,0.255
8.73,25.81,0.255
8.75,26.00,0.256
8.76,26.18,0.256
8.78,26.36,0.256
8.80,26.55,0.256
8.82,26.73,0.256
8.84,26.91,0.256
8.85,27.10,0.256
8.87,27.28,0.257
8.89,27.47,0.257
8.91,27.65,0.257
8.93,27.83,0.257
8.95,28.02,0.257
8.97,28.20,0.257
8.98,28.38,0.257
9.00,28.57,0.257
9.02,28.75,0.258
9.04,28.93,0.258
9.06,29.12,0.258
9.08,29.30,0.258
9.09,29.48,0.258
9.11,29.67,0.258
9.13,29.85,0.258
9.15,30.03,0.259
9.17,30.22,0.259
9.18,30.40,0.259
9.20,30.59,0.259
9.22,30.77,0.259
9.24,30.95,0.259
9.26,31.14,0.259
9.28,31.32,0.259
9.30,31.50,0.260
9.31,31.69,0.260
9.33,31.87,0.260
9.35,32.05,0.260
9.37,32.24,0.260
9.39,32.42,0.260
9.40,32.60,0.260
9.42,32.79,0.260
9.44,32.97,0.261
9.46,33.15,0.261
9.48,33.34,0.261
9.50,33.52,0.261
9.52,33.71,0.261
9.53,33.89,0.261
9.55,34.07,0.261
9.57,34.26,0.261
9.59,34.44,0.262
9.61,34.62,0.262
9.63,34.81,0.262
9.64,34.99,0.262
9.66,35.17,0.262
9.68,35.36,0.262
9.70,35.54,0.262
9.72,35.72,0.263
9.73,35.91,0.263
9.75,36.09,0.263
9.77,36.27,0.263
9.79,36.46,0.263
9.81,36.64,0.263
9.83,36.83,0.263
9.85,37.01,0.263
9.86,37.19,0.264
9.88,37.38,0.264
9.90,37.56,0.264
9.92,37.74,0.264
9.94,37.93,0.264
9.95,38.11,0.264
9.97,38.29,0.264
9.99,38.48,0.264
10.01,38.66,0.265
10.03,38.84,0.265
10.05,39.03,0.265
10.07,39.21,0.265
10.08,39.40,0.265
10.10,39.58,0.265
10.12,39.76,0.265
10.14,39.95,0.266
10.16,40.13,0.266
10.18,40.31,0.266
10.19,40.50,0.266
10.21,40.68,0.266
10.23,40.86,0.266
10.25,41.05,0.266
10.27,41.23,0.267
10.28,41.41,0.267
10.30,41.60,0.267
10.32,41.78,0.267
10.34,41.96,0.267
10.36,42.15,0.267
10.38,42.33,0.267
10.40,42.51,0.268
10.41,42.70,0.268
10.43,42.88,0.268
10.45,43.07,0.268
10.47,43.25,0.268
10.49,43.43,0.268
10.50,43.61,0.268
10.52,43.80,0.269
10.54,43.98,0.269
10.56,44.17,0.269
10.58,44.35,0.269
10.60,44.53,0.269
10.62,44.72,0.269
10.63,44.90,0.270
10.65,45.08,0.270
10.67,45.27,0.270
10.69,45.45,0.270
10.71,45.64,0.270
10.73,45.82,0.270
10.74,46.00,0.271
10.76,46.18,0.271
10.78,46.37,0.271
10.80,46.55,0.271
10.82,46.73,0.271
10.83,46.92,0.272
10.85,47.10,0.272
10.87,47.29,0.272
10.89,47.47,0.272
10.91,47.65,0.272
10.93,47.84,0.272
10.95,48.02,0.273
10.96,48.20,0.273
10.98,48.39,0.273
11.00,48.57,0.273
11.02,48.75,0.273
11.04,48.94,0.274
11.05,49.12,0.274
11.07,49.30,0.274
11.09,49.49,0.274
11.11,49.67,0.274
11.13,49.85,0.275
11.15,50.04,0.275
11.17,50.22,0.275
11.18,50.40,0.275
11.20,50.59,0.275
11.22,50.77,0.276
11.24,50.96,0.276
11.26,51.14,0.276
11.28,51.32,0.276
11.29,51.51,0.276
11.31,51.69,0.277
11.33,51.87,0.277
11.35,52.06,0.277
11.37,52.24,0.277
11.38,52.42,0.277
11.40,52.61,0.278
11.42,52.79,0.278
11.44,52.98,0.278
11.46,53.16,0.279
11.48,53.34,0.279
11.50,53.53,0.279
11.51,53.71,0.279
11.53,53.89,0.280
11.55,54.08,0.280
11.57,54.26,0.280
11.59,54.44,0.280
11.60,54.62,0.281
11.62,54.81,0.281
11.64,54.99,0.281
11.66,55.17,0.282
11.68,55.36,0.282
11.70,55.54,0.282
11.72,55.72,0.283
11.73,55.91,0.283
11.75,56.09,0.283
11.77,56.28,0.284
11.79,56.46,0.284
11.81,56.64,0.284
11.83,56.83,0.285
11.84,57.01,0.285
11.86,57.19,0.286
11.88,57.38,0.286
11.90,57.56,0.287
11.92,57.74,0.287
11.93,57.93,0.288
11.95,58.11,0.288
11.97,58.29,0.289
11.99,58.48,0.290
12.01,58.66,0.290
12.03,58.84,0.291
12.05,59.03,0.291
12.06,59.21,0.293
12.08,59.39,0.293
12.10,59.58,0.294
12.12,59.76,0.295
12.14,59.94,0.296
12.15,60.13,0.298
12.17,60.31,0.299
12.19,60.50,0.302
12.21,60.68,0.302
12.23,60.86,0.304
12.25,61.04,0.307
12.27,61.23,0.308
12.28,61.41,0.310
12.30,61.59,0.314
12.32,61.78,0.318
12.34,61.96,0.322
12.36,62.14,0.326
12.38,62.33,0.332
12.39,62.51,0.336
12.41,62.69,0.342
12.43,62.87,0.349
12.45,63.06,0.354
12.47,63.24,0.365
12.48,63.42,0.371
12.50,63.60,0.383
12.52,63.78,0.392
12.54,63.97,0.406
12.56,64.15,0.420
12.58,64.33,0.435
12.60,64.51,0.454
12.61,64.69,0.472
12.63,64.87,0.496
12.65,65.05,0.517
12.67,65.23,0.547
12.69,65.40,0.577
12.70,65.58,0.609
12.72,65.76,0.641
12.74,65.93,0.678
12.76,66.11,0.712
12.78,66.29,0.749
12.80,66.46,0.786
12.82,66.64,0.831
12.83,66.81,0.868
12.85,66.98,0.908
12.87,67.16,0.946
12.89,67.33,0.988
12.91,67.51,1.027
12.93,67.68,1.065
12.94,67.86,1.101
12.96,68.03,1.140
12.98,68.21,1.176
13.00,68.38,1.210
13.02,68.56,1.241
13.03,68.73,1.269
13.05,68.91,1.297
13.07,69.08,1.325
13.09,69.26,1.348
13.11,69.44,1.372
13.13,69.61,1.393
13.15,69.79,1.409
13.16,69.97,1.439
13.18,70.15,1.470
13.20,70.32,1.488
13.22,70.50,1.509
13.24,70.68,1.513
13.25,70.86,1.519
13.27,71.04,1.514
13.29,71.22,1.502
13.31,71.41,1.473
13.33,71.60,1.441
13.35,71.78,1.390
13.37,71.97,1.330
13.38,72.17,1.259
13.40,72.36,1.178
13.42,72.56,1.091
13.44,72.76,1.003
13.46,72.96,0.916
13.48,73.16,0.837
13.49,73.36,0.768
13.51,73.56,0.703
13.53,73.76,0.647
13.55,73.96,0.598
13.57,74.16,0.558
13.58,74.36,0.523
13.60,74.55,0.493
13.62,74.74,0.469
13.64,74.93,0.448
13.66,75.13,0.430
13.68,75.32,0.417
13.70,75.50,0.406
13.71,75.69,0.395
13.73,75.88,0.387
13.75,76.07,0.378
13.77,76.25,0.374
13.79,76.44,0.368
13.80,76.63,0.362
13.82,76.81,0.360
13.84,77.00,0.357
13.86,77.18,0.355
13.88,77.37,0.353
13.90,77.55,0.351
13.92,77.73,0.350
13.93,77.92,0.349
13.95,78.10,0.348
13.97,78.29,0.348
13.99,78.47,0.347
14.01,78.65,0.347
14.03,78.84,0.346
14.04,79.02,0.346
14.06,79.21,0.345
14.08,79.39,0.345
14.10,79.57,0.344
14.12,79.76,0.344
14.13,79.94,0.343
14.15,80.12,0.343
14.17,80.31,0.343
14.19,80.49,0.342
14.21,80.68,0.342
14.23,80.86,0.342
14.25,81.04,0.342
14.26,81.22,0.341
14.28,81.41,0.341
14.30,81.59,0.341
14.32,81.77,0.341
14.34,81.96,0.340
14.35,82.14,0.340
14.37,82.33,0.340
14.39,82.51,0.340
14.41,82.69,0.340
14.43,82.88,0.340
14.45,83.06,0.339
14.47,83.24,0.339
14.48,83.43,0.339
14.50,83.61,0.339
14.52,83.79,0.339
14.54,83.98,0.339
14.56,84.16,0.339
14.58,84.34,0.339
14.59,84.53,0.339
14.61,84.71,0.339
14.63,84.90,0.338
14.65,85.08,0.338
14.67,85.26,0.338
14.68,85.45,0.338
14.70,85.63,0.338
14.72,85.81,0.338
14.74,86.00,0.338
14.76,86.18,0.338
14.78,86.36,0.338
14.80,86.55,0.338
14.81,86.73,0.338
14.83,86.91,0.338
14.85,87.10,0.338
14.87,87.28,0.338
14.89,87.47,0.338
14.90,87.65,0.338
14.92,87.83,0.338
14.94,88.02,0.338
14.96,88.20,0.338
14.98,88.38,0.338
15.00,88.57,0.338
15.02,88.75,0.338
15.03,88.93,0.338
15.05,89.12,0.338
15.07,89.30,0.338
15.09,89.48,0.339
15.11,89.67,0.339
15.13,89.85,0.339
15.14,90.04,0.339
15.16,90.22,0.339
15.18,90.40,0.339
15.20,90.59,0.339
15.22,90.77,0.339
15.23,90.95,0.339
15.25,91.14,0.339
15.27,91.32,0.339
15.29,91.50,0.339
15.31,91.69,0.339
15.33,91.87,0.339
15.35,92.05,0.339
15.36,92.24,0.339
15.38,92.42,0.339
15.40,92.60,0.339
15.42,92.79,0.339
15.44,92.97,0.339
15.45,93.15,0.339
15.47,93.34,0.339
15.49,93.52,0.339
15.51,93.70,0.339
15.53,93.89,0.339
15.55,94.07,0.339
15.57,94.25,0.339
15.58,94.44,0.339
15.60,94.62,0.339
15.62,94.81,0.339
15.64,94.99,0.338
15.66,95.17,0.338
15.68,95.36,0.338
15.69,95.54,0.338
15.71,95.72,0.338
15.73,95.91,0.338
15.75,96.09,0.338
15.77,96.27,0.338
15.78,96.46,0.338
15.80,96.64,0.338
15.82,96.82,0.338
15.84,97.01,0.338
15.86,97.19,0.337
15.88,97.38,0.337
15.90,97.56,0.337
15.91,97.74,0.337
15.93,97.93,0.337
15.95,98.11,0.337
15.97,98.29,0.337
15.99,98.48,0.336
16.00,98.66,0.336
16.02,98.84,0.336
16.04,99.03,0.336
16.06,99.21,0.335
16.08,99.40,0.335
16.10,99.58,0.335
16.12,99.76,0.334
16.13,99.95,0.334
16.15,100.13,0.334
16.17,100.31,0.333
16.19,100.50,0.333
16.21,100.68,0.332
16.23,100.86,0.332
16.24,101.05,0.332
16.26,101.23,0.331
16.28,101.41,0.331
16.30,101.60,0.330
16.32,101.78,0.330
16.33,101.97,0.330
16.35,102.15,0.329
16.37,102.33,0.328
16.39,102.52,0.328
16.41,102.70,0.327
16.43,102.88,0.327
16.45,103.07,0.326
16.46,103.25,0.325
16.48,103.44,0.325
16.50,103.62,0.324
16.52,103.80,0.324
16.54,103.99,0.323
16.55,104.17,0.322
16.57,104.35,0.322
16.59,104.54,0.321
16.61,104.72,0.321
16.63,104.90,0.320
16.65,105.09,0.319
16.67,105.27,0.319
16.68,105.46,0.318
16.70,105.64,0.317
16.72,105.82,0.317
16.74,106.01,0.316
16.76,106.19,0.316
16.78,106.37,0.315
16.79,106.56,0.314
16.81,106.74,0.314
16.83,106.92,0.313
16.85,107.11,0.312
16.87,107.29,0.312
16.88,107.48,0.311
16.90,107.66,0.310
16.92,107.84,0.310
16.94,108.03,0.309
16.96,108.21,0.308
16.98,108.39,0.307
17.00,108.58,0.307
17.01,108.76,0.306
17.03,108.95,0.306
17.05,109.13,0.306
17.07,109.31,0.305
17.09,109.50,0.304
17.11,109.68,0.304
17.12,109.86,0.303
17.14,110.05,0.301
17.16,110.23,0.300
17.18,110.42,0.299
17.20,110.60,0.298
17.22,110.78,0.297
17.23,110.97,0.296
17.25,111.15,0.296
17.27,111.33,0.295
17.29,111.52,0.295
17.31,111.70,0.294
17.33,111.88,0.294
17.34,112.07,0.293
17.36,112.25,0.293
17.38,112.44,0.292
17.40,112.62,0.292
17.42,112.80,0.291
17.43,112.99,0.291
17.45,113.17,0.290
17.47,113.35,0.289
17.49,113.54,0.289
17.51,113.72,0.288
17.53,113.90,0.287
17.54,114.09,0.287
17.56,114.27,0.286
17.58,114.46,0.285
17.60,114.64,0.284
17.62,114.82,0.284
17.64,115.01,0.283
17.66,115.19,0.282
17.67,115.37,0.281
17.69,115.56,0.280
17.71,115.74,0.280
17.73,115.93,0.278
17.75,116.11,0.277
17.77,116.29,0.276
17.78,116.48,0.275
17.80,116.66,0.275
17.82,116.84,0.273
17.84,117.03,0.272
17.86,117.21,0.272
17.88,117.39,0.270
17.89,117.58,0.269
17.91,117.76,0.268
17.93,117.95,0.267
17.95,118.13,0.266
17.97,118.31,0.265
17.98,118.49,0.264
18.00,118.68,0.262
18.02,118.86,0.261
18.04,119.05,0.260
18.06,119.23,0.259
18.08,119.42,0.258
18.09,119.60,0.257
18.11,119.78,0.256
18.13,119.97,0.255
18.15,120.15,0.254
18.17,120.33,0.253
18.19,120.52,0.252
18.21,120.70,0.251
18.22,120.89,0.250
18.24,121.07,0.249
18.26,121.25,0.248
18.28,121.44,0.247
18.30,121.62,0.246
18.32,121.80,0.246
18.33,121.99,0.245
18.35,122.17,0.244
18.37,122.35,0.243
18.39,122.54,0.243
18.41,122.72,0.242
18.43,122.91,0.241
18.44,123.09,0.241
18.46,123.27,0.240
18.48,123.46,0.239
18.50,123.64,0.239
18.52,123.82,0.238
18.53,124.01,0.237
18.55,124.19,0.237
18.57,124.37,0.236
18.59,124.56,0.236
18.61,124.74,0.235
18.63,124.92,0.235
18.64,125.11,0.235
18.66,125.29,0.234
18.68,125.48,0.234
18.70,125.66,0.234
18.72,125.84,0.234
18.74,126.03,0.234
18.76,126.21,0.234
18.77,126.39,0.234
18.79,126.58,0.234
18.81,126.76,0.235
18.83,126.94,0.235
18.85,127.12,0.235
18.87,127.31,0.236
18.88,127.49,0.236
18.90,127.67,0.237
18.92,127.86,0.240
18.94,128.04,0.241
18.96,128.22,0.242
18.98,128.41,0.244
18.99,128.59,0.246
19.01,128.77,0.248
19.03,128.95,0.250
19.05,129.14,0.252
19.07,129.32,0.255
19.08,129.50,0.258
19.10,129.69,0.261
19.12,129.87,0.264
19.14,130.05,0.268
19.16,130.24,0.272
19.18,130.42,0.275
19.19,130.60,0.281
19.21,130.78,0.285
19.23,130.97,0.288
19.25,131.15,0.292
19.27,131.33,0.296
19.29,131.52,0.300
19.31,131.70,0.305
19.32,131.88,0.308
19.34,132.06,0.313
19.36,132.25,0.320
19.38,132.43,0.322
19.40,132.61,0.327
19.42,132.79,0.333
19.43,132.98,0.337
19.45,133.16,0.341
19.47,133.34,0.347
19.49,133.53,0.352
19.51,133.71,0.359
19.53,133.89,0.365
19.54,134.07,0.371
19.56,134.26,0.378
19.58,134.44,0.384
19.60,134.62,0.394
19.62,134.80,0.400
19.63,134.98,0.407
19.65,135.16,0.416
19.67,135.35,0.426
19.69,135.53,0.432
19.71,135.71,0.441
19.73,135.89,0.452
19.74,136.07,0.462
19.76,136.25,0.473
19.78,136.43,0.482
19.80,136.62,0.491
19.82,136.80,0.502
19.84,136.98,0.511
19.86,137.16,0.522
19.87,137.34,0.531
19.89,137.52,0.540
19.91,137.70,0.551
19.93,137.89,0.560
19.95,138.07,0.571
19.97,138.25,0.577
19.98,138.43,0.588
20.00,138.61,0.596
20.02,138.79,0.607
20.04,138.97,0.615
20.06,139.16,0.627
20.08,139.34,0.635
20.09,139.52,0.647
20.11,139.70,0.656
20.13,139.88,0.664
20.15,140.06,0.675
20.17,140.24,0.686
20.18,140.43,0.694
20.20,140.61,0.706
20.22,140.79,0.717
20.24,140.97,0.729
20.26,141.15,0.740
20.28,141.33,0.751
20.29,141.51,0.767
20.31,141.70,0.779
20.33,141.87,0.796
20.35,142.06,0.814
20.37,142.24,0.835
20.39,142.42,0.859
20.41,142.60,0.881
20.42,142.77,0.925
20.44,142.95,0.958
20.46,143.13,0.969
20.48,143.31,0.991
20.50,143.49,1.042
20.52,143.66,1.205
20.53,143.82,1.588
20.55,143.96,1.753
20.57,144.11,1.945
20.59,144.26,2.030
20.61,144.42,1.908
20.63,144.61,1.478
20.64,144.83,1.064
20.66,145.05,0.831
20.68,145.27,0.708
20.70,145.49,0.637
20.72,145.70,0.582
20.73,145.90,0.541
20.75,146.10,0.510
20.77,146.30,0.482
20.79,146.50,0.461
20.81,146.69,0.444
20.83,146.88,0.430
20.84,147.07,0.420
20.86,147.26,0.409
20.88,147.45,0.402
20.90,147.63,0.398
20.92,147.82,0.391
20.94,148.00,0.388
20.96,148.19,0.384
20.97,148.37,0.384
20.99,148.56,0.381
21.01,148.74,0.380
21.03,148.93,0.378
21.05,149.11,0.377
21.07,149.29,0.376
21.08,149.48,0.376
21.10,149.66,0.375
21.12,149.85,0.375
21.14,150.03,0.375
21.16,150.21,0.374
21.18,150.40,0.374
21.19,150.58,0.374
21.21,150.76,0.373
21.23,150.95,0.373
21.25,151.13,0.373
21.27,151.31,0.372
21.28,151.50,0.372
21.30,151.68,0.372
21.32,151.87,0.372
21.34,152.05,0.371
21.36,152.23,0.371
21.38,152.42,0.371
21.39,152.60,0.371
21.41,152.78,0.371
21.43,152.97,0.370
21.45,153.15,0.370
21.47,153.33,0.370
21.49,153.52,0.370
21.51,153.70,0.370
21.52,153.88,0.370
21.54,154.07,0.369
21.56,154.25,0.369
21.58,154.43,0.369
21.60,154.62,0.369
21.62,154.80,0.369
21.63,154.98,0.369
21.65,155.17,0.368
21.67,155.35,0.368
21.69,155.53,0.368
21.71,155.72,0.368
21.73,155.90,0.368
21.74,156.09,0.368
21.76,156.27,0.367
21.78,156.45,0.367
21.80,156.64,0.367
21.82,156.82,0.367
21.83,157.00,0.367
21.85,157.19,0.367
21.87,157.37,0.367
21.89,157.55,0.366
21.91,157.74,0.366
21.93,157.92,0.366
21.94,158.10,0.366
21.96,158.29,0.366
21.98,158.47,0.366
22.00,158.65,0.365
22.02,158.84,0.365
22.04,159.02,0.365
22.06,159.20,0.365
22.07,159.39,0.365
22.09,159.57,0.364
22.11,159.76,0.364
22.13,159.94,0.364
22.15,160.12,0.364
22.17,160.31,0.364
22.18,160.49,0.364
22.20,160.67,0.363
22.22,160.86,0.363
22.24,161.04,0.363
22.26,161.22,0.363
22.28,161.41,0.363
22.29,161.59,0.362
22.31,161.78,0.362
22.33,161.96,0.362
22.35,162.14,0.362
22.37,162.33,0.361
22.38,162.51,0.361
22.40,162.69,0.361
22.42,162.88,0.361
22.44,163.06,0.361
22.46,163.24,0.360
22.48,163.43,0.360
22.49,163.61,0.360
22.51,163.79,0.360
22.53,163.98,0.359
22.55,164.16,0.359
22.57,164.34,0.359
22.59,164.53,0.359
22.61,164.71,0.359
22.62,164.89,0.358
22.64,165.08,0.358
22.66,165.26,0.358
22.68,165.44,0.358
22.70,165.63,0.357
22.72,165.81,0.357
22.73,165.99,0.357
22.75,166.18,0.357
22.77,166.36,0.357
22.79,166.55,0.356
22.81,166.73,0.356
22.83,166.91,0.356
22.84,167.10,0.356
22.86,167.28,0.356
22.88,167.46,0.355
22.90,167.65,0.355
22.92,167.83,0.355
22.93,168.01,0.355
22.95,168.20,0.355
22.97,168.38,0.354
22.99,168.56,0.354
23.01,168.75,0.354
23.03,168.93,0.354
23.04,169.11,0.354
23.06,169.30,0.353
23.08,169.48,0.353
23.10,169.66,0.353
23.12,169.85,0.353
23.14,170.03,0.352
23.16,170.21,0.352
23.17,170.40,0.352
23.19,170.58,0.352
23.21,170.77,0.352
23.23,170.95,0.352
23.25,171.13,0.352
23.27,171.32,0.351
23.28,171.50,0.351
23.30,171.68,0.351
23.32,171.87,0.351
23.34,172.05,0.351
23.36,172.23,0.351
23.38,172.42,0.351
23.39,172.60,0.350
23.41,172.78,0.350
23.43,172.97,0.350
23.45,173.15,0.350
23.47,173.33,0.350
23.48,173.52,0.350
23.50,173.70,0.350
23.52,173.88,0.350
23.54,174.07,0.350
23.56,174.25,0.350
23.58,174.43,0.350
23.59,174.62,0.350
23.61,174.80,0.350
23.63,174.99,0.350
23.65,175.17,0.350
23.67,175.35,0.350
23.69,175.54,0.350
23.71,175.72,0.350
23.72,175.90,0.350
23.74,176.09,0.350
23.76,176.27,0.350
23.78,176.45,0.350
23.80,176.64,0.351
23.82,176.82,0.351
23.83,177.00,0.351
23.85,177.19,0.351
23.87,177.37,0.351
23.89,177.55,0.352
23.91,177.74,0.352
23.93,177.92,0.352
23.94,178.10,0.352
23.96,178.29,0.353
23.98,178.47,0.353
24.00,178.65,0.353
24.02,178.84,0.354
24.03,179.02,0.354
24.05,179.20,0.354
24.07,179.39,0.355
24.09,179.57,0.355
24.11,179.75,0.355
24.13,179.94,0.356
24.14,180.12,0.356
24.16,180.30,0.357
24.18,180.49,0.357
24.20,180.67,0.358
24.22,180.85,0.358
24.24,181.04,0.358
24.26,181.22,0.359
24.27,181.40,0.359
24.29,181.59,0.360
24.31,181.77,0.360
24.33,181.95,0.360
24.35,182.14,0.361
24.37,182.32,0.361
24.38,182.50,0.362
24.40,182.69,0.362
24.42,182.87,0.362
24.44,183.05,0.363
24.46,183.24,0.363
24.48,183.42,0.364
24.49,183.60,0.364
24.51,183.79,0.365
24.53,183.97,0.365
24.55,184.15,0.365
24.57,184.33,0.366
24.58,184.52,0.366
24.60,184.70,0.367
24.62,184.89,0.367
24.64,185.07,0.368
24.66,185.25,0.368
24.68,185.44,0.369
24.69,185.62,0.370
24.71,185.81,0.370
24.73,185.99,0.371
24.75,186.17,0.372
24.77,186.35,0.372
24.79,186.54,0.373
24.81,186.72,0.373
24.82,186.90,0.374
24.84,187.09,0.374
24.86,187.27,0.375
24.88,187.45,0.375
24.90,187.64,0.376
24.92,187.82,0.376
24.93,188.00,0.377
24.95,188.19,0.377
24.97,188.37,0.378
24.99,188.55,0.379
25.01,188.74,0.380
25.03,188.92,0.380
25.04,189.10,0.381
25.06,189.28,0.382
25.08,189.47,0.383
25.10,189.65,0.384
25.12,189.84,0.384
25.13,190.02,0.385
25.15,190.20,0.386
25.17,190.38,0.387
25.19,190.57,0.387
25.21,190.75,0.388
25.23,190.93,0.389
25.24,191.12,0.390
25.26,191.30,0.391
25.28,191.48,0.392
25.30,191.67,0.393
25.32,191.85,0.394
25.34,192.03,0.395
25.36,192.22,0.396
25.37,192.40,0.397
25.39,192.58,0.398
25.41,192.77,0.399
25.43,192.95,0.401
25.45,193.13,0.402
25.47,193.32,0.404
25.48,193.50,0.405
25.50,193.68,0.406
25.52,193.87,0.407
25.54,194.05,0.408
25.56,194.23,0.409
25.58,194.42,0.410
25.59,194.60,0.412
25.61,194.78,0.412
25.63,194.97,0.414
25.65,195.15,0.415
25.67,195.33,0.416
25.68,195.52,0.417
25.70,195.70,0.419
25.72,195.88,0.420
25.74,196.07,0.421
25.76,196.25,0.423
25.78,196.43,0.425
25.79,196.62,0.426
25.81,196.80,0.427
25.83,196.98,0.429
25.85,197.17,0.430
25.87,197.35,0.431
25.89,197.53,0.433
25.91,197.71,0.435
25.92,197.90,0.436
25.94,198.08,
25.96,198.26,
25.98,198.45,
25.99,,

[step]
Ramp 10.00 °C/min to -60.00 °C
Time,Temperature,Heat Flow (Normalized)
min,°C,W/g
26.99,200.07,-0.042
27.01,200.07,-0.042
27.03,200.07,-0.042
27.05,200.06,-0.042
27.07,200.04,-0.047
27.08,200.00,-0.074
27.10,199.94,-0.114
27.12,199.85,-0.164
27.14,199.75,-0.224
27.16,199.63,-0.280
27.18,199.50,-0.335
27.19,199.36,-0.378
27.21,199.20,-0.414
27.23,199.05,-0.445
27.25,198.89,-0.465
27.27,198.72,-0.482
27.29,198.55,-0.497
27.31,198.38,-0.511
27.32,198.21,-0.519
27.34,198.04,-0.524
27.36,197.86,-0.533
27.38,197.69,-0.538
27.40,197.51,-0.543
27.42,197.33,-0.546
27.43,197.15,-0.548
27.45,196.97,-0.552
27.47,196.80,-0.553
27.49,196.62,-0.554
27.51,196.44,-0.555
27.53,196.26,-0.556
27.54,196.08,-0.557
27.56,195.90,-0.558
27.58,195.72,-0.558
27.60,195.54,-0.559
27.62,195.35,-0.560
27.63,195.17,-0.560
27.65,194.99,-0.561
27.67,194.81,-0.561
27.69,194.63,-0.561
27.71,194.45,-0.562
27.73,194.27,-0.562
27.74,194.09,-0.562
27.76,193.91,-0.563
27.78,193.72,-0.563
27.80,193.54,-0.564
27.82,193.36,-0.564
27.84,193.18,-0.564
27.86,193.00,-0.565
27.87,192.82,-0.565
27.89,192.63,-0.565
27.91,192.45,-0.566
27.93,192.27,-0.566
27.95,192.09,-0.566
27.97,191.90,-0.566
27.98,191.72,-0.566
28.00,191.54,-0.567
28.02,191.36,-0.567
28.04,191.17,-0.567
28.06,190.99,-0.567
28.08,190.81,-0.567
28.09,190.63,-0.567
28.11,190.44,-0.567
28.13,190.26,-0.567
28.15,190.08,-0.567
28.17,189.90,-0.567
28.18,189.72,-0.567
28.20,189.53,-0.567
28.22,189.35,-0.567
28.24,189.17,-0.567
28.26,188.98,-0.567
28.28,188.80,-0.567
28.29,188.62,-0.567
28.31,188.44,-0.567
28.33,188.25,-0.567
28.35,188.07,-0.567
28.37,187.89,-0.567
28.39,187.71,-0.567
28.41,187.52,-0.566
28.42,187.34,-0.566
28.44,187.16,-0.566
28.46,186.97,-0.566
28.48,186.79,-0.566
28.50,186.61,-0.566
28.52,186.42,-0.566
28.53,186.24,-0.566
28.55,186.06,-0.566
28.57,185.88,-0.565
28.59,185.69,-0.565
28.61,185.51,-0.565
28.63,185.33,-0.565
28.64,185.15,-0.565
28.66,184.96,-0.565
28.68,184.78,-0.564
28.70,184.60,-0.564
28.72,184.41,-0.564
28.73,184.23,-0.564
28.75,184.05,-0.564
28.77,183.87,-0.564
28.79,183.68,-0.564
28.81,183.50,-0.563
28.83,183.32,-0.563
28.84,183.13,-0.563
28.86,182.95,-0.563
28.88,182.77,-0.562
28.90,182.58,-0.562
28.92,182.40,-0.562
28.94,182.22,-0.562
28.96,182.03,-0.562
28.97,181.85,-0.562
28.99,181.67,-0.561
29.01,181.49,-0.561
29.03,181.30,-0.561
29.05,181.12,-0.561
29.07,180.94,-0.561
29.08,180.75,-0.561
29.10,180.57,-0.560
29.12,180.39,-0.560
29.14,180.20,-0.560
29.16,180.02,-0.560
29.18,179.84,-0.560
29.19,179.66,-0.559
29.21,179.47,-0.559
29.23,179.29,-0.559
29.25,179.11,-0.559
29.27,178.92,-0.559
29.28,178.74,-0.558
29.30,178.56,-0.558
29.32,178.37,-0.558
29.34,178.19,-0.558
29.36,178.01,-0.557
29.38,177.82,-0.557
29.39,177.64,-0.557
29.41,177.46,-0.557
29.43,177.27,-0.557
29.45,177.09,-0.557
29.47,176.91,-0.556
29.49,176.73,-0.556
29.51,176.54,-0.556
29.52,176.36,-0.556
29.54,176.18,-0.556
29.56,175.99,-0.555
29.58,175.81,-0.555
29.60,175.63,-0.555
29.62,175.44,-0.555
29.63,175.26,-0.555
29.65,175.08,-0.555
29.67,174.90,-0.554
29.69,174.71,-0.554
29.71,174.53,-0.554
29.73,174.35,-0.554
29.74,174.16,-0.554
29.76,173.98,-0.554
29.78,173.79,-0.554
29.80,173.61,-0.553
29.82,173.43,-0.553
29.83,173.25,-0.553
29.85,173.06,-0.553
29.87,172.88,-0.553
29.89,172.70,-0.553
29.91,172.51,-0.552
29.93,172.33,-0.552
29.94,172.15,-0.552
29.96,171.96,-0.552
29.98,171.78,-0.551
30.00,171.60,-0.551
30.02,171.41,-0.551
30.04,171.23,-0.551
30.06,171.05,-0.551
30.07,170.87,-0.550
30.09,170.68,-0.550
30.11,170.50,-0.550
30.13,170.32,-0.550
30.15,170.13,-0.550
30.17,169.95,-0.549
30.18,169.77,-0.549
30.20,169.58,-0.549
30.22,169.40,-0.549
30.24,169.22,-0.549
30.26,169.03,-0.549
30.28,168.85,-0.548
30.29,168.67,-0.548
30.31,168.48,-0.548
30.33,168.30,-0.548
30.35,168.12,-0.548
30.37,167.94,-0.547
30.38,167.75,-0.547
30.40,167.57,-0.547
30.42,167.39,-0.547
30.44,167.20,-0.547
30.46,167.02,-0.546
30.48,166.84,-0.546
30.49,166.66,-0.546
30.51,166.47,-0.546
30.53,166.29,-0.546
30.55,166.11,-0.545
30.57,165.92,-0.545
30.59,165.74,-0.545
30.61,165.56,-0.545
30.62,165.37,-0.545
30.64,165.19,-0.545
30.66,165.01,-0.545
30.68,164.82,-0.545
30.70,164.64,-0.545
30.72,164.46,-0.544
30.73,164.27,-0.544
30.75,164.09,-0.544
30.77,163.91,-0.544
30.79,163.72,-0.544
30.81,163.54,-0.544
30.83,163.36,-0.544
30.84,163.17,-0.544
30.86,162.99,-0.544
30.88,162.81,-0.544
30.90,162.63,-0.544
30.92,162.44,-0.543
30.93,162.26,-0.543
30.95,162.08,-0.543
30.97,161.89,-0.543
30.99,161.71,-0.543
31.01,161.53,-0.543
31.03,161.34,-0.542
31.04,161.16,-0.542
31.06,160.98,-0.542
31.08,160.80,-0.542
31.10,160.61,-0.542
31.12,160.43,-0.542
31.14,160.25,-0.542
31.16,160.06,-0.541
31.17,159.88,-0.541
31.19,159.70,-0.541
31.21,159.51,-0.541
31.23,159.33,-0.541
31.25,159.15,-0.541
31.27,158.96,-0.541
31.28,158.78,-0.541
31.30,158.60,-0.541
31.32,158.41,-0.540
31.34,158.23,-0.540
31.36,158.05,-0.540
31.38,157.86,-0.540
31.39,157.68,-0.540
31.41,157.50,-0.540
31.43,157.32,-0.540
31.45,157.13,-0.540
31.47,156.95,-0.539
31.48,156.77,-0.539
31.50,156.58,-0.539
31.52,156.40,-0.539
31.54,156.22,-0.539
31.56,156.03,-0.539
31.58,155.85,-0.539
31.59,155.67,-0.539
31.61,155.48,-0.539
31.63,155.30,-0.538
31.65,155.12,-0.538
31.67,154.94,-0.538
31.69,154.75,-0.538
31.71,154.57,-0.538
31.72,154.39,-0.538
31.74,154.20,-0.538
31.76,154.02,-0.538
31.78,153.84,-0.537
31.80,153.65,-0.537
31.82,153.47,-0.537
31.83,153.29,-0.537
31.85,153.10,-0.537
31.87,152.92,-0.537
31.89,152.74,-0.537
31.91,152.55,-0.536
31.93,152.37,-0.536
31.94,152.19,-0.536
31.96,152.00,-0.536
31.98,151.82,-0.536
32.00,151.64,-0.536
32.02,151.46,-0.536
32.03,151.27,-0.536
32.05,151.09,-0.535
32.07,150.91,-0.535
32.09,150.72,-0.535
32.11,150.54,-0.535
32.13,150.36,-0.535
32.14,150.17,-0.535
32.16,149.99,-0.535
32.18,149.81,-0.535
32.20,149.62,-0.535
32.22,149.44,-0.534
32.24,149.26,-0.534
32.26,149.08,-0.534
32.27,148.89,-0.534
32.29,148.71,-0.534
32.31,148.52,-0.534
32.33,148.34,-0.534
32.35,148.16,-0.534
32.37,147.98,-0.534
32.38,147.79,-0.533
32.40,147.61,-0.533
32.42,147.43,-0.533
32.44,147.24,-0.533
32.46,147.06,-0.533
32.48,146.88,-0.533
32.49,146.69,-0.533
32.51,146.51,-0.533
32.53,146.33,-0.533
32.55,146.15,-0.532
32.57,145.96,-0.532
32.58,145.78,-0.532
32.60,145.60,-0.532
32.62,145.41,-0.532
32.64,145.23,-0.531
32.66,145.05,-0.531
32.68,144.86,-0.531
32.69,144.68,-0.531
32.71,144.50,-0.531
32.73,144.31,-0.531
32.75,144.13,-0.531
32.77,143.95,-0.531
32.79,143.76,-0.531
32.81,143.58,-0.531
32.82,143.40,-0.530
32.84,143.21,-0.530
32.86,143.03,-0.530
32.88,142.85,-0.530
32.90,142.67,-0.530
32.92,142.48,-0.530
32.93,142.30,-0.530
32.95,142.12,-0.530
32.97,141.93,-0.530
32.99,141.75,-0.529
33.01,141.57,-0.529
33.03,141.38,-0.529
33.04,141.20,-0.529
33.06,141.02,-0.529
33.08,140.83,-0.529
33.10,140.65,-0.529
33.12,140.47,-0.529
33.13,140.28,-0.529
33.15,140.10,-0.528
33.17,139.92,-0.528
33.19,139.74,-0.528
33.21,139.55,-0.528
33.23,139.37,-0.528
33.24,139.19,-0.528
33.26,139.00,-0.528
33.28,138.82,-0.528
33.30,138.64,-0.527
33.32,138.45,-0.527
33.34,138.27,-0.527
33.36,138.09,-0.527
33.37,137.90,-0.527
33.39,137.72,-0.527
33.41,137.54,-0.527
33.43,137.35,-0.527
33.45,137.17,-0.526
33.47,136.99,-0.526
33.48,136.80,-0.526
33.50,136.62,-0.526
33.52,136.44,-0.526
33.54,136.25,-0.526
33.56,136.07,-0.526
33.58,135.89,-0.525
33.59,135.71,-0.525
33.61,135.52,-0.525
33.63,135.34,-0.525
33.65,135.16,-0.525
33.67,134.97,-0.525
33.68,134.79,-0.525
33.70,134.61,-0.525
33.72,134.42,-0.525
33.74,134.24,-0.524
33.76,134.06,-0.524
33.78,133.87,-0.524
33.79,133.69,-0.524
33.81,133.51,-0.524
33.83,133.33,-0.524
33.85,133.14,-0.524
33.87,132.96,-0.524
33.89,132.78,-0.524
33.91,132.59,-0.524
33.92,132.41,-0.524
33.94,132.23,-0.523
33.96,132.04,-0.523
33.98,131.86,-0.523
34.00,131.68,-0.523
34.02,131.49,-0.523
34.03,131.31,-0.523
34.05,131.13,-0.523
34.07,130.95,-0.523
34.09,130.76,-0.522
34.11,130.58,-0.522
34.13,130.40,-0.522
34.14,130.21,-0.522
34.16,130.03,-0.522
34.18,129.85,-0.522
34.20,129.66,-0.522
34.22,129.48,-0.522
34.24,129.30,-0.522
34.25,129.11,-0.522
34.27,128.93,-0.522
34.29,128.75,-0.521
[...]
115.21,10.64,0.345
115.23,10.82,0.345
115.25,11.00,0.345
115.27,11.19,0.345
115.29,11.37,0.345
115.31,11.55,0.345
115.33,11.74,0.345
115.34,11.92,0.344
115.36,12.10,0.345
115.38,12.29,0.345
115.40,12.47,0.345
115.42,12.66,0.345
115.44,12.84,0.345
115.45,13.02,0.345
115.47,13.21,0.345
115.49,13.39,0.345
115.51,13.57,0.345
115.53,13.76,0.345
115.55,13.94,0.345
115.56,14.12,0.345
115.58,14.31,0.345
115.60,14.49,0.345
115.62,14.67,0.345
115.64,14.86,0.345
115.65,15.04,0.345
115.67,15.22,0.346
115.69,15.41,0.346
115.71,15.59,0.346
115.73,15.77,0.346
115.75,15.96,0.346
115.76,16.14,0.346
115.78,16.33,0.346
115.80,16.51,0.346
115.82,16.69,0.346
115.84,16.88,0.346
115.86,17.06,0.346
115.88,17.24,0.346
115.89,17.43,0.347
115.91,17.61,0.347
115.93,17.79,0.347
115.95,17.98,0.347
115.97,18.16,0.347
115.99,18.35,0.347
116.00,18.53,0.347
116.02,18.71,0.347
116.04,18.90,0.347
116.06,19.08,0.347
116.08,19.26,0.348
116.10,19.45,0.348
116.11,19.63,0.348
116.13,19.81,0.348
116.15,20.00,0.348
116.17,20.18,0.348
116.19,20.36,0.349
116.20,20.55,0.349
116.22,20.73,0.349
116.24,20.91,0.349
116.26,21.10,0.349
116.28,21.28,0.349
116.30,21.47,0.350
116.31,21.65,0.350
116.33,21.83,0.350
116.35,22.01,0.350
116.37,22.20,0.350
116.39,22.38,0.350
116.41,22.56,0.351
116.43,22.75,0.351
116.44,22.93,0.351
116.46,23.12,0.351
116.48,23.30,0.351
116.50,23.48,0.351
116.52,23.67,0.352
116.54,23.85,0.352
116.55,24.03,0.352
116.57,24.22,0.352
116.59,24.40,0.352
116.61,24.58,0.352
116.63,24.77,0.352
116.65,24.95,0.353
116.66,25.13,0.353
116.68,25.32,0.353
116.70,25.50,0.353
116.72,25.68,0.353
116.74,25.87,0.353
116.75,26.05,0.353
116.77,26.24,0.354
116.79,26.42,0.354
116.81,26.60,0.354
116.83,26.79,0.354
116.85,26.97,0.355
116.86,27.15,0.355
116.88,27.34,0.355
116.90,27.52,0.355
116.92,27.71,0.355
116.94,27.89,0.356
116.96,28.07,0.356
116.98,28.26,0.356
116.99,28.44,0.356
117.01,28.62,0.356
117.03,28.81,0.357
117.05,28.99,0.357
117.07,29.17,0.357
117.09,29.36,0.357
117.10,29.54,0.357
117.12,29.72,0.358
117.14,29.91,0.358
117.16,30.09,0.358
117.18,30.27,0.358
117.20,30.46,0.358
117.21,30.64,0.358
117.23,30.82,0.359
117.25,31.01,0.359
117.27,31.19,0.359
117.29,31.38,0.359
117.30,31.56,0.359
117.32,31.74,0.360
117.34,31.93,0.360
117.36,32.11,0.360
117.38,32.29,0.360
117.40,32.48,0.360
117.41,32.66,0.360
117.43,32.84,0.361
117.45,33.03,0.361
117.47,33.21,0.361
117.49,33.39,0.361
117.51,33.58,0.361
117.53,33.76,0.361
117.54,33.94,0.361
117.56,34.13,0.362
117.58,34.31,0.362
117.60,34.50,0.362
117.62,34.68,0.362
117.64,34.86,0.362
117.65,35.05,0.362
117.67,35.23,0.362
117.69,35.41,0.363
117.71,35.59,0.363
117.73,35.78,0.363
117.75,35.96,0.363
117.76,36.15,0.363
117.78,36.33,0.364
117.80,36.51,0.364
117.82,36.70,0.364
117.84,36.88,0.364
117.85,37.06,0.364
117.87,37.25,0.364
117.89,37.43,0.365
117.91,37.62,0.365
117.93,37.80,0.365
117.95,37.98,0.365
117.96,38.17,0.365
117.98,38.35,0.365
118.00,38.53,0.366
118.02,38.72,0.366
118.04,38.90,0.366
118.06,39.08,0.366
118.08,39.27,0.366
118.09,39.45,0.367
118.11,39.63,0.367
118.13,39.82,0.367
118.15,40.00,0.367
118.17,40.18,0.367
118.19,40.37,0.367
118.20,40.55,0.368
118.22,40.74,0.368
118.24,40.92,0.368
118.26,41.10,0.368
118.28,41.29,0.368
118.30,41.47,0.368
118.31,41.65,0.368
118.33,41.84,0.369
118.35,42.02,0.369
118.37,42.20,0.369
118.39,42.39,0.369
118.40,42.57,0.369
118.42,42.75,0.369
118.44,42.94,0.370
118.46,43.12,0.370
118.48,43.30,0.370
118.50,43.49,0.370
118.51,43.67,0.370
118.53,43.85,0.371
118.55,44.04,0.371
118.57,44.22,0.371
118.59,44.41,0.371
118.61,44.59,0.371
118.63,44.77,0.371
118.64,44.96,0.372
118.66,45.14,0.372
118.68,45.32,0.372
118.70,45.51,0.372
118.72,45.69,0.372
118.74,45.87,0.373
118.75,46.06,0.373
118.77,46.24,0.373
118.79,46.42,0.373
118.81,46.61,0.373
118.83,46.79,0.374
118.85,46.97,0.374
118.86,47.16,0.374
118.88,47.34,0.374
118.90,47.53,0.374
118.92,47.71,0.374
118.94,47.89,0.375
118.95,48.08,0.375
118.97,48.26,0.375
118.99,48.44,0.375
119.01,48.63,0.375
119.03,48.81,0.376
119.05,48.99,0.376
119.06,49.18,0.376
119.08,49.36,0.376
119.10,49.54,0.376
119.12,49.73,0.377
119.14,49.91,0.377
119.16,50.09,0.377
119.18,50.28,0.377
119.19,50.46,0.377
119.21,50.65,0.378
119.23,50.83,0.378
119.25,51.01,0.378
119.27,51.20,0.378
119.29,51.38,0.378
119.30,51.56,0.379
119.32,51.75,0.379
119.34,51.93,0.379
119.36,52.11,0.379
119.38,52.30,0.379
119.40,52.48,0.379
119.41,52.66,0.380
119.43,52.85,0.380
119.45,53.03,0.380
119.47,53.22,0.380
119.49,53.40,0.380
119.50,53.58,0.381
119.52,53.77,0.381
119.54,53.95,0.381
119.56,54.13,0.381
119.58,54.32,0.381
119.60,54.50,0.381
119.61,54.68,0.382
119.63,54.87,0.382
119.65,55.05,0.382
119.67,55.23,0.382
119.69,55.42,0.382
119.71,55.60,0.383
119.73,55.78,0.383
119.74,55.97,0.383
119.76,56.15,0.383
119.78,56.33,0.383
119.80,56.52,0.383
119.82,56.70,0.384
119.84,56.89,0.384
119.85,57.07,0.384
119.87,57.25,0.384
119.89,57.44,0.384
119.91,57.62,0.384
119.93,57.80,0.385
119.95,57.99,0.385
119.96,58.17,0.385
119.98,58.35,0.385
120.00,58.54,0.385
120.02,58.72,0.386
120.04,58.90,0.386
120.05,59.09,0.386
120.07,59.27,0.386
120.09,59.45,0.386
120.11,59.64,0.386
120.13,59.82,0.387
120.15,60.01,0.387
120.16,60.19,0.387
120.18,60.37,0.387
120.20,60.56,0.387
120.22,60.74,0.388
120.24,60.92,0.388
120.26,61.11,0.388
120.28,61.29,0.388
120.29,61.47,0.388
120.31,61.66,0.388
120.33,61.84,0.389
120.35,62.02,0.389
120.37,62.21,0.389
120.39,62.39,0.389
120.40,62.58,0.389
120.42,62.76,0.389
120.44,62.94,0.390
120.46,63.12,0.390
120.48,63.31,0.390
120.50,63.49,0.390
120.51,63.67,0.390
120.53,63.86,0.391
120.55,64.04,0.391
120.57,64.23,0.391
120.59,64.41,0.391
120.60,64.59,0.391
120.62,64.78,0.391
120.64,64.96,0.392
120.66,65.14,0.392
120.68,65.33,0.392
120.70,65.51,0.392
120.71,65.69,0.392
120.73,65.88,0.393
120.75,66.06,0.393
120.77,66.24,0.393
120.79,66.43,0.393
120.81,66.61,0.393
120.83,66.79,0.393
120.84,66.98,0.394
120.86,67.16,0.394
120.88,67.34,0.394
120.90,67.53,0.394
120.92,67.71,0.394
120.94,67.90,0.395
120.95,68.08,0.395
120.97,68.26,0.395
120.99,68.45,0.395
121.01,68.63,0.395
121.03,68.81,0.395
121.05,69.00,0.395
121.06,69.18,0.396
121.08,69.36,0.396
121.10,69.55,0.396
121.12,69.73,0.396
121.14,69.91,0.396
121.15,70.10,0.396
121.17,70.28,0.397
121.19,70.46,0.397
121.21,70.65,0.397
121.23,70.83,0.397
121.25,71.01,0.397
121.26,71.20,0.397
121.28,71.38,0.398
121.30,71.56,0.398
121.32,71.75,0.398
121.34,71.93,0.398
121.36,72.12,0.398
121.38,72.30,0.398
121.39,72.48,0.399
121.41,72.67,0.399
121.43,72.85,0.399
121.45,73.03,0.399
121.47,73.22,0.399
121.49,73.40,0.399
121.50,73.58,0.400
121.52,73.77,0.400
121.54,73.95,0.400
121.56,74.13,0.400
121.58,74.32,0.400
121.60,74.50,0.400
121.61,74.69,0.401
121.63,74.87,0.401
121.65,75.05,0.401
121.67,75.24,0.401
121.69,75.42,0.401
121.70,75.60,0.401
121.72,75.79,0.402
121.74,75.97,0.402
121.76,76.15,0.402
121.78,76.34,0.402
121.80,76.52,0.402
121.81,76.70,0.402
121.83,76.89,0.402
121.85,77.07,0.402
121.87,77.25,0.403
121.89,77.44,0.403
121.91,77.62,0.403
121.93,77.80,0.403
121.94,77.99,0.403
121.96,78.17,0.403
121.98,78.35,0.403
122.00,78.54,0.404
122.02,78.72,0.404
122.04,78.90,0.404
122.05,79.09,0.404
122.07,79.27,0.404
122.09,79.46,0.405
122.11,79.64,0.405
122.13,79.82,0.405
122.15,80.01,0.405
122.16,80.19,0.405
122.18,80.37,0.405
122.20,80.56,0.405
122.22,80.74,0.405
122.24,80.92,0.406
122.25,81.11,0.406
122.27,81.29,0.406
122.29,81.47,0.406
122.31,81.66,0.406
122.33,81.84,0.406
122.35,82.02,0.406
122.36,82.21,0.406
122.38,82.39,0.406
122.40,82.58,0.407
122.42,82.76,0.407
122.44,82.94,0.407
122.46,83.13,0.407
122.48,83.31,0.407
122.49,83.49,0.407
122.51,83.68,0.407
122.53,83.86,0.407
122.55,84.04,0.407
122.57,84.23,0.407
122.59,84.41,0.407
122.60,84.59,0.407
122.62,84.78,0.408
122.64,84.96,0.408
122.66,85.14,0.408
122.68,85.33,0.408
122.70,85.51,0.408
122.71,85.69,0.408
122.73,85.88,0.408
122.75,86.06,0.408
122.77,86.25,0.408
122.79,86.43,0.408
122.80,86.61,0.408
122.82,86.80,0.409
122.84,86.98,0.409
122.86,87.16,0.409
122.88,87.35,0.409
122.90,87.53,0.409
122.91,87.71,0.409
122.93,87.90,0.409
122.95,88.08,0.409
122.97,88.26,0.409
122.99,88.45,0.410
123.01,88.63,0.410
123.03,88.81,0.410
123.04,89.00,0.410
123.06,89.18,0.410
123.08,89.36,0.410
123.10,89.55,0.410
123.12,89.73,0.410
123.14,89.92,0.410
123.15,90.10,0.411
123.17,90.28,0.411
123.19,90.47,0.411
123.21,90.65,0.411
123.23,90.83,0.411
123.25,91.02,0.411
123.26,91.20,0.411
123.28,91.38,0.411
123.30,91.57,0.412
123.32,91.75,0.412
123.34,91.93,0.412
123.35,92.12,0.412
123.37,92.30,0.412
123.39,92.48,0.412
123.41,92.67,0.412
123.43,92.85,0.413
123.45,93.04,0.413
123.46,93.22,0.413
123.48,93.40,0.413
123.50,93.59,0.413
123.52,93.77,0.413
123.54,93.95,0.414
123.56,94.14,0.414
123.58,94.32,0.414
123.59,94.50,0.414
123.61,94.69,0.414
123.63,94.87,0.414
123.65,95.05,0.415
123.67,95.24,0.415
123.69,95.42,0.415
123.70,95.61,0.415
123.72,95.79,0.415
123.74,95.97,0.415
123.76,96.16,0.415
123.78,96.34,0.415
123.80,96.52,0.416
123.81,96.71,0.416
123.83,96.89,0.416
123.85,97.07,0.416
123.87,97.26,0.416
123.89,97.44,0.416
123.90,97.62,0.416
123.92,97.81,0.416
123.94,97.99,0.416
123.96,98.17,0.416
123.98,98.36,0.416
124.00,98.54,0.417
124.01,98.72,0.417
124.03,98.91,0.417
124.05,99.09,0.417
124.07,99.27,0.417
124.09,99.46,0.417
124.11,99.64,0.417
124.13,99.83,0.417
124.14,100.01,0.417
124.16,100.19,0.417
124.18,100.38,0.418
124.20,100.56,0.418
124.22,100.74,0.418
124.24,100.93,0.418
124.25,101.11,0.418
124.27,101.29,0.418
124.29,101.48,0.418
124.31,101.66,0.418
124.33,101.84,0.418
124.35,102.03,0.418
124.36,102.21,0.419
124.38,102.39,0.419
124.40,102.58,0.419
124.42,102.76,0.419
124.44,102.94,0.419
124.45,103.13,0.419
124.47,103.31,0.419
124.49,103.49,0.419
124.51,103.68,0.419
124.53,103.86,0.420
124.55,104.04,0.420
124.56,104.23,0.420
124.58,104.41,0.420
124.60,104.59,0.420
124.62,104.78,0.420
124.64,104.96,0.420
124.66,105.15,0.420
124.68,105.33,0.421
124.69,105.52,0.421
124.71,105.70,0.421
124.73,105.88,0.421
124.75,106.07,0.421
124.77,106.25,0.421
124.79,106.43,0.421
124.80,106.62,0.421
124.82,106.80,0.421
124.84,106.98,0.421
124.86,107.17,0.421
124.88,107.35,0.421
124.90,107.54,0.421
124.91,107.72,0.421
124.93,107.90,0.421
124.95,108.09,0.421
124.97,108.27,0.421
124.99,108.45,0.421
125.00,108.64,0.421
125.02,108.82,0.421
125.04,109.00,0.422
125.06,109.19,0.421
125.08,109.37,0.422
125.10,109.55,0.422
125.11,109.74,0.422
125.13,109.92,0.422
125.15,110.10,0.422
125.17,110.29,0.422
125.19,110.47,0.422
125.21,110.65,0.422
125.23,110.84,0.422
125.24,111.02,0.422
125.26,111.20,0.422
125.28,111.39,0.422
125.30,111.57,0.422
125.32,111.75,0.423
125.34,111.94,0.423
125.35,112.12,0.423
125.37,112.30,0.423
125.39,112.49,0.423
125.41,112.67,0.423
125.43,112.86,0.423
125.45,113.04,0.423
125.46,113.22,0.423
125.48,113.40,0.423
125.50,113.59,0.423
125.52,113.77,0.423
125.54,113.95,0.424
125.55,114.14,0.424
125.57,114.32,0.424
125.59,114.50,0.424
125.61,114.69,0.424
125.63,114.87,0.424
125.65,115.06,0.424
125.66,115.24,0.424
125.68,115.42,0.424
125.70,115.60,0.424
125.72,115.79,0.424
125.74,115.97,0.424
125.76,116.16,0.425
125.78,116.34,0.425
125.79,116.52,0.425
125.81,116.71,0.425
125.83,116.89,0.425
125.85,117.07,0.425
125.87,117.26,0.425
125.89,117.44,0.425
125.90,117.62,0.425
125.92,117.81,0.425
125.94,117.99,0.426
125.96,118.17,0.426
125.98,118.36,0.426
126.00,118.54,0.426
126.01,118.72,0.426
126.03,118.91,0.426
126.05,119.09,0.426
126.07,119.27,0.426
126.09,119.46,0.426
126.10,119.64,0.426
126.12,119.82,0.427
126.14,120.01,0.427
126.16,120.19,0.427
126.18,120.38,0.427
126.20,120.56,0.427
126.21,120.74,0.427
126.23,120.93,0.427
126.25,121.11,0.427
126.27,121.29,0.427
126.29,121.48,0.427
126.31,121.66,0.427
126.33,121.84,0.428
126.34,122.03,0.428
126.36,122.21,0.428
126.38,122.39,0.428
126.40,122.58,0.428
126.42,122.76,0.428
126.44,122.94,0.428
126.45,123.13,0.428
126.47,123.31,0.428
126.49,123.50,0.428
126.51,123.68,0.429
126.53,123.86,0.429
126.55,124.05,0.429
126.56,124.23,0.429
126.58,124.41,0.429
126.60,124.60,0.429
126.62,124.78,0.429
126.64,124.96,0.429
126.65,125.15,0.429
126.67,125.33,0.429
126.69,125.51,0.429
126.71,125.70,0.430
126.73,125.88,0.430
126.75,126.06,0.430
126.76,126.25,0.430
126.78,126.43,0.430
126.80,126.61,0.430
126.82,126.80,0.430
126.84,126.98,0.430
126.86,127.16,0.430
126.88,127.35,0.430
126.89,127.53,0.430
126.91,127.71,0.431
126.93,127.90,0.431
126.95,128.08,0.431
126.97,128.26,0.431
126.99,128.45,0.431
127.00,128.63,0.431
127.02,128.82,0.431
127.04,129.00,0.431
127.06,129.18,0.431
127.08,129.37,0.431
127.10,129.55,0.431
127.11,129.73,0.431
127.13,129.92,0.432
127.15,130.10,0.432
127.17,130.28,0.432
127.19,130.47,0.432
127.20,130.65,0.432
127.22,130.83,0.432
127.24,131.02,0.432
127.26,131.20,0.432
127.28,131.38,0.432
127.30,131.57,0.432
127.31,131.75,0.433
127.33,131.93,0.433
127.35,132.12,0.433
127.37,132.30,0.433
127.39,132.48,0.433
127.41,132.67,0.433
127.43,132.85,0.433
127.44,133.04,0.433
127.46,133.22,0.434
127.48,133.40,0.434
127.50,133.59,0.434
127.52,133.77,0.434
127.54,133.95,0.434
127.55,134.14,0.434
127.57,134.32,0.434
127.59,134.50,0.434
127.61,134.69,0.435
127.63,134.87,0.435
127.65,135.06,0.435
127.66,135.24,0.435
127.68,135.42,0.435
127.70,135.60,0.435
127.72,135.79,0.435
127.74,135.97,0.435
127.75,136.15,0.435
127.77,136.34,0.435
127.79,136.52,0.435
127.81,136.70,0.435
127.83,136.89,0.436
127.85,137.07,0.436
127.86,137.26,0.436
127.88,137.44,0.436
127.90,137.62,0.436
127.92,137.81,0.436
127.94,137.99,0.436
127.96,138.17,0.436
127.98,138.36,0.436
127.99,138.54,0.436
128.01,138.72,0.436
128.03,138.91,0.436
128.05,139.09,0.437
128.07,139.27,0.437
128.09,139.46,0.437
128.10,139.64,0.437
128.12,139.82,0.437
128.14,140.01,0.437
128.16,140.19,0.437
128.18,140.37,0.437
128.20,140.56,0.438
128.21,140.74,0.438
128.23,140.92,0.438
128.25,141.11,0.438
128.27,141.29,0.438
128.29,141.48,0.438
128.30,141.66,0.438
128.32,141.84,0.438
128.34,142.03,0.438
128.36,142.21,0.439
128.38,142.39,0.439
128.40,142.58,0.439
128.41,142.76,0.439
128.43,142.94,0.439
128.45,143.13,0.439
128.47,143.31,0.439
128.49,143.49,0.439
128.51,143.68,0.439
128.53,143.86,0.440
128.54,144.04,0.440
128.56,144.23,0.440
128.58,144.41,0.440
128.60,144.59,0.440
128.62,144.78,0.440
128.64,144.96,0.440
128.65,145.14,0.440
128.67,145.33,0.440
128.69,145.51,0.441
128.71,145.70,0.441
128.73,145.88,0.441
128.75,146.06,0.441
128.76,146.24,0.441
128.78,146.43,0.441
128.80,146.61,0.441
128.82,146.79,0.441
128.84,146.98,0.441
128.85,147.16,0.442
128.87,147.34,0.442
128.89,147.53,0.442
128.91,147.71,0.442
128.93,147.90,0.442
128.95,148.08,0.442
128.96,148.26,0.442
128.98,148.44,0.442
129.00,148.63,0.443
129.02,148.81,0.443
129.04,149.00,0.443
129.06,149.18,0.443
129.08,149.36,0.443
129.09,149.55,0.443
129.11,149.73,0.443
129.13,149.91,0.443
129.15,150.10,0.443
129.17,150.28,0.444
129.19,150.46,0.444
129.20,150.65,0.444
129.22,150.83,0.444
129.24,151.01,0.444
129.26,151.20,0.444
129.28,151.38,0.444
129.30,151.56,0.444
129.31,151.75,0.444
129.33,151.93,0.444
129.35,152.11,0.444
129.37,152.30,0.445
129.39,152.48,0.445
129.40,152.66,0.445
129.42,152.85,0.445
129.44,153.03,0.445
129.46,153.22,0.445
129.48,153.40,0.445
129.50,153.58,0.445
129.51,153.77,0.445
129.53,153.95,0.445
129.55,154.13,0.446
129.57,154.32,0.446
129.59,154.50,0.446
129.61,154.68,0.446
129.63,154.87,0.446
129.64,155.05,0.446
129.66,155.23,0.446
129.68,155.42,0.446
129.70,155.60,0.446
129.72,155.78,0.446
129.74,155.97,0.447
129.75,156.15,0.447
129.77,156.33,0.447
129.79,156.52,0.447
129.81,156.70,0.447
129.83,156.89,0.447
129.85,157.07,0.447
129.86,157.25,0.448
129.88,157.44,0.448
129.90,157.62,0.448
129.92,157.80,0.448
129.94,157.99,0.448
129.95,158.17,0.448
129.97,158.35,0.448
129.99,158.54,0.448
130.01,158.72,0.448
130.03,158.90,0.448
130.05,159.09,0.448
130.06,159.27,0.448
130.08,159.45,0.448
130.10,159.63,0.448
130.12,159.82,0.449
130.14,160.00,0.449
130.16,160.19,0.449
130.18,160.37,0.449
130.19,160.55,0.449
130.21,160.74,0.449
130.23,160.92,0.449
130.25,161.10,0.449
130.27,161.29,0.449
130.29,161.47,0.450
130.30,161.65,0.450
130.32,161.84,0.450
130.34,162.02,0.450
130.36,162.20,0.450
130.38,162.39,0.450
130.40,162.57,0.450
130.41,162.76,0.450
130.43,162.94,0.451
130.45,163.12,0.451
130.47,163.31,0.451
130.49,163.49,0.451
130.50,163.67,0.451
130.52,163.86,0.451
130.54,164.04,0.451
130.56,164.22,0.451
130.58,164.40,0.451
130.60,164.59,0.451
130.61,164.77,0.452
130.63,164.96,0.452
130.65,165.14,0.452
130.67,165.32,0.452
130.69,165.51,0.452
130.71,165.69,0.452
130.73,165.87,0.452
130.74,166.06,0.452
130.76,166.24,0.452
130.78,166.42,0.452
130.80,166.61,0.453
130.82,166.79,0.453
130.84,166.97,0.453
130.85,167.16,0.453
130.87,167.34,0.453
130.89,167.52,0.453
130.91,167.71,0.454
130.93,167.89,0.454
130.95,168.08,0.454
130.96,168.26,0.454
130.98,168.44,0.454
131.00,168.63,0.454
131.02,168.81,0.454
131.04,168.99,0.454
131.05,169.17,0.454
131.07,169.36,0.455
131.09,169.54,0.455
131.11,169.72,0.455
131.13,169.91,0.455
131.15,170.09,0.455
131.16,170.27,0.455
131.18,170.46,0.455
131.20,170.64,0.455
131.22,170.83,0.456
131.24,171.01,0.456
131.26,171.19,0.456
131.28,171.38,0.456
131.29,171.56,0.456
131.31,171.74,0.456
131.33,171.93,0.457
131.35,172.11,0.457
131.37,172.29,0.457
131.39,172.48,0.457
131.40,172.66,0.457
131.42,172.84,0.457
131.44,173.03,0.457
131.46,173.21,0.457
131.48,173.39,0.457
131.50,173.58,0.458
131.51,173.76,0.458
131.53,173.94,0.458
131.55,174.13,0.458
131.57,174.31,0.458
131.59,174.49,0.458
131.60,174.68,0.459
131.62,174.86,0.459
131.64,175.05,0.459
131.66,175.23,0.459
131.68,175.41,0.459
131.70,175.59,0.460
131.71,175.78,0.460
131.73,175.96,0.460
131.75,176.14,0.460
131.77,176.33,0.460
131.79,176.51,0.460
131.81,176.70,0.461
131.83,176.88,0.461
131.84,177.06,0.461
131.86,177.25,0.461
131.88,177.43,0.461
131.90,177.61,0.461
131.92,177.80,0.461
131.94,177.98,0.462
131.95,178.16,0.462
131.97,178.34,0.462
131.99,178.53,0.462
132.01,178.71,0.462
132.03,178.90,0.462
132.05,179.08,0.463
132.06,179.26,0.463
132.08,179.45,0.463
132.10,179.63,0.463
132.12,179.81,0.463
132.14,180.00,0.464
132.15,180.18,0.464
132.17,180.36,0.464
132.19,180.55,0.464
132.21,180.73,0.464
132.23,180.91,0.465
132.25,181.10,0.465
132.26,181.28,0.465
132.28,181.46,0.465
132.30,181.65,0.465
132.32,181.83,0.466
132.34,182.01,0.466
132.36,182.20,0.466
132.38,182.38,0.466
132.39,182.56,0.466
132.41,182.75,0.467
132.43,182.93,0.467
132.45,183.11,0.467
132.47,183.30,0.467
132.49,183.48,0.467
132.50,183.66,0.468
132.52,183.85,0.468
132.54,184.03,0.468
132.56,184.21,0.468
132.58,184.40,0.468
132.60,184.58,0.469
132.61,184.76,0.469
132.63,184.95,0.469
132.65,185.13,0.469
132.67,185.32,0.470
132.69,185.50,0.470
132.70,185.68,0.470
132.72,185.87,0.470
132.74,186.05,0.471
132.76,186.23,0.471
132.78,186.42,0.471
132.80,186.60,0.471
132.81,186.78,0.472
132.83,186.97,0.472
132.85,187.15,0.472
132.87,187.33,0.472
132.89,187.52,0.472
132.91,187.70,0.473
132.93,187.88,0.473
132.94,188.07,0.473
132.96,188.25,0.473
132.98,188.43,0.474
133.00,188.62,0.474
133.02,188.80,0.474
133.04,188.98,0.475
133.05,189.17,0.475
133.07,189.35,0.475
133.09,189.53,0.476
133.11,189.72,0.476
133.13,189.90,0.476
133.15,190.08,0.477
133.16,190.27,0.477
133.18,190.45,0.477
133.20,190.63,0.477
133.22,190.82,0.478
133.24,191.00,0.478
133.25,191.18,0.478
133.27,191.37,0.479
133.29,191.55,0.479
133.31,191.73,0.479
133.33,191.92,0.479
133.35,192.10,0.480
133.36,192.28,0.480
133.38,192.47,0.480
133.40,192.65,0.481
133.42,192.83,0.481
133.44,193.02,0.481
133.46,193.20,0.482
133.48,193.38,0.482
133.49,193.57,0.482
133.51,193.75,0.483
133.53,193.93,0.483
133.55,194.12,0.483
133.57,194.30,0.484
133.59,194.48,0.484
133.60,194.67,0.484
133.62,194.85,0.485
133.64,195.03,0.485
133.66,195.22,0.485
133.68,195.40,0.486
133.70,195.59,0.486
133.71,195.77,0.487
133.73,195.95,0.487
133.75,196.13,0.487
133.77,196.32,0.488
133.79,196.50,0.488
133.80,196.68,0.489
133.82,196.87,0.489
133.84,197.05,0.490
133.86,197.23,0.490
133.88,197.42,0.491
133.90,197.60,0.491
133.91,197.78,0.492
133.93,197.97,
133.95,198.15,
133.97,198.33,
133.99,,