File: DSC/2025_04_20_PVP29_n60C_200C_10Cmin_x3.csv
Filename,2025_04_20_PVP29_n60C_200C_10Cmin_x3
Instrument name,DSC2A-00468 (192.168.1.100)
Operator,Yarger
rundate,4/20/2025
Sample name,2025_04_20_PVP29_n60C_200C_10Cmin_x3
proceduresegments,Data Off ; Equilibrate -60.00 °C; Data On ; Ramp 10.00 °C/min to 200.00 °C; Data Off ; Isothermal 1.0 min; Data On ; Ramp 10.00 °C/min to -60.00 °C; Data Off ; Isothermal 1.0 min; Data On ; Ramp 10.00 °C/min to 200.00 °C; Data Off ; Isothermal 1.0 min; Data On ; Ramp 10.00 °C/min to -60.00 °C; Data Off ; Isothermal 1.0 min; Data On ; Ramp 10.00 °C/min to 200.00 °C
[File Parameters]
Run date,4/20/2025 4:44:10 PM
Trios version,5.1.1.46572
Original File Name,
Current File Name,D:\DSC2500\JYarger\2025_04_20_PVP29_n60C_200C_10Cmin_x3.tri
[Procedure]
Procedure Name,PVP29_n60_160C_10Cmin_x3
Sample Name,2025_04_20_PVP29_n60C_200C_10Cmin_x3
Sample Mass,12.45 mg
Reference Sample Mass,0 mg
Pan Mass,25.63 mg
Pan Number,34
Reference Pan Mass,25.8 mg
Reference Pan Number,28
Pan Type,Tzero Aluminum
Comments,"Al Pan/Lid, Not sealed."
Project Name,CA
Operator,Yarger
Test,Custom
Unload Max Temperature,30
Unload Min Temperature,30
Load Max Temperature,30
Load Min Temperature,30
Stop on Gas Flow Error,Yes
[Signal List]
Signal #1,Time (min)
Signal #2,Temperature (°C)
Signal #3,Heat Flow (mW)
Signal #4,Delta T (µV)
Signal #5,Delta Tzero (µV)
Signal #6,Tzero Temperature (°C)
Signal #7,Cell Purge (mL/min)
Signal #8,Heater Temp (°C)
Signal #9,Power Delivered (W)
Signal #10,Reference Junction Temperature (°C)
Signal #11,Flange Temperature (°C)
Signal #12,Heat Flow Phase (rad)
Signal #13,Total Heat Capacity (J/°C)
Signal #14,Heat Capacity (J/°C)
[Configuration]
Company Name,ASU
Instrument Name,DSC2A-00468
Instrument Type,DSC2500
Serial Number,DSC2A-00468
IP,192.168.1.100
Location of Instrument,MRRC
DisplayType,Unknown
Sample Interval ,0.1 s/pt
Selected Heat Flow,T4P
Exotherm Direction,Down
Cell Serial,DRC2-00792
Lid Type,Standard
Cooler,RCS 90
Leave Cooler on at End of Sequence,On
Gas 2,Nitrogen
Gas Selected,Channel 1
Flow Rate,50 mL/min
Secondary Purge,On
Licensed Heat Flow,Heat Flow T4P
Modulation Licensed,Yes
[Versions]
Common IDD Version,1
Cortex Version,VER 2.10.2.31
Driver,5.0.0.6
GDM Version,1.0.3.3
TouchscreenVersion,1.0.0.16145
FEP Version,1.2.1.21
FEP Bootloader,2.0.0.5
AutoSampler Version,2.1.1.26
Auto Sampler Bootloader,2.0.0.5
FCM Version,1.1.0.3
FCM Bootloader,2.0.0.5
[Experiment Logs]
Experiment Log Entry # 1,Data On set to 0
Experiment Log Entry # 3,Equilibrate Segment -60 (C) Started
Experiment Log Entry # 5,Air Cool is off.
Experiment Log Entry # 7,Data On set to 1
Experiment Log Entry # 9,Ramp Segment 10 C/min to 200 Started
Experiment Log Entry # 11,Data On set to 0
Experiment Log Entry # 13,Isothermal Segment 1 min started
Experiment Log Entry # 15,Data On set to 1
Experiment Log Entry # 17,Ramp Segment 10 C/min to -60 Started
Experiment Log Entry # 19,Data On set to 0
Experiment Log Entry # 21,Isothermal Segment 1 min started
Experiment Log Entry # 23,Data On set to 1
Experiment Log Entry # 25,Ramp Segment 10 C/min to 200 Started
Experiment Log Entry # 27,Data On set to 0
Experiment Log Entry # 29,Isothermal Segment 1 min started
Experiment Log Entry # 31,Data On set to 1
Experiment Log Entry # 33,Ramp Segment 10 C/min to -60 Started
Experiment Log Entry # 35,Data On set to 0
Experiment Log Entry # 37,Isothermal Segment 1 min started
Experiment Log Entry # 39,Data On set to 1
Experiment Log Entry # 41,Ramp Segment 10 C/min to 200 Started
Experiment Log Entry # 43,Auto sampler has detected that GDM has gone offline
[Method Log]
Method Log Entry # 1,Data Off
Method Log Entry # 2,Equilibrate -60 °C
Method Log Entry # 3,Data On
Method Log Entry # 4,(Ramp 567058) Ramp 10 °C/minute to 200 °C
Method Log Entry # 5,Data Off
Method Log Entry # 6,Isothermal 1 minutes
Method Log Entry # 7,Data On
Method Log Entry # 8,(Ramp 567062) Ramp 10 °C/minute to -60 °C
Method Log Entry # 9,Data Off
Method Log Entry # 10,Isothermal 1 minutes
Method Log Entry # 11,Data On
Method Log Entry # 12,(Ramp 567066) Ramp 10 °C/minute to 200 °C
Method Log Entry # 13,Data Off
Method Log Entry # 14,Isothermal 1 minutes
Method Log Entry # 15,Data On
Method Log Entry # 16,(Ramp 567070) Ramp 10 °C/minute to -60 °C
Method Log Entry # 17,Data Off
Method Log Entry # 18,Isothermal 1 minutes
Method Log Entry # 19,Data On
Method Log Entry # 20,(Ramp 567074) Ramp 10 °C/minute to 200 °C
Cell Serial,DRC2-00792
[T1 Calibration]
Slope,-0.008529666
Offset,9.636258
Initial Temperature,98.23
GUID,f8bfdadc-4977-4fdf-ba6d-0ba9134940c3
[TZero Calibration]
Date Applied,11/29/2022 4:06:13 PM
Description,From -89.059 °C to 396.009 °C at 20.000°C/min
Gas Type,Nitrogen
Pan Type,None
Source Files 1,C:\Users\yargerlab\Desktop\DSC Data\General\TZero_calibration_11_29_22_2nd(2).tri
Source Files 2,C:\Users\yargerlab\Desktop\DSC Data\General\TZero_calibration_11_29_22_2nd(3).tri
Delta T Offset,13.05235
Delta T Slope,-0.007271007
Delta T0 Offset,-13.69128
Delta T0 Slope,0.06063341
[Temperature Calibration]
Date Applied,11/29/2022 7:12:28 PM
Description,From 106.590 °C to 186.590 °C at 10.000°C/min
Gas Type,Nitrogen
Pan Type,Tzero Aluminum Hermetic
Source Files 1,C:\Users\yargerlab\Desktop\DSC Data\General\Indium(6).tri
Measured 1,157.391
Known 1,156.598
[Cell Constant Calibration]
Date Applied,11/29/2022 7:12:29 PM
Description,From 106.590 °C to 186.590 °C at 10.000°C/min
Gas Type,Nitrogen
Pan Type,Tzero Aluminum Hermetic
Source Files 1,C:\Users\yargerlab\Desktop\DSC Data\General\Indium(6).tri
T4P KCell,1.006051
Onset Slope,63.26126 mW/°C
[Direct Cp Calibration]
Date Applied,11/30/2022 11:04:51 AM
Description,From -79.983 °C to 298.409 °C at 10.000°C/min
Gas Type,Nitrogen
Pan Type,Tzero Aluminum Hermetic
Source Files 1,C:\Users\yargerlab\Desktop\DSC Data\General\Sapphire_Heat_Capacity_11_30_22.tri
[Rev Cp Calibration]
Date Applied,11/30/2022 1:58:51 PM
Description,From -79.996 °C to 292.812 °C at 3.000°C/min
Gas Type,Nitrogen
Pan Type,Tzero Aluminum Hermetic
Source Files 1,C:\Users\yargerlab\Desktop\DSC Data\General\Sapphire_MDSC_Calibration_11_30_22.tri
[step]
Ramp 10.00 °C/min to 200.00 °C
Time,Temperature,Heat Flow (Normalized)
min,°C,W/g
0.00,-59.77,-0.036
0.02,-59.78,-0.035
0.04,-59.78,-0.031
0.05,-59.77,-0.027
0.07,-59.74,-0.022
0.09,-59.69,-0.015
0.11,-59.61,-0.005
0.13,-59.51,0.009
0.15,-59.39,0.025
0.16,-59.26,0.042
0.18,-59.11,0.059
0.20,-58.96,0.076
0.22,-58.80,0.091
0.24,-58.64,0.105
0.26,-58.47,0.116
0.28,-58.31,0.126
0.29,-58.14,0.134
0.31,-57.97,0.140
0.33,-57.80,0.146
0.35,-57.62,0.151
0.37,-57.45,0.154
0.39,-57.28,0.158
0.40,-57.10,0.161
0.42,-56.93,0.163
0.44,-56.75,0.165
0.46,-56.57,0.167
0.48,-56.40,0.168
0.50,-56.22,0.170
0.51,-56.04,0.171
0.53,-55.86,0.172
0.55,-55.68,0.173
0.57,-55.50,0.174
0.59,-55.32,0.174
0.60,-55.15,0.175
0.62,-54.96,0.176
0.64,-54.79,0.176
0.66,-54.61,0.176
0.68,-54.43,0.177
0.70,-54.25,0.177
0.72,-54.06,0.178
0.73,-53.88,0.178
0.75,-53.70,0.179
0.77,-53.52,0.179
0.79,-53.34,0.179
0.81,-53.16,0.179
0.83,-52.98,0.180
0.84,-52.80,0.180
0.86,-52.62,0.180
0.88,-52.44,0.180
0.90,-52.26,0.181
0.92,-52.07,0.181
0.93,-51.89,0.181
0.95,-51.71,0.182
0.97,-51.53,0.182
0.99,-51.35,0.182
1.01,-51.17,0.182
1.03,-50.98,0.183
1.05,-50.80,0.183
1.06,-50.62,0.183
1.08,-50.44,0.183
1.10,-50.26,0.183
1.12,-50.07,0.184
1.14,-49.89,0.184
1.16,-49.71,0.184
1.17,-49.53,0.184
1.19,-49.34,0.185
1.21,-49.16,0.185
1.23,-48.98,0.185
1.25,-48.80,0.185
1.27,-48.61,0.186
1.28,-48.43,0.186
1.30,-48.25,0.186
1.32,-48.07,0.186
1.34,-47.88,0.186
1.36,-47.70,0.187
1.38,-47.52,0.187
1.39,-47.33,0.187
1.41,-47.15,0.187
1.43,-46.97,0.187
1.45,-46.78,0.187
1.47,-46.60,0.188
1.48,-46.42,0.188
1.50,-46.24,0.188
1.52,-46.05,0.188
1.54,-45.87,0.188
1.56,-45.69,0.189
1.58,-45.50,0.189
1.59,-45.32,0.189
1.61,-45.14,0.189
1.63,-44.95,0.189
1.65,-44.77,0.189
1.67,-44.59,0.190
1.69,-44.40,0.190
1.71,-44.22,0.190
1.72,-44.04,0.190
1.74,-43.85,0.190
1.76,-43.67,0.190
1.78,-43.49,0.191
1.80,-43.31,0.191
1.82,-43.12,0.191
1.83,-42.94,0.191
1.85,-42.75,0.191
1.87,-42.57,0.191
1.89,-42.39,0.191
1.91,-42.21,0.192
1.93,-42.02,0.192
1.94,-41.84,0.192
1.96,-41.66,0.192
1.98,-41.47,0.192
2.00,-41.29,0.192
2.02,-41.10,0.192
2.03,-40.92,0.193
2.05,-40.74,0.193
2.07,-40.55,0.193
2.09,-40.37,0.193
2.11,-40.19,0.193
2.13,-40.01,0.193
2.14,-39.82,0.193
2.16,-39.64,0.194
2.18,-39.46,0.194
2.20,-39.27,0.194
2.22,-39.09,0.194
2.24,-38.91,0.194
2.26,-38.72,0.194
2.27,-38.54,0.194
2.29,-38.35,0.195
2.31,-38.17,0.195
2.33,-37.99,0.195
2.35,-37.80,0.195
2.36,-37.62,0.195
2.38,-37.44,0.195
2.40,-37.25,0.195
2.42,-37.07,0.196
2.44,-36.88,0.196
2.46,-36.70,0.196
2.48,-36.52,0.196
2.49,-36.34,0.196
2.51,-36.15,0.196
2.53,-35.97,0.196
2.55,-35.79,0.196
2.57,-35.60,0.197
2.59,-35.42,0.197
2.60,-35.23,0.197
2.62,-35.05,0.197
2.64,-34.87,0.197
2.66,-34.68,0.197
2.68,-34.50,0.197
2.69,-34.32,0.197
2.71,-34.13,0.198
2.73,-33.95,0.198
2.75,-33.77,0.198
2.77,-33.58,0.198
2.79,-33.40,0.198
2.81,-33.22,0.198
2.82,-33.03,0.198
2.84,-32.85,0.199
2.86,-32.67,0.199
2.88,-32.48,0.199
2.90,-32.30,0.199
2.91,-32.12,0.199
2.93,-31.93,0.199
2.95,-31.75,0.199
2.97,-31.57,0.199
2.99,-31.38,0.200
3.01,-31.20,0.200
3.03,-31.02,0.200
3.04,-30.83,0.200
3.06,-30.65,0.200
3.08,-30.46,0.200
3.10,-30.28,0.200
3.12,-30.10,0.201
3.14,-29.92,0.201
3.15,-29.73,0.201
3.17,-29.55,0.201
3.19,-29.36,0.201
3.21,-29.18,0.201
3.23,-29.00,0.201
3.24,-28.81,0.202
3.26,-28.63,0.202
3.28,-28.45,0.202
3.30,-28.26,0.202
3.32,-28.08,0.202
3.34,-27.90,0.202
3.36,-27.71,0.202
3.37,-27.53,0.203
3.39,-27.35,0.203
3.41,-27.16,0.203
3.43,-26.98,0.203
3.45,-26.80,0.203
3.46,-26.61,0.203
3.48,-26.43,0.203
3.50,-26.25,0.204
3.52,-26.06,0.204
3.54,-25.88,0.204
3.56,-25.70,0.204
3.58,-25.51,0.204
3.59,-25.33,0.204
3.61,-25.15,0.205
3.63,-24.96,0.205
3.65,-24.78,0.205
3.67,-24.59,0.205
3.69,-24.41,0.205
3.70,-24.23,0.205
3.72,-24.04,0.205
3.74,-23.86,0.206
3.76,-23.68,0.206
3.78,-23.49,0.206
3.79,-23.31,0.206
3.81,-23.13,0.206
3.83,-22.94,0.206
3.85,-22.76,0.207
3.87,-22.58,0.207
3.89,-22.39,0.207
3.91,-22.21,0.207
3.92,-22.03,0.207
3.94,-21.84,0.207
3.96,-21.66,0.208
3.98,-21.48,0.208
4.00,-21.29,0.208
4.01,-21.11,0.208
4.03,-20.93,0.208
4.05,-20.74,0.208
4.07,-20.56,0.208
4.09,-20.38,0.209
4.11,-20.19,0.209
4.13,-20.01,0.209
4.14,-19.83,0.209
4.16,-19.64,0.209
4.18,-19.46,0.209
4.20,-19.28,0.210
4.22,-19.09,0.210
4.24,-18.91,0.210
4.25,-18.72,0.210
4.27,-18.54,0.210
4.29,-18.36,0.210
4.31,-18.17,0.211
4.33,-17.99,0.211
4.35,-17.81,0.211
4.36,-17.62,0.211
4.38,-17.44,0.211
4.40,-17.26,0.211
4.42,-17.07,0.212
4.44,-16.89,0.212
4.45,-16.71,0.212
4.47,-16.52,0.212
4.49,-16.34,0.212
4.51,-16.16,0.212
4.53,-15.97,0.213
4.55,-15.79,0.213
4.56,-15.61,0.213
4.58,-15.42,0.213
4.60,-15.24,0.213
4.62,-15.06,0.213
4.64,-14.87,0.214
4.66,-14.69,0.214
4.68,-14.51,0.214
4.69,-14.32,0.214
4.71,-14.14,0.214
4.73,-13.96,0.215
4.75,-13.77,0.215
4.77,-13.59,0.215
4.79,-13.41,0.215
4.80,-13.22,0.215
4.82,-13.04,0.216
4.84,-12.86,0.216
4.86,-12.67,0.216
4.88,-12.49,0.216
4.90,-12.31,0.216
4.91,-12.12,0.217
4.93,-11.94,0.217
4.95,-11.76,0.217
4.97,-11.57,0.217
4.99,-11.39,0.217
5.00,-11.21,0.218
5.02,-11.02,0.218
5.04,-10.84,0.218
5.06,-10.66,0.218
5.08,-10.47,0.218
5.10,-10.29,0.219
5.11,-10.11,0.219
5.13,-9.92,0.219
5.15,-9.74,0.219
5.17,-9.56,0.219
5.19,-9.37,0.220
5.21,-9.19,0.220
5.23,-9.01,0.220
5.24,-8.82,0.220
5.26,-8.64,0.221
5.28,-8.45,0.221
5.30,-8.27,0.221
5.32,-8.09,0.221
5.34,-7.90,0.222
5.35,-7.72,0.222
5.37,-7.54,0.222
5.39,-7.35,0.222
5.41,-7.17,0.222
5.43,-6.99,0.223
5.45,-6.81,0.223
5.46,-6.62,0.223
5.48,-6.44,0.223
5.50,-6.25,0.224
5.52,-6.07,0.224
5.54,-5.89,0.224
5.55,-5.71,0.224
5.57,-5.52,0.225
5.59,-5.34,0.225
5.61,-5.15,0.225
5.63,-4.97,0.225
5.65,-4.79,0.226
5.66,-4.61,0.226
5.68,-4.42,0.226
5.70,-4.24,0.226
5.72,-4.05,0.227
5.74,-3.87,0.227
5.76,-3.69,0.227
5.78,-3.50,0.228
5.79,-3.32,0.228
5.81,-3.14,0.228
5.83,-2.95,0.228
5.85,-2.77,0.229
5.87,-2.59,0.229
5.89,-2.41,0.229
5.90,-2.22,0.229
5.92,-2.04,0.230
5.94,-1.85,0.230
5.96,-1.67,0.230
5.98,-1.49,0.231
6.00,-1.30,0.231
6.01,-1.12,0.231
6.03,-0.94,0.232
6.05,-0.76,0.232
6.07,-0.57,0.232
6.09,-0.39,0.232
6.10,-0.20,0.233
6.12,-0.02,0.233
6.14,0.16,0.233
6.16,0.35,0.234
6.18,0.53,0.234
6.20,0.71,0.234
6.21,0.90,0.235
6.23,1.08,0.235
6.25,1.26,0.235
6.27,1.44,0.236
6.29,1.63,0.236
6.31,1.81,0.236
6.33,1.99,0.237
6.34,2.18,0.237
6.36,2.36,0.237
6.38,2.55,0.238
6.40,2.73,0.238
6.42,2.91,0.239
6.44,3.10,0.239
6.45,3.28,0.239
6.47,3.46,0.240
6.49,3.64,0.240
6.51,3.83,0.241
6.53,4.01,0.241
6.55,4.19,0.241
6.56,4.38,0.242
6.58,4.56,0.242
6.60,4.74,0.243
6.62,4.93,0.243
6.64,5.11,0.243
6.65,5.29,0.244
6.67,5.48,0.244
6.69,5.66,0.245
6.71,5.84,0.245
6.73,6.03,0.246
6.75,6.21,0.246
6.76,6.39,0.246
6.78,6.58,0.247
6.80,6.76,0.247
6.82,6.94,0.248
6.84,7.12,0.248
6.86,7.31,0.248
6.88,7.49,0.249
6.89,7.68,0.249
6.91,7.86,0.250
6.93,8.04,0.250
6.95,8.22,0.251
6.97,8.41,0.251
6.99,8.59,0.252
7.00,8.77,0.252
7.02,8.96,0.253
7.04,9.14,0.253
7.06,9.32,0.254
7.08,9.51,0.254
7.10,9.69,0.255
7.11,9.87,0.255
7.13,10.06,0.255
7.15,10.24,0.256
7.17,10.42,0.257
7.19,10.61,0.257
7.20,10.79,0.258
7.22,10.97,0.258
7.24,11.15,0.259
7.26,11.34,0.259
7.28,11.52,0.260
7.30,11.71,0.261
7.31,11.89,0.261
7.33,12.07,0.262
7.35,12.25,0.262
7.37,12.44,0.263
7.39,12.62,0.263
7.41,12.80,0.264
7.43,12.99,0.265
7.44,13.17,0.265
7.46,13.35,0.266
7.48,13.54,0.266
7.50,13.72,0.267
7.52,13.90,0.268
7.54,14.09,0.268
7.55,14.27,0.268
7.57,14.45,0.269
7.59,14.63,0.270
7.61,14.82,0.271
7.63,15.00,0.271
7.65,15.18,0.272
7.66,15.37,0.273
7.68,15.55,0.273
7.70,15.73,0.274
7.72,15.92,0.275
7.74,16.10,0.275
7.75,16.28,0.276
7.77,16.46,0.277
7.79,16.65,0.277
7.81,16.83,0.278
7.83,17.01,0.279
7.85,17.20,0.279
7.86,17.38,0.280
7.88,17.56,0.281
7.90,17.74,0.282
7.92,17.93,0.282
7.94,18.11,0.283
7.96,18.29,0.284
7.98,18.48,0.285
7.99,18.66,0.285
8.01,18.84,0.286
8.03,19.03,0.287
8.05,19.21,0.287
8.07,19.39,0.288
8.09,19.57,0.289
8.10,19.76,0.290
8.12,19.94,0.291
8.14,20.12,0.291
8.16,20.31,0.292
8.18,20.49,0.293
8.20,20.67,0.294
8.21,20.86,0.295
8.23,21.04,0.296
8.25,21.22,0.296
8.27,21.40,0.297
8.29,21.59,0.298
8.30,21.77,0.299
8.32,21.95,0.300
8.34,22.13,0.301
8.36,22.32,0.302
8.38,22.50,0.303
8.40,22.68,0.304
8.41,22.87,0.305
8.43,23.05,0.306
8.45,23.23,0.307
8.47,23.41,0.308
8.49,23.60,0.308
8.51,23.78,0.309
8.53,23.96,0.310
8.54,24.15,0.311
8.56,24.33,0.312
8.58,24.51,0.313
8.60,24.69,0.314
8.62,24.88,0.315
8.63,25.06,0.317
8.65,25.24,0.318
8.67,25.42,0.318
8.69,25.61,0.320
8.71,25.79,0.321
8.73,25.97,0.322
8.75,26.15,0.323
8.76,26.34,0.324
8.78,26.52,0.325
8.80,26.70,0.326
8.82,26.88,0.327
8.84,27.07,0.328
8.85,27.25,0.329
8.87,27.43,0.331
8.89,27.62,0.332
8.91,27.80,0.333
8.93,27.98,0.334
8.95,28.16,0.336
8.97,28.35,0.336
8.98,28.53,0.338
9.00,28.71,0.339
9.02,28.90,0.340
9.04,29.08,0.341
9.06,29.26,0.343
9.08,29.44,0.344
9.09,29.63,0.345
9.11,29.81,0.346
9.13,29.99,0.347
9.15,30.17,0.349
9.17,30.35,0.350
9.18,30.54,0.351
9.20,30.72,0.353
9.22,30.90,0.354
9.24,31.09,0.355
9.26,31.27,0.357
9.28,31.45,0.358
9.30,31.63,0.360
9.31,31.81,0.361
9.33,32.00,0.362
9.35,32.18,0.363
9.37,32.36,0.365
9.39,32.54,0.366
9.40,32.73,0.367
9.42,32.91,0.369
9.44,33.09,0.371
9.46,33.27,0.372
9.48,33.46,0.374
9.50,33.64,0.375
9.52,33.82,0.377
9.53,34.00,0.378
9.55,34.19,0.380
9.57,34.37,0.381
9.59,34.55,0.382
9.61,34.73,0.384
9.63,34.91,0.386
9.64,35.10,0.387
9.66,35.28,0.389
9.68,35.46,0.391
9.70,35.64,0.393
9.72,35.83,0.394
9.73,36.01,0.396
9.75,36.19,0.397
9.77,36.37,0.399
9.79,36.56,0.400
9.81,36.74,0.402
9.83,36.92,0.404
9.85,37.10,0.406
9.86,37.28,0.408
9.88,37.47,0.409
9.90,37.65,0.411
9.92,37.83,0.413
9.94,38.01,0.415
9.95,38.19,0.417
9.97,38.38,0.418
9.99,38.56,0.420
10.01,38.74,0.422
10.03,38.92,0.424
10.05,39.10,0.426
10.07,39.28,0.428
10.08,39.47,0.430
10.10,39.65,0.432
10.12,39.83,0.434
10.14,40.01,0.436
10.16,40.20,0.438
10.18,40.38,0.440
10.19,40.56,0.442
10.21,40.74,0.444
10.23,40.92,0.446
10.25,41.11,0.448
10.27,41.29,0.450
10.28,41.47,0.452
10.30,41.65,0.454
10.32,41.83,0.456
10.34,42.02,0.459
10.36,42.20,0.461
10.38,42.38,0.463
10.40,42.56,0.465
10.41,42.74,0.467
10.43,42.92,0.469
10.45,43.10,0.472
10.47,43.29,0.474
10.49,43.47,0.476
10.50,43.65,0.478
10.52,43.83,0.481
10.54,44.01,0.483
10.56,44.19,0.485
10.58,44.38,0.488
10.60,44.56,0.490
10.62,44.74,0.493
10.63,44.92,0.495
10.65,45.10,0.498
10.67,45.29,0.500
10.69,45.47,0.503
10.71,45.65,0.506
10.73,45.83,0.508
10.74,46.01,0.510
10.76,46.19,0.513
10.78,46.37,0.516
10.80,46.56,0.518
10.82,46.74,0.521
10.83,46.92,0.523
10.85,47.10,0.526
10.87,47.28,0.529
10.89,47.46,0.532
10.91,47.64,0.534
10.93,47.83,0.537
10.95,48.01,0.540
10.96,48.19,0.542
10.98,48.37,0.546
11.00,48.55,0.548
11.02,48.73,0.551
11.04,48.91,0.554
11.05,49.09,0.557
11.07,49.28,0.560
11.09,49.46,0.563
11.11,49.64,0.565
11.13,49.82,0.569
11.15,50.00,0.571
11.17,50.18,0.574
11.18,50.36,0.578
11.20,50.54,0.580
11.22,50.72,0.584
11.24,50.91,0.587
11.26,51.09,0.590
11.28,51.27,0.592
11.29,51.45,0.595
11.31,51.63,0.598
11.33,51.81,0.602
11.35,51.99,0.605
11.37,52.17,0.608
11.38,52.36,0.611
11.40,52.54,0.614
11.42,52.72,0.618
11.44,52.90,0.621
11.46,53.08,0.624
11.48,53.26,0.628
11.50,53.44,0.631
11.51,53.62,0.634
11.53,53.80,0.637
11.55,53.98,0.641
11.57,54.16,0.644
11.59,54.35,0.647
11.60,54.53,0.651
11.62,54.71,0.654
11.64,54.89,0.657
11.66,55.07,0.661
11.68,55.25,0.664
11.70,55.43,0.668
11.72,55.61,0.671
11.73,55.79,0.675
11.75,55.97,0.678
11.77,56.15,0.682
11.79,56.33,0.685
11.81,56.51,0.689
11.83,56.69,0.692
11.84,56.87,0.696
11.86,57.06,0.700
11.88,57.24,0.703
11.90,57.42,0.707
11.92,57.60,0.710
11.93,57.78,0.714
11.95,57.96,0.718
11.97,58.14,0.721
11.99,58.32,0.725
12.01,58.50,0.729
12.03,58.68,0.733
12.05,58.86,0.737
12.06,59.04,0.741
12.08,59.22,0.744
12.10,59.40,0.748
12.12,59.59,0.752
12.14,59.77,0.756
12.15,59.95,0.760
12.17,60.13,0.764
12.19,60.31,0.767
12.21,60.49,0.772
12.23,60.67,0.775
12.25,60.85,0.780
12.27,61.03,0.784
12.28,61.21,0.788
12.30,61.39,0.792
12.32,61.57,0.796
12.34,61.75,0.800
12.36,61.93,0.804
12.38,62.11,0.808
12.39,62.29,0.812
12.41,62.47,0.816
12.43,62.65,0.820
12.45,62.83,0.824
12.47,63.01,0.828
12.48,63.19,0.832
12.50,63.37,0.836
12.52,63.55,0.841
12.54,63.73,0.845
12.56,63.91,0.849
12.58,64.09,0.853
12.60,64.27,0.857
12.61,64.45,0.861
12.63,64.63,0.865
12.65,64.81,0.869
12.67,64.99,0.874
12.69,65.17,0.878
12.70,65.36,0.882
12.72,65.53,0.886
12.74,65.72,0.891
12.76,65.89,0.895
12.78,66.07,0.899
12.80,66.25,0.903
12.82,66.44,0.907
12.83,66.62,0.912
12.85,66.80,0.916
12.87,66.98,0.920
12.89,67.16,0.924
12.91,67.34,0.928
12.93,67.52,0.933
12.94,67.70,0.937
12.96,67.88,0.941
12.98,68.06,0.946
13.00,68.24,0.950
13.02,68.42,0.954
13.03,68.60,0.958
13.05,68.78,0.962
13.07,68.96,0.966
13.09,69.14,0.971
13.11,69.32,0.975
13.13,69.50,0.979
13.15,69.68,0.984
13.16,69.86,0.988
13.18,70.04,0.992
13.20,70.22,0.996
13.22,70.40,1.000
13.24,70.58,1.004
13.25,70.76,1.009
13.27,70.94,1.013
13.29,71.12,1.017
13.31,71.30,1.022
13.33,71.48,1.026
13.35,71.66,1.029
13.37,71.84,1.033
13.38,72.02,1.038
13.40,72.21,1.042
13.42,72.38,1.046
13.44,72.56,1.050
13.46,72.74,1.054
13.48,72.92,1.059
13.49,73.11,1.062
13.51,73.29,1.067
13.53,73.47,1.071
13.55,73.65,1.075
13.57,73.83,1.079
13.58,74.01,1.083
13.60,74.19,1.087
13.62,74.37,1.090
13.64,74.55,1.094
13.66,74.73,1.099
13.68,74.91,1.102
13.70,75.09,1.106
13.71,75.27,1.110
13.73,75.45,1.113
13.75,75.63,1.117
13.77,75.81,1.120
13.79,75.99,1.124
13.80,76.18,1.127
13.82,76.36,1.131
13.84,76.54,1.134
13.86,76.72,1.137
13.88,76.90,1.141
13.90,77.08,1.144
13.92,77.26,1.148
13.93,77.44,1.151
13.95,77.62,1.155
13.97,77.80,1.158
13.99,77.99,1.161
14.01,78.17,1.164
14.03,78.35,1.168
14.04,78.53,1.171
14.06,78.71,1.174
14.08,78.89,1.177
14.10,79.07,1.180
14.12,79.25,1.183
14.13,79.43,1.186
14.15,79.62,1.188
14.17,79.80,1.191
14.19,79.98,1.194
14.21,80.16,1.197
14.23,80.34,1.200
14.25,80.52,1.202
14.26,80.71,1.205
14.28,80.89,1.207
14.30,81.07,1.210
14.32,81.25,1.211
14.34,81.43,1.213
14.35,81.61,1.214
14.37,81.80,1.216
14.39,81.98,1.217
14.41,82.16,1.218
14.43,82.35,1.219
14.45,82.53,1.220
14.47,82.71,1.221
14.48,82.89,1.222
14.50,83.08,1.223
14.52,83.26,1.225
14.54,83.44,1.226
14.56,83.62,1.228
14.58,83.81,1.229
14.59,83.99,1.230
14.61,84.17,1.231
14.63,84.36,1.232
14.65,84.54,1.233
14.67,84.72,1.234
14.68,84.90,1.235
14.70,85.09,1.235
14.72,85.27,1.235
14.74,85.45,1.236
14.76,85.64,1.236
14.78,85.82,1.236
14.80,86.00,1.236
14.81,86.19,1.237
14.83,86.37,1.237
14.85,86.55,1.237
14.87,86.74,1.237
14.89,86.92,1.237
14.90,87.11,1.237
14.92,87.29,1.238
14.94,87.47,1.238
14.96,87.66,1.238
14.98,87.84,1.238
15.00,88.02,1.238
15.02,88.21,1.237
15.03,88.39,1.237
15.05,88.58,1.237
15.07,88.76,1.236
15.09,88.95,1.235
15.11,89.13,1.234
15.13,89.32,1.233
15.14,89.50,1.232
15.16,89.68,1.230
15.18,89.87,1.228
15.20,90.05,1.227
15.22,90.24,1.225
15.23,90.42,1.224
15.25,90.61,1.221
15.27,90.79,1.220
15.29,90.98,1.218
15.31,91.16,1.216
15.33,91.35,1.215
15.35,91.53,1.213
15.36,91.72,1.210
15.38,91.91,1.208
15.40,92.09,1.206
15.42,92.28,1.203
15.44,92.46,1.201
15.45,92.65,1.198
15.47,92.83,1.195
15.49,93.02,1.193
15.51,93.20,1.189
15.53,93.39,1.187
15.55,93.58,1.184
15.57,93.76,1.180
15.58,93.95,1.177
15.60,94.13,1.174
15.62,94.32,1.171
15.64,94.51,1.167
15.66,94.69,1.164
15.68,94.88,1.160
15.69,95.07,1.156
15.71,95.25,1.153
15.73,95.44,1.149
15.75,95.63,1.145
15.77,95.81,1.140
15.78,96.00,1.136
15.80,96.19,1.132
15.82,96.37,1.127
15.84,96.56,1.124
15.86,96.75,1.119
15.88,96.93,1.115
15.90,97.12,1.110
15.91,97.31,1.106
15.93,97.49,1.101
15.95,97.68,1.097
15.97,97.87,1.092
15.99,98.06,1.088
16.00,98.25,1.083
16.02,98.43,1.078
16.04,98.62,1.073
16.06,98.81,1.068
16.08,99.00,1.063
16.10,99.18,1.058
16.12,99.37,1.054
16.13,99.56,1.048
16.15,99.75,1.043
16.17,99.93,1.038
16.19,100.12,1.033
16.21,100.31,1.027
16.23,100.50,1.022
16.24,100.69,1.017
16.26,100.87,1.011
16.28,101.06,1.006
16.30,101.25,1.001
16.32,101.44,0.995
16.33,101.62,0.989
16.35,101.81,0.984
16.37,102.00,0.978
16.39,102.19,0.973
16.41,102.38,0.968
16.43,102.57,0.962
16.45,102.75,0.957
16.46,102.94,0.952
16.48,103.13,0.945
16.50,103.32,0.939
16.52,103.50,0.934
16.54,103.69,0.928
16.55,103.88,0.922
16.57,104.07,0.916
16.59,104.26,0.910
16.61,104.45,0.904
16.63,104.63,0.898
16.65,104.82,0.892
16.67,105.01,0.887
16.68,105.20,0.880
16.70,105.39,0.875
16.72,105.57,0.869
16.74,105.76,0.863
16.76,105.95,0.857
16.78,106.14,0.851
16.79,106.33,0.845
16.81,106.52,0.838
16.83,106.70,0.833
16.85,106.89,0.826
16.87,107.08,0.820
16.88,107.27,0.814
16.90,107.46,0.808
16.92,107.65,0.802
16.94,107.83,0.796
16.96,108.02,0.790
16.98,108.21,0.784
17.00,108.40,0.778
17.01,108.59,0.772
17.03,108.78,0.766
17.05,108.96,0.759
17.07,109.15,0.754
17.09,109.34,0.748
17.11,109.53,0.742
17.12,109.72,0.736
17.14,109.90,0.730
17.16,110.09,0.724
17.18,110.28,0.718
17.20,110.47,0.712
17.22,110.66,0.706
17.23,110.85,0.701
17.25,111.03,0.695
17.27,111.22,0.690
17.29,111.41,0.684
17.31,111.60,0.679
17.33,111.79,0.672
17.34,111.97,0.667
17.36,112.16,0.661
17.38,112.35,0.655
17.40,112.54,0.649
17.42,112.73,0.644
17.43,112.91,0.638
17.45,113.10,0.633
17.47,113.29,0.627
17.49,113.48,0.621
17.51,113.66,0.616
17.53,113.85,0.611
17.54,114.04,0.605
17.56,114.23,0.600
17.58,114.42,0.595
17.60,114.60,0.589
17.62,114.79,0.584
17.64,114.98,0.578
17.66,115.17,0.574
17.67,115.35,0.568
17.69,115.54,0.563
17.71,115.73,0.558
17.73,115.92,0.553
17.75,116.10,0.548
17.77,116.29,0.543
17.78,116.48,0.538
17.80,116.67,0.534
17.82,116.85,0.528
17.84,117.04,0.524
17.86,117.23,0.519
17.88,117.41,0.514
17.89,117.60,0.510
17.91,117.79,0.505
17.93,117.98,0.500
17.95,118.16,0.495
17.97,118.35,0.491
17.98,118.54,0.486
18.00,118.72,0.482
18.02,118.91,0.477
18.04,119.10,0.473
18.06,119.28,0.468
18.08,119.47,0.464
18.09,119.66,0.460
18.11,119.85,0.456
18.13,120.03,0.452
18.15,120.22,0.448
18.17,120.41,0.444
18.19,120.59,0.440
18.21,120.78,0.437
18.22,120.97,0.432
18.24,121.15,0.428
18.26,121.34,0.424
18.28,121.53,0.421
18.30,121.71,0.417
18.32,121.90,0.413
18.33,122.09,0.410
18.35,122.27,0.406
18.37,122.46,0.403
18.39,122.64,0.399
18.41,122.83,0.396
18.43,123.02,0.392
18.44,123.20,0.389
18.46,123.39,0.385
18.48,123.57,0.382
18.50,123.76,0.379
18.52,123.94,0.376
18.53,124.13,0.372
18.55,124.32,0.370
18.57,124.51,0.367
18.59,124.69,0.364
18.61,124.88,0.361
18.63,125.06,0.358
18.64,125.25,0.355
18.66,125.43,0.352
18.68,125.62,0.350
18.70,125.80,0.347
18.72,125.99,0.344
18.74,126.18,0.342
18.76,126.36,0.339
18.77,126.55,0.336
18.79,126.73,0.334
18.81,126.92,0.332
18.83,127.10,0.329
18.85,127.29,0.327
18.87,127.47,0.325
18.88,127.66,0.322
18.90,127.84,0.320
18.92,128.03,0.318
18.94,128.21,0.316
18.96,128.40,0.314
18.98,128.58,0.312
18.99,128.77,0.310
19.01,128.95,0.308
19.03,129.14,0.306
19.05,129.32,0.305
19.07,129.51,0.303
19.08,129.69,0.301
19.10,129.88,0.299
19.12,130.06,0.297
19.14,130.25,0.296
19.16,130.43,0.294
19.18,130.62,0.292
19.19,130.80,0.291
19.21,130.99,0.289
19.23,131.17,0.288
19.25,131.36,0.287
19.27,131.54,0.286
19.29,131.73,0.284
19.31,131.91,0.283
19.32,132.09,0.282
19.34,132.28,0.280
19.36,132.46,0.279
19.38,132.65,0.278
19.40,132.83,0.277
19.42,133.02,0.276
19.43,133.20,0.275
19.45,133.39,0.274
19.47,133.57,0.273
19.49,133.75,0.272
19.51,133.94,0.271
19.53,134.12,0.270
19.54,134.31,0.269
19.56,134.49,0.268
19.58,134.68,0.268
19.60,134.86,0.267
19.62,135.04,0.266
19.63,135.23,0.266
19.65,135.41,0.265
19.67,135.60,0.264
19.69,135.78,0.264
19.71,135.96,0.263
19.73,136.15,0.262
19.74,136.33,0.261
19.76,136.51,0.261
19.78,136.70,0.261
19.80,136.88,0.260
19.82,137.07,0.260
19.84,137.25,0.260
19.86,137.43,0.259
19.87,137.62,0.259
19.89,137.80,0.259
19.91,137.99,0.258
19.93,138.17,0.258
19.95,138.35,0.258
19.97,138.54,0.258
19.98,138.72,0.257
20.00,138.91,0.257
20.02,139.09,0.257
20.04,139.27,0.257
20.06,139.46,0.256
20.08,139.64,0.256
20.09,139.82,0.256
20.11,140.01,0.256
20.13,140.19,0.255
20.15,140.37,0.255
20.17,140.56,0.255
20.18,140.74,0.254
20.20,140.92,0.254
20.22,141.11,0.254
20.24,141.29,0.254
20.26,141.48,0.254
20.28,141.66,0.254
20.29,141.84,0.253
20.31,142.03,0.253
20.33,142.21,0.253
20.35,142.39,0.253
20.37,142.58,0.253
20.39,142.76,0.253
20.41,142.94,0.253
20.42,143.13,0.252
20.44,143.31,0.252
20.46,143.50,0.252
20.48,143.68,0.252
20.50,143.86,0.252
20.52,144.05,0.252
20.53,144.23,0.252
20.55,144.41,0.252
20.57,144.60,0.252
20.59,144.78,0.252
20.61,144.96,0.252
20.63,145.15,0.252
20.64,145.33,0.252
20.66,145.51,0.251
20.68,145.70,0.251
20.70,145.88,0.251
20.72,146.06,0.251
20.73,146.25,0.251
20.75,146.43,0.251
20.77,146.61,0.251
20.79,146.80,0.251
20.81,146.98,0.251
20.83,147.16,0.251
20.84,147.35,0.251
20.86,147.53,0.251
20.88,147.71,0.251
20.90,147.90,0.251
20.92,148.08,0.252
20.94,148.26,0.252
20.96,148.45,0.252
20.97,148.63,0.252
20.99,148.82,0.252
21.01,149.00,0.252
21.03,149.18,0.252
21.05,149.36,0.252
21.07,149.55,0.252
21.08,149.73,0.252
21.10,149.92,0.252
21.12,150.10,0.252
21.14,150.28,0.252
21.16,150.47,0.252
21.18,150.65,0.252
21.19,150.83,0.252
21.21,151.01,0.253
21.23,151.20,0.253
21.25,151.38,0.253
21.27,151.57,0.253
21.28,151.75,0.253
21.30,151.93,0.253
21.32,152.12,0.253
21.34,152.30,0.253
21.36,152.48,0.253
21.38,152.67,0.253
21.39,152.85,0.254
21.41,153.03,0.254
21.43,153.22,0.254
21.45,153.40,0.254
21.47,153.58,0.254
21.49,153.77,0.254
21.51,153.95,0.254
21.52,154.13,0.254
21.54,154.32,0.254
21.56,154.50,0.254
21.58,154.68,0.255
21.60,154.87,0.255
21.62,155.05,0.255
21.63,155.23,0.255
21.65,155.42,0.255
21.67,155.60,0.255
21.69,155.78,0.255
21.71,155.97,0.255
21.73,156.15,0.255
21.74,156.33,0.256
21.76,156.52,0.256
21.78,156.70,0.256
21.80,156.88,0.256
21.82,157.07,0.256
21.83,157.25,0.256
21.85,157.44,0.256
21.87,157.62,0.256
21.89,157.80,0.256
21.91,157.98,0.257
21.93,158.17,0.257
21.94,158.35,0.257
21.96,158.54,0.257
21.98,158.72,0.257
22.00,158.90,0.257
22.02,159.09,0.257
22.04,159.27,0.258
22.06,159.45,0.258
22.07,159.64,0.258
22.09,159.82,0.258
22.11,160.00,0.258
22.13,160.19,0.258
22.15,160.37,0.258
22.17,160.55,0.259
22.18,160.74,0.259
22.20,160.92,0.259
22.22,161.10,0.259
22.24,161.29,0.259
22.26,161.47,0.259
22.28,161.65,0.259
22.29,161.84,0.260
22.31,162.02,0.260
22.33,162.20,0.260
22.35,162.39,0.260
22.37,162.57,0.260
22.38,162.75,0.260
22.40,162.94,0.261
22.42,163.12,0.261
22.44,163.30,0.261
22.46,163.49,0.261
22.48,163.67,0.261
22.49,163.85,0.262
22.51,164.04,0.262
22.53,164.22,0.262
22.55,164.40,0.262
22.57,164.59,0.262
22.59,164.77,0.263
22.61,164.95,0.263
22.62,165.13,0.263
22.64,165.32,0.263
22.66,165.50,0.263
22.68,165.68,0.264
22.70,165.87,0.264
22.72,166.05,0.264
22.73,166.23,0.265
22.75,166.42,0.265
22.77,166.60,0.265
22.79,166.78,0.266
22.81,166.97,0.266
22.83,167.15,0.266
22.84,167.33,0.267
22.86,167.52,0.267
22.88,167.70,0.267
22.90,167.88,0.267
22.92,168.07,0.268
22.93,168.25,0.268
22.95,168.43,0.269
22.97,168.62,0.269
22.99,168.80,0.270
23.01,168.98,0.270
23.03,169.17,0.271
23.04,169.35,0.271
23.06,169.53,0.272
23.08,169.72,0.273
23.10,169.90,0.273
23.12,170.08,0.274
23.14,170.26,0.275
23.16,170.45,0.275
23.17,170.63,0.276
23.19,170.81,0.276
23.21,171.00,0.277
23.23,171.18,0.278
23.25,171.36,0.279
23.27,171.55,0.279
23.28,171.73,0.280
23.30,171.91,0.281
23.32,172.09,0.282
23.34,172.28,0.283
23.36,172.46,0.284
23.38,172.64,0.285
23.39,172.83,0.286
23.41,173.01,0.287
23.43,173.19,0.288
23.45,173.38,0.289
23.47,173.56,0.290
23.48,173.74,0.291
23.50,173.92,0.292
23.52,174.11,0.292
23.54,174.29,0.293
23.56,174.47,0.294
23.58,174.66,0.295
23.59,174.84,0.296
23.61,175.02,0.297
23.63,175.20,0.299
23.65,175.39,0.299
23.67,175.57,0.300
23.69,175.75,0.301
23.71,175.93,0.302
23.72,176.12,0.303
23.74,176.30,0.304
23.76,176.48,0.304
23.78,176.67,0.305
23.80,176.85,0.306
23.82,177.03,0.307
23.83,177.21,0.308
23.85,177.40,0.308
23.87,177.58,0.309
23.89,177.76,0.309
23.91,177.95,0.310
23.93,178.13,0.310
23.94,178.31,0.311
23.96,178.50,0.311
23.98,178.68,0.311
24.00,178.86,0.311
24.02,179.05,0.311
24.03,179.23,0.312
24.05,179.41,0.312
24.07,179.60,0.312
24.09,179.78,0.312
24.11,179.96,0.312
24.13,180.15,0.312
24.14,180.33,0.313
24.16,180.51,0.313
24.18,180.70,0.313
24.20,180.88,0.313
24.22,181.06,0.313
24.24,181.25,0.313
24.26,181.43,0.313
24.27,181.61,0.314
24.29,181.80,0.314
24.31,181.98,0.314
24.33,182.16,0.314
24.35,182.35,0.314
24.37,182.53,0.314
24.38,182.71,0.314
24.40,182.90,0.314
24.42,183.08,0.314
24.44,183.26,0.314
24.46,183.45,0.314
24.48,183.63,0.314
24.49,183.82,0.314
24.51,184.00,0.314
24.53,184.18,0.314
24.55,184.37,0.314
24.57,184.55,0.314
24.58,184.73,0.314
24.60,184.92,0.314
24.62,185.10,0.314
24.64,185.28,0.314
24.66,185.47,0.314
24.68,185.65,0.314
24.69,185.83,0.314
24.71,186.02,0.314
24.73,186.20,0.314
24.75,186.38,0.314
24.77,186.57,0.315
24.79,186.75,0.315
24.81,186.93,0.315
24.82,187.12,0.315
24.84,187.30,0.315
24.86,187.48,0.315
24.88,187.67,0.315
24.90,187.85,0.315
24.92,188.03,0.315
24.93,188.22,0.315
24.95,188.40,0.315
24.97,188.59,0.315
24.99,188.77,0.315
25.01,188.95,0.316
25.03,189.14,0.316
25.04,189.32,0.316
25.06,189.50,0.316
25.08,189.68,0.316
25.10,189.87,0.316
25.12,190.05,0.316
25.13,190.23,0.316
25.15,190.42,0.316
25.17,190.60,0.316
25.19,190.78,0.316
25.21,190.97,0.317
25.23,191.15,0.317
25.24,191.33,0.317
25.26,191.52,0.317
25.28,191.70,0.317
25.30,191.89,0.317
25.32,192.07,0.317
25.34,192.25,0.317
25.36,192.43,0.318
25.37,192.62,0.318
25.39,192.80,0.318
25.41,192.99,0.318
25.43,193.17,0.318
25.45,193.35,0.318
25.47,193.54,0.318
25.48,193.72,0.318
25.50,193.90,0.319
25.52,194.09,0.319
25.54,194.27,0.319
25.56,194.45,0.319
25.58,194.64,0.319
25.59,194.82,0.319
25.61,195.00,0.319
25.63,195.19,0.319
25.65,195.37,0.320
25.67,195.55,0.320
25.68,195.74,0.320
25.70,195.92,0.320
25.72,196.10,0.320
25.74,196.29,0.320
25.76,196.47,0.320
25.78,196.65,0.320
25.79,196.84,0.320
25.81,197.02,0.321
25.83,197.20,0.321
25.85,197.39,0.321
25.87,197.57,0.321
25.89,197.75,0.321
25.91,197.94,0.321
25.92,198.12,0.321
25.94,198.30,
25.96,198.49,
25.98,198.67,
25.99,,

[step]
Ramp 10.00 °C/min to -60.00 °C
Time,Temperature,Heat Flow (Normalized)
min,°C,W/g
26.99,200.13,-0.006
27.01,200.13,-0.006
27.03,200.13,-0.006
27.05,200.11,-0.007
27.07,200.08,-0.017
27.08,200.03,-0.032
27.10,199.95,-0.055
27.12,199.85,-0.086
27.14,199.72,-0.120
27.16,199.59,-0.155
27.18,199.44,-0.187
27.19,199.28,-0.215
27.21,199.12,-0.237
27.23,198.96,-0.255
27.25,198.80,-0.270
27.27,198.63,-0.281
27.29,198.46,-0.290
27.31,198.28,-0.297
27.32,198.11,-0.304
27.34,197.94,-0.308
27.36,197.76,-0.313
27.38,197.58,-0.317
27.40,197.40,-0.320
27.42,197.23,-0.323
27.43,197.05,-0.325
27.45,196.87,-0.326
27.47,196.69,-0.327
27.49,196.51,-0.329
27.51,196.33,-0.330
27.53,196.15,-0.331
27.54,195.97,-0.332
27.56,195.78,-0.332
27.58,195.60,-0.333
27.60,195.42,-0.333
27.62,195.24,-0.333
27.63,195.06,-0.333
27.65,194.88,-0.334
27.67,194.70,-0.334
27.69,194.52,-0.334
27.71,194.33,-0.334
27.73,194.15,-0.334
27.74,193.97,-0.334
27.76,193.79,-0.335
27.78,193.61,-0.335
27.80,193.42,-0.335
27.82,193.24,-0.335
27.84,193.06,-0.335
27.86,192.88,-0.335
27.87,192.70,-0.335
27.89,192.51,-0.335
27.91,192.33,-0.335
27.93,192.15,-0.336
27.95,191.97,-0.336
27.97,191.78,-0.336
27.98,191.60,-0.336
28.00,191.42,-0.336
28.02,191.24,-0.336
28.04,191.05,-0.336
28.06,190.87,-0.336
28.08,190.69,-0.336
28.09,190.51,-0.336
28.11,190.32,-0.336
28.13,190.14,-0.337
28.15,189.96,-0.337
28.17,189.77,-0.337
28.18,189.59,-0.337
28.20,189.41,-0.337
28.22,189.23,-0.337
28.24,189.04,-0.337
28.26,188.86,-0.337
28.28,188.68,-0.337
28.29,188.49,-0.337
28.31,188.31,-0.337
28.33,188.13,-0.337
28.35,187.95,-0.337
28.37,187.76,-0.337
28.39,187.58,-0.337
28.41,187.40,-0.337
28.42,187.22,-0.337
28.44,187.03,-0.337
28.46,186.85,-0.337
28.48,186.66,-0.337
28.50,186.48,-0.337
28.52,186.30,-0.337
28.53,186.12,-0.337
28.55,185.93,-0.337
28.57,185.75,-0.337
28.59,185.57,-0.337
28.61,185.38,-0.337
28.63,185.20,-0.336
28.64,185.02,-0.336
28.66,184.83,-0.336
28.68,184.65,-0.336
28.70,184.47,-0.336
28.72,184.29,-0.336
28.73,184.10,-0.336
28.75,183.92,-0.336
28.77,183.74,-0.336
28.79,183.55,-0.336
28.81,183.37,-0.336
28.83,183.19,-0.336
28.84,183.00,-0.336
28.86,182.82,-0.336
28.88,182.64,-0.336
28.90,182.45,-0.336
28.92,182.27,-0.336
28.94,182.09,-0.335
28.96,181.90,-0.335
28.97,181.72,-0.335
28.99,181.54,-0.335
29.01,181.35,-0.335
29.03,181.17,-0.335
29.05,180.99,-0.335
29.07,180.80,-0.335
29.08,180.62,-0.335
29.10,180.44,-0.335
29.12,180.25,-0.334
29.14,180.07,-0.334
29.16,179.89,-0.334
29.18,179.70,-0.334
29.19,179.52,-0.334
29.21,179.34,-0.334
29.23,179.15,-0.334
29.25,178.97,-0.333
29.27,178.79,-0.333
29.28,178.61,-0.333
29.30,178.42,-0.333
29.32,178.24,-0.333
29.34,178.05,-0.333
29.36,177.87,-0.333
29.38,177.69,-0.332
29.39,177.50,-0.332
29.41,177.32,-0.332
29.43,177.14,-0.332
29.45,176.95,-0.331
29.47,176.77,-0.331
29.49,176.59,-0.331
29.51,176.41,-0.331
29.52,176.22,-0.331
29.54,176.04,-0.330
29.56,175.86,-0.330
29.58,175.67,-0.330
29.60,175.49,-0.330
29.62,175.31,-0.329
29.63,175.12,-0.329
29.65,174.94,-0.329
29.67,174.75,-0.329
29.69,174.57,-0.328
29.71,174.39,-0.328
29.73,174.20,-0.328
29.74,174.02,-0.327
29.76,173.84,-0.327
29.78,173.65,-0.327
29.80,173.47,-0.327
29.82,173.29,-0.326
29.83,173.10,-0.326
29.85,172.92,-0.325
29.87,172.74,-0.325
29.89,172.55,-0.324
29.91,172.37,-0.324
29.93,172.19,-0.323
29.94,172.00,-0.323
29.96,171.82,-0.322
29.98,171.64,-0.322
30.00,171.45,-0.322
30.02,171.27,-0.321
30.04,171.08,-0.321
30.06,170.90,-0.320
30.07,170.72,-0.320
30.09,170.53,-0.319
30.11,170.35,-0.319
30.13,170.17,-0.318
30.15,169.98,-0.318
30.17,169.80,-0.317
30.18,169.62,-0.317
30.20,169.43,-0.316
30.22,169.25,-0.316
30.24,169.07,-0.315
30.26,168.88,-0.315
30.28,168.70,-0.314
30.29,168.51,-0.314
30.31,168.33,-0.313
30.33,168.15,-0.313
30.35,167.96,-0.312
30.37,167.78,-0.312
30.38,167.60,-0.312
30.40,167.41,-0.311
30.42,167.23,-0.311
30.44,167.05,-0.310
30.46,166.86,-0.310
30.48,166.68,-0.310
30.49,166.50,-0.309
30.51,166.31,-0.309
30.53,166.13,-0.308
30.55,165.95,-0.308
30.57,165.76,-0.307
30.59,165.58,-0.307
30.61,165.39,-0.307
30.62,165.21,-0.306
30.64,165.03,-0.306
30.66,164.84,-0.306
30.68,164.66,-0.305
30.70,164.48,-0.305
30.72,164.29,-0.305
30.73,164.11,-0.304
30.75,163.93,-0.304
30.77,163.74,-0.303
30.79,163.56,-0.303
30.81,163.38,-0.303
30.83,163.19,-0.302
30.84,163.01,-0.302
30.86,162.83,-0.302
30.88,162.64,-0.301
30.90,162.46,-0.301
30.92,162.28,-0.301
30.93,162.09,-0.300
30.95,161.91,-0.300
30.97,161.73,-0.300
30.99,161.54,-0.299
31.01,161.36,-0.299
31.03,161.17,-0.299
31.04,160.99,-0.299
31.06,160.81,-0.298
31.08,160.62,-0.298
31.10,160.44,-0.297
31.12,160.26,-0.297
31.14,160.07,-0.297
31.16,159.89,-0.297
31.17,159.71,-0.296
31.19,159.52,-0.296
31.21,159.34,-0.296
31.23,159.16,-0.295
31.25,158.97,-0.295
31.27,158.79,-0.295
31.28,158.61,-0.294
31.30,158.42,-0.294
31.32,158.24,-0.294
31.34,158.06,-0.294
31.36,157.87,-0.293
31.38,157.69,-0.293
31.39,157.51,-0.293
31.41,157.33,-0.293
31.43,157.14,-0.292
31.45,156.96,-0.292
31.47,156.77,-0.292
31.48,156.59,-0.292
31.50,156.41,-0.291
31.52,156.22,-0.291
31.54,156.04,-0.291
31.56,155.86,-0.291
31.58,155.67,-0.290
31.59,155.49,-0.290
31.61,155.30,-0.290
31.63,155.12,-0.290
31.65,154.94,-0.290
31.67,154.76,-0.290
31.69,154.57,-0.289
31.71,154.39,-0.289
31.72,154.20,-0.289
31.74,154.02,-0.288
31.76,153.84,-0.288
31.78,153.66,-0.288
31.80,153.47,-0.288
31.82,153.29,-0.288
31.83,153.10,-0.287
31.85,152.92,-0.287
31.87,152.74,-0.287
31.89,152.55,-0.287
31.91,152.37,-0.287
31.93,152.19,-0.287
31.94,152.00,-0.286
31.96,151.82,-0.286
31.98,151.64,-0.286
32.00,151.46,-0.286
32.02,151.27,-0.286
32.03,151.09,-0.285
32.05,150.91,-0.285
32.07,150.72,-0.285
32.09,150.54,-0.285
32.11,150.36,-0.285
32.13,150.17,-0.285
32.14,149.99,-0.284
32.16,149.81,-0.284
32.18,149.62,-0.284
32.20,149.44,-0.284
32.22,149.26,-0.284
32.24,149.07,-0.283
32.26,148.89,-0.283
32.27,148.71,-0.283
32.29,148.52,-0.283
32.31,148.34,-0.283
32.33,148.15,-0.283
32.35,147.97,-0.283
32.37,147.79,-0.282
32.38,147.61,-0.282
32.40,147.42,-0.282
32.42,147.24,-0.282
32.44,147.05,-0.282
32.46,146.87,-0.282
32.48,146.69,-0.281
32.49,146.51,-0.281
32.51,146.32,-0.281
32.53,146.14,-0.281
32.55,145.95,-0.281
32.57,145.77,-0.281
32.58,145.59,-0.281
32.60,145.40,-0.280
32.62,145.22,-0.280
32.64,145.04,-0.280
32.66,144.85,-0.280
32.68,144.67,-0.280
32.69,144.49,-0.280
32.71,144.30,-0.280
32.73,144.12,-0.279
32.75,143.94,-0.279
32.77,143.75,-0.279
32.79,143.57,-0.279
32.81,143.39,-0.279
32.82,143.20,-0.279
32.84,143.02,-0.279
32.86,142.84,-0.278
32.88,142.65,-0.278
32.90,142.47,-0.278
32.92,142.29,-0.278
32.93,142.11,-0.278
32.95,141.92,-0.278
32.97,141.74,-0.278
32.99,141.55,-0.277
33.01,141.37,-0.277
33.03,141.19,-0.277
33.04,141.00,-0.277
33.06,140.82,-0.277
33.08,140.64,-0.277
33.10,140.46,-0.277
33.12,140.27,-0.276
33.13,140.09,-0.276
33.15,139.90,-0.276
33.17,139.72,-0.276
33.19,139.54,-0.276
33.21,139.35,-0.276
33.23,139.17,-0.276
33.24,138.99,-0.276
33.26,138.80,-0.276
33.28,138.62,-0.275
33.30,138.44,-0.275
33.32,138.25,-0.275
33.34,138.07,-0.275
33.36,137.89,-0.275
33.37,137.70,-0.275
33.39,137.52,-0.275
33.41,137.34,-0.275
33.43,137.15,-0.274
33.45,136.97,-0.274
33.47,136.79,-0.274
33.48,136.60,-0.274
33.50,136.42,-0.274
33.52,136.24,-0.274
33.54,136.05,-0.274
33.56,135.87,-0.274
33.58,135.69,-0.273
33.59,135.50,-0.273
33.61,135.32,-0.273
33.63,135.14,-0.273
33.65,134.95,-0.273
33.67,134.77,-0.273
33.68,134.59,-0.273
33.70,134.40,-0.273
33.72,134.22,-0.272
33.74,134.04,-0.272
33.76,133.85,-0.272
33.78,133.67,-0.272
33.79,133.49,-0.272
33.81,133.31,-0.272
33.83,133.12,-0.272
33.85,132.94,-0.272
33.87,132.76,-0.272
33.89,132.57,-0.271
33.91,132.39,-0.271
33.92,132.20,-0.271
33.94,132.02,-0.271
33.96,131.84,-0.271
33.98,131.66,-0.271
34.00,131.47,-0.271
34.02,131.29,-0.271
34.03,131.10,-0.271
34.05,130.92,-0.270
34.07,130.74,-0.270
34.09,130.55,-0.270
34.11,130.37,-0.270
34.13,130.19,-0.270
34.14,130.01,-0.270
34.16,129.82,-0.270
34.18,129.64,-0.270
34.20,129.46,-0.270
34.22,129.27,-0.269
34.24,129.09,-0.269
34.25,128.91,-0.269
34.27,128.72,-0.269
34.29,128.54,-0.269
[...]
115.21,10.95,0.172
115.23,11.13,0.172
115.25,11.31,0.172
115.27,11.50,0.172
115.29,11.68,0.172
115.31,11.86,0.173
115.33,12.05,0.173
115.34,12.23,0.173
115.36,12.41,0.173
115.38,12.60,0.173
115.40,12.78,0.173
115.42,12.96,0.173
115.44,13.15,0.173
115.45,13.33,0.174
115.47,13.51,0.174
115.49,13.70,0.174
115.51,13.88,0.174
115.53,14.06,0.174
115.55,14.25,0.174
115.56,14.43,0.174
115.58,14.61,0.174
115.60,14.80,0.174
115.62,14.98,0.175
115.64,15.16,0.175
115.65,15.35,0.175
115.67,15.53,0.175
115.69,15.72,0.175
115.71,15.90,0.175
115.73,16.08,0.175
115.75,16.27,0.175
115.76,16.45,0.175
115.78,16.63,0.176
115.80,16.82,0.176
115.82,17.00,0.176
115.84,17.18,0.176
115.86,17.37,0.176
115.88,17.55,0.176
115.89,17.73,0.176
115.91,17.92,0.176
115.93,18.10,0.176
115.95,18.28,0.177
115.97,18.47,0.177
115.99,18.65,0.177
116.00,18.83,0.177
116.02,19.02,0.177
116.04,19.20,0.177
116.06,19.38,0.177
116.08,19.57,0.177
116.10,19.75,0.177
116.11,19.94,0.178
116.13,20.12,0.178
116.15,20.30,0.178
116.17,20.49,0.178
116.19,20.67,0.178
116.20,20.85,0.178
116.22,21.04,0.178
116.24,21.22,0.178
116.26,21.40,0.178
116.28,21.59,0.179
116.30,21.77,0.179
116.31,21.95,0.179
116.33,22.14,0.179
116.35,22.32,0.179
116.37,22.50,0.179
116.39,22.69,0.179
116.41,22.87,0.179
116.43,23.05,0.179
116.44,23.24,0.180
116.46,23.42,0.180
116.48,23.60,0.180
116.50,23.79,0.180
116.52,23.97,0.180
116.54,24.15,0.180
116.55,24.34,0.180
116.57,24.52,0.180
116.59,24.70,0.181
116.61,24.89,0.181
116.63,25.07,0.181
116.65,25.26,0.181
116.66,25.44,0.181
116.68,25.62,0.181
116.70,25.81,0.181
116.72,25.99,0.181
116.74,26.17,0.182
116.75,26.36,0.182
116.77,26.54,0.182
116.79,26.72,0.182
116.81,26.91,0.182
116.83,27.09,0.182
116.85,27.27,0.182
116.86,27.46,0.182
116.88,27.64,0.182
116.90,27.83,0.183
116.92,28.01,0.183
116.94,28.19,0.183
116.96,28.38,0.183
116.98,28.56,0.183
116.99,28.74,0.183
117.01,28.93,0.183
117.03,29.11,0.183
117.05,29.29,0.184
117.07,29.48,0.184
117.09,29.66,0.184
117.10,29.84,0.184
117.12,30.03,0.184
117.14,30.21,0.184
117.16,30.39,0.184
117.18,30.58,0.184
117.20,30.76,0.184
117.21,30.94,0.185
117.23,31.13,0.185
117.25,31.31,0.185
117.27,31.50,0.185
117.29,31.68,0.185
117.30,31.86,0.185
117.32,32.05,0.185
117.34,32.23,0.185
117.36,32.41,0.185
117.38,32.59,0.185
117.40,32.78,0.186
117.41,32.96,0.186
117.43,33.14,0.186
117.45,33.33,0.186
117.47,33.51,0.186
117.49,33.70,0.186
117.51,33.88,0.186
117.53,34.06,0.186
117.54,34.25,0.186
117.56,34.43,0.187
117.58,34.61,0.187
117.60,34.80,0.187
117.62,34.98,0.187
117.64,35.16,0.187
117.65,35.35,0.187
117.67,35.53,0.187
117.69,35.71,0.187
117.71,35.90,0.187
117.73,36.08,0.188
117.75,36.26,0.188
117.76,36.45,0.188
117.78,36.63,0.188
117.80,36.81,0.188
117.82,37.00,0.188
117.84,37.18,0.188
117.85,37.37,0.188
117.87,37.55,0.188
117.89,37.73,0.189
117.91,37.92,0.189
117.93,38.10,0.189
117.95,38.28,0.189
117.96,38.46,0.189
117.98,38.65,0.189
118.00,38.83,0.189
118.02,39.01,0.189
118.04,39.20,0.189
118.06,39.38,0.190
118.08,39.56,0.190
118.09,39.75,0.190
118.11,39.93,0.190
118.13,40.11,0.190
118.15,40.30,0.190
118.17,40.48,0.190
118.19,40.67,0.190
118.20,40.85,0.190
118.22,41.03,0.191
118.24,41.22,0.191
118.26,41.40,0.191
118.28,41.58,0.191
118.30,41.77,0.191
118.31,41.95,0.191
118.33,42.13,0.191
118.35,42.32,0.191
118.37,42.50,0.192
118.39,42.68,0.192
118.40,42.87,0.192
118.42,43.05,0.192
118.44,43.23,0.192
118.46,43.42,0.192
118.48,43.60,0.192
118.50,43.78,0.192
118.51,43.97,0.192
118.53,44.15,0.193
118.55,44.33,0.193
118.57,44.52,0.193
118.59,44.70,0.193
118.61,44.89,0.193
118.63,45.07,0.193
118.64,45.25,0.193
118.66,45.44,0.193
118.68,45.62,0.194
118.70,45.80,0.194
118.72,45.99,0.194
118.74,46.17,0.194
118.75,46.35,0.194
118.77,46.54,0.194
118.79,46.72,0.194
118.81,46.90,0.194
118.83,47.09,0.194
118.85,47.27,0.195
118.86,47.45,0.195
118.88,47.64,0.195
118.90,47.82,0.195
118.92,48.00,0.195
118.94,48.19,0.195
118.95,48.37,0.195
118.97,48.55,0.195
118.99,48.74,0.196
119.01,48.92,0.196
119.03,49.11,0.196
119.05,49.29,0.196
119.06,49.47,0.196
119.08,49.66,0.196
119.10,49.84,0.196
119.12,50.02,0.196
119.14,50.21,0.196
119.16,50.39,0.197
119.18,50.57,0.197
119.19,50.76,0.197
119.21,50.94,0.197
119.23,51.12,0.197
119.25,51.31,0.197
119.27,51.49,0.197
119.29,51.67,0.197
119.30,51.86,0.197
119.32,52.04,0.198
119.34,52.22,0.198
119.36,52.41,0.198
119.38,52.59,0.198
119.40,52.77,0.198
119.41,52.96,0.198
119.43,53.14,0.198
119.45,53.32,0.198
119.47,53.51,0.199
119.49,53.69,0.199
119.50,53.87,0.199
119.52,54.06,0.199
119.54,54.24,0.199
119.56,54.43,0.199
119.58,54.61,0.199
119.60,54.79,0.199
119.61,54.97,0.199
119.63,55.16,0.200
119.65,55.34,0.200
119.67,55.53,0.200
119.69,55.71,0.200
119.71,55.89,0.200
119.73,56.08,0.200
119.74,56.26,0.200
119.76,56.44,0.200
119.78,56.63,0.200
119.80,56.81,0.201
119.82,56.99,0.201
119.84,57.18,0.201
119.85,57.36,0.201
119.87,57.54,0.201
119.89,57.73,0.201
119.91,57.91,0.201
119.93,58.09,0.201
119.95,58.28,0.202
119.96,58.46,0.202
119.98,58.64,0.202
120.00,58.83,0.202
120.02,59.01,0.202
120.04,59.19,0.202
120.05,59.38,0.202
120.07,59.56,0.202
120.09,59.74,0.202
120.11,59.93,0.203
120.13,60.11,0.203
120.15,60.29,0.203
120.16,60.48,0.203
120.18,60.66,0.203
120.20,60.85,0.203
120.22,61.03,0.203
120.24,61.21,0.203
120.26,61.40,0.203
120.28,61.58,0.204
120.29,61.76,0.204
120.31,61.95,0.204
120.33,62.13,0.204
120.35,62.31,0.204
120.37,62.50,0.204
120.39,62.68,0.204
120.40,62.86,0.204
120.42,63.05,0.204
120.44,63.23,0.205
120.46,63.41,0.205
120.48,63.60,0.205
120.50,63.78,0.205
120.51,63.96,0.205
120.53,64.15,0.205
120.55,64.33,0.205
120.57,64.52,0.205
120.59,64.70,0.206
120.60,64.88,0.206
120.62,65.07,0.206
120.64,65.25,0.206
120.66,65.43,0.206
120.68,65.62,0.206
120.70,65.80,0.206
120.71,65.98,0.206
120.73,66.17,0.206
120.75,66.35,0.207
120.77,66.53,0.207
120.79,66.72,0.207
120.81,66.90,0.207
120.83,67.08,0.207
120.84,67.27,0.207
120.86,67.45,0.207
120.88,67.63,0.207
120.90,67.82,0.207
120.92,68.00,0.208
120.94,68.18,0.208
120.95,68.37,0.208
120.97,68.55,0.208
120.99,68.73,0.208
121.01,68.92,0.208
121.03,69.10,0.208
121.05,69.29,0.208
121.06,69.47,0.208
121.08,69.65,0.209
121.10,69.84,0.209
121.12,70.02,0.209
121.14,70.20,0.209
121.15,70.39,0.209
121.17,70.57,0.209
121.19,70.75,0.209
121.21,70.94,0.209
121.23,71.12,0.210
121.25,71.30,0.210
121.26,71.49,0.210
121.28,71.67,0.210
121.30,71.85,0.210
121.32,72.04,0.210
121.34,72.22,0.210
121.36,72.40,0.210
121.38,72.59,0.210
121.39,72.77,0.211
121.41,72.95,0.211
121.43,73.14,0.211
121.45,73.32,0.211
121.47,73.50,0.211
121.49,73.69,0.211
121.50,73.87,0.211
121.52,74.05,0.211
121.54,74.24,0.212
121.56,74.42,0.212
121.58,74.60,0.212
121.60,74.79,0.212
121.61,74.97,0.212
121.63,75.15,0.212
121.65,75.34,0.212
121.67,75.52,0.212
121.69,75.70,0.213
121.70,75.89,0.213
121.72,76.07,0.213
121.74,76.25,0.213
121.76,76.44,0.213
121.78,76.62,0.213
121.80,76.80,0.213
121.81,76.99,0.213
121.83,77.17,0.213
121.85,77.36,0.214
121.87,77.54,0.214
121.89,77.72,0.214
121.91,77.91,0.214
121.93,78.09,0.214
121.94,78.27,0.214
121.96,78.46,0.214
121.98,78.64,0.214
122.00,78.82,0.214
122.02,79.01,0.215
122.04,79.19,0.215
122.05,79.37,0.215
122.07,79.56,0.215
122.09,79.74,0.215
122.11,79.92,0.215
122.13,80.11,0.215
122.15,80.29,0.215
122.16,80.47,0.215
122.18,80.66,0.216
122.20,80.84,0.216
122.22,81.02,0.216
122.24,81.21,0.216
122.25,81.39,0.216
122.27,81.57,0.216
122.29,81.76,0.216
122.31,81.94,0.216
122.33,82.12,0.216
122.35,82.31,0.217
122.36,82.49,0.217
122.38,82.67,0.217
122.40,82.86,0.217
122.42,83.04,0.217
122.44,83.22,0.217
122.46,83.41,0.217
122.48,83.59,0.217
122.49,83.78,0.218
122.51,83.96,0.218
122.53,84.14,0.218
122.55,84.33,0.218
122.57,84.51,0.218
122.59,84.69,0.218
122.60,84.88,0.218
122.62,85.06,0.218
122.64,85.24,0.218
122.66,85.43,0.218
122.68,85.61,0.219
122.70,85.79,0.219
122.71,85.98,0.219
122.73,86.16,0.219
122.75,86.34,0.219
122.77,86.53,0.219
122.79,86.71,0.219
122.80,86.89,0.219
122.82,87.08,0.219
122.84,87.26,0.220
122.86,87.44,0.220
122.88,87.63,0.220
122.90,87.81,0.220
122.91,87.99,0.220
122.93,88.18,0.220
122.95,88.36,0.220
122.97,88.54,0.220
122.99,88.73,0.220
123.01,88.91,0.221
123.03,89.09,0.221
123.04,89.28,0.221
123.06,89.46,0.221
123.08,89.65,0.221
123.10,89.83,0.221
123.12,90.01,0.221
123.14,90.20,0.221
123.15,90.38,0.221
123.17,90.56,0.222
123.19,90.75,0.222
123.21,90.93,0.222
123.23,91.11,0.222
123.25,91.30,0.222
123.26,91.48,0.222
123.28,91.66,0.222
123.30,91.85,0.222
123.32,92.03,0.223
123.34,92.21,0.223
123.35,92.40,0.223
123.37,92.58,0.223
123.39,92.76,0.223
123.41,92.95,0.223
123.43,93.13,0.223
123.45,93.31,0.223
123.46,93.50,0.223
123.48,93.68,0.224
123.50,93.86,0.224
123.52,94.05,0.224
123.54,94.23,0.224
123.56,94.41,0.224
123.58,94.60,0.224
123.59,94.78,0.224
123.61,94.96,0.224
123.63,95.15,0.224
123.65,95.33,0.224
123.67,95.52,0.225
123.69,95.70,0.225
123.70,95.88,0.225
123.72,96.07,0.225
123.74,96.25,0.225
123.76,96.43,0.225
123.78,96.62,0.225
123.80,96.80,0.225
123.81,96.98,0.226
123.83,97.17,0.226
123.85,97.35,0.226
123.87,97.53,0.226
123.89,97.72,0.226
123.90,97.90,0.226
123.92,98.08,0.226
123.94,98.27,0.226
123.96,98.45,0.226
123.98,98.63,0.227
124.00,98.82,0.227
124.01,99.00,0.227
124.03,99.18,0.227
124.05,99.37,0.227
124.07,99.55,0.227
124.09,99.73,0.227
124.11,99.92,0.227
124.13,100.10,0.227
124.14,100.28,0.227
124.16,100.47,0.228
124.18,100.65,0.228
124.20,100.83,0.228
124.22,101.02,0.228
124.24,101.20,0.228
124.25,101.39,0.228
124.27,101.57,0.228
124.29,101.75,0.228
124.31,101.93,0.228
124.33,102.12,0.229
124.35,102.30,0.229
124.36,102.49,0.229
124.38,102.67,0.229
124.40,102.85,0.229
124.42,103.04,0.229
124.44,103.22,0.229
124.45,103.40,0.229
124.47,103.59,0.229
124.49,103.77,0.229
124.51,103.95,0.229
124.53,104.14,0.230
124.55,104.32,0.230
124.56,104.50,0.230
124.58,104.69,0.230
124.60,104.87,0.230
124.62,105.05,0.230
124.64,105.24,0.230
124.66,105.42,0.230
124.68,105.60,0.230
124.69,105.79,0.230
124.71,105.97,0.230
124.73,106.15,0.231
124.75,106.34,0.231
124.77,106.52,0.231
124.79,106.70,0.231
124.80,106.89,0.231
124.82,107.07,0.231
124.84,107.25,0.231
124.86,107.44,0.231
124.88,107.62,0.231
124.90,107.80,0.231
124.91,107.99,0.232
124.93,108.17,0.232
124.95,108.35,0.232
124.97,108.54,0.232
124.99,108.72,0.232
125.00,108.90,0.232
125.02,109.09,0.232
125.04,109.27,0.232
125.06,109.46,0.232
125.08,109.64,0.232
125.10,109.82,0.232
125.11,110.01,0.233
125.13,110.19,0.233
125.15,110.37,0.233
125.17,110.56,0.233
125.19,110.74,0.233
125.21,110.92,0.233
125.23,111.11,0.233
125.24,111.29,0.233
125.26,111.47,0.233
125.28,111.66,0.233
125.30,111.84,0.234
125.32,112.02,0.234
125.34,112.21,0.234
125.35,112.39,0.234
125.37,112.57,0.234
125.39,112.76,0.234
125.41,112.94,0.234
125.43,113.12,0.234
125.45,113.31,0.234
125.46,113.49,0.234
125.48,113.68,0.234
125.50,113.86,0.235
125.52,114.04,0.235
125.54,114.23,0.235
125.55,114.41,0.235
125.57,114.59,0.235
125.59,114.78,0.235
125.61,114.96,0.235
125.63,115.14,0.235
125.65,115.33,0.235
125.66,115.51,0.235
125.68,115.69,0.235
125.70,115.88,0.235
125.72,116.06,0.236
125.74,116.24,0.236
125.76,116.43,0.236
125.78,116.61,0.236
125.79,116.80,0.236
125.81,116.98,0.236
125.83,117.16,0.236
125.85,117.34,0.236
125.87,117.53,0.236
125.89,117.71,0.236
125.90,117.89,0.236
125.92,118.08,0.236
125.94,118.26,0.237
125.96,118.44,0.237
125.98,118.63,0.237
126.00,118.81,0.237
126.01,119.00,0.237
126.03,119.18,0.237
126.05,119.36,0.237
126.07,119.55,0.237
126.09,119.73,0.237
126.10,119.91,0.237
126.12,120.10,0.237
126.14,120.28,0.238
126.16,120.46,0.238
126.18,120.65,0.238
126.20,120.83,0.238
126.21,121.01,0.238
126.23,121.20,0.238
126.25,121.38,0.238
126.27,121.56,0.238
126.29,121.75,0.238
126.31,121.93,0.238
126.33,122.11,0.238
126.34,122.30,0.239
126.36,122.48,0.239
126.38,122.66,0.239
126.40,122.85,0.239
126.42,123.03,0.239
126.44,123.21,0.239
126.45,123.40,0.239
126.47,123.58,0.239
126.49,123.76,0.239
126.51,123.95,0.239
126.53,124.13,0.239
126.55,124.31,0.240
126.56,124.50,0.240
126.58,124.68,0.240
126.60,124.86,0.240
126.62,125.05,0.240
126.64,125.23,0.240
126.65,125.41,0.240
126.67,125.60,0.240
126.69,125.78,0.240
126.71,125.96,0.240
126.73,126.15,0.241
126.75,126.33,0.241
126.76,126.52,0.241
126.78,126.70,0.241
126.80,126.88,0.241
126.82,127.07,0.241
126.84,127.25,0.241
126.86,127.43,0.241
126.88,127.62,0.241
126.89,127.80,0.241
126.91,127.98,0.242
126.93,128.17,0.242
126.95,128.35,0.242
126.97,128.53,0.242
126.99,128.72,0.242
127.00,128.90,0.242
127.02,129.09,0.242
127.04,129.27,0.242
127.06,129.45,0.242
127.08,129.63,0.242
127.10,129.82,0.243
127.11,130.00,0.243
127.13,130.18,0.243
127.15,130.37,0.243
127.17,130.55,0.243
127.19,130.74,0.243
127.20,130.92,0.243
127.22,131.10,0.243
127.24,131.28,0.243
127.26,131.47,0.243
127.28,131.65,0.244
127.30,131.83,0.244
127.31,132.02,0.244
127.33,132.20,0.244
127.35,132.38,0.244
127.37,132.57,0.244
127.39,132.75,0.244
127.41,132.93,0.244
127.43,133.12,0.244
127.44,133.30,0.245
127.46,133.49,0.245
127.48,133.67,0.245
127.50,133.85,0.245
127.52,134.04,0.245
127.54,134.22,0.245
127.55,134.40,0.245
127.57,134.58,0.245
127.59,134.77,0.245
127.61,134.95,0.245
127.63,135.14,0.246
127.65,135.32,0.246
127.66,135.50,0.246
127.68,135.69,0.246
127.70,135.87,0.246
127.72,136.05,0.246
127.74,136.24,0.246
127.75,136.42,0.246
127.77,136.60,0.246
127.79,136.79,0.246
127.81,136.97,0.247
127.83,137.15,0.247
127.85,137.34,0.247
127.86,137.52,0.247
127.88,137.70,0.247
127.90,137.89,0.247
127.92,138.07,0.247
127.94,138.25,0.247
127.96,138.44,0.247
127.98,138.62,0.248
127.99,138.80,0.248
128.01,138.99,0.248
128.03,139.17,0.248
128.05,139.35,0.248
128.07,139.54,0.248
128.09,139.72,0.248
128.10,139.90,0.248
128.12,140.09,0.248
128.14,140.27,0.249
128.16,140.45,0.249
128.18,140.64,0.249
128.20,140.82,0.249
128.21,141.00,0.249
128.23,141.19,0.249
128.25,141.37,0.249
128.27,141.55,0.249
128.29,141.74,0.249
128.30,141.92,0.250
128.32,142.10,0.250
128.34,142.29,0.250
128.36,142.47,0.250
128.38,142.66,0.250
128.40,142.84,0.250
128.41,143.02,0.250
128.43,143.21,0.250
128.45,143.39,0.251
128.47,143.57,0.251
128.49,143.76,0.251
128.51,143.94,0.251
128.53,144.12,0.251
128.54,144.31,0.251
128.56,144.49,0.251
128.58,144.67,0.251
128.60,144.86,0.251
128.62,145.04,0.252
128.64,145.22,0.252
128.65,145.41,0.252
128.67,145.59,0.252
128.69,145.77,0.252
128.71,145.96,0.252
128.73,146.14,0.252
128.75,146.32,0.252
128.76,146.51,0.253
128.78,146.69,0.253
128.80,146.87,0.253
128.82,147.06,0.253
128.84,147.24,0.253
128.85,147.42,0.253
128.87,147.61,0.253
128.89,147.79,0.253
128.91,147.97,0.254
128.93,148.16,0.254
128.95,148.34,0.254
128.96,148.52,0.254
128.98,148.71,0.254
129.00,148.89,0.254
129.02,149.07,0.254
129.04,149.26,0.254
129.06,149.44,0.255
129.08,149.62,0.255
129.09,149.81,0.255
129.11,149.99,0.255
129.13,150.17,0.255
129.15,150.36,0.255
129.17,150.54,0.255
129.19,150.72,0.255
129.20,150.91,0.256
129.22,151.09,0.256
129.24,151.28,0.256
129.26,151.46,0.256
129.28,151.64,0.256
129.30,151.83,0.256
129.31,152.01,0.257
129.33,152.19,0.257
129.35,152.38,0.257
129.37,152.56,0.257
129.39,152.74,0.257
129.40,152.93,0.257
129.42,153.11,0.257
129.44,153.29,0.258
129.46,153.48,0.258
129.48,153.66,0.258
129.50,153.84,0.258
129.51,154.03,0.258
129.53,154.21,0.258
129.55,154.39,0.258
129.57,154.58,0.258
129.59,154.76,0.258
129.61,154.94,0.259
129.63,155.13,0.259
129.64,155.31,0.259
129.66,155.49,0.259
129.68,155.68,0.259
129.70,155.86,0.259
129.72,156.04,0.259
129.74,156.23,0.260
129.75,156.41,0.260
129.77,156.59,0.260
129.79,156.78,0.260
129.81,156.96,0.260
129.83,157.14,0.260
129.85,157.33,0.261
129.86,157.51,0.261
129.88,157.69,0.261
129.90,157.88,0.261
129.92,158.06,0.261
129.94,158.24,0.261
129.95,158.43,0.261
129.97,158.61,0.262
129.99,158.79,0.262
130.01,158.98,0.262
130.03,159.16,0.262
130.05,159.34,0.262
130.06,159.53,0.262
130.08,159.71,0.263
130.10,159.89,0.263
130.12,160.08,0.263
130.14,160.26,0.263
130.16,160.44,0.263
130.18,160.63,0.264
130.19,160.81,0.264
130.21,160.99,0.264
130.23,161.18,0.264
130.25,161.36,0.264
130.27,161.54,0.265
130.29,161.73,0.265
130.30,161.91,0.265
130.32,162.09,0.265
130.34,162.28,0.265
130.36,162.46,0.266
130.38,162.64,0.266
130.40,162.83,0.266
130.41,163.01,0.266
130.43,163.19,0.266
130.45,163.38,0.267
130.47,163.56,0.267
130.49,163.74,0.267
130.50,163.93,0.268
130.52,164.11,0.268
130.54,164.29,0.268
130.56,164.48,0.268
130.58,164.66,0.269
130.60,164.84,0.269
130.61,165.03,0.269
130.63,165.21,0.269
130.65,165.39,0.270
130.67,165.58,0.270
130.69,165.76,0.271
130.71,165.94,0.271
130.73,166.13,0.271
130.74,166.31,0.272
130.76,166.49,0.272
130.78,166.68,0.272
130.80,166.86,0.273
130.82,167.04,0.273
130.84,167.22,0.273
130.85,167.41,0.274
130.87,167.59,0.274
130.89,167.77,0.274
130.91,167.96,0.275
130.93,168.14,0.275
130.95,168.32,0.276
130.96,168.51,0.276
130.98,168.69,0.277
131.00,168.87,0.278
131.02,169.05,0.278
131.04,169.24,0.279
131.05,169.42,0.280
131.07,169.61,0.281
131.09,169.79,0.282
131.11,169.97,0.282
131.13,170.15,0.283
131.15,170.34,0.284
131.16,170.52,0.284
131.18,170.71,0.285
131.20,170.89,0.286
131.22,171.07,0.286
131.24,171.25,0.287
131.26,171.44,0.288
131.28,171.62,0.289
131.29,171.80,0.289
131.31,171.98,0.290
131.33,172.17,0.291
131.35,172.35,0.292
131.37,172.53,0.293
131.39,172.72,0.294
131.40,172.90,0.296
131.42,173.08,0.297
131.44,173.26,0.298
131.46,173.45,0.299
131.48,173.63,0.300
131.50,173.81,0.301
131.51,173.99,0.302
131.53,174.18,0.303
131.55,174.36,0.304
131.57,174.54,0.305
131.59,174.73,0.306
131.60,174.91,0.308
131.62,175.09,0.309
131.64,175.28,0.310
131.66,175.46,0.311
131.68,175.64,0.312
131.70,175.82,0.313
131.71,176.01,0.314
131.73,176.19,0.315
131.75,176.37,0.315
131.77,176.55,0.316
131.79,176.74,0.317
131.81,176.92,0.317
131.83,177.10,0.318
131.84,177.29,0.319
131.86,177.47,0.319
131.88,177.65,0.319
131.90,177.83,0.320
131.92,178.02,0.320
131.94,178.20,0.320
131.95,178.38,0.321
131.97,178.57,0.321
131.99,178.75,0.321
132.01,178.93,0.321
132.03,179.12,0.321
132.05,179.30,0.321
132.06,179.48,0.321
132.08,179.67,0.322
132.10,179.85,0.322
132.12,180.04,0.322
132.14,180.22,0.322
132.15,180.40,0.322
132.17,180.59,0.322
132.19,180.77,0.322
132.21,180.95,0.322
132.23,181.14,0.321
132.25,181.32,0.321
132.26,181.50,0.321
132.28,181.69,0.321
132.30,181.87,0.321
132.32,182.06,0.321
132.34,182.24,0.321
132.36,182.42,0.320
132.38,182.61,0.320
132.39,182.79,0.320
132.41,182.97,0.320
132.43,183.16,0.320
132.45,183.34,0.320
132.47,183.52,0.319
132.49,183.71,0.319
132.50,183.89,0.319
132.52,184.08,0.319
132.54,184.26,0.319
132.56,184.44,0.319
132.58,184.63,0.319
132.60,184.81,0.319
132.61,184.99,0.319
132.63,185.18,0.319
132.65,185.36,0.319
132.67,185.54,0.318
132.69,185.73,0.318
132.70,185.91,0.318
132.72,186.09,0.318
132.74,186.28,0.318
132.76,186.46,0.318
132.78,186.64,0.318
132.80,186.83,0.318
132.81,187.01,0.318
132.83,187.19,0.318
132.85,187.38,0.318
132.87,187.56,0.318
132.89,187.74,0.318
132.91,187.93,0.318
132.93,188.11,0.318
132.94,188.30,0.318
132.96,188.48,0.318
132.98,188.66,0.318
133.00,188.85,0.318
133.02,189.03,0.318
133.04,189.21,0.318
133.05,189.40,0.318
133.07,189.58,0.318
133.09,189.76,0.318
133.11,189.95,0.318
133.13,190.13,0.318
133.15,190.31,0.318
133.16,190.50,0.318
133.18,190.68,0.318
133.20,190.86,0.318
133.22,191.05,0.318
133.24,191.23,0.319
133.25,191.41,0.319
133.27,191.60,0.319
133.29,191.78,0.319
133.31,191.96,0.319
133.33,192.15,0.319
133.35,192.33,0.319
133.36,192.51,0.319
133.38,192.70,0.319
133.40,192.88,0.319
133.42,193.06,0.319
133.44,193.25,0.319
133.46,193.43,0.319
133.48,193.61,0.320
133.49,193.80,0.320
133.51,193.98,0.320
133.53,194.17,0.320
133.55,194.35,0.320
133.57,194.53,0.320
133.59,194.72,0.320
133.60,194.90,0.320
133.62,195.08,0.320
133.64,195.27,0.320
133.66,195.45,0.320
133.68,195.63,0.320
133.70,195.82,0.320
133.71,196.00,0.320
133.73,196.18,0.321
133.75,196.37,0.321
133.77,196.55,0.321
133.79,196.73,0.321
133.80,196.92,0.321
133.82,197.10,0.321
133.84,197.28,0.321
133.86,197.47,0.321
133.88,197.65,0.321
133.90,197.83,0.321
133.91,198.02,0.321
133.93,198.20,
133.95,198.38,
133.97,198.57,
133.99,,