File: DSC/2025_04_13_CBN_Pro_Slurry_Heptane_n60C_200C_10Cmin_x3.csv
Filename,2025_04_13_CBN_Pro_Slurry_Heptane_n60C_200C_10Cmin_x3
Instrument name,DSC2A-00468 (192.168.1.100)
Operator,Yarger
rundate,4/13/2025
Sample name,2025_04_13_CBN_Pro_Slurry_Heptane_n60C_200C_10Cmin_x3
proceduresegments,Data Off ; Equilibrate -60.00 °C; Data On ; Ramp 10.00 °C/min to 200.00 °C; Data Off ; Isothermal 1.0 min; Data On ; Ramp 10.00 °C/min to -60.00 °C; Data Off ; Isothermal 1.0 min; Data On ; Ramp 10.00 °C/min to 200.00 °C; Data Off ; Isothermal 1.0 min; Data On ; Ramp 10.00 °C/min to -60.00 °C; Data Off ; Isothermal 1.0 min; Data On ; Ramp 10.00 °C/min to 200.00 °C
[File Parameters]
Run date,4/13/2025 10:20:26 AM
Trios version,5.1.1.46572
Original File Name,
Current File Name,D:\DSC2500\JYarger\2025_04_13_CBN_Pro_Slurry_Heptane_n60C_200C_10Cmin_x3.tri
[Procedure]
Procedure Name,CBN_Pro_n60_200C_10Cmin_x3
Sample Name,2025_04_13_CBN_Pro_Slurry_Heptane_n60C_200C_10Cmin_x3
Sample Mass,9.53 mg
Reference Sample Mass,0 mg
Pan Mass,53.4 mg
Pan Number,26
Reference Pan Mass,53.32 mg
Reference Pan Number,10
Pan Type,Tzero Aluminum Hermetic
Comments,Hermetic Sealed Al DSC Consumables Pan/Lids.
Project Name,CA
Operator,Yarger
Test,Custom
Unload Max Temperature,30
Unload Min Temperature,30
Load Max Temperature,30
Load Min Temperature,30
Stop on Gas Flow Error,Yes
[Signal List]
Signal #1,Time (min)
Signal #2,Temperature (°C)
Signal #3,Heat Flow (mW)
Signal #4,Delta T (µV)
Signal #5,Delta Tzero (µV)
Signal #6,Tzero Temperature (°C)
Signal #7,Cell Purge (mL/min)
Signal #8,Heater Temp (°C)
Signal #9,Power Delivered (W)
Signal #10,Reference Junction Temperature (°C)
Signal #11,Flange Temperature (°C)
Signal #12,Heat Flow Phase (rad)
Signal #13,Total Heat Capacity (J/°C)
Signal #14,Heat Capacity (J/°C)
[Configuration]
Company Name,ASU
Instrument Name,DSC2A-00468
Instrument Type,DSC2500
Serial Number,DSC2A-00468
IP,192.168.1.100
Location of Instrument,MRRC
DisplayType,Unknown
Sample Interval ,0.1 s/pt
Selected Heat Flow,T4P
Exotherm Direction,Down
Cell Serial,DRC2-00792
Lid Type,Standard
Cooler,RCS 90
Leave Cooler on at End of Sequence,On
Gas 2,Nitrogen
Gas Selected,Channel 1
Flow Rate,50 mL/min
Secondary Purge,On
Licensed Heat Flow,Heat Flow T4P
Modulation Licensed,Yes
[Versions]
Common IDD Version,1
Cortex Version,VER 2.10.2.31
Driver,5.0.0.6
GDM Version,1.0.3.3
TouchscreenVersion,1.0.0.16145
FEP Version,1.2.1.21
FEP Bootloader,2.0.0.5
AutoSampler Version,2.1.1.26
Auto Sampler Bootloader,2.0.0.5
FCM Version,1.1.0.3
FCM Bootloader,2.0.0.5
[Experiment Logs]
Experiment Log Entry # 1,Air Cool is off.
Experiment Log Entry # 3,Data On set to 0
Experiment Log Entry # 5,Equilibrate Segment -60 (C) Started
Experiment Log Entry # 7,Data On set to 1
Experiment Log Entry # 9,Ramp Segment 10 C/min to 200 Started
Experiment Log Entry # 11,Data On set to 0
Experiment Log Entry # 13,Isothermal Segment 1 min started
Experiment Log Entry # 15,Data On set to 1
Experiment Log Entry # 17,Ramp Segment 10 C/min to -60 Started
Experiment Log Entry # 19,Data On set to 0
Experiment Log Entry # 21,Isothermal Segment 1 min started
Experiment Log Entry # 23,Data On set to 1
Experiment Log Entry # 25,Ramp Segment 10 C/min to 200 Started
Experiment Log Entry # 27,Data On set to 0
Experiment Log Entry # 29,Isothermal Segment 1 min started
Experiment Log Entry # 31,Data On set to 1
Experiment Log Entry # 33,Ramp Segment 10 C/min to -60 Started
Experiment Log Entry # 35,Data On set to 0
Experiment Log Entry # 37,Isothermal Segment 1 min started
Experiment Log Entry # 39,Data On set to 1
Experiment Log Entry # 41,Ramp Segment 10 C/min to 200 Started
[Method Log]
Method Log Entry # 1,Data Off
Method Log Entry # 2,Equilibrate -60 °C
Method Log Entry # 3,Data On
Method Log Entry # 4,(Ramp 401559) Ramp 10 °C/minute to 200 °C
Method Log Entry # 5,Data Off
Method Log Entry # 6,Isothermal 1 minutes
Method Log Entry # 7,Data On
Method Log Entry # 8,(Ramp 401563) Ramp 10 °C/minute to -60 °C
Method Log Entry # 9,Data Off
Method Log Entry # 10,Isothermal 1 minutes
Method Log Entry # 11,Data On
Method Log Entry # 12,(Ramp 401567) Ramp 10 °C/minute to 200 °C
Method Log Entry # 13,Data Off
Method Log Entry # 14,Isothermal 1 minutes
Method Log Entry # 15,Data On
Method Log Entry # 16,(Ramp 401571) Ramp 10 °C/minute to -60 °C
Method Log Entry # 17,Data Off
Method Log Entry # 18,Isothermal 1 minutes
Method Log Entry # 19,Data On
Method Log Entry # 20,(Ramp 401575) Ramp 10 °C/minute to 200 °C
Cell Serial,DRC2-00792
[T1 Calibration]
Slope,-0.008529666
Offset,9.636258
Initial Temperature,98.23
GUID,f8bfdadc-4977-4fdf-ba6d-0ba9134940c3
[TZero Calibration]
Date Applied,11/29/2022 4:06:13 PM
Description,From -89.059 °C to 396.009 °C at 20.000°C/min
Gas Type,Nitrogen
Pan Type,None
Source Files 1,C:\Users\yargerlab\Desktop\DSC Data\General\TZero_calibration_11_29_22_2nd(2).tri
Source Files 2,C:\Users\yargerlab\Desktop\DSC Data\General\TZero_calibration_11_29_22_2nd(3).tri
Delta T Offset,13.05235
Delta T Slope,-0.007271007
Delta T0 Offset,-13.69128
Delta T0 Slope,0.06063341
[Temperature Calibration]
Date Applied,11/29/2022 7:12:28 PM
Description,From 106.590 °C to 186.590 °C at 10.000°C/min
Gas Type,Nitrogen
Pan Type,Tzero Aluminum Hermetic
Source Files 1,C:\Users\yargerlab\Desktop\DSC Data\General\Indium(6).tri
Measured 1,157.391
Known 1,156.598
[Cell Constant Calibration]
Date Applied,11/29/2022 7:12:29 PM
Description,From 106.590 °C to 186.590 °C at 10.000°C/min
Gas Type,Nitrogen
Pan Type,Tzero Aluminum Hermetic
Source Files 1,C:\Users\yargerlab\Desktop\DSC Data\General\Indium(6).tri
T4P KCell,1.006051
Onset Slope,63.26126 mW/°C
[Direct Cp Calibration]
Date Applied,11/30/2022 11:04:51 AM
Description,From -79.983 °C to 298.409 °C at 10.000°C/min
Gas Type,Nitrogen
Pan Type,Tzero Aluminum Hermetic
Source Files 1,C:\Users\yargerlab\Desktop\DSC Data\General\Sapphire_Heat_Capacity_11_30_22.tri
[Rev Cp Calibration]
Date Applied,11/30/2022 1:58:51 PM
Description,From -79.996 °C to 292.812 °C at 3.000°C/min
Gas Type,Nitrogen
Pan Type,Tzero Aluminum Hermetic
Source Files 1,C:\Users\yargerlab\Desktop\DSC Data\General\Sapphire_MDSC_Calibration_11_30_22.tri
[step]
Ramp 10.00 °C/min to 200.00 °C
Time,Temperature,Heat Flow (Normalized)
min,°C,W/g
0.00,-59.66,-0.054
0.02,-59.67,-0.052
0.04,-59.68,-0.047
0.05,-59.68,-0.041
0.07,-59.67,-0.035
0.09,-59.64,-0.029
0.11,-59.59,-0.020
0.13,-59.52,-0.009
0.15,-59.43,0.004
0.16,-59.33,0.018
0.18,-59.21,0.033
0.20,-59.09,0.048
0.22,-58.95,0.063
0.24,-58.81,0.076
0.26,-58.66,0.088
0.28,-58.51,0.100
0.29,-58.35,0.110
0.31,-58.19,0.120
0.33,-58.03,0.128
0.35,-57.87,0.136
0.37,-57.70,0.141
0.39,-57.53,0.147
0.40,-57.37,0.152
0.42,-57.20,0.156
0.44,-57.03,0.160
0.46,-56.86,0.163
0.48,-56.68,0.166
0.50,-56.51,0.169
0.51,-56.34,0.171
0.53,-56.16,0.174
0.55,-55.98,0.175
0.57,-55.81,0.177
0.59,-55.63,0.178
0.60,-55.46,0.180
0.62,-55.28,0.181
0.64,-55.10,0.181
0.66,-54.92,0.183
0.68,-54.75,0.183
0.70,-54.57,0.184
0.72,-54.39,0.184
0.73,-54.21,0.185
0.75,-54.03,0.185
0.77,-53.85,0.186
0.79,-53.67,0.186
0.81,-53.49,0.187
0.83,-53.31,0.187
0.84,-53.13,0.187
0.86,-52.95,0.188
0.88,-52.77,0.188
0.90,-52.59,0.188
0.92,-52.41,0.188
0.93,-52.23,0.189
0.95,-52.05,0.189
0.97,-51.87,0.189
0.99,-51.69,0.189
1.01,-51.50,0.190
1.03,-51.32,0.190
1.05,-51.14,0.190
1.06,-50.96,0.190
1.08,-50.78,0.190
1.10,-50.60,0.191
1.12,-50.41,0.191
1.14,-50.23,0.191
1.16,-50.05,0.191
1.17,-49.87,0.192
1.19,-49.69,0.192
1.21,-49.50,0.192
1.23,-49.32,0.192
1.25,-49.14,0.192
1.27,-48.96,0.193
1.28,-48.77,0.193
1.30,-48.59,0.193
1.32,-48.41,0.193
1.34,-48.23,0.193
1.36,-48.04,0.194
1.38,-47.86,0.194
1.39,-47.68,0.194
1.41,-47.50,0.194
1.43,-47.31,0.194
1.45,-47.13,0.194
1.47,-46.95,0.194
1.48,-46.76,0.195
1.50,-46.58,0.195
1.52,-46.40,0.195
1.54,-46.22,0.195
1.56,-46.03,0.195
1.58,-45.85,0.195
1.59,-45.67,0.195
1.61,-45.48,0.196
1.63,-45.30,0.196
1.65,-45.12,0.196
1.67,-44.94,0.196
1.69,-44.75,0.196
1.71,-44.57,0.196
1.72,-44.39,0.196
1.74,-44.20,0.196
1.76,-44.02,0.197
1.78,-43.84,0.197
1.80,-43.65,0.197
1.82,-43.47,0.197
1.83,-43.29,0.197
1.85,-43.10,0.197
1.87,-42.92,0.197
1.89,-42.74,0.197
1.91,-42.55,0.197
1.93,-42.37,0.198
1.94,-42.19,0.198
1.96,-42.00,0.198
1.98,-41.82,0.198
2.00,-41.64,0.198
2.02,-41.45,0.198
2.03,-41.27,0.198
2.05,-41.09,0.198
2.07,-40.90,0.198
2.09,-40.72,0.198
2.11,-40.54,0.199
2.13,-40.35,0.199
2.14,-40.17,0.199
2.16,-39.99,0.199
2.18,-39.80,0.199
2.20,-39.62,0.199
2.22,-39.44,0.199
2.24,-39.25,0.199
2.26,-39.07,0.199
2.27,-38.89,0.200
2.29,-38.70,0.200
2.31,-38.52,0.200
2.33,-38.34,0.200
2.35,-38.15,0.200
2.36,-37.97,0.200
2.38,-37.79,0.200
2.40,-37.60,0.200
2.42,-37.42,0.200
2.44,-37.24,0.200
2.46,-37.05,0.200
2.48,-36.87,0.201
2.49,-36.68,0.201
2.51,-36.50,0.201
2.53,-36.32,0.201
2.55,-36.13,0.201
2.57,-35.95,0.201
2.59,-35.77,0.201
2.60,-35.58,0.201
2.62,-35.40,0.201
2.64,-35.21,0.201
2.66,-35.03,0.202
2.68,-34.85,0.202
2.69,-34.67,0.202
2.71,-34.48,0.202
2.73,-34.30,0.202
2.75,-34.11,0.202
2.77,-33.93,0.202
2.79,-33.75,0.202
2.81,-33.56,0.202
2.82,-33.38,0.202
2.84,-33.20,0.202
2.86,-33.01,0.203
2.88,-32.83,0.203
2.90,-32.65,0.203
2.91,-32.46,0.203
2.93,-32.28,0.203
2.95,-32.09,0.203
2.97,-31.91,0.203
2.99,-31.73,0.203
3.01,-31.54,0.203
3.03,-31.36,0.203
3.04,-31.18,0.204
3.06,-30.99,0.204
3.08,-30.81,0.204
3.10,-30.63,0.204
3.12,-30.44,0.204
3.14,-30.26,0.204
3.15,-30.08,0.204
3.17,-29.89,0.204
3.19,-29.71,0.204
3.21,-29.52,0.204
3.23,-29.34,0.204
3.24,-29.16,0.205
3.26,-28.97,0.205
3.28,-28.79,0.205
3.30,-28.61,0.205
3.32,-28.42,0.205
3.34,-28.24,0.205
3.36,-28.06,0.205
3.37,-27.87,0.205
3.39,-27.69,0.205
3.41,-27.50,0.205
3.43,-27.32,0.206
3.45,-27.14,0.206
3.46,-26.96,0.206
3.48,-26.77,0.206
3.50,-26.59,0.206
3.52,-26.40,0.206
3.54,-26.22,0.206
3.56,-26.04,0.206
3.58,-25.85,0.206
3.59,-25.67,0.206
3.61,-25.49,0.207
3.63,-25.30,0.207
3.65,-25.12,0.207
3.67,-24.94,0.207
3.69,-24.75,0.207
3.70,-24.57,0.207
3.72,-24.39,0.207
3.74,-24.20,0.207
3.76,-24.02,0.207
3.78,-23.83,0.207
3.79,-23.65,0.208
3.81,-23.47,0.208
3.83,-23.28,0.208
3.85,-23.10,0.208
3.87,-22.92,0.208
3.89,-22.73,0.208
3.91,-22.55,0.208
3.92,-22.37,0.208
3.94,-22.18,0.208
3.96,-22.00,0.209
3.98,-21.82,0.209
4.00,-21.63,0.209
4.01,-21.45,0.209
4.03,-21.27,0.209
4.05,-21.08,0.209
4.07,-20.90,0.209
4.09,-20.72,0.209
4.11,-20.53,0.210
4.13,-20.35,0.210
4.14,-20.17,0.210
4.16,-19.98,0.210
4.18,-19.80,0.210
4.20,-19.61,0.210
4.22,-19.43,0.210
4.24,-19.25,0.210
4.25,-19.06,0.210
4.27,-18.88,0.211
4.29,-18.70,0.211
4.31,-18.51,0.211
4.33,-18.33,0.211
4.35,-18.15,0.211
4.36,-17.96,0.211
4.38,-17.78,0.211
4.40,-17.60,0.211
4.42,-17.41,0.211
4.44,-17.23,0.212
4.45,-17.04,0.212
4.47,-16.86,0.212
4.49,-16.68,0.212
4.51,-16.49,0.212
4.53,-16.31,0.212
4.55,-16.13,0.212
4.56,-15.94,0.212
4.58,-15.76,0.212
4.60,-15.58,0.213
4.62,-15.39,0.213
4.64,-15.21,0.213
4.66,-15.03,0.213
4.68,-14.84,0.213
4.69,-14.66,0.213
4.71,-14.48,0.213
4.73,-14.29,0.213
4.75,-14.11,0.214
4.77,-13.93,0.214
4.79,-13.74,0.214
4.80,-13.56,0.214
4.82,-13.37,0.214
4.84,-13.19,0.214
4.86,-13.01,0.214
4.88,-12.82,0.214
4.90,-12.64,0.214
4.91,-12.46,0.215
4.93,-12.28,0.215
4.95,-12.09,0.215
4.97,-11.91,0.215
4.99,-11.72,0.215
5.00,-11.54,0.215
5.02,-11.36,0.215
5.04,-11.17,0.215
5.06,-10.99,0.215
5.08,-10.81,0.216
5.10,-10.62,0.216
5.11,-10.44,0.216
5.13,-10.26,0.216
5.15,-10.07,0.216
5.17,-9.89,0.216
5.19,-9.70,0.216
5.21,-9.52,0.217
5.23,-9.34,0.217
5.24,-9.15,0.217
5.26,-8.97,0.217
5.28,-8.79,0.217
5.30,-8.60,0.217
5.32,-8.42,0.217
5.34,-8.24,0.217
5.35,-8.05,0.218
5.37,-7.87,0.218
5.39,-7.69,0.218
5.41,-7.50,0.218
5.43,-7.32,0.218
5.45,-7.13,0.218
5.46,-6.95,0.218
5.48,-6.77,0.219
5.50,-6.58,0.219
5.52,-6.40,0.219
5.54,-6.22,0.219
5.55,-6.03,0.219
5.57,-5.85,0.219
5.59,-5.67,0.219
5.61,-5.48,0.220
5.63,-5.30,0.220
5.65,-5.12,0.220
5.66,-4.93,0.220
5.68,-4.75,0.220
5.70,-4.57,0.220
5.72,-4.38,0.220
5.74,-4.20,0.220
5.76,-4.02,0.221
5.78,-3.83,0.221
5.79,-3.65,0.221
5.81,-3.47,0.221
5.83,-3.28,0.221
5.85,-3.10,0.221
5.87,-2.91,0.221
5.89,-2.73,0.222
5.90,-2.55,0.222
5.92,-2.36,0.222
5.94,-2.18,0.222
5.96,-2.00,0.222
5.98,-1.81,0.222
6.00,-1.63,0.222
6.01,-1.45,0.222
6.03,-1.26,0.223
6.05,-1.08,0.223
6.07,-0.90,0.223
6.09,-0.71,0.223
6.10,-0.53,0.223
6.12,-0.34,0.223
6.14,-0.16,0.223
6.16,0.02,0.224
6.18,0.21,0.224
6.20,0.39,0.224
6.21,0.57,0.224
6.23,0.76,0.224
6.25,0.94,0.224
6.27,1.12,0.224
6.29,1.31,0.225
6.31,1.49,0.225
6.33,1.67,0.225
6.34,1.86,0.225
6.36,2.04,0.225
6.38,2.22,0.225
6.40,2.41,0.225
6.42,2.59,0.225
6.44,2.77,0.226
6.45,2.96,0.226
6.47,3.14,0.226
6.49,3.32,0.226
6.51,3.51,0.226
6.53,3.69,0.226
6.55,3.88,0.226
6.56,4.06,0.227
6.58,4.24,0.227
6.60,4.43,0.227
6.62,4.61,0.227
6.64,4.79,0.227
6.65,4.98,0.227
6.67,5.16,0.228
6.69,5.34,0.228
6.71,5.53,0.228
6.73,5.71,0.228
6.75,5.89,0.228
6.76,6.08,0.228
6.78,6.26,0.229
6.80,6.44,0.229
6.82,6.63,0.229
6.84,6.81,0.229
6.86,6.99,0.229
6.88,7.18,0.229
6.89,7.36,0.229
6.91,7.54,0.230
6.93,7.73,0.230
6.95,7.91,0.230
6.97,8.10,0.230
6.99,8.28,0.230
7.00,8.46,0.230
7.02,8.65,0.230
7.04,8.83,0.230
7.06,9.01,0.231
7.08,9.20,0.231
7.10,9.38,0.231
7.11,9.56,0.231
7.13,9.75,0.231
7.15,9.93,0.232
7.17,10.11,0.232
7.19,10.30,0.232
7.20,10.48,0.232
7.22,10.67,0.232
7.24,10.85,0.232
7.26,11.03,0.232
7.28,11.22,0.233
7.30,11.40,0.233
7.31,11.58,0.233
7.33,11.77,0.233
7.35,11.95,0.233
7.37,12.13,0.233
7.39,12.32,0.234
7.41,12.50,0.234
7.43,12.68,0.234
7.44,12.87,0.234
7.46,13.05,0.234
7.48,13.23,0.234
7.50,13.42,0.234
7.52,13.60,0.235
7.54,13.79,0.235
7.55,13.97,0.235
7.57,14.15,0.235
7.59,14.34,0.235
7.61,14.52,0.235
7.63,14.70,0.235
7.65,14.89,0.236
7.66,15.07,0.236
7.68,15.25,0.236
7.70,15.44,0.236
7.72,15.62,0.236
7.74,15.80,0.237
7.75,15.99,0.237
7.77,16.17,0.237
7.79,16.35,0.237
7.81,16.54,0.237
7.83,16.72,0.237
7.85,16.90,0.237
7.86,17.09,0.238
7.88,17.27,0.238
7.90,17.46,0.238
7.92,17.64,0.238
7.94,17.82,0.238
7.96,18.01,0.238
7.98,18.19,0.238
7.99,18.37,0.238
8.01,18.56,0.239
8.03,18.74,0.239
8.05,18.92,0.239
8.07,19.11,0.239
8.09,19.29,0.239
8.10,19.47,0.239
8.12,19.66,0.240
8.14,19.84,0.240
8.16,20.02,0.240
8.18,20.21,0.240
8.20,20.39,0.240
8.21,20.57,0.240
8.23,20.76,0.241
8.25,20.94,0.241
8.27,21.12,0.241
8.29,21.31,0.241
8.30,21.49,0.241
8.32,21.68,0.241
8.34,21.86,0.242
8.36,22.04,0.242
8.38,22.23,0.242
8.40,22.41,0.242
8.41,22.59,0.242
8.43,22.78,0.242
8.45,22.96,0.242
8.47,23.14,0.243
8.49,23.33,0.243
8.51,23.51,0.243
8.53,23.69,0.243
8.54,23.88,0.243
8.56,24.06,0.244
8.58,24.24,0.244
8.60,24.43,0.244
8.62,24.61,0.244
8.63,24.79,0.244
8.65,24.98,0.244
8.67,25.16,0.244
8.69,25.35,0.245
8.71,25.53,0.245
8.73,25.71,0.245
8.75,25.90,0.245
8.76,26.08,0.245
8.78,26.26,0.245
8.80,26.45,0.246
8.82,26.63,0.246
8.84,26.81,0.246
8.85,27.00,0.246
8.87,27.18,0.246
8.89,27.36,0.247
8.91,27.55,0.247
8.93,27.73,0.247
8.95,27.91,0.247
8.97,28.10,0.247
8.98,28.28,0.248
9.00,28.46,0.248
9.02,28.65,0.248
9.04,28.83,0.248
9.06,29.01,0.248
9.08,29.20,0.248
9.09,29.38,0.249
9.11,29.57,0.249
9.13,29.75,0.249
9.15,29.93,0.249
9.17,30.12,0.249
9.18,30.30,0.249
9.20,30.48,0.250
9.22,30.67,0.250
9.24,30.85,0.250
9.26,31.04,0.250
9.28,31.22,0.250
9.30,31.40,0.251
9.31,31.58,0.251
9.33,31.77,0.251
9.35,31.95,0.251
9.37,32.13,0.251
9.39,32.32,0.251
9.40,32.50,0.251
9.42,32.68,0.252
9.44,32.87,0.252
9.46,33.05,0.252
9.48,33.23,0.252
9.50,33.42,0.252
9.52,33.60,0.253
9.53,33.78,0.253
9.55,33.97,0.253
9.57,34.15,0.253
9.59,34.34,0.253
9.61,34.52,0.253
9.63,34.70,0.254
9.64,34.89,0.254
9.66,35.07,0.254
9.68,35.25,0.254
9.70,35.44,0.254
9.72,35.62,0.255
9.73,35.80,0.255
9.75,35.99,0.255
9.77,36.17,0.255
9.79,36.35,0.255
9.81,36.54,0.256
9.83,36.72,0.256
9.85,36.90,0.256
9.86,37.09,0.256
9.88,37.27,0.256
9.90,37.45,0.257
9.92,37.64,0.257
9.94,37.82,0.257
9.95,38.01,0.257
9.97,38.19,0.257
9.99,38.37,0.258
10.01,38.56,0.258
10.03,38.74,0.258
10.05,38.92,0.258
10.07,39.11,0.259
10.08,39.29,0.259
10.10,39.47,0.259
10.12,39.66,0.259
10.14,39.84,0.260
10.16,40.02,0.260
10.18,40.21,0.260
10.19,40.39,0.260
10.21,40.57,0.261
10.23,40.76,0.261
10.25,40.94,0.261
10.27,41.12,0.261
10.28,41.31,0.261
10.30,41.49,0.262
10.32,41.67,0.262
10.34,41.86,0.262
10.36,42.04,0.262
10.38,42.22,0.263
10.40,42.41,0.263
10.41,42.59,0.263
10.43,42.77,0.263
10.45,42.96,0.264
10.47,43.14,0.264
10.49,43.32,0.264
10.50,43.51,0.264
10.52,43.69,0.265
10.54,43.87,0.265
10.56,44.06,0.265
10.58,44.24,0.266
10.60,44.42,0.266
10.62,44.61,0.266
10.63,44.79,0.266
10.65,44.97,0.267
10.67,45.16,0.267
10.69,45.34,0.267
10.71,45.53,0.267
10.73,45.71,0.268
10.74,45.89,0.268
10.76,46.08,0.268
10.78,46.26,0.269
10.80,46.44,0.269
10.82,46.63,0.269
10.83,46.81,0.269
10.85,46.99,0.269
10.87,47.18,0.270
10.89,47.36,0.270
10.91,47.54,0.270
10.93,47.73,0.271
10.95,47.91,0.271
10.96,48.09,0.271
10.98,48.28,0.271
11.00,48.46,0.271
11.02,48.64,0.272
11.04,48.83,0.272
11.05,49.01,0.272
11.07,49.20,0.272
11.09,49.38,0.273
11.11,49.56,0.273
11.13,49.75,0.273
11.15,49.93,0.273
11.17,50.11,0.273
11.18,50.30,0.274
11.20,50.48,0.274
11.22,50.66,0.274
11.24,50.85,0.274
11.26,51.03,0.274
11.28,51.21,0.275
11.29,51.40,0.275
11.31,51.58,0.275
11.33,51.76,0.275
11.35,51.95,0.275
11.37,52.13,0.276
11.38,52.31,0.276
11.40,52.50,0.276
11.42,52.68,0.276
11.44,52.86,0.277
11.46,53.05,0.277
11.48,53.23,0.277
11.50,53.41,0.277
11.51,53.60,0.278
11.53,53.78,0.278
11.55,53.96,0.278
11.57,54.15,0.278
11.59,54.33,0.279
11.60,54.51,0.279
11.62,54.70,0.279
11.64,54.88,0.279
11.66,55.07,0.280
11.68,55.25,0.280
11.70,55.43,0.280
11.72,55.61,0.280
11.73,55.80,0.281
11.75,55.98,0.281
11.77,56.17,0.282
11.79,56.35,0.282
11.81,56.53,0.282
11.83,56.72,0.282
11.84,56.90,0.283
11.86,57.08,0.283
11.88,57.27,0.283
11.90,57.45,0.284
11.92,57.63,0.284
11.93,57.82,0.284
11.95,58.00,0.284
11.97,58.18,0.285
11.99,58.36,0.285
12.01,58.55,0.285
12.03,58.73,0.286
12.05,58.92,0.286
12.06,59.10,0.286
12.08,59.28,0.287
12.10,59.47,0.287
12.12,59.65,0.287
12.14,59.83,0.287
12.15,60.02,0.288
12.17,60.20,0.288
12.19,60.38,0.288
12.21,60.57,0.289
12.23,60.75,0.289
12.25,60.93,0.289
12.27,61.12,0.289
12.28,61.30,0.290
12.30,61.48,0.290
12.32,61.67,0.290
12.34,61.85,0.291
12.36,62.03,0.291
12.38,62.22,0.291
12.39,62.40,0.291
12.41,62.58,0.292
12.43,62.76,0.292
12.45,62.95,0.293
12.47,63.13,0.293
12.48,63.32,0.294
12.50,63.50,0.294
12.52,63.68,0.295
12.54,63.87,0.295
12.56,64.05,0.295
12.58,64.23,0.296
12.60,64.41,0.297
12.61,64.60,0.297
12.63,64.78,0.298
12.65,64.96,0.298
12.67,65.15,0.299
12.69,65.33,0.299
12.70,65.51,0.300
12.72,65.70,0.300
12.74,65.88,0.301
12.76,66.06,0.302
12.78,66.25,0.302
12.80,66.43,0.303
12.82,66.61,0.304
12.83,66.80,0.304
12.85,66.98,0.304
12.87,67.16,0.305
12.89,67.35,0.306
12.91,67.53,0.306
12.93,67.71,0.307
12.94,67.90,0.308
12.96,68.08,0.308
12.98,68.26,0.309
13.00,68.45,0.310
13.02,68.63,0.311
13.03,68.81,0.311
13.05,69.00,0.312
13.07,69.18,0.312
13.09,69.36,0.313
13.11,69.55,0.314
13.13,69.73,0.314
13.15,69.91,0.315
13.16,70.09,0.315
13.18,70.28,0.316
13.20,70.46,0.317
13.22,70.64,0.318
13.24,70.83,0.318
13.25,71.01,0.320
13.27,71.19,0.321
13.29,71.38,0.322
13.31,71.56,0.323
13.33,71.74,0.323
13.35,71.93,0.325
13.37,72.11,0.326
13.38,72.29,0.327
13.40,72.47,0.328
13.42,72.66,0.329
13.44,72.84,0.330
13.46,73.02,0.331
13.48,73.20,0.333
13.49,73.39,0.334
13.51,73.57,0.335
13.53,73.75,0.336
13.55,73.94,0.337
13.57,74.12,0.337
13.58,74.30,0.339
13.60,74.49,0.340
13.62,74.67,0.340
13.64,74.85,0.342
13.66,75.03,0.343
13.68,75.22,0.343
13.70,75.40,0.345
13.71,75.58,0.345
13.73,75.77,0.346
13.75,75.95,0.347
13.77,76.13,0.348
13.79,76.31,0.349
13.80,76.50,0.349
13.82,76.68,0.350
13.84,76.86,0.350
13.86,77.05,0.351
13.88,77.23,0.351
13.90,77.41,0.352
13.92,77.60,0.352
13.93,77.78,0.353
13.95,77.96,0.353
13.97,78.15,0.354
13.99,78.33,0.355
14.01,78.51,0.355
14.03,78.70,0.356
14.04,78.88,0.356
14.06,79.06,0.357
14.08,79.25,0.358
14.10,79.43,0.358
14.12,79.61,0.359
14.13,79.80,0.360
14.15,79.98,0.361
14.17,80.16,0.363
14.19,80.35,0.365
14.21,80.53,0.366
14.23,80.71,0.368
14.25,80.89,0.369
14.26,81.08,0.372
14.28,81.26,0.373
14.30,81.44,0.375
14.32,81.62,0.377
14.34,81.81,0.380
14.35,81.99,0.381
14.37,82.17,0.384
14.39,82.35,0.386
14.41,82.53,0.389
14.43,82.72,0.392
14.45,82.90,0.394
14.47,83.08,0.397
14.48,83.26,0.400
14.50,83.44,0.403
14.52,83.63,0.406
14.54,83.81,0.410
14.56,83.99,0.413
14.58,84.17,0.417
14.59,84.35,0.421
14.61,84.53,0.426
14.63,84.72,0.430
14.65,84.90,0.434
14.67,85.08,0.438
14.68,85.26,0.442
14.70,85.44,0.446
14.72,85.62,0.449
14.74,85.80,0.454
14.76,85.98,0.458
14.78,86.16,0.464
14.80,86.34,0.466
14.81,86.53,0.470
14.83,86.71,0.474
14.85,86.89,0.478
14.87,87.07,0.482
14.89,87.25,0.487
14.90,87.43,0.491
14.92,87.61,0.497
14.94,87.79,0.502
14.96,87.97,0.509
14.98,88.15,0.516
15.00,88.33,0.521
15.02,88.51,0.525
15.03,88.69,0.530
15.05,88.87,0.535
15.07,89.05,0.541
15.09,89.23,0.548
15.11,89.41,0.554
15.13,89.59,0.561
15.14,89.77,0.567
15.16,89.95,0.576
15.18,90.13,0.583
15.20,90.31,0.592
15.22,90.49,0.601
15.23,90.67,0.611
15.25,90.85,0.620
15.27,91.02,0.629
15.29,91.20,0.639
15.31,91.38,0.651
15.33,91.56,0.664
15.35,91.73,0.680
15.36,91.91,0.694
15.38,92.08,0.713
15.40,92.26,0.732
15.42,92.43,0.750
15.44,92.60,0.769
15.45,92.78,0.788
15.47,92.95,0.813
15.49,93.12,0.840
15.51,93.29,0.859
15.53,93.46,0.883
15.55,93.63,0.897
15.57,93.80,0.904
15.58,93.98,0.906
15.60,94.15,0.909
15.62,94.33,0.909
15.64,94.51,0.907
15.66,94.69,0.900
15.68,94.88,0.886
15.69,95.07,0.871
15.71,95.25,0.852
15.73,95.45,0.832
15.75,95.64,0.810
15.77,95.84,0.784
15.78,96.03,0.756
15.80,96.23,0.725
15.82,96.43,0.690
15.84,96.63,0.651
15.86,96.83,0.615
15.88,97.04,0.579
15.90,97.24,0.544
15.91,97.45,0.518
15.93,97.65,0.491
15.95,97.85,0.467
15.97,98.05,0.448
15.99,98.25,0.432
16.00,98.45,0.417
16.02,98.64,0.406
16.04,98.83,0.395
16.06,99.03,0.387
16.08,99.22,0.380
16.10,99.41,0.374
16.12,99.60,0.368
16.13,99.79,0.365
16.15,99.98,0.360
16.17,100.16,0.358
16.19,100.35,0.356
16.21,100.54,0.354
16.23,100.72,0.353
16.24,100.91,0.352
16.26,101.09,0.351
16.28,101.28,0.350
16.30,101.46,0.350
16.32,101.65,0.350
16.33,101.83,0.350
16.35,102.01,0.349
16.37,102.20,0.349
16.39,102.38,0.349
16.41,102.57,0.348
16.43,102.75,0.348
16.45,102.93,0.348
16.46,103.12,0.348
16.48,103.30,0.347
16.50,103.49,0.347
16.52,103.67,0.347
16.54,103.85,0.347
16.55,104.04,0.347
16.57,104.22,0.346
16.59,104.40,0.346
16.61,104.59,0.346
16.63,104.77,0.346
16.65,104.95,0.346
16.67,105.14,0.346
16.68,105.32,0.345
16.70,105.51,0.345
16.72,105.69,0.345
16.74,105.87,0.345
16.76,106.06,0.345
16.78,106.24,0.345
16.79,106.42,0.345
16.81,106.61,0.345
16.83,106.79,0.345
16.85,106.97,0.345
16.87,107.16,0.345
16.88,107.34,0.345
16.90,107.52,0.344
16.92,107.71,0.344
16.94,107.89,0.344
16.96,108.07,0.344
16.98,108.26,0.344
17.00,108.44,0.344
17.01,108.63,0.344
17.03,108.81,0.344
17.05,108.99,0.344
17.07,109.18,0.344
17.09,109.36,0.344
17.11,109.55,0.344
17.12,109.73,0.344
17.14,109.91,0.343
17.16,110.10,0.343
17.18,110.28,0.343
17.20,110.46,0.343
17.22,110.65,0.343
17.23,110.83,0.343
17.25,111.01,0.343
17.27,111.20,0.343
17.29,111.38,0.343
17.31,111.56,0.343
17.33,111.75,0.343
17.34,111.93,0.343
17.36,112.11,0.343
17.38,112.30,0.343
17.40,112.48,0.343
17.42,112.66,0.343
17.43,112.85,0.343
17.45,113.03,0.343
17.47,113.21,0.343
17.49,113.40,0.343
17.51,113.58,0.343
17.53,113.77,0.342
17.54,113.95,0.342
17.56,114.13,0.342
17.58,114.32,0.342
17.60,114.50,0.342
17.62,114.68,0.342
17.64,114.87,0.342
17.66,115.05,0.342
17.67,115.23,0.343
17.69,115.42,0.343
17.71,115.60,0.343
17.73,115.78,0.343
17.75,115.97,0.343
17.77,116.15,0.343
17.78,116.33,0.343
17.80,116.52,0.343
17.82,116.70,0.343
17.84,116.88,0.343
17.86,117.07,0.343
17.88,117.25,0.343
17.89,117.43,0.343
17.91,117.62,0.343
17.93,117.80,0.343
17.95,117.99,0.343
17.97,118.17,0.343
17.98,118.35,0.343
18.00,118.54,0.343
18.02,118.72,0.343
18.04,118.90,0.343
18.06,119.09,0.343
18.08,119.27,0.343
18.09,119.45,0.343
18.11,119.64,0.343
18.13,119.82,0.343
18.15,120.00,0.343
18.17,120.19,0.343
18.19,120.37,0.344
18.21,120.55,0.344
18.22,120.74,0.344
18.24,120.92,0.344
18.26,121.10,0.344
18.28,121.29,0.344
18.30,121.47,0.344
18.32,121.66,0.344
18.33,121.84,0.344
18.35,122.02,0.344
18.37,122.21,0.344
18.39,122.39,0.344
18.41,122.57,0.344
18.43,122.76,0.344
18.44,122.94,0.344
18.46,123.12,0.344
18.48,123.31,0.344
18.50,123.49,0.344
18.52,123.67,0.345
18.53,123.86,0.345
18.55,124.04,0.345
18.57,124.22,0.345
18.59,124.41,0.345
18.61,124.59,0.345
18.63,124.77,0.345
18.64,124.96,0.345
18.66,125.14,0.345
18.68,125.33,0.345
18.70,125.51,0.345
18.72,125.69,0.345
18.74,125.88,0.345
18.76,126.06,0.345
18.77,126.24,0.345
18.79,126.43,0.346
18.81,126.61,0.346
18.83,126.79,0.346
18.85,126.98,0.346
18.87,127.16,0.346
18.88,127.34,0.346
18.90,127.53,0.346
18.92,127.71,0.346
18.94,127.90,0.346
18.96,128.08,0.346
18.98,128.26,0.346
18.99,128.44,0.346
19.01,128.63,0.346
19.03,128.81,0.346
19.05,128.99,0.346
19.07,129.18,0.346
19.08,129.36,0.346
19.10,129.55,0.346
19.12,129.73,0.346
19.14,129.91,0.347
19.16,130.10,0.347
19.18,130.28,0.347
19.19,130.46,0.347
19.21,130.65,0.347
19.23,130.83,0.347
19.25,131.01,0.347
19.27,131.20,0.347
19.29,131.38,0.347
19.31,131.56,0.348
19.32,131.75,0.348
19.34,131.93,0.348
19.36,132.11,0.348
19.38,132.30,0.348
19.40,132.48,0.348
19.42,132.66,0.348
19.43,132.85,0.348
19.45,133.03,0.349
19.47,133.22,0.349
19.49,133.40,0.349
19.51,133.58,0.349
19.53,133.77,0.349
19.54,133.95,0.349
19.56,134.13,0.350
19.58,134.32,0.350
19.60,134.50,0.350
19.62,134.68,0.350
19.63,134.87,0.350
19.65,135.05,0.350
19.67,135.23,0.350
19.69,135.42,0.350
19.71,135.60,0.351
19.73,135.78,0.351
19.74,135.97,0.351
19.76,136.15,0.351
19.78,136.33,0.352
19.80,136.51,0.354
19.82,136.70,0.357
19.84,136.88,0.359
19.86,137.06,0.361
19.87,137.24,0.363
19.89,137.43,0.365
19.91,137.61,0.366
19.93,137.79,0.360
19.95,137.98,0.359
19.97,138.16,0.358
19.98,138.35,0.357
20.00,138.53,0.356
20.02,138.72,0.356
20.04,138.90,0.356
20.06,139.08,0.356
20.08,139.27,0.355
20.09,139.45,0.355
20.11,139.63,0.355
20.13,139.82,0.355
20.15,140.00,0.355
20.17,140.19,0.354
20.18,140.37,0.354
20.20,140.55,0.354
20.22,140.74,0.354
20.24,140.92,0.354
20.26,141.10,0.354
20.28,141.29,0.353
20.29,141.47,0.353
20.31,141.65,0.353
20.33,141.84,0.353
20.35,142.02,0.353
20.37,142.21,0.353
20.39,142.39,0.353
20.41,142.57,0.352
20.42,142.76,0.352
20.44,142.94,0.352
20.46,143.12,0.352
20.48,143.31,0.352
20.50,143.49,0.352
20.52,143.67,0.352
20.53,143.86,0.352
20.55,144.04,0.352
20.57,144.22,0.352
20.59,144.41,0.351
20.61,144.59,0.351
20.63,144.77,0.351
20.64,144.96,0.351
20.66,145.14,0.351
20.68,145.33,0.351
20.70,145.51,0.351
20.72,145.69,0.351
20.73,145.88,0.350
20.75,146.06,0.350
20.77,146.25,0.350
20.79,146.43,0.350
20.81,146.61,0.350
20.83,146.79,0.350
20.84,146.98,0.349
20.86,147.16,0.349
20.88,147.35,0.349
20.90,147.53,0.349
20.92,147.71,0.349
20.94,147.90,0.348
20.96,148.08,0.348
20.97,148.26,0.348
20.99,148.45,0.348
21.01,148.63,0.348
21.03,148.81,0.348
21.05,149.00,0.347
21.07,149.18,0.347
21.08,149.37,0.347
21.10,149.55,0.347
21.12,149.73,0.347
21.14,149.92,0.346
21.16,150.10,0.346
21.18,150.28,0.346
21.19,150.47,0.346
21.21,150.65,0.346
21.23,150.83,0.346
21.25,151.02,0.346
21.27,151.20,0.345
21.28,151.38,0.345
21.30,151.57,0.345
21.32,151.75,0.345
21.34,151.94,0.345
21.36,152.12,0.345
21.38,152.30,0.345
21.39,152.49,0.345
21.41,152.67,0.345
21.43,152.85,0.345
21.45,153.04,0.344
21.47,153.22,0.344
21.49,153.40,0.344
21.51,153.59,0.344
21.52,153.77,0.344
21.54,153.96,0.344
21.56,154.14,0.344
21.58,154.32,0.344
21.60,154.51,0.344
21.62,154.69,0.344
21.63,154.87,0.344
21.65,155.06,0.343
21.67,155.24,0.343
21.69,155.42,0.343
21.71,155.61,0.343
21.73,155.79,0.343
21.74,155.97,0.343
21.76,156.16,0.343
21.78,156.34,0.343
21.80,156.52,0.343
21.82,156.71,0.343
21.83,156.89,0.343
21.85,157.07,0.343
21.87,157.26,0.343
21.89,157.44,0.343
21.91,157.62,0.343
21.93,157.81,0.343
21.94,157.99,0.343
21.96,158.17,0.343
21.98,158.36,0.343
22.00,158.54,0.343
22.02,158.73,0.343
22.04,158.91,0.343
22.06,159.09,0.343
22.07,159.27,0.343
22.09,159.46,0.343
22.11,159.64,0.343
22.13,159.83,0.343
22.15,160.01,0.343
22.17,160.19,0.343
22.18,160.38,0.343
22.20,160.56,0.343
22.22,160.74,0.344
22.24,160.93,0.344
22.26,161.11,0.344
22.28,161.29,0.344
22.29,161.48,0.344
22.31,161.66,0.344
22.33,161.84,0.344
22.35,162.03,0.344
22.37,162.21,0.345
22.38,162.39,0.345
22.40,162.58,0.345
22.42,162.76,0.345
22.44,162.94,0.345
22.46,163.13,0.345
22.48,163.31,0.346
22.49,163.49,0.346
22.51,163.68,0.346
22.53,163.86,0.346
22.55,164.04,0.346
22.57,164.23,0.346
22.59,164.41,0.347
22.61,164.59,0.347
22.62,164.78,0.347
22.64,164.96,0.348
22.66,165.14,0.348
22.68,165.33,0.348
22.70,165.51,0.348
22.72,165.69,0.349
22.73,165.88,0.349
22.75,166.06,0.349
22.77,166.24,0.349
22.79,166.43,0.350
22.81,166.61,0.350
22.83,166.79,0.351
22.84,166.98,0.351
22.86,167.16,0.352
22.88,167.34,0.352
22.90,167.53,0.353
22.92,167.71,0.353
22.93,167.89,0.353
22.95,168.08,0.353
22.97,168.26,0.354
22.99,168.44,0.354
23.01,168.63,0.354
23.03,168.81,0.355
23.04,168.99,0.355
23.06,169.17,0.356
23.08,169.36,0.356
23.10,169.54,0.357
23.12,169.72,0.358
23.14,169.91,0.358
23.16,170.09,0.360
23.17,170.27,0.361
23.19,170.46,0.362
23.21,170.64,0.362
23.23,170.82,0.363
23.25,171.01,0.364
23.27,171.19,0.365
23.28,171.37,0.365
23.30,171.56,0.365
23.32,171.74,0.366
23.34,171.92,0.366
23.36,172.11,0.367
23.38,172.29,0.367
23.39,172.47,0.368
23.41,172.65,0.368
23.43,172.84,0.369
23.45,173.02,0.370
23.47,173.20,0.370
23.48,173.39,0.371
23.50,173.57,0.372
23.52,173.75,0.373
23.54,173.93,0.374
23.56,174.12,0.376
23.58,174.30,0.377
23.59,174.49,0.378
23.61,174.67,0.379
23.63,174.85,0.380
23.65,175.04,0.380
23.67,175.22,0.381
23.69,175.40,0.382
23.71,175.58,0.382
23.72,175.77,0.383
23.74,175.95,0.384
23.76,176.13,0.384
23.78,176.32,0.385
23.80,176.50,0.386
23.82,176.68,0.387
23.83,176.86,0.388
23.85,177.05,0.389
23.87,177.23,0.390
23.89,177.41,0.391
23.91,177.60,0.392
23.93,177.78,0.393
23.94,177.96,0.395
23.96,178.15,0.396
23.98,178.33,0.396
24.00,178.51,0.397
24.02,178.69,0.398
24.03,178.88,0.399
24.05,179.06,0.400
24.07,179.24,0.401
24.09,179.43,0.403
24.11,179.61,0.404
24.13,179.79,0.405
24.14,179.98,0.406
24.16,180.16,0.407
24.18,180.34,0.408
24.20,180.52,0.408
24.22,180.71,0.409
24.24,180.89,0.410
24.26,181.07,0.411
24.27,181.26,0.413
24.29,181.44,0.414
24.31,181.62,0.415
24.33,181.81,0.416
24.35,181.99,0.418
24.37,182.17,0.418
24.38,182.35,0.420
24.40,182.54,0.420
24.42,182.72,0.421
24.44,182.90,0.422
24.46,183.08,0.423
24.48,183.27,0.424
24.49,183.45,0.425
24.51,183.63,0.427
24.53,183.81,0.427
24.55,184.00,0.428
24.57,184.18,0.430
24.58,184.36,0.431
24.60,184.55,0.432
24.62,184.73,0.434
24.64,184.91,0.435
24.66,185.10,0.436
24.68,185.28,0.437
24.69,185.46,0.438
24.71,185.65,0.440
24.73,185.83,0.440
24.75,186.01,0.442
24.77,186.19,0.442
24.79,186.38,0.443
24.81,186.56,0.443
24.82,186.74,0.445
24.84,186.93,0.445
24.86,187.11,0.447
24.88,187.29,0.448
24.90,187.47,0.449
24.92,187.66,0.451
24.93,187.84,0.452
24.95,188.02,0.454
24.97,188.20,0.455
24.99,188.39,0.456
25.01,188.57,0.457
25.03,188.75,0.459
25.04,188.93,0.461
25.06,189.12,0.462
25.08,189.30,0.464
25.10,189.48,0.465
25.12,189.67,0.467
25.13,189.85,0.468
25.15,190.03,0.469
25.17,190.22,0.471
25.19,190.40,0.473
25.21,190.58,0.474
25.23,190.76,0.476
25.24,190.95,0.478
25.26,191.13,0.479
25.28,191.31,0.481
25.30,191.49,0.482
25.32,191.68,0.485
25.34,191.86,0.487
25.36,192.04,0.490
25.37,192.22,0.491
25.39,192.41,0.492
25.41,192.59,0.494
25.43,192.77,0.496
25.45,192.95,0.497
25.47,193.13,0.500
25.48,193.32,0.501
25.50,193.50,0.503
25.52,193.68,0.505
25.54,193.86,0.508
25.56,194.05,0.510
25.58,194.23,0.513
25.59,194.41,0.515
25.61,194.60,0.517
25.63,194.78,0.520
25.65,194.96,0.521
25.67,195.14,0.525
25.68,195.32,0.526
25.70,195.51,0.528
25.72,195.69,0.531
25.74,195.87,0.532
25.76,196.05,0.535
25.78,196.24,0.538
25.79,196.42,0.540
25.81,196.60,0.543
25.83,196.78,0.546
25.85,196.96,0.548
25.87,197.15,0.550
25.89,197.33,0.553
25.91,197.51,0.557
25.92,197.69,0.561
25.94,197.87,
25.96,198.06,
25.98,198.24,
25.99,,

[step]
Ramp 10.00 °C/min to -60.00 °C
Time,Temperature,Heat Flow (Normalized)
min,°C,W/g
26.99,199.99,0.146
27.01,199.99,0.145
27.03,199.98,0.145
27.05,199.97,0.141
27.07,199.95,0.128
27.08,199.92,0.107
27.10,199.86,0.074
27.12,199.79,0.031
27.14,199.69,-0.017
27.16,199.58,-0.066
27.18,199.46,-0.110
27.19,199.33,-0.149
27.21,199.19,-0.182
27.23,199.04,-0.210
27.25,198.89,-0.233
27.27,198.73,-0.253
27.29,198.57,-0.270
27.31,198.41,-0.284
27.32,198.24,-0.297
27.34,198.07,-0.307
27.36,197.91,-0.317
27.38,197.73,-0.325
27.40,197.56,-0.332
27.42,197.39,-0.339
27.43,197.21,-0.344
27.45,197.04,-0.350
27.47,196.86,-0.354
27.49,196.69,-0.358
27.51,196.51,-0.361
27.53,196.33,-0.365
27.54,196.15,-0.370
27.56,195.97,-0.371
27.58,195.79,-0.374
27.60,195.62,-0.377
27.62,195.44,-0.379
27.63,195.26,-0.381
27.65,195.08,-0.383
27.67,194.90,-0.385
27.69,194.72,-0.388
27.71,194.54,-0.389
27.73,194.36,-0.391
27.74,194.18,-0.393
27.76,194.00,-0.395
27.78,193.81,-0.396
27.80,193.64,-0.398
27.82,193.45,-0.399
27.84,193.27,-0.400
27.86,193.09,-0.402
27.87,192.91,-0.403
27.89,192.73,-0.404
27.91,192.55,-0.406
27.93,192.37,-0.407
27.95,192.19,-0.407
27.97,192.01,-0.409
27.98,191.83,-0.410
28.00,191.64,-0.411
28.02,191.46,-0.412
28.04,191.28,-0.413
28.06,191.10,-0.415
28.08,190.92,-0.416
28.09,190.73,-0.417
28.11,190.55,-0.418
28.13,190.37,-0.419
28.15,190.19,-0.420
28.17,190.01,-0.420
28.18,189.82,-0.421
28.20,189.64,-0.422
28.22,189.46,-0.422
28.24,189.28,-0.423
28.26,189.10,-0.423
28.28,188.91,-0.424
28.29,188.73,-0.425
28.31,188.55,-0.425
28.33,188.37,-0.426
28.35,188.19,-0.427
28.37,188.00,-0.427
28.39,187.82,-0.428
28.41,187.64,-0.429
28.42,187.46,-0.429
28.44,187.27,-0.429
28.46,187.09,-0.430
28.48,186.91,-0.430
28.50,186.73,-0.431
28.52,186.54,-0.431
28.53,186.36,-0.432
28.55,186.18,-0.433
28.57,186.00,-0.433
28.59,185.82,-0.433
28.61,185.63,-0.434
28.63,185.45,-0.435
28.64,185.27,-0.435
28.66,185.08,-0.435
28.68,184.90,-0.436
28.70,184.72,-0.436
28.72,184.54,-0.437
28.73,184.35,-0.437
28.75,184.17,-0.438
28.77,183.99,-0.438
28.79,183.80,-0.438
28.81,183.62,-0.438
28.83,183.44,-0.438
28.84,183.26,-0.439
28.86,183.07,-0.439
28.88,182.89,-0.440
28.90,182.71,-0.440
28.92,182.53,-0.440
28.94,182.34,-0.440
28.96,182.16,-0.441
28.97,181.98,-0.441
28.99,181.79,-0.441
29.01,181.61,-0.442
29.03,181.43,-0.442
29.05,181.25,-0.442
29.07,181.06,-0.442
29.08,180.88,-0.443
29.10,180.70,-0.443
29.12,180.51,-0.443
29.14,180.33,-0.443
29.16,180.15,-0.444
29.18,179.96,-0.444
29.19,179.78,-0.444
29.21,179.60,-0.444
29.23,179.42,-0.444
29.25,179.23,-0.445
29.27,179.05,-0.445
29.28,178.87,-0.445
29.30,178.69,-0.445
29.32,178.50,-0.445
29.34,178.32,-0.445
29.36,178.14,-0.446
29.38,177.95,-0.446
29.39,177.77,-0.446
29.41,177.59,-0.446
29.43,177.40,-0.446
29.45,177.22,-0.446
29.47,177.04,-0.446
29.49,176.86,-0.447
29.51,176.67,-0.447
29.52,176.49,-0.447
29.54,176.31,-0.447
29.56,176.12,-0.447
29.58,175.94,-0.447
29.60,175.76,-0.447
29.62,175.57,-0.447
29.63,175.39,-0.448
29.65,175.21,-0.448
29.67,175.03,-0.448
29.69,174.84,-0.448
29.71,174.66,-0.448
29.73,174.48,-0.448
29.74,174.29,-0.448
29.76,174.11,-0.448
29.78,173.93,-0.448
29.80,173.74,-0.448
29.82,173.56,-0.448
29.83,173.38,-0.448
29.85,173.19,-0.448
29.87,173.01,-0.448
29.89,172.83,-0.448
29.91,172.65,-0.448
29.93,172.46,-0.448
29.94,172.28,-0.448
29.96,172.09,-0.448
29.98,171.91,-0.448
30.00,171.73,-0.448
30.02,171.55,-0.448
30.04,171.36,-0.448
30.06,171.18,-0.448
30.07,171.00,-0.448
30.09,170.81,-0.448
30.11,170.63,-0.448
30.13,170.45,-0.448
30.15,170.27,-0.448
30.17,170.08,-0.448
30.18,169.90,-0.448
30.20,169.72,-0.448
30.22,169.53,-0.448
30.24,169.35,-0.448
30.26,169.17,-0.448
30.28,168.98,-0.448
30.29,168.80,-0.448
30.31,168.62,-0.448
30.33,168.44,-0.448
30.35,168.25,-0.448
30.37,168.07,-0.448
30.38,167.88,-0.447
30.40,167.70,-0.447
30.42,167.52,-0.447
30.44,167.34,-0.447
30.46,167.15,-0.447
30.48,166.97,-0.447
30.49,166.79,-0.447
30.51,166.60,-0.447
30.53,166.42,-0.447
30.55,166.24,-0.447
30.57,166.06,-0.447
30.59,165.87,-0.447
30.61,165.69,-0.447
30.62,165.51,-0.446
30.64,165.32,-0.446
30.66,165.14,-0.446
30.68,164.96,-0.446
30.70,164.77,-0.446
30.72,164.59,-0.446
30.73,164.41,-0.446
30.75,164.23,-0.446
30.77,164.04,-0.446
30.79,163.86,-0.446
30.81,163.68,-0.446
30.83,163.49,-0.446
30.84,163.31,-0.446
30.86,163.13,-0.446
30.88,162.94,-0.446
30.90,162.76,-0.446
30.92,162.58,-0.445
30.93,162.40,-0.445
30.95,162.21,-0.445
30.97,162.03,-0.445
30.99,161.84,-0.445
31.01,161.66,-0.445
31.03,161.48,-0.445
31.04,161.29,-0.445
31.06,161.11,-0.445
31.08,160.93,-0.445
31.10,160.74,-0.445
31.12,160.56,-0.444
31.14,160.38,-0.444
31.16,160.20,-0.444
31.17,160.01,-0.444
31.19,159.83,-0.444
31.21,159.65,-0.444
31.23,159.46,-0.444
31.25,159.28,-0.444
31.27,159.10,-0.444
31.28,158.91,-0.444
31.30,158.73,-0.444
31.32,158.55,-0.443
31.34,158.37,-0.443
31.36,158.18,-0.443
31.38,158.00,-0.443
31.39,157.82,-0.443
31.41,157.63,-0.443
31.43,157.45,-0.443
31.45,157.27,-0.443
31.47,157.08,-0.443
31.48,156.90,-0.443
31.50,156.72,-0.443
31.52,156.53,-0.442
31.54,156.35,-0.442
31.56,156.17,-0.442
31.58,155.98,-0.442
31.59,155.80,-0.442
31.61,155.62,-0.442
31.63,155.44,-0.442
31.65,155.25,-0.442
31.67,155.07,-0.442
31.69,154.89,-0.442
31.71,154.70,-0.442
31.72,154.52,-0.442
31.74,154.34,-0.442
31.76,154.15,-0.442
31.78,153.97,-0.441
31.80,153.79,-0.441
31.82,153.60,-0.441
31.83,153.42,-0.441
31.85,153.24,-0.441
31.87,153.05,-0.441
31.89,152.87,-0.441
31.91,152.69,-0.441
31.93,152.51,-0.441
31.94,152.32,-0.441
31.96,152.14,-0.440
31.98,151.96,-0.440
32.00,151.77,-0.440
32.02,151.59,-0.440
32.03,151.41,-0.440
32.05,151.22,-0.440
32.07,151.04,-0.440
32.09,150.86,-0.440
32.11,150.67,-0.440
32.13,150.49,-0.440
32.14,150.31,-0.440
32.16,150.12,-0.440
32.18,149.94,-0.439
32.20,149.76,-0.439
32.22,149.57,-0.439
32.24,149.39,-0.439
32.26,149.21,-0.439
32.27,149.03,-0.439
32.29,148.84,-0.439
32.31,148.66,-0.439
32.33,148.48,-0.439
32.35,148.29,-0.438
32.37,148.11,-0.438
32.38,147.93,-0.438
32.40,147.74,-0.438
32.42,147.56,-0.438
32.44,147.38,-0.438
32.46,147.19,-0.438
32.48,147.01,-0.438
32.49,146.83,-0.438
32.51,146.65,-0.437
32.53,146.46,-0.437
32.55,146.28,-0.437
32.57,146.10,-0.437
32.58,145.91,-0.437
32.60,145.73,-0.437
32.62,145.55,-0.437
32.64,145.36,-0.437
32.66,145.18,-0.437
32.68,145.00,-0.436
32.69,144.81,-0.436
32.71,144.63,-0.436
32.73,144.45,-0.436
32.75,144.27,-0.436
32.77,144.08,-0.436
32.79,143.90,-0.436
32.81,143.72,-0.436
32.82,143.53,-0.436
32.84,143.35,-0.436
32.86,143.17,-0.436
32.88,142.98,-0.435
32.90,142.80,-0.435
32.92,142.62,-0.435
32.93,142.43,-0.435
32.95,142.25,-0.435
32.97,142.07,-0.435
32.99,141.88,-0.435
33.01,141.70,-0.435
33.03,141.52,-0.435
33.04,141.33,-0.435
33.06,141.15,-0.435
33.08,140.97,-0.434
33.10,140.78,-0.434
33.12,140.60,-0.434
33.13,140.42,-0.434
33.15,140.24,-0.434
33.17,140.05,-0.434
33.19,139.87,-0.434
33.21,139.69,-0.434
33.23,139.50,-0.433
33.24,139.32,-0.433
33.26,139.14,-0.433
33.28,138.95,-0.433
33.30,138.77,-0.433
33.32,138.59,-0.433
33.34,138.40,-0.433
33.36,138.22,-0.433
33.37,138.04,-0.433
33.39,137.85,-0.433
33.41,137.67,-0.432
33.43,137.49,-0.432
33.45,137.30,-0.432
33.47,137.12,-0.432
33.48,136.94,-0.432
33.50,136.76,-0.432
33.52,136.57,-0.432
33.54,136.39,-0.432
33.56,136.20,-0.432
33.58,136.02,-0.432
33.59,135.84,-0.432
33.61,135.66,-0.431
33.63,135.47,-0.431
33.65,135.29,-0.431
33.67,135.11,-0.431
33.68,134.92,-0.431
33.70,134.74,-0.431
33.72,134.56,-0.431
33.74,134.37,-0.431
33.76,134.19,-0.430
33.78,134.01,-0.430
33.79,133.83,-0.430
33.81,133.64,-0.430
33.83,133.46,-0.430
33.85,133.28,-0.430
33.87,133.09,-0.430
33.89,132.91,-0.430
33.91,132.73,-0.430
33.92,132.54,-0.430
33.94,132.36,-0.430
33.96,132.18,-0.429
33.98,131.99,-0.429
34.00,131.81,-0.429
34.02,131.63,-0.429
34.03,131.45,-0.429
34.05,131.26,-0.429
34.07,131.08,-0.429
34.09,130.89,-0.429
34.11,130.71,-0.429
34.13,130.53,-0.429
34.14,130.35,-0.428
34.16,130.16,-0.428
34.18,129.98,-0.428
34.20,129.80,-0.428
34.22,129.61,-0.428
34.24,129.43,-0.428
34.25,129.25,-0.428
34.27,129.06,-0.428
34.29,128.88,-0.428
[...]
115.21,10.51,0.307
115.23,10.69,0.308
115.25,10.87,0.310
115.27,11.06,0.312
115.29,11.24,0.313
115.31,11.42,0.314
115.33,11.60,0.316
115.34,11.79,0.317
115.36,11.97,0.319
115.38,12.15,0.321
115.40,12.33,0.322
115.42,12.52,0.323
115.44,12.70,0.325
115.45,12.88,0.326
115.47,13.06,0.329
115.49,13.25,0.330
115.51,13.43,0.331
115.53,13.61,0.332
115.55,13.79,0.334
115.56,13.98,0.334
115.58,14.16,0.336
115.60,14.34,0.337
115.62,14.53,0.338
115.64,14.71,0.338
115.65,14.89,0.339
115.67,15.07,0.340
115.69,15.26,0.340
115.71,15.44,0.341
115.73,15.62,0.341
115.75,15.81,0.341
115.76,15.99,0.342
115.78,16.17,0.342
115.80,16.36,0.342
115.82,16.54,0.342
115.84,16.72,0.342
115.86,16.91,0.342
115.88,17.09,0.342
115.89,17.27,0.342
115.91,17.46,0.342
115.93,17.64,0.342
115.95,17.83,0.342
115.97,18.01,0.342
115.99,18.19,0.342
116.00,18.38,0.342
116.02,18.56,0.341
116.04,18.75,0.341
116.06,18.93,0.341
116.08,19.11,0.341
116.10,19.30,0.341
116.11,19.48,0.340
116.13,19.66,0.340
116.15,19.85,0.340
116.17,20.03,0.340
116.19,20.22,0.340
116.20,20.40,0.339
116.22,20.58,0.339
116.24,20.77,0.339
116.26,20.95,0.339
116.28,21.13,0.339
116.30,21.32,0.339
116.31,21.50,0.338
116.33,21.69,0.338
116.35,21.87,0.338
116.37,22.05,0.338
116.39,22.24,0.338
116.41,22.42,0.338
116.43,22.60,0.338
116.44,22.79,0.338
116.46,22.97,0.338
116.48,23.16,0.338
116.50,23.34,0.338
116.52,23.52,0.338
116.54,23.70,0.338
116.55,23.89,0.338
116.57,24.07,0.338
116.59,24.26,0.338
116.61,24.44,0.338
116.63,24.62,0.338
116.65,24.81,0.338
116.66,24.99,0.338
116.68,25.17,0.338
116.70,25.36,0.338
116.72,25.54,0.338
116.74,25.72,0.338
116.75,25.91,0.338
116.77,26.09,0.338
116.79,26.27,0.339
116.81,26.46,0.339
116.83,26.64,0.339
116.85,26.83,0.339
116.86,27.01,0.339
116.88,27.19,0.339
116.90,27.38,0.339
116.92,27.56,0.339
116.94,27.74,0.340
116.96,27.93,0.340
116.98,28.11,0.340
116.99,28.29,0.340
117.01,28.48,0.340
117.03,28.66,0.340
117.05,28.84,0.340
117.07,29.03,0.340
117.09,29.21,0.341
117.10,29.40,0.341
117.12,29.58,0.341
117.14,29.76,0.341
117.16,29.95,0.341
117.18,30.13,0.341
117.20,30.31,0.341
117.21,30.50,0.342
117.23,30.68,0.342
117.25,30.86,0.342
117.27,31.05,0.342
117.29,31.23,0.342
117.30,31.41,0.343
117.32,31.60,0.343
117.34,31.78,0.343
117.36,31.96,0.343
117.38,32.15,0.343
117.40,32.33,0.343
117.41,32.51,0.343
117.43,32.70,0.344
117.45,32.88,0.344
117.47,33.07,0.344
117.49,33.25,0.344
117.51,33.43,0.344
117.53,33.62,0.344
117.54,33.80,0.345
117.56,33.98,0.345
117.58,34.17,0.345
117.60,34.35,0.345
117.62,34.53,0.345
117.64,34.72,0.345
117.65,34.90,0.346
117.67,35.08,0.346
117.69,35.27,0.346
117.71,35.45,0.346
117.73,35.63,0.346
117.75,35.82,0.346
117.76,36.00,0.347
117.78,36.18,0.347
117.80,36.37,0.347
117.82,36.55,0.347
117.84,36.74,0.347
117.85,36.92,0.347
117.87,37.10,0.348
117.89,37.29,0.348
117.91,37.47,0.348
117.93,37.65,0.348
117.95,37.84,0.348
117.96,38.02,0.349
117.98,38.20,0.349
118.00,38.39,0.349
118.02,38.57,0.349
118.04,38.75,0.349
118.06,38.94,0.350
118.08,39.12,0.350
118.09,39.30,0.350
118.11,39.49,0.350
118.13,39.67,0.350
118.15,39.86,0.351
118.17,40.04,0.351
118.19,40.22,0.351
118.20,40.40,0.351
118.22,40.59,0.351
118.24,40.77,0.352
118.26,40.96,0.352
118.28,41.14,0.352
118.30,41.32,0.352
118.31,41.51,0.352
118.33,41.69,0.353
118.35,41.87,0.353
118.37,42.06,0.353
118.39,42.24,0.353
118.40,42.42,0.354
118.42,42.61,0.354
118.44,42.79,0.354
118.46,42.97,0.355
118.48,43.16,0.355
118.50,43.34,0.355
118.51,43.52,0.355
118.53,43.71,0.355
118.55,43.89,0.355
118.57,44.07,0.356
118.59,44.26,0.356
118.61,44.44,0.356
118.63,44.63,0.356
118.64,44.81,0.356
118.66,44.99,0.356
118.68,45.18,0.356
118.70,45.36,0.356
118.72,45.54,0.357
118.74,45.73,0.357
118.75,45.91,0.357
118.77,46.09,0.357
118.79,46.28,0.357
118.81,46.46,0.357
118.83,46.64,0.357
118.85,46.83,0.358
118.86,47.01,0.358
118.88,47.20,0.358
118.90,47.38,0.358
118.92,47.56,0.358
118.94,47.75,0.358
118.95,47.93,0.359
118.97,48.11,0.359
118.99,48.30,0.359
119.01,48.48,0.359
119.03,48.66,0.359
119.05,48.85,0.359
119.06,49.03,0.360
119.08,49.21,0.360
119.10,49.40,0.360
119.12,49.58,0.360
119.14,49.76,0.360
119.16,49.95,0.361
119.18,50.13,0.361
119.19,50.32,0.361
119.21,50.50,0.361
119.23,50.68,0.361
119.25,50.86,0.362
119.27,51.05,0.362
119.29,51.23,0.362
119.30,51.41,0.362
119.32,51.60,0.363
119.34,51.78,0.363
119.36,51.97,0.363
119.38,52.15,0.363
119.40,52.33,0.364
119.41,52.52,0.364
119.43,52.70,0.364
119.45,52.88,0.364
119.47,53.07,0.364
119.49,53.25,0.365
119.50,53.43,0.365
119.52,53.62,0.365
119.54,53.80,0.365
119.56,53.98,0.365
119.58,54.17,0.365
119.60,54.35,0.365
119.61,54.54,0.365
119.63,54.72,0.365
119.65,54.90,0.365
119.67,55.09,0.365
119.69,55.27,0.365
119.71,55.46,0.364
119.73,55.64,0.364
119.74,55.82,0.364
119.76,56.01,0.364
119.78,56.19,0.364
119.80,56.37,0.363
119.82,56.56,0.363
119.84,56.74,0.363
119.85,56.93,0.363
119.87,57.11,0.363
119.89,57.29,0.362
119.91,57.48,0.362
119.93,57.66,0.362
119.95,57.84,0.362
119.96,58.03,0.362
119.98,58.21,0.362
120.00,58.40,0.361
120.02,58.58,0.361
120.04,58.76,0.361
120.05,58.95,0.361
120.07,59.13,0.361
120.09,59.31,0.361
120.11,59.50,0.361
120.13,59.68,0.360
120.15,59.87,0.360
120.16,60.05,0.360
120.18,60.23,0.360
120.20,60.42,0.360
120.22,60.60,0.359
120.24,60.79,0.359
120.26,60.97,0.359
120.28,61.15,0.359
120.29,61.34,0.358
120.31,61.52,0.358
120.33,61.70,0.358
120.35,61.89,0.358
120.37,62.07,0.358
120.39,62.26,0.357
120.40,62.44,0.357
120.42,62.62,0.357
120.44,62.81,0.357
120.46,62.99,0.356
120.48,63.17,0.356
120.50,63.36,0.356
120.51,63.54,0.356
120.53,63.73,0.355
120.55,63.91,0.355
120.57,64.09,0.355
120.59,64.28,0.355
120.60,64.46,0.355
120.62,64.64,0.355
120.64,64.83,0.354
120.66,65.01,0.354
120.68,65.19,0.354
120.70,65.38,0.354
120.71,65.56,0.354
120.73,65.75,0.354
120.75,65.93,0.354
120.77,66.11,0.354
120.79,66.29,0.354
120.81,66.48,0.354
120.83,66.66,0.354
120.84,66.84,0.355
120.86,67.03,0.355
120.88,67.21,0.355
120.90,67.39,0.355
120.92,67.58,0.355
120.94,67.76,0.355
120.95,67.95,0.356
120.97,68.13,0.356
120.99,68.31,0.356
121.01,68.49,0.356
121.03,68.68,0.356
121.05,68.86,0.356
121.06,69.04,0.357
121.08,69.23,0.357
121.10,69.41,0.357
121.12,69.59,0.357
121.14,69.78,0.358
121.15,69.96,0.358
121.17,70.14,0.358
121.19,70.33,0.358
121.21,70.51,0.359
121.23,70.69,0.359
121.25,70.88,0.359
121.26,71.06,0.360
121.28,71.24,0.360
121.30,71.43,0.360
121.32,71.61,0.361
121.34,71.79,0.361
121.36,71.98,0.361
121.38,72.16,0.362
121.39,72.34,0.362
121.41,72.53,0.363
121.43,72.71,0.363
121.45,72.89,0.363
121.47,73.08,0.364
121.49,73.26,0.365
121.50,73.44,0.365
121.52,73.63,0.366
121.54,73.81,0.367
121.56,73.99,0.367
121.58,74.18,0.368
121.60,74.36,0.368
121.61,74.54,0.369
121.63,74.73,0.369
121.65,74.91,0.370
121.67,75.09,0.370
121.69,75.28,0.371
121.70,75.46,0.371
121.72,75.64,0.372
121.74,75.83,0.372
121.76,76.01,0.373
121.78,76.19,0.373
121.80,76.38,0.373
121.81,76.56,0.374
121.83,76.74,0.374
121.85,76.93,0.375
121.87,77.11,0.375
121.89,77.29,0.375
121.91,77.48,0.376
121.93,77.66,0.376
121.94,77.84,0.376
121.96,78.03,0.377
121.98,78.21,0.377
122.00,78.39,0.377
122.02,78.58,0.378
122.04,78.76,0.378
122.05,78.94,0.378
122.07,79.13,0.379
122.09,79.31,0.379
122.11,79.49,0.379
122.13,79.67,0.379
122.15,79.86,0.379
122.16,80.04,0.380
122.18,80.23,0.380
122.20,80.41,0.380
122.22,80.59,0.381
122.24,80.78,0.381
122.25,80.96,0.381
122.27,81.14,0.381
122.29,81.33,0.381
122.31,81.51,0.382
122.33,81.69,0.382
122.35,81.88,0.382
122.36,82.06,0.382
122.38,82.25,0.382
122.40,82.43,0.383
122.42,82.61,0.383
122.44,82.80,0.383
122.46,82.98,0.383
122.48,83.16,0.383
122.49,83.35,0.383
122.51,83.53,0.384
122.53,83.71,0.384
122.55,83.90,0.384
122.57,84.08,0.384
122.59,84.26,0.384
122.60,84.45,0.384
122.62,84.63,0.384
122.64,84.81,0.385
122.66,85.00,0.385
122.68,85.18,0.385
122.70,85.36,0.385
122.71,85.55,0.385
122.73,85.73,0.385
122.75,85.91,0.385
122.77,86.10,0.385
122.79,86.28,0.386
122.80,86.46,0.386
122.82,86.65,0.386
122.84,86.83,0.386
122.86,87.02,0.386
122.88,87.20,0.386
122.90,87.38,0.386
122.91,87.57,0.387
122.93,87.75,0.387
122.95,87.93,0.387
122.97,88.12,0.387
122.99,88.30,0.387
123.01,88.48,0.387
123.03,88.67,0.388
123.04,88.85,0.388
123.06,89.03,0.388
123.08,89.22,0.388
123.10,89.40,0.388
123.12,89.59,0.389
123.14,89.77,0.389
123.15,89.95,0.389
123.17,90.14,0.389
123.19,90.32,0.389
123.21,90.50,0.389
123.23,90.69,0.390
123.25,90.87,0.390
123.26,91.05,0.390
123.28,91.24,0.390
123.30,91.42,0.390
123.32,91.60,0.390
123.34,91.79,0.391
123.35,91.97,0.391
123.37,92.15,0.391
123.39,92.34,0.391
123.41,92.52,0.391
123.43,92.70,0.392
123.45,92.89,0.392
123.46,93.07,0.392
123.48,93.25,0.392
123.50,93.44,0.392
123.52,93.62,0.392
123.54,93.80,0.393
123.56,93.99,0.393
123.58,94.17,0.393
123.59,94.35,0.393
123.61,94.54,0.393
123.63,94.72,0.394
123.65,94.91,0.394
123.67,95.09,0.394
123.69,95.27,0.394
123.70,95.46,0.394
123.72,95.64,0.394
123.74,95.82,0.395
123.76,96.01,0.395
123.78,96.19,0.395
123.80,96.37,0.395
123.81,96.56,0.395
123.83,96.74,0.396
123.85,96.92,0.396
123.87,97.11,0.396
123.89,97.29,0.396
123.90,97.47,0.396
123.92,97.66,0.396
123.94,97.84,0.397
123.96,98.02,0.397
123.98,98.21,0.397
124.00,98.39,0.397
124.01,98.57,0.397
124.03,98.76,0.397
124.05,98.94,0.397
124.07,99.12,0.398
124.09,99.31,0.398
124.11,99.49,0.398
124.13,99.68,0.398
124.14,99.86,0.398
124.16,100.04,0.398
124.18,100.22,0.398
124.20,100.41,0.399
124.22,100.59,0.399
124.24,100.78,0.399
124.25,100.96,0.399
124.27,101.14,0.399
124.29,101.33,0.399
124.31,101.51,0.400
124.33,101.69,0.400
124.35,101.88,0.400
124.36,102.06,0.400
124.38,102.24,0.400
124.40,102.43,0.401
124.42,102.61,0.401
124.44,102.80,0.401
124.45,102.98,0.401
124.47,103.17,0.402
124.49,103.35,0.402
124.51,103.53,0.402
124.53,103.72,0.402
124.55,103.90,0.402
124.56,104.08,0.402
124.58,104.27,0.402
124.60,104.45,0.402
124.62,104.63,0.403
124.64,104.82,0.403
124.66,105.00,0.403
124.68,105.18,0.403
124.69,105.37,0.403
124.71,105.55,0.403
124.73,105.73,0.403
124.75,105.92,0.403
124.77,106.10,0.404
124.79,106.28,0.404
124.80,106.47,0.404
124.82,106.65,0.404
124.84,106.83,0.404
124.86,107.01,0.404
124.88,107.20,0.404
124.90,107.38,0.405
124.91,107.57,0.405
124.93,107.75,0.405
124.95,107.93,0.405
124.97,108.11,0.405
124.99,108.30,0.405
125.00,108.48,0.406
125.02,108.66,0.406
125.04,108.85,0.406
125.06,109.03,0.406
125.08,109.22,0.407
125.10,109.40,0.407
125.11,109.58,0.407
125.13,109.77,0.407
125.15,109.95,0.407
125.17,110.13,0.408
125.19,110.32,0.408
125.21,110.50,0.408
125.23,110.68,0.408
125.24,110.87,0.408
125.26,111.05,0.409
125.28,111.23,0.409
125.30,111.42,0.409
125.32,111.60,0.409
125.34,111.78,0.409
125.35,111.97,0.410
125.37,112.15,0.410
125.39,112.33,0.410
125.41,112.52,0.410
125.43,112.70,0.411
125.45,112.88,0.411
125.46,113.07,0.411
125.48,113.25,0.411
125.50,113.43,0.411
125.52,113.62,0.412
125.54,113.80,0.412
125.55,113.98,0.412
125.57,114.17,0.412
125.59,114.35,0.412
125.61,114.53,0.413
125.63,114.72,0.413
125.65,114.90,0.413
125.66,115.08,0.413
125.68,115.27,0.414
125.70,115.45,0.414
125.72,115.63,0.414
125.74,115.82,0.414
125.76,116.00,0.414
125.78,116.18,0.415
125.79,116.37,0.415
125.81,116.55,0.415
125.83,116.74,0.415
125.85,116.92,0.416
125.87,117.10,0.416
125.89,117.28,0.416
125.90,117.47,0.416
125.92,117.65,0.417
125.94,117.84,0.417
125.96,118.02,0.417
125.98,118.20,0.418
126.00,118.38,0.418
126.01,118.57,0.418
126.03,118.75,0.418
126.05,118.93,0.419
126.07,119.12,0.419
126.09,119.30,0.419
126.10,119.48,0.420
126.12,119.67,0.420
126.14,119.85,0.420
126.16,120.03,0.421
126.18,120.22,0.421
126.20,120.40,0.421
126.21,120.59,0.421
126.23,120.77,0.422
126.25,120.95,0.422
126.27,121.13,0.422
126.29,121.32,0.422
126.31,121.50,0.423
126.33,121.69,0.423
126.34,121.87,0.423
126.36,122.05,0.424
126.38,122.24,0.424
126.40,122.42,0.424
126.42,122.60,0.424
126.44,122.79,0.425
126.45,122.97,0.425
126.47,123.15,0.425
126.49,123.34,0.426
126.51,123.52,0.426
126.53,123.70,0.426
126.55,123.89,0.427
126.56,124.07,0.428
126.58,124.25,0.428
126.60,124.44,0.428
126.62,124.62,0.429
126.64,124.80,0.429
126.65,124.99,0.429
126.67,125.17,0.429
126.69,125.35,0.430
126.71,125.53,0.430
126.73,125.72,0.430
126.75,125.90,0.430
126.76,126.09,0.431
126.78,126.27,0.431
126.80,126.45,0.431
126.82,126.63,0.432
126.84,126.82,0.432
126.86,127.00,0.432
126.88,127.18,0.433
126.89,127.37,0.433
126.91,127.55,0.433
126.93,127.73,0.434
126.95,127.92,0.434
126.97,128.10,0.434
126.99,128.29,0.435
127.00,128.47,0.435
127.02,128.65,0.435
127.04,128.84,0.436
127.06,129.02,0.436
127.08,129.20,0.436
127.10,129.39,0.437
127.11,129.57,0.437
127.13,129.75,0.437
127.15,129.94,0.438
127.17,130.12,0.438
127.19,130.30,0.438
127.20,130.49,0.439
127.22,130.67,0.439
127.24,130.85,0.439
127.26,131.04,0.439
127.28,131.22,0.440
127.30,131.40,0.440
127.31,131.59,0.441
127.33,131.77,0.441
127.35,131.95,0.441
127.37,132.14,0.442
127.39,132.32,0.442
127.41,132.50,0.443
127.43,132.69,0.443
127.44,132.87,0.443
127.46,133.05,0.444
127.48,133.24,0.444
127.50,133.42,0.444
127.52,133.60,0.445
127.54,133.79,0.445
127.55,133.97,0.445
127.57,134.15,0.445
127.59,134.34,0.446
127.61,134.52,0.446
127.63,134.70,0.446
127.65,134.89,0.447
127.66,135.07,0.447
127.68,135.25,0.448
127.70,135.44,0.448
127.72,135.62,0.448
127.74,135.80,0.449
127.75,135.99,0.449
127.77,136.17,0.450
127.79,136.35,0.450
127.81,136.54,0.450
127.83,136.72,0.451
127.85,136.90,0.451
127.86,137.08,0.452
127.88,137.27,0.452
127.90,137.45,0.452
127.92,137.63,0.453
127.94,137.82,0.453
127.96,138.00,0.453
127.98,138.18,0.453
127.99,138.37,0.454
128.01,138.55,0.454
128.03,138.73,0.455
128.05,138.92,0.455
128.07,139.10,0.456
128.09,139.28,0.456
128.10,139.47,0.457
128.12,139.65,0.457
128.14,139.83,0.457
128.16,140.02,0.458
128.18,140.20,0.458
128.20,140.38,0.459
128.21,140.57,0.459
128.23,140.75,0.459
128.25,140.93,0.460
128.27,141.12,0.460
128.29,141.30,0.461
128.30,141.49,0.461
128.32,141.67,0.462
128.34,141.85,0.462
128.36,142.04,0.463
128.38,142.22,0.463
128.40,142.40,0.463
128.41,142.59,0.464
128.43,142.77,0.464
128.45,142.95,0.464
128.47,143.13,0.465
128.49,143.32,0.465
128.51,143.50,0.465
128.53,143.68,0.466
128.54,143.87,0.466
128.56,144.05,0.467
128.58,144.23,0.467
128.60,144.42,0.467
128.62,144.60,0.468
128.64,144.78,0.469
128.65,144.97,0.469
128.67,145.15,0.469
128.69,145.33,0.470
128.71,145.52,0.470
128.73,145.70,0.470
128.75,145.88,0.471
128.76,146.07,0.471
128.78,146.25,0.472
128.80,146.43,0.472
128.82,146.61,0.472
128.84,146.80,0.473
128.85,146.98,0.473
128.87,147.17,0.474
128.89,147.35,0.474
128.91,147.53,0.475
128.93,147.72,0.475
128.95,147.90,0.476
128.96,148.08,0.476
128.98,148.27,0.477
129.00,148.45,0.477
129.02,148.63,0.477
129.04,148.82,0.478
129.06,149.00,0.478
129.08,149.18,0.479
129.09,149.37,0.479
129.11,149.55,0.479
129.13,149.73,0.480
129.15,149.92,0.480
129.17,150.10,0.481
129.19,150.28,0.481
129.20,150.46,0.481
129.22,150.65,0.481
129.24,150.83,0.482
129.26,151.01,0.482
129.28,151.20,0.482
129.30,151.38,0.483
129.31,151.56,0.483
129.33,151.75,0.484
129.35,151.93,0.484
129.37,152.11,0.485
129.39,152.30,0.485
129.40,152.48,0.485
129.42,152.66,0.486
129.44,152.85,0.486
129.46,153.03,0.487
129.48,153.22,0.487
129.50,153.40,0.487
129.51,153.58,0.488
129.53,153.76,0.488
129.55,153.95,0.489
129.57,154.13,0.489
129.59,154.31,0.489
129.61,154.50,0.489
129.63,154.68,0.490
129.64,154.86,0.490
129.66,155.05,0.490
129.68,155.23,0.491
129.70,155.41,0.492
129.72,155.60,0.492
129.74,155.78,0.493
129.75,155.96,0.493
129.77,156.15,0.493
129.79,156.33,0.494
129.81,156.51,0.494
129.83,156.70,0.495
129.85,156.88,0.495
129.86,157.06,0.495
129.88,157.25,0.496
129.90,157.43,0.496
129.92,157.61,0.496
129.94,157.80,0.497
129.95,157.98,0.497
129.97,158.16,0.497
129.99,158.35,0.497
130.01,158.53,0.498
130.03,158.71,0.498
130.05,158.90,0.498
130.06,159.08,0.498
130.08,159.26,0.499
130.10,159.45,0.499
130.12,159.63,0.499
130.14,159.81,0.500
130.16,160.00,0.500
130.18,160.18,0.500
130.19,160.36,0.500
130.21,160.55,0.501
130.23,160.73,0.501
130.25,160.91,0.501
130.27,161.10,0.501
130.29,161.28,0.501
130.30,161.47,0.501
130.32,161.65,0.502
130.34,161.83,0.502
130.36,162.02,0.502
130.38,162.20,0.502
130.40,162.38,0.502
130.41,162.57,0.502
130.43,162.75,0.502
130.45,162.93,0.502
130.47,163.12,0.502
130.49,163.30,0.502
130.50,163.48,0.502
130.52,163.67,0.502
130.54,163.85,0.502
130.56,164.04,0.502
130.58,164.22,0.502
130.60,164.40,0.502
130.61,164.59,0.501
130.63,164.77,0.501
130.65,164.95,0.501
130.67,165.14,0.501
130.69,165.32,0.501
130.71,165.50,0.501
130.73,165.69,0.501
130.74,165.87,0.501
130.76,166.05,0.501
130.78,166.24,0.501
130.80,166.42,0.501
130.82,166.61,0.501
130.84,166.79,0.501
130.85,166.97,0.501
130.87,167.16,0.501
130.89,167.34,0.501
130.91,167.52,0.501
130.93,167.71,0.501
130.95,167.89,0.501
130.96,168.07,0.502
130.98,168.26,0.502
131.00,168.44,0.502
131.02,168.62,0.502
131.04,168.81,0.502
131.05,168.99,0.502
131.07,169.17,0.502
131.09,169.35,0.503
131.11,169.54,0.503
131.13,169.72,0.503
131.15,169.90,0.504
131.16,170.09,0.504
131.18,170.27,0.504
131.20,170.46,0.504
131.22,170.64,0.505
131.24,170.82,0.505
131.26,171.01,0.505
131.28,171.19,0.505
131.29,171.37,0.506
131.31,171.56,0.506
131.33,171.74,0.506
131.35,171.92,0.506
131.37,172.11,0.506
131.39,172.29,0.507
131.40,172.47,0.507
131.42,172.66,0.507
131.44,172.84,0.507
131.46,173.02,0.507
131.48,173.21,0.508
131.50,173.39,0.508
131.51,173.57,0.508
131.53,173.76,0.508
131.55,173.94,0.508
131.57,174.12,0.509
131.59,174.31,0.509
131.60,174.49,0.509
131.62,174.67,0.509
131.64,174.86,0.509
131.66,175.04,0.509
131.68,175.23,0.509
131.70,175.41,0.509
131.71,175.59,0.509
131.73,175.78,0.509
131.75,175.96,0.509
131.77,176.14,0.509
131.79,176.33,0.509
131.81,176.51,0.508
131.83,176.69,0.508
131.84,176.88,0.508
131.86,177.06,0.507
131.88,177.24,0.507
131.90,177.43,0.507
131.92,177.61,0.506
131.94,177.80,0.505
131.95,177.98,0.505
131.97,178.16,0.504
131.99,178.35,0.504
132.01,178.53,0.503
132.03,178.72,0.503
132.05,178.90,0.502
132.06,179.08,0.502
132.08,179.27,0.501
132.10,179.45,0.500
132.12,179.63,0.500
132.14,179.82,0.499
132.15,180.00,0.498
132.17,180.19,0.497
132.19,180.37,0.496
132.21,180.55,0.496
132.23,180.74,0.495
132.25,180.92,0.495
132.26,181.11,0.494
132.28,181.29,0.494
132.30,181.47,0.493
132.32,181.66,0.493
132.34,181.84,0.492
132.36,182.02,0.492
132.38,182.21,0.492
132.39,182.39,0.491
132.41,182.58,0.491
132.43,182.76,0.490
132.45,182.94,0.490
132.47,183.13,0.489
132.49,183.31,0.489
132.50,183.49,0.489
132.52,183.68,0.489
132.54,183.86,0.488
132.56,184.04,0.488
132.58,184.23,0.488
132.60,184.41,0.488
132.61,184.60,0.488
132.63,184.78,0.488
132.65,184.96,0.487
132.67,185.15,0.487
132.69,185.33,0.487
132.70,185.51,0.487
132.72,185.70,0.488
132.74,185.88,0.488
132.76,186.06,0.487
132.78,186.25,0.488
132.80,186.43,0.488
132.81,186.61,0.488
132.83,186.80,0.488
132.85,186.98,0.488
132.87,187.16,0.488
132.89,187.35,0.488
132.91,187.53,0.489
132.93,187.71,0.489
132.94,187.90,0.489
132.96,188.08,0.489
132.98,188.26,0.489
133.00,188.45,0.489
133.02,188.63,0.489
133.04,188.81,0.489
133.05,189.00,0.490
133.07,189.18,0.490
133.09,189.36,0.490
133.11,189.55,0.490
133.13,189.73,0.490
133.15,189.91,0.491
133.16,190.10,0.491
133.18,190.28,0.491
133.20,190.46,0.491
133.22,190.65,0.491
133.24,190.83,0.492
133.25,191.01,0.492
133.27,191.20,0.492
133.29,191.38,0.492
133.31,191.56,0.493
133.33,191.75,0.493
133.35,191.93,0.493
133.36,192.11,0.493
133.38,192.30,0.494
133.40,192.48,0.494
133.42,192.66,0.494
133.44,192.85,0.494
133.46,193.03,0.494
133.48,193.21,0.495
133.49,193.40,0.495
133.51,193.58,0.495
133.53,193.76,0.495
133.55,193.95,0.496
133.57,194.13,0.496
133.59,194.31,0.496
133.60,194.50,0.496
133.62,194.68,0.497
133.64,194.86,0.497
133.66,195.05,0.497
133.68,195.23,0.497
133.70,195.41,0.497
133.71,195.60,0.498
133.73,195.78,0.498
133.75,195.96,0.498
133.77,196.15,0.498
133.79,196.33,0.499
133.80,196.51,0.499
133.82,196.70,0.499
133.84,196.88,0.499
133.86,197.06,0.499
133.88,197.25,0.500
133.90,197.43,0.500
133.91,197.61,0.500
133.93,197.80,
133.95,197.98,
133.97,198.16,
133.99,,