File: DSC/2025_04_11_CBD_Pro_MechanoChem_15min_10Cmin_n60C_150C.csv
Filename,2025_04_11_CBD_Pro_MechanoChem_15min_10Cmin_n60C_150C
Instrument name,DSC2A-00468 (192.168.1.100)
Operator,Yarger
rundate,4/11/2025
Sample name,2025_04_11_CBD_Pro_MechanoChem_15min_10Cmin_n60C_150C
proceduresegments,Data Off ; Equilibrate -60.00 °C; Data On ; Ramp 10.00 °C/min to 150.00 °C; Data Off ; Isothermal 1.0 min; Data On ; Ramp 10.00 °C/min to -60.00 °C; Data Off ; Isothermal 1.0 min; Data On ; Ramp 10.00 °C/min to 150.00 °C; Data Off ; Isothermal 1.0 min; Data On ; Ramp 10.00 °C/min to -60.00 °C; Data Off ; Isothermal 1.0 min; Data On ; Ramp 10.00 °C/min to 150.00 °C; Data Off
[File Parameters]
Run date,4/11/2025 5:52:01 PM
Trios version,5.1.1.46572
Original File Name,
Current File Name,D:\DSC2500\JYarger\2025_04_11_CBD_Pro_MechanoChem_15min_10Cmin_n60C_150C.tri
[Procedure]
Procedure Name,CBD_Pro_n60_150C_3x
Sample Name,2025_04_11_CBD_Pro_MechanoChem_15min_10Cmin_n60C_150C
Sample Mass,6.95 mg
Reference Sample Mass,0 mg
Pan Mass,53.94 mg
Pan Number,16
Reference Pan Mass,53.32 mg
Reference Pan Number,10
Pan Type,Tzero Aluminum Hermetic
Comments,Hermetic Sealed Al DSC Consumables Pan/Lids.
Project Name,CA
Operator,Yarger
Test,Custom
Unload Max Temperature,30
Unload Min Temperature,30
Load Max Temperature,30
Load Min Temperature,30
Stop on Gas Flow Error,Yes
[Signal List]
Signal #1,Time (min)
Signal #2,Temperature (°C)
Signal #3,Heat Flow (mW)
Signal #4,Delta T (µV)
Signal #5,Delta Tzero (µV)
Signal #6,Tzero Temperature (°C)
Signal #7,Cell Purge (mL/min)
Signal #8,Heater Temp (°C)
Signal #9,Power Delivered (W)
Signal #10,Reference Junction Temperature (°C)
Signal #11,Flange Temperature (°C)
Signal #12,Heat Flow Phase (rad)
Signal #13,Total Heat Capacity (J/°C)
Signal #14,Heat Capacity (J/°C)
[Configuration]
Company Name,ASU
Instrument Name,DSC2A-00468
Instrument Type,DSC2500
Serial Number,DSC2A-00468
IP,192.168.1.100
Location of Instrument,MRRC
DisplayType,Unknown
Sample Interval ,0.1 s/pt
Selected Heat Flow,T4P
Exotherm Direction,Down
Cell Serial,DRC2-00792
Lid Type,Standard
Cooler,RCS 90
Leave Cooler on at End of Sequence,On
Gas 2,Nitrogen
Gas Selected,Channel 1
Flow Rate,50 mL/min
Secondary Purge,On
Licensed Heat Flow,Heat Flow T4P
Modulation Licensed,Yes
[Versions]
Common IDD Version,1
Cortex Version,VER 2.10.2.31
Driver,5.0.0.6
GDM Version,1.0.3.3
TouchscreenVersion,1.0.0.16145
FEP Version,1.2.1.21
FEP Bootloader,2.0.0.5
AutoSampler Version,2.1.1.26
Auto Sampler Bootloader,2.0.0.5
FCM Version,1.1.0.3
FCM Bootloader,2.0.0.5
[Experiment Logs]
Experiment Log Entry # 1,Data On set to 0
Experiment Log Entry # 3,Equilibrate Segment -60 (C) Started
Experiment Log Entry # 5,Air Cool is off.
Experiment Log Entry # 7,Data On set to 1
Experiment Log Entry # 9,Ramp Segment 10 C/min to 150 Started
Experiment Log Entry # 11,Data On set to 0
Experiment Log Entry # 13,Isothermal Segment 1 min started
Experiment Log Entry # 15,Data On set to 1
Experiment Log Entry # 17,Ramp Segment 10 C/min to -60 Started
Experiment Log Entry # 19,Data On set to 0
Experiment Log Entry # 21,Isothermal Segment 1 min started
Experiment Log Entry # 23,Data On set to 1
Experiment Log Entry # 25,Ramp Segment 10 C/min to 150 Started
Experiment Log Entry # 27,Data On set to 0
Experiment Log Entry # 29,Isothermal Segment 1 min started
Experiment Log Entry # 31,Data On set to 1
Experiment Log Entry # 33,Ramp Segment 10 C/min to -60 Started
Experiment Log Entry # 35,Data On set to 0
Experiment Log Entry # 37,Isothermal Segment 1 min started
Experiment Log Entry # 39,Data On set to 1
Experiment Log Entry # 41,Ramp Segment 10 C/min to 150 Started
Experiment Log Entry # 43,Data On set to 0
[Method Log]
Method Log Entry # 1,Data Off
Method Log Entry # 2,Equilibrate -60 °C
Method Log Entry # 3,Data On
Method Log Entry # 4,(Ramp 13324) Ramp 10 °C/minute to 150 °C
Method Log Entry # 5,Data Off
Method Log Entry # 6,Isothermal 1 minutes
Method Log Entry # 7,Data On
Method Log Entry # 8,(Ramp 13328) Ramp 10 °C/minute to -60 °C
Method Log Entry # 9,Data Off
Method Log Entry # 10,Isothermal 1 minutes
Method Log Entry # 11,Data On
Method Log Entry # 12,(Ramp 13332) Ramp 10 °C/minute to 150 °C
Method Log Entry # 13,Data Off
Method Log Entry # 14,Isothermal 1 minutes
Method Log Entry # 15,Data On
Method Log Entry # 16,(Ramp 13336) Ramp 10 °C/minute to -60 °C
Method Log Entry # 17,Data Off
Method Log Entry # 18,Isothermal 1 minutes
Method Log Entry # 19,Data On
Method Log Entry # 20,(Ramp 13340) Ramp 10 °C/minute to 150 °C
Method Log Entry # 21,Data Off
Cell Serial,DRC2-00792
[T1 Calibration]
Slope,-0.008529666
Offset,9.636258
Initial Temperature,98.23
GUID,f8bfdadc-4977-4fdf-ba6d-0ba9134940c3
[TZero Calibration]
Date Applied,11/29/2022 4:06:13 PM
Description,From -89.059 °C to 396.009 °C at 20.000°C/min
Gas Type,Nitrogen
Pan Type,None
Source Files 1,C:\Users\yargerlab\Desktop\DSC Data\General\TZero_calibration_11_29_22_2nd(2).tri
Source Files 2,C:\Users\yargerlab\Desktop\DSC Data\General\TZero_calibration_11_29_22_2nd(3).tri
Delta T Offset,13.05235
Delta T Slope,-0.007271007
Delta T0 Offset,-13.69128
Delta T0 Slope,0.06063341
[Temperature Calibration]
Date Applied,11/29/2022 7:12:28 PM
Description,From 106.590 °C to 186.590 °C at 10.000°C/min
Gas Type,Nitrogen
Pan Type,Tzero Aluminum Hermetic
Source Files 1,C:\Users\yargerlab\Desktop\DSC Data\General\Indium(6).tri
Measured 1,157.391
Known 1,156.598
[Cell Constant Calibration]
Date Applied,11/29/2022 7:12:29 PM
Description,From 106.590 °C to 186.590 °C at 10.000°C/min
Gas Type,Nitrogen
Pan Type,Tzero Aluminum Hermetic
Source Files 1,C:\Users\yargerlab\Desktop\DSC Data\General\Indium(6).tri
T4P KCell,1.006051
Onset Slope,63.26126 mW/°C
[Direct Cp Calibration]
Date Applied,11/30/2022 11:04:51 AM
Description,From -79.983 °C to 298.409 °C at 10.000°C/min
Gas Type,Nitrogen
Pan Type,Tzero Aluminum Hermetic
Source Files 1,C:\Users\yargerlab\Desktop\DSC Data\General\Sapphire_Heat_Capacity_11_30_22.tri
[Rev Cp Calibration]
Date Applied,11/30/2022 1:58:51 PM
Description,From -79.996 °C to 292.812 °C at 3.000°C/min
Gas Type,Nitrogen
Pan Type,Tzero Aluminum Hermetic
Source Files 1,C:\Users\yargerlab\Desktop\DSC Data\General\Sapphire_MDSC_Calibration_11_30_22.tri
[step]
Ramp 10.00 °C/min to 150.00 °C
Time,Temperature,Heat Flow (Normalized)
min,°C,W/g
0.00,-59.69,-0.040
0.01,-59.70,-0.040
0.03,-59.71,-0.036
0.05,-59.71,-0.030
0.06,-59.71,-0.022
0.08,-59.70,-0.013
0.09,-59.67,-0.001
0.11,-59.63,0.011
0.12,-59.58,0.023
0.14,-59.52,0.036
0.15,-59.44,0.047
0.16,-59.35,0.060
0.18,-59.25,0.071
0.19,-59.15,0.082
0.21,-59.04,0.092
0.23,-58.92,0.102
0.24,-58.80,0.110
0.26,-58.68,0.118
0.27,-58.55,0.127
0.29,-58.43,0.134
0.30,-58.29,0.141
0.31,-58.16,0.146
0.33,-58.03,0.153
0.35,-57.89,0.157
0.36,-57.76,0.162
0.38,-57.62,0.166
0.39,-57.48,0.169
0.40,-57.34,0.174
0.42,-57.21,0.176
0.44,-57.06,0.179
0.45,-56.92,0.181
0.46,-56.78,0.184
0.48,-56.64,0.186
0.50,-56.50,0.187
0.51,-56.36,0.189
0.53,-56.21,0.191
0.54,-56.07,0.192
0.55,-55.92,0.194
0.57,-55.78,0.194
0.58,-55.64,0.195
0.60,-55.49,0.197
0.62,-55.34,0.197
0.63,-55.20,0.198
0.65,-55.05,0.198
0.66,-54.91,0.199
0.68,-54.76,0.199
0.69,-54.61,0.199
0.70,-54.47,0.199
0.72,-54.32,0.200
0.73,-54.18,0.200
0.75,-54.03,0.201
0.77,-53.88,0.201
0.78,-53.74,0.201
0.80,-53.59,0.201
0.81,-53.44,0.202
0.83,-53.29,0.202
0.84,-53.14,0.202
0.85,-53.00,0.203
0.87,-52.85,0.203
0.88,-52.70,0.203
0.90,-52.55,0.203
0.92,-52.40,0.204
0.93,-52.26,0.204
0.95,-52.11,0.204
0.96,-51.96,0.204
0.98,-51.81,0.204
0.99,-51.67,0.205
1.00,-51.52,0.205
1.02,-51.37,0.205
1.03,-51.22,0.205
1.05,-51.07,0.205
1.07,-50.92,0.205
1.08,-50.77,0.206
1.09,-50.63,0.206
1.11,-50.48,0.206
1.13,-50.33,0.206
1.14,-50.18,0.206
1.16,-50.03,0.207
1.17,-49.88,0.207
1.18,-49.73,0.207
1.20,-49.58,0.207
1.22,-49.43,0.207
1.23,-49.29,0.207
1.24,-49.14,0.207
1.26,-48.99,0.207
1.28,-48.84,0.208
1.29,-48.69,0.208
1.31,-48.54,0.208
1.32,-48.39,0.208
1.33,-48.24,0.208
1.35,-48.09,0.208
1.37,-47.94,0.208
1.38,-47.79,0.208
1.39,-47.64,0.208
1.41,-47.49,0.209
1.43,-47.34,0.209
1.44,-47.19,0.209
1.46,-47.04,0.209
1.47,-46.89,0.209
1.48,-46.74,0.209
1.50,-46.59,0.209
1.52,-46.45,0.209
1.53,-46.30,0.209
1.54,-46.15,0.209
1.56,-46.00,0.210
1.58,-45.85,0.210
1.59,-45.70,0.210
1.61,-45.55,0.210
1.62,-45.40,0.210
1.63,-45.25,0.210
1.65,-45.10,0.210
1.67,-44.95,0.210
1.68,-44.80,0.210
1.69,-44.65,0.210
1.71,-44.50,0.210
1.73,-44.35,0.211
1.74,-44.20,0.211
1.76,-44.05,0.211
1.77,-43.90,0.211
1.78,-43.75,0.211
1.80,-43.60,0.211
1.82,-43.45,0.211
1.83,-43.30,0.211
1.84,-43.15,0.211
1.86,-43.00,0.211
1.88,-42.85,0.211
1.89,-42.70,0.211
1.91,-42.55,0.212
1.92,-42.40,0.212
1.93,-42.25,0.212
1.95,-42.10,0.212
1.97,-41.95,0.212
1.98,-41.80,0.212
1.99,-41.65,0.212
2.01,-41.50,0.212
2.03,-41.35,0.212
2.04,-41.20,0.212
2.06,-41.05,0.212
2.07,-40.90,0.212
2.08,-40.75,0.213
2.10,-40.60,0.213
2.12,-40.45,0.213
2.13,-40.30,0.213
2.14,-40.15,0.213
2.16,-40.00,0.213
2.18,-39.85,0.213
2.19,-39.69,0.213
2.21,-39.55,0.213
2.22,-39.40,0.213
2.24,-39.25,0.213
2.25,-39.10,0.213
2.26,-38.94,0.213
2.28,-38.79,0.213
2.29,-38.64,0.213
2.31,-38.49,0.214
2.33,-38.35,0.214
2.34,-38.19,0.214
2.36,-38.04,0.214
2.37,-37.89,0.214
2.39,-37.74,0.214
2.40,-37.59,0.214
2.41,-37.44,0.214
2.43,-37.29,0.214
2.44,-37.14,0.214
2.46,-36.99,0.214
2.48,-36.84,0.214
2.49,-36.69,0.214
2.51,-36.54,0.215
2.52,-36.39,0.215
2.54,-36.24,0.215
2.55,-36.09,0.215
2.56,-35.94,0.215
2.58,-35.79,0.215
2.59,-35.64,0.215
2.61,-35.49,0.215
2.63,-35.34,0.215
2.64,-35.19,0.215
2.66,-35.04,0.215
2.67,-34.89,0.215
2.69,-34.74,0.215
2.70,-34.59,0.215
2.71,-34.44,0.215
2.73,-34.29,0.215
2.74,-34.14,0.215
2.76,-33.99,0.216
2.78,-33.84,0.216
2.79,-33.69,0.216
2.81,-33.54,0.216
2.82,-33.39,0.216
2.84,-33.24,0.216
2.85,-33.09,0.216
2.86,-32.94,0.216
2.88,-32.79,0.216
2.89,-32.64,0.216
2.91,-32.49,0.216
2.93,-32.34,0.216
2.94,-32.19,0.216
2.96,-32.04,0.216
2.97,-31.89,0.216
2.99,-31.74,0.217
3.00,-31.59,0.217
3.01,-31.44,0.217
3.03,-31.29,0.217
3.04,-31.14,0.217
3.06,-30.99,0.217
3.08,-30.84,0.217
3.09,-30.69,0.217
3.11,-30.54,0.217
3.12,-30.38,0.217
3.14,-30.23,0.217
3.15,-30.08,0.217
3.16,-29.93,0.217
3.18,-29.78,0.218
3.19,-29.63,0.218
3.21,-29.48,0.218
3.23,-29.33,0.218
3.24,-29.18,0.218
3.26,-29.03,0.218
3.27,-28.88,0.218
3.29,-28.73,0.218
3.30,-28.58,0.218
3.31,-28.43,0.218
3.33,-28.28,0.218
3.34,-28.13,0.218
3.36,-27.98,0.219
3.38,-27.83,0.219
3.39,-27.68,0.219
3.41,-27.53,0.219
3.42,-27.38,0.219
3.44,-27.23,0.219
3.45,-27.08,0.219
3.46,-26.93,0.219
3.48,-26.78,0.219
3.49,-26.63,0.219
3.51,-26.48,0.219
3.53,-26.33,0.219
3.54,-26.18,0.219
3.56,-26.03,0.219
3.57,-25.88,0.219
3.59,-25.73,0.220
3.60,-25.58,0.220
3.61,-25.43,0.220
3.63,-25.28,0.220
3.64,-25.13,0.220
3.66,-24.98,0.220
3.68,-24.83,0.220
3.69,-24.68,0.220
3.71,-24.53,0.220
3.72,-24.38,0.220
3.74,-24.23,0.220
3.75,-24.08,0.220
3.76,-23.93,0.220
3.78,-23.78,0.221
3.79,-23.63,0.221
3.81,-23.48,0.221
3.83,-23.32,0.221
3.84,-23.17,0.221
3.86,-23.02,0.221
3.87,-22.87,0.221
3.89,-22.73,0.221
3.90,-22.57,0.221
3.91,-22.43,0.221
3.93,-22.27,0.221
3.94,-22.12,0.221
3.96,-21.97,0.222
3.98,-21.82,0.222
3.99,-21.67,0.222
4.01,-21.52,0.222
4.02,-21.37,0.222
4.04,-21.22,0.222
4.05,-21.07,0.222
4.06,-20.92,0.222
4.08,-20.77,0.222
4.09,-20.62,0.222
4.11,-20.47,0.222
4.13,-20.32,0.223
4.14,-20.17,0.223
4.16,-20.02,0.223
4.17,-19.87,0.223
4.19,-19.72,0.223
4.20,-19.57,0.223
4.21,-19.42,0.223
4.23,-19.27,0.223
4.24,-19.12,0.223
4.26,-18.97,0.223
4.28,-18.82,0.223
4.29,-18.67,0.223
4.30,-18.52,0.224
4.32,-18.37,0.224
4.34,-18.22,0.224
4.35,-18.07,0.224
4.36,-17.92,0.224
4.38,-17.77,0.224
4.40,-17.62,0.224
4.41,-17.47,0.224
4.43,-17.32,0.224
4.44,-17.17,0.224
4.45,-17.02,0.224
4.47,-16.87,0.224
4.49,-16.72,0.225
4.50,-16.57,0.225
4.51,-16.42,0.225
4.53,-16.27,0.225
4.55,-16.12,0.225
4.56,-15.97,0.225
4.58,-15.82,0.225
4.59,-15.67,0.225
4.60,-15.52,0.225
4.62,-15.37,0.225
4.64,-15.22,0.225
4.65,-15.07,0.225
4.66,-14.91,0.226
4.68,-14.77,0.226
4.70,-14.61,0.226
4.71,-14.47,0.226
4.73,-14.31,0.226
4.74,-14.16,0.226
4.75,-14.01,0.226
4.77,-13.86,0.226
4.79,-13.71,0.226
4.80,-13.56,0.226
4.81,-13.41,0.226
4.83,-13.26,0.226
4.85,-13.11,0.227
4.86,-12.96,0.227
4.88,-12.81,0.227
4.89,-12.66,0.227
4.90,-12.51,0.227
4.92,-12.36,0.227
4.94,-12.21,0.227
4.95,-12.06,0.227
4.96,-11.91,0.227
4.98,-11.76,0.228
5.00,-11.61,0.228
5.01,-11.46,0.228
5.03,-11.31,0.228
5.04,-11.16,0.228
5.05,-11.01,0.228
5.07,-10.86,0.228
5.09,-10.71,0.228
5.10,-10.56,0.228
5.11,-10.41,0.228
5.13,-10.26,0.228
5.15,-10.11,0.228
5.16,-9.96,0.229
5.18,-9.81,0.229
5.19,-9.66,0.229
5.20,-9.51,0.229
5.22,-9.36,0.229
5.24,-9.21,0.229
5.25,-9.06,0.229
5.26,-8.91,0.229
5.28,-8.76,0.229
5.30,-8.61,0.229
5.31,-8.46,0.230
5.33,-8.31,0.230
5.34,-8.16,0.230
5.35,-8.01,0.230
5.37,-7.86,0.230
5.39,-7.71,0.230
5.40,-7.56,0.230
5.41,-7.41,0.230
5.43,-7.26,0.230
5.45,-7.11,0.231
5.46,-6.96,0.231
5.48,-6.81,0.231
5.49,-6.66,0.231
5.50,-6.51,0.231
5.52,-6.36,0.231
5.54,-6.21,0.231
5.55,-6.05,0.231
5.56,-5.91,0.231
5.58,-5.76,0.232
5.60,-5.61,0.232
5.61,-5.46,0.232
5.63,-5.31,0.232
5.64,-5.15,0.232
5.65,-5.01,0.232
5.67,-4.85,0.232
5.69,-4.70,0.232
5.70,-4.55,0.232
5.71,-4.41,0.232
5.73,-4.26,0.232
5.75,-4.10,0.232
5.76,-3.96,0.233
5.78,-3.80,0.233
5.79,-3.65,0.233
5.80,-3.50,0.233
5.82,-3.35,0.233
5.84,-3.20,0.233
5.85,-3.05,0.233
5.86,-2.90,0.233
5.88,-2.75,0.233
5.90,-2.60,0.233
5.91,-2.45,0.233
5.93,-2.30,0.234
5.94,-2.15,0.234
5.95,-2.00,0.234
5.97,-1.85,0.234
5.99,-1.70,0.234
6.00,-1.55,0.234
6.01,-1.40,0.234
6.03,-1.25,0.234
6.05,-1.10,0.234
6.06,-0.95,0.234
6.08,-0.80,0.235
6.09,-0.65,0.235
6.10,-0.50,0.235
6.12,-0.35,0.235
6.14,-0.20,0.235
6.15,-0.05,0.235
6.16,0.10,0.235
6.18,0.25,0.235
6.20,0.40,0.235
6.21,0.55,0.235
6.23,0.70,0.236
6.24,0.85,0.236
6.25,1.00,0.236
6.27,1.15,0.236
6.29,1.30,0.236
6.30,1.45,0.236
6.31,1.60,0.236
6.33,1.75,0.236
6.35,1.90,0.236
6.36,2.05,0.236
6.38,2.20,0.236
6.39,2.35,0.237
6.40,2.50,0.237
6.42,2.65,0.237
6.44,2.80,0.237
6.45,2.95,0.237
6.46,3.10,0.237
6.48,3.25,0.237
6.50,3.41,0.237
6.51,3.55,0.237
6.53,3.71,0.237
6.54,3.86,0.237
6.55,4.01,0.238
6.57,4.16,0.238
6.59,4.31,0.238
6.60,4.46,0.238
6.61,4.61,0.238
6.63,4.76,0.238
6.65,4.91,0.238
6.66,5.06,0.238
6.68,5.21,0.238
6.69,5.36,0.238
6.70,5.51,0.239
6.72,5.66,0.239
6.74,5.81,0.239
6.75,5.96,0.239
6.76,6.11,0.239
6.78,6.26,0.239
6.80,6.41,0.239
6.81,6.56,0.239
6.83,6.71,0.239
6.84,6.86,0.240
6.85,7.01,0.240
6.87,7.16,0.240
6.89,7.31,0.240
6.90,7.46,0.240
6.91,7.61,0.240
6.93,7.76,0.240
6.95,7.91,0.240
6.96,8.06,0.240
6.98,8.21,0.240
6.99,8.36,0.241
7.00,8.51,0.241
7.02,8.66,0.241
7.04,8.81,0.241
7.05,8.96,0.241
7.06,9.11,0.241
7.08,9.26,0.241
7.10,9.41,0.241
7.11,9.56,0.241
7.13,9.71,0.242
7.14,9.86,0.242
7.15,10.01,0.242
7.17,10.16,0.242
7.19,10.31,0.242
7.20,10.46,0.242
7.21,10.61,0.242
7.23,10.77,0.242
7.25,10.91,0.243
7.26,11.06,0.243
7.28,11.21,0.243
7.29,11.36,0.243
7.30,11.51,0.243
7.32,11.66,0.243
7.34,11.82,0.243
7.35,11.97,0.243
7.36,12.11,0.243
7.38,12.27,0.244
7.40,12.42,0.244
7.41,12.57,0.244
7.43,12.72,0.244
7.44,12.87,0.244
7.45,13.02,0.244
7.47,13.17,0.244
7.49,13.32,0.244
7.50,13.47,0.244
7.51,13.62,0.245
7.53,13.77,0.245
7.55,13.92,0.245
7.56,14.07,0.245
7.58,14.22,0.245
7.59,14.37,0.245
7.60,14.52,0.245
7.62,14.67,0.245
7.64,14.82,0.246
7.65,14.97,0.246
7.66,15.12,0.246
7.68,15.27,0.246
7.70,15.42,0.246
7.71,15.57,0.246
7.73,15.72,0.246
7.74,15.87,0.246
7.75,16.02,0.247
7.77,16.17,0.247
7.79,16.32,0.247
7.80,16.47,0.247
7.81,16.62,0.247
7.83,16.77,0.247
7.85,16.92,0.247
7.86,17.07,0.247
7.88,17.22,0.247
7.89,17.37,0.248
7.90,17.52,0.248
7.92,17.67,0.248
7.94,17.82,0.248
7.95,17.97,0.248
7.96,18.12,0.248
7.98,18.27,0.248
8.00,18.42,0.249
8.01,18.57,0.249
8.03,18.72,0.249
8.04,18.87,0.249
8.05,19.02,0.249
8.07,19.17,0.249
8.09,19.32,0.249
8.10,19.47,0.249
8.11,19.62,0.250
8.13,19.77,0.250
8.15,19.92,0.250
8.16,20.07,0.250
8.18,20.22,0.250
8.19,20.37,0.250
8.20,20.52,0.250
8.22,20.67,0.250
8.24,20.83,0.251
8.25,20.97,0.251
8.26,21.13,0.251
8.28,21.27,0.251
8.30,21.43,0.251
8.31,21.57,0.251
8.33,21.72,0.251
8.34,21.87,0.251
8.35,22.03,0.252
8.37,22.17,0.252
8.39,22.33,0.252
8.40,22.47,0.252
8.41,22.63,0.252
8.43,22.77,0.252
8.45,22.93,0.252
8.46,23.08,0.252
8.48,23.23,0.253
8.49,23.38,0.253
8.50,23.53,0.253
8.52,23.68,0.253
8.53,23.83,0.253
8.55,23.98,0.253
8.57,24.13,0.253
8.58,24.28,0.254
8.60,24.43,0.254
8.61,24.58,0.254
8.63,24.73,0.254
8.64,24.88,0.254
8.65,25.03,0.254
8.67,25.18,0.254
8.68,25.33,0.254
8.70,25.48,0.255
8.72,25.63,0.255
8.73,25.78,0.255
8.75,25.93,0.255
8.76,26.08,0.255
8.78,26.23,0.256
8.79,26.38,0.256
8.80,26.53,0.256
8.82,26.68,0.256
8.83,26.83,0.256
8.85,26.98,0.256
8.87,27.13,0.256
8.88,27.28,0.257
8.90,27.43,0.257
8.91,27.58,0.257
8.93,27.73,0.257
8.94,27.88,0.257
8.95,28.03,0.257
8.97,28.18,0.257
8.98,28.33,0.257
9.00,28.48,0.257
9.02,28.63,0.258
9.03,28.78,0.258
9.05,28.93,0.258
9.06,29.08,0.258
9.08,29.23,0.258
9.09,29.38,0.258
9.10,29.53,0.258
9.12,29.68,0.258
9.13,29.83,0.259
9.15,29.98,0.259
9.17,30.13,0.259
9.18,30.28,0.259
9.20,30.43,0.259
9.21,30.58,0.259
9.23,30.73,0.259
9.24,30.88,0.260
9.25,31.04,0.260
9.27,31.19,0.260
9.28,31.34,0.260
9.30,31.48,0.260
9.32,31.64,0.260
9.33,31.79,0.260
9.35,31.94,0.260
9.36,32.09,0.260
9.38,32.24,0.261
9.39,32.39,0.261
9.40,32.54,0.261
9.42,32.69,0.261
9.43,32.84,0.261
9.45,32.99,0.261
9.47,33.14,0.261
9.48,33.29,0.261
9.50,33.44,0.262
9.51,33.59,0.262
9.53,33.74,0.262
9.54,33.89,0.262
9.55,34.04,0.262
9.57,34.19,0.262
9.58,34.34,0.262
9.60,34.49,0.263
9.62,34.64,0.263
9.63,34.79,0.263
9.65,34.94,0.263
9.66,35.09,0.263
9.68,35.24,0.263
9.69,35.39,0.263
9.70,35.54,0.263
9.72,35.69,0.264
9.73,35.84,0.264
9.75,35.99,0.264
9.77,36.14,0.264
9.78,36.29,0.264
9.80,36.44,0.264
9.81,36.59,0.264
9.83,36.74,0.264
9.84,36.89,0.265
9.85,37.04,0.265
9.87,37.19,0.265
9.88,37.34,0.265
9.90,37.49,0.265
9.92,37.64,0.265
9.93,37.79,0.265
9.95,37.94,0.266
9.96,38.09,0.266
9.98,38.24,0.266
9.99,38.39,0.266
10.00,38.54,0.266
10.02,38.69,0.266
10.03,38.84,0.266
10.05,38.99,0.266
10.07,39.14,0.267
10.08,39.29,0.267
10.10,39.44,0.267
10.11,39.59,0.267
10.13,39.74,0.267
10.14,39.89,0.267
10.15,40.04,0.268
10.17,40.19,0.268
10.18,40.34,0.268
10.20,40.49,0.268
10.22,40.64,0.268
10.23,40.79,0.268
10.25,40.94,0.268
10.26,41.09,0.268
10.28,41.24,0.269
10.29,41.40,0.269
10.30,41.54,0.269
10.32,41.69,0.269
10.33,41.84,0.269
10.35,41.99,0.269
10.37,42.14,0.269
10.38,42.29,0.270
10.40,42.45,0.270
10.41,42.60,0.270
10.43,42.75,0.270
10.44,42.89,0.270
10.45,43.05,0.270
10.47,43.20,0.270
10.48,43.35,0.271
10.50,43.50,0.271
10.52,43.65,0.271
10.53,43.80,0.271
10.55,43.95,0.271
10.56,44.10,0.271
10.58,44.25,0.271
10.59,44.40,0.272
10.60,44.55,0.272
10.62,44.70,0.272
10.63,44.85,0.272
10.65,45.00,0.272
10.67,45.15,0.272
10.68,45.30,0.273
10.70,45.45,0.273
10.71,45.60,0.273
10.73,45.75,0.273
10.74,45.90,0.273
10.75,46.05,0.273
10.77,46.20,0.273
10.78,46.35,0.274
10.80,46.50,0.274
10.82,46.65,0.274
10.83,46.80,0.274
10.85,46.95,0.274
10.86,47.10,0.274
10.88,47.25,0.275
10.89,47.40,0.275
10.90,47.55,0.275
10.92,47.70,0.275
10.93,47.85,0.275
10.95,48.00,0.275
10.97,48.15,0.275
10.98,48.30,0.276
11.00,48.45,0.276
11.01,48.60,0.276
11.03,48.75,0.276
11.04,48.90,0.276
11.05,49.05,0.277
11.07,49.20,0.277
11.08,49.35,0.277
11.10,49.50,0.277
11.12,49.65,0.277
11.13,49.80,0.277
11.15,49.95,0.278
11.16,50.10,0.278
11.18,50.25,0.278
11.19,50.40,0.278
11.20,50.55,0.278
11.22,50.70,0.278
11.23,50.85,0.279
11.25,51.00,0.279
11.27,51.15,0.279
11.28,51.30,0.279
11.30,51.45,0.279
11.31,51.60,0.279
11.33,51.75,0.280
11.34,51.90,0.280
11.35,52.05,0.280
11.37,52.20,0.280
11.38,52.35,0.280
11.40,52.50,0.281
11.42,52.65,0.281
11.43,52.80,0.281
11.45,52.95,0.281
11.46,53.10,0.281
11.48,53.25,0.282
11.49,53.40,0.282
11.50,53.56,0.282
11.52,53.70,0.282
11.53,53.85,0.283
11.55,54.00,0.283
11.57,54.16,0.283
11.58,54.31,0.283
11.60,54.46,0.283
11.61,54.61,0.284
11.63,54.76,0.284
11.64,54.91,0.284
11.65,55.06,0.284
11.67,55.21,0.284
11.68,55.35,0.285
11.70,55.51,0.285
11.72,55.66,0.285
11.73,55.81,0.285
11.75,55.96,0.286
11.76,56.11,0.286
11.78,56.26,0.286
11.79,56.41,0.287
11.80,56.56,0.287
11.82,56.71,0.287
11.83,56.86,0.287
11.85,57.01,0.288
11.87,57.16,0.288
11.88,57.31,0.289
11.90,57.46,0.289
11.91,57.61,0.289
11.93,57.76,0.290
11.94,57.91,0.290
11.95,58.06,0.290
11.97,58.21,0.291
11.98,58.36,0.291
12.00,58.51,0.291
12.02,58.66,0.291
12.03,58.81,0.292
12.05,58.95,0.292
12.06,59.11,0.293
12.08,59.26,0.294
12.09,59.40,0.294
12.10,59.56,0.294
12.12,59.71,0.296
12.13,59.85,0.296
12.15,60.01,0.297
12.17,60.16,0.297
12.18,60.31,0.298
12.20,60.46,0.299
12.21,60.60,0.299
12.23,60.75,0.300
12.24,60.90,0.302
12.25,61.05,0.303
12.27,61.20,0.305
12.28,61.35,0.306
12.30,61.50,0.308
12.32,61.65,0.309
12.33,61.80,0.311
12.35,61.95,0.313
12.36,62.10,0.314
12.38,62.25,0.318
12.39,62.40,0.321
12.40,62.55,0.323
12.42,62.70,0.327
12.43,62.85,0.330
12.45,63.00,0.334
12.47,63.15,0.340
12.48,63.29,0.346
12.50,63.44,0.351
12.51,63.59,0.358
12.53,63.74,0.367
12.54,63.89,0.377
12.55,64.03,0.387
12.57,64.18,0.399
12.58,64.32,0.413
12.60,64.47,0.429
12.62,64.61,0.448
12.63,64.76,0.467
12.65,64.90,0.489
12.66,65.04,0.514
12.68,65.18,0.540
12.69,65.32,0.569
12.70,65.46,0.595
12.72,65.60,0.625
12.73,65.74,0.653
12.75,65.88,0.682
12.77,66.01,0.710
12.78,66.15,0.738
12.80,66.29,0.766
12.81,66.43,0.794
12.83,66.56,0.820
12.84,66.70,0.846
12.85,66.84,0.869
12.87,66.98,0.890
12.88,67.12,0.910
12.90,67.25,0.928
12.92,67.39,0.950
12.93,67.53,0.967
12.95,67.67,0.983
12.96,67.82,0.998
12.98,67.96,1.009
12.99,68.10,1.022
13.00,68.24,1.035
13.02,68.39,1.049
13.03,68.53,1.062
13.05,68.67,1.076
13.07,68.82,1.085
13.08,68.96,1.095
13.10,69.10,1.102
13.11,69.25,1.110
13.13,69.39,1.116
13.14,69.54,1.122
13.15,69.69,1.124
13.17,69.84,1.127
13.18,69.98,1.127
13.20,70.13,1.128
13.22,70.28,1.129
13.23,70.43,1.129
13.25,70.58,1.129
13.26,70.73,1.128
13.28,70.88,1.127
13.29,71.03,1.123
13.30,71.18,1.119
13.32,71.33,1.112
13.33,71.48,1.102
13.35,71.64,1.090
13.37,71.79,1.074
13.38,71.94,1.057
13.40,72.10,1.036
13.41,72.26,1.008
13.43,72.42,0.975
13.44,72.58,0.938
13.45,72.74,0.897
13.47,72.91,0.855
13.48,73.07,0.813
13.50,73.24,0.766
13.52,73.41,0.725
13.53,73.57,0.692
13.55,73.74,0.655
13.56,73.91,0.621
13.58,74.08,0.591
13.59,74.24,0.567
13.60,74.41,0.542
13.62,74.57,0.521
13.63,74.73,0.502
13.65,74.89,0.485
13.67,75.06,0.469
13.68,75.22,0.455
13.70,75.37,0.443
13.71,75.53,0.432
13.73,75.69,0.422
13.74,75.85,0.414
13.75,76.00,0.405
13.77,76.16,0.397
13.78,76.31,0.392
13.80,76.47,0.386
13.82,76.62,0.382
13.83,76.78,0.375
13.85,76.93,0.373
13.86,77.08,0.369
13.88,77.24,0.366
13.89,77.39,0.363
13.90,77.54,0.361
13.92,77.69,0.359
13.93,77.85,0.356
13.95,78.00,0.354
13.97,78.15,0.353
13.98,78.30,0.352
14.00,78.45,0.351
14.01,78.60,0.350
14.03,78.75,0.349
14.04,78.90,0.348
14.05,79.06,0.348
14.07,79.21,0.347
14.08,79.36,0.347
14.10,79.51,0.346
14.12,79.66,0.346
14.13,79.81,0.345
14.15,79.96,0.345
14.16,80.11,0.344
14.18,80.26,0.344
14.19,80.41,0.344
14.20,80.56,0.343
14.22,80.71,0.343
14.23,80.86,0.343
14.25,81.01,0.343
14.27,81.16,0.343
14.28,81.31,0.343
14.30,81.46,0.342
14.31,81.61,0.342
14.33,81.76,0.342
14.34,81.91,0.342
14.35,82.06,0.342
14.37,82.21,0.342
14.38,82.37,0.342
14.40,82.51,0.341
14.42,82.66,0.341
14.43,82.81,0.341
14.45,82.97,0.341
14.46,83.11,0.341
14.48,83.27,0.341
14.49,83.42,0.341
14.50,83.56,0.341
14.52,83.72,0.341
14.53,83.87,0.341
14.55,84.02,0.341
14.57,84.17,0.341
14.58,84.32,0.341
14.60,84.47,0.340
14.61,84.62,0.340
14.63,84.77,0.340
14.64,84.92,0.340
14.65,85.07,0.340
14.67,85.22,0.340
14.68,85.37,0.340
14.70,85.52,0.340
14.72,85.67,0.340
14.73,85.82,0.340
14.75,85.97,0.340
14.76,86.12,0.340
14.78,86.27,0.340
14.79,86.42,0.340
14.80,86.57,0.340
14.82,86.72,0.340
14.83,86.87,0.340
14.85,87.02,0.340
14.87,87.17,0.340
14.88,87.32,0.340
14.90,87.47,0.340
14.91,87.62,0.340
14.93,87.77,0.340
14.94,87.92,0.340
14.95,88.07,0.340
14.97,88.22,0.340
14.98,88.37,0.340
15.00,88.52,0.340
15.02,88.67,0.340
15.03,88.82,0.340
15.05,88.97,0.340
15.06,89.12,0.340
15.08,89.27,0.340
15.09,89.42,0.340
15.10,89.57,0.340
15.12,89.72,0.340
15.13,89.87,0.340
15.15,90.02,0.340
15.17,90.17,0.340
15.18,90.32,0.340
15.20,90.47,0.340
15.21,90.62,0.340
15.23,90.78,0.340
15.24,90.92,0.340
15.25,91.07,0.340
15.27,91.22,0.340
15.28,91.38,0.340
15.30,91.53,0.340
15.32,91.68,0.340
15.33,91.83,0.339
15.35,91.98,0.339
15.36,92.13,0.339
15.38,92.28,0.339
15.39,92.43,0.339
15.40,92.58,0.339
15.42,92.73,0.339
15.43,92.88,0.339
15.45,93.03,0.339
15.47,93.18,0.339
15.48,93.33,0.339
15.50,93.48,0.339
15.51,93.63,0.338
15.53,93.78,0.338
15.54,93.93,0.338
15.55,94.08,0.338
15.57,94.23,0.338
15.58,94.38,0.338
15.60,94.53,0.338
15.62,94.68,0.337
15.63,94.83,0.337
15.65,94.98,0.337
15.66,95.13,0.336
15.68,95.28,0.336
15.69,95.43,0.336
15.70,95.58,0.335
15.72,95.73,0.335
15.73,95.88,0.335
15.75,96.03,0.334
15.77,96.19,0.334
15.78,96.34,0.333
15.80,96.49,0.333
15.81,96.64,0.333
15.83,96.79,0.332
15.84,96.94,0.332
15.85,97.09,0.331
15.87,97.24,0.330
15.88,97.39,0.329
15.90,97.54,0.328
15.92,97.69,0.328
15.93,97.84,0.327
15.95,97.99,0.326
15.96,98.14,0.325
15.98,98.29,0.323
15.99,98.44,0.323
16.00,98.59,0.322
16.02,98.74,0.321
16.03,98.89,0.321
16.05,99.04,0.320
16.07,99.20,0.319
16.08,99.35,0.318
16.10,99.50,0.317
16.11,99.65,0.316
16.13,99.80,0.316
16.14,99.95,0.314
16.15,100.10,0.312
16.17,100.25,0.311
16.18,100.40,0.309
16.20,100.55,0.308
16.22,100.70,0.306
16.23,100.85,0.305
16.25,101.00,0.304
16.26,101.15,0.302
16.28,101.31,0.300
16.29,101.46,0.299
16.30,101.61,0.297
16.32,101.76,0.295
16.33,101.91,0.293
16.35,102.06,0.292
16.37,102.21,0.290
16.38,102.36,0.289
16.40,102.51,0.287
16.41,102.66,0.285
16.43,102.81,0.283
16.44,102.97,0.281
16.45,103.11,0.279
16.47,103.27,0.277
16.48,103.42,0.275
16.50,103.57,0.273
16.52,103.72,0.270
16.53,103.87,0.268
16.55,104.02,0.267
16.56,104.17,0.264
16.58,104.32,0.263
16.59,104.47,0.261
16.60,104.63,0.258
16.62,104.78,0.256
16.63,104.93,0.254
16.65,105.08,0.252
16.67,105.23,0.250
16.68,105.38,0.248
16.70,105.53,0.244
16.71,105.68,0.243
16.73,105.83,0.241
16.74,105.99,0.238
16.75,106.14,0.236
16.77,106.29,0.235
16.78,106.44,0.232
16.80,106.59,0.231
16.82,106.74,0.227
16.83,106.89,0.226
16.85,107.04,0.224
16.86,107.19,0.222
16.88,107.35,0.220
16.89,107.50,0.218
16.90,107.65,0.217
16.92,107.80,0.214
16.93,107.95,0.214
16.95,108.10,0.211
16.97,108.25,0.210
16.98,108.40,0.207
17.00,108.55,0.207
17.01,108.71,0.204
17.03,108.86,0.203
17.04,109.01,0.202
17.05,109.16,0.200
17.07,109.31,0.199
17.08,109.46,0.198
17.10,109.61,0.196
17.12,109.76,0.196
17.13,109.91,0.195
17.14,110.06,0.194
17.16,110.21,0.192
17.18,110.36,0.192
17.19,110.51,0.191
17.21,110.67,0.190
17.22,110.82,0.190
17.23,110.97,0.189
17.25,111.12,0.189
17.27,111.27,0.188
17.28,111.42,0.187
17.29,111.57,0.187
17.31,111.72,0.187
17.33,111.87,0.186
17.34,112.02,0.186
17.36,112.17,0.186
17.37,112.32,0.185
17.38,112.47,0.185
17.40,112.62,0.185
17.42,112.77,0.185
17.43,112.92,0.184
17.44,113.07,0.184
17.46,113.22,0.184
17.48,113.37,0.184
17.49,113.52,0.184
17.51,113.67,0.184
17.52,113.82,0.183
17.53,113.97,0.183
17.55,114.12,0.183
17.57,114.27,0.183
17.58,114.42,0.183
17.59,114.57,0.183
17.61,114.72,0.183
17.63,114.87,0.183
17.64,115.02,0.183
17.66,115.17,0.183
17.67,115.32,0.184
17.68,115.47,0.184
17.70,115.62,0.184
17.72,115.77,0.184
17.73,115.92,0.184
17.74,116.07,0.185
17.76,116.22,0.185
17.78,116.37,0.186
17.79,116.52,0.187
17.81,116.67,0.188
17.82,116.82,0.188
17.83,116.97,0.189
17.85,117.12,0.189
17.87,117.27,0.190
17.88,117.42,0.190
17.89,117.57,0.190
17.91,117.72,0.192
17.93,117.87,0.193
17.94,118.02,0.194
17.96,118.17,0.195
17.97,118.32,0.197
17.98,118.47,0.198
18.00,118.62,0.199
18.02,118.77,0.201
18.03,118.92,0.202
18.04,119.06,0.204
18.06,119.22,0.206
18.08,119.36,0.207
18.09,119.51,0.209
18.11,119.66,0.210
18.12,119.81,0.211
18.13,119.96,0.213
18.15,120.11,0.215
18.17,120.26,0.216
18.18,120.41,0.217
18.19,120.56,0.219
18.21,120.71,0.220
18.23,120.86,0.222
18.24,121.01,0.223
18.26,121.16,0.225
18.27,121.31,0.226
18.28,121.46,0.229
18.30,121.61,0.230
18.32,121.76,0.231
18.33,121.91,0.233
18.34,122.06,0.235
18.36,122.21,0.236
18.38,122.36,0.238
18.39,122.51,0.240
18.41,122.65,0.242
18.42,122.80,0.244
18.43,122.95,0.245
18.45,123.10,0.246
18.47,123.25,0.248
18.48,123.40,0.251
18.49,123.55,0.253
18.51,123.70,0.254
18.53,123.85,0.257
18.54,124.00,0.259
18.56,124.15,0.260
18.57,124.30,0.262
18.58,124.45,0.264
18.60,124.60,0.265
18.62,124.75,0.267
18.63,124.90,0.270
18.64,125.05,0.272
18.66,125.19,0.274
18.68,125.34,0.276
18.69,125.49,0.278
18.71,125.64,0.280
18.72,125.79,0.282
18.73,125.94,0.284
18.75,126.09,0.287
18.77,126.24,0.289
18.78,126.39,0.291
18.79,126.54,0.294
18.81,126.69,0.295
18.83,126.84,0.298
18.84,126.99,0.300
18.86,127.13,0.303
18.87,127.28,0.305
18.88,127.43,0.308
18.90,127.58,0.310
18.92,127.73,0.313
18.93,127.88,0.315
18.94,128.03,0.318
18.96,128.18,0.320
18.98,128.33,0.323
18.99,128.48,0.325
19.01,128.63,0.329
19.02,128.78,0.331
19.03,128.92,0.335
19.05,129.07,0.336
19.07,129.22,0.339
19.08,129.37,0.342
19.09,129.52,0.346
19.11,129.67,0.348
19.13,129.82,0.351
19.14,129.97,0.354
19.16,130.11,0.357
19.17,130.26,0.360
19.18,130.41,0.364
19.20,130.56,0.368
19.22,130.71,0.371
19.23,130.86,0.373
19.24,131.01,0.377
19.26,131.16,0.381
19.28,131.31,0.385
19.29,131.45,0.388
19.31,131.60,0.392
19.32,131.75,0.396
19.33,131.90,0.399
19.35,132.05,0.402
19.37,132.20,0.406
19.38,132.35,0.410
19.39,132.49,0.413
19.41,132.64,0.417
19.43,132.79,0.421
19.44,132.94,0.425
19.46,133.09,0.429
19.47,133.24,0.433
19.48,133.38,0.437
19.50,133.53,0.442
19.52,133.68,0.445
19.53,133.83,0.450
19.54,133.98,0.453
19.56,134.13,0.459
19.58,134.28,0.462
19.59,134.42,0.467
19.61,134.57,0.471
19.62,134.72,0.476
19.63,134.87,0.482
19.65,135.02,0.486
19.67,135.16,0.490
19.68,135.31,0.495
19.69,135.46,0.500
19.71,135.61,0.506
19.73,135.76,0.510
19.74,135.91,0.515
19.76,136.05,0.520
19.77,136.20,0.526
19.78,136.35,0.530
19.80,136.50,0.536
19.82,136.64,0.541
19.83,136.79,0.547
19.84,136.94,0.551
19.86,137.09,0.558
19.88,137.24,0.563
19.89,137.39,0.568
19.91,137.53,0.575
19.92,137.68,0.581
19.93,137.83,0.586
19.95,137.98,0.592
19.97,138.12,0.599
19.98,138.27,0.605
19.99,138.42,0.612
20.01,138.57,0.618
20.03,138.71,0.626
20.04,138.86,0.632
20.06,139.01,0.639
20.07,139.15,0.647
20.08,139.30,0.654
20.10,139.45,0.663
20.12,139.60,0.669
20.13,139.74,0.678
20.14,139.89,0.687
20.16,140.04,0.696
20.18,140.18,0.704
20.19,140.33,0.713
20.21,140.48,0.722
20.22,140.62,0.733
20.23,140.77,0.742
20.25,140.92,0.752
20.27,141.06,0.763
20.28,141.21,0.772
20.29,141.36,0.783
20.31,141.50,0.796
20.33,141.65,0.806
20.34,141.79,0.818
20.36,141.94,0.830
20.37,142.08,0.843
20.38,142.23,0.854
20.40,142.37,0.869
20.42,142.52,0.882
20.43,142.66,0.897
20.44,142.81,0.914
20.46,142.95,0.931
20.48,143.09,0.948
20.49,143.24,0.970
20.51,143.38,0.997
20.52,143.52,1.024
20.53,143.66,1.054
20.55,143.80,1.087
20.57,143.94,1.124
20.58,144.08,1.179
20.59,144.21,1.240
20.61,144.34,1.322
20.63,144.47,1.413
20.64,144.59,1.496
20.66,144.71,1.549
20.67,144.84,1.575
20.68,144.97,1.609
20.70,145.10,1.639
20.72,145.23,1.656
20.73,145.37,1.689
20.74,145.50,1.747
20.76,145.63,1.932
20.78,145.73,2.190
20.79,145.83,2.246
20.81,145.96,1.997
20.82,146.13,1.665
20.83,146.32,1.384
20.85,146.53,1.134
20.87,146.75,0.946
20.88,146.97,0.821
20.89,147.17,0.742
20.91,147.38,0.685
20.93,147.57,0.640
20.94,147.76,
20.96,147.94,
20.97,148.12,
20.98,,
20.99,,

[step]
Ramp 10.00 °C/min to -60.00 °C
Time,Temperature,Heat Flow (Normalized)
min,°C,W/g
21.99,150.09,-0.040
22.01,150.09,-0.040
22.02,150.09,-0.040
22.04,150.08,-0.042
22.05,150.07,-0.057
22.07,150.05,-0.077
22.08,150.02,-0.105
22.10,149.97,-0.139
22.11,149.91,-0.177
22.13,149.83,-0.213
22.14,149.75,-0.247
22.16,149.65,-0.277
22.17,149.54,-0.302
22.19,149.43,-0.324
22.20,149.32,-0.343
22.22,149.20,-0.358
22.23,149.08,-0.372
22.25,148.95,-0.383
22.26,148.82,-0.395
22.28,148.69,-0.403
22.29,148.55,-0.411
22.31,148.41,-0.418
22.32,148.28,-0.423
22.34,148.14,-0.428
22.35,148.00,-0.431
22.37,147.85,-0.436
22.38,147.71,-0.439
22.40,147.57,-0.440
22.41,147.42,-0.443
22.43,147.28,-0.444
22.44,147.13,-0.447
22.46,146.99,-0.448
22.47,146.84,-0.448
22.49,146.70,-0.449
22.50,146.55,-0.450
22.52,146.40,-0.451
22.53,146.26,-0.451
22.55,146.11,-0.451
22.56,145.96,-0.452
22.58,145.82,-0.452
22.59,145.67,-0.452
22.61,145.52,-0.452
22.62,145.37,-0.453
22.64,145.23,-0.453
22.65,145.08,-0.453
22.67,144.93,-0.453
22.68,144.78,-0.453
22.70,144.63,-0.453
22.71,144.48,-0.453
22.73,144.34,-0.454
22.74,144.19,-0.454
22.76,144.04,-0.454
22.77,143.89,-0.454
22.79,143.74,-0.454
22.80,143.59,-0.454
22.82,143.44,-0.454
22.83,143.29,-0.454
22.85,143.14,-0.454
22.86,143.00,-0.454
22.88,142.85,-0.454
22.89,142.70,-0.454
22.91,142.55,-0.454
22.92,142.40,-0.454
22.94,142.25,-0.454
22.95,142.10,-0.454
22.97,141.95,-0.454
22.98,141.81,-0.454
23.00,141.65,-0.454
23.01,141.51,-0.454
23.03,141.36,-0.454
23.04,141.21,-0.454
23.06,141.06,-0.453
23.07,140.91,-0.453
23.09,140.76,-0.453
23.10,140.61,-0.453
23.12,140.46,-0.453
23.13,140.31,-0.453
23.15,140.16,-0.453
23.16,140.01,-0.453
23.18,139.86,-0.453
23.19,139.72,-0.452
23.21,139.57,-0.452
23.22,139.42,-0.452
23.24,139.27,-0.452
23.25,139.12,-0.452
23.27,138.97,-0.452
23.28,138.82,-0.452
23.30,138.67,-0.452
23.31,138.52,-0.451
23.33,138.37,-0.451
23.34,138.22,-0.451
23.36,138.07,-0.451
23.37,137.92,-0.451
23.39,137.77,-0.450
23.40,137.62,-0.450
23.42,137.47,-0.450
23.43,137.32,-0.450
23.45,137.17,-0.450
23.46,137.02,-0.450
23.48,136.87,-0.450
23.49,136.72,-0.450
23.51,136.57,-0.449
23.52,136.42,-0.449
23.54,136.27,-0.449
23.55,136.12,-0.449
23.57,135.97,-0.449
23.58,135.82,-0.449
23.60,135.67,-0.448
23.61,135.52,-0.448
23.63,135.38,-0.448
23.64,135.22,-0.448
23.66,135.08,-0.448
23.67,134.93,-0.447
23.69,134.78,-0.447
23.70,134.63,-0.447
23.72,134.48,-0.447
23.73,134.33,-0.447
23.75,134.18,-0.447
23.76,134.03,-0.446
23.78,133.88,-0.446
23.79,133.73,-0.446
23.81,133.58,-0.446
23.82,133.43,-0.446
23.84,133.28,-0.445
23.85,133.13,-0.445
23.87,132.98,-0.445
23.88,132.83,-0.445
23.90,132.68,-0.445
23.91,132.53,-0.444
23.93,132.38,-0.444
23.94,132.23,-0.444
23.96,132.08,-0.444
23.97,131.93,-0.444
23.99,131.78,-0.444
24.00,131.63,-0.444
24.02,131.48,-0.443
24.03,131.33,-0.443
24.05,131.18,-0.443
24.06,131.03,-0.443
24.08,130.88,-0.443
24.09,130.73,-0.443
24.11,130.58,-0.442
24.12,130.43,-0.442
24.14,130.28,-0.442
24.15,130.13,-0.442
24.17,129.98,-0.442
24.18,129.83,-0.442
24.20,129.68,-0.441
24.21,129.53,-0.441
24.23,129.38,-0.441
24.24,129.23,-0.441
24.26,129.08,-0.441
24.27,128.93,-0.441
24.29,128.78,-0.440
24.30,128.64,-0.440
24.32,128.48,-0.440
24.33,128.34,-0.440
24.35,128.19,-0.440
24.36,128.04,-0.440
24.38,127.89,-0.440
24.39,127.74,-0.439
24.41,127.59,-0.439
24.42,127.44,-0.439
24.44,127.29,-0.439
24.45,127.14,-0.439
24.47,126.99,-0.439
24.48,126.84,-0.438
24.50,126.69,-0.438
24.51,126.54,-0.438
24.53,126.39,-0.438
24.54,126.24,-0.438
24.56,126.09,-0.438
24.57,125.94,-0.438
24.59,125.79,-0.437
24.60,125.64,-0.437
24.62,125.49,-0.437
24.63,125.34,-0.437
24.65,125.19,-0.437
24.66,125.04,-0.437
24.68,124.89,-0.436
24.69,124.74,-0.436
24.71,124.59,-0.436
24.72,124.44,-0.436
24.74,124.29,-0.436
24.75,124.14,-0.436
24.77,123.99,-0.436
24.78,123.84,-0.435
24.80,123.69,-0.435
24.81,123.54,-0.435
24.83,123.39,-0.435
24.84,123.24,-0.435
24.86,123.09,-0.435
24.87,122.94,-0.434
24.89,122.79,-0.434
24.90,122.64,-0.434
24.92,122.49,-0.434
24.93,122.34,-0.434
24.95,122.19,-0.433
24.96,122.04,-0.433
24.98,121.89,-0.433
24.99,121.74,-0.433
25.01,121.59,-0.433
25.02,121.44,-0.433
25.04,121.29,-0.433
25.05,121.14,-0.433
25.07,120.99,-0.432
25.08,120.84,-0.432
25.10,120.69,-0.432
25.11,120.54,-0.432
25.13,120.39,-0.432
25.14,120.24,-0.432
25.16,120.09,-0.432
25.17,119.94,-0.431
25.19,119.79,-0.431
25.20,119.64,-0.431
25.22,119.49,-0.431
25.23,119.34,-0.431
25.25,119.19,-0.431
25.26,119.05,-0.431
25.28,118.90,-0.430
25.29,118.75,-0.430
25.31,118.60,-0.430
25.32,118.45,-0.430
25.34,118.30,-0.430
25.35,118.15,-0.430
25.37,118.00,-0.430
25.38,117.85,-0.429
25.40,117.70,-0.429
25.41,117.55,-0.429
25.43,117.40,-0.429
25.44,117.25,-0.429
25.46,117.10,-0.429
25.47,116.95,-0.429
25.49,116.80,-0.428
25.50,116.65,-0.428
25.52,116.50,-0.428
25.53,116.35,-0.428
25.55,116.20,-0.428
25.56,116.05,-0.428
25.58,115.90,-0.428
25.59,115.75,-0.428
25.61,115.60,-0.427
25.62,115.45,-0.427
25.64,115.30,-0.427
25.65,115.15,-0.427
25.67,115.00,-0.427
25.68,114.85,-0.427
25.70,114.70,-0.427
25.71,114.55,-0.427
25.73,114.40,-0.426
25.74,114.25,-0.426
25.76,114.10,-0.426
25.77,113.95,-0.426
25.79,113.80,-0.426
25.80,113.65,-0.426
25.82,113.50,-0.426
25.83,113.35,-0.426
25.85,113.20,-0.426
25.86,113.05,-0.425
25.88,112.90,-0.425
25.89,112.75,-0.425
25.91,112.60,-0.425
25.92,112.45,-0.425
25.94,112.30,-0.424
25.95,112.15,-0.424
25.97,112.00,-0.424
25.98,111.85,-0.424
26.00,111.70,-0.424
26.01,111.55,-0.424
26.03,111.40,-0.424
26.04,111.25,-0.424
26.06,111.10,-0.424
26.07,110.95,-0.423
26.09,110.80,-0.423
26.10,110.65,-0.423
26.12,110.50,-0.423
26.13,110.35,-0.423
26.15,110.20,-0.423
26.16,110.05,-0.423
26.18,109.90,-0.422
26.19,109.75,-0.422
26.21,109.61,-0.422
26.22,109.45,-0.422
26.24,109.30,-0.422
26.25,109.15,-0.422
26.27,109.01,-0.422
26.28,108.86,-0.422
26.30,108.71,-0.422
26.31,108.56,-0.421
26.33,108.41,-0.421
26.34,108.26,-0.421
26.36,108.11,-0.421
26.37,107.96,-0.421
26.39,107.81,-0.421
26.40,107.66,-0.421
26.42,107.51,-0.421
26.43,107.36,-0.421
26.45,107.21,-0.420
26.46,107.06,-0.420
26.48,106.91,-0.420
26.49,106.76,-0.420
26.51,106.61,-0.420
26.52,106.46,-0.420
26.54,106.31,-0.420
26.55,106.16,-0.420
26.57,106.01,-0.419
26.58,105.86,-0.419
26.60,105.71,-0.419
26.61,105.56,-0.419
26.63,105.41,-0.419
26.64,105.26,-0.419
26.66,105.11,-0.419
26.67,104.96,-0.419
26.69,104.81,-0.419
26.70,104.66,-0.419
26.72,104.51,-0.418
26.73,104.36,-0.418
26.75,104.21,-0.418
26.76,104.06,-0.418
26.78,103.91,-0.418
26.79,103.76,-0.418
26.81,103.61,-0.417
26.82,103.46,-0.417
26.84,103.31,-0.417
26.85,103.16,-0.417
26.87,103.01,-0.417
26.88,102.86,-0.417
26.90,102.71,-0.417
26.91,102.56,-0.417
26.93,102.41,-0.417
26.94,102.26,-0.416
26.96,102.11,-0.416
26.97,101.96,-0.416
26.99,101.81,-0.416
27.00,101.66,-0.416
27.02,101.51,-0.416
27.03,101.36,-0.416
27.05,101.21,-0.416
27.06,101.06,-0.415
27.08,100.92,-0.415
27.09,100.76,-0.415
27.11,100.62,-0.415
27.12,100.47,-0.415
27.14,100.32,-0.415
27.15,100.17,-0.415
27.17,100.02,-0.415
27.18,99.87,-0.415
27.20,99.72,-0.414
27.21,99.57,-0.414
27.23,99.42,-0.414
27.24,99.27,-0.414
27.26,99.12,-0.414
27.27,98.97,-0.414
27.29,98.82,-0.414
27.30,98.67,-0.414
27.32,98.52,-0.414
27.33,98.37,-0.413
27.35,98.22,-0.413
27.36,98.07,-0.413
27.38,97.92,-0.413
27.39,97.77,-0.413
27.41,97.62,-0.413
27.42,97.47,-0.413
27.44,97.32,-0.413
27.45,97.17,-0.412
27.47,97.02,-0.412
27.48,96.87,-0.412
27.50,96.72,-0.412
27.51,96.57,-0.412
27.53,96.42,-0.412
27.54,96.27,-0.412
27.56,96.12,-0.412
27.57,95.97,-0.412
27.59,95.82,-0.411
27.60,95.67,-0.411
27.62,95.52,-0.411
27.63,95.37,-0.411
27.65,95.22,-0.411
27.66,95.07,-0.411
27.68,94.92,-0.411
27.69,94.77,-0.411
27.71,94.62,-0.410
27.72,94.47,-0.410
27.74,94.32,-0.410
27.75,94.17,-0.410
27.77,94.02,-0.410
27.78,93.87,-0.410
27.80,93.72,-0.410
27.81,93.57,-0.410
27.83,93.42,-0.409
27.84,93.27,-0.409
27.86,93.12,-0.409
27.87,92.97,-0.409
27.89,92.82,-0.409
27.90,92.67,-0.409
27.92,92.52,-0.408
27.93,92.37,-0.408
27.95,92.22,-0.408
27.96,92.07,-0.408
27.98,91.92,-0.408
27.99,91.77,-0.408
28.01,91.62,-0.408
28.02,91.47,-0.408
28.04,91.32,-0.407
28.05,91.17,-0.407
28.07,91.02,-0.407
28.08,90.87,-0.407
28.10,90.72,-0.407
28.11,90.57,-0.407
28.13,90.42,-0.407
28.14,90.28,-0.407
28.16,90.12,-0.406
28.17,89.97,-0.406
28.19,89.82,-0.406
28.20,89.68,-0.406
28.22,89.53,-0.406
28.23,89.37,-0.406
28.25,89.23,-0.406
28.26,89.08,-0.406
28.28,88.93,-0.405
28.29,88.78,-0.405
28.31,88.63,-0.405
28.32,88.48,-0.405
28.34,88.33,-0.405
28.35,88.18,-0.405
28.37,88.03,-0.405
28.38,87.88,-0.404
28.40,87.73,-0.404
28.41,87.58,-0.404
28.43,87.43,-0.404
[...]
93.05,-11.13,0.234
93.06,-10.98,0.235
93.08,-10.83,0.235
93.09,-10.69,0.236
93.11,-10.53,0.236
93.12,-10.39,0.237
93.14,-10.23,0.237
93.15,-10.09,0.238
93.17,-9.94,0.238
93.18,-9.79,0.240
93.20,-9.64,0.240
93.21,-9.49,0.241
93.23,-9.34,0.241
93.24,-9.19,0.242
93.26,-9.04,0.243
93.27,-8.89,0.244
93.29,-8.74,0.245
93.30,-8.59,0.246
93.32,-8.44,0.246
93.33,-8.29,0.247
93.35,-8.14,0.248
93.36,-7.99,0.250
93.38,-7.84,0.250
93.39,-7.69,0.252
93.41,-7.54,0.253
93.42,-7.39,0.255
93.44,-7.24,0.255
93.45,-7.09,0.256
93.47,-6.94,0.257
93.48,-6.79,0.258
93.50,-6.64,0.260
93.51,-6.49,0.261
93.53,-6.34,0.262
93.54,-6.19,0.263
93.56,-6.04,0.265
93.57,-5.89,0.265
93.59,-5.74,0.267
93.60,-5.59,0.268
93.62,-5.44,0.269
93.63,-5.30,0.271
93.65,-5.15,0.272
93.66,-5.00,0.273
93.68,-4.85,0.274
93.69,-4.70,0.275
93.71,-4.55,0.276
93.72,-4.40,0.278
93.74,-4.25,0.279
93.75,-4.10,0.280
93.77,-3.95,0.281
93.78,-3.80,0.282
93.80,-3.65,0.283
93.81,-3.50,0.284
93.83,-3.35,0.285
93.84,-3.20,0.285
93.86,-3.05,0.286
93.87,-2.90,0.286
93.89,-2.75,0.287
93.90,-2.60,0.288
93.92,-2.45,0.288
93.93,-2.30,0.289
93.95,-2.15,0.290
93.96,-2.00,0.290
93.98,-1.85,0.290
93.99,-1.70,0.291
94.01,-1.55,0.291
94.02,-1.40,0.291
94.04,-1.25,0.291
94.05,-1.10,0.291
94.07,-0.95,0.292
94.08,-0.80,0.292
94.10,-0.65,0.292
94.11,-0.50,0.292
94.13,-0.35,0.292
94.14,-0.20,0.292
94.16,-0.05,0.293
94.17,0.10,0.293
94.19,0.25,0.293
94.20,0.40,0.293
94.22,0.55,0.293
94.23,0.70,0.293
94.25,0.85,0.293
94.26,1.00,0.293
94.28,1.15,0.293
94.29,1.30,0.293
94.31,1.45,0.293
94.32,1.60,0.293
94.34,1.75,0.293
94.35,1.90,0.293
94.37,2.05,0.293
94.38,2.20,0.293
94.40,2.35,0.293
94.41,2.50,0.293
94.43,2.65,0.293
94.44,2.80,0.293
94.46,2.95,0.293
94.47,3.11,0.293
94.49,3.26,0.293
94.50,3.41,0.293
94.52,3.56,0.293
94.53,3.71,0.293
94.55,3.86,0.293
94.56,4.01,0.293
94.58,4.16,0.293
94.59,4.31,0.293
94.61,4.46,0.293
94.62,4.61,0.293
94.64,4.76,0.293
94.65,4.91,0.293
94.67,5.06,0.293
94.68,5.21,0.293
94.70,5.36,0.293
94.71,5.51,0.293
94.73,5.66,0.292
94.74,5.81,0.292
94.76,5.96,0.292
94.77,6.11,0.292
94.79,6.26,0.292
94.80,6.41,0.292
94.82,6.56,0.292
94.83,6.71,0.293
94.85,6.86,0.293
94.86,7.01,0.293
94.88,7.16,0.293
94.89,7.31,0.293
94.91,7.46,0.293
94.92,7.61,0.293
94.94,7.76,0.293
94.95,7.91,0.293
94.97,8.06,0.293
94.98,8.21,0.293
95.00,8.36,0.293
95.01,8.51,0.293
95.03,8.66,0.293
95.04,8.81,0.293
95.06,8.96,0.293
95.07,9.12,0.293
95.09,9.26,0.294
95.10,9.42,0.294
95.12,9.57,0.294
95.13,9.72,0.294
95.15,9.87,0.294
95.16,10.02,0.294
95.18,10.17,0.294
95.19,10.32,0.294
95.21,10.47,0.294
95.22,10.62,0.295
95.24,10.77,0.295
95.25,10.92,0.295
95.27,11.07,0.295
95.28,11.22,0.295
95.30,11.37,0.295
95.31,11.51,0.295
95.33,11.66,0.296
95.34,11.82,0.296
95.36,11.97,0.296
95.37,12.12,0.296
95.39,12.27,0.296
95.40,12.42,0.297
95.42,12.57,0.297
95.43,12.72,0.297
95.45,12.87,0.297
95.46,13.02,0.297
95.48,13.17,0.298
95.49,13.32,0.298
95.51,13.47,0.298
95.52,13.62,0.298
95.54,13.77,0.298
95.55,13.92,0.299
95.57,14.07,0.299
95.58,14.22,0.299
95.60,14.37,0.299
95.61,14.52,0.299
95.63,14.67,0.299
95.64,14.82,0.300
95.66,14.97,0.300
95.67,15.12,0.300
95.69,15.27,0.300
95.70,15.42,0.300
95.72,15.57,0.300
95.73,15.72,0.300
95.75,15.87,0.301
95.76,16.02,0.301
95.78,16.17,0.301
95.79,16.32,0.301
95.81,16.47,0.301
95.82,16.62,0.301
95.84,16.77,0.301
95.85,16.92,0.301
95.87,17.07,0.302
95.88,17.22,0.302
95.90,17.37,0.302
95.91,17.52,0.302
95.93,17.67,0.302
95.94,17.82,0.302
95.96,17.97,0.302
95.97,18.12,0.302
95.99,18.27,0.302
96.00,18.42,0.303
96.02,18.57,0.303
96.03,18.73,0.303
96.05,18.88,0.303
96.06,19.02,0.303
96.08,19.18,0.303
96.09,19.33,0.303
96.11,19.48,0.303
96.12,19.63,0.303
96.14,19.78,0.304
96.15,19.93,0.304
96.17,20.08,0.304
96.18,20.23,0.304
96.20,20.38,0.304
96.21,20.53,0.304
96.23,20.68,0.304
96.24,20.83,0.304
96.26,20.98,0.304
96.27,21.13,0.305
96.29,21.28,0.305
96.30,21.43,0.305
96.32,21.58,0.305
96.33,21.73,0.305
96.35,21.88,0.305
96.36,22.03,0.305
96.38,22.18,0.305
96.39,22.33,0.305
96.41,22.48,0.305
96.42,22.63,0.305
96.44,22.78,0.306
96.45,22.93,0.306
96.47,23.08,0.306
96.48,23.23,0.306
96.50,23.38,0.306
96.51,23.53,0.306
96.53,23.68,0.306
96.54,23.83,0.306
96.56,23.98,0.306
96.57,24.13,0.306
96.59,24.28,0.307
96.60,24.43,0.307
96.62,24.58,0.307
96.63,24.73,0.307
96.65,24.88,0.307
96.66,25.03,0.307
96.68,25.18,0.307
96.69,25.33,0.307
96.71,25.48,0.308
96.72,25.63,0.308
96.74,25.78,0.308
96.75,25.93,0.308
96.77,26.08,0.308
96.78,26.23,0.308
96.80,26.38,0.308
96.81,26.53,0.308
96.83,26.68,0.309
96.84,26.83,0.309
96.86,26.98,0.309
96.87,27.13,0.309
96.89,27.28,0.309
96.90,27.43,0.309
96.92,27.58,0.309
96.93,27.73,0.309
96.95,27.88,0.309
96.96,28.04,0.310
96.98,28.18,0.310
96.99,28.33,0.310
97.01,28.48,0.310
97.02,28.64,0.310
97.04,28.79,0.310
97.05,28.93,0.310
97.07,29.09,0.310
97.08,29.23,0.311
97.10,29.39,0.311
97.11,29.54,0.311
97.13,29.69,0.311
97.14,29.84,0.311
97.16,29.99,0.311
97.17,30.14,0.311
97.19,30.29,0.311
97.20,30.44,0.312
97.22,30.59,0.312
97.23,30.74,0.312
97.25,30.89,0.312
97.26,31.04,0.312
97.28,31.19,0.312
97.29,31.34,0.312
97.31,31.49,0.312
97.32,31.64,0.313
97.34,31.79,0.313
97.35,31.94,0.313
97.37,32.09,0.313
97.38,32.24,0.313
97.40,32.39,0.313
97.41,32.54,0.313
97.43,32.69,0.313
97.44,32.84,0.313
97.46,32.99,0.314
97.47,33.14,0.314
97.49,33.29,0.314
97.50,33.44,0.314
97.52,33.59,0.314
97.53,33.74,0.314
97.55,33.89,0.314
97.56,34.04,0.314
97.58,34.19,0.315
97.59,34.34,0.315
97.61,34.49,0.315
97.62,34.64,0.315
97.64,34.79,0.315
97.65,34.94,0.315
97.67,35.09,0.315
97.68,35.24,0.315
97.70,35.39,0.315
97.71,35.54,0.315
97.73,35.69,0.316
97.74,35.84,0.316
97.76,35.99,0.316
97.77,36.14,0.316
97.79,36.29,0.316
97.80,36.44,0.316
97.82,36.59,0.316
97.83,36.74,0.316
97.85,36.89,0.316
97.86,37.04,0.317
97.88,37.19,0.317
97.89,37.34,0.317
97.91,37.49,0.317
97.92,37.65,0.317
97.94,37.80,0.317
97.95,37.95,0.317
97.97,38.10,0.317
97.98,38.25,0.318
98.00,38.40,0.318
98.01,38.55,0.318
98.03,38.70,0.318
98.04,38.85,0.318
98.06,39.00,0.318
98.07,39.15,0.318
98.09,39.30,0.318
98.10,39.45,0.318
98.12,39.60,0.319
98.13,39.75,0.319
98.15,39.90,0.319
98.16,40.05,0.319
98.18,40.20,0.319
98.19,40.35,0.319
98.21,40.50,0.319
98.22,40.65,0.319
98.24,40.80,0.319
98.25,40.95,0.320
98.27,41.10,0.320
98.28,41.25,0.320
98.30,41.40,0.320
98.31,41.55,0.320
98.33,41.70,0.320
98.34,41.85,0.320
98.36,42.00,0.320
98.37,42.15,0.321
98.39,42.30,0.321
98.40,42.45,0.321
98.42,42.60,0.321
98.43,42.75,0.321
98.45,42.90,0.321
98.46,43.05,0.321
98.48,43.20,0.322
98.49,43.35,0.322
98.51,43.50,0.322
98.52,43.65,0.322
98.54,43.80,0.322
98.55,43.95,0.322
98.57,44.10,0.322
98.58,44.25,0.322
98.60,44.40,0.323
98.61,44.55,0.323
98.63,44.70,0.323
98.64,44.85,0.323
98.66,45.00,0.323
98.67,45.15,0.323
98.69,45.30,0.323
98.70,45.45,0.323
98.72,45.60,0.323
98.73,45.75,0.324
98.75,45.90,0.324
98.76,46.05,0.324
98.78,46.20,0.324
98.79,46.35,0.324
98.81,46.50,0.324
98.82,46.65,0.324
98.84,46.80,0.324
98.85,46.95,0.325
98.87,47.10,0.325
98.88,47.26,0.325
98.90,47.41,0.325
98.91,47.55,0.325
98.93,47.70,0.325
98.94,47.85,0.325
98.96,48.00,0.325
98.97,48.15,0.326
98.99,48.30,0.326
99.00,48.46,0.326
99.02,48.61,0.326
99.03,48.76,0.326
99.05,48.90,0.326
99.06,49.06,0.326
99.08,49.21,0.326
99.09,49.36,0.327
99.11,49.51,0.327
99.12,49.66,0.327
99.14,49.81,0.327
99.15,49.96,0.327
99.17,50.11,0.327
99.18,50.26,0.327
99.20,50.41,0.327
99.21,50.56,0.328
99.23,50.71,0.328
99.24,50.86,0.328
99.26,51.01,0.328
99.27,51.16,0.328
99.29,51.31,0.328
99.30,51.46,0.328
99.32,51.61,0.328
99.33,51.76,0.328
99.35,51.91,0.329
99.36,52.06,0.329
99.38,52.21,0.329
99.39,52.36,0.329
99.41,52.51,0.329
99.42,52.66,0.329
99.44,52.81,0.329
99.45,52.96,0.329
99.47,53.11,0.329
99.48,53.26,0.330
99.50,53.41,0.330
99.51,53.56,0.330
99.53,53.71,0.330
99.54,53.86,0.330
99.56,54.01,0.330
99.57,54.16,0.330
99.59,54.31,0.330
99.60,54.46,0.330
99.62,54.61,0.331
99.63,54.76,0.331
99.65,54.91,0.331
99.66,55.06,0.331
99.68,55.21,0.331
99.69,55.36,0.331
99.71,55.51,0.331
99.72,55.66,0.331
99.74,55.81,0.332
99.75,55.96,0.332
99.77,56.11,0.332
99.78,56.26,0.332
99.80,56.41,0.332
99.81,56.56,0.332
99.83,56.71,0.332
99.84,56.86,0.332
99.86,57.01,0.332
99.87,57.17,0.333
99.89,57.31,0.333
99.90,57.47,0.333
99.92,57.62,0.333
99.93,57.77,0.333
99.95,57.92,0.333
99.96,58.07,0.333
99.98,58.22,0.333
99.99,58.37,0.334
100.01,58.52,0.334
100.02,58.67,0.334
100.04,58.82,0.334
100.05,58.97,0.334
100.07,59.12,0.334
100.08,59.27,0.334
100.10,59.42,0.334
100.11,59.57,0.335
100.13,59.72,0.335
100.14,59.87,0.335
100.16,60.02,0.335
100.17,60.17,0.335
100.19,60.32,0.335
100.20,60.47,0.335
100.22,60.62,0.335
100.23,60.77,0.335
100.25,60.92,0.336
100.26,61.07,0.336
100.28,61.22,0.336
100.29,61.37,0.336
100.31,61.52,0.336
100.32,61.67,0.336
100.34,61.82,0.337
100.35,61.97,0.337
100.37,62.12,0.337
100.38,62.27,0.337
100.40,62.42,0.337
100.41,62.57,0.337
100.43,62.72,0.337
100.44,62.87,0.337
100.46,63.02,0.337
100.47,63.17,0.337
100.49,63.32,0.338
100.50,63.47,0.338
100.52,63.62,0.338
100.53,63.77,0.338
100.55,63.92,0.338
100.56,64.07,0.338
100.58,64.22,0.338
100.59,64.37,0.338
100.61,64.52,0.338
100.62,64.67,0.339
100.64,64.82,0.339
100.65,64.97,0.339
100.67,65.12,0.339
100.68,65.27,0.339
100.70,65.42,0.339
100.71,65.57,0.339
100.73,65.72,0.339
100.74,65.87,0.339
100.76,66.02,0.339
100.77,66.17,0.340
100.79,66.32,0.340
100.80,66.48,0.340
100.82,66.63,0.340
100.83,66.78,0.340
100.85,66.93,0.340
100.86,67.08,0.340
100.88,67.23,0.340
100.89,67.38,0.341
100.91,67.53,0.341
100.92,67.68,0.341
100.94,67.83,0.341
100.95,67.98,0.341
100.97,68.13,0.341
100.98,68.28,0.341
101.00,68.43,0.341
101.01,68.58,0.341
101.03,68.73,0.342
101.04,68.88,0.342
101.06,69.03,0.342
101.07,69.18,0.342
101.09,69.33,0.342
101.10,69.48,0.342
101.12,69.63,0.342
101.13,69.78,0.342
101.15,69.93,0.342
101.16,70.08,0.342
101.18,70.23,0.343
101.19,70.38,0.343
101.21,70.53,0.343
101.22,70.68,0.343
101.24,70.83,0.343
101.25,70.98,0.343
101.27,71.13,0.343
101.28,71.28,0.343
101.30,71.43,0.344
101.31,71.58,0.344
101.33,71.73,0.344
101.34,71.88,0.344
101.36,72.03,0.344
101.37,72.18,0.344
101.39,72.33,0.344
101.40,72.48,0.344
101.42,72.63,0.344
101.43,72.78,0.345
101.45,72.93,0.345
101.46,73.08,0.345
101.48,73.23,0.345
101.49,73.38,0.345
101.51,73.53,0.345
101.52,73.68,0.345
101.54,73.83,0.345
101.55,73.98,0.345
101.57,74.13,0.345
101.58,74.28,0.346
101.60,74.43,0.346
101.61,74.58,0.346
101.63,74.73,0.346
101.64,74.88,0.346
101.66,75.03,0.346
101.67,75.18,0.346
101.69,75.33,0.346
101.70,75.48,0.346
101.72,75.63,0.347
101.73,75.78,0.347
101.75,75.93,0.347
101.76,76.08,0.347
101.78,76.23,0.347
101.79,76.38,0.347
101.81,76.53,0.347
101.82,76.68,0.347
101.84,76.83,0.348
101.85,76.98,0.348
101.87,77.13,0.348
101.88,77.28,0.348
101.90,77.43,0.348
101.91,77.58,0.348
101.93,77.73,0.348
101.94,77.88,0.348
101.96,78.03,0.348
101.97,78.19,0.349
101.99,78.34,0.349
102.00,78.49,0.349
102.02,78.63,0.349
102.03,78.79,0.349
102.05,78.94,0.349
102.06,79.09,0.349
102.08,79.24,0.349
102.09,79.39,0.349
102.11,79.54,0.350
102.12,79.69,0.350
102.14,79.84,0.350
102.15,79.99,0.350
102.17,80.14,0.350
102.18,80.29,0.350
102.20,80.44,0.350
102.21,80.59,0.350
102.23,80.74,0.350
102.24,80.89,0.350
102.26,81.04,0.351
102.27,81.19,0.351
102.29,81.34,0.351
102.30,81.49,0.351
102.32,81.64,0.351
102.33,81.79,0.351
102.35,81.94,0.351
102.36,82.09,0.351
102.38,82.24,0.351
102.39,82.39,0.351
102.41,82.54,0.351
102.42,82.69,0.352
102.44,82.84,0.352
102.45,82.99,0.352
102.47,83.14,0.352
102.48,83.29,0.352
102.50,83.44,0.352
102.51,83.59,0.352
102.53,83.74,0.352
102.54,83.89,0.352
102.56,84.04,0.352
102.57,84.19,0.352
102.59,84.34,0.352
102.60,84.49,0.353
102.62,84.64,0.353
102.63,84.79,0.353
102.65,84.94,0.353
102.66,85.09,0.353
102.68,85.24,0.353
102.69,85.39,0.353
102.71,85.54,0.353
102.72,85.69,0.353
102.74,85.84,0.353
102.75,85.99,0.353
102.77,86.14,0.354
102.78,86.29,0.354
102.80,86.44,0.354
102.81,86.59,0.354
102.83,86.74,0.354
102.84,86.89,0.354
102.86,87.04,0.354
102.87,87.19,0.354
102.89,87.34,0.354
102.90,87.49,0.354
102.92,87.65,0.354
102.93,87.79,0.355
102.95,87.94,0.355
102.96,88.10,0.355
102.98,88.24,0.355
102.99,88.40,0.355
103.01,88.54,0.355
103.02,88.69,0.355
103.04,88.84,0.355
103.05,88.99,0.355
103.07,89.15,0.355
103.08,89.30,0.355
103.10,89.45,0.356
103.11,89.60,0.356
103.13,89.75,0.356
103.14,89.90,0.356
103.16,90.05,0.356
103.17,90.20,0.356
103.19,90.35,0.356
103.20,90.50,0.356
103.22,90.65,0.356
103.23,90.80,0.356
103.25,90.95,0.357
103.26,91.10,0.357
103.28,91.25,0.357
103.29,91.40,0.357
103.31,91.55,0.357
103.32,91.70,0.357
103.34,91.85,0.357
103.35,92.00,0.357
103.37,92.15,0.357
103.38,92.30,0.358
103.40,92.45,0.358
103.41,92.60,0.358
103.43,92.75,0.358
103.44,92.90,0.358
103.46,93.05,0.358
103.47,93.20,0.358
103.49,93.35,0.358
103.50,93.50,0.358
103.52,93.65,0.359
103.53,93.80,0.359
103.55,93.95,0.359
103.56,94.10,0.359
103.58,94.25,0.359
103.59,94.40,0.359
103.61,94.55,0.359
103.62,94.70,0.359
103.64,94.85,0.359
103.65,95.00,0.360
103.67,95.15,0.360
103.68,95.30,0.360
103.70,95.45,0.360
103.71,95.60,0.360
103.73,95.75,0.360
103.74,95.90,0.360
103.76,96.05,0.360
103.77,96.20,0.360
103.79,96.35,0.361
103.80,96.50,0.361
103.82,96.65,0.361
103.83,96.80,0.361
103.85,96.95,0.361
103.86,97.10,0.361
103.88,97.25,0.361
103.89,97.40,0.361
103.91,97.55,0.361
103.92,97.70,0.361
103.94,97.85,0.362
103.95,98.00,0.362
103.97,98.15,0.362
103.98,98.30,0.362
104.00,98.45,0.362
104.01,98.60,0.362
104.03,98.75,0.362
104.04,98.90,0.362
104.06,99.05,0.362
104.07,99.20,0.362
104.09,99.35,0.362
104.10,99.50,0.363
104.12,99.65,0.363
104.13,99.80,0.363
104.15,99.96,0.363
104.16,100.10,0.363
104.18,100.25,0.363
104.19,100.40,0.363
104.21,100.56,0.363
104.22,100.71,0.363
104.24,100.86,0.363
104.25,101.01,0.363
104.27,101.16,0.363
104.28,101.31,0.363
104.30,101.46,0.364
104.31,101.61,0.364
104.33,101.76,0.364
104.34,101.91,0.364
104.36,102.06,0.364
104.37,102.21,0.364
104.39,102.36,0.364
104.40,102.51,0.364
104.42,102.66,0.364
104.43,102.81,0.364
104.45,102.96,0.364
104.46,103.11,0.364
104.48,103.26,0.364
104.49,103.41,0.364
104.51,103.56,0.364
104.52,103.71,0.364
104.54,103.86,0.365
104.55,104.01,0.365
104.57,104.16,0.365
104.58,104.31,0.365
104.60,104.46,0.365
104.61,104.61,0.365
104.63,104.76,0.365
104.64,104.91,0.365
104.66,105.06,0.365
104.67,105.21,0.365
104.69,105.36,0.365
104.70,105.51,0.365
104.72,105.66,0.365
104.73,105.81,0.365
104.75,105.96,0.365
104.76,106.11,0.365
104.78,106.26,0.365
104.79,106.41,0.366
104.81,106.56,0.366
104.82,106.71,0.366
104.84,106.86,0.366
104.85,107.01,0.366
104.87,107.16,0.366
104.88,107.31,0.366
104.90,107.46,0.366
104.91,107.61,0.366
104.93,107.76,0.366
104.94,107.91,0.366
104.96,108.06,0.366
104.97,108.21,0.366
104.99,108.36,0.366
105.00,108.51,0.366
105.02,108.66,0.366
105.03,108.81,0.366
105.05,108.97,0.366
105.06,109.11,0.366
105.08,109.27,0.366
105.09,109.42,0.366
105.11,109.57,0.366
105.12,109.72,0.366
105.14,109.87,0.366
105.15,110.02,0.367
105.17,110.17,0.367
105.18,110.32,0.367
105.20,110.47,0.367
105.21,110.62,0.367
105.23,110.77,0.367
105.24,110.92,0.367
105.26,111.07,0.367
105.27,111.22,0.367
105.29,111.37,0.367
105.30,111.52,0.367
105.32,111.67,0.367
105.33,111.82,0.367
105.35,111.97,0.367
105.36,112.12,0.367
105.38,112.27,0.367
105.39,112.42,0.367
105.41,112.57,0.367
105.42,112.72,0.367
105.44,112.87,0.367
105.45,113.02,0.367
105.47,113.17,0.367
105.48,113.32,0.367
105.50,113.47,0.367
105.51,113.62,0.367
105.53,113.77,0.367
105.54,113.92,0.367
105.56,114.07,0.367
105.57,114.22,0.367
105.59,114.37,0.367
105.60,114.52,0.367
105.62,114.67,0.367
105.63,114.82,0.367
105.65,114.97,0.367
105.66,115.12,0.367
105.68,115.27,0.367
105.69,115.42,0.367
105.71,115.57,0.367
105.72,115.72,0.367
105.74,115.87,0.367
105.75,116.02,0.367
105.77,116.17,0.367
105.78,116.32,0.367
105.80,116.47,0.367
105.81,116.62,0.367
105.83,116.77,0.367
105.84,116.92,0.367
105.86,117.07,0.367
105.87,117.22,0.367
105.89,117.37,0.367
105.90,117.52,0.367
105.92,117.67,0.367
105.93,117.82,0.367
105.95,117.97,0.367
105.96,118.12,0.367
105.98,118.27,0.367
105.99,118.42,0.367
106.01,118.57,0.367
106.02,118.72,0.367
106.04,118.87,0.367
106.05,119.02,0.367
106.07,119.17,0.367
106.08,119.32,0.367
106.10,119.48,0.367
106.11,119.63,0.367
106.13,119.78,0.367
106.14,119.93,0.367
106.16,120.08,0.367
106.17,120.23,0.367
106.19,120.38,0.367
106.20,120.53,0.367
106.22,120.68,0.367
106.23,120.83,0.367
106.25,120.98,0.367
106.26,121.13,0.367
106.28,121.28,0.367
106.29,121.43,0.367
106.31,121.58,0.367
106.32,121.73,0.367
106.34,121.88,0.367
106.35,122.03,0.367
106.37,122.18,0.367
106.38,122.33,0.367
106.40,122.48,0.368
106.41,122.63,0.368
106.43,122.78,0.368
106.44,122.93,0.368
106.46,123.08,0.368
106.47,123.23,0.368
106.49,123.38,0.368
106.50,123.53,0.368
106.52,123.68,0.368
106.53,123.83,0.368
106.55,123.98,0.368
106.56,124.13,0.368
106.58,124.28,0.368
106.59,124.43,0.368
106.61,124.58,0.368
106.62,124.73,0.368
106.64,124.88,0.368
106.65,125.03,0.368
106.67,125.18,0.368
106.68,125.33,0.368
106.70,125.48,0.368
106.71,125.63,0.368
106.73,125.78,0.368
106.74,125.93,0.368
106.76,126.08,0.368
106.77,126.23,0.368
106.79,126.38,0.368
106.80,126.53,0.369
106.82,126.68,0.369
106.83,126.83,0.369
106.85,126.98,0.369
106.86,127.13,0.369
106.88,127.28,0.369
106.89,127.43,0.369
106.91,127.58,0.369
106.92,127.73,0.369
106.94,127.88,0.369
106.95,128.03,0.369
106.97,128.18,0.369
106.98,128.34,0.370
107.00,128.48,0.370
107.01,128.63,0.370
107.03,128.79,0.370
107.04,128.93,0.370
107.06,129.09,0.370
107.07,129.23,0.370
107.09,129.39,0.370
107.10,129.54,0.370
107.12,129.68,0.370
107.13,129.84,0.370
107.15,129.99,0.371
107.16,130.14,0.371
107.18,130.28,0.371
107.19,130.44,0.371
107.21,130.59,0.371
107.22,130.74,0.371
107.24,130.89,0.371
107.25,131.04,0.371
107.27,131.19,0.372
107.28,131.34,0.372
107.30,131.49,0.372
107.31,131.64,0.372
107.33,131.79,0.372
107.34,131.94,0.372
107.36,132.09,0.372
107.37,132.24,0.373
107.39,132.39,0.373
107.40,132.54,0.373
107.42,132.69,0.373
107.43,132.84,0.373
107.45,132.99,0.373
107.46,133.14,0.373
107.48,133.29,0.374
107.49,133.44,0.374
107.51,133.59,0.374
107.52,133.74,0.374
107.54,133.89,0.374
107.55,134.04,0.375
107.57,134.19,0.375
107.58,134.34,0.375
107.60,134.49,0.375
107.61,134.64,0.375
107.63,134.79,0.376
107.64,134.94,0.376
107.66,135.09,0.376
107.67,135.24,0.377
107.69,135.39,0.377
107.70,135.54,0.377
107.72,135.69,0.377
107.73,135.84,0.378
107.75,135.99,0.378
107.76,136.14,0.378
107.78,136.29,0.378
107.79,136.44,0.378
107.81,136.59,0.379
107.82,136.74,0.379
107.84,136.89,0.379
107.85,137.04,0.379
107.87,137.19,0.379
107.88,137.34,0.380
107.90,137.49,0.380
107.91,137.64,0.380
107.93,137.79,0.380
107.94,137.94,0.380
107.96,138.09,0.380
107.97,138.24,0.381
107.99,138.39,0.381
108.00,138.54,0.381
108.02,138.69,0.381
108.03,138.84,0.381
108.05,138.99,0.382
108.06,139.14,0.382
108.08,139.29,0.382
108.09,139.44,0.382
108.11,139.59,0.383
108.12,139.74,0.383
108.14,139.89,0.383
108.15,140.04,0.384
108.17,140.19,0.384
108.18,140.34,0.385
108.20,140.49,0.386
108.21,140.64,0.388
108.23,140.79,0.390
108.24,140.94,0.394
108.26,141.09,0.399
108.27,141.24,0.405
108.29,141.38,0.412
108.30,141.53,0.421
108.32,141.68,0.431
108.33,141.83,0.444
108.35,141.97,0.460
108.36,142.12,0.476
108.38,142.26,0.494
108.39,142.41,0.510
108.41,142.55,0.524
108.42,142.70,0.535
108.44,142.84,0.543
108.45,142.99,0.544
108.47,143.13,0.543
108.48,143.28,0.537
108.50,143.43,0.526
108.51,143.58,0.512
108.53,143.74,0.498
108.54,143.89,0.483
108.56,144.04,0.469
108.57,144.20,0.456
108.59,144.35,0.446
108.60,144.51,0.436
108.62,144.66,0.428
108.63,144.81,0.422
108.65,144.97,0.417
108.66,145.12,0.413
108.68,145.27,0.410
108.69,145.43,0.406
108.71,145.58,0.404
108.72,145.73,0.402
108.74,145.88,0.400
108.75,146.03,0.399
108.77,146.19,0.398
108.78,146.34,0.397
108.80,146.49,0.397
108.81,146.64,0.396
108.83,146.79,0.395
108.84,146.94,0.395
108.86,147.09,0.395
108.87,147.24,0.394
108.89,147.39,0.394
108.90,147.54,0.394
108.92,147.69,0.394
108.93,147.84,0.394
108.95,147.99,
108.96,148.14,
108.98,148.29,
108.99,,