File: DSC/2025_04_11_CBD_10Cmin_n60C_150C_x3.csv
Filename,2025_04_11_CBD_10Cmin_n60C_150C_x3
Instrument name,DSC2A-00468 (192.168.1.100)
Operator,Yarger
rundate,4/12/2025
Sample name,2025_04_11_CBD_10Cmin_n60C_150C_x3
proceduresegments,Data Off ; Equilibrate -60.00 °C; Data On ; Ramp 10.00 °C/min to 150.00 °C; Data Off ; Isothermal 1.0 min; Data On ; Ramp 10.00 °C/min to -60.00 °C; Data Off ; Isothermal 1.0 min; Data On ; Ramp 10.00 °C/min to 150.00 °C; Data Off ; Isothermal 1.0 min; Data On ; Ramp 10.00 °C/min to -60.00 °C; Data Off ; Isothermal 1.0 min; Data On ; Ramp 10.00 °C/min to 150.00 °C
[File Parameters]
Run date,4/12/2025 12:39:26 AM
Trios version,5.1.1.46572
Original File Name,
Current File Name,D:\DSC2500\JYarger\2025_04_11_CBD_10Cmin_n60C_150C_x3.tri
[Procedure]
Procedure Name,CBD_n60_150C_10Cmin_x3
Sample Name,2025_04_11_CBD_10Cmin_n60C_150C_x3
Sample Mass,5.09 mg
Reference Sample Mass,0 mg
Pan Mass,54.65 mg
Pan Number,14
Reference Pan Mass,53.32 mg
Reference Pan Number,10
Pan Type,Tzero Aluminum Hermetic
Comments,Hermetic Sealed Al DSC Consumables Pan/Lids.
Project Name,CA
Operator,Yarger
Test,Custom
Unload Max Temperature,30
Unload Min Temperature,30
Load Max Temperature,30
Load Min Temperature,30
Stop on Gas Flow Error,Yes
[Signal List]
Signal #1,Time (min)
Signal #2,Temperature (°C)
Signal #3,Heat Flow (mW)
Signal #4,Delta T (µV)
Signal #5,Delta Tzero (µV)
Signal #6,Tzero Temperature (°C)
Signal #7,Cell Purge (mL/min)
Signal #8,Heater Temp (°C)
Signal #9,Power Delivered (W)
Signal #10,Reference Junction Temperature (°C)
Signal #11,Flange Temperature (°C)
Signal #12,Heat Flow Phase (rad)
Signal #13,Total Heat Capacity (J/°C)
Signal #14,Heat Capacity (J/°C)
[Configuration]
Company Name,ASU
Instrument Name,DSC2A-00468
Instrument Type,DSC2500
Serial Number,DSC2A-00468
IP,192.168.1.100
Location of Instrument,MRRC
DisplayType,Unknown
Sample Interval ,0.1 s/pt
Selected Heat Flow,T4P
Exotherm Direction,Down
Cell Serial,DRC2-00792
Lid Type,Standard
Cooler,RCS 90
Leave Cooler on at End of Sequence,On
Gas 2,Nitrogen
Gas Selected,Channel 1
Flow Rate,50 mL/min
Secondary Purge,On
Licensed Heat Flow,Heat Flow T4P
Modulation Licensed,Yes
[Versions]
Common IDD Version,1
Cortex Version,VER 2.10.2.31
Driver,5.0.0.6
GDM Version,1.0.3.3
TouchscreenVersion,1.0.0.16145
FEP Version,1.2.1.21
FEP Bootloader,2.0.0.5
AutoSampler Version,2.1.1.26
Auto Sampler Bootloader,2.0.0.5
FCM Version,1.1.0.3
FCM Bootloader,2.0.0.5
[Experiment Logs]
Experiment Log Entry # 1,Data On set to 0
Experiment Log Entry # 3,Equilibrate Segment -60 (C) Started
Experiment Log Entry # 5,Air Cool is off.
Experiment Log Entry # 7,Data On set to 1
Experiment Log Entry # 9,Ramp Segment 10 C/min to 150 Started
Experiment Log Entry # 11,Data On set to 0
Experiment Log Entry # 13,Isothermal Segment 1 min started
Experiment Log Entry # 15,Data On set to 1
Experiment Log Entry # 17,Ramp Segment 10 C/min to -60 Started
Experiment Log Entry # 19,Data On set to 0
Experiment Log Entry # 21,Isothermal Segment 1 min started
Experiment Log Entry # 23,Data On set to 1
Experiment Log Entry # 25,Ramp Segment 10 C/min to 150 Started
Experiment Log Entry # 27,Data On set to 0
Experiment Log Entry # 29,Isothermal Segment 1 min started
Experiment Log Entry # 31,Data On set to 1
Experiment Log Entry # 33,Ramp Segment 10 C/min to -60 Started
Experiment Log Entry # 35,Data On set to 0
Experiment Log Entry # 37,Isothermal Segment 1 min started
Experiment Log Entry # 39,Data On set to 1
Experiment Log Entry # 41,Ramp Segment 10 C/min to 150 Started
[Method Log]
Method Log Entry # 1,Data Off
Method Log Entry # 2,Equilibrate -60 °C
Method Log Entry # 3,Data On
Method Log Entry # 4,(Ramp 103164) Ramp 10 °C/minute to 150 °C
Method Log Entry # 5,Data Off
Method Log Entry # 6,Isothermal 1 minutes
Method Log Entry # 7,Data On
Method Log Entry # 8,(Ramp 103168) Ramp 10 °C/minute to -60 °C
Method Log Entry # 9,Data Off
Method Log Entry # 10,Isothermal 1 minutes
Method Log Entry # 11,Data On
Method Log Entry # 12,(Ramp 103172) Ramp 10 °C/minute to 150 °C
Method Log Entry # 13,Data Off
Method Log Entry # 14,Isothermal 1 minutes
Method Log Entry # 15,Data On
Method Log Entry # 16,(Ramp 103176) Ramp 10 °C/minute to -60 °C
Method Log Entry # 17,Data Off
Method Log Entry # 18,Isothermal 1 minutes
Method Log Entry # 19,Data On
Method Log Entry # 20,(Ramp 103180) Ramp 10 °C/minute to 150 °C
Cell Serial,DRC2-00792
[T1 Calibration]
Slope,-0.008529666
Offset,9.636258
Initial Temperature,98.23
GUID,f8bfdadc-4977-4fdf-ba6d-0ba9134940c3
[TZero Calibration]
Date Applied,11/29/2022 4:06:13 PM
Description,From -89.059 °C to 396.009 °C at 20.000°C/min
Gas Type,Nitrogen
Pan Type,None
Source Files 1,C:\Users\yargerlab\Desktop\DSC Data\General\TZero_calibration_11_29_22_2nd(2).tri
Source Files 2,C:\Users\yargerlab\Desktop\DSC Data\General\TZero_calibration_11_29_22_2nd(3).tri
Delta T Offset,13.05235
Delta T Slope,-0.007271007
Delta T0 Offset,-13.69128
Delta T0 Slope,0.06063341
[Temperature Calibration]
Date Applied,11/29/2022 7:12:28 PM
Description,From 106.590 °C to 186.590 °C at 10.000°C/min
Gas Type,Nitrogen
Pan Type,Tzero Aluminum Hermetic
Source Files 1,C:\Users\yargerlab\Desktop\DSC Data\General\Indium(6).tri
Measured 1,157.391
Known 1,156.598
[Cell Constant Calibration]
Date Applied,11/29/2022 7:12:29 PM
Description,From 106.590 °C to 186.590 °C at 10.000°C/min
Gas Type,Nitrogen
Pan Type,Tzero Aluminum Hermetic
Source Files 1,C:\Users\yargerlab\Desktop\DSC Data\General\Indium(6).tri
T4P KCell,1.006051
Onset Slope,63.26126 mW/°C
[Direct Cp Calibration]
Date Applied,11/30/2022 11:04:51 AM
Description,From -79.983 °C to 298.409 °C at 10.000°C/min
Gas Type,Nitrogen
Pan Type,Tzero Aluminum Hermetic
Source Files 1,C:\Users\yargerlab\Desktop\DSC Data\General\Sapphire_Heat_Capacity_11_30_22.tri
[Rev Cp Calibration]
Date Applied,11/30/2022 1:58:51 PM
Description,From -79.996 °C to 292.812 °C at 3.000°C/min
Gas Type,Nitrogen
Pan Type,Tzero Aluminum Hermetic
Source Files 1,C:\Users\yargerlab\Desktop\DSC Data\General\Sapphire_MDSC_Calibration_11_30_22.tri
[step]
Ramp 10.00 °C/min to 150.00 °C
Time,Temperature,Heat Flow (Normalized)
min,°C,W/g
0.00,-59.69,-0.033
0.01,-59.70,-0.033
0.03,-59.71,-0.030
0.05,-59.71,-0.025
0.06,-59.71,-0.021
0.08,-59.69,-0.018
0.09,-59.66,-0.013
0.11,-59.63,-0.008
0.12,-59.57,0.002
0.14,-59.50,0.013
0.15,-59.42,0.025
0.16,-59.34,0.040
0.18,-59.24,0.053
0.19,-59.13,0.070
0.21,-59.02,0.084
0.23,-58.91,0.096
0.24,-58.79,0.110
0.26,-58.66,0.119
0.27,-58.54,0.128
0.29,-58.41,0.136
0.30,-58.28,0.143
0.31,-58.15,0.150
0.33,-58.01,0.155
0.35,-57.87,0.159
0.36,-57.74,0.164
0.38,-57.60,0.166
0.39,-57.46,0.170
0.40,-57.32,0.174
0.42,-57.18,0.175
0.44,-57.04,0.178
0.45,-56.90,0.180
0.46,-56.76,0.181
0.48,-56.61,0.182
0.50,-56.47,0.183
0.51,-56.33,0.187
0.53,-56.18,0.187
0.54,-56.04,0.187
0.55,-55.89,0.187
0.57,-55.75,0.188
0.58,-55.60,0.189
0.60,-55.46,0.189
0.62,-55.31,0.190
0.63,-55.17,0.191
0.65,-55.02,0.191
0.66,-54.87,0.191
0.68,-54.73,0.191
0.69,-54.58,0.192
0.70,-54.44,0.192
0.72,-54.29,0.192
0.73,-54.14,0.192
0.75,-53.99,0.193
0.77,-53.85,0.193
0.78,-53.70,0.193
0.80,-53.55,0.194
0.81,-53.40,0.194
0.83,-53.26,0.194
0.84,-53.11,0.194
0.85,-52.96,0.195
0.87,-52.81,0.195
0.88,-52.67,0.195
0.90,-52.52,0.195
0.92,-52.37,0.196
0.93,-52.22,0.196
0.95,-52.07,0.196
0.96,-51.93,0.196
0.98,-51.78,0.197
0.99,-51.63,0.197
1.00,-51.48,0.197
1.02,-51.33,0.198
1.03,-51.18,0.198
1.05,-51.04,0.198
1.07,-50.89,0.198
1.08,-50.74,0.198
1.09,-50.59,0.199
1.11,-50.44,0.199
1.13,-50.29,0.199
1.14,-50.14,0.199
1.16,-50.00,0.199
1.17,-49.85,0.200
1.18,-49.70,0.200
1.20,-49.55,0.200
1.22,-49.40,0.201
1.23,-49.25,0.201
1.24,-49.10,0.201
1.26,-48.95,0.201
1.28,-48.80,0.201
1.29,-48.65,0.201
1.31,-48.50,0.201
1.32,-48.35,0.202
1.33,-48.20,0.202
1.35,-48.06,0.202
1.37,-47.91,0.202
1.38,-47.76,0.202
1.39,-47.61,0.202
1.41,-47.46,0.203
1.43,-47.31,0.203
1.44,-47.16,0.203
1.46,-47.01,0.203
1.47,-46.86,0.203
1.48,-46.71,0.203
1.50,-46.56,0.203
1.52,-46.41,0.204
1.53,-46.26,0.204
1.54,-46.11,0.204
1.56,-45.96,0.204
1.58,-45.81,0.204
1.59,-45.66,0.204
1.61,-45.51,0.204
1.62,-45.36,0.205
1.63,-45.21,0.205
1.65,-45.06,0.205
1.67,-44.91,0.205
1.68,-44.76,0.205
1.69,-44.61,0.205
1.71,-44.46,0.206
1.73,-44.31,0.206
1.74,-44.16,0.206
1.76,-44.01,0.206
1.77,-43.86,0.206
1.78,-43.71,0.206
1.80,-43.56,0.206
1.82,-43.41,0.206
1.83,-43.26,0.207
1.84,-43.11,0.207
1.86,-42.96,0.207
1.88,-42.81,0.207
1.89,-42.66,0.207
1.91,-42.51,0.207
1.92,-42.36,0.207
1.93,-42.21,0.208
1.95,-42.06,0.208
1.97,-41.91,0.208
1.98,-41.76,0.208
1.99,-41.61,0.208
2.01,-41.46,0.208
2.03,-41.31,0.208
2.04,-41.16,0.209
2.06,-41.01,0.209
2.07,-40.86,0.209
2.08,-40.71,0.209
2.10,-40.56,0.209
2.12,-40.41,0.209
2.13,-40.26,0.209
2.14,-40.11,0.209
2.16,-39.96,0.210
2.18,-39.81,0.210
2.19,-39.66,0.210
2.21,-39.51,0.210
2.22,-39.36,0.210
2.24,-39.21,0.210
2.25,-39.06,0.211
2.26,-38.91,0.211
2.28,-38.76,0.211
2.29,-38.61,0.211
2.31,-38.46,0.211
2.33,-38.31,0.212
2.34,-38.16,0.212
2.36,-38.01,0.212
2.37,-37.86,0.212
2.39,-37.71,0.212
2.40,-37.56,0.212
2.41,-37.41,0.212
2.43,-37.26,0.212
2.44,-37.11,0.213
2.46,-36.96,0.213
2.48,-36.81,0.213
2.49,-36.66,0.213
2.51,-36.51,0.213
2.52,-36.36,0.213
2.54,-36.21,0.213
2.55,-36.06,0.214
2.56,-35.91,0.214
2.58,-35.76,0.214
2.59,-35.61,0.214
2.61,-35.46,0.214
2.63,-35.31,0.214
2.64,-35.16,0.214
2.66,-35.01,0.215
2.67,-34.86,0.215
2.69,-34.71,0.215
2.70,-34.56,0.215
2.71,-34.41,0.215
2.73,-34.26,0.215
2.74,-34.11,0.216
2.76,-33.96,0.216
2.78,-33.81,0.216
2.79,-33.66,0.216
2.81,-33.51,0.216
2.82,-33.36,0.216
2.84,-33.21,0.216
2.85,-33.06,0.217
2.86,-32.91,0.217
2.88,-32.76,0.217
2.89,-32.60,0.217
2.91,-32.46,0.217
2.93,-32.31,0.217
2.94,-32.16,0.218
2.96,-32.01,0.218
2.97,-31.85,0.218
2.99,-31.71,0.218
3.00,-31.56,0.218
3.01,-31.41,0.218
3.03,-31.26,0.219
3.04,-31.11,0.219
3.06,-30.95,0.219
3.08,-30.81,0.219
3.09,-30.65,0.219
3.11,-30.50,0.219
3.12,-30.35,0.220
3.14,-30.20,0.220
3.15,-30.05,0.220
3.16,-29.90,0.220
3.18,-29.75,0.220
3.19,-29.60,0.220
3.21,-29.45,0.220
3.23,-29.30,0.221
3.24,-29.15,0.221
3.26,-29.00,0.221
3.27,-28.85,0.221
3.29,-28.70,0.221
3.30,-28.55,0.221
3.31,-28.40,0.222
3.33,-28.25,0.222
3.34,-28.10,0.222
3.36,-27.95,0.222
3.38,-27.80,0.222
3.39,-27.65,0.223
3.41,-27.50,0.223
3.42,-27.35,0.223
3.44,-27.20,0.223
3.45,-27.05,0.223
3.46,-26.90,0.224
3.48,-26.75,0.224
3.49,-26.60,0.224
3.51,-26.45,0.224
3.53,-26.30,0.225
3.54,-26.15,0.225
3.56,-26.00,0.225
3.57,-25.85,0.225
3.59,-25.70,0.225
3.60,-25.55,0.225
3.61,-25.40,0.226
3.63,-25.25,0.226
3.64,-25.10,0.227
3.66,-24.95,0.227
3.68,-24.80,0.227
3.69,-24.65,0.228
3.71,-24.50,0.228
3.72,-24.35,0.228
3.74,-24.20,0.228
3.75,-24.05,0.228
3.76,-23.90,0.229
3.78,-23.75,0.229
3.79,-23.60,0.229
3.81,-23.45,0.229
3.83,-23.30,0.229
3.84,-23.15,0.230
3.86,-23.00,0.230
3.87,-22.85,0.231
3.89,-22.70,0.231
3.90,-22.55,0.231
3.91,-22.40,0.231
3.93,-22.25,0.232
3.94,-22.10,0.232
3.96,-21.95,0.232
3.98,-21.80,0.233
3.99,-21.65,0.233
4.01,-21.50,0.233
4.02,-21.35,0.233
4.04,-21.20,0.234
4.05,-21.05,0.234
4.06,-20.90,0.235
4.08,-20.75,0.235
4.09,-20.60,0.235
4.11,-20.45,0.236
4.13,-20.30,0.236
4.14,-20.15,0.236
4.16,-20.00,0.237
4.17,-19.85,0.238
4.19,-19.70,0.238
4.20,-19.55,0.238
4.21,-19.40,0.239
4.23,-19.25,0.239
4.24,-19.10,0.240
4.26,-18.95,0.240
4.28,-18.80,0.241
4.29,-18.64,0.242
4.30,-18.50,0.242
4.32,-18.35,0.243
4.34,-18.20,0.244
4.35,-18.05,0.245
4.36,-17.90,0.246
4.38,-17.75,0.247
4.40,-17.60,0.247
4.41,-17.45,0.248
4.43,-17.30,0.248
4.44,-17.15,0.250
4.45,-17.00,0.250
4.47,-16.85,0.252
4.49,-16.70,0.254
4.50,-16.55,0.255
4.51,-16.40,0.256
4.53,-16.25,0.258
4.55,-16.10,0.259
4.56,-15.95,0.261
4.58,-15.80,0.262
4.59,-15.65,0.264
4.60,-15.50,0.266
4.62,-15.35,0.268
4.64,-15.20,0.269
4.65,-15.05,0.271
4.66,-14.90,0.273
4.68,-14.75,0.275
4.70,-14.60,0.277
4.71,-14.46,0.281
4.73,-14.30,0.282
4.74,-14.16,0.285
4.75,-14.01,0.287
4.77,-13.86,0.290
4.79,-13.71,0.292
4.80,-13.56,0.294
4.81,-13.41,0.297
4.83,-13.26,0.300
4.85,-13.11,0.302
4.86,-12.96,0.304
4.88,-12.81,0.307
4.89,-12.66,0.309
4.90,-12.51,0.311
4.92,-12.36,0.313
4.94,-12.21,0.314
4.95,-12.06,0.316
4.96,-11.92,0.318
4.98,-11.77,0.319
5.00,-11.62,0.320
5.01,-11.47,0.320
5.03,-11.32,0.321
5.04,-11.17,0.321
5.05,-11.02,0.322
5.07,-10.87,0.322
5.09,-10.72,0.322
5.10,-10.57,0.322
5.11,-10.42,0.322
5.13,-10.27,0.322
5.15,-10.12,0.322
5.16,-9.97,0.321
5.18,-9.82,0.320
5.19,-9.67,0.320
5.20,-9.51,0.319
5.22,-9.37,0.318
5.24,-9.21,0.318
5.25,-9.06,0.317
5.26,-8.91,0.316
5.28,-8.76,0.316
5.30,-8.61,0.315
5.31,-8.46,0.315
5.33,-8.31,0.315
5.34,-8.16,0.314
5.35,-8.01,0.314
5.37,-7.86,0.313
5.39,-7.71,0.313
5.40,-7.56,0.313
5.41,-7.41,0.312
5.43,-7.26,0.312
5.45,-7.11,0.312
5.46,-6.96,0.311
5.48,-6.81,0.311
5.49,-6.66,0.311
5.50,-6.51,0.311
5.52,-6.35,0.311
5.54,-6.21,0.310
5.55,-6.06,0.310
5.56,-5.91,0.310
5.58,-5.76,0.310
5.60,-5.60,0.310
5.61,-5.45,0.309
5.63,-5.30,0.309
5.64,-5.15,0.309
5.65,-5.00,0.309
5.67,-4.85,0.309
5.69,-4.70,0.309
5.70,-4.55,0.309
5.71,-4.40,0.309
5.73,-4.25,0.309
5.75,-4.10,0.308
5.76,-3.95,0.308
5.78,-3.80,0.308
5.79,-3.65,0.308
5.80,-3.50,0.308
5.82,-3.35,0.308
5.84,-3.20,0.308
5.85,-3.05,0.308
5.86,-2.90,0.308
5.88,-2.75,0.308
5.90,-2.60,0.308
5.91,-2.45,0.308
5.93,-2.30,0.308
5.94,-2.15,0.308
5.95,-2.00,0.308
5.97,-1.85,0.308
5.99,-1.70,0.308
6.00,-1.55,0.308
6.01,-1.40,0.308
6.03,-1.25,0.308
6.05,-1.10,0.308
6.06,-0.95,0.308
6.08,-0.80,0.308
6.09,-0.65,0.308
6.10,-0.50,0.308
6.12,-0.35,0.309
6.14,-0.20,0.309
6.15,-0.05,0.309
6.16,0.10,0.309
6.18,0.25,0.309
6.20,0.40,0.309
6.21,0.55,0.309
6.23,0.70,0.309
6.24,0.85,0.309
6.25,1.00,0.309
6.27,1.16,0.309
6.29,1.31,0.309
6.30,1.46,0.309
6.31,1.60,0.309
6.33,1.76,0.309
6.35,1.91,0.309
6.36,2.06,0.310
6.38,2.21,0.310
6.39,2.36,0.310
6.40,2.51,0.310
6.42,2.66,0.310
6.44,2.81,0.310
6.45,2.96,0.310
6.46,3.11,0.310
6.48,3.26,0.310
6.50,3.41,0.310
6.51,3.56,0.310
6.53,3.71,0.311
6.54,3.86,0.311
6.55,4.01,0.311
6.57,4.16,0.311
6.59,4.31,0.311
6.60,4.46,0.311
6.61,4.61,0.311
6.63,4.76,0.312
6.65,4.91,0.312
6.66,5.06,0.312
6.68,5.21,0.312
6.69,5.36,0.312
6.70,5.51,0.312
6.72,5.66,0.312
6.74,5.81,0.312
6.75,5.96,0.312
6.76,6.11,0.312
6.78,6.26,0.312
6.80,6.41,0.313
6.81,6.56,0.313
6.83,6.71,0.313
6.84,6.86,0.313
6.85,7.01,0.313
6.87,7.16,0.313
6.89,7.31,0.313
6.90,7.46,0.313
6.91,7.61,0.314
6.93,7.76,0.314
6.95,7.91,0.314
6.96,8.06,0.314
6.98,8.21,0.314
6.99,8.36,0.314
7.00,8.51,0.314
7.02,8.67,0.314
7.04,8.82,0.314
7.05,8.97,0.314
7.06,9.12,0.315
7.08,9.27,0.315
7.10,9.42,0.315
7.11,9.56,0.315
7.13,9.72,0.315
7.14,9.87,0.315
7.15,10.02,0.315
7.17,10.17,0.315
7.19,10.32,0.316
7.20,10.47,0.316
7.21,10.62,0.316
7.23,10.77,0.316
7.25,10.92,0.316
7.26,11.07,0.316
7.28,11.22,0.316
7.29,11.37,0.316
7.30,11.52,0.317
7.32,11.67,0.317
7.34,11.82,0.317
7.35,11.97,0.317
7.36,12.12,0.317
7.38,12.27,0.317
7.40,12.42,0.317
7.41,12.57,0.317
7.43,12.72,0.318
7.44,12.87,0.318
7.45,13.02,0.318
7.47,13.17,0.318
7.49,13.32,0.318
7.50,13.47,0.318
7.51,13.62,0.318
7.53,13.77,0.318
7.55,13.92,0.319
7.56,14.07,0.319
7.58,14.22,0.319
7.59,14.37,0.319
7.60,14.52,0.319
7.62,14.67,0.319
7.64,14.82,0.319
7.65,14.97,0.319
7.66,15.12,0.320
7.68,15.27,0.320
7.70,15.42,0.320
7.71,15.57,0.320
7.73,15.72,0.320
7.74,15.87,0.320
7.75,16.02,0.320
7.77,16.17,0.320
7.79,16.32,0.321
7.80,16.47,0.321
7.81,16.63,0.321
7.83,16.78,0.321
7.85,16.93,0.321
7.86,17.08,0.321
7.88,17.23,0.321
7.89,17.38,0.321
7.90,17.53,0.321
7.92,17.68,0.321
7.94,17.83,0.321
7.95,17.98,0.322
7.96,18.13,0.322
7.98,18.28,0.322
8.00,18.43,0.322
8.01,18.58,0.322
8.03,18.73,0.322
8.04,18.88,0.322
8.05,19.03,0.322
8.07,19.18,0.323
8.09,19.33,0.323
8.10,19.48,0.323
8.11,19.63,0.323
8.13,19.78,0.323
8.15,19.93,0.323
8.16,20.08,0.323
8.18,20.23,0.324
8.19,20.38,0.324
8.20,20.53,0.324
8.22,20.68,0.324
8.24,20.83,0.324
8.25,20.98,0.324
8.26,21.13,0.324
8.28,21.28,0.324
8.30,21.43,0.325
8.31,21.58,0.325
8.33,21.73,0.325
8.34,21.88,0.325
8.35,22.03,0.325
8.37,22.18,0.325
8.39,22.33,0.325
8.40,22.48,0.326
8.41,22.63,0.326
8.43,22.78,0.326
8.45,22.93,0.326
8.46,23.08,0.326
8.48,23.23,0.326
8.49,23.38,0.326
8.50,23.53,0.326
8.52,23.68,0.326
8.53,23.83,0.327
8.55,23.98,0.327
8.57,24.13,0.327
8.58,24.28,0.327
8.60,24.43,0.327
8.61,24.58,0.327
8.63,24.73,0.327
8.64,24.88,0.327
8.65,25.03,0.328
8.67,25.18,0.328
8.68,25.33,0.328
8.70,25.48,0.328
8.72,25.63,0.328
8.73,25.78,0.328
8.75,25.93,0.328
8.76,26.08,0.329
8.78,26.23,0.329
8.79,26.38,0.329
8.80,26.54,0.329
8.82,26.68,0.329
8.83,26.83,0.329
8.85,26.98,0.330
8.87,27.14,0.330
8.88,27.28,0.330
8.90,27.44,0.330
8.91,27.58,0.330
8.93,27.74,0.330
8.94,27.88,0.330
8.95,28.04,0.330
8.97,28.19,0.331
8.98,28.34,0.331
9.00,28.49,0.331
9.02,28.64,0.331
9.03,28.79,0.331
9.05,28.94,0.331
9.06,29.09,0.331
9.08,29.24,0.332
9.09,29.39,0.332
9.10,29.54,0.332
9.12,29.69,0.332
9.13,29.84,0.332
9.15,29.99,0.332
9.17,30.14,0.332
9.18,30.29,0.333
9.20,30.44,0.333
9.21,30.59,0.333
9.23,30.74,0.333
9.24,30.89,0.333
9.25,31.04,0.333
9.27,31.19,0.333
9.28,31.34,0.334
9.30,31.49,0.334
9.32,31.64,0.334
9.33,31.79,0.334
9.35,31.94,0.334
9.36,32.09,0.334
9.38,32.24,0.334
9.39,32.39,0.334
9.40,32.54,0.334
9.42,32.69,0.335
9.43,32.84,0.335
9.45,32.99,0.335
9.47,33.14,0.335
9.48,33.29,0.335
9.50,33.44,0.335
9.51,33.59,0.335
9.53,33.74,0.336
9.54,33.89,0.336
9.55,34.04,0.336
9.57,34.19,0.336
9.58,34.34,0.336
9.60,34.49,0.336
9.62,34.64,0.336
9.63,34.80,0.336
9.65,34.94,0.337
9.66,35.09,0.337
9.68,35.25,0.337
9.69,35.40,0.337
9.70,35.55,0.337
9.72,35.70,0.337
9.73,35.85,0.337
9.75,36.00,0.337
9.77,36.15,0.338
9.78,36.30,0.338
9.80,36.45,0.338
9.81,36.60,0.338
9.83,36.75,0.338
9.84,36.90,0.338
9.85,37.05,0.338
9.87,37.20,0.338
9.88,37.35,0.338
9.90,37.50,0.339
9.92,37.65,0.339
9.93,37.80,0.339
9.95,37.95,0.339
9.96,38.10,0.339
9.98,38.25,0.339
9.99,38.40,0.339
10.00,38.55,0.340
10.02,38.70,0.340
10.03,38.85,0.340
10.05,39.00,0.340
10.07,39.15,0.340
10.08,39.30,0.340
10.10,39.45,0.340
10.11,39.60,0.340
10.13,39.75,0.341
10.14,39.90,0.341
10.15,40.05,0.341
10.17,40.20,0.341
10.18,40.35,0.341
10.20,40.50,0.341
10.22,40.65,0.341
10.23,40.80,0.342
10.25,40.95,0.342
10.26,41.10,0.342
10.28,41.25,0.342
10.29,41.40,0.342
10.30,41.55,0.342
10.32,41.70,0.342
10.33,41.85,0.342
10.35,42.00,0.343
10.37,42.15,0.343
10.38,42.30,0.343
10.40,42.45,0.343
10.41,42.60,0.343
10.43,42.75,0.343
10.44,42.90,0.343
10.45,43.05,0.343
10.47,43.20,0.344
10.48,43.35,0.344
10.50,43.50,0.344
10.52,43.65,0.344
10.53,43.80,0.344
10.55,43.95,0.344
10.56,44.10,0.344
10.58,44.25,0.344
10.59,44.40,0.344
10.60,44.55,0.345
10.62,44.70,0.345
10.63,44.86,0.345
10.65,45.01,0.345
10.67,45.16,0.345
10.68,45.31,0.345
10.70,45.46,0.346
10.71,45.61,0.346
10.73,45.76,0.346
10.74,45.91,0.346
10.75,46.06,0.346
10.77,46.21,0.346
10.78,46.36,0.346
10.80,46.51,0.346
10.82,46.66,0.346
10.83,46.81,0.347
10.85,46.96,0.347
10.86,47.11,0.347
10.88,47.26,0.347
10.89,47.41,0.347
10.90,47.56,0.347
10.92,47.71,0.347
10.93,47.86,0.347
10.95,48.01,0.348
10.97,48.16,0.348
10.98,48.31,0.348
11.00,48.46,0.348
11.01,48.61,0.348
11.03,48.76,0.348
11.04,48.91,0.348
11.05,49.06,0.349
11.07,49.21,0.349
11.08,49.36,0.349
11.10,49.51,0.349
11.12,49.66,0.349
11.13,49.81,0.349
11.15,49.96,0.349
11.16,50.11,0.349
11.18,50.26,0.350
11.19,50.41,0.350
11.20,50.56,0.350
11.22,50.71,0.350
11.23,50.86,0.350
11.25,51.01,0.350
11.27,51.16,0.350
11.28,51.31,0.350
11.30,51.46,0.351
11.31,51.61,0.351
11.33,51.76,0.351
11.34,51.91,0.351
11.35,52.06,0.351
11.37,52.21,0.351
11.38,52.36,0.351
11.40,52.51,0.352
11.42,52.66,0.352
11.43,52.81,0.352
11.45,52.96,0.352
11.46,53.11,0.352
11.48,53.26,0.352
11.49,53.41,0.352
11.50,53.57,0.352
11.52,53.72,0.353
11.53,53.86,0.353
11.55,54.02,0.353
11.57,54.17,0.353
11.58,54.32,0.353
11.60,54.47,0.353
11.61,54.62,0.353
11.63,54.77,0.354
11.64,54.92,0.354
11.65,55.07,0.354
11.67,55.22,0.354
11.68,55.37,0.354
11.70,55.52,0.354
11.72,55.67,0.354
11.73,55.82,0.355
11.75,55.97,0.355
11.76,56.12,0.355
11.78,56.27,0.355
11.79,56.42,0.355
11.80,56.57,0.355
11.82,56.72,0.355
11.83,56.87,0.355
11.85,57.02,0.355
11.87,57.17,0.356
11.88,57.32,0.356
11.90,57.47,0.356
11.91,57.62,0.356
11.93,57.77,0.356
11.94,57.92,0.356
11.95,58.07,0.356
11.97,58.22,0.357
11.98,58.37,0.357
12.00,58.52,0.357
12.02,58.67,0.357
12.03,58.82,0.357
12.05,58.97,0.357
12.06,59.12,0.357
12.08,59.27,0.357
12.09,59.42,0.357
12.10,59.57,0.358
12.12,59.72,0.358
12.13,59.87,0.358
12.15,60.02,0.358
12.17,60.17,0.358
12.18,60.32,0.358
12.20,60.47,0.358
12.21,60.62,0.358
12.23,60.77,0.359
12.24,60.92,0.359
12.25,61.07,0.359
12.27,61.22,0.359
12.28,61.37,0.359
12.30,61.52,0.359
12.32,61.67,0.359
12.33,61.82,0.359
12.35,61.97,0.359
12.36,62.12,0.360
12.38,62.27,0.360
12.39,62.43,0.360
12.40,62.57,0.360
12.42,62.73,0.360
12.43,62.87,0.360
12.45,63.03,0.360
12.47,63.18,0.360
12.48,63.33,0.361
12.50,63.48,0.361
12.51,63.63,0.361
12.53,63.78,0.361
12.54,63.93,0.361
12.55,64.08,0.361
12.57,64.23,0.361
12.58,64.38,0.362
12.60,64.53,0.362
12.62,64.68,0.362
12.63,64.83,0.362
12.65,64.98,0.362
12.66,65.13,0.362
12.68,65.28,0.362
12.69,65.43,0.362
12.70,65.58,0.362
12.72,65.73,0.363
12.73,65.88,0.363
12.75,66.03,0.363
12.77,66.18,0.363
12.78,66.33,0.363
12.80,66.48,0.363
12.81,66.63,0.363
12.83,66.78,0.363
12.84,66.93,0.363
12.85,67.08,0.364
12.87,67.23,0.364
12.88,67.38,0.364
12.90,67.53,0.364
12.92,67.68,0.364
12.93,67.83,0.364
12.95,67.98,0.364
12.96,68.13,0.364
12.98,68.28,0.364
12.99,68.43,0.365
13.00,68.58,0.365
13.02,68.73,0.365
13.03,68.88,0.365
13.05,69.03,0.365
13.07,69.18,0.365
13.08,69.33,0.365
13.10,69.48,0.365
13.11,69.63,0.365
13.13,69.78,0.366
13.14,69.93,0.366
13.15,70.08,0.366
13.17,70.23,0.366
13.18,70.38,0.366
13.20,70.53,0.366
13.22,70.68,0.366
13.23,70.83,0.366
13.25,70.98,0.366
13.26,71.13,0.367
13.28,71.28,0.367
13.29,71.43,0.367
13.30,71.59,0.367
13.32,71.73,0.367
13.33,71.89,0.367
13.35,72.04,0.367
13.37,72.18,0.367
13.38,72.34,0.367
13.40,72.48,0.368
13.41,72.64,0.368
13.43,72.79,0.368
13.44,72.93,0.368
13.45,73.09,0.368
13.47,73.24,0.368
13.48,73.39,0.368
13.50,73.54,0.368
13.52,73.69,0.369
13.53,73.84,0.369
13.55,73.99,0.369
13.56,74.14,0.369
13.58,74.29,0.369
13.59,74.44,0.369
13.60,74.59,0.369
13.62,74.74,0.369
13.63,74.89,0.369
13.65,75.04,0.370
13.67,75.19,0.370
13.68,75.34,0.370
13.70,75.49,0.370
13.71,75.64,0.370
13.73,75.79,0.370
13.74,75.94,0.370
13.75,76.09,0.371
13.77,76.24,0.371
13.78,76.39,0.371
13.80,76.54,0.371
13.82,76.69,0.371
13.83,76.84,0.371
13.85,76.99,0.371
13.86,77.14,0.371
13.88,77.29,0.371
13.89,77.44,0.372
13.90,77.59,0.372
13.92,77.74,0.372
13.93,77.89,0.372
13.95,78.04,0.372
13.97,78.19,0.372
13.98,78.34,0.372
14.00,78.49,0.372
14.01,78.64,0.373
14.03,78.79,0.373
14.04,78.94,0.373
14.05,79.09,0.373
14.07,79.24,0.373
14.08,79.39,0.373
14.10,79.54,0.373
14.12,79.69,0.373
14.13,79.84,0.373
14.15,79.99,0.374
14.16,80.14,0.374
14.18,80.29,0.374
14.19,80.44,0.374
14.20,80.59,0.374
14.22,80.74,0.374
14.23,80.89,0.374
14.25,81.04,0.374
14.27,81.19,0.374
14.28,81.34,0.375
14.30,81.49,0.375
14.31,81.64,0.375
14.33,81.79,0.375
14.34,81.94,0.375
14.35,82.09,0.375
14.37,82.24,0.375
14.38,82.39,0.375
14.40,82.54,0.375
14.42,82.69,0.375
14.43,82.84,0.375
14.45,82.99,0.375
14.46,83.14,0.376
14.48,83.29,0.376
14.49,83.44,0.376
14.50,83.59,0.376
14.52,83.75,0.376
14.53,83.90,0.376
14.55,84.05,0.376
14.57,84.20,0.376
14.58,84.35,0.376
14.60,84.50,0.376
14.61,84.65,0.376
14.63,84.80,0.376
14.64,84.95,0.377
14.65,85.10,0.377
14.67,85.25,0.377
14.68,85.40,0.377
14.70,85.55,0.377
14.72,85.70,0.377
14.73,85.85,0.377
14.75,86.00,0.377
14.76,86.15,0.377
14.78,86.30,0.377
14.79,86.45,0.377
14.80,86.60,0.377
14.82,86.75,0.377
14.83,86.90,0.378
14.85,87.05,0.378
14.87,87.20,0.378
14.88,87.35,0.378
14.90,87.50,0.378
14.91,87.65,0.378
14.93,87.80,0.378
14.94,87.95,0.378
14.95,88.10,0.379
14.97,88.25,0.379
14.98,88.40,0.379
15.00,88.55,0.379
15.02,88.70,0.379
15.03,88.85,0.379
15.05,89.00,0.379
15.06,89.15,0.379
15.08,89.30,0.379
15.09,89.45,0.380
15.10,89.60,0.380
15.12,89.75,0.380
15.13,89.90,0.380
15.15,90.05,0.380
15.17,90.20,0.380
15.18,90.35,0.380
15.20,90.50,0.380
15.21,90.65,0.380
15.23,90.80,0.381
15.24,90.95,0.381
15.25,91.10,0.381
15.27,91.25,0.381
15.28,91.40,0.381
15.30,91.55,0.381
15.32,91.70,0.381
15.33,91.85,0.381
15.35,92.00,0.382
15.36,92.15,0.382
15.38,92.30,0.382
15.39,92.45,0.382
15.40,92.60,0.382
15.42,92.76,0.382
15.43,92.90,0.382
15.45,93.05,0.382
15.47,93.20,0.382
15.48,93.35,0.383
15.50,93.50,0.383
15.51,93.66,0.383
15.53,93.81,0.383
15.54,93.96,0.383
15.55,94.10,0.383
15.57,94.26,0.383
15.58,94.40,0.383
15.60,94.56,0.384
15.62,94.70,0.384
15.63,94.86,0.384
15.65,95.00,0.384
15.66,95.16,0.384
15.68,95.31,0.384
15.69,95.46,0.384
15.70,95.61,0.384
15.72,95.76,0.385
15.73,95.91,0.385
15.75,96.06,0.385
15.77,96.21,0.385
15.78,96.36,0.385
15.80,96.51,0.385
15.81,96.66,0.385
15.83,96.81,0.386
15.84,96.96,0.386
15.85,97.11,0.386
15.87,97.26,0.386
15.88,97.41,0.386
15.90,97.56,0.386
15.92,97.71,0.386
15.93,97.86,0.386
15.95,98.01,0.387
15.96,98.16,0.387
15.98,98.31,0.387
15.99,98.46,0.387
16.00,98.61,0.387
16.02,98.76,0.387
16.03,98.91,0.387
16.05,99.06,0.388
16.07,99.21,0.388
16.08,99.36,0.388
16.10,99.51,0.388
16.11,99.66,0.388
16.13,99.81,0.388
16.14,99.96,0.388
16.15,100.11,0.388
16.17,100.26,0.388
16.18,100.41,0.389
16.20,100.56,0.389
16.22,100.71,0.389
16.23,100.86,0.389
16.25,101.01,0.389
16.26,101.16,0.389
16.28,101.31,0.389
16.29,101.46,0.389
16.30,101.61,0.390
16.32,101.76,0.390
16.33,101.91,0.390
16.35,102.06,0.390
16.37,102.21,0.390
16.38,102.36,0.390
16.40,102.51,0.390
16.41,102.66,0.391
16.43,102.81,0.391
16.44,102.96,0.391
16.45,103.11,0.391
16.47,103.26,0.391
16.48,103.41,0.391
16.50,103.56,0.391
16.52,103.71,0.391
16.53,103.86,0.392
16.55,104.01,0.392
16.56,104.17,0.392
16.58,104.31,0.392
16.59,104.47,0.392
16.60,104.61,0.392
16.62,104.76,0.392
16.63,104.92,0.392
16.65,105.07,0.392
16.67,105.22,0.392
16.68,105.37,0.393
16.70,105.51,0.393
16.71,105.66,0.393
16.73,105.82,0.393
16.74,105.97,0.393
16.75,106.12,0.393
16.77,106.27,0.393
16.78,106.42,0.393
16.80,106.57,0.393
16.82,106.72,0.393
16.83,106.87,0.394
16.85,107.02,0.394
16.86,107.17,0.394
16.88,107.32,0.394
16.89,107.47,0.394
16.90,107.62,0.394
16.92,107.77,0.394
16.93,107.92,0.394
16.95,108.07,0.394
16.97,108.22,0.394
16.98,108.37,0.395
17.00,108.52,0.395
17.01,108.67,0.395
17.03,108.82,0.395
17.04,108.97,0.395
17.05,109.12,0.395
17.07,109.27,0.395
17.08,109.42,0.395
17.10,109.57,0.396
17.12,109.72,0.396
17.13,109.87,0.396
17.14,110.02,0.396
17.16,110.17,0.396
17.18,110.32,0.396
17.19,110.47,0.396
17.21,110.62,0.396
17.22,110.77,0.396
17.23,110.92,0.396
17.25,111.07,0.396
17.27,111.22,0.397
17.28,111.37,0.397
17.29,111.52,0.397
17.31,111.67,0.397
17.33,111.82,0.397
17.34,111.97,0.397
17.36,112.12,0.397
17.37,112.27,0.397
17.38,112.42,0.397
17.40,112.57,0.397
17.42,112.72,0.397
17.43,112.87,0.397
17.44,113.02,0.397
17.46,113.17,0.397
17.48,113.32,0.398
17.49,113.47,0.398
17.51,113.62,0.398
17.52,113.77,0.398
17.53,113.92,0.398
17.55,114.07,0.398
17.57,114.22,0.398
17.58,114.37,0.398
17.59,114.52,0.398
17.61,114.67,0.398
17.63,114.82,0.398
17.64,114.97,0.398
17.66,115.12,0.399
17.67,115.27,0.399
17.68,115.42,0.399
17.70,115.57,0.399
17.72,115.72,0.399
17.73,115.88,0.399
17.74,116.02,0.399
17.76,116.17,0.399
17.78,116.33,0.399
17.79,116.48,0.399
17.81,116.63,0.399
17.82,116.78,0.400
17.83,116.93,0.400
17.85,117.08,0.400
17.87,117.23,0.400
17.88,117.38,0.400
17.89,117.53,0.400
17.91,117.68,0.400
17.93,117.83,0.400
17.94,117.98,0.400
17.96,118.13,0.400
17.97,118.28,0.400
17.98,118.43,0.401
18.00,118.58,0.401
18.02,118.73,0.401
18.03,118.88,0.401
18.04,119.03,0.401
18.06,119.18,0.401
18.08,119.33,0.401
18.09,119.48,0.401
18.11,119.63,0.401
18.12,119.78,0.402
18.13,119.93,0.402
18.15,120.08,0.402
18.17,120.23,0.402
18.18,120.38,0.402
18.19,120.53,0.402
18.21,120.68,0.402
18.23,120.83,0.402
18.24,120.98,0.402
18.26,121.13,0.402
18.27,121.28,0.402
18.28,121.43,0.403
18.30,121.58,0.403
18.32,121.73,0.403
18.33,121.88,0.403
18.34,122.03,0.403
18.36,122.18,0.403
18.38,122.33,0.403
18.39,122.48,0.403
18.41,122.63,0.403
18.42,122.78,0.403
18.43,122.93,0.403
18.45,123.08,0.403
18.47,123.23,0.403
18.48,123.38,0.404
18.49,123.53,0.404
18.51,123.68,0.404
18.53,123.83,0.404
18.54,123.98,0.404
18.56,124.13,0.404
18.57,124.28,0.404
18.58,124.43,0.404
18.60,124.58,0.404
18.62,124.73,0.404
18.63,124.88,0.404
18.64,125.03,0.404
18.66,125.18,0.404
18.68,125.33,0.405
18.69,125.48,0.405
18.71,125.63,0.405
18.72,125.78,0.405
18.73,125.93,0.405
18.75,126.08,0.405
18.77,126.23,0.405
18.78,126.38,0.405
18.79,126.53,0.405
18.81,126.68,0.405
18.83,126.83,0.406
18.84,126.98,0.406
18.86,127.13,0.406
18.87,127.28,0.406
18.88,127.43,0.406
18.90,127.58,0.406
18.92,127.73,0.406
18.93,127.88,0.406
18.94,128.03,0.406
18.96,128.18,0.406
18.98,128.33,0.406
18.99,128.49,0.406
19.01,128.63,0.406
19.02,128.78,0.406
19.03,128.93,0.407
19.05,129.08,0.407
19.07,129.24,0.407
19.08,129.38,0.407
19.09,129.53,0.407
19.11,129.68,0.407
19.13,129.84,0.407
19.14,129.99,0.407
19.16,130.14,0.407
19.17,130.29,0.407
19.18,130.43,0.407
19.20,130.59,0.408
19.22,130.74,0.408
19.23,130.89,0.408
19.24,131.04,0.408
19.26,131.19,0.408
19.28,131.34,0.408
19.29,131.49,0.408
19.31,131.64,0.408
19.32,131.79,0.408
19.33,131.94,0.408
19.35,132.09,0.409
19.37,132.24,0.409
19.38,132.39,0.409
19.39,132.54,0.409
19.41,132.69,0.409
19.43,132.84,0.409
19.44,132.99,0.409
19.46,133.14,0.409
19.47,133.29,0.409
19.48,133.44,0.409
19.50,133.59,0.409
19.52,133.74,0.409
19.53,133.89,0.409
19.54,134.04,0.410
19.56,134.19,0.410
19.58,134.34,0.410
19.59,134.49,0.410
19.61,134.64,0.410
19.62,134.79,0.410
19.63,134.94,0.410
19.65,135.09,0.410
19.67,135.24,0.410
19.68,135.39,0.410
19.69,135.54,0.410
19.71,135.69,0.410
19.73,135.84,0.410
19.74,135.99,0.410
19.76,136.14,0.410
19.77,136.29,0.410
19.78,136.44,0.410
19.80,136.59,0.410
19.82,136.74,0.410
19.83,136.89,0.411
19.84,137.04,0.411
19.86,137.19,0.411
19.88,137.34,0.411
19.89,137.49,0.411
19.91,137.64,0.411
19.92,137.79,0.411
19.93,137.94,0.411
19.95,138.09,0.411
19.97,138.24,0.411
19.98,138.39,0.411
19.99,138.54,0.411
20.01,138.69,0.411
20.03,138.84,0.411
20.04,138.99,0.411
20.06,139.14,0.411
20.07,139.29,0.411
20.08,139.44,0.411
20.10,139.59,0.411
20.12,139.74,0.411
20.13,139.89,0.412
20.14,140.04,0.412
20.16,140.19,0.412
20.18,140.35,0.412
20.19,140.49,0.412
20.21,140.64,0.412
20.22,140.79,0.412
20.23,140.95,0.412
20.25,141.09,0.412
20.27,141.24,0.412
20.28,141.40,0.412
20.29,141.55,0.412
20.31,141.70,0.412
20.33,141.85,0.412
20.34,142.00,0.412
20.36,142.15,0.412
20.37,142.30,0.412
20.38,142.45,0.412
20.40,142.60,0.412
20.42,142.75,0.412
20.43,142.90,0.412
20.44,143.05,0.412
20.46,143.20,0.412
20.48,143.35,0.412
20.49,143.50,0.412
20.51,143.65,0.412
20.52,143.80,0.412
20.53,143.95,0.412
20.55,144.10,0.412
20.57,144.25,0.412
20.58,144.40,0.412
20.59,144.55,0.412
20.61,144.70,0.412
20.63,144.85,0.412
20.64,145.00,0.412
20.66,145.15,0.412
20.67,145.30,0.412
20.68,145.45,0.412
20.70,145.60,0.413
20.72,145.75,0.413
20.73,145.90,0.413
20.74,146.05,0.413
20.76,146.20,0.413
20.78,146.35,0.413
20.79,146.50,0.413
20.81,146.65,0.413
20.82,146.80,0.413
20.83,146.95,0.413
20.85,147.10,0.413
20.87,147.25,0.413
20.88,147.40,0.413
20.89,147.55,0.413
20.91,147.70,0.413
20.93,147.85,0.413
20.94,148.00,
20.96,148.15,
20.97,148.30,
20.98,,
20.99,,

[step]
Ramp 10.00 °C/min to -60.00 °C
Time,Temperature,Heat Flow (Normalized)
min,°C,W/g
21.99,150.09,-0.031
22.01,150.09,-0.031
22.02,150.09,-0.032
22.04,150.08,-0.034
22.05,150.07,-0.049
22.07,150.05,-0.070
22.08,150.01,-0.098
22.10,149.96,-0.132
22.11,149.90,-0.169
22.13,149.82,-0.207
22.14,149.74,-0.244
22.16,149.64,-0.276
22.17,149.53,-0.303
22.19,149.42,-0.328
22.20,149.30,-0.347
22.22,149.18,-0.365
22.23,149.05,-0.379
22.25,148.92,-0.393
22.26,148.79,-0.403
22.28,148.66,-0.411
22.29,148.52,-0.421
22.31,148.39,-0.429
22.32,148.25,-0.432
22.34,148.11,-0.440
22.35,147.97,-0.442
22.37,147.82,-0.446
22.38,147.68,-0.450
22.40,147.54,-0.453
22.41,147.39,-0.455
22.43,147.25,-0.457
22.44,147.10,-0.459
22.46,146.96,-0.459
22.47,146.81,-0.461
22.49,146.66,-0.461
22.50,146.52,-0.463
22.52,146.37,-0.463
22.53,146.22,-0.463
22.55,146.08,-0.464
22.56,145.93,-0.464
22.58,145.78,-0.464
22.59,145.63,-0.464
22.61,145.49,-0.465
22.62,145.34,-0.465
22.64,145.19,-0.465
22.65,145.04,-0.466
22.67,144.89,-0.466
22.68,144.74,-0.466
22.70,144.60,-0.466
22.71,144.45,-0.466
22.73,144.30,-0.467
22.74,144.15,-0.467
22.76,144.00,-0.467
22.77,143.86,-0.467
22.79,143.71,-0.467
22.80,143.56,-0.467
22.82,143.41,-0.467
22.83,143.26,-0.468
22.85,143.11,-0.468
22.86,142.96,-0.468
22.88,142.81,-0.468
22.89,142.66,-0.468
22.91,142.52,-0.468
22.92,142.37,-0.468
22.94,142.22,-0.468
22.95,142.07,-0.468
22.97,141.92,-0.468
22.98,141.77,-0.468
23.00,141.62,-0.468
23.01,141.47,-0.468
23.03,141.32,-0.468
23.04,141.17,-0.468
23.06,141.02,-0.468
23.07,140.88,-0.468
23.09,140.73,-0.468
23.10,140.58,-0.468
23.12,140.43,-0.468
23.13,140.28,-0.468
23.15,140.13,-0.467
23.16,139.98,-0.467
23.18,139.83,-0.467
23.19,139.68,-0.467
23.21,139.53,-0.467
23.22,139.38,-0.467
23.24,139.23,-0.467
23.25,139.08,-0.467
23.27,138.93,-0.467
23.28,138.78,-0.467
23.30,138.63,-0.466
23.31,138.48,-0.466
23.33,138.33,-0.466
23.34,138.18,-0.466
23.36,138.03,-0.466
23.37,137.89,-0.466
23.39,137.74,-0.466
23.40,137.59,-0.465
23.42,137.44,-0.465
23.43,137.29,-0.465
23.45,137.14,-0.465
23.46,136.99,-0.465
23.48,136.84,-0.464
23.49,136.69,-0.464
23.51,136.54,-0.464
23.52,136.39,-0.464
23.54,136.24,-0.464
23.55,136.09,-0.464
23.57,135.94,-0.464
23.58,135.79,-0.464
23.60,135.64,-0.463
23.61,135.49,-0.463
23.63,135.34,-0.463
23.64,135.19,-0.463
23.66,135.04,-0.463
23.67,134.89,-0.463
23.69,134.74,-0.462
23.70,134.59,-0.462
23.72,134.44,-0.462
23.73,134.29,-0.462
23.75,134.14,-0.462
23.76,133.99,-0.462
23.78,133.84,-0.462
23.79,133.69,-0.461
23.81,133.54,-0.461
23.82,133.39,-0.461
23.84,133.24,-0.461
23.85,133.09,-0.461
23.87,132.95,-0.460
23.88,132.80,-0.460
23.90,132.65,-0.460
23.91,132.49,-0.460
23.93,132.35,-0.460
23.94,132.20,-0.460
23.96,132.05,-0.459
23.97,131.90,-0.459
23.99,131.75,-0.459
24.00,131.60,-0.459
24.02,131.45,-0.459
24.03,131.30,-0.459
24.05,131.15,-0.458
24.06,131.00,-0.458
24.08,130.85,-0.458
24.09,130.70,-0.458
24.11,130.55,-0.458
24.12,130.40,-0.458
24.14,130.25,-0.458
24.15,130.10,-0.457
24.17,129.95,-0.457
24.18,129.80,-0.457
24.20,129.65,-0.457
24.21,129.50,-0.457
24.23,129.35,-0.457
24.24,129.20,-0.457
24.26,129.05,-0.456
24.27,128.90,-0.456
24.29,128.75,-0.456
24.30,128.60,-0.456
24.32,128.45,-0.456
24.33,128.30,-0.455
24.35,128.15,-0.455
24.36,128.00,-0.455
24.38,127.85,-0.455
24.39,127.70,-0.455
24.41,127.55,-0.455
24.42,127.40,-0.455
24.44,127.25,-0.455
24.45,127.10,-0.455
24.47,126.95,-0.454
24.48,126.80,-0.454
24.50,126.65,-0.454
24.51,126.50,-0.454
24.53,126.35,-0.454
24.54,126.20,-0.454
24.56,126.05,-0.454
24.57,125.90,-0.453
24.59,125.75,-0.453
24.60,125.60,-0.453
24.62,125.45,-0.453
24.63,125.30,-0.453
24.65,125.15,-0.453
24.66,125.00,-0.452
24.68,124.86,-0.452
24.69,124.70,-0.452
24.71,124.55,-0.452
24.72,124.40,-0.452
24.74,124.26,-0.452
24.75,124.10,-0.452
24.77,123.96,-0.451
24.78,123.81,-0.451
24.80,123.66,-0.451
24.81,123.51,-0.451
24.83,123.36,-0.451
24.84,123.21,-0.451
24.86,123.06,-0.451
24.87,122.91,-0.450
24.89,122.76,-0.450
24.90,122.61,-0.450
24.92,122.46,-0.450
24.93,122.31,-0.450
24.95,122.16,-0.450
24.96,122.01,-0.450
24.98,121.86,-0.449
24.99,121.71,-0.449
25.01,121.56,-0.449
25.02,121.41,-0.449
25.04,121.26,-0.449
25.05,121.11,-0.449
25.07,120.96,-0.449
25.08,120.81,-0.449
25.10,120.66,-0.448
25.11,120.51,-0.448
25.13,120.36,-0.448
25.14,120.21,-0.448
25.16,120.06,-0.448
25.17,119.91,-0.448
25.19,119.76,-0.448
25.20,119.61,-0.447
25.22,119.46,-0.447
25.23,119.31,-0.447
25.25,119.16,-0.447
25.26,119.01,-0.447
25.28,118.86,-0.447
25.29,118.71,-0.447
25.31,118.56,-0.446
25.32,118.41,-0.446
25.34,118.26,-0.446
25.35,118.11,-0.446
25.37,117.96,-0.446
25.38,117.81,-0.446
25.40,117.66,-0.446
25.41,117.51,-0.445
25.43,117.36,-0.445
25.44,117.21,-0.445
25.46,117.06,-0.445
25.47,116.91,-0.445
25.49,116.76,-0.445
25.50,116.61,-0.445
25.52,116.46,-0.445
25.53,116.32,-0.445
25.55,116.17,-0.444
25.56,116.01,-0.444
25.58,115.87,-0.444
25.59,115.72,-0.444
25.61,115.57,-0.444
25.62,115.42,-0.444
25.64,115.27,-0.444
25.65,115.12,-0.444
25.67,114.97,-0.444
25.68,114.82,-0.444
25.70,114.67,-0.443
25.71,114.52,-0.443
25.73,114.37,-0.443
25.74,114.22,-0.443
25.76,114.07,-0.443
25.77,113.92,-0.443
25.79,113.77,-0.442
25.80,113.62,-0.442
25.82,113.47,-0.442
25.83,113.32,-0.442
25.85,113.17,-0.442
25.86,113.02,-0.442
25.88,112.87,-0.442
25.89,112.72,-0.442
25.91,112.57,-0.441
25.92,112.42,-0.441
25.94,112.27,-0.441
25.95,112.12,-0.441
25.97,111.97,-0.441
25.98,111.82,-0.441
26.00,111.67,-0.441
26.01,111.52,-0.441
26.03,111.37,-0.441
26.04,111.22,-0.440
26.06,111.07,-0.440
26.07,110.92,-0.440
26.09,110.77,-0.440
26.10,110.62,-0.440
26.12,110.47,-0.440
26.13,110.32,-0.440
26.15,110.17,-0.439
26.16,110.02,-0.439
26.18,109.87,-0.439
26.19,109.72,-0.439
26.21,109.57,-0.439
26.22,109.42,-0.439
26.24,109.27,-0.439
26.25,109.12,-0.439
26.27,108.97,-0.438
26.28,108.82,-0.438
26.30,108.67,-0.438
26.31,108.52,-0.438
26.33,108.37,-0.438
26.34,108.22,-0.438
26.36,108.07,-0.438
26.37,107.92,-0.438
26.39,107.77,-0.437
26.40,107.62,-0.437
26.42,107.47,-0.437
26.43,107.32,-0.437
26.45,107.17,-0.437
26.46,107.02,-0.437
26.48,106.88,-0.437
26.49,106.73,-0.437
26.51,106.58,-0.437
26.52,106.43,-0.436
26.54,106.28,-0.436
26.55,106.13,-0.436
26.57,105.98,-0.436
26.58,105.83,-0.436
26.60,105.68,-0.436
26.61,105.53,-0.436
26.63,105.38,-0.436
26.64,105.23,-0.435
26.66,105.08,-0.435
26.67,104.93,-0.435
26.69,104.78,-0.435
26.70,104.63,-0.435
26.72,104.48,-0.435
26.73,104.33,-0.435
26.75,104.18,-0.435
26.76,104.03,-0.435
26.78,103.88,-0.435
26.79,103.73,-0.434
26.81,103.58,-0.434
26.82,103.43,-0.434
26.84,103.28,-0.434
26.85,103.13,-0.434
26.87,102.98,-0.434
26.88,102.83,-0.434
26.90,102.68,-0.434
26.91,102.53,-0.434
26.93,102.38,-0.433
26.94,102.23,-0.433
26.96,102.08,-0.433
26.97,101.93,-0.433
26.99,101.78,-0.433
27.00,101.63,-0.433
27.02,101.48,-0.433
27.03,101.33,-0.433
27.05,101.18,-0.432
27.06,101.03,-0.432
27.08,100.88,-0.432
27.09,100.73,-0.432
27.11,100.58,-0.432
27.12,100.43,-0.432
27.14,100.28,-0.432
27.15,100.13,-0.432
27.17,99.98,-0.431
27.18,99.83,-0.431
27.20,99.68,-0.431
27.21,99.53,-0.431
27.23,99.38,-0.431
27.24,99.23,-0.431
27.26,99.08,-0.431
27.27,98.93,-0.431
27.29,98.78,-0.430
27.30,98.63,-0.430
27.32,98.49,-0.430
27.33,98.33,-0.430
27.35,98.18,-0.430
27.36,98.03,-0.430
27.38,97.88,-0.430
27.39,97.73,-0.430
27.41,97.59,-0.430
27.42,97.44,-0.429
27.44,97.28,-0.429
27.45,97.13,-0.429
27.47,96.99,-0.429
27.48,96.83,-0.429
27.50,96.69,-0.429
27.51,96.54,-0.429
27.53,96.39,-0.429
27.54,96.24,-0.428
27.56,96.09,-0.428
27.57,95.94,-0.428
27.59,95.79,-0.428
27.60,95.64,-0.428
27.62,95.49,-0.428
27.63,95.34,-0.428
27.65,95.19,-0.427
27.66,95.04,-0.427
27.68,94.89,-0.427
27.69,94.74,-0.427
27.71,94.59,-0.427
27.72,94.44,-0.427
27.74,94.29,-0.427
27.75,94.14,-0.427
27.77,93.99,-0.426
27.78,93.84,-0.426
27.80,93.69,-0.426
27.81,93.54,-0.426
27.83,93.39,-0.426
27.84,93.24,-0.426
27.86,93.09,-0.426
27.87,92.94,-0.426
27.89,92.79,-0.426
27.90,92.64,-0.425
27.92,92.49,-0.425
27.93,92.34,-0.425
27.95,92.19,-0.425
27.96,92.04,-0.425
27.98,91.89,-0.425
27.99,91.74,-0.425
28.01,91.59,-0.424
28.02,91.44,-0.424
28.04,91.29,-0.424
28.05,91.14,-0.424
28.07,90.99,-0.424
28.08,90.84,-0.424
28.10,90.69,-0.424
28.11,90.54,-0.423
28.13,90.39,-0.423
28.14,90.24,-0.423
28.16,90.09,-0.423
28.17,89.94,-0.423
28.19,89.79,-0.423
28.20,89.64,-0.423
28.22,89.49,-0.423
28.23,89.34,-0.422
28.25,89.19,-0.422
28.26,89.04,-0.422
28.28,88.89,-0.422
28.29,88.74,-0.422
28.31,88.59,-0.422
28.32,88.44,-0.421
28.34,88.29,-0.421
28.35,88.14,-0.421
28.37,87.99,-0.421
28.38,87.84,-0.421
28.40,87.69,-0.421
28.41,87.54,-0.420
28.43,87.40,-0.420
28.44,87.25,-0.420
28.46,87.10,-0.420
28.47,86.95,-0.420
28.49,86.80,-0.420
28.50,86.65,-0.420
28.52,86.50,-0.420
28.53,86.35,-0.419
28.55,86.20,-0.419
[...]
93.05,-11.13,0.315
93.06,-10.98,0.315
93.08,-10.83,0.315
93.09,-10.68,0.315
93.11,-10.53,0.315
93.12,-10.38,0.315
93.14,-10.23,0.314
93.15,-10.08,0.313
93.17,-9.93,0.312
93.18,-9.78,0.310
93.20,-9.63,0.309
93.21,-9.48,0.306
93.23,-9.32,0.305
93.24,-9.17,0.304
93.26,-9.02,0.303
93.27,-8.87,0.303
93.29,-8.72,0.302
93.30,-8.57,0.301
93.32,-8.42,0.300
93.33,-8.27,0.299
93.35,-8.12,0.299
93.36,-7.97,0.299
93.38,-7.82,0.298
93.39,-7.67,0.298
93.41,-7.52,0.298
93.42,-7.37,0.297
93.44,-7.22,0.297
93.45,-7.06,0.297
93.47,-6.91,0.297
93.48,-6.76,0.296
93.50,-6.61,0.296
93.51,-6.46,0.296
93.53,-6.31,0.295
93.54,-6.16,0.295
93.56,-6.01,0.295
93.57,-5.86,0.295
93.59,-5.71,0.295
93.60,-5.56,0.295
93.62,-5.41,0.294
93.63,-5.26,0.294
93.65,-5.11,0.294
93.66,-4.96,0.294
93.68,-4.81,0.294
93.69,-4.66,0.294
93.71,-4.51,0.294
93.72,-4.36,0.293
93.74,-4.21,0.293
93.75,-4.06,0.293
93.77,-3.91,0.293
93.78,-3.76,0.293
93.80,-3.61,0.293
93.81,-3.46,0.293
93.83,-3.31,0.293
93.84,-3.16,0.293
93.86,-3.01,0.293
93.87,-2.86,0.293
93.89,-2.71,0.293
93.90,-2.56,0.293
93.92,-2.41,0.293
93.93,-2.26,0.293
93.95,-2.11,0.293
93.96,-1.96,0.293
93.98,-1.80,0.293
93.99,-1.66,0.293
94.01,-1.51,0.293
94.02,-1.35,0.293
94.04,-1.20,0.293
94.05,-1.06,0.293
94.07,-0.90,0.293
94.08,-0.75,0.293
94.10,-0.60,0.293
94.11,-0.45,0.293
94.13,-0.30,0.293
94.14,-0.15,0.293
94.16,0.00,0.293
94.17,0.15,0.293
94.19,0.30,0.293
94.20,0.45,0.293
94.22,0.60,0.293
94.23,0.75,0.293
94.25,0.90,0.293
94.26,1.05,0.293
94.28,1.20,0.294
94.29,1.35,0.294
94.31,1.50,0.294
94.32,1.65,0.294
94.34,1.80,0.294
94.35,1.95,0.294
94.37,2.10,0.294
94.38,2.25,0.294
94.40,2.40,0.294
94.41,2.55,0.294
94.43,2.70,0.294
94.44,2.85,0.294
94.46,3.00,0.294
94.47,3.15,0.294
94.49,3.30,0.294
94.50,3.45,0.295
94.52,3.60,0.295
94.53,3.75,0.295
94.55,3.90,0.295
94.56,4.05,0.295
94.58,4.20,0.295
94.59,4.35,0.295
94.61,4.50,0.295
94.62,4.65,0.295
94.64,4.80,0.295
94.65,4.95,0.295
94.67,5.10,0.296
94.68,5.25,0.296
94.70,5.40,0.296
94.71,5.55,0.296
94.73,5.70,0.296
94.74,5.85,0.296
94.76,6.00,0.296
94.77,6.15,0.296
94.79,6.31,0.296
94.80,6.46,0.297
94.82,6.61,0.297
94.83,6.76,0.297
94.85,6.91,0.297
94.86,7.05,0.297
94.88,7.21,0.297
94.89,7.36,0.297
94.91,7.51,0.297
94.92,7.66,0.297
94.94,7.81,0.298
94.95,7.96,0.298
94.97,8.11,0.298
94.98,8.26,0.298
95.00,8.41,0.298
95.01,8.56,0.298
95.03,8.71,0.298
95.04,8.86,0.298
95.06,9.01,0.298
95.07,9.16,0.298
95.09,9.31,0.299
95.10,9.46,0.299
95.12,9.61,0.299
95.13,9.76,0.299
95.15,9.91,0.299
95.16,10.06,0.299
95.18,10.21,0.299
95.19,10.36,0.299
95.21,10.51,0.300
95.22,10.66,0.300
95.24,10.81,0.300
95.25,10.96,0.300
95.27,11.11,0.300
95.28,11.26,0.300
95.30,11.41,0.300
95.31,11.56,0.300
95.33,11.71,0.300
95.34,11.86,0.301
95.36,12.01,0.301
95.37,12.16,0.301
95.39,12.31,0.301
95.40,12.46,0.301
95.42,12.61,0.301
95.43,12.76,0.301
95.45,12.91,0.301
95.46,13.06,0.302
95.48,13.21,0.302
95.49,13.36,0.302
95.51,13.51,0.302
95.52,13.66,0.302
95.54,13.82,0.302
95.55,13.96,0.302
95.57,14.11,0.302
95.58,14.27,0.303
95.60,14.42,0.303
95.61,14.56,0.303
95.63,14.72,0.303
95.64,14.87,0.303
95.66,15.02,0.303
95.67,15.17,0.303
95.69,15.32,0.303
95.70,15.47,0.303
95.72,15.62,0.304
95.73,15.77,0.304
95.75,15.92,0.304
95.76,16.07,0.304
95.78,16.22,0.304
95.79,16.37,0.304
95.81,16.52,0.304
95.82,16.67,0.304
95.84,16.82,0.304
95.85,16.97,0.304
95.87,17.12,0.305
95.88,17.27,0.305
95.90,17.42,0.305
95.91,17.57,0.305
95.93,17.72,0.305
95.94,17.87,0.305
95.96,18.02,0.305
95.97,18.17,0.305
95.99,18.32,0.305
96.00,18.47,0.305
96.02,18.62,0.306
96.03,18.77,0.306
96.05,18.92,0.306
96.06,19.07,0.306
96.08,19.22,0.306
96.09,19.37,0.306
96.11,19.52,0.306
96.12,19.67,0.307
96.14,19.82,0.307
96.15,19.97,0.307
96.17,20.12,0.307
96.18,20.27,0.307
96.20,20.42,0.307
96.21,20.57,0.307
96.23,20.72,0.307
96.24,20.87,0.307
96.26,21.02,0.308
96.27,21.17,0.308
96.29,21.32,0.308
96.30,21.47,0.308
96.32,21.62,0.308
96.33,21.77,0.308
96.35,21.92,0.308
96.36,22.07,0.308
96.38,22.22,0.308
96.39,22.37,0.309
96.41,22.52,0.309
96.42,22.67,0.309
96.44,22.82,0.309
96.45,22.97,0.309
96.47,23.13,0.309
96.48,23.27,0.309
96.50,23.42,0.309
96.51,23.58,0.309
96.53,23.73,0.309
96.54,23.88,0.310
96.56,24.03,0.310
96.57,24.18,0.310
96.59,24.33,0.310
96.60,24.48,0.310
96.62,24.63,0.310
96.63,24.78,0.310
96.65,24.93,0.311
96.66,25.08,0.311
96.68,25.23,0.311
96.69,25.38,0.311
96.71,25.53,0.311
96.72,25.68,0.311
96.74,25.83,0.311
96.75,25.98,0.312
96.77,26.13,0.312
96.78,26.28,0.312
96.80,26.43,0.312
96.81,26.58,0.312
96.83,26.73,0.312
96.84,26.88,0.312
96.86,27.03,0.312
96.87,27.18,0.313
96.89,27.33,0.313
96.90,27.48,0.313
96.92,27.63,0.313
96.93,27.78,0.313
96.95,27.93,0.313
96.96,28.08,0.313
96.98,28.23,0.314
96.99,28.38,0.314
97.01,28.53,0.314
97.02,28.68,0.314
97.04,28.83,0.314
97.05,28.98,0.314
97.07,29.13,0.314
97.08,29.28,0.315
97.10,29.43,0.315
97.11,29.58,0.315
97.13,29.73,0.315
97.14,29.88,0.315
97.16,30.03,0.315
97.17,30.18,0.315
97.19,30.33,0.316
97.20,30.48,0.316
97.22,30.63,0.316
97.23,30.78,0.316
97.25,30.94,0.316
97.26,31.09,0.316
97.28,31.24,0.316
97.29,31.38,0.316
97.31,31.54,0.317
97.32,31.69,0.317
97.34,31.83,0.317
97.35,31.99,0.317
97.37,32.14,0.317
97.38,32.29,0.317
97.40,32.44,0.317
97.41,32.59,0.317
97.43,32.74,0.318
97.44,32.89,0.318
97.46,33.04,0.318
97.47,33.19,0.318
97.49,33.34,0.318
97.50,33.49,0.318
97.52,33.64,0.318
97.53,33.79,0.318
97.55,33.94,0.318
97.56,34.09,0.318
97.58,34.24,0.319
97.59,34.39,0.319
97.61,34.54,0.319
97.62,34.69,0.319
97.64,34.84,0.319
97.65,34.99,0.319
97.67,35.14,0.319
97.68,35.29,0.319
97.70,35.44,0.320
97.71,35.59,0.320
97.73,35.74,0.320
97.74,35.89,0.320
97.76,36.04,0.320
97.77,36.19,0.320
97.79,36.34,0.320
97.80,36.49,0.320
97.82,36.64,0.320
97.83,36.79,0.320
97.85,36.94,0.320
97.86,37.09,0.321
97.88,37.24,0.321
97.89,37.39,0.321
97.91,37.54,0.321
97.92,37.69,0.321
97.94,37.84,0.321
97.95,37.99,0.321
97.97,38.14,0.321
97.98,38.29,0.322
98.00,38.44,0.322
98.01,38.59,0.322
98.03,38.74,0.322
98.04,38.89,0.322
98.06,39.04,0.322
98.07,39.19,0.322
98.09,39.34,0.322
98.10,39.49,0.323
98.12,39.64,0.323
98.13,39.79,0.323
98.15,39.94,0.323
98.16,40.10,0.323
98.18,40.24,0.323
98.19,40.39,0.323
98.21,40.54,0.323
98.22,40.69,0.324
98.24,40.84,0.324
98.25,41.00,0.324
98.27,41.15,0.324
98.28,41.30,0.324
98.30,41.45,0.324
98.31,41.60,0.324
98.33,41.75,0.324
98.34,41.90,0.325
98.36,42.05,0.325
98.37,42.20,0.325
98.39,42.35,0.325
98.40,42.50,0.325
98.42,42.65,0.325
98.43,42.80,0.325
98.45,42.95,0.325
98.46,43.10,0.326
98.48,43.25,0.326
98.49,43.40,0.326
98.51,43.55,0.326
98.52,43.70,0.326
98.54,43.85,0.326
98.55,44.00,0.326
98.57,44.15,0.326
98.58,44.30,0.327
98.60,44.45,0.327
98.61,44.60,0.327
98.63,44.75,0.327
98.64,44.90,0.327
98.66,45.05,0.327
98.67,45.20,0.327
98.69,45.35,0.327
98.70,45.50,0.327
98.72,45.65,0.328
98.73,45.80,0.328
98.75,45.95,0.328
98.76,46.10,0.328
98.78,46.25,0.328
98.79,46.40,0.328
98.81,46.55,0.328
98.82,46.70,0.328
98.84,46.85,0.328
98.85,47.00,0.329
98.87,47.15,0.329
98.88,47.30,0.329
98.90,47.45,0.329
98.91,47.60,0.329
98.93,47.75,0.329
98.94,47.90,0.329
98.96,48.05,0.329
98.97,48.20,0.330
98.99,48.35,0.330
99.00,48.50,0.330
99.02,48.65,0.330
99.03,48.80,0.330
99.05,48.95,0.330
99.06,49.10,0.330
99.08,49.25,0.330
99.09,49.40,0.331
99.11,49.55,0.331
99.12,49.70,0.331
99.14,49.85,0.331
99.15,50.00,0.331
99.17,50.16,0.331
99.18,50.30,0.331
99.20,50.45,0.331
99.21,50.61,0.332
99.23,50.76,0.332
99.24,50.90,0.332
99.26,51.06,0.332
99.27,51.21,0.332
99.29,51.36,0.332
99.30,51.51,0.332
99.32,51.66,0.332
99.33,51.81,0.332
99.35,51.96,0.333
99.36,52.11,0.333
99.38,52.26,0.333
99.39,52.41,0.333
99.41,52.56,0.333
99.42,52.71,0.333
99.44,52.86,0.333
99.45,53.01,0.333
99.47,53.16,0.334
99.48,53.31,0.334
99.50,53.46,0.334
99.51,53.61,0.334
99.53,53.76,0.334
99.54,53.91,0.334
99.56,54.06,0.334
99.57,54.21,0.334
99.59,54.36,0.334
99.60,54.51,0.335
99.62,54.66,0.335
99.63,54.81,0.335
99.65,54.96,0.335
99.66,55.11,0.335
99.68,55.26,0.335
99.69,55.41,0.335
99.71,55.56,0.335
99.72,55.71,0.336
99.74,55.86,0.336
99.75,56.01,0.336
99.77,56.16,0.336
99.78,56.31,0.336
99.80,56.46,0.336
99.81,56.61,0.336
99.83,56.76,0.336
99.84,56.91,0.336
99.86,57.06,0.336
99.87,57.21,0.337
99.89,57.36,0.337
99.90,57.51,0.337
99.92,57.66,0.337
99.93,57.81,0.337
99.95,57.97,0.337
99.96,58.11,0.337
99.98,58.26,0.337
99.99,58.41,0.337
100.01,58.56,0.338
100.02,58.72,0.338
100.04,58.87,0.338
100.05,59.02,0.338
100.07,59.17,0.338
100.08,59.32,0.338
100.10,59.47,0.338
100.11,59.62,0.338
100.13,59.77,0.338
100.14,59.92,0.339
100.16,60.07,0.339
100.17,60.22,0.339
100.19,60.37,0.339
100.20,60.52,0.339
100.22,60.67,0.339
100.23,60.82,0.339
100.25,60.97,0.339
100.26,61.12,0.339
100.28,61.27,0.340
100.29,61.42,0.340
100.31,61.57,0.340
100.32,61.72,0.340
100.34,61.87,0.340
100.35,62.02,0.340
100.37,62.17,0.340
100.38,62.32,0.340
100.40,62.47,0.340
100.41,62.62,0.341
100.43,62.77,0.341
100.44,62.92,0.341
100.46,63.07,0.341
100.47,63.22,0.341
100.49,63.37,0.341
100.50,63.52,0.341
100.52,63.67,0.341
100.53,63.82,0.341
100.55,63.97,0.342
100.56,64.12,0.342
100.58,64.27,0.342
100.59,64.42,0.342
100.61,64.57,0.342
100.62,64.72,0.342
100.64,64.87,0.342
100.65,65.02,0.342
100.67,65.17,0.342
100.68,65.32,0.343
100.70,65.47,0.343
100.71,65.62,0.343
100.73,65.77,0.343
100.74,65.92,0.343
100.76,66.07,0.343
100.77,66.22,0.343
100.79,66.37,0.343
100.80,66.52,0.343
100.82,66.67,0.343
100.83,66.82,0.344
100.85,66.97,0.344
100.86,67.12,0.344
100.88,67.27,0.344
100.89,67.42,0.344
100.91,67.57,0.344
100.92,67.72,0.344
100.94,67.87,0.344
100.95,68.02,0.345
100.97,68.17,0.345
100.98,68.32,0.345
101.00,68.47,0.345
101.01,68.62,0.345
101.03,68.77,0.345
101.04,68.92,0.345
101.06,69.08,0.345
101.07,69.22,0.345
101.09,69.38,0.345
101.10,69.53,0.346
101.12,69.68,0.346
101.13,69.83,0.346
101.15,69.98,0.346
101.16,70.13,0.346
101.18,70.28,0.346
101.19,70.43,0.346
101.21,70.58,0.346
101.22,70.73,0.347
101.24,70.88,0.347
101.25,71.03,0.347
101.27,71.18,0.347
101.28,71.33,0.347
101.30,71.48,0.347
101.31,71.63,0.347
101.33,71.78,0.347
101.34,71.93,0.347
101.36,72.08,0.348
101.37,72.23,0.348
101.39,72.38,0.348
101.40,72.53,0.348
101.42,72.68,0.348
101.43,72.83,0.348
101.45,72.98,0.348
101.46,73.13,0.348
101.48,73.28,0.348
101.49,73.43,0.349
101.51,73.58,0.349
101.52,73.73,0.349
101.54,73.88,0.349
101.55,74.03,0.349
101.57,74.18,0.349
101.58,74.33,0.349
101.60,74.48,0.349
101.61,74.63,0.349
101.63,74.78,0.350
101.64,74.93,0.350
101.66,75.08,0.350
101.67,75.23,0.350
101.69,75.38,0.350
101.70,75.53,0.350
101.72,75.68,0.350
101.73,75.83,0.350
101.75,75.98,0.351
101.76,76.13,0.351
101.78,76.28,0.351
101.79,76.43,0.351
101.81,76.58,0.351
101.82,76.73,0.351
101.84,76.88,0.351
101.85,77.03,0.351
101.87,77.18,0.352
101.88,77.33,0.352
101.90,77.48,0.352
101.91,77.63,0.352
101.93,77.78,0.352
101.94,77.93,0.352
101.96,78.08,0.352
101.97,78.23,0.352
101.99,78.38,0.352
102.00,78.53,0.353
102.02,78.68,0.353
102.03,78.83,0.353
102.05,78.98,0.353
102.06,79.14,0.353
102.08,79.28,0.353
102.09,79.43,0.353
102.11,79.58,0.353
102.12,79.73,0.353
102.14,79.88,0.354
102.15,80.04,0.354
102.17,80.19,0.354
102.18,80.33,0.354
102.20,80.49,0.354
102.21,80.64,0.354
102.23,80.79,0.354
102.24,80.94,0.354
102.26,81.09,0.354
102.27,81.23,0.354
102.29,81.39,0.354
102.30,81.54,0.355
102.32,81.69,0.355
102.33,81.84,0.355
102.35,81.99,0.355
102.36,82.14,0.355
102.38,82.29,0.355
102.39,82.44,0.355
102.41,82.59,0.355
102.42,82.74,0.355
102.44,82.89,0.355
102.45,83.04,0.355
102.47,83.19,0.355
102.48,83.34,0.356
102.50,83.49,0.356
102.51,83.64,0.356
102.53,83.79,0.356
102.54,83.94,0.356
102.56,84.09,0.356
102.57,84.24,0.356
102.59,84.39,0.356
102.60,84.54,0.356
102.62,84.69,0.356
102.63,84.84,0.356
102.65,84.99,0.357
102.66,85.14,0.357
102.68,85.29,0.357
102.69,85.44,0.357
102.71,85.59,0.357
102.72,85.74,0.357
102.74,85.89,0.357
102.75,86.04,0.357
102.77,86.19,0.357
102.78,86.34,0.357
102.80,86.49,0.357
102.81,86.64,0.357
102.83,86.79,0.357
102.84,86.94,0.358
102.86,87.09,0.358
102.87,87.24,0.358
102.89,87.39,0.358
102.90,87.54,0.358
102.92,87.69,0.358
102.93,87.84,0.358
102.95,87.99,0.358
102.96,88.14,0.358
102.98,88.29,0.358
102.99,88.44,0.359
103.01,88.59,0.359
103.02,88.74,0.359
103.04,88.89,0.359
103.05,89.04,0.359
103.07,89.19,0.359
103.08,89.35,0.359
103.10,89.49,0.359
103.11,89.65,0.360
103.13,89.80,0.360
103.14,89.95,0.360
103.16,90.10,0.360
103.17,90.25,0.360
103.19,90.40,0.360
103.20,90.55,0.360
103.22,90.70,0.360
103.23,90.85,0.360
103.25,91.00,0.361
103.26,91.15,0.361
103.28,91.30,0.361
103.29,91.45,0.361
103.31,91.60,0.361
103.32,91.75,0.361
103.34,91.90,0.361
103.35,92.05,0.361
103.37,92.20,0.362
103.38,92.35,0.362
103.40,92.50,0.362
103.41,92.65,0.362
103.43,92.80,0.362
103.44,92.95,0.362
103.46,93.10,0.362
103.47,93.25,0.362
103.49,93.40,0.363
103.50,93.55,0.363
103.52,93.70,0.363
103.53,93.85,0.363
103.55,94.00,0.363
103.56,94.15,0.363
103.58,94.30,0.363
103.59,94.45,0.363
103.61,94.60,0.363
103.62,94.75,0.364
103.64,94.90,0.364
103.65,95.05,0.364
103.67,95.20,0.364
103.68,95.35,0.364
103.70,95.50,0.364
103.71,95.65,0.364
103.73,95.80,0.364
103.74,95.95,0.364
103.76,96.10,0.365
103.77,96.25,0.365
103.79,96.40,0.365
103.80,96.55,0.365
103.82,96.70,0.365
103.83,96.85,0.365
103.85,97.00,0.365
103.86,97.15,0.365
103.88,97.30,0.366
103.89,97.45,0.366
103.91,97.60,0.366
103.92,97.75,0.366
103.94,97.90,0.366
103.95,98.05,0.366
103.97,98.20,0.366
103.98,98.35,0.366
104.00,98.50,0.366
104.01,98.65,0.366
104.03,98.80,0.367
104.04,98.95,0.367
104.06,99.10,0.367
104.07,99.25,0.367
104.09,99.40,0.367
104.10,99.55,0.367
104.12,99.70,0.367
104.13,99.85,0.367
104.15,100.00,0.367
104.16,100.15,0.368
104.18,100.30,0.368
104.19,100.45,0.368
104.21,100.61,0.368
104.22,100.76,0.368
104.24,100.90,0.368
104.25,101.06,0.368
104.27,101.20,0.368
104.28,101.35,0.368
104.30,101.51,0.369
104.31,101.66,0.369
104.33,101.81,0.369
104.34,101.96,0.369
104.36,102.11,0.369
104.37,102.26,0.369
104.39,102.41,0.369
104.40,102.56,0.369
104.42,102.71,0.370
104.43,102.86,0.370
104.45,103.01,0.370
104.46,103.16,0.370
104.48,103.31,0.370
104.49,103.46,0.370
104.51,103.61,0.370
104.52,103.76,0.370
104.54,103.91,0.370
104.55,104.06,0.370
104.57,104.21,0.370
104.58,104.36,0.371
104.60,104.51,0.371
104.61,104.66,0.371
104.63,104.81,0.371
104.64,104.96,0.371
104.66,105.11,0.371
104.67,105.26,0.371
104.69,105.41,0.371
104.70,105.56,0.371
104.72,105.71,0.372
104.73,105.86,0.372
104.75,106.01,0.372
104.76,106.16,0.372
104.78,106.31,0.372
104.79,106.46,0.372
104.81,106.61,0.372
104.82,106.76,0.372
104.84,106.91,0.372
104.85,107.06,0.372
104.87,107.21,0.373
104.88,107.36,0.373
104.90,107.51,0.373
104.91,107.66,0.373
104.93,107.81,0.373
104.94,107.96,0.373
104.96,108.11,0.373
104.97,108.26,0.373
104.99,108.41,0.373
105.00,108.56,0.374
105.02,108.71,0.374
105.03,108.86,0.374
105.05,109.01,0.374
105.06,109.16,0.374
105.08,109.31,0.374
105.09,109.46,0.374
105.11,109.61,0.374
105.12,109.76,0.374
105.14,109.91,0.375
105.15,110.06,0.375
105.17,110.21,0.375
105.18,110.36,0.375
105.20,110.51,0.375
105.21,110.66,0.375
105.23,110.81,0.375
105.24,110.96,0.375
105.26,111.12,0.375
105.27,111.26,0.375
105.29,111.41,0.376
105.30,111.56,0.376
105.32,111.71,0.376
105.33,111.87,0.376
105.35,112.02,0.376
105.36,112.17,0.376
105.38,112.32,0.376
105.39,112.47,0.376
105.41,112.62,0.376
105.42,112.77,0.376
105.44,112.92,0.376
105.45,113.07,0.376
105.47,113.22,0.377
105.48,113.37,0.377
105.50,113.52,0.377
105.51,113.67,0.377
105.53,113.82,0.377
105.54,113.97,0.377
105.56,114.12,0.377
105.57,114.27,0.377
105.59,114.42,0.377
105.60,114.57,0.377
105.62,114.72,0.378
105.63,114.87,0.378
105.65,115.02,0.378
105.66,115.17,0.378
105.68,115.32,0.378
105.69,115.47,0.378
105.71,115.62,0.378
105.72,115.77,0.378
105.74,115.92,0.379
105.75,116.07,0.379
105.77,116.22,0.379
105.78,116.37,0.379
105.80,116.52,0.379
105.81,116.67,0.379
105.83,116.82,0.379
105.84,116.97,0.379
105.86,117.12,0.379
105.87,117.27,0.379
105.89,117.42,0.380
105.90,117.57,0.380
105.92,117.72,0.380
105.93,117.87,0.380
105.95,118.02,0.380
105.96,118.17,0.380
105.98,118.32,0.380
105.99,118.47,0.380
106.01,118.62,0.380
106.02,118.77,0.380
106.04,118.92,0.380
106.05,119.07,0.381
106.07,119.22,0.381
106.08,119.37,0.381
106.10,119.52,0.381
106.11,119.67,0.381
106.13,119.82,0.381
106.14,119.97,0.381
106.16,120.12,0.381
106.17,120.27,0.381
106.19,120.42,0.381
106.20,120.57,0.382
106.22,120.72,0.382
106.23,120.87,0.382
106.25,121.02,0.382
106.26,121.17,0.382
106.28,121.32,0.382
106.29,121.47,0.382
106.31,121.62,0.382
106.32,121.77,0.382
106.34,121.92,0.382
106.35,122.07,0.383
106.37,122.22,0.383
106.38,122.37,0.383
106.40,122.52,0.383
106.41,122.67,0.383
106.43,122.82,0.383
106.44,122.98,0.383
106.46,123.12,0.383
106.47,123.28,0.383
106.49,123.42,0.383
106.50,123.57,0.383
106.52,123.72,0.383
106.53,123.87,0.384
106.55,124.02,0.384
106.56,124.17,0.384
106.58,124.32,0.384
106.59,124.47,0.384
106.61,124.62,0.384
106.62,124.77,0.384
106.64,124.92,0.384
106.65,125.07,0.384
106.67,125.22,0.384
106.68,125.37,0.384
106.70,125.52,0.384
106.71,125.67,0.385
106.73,125.83,0.385
106.74,125.97,0.385
106.76,126.12,0.385
106.77,126.28,0.385
106.79,126.43,0.385
106.80,126.57,0.385
106.82,126.73,0.385
106.83,126.88,0.385
106.85,127.03,0.386
106.86,127.18,0.386
106.88,127.33,0.386
106.89,127.48,0.386
106.91,127.63,0.386
106.92,127.78,0.386
106.94,127.93,0.386
106.95,128.08,0.386
106.97,128.23,0.386
106.98,128.38,0.386
107.00,128.53,0.387
107.01,128.68,0.387
107.03,128.83,0.387
107.04,128.98,0.387
107.06,129.13,0.387
107.07,129.28,0.387
107.09,129.43,0.387
107.10,129.58,0.387
107.12,129.73,0.387
107.13,129.88,0.387
107.15,130.03,0.387
107.16,130.18,0.387
107.18,130.33,0.387
107.19,130.48,0.388
107.21,130.63,0.388
107.22,130.78,0.388
107.24,130.93,0.388
107.25,131.08,0.388
107.27,131.23,0.388
107.28,131.38,0.388
107.30,131.53,0.388
107.31,131.68,0.388
107.33,131.83,0.388
107.34,131.98,0.388
107.36,132.13,0.388
107.37,132.28,0.389
107.39,132.43,0.389
107.40,132.58,0.389
107.42,132.73,0.389
107.43,132.88,0.389
107.45,133.03,0.389
107.46,133.18,0.389
107.48,133.33,0.389
107.49,133.48,0.389
107.51,133.63,0.389
107.52,133.78,0.389
107.54,133.93,0.389
107.55,134.08,0.390
107.57,134.23,0.390
107.58,134.38,0.390
107.60,134.53,0.390
107.61,134.68,0.390
107.63,134.83,0.390
107.64,134.98,0.390
107.66,135.13,0.390
107.67,135.28,0.390
107.69,135.43,0.390
107.70,135.58,0.390
107.72,135.73,0.390
107.73,135.88,0.390
107.75,136.03,0.391
107.76,136.18,0.391
107.78,136.33,0.391
107.79,136.48,0.391
107.81,136.63,0.391
107.82,136.79,0.391
107.84,136.94,0.391
107.85,137.09,0.391
107.87,137.24,0.391
107.88,137.39,0.391
107.90,137.54,0.391
107.91,137.69,0.392
107.93,137.84,0.392
107.94,137.99,0.392
107.96,138.14,0.392
107.97,138.29,0.392
107.99,138.44,0.392
108.00,138.59,0.392
108.02,138.74,0.392
108.03,138.88,0.392
108.05,139.04,0.392
108.06,139.18,0.392
108.08,139.34,0.392
108.09,139.49,0.392
108.11,139.64,0.392
108.12,139.79,0.392
108.14,139.94,0.393
108.15,140.09,0.393
108.17,140.24,0.393
108.18,140.39,0.393
108.20,140.54,0.393
108.21,140.69,0.393
108.23,140.84,0.393
108.24,140.99,0.393
108.26,141.14,0.393
108.27,141.29,0.394
108.29,141.44,0.394
108.30,141.59,0.394
108.32,141.74,0.394
108.33,141.89,0.394
108.35,142.04,0.394
108.36,142.19,0.394
108.38,142.34,0.394
108.39,142.49,0.394
108.41,142.64,0.394
108.42,142.79,0.394
108.44,142.94,0.394
108.45,143.09,0.394
108.47,143.24,0.394
108.48,143.39,0.394
108.50,143.54,0.394
108.51,143.69,0.394
108.53,143.84,0.395
108.54,143.99,0.395
108.56,144.14,0.395
108.57,144.29,0.395
108.59,144.44,0.395
108.60,144.59,0.395
108.62,144.74,0.395
108.63,144.89,0.395
108.65,145.04,0.395
108.66,145.19,0.395
108.68,145.34,0.395
108.69,145.49,0.395
108.71,145.64,0.395
108.72,145.79,0.395
108.74,145.94,0.395
108.75,146.09,0.395
108.77,146.24,0.395
108.78,146.39,0.396
108.80,146.54,0.396
108.81,146.69,0.396
108.83,146.84,0.396
108.84,146.99,0.396
108.86,147.14,0.396
108.87,147.29,0.396
108.89,147.44,0.396
108.90,147.59,0.396
108.92,147.74,0.396
108.93,147.89,0.396
108.95,148.04,
108.96,148.19,
108.98,148.34,
108.99,,