File: DSC/2025_04_20_4THCa_6PVP_ASD_n60C_160C_10Cmin_x3.csv
Filename,2025_04_20_4THCa_6PVP_ASD_n60C_160C_10Cmin_x3
Instrument name,DSC2A-00468 (192.168.1.100)
Operator,Yarger
rundate,4/20/2025
Sample name,2025_04_20_4THCa_6PVP_ASD_n60C_160C_10Cmin_x3
proceduresegments,Data Off ; Equilibrate -60.00 °C; Data On ; Ramp 10.00 °C/min to 160.00 °C; Data Off ; Isothermal 1.0 min; Data On ; Ramp 10.00 °C/min to -60.00 °C; Data Off ; Isothermal 1.0 min; Data On ; Ramp 10.00 °C/min to 160.00 °C; Data Off ; Isothermal 1.0 min; Data On ; Ramp 10.00 °C/min to -60.00 °C; Data Off ; Isothermal 1.0 min; Data On ; Ramp 10.00 °C/min to 160.00 °C
[File Parameters]
Run date,4/20/2025 7:08:24 PM
Trios version,5.1.1.46572
Original File Name,
Current File Name,D:\DSC2500\JYarger\2025_04_20_4THCa_6PVP_ASD_n60C_160C_10Cmin_x3.tri
[Procedure]
Procedure Name,THCa_PVP_ASU_n60_160C_10Cmin_x3
Sample Name,2025_04_20_4THCa_6PVP_ASD_n60C_160C_10Cmin_x3
Sample Mass,1.68 mg
Reference Sample Mass,0 mg
Pan Mass,25.36 mg
Pan Number,35
Reference Pan Mass,25.8 mg
Reference Pan Number,28
Pan Type,Tzero Aluminum
Comments,"Al Pan/Lid, Not sealed."
Project Name,CA
Operator,Yarger
Test,Custom
Unload Max Temperature,30
Unload Min Temperature,30
Load Max Temperature,30
Load Min Temperature,30
Stop on Gas Flow Error,Yes
[Signal List]
Signal #1,Time (min)
Signal #2,Temperature (°C)
Signal #3,Heat Flow (mW)
Signal #4,Delta T (µV)
Signal #5,Delta Tzero (µV)
Signal #6,Tzero Temperature (°C)
Signal #7,Cell Purge (mL/min)
Signal #8,Heater Temp (°C)
Signal #9,Power Delivered (W)
Signal #10,Reference Junction Temperature (°C)
Signal #11,Flange Temperature (°C)
Signal #12,Heat Flow Phase (rad)
Signal #13,Total Heat Capacity (J/°C)
Signal #14,Heat Capacity (J/°C)
[Configuration]
Company Name,ASU
Instrument Name,DSC2A-00468
Instrument Type,DSC2500
Serial Number,DSC2A-00468
IP,192.168.1.100
Location of Instrument,MRRC
DisplayType,Unknown
Sample Interval ,0.1 s/pt
Selected Heat Flow,T4P
Exotherm Direction,Down
Cell Serial,DRC2-00792
Lid Type,Standard
Cooler,RCS 90
Leave Cooler on at End of Sequence,On
Gas 2,Nitrogen
Gas Selected,Channel 1
Flow Rate,50 mL/min
Secondary Purge,On
Licensed Heat Flow,Heat Flow T4P
Modulation Licensed,Yes
[Versions]
Common IDD Version,1
Cortex Version,VER 2.10.2.31
Driver,5.0.0.6
GDM Version,1.0.3.3
TouchscreenVersion,1.0.0.16145
FEP Version,1.2.1.21
FEP Bootloader,2.0.0.5
AutoSampler Version,2.1.1.26
Auto Sampler Bootloader,2.0.0.5
FCM Version,1.1.0.3
FCM Bootloader,2.0.0.5
[Experiment Logs]
Experiment Log Entry # 1,Air Cool is off.
Experiment Log Entry # 3,Data On set to 0
Experiment Log Entry # 5,Equilibrate Segment -60 (C) Started
Experiment Log Entry # 7,Data On set to 1
Experiment Log Entry # 9,Ramp Segment 10 C/min to 160 Started
Experiment Log Entry # 11,Data On set to 0
Experiment Log Entry # 13,Isothermal Segment 1 min started
Experiment Log Entry # 15,Data On set to 1
Experiment Log Entry # 17,Ramp Segment 10 C/min to -60 Started
Experiment Log Entry # 19,Data On set to 0
Experiment Log Entry # 21,Isothermal Segment 1 min started
Experiment Log Entry # 23,Data On set to 1
Experiment Log Entry # 25,Ramp Segment 10 C/min to 160 Started
Experiment Log Entry # 27,Data On set to 0
Experiment Log Entry # 29,Isothermal Segment 1 min started
Experiment Log Entry # 31,Data On set to 1
Experiment Log Entry # 33,Ramp Segment 10 C/min to -60 Started
Experiment Log Entry # 35,Data On set to 0
Experiment Log Entry # 37,Isothermal Segment 1 min started
Experiment Log Entry # 39,Data On set to 1
Experiment Log Entry # 41,Ramp Segment 10 C/min to 160 Started
[Method Log]
Method Log Entry # 1,Data Off
Method Log Entry # 2,Equilibrate -60 °C
Method Log Entry # 3,Data On
Method Log Entry # 4,(Ramp 598159) Ramp 10 °C/minute to 160 °C
Method Log Entry # 5,Data Off
Method Log Entry # 6,Isothermal 1 minutes
Method Log Entry # 7,Data On
Method Log Entry # 8,(Ramp 598163) Ramp 10 °C/minute to -60 °C
Method Log Entry # 9,Data Off
Method Log Entry # 10,Isothermal 1 minutes
Method Log Entry # 11,Data On
Method Log Entry # 12,(Ramp 598167) Ramp 10 °C/minute to 160 °C
Method Log Entry # 13,Data Off
Method Log Entry # 14,Isothermal 1 minutes
Method Log Entry # 15,Data On
Method Log Entry # 16,(Ramp 598171) Ramp 10 °C/minute to -60 °C
Method Log Entry # 17,Data Off
Method Log Entry # 18,Isothermal 1 minutes
Method Log Entry # 19,Data On
Method Log Entry # 20,(Ramp 598175) Ramp 10 °C/minute to 160 °C
Cell Serial,DRC2-00792
[T1 Calibration]
Slope,-0.008529666
Offset,9.636258
Initial Temperature,98.23
GUID,f8bfdadc-4977-4fdf-ba6d-0ba9134940c3
[TZero Calibration]
Date Applied,11/29/2022 4:06:13 PM
Description,From -89.059 °C to 396.009 °C at 20.000°C/min
Gas Type,Nitrogen
Pan Type,None
Source Files 1,C:\Users\yargerlab\Desktop\DSC Data\General\TZero_calibration_11_29_22_2nd(2).tri
Source Files 2,C:\Users\yargerlab\Desktop\DSC Data\General\TZero_calibration_11_29_22_2nd(3).tri
Delta T Offset,13.05235
Delta T Slope,-0.007271007
Delta T0 Offset,-13.69128
Delta T0 Slope,0.06063341
[Temperature Calibration]
Date Applied,11/29/2022 7:12:28 PM
Description,From 106.590 °C to 186.590 °C at 10.000°C/min
Gas Type,Nitrogen
Pan Type,Tzero Aluminum Hermetic
Source Files 1,C:\Users\yargerlab\Desktop\DSC Data\General\Indium(6).tri
Measured 1,157.391
Known 1,156.598
[Cell Constant Calibration]
Date Applied,11/29/2022 7:12:29 PM
Description,From 106.590 °C to 186.590 °C at 10.000°C/min
Gas Type,Nitrogen
Pan Type,Tzero Aluminum Hermetic
Source Files 1,C:\Users\yargerlab\Desktop\DSC Data\General\Indium(6).tri
T4P KCell,1.006051
Onset Slope,63.26126 mW/°C
[Direct Cp Calibration]
Date Applied,11/30/2022 11:04:51 AM
Description,From -79.983 °C to 298.409 °C at 10.000°C/min
Gas Type,Nitrogen
Pan Type,Tzero Aluminum Hermetic
Source Files 1,C:\Users\yargerlab\Desktop\DSC Data\General\Sapphire_Heat_Capacity_11_30_22.tri
[Rev Cp Calibration]
Date Applied,11/30/2022 1:58:51 PM
Description,From -79.996 °C to 292.812 °C at 3.000°C/min
Gas Type,Nitrogen
Pan Type,Tzero Aluminum Hermetic
Source Files 1,C:\Users\yargerlab\Desktop\DSC Data\General\Sapphire_MDSC_Calibration_11_30_22.tri
[step]
Ramp 10.00 °C/min to 160.00 °C
Time,Temperature,Heat Flow (Normalized)
min,°C,W/g
0.00,-59.80,-0.094
0.01,-59.81,-0.094
0.03,-59.81,-0.091
0.05,-59.80,-0.084
0.06,-59.79,-0.069
0.08,-59.76,-0.049
0.09,-59.71,-0.028
0.11,-59.65,-0.011
0.12,-59.57,0.008
0.14,-59.47,0.026
0.15,-59.36,0.045
0.16,-59.24,0.061
0.18,-59.11,0.078
0.19,-58.98,0.093
0.21,-58.84,0.106
0.23,-58.70,0.119
0.24,-58.55,0.130
0.26,-58.41,0.139
0.27,-58.26,0.144
0.29,-58.12,0.150
0.30,-57.97,0.154
0.31,-57.83,0.159
0.33,-57.68,0.161
0.35,-57.54,0.163
0.36,-57.39,0.164
0.38,-57.24,0.166
0.39,-57.10,0.167
0.40,-56.95,0.168
0.42,-56.80,0.169
0.44,-56.66,0.169
0.45,-56.51,0.170
0.46,-56.36,0.171
0.48,-56.22,0.171
0.50,-56.07,0.172
0.51,-55.92,0.173
0.53,-55.78,0.174
0.54,-55.63,0.174
0.55,-55.48,0.175
0.57,-55.33,0.175
0.58,-55.19,0.176
0.60,-55.04,0.177
0.62,-54.89,0.177
0.63,-54.74,0.178
0.65,-54.60,0.179
0.66,-54.45,0.179
0.68,-54.30,0.180
0.69,-54.15,0.180
0.70,-54.00,0.181
0.72,-53.85,0.181
0.73,-53.71,0.182
0.75,-53.56,0.182
0.77,-53.41,0.183
0.78,-53.26,0.183
0.80,-53.11,0.184
0.81,-52.97,0.184
0.83,-52.82,0.185
0.84,-52.67,0.185
0.85,-52.52,0.185
0.87,-52.37,0.186
0.88,-52.22,0.186
0.90,-52.08,0.186
0.92,-51.93,0.186
0.93,-51.78,0.187
0.95,-51.63,0.187
0.96,-51.48,0.187
0.98,-51.33,0.188
0.99,-51.18,0.188
1.00,-51.03,0.188
1.02,-50.89,0.188
1.03,-50.74,0.188
1.05,-50.59,0.189
1.07,-50.44,0.189
1.08,-50.29,0.189
1.09,-50.14,0.189
1.11,-49.99,0.189
1.13,-49.84,0.190
1.14,-49.69,0.190
1.16,-49.54,0.190
1.17,-49.39,0.190
1.18,-49.24,0.190
1.20,-49.09,0.190
1.22,-48.94,0.190
1.23,-48.79,0.191
1.24,-48.64,0.191
1.26,-48.50,0.191
1.28,-48.35,0.191
1.29,-48.20,0.191
1.31,-48.05,0.191
1.32,-47.90,0.191
1.33,-47.75,0.191
1.35,-47.60,0.191
1.37,-47.45,0.191
1.38,-47.30,0.191
1.39,-47.15,0.191
1.41,-47.00,0.191
1.43,-46.85,0.191
1.44,-46.70,0.191
1.46,-46.55,0.191
1.47,-46.40,0.191
1.48,-46.25,0.191
1.50,-46.10,0.191
1.52,-45.95,0.191
1.53,-45.80,0.191
1.54,-45.65,0.191
1.56,-45.50,0.191
1.58,-45.35,0.191
1.59,-45.20,0.191
1.61,-45.05,0.191
1.62,-44.90,0.191
1.63,-44.75,0.191
1.65,-44.60,0.191
1.67,-44.45,0.191
1.68,-44.30,0.191
1.69,-44.15,0.191
1.71,-44.00,0.191
1.73,-43.85,0.191
1.74,-43.70,0.191
1.76,-43.55,0.191
1.77,-43.40,0.191
1.78,-43.25,0.191
1.80,-43.10,0.191
1.82,-42.95,0.191
1.83,-42.80,0.191
1.84,-42.65,0.191
1.86,-42.50,0.191
1.88,-42.35,0.191
1.89,-42.20,0.191
1.91,-42.05,0.191
1.92,-41.90,0.191
1.93,-41.75,0.191
1.95,-41.60,0.191
1.97,-41.45,0.190
1.98,-41.30,0.190
1.99,-41.15,0.190
2.01,-41.00,0.190
2.03,-40.85,0.190
2.04,-40.70,0.190
2.06,-40.55,0.190
2.07,-40.40,0.190
2.08,-40.25,0.190
2.10,-40.10,0.190
2.12,-39.95,0.190
2.13,-39.80,0.190
2.14,-39.65,0.189
2.16,-39.50,0.189
2.18,-39.35,0.189
2.19,-39.20,0.189
2.21,-39.05,0.189
2.22,-38.90,0.189
2.24,-38.75,0.189
2.25,-38.60,0.189
2.26,-38.45,0.189
2.28,-38.30,0.189
2.29,-38.15,0.189
2.31,-38.00,0.189
2.33,-37.85,0.188
2.34,-37.70,0.188
2.36,-37.55,0.188
2.37,-37.40,0.188
2.39,-37.25,0.188
2.40,-37.10,0.188
2.41,-36.95,0.188
2.43,-36.80,0.188
2.44,-36.65,0.188
2.46,-36.50,0.188
2.48,-36.35,0.188
2.49,-36.20,0.187
2.51,-36.05,0.187
2.52,-35.90,0.187
2.54,-35.74,0.187
2.55,-35.59,0.187
2.56,-35.44,0.187
2.58,-35.29,0.187
2.59,-35.14,0.187
2.61,-34.99,0.187
2.63,-34.84,0.187
2.64,-34.69,0.187
2.66,-34.54,0.187
2.67,-34.39,0.186
2.69,-34.24,0.186
2.70,-34.09,0.186
2.71,-33.94,0.186
2.73,-33.79,0.186
2.74,-33.64,0.186
2.76,-33.49,0.186
2.78,-33.34,0.186
2.79,-33.19,0.186
2.81,-33.04,0.186
2.82,-32.89,0.186
2.84,-32.74,0.186
2.85,-32.59,0.186
2.86,-32.44,0.186
2.88,-32.29,0.185
2.89,-32.14,0.185
2.91,-31.99,0.185
2.93,-31.84,0.185
2.94,-31.69,0.185
2.96,-31.54,0.185
2.97,-31.39,0.185
2.99,-31.24,0.185
3.00,-31.09,0.185
3.01,-30.94,0.185
3.03,-30.79,0.185
3.04,-30.64,0.185
3.06,-30.49,0.185
3.08,-30.34,0.185
3.09,-30.19,0.185
3.11,-30.04,0.185
3.12,-29.89,0.185
3.14,-29.74,0.184
3.15,-29.59,0.184
3.16,-29.44,0.184
3.18,-29.29,0.184
3.19,-29.14,0.184
3.21,-28.99,0.184
3.23,-28.84,0.184
3.24,-28.69,0.184
3.26,-28.54,0.184
3.27,-28.39,0.184
3.29,-28.24,0.184
3.30,-28.09,0.184
3.31,-27.93,0.184
3.33,-27.79,0.184
3.34,-27.64,0.184
3.36,-27.48,0.184
3.38,-27.33,0.184
3.39,-27.18,0.184
3.41,-27.03,0.184
3.42,-26.88,0.184
3.44,-26.73,0.183
3.45,-26.58,0.183
3.46,-26.43,0.183
3.48,-26.28,0.183
3.49,-26.13,0.183
3.51,-25.98,0.183
3.53,-25.83,0.183
3.54,-25.68,0.183
3.56,-25.53,0.183
3.57,-25.38,0.183
3.59,-25.23,0.183
3.60,-25.08,0.183
3.61,-24.93,0.183
3.63,-24.78,0.183
3.64,-24.63,0.183
3.66,-24.48,0.183
3.68,-24.33,0.183
3.69,-24.18,0.183
3.71,-24.03,0.183
3.72,-23.88,0.183
3.74,-23.73,0.183
3.75,-23.58,0.183
3.76,-23.43,0.183
3.78,-23.28,0.183
3.79,-23.13,0.183
3.81,-22.98,0.183
3.83,-22.83,0.183
3.84,-22.68,0.183
3.86,-22.53,0.183
3.87,-22.38,0.183
3.89,-22.23,0.183
3.90,-22.08,0.183
3.91,-21.93,0.183
3.93,-21.78,0.183
3.94,-21.63,0.183
3.96,-21.48,0.183
3.98,-21.33,0.183
3.99,-21.18,0.183
4.01,-21.03,0.183
4.02,-20.88,0.183
4.04,-20.73,0.183
4.05,-20.58,0.183
4.06,-20.43,0.183
4.08,-20.28,0.183
4.09,-20.13,0.183
4.11,-19.98,0.183
4.13,-19.83,0.183
4.14,-19.68,0.183
4.16,-19.53,0.183
4.17,-19.38,0.183
4.19,-19.23,0.183
4.20,-19.08,0.183
4.21,-18.93,0.183
4.23,-18.78,0.183
4.24,-18.63,0.183
4.26,-18.48,0.183
4.28,-18.33,0.183
4.29,-18.18,0.183
4.30,-18.03,0.183
4.32,-17.87,0.183
4.34,-17.72,0.183
4.35,-17.57,0.183
4.36,-17.42,0.183
4.38,-17.27,0.183
4.40,-17.12,0.183
4.41,-16.97,0.183
4.43,-16.82,0.183
4.44,-16.67,0.183
4.45,-16.52,0.183
4.47,-16.37,0.183
4.49,-16.22,0.183
4.50,-16.07,0.183
4.51,-15.92,0.183
4.53,-15.77,0.183
4.55,-15.62,0.183
4.56,-15.47,0.183
4.58,-15.32,0.183
4.59,-15.17,0.183
4.60,-15.02,0.184
4.62,-14.87,0.183
4.64,-14.72,0.184
4.65,-14.57,0.184
4.66,-14.42,0.184
4.68,-14.27,0.184
4.70,-14.12,0.184
4.71,-13.97,0.184
4.73,-13.82,0.184
4.74,-13.67,0.184
4.75,-13.52,0.184
4.77,-13.37,0.184
4.79,-13.22,0.184
4.80,-13.07,0.185
4.81,-12.92,0.185
4.83,-12.77,0.185
4.85,-12.62,0.185
4.86,-12.47,0.185
4.88,-12.32,0.185
4.89,-12.17,0.185
4.90,-12.02,0.185
4.92,-11.87,0.185
4.94,-11.72,0.185
4.95,-11.57,0.185
4.96,-11.42,0.185
4.98,-11.27,0.186
5.00,-11.12,0.186
5.01,-10.97,0.186
5.03,-10.82,0.186
5.04,-10.67,0.186
5.05,-10.52,0.186
5.07,-10.37,0.186
5.09,-10.22,0.186
5.10,-10.07,0.186
5.11,-9.92,0.186
5.13,-9.77,0.186
5.15,-9.62,0.187
5.16,-9.47,0.187
5.18,-9.32,0.187
5.19,-9.17,0.187
5.20,-9.02,0.187
5.22,-8.87,0.187
5.24,-8.72,0.188
5.25,-8.57,0.188
5.26,-8.41,0.188
5.28,-8.27,0.188
5.30,-8.11,0.188
5.31,-7.97,0.188
5.33,-7.82,0.188
5.34,-7.67,0.189
5.35,-7.51,0.189
5.37,-7.36,0.189
5.39,-7.21,0.189
5.40,-7.07,0.189
5.41,-6.91,0.189
5.43,-6.76,0.189
5.45,-6.61,0.190
5.46,-6.46,0.190
5.48,-6.31,0.190
5.49,-6.16,0.190
5.50,-6.01,0.190
5.52,-5.86,0.190
5.54,-5.71,0.191
5.55,-5.56,0.191
5.56,-5.41,0.191
5.58,-5.26,0.191
5.60,-5.11,0.191
5.61,-4.96,0.191
5.63,-4.81,0.192
5.64,-4.66,0.192
5.65,-4.51,0.192
5.67,-4.36,0.192
5.69,-4.21,0.192
5.70,-4.06,0.193
5.71,-3.91,0.193
5.73,-3.76,0.193
5.75,-3.61,0.193
5.76,-3.46,0.193
5.78,-3.31,0.193
5.79,-3.16,0.193
5.80,-3.01,0.194
5.82,-2.86,0.194
5.84,-2.71,0.194
5.85,-2.56,0.194
5.86,-2.41,0.194
5.88,-2.26,0.195
5.90,-2.11,0.195
5.91,-1.96,0.195
5.93,-1.81,0.195
5.94,-1.66,0.195
5.95,-1.51,0.196
5.97,-1.36,0.196
5.99,-1.21,0.196
6.00,-1.06,0.196
6.01,-0.91,0.196
6.03,-0.76,0.197
6.05,-0.61,0.197
6.06,-0.46,0.197
6.08,-0.31,0.197
6.09,-0.16,0.198
6.10,-0.01,0.198
6.12,0.14,0.198
6.14,0.29,0.198
6.15,0.44,0.199
6.16,0.59,0.199
6.18,0.74,0.199
6.20,0.89,0.199
6.21,1.04,0.200
6.23,1.19,0.200
6.24,1.34,0.200
6.25,1.49,0.200
6.27,1.64,0.201
6.29,1.79,0.201
6.30,1.94,0.201
6.31,2.09,0.201
6.33,2.24,0.202
6.35,2.39,0.202
6.36,2.55,0.202
6.38,2.70,0.203
6.39,2.85,0.203
6.40,3.00,0.203
6.42,3.15,0.204
6.44,3.30,0.204
6.45,3.45,0.204
6.46,3.60,0.205
6.48,3.75,0.205
6.50,3.90,0.205
6.51,4.05,0.205
6.53,4.20,0.206
6.54,4.35,0.206
6.55,4.50,0.207
6.57,4.65,0.207
6.59,4.80,0.207
6.60,4.95,0.208
6.61,5.10,0.208
6.63,5.25,0.208
6.65,5.40,0.209
6.66,5.55,0.209
6.68,5.70,0.209
6.69,5.85,0.210
6.70,6.00,0.210
6.72,6.15,0.210
6.74,6.30,0.211
6.75,6.45,0.211
6.76,6.60,0.211
6.78,6.75,0.212
6.80,6.90,0.212
6.81,7.05,0.213
6.83,7.20,0.213
6.84,7.35,0.213
6.85,7.50,0.214
6.87,7.65,0.214
6.89,7.80,0.214
6.90,7.95,0.215
6.91,8.10,0.215
6.93,8.25,0.215
6.95,8.40,0.216
6.96,8.55,0.216
6.98,8.70,0.216
6.99,8.85,0.217
7.00,9.00,0.217
7.02,9.15,0.217
7.04,9.30,0.218
7.05,9.45,0.218
7.06,9.60,0.219
7.08,9.75,0.219
7.10,9.90,0.220
7.11,10.05,0.220
7.13,10.20,0.220
7.14,10.35,0.221
7.15,10.50,0.221
7.17,10.65,0.221
7.19,10.80,0.222
7.20,10.95,0.222
7.21,11.10,0.223
7.23,11.25,0.223
7.25,11.40,0.223
7.26,11.55,0.224
7.28,11.70,0.224
7.29,11.85,0.225
7.30,12.00,0.225
7.32,12.15,0.225
7.34,12.30,0.226
7.35,12.45,0.226
7.36,12.60,0.227
7.38,12.75,0.227
7.40,12.90,0.227
7.41,13.05,0.228
7.43,13.20,0.228
7.44,13.35,0.229
7.45,13.50,0.229
7.47,13.65,0.230
7.49,13.80,0.230
7.50,13.95,0.231
7.51,14.10,0.231
7.53,14.25,0.231
7.55,14.40,0.232
7.56,14.55,0.232
7.58,14.70,0.233
7.59,14.85,0.233
7.60,15.00,0.234
7.62,15.15,0.234
7.64,15.30,0.235
7.65,15.45,0.235
7.66,15.60,0.235
7.68,15.75,0.236
7.70,15.90,0.236
7.71,16.05,0.237
7.73,16.20,0.237
7.74,16.35,0.238
7.75,16.51,0.238
7.77,16.65,0.239
7.79,16.80,0.239
7.80,16.95,0.240
7.81,17.11,0.241
7.83,17.26,0.241
7.85,17.41,0.242
7.86,17.55,0.242
7.88,17.71,0.243
7.89,17.86,0.243
7.90,18.01,0.244
7.92,18.15,0.244
7.94,18.31,0.245
7.95,18.46,0.245
7.96,18.61,0.246
7.98,18.76,0.246
8.00,18.91,0.247
8.01,19.06,0.247
8.03,19.21,0.248
8.04,19.36,0.248
8.05,19.51,0.249
8.07,19.66,0.250
8.09,19.81,0.250
8.10,19.96,0.251
8.11,20.11,0.251
8.13,20.26,0.252
8.15,20.41,0.252
8.16,20.56,0.253
8.18,20.71,0.253
8.19,20.86,0.254
8.20,21.01,0.255
8.22,21.16,0.255
8.24,21.31,0.256
8.25,21.46,0.256
8.26,21.61,0.257
8.28,21.76,0.258
8.30,21.91,0.258
8.31,22.06,0.259
8.33,22.21,0.260
8.34,22.36,0.260
8.35,22.51,0.261
8.37,22.66,0.261
8.39,22.81,0.262
8.40,22.96,0.263
8.41,23.11,0.263
8.43,23.26,0.264
8.45,23.41,0.264
8.46,23.56,0.265
8.48,23.71,0.266
8.49,23.86,0.266
8.50,24.01,0.267
8.52,24.16,0.268
8.53,24.31,0.268
8.55,24.46,0.269
8.57,24.61,0.269
8.58,24.76,0.270
8.60,24.91,0.271
8.61,25.06,0.271
8.63,25.21,0.272
8.64,25.36,0.273
8.65,25.51,0.273
8.67,25.66,0.274
8.68,25.81,0.275
8.70,25.96,0.275
8.72,26.11,0.276
8.73,26.26,0.277
8.75,26.41,0.278
8.76,26.56,0.278
8.78,26.71,0.279
8.79,26.86,0.279
8.80,27.01,0.280
8.82,27.16,0.281
8.83,27.31,0.281
8.85,27.46,0.282
8.87,27.61,0.283
8.88,27.76,0.283
8.90,27.91,0.284
8.91,28.06,0.285
8.93,28.21,0.286
8.94,28.36,0.286
8.95,28.51,0.287
8.97,28.66,0.288
8.98,28.81,0.288
9.00,28.96,0.289
9.02,29.11,0.290
9.03,29.26,0.291
9.05,29.41,0.291
9.06,29.56,0.292
9.08,29.71,0.293
9.09,29.86,0.293
9.10,30.01,0.294
9.12,30.16,0.295
9.13,30.31,0.296
9.15,30.46,0.296
9.17,30.61,0.297
9.18,30.76,0.298
9.20,30.91,0.299
9.21,31.06,0.300
9.23,31.21,0.300
9.24,31.36,0.301
9.25,31.51,0.302
9.27,31.66,0.302
9.28,31.81,0.303
9.30,31.96,0.304
9.32,32.11,0.305
9.33,32.26,0.306
9.35,32.41,0.306
9.36,32.56,0.307
9.38,32.71,0.308
9.39,32.86,0.309
9.40,33.01,0.309
9.42,33.16,0.310
9.43,33.31,0.311
9.45,33.46,0.312
9.47,33.61,0.313
9.48,33.76,0.313
9.50,33.91,0.314
9.51,34.06,0.315
9.53,34.21,0.316
9.54,34.36,0.317
9.55,34.51,0.318
9.57,34.66,0.318
9.58,34.81,0.319
9.60,34.96,0.320
9.62,35.11,0.321
9.63,35.26,0.321
9.65,35.41,0.322
9.66,35.56,0.323
9.68,35.71,0.324
9.69,35.86,0.325
9.70,36.01,0.326
9.72,36.16,0.326
9.73,36.31,0.327
9.75,36.46,0.328
9.77,36.61,0.329
9.78,36.76,0.329
9.80,36.91,0.330
9.81,37.06,0.331
9.83,37.21,0.332
9.84,37.36,0.333
9.85,37.51,0.333
9.87,37.66,0.334
9.88,37.82,0.335
9.90,37.96,0.336
9.92,38.11,0.337
9.93,38.26,0.338
9.95,38.41,0.339
9.96,38.56,0.339
9.98,38.71,0.340
9.99,38.87,0.341
10.00,39.01,0.342
10.02,39.16,0.343
10.03,39.31,0.343
10.05,39.46,0.344
10.07,39.61,0.345
10.08,39.76,0.346
10.10,39.91,0.347
10.11,40.06,0.348
10.13,40.22,0.348
10.14,40.36,0.349
10.15,40.51,0.350
10.17,40.67,0.351
10.18,40.82,0.352
10.20,40.96,0.353
10.22,41.12,0.354
10.23,41.27,0.354
10.25,41.42,0.355
10.26,41.56,0.356
10.28,41.72,0.357
10.29,41.86,0.358
10.30,42.01,0.358
10.32,42.16,0.359
10.33,42.32,0.360
10.35,42.46,0.361
10.37,42.62,0.362
10.38,42.77,0.363
10.40,42.92,0.364
10.41,43.06,0.364
10.43,43.22,0.365
10.44,43.37,0.366
10.45,43.52,0.367
10.47,43.66,0.368
10.48,43.81,0.369
10.50,43.97,0.370
10.52,44.12,0.371
10.53,44.27,0.372
10.55,44.42,0.372
10.56,44.57,0.373
10.58,44.72,0.374
10.59,44.87,0.375
10.60,45.02,0.376
10.62,45.17,0.377
10.63,45.32,0.378
10.65,45.47,0.378
10.67,45.62,0.380
10.68,45.77,0.380
10.70,45.92,0.381
10.71,46.07,0.382
10.73,46.22,0.384
10.74,46.37,0.384
10.75,46.52,0.385
10.77,46.67,0.386
10.78,46.82,0.387
10.80,46.96,0.388
10.82,47.12,0.389
10.83,47.27,0.390
10.85,47.42,0.390
10.86,47.57,0.391
10.88,47.72,0.392
10.89,47.87,0.393
10.90,48.02,0.394
10.92,48.17,0.395
10.93,48.32,0.396
10.95,48.47,0.397
10.97,48.62,0.398
10.98,48.77,0.399
11.00,48.92,0.399
11.01,49.07,0.400
11.03,49.22,0.401
11.04,49.37,0.402
11.05,49.52,0.403
11.07,49.67,0.404
11.08,49.82,0.405
11.10,49.97,0.405
11.12,50.12,0.406
11.13,50.27,0.407
11.15,50.42,0.408
11.16,50.57,0.409
11.18,50.72,0.410
11.19,50.87,0.411
11.20,51.02,0.411
11.22,51.17,0.412
11.23,51.32,0.413
11.25,51.47,0.414
11.27,51.62,0.415
11.28,51.77,0.416
11.30,51.92,0.417
11.31,52.07,0.418
11.33,52.22,0.419
11.34,52.37,0.420
11.35,52.52,0.420
11.37,52.67,0.421
11.38,52.82,0.422
11.40,52.97,0.423
11.42,53.12,0.424
11.43,53.27,0.425
11.45,53.42,0.426
11.46,53.57,0.427
11.48,53.72,0.428
11.49,53.87,0.428
11.50,54.02,0.429
11.52,54.17,0.430
11.53,54.32,0.431
11.55,54.47,0.432
11.57,54.62,0.433
11.58,54.77,0.434
11.60,54.92,0.435
11.61,55.07,0.436
11.63,55.22,0.437
11.64,55.37,0.437
11.65,55.52,0.438
11.67,55.67,0.439
11.68,55.82,0.440
11.70,55.97,0.441
11.72,56.12,0.442
11.73,56.27,0.443
11.75,56.42,0.443
11.76,56.57,0.444
11.78,56.72,0.445
11.79,56.87,0.446
11.80,57.02,0.447
11.82,57.17,0.448
11.83,57.32,0.449
11.85,57.47,0.449
11.87,57.62,0.450
11.88,57.77,0.451
11.90,57.92,0.452
11.91,58.07,0.453
11.93,58.22,0.454
11.94,58.37,0.455
11.95,58.52,0.455
11.97,58.67,0.456
11.98,58.82,0.457
12.00,58.97,0.458
12.02,59.12,0.459
12.03,59.27,0.460
12.05,59.42,0.461
12.06,59.57,0.461
12.08,59.72,0.462
12.09,59.87,0.463
12.10,60.02,0.464
12.12,60.17,0.465
12.13,60.32,0.465
12.15,60.47,0.466
12.17,60.62,0.467
12.18,60.77,0.468
12.20,60.92,0.469
12.21,61.07,0.469
12.23,61.22,0.470
12.24,61.37,0.471
12.25,61.52,0.472
12.27,61.67,0.473
12.28,61.82,0.473
12.30,61.97,0.474
12.32,62.12,0.475
12.33,62.27,0.476
12.35,62.42,0.477
12.36,62.57,0.478
12.38,62.72,0.478
12.39,62.87,0.479
12.40,63.02,0.480
12.42,63.17,0.481
12.43,63.32,0.481
12.45,63.47,0.482
12.47,63.62,0.483
12.48,63.77,0.484
12.50,63.92,0.484
12.51,64.07,0.485
12.53,64.22,0.486
12.54,64.37,0.486
12.55,64.52,0.487
12.57,64.67,0.488
12.58,64.82,0.489
12.60,64.97,0.489
12.62,65.12,0.490
12.63,65.27,0.491
12.65,65.42,0.491
12.66,65.57,0.492
12.68,65.72,0.493
12.69,65.87,0.493
12.70,66.02,0.494
12.72,66.17,0.495
12.73,66.32,0.495
12.75,66.47,0.496
12.77,66.62,0.497
12.78,66.77,0.497
12.80,66.92,0.498
12.81,67.08,0.498
12.83,67.22,0.499
12.84,67.37,0.499
12.85,67.53,0.500
12.87,67.68,0.501
12.88,67.83,0.501
12.90,67.98,0.502
12.92,68.12,0.502
12.93,68.27,0.503
12.95,68.42,0.503
12.96,68.58,0.503
12.98,68.72,0.504
12.99,68.87,0.504
13.00,69.03,0.505
13.02,69.18,0.505
13.03,69.33,0.506
13.05,69.48,0.506
13.07,69.63,0.506
13.08,69.78,0.507
13.10,69.92,0.507
13.11,70.08,0.508
13.13,70.22,0.508
13.14,70.38,0.508
13.15,70.53,0.509
13.17,70.68,0.509
13.18,70.83,0.509
13.20,70.98,0.510
13.22,71.13,0.510
13.23,71.28,0.510
13.25,71.43,0.510
13.26,71.58,0.511
13.28,71.73,0.511
13.29,71.88,0.511
13.30,72.03,0.511
13.32,72.18,0.511
13.33,72.33,0.511
13.35,72.48,0.511
13.37,72.63,0.511
13.38,72.78,0.512
13.40,72.93,0.511
13.41,73.08,0.512
13.43,73.23,0.511
13.44,73.38,0.512
13.45,73.53,0.512
13.47,73.68,0.511
13.48,73.83,0.511
13.50,73.98,0.511
13.52,74.13,0.511
13.53,74.28,0.511
13.55,74.43,0.511
13.56,74.58,0.510
13.58,74.73,0.510
13.59,74.88,0.510
13.60,75.03,0.510
13.62,75.18,0.510
13.63,75.33,0.509
13.65,75.48,0.509
13.67,75.63,0.508
13.68,75.78,0.508
13.70,75.93,0.508
13.71,76.08,0.507
13.73,76.23,0.507
13.74,76.38,0.506
13.75,76.53,0.506
13.77,76.68,0.505
13.78,76.83,0.504
13.80,76.98,0.504
13.82,77.13,0.503
13.83,77.28,0.502
13.85,77.43,0.502
13.86,77.58,0.501
13.88,77.73,0.500
13.89,77.88,0.499
13.90,78.03,0.498
13.92,78.18,0.497
13.93,78.33,0.497
13.95,78.48,0.496
13.97,78.64,0.495
13.98,78.79,0.494
14.00,78.94,0.493
14.01,79.09,0.492
14.03,79.24,0.491
14.04,79.39,0.489
14.05,79.54,0.488
14.07,79.69,0.487
14.08,79.84,0.486
14.10,79.99,0.485
14.12,80.14,0.483
14.13,80.29,0.482
14.15,80.44,0.481
14.16,80.59,0.479
14.18,80.74,0.478
14.19,80.89,0.477
14.20,81.04,0.475
14.22,81.19,0.473
14.23,81.34,0.471
14.25,81.49,0.470
14.27,81.64,0.468
14.28,81.79,0.467
14.30,81.94,0.465
14.31,82.09,0.463
14.33,82.24,0.461
14.34,82.39,0.459
14.35,82.54,0.458
14.37,82.69,0.456
14.38,82.85,0.454
14.40,83.00,0.452
14.42,83.15,0.450
14.43,83.30,0.448
14.45,83.45,0.446
14.46,83.60,0.444
14.48,83.75,0.442
14.49,83.90,0.440
14.50,84.05,0.438
14.52,84.20,0.436
14.53,84.35,0.434
14.55,84.50,0.431
14.57,84.65,0.430
14.58,84.80,0.427
14.60,84.95,0.425
14.61,85.10,0.424
14.63,85.25,0.421
14.64,85.40,0.419
14.65,85.55,0.416
14.67,85.70,0.414
14.68,85.85,0.412
14.70,86.00,0.410
14.72,86.15,0.408
14.73,86.30,0.406
14.75,86.45,0.404
14.76,86.60,0.402
14.78,86.75,0.399
14.79,86.90,0.398
14.80,87.06,0.396
14.82,87.21,0.394
14.83,87.36,0.393
14.85,87.51,0.390
14.87,87.66,0.388
14.88,87.81,0.385
14.90,87.96,0.383
14.91,88.11,0.381
14.93,88.26,0.379
14.94,88.41,0.376
14.95,88.56,0.374
14.97,88.71,0.373
14.98,88.86,0.370
15.00,89.01,0.368
15.02,89.16,0.366
15.03,89.31,0.364
15.05,89.46,0.362
15.06,89.61,0.360
15.08,89.76,0.358
15.09,89.91,0.355
15.10,90.06,0.353
15.12,90.21,0.351
15.13,90.36,0.349
15.15,90.51,0.348
15.17,90.66,0.346
15.18,90.81,0.344
15.20,90.96,0.343
15.21,91.12,0.340
15.23,91.26,0.338
15.24,91.41,0.337
15.25,91.57,0.335
15.27,91.71,0.333
15.28,91.87,0.332
15.30,92.02,0.330
15.32,92.17,0.328
15.33,92.32,0.327
15.35,92.47,0.325
15.36,92.62,0.324
15.38,92.77,0.322
15.39,92.92,0.321
15.40,93.07,0.319
15.42,93.22,0.318
15.43,93.37,0.316
15.45,93.52,0.314
15.47,93.67,0.312
15.48,93.82,0.310
15.50,93.97,0.308
15.51,94.12,0.307
15.53,94.27,0.305
15.54,94.42,0.304
15.55,94.57,0.302
15.57,94.72,0.301
15.58,94.87,0.300
15.60,95.02,0.298
15.62,95.17,0.297
15.63,95.32,0.295
15.65,95.47,0.294
15.66,95.62,0.292
15.68,95.77,0.291
15.69,95.92,0.289
15.70,96.07,0.288
15.72,96.22,0.287
15.73,96.37,0.285
15.75,96.52,0.284
15.77,96.67,0.283
15.78,96.82,0.281
15.80,96.98,0.280
15.81,97.12,0.279
15.83,97.27,0.278
15.84,97.42,0.276
15.85,97.58,0.275
15.87,97.72,0.274
15.88,97.88,0.273
15.90,98.03,0.272
15.92,98.18,0.270
15.93,98.33,0.269
15.95,98.48,0.268
15.96,98.62,0.267
15.98,98.78,0.266
15.99,98.93,0.265
16.00,99.08,0.264
16.02,99.23,0.263
16.03,99.38,0.262
16.05,99.53,0.261
16.07,99.68,0.260
16.08,99.83,0.259
16.10,99.98,0.258
16.11,100.13,0.257
16.13,100.28,0.256
16.14,100.43,0.255
16.15,100.58,0.254
16.17,100.73,0.253
16.18,100.88,0.252
16.20,101.03,0.251
16.22,101.18,0.250
16.23,101.33,0.250
16.25,101.48,0.249
16.26,101.63,0.248
16.28,101.78,0.247
16.29,101.93,0.247
16.30,102.08,0.246
16.32,102.23,0.245
16.33,102.38,0.244
16.35,102.53,0.244
16.37,102.68,0.243
16.38,102.83,0.243
16.40,102.98,0.242
16.41,103.13,0.242
16.43,103.28,0.241
16.44,103.43,0.240
16.45,103.58,0.240
16.47,103.73,0.239
16.48,103.88,0.239
16.50,104.03,0.238
16.52,104.18,0.238
16.53,104.33,0.238
16.55,104.48,0.237
16.56,104.63,0.237
16.58,104.78,0.236
16.59,104.93,0.236
16.60,105.08,0.236
16.62,105.23,0.235
16.63,105.38,0.235
16.65,105.53,0.235
16.67,105.69,0.234
16.68,105.83,0.234
16.70,105.98,0.234
16.71,106.13,0.234
16.73,106.29,0.233
16.74,106.44,0.233
16.75,106.59,0.233
16.77,106.74,0.233
16.78,106.89,0.233
16.80,107.04,0.232
16.82,107.19,0.232
16.83,107.34,0.232
16.85,107.49,0.232
16.86,107.63,0.232
16.88,107.79,0.232
16.89,107.94,0.232
16.90,108.09,0.232
16.92,108.24,0.232
16.93,108.39,0.232
16.95,108.54,0.232
16.97,108.69,0.232
16.98,108.84,0.232
17.00,108.99,0.232
17.01,109.14,0.233
17.03,109.29,0.233
17.04,109.44,0.233
17.05,109.59,0.233
17.07,109.74,0.233
17.08,109.89,0.233
17.10,110.04,0.233
17.12,110.19,0.233
17.13,110.34,0.233
17.14,110.49,0.234
17.16,110.64,0.234
17.18,110.79,0.234
17.19,110.94,0.234
17.21,111.09,0.234
17.22,111.24,0.235
17.23,111.39,0.235
17.25,111.54,0.235
17.27,111.69,0.235
17.28,111.84,0.235
17.29,111.99,0.236
17.31,112.14,0.236
17.33,112.29,0.236
17.34,112.44,0.237
17.36,112.59,0.237
17.37,112.74,0.237
17.38,112.89,0.237
17.40,113.04,0.238
17.42,113.19,0.238
17.43,113.34,0.238
17.44,113.49,0.238
17.46,113.64,0.239
17.48,113.79,0.239
17.49,113.94,0.239
17.51,114.09,0.240
17.52,114.24,0.240
17.53,114.39,0.240
17.55,114.54,0.241
17.57,114.69,0.241
17.58,114.84,0.241
17.59,114.99,0.242
17.61,115.14,0.242
17.63,115.29,0.242
17.64,115.44,0.242
17.66,115.59,0.243
17.67,115.74,0.243
17.68,115.89,0.243
17.70,116.04,0.244
17.72,116.19,0.244
17.73,116.34,0.244
17.74,116.49,0.244
17.76,116.64,0.245
17.78,116.79,0.245
17.79,116.94,0.245
17.81,117.09,0.245
17.82,117.24,0.246
17.83,117.39,0.246
17.85,117.54,0.246
17.87,117.69,0.246
17.88,117.84,0.247
17.89,117.99,0.247
17.91,118.14,0.247
17.93,118.29,0.247
17.94,118.44,0.247
17.96,118.59,0.247
17.97,118.74,0.248
17.98,118.89,0.248
18.00,119.04,0.248
18.02,119.19,0.248
18.03,119.34,0.248
18.04,119.49,0.248
18.06,119.65,0.248
18.08,119.79,0.248
18.09,119.94,0.248
18.11,120.10,0.249
18.12,120.24,0.249
18.13,120.39,0.249
18.15,120.54,0.249
18.17,120.70,0.249
18.18,120.85,0.249
18.19,121.00,0.249
18.21,121.15,0.249
18.23,121.30,0.249
18.24,121.45,0.249
18.26,121.60,0.250
18.27,121.75,0.250
18.28,121.90,0.250
18.30,122.05,0.250
18.32,122.20,0.250
18.33,122.35,0.250
18.34,122.50,0.250
18.36,122.65,0.250
18.38,122.80,0.250
18.39,122.94,0.250
18.41,123.10,0.250
18.42,123.25,0.250
18.43,123.40,0.250
18.45,123.55,0.250
18.47,123.70,0.250
18.48,123.85,0.250
18.49,124.00,0.250
18.51,124.15,0.250
18.53,124.30,0.250
18.54,124.45,0.250
18.56,124.60,0.250
18.57,124.75,0.250
18.58,124.90,0.250
18.60,125.05,0.250
18.62,125.20,0.250
18.63,125.35,0.250
18.64,125.50,0.250
18.66,125.65,0.250
18.68,125.80,0.250
18.69,125.95,0.250
18.71,126.10,0.250
18.72,126.25,0.250
18.73,126.40,0.250
18.75,126.55,0.250
18.77,126.70,0.250
18.78,126.85,0.250
18.79,127.00,0.249
18.81,127.15,0.249
18.83,127.30,0.249
18.84,127.45,0.249
18.86,127.60,0.249
18.87,127.75,0.249
18.88,127.90,0.249
18.90,128.05,0.249
18.92,128.20,0.249
18.93,128.35,0.249
18.94,128.50,0.249
18.96,128.65,0.249
18.98,128.80,0.249
18.99,128.95,0.249
19.01,129.10,0.249
19.02,129.25,0.249
19.03,129.40,0.249
19.05,129.55,0.249
19.07,129.70,0.249
19.08,129.85,0.249
19.09,130.00,0.249
19.11,130.15,0.249
19.13,130.30,0.249
19.14,130.45,0.249
19.16,130.60,0.249
19.17,130.75,0.249
19.18,130.90,0.249
19.20,131.05,0.248
19.22,131.20,0.248
19.23,131.35,0.248
19.24,131.50,0.248
19.26,131.65,0.248
19.28,131.80,0.248
19.29,131.95,0.248
19.31,132.10,0.248
19.32,132.25,0.248
19.33,132.40,0.248
19.35,132.55,0.248
19.37,132.70,0.248
19.38,132.85,0.248
19.39,133.00,0.248
19.41,133.15,0.248
19.43,133.30,0.248
19.44,133.45,0.248
19.46,133.60,0.248
19.47,133.75,0.248
19.48,133.90,0.248
19.50,134.05,0.248
19.52,134.20,0.248
19.53,134.35,0.248
19.54,134.50,0.247
19.56,134.65,0.247
19.58,134.80,0.247
19.59,134.95,0.247
19.61,135.10,0.247
19.62,135.26,0.247
19.63,135.40,0.247
19.65,135.55,0.247
19.67,135.71,0.247
19.68,135.86,0.247
19.69,136.01,0.247
19.71,136.16,0.247
19.73,136.30,0.246
19.74,136.45,0.246
19.76,136.60,0.246
19.77,136.75,0.246
19.78,136.90,0.246
19.80,137.06,0.246
19.82,137.20,0.246
19.83,137.35,0.246
19.84,137.51,0.246
19.86,137.66,0.246
19.88,137.80,0.245
19.89,137.95,0.245
19.91,138.10,0.245
19.92,138.26,0.245
19.93,138.41,0.245
19.95,138.56,0.245
19.97,138.71,0.245
19.98,138.86,0.245
19.99,139.01,0.245
20.01,139.16,0.245
20.03,139.31,0.245
20.04,139.46,0.245
20.06,139.61,0.245
20.07,139.76,0.245
20.08,139.91,0.245
20.10,140.06,0.245
20.12,140.21,0.245
20.13,140.36,0.245
20.14,140.51,0.245
20.16,140.66,0.245
20.18,140.81,0.244
20.19,140.96,0.244
20.21,141.11,0.244
20.22,141.26,0.244
20.23,141.41,0.244
20.25,141.56,0.244
20.27,141.71,0.244
20.28,141.86,0.244
20.29,142.01,0.243
20.31,142.16,0.243
20.33,142.31,0.243
20.34,142.46,0.243
20.36,142.61,0.243
20.37,142.76,0.243
20.38,142.91,0.243
20.40,143.06,0.243
20.42,143.21,0.242
20.43,143.36,0.242
20.44,143.51,0.242
20.46,143.66,0.242
20.48,143.81,0.242
20.49,143.96,0.242
20.51,144.11,0.242
20.52,144.26,0.242
20.53,144.41,0.242
20.55,144.56,0.241
20.57,144.71,0.241
20.58,144.86,0.241
20.59,145.01,0.241
20.61,145.16,0.241
20.63,145.31,0.241
20.64,145.46,0.241
20.66,145.61,0.241
20.67,145.76,0.241
20.68,145.91,0.240
20.70,146.06,0.240
20.72,146.21,0.240
20.73,146.36,0.240
20.74,146.51,0.240
20.76,146.66,0.240
20.78,146.81,0.240
20.79,146.96,0.240
20.81,147.11,0.240
20.82,147.26,0.239
20.83,147.41,0.239
20.85,147.56,0.239
20.87,147.71,0.239
20.88,147.86,0.239
20.89,148.01,0.239
20.91,148.16,0.239
20.93,148.31,0.239
20.94,148.46,0.238
20.96,148.61,0.238
20.97,148.76,0.238
20.98,148.91,0.238
21.00,149.06,0.238
21.02,149.21,0.238
21.03,149.36,0.238
21.04,149.51,0.238
21.06,149.66,0.237
21.08,149.81,0.237
21.09,149.96,0.237
21.11,150.11,0.237
21.12,150.26,0.237
21.13,150.41,0.237
21.15,150.56,0.237
21.17,150.71,0.237
21.18,150.86,0.236
21.19,151.01,0.236
21.21,151.16,0.236
21.23,151.31,0.236
21.24,151.46,0.236
21.26,151.62,0.236
21.27,151.76,0.236
21.28,151.92,0.236
21.30,152.06,0.236
21.32,152.22,0.235
21.33,152.37,0.235
21.34,152.52,0.235
21.36,152.67,0.235
21.38,152.82,0.235
21.39,152.97,0.235
21.41,153.12,0.235
21.42,153.27,0.234
21.43,153.42,0.234
21.45,153.57,0.234
21.47,153.72,0.234
21.48,153.87,0.234
21.49,154.02,0.234
21.51,154.17,0.234
21.53,154.32,0.235
21.54,154.47,0.235
21.56,154.62,0.238
21.57,154.77,0.238
21.58,154.92,0.238
21.60,155.07,0.238
21.62,155.22,0.238
21.63,155.37,0.237
21.64,155.52,0.237
21.66,155.67,0.237
21.68,155.82,0.236
21.69,155.97,0.236
21.71,156.12,0.235
21.72,156.27,0.235
21.73,156.42,0.235
21.75,156.57,0.234
21.77,156.72,0.234
21.78,156.87,0.234
21.79,157.02,0.233
21.81,157.17,0.233
21.83,157.32,0.233
21.84,157.47,0.233
21.86,157.62,0.232
21.87,157.77,0.232
21.88,157.92,0.232
21.90,158.07,0.232
21.92,158.22,0.231
21.93,158.37,0.231
21.94,158.52,
21.96,158.67,
21.98,158.82,
21.99,,
21.99,,

[step]
Ramp 10.00 °C/min to -60.00 °C
Time,Temperature,Heat Flow (Normalized)
min,°C,W/g
22.99,160.14,-0.163
23.01,160.14,-0.163
23.02,160.13,-0.163
23.04,160.13,-0.163
23.05,160.11,-0.169
23.07,160.08,-0.195
23.08,160.03,-0.227
23.10,159.96,-0.266
23.11,159.87,-0.302
23.13,159.77,-0.343
23.14,159.65,-0.379
23.16,159.52,-0.415
23.17,159.39,-0.446
23.19,159.25,-0.467
23.20,159.11,-0.487
23.22,158.97,-0.498
23.23,158.83,-0.510
23.25,158.68,-0.515
23.26,158.54,-0.521
23.28,158.39,-0.527
23.29,158.24,-0.529
23.31,158.10,-0.531
23.32,157.95,-0.532
23.34,157.80,-0.534
23.35,157.65,-0.536
23.37,157.51,-0.536
23.38,157.36,-0.537
23.40,157.21,-0.538
23.41,157.06,-0.538
23.43,156.91,-0.539
23.44,156.77,-0.539
23.46,156.62,-0.540
23.47,156.47,-0.540
23.49,156.32,-0.541
23.50,156.17,-0.541
23.52,156.02,-0.542
23.53,155.87,-0.542
23.55,155.73,-0.543
23.56,155.58,-0.543
23.58,155.43,-0.543
23.59,155.28,-0.544
23.61,155.13,-0.544
23.62,154.98,-0.544
23.64,154.83,-0.545
23.65,154.68,-0.545
23.67,154.53,-0.545
23.68,154.39,-0.546
23.70,154.24,-0.546
23.71,154.09,-0.546
23.73,153.94,-0.546
23.74,153.79,-0.546
23.76,153.64,-0.546
23.77,153.49,-0.547
23.79,153.34,-0.547
23.80,153.19,-0.547
23.82,153.04,-0.547
23.83,152.89,-0.547
23.85,152.74,-0.547
23.86,152.60,-0.547
23.88,152.45,-0.547
23.89,152.30,-0.547
23.91,152.15,-0.547
23.92,152.00,-0.547
23.94,151.85,-0.546
23.95,151.70,-0.546
23.97,151.55,-0.546
23.98,151.40,-0.546
24.00,151.25,-0.546
24.01,151.10,-0.546
24.03,150.95,-0.545
24.04,150.80,-0.545
24.06,150.65,-0.545
24.07,150.50,-0.544
24.09,150.35,-0.544
24.10,150.20,-0.544
24.12,150.06,-0.544
24.13,149.90,-0.543
24.15,149.76,-0.543
24.16,149.61,-0.543
24.18,149.46,-0.543
24.19,149.31,-0.542
24.21,149.16,-0.542
24.22,149.01,-0.542
24.24,148.86,-0.542
24.25,148.71,-0.542
24.27,148.56,-0.541
24.28,148.41,-0.541
24.30,148.26,-0.541
24.31,148.11,-0.541
24.33,147.96,-0.540
24.34,147.81,-0.540
24.36,147.66,-0.540
24.37,147.51,-0.539
24.39,147.36,-0.539
24.40,147.21,-0.539
24.42,147.06,-0.539
24.43,146.91,-0.538
24.45,146.76,-0.538
24.46,146.61,-0.538
24.48,146.46,-0.537
24.49,146.31,-0.537
24.51,146.16,-0.537
24.52,146.01,-0.536
24.54,145.86,-0.536
24.55,145.71,-0.536
24.57,145.56,-0.536
24.58,145.41,-0.535
24.60,145.26,-0.535
24.61,145.11,-0.535
24.63,144.96,-0.535
24.64,144.81,-0.534
24.66,144.66,-0.534
24.67,144.52,-0.534
24.69,144.37,-0.534
24.70,144.22,-0.533
24.72,144.07,-0.533
24.73,143.92,-0.533
24.75,143.77,-0.532
24.76,143.62,-0.532
24.78,143.47,-0.532
24.79,143.32,-0.532
24.81,143.17,-0.531
24.82,143.02,-0.531
24.84,142.86,-0.531
24.85,142.72,-0.531
24.87,142.57,-0.530
24.88,142.42,-0.530
24.90,142.27,-0.530
24.91,142.12,-0.530
24.93,141.97,-0.529
24.94,141.82,-0.529
24.96,141.67,-0.529
24.97,141.52,-0.528
24.99,141.36,-0.528
25.00,141.22,-0.528
25.02,141.07,-0.527
25.03,140.92,-0.527
25.05,140.77,-0.527
25.06,140.61,-0.527
25.08,140.46,-0.526
25.09,140.31,-0.526
25.11,140.16,-0.526
25.12,140.01,-0.525
25.14,139.86,-0.525
25.15,139.71,-0.525
25.17,139.56,-0.524
25.18,139.41,-0.524
25.20,139.26,-0.523
25.21,139.11,-0.523
25.23,138.97,-0.523
25.24,138.82,-0.522
25.26,138.67,-0.522
25.27,138.52,-0.522
25.29,138.37,-0.521
25.30,138.21,-0.521
25.32,138.07,-0.521
25.33,137.92,-0.520
25.35,137.77,-0.520
25.36,137.61,-0.520
25.38,137.47,-0.519
25.39,137.32,-0.519
25.41,137.17,-0.519
25.42,137.02,-0.518
25.44,136.87,-0.518
25.45,136.72,-0.518
25.47,136.57,-0.518
25.48,136.42,-0.517
25.50,136.27,-0.517
25.51,136.12,-0.517
25.53,135.97,-0.517
25.54,135.82,-0.516
25.56,135.67,-0.516
25.57,135.52,-0.516
25.59,135.37,-0.516
25.60,135.22,-0.515
25.62,135.07,-0.515
25.63,134.92,-0.515
25.65,134.77,-0.515
25.66,134.62,-0.514
25.68,134.47,-0.514
25.69,134.32,-0.514
25.71,134.17,-0.514
25.72,134.02,-0.514
25.74,133.87,-0.514
25.75,133.72,-0.513
25.77,133.57,-0.513
25.78,133.42,-0.513
25.80,133.27,-0.513
25.81,133.12,-0.512
25.83,132.97,-0.512
25.84,132.82,-0.512
25.86,132.67,-0.512
25.87,132.52,-0.512
25.89,132.37,-0.512
25.90,132.22,-0.511
25.92,132.07,-0.511
25.93,131.92,-0.511
25.95,131.77,-0.511
25.96,131.62,-0.511
25.98,131.47,-0.510
25.99,131.32,-0.510
26.01,131.17,-0.510
26.02,131.02,-0.510
26.04,130.87,-0.510
26.05,130.72,-0.510
26.07,130.57,-0.509
26.08,130.42,-0.509
26.10,130.27,-0.509
26.11,130.12,-0.509
26.13,129.97,-0.509
26.14,129.82,-0.509
26.16,129.67,-0.508
26.17,129.52,-0.508
26.19,129.37,-0.508
26.20,129.22,-0.508
26.22,129.07,-0.508
26.23,128.92,-0.508
26.25,128.77,-0.507
26.26,128.62,-0.507
26.28,128.47,-0.507
26.29,128.32,-0.507
26.31,128.17,-0.507
26.32,128.02,-0.507
26.34,127.87,-0.507
26.35,127.72,-0.506
26.37,127.57,-0.506
26.38,127.42,-0.506
26.40,127.27,-0.506
26.41,127.12,-0.506
26.43,126.97,-0.506
26.44,126.82,-0.505
26.46,126.67,-0.505
26.47,126.52,-0.505
26.49,126.37,-0.505
26.50,126.22,-0.505
26.52,126.07,-0.505
26.53,125.92,-0.504
26.55,125.77,-0.504
26.56,125.62,-0.504
26.58,125.47,-0.504
26.59,125.32,-0.504
26.61,125.17,-0.503
26.62,125.02,-0.503
26.64,124.87,-0.503
26.65,124.72,-0.503
26.67,124.57,-0.503
26.68,124.42,-0.503
26.70,124.27,-0.503
26.71,124.12,-0.502
26.73,123.97,-0.502
26.74,123.82,-0.502
26.76,123.67,-0.502
26.77,123.52,-0.502
26.79,123.37,-0.501
26.80,123.22,-0.501
26.82,123.07,-0.501
26.83,122.92,-0.501
26.85,122.77,-0.501
26.86,122.62,-0.500
26.88,122.47,-0.500
26.89,122.32,-0.500
26.91,122.17,-0.500
26.92,122.02,-0.500
26.94,121.87,-0.499
26.95,121.72,-0.499
26.97,121.57,-0.499
26.98,121.42,-0.499
27.00,121.27,-0.499
27.01,121.12,-0.499
27.03,120.97,-0.498
27.04,120.82,-0.498
27.06,120.67,-0.498
27.07,120.52,-0.498
27.09,120.37,-0.498
27.10,120.22,-0.498
27.12,120.07,-0.497
27.13,119.92,-0.497
27.15,119.77,-0.497
27.16,119.62,-0.497
27.18,119.47,-0.497
27.19,119.32,-0.496
27.21,119.17,-0.496
27.22,119.02,-0.496
27.24,118.87,-0.496
27.25,118.72,-0.496
27.27,118.57,-0.495
27.28,118.42,-0.495
27.30,118.27,-0.495
27.31,118.12,-0.495
27.33,117.97,-0.495
27.34,117.82,-0.494
27.36,117.67,-0.494
27.37,117.52,-0.494
27.39,117.37,-0.494
27.40,117.22,-0.494
27.42,117.07,-0.494
27.43,116.92,-0.493
27.45,116.77,-0.493
27.46,116.62,-0.493
27.48,116.47,-0.493
27.49,116.32,-0.493
27.51,116.17,-0.492
27.52,116.02,-0.492
27.54,115.87,-0.492
27.55,115.72,-0.492
27.57,115.57,-0.491
27.58,115.42,-0.491
27.60,115.27,-0.491
27.61,115.12,-0.491
27.63,114.97,-0.491
27.64,114.82,-0.490
27.66,114.67,-0.490
27.67,114.52,-0.490
27.69,114.37,-0.490
27.70,114.22,-0.489
27.72,114.07,-0.489
27.73,113.92,-0.489
27.75,113.77,-0.488
27.76,113.62,-0.488
27.78,113.47,-0.488
27.79,113.32,-0.488
27.81,113.17,-0.488
27.82,113.02,-0.487
27.84,112.87,-0.487
27.85,112.72,-0.487
27.87,112.57,-0.486
27.88,112.42,-0.486
27.90,112.27,-0.486
27.91,112.12,-0.485
27.93,111.97,-0.485
27.94,111.82,-0.485
27.96,111.67,-0.485
27.97,111.52,-0.484
27.99,111.37,-0.484
28.00,111.22,-0.484
28.02,111.07,-0.483
28.03,110.92,-0.483
28.05,110.77,-0.483
28.06,110.62,-0.482
28.08,110.47,-0.482
28.09,110.32,-0.482
28.11,110.17,-0.481
28.12,110.02,-0.481
28.14,109.87,-0.481
28.15,109.72,-0.480
28.17,109.57,-0.480
28.18,109.42,-0.480
28.20,109.27,-0.479
28.21,109.12,-0.479
28.23,108.97,-0.479
28.24,108.82,-0.478
28.26,108.67,-0.478
28.27,108.52,-0.478
28.29,108.37,-0.477
28.30,108.22,-0.477
28.32,108.07,-0.477
28.33,107.92,-0.476
28.35,107.77,-0.476
28.36,107.62,-0.475
28.38,107.47,-0.475
28.39,107.33,-0.475
28.41,107.17,-0.474
28.42,107.02,-0.474
28.44,106.87,-0.474
28.45,106.72,-0.473
28.47,106.58,-0.473
28.48,106.43,-0.473
28.50,106.27,-0.472
[...]
98.40,2.88,0.166
98.41,3.03,0.166
98.43,3.19,0.166
98.44,3.34,0.166
98.46,3.49,0.166
98.47,3.64,0.166
98.49,3.79,0.167
98.50,3.94,0.167
98.52,4.09,0.167
98.53,4.24,0.166
98.55,4.39,0.167
98.56,4.54,0.167
98.58,4.69,0.166
98.59,4.84,0.167
98.61,4.99,0.167
98.62,5.14,0.167
98.64,5.29,0.167
98.65,5.44,0.167
98.67,5.59,0.167
98.68,5.74,0.167
98.70,5.89,0.167
98.71,6.04,0.167
98.73,6.19,0.167
98.74,6.34,0.167
98.76,6.49,0.167
98.77,6.64,0.167
98.79,6.79,0.167
98.80,6.94,0.167
98.82,7.09,0.167
98.83,7.24,0.167
98.85,7.39,0.167
98.86,7.54,0.167
98.88,7.69,0.167
98.89,7.84,0.168
98.91,7.99,0.168
98.92,8.14,0.168
98.94,8.29,0.168
98.95,8.44,0.168
98.97,8.59,0.168
98.98,8.74,0.168
99.00,8.89,0.168
99.01,9.04,0.168
99.03,9.19,0.168
99.04,9.34,0.168
99.06,9.49,0.168
99.07,9.64,0.168
99.09,9.79,0.169
99.10,9.94,0.169
99.12,10.09,0.169
99.13,10.24,0.169
99.15,10.39,0.169
99.16,10.54,0.169
99.18,10.69,0.169
99.19,10.84,0.169
99.21,10.99,0.170
99.22,11.14,0.170
99.24,11.29,0.170
99.25,11.44,0.170
99.27,11.59,0.170
99.28,11.74,0.170
99.30,11.89,0.170
99.31,12.04,0.170
99.33,12.19,0.170
99.34,12.34,0.170
99.36,12.49,0.170
99.37,12.64,0.171
99.39,12.79,0.171
99.40,12.94,0.171
99.42,13.10,0.171
99.43,13.24,0.171
99.45,13.39,0.171
99.46,13.54,0.171
99.48,13.69,0.171
99.49,13.84,0.171
99.51,13.99,0.171
99.52,14.15,0.171
99.54,14.29,0.171
99.55,14.45,0.172
99.57,14.60,0.172
99.58,14.75,0.172
99.60,14.90,0.172
99.61,15.05,0.172
99.63,15.20,0.172
99.64,15.35,0.172
99.66,15.50,0.172
99.67,15.65,0.172
99.69,15.80,0.172
99.70,15.95,0.172
99.72,16.10,0.173
99.73,16.25,0.173
99.75,16.40,0.173
99.76,16.55,0.173
99.78,16.70,0.173
99.79,16.85,0.173
99.81,17.00,0.173
99.82,17.15,0.173
99.84,17.30,0.173
99.85,17.45,0.173
99.87,17.60,0.173
99.88,17.75,0.173
99.90,17.90,0.173
99.91,18.05,0.173
99.93,18.20,0.173
99.94,18.35,0.173
99.96,18.50,0.173
99.97,18.65,0.173
99.99,18.80,0.173
100.00,18.95,0.173
100.02,19.10,0.173
100.03,19.25,0.174
100.05,19.40,0.174
100.06,19.55,0.174
100.08,19.70,0.174
100.09,19.85,0.174
100.11,20.00,0.174
100.12,20.15,0.174
100.14,20.30,0.174
100.15,20.45,0.174
100.17,20.60,0.174
100.18,20.75,0.174
100.20,20.90,0.174
100.21,21.05,0.174
100.23,21.20,0.174
100.24,21.35,0.174
100.26,21.50,0.174
100.27,21.65,0.175
100.29,21.80,0.175
100.30,21.95,0.175
100.32,22.10,0.175
100.33,22.25,0.175
100.35,22.40,0.175
100.36,22.56,0.175
100.38,22.70,0.175
100.39,22.86,0.175
100.41,23.01,0.175
100.42,23.16,0.175
100.44,23.31,0.175
100.45,23.46,0.175
100.47,23.61,0.175
100.48,23.76,0.175
100.50,23.90,0.175
100.51,24.06,0.175
100.53,24.20,0.175
100.54,24.36,0.175
100.56,24.51,0.176
100.57,24.66,0.176
100.59,24.81,0.176
100.60,24.96,0.176
100.62,25.11,0.176
100.63,25.26,0.176
100.65,25.41,0.176
100.66,25.56,0.176
100.68,25.71,0.176
100.69,25.86,0.176
100.71,26.01,0.176
100.72,26.16,0.176
100.74,26.31,0.177
100.75,26.46,0.177
100.77,26.61,0.177
100.78,26.76,0.177
100.80,26.91,0.177
100.81,27.06,0.177
100.83,27.21,0.177
100.84,27.36,0.177
100.86,27.51,0.177
100.87,27.66,0.177
100.89,27.81,0.177
100.90,27.96,0.177
100.92,28.11,0.177
100.93,28.26,0.177
100.95,28.41,0.177
100.96,28.56,0.177
100.98,28.71,0.177
100.99,28.86,0.177
101.01,29.01,0.178
101.02,29.16,0.178
101.04,29.31,0.178
101.05,29.46,0.178
101.07,29.61,0.178
101.08,29.76,0.178
101.10,29.91,0.178
101.11,30.06,0.178
101.13,30.21,0.178
101.14,30.36,0.179
101.16,30.51,0.179
101.17,30.66,0.179
101.19,30.81,0.179
101.20,30.96,0.179
101.22,31.11,0.179
101.23,31.26,0.179
101.25,31.41,0.179
101.26,31.56,0.179
101.28,31.71,0.179
101.29,31.86,0.179
101.31,32.01,0.180
101.32,32.16,0.180
101.34,32.31,0.180
101.35,32.46,0.180
101.37,32.61,0.180
101.38,32.76,0.180
101.40,32.91,0.180
101.41,33.06,0.180
101.43,33.21,0.180
101.44,33.36,0.180
101.46,33.51,0.180
101.47,33.66,0.180
101.49,33.81,0.180
101.50,33.97,0.180
101.52,34.11,0.180
101.53,34.26,0.181
101.55,34.41,0.181
101.56,34.56,0.181
101.58,34.71,0.181
101.59,34.87,0.181
101.61,35.01,0.181
101.62,35.17,0.181
101.64,35.32,0.181
101.65,35.46,0.181
101.67,35.61,0.181
101.68,35.76,0.181
101.70,35.92,0.181
101.71,36.06,0.182
101.73,36.22,0.181
101.74,36.37,0.182
101.76,36.52,0.182
101.77,36.67,0.182
101.79,36.82,0.182
101.80,36.97,0.182
101.82,37.12,0.182
101.83,37.27,0.182
101.85,37.42,0.182
101.86,37.57,0.182
101.88,37.72,0.182
101.89,37.87,0.182
101.91,38.02,0.182
101.92,38.17,0.182
101.94,38.32,0.182
101.95,38.47,0.182
101.97,38.62,0.183
101.98,38.77,0.183
102.00,38.92,0.183
102.01,39.07,0.183
102.03,39.22,0.183
102.04,39.37,0.183
102.06,39.52,0.183
102.07,39.67,0.183
102.09,39.82,0.183
102.10,39.97,0.183
102.12,40.12,0.183
102.13,40.27,0.184
102.15,40.42,0.184
102.16,40.57,0.184
102.18,40.72,0.184
102.19,40.87,0.184
102.21,41.02,0.184
102.22,41.17,0.184
102.24,41.32,0.184
102.25,41.47,0.184
102.27,41.62,0.184
102.28,41.77,0.184
102.30,41.92,0.184
102.31,42.07,0.184
102.33,42.22,0.184
102.34,42.37,0.185
102.36,42.52,0.185
102.37,42.67,0.185
102.39,42.82,0.185
102.40,42.97,0.185
102.42,43.12,0.185
102.43,43.27,0.185
102.45,43.42,0.185
102.46,43.57,0.185
102.48,43.72,0.185
102.49,43.87,0.185
102.51,44.02,0.185
102.52,44.17,0.185
102.54,44.32,0.185
102.55,44.47,0.185
102.57,44.62,0.185
102.58,44.77,0.186
102.60,44.92,0.186
102.61,45.07,0.186
102.63,45.22,0.186
102.64,45.37,0.186
102.66,45.52,0.186
102.67,45.67,0.186
102.69,45.83,0.186
102.70,45.97,0.186
102.72,46.12,0.186
102.73,46.28,0.186
102.75,46.43,0.186
102.76,46.58,0.186
102.78,46.73,0.186
102.79,46.88,0.186
102.81,47.03,0.186
102.82,47.18,0.187
102.84,47.33,0.187
102.85,47.48,0.187
102.87,47.63,0.187
102.88,47.78,0.187
102.90,47.93,0.187
102.91,48.08,0.187
102.93,48.23,0.187
102.94,48.38,0.187
102.96,48.53,0.187
102.97,48.68,0.187
102.99,48.83,0.187
103.00,48.98,0.187
103.02,49.13,0.188
103.03,49.28,0.187
103.05,49.43,0.188
103.06,49.58,0.188
103.08,49.73,0.188
103.09,49.88,0.188
103.11,50.03,0.188
103.12,50.18,0.188
103.14,50.33,0.188
103.15,50.48,0.188
103.17,50.63,0.188
103.18,50.78,0.188
103.20,50.93,0.188
103.21,51.08,0.189
103.23,51.23,0.188
103.24,51.38,0.189
103.26,51.53,0.189
103.27,51.68,0.189
103.29,51.83,0.189
103.30,51.98,0.189
103.32,52.13,0.189
103.33,52.28,0.189
103.35,52.43,0.189
103.36,52.58,0.189
103.38,52.73,0.189
103.39,52.88,0.189
103.41,53.03,0.189
103.42,53.18,0.189
103.44,53.33,0.189
103.45,53.48,0.189
103.47,53.63,0.189
103.48,53.78,0.189
103.50,53.93,0.190
103.51,54.08,0.190
103.53,54.23,0.190
103.54,54.38,0.190
103.56,54.53,0.190
103.57,54.68,0.190
103.59,54.83,0.190
103.60,54.98,0.190
103.62,55.13,0.190
103.63,55.28,0.190
103.65,55.43,0.190
103.66,55.58,0.190
103.68,55.73,0.190
103.69,55.88,0.190
103.71,56.03,0.190
103.72,56.18,0.190
103.74,56.33,0.191
103.75,56.48,0.190
103.77,56.63,0.191
103.78,56.78,0.191
103.80,56.93,0.191
103.81,57.08,0.191
103.83,57.23,0.191
103.84,57.38,0.191
103.86,57.53,0.191
103.87,57.69,0.191
103.89,57.84,0.191
103.90,57.99,0.191
103.92,58.14,0.192
103.93,58.29,0.192
103.95,58.44,0.192
103.96,58.59,0.192
103.98,58.74,0.192
103.99,58.89,0.192
104.01,59.04,0.192
104.02,59.19,0.192
104.04,59.34,0.192
104.05,59.49,0.192
104.07,59.64,0.192
104.08,59.79,0.192
104.10,59.94,0.192
104.11,60.09,0.192
104.13,60.24,0.192
104.14,60.39,0.193
104.16,60.54,0.193
104.17,60.69,0.193
104.19,60.84,0.193
104.20,60.99,0.193
104.22,61.14,0.193
104.23,61.29,0.193
104.25,61.44,0.193
104.26,61.59,0.193
104.28,61.74,0.193
104.29,61.89,0.193
104.31,62.04,0.193
104.32,62.19,0.193
104.34,62.34,0.193
104.35,62.49,0.193
104.37,62.64,0.193
104.38,62.79,0.193
104.40,62.94,0.193
104.41,63.09,0.193
104.43,63.24,0.194
104.44,63.39,0.194
104.46,63.54,0.194
104.47,63.69,0.194
104.49,63.84,0.194
104.50,63.99,0.194
104.52,64.14,0.194
104.53,64.29,0.194
104.55,64.44,0.194
104.56,64.59,0.194
104.58,64.74,0.194
104.59,64.89,0.194
104.61,65.04,0.195
104.62,65.19,0.195
104.64,65.34,0.195
104.65,65.49,0.195
104.67,65.64,0.195
104.68,65.79,0.195
104.70,65.94,0.195
104.71,66.09,0.195
104.73,66.24,0.195
104.74,66.39,0.195
104.76,66.54,0.195
104.77,66.69,0.195
104.79,66.84,0.195
104.80,66.99,0.196
104.82,67.14,0.196
104.83,67.29,0.196
104.85,67.44,0.196
104.86,67.59,0.196
104.88,67.74,0.196
104.89,67.89,0.196
104.91,68.05,0.196
104.92,68.19,0.196
104.94,68.34,0.196
104.95,68.49,0.196
104.97,68.64,0.196
104.98,68.79,0.196
105.00,68.94,0.196
105.01,69.09,0.196
105.03,69.24,0.196
105.04,69.40,0.197
105.06,69.54,0.197
105.07,69.70,0.197
105.09,69.85,0.197
105.10,70.00,0.197
105.12,70.15,0.197
105.13,70.29,0.197
105.15,70.45,0.197
105.16,70.60,0.197
105.18,70.75,0.197
105.19,70.90,0.198
105.21,71.05,0.198
105.22,71.20,0.198
105.24,71.35,0.198
105.25,71.50,0.198
105.27,71.65,0.198
105.28,71.80,0.198
105.30,71.95,0.198
105.31,72.10,0.198
105.33,72.25,0.198
105.34,72.40,0.198
105.36,72.55,0.198
105.37,72.70,0.198
105.39,72.85,0.198
105.40,73.00,0.198
105.42,73.15,0.199
105.43,73.30,0.199
105.45,73.45,0.199
105.46,73.60,0.199
105.48,73.75,0.199
105.49,73.90,0.199
105.51,74.05,0.199
105.52,74.20,0.199
105.54,74.35,0.199
105.55,74.50,0.199
105.57,74.65,0.199
105.58,74.80,0.199
105.60,74.95,0.200
105.61,75.10,0.200
105.63,75.25,0.200
105.64,75.40,0.200
105.66,75.55,0.200
105.67,75.70,0.200
105.69,75.85,0.200
105.70,76.00,0.200
105.72,76.15,0.200
105.73,76.30,0.200
105.75,76.45,0.200
105.76,76.60,0.201
105.78,76.75,0.201
105.79,76.90,0.201
105.81,77.05,0.201
105.82,77.20,0.201
105.84,77.35,0.201
105.85,77.50,0.201
105.87,77.65,0.201
105.88,77.80,0.201
105.90,77.95,0.201
105.91,78.10,0.201
105.93,78.25,0.201
105.94,78.40,0.202
105.96,78.55,0.202
105.97,78.70,0.202
105.99,78.85,0.202
106.00,79.00,0.202
106.02,79.15,0.202
106.03,79.30,0.202
106.05,79.45,0.202
106.06,79.60,0.202
106.08,79.75,0.202
106.09,79.90,0.202
106.11,80.05,0.202
106.12,80.20,0.203
106.14,80.35,0.203
106.15,80.50,0.203
106.17,80.65,0.203
106.18,80.80,0.203
106.20,80.95,0.203
106.21,81.10,0.203
106.23,81.25,0.203
106.24,81.40,0.203
106.26,81.55,0.203
106.27,81.70,0.203
106.29,81.85,0.204
106.30,82.00,0.204
106.32,82.15,0.204
106.33,82.30,0.204
106.35,82.45,0.204
106.36,82.61,0.204
106.38,82.75,0.204
106.39,82.90,0.204
106.41,83.06,0.204
106.42,83.21,0.204
106.44,83.36,0.205
106.45,83.50,0.205
106.47,83.66,0.205
106.48,83.80,0.205
106.50,83.96,0.205
106.51,84.11,0.205
106.53,84.26,0.205
106.54,84.41,0.205
106.56,84.56,0.205
106.57,84.71,0.205
106.59,84.86,0.205
106.60,85.01,0.206
106.62,85.16,0.206
106.63,85.31,0.206
106.65,85.46,0.206
106.66,85.61,0.206
106.68,85.76,0.206
106.69,85.91,0.206
106.71,86.06,0.206
106.72,86.21,0.206
106.74,86.36,0.206
106.75,86.51,0.207
106.77,86.66,0.207
106.78,86.81,0.207
106.80,86.96,0.207
106.81,87.11,0.207
106.83,87.26,0.207
106.84,87.41,0.207
106.86,87.56,0.208
106.87,87.71,0.208
106.89,87.86,0.208
106.90,88.01,0.208
106.92,88.16,0.208
106.93,88.31,0.208
106.95,88.46,0.208
106.96,88.61,0.209
106.98,88.76,0.209
106.99,88.91,0.209
107.01,89.06,0.209
107.02,89.21,0.209
107.04,89.36,0.209
107.05,89.51,0.209
107.07,89.66,0.209
107.08,89.81,0.210
107.10,89.96,0.210
107.11,90.11,0.210
107.13,90.26,0.210
107.14,90.41,0.210
107.16,90.56,0.210
107.17,90.71,0.210
107.19,90.86,0.211
107.20,91.01,0.211
107.22,91.16,0.211
107.23,91.31,0.211
107.25,91.46,0.211
107.26,91.61,0.212
107.28,91.76,0.212
107.29,91.91,0.212
107.31,92.06,0.212
107.32,92.21,0.212
107.34,92.36,0.212
107.35,92.51,0.212
107.37,92.66,0.213
107.38,92.81,0.213
107.40,92.96,0.213
107.41,93.11,0.213
107.43,93.26,0.214
107.44,93.41,0.214
107.46,93.56,0.214
107.47,93.71,0.214
107.49,93.86,0.214
107.50,94.01,0.215
107.52,94.16,0.215
107.53,94.31,0.215
107.55,94.46,0.215
107.56,94.61,0.215
107.58,94.76,0.216
107.59,94.91,0.216
107.61,95.06,0.216
107.62,95.21,0.216
107.64,95.36,0.216
107.65,95.51,0.217
107.67,95.66,0.217
107.68,95.81,0.217
107.70,95.96,0.217
107.71,96.11,0.218
107.73,96.26,0.218
107.74,96.41,0.218
107.76,96.56,0.218
107.77,96.71,0.219
107.79,96.86,0.219
107.80,97.01,0.219
107.82,97.16,0.219
107.83,97.31,0.220
107.85,97.46,0.220
107.86,97.61,0.220
107.88,97.76,0.220
107.89,97.92,0.221
107.91,98.07,0.221
107.92,98.22,0.221
107.94,98.36,0.222
107.95,98.52,0.222
107.97,98.67,0.222
107.98,98.82,0.222
108.00,98.97,0.223
108.01,99.12,0.223
108.03,99.27,0.223
108.04,99.42,0.224
108.06,99.57,0.224
108.07,99.72,0.224
108.09,99.87,0.224
108.10,100.02,0.225
108.12,100.17,0.225
108.13,100.32,0.225
108.15,100.47,0.226
108.16,100.62,0.226
108.18,100.77,0.226
108.19,100.92,0.227
108.21,101.07,0.227
108.22,101.22,0.227
108.24,101.37,0.228
108.25,101.52,0.228
108.27,101.67,0.228
108.28,101.82,0.229
108.30,101.97,0.229
108.31,102.12,0.229
108.33,102.27,0.230
108.34,102.42,0.230
108.36,102.57,0.230
108.37,102.72,0.231
108.39,102.87,0.231
108.40,103.02,0.232
108.42,103.17,0.232
108.43,103.32,0.232
108.45,103.47,0.233
108.46,103.62,0.233
108.48,103.77,0.234
108.49,103.92,0.234
108.51,104.07,0.234
108.52,104.22,0.235
108.54,104.37,0.235
108.55,104.52,0.236
108.57,104.67,0.236
108.58,104.82,0.236
108.60,104.97,0.237
108.61,105.12,0.237
108.63,105.27,0.238
108.64,105.42,0.238
108.66,105.57,0.239
108.67,105.72,0.239
108.69,105.87,0.240
108.70,106.02,0.240
108.72,106.17,0.240
108.73,106.32,0.241
108.75,106.47,0.241
108.76,106.62,0.242
108.78,106.77,0.242
108.79,106.92,0.243
108.81,107.07,0.243
108.82,107.22,0.244
108.84,107.37,0.245
108.85,107.52,0.245
108.87,107.67,0.246
108.88,107.82,0.246
108.90,107.97,0.247
108.91,108.12,0.247
108.93,108.27,0.248
108.94,108.42,0.248
108.96,108.57,0.249
108.97,108.72,0.249
108.99,108.87,0.250
109.00,109.02,0.250
109.02,109.17,0.251
109.03,109.32,0.251
109.05,109.47,0.252
109.06,109.62,0.252
109.08,109.77,0.253
109.09,109.92,0.253
109.11,110.07,0.254
109.12,110.22,0.254
109.14,110.37,0.255
109.15,110.52,0.255
109.17,110.67,0.256
109.18,110.82,0.256
109.20,110.97,0.257
109.21,111.12,0.257
109.23,111.27,0.258
109.24,111.42,0.258
109.26,111.57,0.259
109.27,111.72,0.259
109.29,111.87,0.260
109.30,112.02,0.261
109.32,112.17,0.261
109.33,112.32,0.261
109.35,112.48,0.262
109.36,112.63,0.262
109.38,112.78,0.263
109.39,112.93,0.263
109.41,113.08,0.264
109.42,113.23,0.264
109.44,113.38,0.264
109.45,113.53,0.265
109.47,113.68,0.265
109.48,113.83,0.265
109.50,113.98,0.266
109.51,114.13,0.266
109.53,114.28,0.266
109.54,114.43,0.266
109.56,114.58,0.267
109.57,114.73,0.267
109.59,114.88,0.267
109.60,115.03,0.267
109.62,115.18,0.268
109.63,115.33,0.268
109.65,115.48,0.268
109.66,115.63,0.268
109.68,115.78,0.268
109.69,115.93,0.269
109.71,116.08,0.269
109.72,116.23,0.269
109.74,116.38,0.269
109.75,116.53,0.269
109.77,116.68,0.270
109.78,116.82,0.270
109.80,116.98,0.270
109.81,117.13,0.270
109.83,117.28,0.270
109.84,117.43,0.270
109.86,117.58,0.271
109.87,117.73,0.271
109.89,117.88,0.271
109.90,118.03,0.271
109.92,118.18,0.271
109.93,118.33,0.272
109.95,118.48,0.272
109.96,118.63,0.272
109.98,118.78,0.272
109.99,118.93,0.272
110.01,119.08,0.272
110.02,119.23,0.272
110.04,119.38,0.272
110.05,119.53,0.272
110.07,119.68,0.272
110.08,119.83,0.272
110.10,119.98,0.273
110.11,120.13,0.273
110.13,120.28,0.273
110.14,120.43,0.273
110.16,120.58,0.273
110.17,120.73,0.273
110.19,120.88,0.273
110.20,121.03,0.273
110.22,121.18,0.273
110.23,121.33,0.273
110.25,121.48,0.273
110.26,121.63,0.274
110.28,121.78,0.274
110.29,121.93,0.274
110.31,122.08,0.274
110.32,122.23,0.274
110.34,122.38,0.274
110.35,122.53,0.274
110.37,122.68,0.274
110.38,122.83,0.274
110.40,122.98,0.274
110.41,123.13,0.274
110.43,123.28,0.274
110.44,123.43,0.274
110.46,123.58,0.274
110.47,123.73,0.274
110.49,123.88,0.274
110.50,124.03,0.274
110.52,124.18,0.274
110.53,124.33,0.274
110.55,124.48,0.274
110.56,124.63,0.274
110.58,124.78,0.275
110.59,124.93,0.275
110.61,125.08,0.275
110.62,125.23,0.275
110.64,125.38,0.275
110.65,125.53,0.275
110.67,125.68,0.275
110.68,125.83,0.275
110.70,125.98,0.275
110.71,126.13,0.275
110.73,126.28,0.275
110.74,126.43,0.275
110.76,126.58,0.275
110.77,126.73,0.275
110.79,126.88,0.275
110.80,127.03,0.275
110.82,127.18,0.276
110.83,127.33,0.276
110.85,127.48,0.276
110.86,127.63,0.276
110.88,127.78,0.276
110.89,127.93,0.276
110.91,128.08,0.276
110.92,128.23,0.276
110.94,128.38,0.276
110.95,128.53,0.276
110.97,128.68,0.276
110.98,128.83,0.277
111.00,128.98,0.277
111.01,129.13,0.277
111.03,129.28,0.277
111.04,129.43,0.277
111.06,129.58,0.277
111.07,129.73,0.277
111.09,129.88,0.277
111.10,130.03,0.277
111.12,130.18,0.277
111.13,130.33,0.277
111.15,130.48,0.277
111.16,130.63,0.277
111.18,130.78,0.278
111.19,130.93,0.278
111.21,131.08,0.278
111.22,131.23,0.278
111.24,131.38,0.278
111.25,131.53,0.278
111.27,131.68,0.278
111.28,131.83,0.278
111.30,131.99,0.278
111.31,132.14,0.278
111.33,132.29,0.278
111.34,132.44,0.278
111.36,132.58,0.278
111.37,132.74,0.278
111.39,132.88,0.278
111.40,133.04,0.278
111.42,133.19,0.278
111.43,133.34,0.279
111.45,133.48,0.279
111.46,133.64,0.279
111.48,133.79,0.279
111.49,133.94,0.279
111.51,134.09,0.279
111.52,134.24,0.279
111.54,134.39,0.279
111.55,134.54,0.279
111.57,134.69,0.279
111.58,134.84,0.279
111.60,134.99,0.279
111.61,135.14,0.279
111.63,135.29,0.279
111.64,135.44,0.279
111.66,135.59,0.280
111.67,135.74,0.280
111.69,135.89,0.280
111.70,136.04,0.280
111.72,136.19,0.280
111.73,136.34,0.280
111.75,136.49,0.280
111.76,136.64,0.280
111.78,136.79,0.280
111.79,136.94,0.280
111.81,137.09,0.280
111.82,137.24,0.280
111.84,137.39,0.280
111.85,137.54,0.281
111.87,137.69,0.281
111.88,137.84,0.281
111.90,137.99,0.281
111.91,138.14,0.281
111.93,138.29,0.281
111.94,138.44,0.281
111.96,138.59,0.281
111.97,138.74,0.281
111.99,138.89,0.281
112.00,139.04,0.281
112.02,139.19,0.281
112.03,139.34,0.282
112.05,139.49,0.282
112.06,139.64,0.282
112.08,139.79,0.282
112.09,139.94,0.282
112.11,140.09,0.282
112.12,140.24,0.282
112.14,140.39,0.282
112.15,140.54,0.282
112.17,140.69,0.282
112.18,140.84,0.282
112.20,140.99,0.282
112.21,141.14,0.282
112.23,141.29,0.283
112.24,141.44,0.282
112.26,141.59,0.283
112.27,141.74,0.283
112.29,141.89,0.283
112.30,142.04,0.283
112.32,142.19,0.283
112.33,142.34,0.283
112.35,142.49,0.283
112.36,142.64,0.283
112.38,142.79,0.283
112.39,142.94,0.283
112.41,143.09,0.283
112.42,143.24,0.284
112.44,143.39,0.284
112.45,143.54,0.284
112.47,143.69,0.284
112.48,143.84,0.284
112.50,143.99,0.284
112.51,144.14,0.284
112.53,144.29,0.284
112.54,144.44,0.284
112.56,144.59,0.284
112.57,144.74,0.284
112.59,144.89,0.284
112.60,145.04,0.284
112.62,145.19,0.284
112.63,145.34,0.285
112.65,145.49,0.285
112.66,145.64,0.285
112.68,145.79,0.285
112.69,145.94,0.285
112.71,146.09,0.285
112.72,146.24,0.285
112.74,146.39,0.285
112.75,146.54,0.286
112.77,146.69,0.286
112.78,146.84,0.286
112.80,146.99,0.286
112.81,147.14,0.286
112.83,147.29,0.286
112.84,147.44,0.286
112.86,147.59,0.286
112.87,147.74,0.287
112.89,147.89,0.287
112.90,148.04,0.287
112.92,148.19,0.287
112.93,148.34,0.287
112.95,148.49,0.287
112.96,148.64,0.288
112.98,148.79,0.288
112.99,148.94,0.288
113.01,149.09,0.288
113.02,149.24,0.288
113.04,149.40,0.288
113.05,149.54,0.288
113.07,149.69,0.288
113.08,149.84,0.288
113.10,149.99,0.288
113.11,150.14,0.289
113.13,150.30,0.289
113.14,150.44,0.289
113.16,150.59,0.289
113.17,150.74,0.289
113.19,150.89,0.289
113.20,151.04,0.289
113.22,151.20,0.289
113.23,151.35,0.289
113.25,151.50,0.289
113.26,151.65,0.289
113.28,151.80,0.289
113.29,151.95,0.290
113.31,152.10,0.290
113.32,152.25,0.290
113.34,152.40,0.290
113.35,152.55,0.290
113.37,152.70,0.290
113.38,152.85,0.290
113.40,153.00,0.290
113.41,153.15,0.290
113.43,153.30,0.290
113.44,153.45,0.290
113.46,153.60,0.291
113.47,153.75,0.291
113.49,153.90,0.291
113.50,154.05,0.291
113.52,154.20,0.291
113.53,154.35,0.291
113.55,154.50,0.291
113.56,154.65,0.291
113.58,154.80,0.291
113.59,154.95,0.291
113.61,155.10,0.291
113.62,155.25,0.291
113.64,155.40,0.292
113.65,155.55,0.292
113.67,155.70,0.292
113.68,155.85,0.292
113.70,156.00,0.292
113.71,156.15,0.292
113.73,156.30,0.292
113.74,156.45,0.292
113.76,156.60,0.292
113.77,156.75,0.292
113.79,156.90,0.292
113.80,157.05,0.292
113.82,157.20,0.293
113.83,157.35,0.293
113.85,157.50,0.293
113.86,157.65,0.293
113.88,157.80,0.293
113.89,157.95,0.293
113.91,158.10,0.293
113.92,158.25,0.293
113.94,158.40,
113.95,158.55,
113.97,158.70,
113.98,158.85,
113.99,,