File: DSC/2025_04_19_Empty_Pans_n60C_150C_5Cmin_x3.csv
Filename,2025_04_19_Empty_Pans_n60C_150C_5Cmin_x3
Instrument name,DSC2A-00468 (192.168.1.100)
Operator,Yarger
rundate,4/19/2025
Sample name,2025_04_19_Empty_Pans_n60C_150C_5Cmin_x3
proceduresegments,Data Off ; Equilibrate -60.00 °C; Data On ; Ramp 5.00 °C/min to 150.00 °C; Data Off ; Isothermal 0.1 min; Data On ; Ramp 10.00 °C/min to -60.00 °C; Data Off ; Isothermal 1.0 min; Data On ; Ramp 5.00 °C/min to 150.00 °C; Data Off ; Isothermal 0.1 min; Data On ; Ramp 10.00 °C/min to -60.00 °C; Data Off ; Isothermal 1.0 min; Data On ; Ramp 5.00 °C/min to 30.00 °C
[File Parameters]
Run date,4/19/2025 2:51:57 PM
Trios version,5.1.1.46572
Original File Name,
Current File Name,D:\DSC2500\JYarger\2025_04_19_Empty_Pans_n60C_150C_5Cmin_x3.tri
[Procedure]
Procedure Name,Empty_Pans_n60_150C_5Cmin_x3
Sample Name,2025_04_19_Empty_Pans_n60C_150C_5Cmin_x3
Sample Mass,0 mg
Reference Sample Mass,0 mg
Pan Mass,54.56 mg
Pan Number,24
Reference Pan Mass,53.66 mg
Reference Pan Number,46
Pan Type,Tzero Aluminum Hermetic
Comments,Hermetic Sealed Al DSC Consumables Pan/Lids.
Project Name,CA
Operator,Yarger
Test,Custom
Unload Max Temperature,30
Unload Min Temperature,30
Load Max Temperature,30
Load Min Temperature,30
Stop on Gas Flow Error,Yes
[Signal List]
Signal #1,Time (min)
Signal #2,Temperature (°C)
Signal #3,Heat Flow (mW)
Signal #4,Delta T (µV)
Signal #5,Delta Tzero (µV)
Signal #6,Tzero Temperature (°C)
Signal #7,Cell Purge (mL/min)
Signal #8,Heater Temp (°C)
Signal #9,Power Delivered (W)
Signal #10,Reference Junction Temperature (°C)
Signal #11,Flange Temperature (°C)
Signal #12,Heat Flow Phase (rad)
Signal #13,Total Heat Capacity (J/°C)
Signal #14,Heat Capacity (J/°C)
[Configuration]
Company Name,ASU
Instrument Name,DSC2A-00468
Instrument Type,DSC2500
Serial Number,DSC2A-00468
IP,192.168.1.100
Location of Instrument,MRRC
DisplayType,Unknown
Sample Interval ,0.1 s/pt
Selected Heat Flow,T4P
Exotherm Direction,Down
Cell Serial,DRC2-00792
Lid Type,Standard
Cooler,RCS 90
Leave Cooler on at End of Sequence,On
Gas 2,Nitrogen
Gas Selected,Channel 1
Flow Rate,50 mL/min
Secondary Purge,On
Licensed Heat Flow,Heat Flow T4P
Modulation Licensed,Yes
[Versions]
Common IDD Version,1
Cortex Version,VER 2.10.2.31
Driver,5.0.0.6
GDM Version,1.0.3.3
TouchscreenVersion,1.0.0.16145
FEP Version,1.2.1.21
FEP Bootloader,2.0.0.5
AutoSampler Version,2.1.1.26
Auto Sampler Bootloader,2.0.0.5
FCM Version,1.1.0.3
FCM Bootloader,2.0.0.5
[Experiment Logs]
Experiment Log Entry # 1,Data On set to 0
Experiment Log Entry # 3,Equilibrate Segment -60 (C) Started
Experiment Log Entry # 5,Air Cool is off.
Experiment Log Entry # 7,Data On set to 1
Experiment Log Entry # 9,Ramp Segment 5 C/min to 150 Started
Experiment Log Entry # 11,Data On set to 0
Experiment Log Entry # 13,Isothermal Segment 0.1 min started
Experiment Log Entry # 15,Data On set to 1
Experiment Log Entry # 17,Ramp Segment 10 C/min to -60 Started
Experiment Log Entry # 19,Data On set to 0
Experiment Log Entry # 21,Isothermal Segment 1 min started
Experiment Log Entry # 23,Data On set to 1
Experiment Log Entry # 25,Ramp Segment 5 C/min to 150 Started
Experiment Log Entry # 27,Data On set to 0
Experiment Log Entry # 29,Isothermal Segment 0.1 min started
Experiment Log Entry # 31,Data On set to 1
Experiment Log Entry # 33,Ramp Segment 10 C/min to -60 Started
Experiment Log Entry # 35,Data On set to 0
Experiment Log Entry # 37,Isothermal Segment 1 min started
Experiment Log Entry # 39,Data On set to 1
Experiment Log Entry # 41,Ramp Segment 5 C/min to 30 Started
[Method Log]
Method Log Entry # 1,Data Off
Method Log Entry # 2,Equilibrate -60 °C
Method Log Entry # 3,Data On
Method Log Entry # 4,(Ramp 327580) Ramp 5 °C/minute to 150 °C
Method Log Entry # 5,Data Off
Method Log Entry # 6,Isothermal 0.1 minutes
Method Log Entry # 7,Data On
Method Log Entry # 8,(Ramp 327584) Ramp 10 °C/minute to -60 °C
Method Log Entry # 9,Data Off
Method Log Entry # 10,Isothermal 1 minutes
Method Log Entry # 11,Data On
Method Log Entry # 12,(Ramp 327588) Ramp 5 °C/minute to 150 °C
Method Log Entry # 13,Data Off
Method Log Entry # 14,Isothermal 0.1 minutes
Method Log Entry # 15,Data On
Method Log Entry # 16,(Ramp 327592) Ramp 10 °C/minute to -60 °C
Method Log Entry # 17,Data Off
Method Log Entry # 18,Isothermal 1 minutes
Method Log Entry # 19,Data On
Method Log Entry # 20,(Ramp 327596) Ramp 5 °C/minute to 30 °C
Cell Serial,DRC2-00792
[T1 Calibration]
Slope,-0.008529666
Offset,9.636258
Initial Temperature,98.23
GUID,f8bfdadc-4977-4fdf-ba6d-0ba9134940c3
[TZero Calibration]
Date Applied,11/29/2022 4:06:13 PM
Description,From -89.059 °C to 396.009 °C at 20.000°C/min
Gas Type,Nitrogen
Pan Type,None
Source Files 1,C:\Users\yargerlab\Desktop\DSC Data\General\TZero_calibration_11_29_22_2nd(2).tri
Source Files 2,C:\Users\yargerlab\Desktop\DSC Data\General\TZero_calibration_11_29_22_2nd(3).tri
Delta T Offset,13.05235
Delta T Slope,-0.007271007
Delta T0 Offset,-13.69128
Delta T0 Slope,0.06063341
[Temperature Calibration]
Date Applied,11/29/2022 7:12:28 PM
Description,From 106.590 °C to 186.590 °C at 10.000°C/min
Gas Type,Nitrogen
Pan Type,Tzero Aluminum Hermetic
Source Files 1,C:\Users\yargerlab\Desktop\DSC Data\General\Indium(6).tri
Measured 1,157.391
Known 1,156.598
[Cell Constant Calibration]
Date Applied,11/29/2022 7:12:29 PM
Description,From 106.590 °C to 186.590 °C at 10.000°C/min
Gas Type,Nitrogen
Pan Type,Tzero Aluminum Hermetic
Source Files 1,C:\Users\yargerlab\Desktop\DSC Data\General\Indium(6).tri
T4P KCell,1.006051
Onset Slope,63.26126 mW/°C
[Direct Cp Calibration]
Date Applied,11/30/2022 11:04:51 AM
Description,From -79.983 °C to 298.409 °C at 10.000°C/min
Gas Type,Nitrogen
Pan Type,Tzero Aluminum Hermetic
Source Files 1,C:\Users\yargerlab\Desktop\DSC Data\General\Sapphire_Heat_Capacity_11_30_22.tri
[Rev Cp Calibration]
Date Applied,11/30/2022 1:58:51 PM
Description,From -79.996 °C to 292.812 °C at 3.000°C/min
Gas Type,Nitrogen
Pan Type,Tzero Aluminum Hermetic
Source Files 1,C:\Users\yargerlab\Desktop\DSC Data\General\Sapphire_MDSC_Calibration_11_30_22.tri
[step]
Ramp 5.00 °C/min to 150.00 °C
Time,Temperature,Heat Flow (Normalized)
min,°C,W/g
0.00,-59.70,
0.03,-59.71,
0.06,-59.72,
0.08,-59.69,
0.11,-59.64,
0.14,-59.57,
0.17,-59.47,
0.20,-59.36,
0.23,-59.25,
0.26,-59.13,
0.28,-59.00,
0.31,-58.88,
0.34,-58.75,
0.37,-58.62,
0.40,-58.48,
0.43,-58.35,
0.45,-58.22,
0.48,-58.08,
0.51,-57.94,
0.54,-57.81,
0.57,-57.67,
0.60,-57.53,
0.62,-57.40,
0.65,-57.26,
0.68,-57.12,
0.71,-56.98,
0.74,-56.84,
0.77,-56.71,
0.79,-56.57,
0.82,-56.43,
0.85,-56.29,
0.88,-56.15,
0.91,-56.01,
0.93,-55.87,
0.96,-55.73,
0.99,-55.59,
1.02,-55.45,
1.05,-55.31,
1.08,-55.17,
1.11,-55.03,
1.13,-54.89,
1.16,-54.75,
1.19,-54.61,
1.22,-54.46,
1.25,-54.32,
1.28,-54.19,
1.30,-54.04,
1.33,-53.90,
1.36,-53.76,
1.39,-53.62,
1.42,-53.48,
1.44,-53.34,
1.47,-53.20,
1.50,-53.06,
1.53,-52.92,
1.56,-52.78,
1.59,-52.63,
1.62,-52.49,
1.64,-52.35,
1.67,-52.21,
1.70,-52.07,
1.73,-51.93,
1.76,-51.79,
1.78,-51.65,
1.81,-51.50,
1.84,-51.36,
1.87,-51.22,
1.90,-51.08,
1.93,-50.94,
1.96,-50.80,
1.98,-50.66,
2.01,-50.51,
2.04,-50.37,
2.07,-50.23,
2.10,-50.09,
2.13,-49.95,
2.15,-49.81,
2.18,-49.66,
2.21,-49.52,
2.24,-49.38,
2.27,-49.24,
2.29,-49.10,
2.32,-48.96,
2.35,-48.82,
2.38,-48.68,
2.41,-48.53,
2.44,-48.39,
2.46,-48.25,
2.49,-48.11,
2.52,-47.97,
2.55,-47.83,
2.58,-47.69,
2.61,-47.54,
2.64,-47.40,
2.66,-47.26,
2.69,-47.12,
2.72,-46.98,
2.75,-46.84,
2.78,-46.69,
2.81,-46.55,
2.83,-46.41,
2.86,-46.27,
2.89,-46.13,
2.92,-45.99,
2.95,-45.85,
2.98,-45.70,
3.00,-45.56,
3.03,-45.42,
3.06,-45.28,
3.09,-45.14,
3.12,-45.00,
3.14,-44.85,
3.17,-44.71,
3.20,-44.57,
3.23,-44.43,
3.26,-44.29,
3.29,-44.15,
3.31,-44.00,
3.34,-43.86,
3.37,-43.72,
3.40,-43.58,
3.43,-43.44,
3.46,-43.29,
3.49,-43.15,
3.51,-43.01,
3.54,-42.87,
3.57,-42.73,
3.60,-42.59,
3.63,-42.44,
3.66,-42.30,
3.68,-42.16,
3.71,-42.02,
3.74,-41.88,
3.77,-41.73,
3.80,-41.59,
3.83,-41.45,
3.85,-41.31,
3.88,-41.17,
3.91,-41.02,
3.94,-40.88,
3.97,-40.74,
3.99,-40.60,
4.02,-40.46,
4.05,-40.32,
4.08,-40.17,
4.11,-40.03,
4.14,-39.89,
4.16,-39.75,
4.19,-39.61,
4.22,-39.46,
4.25,-39.32,
4.28,-39.18,
4.31,-39.04,
4.34,-38.90,
4.36,-38.76,
4.39,-38.61,
4.42,-38.47,
4.45,-38.33,
4.48,-38.19,
4.50,-38.05,
4.53,-37.91,
4.56,-37.76,
4.59,-37.62,
4.62,-37.48,
4.65,-37.34,
4.68,-37.19,
4.70,-37.05,
4.73,-36.91,
4.76,-36.77,
4.79,-36.63,
4.82,-36.48,
4.85,-36.34,
4.87,-36.20,
4.90,-36.06,
4.93,-35.92,
4.96,-35.78,
4.99,-35.63,
5.01,-35.49,
5.04,-35.35,
5.07,-35.21,
5.10,-35.07,
5.13,-34.92,
5.16,-34.78,
5.19,-34.64,
5.21,-34.50,
5.24,-34.36,
5.27,-34.22,
5.30,-34.08,
5.33,-33.93,
5.35,-33.79,
5.38,-33.65,
5.41,-33.51,
5.44,-33.37,
5.47,-33.22,
5.50,-33.08,
5.53,-32.94,
5.55,-32.80,
5.58,-32.66,
5.61,-32.52,
5.64,-32.37,
5.67,-32.23,
5.70,-32.09,
5.72,-31.95,
5.75,-31.81,
5.78,-31.66,
5.81,-31.52,
5.84,-31.38,
5.86,-31.24,
5.89,-31.10,
5.92,-30.96,
5.95,-30.81,
5.98,-30.67,
6.01,-30.53,
6.04,-30.39,
6.06,-30.25,
6.09,-30.10,
6.12,-29.96,
6.15,-29.82,
6.18,-29.68,
6.20,-29.54,
6.23,-29.39,
6.26,-29.25,
6.29,-29.11,
6.32,-28.97,
6.35,-28.83,
6.38,-28.69,
6.40,-28.55,
6.43,-28.41,
6.46,-28.26,
6.49,-28.12,
6.52,-27.98,
6.55,-27.84,
6.57,-27.70,
6.60,-27.55,
6.63,-27.41,
6.66,-27.27,
6.69,-27.13,
6.71,-26.99,
6.74,-26.84,
6.77,-26.70,
6.80,-26.56,
6.83,-26.42,
6.86,-26.28,
6.89,-26.14,
6.91,-25.99,
6.94,-25.85,
6.97,-25.71,
7.00,-25.57,
7.03,-25.42,
7.05,-25.28,
7.08,-25.14,
7.11,-25.00,
7.14,-24.86,
7.17,-24.72,
7.20,-24.58,
7.23,-24.43,
7.25,-24.29,
7.28,-24.15,
7.31,-24.01,
7.34,-23.87,
7.37,-23.72,
7.40,-23.58,
7.42,-23.44,
7.45,-23.30,
7.48,-23.15,
7.51,-23.01,
7.54,-22.87,
7.56,-22.73,
7.59,-22.59,
7.62,-22.45,
7.65,-22.31,
7.68,-22.16,
7.71,-22.02,
7.74,-21.88,
7.76,-21.74,
7.79,-21.59,
7.82,-21.45,
7.85,-21.31,
7.88,-21.17,
7.90,-21.03,
7.93,-20.89,
7.96,-20.75,
7.99,-20.60,
8.02,-20.46,
8.05,-20.32,
8.08,-20.18,
8.10,-20.04,
8.13,-19.89,
8.16,-19.75,
8.19,-19.61,
8.22,-19.47,
8.25,-19.33,
8.27,-19.18,
8.30,-19.04,
8.33,-18.90,
8.36,-18.76,
8.39,-18.62,
8.41,-18.48,
8.44,-18.33,
8.47,-18.19,
8.50,-18.05,
8.53,-17.91,
8.56,-17.77,
8.58,-17.63,
8.61,-17.48,
8.64,-17.34,
8.67,-17.20,
8.70,-17.06,
8.73,-16.92,
8.75,-16.78,
8.78,-16.63,
8.81,-16.49,
8.84,-16.35,
8.87,-16.21,
8.90,-16.07,
8.93,-15.92,
8.95,-15.78,
8.98,-15.64,
9.01,-15.50,
9.04,-15.36,
9.07,-15.22,
9.10,-15.07,
9.12,-14.93,
9.15,-14.79,
9.18,-14.65,
9.21,-14.51,
9.24,-14.36,
9.27,-14.22,
9.29,-14.08,
9.32,-13.94,
9.35,-13.80,
9.38,-13.66,
9.41,-13.51,
9.43,-13.37,
9.46,-13.23,
9.49,-13.09,
9.52,-12.95,
9.55,-12.80,
9.58,-12.66,
9.60,-12.52,
9.63,-12.38,
9.66,-12.24,
9.69,-12.10,
9.72,-11.95,
9.75,-11.81,
9.78,-11.67,
9.80,-11.53,
9.83,-11.39,
9.86,-11.25,
9.89,-11.10,
9.92,-10.96,
9.95,-10.82,
9.97,-10.68,
10.00,-10.54,
10.03,-10.39,
10.06,-10.25,
10.09,-10.11,
10.12,-9.97,
10.14,-9.83,
10.17,-9.69,
10.20,-9.54,
10.23,-9.40,
10.26,-9.26,
10.28,-9.12,
10.31,-8.98,
10.34,-8.83,
10.37,-8.69,
10.40,-8.55,
10.43,-8.41,
10.45,-8.27,
10.48,-8.13,
10.51,-7.98,
10.54,-7.84,
10.57,-7.70,
10.60,-7.56,
10.63,-7.42,
10.65,-7.28,
10.68,-7.13,
10.71,-6.99,
10.74,-6.85,
10.77,-6.71,
10.80,-6.57,
10.82,-6.42,
10.85,-6.28,
10.88,-6.14,
10.91,-6.00,
10.94,-5.86,
10.97,-5.72,
10.99,-5.57,
11.02,-5.43,
11.05,-5.29,
11.08,-5.15,
11.11,-5.01,
11.13,-4.87,
11.16,-4.72,
11.19,-4.58,
11.22,-4.44,
11.25,-4.30,
11.28,-4.15,
11.30,-4.01,
11.33,-3.87,
11.36,-3.73,
11.39,-3.58,
11.42,-3.44,
11.45,-3.30,
11.48,-3.16,
11.50,-3.02,
11.53,-2.88,
11.56,-2.73,
11.59,-2.59,
11.62,-2.45,
11.65,-2.31,
11.67,-2.17,
11.70,-2.03,
11.73,-1.89,
11.76,-1.74,
11.79,-1.60,
11.82,-1.46,
11.84,-1.32,
11.87,-1.18,
11.90,-1.03,
11.93,-0.89,
11.96,-0.75,
11.98,-0.61,
12.01,-0.47,
12.04,-0.33,
12.07,-0.19,
12.10,-0.05,
12.13,0.10,
12.15,0.24,
12.18,0.38,
12.21,0.52,
12.24,0.66,
12.27,0.81,
12.30,0.95,
12.33,1.09,
12.35,1.23,
12.38,1.37,
12.41,1.52,
12.44,1.66,
12.47,1.80,
12.50,1.94,
12.52,2.08,
12.55,2.22,
12.58,2.36,
12.61,2.51,
12.64,2.65,
12.67,2.79,
12.69,2.93,
12.72,3.08,
12.75,3.22,
12.78,3.36,
12.81,3.50,
12.83,3.64,
12.86,3.78,
12.89,3.93,
12.92,4.07,
12.95,4.21,
12.98,4.35,
13.00,4.49,
13.03,4.63,
13.06,4.78,
13.09,4.92,
13.12,5.06,
13.15,5.20,
13.18,5.34,
13.20,5.48,
13.23,5.63,
13.26,5.77,
13.29,5.91,
13.32,6.05,
13.35,6.19,
13.37,6.34,
13.40,6.48,
13.43,6.62,
13.46,6.76,
13.49,6.90,
13.52,7.04,
13.54,7.19,
13.57,7.33,
13.60,7.47,
13.63,7.61,
13.66,7.75,
13.68,7.90,
13.71,8.04,
13.74,8.18,
13.77,8.32,
13.80,8.46,
13.83,8.60,
13.85,8.74,
13.88,8.89,
13.91,9.03,
13.94,9.17,
13.97,9.31,
14.00,9.45,
14.03,9.60,
14.05,9.74,
14.08,9.88,
14.11,10.02,
14.14,10.16,
14.17,10.31,
14.20,10.45,
14.22,10.59,
14.25,10.73,
14.28,10.87,
14.31,11.01,
14.34,11.16,
14.37,11.30,
14.39,11.44,
14.42,11.58,
14.45,11.72,
14.48,11.86,
14.51,12.00,
14.53,12.15,
14.56,12.29,
14.59,12.43,
14.62,12.57,
14.65,12.72,
14.68,12.86,
14.70,13.00,
14.73,13.14,
14.76,13.28,
14.79,13.42,
14.82,13.57,
14.85,13.71,
14.88,13.85,
14.90,13.99,
14.93,14.13,
14.96,14.28,
14.99,14.42,
15.02,14.56,
15.05,14.70,
15.07,14.84,
15.10,14.98,
15.13,15.13,
15.16,15.27,
15.19,15.41,
15.22,15.55,
15.24,15.69,
15.27,15.84,
15.30,15.98,
15.33,16.12,
15.36,16.26,
15.38,16.40,
15.41,16.54,
15.44,16.68,
15.47,16.83,
15.50,16.97,
15.53,17.11,
15.55,17.25,
15.58,17.39,
15.61,17.54,
15.64,17.68,
15.67,17.82,
15.70,17.96,
15.73,18.10,
15.75,18.24,
15.78,18.39,
15.81,18.53,
15.84,18.67,
15.87,18.81,
15.90,18.95,
15.92,19.09,
15.95,19.24,
15.98,19.38,
16.01,19.52,
16.04,19.66,
16.07,19.80,
16.09,19.95,
16.12,20.09,
16.15,20.23,
16.18,20.37,
16.21,20.51,
16.23,20.65,
16.26,20.80,
16.29,20.94,
16.32,21.08,
16.35,21.22,
16.38,21.36,
16.40,21.51,
16.43,21.65,
16.46,21.79,
16.49,21.93,
16.52,22.07,
16.55,22.21,
16.58,22.36,
16.60,22.50,
16.63,22.64,
16.66,22.78,
16.69,22.92,
16.72,23.06,
16.75,23.21,
16.77,23.35,
16.80,23.49,
16.83,23.63,
16.86,23.77,
16.89,23.91,
16.92,24.06,
16.94,24.20,
16.97,24.34,
17.00,24.48,
17.03,24.62,
17.06,24.77,
17.08,24.91,
17.11,25.05,
17.14,25.19,
17.17,25.33,
17.20,25.47,
17.23,25.62,
17.26,25.76,
17.28,25.90,
17.31,26.04,
17.34,26.18,
17.37,26.32,
17.40,26.47,
17.43,26.61,
17.45,26.75,
17.48,26.89,
17.51,27.04,
17.54,27.18,
17.57,27.32,
17.59,27.46,
17.62,27.60,
17.65,27.74,
17.68,27.89,
17.71,28.03,
17.74,28.17,
17.77,28.31,
17.79,28.45,
17.82,28.59,
17.85,28.74,
17.88,28.88,
17.91,29.02,
17.93,29.16,
17.96,29.30,
17.99,29.44,
18.02,29.59,
18.05,29.73,
18.08,29.87,
18.11,30.01,
18.13,30.15,
18.16,30.29,
18.19,30.44,
18.22,30.58,
18.25,30.72,
18.28,30.86,
18.30,31.00,
18.33,31.15,
18.36,31.29,
18.39,31.43,
18.42,31.57,
18.44,31.71,
18.47,31.85,
18.50,32.00,
18.53,32.14,
18.56,32.28,
18.59,32.42,
18.62,32.56,
18.64,32.71,
18.67,32.85,
18.70,32.99,
18.73,33.13,
18.76,33.27,
18.78,33.41,
18.81,33.56,
18.84,33.70,
18.87,33.84,
18.90,33.98,
18.93,34.12,
18.96,34.27,
18.98,34.41,
19.01,34.55,
19.04,34.69,
19.07,34.83,
19.10,34.97,
19.13,35.12,
19.15,35.26,
19.18,35.40,
19.21,35.54,
19.24,35.68,
19.27,35.82,
19.29,35.97,
19.32,36.11,
19.35,36.25,
19.38,36.39,
19.41,36.53,
19.44,36.68,
19.47,36.82,
19.49,36.96,
19.52,37.10,
19.55,37.24,
19.58,37.38,
19.61,37.52,
19.63,37.67,
19.66,37.81,
19.69,37.95,
19.72,38.09,
19.75,38.23,
19.78,38.38,
19.81,38.52,
19.83,38.66,
19.86,38.80,
19.89,38.94,
19.92,39.08,
19.95,39.23,
19.98,39.37,
20.00,39.51,
20.03,39.65,
20.06,39.79,
20.09,39.94,
20.12,40.08,
20.14,40.22,
20.17,40.36,
20.20,40.50,
20.23,40.64,
20.26,40.79,
20.29,40.93,
20.32,41.07,
20.34,41.21,
20.37,41.35,
20.40,41.49,
20.43,41.64,
20.46,41.78,
20.48,41.92,
20.51,42.06,
20.54,42.20,
20.57,42.34,
20.60,42.49,
20.63,42.63,
20.66,42.77,
20.68,42.91,
20.71,43.05,
20.74,43.19,
20.77,43.34,
20.80,43.48,
20.83,43.62,
20.85,43.76,
20.88,43.91,
20.91,44.05,
20.94,44.19,
20.97,44.33,
20.99,44.47,
21.02,44.61,
21.05,44.76,
21.08,44.90,
21.11,45.04,
21.14,45.18,
21.17,45.32,
21.19,45.46,
21.22,45.61,
21.25,45.75,
21.28,45.89,
21.31,46.03,
21.33,46.17,
21.36,46.32,
21.39,46.46,
21.42,46.60,
21.45,46.74,
21.48,46.88,
21.51,47.02,
21.53,47.16,
21.56,47.31,
21.59,47.45,
21.62,47.59,
21.65,47.73,
21.68,47.87,
21.70,48.02,
21.73,48.16,
21.76,48.30,
21.79,48.44,
21.82,48.58,
21.84,48.72,
21.87,48.86,
21.90,49.01,
21.93,49.15,
21.96,49.29,
21.99,49.43,
22.02,49.57,
22.04,49.72,
22.07,49.86,
22.10,50.00,
22.13,50.14,
22.16,50.28,
22.18,50.42,
22.21,50.57,
22.24,50.71,
22.27,50.85,
22.30,50.99,
22.33,51.13,
22.36,51.27,
22.38,51.42,
22.41,51.56,
22.44,51.70,
22.47,51.84,
22.50,51.98,
22.53,52.12,
22.55,52.27,
22.58,52.41,
22.61,52.55,
22.64,52.69,
22.67,52.83,
22.69,52.98,
22.72,53.12,
22.75,53.26,
22.78,53.40,
22.81,53.54,
22.84,53.68,
22.87,53.83,
22.89,53.97,
22.92,54.11,
22.95,54.25,
22.98,54.39,
23.01,54.53,
23.03,54.68,
23.06,54.82,
23.09,54.96,
23.12,55.10,
23.15,55.24,
23.18,55.39,
23.21,55.53,
23.23,55.67,
23.26,55.81,
23.29,55.95,
23.32,56.09,
23.35,56.24,
23.38,56.38,
23.40,56.52,
23.43,56.66,
23.46,56.80,
23.49,56.95,
23.52,57.09,
23.54,57.23,
23.57,57.37,
23.60,57.51,
23.63,57.65,
23.66,57.80,
23.69,57.94,
23.72,58.08,
23.74,58.22,
23.77,58.36,
23.80,58.51,
23.83,58.65,
23.86,58.79,
23.88,58.93,
23.91,59.07,
23.94,59.21,
23.97,59.35,
24.00,59.50,
24.03,59.64,
24.06,59.78,
24.08,59.92,
24.11,60.06,
24.14,60.20,
24.17,60.35,
24.20,60.49,
24.23,60.63,
24.25,60.77,
24.28,60.91,
24.31,61.06,
24.34,61.20,
24.37,61.34,
24.39,61.48,
24.42,61.62,
24.45,61.76,
24.48,61.91,
24.51,62.05,
24.54,62.19,
24.57,62.33,
24.59,62.47,
24.62,62.62,
24.65,62.76,
24.68,62.90,
24.71,63.04,
24.73,63.18,
24.76,63.32,
24.79,63.47,
24.82,63.61,
24.85,63.75,
24.88,63.89,
24.91,64.03,
24.93,64.17,
24.96,64.32,
24.99,64.46,
25.02,64.60,
25.05,64.74,
25.08,64.88,
25.10,65.02,
25.13,65.17,
25.16,65.31,
25.19,65.45,
25.22,65.59,
25.24,65.73,
25.27,65.87,
25.30,66.02,
25.33,66.16,
25.36,66.30,
25.39,66.44,
25.42,66.58,
25.44,66.73,
25.47,66.87,
25.50,67.01,
25.53,67.15,
25.56,67.29,
25.58,67.43,
25.61,67.58,
25.64,67.72,
25.67,67.86,
25.70,68.00,
25.73,68.14,
25.76,68.29,
25.78,68.43,
25.81,68.57,
25.84,68.71,
25.87,68.85,
25.90,69.00,
25.93,69.14,
25.95,69.28,
25.98,69.42,
26.01,69.56,
26.04,69.70,
26.07,69.84,
26.09,69.99,
26.12,70.13,
26.15,70.27,
26.18,70.41,
26.21,70.55,
26.24,70.70,
26.27,70.84,
26.29,70.98,
26.32,71.12,
26.35,71.26,
26.38,71.40,
26.41,71.55,
26.43,71.69,
26.46,71.83,
26.49,71.97,
26.52,72.11,
26.55,72.25,
26.58,72.39,
26.61,72.54,
26.63,72.68,
26.66,72.82,
26.69,72.96,
26.72,73.10,
26.75,73.25,
26.78,73.39,
26.80,73.53,
26.83,73.67,
26.86,73.81,
26.89,73.95,
26.92,74.10,
26.94,74.24,
26.97,74.38,
27.00,74.52,
27.03,74.66,
27.06,74.80,
27.09,74.94,
27.12,75.09,
27.14,75.23,
27.17,75.37,
27.20,75.51,
27.23,75.65,
27.26,75.80,
27.28,75.94,
27.31,76.08,
27.34,76.22,
27.37,76.36,
27.40,76.50,
27.43,76.65,
27.46,76.79,
27.48,76.93,
27.51,77.07,
27.54,77.21,
27.57,77.36,
27.60,77.50,
27.63,77.64,
27.65,77.78,
27.68,77.92,
27.71,78.06,
27.74,78.21,
27.77,78.35,
27.79,78.49,
27.82,78.63,
27.85,78.77,
27.88,78.91,
27.91,79.06,
27.94,79.20,
27.97,79.34,
27.99,79.48,
28.02,79.62,
28.05,79.77,
28.08,79.91,
28.11,80.05,
28.13,80.19,
28.16,80.33,
28.19,80.48,
28.22,80.62,
28.25,80.76,
28.28,80.90,
28.31,81.04,
28.33,81.18,
28.36,81.33,
28.39,81.47,
28.42,81.61,
28.45,81.75,
28.48,81.89,
28.50,82.03,
28.53,82.18,
28.56,82.32,
28.59,82.46,
28.62,82.60,
28.64,82.74,
28.67,82.88,
28.70,83.03,
28.73,83.17,
28.76,83.31,
28.79,83.45,
28.82,83.59,
28.84,83.73,
28.87,83.88,
28.90,84.02,
28.93,84.16,
28.96,84.30,
28.98,84.44,
29.01,84.59,
29.04,84.73,
29.07,84.87,
29.10,85.01,
29.13,85.15,
29.16,85.29,
29.18,85.43,
29.21,85.58,
29.24,85.72,
29.27,85.86,
29.30,86.00,
29.33,86.14,
29.35,86.29,
29.38,86.43,
29.41,86.57,
29.44,86.71,
29.47,86.85,
29.49,86.99,
29.52,87.14,
29.55,87.28,
29.58,87.42,
29.61,87.56,
29.64,87.70,
29.67,87.84,
29.69,87.99,
29.72,88.13,
29.75,88.27,
29.78,88.41,
29.81,88.55,
29.83,88.69,
29.86,88.84,
29.89,88.98,
29.92,89.12,
29.95,89.26,
29.98,89.40,
30.01,89.55,
30.03,89.69,
30.06,89.83,
30.09,89.97,
30.12,90.11,
30.15,90.25,
30.18,90.40,
30.20,90.54,
30.23,90.68,
30.26,90.82,
30.29,90.96,
30.32,91.10,
30.34,91.25,
30.37,91.39,
30.40,91.53,
30.43,91.67,
30.46,91.81,
30.49,91.95,
30.52,92.10,
30.54,92.24,
30.57,92.38,
30.60,92.52,
30.63,92.66,
30.66,92.80,
30.68,92.95,
30.71,93.09,
30.74,93.23,
30.77,93.37,
30.80,93.51,
30.83,93.66,
30.86,93.80,
30.88,93.94,
30.91,94.08,
30.94,94.22,
30.97,94.36,
31.00,94.51,
31.03,94.65,
31.05,94.79,
31.08,94.93,
31.11,95.07,
31.14,95.22,
31.17,95.36,
31.19,95.50,
31.22,95.64,
31.25,95.78,
31.28,95.92,
31.31,96.06,
31.34,96.21,
31.37,96.35,
31.39,96.49,
31.42,96.63,
31.45,96.77,
31.48,96.92,
31.51,97.06,
31.53,97.20,
31.56,97.34,
31.59,97.48,
31.62,97.63,
31.65,97.77,
31.68,97.91,
31.71,98.05,
31.73,98.19,
31.76,98.33,
31.79,98.48,
31.82,98.62,
31.85,98.76,
31.88,98.90,
31.90,99.04,
31.93,99.18,
31.96,99.32,
31.99,99.47,
32.02,99.61,
32.04,99.75,
32.07,99.89,
32.10,100.03,
32.13,100.18,
32.16,100.32,
32.19,100.46,
32.22,100.60,
32.24,100.74,
32.27,100.88,
32.30,101.02,
32.33,101.17,
32.36,101.31,
32.38,101.45,
32.41,101.59,
32.44,101.73,
32.47,101.88,
32.50,102.02,
32.53,102.16,
32.56,102.30,
32.58,102.44,
32.61,102.58,
32.64,102.73,
32.67,102.87,
32.70,103.01,
32.73,103.15,
32.75,103.29,
32.78,103.43,
32.81,103.58,
32.84,103.72,
32.87,103.86,
32.89,104.00,
32.92,104.14,
32.95,104.29,
32.98,104.43,
33.01,104.57,
33.04,104.71,
33.07,104.85,
33.09,104.99,
33.12,105.14,
33.15,105.28,
33.18,105.42,
33.21,105.56,
33.23,105.70,
33.26,105.84,
33.29,105.99,
33.32,106.13,
33.35,106.27,
33.38,106.41,
33.41,106.55,
33.43,106.69,
33.46,106.84,
33.49,106.98,
33.52,107.12,
33.55,107.26,
33.58,107.40,
33.60,107.54,
33.63,107.69,
33.66,107.83,
33.69,107.97,
33.72,108.11,
33.74,108.25,
33.77,108.40,
33.80,108.54,
33.83,108.68,
33.86,108.82,
33.89,108.97,
33.92,109.11,
33.94,109.25,
33.97,109.39,
34.00,109.53,
34.03,109.67,
34.06,109.82,
34.08,109.96,
34.11,110.10,
34.14,110.24,
34.17,110.38,
34.20,110.52,
34.23,110.67,
34.26,110.81,
34.28,110.95,
34.31,111.09,
34.34,111.23,
34.37,111.37,
34.40,111.52,
34.43,111.66,
34.45,111.80,
34.48,111.94,
34.51,112.08,
34.54,112.22,
34.57,112.37,
34.59,112.51,
34.62,112.65,
34.65,112.79,
34.68,112.93,
34.71,113.07,
34.74,113.21,
34.76,113.35,
34.79,113.50,
34.82,113.64,
34.85,113.78,
34.88,113.92,
34.91,114.06,
34.94,114.21,
34.96,114.35,
34.99,114.49,
35.02,114.63,
35.05,114.77,
35.08,114.92,
35.11,115.06,
35.13,115.20,
35.16,115.34,
35.19,115.48,
35.22,115.62,
35.25,115.76,
35.28,115.91,
35.30,116.05,
35.33,116.19,
35.36,116.33,
35.39,116.47,
35.42,116.62,
35.44,116.76,
35.47,116.90,
35.50,117.04,
35.53,117.18,
35.56,117.32,
35.59,117.47,
35.61,117.61,
35.64,117.75,
35.67,117.89,
35.70,118.03,
35.73,118.17,
35.76,118.32,
35.79,118.46,
35.81,118.60,
35.84,118.74,
35.87,118.88,
35.90,119.03,
35.93,119.17,
35.96,119.31,
35.98,119.45,
36.01,119.59,
36.04,119.73,
36.07,119.87,
36.10,120.02,
36.13,120.16,
36.15,120.30,
36.18,120.44,
36.21,120.58,
36.24,120.72,
36.27,120.87,
36.29,121.01,
36.32,121.15,
36.35,121.29,
36.38,121.43,
36.41,121.58,
36.44,121.72,
36.46,121.86,
36.49,122.00,
36.52,122.14,
36.55,122.28,
36.58,122.43,
36.61,122.57,
36.64,122.71,
36.66,122.85,
36.69,122.99,
36.72,123.13,
36.75,123.28,
36.78,123.42,
36.81,123.56,
36.83,123.70,
36.86,123.84,
36.89,123.98,
36.92,124.13,
36.95,124.27,
36.98,124.41,
37.00,124.55,
37.03,124.69,
37.06,124.83,
37.09,124.98,
37.12,125.12,
37.14,125.26,
37.17,125.40,
37.20,125.54,
37.23,125.68,
37.26,125.83,
37.29,125.97,
37.31,126.11,
37.34,126.25,
37.37,126.39,
37.40,126.53,
37.43,126.68,
37.46,126.82,
37.49,126.96,
37.51,127.10,
37.54,127.24,
37.57,127.39,
37.60,127.53,
37.63,127.67,
37.66,127.81,
37.68,127.95,
37.71,128.10,
37.74,128.24,
37.77,128.38,
37.80,128.52,
37.83,128.66,
37.85,128.80,
37.88,128.94,
37.91,129.09,
37.94,129.23,
37.97,129.37,
37.99,129.51,
38.02,129.65,
38.05,129.79,
38.08,129.94,
38.11,130.08,
38.14,130.22,
38.16,130.36,
38.19,130.50,
38.22,130.64,
38.25,130.79,
38.28,130.93,
38.31,131.07,
38.34,131.21,
38.36,131.35,
38.39,131.49,
38.42,131.64,
38.45,131.78,
38.48,131.92,
38.51,132.06,
38.53,132.20,
38.56,132.35,
38.59,132.49,
38.62,132.63,
38.65,132.77,
38.68,132.91,
38.70,133.05,
38.73,133.20,
38.76,133.34,
38.79,133.48,
38.82,133.62,
38.84,133.76,
38.87,133.90,
38.90,134.05,
38.93,134.19,
38.96,134.33,
38.99,134.47,
39.01,134.61,
39.04,134.75,
39.07,134.90,
39.10,135.04,
39.13,135.18,
39.16,135.32,
39.19,135.46,
39.21,135.60,
39.24,135.75,
39.27,135.89,
39.30,136.03,
39.33,136.17,
39.36,136.31,
39.38,136.46,
39.41,136.60,
39.44,136.74,
39.47,136.88,
39.50,137.02,
39.53,137.16,
39.55,137.31,
39.58,137.45,
39.61,137.59,
39.64,137.73,
39.67,137.87,
39.69,138.01,
39.72,138.16,
39.75,138.30,
39.78,138.44,
39.81,138.58,
39.84,138.72,
39.86,138.86,
39.89,139.01,
39.92,139.15,
39.95,139.29,
39.98,139.43,
40.01,139.57,
40.04,139.71,
40.06,139.86,
40.09,140.00,
40.12,140.14,
40.15,140.28,
40.18,140.42,
40.21,140.56,
40.23,140.71,
40.26,140.85,
40.29,140.99,
40.32,141.13,
40.35,141.27,
40.38,141.41,
40.40,141.56,
40.43,141.70,
40.46,141.84,
40.49,141.98,
40.52,142.12,
40.54,142.26,
40.57,142.41,
40.60,142.55,
40.63,142.69,
40.66,142.83,
40.69,142.97,
40.71,143.11,
40.74,143.26,
40.77,143.40,
40.80,143.54,
40.83,143.68,
40.86,143.82,
40.89,143.97,
40.91,144.11,
40.94,144.25,
40.97,144.39,
41.00,144.53,
41.03,144.67,
41.06,144.81,
41.08,144.96,
41.11,145.10,
41.14,145.24,
41.17,145.38,
41.20,145.52,
41.23,145.67,
41.25,145.81,
41.28,145.95,
41.31,146.09,
41.34,146.23,
41.37,146.38,
41.39,146.52,
41.42,146.66,
41.45,146.80,
41.48,146.94,
41.51,147.08,
41.54,147.23,
41.56,147.37,
41.59,147.51,
41.62,147.65,
41.65,147.79,
41.68,147.93,
41.71,148.08,
41.74,148.22,
41.76,148.36,
41.79,148.50,
41.82,148.64,
41.85,148.78,
41.88,148.92,
41.91,149.07,
41.93,149.21,
41.96,149.35,
41.98,,

[step]
Ramp 10.00 °C/min to -60.00 °C
Time,Temperature,Heat Flow (Normalized)
min,°C,W/g
42.09,149.91,
42.10,149.95,
42.11,149.99,
42.13,150.02,
42.14,150.04,
42.16,150.04,
42.18,150.03,
42.19,150.00,
42.21,149.95,
42.22,149.88,
42.24,149.80,
42.25,149.71,
42.26,149.60,
42.28,149.49,
42.29,149.38,
42.31,149.25,
42.33,149.13,
42.34,149.00,
42.36,148.87,
42.37,148.73,
42.39,148.60,
42.40,148.46,
42.41,148.32,
42.43,148.18,
42.44,148.04,
42.46,147.90,
42.48,147.75,
42.49,147.61,
42.51,147.46,
42.52,147.32,
42.54,147.17,
42.55,147.03,
42.56,146.88,
42.58,146.73,
42.59,146.59,
42.61,146.44,
42.63,146.30,
42.64,146.15,
42.66,146.00,
42.67,145.85,
42.69,145.71,
42.70,145.56,
42.71,145.41,
42.73,145.26,
42.74,145.11,
42.76,144.97,
42.78,144.82,
42.79,144.67,
42.81,144.52,
42.82,144.38,
42.84,144.23,
42.85,144.08,
42.86,143.93,
42.88,143.78,
42.89,143.63,
42.91,143.48,
42.93,143.34,
42.94,143.19,
42.96,143.04,
42.97,142.89,
42.99,142.74,
43.00,142.59,
43.01,142.44,
43.03,142.29,
43.04,142.14,
43.06,141.99,
43.08,141.85,
43.09,141.70,
43.11,141.55,
43.12,141.40,
43.14,141.25,
43.15,141.10,
43.16,140.95,
43.18,140.80,
43.19,140.65,
43.21,140.50,
43.23,140.35,
43.24,140.20,
43.26,140.06,
43.27,139.91,
43.29,139.76,
43.30,139.61,
43.31,139.46,
43.33,139.31,
43.34,139.16,
43.36,139.01,
43.38,138.86,
43.39,138.71,
43.41,138.56,
43.42,138.41,
43.44,138.26,
43.45,138.11,
43.46,137.96,
43.48,137.81,
43.49,137.67,
43.51,137.52,
43.53,137.37,
43.54,137.22,
43.56,137.07,
43.57,136.92,
43.59,136.77,
43.60,136.62,
43.61,136.47,
43.63,136.32,
43.64,136.17,
43.66,136.02,
43.68,135.87,
43.69,135.72,
43.71,135.57,
43.72,135.42,
43.74,135.27,
43.75,135.12,
43.76,134.97,
43.78,134.83,
43.79,134.67,
43.81,134.53,
43.83,134.38,
43.84,134.23,
43.86,134.08,
43.87,133.93,
43.89,133.78,
43.90,133.63,
43.91,133.48,
43.93,133.33,
43.94,133.18,
43.96,133.03,
43.98,132.88,
43.99,132.73,
44.01,132.58,
44.02,132.43,
44.04,132.28,
44.05,132.13,
44.06,131.98,
44.08,131.83,
44.09,131.68,
44.11,131.53,
44.13,131.38,
44.14,131.23,
44.16,131.08,
44.17,130.93,
44.19,130.78,
44.20,130.63,
44.21,130.48,
44.23,130.33,
44.24,130.18,
44.26,130.03,
44.28,129.88,
44.29,129.73,
44.31,129.58,
44.32,129.43,
44.34,129.28,
44.35,129.13,
44.36,128.98,
44.38,128.83,
44.39,128.68,
44.41,128.53,
44.43,128.38,
44.44,128.23,
44.46,128.08,
44.47,127.93,
44.49,127.78,
44.50,127.63,
44.51,127.49,
44.53,127.33,
44.54,127.18,
44.56,127.03,
44.58,126.89,
44.59,126.74,
44.61,126.59,
44.62,126.44,
44.64,126.29,
44.65,126.14,
44.66,125.99,
44.68,125.84,
44.69,125.69,
44.71,125.54,
44.73,125.39,
44.74,125.24,
44.76,125.09,
44.77,124.94,
44.79,124.79,
44.80,124.64,
44.81,124.49,
44.83,124.34,
44.84,124.19,
44.86,124.04,
44.88,123.89,
44.89,123.74,
44.91,123.59,
44.92,123.44,
44.94,123.29,
44.95,123.14,
44.96,122.99,
44.98,122.84,
44.99,122.69,
45.01,122.54,
45.03,122.39,
45.04,122.24,
45.06,122.09,
45.07,121.94,
45.09,121.79,
45.10,121.64,
45.11,121.49,
45.13,121.34,
45.14,121.19,
45.16,121.04,
45.18,120.89,
45.19,120.74,
45.21,120.59,
45.22,120.44,
45.24,120.29,
45.25,120.14,
45.26,119.99,
45.28,119.84,
45.29,119.69,
45.31,119.54,
45.33,119.39,
45.34,119.24,
45.36,119.10,
45.37,118.94,
45.39,118.79,
45.40,118.65,
45.41,118.50,
45.43,118.35,
45.44,118.20,
45.46,118.05,
45.48,117.90,
45.49,117.75,
45.51,117.60,
45.52,117.45,
45.54,117.30,
45.55,117.15,
45.56,117.00,
45.58,116.85,
45.59,116.70,
45.61,116.55,
45.63,116.40,
45.64,116.25,
45.66,116.10,
45.67,115.95,
45.69,115.80,
45.70,115.65,
45.71,115.50,
45.73,115.35,
45.74,115.20,
45.76,115.05,
45.78,114.90,
45.79,114.75,
45.81,114.60,
45.82,114.45,
45.84,114.30,
45.85,114.15,
45.86,114.00,
45.88,113.85,
45.89,113.70,
45.91,113.55,
45.93,113.40,
45.94,113.25,
45.96,113.10,
45.97,112.95,
45.99,112.80,
46.00,112.65,
46.01,112.50,
46.03,112.35,
46.04,112.20,
46.06,112.05,
46.08,111.90,
46.09,111.75,
46.11,111.60,
46.12,111.45,
46.14,111.30,
46.15,111.15,
46.16,111.00,
46.18,110.85,
46.19,110.70,
46.21,110.55,
46.23,110.40,
46.24,110.25,
46.26,110.10,
46.27,109.95,
46.29,109.80,
46.30,109.65,
46.31,109.50,
46.33,109.36,
46.34,109.21,
46.36,109.06,
46.38,108.90,
46.39,108.76,
46.41,108.61,
46.42,108.46,
46.44,108.31,
46.45,108.16,
46.46,108.01,
46.48,107.86,
46.49,107.71,
46.51,107.56,
46.53,107.41,
46.54,107.26,
46.56,107.11,
46.57,106.96,
46.59,106.81,
46.60,106.66,
46.61,106.51,
46.63,106.36,
46.64,106.21,
46.66,106.06,
46.68,105.91,
46.69,105.76,
46.71,105.61,
46.72,105.46,
46.74,105.31,
46.75,105.16,
46.76,105.01,
46.78,104.86,
46.79,104.71,
46.81,104.56,
46.83,104.41,
46.84,104.26,
46.86,104.11,
46.87,103.96,
46.89,103.81,
46.90,103.66,
46.91,103.51,
46.93,103.36,
46.94,103.21,
46.96,103.06,
46.98,102.91,
46.99,102.76,
47.01,102.61,
47.02,102.46,
47.04,102.31,
47.05,102.16,
47.06,102.01,
47.08,101.86,
47.09,101.71,
47.11,101.56,
47.13,101.41,
47.14,101.26,
47.16,101.11,
47.17,100.96,
47.19,100.81,
47.20,100.66,
47.21,100.51,
47.23,100.36,
47.24,100.21,
47.26,100.06,
47.28,99.91,
47.29,99.76,
47.31,99.61,
47.32,99.46,
47.34,99.31,
47.35,99.17,
47.36,99.01,
47.38,98.87,
47.39,98.72,
47.41,98.57,
47.43,98.42,
47.44,98.27,
47.46,98.12,
47.47,97.97,
47.49,97.82,
47.50,97.67,
47.51,97.52,
47.53,97.37,
47.54,97.22,
47.56,97.07,
47.58,96.92,
47.59,96.77,
47.61,96.62,
47.62,96.47,
47.64,96.32,
47.65,96.17,
47.66,96.02,
47.68,95.87,
47.69,95.72,
47.71,95.57,
47.73,95.42,
47.74,95.27,
47.76,95.12,
47.77,94.97,
47.79,94.82,
47.80,94.67,
47.81,94.52,
47.83,94.37,
47.84,94.22,
47.86,94.07,
47.88,93.92,
47.89,93.77,
47.91,93.62,
47.92,93.47,
47.94,93.32,
47.95,93.17,
47.96,93.02,
47.98,92.87,
47.99,92.72,
48.01,92.57,
48.03,92.42,
48.04,92.27,
48.06,92.12,
48.07,91.97,
48.09,91.83,
48.10,91.67,
48.11,91.53,
48.13,91.38,
48.14,91.22,
48.16,91.08,
48.18,90.93,
48.19,90.78,
48.21,90.62,
48.22,90.47,
48.24,90.33,
48.25,90.18,
48.26,90.03,
48.28,89.88,
48.29,89.72,
48.31,89.58,
48.33,89.43,
48.34,89.28,
48.36,89.13,
48.37,88.98,
48.39,88.83,
48.40,88.68,
48.41,88.53,
48.43,88.38,
48.44,88.23,
48.46,88.08,
48.48,87.93,
48.49,87.78,
48.51,87.63,
48.52,87.48,
48.54,87.33,
48.55,87.18,
48.56,87.03,
48.58,86.88,
48.59,86.73,
48.61,86.58,
48.63,86.43,
48.64,86.28,
48.66,86.13,
48.67,85.98,
48.69,85.83,
48.70,85.68,
48.71,85.53,
48.73,85.38,
48.74,85.23,
48.76,85.08,
48.78,84.93,
48.79,84.78,
48.81,84.63,
48.82,84.48,
48.84,84.33,
48.85,84.18,
48.86,84.03,
48.88,83.88,
48.89,83.73,
48.91,83.58,
48.93,83.43,
48.94,83.28,
48.96,83.13,
48.97,82.98,
48.99,82.83,
49.00,82.68,
49.01,82.53,
49.03,82.38,
49.04,82.23,
49.06,82.08,
49.08,81.93,
49.09,81.78,
49.11,81.63,
49.12,81.48,
49.14,81.33,
49.15,81.18,
49.16,81.03,
49.18,80.88,
49.19,80.73,
49.21,80.58,
49.23,80.43,
49.24,80.29,
49.26,80.14,
49.27,79.98,
49.29,79.84,
49.30,79.69,
49.31,79.53,
49.33,79.39,
49.34,79.24,
49.36,79.09,
49.38,78.94,
49.39,78.79,
49.41,78.63,
49.42,78.49,
49.44,78.34,
49.45,78.19,
49.46,78.04,
49.48,77.89,
49.49,77.74,
49.51,77.59,
49.53,77.44,
49.54,77.29,
49.56,77.14,
49.57,76.99,
49.59,76.84,
49.60,76.69,
49.61,76.54,
49.63,76.39,
49.64,76.24,
49.66,76.09,
49.68,75.94,
49.69,75.79,
49.71,75.64,
49.72,75.49,
49.74,75.34,
49.75,75.19,
49.76,75.04,
49.78,74.89,
49.79,74.74,
49.81,74.59,
49.83,74.44,
49.84,74.29,
49.86,74.14,
49.87,73.99,
49.89,73.84,
49.90,73.69,
49.91,73.54,
49.93,73.39,
49.94,73.24,
49.96,73.09,
49.98,72.94,
49.99,72.79,
50.01,72.64,
50.02,72.49,
50.04,72.34,
50.05,72.19,
50.06,72.05,
50.08,71.89,
50.09,71.75,
50.11,71.60,
50.13,71.44,
50.14,71.30,
50.16,71.15,
50.17,71.00,
50.19,70.85,
50.20,70.70,
50.21,70.55,
50.23,70.40,
50.24,70.25,
50.26,70.10,
50.28,69.95,
50.29,69.80,
50.31,69.65,
50.32,69.50,
50.34,69.35,
50.35,69.20,
50.36,69.05,
50.38,68.90,
50.39,68.75,
50.41,68.60,
50.43,68.45,
50.44,68.30,
50.46,68.15,
50.47,68.00,
50.49,67.85,
50.50,67.70,
50.51,67.55,
50.53,67.40,
50.54,67.25,
50.56,67.10,
50.58,66.95,
50.59,66.80,
50.61,66.65,
50.62,66.50,
50.64,66.35,
50.65,66.20,
50.66,66.05,
50.68,65.90,
50.69,65.75,
50.71,65.60,
50.73,65.45,
50.74,65.30,
50.76,65.15,
50.77,65.00,
50.79,64.85,
50.80,64.70,
50.81,64.55,
50.83,64.40,
50.84,64.25,
50.86,64.10,
50.88,63.95,
50.89,63.80,
50.91,63.65,
50.92,63.50,
50.94,63.35,
50.95,63.20,
50.96,63.05,
50.98,62.90,
50.99,62.75,
51.01,62.60,
51.03,62.45,
51.04,62.30,
51.06,62.15,
51.07,62.00,
51.09,61.86,
51.10,61.71,
51.11,61.56,
51.13,61.41,
51.14,61.26,
51.16,61.11,
51.18,60.96,
51.19,60.81,
51.21,60.66,
51.22,60.51,
51.24,60.36,
51.25,60.21,
51.26,60.06,
51.28,59.91,
51.29,59.76,
51.31,59.61,
51.33,59.46,
51.34,59.31,
51.36,59.16,
51.37,59.01,
51.39,58.86,
51.40,58.71,
51.41,58.56,
51.43,58.41,
51.44,58.26,
51.46,58.11,
51.48,57.96,
51.49,57.81,
51.51,57.66,
51.52,57.51,
51.54,57.36,
51.55,57.21,
51.56,57.06,
51.58,56.91,
51.59,56.76,
51.61,56.61,
51.63,56.46,
51.64,56.31,
51.66,56.16,
51.67,56.01,
51.69,55.86,
51.70,55.71,
51.71,55.56,
51.73,55.41,
51.74,55.26,
51.76,55.11,
51.78,54.96,
51.79,54.81,
51.81,54.66,
51.82,54.51,
51.84,54.36,
51.85,54.21,
51.86,54.06,
51.88,53.91,
51.89,53.76,
51.91,53.61,
51.93,53.46,
51.94,53.31,
51.96,53.16,
51.97,53.02,
51.99,52.86,
52.00,52.72,
52.01,52.57,
52.03,52.42,
52.04,52.26,
52.06,52.12,
52.08,51.97,
52.09,51.82,
52.11,51.67,
52.12,51.52,
52.14,51.37,
52.15,51.22,
52.16,51.07,
52.18,50.92,
52.19,50.77,
52.21,50.62,
52.23,50.47,
52.24,50.32,
52.26,50.17,
52.27,50.02,
52.29,49.87,
52.30,49.72,
52.31,49.57,
52.33,49.42,
52.34,49.27,
52.36,49.12,
52.38,48.97,
52.39,48.82,
52.41,48.67,
52.42,48.52,
52.44,48.37,
52.45,48.22,
52.46,48.07,
52.48,47.92,
52.49,47.77,
52.51,47.62,
52.53,47.47,
52.54,47.32,
52.56,47.17,
52.57,47.02,
52.59,46.87,
52.60,46.72,
52.61,46.57,
52.63,46.42,
52.64,46.27,
52.66,46.12,
52.68,45.97,
52.69,45.82,
52.71,45.67,
52.72,45.52,
52.74,45.37,
52.75,45.22,
52.76,45.07,
52.78,44.92,
52.79,44.77,
52.81,44.62,
52.83,44.47,
52.84,44.32,
52.86,44.17,
52.87,44.03,
52.89,43.87,
52.90,43.73,
52.91,43.57,
52.93,43.43,
52.94,43.27,
52.96,43.13,
52.98,42.98,
52.99,42.83,
53.01,42.68,
53.02,42.53,
53.04,42.38,
53.05,42.23,
53.06,42.08,
53.08,41.93,
53.09,41.78,
53.11,41.63,
53.13,41.48,
53.14,41.33,
53.16,41.18,
53.17,41.03,
53.19,40.88,
53.20,40.73,
53.21,40.58,
53.23,40.43,
53.24,40.28,
53.26,40.13,
53.28,39.98,
53.29,39.83,
53.31,39.68,
53.32,39.53,
53.34,39.38,
53.35,39.23,
53.36,39.08,
53.38,38.93,
53.39,38.78,
53.41,38.63,
53.43,38.48,
53.44,38.33,
53.46,38.18,
53.47,38.03,
53.49,37.88,
53.50,37.73,
53.51,37.58,
53.53,37.43,
53.54,37.28,
53.56,37.13,
53.58,36.98,
53.59,36.83,
53.61,36.68,
53.62,36.53,
53.64,36.38,
53.65,36.23,
53.66,36.08,
53.68,35.93,
53.69,35.78,
53.71,35.63,
53.73,35.48,
53.74,35.33,
53.76,35.18,
53.77,35.03,
53.79,34.88,
53.80,34.73,
53.81,34.58,
53.83,34.43,
53.84,34.28,
53.86,34.13,
53.88,33.98,
53.89,33.83,
53.91,33.68,
53.92,33.53,
53.94,33.38,
53.95,33.24,
53.96,33.09,
53.98,32.94,
53.99,32.79,
54.01,32.64,
54.03,32.49,
54.04,32.34,
54.06,32.19,
54.07,32.04,
54.09,31.89,
54.10,31.74,
54.11,31.59,
54.13,31.44,
54.14,31.29,
54.16,31.14,
54.18,30.99,
54.19,30.84,
54.21,30.69,
54.22,30.54,
54.24,30.39,
54.25,30.24,
54.26,30.09,
54.28,29.94,
54.29,29.79,
54.31,29.64,
54.33,29.49,
54.34,29.34,
54.36,29.19,
54.37,29.04,
54.39,28.89,
54.40,28.74,
54.41,28.59,
54.43,28.44,
54.44,28.29,
54.46,28.14,
54.48,27.99,
54.49,27.84,
54.51,27.69,
54.52,27.54,
54.54,27.39,
54.55,27.24,
54.56,27.09,
54.58,26.95,
54.59,26.79,
54.61,26.65,
54.63,26.50,
54.64,26.34,
54.66,26.20,
54.67,26.05,
54.69,25.90,
54.70,25.75,
54.71,25.60,
54.73,25.45,
54.74,25.30,
54.76,25.15,
54.78,25.00,
54.79,24.85,
54.81,24.70,
54.82,24.55,
54.84,24.40,
54.85,24.25,
54.86,24.10,
54.88,23.95,
54.89,23.80,
54.91,23.65,
54.93,23.50,
54.94,23.35,
54.96,23.20,
54.97,23.05,
54.99,22.90,
55.00,22.75,
55.01,22.60,
55.03,22.45,
55.04,22.30,
55.06,22.15,
55.08,22.00,
55.09,21.85,
55.11,21.70,
55.12,21.55,
55.14,21.40,
55.15,21.25,
55.16,21.10,
55.18,20.95,
55.19,20.80,
55.21,20.65,
55.23,20.50,
55.24,20.35,
55.26,20.20,
55.27,20.05,
55.29,19.90,
55.30,19.75,
55.31,19.60,
55.33,19.45,
55.34,19.30,
55.36,19.15,
55.38,19.00,
55.39,18.85,
55.41,18.70,
55.42,18.55,
55.44,18.41,
55.45,18.25,
55.46,18.11,
55.48,17.96,
55.49,17.81,
55.51,17.66,
55.53,17.51,
55.54,17.36,
55.56,17.21,
55.57,17.06,
55.59,16.91,
55.60,16.76,
55.61,16.61,
55.63,16.46,
55.64,16.31,
55.66,16.16,
55.68,16.01,
55.69,15.86,
55.71,15.71,
55.72,15.56,
55.74,15.41,
55.75,15.26,
55.76,15.11,
55.78,14.96,
55.79,14.81,
55.81,14.66,
55.83,14.51,
55.84,14.36,
55.86,14.21,
55.87,14.06,
55.89,13.91,
55.90,13.76,
55.91,13.61,
55.93,13.46,
55.94,13.31,
55.96,13.16,
55.98,13.01,
55.99,12.86,
56.01,12.71,
56.02,12.56,
56.04,12.41,
56.05,12.26,
56.06,12.11,
56.08,11.97,
56.09,11.82,
56.11,11.67,
56.13,11.52,
56.14,11.37,
56.16,11.22,
56.17,11.07,
56.19,10.92,
56.20,10.77,
56.21,10.62,
56.23,10.47,
56.24,10.32,
56.26,10.17,
56.28,10.02,
56.29,9.87,
56.31,9.72,
56.32,9.57,
56.34,9.42,
56.35,9.27,
56.36,9.12,
56.38,8.97,
56.39,8.82,
56.41,8.67,
56.43,8.52,
56.44,8.37,
56.46,8.22,
56.47,8.07,
56.49,7.92,
56.50,7.77,
56.51,7.62,
56.53,7.48,
56.54,7.32,
56.56,7.17,
56.58,7.02,
56.59,6.88,
56.61,6.73,
56.62,6.58,
56.64,6.43,
56.65,6.28,
56.66,6.13,
56.68,5.98,
56.69,5.83,
56.71,5.68,
56.73,5.53,
56.74,5.38,
56.76,5.23,
56.77,5.08,
56.79,4.93,
56.80,4.78,
56.81,4.63,
56.83,4.48,
56.84,4.33,
56.86,4.18,
56.88,4.03,
56.89,3.88,
56.91,3.73,
56.92,3.58,
56.94,3.43,
56.95,3.28,
56.96,3.13,
56.98,2.98,
56.99,2.83,
57.01,2.68,
57.03,2.53,
57.04,2.38,
57.06,2.23,
57.07,2.08,
57.09,1.93,
57.10,1.78,
57.11,1.63,
57.13,1.48,
57.14,1.33,
57.16,1.18,
57.18,1.03,
57.19,0.88,
57.21,0.73,
57.22,0.58,
57.24,0.43,
57.25,0.28,
57.26,0.13,
57.28,-0.02,
57.29,-0.17,
57.31,-0.32,
57.33,-0.47,
57.34,-0.62,
57.36,-0.77,
57.37,-0.92,
57.39,-1.07,
57.40,-1.22,
57.41,-1.37,
57.43,-1.52,
57.44,-1.67,
57.46,-1.82,
57.48,-1.97,
57.49,-2.12,
57.51,-2.27,
57.52,-2.42,
57.54,-2.57,
57.55,-2.72,
57.56,-2.87,
57.58,-3.02,
57.59,-3.17,
57.61,-3.32,
57.63,-3.47,
57.64,-3.62,
57.66,-3.77,
57.67,-3.92,
57.69,-4.07,
57.70,-4.23,
57.71,-4.37,
57.73,-4.53,
57.74,-4.67,
57.76,-4.82,
57.78,-4.98,
57.79,-5.13,
57.81,-5.28,
57.82,-5.43,
57.84,-5.58,
57.85,-5.73,
57.86,-5.88,
57.88,-6.03,
57.89,-6.18,
57.91,-6.33,
57.93,-6.48,
57.94,-6.63,
57.96,-6.78,
57.97,-6.93,
57.99,-7.08,
58.00,-7.23,
58.01,-7.38,
58.03,-7.53,
58.04,-7.68,
58.06,-7.83,
58.08,-7.98,
58.09,-8.13,
58.11,-8.28,
58.12,-8.43,
58.14,-8.58,
58.15,-8.73,
[...]
133.63,-33.54,,-0.052
133.64,-33.48,,-0.052
133.65,-33.41,,-0.052
133.67,-33.34,,-0.052
133.68,-33.28,,-0.052
133.69,-33.21,,-0.052
133.71,-33.14,,-0.052
133.72,-33.08,,-0.052
133.73,-33.01,,-0.052
133.75,-32.94,,-0.052
133.76,-32.87,,-0.052
133.77,-32.81,,-0.052
133.79,-32.74,,-0.052
133.80,-32.67,,-0.052
133.81,-32.61,,-0.052
133.83,-32.54,,-0.052
133.84,-32.48,,-0.052
133.85,-32.41,,-0.052
133.87,-32.34,,-0.052
133.88,-32.28,,-0.053
133.89,-32.21,,-0.053
133.91,-32.14,,-0.053
133.92,-32.08,,-0.053
133.93,-32.01,,-0.053
133.95,-31.94,,-0.053
133.96,-31.88,,-0.053
133.97,-31.81,,-0.054
133.99,-31.75,,-0.053
134.00,-31.68,,-0.054
134.01,-31.61,,-0.054
134.03,-31.55,,-0.054
134.04,-31.48,,-0.054
134.05,-31.41,,-0.054
134.07,-31.35,,-0.054
134.08,-31.28,,-0.054
134.09,-31.21,,-0.054
134.11,-31.15,,-0.054
134.12,-31.08,,-0.054
134.13,-31.01,,-0.055
134.15,-30.94,,-0.054
134.16,-30.88,,-0.055
134.17,-30.81,,-0.055
134.19,-30.74,,-0.055
134.20,-30.68,,-0.055
134.21,-30.61,,-0.055
134.23,-30.54,,-0.055
134.24,-30.48,,-0.055
134.25,-30.41,,-0.055
134.27,-30.34,,-0.055
134.28,-30.28,,-0.055
134.29,-30.21,,-0.055
134.31,-30.14,,-0.055
134.32,-30.08,,-0.055
134.33,-30.01,,-0.055
134.35,-29.94,,-0.055
134.36,-29.88,,-0.055
134.37,-29.81,,-0.055
134.39,-29.74,,-0.055
134.40,-29.67,,-0.056
134.41,-29.61,,-0.056
134.43,-29.54,,-0.056
134.44,-29.47,,-0.056
134.45,-29.41,,-0.056
134.47,-29.34,,-0.056
134.48,-29.27,,-0.056
134.49,-29.21,,-0.056
134.51,-29.14,,-0.056
134.52,-29.07,,-0.056
134.53,-29.01,,-0.056
134.55,-28.94,,-0.055
134.56,-28.87,,-0.056
134.57,-28.80,,-0.056
134.59,-28.74,,-0.056
134.60,-28.67,,-0.056
134.61,-28.61,,-0.056
134.63,-28.54,,-0.056
134.64,-28.47,,-0.056
134.65,-28.40,,-0.056
134.67,-28.34,,-0.057
134.68,-28.27,,-0.056
134.69,-28.20,,-0.057
134.71,-28.14,,-0.056
134.72,-28.07,,-0.057
134.73,-28.00,,-0.057
134.75,-27.94,,-0.057
134.76,-27.87,,-0.056
134.77,-27.80,,-0.058
134.79,-27.74,,-0.058
134.80,-27.67,,-0.058
134.81,-27.60,,-0.058
134.83,-27.54,,-0.058
134.84,-27.47,,-0.058
134.85,-27.40,,-0.058
134.87,-27.34,,-0.058
134.88,-27.27,,-0.058
134.89,-27.20,,-0.058
134.91,-27.14,,-0.058
134.92,-27.07,,-0.058
134.93,-27.00,,-0.058
134.95,-26.94,,-0.058
134.96,-26.87,,-0.058
134.97,-26.80,,-0.058
134.99,-26.74,,-0.058
135.00,-26.67,,-0.058
135.01,-26.60,,-0.058
135.03,-26.54,,-0.058
135.04,-26.47,,-0.058
135.05,-26.40,,-0.058
135.07,-26.34,,-0.058
135.08,-26.27,,-0.058
135.09,-26.20,,-0.058
135.11,-26.13,,-0.058
135.12,-26.07,,-0.059
135.13,-26.00,,-0.059
135.15,-25.94,,-0.059
135.16,-25.87,,-0.059
135.17,-25.80,,-0.059
135.19,-25.74,,-0.059
135.20,-25.67,,-0.059
135.21,-25.60,,-0.059
135.23,-25.53,,-0.059
135.24,-25.47,,-0.059
135.25,-25.40,,-0.059
135.27,-25.34,,-0.059
135.28,-25.27,,-0.059
135.29,-25.20,,-0.059
135.31,-25.14,,-0.059
135.32,-25.07,,-0.060
135.33,-25.00,,-0.060
135.35,-24.94,,-0.060
135.36,-24.87,,-0.060
135.37,-24.80,,-0.060
135.39,-24.73,,-0.060
135.40,-24.67,,-0.060
135.41,-24.60,,-0.061
135.43,-24.53,,-0.061
135.44,-24.47,,-0.061
135.45,-24.40,,-0.061
135.47,-24.34,,-0.061
135.48,-24.27,,-0.061
135.49,-24.20,,-0.061
135.51,-24.13,,-0.061
135.52,-24.07,,-0.061
135.53,-24.00,,-0.062
135.55,-23.93,,-0.062
135.56,-23.87,,-0.062
135.57,-23.80,,-0.062
135.59,-23.73,,-0.062
135.60,-23.67,,-0.062
135.61,-23.60,,-0.062
135.63,-23.53,,-0.062
135.64,-23.47,,-0.062
135.65,-23.40,,-0.062
135.67,-23.33,,-0.062
135.68,-23.27,,-0.063
135.69,-23.20,,-0.063
135.71,-23.13,,-0.063
135.72,-23.07,,-0.063
135.73,-23.00,,-0.063
135.75,-22.93,,-0.063
135.76,-22.87,,-0.063
135.77,-22.80,,-0.063
135.79,-22.73,,-0.063
135.80,-22.66,,-0.063
135.81,-22.60,,-0.063
135.83,-22.53,,-0.063
135.84,-22.47,,-0.063
135.85,-22.40,,-0.063
135.87,-22.33,,-0.064
135.88,-22.27,,-0.064
135.89,-22.20,,-0.064
135.91,-22.13,,-0.064
135.92,-22.07,,-0.064
135.93,-22.00,,-0.064
135.95,-21.93,,-0.064
135.96,-21.86,,-0.064
135.97,-21.80,,-0.064
135.99,-21.73,,-0.064
136.00,-21.66,,-0.064
136.01,-21.60,,-0.064
136.03,-21.53,,-0.064
136.04,-21.46,,-0.064
136.05,-21.40,,-0.064
136.07,-21.33,,-0.064
136.08,-21.26,,-0.064
136.09,-21.20,,-0.064
136.11,-21.13,,-0.064
136.12,-21.06,,-0.065
136.13,-21.00,,-0.065
136.15,-20.93,,-0.065
136.16,-20.86,,-0.065
136.17,-20.80,,-0.065
136.19,-20.73,,-0.065
136.20,-20.66,,-0.065
136.21,-20.60,,-0.065
136.23,-20.53,,-0.065
136.24,-20.46,,-0.065
136.25,-20.40,,-0.065
136.27,-20.33,,-0.065
136.28,-20.26,,-0.065
136.29,-20.20,,-0.065
136.31,-20.13,,-0.065
136.32,-20.06,,-0.065
136.33,-19.99,,-0.065
136.35,-19.93,,-0.065
136.36,-19.86,,-0.065
136.37,-19.80,,-0.065
136.39,-19.73,,-0.065
136.40,-19.66,,-0.065
136.41,-19.60,,-0.066
136.43,-19.53,,-0.065
136.44,-19.46,,-0.065
136.45,-19.40,,-0.065
136.47,-19.33,,-0.065
136.48,-19.26,,-0.065
136.49,-19.20,,-0.065
136.51,-19.13,,-0.066
136.52,-19.06,,-0.066
136.53,-19.00,,-0.066
136.55,-18.93,,-0.066
136.56,-18.86,,-0.066
136.57,-18.79,,-0.066
136.59,-18.73,,-0.066
136.60,-18.66,,-0.066
136.61,-18.60,,-0.066
136.63,-18.53,,-0.066
136.64,-18.46,,-0.066
136.65,-18.40,,-0.066
136.67,-18.33,,-0.066
136.68,-18.26,,-0.066
136.69,-18.19,,-0.066
136.71,-18.13,,-0.066
136.72,-18.06,,-0.066
136.73,-17.99,,-0.066
136.75,-17.93,,-0.066
136.76,-17.86,,-0.066
136.77,-17.79,,-0.066
136.79,-17.73,,-0.067
136.80,-17.66,,-0.066
136.81,-17.59,,-0.067
136.83,-17.53,,-0.066
136.84,-17.46,,-0.066
136.85,-17.39,,-0.067
136.87,-17.33,,-0.067
136.88,-17.26,,-0.067
136.89,-17.19,,-0.067
136.91,-17.13,,-0.067
136.92,-17.06,,-0.067
136.93,-16.99,,-0.068
136.95,-16.93,,-0.068
136.96,-16.86,,-0.068
136.97,-16.79,,-0.068
136.99,-16.73,,-0.068
137.00,-16.66,,-0.068
137.01,-16.59,,-0.068
137.03,-16.53,,-0.068
137.04,-16.46,,-0.068
137.05,-16.39,,-0.068
137.07,-16.33,,-0.068
137.08,-16.26,,-0.068
137.09,-16.19,,-0.068
137.11,-16.13,,-0.068
137.12,-16.06,,-0.068
137.13,-15.99,,-0.068
137.15,-15.93,,-0.068
137.16,-15.86,,-0.068
137.17,-15.79,,-0.069
137.19,-15.73,,-0.069
137.20,-15.66,,-0.069
137.21,-15.59,,-0.069
137.23,-15.53,,-0.069
137.24,-15.46,,-0.069
137.25,-15.39,,-0.069
137.27,-15.32,,-0.069
137.28,-15.26,,-0.069
137.29,-15.19,,-0.069
137.31,-15.13,,-0.069
137.32,-15.06,,-0.069
137.33,-14.99,,-0.069
137.35,-14.92,,-0.069
137.36,-14.86,,-0.069
137.37,-14.79,,-0.070
137.39,-14.72,,-0.070
137.40,-14.66,,-0.070
137.41,-14.59,,-0.070
137.43,-14.52,,-0.071
137.44,-14.45,,-0.071
137.45,-14.39,,-0.070
137.47,-14.32,,-0.071
137.48,-14.25,,-0.071
137.49,-14.18,,-0.070
137.51,-14.12,,-0.070
137.52,-14.05,,-0.070
137.53,-13.99,,-0.070
137.55,-13.92,,-0.070
137.56,-13.85,,-0.070
137.57,-13.78,,-0.070
137.59,-13.72,,-0.070
137.60,-13.65,,-0.070
137.61,-13.59,,-0.070
137.63,-13.52,,-0.070
137.64,-13.45,,-0.070
137.65,-13.39,,-0.070
137.67,-13.32,,-0.070
137.68,-13.25,,-0.070
137.69,-13.19,,-0.070
137.71,-13.12,,-0.070
137.72,-13.05,,-0.070
137.73,-12.99,,-0.070
137.75,-12.92,,-0.070
137.76,-12.85,,-0.071
137.77,-12.79,,-0.070
137.79,-12.72,,-0.071
137.80,-12.65,,-0.071
137.81,-12.59,,-0.071
137.83,-12.52,,-0.071
137.84,-12.45,,-0.071
137.85,-12.39,,-0.071
137.87,-12.32,,-0.071
137.88,-12.25,,-0.071
137.89,-12.19,,-0.071
137.91,-12.12,,-0.071
137.92,-12.05,,-0.071
137.93,-11.99,,-0.071
137.95,-11.92,,-0.071
137.96,-11.85,,-0.071
137.97,-11.79,,-0.072
137.99,-11.72,,-0.072
138.00,-11.65,,-0.072
138.01,-11.59,,-0.072
138.03,-11.52,,-0.072
138.04,-11.46,,-0.072
138.05,-11.39,,-0.072
138.07,-11.32,,-0.072
138.08,-11.25,,-0.072
138.09,-11.19,,-0.072
138.11,-11.12,,-0.072
138.12,-11.06,,-0.072
138.13,-10.99,,-0.072
138.15,-10.92,,-0.072
138.16,-10.85,,-0.072
138.17,-10.79,,-0.073
138.19,-10.72,,-0.073
138.20,-10.66,,-0.073
138.21,-10.59,,-0.073
138.23,-10.52,,-0.073
138.24,-10.45,,-0.073
138.25,-10.39,,-0.073
138.27,-10.32,,-0.073
138.28,-10.26,,-0.073
138.29,-10.19,,-0.073
138.31,-10.12,,-0.073
138.32,-10.05,,-0.073
138.33,-9.99,,-0.073
138.35,-9.92,,-0.074
138.36,-9.86,,-0.074
138.37,-9.79,,-0.074
138.39,-9.72,,-0.074
138.40,-9.66,,-0.074
138.41,-9.59,,-0.074
138.43,-9.52,,-0.074
138.44,-9.46,,-0.074
138.45,-9.39,,-0.074
138.47,-9.32,,-0.074
138.48,-9.25,,-0.074
138.49,-9.19,,-0.074
138.51,-9.12,,-0.074
138.52,-9.05,,-0.074
138.53,-8.99,,-0.074
138.55,-8.92,,-0.074
138.56,-8.85,,-0.074
138.57,-8.79,,-0.074
138.59,-8.72,,-0.074
138.60,-8.65,,-0.074
138.61,-8.59,,-0.074
138.63,-8.52,,-0.075
138.64,-8.45,,-0.074
138.65,-8.39,,-0.075
138.67,-8.32,,-0.075
138.68,-8.25,,-0.075
138.69,-8.19,,-0.075
138.71,-8.12,,-0.075
138.72,-8.05,,-0.075
138.73,-7.99,,-0.075
138.75,-7.92,,-0.075
138.76,-7.85,,-0.075
138.77,-7.79,,-0.075
138.79,-7.72,,-0.075
138.80,-7.65,,-0.075
138.81,-7.59,,-0.075
138.83,-7.52,,-0.075
138.84,-7.45,,-0.075
138.85,-7.39,,-0.075
138.87,-7.32,,-0.075
138.88,-7.25,,-0.075
138.89,-7.18,,-0.075
138.91,-7.12,,-0.075
138.92,-7.05,,-0.075
138.93,-6.99,,-0.075
138.95,-6.92,,-0.075
138.96,-6.85,,-0.075
138.97,-6.79,,-0.075
138.99,-6.72,,-0.075
139.00,-6.65,,-0.075
139.01,-6.58,,-0.075
139.03,-6.52,,-0.075
139.04,-6.45,,-0.075
139.05,-6.38,,-0.075
139.07,-6.32,,-0.075
139.08,-6.25,,-0.075
139.09,-6.19,,-0.075
139.11,-6.12,,-0.075
139.12,-6.05,,-0.075
139.13,-5.99,,-0.075
139.15,-5.92,,-0.075
139.16,-5.85,,-0.075
139.17,-5.79,,-0.075
139.19,-5.72,,-0.077
139.20,-5.65,,-0.076
139.21,-5.59,,-0.076
139.23,-5.52,,-0.076
139.24,-5.45,,-0.076
139.25,-5.39,,-0.076
139.27,-5.32,,-0.076
139.28,-5.25,,-0.076
139.29,-5.19,,-0.076
139.31,-5.12,,-0.076
139.32,-5.05,,-0.076
139.33,-4.99,,-0.077
139.35,-4.92,,-0.077
139.36,-4.85,,-0.077
139.37,-4.79,,-0.077
139.39,-4.72,,-0.077
139.40,-4.65,,-0.077
139.41,-4.58,,-0.077
139.43,-4.52,,-0.077
139.44,-4.45,,-0.077
139.45,-4.38,,-0.077
139.47,-4.32,,-0.077
139.48,-4.25,,-0.077
139.49,-4.18,,-0.077
139.51,-4.12,,-0.077
139.52,-4.05,,-0.077
139.53,-3.98,,-0.077
139.55,-3.92,,-0.077
139.56,-3.85,,-0.077
139.57,-3.78,,-0.077
139.59,-3.72,,-0.077
139.60,-3.65,,-0.077
139.61,-3.58,,-0.077
139.63,-3.52,,-0.077
139.64,-3.45,,-0.077
139.65,-3.38,,-0.077
139.67,-3.32,,-0.077
139.68,-3.25,,-0.077
139.69,-3.18,,-0.077
139.71,-3.12,,-0.077
139.72,-3.05,,-0.077
139.73,-2.98,,-0.077
139.75,-2.92,,-0.077
139.76,-2.85,,-0.077
139.77,-2.78,,-0.077
139.79,-2.72,,-0.077
139.80,-2.65,,-0.077
139.81,-2.58,,-0.077
139.83,-2.52,,-0.077
139.84,-2.45,,-0.077
139.85,-2.38,,-0.077
139.87,-2.32,,-0.077
139.88,-2.25,,-0.077
139.89,-2.18,,-0.077
139.91,-2.12,,-0.077
139.92,-2.05,,-0.077
139.93,-1.98,,-0.078
139.95,-1.91,,-0.077
139.96,-1.85,,-0.078
139.97,-1.78,,-0.077
139.99,-1.72,,-0.077
140.00,-1.65,,-0.077
140.01,-1.58,,-0.078
140.03,-1.51,,-0.078
140.04,-1.45,,-0.077
140.05,-1.38,,-0.078
140.07,-1.31,,-0.078
140.08,-1.25,,-0.077
140.09,-1.18,,-0.078
140.11,-1.11,,-0.078
140.12,-1.05,,-0.078
140.13,-0.98,,-0.078
140.15,-0.91,,-0.078
140.16,-0.85,,-0.078
140.17,-0.78,,-0.078
140.19,-0.71,,-0.078
140.20,-0.65,,-0.078
140.21,-0.58,,-0.078
140.23,-0.51,,-0.078
140.24,-0.45,,-0.078
140.25,-0.38,,-0.078
140.27,-0.31,,-0.078
140.28,-0.24,,-0.078
140.29,-0.18,,-0.078
140.31,-0.11,,-0.078
140.32,-0.04,,-0.078
140.33,0.02,,-0.078
140.35,0.09,,-0.078
140.36,0.15,,-0.078
140.37,0.22,,-0.078
140.39,0.29,,-0.079
140.40,0.35,,-0.078
140.41,0.42,,-0.079
140.43,0.49,,-0.079
140.44,0.55,,-0.079
140.45,0.62,,-0.079
140.47,0.69,,-0.079
140.48,0.75,,-0.079
140.49,0.82,,-0.079
140.51,0.89,,-0.079
140.52,0.95,,-0.078
140.53,1.02,,-0.079
140.55,1.09,,-0.079
140.56,1.15,,-0.079
140.57,1.22,,-0.079
140.59,1.29,,-0.079
140.60,1.35,,-0.078
140.61,1.42,,-0.079
140.63,1.49,,-0.079
140.64,1.56,,-0.079
140.65,1.62,,-0.079
140.67,1.69,,-0.079
140.68,1.75,,-0.079
140.69,1.82,,-0.079
140.71,1.89,,-0.079
140.72,1.96,,-0.079
140.73,2.02,,-0.079
140.75,2.09,,-0.079
140.76,2.16,,-0.079
140.77,2.22,,-0.079
140.79,2.29,,-0.079
140.80,2.35,,-0.079
140.81,2.42,,-0.080
140.83,2.49,,-0.080
140.84,2.56,,-0.080
140.85,2.62,,-0.080
140.87,2.69,,-0.080
140.88,2.75,,-0.079
140.89,2.82,,-0.079
140.91,2.89,,-0.080
140.92,2.95,,-0.080
140.93,3.02,,-0.080
140.95,3.09,,-0.080
140.96,3.15,,-0.080
140.97,3.22,,-0.080
140.99,3.29,,-0.080
141.00,3.36,,-0.080
141.01,3.42,,-0.080
141.03,3.49,,-0.080
141.04,3.56,,-0.080
141.05,3.62,,-0.080
141.07,3.69,,-0.080
141.08,3.76,,-0.080
141.09,3.82,,-0.080
141.11,3.89,,-0.080
141.12,3.96,,-0.080
141.13,4.02,,-0.080
141.15,4.09,,-0.080
141.16,4.16,,-0.080
141.17,4.22,,-0.080
141.19,4.29,,-0.080
141.20,4.36,,-0.080
141.21,4.42,,-0.080
141.23,4.49,,-0.080
141.24,4.56,,-0.080
141.25,4.62,,-0.080
141.27,4.69,,-0.080
141.28,4.76,,-0.080
141.29,4.82,,-0.080
141.31,4.89,,-0.080
141.32,4.96,,-0.080
141.33,5.02,,-0.080
141.35,5.09,,-0.080
141.36,5.16,,-0.080
141.37,5.22,,-0.080
141.39,5.29,,-0.081
141.40,5.36,,-0.081
141.41,5.42,,-0.081
141.43,5.49,,-0.081
141.44,5.56,,-0.081
141.45,5.62,,-0.080
141.47,5.69,,-0.081
141.48,5.76,,-0.081
141.49,5.82,,-0.080
141.51,5.89,,-0.080
141.52,5.96,,-0.081
141.53,6.02,,-0.081
141.55,6.09,,-0.081
141.56,6.16,,-0.081
141.57,6.22,,-0.081
141.59,6.29,,-0.081
141.60,6.36,,-0.081
141.61,6.42,,-0.081
141.63,6.49,,-0.081
141.64,6.56,,-0.081
141.65,6.63,,-0.081
141.67,6.69,,-0.081
141.68,6.76,,-0.081
141.69,6.83,,-0.081
141.71,6.89,,-0.081
141.72,6.96,,-0.081
141.73,7.03,,-0.081
141.75,7.09,,-0.082
141.76,7.16,,-0.081
141.77,7.23,,-0.082
141.79,7.29,,-0.082
141.80,7.36,,-0.081
141.81,7.42,,-0.081
141.83,7.49,,-0.081
141.84,7.56,,-0.081
141.85,7.63,,-0.081
141.87,7.69,,-0.081
141.88,7.76,,-0.082
141.89,7.83,,-0.082
141.91,7.89,,-0.082
141.92,7.96,,-0.082
141.93,8.03,,-0.082
141.95,8.09,,-0.082
141.96,8.16,,-0.082
141.97,8.23,,-0.082
141.99,8.29,,-0.082
142.00,8.36,,-0.082
142.01,8.43,,-0.082
142.03,8.49,,-0.082
142.04,8.56,,-0.082
142.05,8.63,,-0.082
142.07,8.69,,-0.082
142.08,8.76,,-0.082
142.09,8.83,,-0.082
142.11,8.89,,-0.082
142.12,8.96,,-0.082
142.13,9.03,,-0.082
142.15,9.09,,-0.082
142.16,9.16,,-0.082
142.17,9.23,,-0.082
142.19,9.29,,-0.082
142.20,9.36,,-0.082
142.21,9.43,,-0.082
142.23,9.50,,-0.082
142.24,9.56,,-0.082
142.25,9.63,,-0.082
142.27,9.70,,-0.082
142.28,9.76,,-0.083
142.29,9.83,,-0.082
142.31,9.89,,-0.083
142.32,9.96,,-0.082
142.33,10.03,,-0.082
142.35,10.10,,-0.082
142.36,10.16,,-0.082
142.37,10.23,,-0.082
142.39,10.30,,-0.083
142.40,10.36,,-0.083
142.41,10.43,,-0.082
142.43,10.50,,-0.082
142.44,10.56,,-0.082
142.45,10.63,,-0.083
142.47,10.70,,-0.083
142.48,10.76,,-0.082
142.49,10.83,,-0.082
142.51,10.90,,-0.083
142.52,10.96,,-0.083
142.53,11.03,,-0.082
142.55,11.10,,-0.083
142.56,11.16,,-0.083
142.57,11.23,,-0.083
142.59,11.30,,-0.083
142.60,11.36,,-0.083
142.61,11.43,,-0.083
142.63,11.50,,-0.083
142.64,11.56,,-0.083
142.65,11.63,,-0.083
142.67,11.70,,-0.083
142.68,11.76,,-0.083
142.69,11.83,,-0.083
142.71,11.90,,-0.083
142.72,11.96,,-0.083
142.73,12.03,,-0.083
142.75,12.10,,-0.083
142.76,12.16,,-0.083
142.77,12.23,,-0.083
142.79,12.30,,-0.083
142.80,12.36,,-0.083
142.81,12.43,,-0.083
142.83,12.49,,-0.083
142.84,12.56,,-0.083
142.85,12.63,,-0.084
142.87,12.70,,-0.084
142.88,12.76,,-0.084
142.89,12.83,,-0.084
142.91,12.90,,-0.084
142.92,12.96,,-0.084
142.93,13.03,,-0.084
142.95,13.10,,-0.084
142.96,13.16,,-0.084
142.97,13.23,,-0.084
142.99,13.30,,-0.084
143.00,13.36,,-0.084
143.01,13.43,,-0.084
143.03,13.50,,-0.084
143.04,13.56,,-0.084
143.05,13.63,,-0.084
143.07,13.70,,-0.084
143.08,13.76,,-0.084
143.09,13.83,,-0.084
143.11,13.90,,-0.084
143.12,13.96,,-0.084
143.13,14.03,,-0.084
143.15,14.10,,-0.084
143.16,14.17,,-0.084
143.17,14.23,,-0.084
143.19,14.30,,-0.084
143.20,14.36,,-0.084
143.21,14.43,,-0.084
143.23,14.50,,-0.084
143.24,14.56,,-0.084
143.25,14.63,,-0.084
143.27,14.70,,-0.084
143.28,14.77,,-0.084
143.29,14.83,,-0.085
143.31,14.90,,-0.085
143.32,14.97,,-0.085
143.33,15.03,,-0.084
143.35,15.10,,-0.084
143.36,15.17,,-0.084
143.37,15.23,,-0.085
143.39,15.30,,-0.085
143.40,15.37,,-0.085
143.41,15.43,,-0.085
143.43,15.50,,-0.085
143.44,15.56,,-0.085
143.45,15.63,,-0.085
143.47,15.70,,-0.085
143.48,15.76,,-0.086
143.49,15.83,,-0.086
143.51,15.90,,-0.086
143.52,15.96,,-0.086
143.53,16.03,,-0.086
143.55,16.10,,-0.086
143.56,16.17,,-0.087
143.57,16.23,,-0.087
143.59,16.30,,-0.087
143.60,16.37,,-0.087
143.61,16.43,,-0.087
143.63,16.50,,-0.087
143.64,16.57,,-0.087
143.65,16.63,,-0.087
143.67,16.70,,-0.087
143.68,16.77,,-0.087
143.69,16.83,,-0.087
143.71,16.90,,-0.087
143.72,16.97,,-0.087
143.73,17.03,,-0.087
143.75,17.10,,-0.087
143.76,17.17,,-0.087
143.77,17.23,,-0.086
143.79,17.30,,-0.086
143.80,17.37,,-0.086
143.81,17.44,,-0.086
143.83,17.50,,-0.086
143.84,17.57,,-0.086
143.85,17.63,,-0.086
143.87,17.70,,-0.086
143.88,17.77,,-0.086
143.89,17.83,,-0.086
143.91,17.90,,-0.086
143.92,17.97,,-0.086
143.93,18.03,,-0.086
143.95,18.10,,-0.086
143.96,18.17,,-0.086
143.97,18.23,,-0.086
143.99,18.30,,-0.086
144.00,18.37,,-0.086
144.01,18.43,,-0.086
144.03,18.50,,-0.085
144.04,18.57,,-0.086
144.05,18.63,,-0.085
144.07,18.70,,-0.086
144.08,18.77,,-0.085
144.09,18.83,,-0.086
144.11,18.90,,-0.086
144.12,18.97,,-0.086
144.13,19.03,,-0.086
144.15,19.10,,-0.086
144.16,19.17,,-0.086
144.17,19.23,,-0.086
144.19,19.30,,-0.086
144.20,19.37,,-0.086
144.21,19.44,,-0.086
144.23,19.50,,-0.086
144.24,19.57,,-0.086
144.25,19.64,,-0.086
144.27,19.70,,-0.086
144.28,19.77,,-0.086
144.29,19.84,,-0.086
144.31,19.90,,-0.086
144.32,19.97,,-0.086
144.33,20.04,,-0.086
144.35,20.10,,-0.086
144.36,20.17,,-0.086
144.37,20.24,,-0.086
144.39,20.30,,-0.086
144.40,20.37,,-0.086
144.41,20.44,,-0.086
144.43,20.50,,-0.086
144.44,20.57,,-0.086
144.45,20.64,,-0.086
144.47,20.70,,-0.086
144.48,20.77,,-0.086
144.49,20.84,,-0.086
144.51,20.90,,-0.086
144.52,20.97,,-0.086
144.53,21.04,,-0.086
144.55,21.10,,-0.086
144.56,21.17,,-0.087
144.57,21.24,,-0.087
144.59,21.30,,-0.087
144.60,21.37,,-0.087
144.61,21.44,,-0.087
144.63,21.50,,-0.087
144.64,21.57,,-0.087
144.65,21.64,,-0.087
144.67,21.70,,-0.087
144.68,21.77,,-0.087
144.69,21.83,,-0.087
144.71,21.90,,-0.087
144.72,21.97,,-0.087
144.73,22.04,,-0.087
144.75,22.10,,-0.087
144.76,22.17,,-0.087
144.77,22.24,,-0.087
144.79,22.30,,-0.087
144.80,22.37,,-0.087
144.81,22.44,,-0.087
144.83,22.50,,-0.087
144.84,22.57,,-0.087
144.85,22.64,,-0.087
144.87,22.70,,-0.087
144.88,22.77,,-0.088
144.89,22.84,,-0.088
144.91,22.91,,-0.088
144.92,22.97,,-0.088
144.93,23.04,,-0.088
144.95,23.10,,-0.088
144.96,23.17,,-0.088
144.97,23.24,,-0.088
144.99,23.30,,-0.088
145.00,23.37,,-0.088
145.01,23.44,,-0.088
145.03,23.50,,-0.088
145.04,23.57,,-0.088
145.05,23.64,,-0.088
145.07,23.70,,-0.088
145.08,23.77,,-0.088
145.09,23.84,,-0.088
145.11,23.90,,-0.088
145.12,23.97,,-0.088
145.13,24.04,,-0.088
145.15,24.10,,-0.088
145.16,24.17,,-0.088
145.17,24.24,,-0.088
145.19,24.30,,-0.088
145.20,24.37,,-0.088
145.21,24.44,,-0.088
145.23,24.51,,-0.088
145.24,24.57,,-0.088
145.25,24.64,,-0.088
145.27,24.71,,-0.088
145.28,24.77,,-0.088
145.29,24.84,,-0.088
145.31,24.91,,-0.088
145.32,24.97,,-0.088
145.33,25.04,,-0.088
145.35,25.11,,-0.088
145.36,25.17,,-0.088
145.37,25.24,,-0.088
145.39,25.31,,-0.088
145.40,25.37,,-0.088
145.41,25.44,,-0.088
145.43,25.51,,-0.088
145.44,25.57,,-0.088
145.45,25.64,,-0.088
145.47,25.71,,-0.087
145.48,25.77,,-0.088
145.49,25.84,,-0.088
145.51,25.91,,-0.088
145.52,25.97,,-0.088
145.53,26.04,,-0.088
145.55,26.11,,-0.088
145.56,26.17,,-0.088
145.57,26.24,,-0.088
145.59,26.31,,-0.088
145.60,26.37,,-0.088
145.61,26.44,,-0.088
145.63,26.51,,-0.088
145.64,26.57,,-0.088
145.65,26.64,,-0.088
145.67,26.71,,-0.088
145.68,26.77,,-0.088
145.69,26.84,,-0.088
145.71,26.91,,-0.088
145.72,26.97,,-0.088
145.73,27.04,,-0.088
145.75,27.11,,-0.088
145.76,27.17,,-0.088
145.77,27.24,,-0.088
145.79,27.31,,-0.089
145.80,27.37,,-0.089
145.81,27.44,,-0.089
145.83,27.51,,-0.089
145.84,27.57,,-0.089
145.85,27.64,,-0.089
145.87,27.71,,-0.089
145.88,27.77,,-0.089
145.89,27.84,,-0.089
145.91,27.91,,-0.090
145.92,27.97,,-0.090
145.93,28.04,,-0.090
145.95,28.11,,-0.090
145.96,28.17,,-0.090
145.97,28.24,,-0.090
145.99,28.31,,-0.090
146.00,28.37,,-0.090
146.01,28.44,,-0.090
146.03,28.51,,-0.090
146.04,28.57,,-0.090
146.05,28.64,,-0.090
146.07,28.71,,-0.090
146.08,28.77,,-0.090
146.09,28.84,,-0.090
146.11,28.91,,-0.090
146.12,28.98,,-0.090
146.13,29.04,,-0.090
146.15,29.11,,
146.16,29.17,,
146.17,29.24,,
146.19,29.31,,
146.20,,,