File: DSC/2025_04_13_CBD_Pro_MechanoChem_15min_n60C_90C_10Cmin_x3.csv
Filename,2025_04_13_CBD_Pro_MechanoChem_15min_n60C_90C_10Cmin_x3
Instrument name,DSC2A-00468 (192.168.1.100)
Operator,Yarger
rundate,4/13/2025
Sample name,2025_04_13_CBD_Pro_MechanoChem_15min_n60C_90C_10Cmin_x3
proceduresegments,Data Off ; Equilibrate -60.00 °C; Data On ; Ramp 10.00 °C/min to 90.00 °C; Data Off ; Isothermal 1.0 min; Data On ; Ramp 10.00 °C/min to -60.00 °C; Data Off ; Isothermal 1.0 min; Data On ; Ramp 10.00 °C/min to 90.00 °C; Data Off ; Isothermal 1.0 min; Data On ; Ramp 10.00 °C/min to -60.00 °C; Data Off ; Isothermal 1.0 min; Data On ; Ramp 10.00 °C/min to 90.00 °C
[File Parameters]
Run date,4/13/2025 8:52:58 AM
Trios version,5.1.1.46572
Original File Name,
Current File Name,D:\DSC2500\JYarger\2025_04_13_CBD_Pro_MechanoChem_15min_n60C_90C_10Cmin_x3.tri
[Procedure]
Procedure Name,CBD_Pro_n60_90C_10Cmin_x3
Sample Name,2025_04_13_CBD_Pro_MechanoChem_15min_n60C_90C_10Cmin_x3
Sample Mass,3.29 mg
Reference Sample Mass,0 mg
Pan Mass,54.09 mg
Pan Number,22
Reference Pan Mass,53.32 mg
Reference Pan Number,10
Pan Type,Tzero Aluminum Hermetic
Comments,Hermetic Sealed Al DSC Consumables Pan/Lids.
Project Name,CA
Operator,Yarger
Test,Custom
Unload Max Temperature,30
Unload Min Temperature,30
Load Max Temperature,30
Load Min Temperature,30
Stop on Gas Flow Error,Yes
[Signal List]
Signal #1,Time (min)
Signal #2,Temperature (°C)
Signal #3,Heat Flow (mW)
Signal #4,Delta T (µV)
Signal #5,Delta Tzero (µV)
Signal #6,Tzero Temperature (°C)
Signal #7,Cell Purge (mL/min)
Signal #8,Heater Temp (°C)
Signal #9,Power Delivered (W)
Signal #10,Reference Junction Temperature (°C)
Signal #11,Flange Temperature (°C)
Signal #12,Heat Flow Phase (rad)
Signal #13,Total Heat Capacity (J/°C)
Signal #14,Heat Capacity (J/°C)
[Configuration]
Company Name,ASU
Instrument Name,DSC2A-00468
Instrument Type,DSC2500
Serial Number,DSC2A-00468
IP,192.168.1.100
Location of Instrument,MRRC
DisplayType,Unknown
Sample Interval ,0.1 s/pt
Selected Heat Flow,T4P
Exotherm Direction,Down
Cell Serial,DRC2-00792
Lid Type,Standard
Cooler,RCS 90
Leave Cooler on at End of Sequence,On
Gas 2,Nitrogen
Gas Selected,Channel 1
Flow Rate,50 mL/min
Secondary Purge,On
Licensed Heat Flow,Heat Flow T4P
Modulation Licensed,Yes
[Versions]
Common IDD Version,1
Cortex Version,VER 2.10.2.31
Driver,5.0.0.6
GDM Version,1.0.3.3
TouchscreenVersion,1.0.0.16145
FEP Version,1.2.1.21
FEP Bootloader,2.0.0.5
AutoSampler Version,2.1.1.26
Auto Sampler Bootloader,2.0.0.5
FCM Version,1.1.0.3
FCM Bootloader,2.0.0.5
[Experiment Logs]
Experiment Log Entry # 1,Data On set to 0
Experiment Log Entry # 3,Equilibrate Segment -60 (C) Started
Experiment Log Entry # 5,Air Cool is off.
Experiment Log Entry # 7,Data On set to 1
Experiment Log Entry # 9,Ramp Segment 10 C/min to 90 Started
Experiment Log Entry # 11,Data On set to 0
Experiment Log Entry # 13,Isothermal Segment 1 min started
Experiment Log Entry # 15,Data On set to 1
Experiment Log Entry # 17,Ramp Segment 10 C/min to -60 Started
Experiment Log Entry # 19,Data On set to 0
Experiment Log Entry # 21,Isothermal Segment 1 min started
Experiment Log Entry # 23,Data On set to 1
Experiment Log Entry # 25,Ramp Segment 10 C/min to 90 Started
Experiment Log Entry # 27,Data On set to 0
Experiment Log Entry # 29,Isothermal Segment 1 min started
Experiment Log Entry # 31,Data On set to 1
Experiment Log Entry # 33,Ramp Segment 10 C/min to -60 Started
Experiment Log Entry # 35,Data On set to 0
Experiment Log Entry # 37,Isothermal Segment 1 min started
Experiment Log Entry # 39,Data On set to 1
Experiment Log Entry # 41,Ramp Segment 10 C/min to 90 Started
[Method Log]
Method Log Entry # 1,Data Off
Method Log Entry # 2,Equilibrate -60 °C
Method Log Entry # 3,Data On
Method Log Entry # 4,(Ramp 381762) Ramp 10 °C/minute to 90 °C
Method Log Entry # 5,Data Off
Method Log Entry # 6,Isothermal 1 minutes
Method Log Entry # 7,Data On
Method Log Entry # 8,(Ramp 381766) Ramp 10 °C/minute to -60 °C
Method Log Entry # 9,Data Off
Method Log Entry # 10,Isothermal 1 minutes
Method Log Entry # 11,Data On
Method Log Entry # 12,(Ramp 381770) Ramp 10 °C/minute to 90 °C
Method Log Entry # 13,Data Off
Method Log Entry # 14,Isothermal 1 minutes
Method Log Entry # 15,Data On
Method Log Entry # 16,(Ramp 381774) Ramp 10 °C/minute to -60 °C
Method Log Entry # 17,Data Off
Method Log Entry # 18,Isothermal 1 minutes
Method Log Entry # 19,Data On
Method Log Entry # 20,(Ramp 381778) Ramp 10 °C/minute to 90 °C
Cell Serial,DRC2-00792
[T1 Calibration]
Slope,-0.008529666
Offset,9.636258
Initial Temperature,98.23
GUID,f8bfdadc-4977-4fdf-ba6d-0ba9134940c3
[TZero Calibration]
Date Applied,11/29/2022 4:06:13 PM
Description,From -89.059 °C to 396.009 °C at 20.000°C/min
Gas Type,Nitrogen
Pan Type,None
Source Files 1,C:\Users\yargerlab\Desktop\DSC Data\General\TZero_calibration_11_29_22_2nd(2).tri
Source Files 2,C:\Users\yargerlab\Desktop\DSC Data\General\TZero_calibration_11_29_22_2nd(3).tri
Delta T Offset,13.05235
Delta T Slope,-0.007271007
Delta T0 Offset,-13.69128
Delta T0 Slope,0.06063341
[Temperature Calibration]
Date Applied,11/29/2022 7:12:28 PM
Description,From 106.590 °C to 186.590 °C at 10.000°C/min
Gas Type,Nitrogen
Pan Type,Tzero Aluminum Hermetic
Source Files 1,C:\Users\yargerlab\Desktop\DSC Data\General\Indium(6).tri
Measured 1,157.391
Known 1,156.598
[Cell Constant Calibration]
Date Applied,11/29/2022 7:12:29 PM
Description,From 106.590 °C to 186.590 °C at 10.000°C/min
Gas Type,Nitrogen
Pan Type,Tzero Aluminum Hermetic
Source Files 1,C:\Users\yargerlab\Desktop\DSC Data\General\Indium(6).tri
T4P KCell,1.006051
Onset Slope,63.26126 mW/°C
[Direct Cp Calibration]
Date Applied,11/30/2022 11:04:51 AM
Description,From -79.983 °C to 298.409 °C at 10.000°C/min
Gas Type,Nitrogen
Pan Type,Tzero Aluminum Hermetic
Source Files 1,C:\Users\yargerlab\Desktop\DSC Data\General\Sapphire_Heat_Capacity_11_30_22.tri
[Rev Cp Calibration]
Date Applied,11/30/2022 1:58:51 PM
Description,From -79.996 °C to 292.812 °C at 3.000°C/min
Gas Type,Nitrogen
Pan Type,Tzero Aluminum Hermetic
Source Files 1,C:\Users\yargerlab\Desktop\DSC Data\General\Sapphire_MDSC_Calibration_11_30_22.tri
[step]
Ramp 10.00 °C/min to 90.00 °C
Time,Temperature,Heat Flow (Normalized)
min,°C,W/g
0.00,-59.69,-0.049
0.01,-59.70,-0.049
0.02,-59.70,-0.048
0.03,-59.71,-0.045
0.04,-59.71,-0.041
0.05,-59.71,-0.033
0.06,-59.71,-0.026
0.07,-59.70,-0.017
0.08,-59.69,-0.008
0.09,-59.67,0.002
0.10,-59.65,0.013
0.11,-59.61,0.024
0.12,-59.58,0.036
0.13,-59.54,0.046
0.14,-59.49,0.059
0.15,-59.44,0.070
0.16,-59.38,0.081
0.17,-59.32,0.093
0.18,-59.25,0.103
0.19,-59.18,0.114
0.20,-59.11,0.124
0.21,-59.03,0.131
0.22,-58.95,0.141
0.23,-58.87,0.152
0.24,-58.79,0.158
0.25,-58.70,0.166
0.26,-58.62,0.172
0.27,-58.53,0.179
0.28,-58.45,0.185
0.29,-58.36,0.189
0.30,-58.27,0.195
0.31,-58.18,0.199
0.32,-58.09,0.205
0.33,-58.00,0.210
0.34,-57.91,0.209
0.35,-57.81,0.214
0.36,-57.72,0.218
0.37,-57.63,0.221
0.38,-57.54,0.223
0.39,-57.44,0.226
0.40,-57.35,0.228
0.41,-57.25,0.229
0.42,-57.16,0.231
0.43,-57.07,0.234
0.44,-56.97,0.235
0.45,-56.88,0.236
0.46,-56.78,0.237
0.47,-56.69,0.238
0.48,-56.59,0.239
0.49,-56.49,0.240
0.50,-56.40,0.240
0.51,-56.30,0.241
0.52,-56.20,0.241
0.53,-56.11,0.242
0.54,-56.01,0.242
0.55,-55.92,0.243
0.56,-55.82,0.244
0.57,-55.72,0.244
0.58,-55.62,0.244
0.59,-55.53,0.244
0.60,-55.43,0.245
0.61,-55.33,0.246
0.62,-55.23,0.246
0.63,-55.14,0.246
0.64,-55.04,0.246
0.65,-54.94,0.247
0.66,-54.84,0.247
0.67,-54.75,0.247
0.68,-54.65,0.247
0.69,-54.55,0.248
0.70,-54.45,0.248
0.71,-54.35,0.248
0.72,-54.26,0.248
0.73,-54.16,0.248
0.74,-54.06,0.248
0.75,-53.96,0.249
0.76,-53.87,0.249
0.77,-53.77,0.249
0.78,-53.67,0.249
0.79,-53.57,0.250
0.80,-53.47,0.250
0.81,-53.37,0.250
0.82,-53.27,0.250
0.83,-53.18,0.250
0.84,-53.08,0.250
0.85,-52.98,0.250
0.86,-52.88,0.250
0.87,-52.78,0.250
0.88,-52.68,0.250
0.89,-52.59,0.250
0.90,-52.49,0.251
0.91,-52.39,0.251
0.92,-52.29,0.251
0.93,-52.19,0.251
0.94,-52.09,0.251
0.95,-51.99,0.251
0.96,-51.89,0.251
0.97,-51.79,0.251
0.98,-51.70,0.251
0.99,-51.60,0.251
1.00,-51.50,0.251
1.01,-51.40,0.251
1.02,-51.30,0.251
1.03,-51.20,0.251
1.04,-51.10,0.251
1.05,-51.00,0.251
1.06,-50.90,0.251
1.07,-50.80,0.251
1.08,-50.70,0.251
1.09,-50.61,0.251
1.10,-50.51,0.251
1.11,-50.41,0.251
1.12,-50.31,0.251
1.13,-50.21,0.251
1.14,-50.11,0.251
1.15,-50.01,0.251
1.16,-49.91,0.251
1.17,-49.81,0.251
1.18,-49.71,0.251
1.19,-49.61,0.251
1.20,-49.51,0.251
1.21,-49.41,0.251
1.22,-49.32,0.251
1.23,-49.22,0.251
1.24,-49.12,0.251
1.25,-49.02,0.251
1.26,-48.92,0.251
1.27,-48.82,0.251
1.28,-48.72,0.251
1.29,-48.62,0.252
1.30,-48.52,0.252
1.31,-48.42,0.252
1.32,-48.32,0.251
1.33,-48.22,0.252
1.34,-48.12,0.252
1.35,-48.02,0.252
1.36,-47.92,0.252
1.37,-47.82,0.251
1.38,-47.72,0.251
1.39,-47.62,0.252
1.40,-47.52,0.251
1.41,-47.42,0.251
1.42,-47.32,0.251
1.43,-47.22,0.251
1.44,-47.12,0.251
1.45,-47.02,0.251
1.46,-46.93,0.251
1.47,-46.82,0.251
1.48,-46.72,0.251
1.49,-46.63,0.251
1.50,-46.52,0.251
1.51,-46.43,0.251
1.52,-46.33,0.251
1.53,-46.23,0.251
1.54,-46.12,0.251
1.55,-46.03,0.251
1.56,-45.93,0.252
1.57,-45.83,0.252
1.58,-45.73,0.252
1.59,-45.63,0.252
1.60,-45.53,0.252
1.61,-45.43,0.252
1.62,-45.33,0.252
1.63,-45.23,0.252
1.64,-45.13,0.251
1.65,-45.03,0.251
1.66,-44.93,0.251
1.67,-44.83,0.251
1.68,-44.73,0.251
1.69,-44.63,0.251
1.70,-44.53,0.251
1.71,-44.43,0.251
1.72,-44.33,0.251
1.73,-44.23,0.251
1.74,-44.13,0.251
1.75,-44.03,0.251
1.76,-43.93,0.251
1.77,-43.83,0.251
1.78,-43.73,0.251
1.79,-43.63,0.251
1.80,-43.53,0.251
1.81,-43.43,0.251
1.82,-43.33,0.251
1.83,-43.23,0.251
1.84,-43.13,0.251
1.85,-43.03,0.251
1.86,-42.93,0.251
1.87,-42.83,0.251
1.88,-42.73,0.251
1.89,-42.63,0.251
1.90,-42.53,0.251
1.91,-42.43,0.251
1.92,-42.33,0.251
1.93,-42.23,0.251
1.94,-42.13,0.251
1.95,-42.03,0.251
1.96,-41.93,0.251
1.97,-41.83,0.251
1.98,-41.73,0.251
1.99,-41.63,0.251
2.00,-41.53,0.251
2.01,-41.43,0.251
2.02,-41.33,0.251
2.03,-41.23,0.251
2.04,-41.13,0.251
2.05,-41.03,0.251
2.06,-40.93,0.251
2.07,-40.83,0.251
2.08,-40.73,0.251
2.09,-40.63,0.251
2.10,-40.53,0.251
2.11,-40.43,0.251
2.12,-40.33,0.251
2.13,-40.23,0.251
2.14,-40.13,0.251
2.15,-40.03,0.251
2.16,-39.93,0.251
2.17,-39.83,0.251
2.18,-39.73,0.251
2.19,-39.63,0.251
2.20,-39.53,0.251
2.21,-39.43,0.251
2.22,-39.33,0.251
2.23,-39.23,0.251
2.24,-39.13,0.251
2.25,-39.03,0.251
2.26,-38.92,0.251
2.27,-38.82,0.251
2.28,-38.73,0.251
2.29,-38.63,0.251
2.30,-38.52,0.251
2.31,-38.42,0.251
2.32,-38.32,0.251
2.33,-38.22,0.251
2.34,-38.12,0.251
2.35,-38.02,0.251
2.36,-37.92,0.251
2.37,-37.82,0.251
2.38,-37.72,0.251
2.39,-37.62,0.251
2.40,-37.52,0.251
2.41,-37.42,0.251
2.42,-37.32,0.251
2.43,-37.22,0.252
2.44,-37.12,0.251
2.45,-37.02,0.251
2.46,-36.92,0.251
2.47,-36.82,0.251
2.48,-36.72,0.251
2.49,-36.62,0.251
2.50,-36.52,0.251
2.51,-36.42,0.251
2.52,-36.32,0.252
2.53,-36.22,0.252
2.54,-36.12,0.251
2.55,-36.02,0.251
2.56,-35.92,0.252
2.57,-35.82,0.251
2.58,-35.72,0.252
2.59,-35.62,0.252
2.60,-35.52,0.252
2.61,-35.42,0.252
2.62,-35.32,0.252
2.63,-35.22,0.252
2.64,-35.12,0.252
2.65,-35.02,0.252
2.66,-34.92,0.252
2.67,-34.82,0.252
2.68,-34.72,0.252
2.69,-34.62,0.252
2.70,-34.52,0.252
2.71,-34.42,0.252
2.72,-34.32,0.252
2.73,-34.22,0.252
2.74,-34.12,0.252
2.75,-34.02,0.252
2.76,-33.92,0.252
2.77,-33.82,0.252
2.78,-33.72,0.252
2.79,-33.62,0.252
2.80,-33.52,0.252
2.81,-33.42,0.252
2.82,-33.32,0.252
2.83,-33.22,0.252
2.84,-33.12,0.252
2.85,-33.02,0.252
2.86,-32.92,0.252
2.87,-32.82,0.252
2.88,-32.72,0.252
2.89,-32.62,0.252
2.90,-32.52,0.252
2.91,-32.42,0.252
2.92,-32.32,0.252
2.93,-32.22,0.252
2.94,-32.12,0.252
2.95,-32.02,0.252
2.96,-31.92,0.252
2.97,-31.82,0.252
2.98,-31.71,0.252
2.99,-31.62,0.252
3.00,-31.52,0.252
3.01,-31.42,0.252
3.02,-31.31,0.252
3.03,-31.21,0.252
3.04,-31.11,0.252
3.05,-31.01,0.252
3.06,-30.91,0.252
3.07,-30.81,0.252
3.08,-30.71,0.252
3.09,-30.61,0.252
3.10,-30.51,0.252
3.11,-30.41,0.252
3.12,-30.31,0.252
3.13,-30.21,0.252
3.14,-30.11,0.252
3.15,-30.01,0.252
3.16,-29.91,0.252
3.17,-29.81,0.252
3.18,-29.71,0.252
3.19,-29.61,0.252
3.20,-29.51,0.252
3.21,-29.41,0.252
3.22,-29.31,0.252
3.23,-29.21,0.252
3.24,-29.11,0.252
3.25,-29.01,0.252
3.26,-28.91,0.253
3.27,-28.81,0.252
3.28,-28.71,0.253
3.29,-28.61,0.253
3.30,-28.51,0.253
3.31,-28.41,0.253
3.32,-28.31,0.253
3.33,-28.21,0.253
3.34,-28.11,0.253
3.35,-28.01,0.253
3.36,-27.91,0.253
3.37,-27.81,0.253
3.38,-27.71,0.253
3.39,-27.61,0.253
3.40,-27.51,0.253
3.41,-27.41,0.253
3.42,-27.31,0.253
3.43,-27.21,0.253
3.44,-27.11,0.253
3.45,-27.01,0.253
3.46,-26.91,0.253
3.47,-26.81,0.253
3.48,-26.71,0.253
3.49,-26.61,0.253
3.50,-26.51,0.253
3.51,-26.41,0.253
3.52,-26.31,0.253
3.53,-26.21,0.253
3.54,-26.11,0.253
3.55,-26.01,0.253
3.56,-25.91,0.253
3.57,-25.81,0.253
3.58,-25.71,0.253
3.59,-25.61,0.253
3.60,-25.51,0.254
3.61,-25.41,0.254
3.62,-25.31,0.254
3.63,-25.21,0.254
3.64,-25.11,0.254
3.65,-25.01,0.254
3.66,-24.91,0.254
3.67,-24.81,0.254
3.68,-24.71,0.254
3.69,-24.61,0.254
3.70,-24.51,0.254
3.71,-24.41,0.254
3.72,-24.31,0.254
3.73,-24.21,0.254
3.74,-24.11,0.254
3.75,-24.01,0.254
3.76,-23.90,0.254
3.77,-23.81,0.254
3.78,-23.71,0.254
3.79,-23.60,0.254
3.80,-23.50,0.254
3.81,-23.40,0.254
3.82,-23.30,0.254
3.83,-23.20,0.254
3.84,-23.10,0.254
3.85,-23.00,0.254
3.86,-22.91,0.254
3.87,-22.80,0.254
3.88,-22.71,0.254
3.89,-22.60,0.255
3.90,-22.50,0.255
3.91,-22.40,0.255
3.92,-22.30,0.255
3.93,-22.20,0.255
3.94,-22.10,0.255
3.95,-22.00,0.255
3.96,-21.90,0.255
3.97,-21.80,0.255
3.98,-21.70,0.255
3.99,-21.60,0.255
4.00,-21.50,0.255
4.01,-21.40,0.255
4.02,-21.30,0.255
4.03,-21.20,0.255
4.04,-21.10,0.255
4.05,-21.00,0.255
4.06,-20.90,0.255
4.07,-20.80,0.255
4.08,-20.70,0.255
4.09,-20.60,0.255
4.10,-20.50,0.255
4.11,-20.40,0.255
4.12,-20.30,0.255
4.13,-20.20,0.255
4.14,-20.10,0.255
4.15,-20.00,0.255
4.16,-19.90,0.255
4.17,-19.80,0.255
4.18,-19.70,0.256
4.19,-19.60,0.256
4.20,-19.50,0.256
4.21,-19.40,0.256
4.22,-19.30,0.256
4.23,-19.20,0.256
4.24,-19.10,0.256
4.25,-19.00,0.256
4.26,-18.90,0.256
4.27,-18.80,0.256
4.28,-18.70,0.256
4.29,-18.60,0.256
4.30,-18.50,0.256
4.31,-18.40,0.256
4.32,-18.30,0.256
4.33,-18.20,0.256
4.34,-18.10,0.256
4.35,-18.00,0.256
4.36,-17.90,0.256
4.37,-17.80,0.256
4.38,-17.70,0.256
4.39,-17.60,0.256
4.40,-17.50,0.256
4.41,-17.40,0.256
4.42,-17.30,0.256
4.43,-17.20,0.256
4.44,-17.10,0.256
4.45,-17.00,0.256
4.46,-16.90,0.256
4.47,-16.80,0.257
4.48,-16.70,0.257
4.49,-16.60,0.257
4.50,-16.50,0.257
4.51,-16.40,0.257
4.52,-16.30,0.257
4.53,-16.20,0.257
4.54,-16.10,0.257
4.55,-16.00,0.257
4.56,-15.90,0.257
4.57,-15.79,0.257
4.58,-15.70,0.257
4.59,-15.60,0.257
4.60,-15.49,0.257
4.61,-15.40,0.257
4.62,-15.29,0.257
4.63,-15.19,0.257
4.64,-15.10,0.257
4.65,-14.99,0.257
4.66,-14.89,0.257
4.67,-14.79,0.257
4.68,-14.69,0.257
4.69,-14.59,0.257
4.70,-14.49,0.257
4.71,-14.40,0.257
4.72,-14.30,0.257
4.73,-14.19,0.258
4.74,-14.09,0.258
4.75,-13.99,0.258
4.76,-13.89,0.258
4.77,-13.79,0.258
4.78,-13.69,0.258
4.79,-13.59,0.258
4.80,-13.49,0.258
4.81,-13.39,0.258
4.82,-13.29,0.258
4.83,-13.19,0.258
4.84,-13.09,0.258
4.85,-12.99,0.258
4.86,-12.89,0.258
4.87,-12.79,0.258
4.88,-12.69,0.258
4.89,-12.59,0.258
4.90,-12.49,0.258
4.91,-12.39,0.258
4.92,-12.29,0.258
4.93,-12.19,0.259
4.94,-12.09,0.259
4.95,-11.99,0.259
4.96,-11.89,0.259
4.97,-11.79,0.259
4.98,-11.69,0.259
4.99,-11.59,0.259
5.00,-11.49,0.259
5.01,-11.39,0.259
5.02,-11.29,0.259
5.03,-11.19,0.259
5.04,-11.09,0.259
5.05,-10.99,0.259
5.06,-10.89,0.259
5.07,-10.79,0.259
5.08,-10.69,0.259
5.09,-10.59,0.259
5.10,-10.49,0.259
5.11,-10.39,0.260
5.12,-10.29,0.260
5.13,-10.19,0.260
5.14,-10.09,0.260
5.15,-9.99,0.260
5.16,-9.89,0.260
5.17,-9.79,0.260
5.18,-9.69,0.260
5.19,-9.59,0.260
5.20,-9.49,0.260
5.21,-9.39,0.260
5.22,-9.29,0.260
5.23,-9.19,0.260
5.24,-9.09,0.260
5.25,-8.99,0.261
5.26,-8.89,0.261
5.27,-8.79,0.261
5.28,-8.69,0.261
5.29,-8.59,0.261
5.30,-8.49,0.261
5.31,-8.39,0.261
5.32,-8.29,0.261
5.33,-8.19,0.261
5.34,-8.09,0.261
5.35,-7.99,0.261
5.36,-7.89,0.261
5.37,-7.79,0.261
5.38,-7.69,0.261
5.39,-7.59,0.261
5.40,-7.49,0.262
5.41,-7.39,0.262
5.42,-7.29,0.262
5.43,-7.19,0.262
5.44,-7.09,0.262
5.45,-6.99,0.262
5.46,-6.89,0.262
5.47,-6.79,0.262
5.48,-6.69,0.262
5.49,-6.59,0.262
5.50,-6.49,0.262
5.51,-6.39,0.262
5.52,-6.29,0.262
5.53,-6.18,0.262
5.54,-6.09,0.262
5.55,-5.99,0.262
5.56,-5.89,0.263
5.57,-5.78,0.263
5.58,-5.68,0.263
5.59,-5.58,0.263
5.60,-5.49,0.263
5.61,-5.38,0.263
5.62,-5.28,0.263
5.63,-5.18,0.263
5.64,-5.08,0.263
5.65,-4.98,0.263
5.66,-4.88,0.263
5.67,-4.78,0.263
5.68,-4.68,0.263
5.69,-4.58,0.263
5.70,-4.48,0.263
5.71,-4.38,0.263
5.72,-4.28,0.263
5.73,-4.18,0.263
5.74,-4.08,0.264
5.75,-3.98,0.263
5.76,-3.88,0.263
5.77,-3.78,0.264
5.78,-3.68,0.264
5.79,-3.58,0.264
5.80,-3.48,0.264
5.81,-3.38,0.264
5.82,-3.28,0.264
5.83,-3.18,0.264
5.84,-3.08,0.264
5.85,-2.98,0.264
5.86,-2.88,0.264
5.87,-2.78,0.264
5.88,-2.68,0.264
5.89,-2.58,0.264
5.90,-2.48,0.264
5.91,-2.38,0.264
5.92,-2.28,0.264
5.93,-2.18,0.264
5.94,-2.08,0.264
5.95,-1.98,0.264
5.96,-1.88,0.264
5.97,-1.78,0.265
5.98,-1.68,0.264
5.99,-1.58,0.265
6.00,-1.48,0.265
6.01,-1.38,0.265
6.02,-1.28,0.265
6.03,-1.18,0.265
6.04,-1.08,0.265
6.05,-0.98,0.265
6.06,-0.88,0.265
6.07,-0.78,0.265
6.08,-0.68,0.265
6.09,-0.58,0.265
6.10,-0.48,0.265
6.11,-0.38,0.265
6.12,-0.28,0.265
6.13,-0.18,0.265
6.14,-0.08,0.265
6.15,0.02,0.265
6.16,0.12,0.265
6.17,0.22,0.265
6.18,0.32,0.265
6.19,0.42,0.265
6.20,0.52,0.266
6.21,0.62,0.266
6.22,0.72,0.266
6.23,0.82,0.266
6.24,0.92,0.266
6.25,1.02,0.266
6.26,1.12,0.266
6.27,1.22,0.266
6.28,1.32,0.266
6.29,1.43,0.266
6.30,1.52,0.266
6.31,1.62,0.266
6.32,1.72,0.266
6.33,1.82,0.266
6.34,1.92,0.266
6.35,2.02,0.266
6.36,2.13,0.266
6.37,2.23,0.266
6.38,2.32,0.266
6.39,2.43,0.266
6.40,2.53,0.267
6.41,2.63,0.267
6.42,2.73,0.267
6.43,2.83,0.267
6.44,2.93,0.267
6.45,3.03,0.267
6.46,3.13,0.267
6.47,3.23,0.267
6.48,3.33,0.267
6.49,3.43,0.267
6.50,3.53,0.267
6.51,3.63,0.267
6.52,3.73,0.267
6.53,3.83,0.267
6.54,3.93,0.267
6.55,4.03,0.267
6.56,4.13,0.267
6.57,4.23,0.267
6.58,4.33,0.267
6.59,4.43,0.268
6.60,4.53,0.268
6.61,4.63,0.268
6.62,4.73,0.268
6.63,4.83,0.268
6.64,4.93,0.268
6.65,5.03,0.268
6.66,5.13,0.268
6.67,5.23,0.268
6.68,5.33,0.268
6.69,5.43,0.268
6.70,5.53,0.268
6.71,5.63,0.268
6.72,5.73,0.268
6.73,5.83,0.268
6.74,5.93,0.268
6.75,6.03,0.268
6.76,6.13,0.268
6.77,6.23,0.268
6.78,6.33,0.269
6.79,6.43,0.269
6.80,6.53,0.269
6.81,6.63,0.269
6.82,6.73,0.269
6.83,6.83,0.269
6.84,6.93,0.269
6.85,7.03,0.269
6.86,7.13,0.269
6.87,7.23,0.269
6.88,7.33,0.269
6.89,7.43,0.269
6.90,7.53,0.269
6.91,7.63,0.269
6.92,7.73,0.269
6.93,7.83,0.269
6.94,7.93,0.270
6.95,8.03,0.270
6.96,8.13,0.270
6.97,8.23,0.270
6.98,8.33,0.270
6.99,8.43,0.270
7.00,8.53,0.270
7.01,8.63,0.270
7.02,8.73,0.270
7.03,8.83,0.270
7.04,8.93,0.270
7.05,9.03,0.270
7.06,9.13,0.270
7.07,9.23,0.270
7.08,9.33,0.270
7.09,9.43,0.271
7.10,9.53,0.271
7.11,9.63,0.271
7.12,9.73,0.271
7.13,9.83,0.271
7.14,9.93,0.271
7.15,10.03,0.271
7.16,10.13,0.271
7.17,10.23,0.271
7.18,10.33,0.271
7.19,10.43,0.271
7.20,10.54,0.271
7.21,10.64,0.271
7.22,10.73,0.271
7.23,10.84,0.272
7.24,10.93,0.272
7.25,11.04,0.272
7.26,11.14,0.272
7.27,11.24,0.272
7.28,11.34,0.272
7.29,11.44,0.272
7.30,11.54,0.272
7.31,11.64,0.272
7.32,11.74,0.272
7.33,11.84,0.272
7.34,11.94,0.272
7.35,12.04,0.272
7.36,12.14,0.272
7.37,12.24,0.273
7.38,12.34,0.273
7.39,12.44,0.273
7.40,12.54,0.273
7.41,12.64,0.273
7.42,12.74,0.273
7.43,12.84,0.273
7.44,12.94,0.273
7.45,13.04,0.273
7.46,13.14,0.273
7.47,13.24,0.273
7.48,13.34,0.273
7.49,13.44,0.273
7.50,13.54,0.273
7.51,13.64,0.273
7.52,13.74,0.273
7.53,13.84,0.274
7.54,13.94,0.274
7.55,14.04,0.274
7.56,14.14,0.274
7.57,14.24,0.274
7.58,14.34,0.274
7.59,14.44,0.274
7.60,14.54,0.274
7.61,14.64,0.274
7.62,14.74,0.274
7.63,14.84,0.274
7.64,14.94,0.274
7.65,15.04,0.274
7.66,15.14,0.274
7.67,15.24,0.274
7.68,15.34,0.274
7.69,15.44,0.274
7.70,15.54,0.275
7.71,15.64,0.275
7.72,15.74,0.275
7.73,15.84,0.275
7.74,15.94,0.275
7.75,16.04,0.275
7.76,16.14,0.275
7.77,16.24,0.275
7.78,16.34,0.275
7.79,16.44,0.275
7.80,16.54,0.275
7.81,16.64,0.275
7.82,16.74,0.275
7.83,16.84,0.275
7.84,16.94,0.275
7.85,17.04,0.276
7.86,17.14,0.276
7.87,17.24,0.276
7.88,17.34,0.276
7.89,17.44,0.276
7.90,17.54,0.276
7.91,17.64,0.276
7.92,17.74,0.276
7.93,17.84,0.276
7.94,17.94,0.276
7.95,18.04,0.276
7.96,18.14,0.276
7.97,18.24,0.276
7.98,18.34,0.276
7.99,18.44,0.276
8.00,18.54,0.276
8.01,18.64,0.276
8.02,18.74,0.276
8.03,18.84,0.276
8.04,18.94,0.277
8.05,19.04,0.277
8.06,19.14,0.277
8.07,19.25,0.277
8.08,19.34,0.277
8.09,19.44,0.277
8.10,19.54,0.277
8.11,19.64,0.277
8.12,19.74,0.277
8.13,19.85,0.277
8.14,19.95,0.278
8.15,20.05,0.278
8.16,20.15,0.278
8.17,20.25,0.278
8.18,20.35,0.278
8.19,20.45,0.278
8.20,20.55,0.278
8.21,20.65,0.278
8.22,20.75,0.278
8.23,20.85,0.278
8.24,20.95,0.278
8.25,21.05,0.279
8.26,21.15,0.279
8.27,21.25,0.279
8.28,21.35,0.279
8.29,21.45,0.279
8.30,21.55,0.279
8.31,21.65,0.279
8.32,21.75,0.279
8.33,21.85,0.279
8.34,21.95,0.279
8.35,22.05,0.279
8.36,22.15,0.279
8.37,22.25,0.279
8.38,22.35,0.280
8.39,22.45,0.280
8.40,22.55,0.280
8.41,22.65,0.280
8.42,22.75,0.280
8.43,22.85,0.280
8.44,22.95,0.280
8.45,23.05,0.280
8.46,23.15,0.280
8.47,23.25,0.280
8.48,23.35,0.280
8.49,23.45,0.280
8.50,23.55,0.280
8.51,23.65,0.280
8.52,23.75,0.280
8.53,23.85,0.280
8.54,23.95,0.280
8.55,24.05,0.280
8.56,24.15,0.281
8.57,24.25,0.281
8.58,24.35,0.281
8.59,24.45,0.281
8.60,24.55,0.281
8.61,24.65,0.281
8.62,24.75,0.281
8.63,24.85,0.281
8.64,24.95,0.281
8.65,25.05,0.281
8.66,25.15,0.281
8.67,25.25,0.281
8.68,25.35,0.281
8.69,25.45,0.281
8.70,25.55,0.281
8.71,25.65,0.282
8.72,25.75,0.282
8.73,25.85,0.282
8.74,25.95,0.282
8.75,26.05,0.282
8.76,26.15,0.282
8.77,26.25,0.282
8.78,26.35,0.282
8.79,26.45,0.282
8.80,26.55,0.282
8.81,26.65,0.282
8.82,26.75,0.283
8.83,26.85,0.283
8.84,26.95,0.283
8.85,27.05,0.283
8.86,27.15,0.283
8.87,27.25,0.283
8.88,27.35,0.283
8.89,27.45,0.283
8.90,27.56,0.283
8.91,27.66,0.283
8.92,27.75,0.284
8.93,27.85,0.284
8.94,27.96,0.284
8.95,28.06,0.284
8.96,28.15,0.284
8.97,28.26,0.284
8.98,28.36,0.284
8.99,28.45,0.284
9.00,28.56,0.284
9.01,28.66,0.284
9.02,28.76,0.284
9.03,28.86,0.284
9.04,28.96,0.284
9.05,29.06,0.285
9.06,29.16,0.285
9.07,29.26,0.285
9.08,29.36,0.285
9.09,29.46,0.285
9.10,29.56,0.285
9.11,29.66,0.285
9.12,29.76,0.285
9.13,29.86,0.285
9.14,29.96,0.285
9.15,30.06,0.285
9.16,30.16,0.286
9.17,30.26,0.286
9.18,30.36,0.286
9.19,30.46,0.286
9.20,30.56,0.286
9.21,30.66,0.286
9.22,30.76,0.286
9.23,30.86,0.286
9.24,30.96,0.286
9.25,31.06,0.286
9.26,31.16,0.286
9.27,31.26,0.286
9.28,31.36,0.287
9.29,31.46,0.287
9.30,31.56,0.287
9.31,31.66,0.287
9.32,31.76,0.287
9.33,31.86,0.287
9.34,31.96,0.287
9.35,32.06,0.287
9.36,32.16,0.287
9.37,32.26,0.287
9.38,32.36,0.287
9.39,32.46,0.287
9.40,32.56,0.288
9.41,32.66,0.288
9.42,32.76,0.288
9.43,32.86,0.288
9.44,32.96,0.288
9.45,33.06,0.288
9.46,33.16,0.288
9.47,33.26,0.288
9.48,33.36,0.288
9.49,33.46,0.288
9.50,33.56,0.288
9.51,33.66,0.288
9.52,33.76,0.288
9.53,33.86,0.289
9.54,33.96,0.289
9.55,34.06,0.289
9.56,34.16,0.289
9.57,34.26,0.289
9.58,34.36,0.289
9.59,34.46,0.289
9.60,34.56,0.289
9.61,34.66,0.289
9.62,34.76,0.289
9.63,34.86,0.289
9.64,34.96,0.289
9.65,35.06,0.289
9.66,35.16,0.290
9.67,35.26,0.290
9.68,35.36,0.290
9.69,35.46,0.290
9.70,35.56,0.290
9.71,35.66,0.290
9.72,35.76,0.290
9.73,35.86,0.290
9.74,35.96,0.290
9.75,36.06,0.290
9.76,36.16,0.290
9.77,36.26,0.290
9.78,36.36,0.290
9.79,36.46,0.291
9.80,36.56,0.291
9.81,36.66,0.291
9.82,36.76,0.291
9.83,36.86,0.291
9.84,36.97,0.291
9.85,37.06,0.291
9.86,37.16,0.291
9.87,37.26,0.291
9.88,37.36,0.291
9.89,37.47,0.291
9.90,37.56,0.291
9.91,37.67,0.292
9.92,37.77,0.292
9.93,37.87,0.292
9.94,37.96,0.292
9.95,38.07,0.292
9.96,38.17,0.292
9.97,38.27,0.292
9.98,38.37,0.292
9.99,38.47,0.292
10.00,38.57,0.292
10.01,38.67,0.292
10.02,38.77,0.293
10.03,38.87,0.293
10.04,38.97,0.293
10.05,39.07,0.293
10.06,39.17,0.293
10.07,39.27,0.293
10.08,39.37,0.293
10.09,39.47,0.293
10.10,39.57,0.293
10.11,39.67,0.293
10.12,39.77,0.293
10.13,39.87,0.293
10.14,39.97,0.294
10.15,40.07,0.294
10.16,40.17,0.294
10.17,40.27,0.294
10.18,40.37,0.294
10.19,40.47,0.294
10.20,40.57,0.294
10.21,40.67,0.294
10.22,40.77,0.294
10.23,40.87,0.294
10.24,40.97,0.294
10.25,41.07,0.295
10.26,41.17,0.295
10.27,41.27,0.295
10.28,41.37,0.295
10.29,41.47,0.295
10.30,41.57,0.295
10.31,41.67,0.295
10.32,41.77,0.295
10.33,41.87,0.295
10.34,41.97,0.295
10.35,42.07,0.295
10.36,42.17,0.295
10.37,42.27,0.295
10.38,42.37,0.295
10.39,42.47,0.296
10.40,42.57,0.296
10.41,42.67,0.296
10.42,42.77,0.296
10.43,42.87,0.296
10.44,42.97,0.296
10.45,43.07,0.296
10.46,43.17,0.296
10.47,43.27,0.296
10.48,43.37,0.296
10.49,43.47,0.297
10.50,43.57,0.297
10.51,43.67,0.297
10.52,43.77,0.297
10.53,43.87,0.297
10.54,43.97,0.297
10.55,44.07,0.297
10.56,44.17,0.297
10.57,44.27,0.297
10.58,44.37,0.297
10.59,44.47,0.297
10.60,44.57,0.298
10.61,44.67,0.298
10.62,44.77,0.298
10.63,44.87,0.298
10.64,44.97,0.298
10.65,45.07,0.298
10.66,45.17,0.298
10.67,45.27,0.298
10.68,45.37,0.298
10.69,45.47,0.299
10.70,45.57,0.299
10.71,45.67,0.299
10.72,45.77,0.299
10.73,45.87,0.299
10.74,45.97,0.299
10.75,46.07,0.299
10.76,46.17,0.299
10.77,46.27,0.299
10.78,46.37,0.299
10.79,46.47,0.300
10.80,46.57,0.300
10.81,46.67,0.300
10.82,46.77,0.300
10.83,46.87,0.300
10.84,46.97,0.300
10.85,47.07,0.300
10.86,47.17,0.300
10.87,47.27,0.301
10.88,47.37,0.301
10.89,47.47,0.301
10.90,47.58,0.301
10.91,47.67,0.301
10.92,47.77,0.301
10.93,47.88,0.301
10.94,47.98,0.301
10.95,48.07,0.301
10.96,48.17,0.302
10.97,48.27,0.302
10.98,48.38,0.302
10.99,48.48,0.302
11.00,48.58,0.302
11.01,48.68,0.302
11.02,48.78,0.302
11.03,48.88,0.302
11.04,48.98,0.303
11.05,49.08,0.303
11.06,49.18,0.303
11.07,49.28,0.303
11.08,49.38,0.303
11.09,49.48,0.303
11.10,49.58,0.303
11.11,49.68,0.303
11.12,49.78,0.303
11.13,49.88,0.303
11.14,49.98,0.304
11.15,50.08,0.304
11.16,50.18,0.304
11.17,50.28,0.304
11.18,50.38,0.304
11.19,50.48,0.304
11.20,50.58,0.304
11.21,50.68,0.304
11.22,50.78,0.304
11.23,50.88,0.305
11.24,50.98,0.305
11.25,51.08,0.305
11.26,51.18,0.305
11.27,51.28,0.305
11.28,51.38,0.305
11.29,51.48,0.305
11.30,51.58,0.305
11.31,51.68,0.305
11.32,51.78,0.306
11.33,51.88,0.306
11.34,51.98,0.306
11.35,52.08,0.306
11.36,52.18,0.306
11.37,52.28,0.306
11.38,52.38,0.307
11.39,52.48,0.307
11.40,52.58,0.307
11.41,52.68,0.307
11.42,52.78,0.307
11.43,52.88,0.307
11.44,52.98,0.307
11.45,53.08,0.307
11.46,53.18,0.307
11.47,53.28,0.308
11.48,53.38,0.308
11.49,53.48,0.308
11.50,53.58,0.308
11.51,53.68,0.308
11.52,53.78,0.308
11.53,53.88,0.308
11.54,53.98,0.308
11.55,54.08,0.309
11.56,54.18,0.309
11.57,54.28,0.309
11.58,54.38,0.309
11.59,54.48,0.309
11.60,54.58,0.309
11.61,54.68,0.309
11.62,54.78,0.310
11.63,54.88,0.310
11.64,54.98,0.310
11.65,55.08,0.310
11.66,55.18,0.310
11.67,55.28,0.310
11.68,55.38,0.310
11.69,55.48,0.311
11.70,55.58,0.311
11.71,55.68,0.311
11.72,55.78,0.311
11.73,55.88,0.311
11.74,55.98,0.311
11.75,56.08,0.312
11.76,56.18,0.312
11.77,56.28,0.312
11.78,56.38,0.312
11.79,56.48,0.312
11.80,56.58,0.312
11.81,56.68,0.313
11.82,56.78,0.313
11.83,56.88,0.313
11.84,56.98,0.313
11.85,57.08,0.313
11.86,57.18,0.313
11.87,57.28,0.314
11.88,57.38,0.314
11.89,57.48,0.314
11.90,57.59,0.314
11.91,57.68,0.314
11.92,57.78,0.315
11.93,57.88,0.315
11.94,57.98,0.315
11.95,58.08,0.315
11.96,58.18,0.315
11.97,58.28,0.316
11.98,58.38,0.316
11.99,58.48,0.316
12.00,58.58,0.316
12.01,58.68,0.317
12.02,58.79,0.317
12.03,58.88,0.317
12.04,58.98,0.317
12.05,59.08,0.317
12.06,59.19,0.318
12.07,59.29,0.318
12.08,59.39,0.318
12.09,59.48,0.318
12.10,59.59,0.319
12.11,59.69,0.319
12.12,59.78,0.319
12.13,59.89,0.319
12.14,59.99,0.320
12.15,60.08,0.320
12.16,60.19,0.320
12.17,60.29,0.321
12.18,60.39,0.321
12.19,60.49,0.321
12.20,60.59,0.322
12.21,60.69,0.322
12.22,60.79,0.322
12.23,60.89,0.323
12.24,60.98,0.323
12.25,61.09,0.323
12.26,61.19,0.324
12.27,61.28,0.324
12.28,61.39,0.325
12.29,61.49,0.325
12.30,61.59,0.326
12.31,61.69,0.327
12.32,61.79,0.327
12.33,61.89,0.327
12.34,61.99,0.328
12.35,62.09,0.329
12.36,62.19,0.331
12.37,62.28,0.332
12.38,62.38,0.332
12.39,62.49,0.334
12.40,62.58,0.336
12.41,62.69,0.336
12.42,62.78,0.340
12.43,62.88,0.341
12.44,62.98,0.344
12.45,63.08,0.346
12.46,63.18,0.348
12.47,63.28,0.352
12.48,63.38,0.356
12.49,63.48,0.358
12.50,63.58,0.361
12.51,63.68,0.367
12.52,63.78,0.370
12.53,63.88,0.374
12.54,63.98,0.381
12.55,64.08,0.386
12.56,64.18,0.392
12.57,64.28,0.397
12.58,64.38,0.406
12.59,64.48,0.413
12.60,64.57,0.424
12.61,64.67,0.433
12.62,64.77,0.444
12.63,64.87,0.454
12.64,64.97,0.468
12.65,65.07,0.482
12.66,65.17,0.494
12.67,65.26,0.509
12.68,65.36,0.528
12.69,65.46,0.543
12.70,65.56,0.562
12.71,65.65,0.581
12.72,65.75,0.601
12.73,65.85,0.620
12.74,65.94,0.643
12.75,66.04,0.664
12.76,66.13,0.688
12.77,66.23,0.713
12.78,66.33,0.738
12.79,66.42,0.763
12.80,66.51,0.788
12.81,66.61,0.819
12.82,66.70,0.846
12.83,66.80,0.874
12.84,66.89,0.899
12.85,66.99,0.922
12.86,67.08,0.947
12.87,67.18,0.973
12.88,67.27,0.995
12.89,67.37,1.022
12.90,67.46,1.054
12.91,67.55,1.077
12.92,67.65,1.093
12.93,67.74,1.112
12.94,67.84,1.132
12.95,67.93,1.145
12.96,68.03,1.162
12.97,68.13,1.178
12.98,68.22,1.190
12.99,68.32,1.205
13.00,68.41,1.220
13.01,68.51,1.232
13.02,68.61,1.244
13.03,68.70,1.257
13.04,68.80,1.267
13.05,68.90,1.275
13.06,68.99,1.283
13.07,69.09,1.287
13.08,69.19,1.291
13.09,69.29,1.291
13.10,69.39,1.291
13.11,69.48,1.287
13.12,69.58,1.288
13.13,69.68,1.281
13.14,69.78,1.271
13.15,69.88,1.257
13.16,69.98,1.237
13.17,70.09,1.219
13.18,70.19,1.198
13.19,70.29,1.175
13.20,70.39,1.150
13.21,70.50,1.127
13.22,70.60,1.098
13.23,70.70,1.066
13.24,70.81,1.035
13.25,70.92,1.000
13.26,71.02,0.966
13.27,71.13,0.927
13.28,71.23,0.887
13.29,71.34,0.849
13.30,71.45,0.811
13.31,71.56,0.772
13.32,71.66,0.738
13.33,71.77,0.705
13.34,71.88,0.676
13.35,71.98,0.646
13.36,72.09,0.622
13.37,72.20,0.598
13.38,72.31,0.578
13.39,72.41,0.557
13.40,72.52,0.539
13.41,72.62,0.523
13.42,72.73,0.508
13.43,72.83,0.494
13.44,72.94,0.482
13.45,73.04,0.471
13.46,73.15,0.461
13.47,73.25,0.449
13.48,73.35,0.440
13.49,73.46,0.434
13.50,73.56,0.427
13.51,73.66,0.419
13.52,73.77,0.413
13.53,73.87,0.407
13.54,73.97,0.402
13.55,74.07,0.398
13.56,74.17,0.393
13.57,74.28,0.390
13.58,74.38,0.386
13.59,74.48,0.385
13.60,74.58,0.381
13.61,74.68,0.376
13.62,74.78,0.375
13.63,74.88,0.374
13.64,74.99,0.373
13.65,75.09,0.370
13.66,75.19,0.367
13.67,75.29,0.367
13.68,75.39,0.366
13.69,75.49,0.365
13.70,75.59,0.364
13.71,75.69,0.363
13.72,75.79,0.363
13.73,75.89,0.361
13.74,75.99,0.361
13.75,76.09,0.360
13.76,76.19,0.360
13.77,76.29,0.359
13.78,76.39,0.359
13.79,76.50,0.359
13.80,76.59,0.359
13.81,76.69,0.358
13.82,76.80,0.358
13.83,76.89,0.358
13.84,77.00,0.357
13.85,77.10,0.357
13.86,77.20,0.356
13.87,77.30,0.356
13.88,77.40,0.356
13.89,77.50,0.356
13.90,77.60,0.356
13.91,77.70,0.356
13.92,77.80,0.355
13.93,77.90,0.355
13.94,78.00,0.355
13.95,78.10,0.355
13.96,78.20,0.355
13.97,78.30,0.354
13.98,78.40,0.354
13.99,78.50,0.354
14.00,78.60,0.354
14.01,78.70,0.354
14.02,78.80,0.354
14.03,78.90,0.353
14.04,79.00,0.353
14.05,79.10,0.353
14.06,79.20,0.353
14.07,79.30,0.353
14.08,79.40,0.353
14.09,79.50,0.353
14.10,79.60,0.353
14.11,79.70,0.353
14.12,79.80,0.352
14.13,79.90,0.352
14.14,80.00,0.352
14.15,80.10,0.352
14.16,80.20,0.352
14.17,80.30,0.352
14.18,80.40,0.352
14.19,80.50,0.352
14.20,80.60,0.352
14.21,80.70,0.352
14.22,80.80,0.352
14.23,80.90,0.352
14.24,81.00,0.352
14.25,81.10,0.352
14.26,81.20,0.351
14.27,81.30,0.351
14.28,81.40,0.351
14.29,81.50,0.351
14.30,81.60,0.351
14.31,81.70,0.351
14.32,81.80,0.351
14.33,81.90,0.351
14.34,82.00,0.351
14.35,82.10,0.351
14.36,82.20,0.351
14.37,82.30,0.351
14.38,82.40,0.351
14.39,82.50,0.351
14.40,82.60,0.351
14.41,82.70,0.351
14.42,82.80,0.351
14.43,82.90,0.351
14.44,83.00,0.351
14.45,83.10,0.351
14.46,83.20,0.351
14.47,83.31,0.351
14.48,83.40,0.351
14.49,83.50,0.351
14.50,83.60,0.351
14.51,83.71,0.351
14.52,83.81,0.351
14.53,83.91,0.351
14.54,84.01,0.351
14.55,84.11,0.351
14.56,84.21,0.351
14.57,84.31,0.351
14.58,84.41,0.351
14.59,84.50,0.351
14.60,84.61,0.351
14.61,84.71,0.351
14.62,84.81,0.351
14.63,84.91,0.351
14.64,85.01,0.351
14.65,85.11,0.351
14.66,85.21,0.351
14.67,85.31,0.351
14.68,85.41,0.351
14.69,85.51,0.351
14.70,85.61,0.351
14.71,85.71,0.351
14.72,85.81,0.351
14.73,85.91,0.351
14.74,86.01,0.351
14.75,86.11,0.351
14.76,86.21,0.351
14.77,86.31,0.351
14.78,86.41,0.351
14.79,86.51,0.351
14.80,86.61,0.351
14.81,86.71,0.351
14.82,86.81,0.351
14.83,86.91,0.351
14.84,87.01,0.351
14.85,87.11,0.351
14.86,87.21,0.351
14.87,87.31,0.351
14.88,87.41,0.351
14.89,87.51,0.351
14.90,87.61,0.351
14.91,87.71,0.351
14.92,87.81,0.351
14.93,87.91,0.351
14.94,88.01,
14.95,88.11,
14.96,88.21,
14.97,88.31,
14.98,88.41,
14.99,,
14.99,,

[step]
Ramp 10.00 °C/min to -60.00 °C
Time,Temperature,Heat Flow (Normalized)
min,°C,W/g
15.99,90.10,-0.063
16.00,90.10,-0.064
16.01,90.10,-0.064
16.02,90.10,-0.064
16.03,90.09,-0.065
16.04,90.09,-0.066
16.05,90.08,-0.067
16.06,90.07,-0.073
16.07,90.05,-0.081
16.08,90.02,-0.092
16.09,89.99,-0.105
16.10,89.95,-0.118
16.11,89.90,-0.131
16.12,89.85,-0.149
16.13,89.79,-0.167
16.14,89.73,-0.183
16.15,89.66,-0.201
16.16,89.59,-0.219
16.17,89.51,-0.236
16.18,89.44,-0.252
16.19,89.36,-0.266
16.20,89.28,-0.283
16.21,89.20,-0.294
16.22,89.11,-0.308
16.23,89.03,-0.321
16.24,88.94,-0.333
16.25,88.86,-0.341
16.26,88.77,-0.353
16.27,88.68,-0.362
16.28,88.59,-0.368
16.29,88.50,-0.380
16.30,88.41,-0.386
16.31,88.31,-0.393
16.32,88.22,-0.401
16.33,88.13,-0.406
16.34,88.03,-0.410
16.35,87.94,-0.416
16.36,87.85,-0.422
16.37,87.75,-0.423
16.38,87.66,-0.429
16.39,87.56,-0.433
16.40,87.46,-0.435
16.41,87.37,-0.438
16.42,87.27,-0.441
16.43,87.17,-0.443
16.44,87.08,-0.446
16.45,86.98,-0.447
16.46,86.89,-0.451
16.47,86.79,-0.452
16.48,86.69,-0.453
16.49,86.59,-0.454
16.50,86.50,-0.456
16.51,86.40,-0.457
16.52,86.30,-0.457
16.53,86.20,-0.459
16.54,86.11,-0.459
16.55,86.01,-0.460
16.56,85.91,-0.461
16.57,85.81,-0.461
16.58,85.71,-0.462
16.59,85.62,-0.462
16.60,85.52,-0.462
16.61,85.42,-0.462
16.62,85.32,-0.463
16.63,85.22,-0.463
16.64,85.12,-0.464
16.65,85.02,-0.464
16.66,84.93,-0.464
16.67,84.83,-0.465
16.68,84.73,-0.465
16.69,84.63,-0.465
16.70,84.53,-0.465
16.71,84.43,-0.466
16.72,84.33,-0.466
16.73,84.23,-0.466
16.74,84.13,-0.466
16.75,84.04,-0.466
16.76,83.94,-0.467
16.77,83.84,-0.467
16.78,83.74,-0.467
16.79,83.64,-0.467
16.80,83.54,-0.467
16.81,83.44,-0.467
16.82,83.34,-0.467
16.83,83.24,-0.467
16.84,83.14,-0.467
16.85,83.05,-0.467
16.86,82.95,-0.468
16.87,82.85,-0.468
16.88,82.75,-0.468
16.89,82.65,-0.468
16.90,82.55,-0.468
16.91,82.45,-0.468
16.92,82.35,-0.468
16.93,82.25,-0.468
16.94,82.15,-0.468
16.95,82.05,-0.468
16.96,81.95,-0.468
16.97,81.85,-0.468
16.98,81.75,-0.468
16.99,81.66,-0.468
17.00,81.56,-0.468
17.01,81.46,-0.468
17.02,81.36,-0.468
17.03,81.26,-0.468
17.04,81.16,-0.468
17.05,81.06,-0.467
17.06,80.96,-0.467
17.07,80.86,-0.467
17.08,80.76,-0.467
17.09,80.66,-0.467
17.10,80.56,-0.467
17.11,80.46,-0.467
17.12,80.36,-0.467
17.13,80.26,-0.467
17.14,80.16,-0.467
17.15,80.06,-0.467
17.16,79.96,-0.467
17.17,79.86,-0.466
17.18,79.76,-0.466
17.19,79.66,-0.466
17.20,79.56,-0.466
17.21,79.46,-0.466
17.22,79.36,-0.466
17.23,79.27,-0.465
17.24,79.17,-0.465
17.25,79.07,-0.465
17.26,78.97,-0.465
17.27,78.87,-0.465
17.28,78.77,-0.465
17.29,78.67,-0.465
17.30,78.57,-0.464
17.31,78.47,-0.464
17.32,78.37,-0.464
17.33,78.27,-0.464
17.34,78.17,-0.464
17.35,78.07,-0.464
17.36,77.97,-0.463
17.37,77.87,-0.463
17.38,77.77,-0.463
17.39,77.67,-0.463
17.40,77.57,-0.463
17.41,77.47,-0.462
17.42,77.37,-0.462
17.43,77.27,-0.462
17.44,77.17,-0.462
17.45,77.07,-0.462
17.46,76.97,-0.461
17.47,76.87,-0.461
17.48,76.77,-0.461
17.49,76.67,-0.461
17.50,76.57,-0.461
17.51,76.47,-0.461
17.52,76.37,-0.460
17.53,76.27,-0.460
17.54,76.17,-0.460
17.55,76.07,-0.460
17.56,75.97,-0.460
17.57,75.87,-0.459
17.58,75.77,-0.459
17.59,75.67,-0.459
17.60,75.57,-0.459
17.61,75.47,-0.459
17.62,75.37,-0.458
17.63,75.27,-0.458
17.64,75.17,-0.458
17.65,75.07,-0.458
17.66,74.97,-0.457
17.67,74.87,-0.457
17.68,74.78,-0.457
17.69,74.68,-0.457
17.70,74.58,-0.457
17.71,74.48,-0.456
17.72,74.37,-0.456
17.73,74.28,-0.456
17.74,74.18,-0.456
17.75,74.07,-0.455
17.76,73.98,-0.455
17.77,73.88,-0.455
17.78,73.78,-0.455
17.79,73.68,-0.454
17.80,73.58,-0.454
17.81,73.48,-0.454
17.82,73.38,-0.454
17.83,73.28,-0.453
17.84,73.18,-0.453
17.85,73.08,-0.453
17.86,72.98,-0.453
17.87,72.88,-0.453
17.88,72.78,-0.452
17.89,72.68,-0.452
17.90,72.58,-0.452
17.91,72.48,-0.452
17.92,72.38,-0.452
17.93,72.28,-0.451
17.94,72.18,-0.451
17.95,72.08,-0.451
17.96,71.98,-0.450
17.97,71.88,-0.450
17.98,71.78,-0.450
17.99,71.68,-0.450
18.00,71.58,-0.450
18.01,71.48,-0.450
18.02,71.38,-0.450
18.03,71.28,-0.449
18.04,71.18,-0.449
18.05,71.08,-0.449
18.06,70.98,-0.449
18.07,70.88,-0.449
18.08,70.78,-0.448
18.09,70.68,-0.448
18.10,70.58,-0.448
18.11,70.48,-0.448
18.12,70.38,-0.448
18.13,70.28,-0.448
18.14,70.18,-0.448
18.15,70.08,-0.447
18.16,69.98,-0.447
18.17,69.88,-0.447
18.18,69.78,-0.447
18.19,69.68,-0.447
18.20,69.58,-0.446
18.21,69.48,-0.446
18.22,69.38,-0.446
18.23,69.28,-0.446
18.24,69.18,-0.446
18.25,69.08,-0.446
18.26,68.98,-0.445
18.27,68.88,-0.445
18.28,68.78,-0.445
18.29,68.68,-0.445
18.30,68.58,-0.445
18.31,68.48,-0.445
18.32,68.38,-0.445
18.33,68.28,-0.443
18.34,68.18,-0.443
18.35,68.08,-0.443
18.36,67.98,-0.443
18.37,67.88,-0.443
18.38,67.78,-0.442
18.39,67.68,-0.442
18.40,67.58,-0.442
18.41,67.48,-0.442
18.42,67.38,-0.442
18.43,67.28,-0.442
18.44,67.18,-0.442
18.45,67.08,-0.442
18.46,66.98,-0.442
18.47,66.89,-0.442
18.48,66.78,-0.441
18.49,66.68,-0.441
18.50,66.58,-0.441
18.51,66.48,-0.441
18.52,66.38,-0.441
18.53,66.28,-0.441
18.54,66.19,-0.440
18.55,66.09,-0.440
18.56,65.99,-0.440
18.57,65.89,-0.440
18.58,65.79,-0.440
18.59,65.69,-0.440
18.60,65.59,-0.439
18.61,65.49,-0.439
18.62,65.39,-0.439
18.63,65.29,-0.439
18.64,65.19,-0.439
18.65,65.09,-0.439
18.66,64.99,-0.439
18.67,64.89,-0.438
18.68,64.79,-0.438
18.69,64.69,-0.438
18.70,64.59,-0.438
18.71,64.49,-0.438
18.72,64.39,-0.438
18.73,64.29,-0.438
18.74,64.19,-0.437
18.75,64.09,-0.437
18.76,63.99,-0.437
18.77,63.89,-0.437
18.78,63.79,-0.437
18.79,63.69,-0.437
18.80,63.59,-0.437
18.81,63.49,-0.436
18.82,63.39,-0.436
18.83,63.29,-0.436
18.84,63.19,-0.436
18.85,63.09,-0.436
18.86,62.99,-0.436
18.87,62.89,-0.436
18.88,62.79,-0.436
18.89,62.69,-0.435
18.90,62.59,-0.435
18.91,62.49,-0.435
18.92,62.39,-0.435
18.93,62.29,-0.435
18.94,62.19,-0.435
18.95,62.09,-0.435
18.96,61.99,-0.435
18.97,61.89,-0.434
18.98,61.79,-0.434
18.99,61.69,-0.434
19.00,61.59,-0.434
19.01,61.49,-0.434
19.02,61.39,-0.434
19.03,61.29,-0.434
19.04,61.19,-0.433
19.05,61.09,-0.433
19.06,60.99,-0.433
19.07,60.89,-0.433
19.08,60.79,-0.433
19.09,60.69,-0.433
19.10,60.59,-0.433
19.11,60.49,-0.432
19.12,60.39,-0.432
19.13,60.29,-0.432
19.14,60.19,-0.432
19.15,60.09,-0.432
19.16,59.99,-0.432
19.17,59.89,-0.432
19.18,59.79,-0.431
19.19,59.69,-0.431
19.20,59.59,-0.431
19.21,59.49,-0.431
19.22,59.39,-0.431
19.23,59.29,-0.431
19.24,59.19,-0.431
19.25,59.09,-0.430
19.26,58.99,-0.430
19.27,58.89,-0.430
19.28,58.79,-0.430
19.29,58.69,-0.430
19.30,58.59,-0.430
19.31,58.49,-0.430
19.32,58.39,-0.429
19.33,58.29,-0.429
19.34,58.19,-0.429
19.35,58.09,-0.429
19.36,57.99,-0.429
19.37,57.89,-0.429
19.38,57.79,-0.429
19.39,57.69,-0.429
19.40,57.59,-0.429
19.41,57.49,-0.429
19.42,57.39,-0.428
19.43,57.29,-0.428
19.44,57.20,-0.428
19.45,57.09,-0.428
19.46,57.00,-0.428
19.47,56.89,-0.428
19.48,56.79,-0.428
19.49,56.69,-0.428
19.50,56.60,-0.428
19.51,56.49,-0.427
19.52,56.40,-0.427
19.53,56.30,-0.427
19.54,56.20,-0.427
19.55,56.09,-0.427
19.56,56.00,-0.427
19.57,55.90,-0.427
19.58,55.80,-0.426
19.59,55.70,-0.426
19.60,55.60,-0.426
19.61,55.50,-0.426
19.62,55.40,-0.426
19.63,55.30,-0.426
19.64,55.20,-0.426
19.65,55.10,-0.425
19.66,55.00,-0.425
19.67,54.90,-0.425
19.68,54.80,-0.425
19.69,54.70,-0.425
19.70,54.60,-0.425
19.71,54.50,-0.425
19.72,54.40,-0.424
19.73,54.30,-0.424
19.74,54.20,-0.424
19.75,54.10,-0.424
19.76,54.00,-0.424
19.77,53.90,-0.424
19.78,53.80,-0.424
19.79,53.70,-0.424
19.80,53.60,-0.424
19.81,53.50,-0.423
19.82,53.40,-0.423
19.83,53.30,-0.423
[...]
67.89,-22.64,0.256
67.90,-22.54,0.256
67.91,-22.44,0.256
67.92,-22.34,0.256
67.93,-22.24,0.256
67.94,-22.14,0.256
67.95,-22.04,0.256
67.96,-21.94,0.256
67.97,-21.84,0.256
67.98,-21.74,0.257
67.99,-21.64,0.257
68.00,-21.54,0.257
68.01,-21.44,0.257
68.02,-21.34,0.257
68.03,-21.24,0.257
68.04,-21.14,0.257
68.05,-21.04,0.258
68.06,-20.93,0.258
68.07,-20.83,0.258
68.08,-20.73,0.258
68.09,-20.63,0.258
68.10,-20.53,0.258
68.11,-20.43,0.258
68.12,-20.33,0.258
68.13,-20.23,0.258
68.14,-20.13,0.259
68.15,-20.03,0.259
68.16,-19.93,0.259
68.17,-19.83,0.259
68.18,-19.73,0.259
68.19,-19.63,0.259
68.20,-19.53,0.259
68.21,-19.43,0.259
68.22,-19.33,0.259
68.23,-19.23,0.259
68.24,-19.13,0.259
68.25,-19.03,0.260
68.26,-18.93,0.260
68.27,-18.83,0.260
68.28,-18.73,0.260
68.29,-18.63,0.260
68.30,-18.53,0.260
68.31,-18.43,0.260
68.32,-18.33,0.261
68.33,-18.23,0.261
68.34,-18.13,0.261
68.35,-18.03,0.261
68.36,-17.93,0.261
68.37,-17.83,0.261
68.38,-17.73,0.262
68.39,-17.63,0.262
68.40,-17.53,0.262
68.41,-17.43,0.262
68.42,-17.33,0.262
68.43,-17.23,0.262
68.44,-17.13,0.262
68.45,-17.03,0.262
68.46,-16.93,0.263
68.47,-16.83,0.263
68.48,-16.73,0.263
68.49,-16.63,0.263
68.50,-16.53,0.263
68.51,-16.43,0.263
68.52,-16.33,0.264
68.53,-16.23,0.264
68.54,-16.13,0.264
68.55,-16.03,0.264
68.56,-15.93,0.265
68.57,-15.83,0.265
68.58,-15.73,0.265
68.59,-15.63,0.265
68.60,-15.53,0.266
68.61,-15.43,0.266
68.62,-15.33,0.266
68.63,-15.23,0.266
68.64,-15.13,0.267
68.65,-15.03,0.267
68.66,-14.93,0.267
68.67,-14.83,0.267
68.68,-14.73,0.268
68.69,-14.63,0.268
68.70,-14.53,0.268
68.71,-14.43,0.269
68.72,-14.33,0.269
68.73,-14.23,0.270
68.74,-14.13,0.270
68.75,-14.03,0.270
68.76,-13.93,0.271
68.77,-13.83,0.271
68.78,-13.73,0.272
68.79,-13.63,0.272
68.80,-13.53,0.272
68.81,-13.43,0.273
68.82,-13.33,0.274
68.83,-13.23,0.274
68.84,-13.13,0.275
68.85,-13.03,0.275
68.86,-12.93,0.275
68.87,-12.83,0.276
68.88,-12.73,0.276
68.89,-12.63,0.277
68.90,-12.53,0.278
68.91,-12.43,0.278
68.92,-12.33,0.279
68.93,-12.23,0.280
68.94,-12.13,0.280
68.95,-12.03,0.281
68.96,-11.93,0.281
68.97,-11.83,0.281
68.98,-11.73,0.282
68.99,-11.63,0.283
69.00,-11.53,0.284
69.01,-11.43,0.284
69.02,-11.33,0.285
69.03,-11.23,0.285
69.04,-11.13,0.286
69.05,-11.03,0.287
69.06,-10.93,0.287
69.07,-10.83,0.287
69.08,-10.73,0.288
69.09,-10.63,0.288
69.10,-10.53,0.289
69.11,-10.43,0.289
69.12,-10.33,0.289
69.13,-10.23,0.290
69.14,-10.13,0.290
69.15,-10.03,0.290
69.16,-9.94,0.291
69.17,-9.83,0.291
69.18,-9.73,0.291
69.19,-9.63,0.292
69.20,-9.53,0.292
69.21,-9.43,0.292
69.22,-9.33,0.292
69.23,-9.23,0.293
69.24,-9.13,0.293
69.25,-9.03,0.293
69.26,-8.93,0.293
69.27,-8.83,0.293
69.28,-8.73,0.293
69.29,-8.63,0.293
69.30,-8.53,0.293
69.31,-8.43,0.293
69.32,-8.33,0.294
69.33,-8.23,0.294
69.34,-8.13,0.294
69.35,-8.03,0.294
69.36,-7.93,0.294
69.37,-7.83,0.294
69.38,-7.73,0.294
69.39,-7.63,0.294
69.40,-7.53,0.294
69.41,-7.43,0.294
69.42,-7.33,0.294
69.43,-7.23,0.294
69.44,-7.13,0.294
69.45,-7.03,0.294
69.46,-6.93,0.294
69.47,-6.83,0.294
69.48,-6.73,0.294
69.49,-6.63,0.294
69.50,-6.53,0.294
69.51,-6.43,0.294
69.52,-6.33,0.294
69.53,-6.23,0.294
69.54,-6.13,0.294
69.55,-6.03,0.294
69.56,-5.93,0.294
69.57,-5.83,0.294
69.58,-5.73,0.294
69.59,-5.63,0.294
69.60,-5.53,0.294
69.61,-5.43,0.294
69.62,-5.33,0.294
69.63,-5.23,0.293
69.64,-5.13,0.293
69.65,-5.03,0.293
69.66,-4.93,0.293
69.67,-4.83,0.293
69.68,-4.73,0.293
69.69,-4.63,0.293
69.70,-4.53,0.293
69.71,-4.43,0.293
69.72,-4.33,0.293
69.73,-4.23,0.293
69.74,-4.12,0.293
69.75,-4.03,0.293
69.76,-3.93,0.293
69.77,-3.83,0.293
69.78,-3.73,0.293
69.79,-3.62,0.293
69.80,-3.53,0.293
69.81,-3.43,0.293
69.82,-3.33,0.293
69.83,-3.22,0.293
69.84,-3.13,0.293
69.85,-3.02,0.293
69.86,-2.92,0.293
69.87,-2.83,0.293
69.88,-2.72,0.293
69.89,-2.62,0.293
69.90,-2.52,0.293
69.91,-2.42,0.293
69.92,-2.32,0.293
69.93,-2.22,0.293
69.94,-2.12,0.293
69.95,-2.02,0.293
69.96,-1.92,0.293
69.97,-1.82,0.293
69.98,-1.72,0.293
69.99,-1.62,0.293
70.00,-1.52,0.293
70.01,-1.42,0.293
70.02,-1.32,0.294
70.03,-1.22,0.294
70.04,-1.12,0.294
70.05,-1.02,0.293
70.06,-0.92,0.293
70.07,-0.82,0.294
70.08,-0.72,0.294
70.09,-0.62,0.294
70.10,-0.52,0.294
70.11,-0.42,0.294
70.12,-0.32,0.294
70.13,-0.22,0.294
70.14,-0.12,0.294
70.15,-0.02,0.294
70.16,0.08,0.294
70.17,0.18,0.294
70.18,0.28,0.294
70.19,0.38,0.294
70.20,0.48,0.294
70.21,0.58,0.294
70.22,0.68,0.294
70.23,0.78,0.294
70.24,0.88,0.294
70.25,0.98,0.294
70.26,1.08,0.294
70.27,1.18,0.294
70.28,1.28,0.294
70.29,1.38,0.294
70.30,1.48,0.294
70.31,1.58,0.294
70.32,1.68,0.294
70.33,1.78,0.294
70.34,1.88,0.295
70.35,1.98,0.295
70.36,2.08,0.295
70.37,2.18,0.295
70.38,2.28,0.295
70.39,2.38,0.295
70.40,2.49,0.295
70.41,2.58,0.295
70.42,2.68,0.295
70.43,2.79,0.295
70.44,2.88,0.295
70.45,2.99,0.295
70.46,3.09,0.295
70.47,3.19,0.295
70.48,3.29,0.295
70.49,3.39,0.295
70.50,3.49,0.295
70.51,3.59,0.295
70.52,3.69,0.295
70.53,3.79,0.295
70.54,3.89,0.295
70.55,3.99,0.295
70.56,4.09,0.295
70.57,4.19,0.296
70.58,4.29,0.296
70.59,4.39,0.296
70.60,4.49,0.296
70.61,4.59,0.296
70.62,4.69,0.296
70.63,4.79,0.296
70.64,4.89,0.296
70.65,4.99,0.296
70.66,5.09,0.296
70.67,5.19,0.296
70.68,5.29,0.296
70.69,5.39,0.296
70.70,5.49,0.296
70.71,5.59,0.296
70.72,5.69,0.296
70.73,5.79,0.297
70.74,5.89,0.297
70.75,5.99,0.297
70.76,6.09,0.297
70.77,6.19,0.297
70.78,6.29,0.297
70.79,6.39,0.297
70.80,6.49,0.297
70.81,6.59,0.297
70.82,6.69,0.297
70.83,6.79,0.297
70.84,6.89,0.297
70.85,6.99,0.297
70.86,7.09,0.297
70.87,7.19,0.298
70.88,7.29,0.298
70.89,7.39,0.298
70.90,7.49,0.298
70.91,7.59,0.298
70.92,7.69,0.298
70.93,7.79,0.298
70.94,7.89,0.298
70.95,7.99,0.298
70.96,8.09,0.298
70.97,8.19,0.298
70.98,8.29,0.298
70.99,8.39,0.298
71.00,8.49,0.298
71.01,8.59,0.298
71.02,8.69,0.298
71.03,8.79,0.298
71.04,8.89,0.299
71.05,8.99,0.299
71.06,9.09,0.299
71.07,9.19,0.299
71.08,9.29,0.299
71.09,9.39,0.299
71.10,9.49,0.299
71.11,9.59,0.299
71.12,9.69,0.299
71.13,9.79,0.299
71.14,9.89,0.299
71.15,9.99,0.299
71.16,10.09,0.300
71.17,10.19,0.300
71.18,10.29,0.300
71.19,10.39,0.300
71.20,10.49,0.300
71.21,10.59,0.300
71.22,10.69,0.300
71.23,10.79,0.300
71.24,10.89,0.300
71.25,10.99,0.300
71.26,11.09,0.300
71.27,11.19,0.300
71.28,11.30,0.300
71.29,11.39,0.300
71.30,11.50,0.300
71.31,11.59,0.300
71.32,11.70,0.301
71.33,11.80,0.301
71.34,11.89,0.301
71.35,12.00,0.301
71.36,12.09,0.301
71.37,12.20,0.301
71.38,12.30,0.301
71.39,12.39,0.301
71.40,12.50,0.301
71.41,12.60,0.301
71.42,12.70,0.301
71.43,12.80,0.301
71.44,12.90,0.301
71.45,13.00,0.301
71.46,13.10,0.302
71.47,13.20,0.302
71.48,13.30,0.302
71.49,13.40,0.302
71.50,13.50,0.302
71.51,13.60,0.302
71.52,13.70,0.302
71.53,13.80,0.302
71.54,13.90,0.302
71.55,14.00,0.302
71.56,14.10,0.302
71.57,14.20,0.302
71.58,14.30,0.302
71.59,14.40,0.303
71.60,14.50,0.303
71.61,14.60,0.303
71.62,14.70,0.303
71.63,14.80,0.303
71.64,14.90,0.303
71.65,15.00,0.303
71.66,15.10,0.303
71.67,15.20,0.303
71.68,15.30,0.303
71.69,15.40,0.303
71.70,15.50,0.303
71.71,15.60,0.303
71.72,15.70,0.303
71.73,15.80,0.303
71.74,15.90,0.303
71.75,16.00,0.303
71.76,16.10,0.303
71.77,16.20,0.304
71.78,16.30,0.304
71.79,16.40,0.304
71.80,16.50,0.304
71.81,16.60,0.304
71.82,16.70,0.304
71.83,16.80,0.304
71.84,16.90,0.304
71.85,17.00,0.304
71.86,17.10,0.304
71.87,17.20,0.304
71.88,17.30,0.304
71.89,17.40,0.304
71.90,17.50,0.304
71.91,17.60,0.304
71.92,17.70,0.304
71.93,17.80,0.304
71.94,17.90,0.304
71.95,18.00,0.304
71.96,18.10,0.305
71.97,18.20,0.305
71.98,18.30,0.305
71.99,18.40,0.305
72.00,18.50,0.305
72.01,18.60,0.305
72.02,18.70,0.305
72.03,18.80,0.305
72.04,18.90,0.305
72.05,19.00,0.305
72.06,19.10,0.305
72.07,19.20,0.305
72.08,19.30,0.305
72.09,19.40,0.305
72.10,19.50,0.306
72.11,19.60,0.306
72.12,19.70,0.306
72.13,19.80,0.306
72.14,19.90,0.306
72.15,20.00,0.306
72.16,20.11,0.306
72.17,20.21,0.306
72.18,20.31,0.306
72.19,20.41,0.306
72.20,20.50,0.306
72.21,20.61,0.306
72.22,20.70,0.307
72.23,20.81,0.307
72.24,20.90,0.307
72.25,21.00,0.307
72.26,21.10,0.307
72.27,21.20,0.307
72.28,21.30,0.307
72.29,21.41,0.307
72.30,21.51,0.307
72.31,21.61,0.307
72.32,21.71,0.307
72.33,21.81,0.308
72.34,21.91,0.308
72.35,22.01,0.308
72.36,22.11,0.308
72.37,22.21,0.308
72.38,22.31,0.308
72.39,22.41,0.308
72.40,22.51,0.308
72.41,22.61,0.308
72.42,22.71,0.308
72.43,22.81,0.308
72.44,22.91,0.308
72.45,23.01,0.308
72.46,23.11,0.309
72.47,23.21,0.309
72.48,23.31,0.309
72.49,23.41,0.309
72.50,23.51,0.309
72.51,23.61,0.309
72.52,23.71,0.309
72.53,23.81,0.309
72.54,23.91,0.309
72.55,24.01,0.309
72.56,24.11,0.309
72.57,24.21,0.309
72.58,24.31,0.309
72.59,24.41,0.309
72.60,24.51,0.309
72.61,24.61,0.309
72.62,24.71,0.309
72.63,24.81,0.310
72.64,24.91,0.310
72.65,25.01,0.310
72.66,25.11,0.310
72.67,25.21,0.310
72.68,25.31,0.310
72.69,25.41,0.310
72.70,25.51,0.310
72.71,25.61,0.310
72.72,25.71,0.310
72.73,25.81,0.310
72.74,25.91,0.310
72.75,26.01,0.310
72.76,26.11,0.310
72.77,26.21,0.311
72.78,26.31,0.311
72.79,26.41,0.311
72.80,26.51,0.311
72.81,26.61,0.311
72.82,26.71,0.311
72.83,26.81,0.311
72.84,26.91,0.311
72.85,27.01,0.311
72.86,27.11,0.311
72.87,27.21,0.311
72.88,27.31,0.312
72.89,27.41,0.312
72.90,27.51,0.312
72.91,27.61,0.312
72.92,27.71,0.312
72.93,27.81,0.312
72.94,27.91,0.312
72.95,28.01,0.312
72.96,28.11,0.312
72.97,28.21,0.312
72.98,28.31,0.312
72.99,28.41,0.312
73.00,28.51,0.313
73.01,28.61,0.313
73.02,28.71,0.313
73.03,28.81,0.313
73.04,28.91,0.313
73.05,29.01,0.313
73.06,29.12,0.313
73.07,29.21,0.313
73.08,29.31,0.313
73.09,29.41,0.313
73.10,29.51,0.313
73.11,29.61,0.313
73.12,29.71,0.313
73.13,29.82,0.313
73.14,29.92,0.314
73.15,30.02,0.314
73.16,30.11,0.314
73.17,30.22,0.314
73.18,30.32,0.314
73.19,30.42,0.314
73.20,30.51,0.314
73.21,30.62,0.314
73.22,30.72,0.314
73.23,30.82,0.314
73.24,30.92,0.314
73.25,31.02,0.314
73.26,31.12,0.314
73.27,31.22,0.315
73.28,31.32,0.315
73.29,31.42,0.315
73.30,31.52,0.315
73.31,31.62,0.315
73.32,31.72,0.315
73.33,31.82,0.315
73.34,31.92,0.315
73.35,32.02,0.315
73.36,32.12,0.315
73.37,32.22,0.315
73.38,32.32,0.315
73.39,32.42,0.315
73.40,32.52,0.315
73.41,32.62,0.316
73.42,32.72,0.316
73.43,32.82,0.316
73.44,32.92,0.316
73.45,33.02,0.316
73.46,33.12,0.316
73.47,33.22,0.316
73.48,33.32,0.316
73.49,33.42,0.316
73.50,33.52,0.316
73.51,33.62,0.316
73.52,33.72,0.316
73.53,33.82,0.316
73.54,33.92,0.316
73.55,34.02,0.316
73.56,34.12,0.317
73.57,34.22,0.317
73.58,34.32,0.317
73.59,34.42,0.317
73.60,34.52,0.317
73.61,34.62,0.317
73.62,34.72,0.317
73.63,34.82,0.317
73.64,34.92,0.317
73.65,35.02,0.317
73.66,35.12,0.317
73.67,35.22,0.317
73.68,35.32,0.317
73.69,35.42,0.317
73.70,35.52,0.318
73.71,35.62,0.318
73.72,35.72,0.318
73.73,35.82,0.318
73.74,35.92,0.318
73.75,36.02,0.318
73.76,36.12,0.318
73.77,36.22,0.318
73.78,36.32,0.318
73.79,36.42,0.318
73.80,36.52,0.318
73.81,36.62,0.318
73.82,36.72,0.318
73.83,36.82,0.318
73.84,36.92,0.319
73.85,37.02,0.319
73.86,37.12,0.319
73.87,37.22,0.319
73.88,37.33,0.319
73.89,37.42,0.319
73.90,37.53,0.319
73.91,37.63,0.319
73.92,37.72,0.319
73.93,37.83,0.319
73.94,37.93,0.319
73.95,38.03,0.319
73.96,38.13,0.319
73.97,38.23,0.320
73.98,38.33,0.320
73.99,38.43,0.320
74.00,38.53,0.320
74.01,38.63,0.320
74.02,38.72,0.320
74.03,38.83,0.320
74.04,38.93,0.320
74.05,39.03,0.320
74.06,39.13,0.320
74.07,39.23,0.320
74.08,39.33,0.320
74.09,39.43,0.320
74.10,39.53,0.320
74.11,39.63,0.320
74.12,39.73,0.321
74.13,39.83,0.321
74.14,39.93,0.321
74.15,40.03,0.321
74.16,40.13,0.321
74.17,40.23,0.321
74.18,40.33,0.321
74.19,40.43,0.321
74.20,40.53,0.321
74.21,40.63,0.321
74.22,40.73,0.321
74.23,40.83,0.321
74.24,40.93,0.321
74.25,41.03,0.321
74.26,41.13,0.321
74.27,41.23,0.322
74.28,41.33,0.322
74.29,41.43,0.322
74.30,41.53,0.322
74.31,41.63,0.322
74.32,41.73,0.322
74.33,41.83,0.322
74.34,41.93,0.322
74.35,42.03,0.322
74.36,42.13,0.322
74.37,42.23,0.322
74.38,42.33,0.322
74.39,42.43,0.322
74.40,42.53,0.322
74.41,42.63,0.322
74.42,42.73,0.323
74.43,42.83,0.323
74.44,42.93,0.323
74.45,43.03,0.323
74.46,43.13,0.323
74.47,43.23,0.323
74.48,43.33,0.323
74.49,43.43,0.323
74.50,43.53,0.323
74.51,43.63,0.323
74.52,43.73,0.323
74.53,43.83,0.323
74.54,43.93,0.323
74.55,44.03,0.324
74.56,44.13,0.324
74.57,44.23,0.324
74.58,44.33,0.324
74.59,44.43,0.324
74.60,44.53,0.324
74.61,44.63,0.324
74.62,44.73,0.324
74.63,44.83,0.324
74.64,44.93,0.324
74.65,45.03,0.324
74.66,45.13,0.324
74.67,45.23,0.324
74.68,45.33,0.324
74.69,45.43,0.324
74.70,45.53,0.325
74.71,45.63,0.325
74.72,45.73,0.325
74.73,45.83,0.325
74.74,45.93,0.325
74.75,46.03,0.325
74.76,46.13,0.325
74.77,46.23,0.325
74.78,46.33,0.325
74.79,46.43,0.325
74.80,46.53,0.325
74.81,46.63,0.325
74.82,46.73,0.325
74.83,46.83,0.325
74.84,46.93,0.326
74.85,47.03,0.326
74.86,47.13,0.326
74.87,47.23,0.326
74.88,47.34,0.326
74.89,47.44,0.326
74.90,47.54,0.326
74.91,47.64,0.326
74.92,47.73,0.326
74.93,47.83,0.326
74.94,47.94,0.326
74.95,48.04,0.326
74.96,48.13,0.326
74.97,48.24,0.326
74.98,48.33,0.327
74.99,48.43,0.327
75.00,48.54,0.327
75.01,48.64,0.327
75.02,48.74,0.327
75.03,48.84,0.327
75.04,48.94,0.327
75.05,49.04,0.327
75.06,49.14,0.327
75.07,49.24,0.327
75.08,49.34,0.327
75.09,49.44,0.327
75.10,49.54,0.327
75.11,49.64,0.327
75.12,49.74,0.328
75.13,49.84,0.328
75.14,49.94,0.328
75.15,50.04,0.328
75.16,50.14,0.328
75.17,50.24,0.328
75.18,50.34,0.328
75.19,50.44,0.328
75.20,50.54,0.328
75.21,50.64,0.328
75.22,50.74,0.328
75.23,50.84,0.328
75.24,50.94,0.328
75.25,51.04,0.328
75.26,51.14,0.328
75.27,51.24,0.328
75.28,51.34,0.329
75.29,51.44,0.329
75.30,51.54,0.329
75.31,51.64,0.329
75.32,51.74,0.329
75.33,51.84,0.329
75.34,51.94,0.329
75.35,52.04,0.329
75.36,52.14,0.329
75.37,52.24,0.329
75.38,52.34,0.329
75.39,52.44,0.329
75.40,52.54,0.329
75.41,52.64,0.329
75.42,52.74,0.329
75.43,52.84,0.329
75.44,52.94,0.329
75.45,53.04,0.330
75.46,53.14,0.330
75.47,53.24,0.330
75.48,53.34,0.330
75.49,53.44,0.330
75.50,53.54,0.330
75.51,53.64,0.330
75.52,53.74,0.330
75.53,53.84,0.330
75.54,53.94,0.330
75.55,54.04,0.330
75.56,54.14,0.330
75.57,54.24,0.330
75.58,54.34,0.330
75.59,54.44,0.330
75.60,54.54,0.330
75.61,54.64,0.330
75.62,54.74,0.331
75.63,54.84,0.331
75.64,54.94,0.331
75.65,55.04,0.331
75.66,55.14,0.331
75.67,55.24,0.331
75.68,55.34,0.331
75.69,55.44,0.331
75.70,55.54,0.331
75.71,55.64,0.331
75.72,55.74,0.331
75.73,55.84,0.331
75.74,55.94,0.331
75.75,56.04,0.331
75.76,56.15,0.331
75.77,56.24,0.331
75.78,56.35,0.331
75.79,56.44,0.331
75.80,56.54,0.331
75.81,56.64,0.331
75.82,56.74,0.332
75.83,56.84,0.332
75.84,56.94,0.332
75.85,57.04,0.332
75.86,57.14,0.332
75.87,57.24,0.332
75.88,57.34,0.332
75.89,57.45,0.332
75.90,57.54,0.332
75.91,57.65,0.332
75.92,57.75,0.332
75.93,57.85,0.332
75.94,57.95,0.332
75.95,58.05,0.332
75.96,58.15,0.332
75.97,58.25,0.332
75.98,58.34,0.332
75.99,58.45,0.332
76.00,58.55,0.332
76.01,58.65,0.333
76.02,58.75,0.333
76.03,58.85,0.333
76.04,58.95,0.333
76.05,59.05,0.333
76.06,59.15,0.333
76.07,59.25,0.333
76.08,59.35,0.333
76.09,59.45,0.333
76.10,59.55,0.333
76.11,59.65,0.333
76.12,59.75,0.333
76.13,59.85,0.333
76.14,59.95,0.333
76.15,60.05,0.333
76.16,60.15,0.334
76.17,60.25,0.334
76.18,60.35,0.334
76.19,60.45,0.334
76.20,60.55,0.334
76.21,60.65,0.334
76.22,60.75,0.334
76.23,60.85,0.334
76.24,60.95,0.334
76.25,61.05,0.334
76.26,61.15,0.334
76.27,61.25,0.334
76.28,61.35,0.334
76.29,61.45,0.334
76.30,61.55,0.334
76.31,61.65,0.334
76.32,61.75,0.335
76.33,61.85,0.335
76.34,61.95,0.335
76.35,62.05,0.335
76.36,62.15,0.335
76.37,62.25,0.335
76.38,62.35,0.335
76.39,62.45,0.335
76.40,62.55,0.335
76.41,62.65,0.335
76.42,62.75,0.335
76.43,62.85,0.335
76.44,62.95,0.335
76.45,63.05,0.335
76.46,63.15,0.335
76.47,63.25,0.335
76.48,63.35,0.335
76.49,63.45,0.335
76.50,63.55,0.335
76.51,63.65,0.336
76.52,63.75,0.336
76.53,63.85,0.336
76.54,63.95,0.336
76.55,64.05,0.336
76.56,64.15,0.336
76.57,64.25,0.336
76.58,64.35,0.336
76.59,64.45,0.336
76.60,64.55,0.336
76.61,64.66,0.336
76.62,64.75,0.336
76.63,64.86,0.336
76.64,64.95,0.336
76.65,65.06,0.336
76.66,65.16,0.336
76.67,65.26,0.336
76.68,65.36,0.336
76.69,65.46,0.336
76.70,65.56,0.336
76.71,65.66,0.337
76.72,65.76,0.337
76.73,65.86,0.337
76.74,65.96,0.337
76.75,66.06,0.337
76.76,66.16,0.337
76.77,66.26,0.337
76.78,66.36,0.337
76.79,66.46,0.337
76.80,66.56,0.337
76.81,66.66,0.337
76.82,66.76,0.337
76.83,66.86,0.337
76.84,66.96,0.337
76.85,67.06,0.337
76.86,67.16,0.337
76.87,67.26,0.337
76.88,67.36,0.337
76.89,67.46,0.337
76.90,67.56,0.337
76.91,67.66,0.337
76.92,67.76,0.337
76.93,67.86,0.337
76.94,67.96,0.338
76.95,68.06,0.338
76.96,68.16,0.338
76.97,68.26,0.338
76.98,68.36,0.338
76.99,68.46,0.338
77.00,68.56,0.338
77.01,68.66,0.338
77.02,68.76,0.338
77.03,68.86,0.338
77.04,68.96,0.338
77.05,69.06,0.338
77.06,69.16,0.338
77.07,69.26,0.338
77.08,69.36,0.338
77.09,69.46,0.338
77.10,69.56,0.338
77.11,69.66,0.338
77.12,69.76,0.338
77.13,69.86,0.338
77.14,69.96,0.338
77.15,70.06,0.338
77.16,70.16,0.338
77.17,70.26,0.339
77.18,70.36,0.338
77.19,70.46,0.338
77.20,70.56,0.339
77.21,70.66,0.339
77.22,70.76,0.339
77.23,70.86,0.339
77.24,70.96,0.339
77.25,71.06,0.339
77.26,71.16,0.339
77.27,71.26,0.339
77.28,71.36,0.339
77.29,71.46,0.339
77.30,71.56,0.339
77.31,71.66,0.339
77.32,71.76,0.339
77.33,71.86,0.339
77.34,71.96,0.339
77.35,72.06,0.339
77.36,72.16,0.339
77.37,72.26,0.339
77.38,72.36,0.339
77.39,72.46,0.340
77.40,72.56,0.340
77.41,72.66,0.340
77.42,72.76,0.340
77.43,72.86,0.340
77.44,72.96,0.340
77.45,73.06,0.340
77.46,73.16,0.340
77.47,73.26,0.340
77.48,73.36,0.340
77.49,73.46,0.340
77.50,73.56,0.340
77.51,73.66,0.340
77.52,73.76,0.340
77.53,73.86,0.340
77.54,73.96,0.340
77.55,74.06,0.340
77.56,74.16,0.340
77.57,74.26,0.340
77.58,74.36,0.340
77.59,74.46,0.340
77.60,74.56,0.340
77.61,74.66,0.340
77.62,74.76,0.340
77.63,74.86,0.340
77.64,74.96,0.340
77.65,75.06,0.340
77.66,75.16,0.340
77.67,75.26,0.340
77.68,75.36,0.340
77.69,75.46,0.340
77.70,75.56,0.340
77.71,75.66,0.341
77.72,75.76,0.341
77.73,75.87,0.341
77.74,75.96,0.341
77.75,76.06,0.341
77.76,76.16,0.341
77.77,76.27,0.341
77.78,76.37,0.341
77.79,76.46,0.341
77.80,76.57,0.341
77.81,76.67,0.341
77.82,76.77,0.341
77.83,76.87,0.341
77.84,76.97,0.341
77.85,77.07,0.341
77.86,77.17,0.341
77.87,77.26,0.341
77.88,77.37,0.341
77.89,77.47,0.341
77.90,77.57,0.341
77.91,77.67,0.341
77.92,77.77,0.341
77.93,77.87,0.341
77.94,77.97,0.341
77.95,78.07,0.341
77.96,78.17,0.341
77.97,78.27,0.341
77.98,78.37,0.341
77.99,78.47,0.341
78.00,78.57,0.341
78.01,78.67,0.341
78.02,78.77,0.341
78.03,78.87,0.341
78.04,78.97,0.341
78.05,79.07,0.341
78.06,79.17,0.341
78.07,79.27,0.341
78.08,79.37,0.341
78.09,79.47,0.341
78.10,79.57,0.341
78.11,79.67,0.341
78.12,79.77,0.341
78.13,79.87,0.341
78.14,79.97,0.341
78.15,80.07,0.341
78.16,80.17,0.341
78.17,80.27,0.341
78.18,80.37,0.341
78.19,80.47,0.341
78.20,80.57,0.341
78.21,80.67,0.341
78.22,80.77,0.341
78.23,80.87,0.341
78.24,80.97,0.341
78.25,81.07,0.341
78.26,81.17,0.341
78.27,81.27,0.341
78.28,81.37,0.341
78.29,81.47,0.341
78.30,81.57,0.341
78.31,81.67,0.341
78.32,81.77,0.341
78.33,81.87,0.341
78.34,81.97,0.341
78.35,82.07,0.341
78.36,82.17,0.341
78.37,82.27,0.341
78.38,82.37,0.341
78.39,82.47,0.341
78.40,82.57,0.341
78.41,82.67,0.341
78.42,82.77,0.341
78.43,82.87,0.341
78.44,82.97,0.341
78.45,83.07,0.341
78.46,83.17,0.341
78.47,83.27,0.341
78.48,83.37,0.341
78.49,83.47,0.341
78.50,83.57,0.341
78.51,83.67,0.341
78.52,83.77,0.341
78.53,83.87,0.341
78.54,83.97,0.341
78.55,84.07,0.340
78.56,84.17,0.340
78.57,84.27,0.340
78.58,84.37,0.340
78.59,84.47,0.340
78.60,84.57,0.340
78.61,84.67,0.340
78.62,84.77,0.340
78.63,84.87,0.340
78.64,84.97,0.340
78.65,85.07,0.340
78.66,85.17,0.340
78.67,85.27,0.340
78.68,85.38,0.340
78.69,85.47,0.340
78.70,85.57,0.340
78.71,85.67,0.340
78.72,85.78,0.340
78.73,85.87,0.340
78.74,85.97,0.340
78.75,86.07,0.340
78.76,86.17,0.340
78.77,86.28,0.340
78.78,86.38,0.340
78.79,86.48,0.339
78.80,86.58,0.339
78.81,86.68,0.339
78.82,86.78,0.339
78.83,86.88,0.339
78.84,86.98,0.339
78.85,87.08,0.339
78.86,87.18,0.339
78.87,87.28,0.339
78.88,87.38,0.339
78.89,87.48,0.339
78.90,87.58,0.339
78.91,87.68,0.339
78.92,87.78,0.339
78.93,87.88,0.339
78.94,87.98,
78.95,88.08,
78.96,88.18,
78.97,88.28,
78.98,88.38,
78.99,,