File: DSC/2025_04_19_CBDa_n60C_150C_5Cmin_x3.csv
Filename,2025_04_19_CBDa_n60C_150C_5Cmin_x3
Instrument name,DSC2A-00468 (192.168.1.100)
Operator,Yarger
rundate,4/19/2025
Sample name,2025_04_19_CBDa_n60C_150C_5Cmin_x3
proceduresegments,Data Off ; Equilibrate -60.00 °C; Data On ; Ramp 5.00 °C/min to 150.00 °C; Data Off ; Isothermal 0.1 min; Data On ; Ramp 10.00 °C/min to -60.00 °C; Data Off ; Isothermal 1.0 min; Data On ; Ramp 5.00 °C/min to 150.00 °C; Data Off ; Isothermal 0.1 min; Data On ; Ramp 10.00 °C/min to -60.00 °C; Data Off ; Isothermal 1.0 min; Data On ; Ramp 5.00 °C/min to 30.00 °C
[File Parameters]
Run date,4/19/2025 9:46:44 AM
Trios version,5.1.1.46572
Original File Name,
Current File Name,D:\DSC2500\JYarger\2025_04_19_CBDa_n60C_150C_5Cmin_x3.tri
[Procedure]
Procedure Name,CBDa_n60_150C_5Cmin_x3
Sample Name,2025_04_19_CBDa_n60C_150C_5Cmin_x3
Sample Mass,13.94 mg
Reference Sample Mass,0 mg
Pan Mass,52.84 mg
Pan Number,42
Reference Pan Mass,53.66 mg
Reference Pan Number,46
Pan Type,Tzero Aluminum Hermetic
Comments,Hermetic Sealed Al DSC Consumables Pan/Lids.
Project Name,CA
Operator,Yarger
Test,Custom
Unload Max Temperature,30
Unload Min Temperature,30
Load Max Temperature,30
Load Min Temperature,30
Stop on Gas Flow Error,Yes
[Signal List]
Signal #1,Time (min)
Signal #2,Temperature (°C)
Signal #3,Heat Flow (mW)
Signal #4,Delta T (µV)
Signal #5,Delta Tzero (µV)
Signal #6,Tzero Temperature (°C)
Signal #7,Cell Purge (mL/min)
Signal #8,Heater Temp (°C)
Signal #9,Power Delivered (W)
Signal #10,Reference Junction Temperature (°C)
Signal #11,Flange Temperature (°C)
Signal #12,Heat Flow Phase (rad)
Signal #13,Total Heat Capacity (J/°C)
Signal #14,Heat Capacity (J/°C)
[Configuration]
Company Name,ASU
Instrument Name,DSC2A-00468
Instrument Type,DSC2500
Serial Number,DSC2A-00468
IP,192.168.1.100
Location of Instrument,MRRC
DisplayType,Unknown
Sample Interval ,0.1 s/pt
Selected Heat Flow,T4P
Exotherm Direction,Down
Cell Serial,DRC2-00792
Lid Type,Standard
Cooler,RCS 90
Leave Cooler on at End of Sequence,On
Gas 2,Nitrogen
Gas Selected,Channel 1
Flow Rate,50 mL/min
Secondary Purge,On
Licensed Heat Flow,Heat Flow T4P
Modulation Licensed,Yes
[Versions]
Common IDD Version,1
Cortex Version,VER 2.10.2.31
Driver,5.0.0.6
GDM Version,1.0.3.3
TouchscreenVersion,1.0.0.16145
FEP Version,1.2.1.21
FEP Bootloader,2.0.0.5
AutoSampler Version,2.1.1.26
Auto Sampler Bootloader,2.0.0.5
FCM Version,1.1.0.3
FCM Bootloader,2.0.0.5
[Experiment Logs]
Experiment Log Entry # 1,Data On set to 0
Experiment Log Entry # 3,Equilibrate Segment -60 (C) Started
Experiment Log Entry # 5,Air Cool is off.
Experiment Log Entry # 7,Data On set to 1
Experiment Log Entry # 9,Ramp Segment 5 C/min to 150 Started
Experiment Log Entry # 11,Data On set to 0
Experiment Log Entry # 13,Isothermal Segment 0.1 min started
Experiment Log Entry # 15,Data On set to 1
Experiment Log Entry # 17,Ramp Segment 10 C/min to -60 Started
Experiment Log Entry # 19,Data On set to 0
Experiment Log Entry # 21,Isothermal Segment 1 min started
Experiment Log Entry # 23,Data On set to 1
Experiment Log Entry # 25,Ramp Segment 5 C/min to 150 Started
Experiment Log Entry # 27,Data On set to 0
Experiment Log Entry # 29,Isothermal Segment 0.1 min started
Experiment Log Entry # 31,Data On set to 1
Experiment Log Entry # 33,Ramp Segment 10 C/min to -60 Started
Experiment Log Entry # 35,Data On set to 0
Experiment Log Entry # 37,Isothermal Segment 1 min started
Experiment Log Entry # 39,Data On set to 1
Experiment Log Entry # 41,Ramp Segment 5 C/min to 30 Started
[Method Log]
Method Log Entry # 1,Data Off
Method Log Entry # 2,Equilibrate -60 °C
Method Log Entry # 3,Data On
Method Log Entry # 4,(Ramp 262198) Ramp 5 °C/minute to 150 °C
Method Log Entry # 5,Data Off
Method Log Entry # 6,Isothermal 0.1 minutes
Method Log Entry # 7,Data On
Method Log Entry # 8,(Ramp 262202) Ramp 10 °C/minute to -60 °C
Method Log Entry # 9,Data Off
Method Log Entry # 10,Isothermal 1 minutes
Method Log Entry # 11,Data On
Method Log Entry # 12,(Ramp 262206) Ramp 5 °C/minute to 150 °C
Method Log Entry # 13,Data Off
Method Log Entry # 14,Isothermal 0.1 minutes
Method Log Entry # 15,Data On
Method Log Entry # 16,(Ramp 262210) Ramp 10 °C/minute to -60 °C
Method Log Entry # 17,Data Off
Method Log Entry # 18,Isothermal 1 minutes
Method Log Entry # 19,Data On
Method Log Entry # 20,(Ramp 262214) Ramp 5 °C/minute to 30 °C
Cell Serial,DRC2-00792
[T1 Calibration]
Slope,-0.008529666
Offset,9.636258
Initial Temperature,98.23
GUID,f8bfdadc-4977-4fdf-ba6d-0ba9134940c3
[TZero Calibration]
Date Applied,11/29/2022 4:06:13 PM
Description,From -89.059 °C to 396.009 °C at 20.000°C/min
Gas Type,Nitrogen
Pan Type,None
Source Files 1,C:\Users\yargerlab\Desktop\DSC Data\General\TZero_calibration_11_29_22_2nd(2).tri
Source Files 2,C:\Users\yargerlab\Desktop\DSC Data\General\TZero_calibration_11_29_22_2nd(3).tri
Delta T Offset,13.05235
Delta T Slope,-0.007271007
Delta T0 Offset,-13.69128
Delta T0 Slope,0.06063341
[Temperature Calibration]
Date Applied,11/29/2022 7:12:28 PM
Description,From 106.590 °C to 186.590 °C at 10.000°C/min
Gas Type,Nitrogen
Pan Type,Tzero Aluminum Hermetic
Source Files 1,C:\Users\yargerlab\Desktop\DSC Data\General\Indium(6).tri
Measured 1,157.391
Known 1,156.598
[Cell Constant Calibration]
Date Applied,11/29/2022 7:12:29 PM
Description,From 106.590 °C to 186.590 °C at 10.000°C/min
Gas Type,Nitrogen
Pan Type,Tzero Aluminum Hermetic
Source Files 1,C:\Users\yargerlab\Desktop\DSC Data\General\Indium(6).tri
T4P KCell,1.006051
Onset Slope,63.26126 mW/°C
[Direct Cp Calibration]
Date Applied,11/30/2022 11:04:51 AM
Description,From -79.983 °C to 298.409 °C at 10.000°C/min
Gas Type,Nitrogen
Pan Type,Tzero Aluminum Hermetic
Source Files 1,C:\Users\yargerlab\Desktop\DSC Data\General\Sapphire_Heat_Capacity_11_30_22.tri
[Rev Cp Calibration]
Date Applied,11/30/2022 1:58:51 PM
Description,From -79.996 °C to 292.812 °C at 3.000°C/min
Gas Type,Nitrogen
Pan Type,Tzero Aluminum Hermetic
Source Files 1,C:\Users\yargerlab\Desktop\DSC Data\General\Sapphire_MDSC_Calibration_11_30_22.tri
[step]
Ramp 5.00 °C/min to 150.00 °C
Time,Temperature,Heat Flow (Normalized)
min,°C,W/g
0.00,-59.64,-0.046
0.03,-59.66,-0.045
0.06,-59.67,-0.038
0.08,-59.65,-0.031
0.11,-59.61,-0.022
0.14,-59.54,-0.011
0.17,-59.46,0.001
0.20,-59.36,0.013
0.23,-59.25,0.024
0.26,-59.14,0.033
0.28,-59.03,0.041
0.31,-58.91,0.048
0.34,-58.79,0.054
0.37,-58.67,0.059
0.40,-58.54,0.062
0.43,-58.41,0.065
0.45,-58.28,0.068
0.48,-58.15,0.071
0.51,-58.02,0.073
0.54,-57.88,0.075
0.57,-57.75,0.076
0.60,-57.62,0.077
0.62,-57.48,0.078
0.65,-57.34,0.079
0.68,-57.21,0.079
0.71,-57.07,0.080
0.74,-56.93,0.080
0.77,-56.79,0.081
0.79,-56.66,0.081
0.82,-56.52,0.081
0.85,-56.38,0.082
0.88,-56.24,0.082
0.91,-56.10,0.082
0.93,-55.96,0.082
0.96,-55.82,0.082
0.99,-55.68,0.083
1.02,-55.54,0.083
1.05,-55.40,0.083
1.08,-55.26,0.083
1.11,-55.12,0.083
1.13,-54.98,0.083
1.16,-54.84,0.084
1.19,-54.70,0.084
1.22,-54.56,0.084
1.25,-54.42,0.084
1.28,-54.28,0.084
1.30,-54.14,0.084
1.33,-54.00,0.084
1.36,-53.86,0.084
1.39,-53.72,0.085
1.42,-53.58,0.085
1.44,-53.44,0.085
1.47,-53.30,0.085
1.50,-53.15,0.085
1.53,-53.01,0.085
1.56,-52.87,0.085
1.59,-52.73,0.085
1.62,-52.59,0.085
1.64,-52.45,0.085
1.67,-52.31,0.085
1.70,-52.17,0.085
1.73,-52.03,0.085
1.76,-51.88,0.085
1.78,-51.74,0.085
1.81,-51.60,0.086
1.84,-51.46,0.086
1.87,-51.32,0.086
1.90,-51.18,0.086
1.93,-51.04,0.086
1.96,-50.89,0.086
1.98,-50.76,0.086
2.01,-50.61,0.086
2.04,-50.47,0.086
2.07,-50.33,0.086
2.10,-50.19,0.086
2.13,-50.05,0.086
2.15,-49.91,0.086
2.18,-49.76,0.086
2.21,-49.62,0.086
2.24,-49.48,0.086
2.27,-49.34,0.086
2.29,-49.20,0.086
2.32,-49.06,0.086
2.35,-48.92,0.086
2.38,-48.77,0.086
2.41,-48.63,0.086
2.44,-48.49,0.086
2.46,-48.35,0.086
2.49,-48.21,0.087
2.52,-48.07,0.087
2.55,-47.93,0.087
2.58,-47.78,0.087
2.61,-47.64,0.087
2.64,-47.50,0.087
2.66,-47.36,0.087
2.69,-47.22,0.087
2.72,-47.08,0.087
2.75,-46.94,0.087
2.78,-46.79,0.087
2.81,-46.65,0.087
2.83,-46.51,0.087
2.86,-46.37,0.087
2.89,-46.23,0.087
2.92,-46.09,0.087
2.95,-45.94,0.087
2.98,-45.80,0.087
3.00,-45.66,0.087
3.03,-45.52,0.087
3.06,-45.38,0.087
3.09,-45.24,0.087
3.12,-45.10,0.087
3.14,-44.95,0.087
3.17,-44.81,0.087
3.20,-44.67,0.087
3.23,-44.53,0.087
3.26,-44.39,0.087
3.29,-44.25,0.087
3.31,-44.10,0.087
3.34,-43.97,0.087
3.37,-43.82,0.087
3.40,-43.68,0.087
3.43,-43.54,0.088
3.46,-43.40,0.088
3.49,-43.26,0.088
3.51,-43.11,0.088
3.54,-42.97,0.088
3.57,-42.83,0.088
3.60,-42.69,0.088
3.63,-42.55,0.088
3.66,-42.40,0.088
3.68,-42.26,0.088
3.71,-42.12,0.088
3.74,-41.98,0.088
3.77,-41.84,0.088
3.80,-41.70,0.088
3.83,-41.55,0.088
3.85,-41.41,0.088
3.88,-41.27,0.088
3.91,-41.13,0.088
3.94,-40.99,0.088
3.97,-40.84,0.088
3.99,-40.70,0.088
4.02,-40.56,0.088
4.05,-40.42,0.088
4.08,-40.28,0.088
4.11,-40.14,0.088
4.14,-39.99,0.089
4.16,-39.85,0.089
4.19,-39.71,0.089
4.22,-39.57,0.089
4.25,-39.43,0.089
4.28,-39.29,0.089
4.31,-39.14,0.089
4.34,-39.00,0.089
4.36,-38.86,0.089
4.39,-38.72,0.089
4.42,-38.58,0.089
4.45,-38.43,0.089
4.48,-38.29,0.089
4.50,-38.15,0.089
4.53,-38.01,0.089
4.56,-37.87,0.089
4.59,-37.72,0.089
4.62,-37.58,0.089
4.65,-37.44,0.089
4.68,-37.30,0.089
4.70,-37.16,0.089
4.73,-37.02,0.089
4.76,-36.87,0.089
4.79,-36.73,0.089
4.82,-36.59,0.089
4.85,-36.45,0.090
4.87,-36.31,0.090
4.90,-36.16,0.090
4.93,-36.02,0.090
4.96,-35.88,0.090
4.99,-35.74,0.090
5.01,-35.60,0.090
5.04,-35.46,0.090
5.07,-35.32,0.090
5.10,-35.17,0.090
5.13,-35.03,0.090
5.16,-34.89,0.090
5.19,-34.75,0.090
5.21,-34.60,0.090
5.24,-34.46,0.090
5.27,-34.32,0.090
5.30,-34.18,0.090
5.33,-34.04,0.090
5.35,-33.89,0.090
5.38,-33.75,0.090
5.41,-33.61,0.090
5.44,-33.47,0.090
5.47,-33.33,0.090
5.50,-33.19,0.090
5.53,-33.05,0.090
5.55,-32.90,0.090
5.58,-32.76,0.090
5.61,-32.62,0.091
5.64,-32.48,0.091
5.67,-32.34,0.091
5.70,-32.19,0.091
5.72,-32.05,0.091
5.75,-31.91,0.091
5.78,-31.77,0.091
5.81,-31.63,0.091
5.84,-31.49,0.091
5.86,-31.34,0.091
5.89,-31.20,0.091
5.92,-31.06,0.091
5.95,-30.92,0.091
5.98,-30.77,0.091
6.01,-30.63,0.091
6.04,-30.49,0.091
6.06,-30.35,0.091
6.09,-30.21,0.091
6.12,-30.07,0.091
6.15,-29.92,0.091
6.18,-29.78,0.091
6.20,-29.64,0.091
6.23,-29.50,0.091
6.26,-29.36,0.091
6.29,-29.22,0.091
6.32,-29.08,0.091
6.35,-28.93,0.091
6.38,-28.79,0.091
6.40,-28.65,0.091
6.43,-28.51,0.092
6.46,-28.37,0.092
6.49,-28.23,0.092
6.52,-28.08,0.092
6.55,-27.94,0.092
6.57,-27.80,0.092
6.60,-27.66,0.092
6.63,-27.52,0.092
6.66,-27.37,0.092
6.69,-27.23,0.092
6.71,-27.09,0.092
6.74,-26.95,0.092
6.77,-26.81,0.092
6.80,-26.67,0.092
6.83,-26.52,0.092
6.86,-26.38,0.092
6.89,-26.24,0.092
6.91,-26.10,0.092
6.94,-25.95,0.092
6.97,-25.81,0.092
7.00,-25.67,0.093
7.03,-25.53,0.093
7.05,-25.39,0.093
7.08,-25.25,0.093
7.11,-25.10,0.093
7.14,-24.96,0.093
7.17,-24.82,0.093
7.20,-24.68,0.093
7.23,-24.54,0.093
7.25,-24.40,0.093
7.28,-24.25,0.093
7.31,-24.11,0.093
7.34,-23.97,0.093
7.37,-23.83,0.093
7.40,-23.69,0.093
7.42,-23.55,0.093
7.45,-23.40,0.093
7.48,-23.26,0.093
7.51,-23.12,0.093
7.54,-22.98,0.093
7.56,-22.84,0.093
7.59,-22.69,0.093
7.62,-22.55,0.093
7.65,-22.41,0.093
7.68,-22.27,0.094
7.71,-22.13,0.094
7.74,-21.99,0.094
7.76,-21.85,0.094
7.79,-21.70,0.094
7.82,-21.56,0.094
7.85,-21.42,0.094
7.88,-21.28,0.094
7.90,-21.14,0.094
7.93,-21.00,0.094
7.96,-20.85,0.094
7.99,-20.71,0.094
8.02,-20.57,0.094
8.05,-20.43,0.094
8.08,-20.28,0.094
8.10,-20.14,0.094
8.13,-20.00,0.094
8.16,-19.86,0.094
8.19,-19.72,0.094
8.22,-19.57,0.094
8.25,-19.43,0.095
8.27,-19.29,0.095
8.30,-19.15,0.095
8.33,-19.01,0.095
8.36,-18.86,0.095
8.39,-18.72,0.095
8.41,-18.58,0.095
8.44,-18.44,0.095
8.47,-18.30,0.095
8.50,-18.16,0.095
8.53,-18.02,0.095
8.56,-17.88,0.095
8.58,-17.73,0.095
8.61,-17.59,0.095
8.64,-17.45,0.095
8.67,-17.31,0.095
8.70,-17.17,0.095
8.73,-17.02,0.095
8.75,-16.88,0.095
8.78,-16.74,0.095
8.81,-16.60,0.095
8.84,-16.46,0.095
8.87,-16.32,0.095
8.90,-16.17,0.095
8.93,-16.03,0.095
8.95,-15.89,0.095
8.98,-15.75,0.096
9.01,-15.61,0.096
9.04,-15.47,0.096
9.07,-15.32,0.096
9.10,-15.18,0.096
9.12,-15.04,0.096
9.15,-14.90,0.096
9.18,-14.76,0.096
9.21,-14.62,0.096
9.24,-14.47,0.096
9.27,-14.33,0.096
9.29,-14.19,0.096
9.32,-14.05,0.096
9.35,-13.90,0.096
9.38,-13.76,0.096
9.41,-13.62,0.096
9.43,-13.48,0.096
9.46,-13.34,0.096
9.49,-13.20,0.096
9.52,-13.05,0.097
9.55,-12.91,0.097
9.58,-12.77,0.097
9.60,-12.63,0.097
9.63,-12.49,0.097
9.66,-12.35,0.097
9.69,-12.21,0.097
9.72,-12.06,0.097
9.75,-11.92,0.097
9.78,-11.78,0.097
9.80,-11.64,0.097
9.83,-11.50,0.097
9.86,-11.35,0.097
9.89,-11.21,0.097
9.92,-11.07,0.097
9.95,-10.93,0.097
9.97,-10.79,0.097
10.00,-10.65,0.097
10.03,-10.50,0.097
10.06,-10.36,0.097
10.09,-10.22,0.097
10.12,-10.08,0.097
10.14,-9.94,0.098
10.17,-9.80,0.098
10.20,-9.65,0.098
10.23,-9.51,0.098
10.26,-9.37,0.098
10.28,-9.23,0.098
10.31,-9.09,0.098
10.34,-8.94,0.098
10.37,-8.80,0.098
10.40,-8.66,0.098
10.43,-8.52,0.098
10.45,-8.38,0.098
10.48,-8.24,0.098
10.51,-8.10,0.098
10.54,-7.95,0.098
10.57,-7.81,0.098
10.60,-7.67,0.098
10.63,-7.53,0.098
10.65,-7.39,0.098
10.68,-7.24,0.098
10.71,-7.10,0.099
10.74,-6.96,0.099
10.77,-6.82,0.099
10.80,-6.68,0.099
10.82,-6.54,0.099
10.85,-6.39,0.099
10.88,-6.25,0.099
10.91,-6.11,0.099
10.94,-5.97,0.099
10.97,-5.83,0.099
10.99,-5.68,0.099
11.02,-5.54,0.099
11.05,-5.40,0.099
11.08,-5.26,0.099
11.11,-5.12,0.099
11.13,-4.98,0.099
11.16,-4.83,0.099
11.19,-4.69,0.099
11.22,-4.55,0.099
11.25,-4.41,0.099
11.28,-4.27,0.099
11.30,-4.13,0.100
11.33,-3.99,0.100
11.36,-3.84,0.100
11.39,-3.70,0.100
11.42,-3.56,0.100
11.45,-3.42,0.100
11.48,-3.28,0.100
11.50,-3.14,0.100
11.53,-2.99,0.100
11.56,-2.85,0.100
11.59,-2.71,0.100
11.62,-2.57,0.100
11.65,-2.43,0.100
11.67,-2.28,0.100
11.70,-2.14,0.100
11.73,-2.00,0.100
11.76,-1.86,0.100
11.79,-1.71,0.101
11.82,-1.57,0.101
11.84,-1.43,0.101
11.87,-1.29,0.101
11.90,-1.15,0.101
11.93,-1.01,0.101
11.96,-0.86,0.101
11.98,-0.72,0.101
12.01,-0.58,0.101
12.04,-0.44,0.101
12.07,-0.30,0.101
12.10,-0.15,0.101
12.13,-0.02,0.101
12.15,0.13,0.101
12.18,0.27,0.101
12.21,0.41,0.101
12.24,0.55,0.101
12.27,0.69,0.101
12.30,0.84,0.101
12.33,0.98,0.101
12.35,1.12,0.101
12.38,1.26,0.101
12.41,1.40,0.102
12.44,1.55,0.102
12.47,1.69,0.102
12.50,1.83,0.102
12.52,1.97,0.102
12.55,2.11,0.102
12.58,2.25,0.102
12.61,2.40,0.102
12.64,2.54,0.102
12.67,2.68,0.102
12.69,2.82,0.102
12.72,2.96,0.102
12.75,3.10,0.102
12.78,3.25,0.102
12.81,3.39,0.102
12.83,3.53,0.102
12.86,3.67,0.102
12.89,3.81,0.102
12.92,3.95,0.103
12.95,4.10,0.103
12.98,4.24,0.103
13.00,4.38,0.103
13.03,4.52,0.103
13.06,4.66,0.103
13.09,4.81,0.103
13.12,4.95,0.103
13.15,5.09,0.103
13.18,5.23,0.103
13.20,5.37,0.103
13.23,5.51,0.103
13.26,5.66,0.103
13.29,5.80,0.103
13.32,5.94,0.103
13.35,6.08,0.103
13.37,6.22,0.103
13.40,6.37,0.103
13.43,6.51,0.104
13.46,6.65,0.104
13.49,6.79,0.104
13.52,6.93,0.104
13.54,7.07,0.104
13.57,7.22,0.104
13.60,7.36,0.104
13.63,7.50,0.104
13.66,7.64,0.104
13.68,7.78,0.104
13.71,7.92,0.104
13.74,8.06,0.104
13.77,8.21,0.104
13.80,8.35,0.104
13.83,8.49,0.104
13.85,8.63,0.104
13.88,8.77,0.104
13.91,8.92,0.104
13.94,9.06,0.104
13.97,9.20,0.105
14.00,9.34,0.105
14.03,9.48,0.105
14.05,9.62,0.105
14.08,9.77,0.105
14.11,9.91,0.105
14.14,10.05,0.105
14.17,10.19,0.105
14.20,10.33,0.105
14.22,10.48,0.105
14.25,10.62,0.105
14.28,10.76,0.105
14.31,10.90,0.105
14.34,11.04,0.105
14.37,11.18,0.105
14.39,11.33,0.105
14.42,11.47,0.105
14.45,11.61,0.106
14.48,11.75,0.106
14.51,11.89,0.106
14.53,12.03,0.106
14.56,12.18,0.106
14.59,12.32,0.106
14.62,12.46,0.106
14.65,12.60,0.106
14.68,12.74,0.106
14.70,12.88,0.106
14.73,13.03,0.106
14.76,13.17,0.106
14.79,13.31,0.106
14.82,13.45,0.106
14.85,13.59,0.106
14.88,13.73,0.106
14.90,13.88,0.106
14.93,14.02,0.106
14.96,14.16,0.107
14.99,14.30,0.107
15.02,14.44,0.107
15.05,14.59,0.107
15.07,14.73,0.107
15.10,14.87,0.107
15.13,15.01,0.107
15.16,15.15,0.107
15.19,15.29,0.107
15.22,15.44,0.107
15.24,15.58,0.107
15.27,15.72,0.107
15.30,15.86,0.107
15.33,16.00,0.107
15.36,16.14,0.107
15.38,16.29,0.107
15.41,16.43,0.107
15.44,16.57,0.107
15.47,16.71,0.107
15.50,16.85,0.108
15.53,17.00,0.108
15.55,17.14,0.108
15.58,17.28,0.108
15.61,17.42,0.108
15.64,17.56,0.108
15.67,17.70,0.108
15.70,17.85,0.108
15.73,17.99,0.108
15.75,18.13,0.108
15.78,18.27,0.108
15.81,18.41,0.108
15.84,18.55,0.108
15.87,18.70,0.108
15.90,18.84,0.108
15.92,18.98,0.108
15.95,19.12,0.109
15.98,19.26,0.109
16.01,19.40,0.109
16.04,19.55,0.109
16.07,19.69,0.109
16.09,19.83,0.109
16.12,19.97,0.109
16.15,20.11,0.109
16.18,20.25,0.109
16.21,20.40,0.109
16.23,20.54,0.109
16.26,20.68,0.109
16.29,20.82,0.109
16.32,20.96,0.109
16.35,21.11,0.109
16.38,21.25,0.109
16.40,21.39,0.109
16.43,21.53,0.110
16.46,21.67,0.110
16.49,21.81,0.110
16.52,21.96,0.110
16.55,22.10,0.110
16.58,22.24,0.110
16.60,22.38,0.110
16.63,22.52,0.110
16.66,22.66,0.110
16.69,22.81,0.110
16.72,22.95,0.110
16.75,23.09,0.110
16.77,23.23,0.110
16.80,23.37,0.110
16.83,23.51,0.110
16.86,23.66,0.110
16.89,23.80,0.111
16.92,23.94,0.111
16.94,24.08,0.111
16.97,24.22,0.111
17.00,24.37,0.111
17.03,24.51,0.111
17.06,24.65,0.111
17.08,24.79,0.111
17.11,24.93,0.111
17.14,25.07,0.111
17.17,25.21,0.111
17.20,25.36,0.111
17.23,25.50,0.111
17.26,25.64,0.111
17.28,25.78,0.111
17.31,25.93,0.111
17.34,26.07,0.111
17.37,26.21,0.112
17.40,26.35,0.112
17.43,26.49,0.112
17.45,26.63,0.112
17.48,26.77,0.112
17.51,26.92,0.112
17.54,27.06,0.112
17.57,27.20,0.112
17.59,27.34,0.112
17.62,27.48,0.112
17.65,27.63,0.112
17.68,27.77,0.112
17.71,27.91,0.112
17.74,28.05,0.112
17.77,28.19,0.112
17.79,28.33,0.112
17.82,28.48,0.113
17.85,28.62,0.113
17.88,28.76,0.113
17.91,28.90,0.113
17.93,29.04,0.113
17.96,29.18,0.113
17.99,29.33,0.113
18.02,29.47,0.113
18.05,29.61,0.113
18.08,29.75,0.113
18.11,29.89,0.113
18.13,30.03,0.113
18.16,30.18,0.113
18.19,30.32,0.113
18.22,30.46,0.113
18.25,30.60,0.113
18.28,30.74,0.113
18.30,30.88,0.113
18.33,31.03,0.114
18.36,31.17,0.114
18.39,31.31,0.114
18.42,31.45,0.114
18.44,31.59,0.114
18.47,31.74,0.114
18.50,31.88,0.114
18.53,32.02,0.114
18.56,32.16,0.114
18.59,32.30,0.114
18.62,32.44,0.114
18.64,32.59,0.114
18.67,32.73,0.114
18.70,32.87,0.114
18.73,33.01,0.114
18.76,33.15,0.114
18.78,33.29,0.114
18.81,33.44,0.115
18.84,33.58,0.115
18.87,33.72,0.115
18.90,33.86,0.115
18.93,34.00,0.115
18.96,34.15,0.115
18.98,34.29,0.115
19.01,34.43,0.115
19.04,34.57,0.115
19.07,34.71,0.115
19.10,34.85,0.115
19.13,34.99,0.115
19.15,35.14,0.115
19.18,35.28,0.115
19.21,35.42,0.115
19.24,35.56,0.115
19.27,35.70,0.115
19.29,35.85,0.116
19.32,35.99,0.116
19.35,36.13,0.116
19.38,36.27,0.116
19.41,36.41,0.116
19.44,36.55,0.116
19.47,36.70,0.116
19.49,36.84,0.116
19.52,36.98,0.116
19.55,37.12,0.116
19.58,37.26,0.116
19.61,37.40,0.116
19.63,37.55,0.116
19.66,37.69,0.116
19.69,37.83,0.116
19.72,37.97,0.116
19.75,38.11,0.117
19.78,38.26,0.117
19.81,38.40,0.117
19.83,38.54,0.117
19.86,38.68,0.117
19.89,38.82,0.117
19.92,38.96,0.117
19.95,39.11,0.117
19.98,39.25,0.117
20.00,39.39,0.117
20.03,39.53,0.117
20.06,39.67,0.117
20.09,39.81,0.117
20.12,39.96,0.117
20.14,40.10,0.117
20.17,40.24,0.117
20.20,40.38,0.118
20.23,40.52,0.118
20.26,40.67,0.118
20.29,40.81,0.118
20.32,40.95,0.118
20.34,41.09,0.118
20.37,41.23,0.118
20.40,41.37,0.118
20.43,41.52,0.118
20.46,41.66,0.118
20.48,41.80,0.118
20.51,41.94,0.118
20.54,42.08,0.118
20.57,42.22,0.118
20.60,42.36,0.118
20.63,42.51,0.118
20.66,42.65,0.119
20.68,42.79,0.119
20.71,42.93,0.119
20.74,43.07,0.119
20.77,43.22,0.119
20.80,43.36,0.119
20.83,43.50,0.119
20.85,43.64,0.119
20.88,43.78,0.119
20.91,43.92,0.119
20.94,44.07,0.119
20.97,44.21,0.119
20.99,44.35,0.119
21.02,44.49,0.120
21.05,44.63,0.120
21.08,44.77,0.120
21.11,44.92,0.120
21.14,45.06,0.120
21.17,45.20,0.120
21.19,45.34,0.120
21.22,45.48,0.120
21.25,45.62,0.120
21.28,45.77,0.120
21.31,45.91,0.120
21.33,46.05,0.120
21.36,46.19,0.120
21.39,46.33,0.120
21.42,46.47,0.120
21.45,46.62,0.121
21.48,46.76,0.121
21.51,46.90,0.121
21.53,47.04,0.121
21.56,47.18,0.121
21.59,47.32,0.121
21.62,47.47,0.121
21.65,47.61,0.121
21.68,47.75,0.121
21.70,47.89,0.121
21.73,48.03,0.121
21.76,48.17,0.121
21.79,48.32,0.121
21.82,48.46,0.121
21.84,48.60,0.122
21.87,48.74,0.122
21.90,48.88,0.122
21.93,49.02,0.122
21.96,49.17,0.122
21.99,49.31,0.122
22.02,49.45,0.122
22.04,49.59,0.122
22.07,49.73,0.122
22.10,49.87,0.122
22.13,50.02,0.122
22.16,50.16,0.122
22.18,50.30,0.122
22.21,50.44,0.123
22.24,50.58,0.123
22.27,50.72,0.123
22.30,50.87,0.123
22.33,51.01,0.123
22.36,51.15,0.123
22.38,51.29,0.123
22.41,51.43,0.123
22.44,51.58,0.123
22.47,51.72,0.123
22.50,51.86,0.123
22.53,52.00,0.123
22.55,52.14,0.124
22.58,52.28,0.124
22.61,52.43,0.124
22.64,52.57,0.124
22.67,52.71,0.124
22.69,52.85,0.124
22.72,52.99,0.124
22.75,53.13,0.124
22.78,53.27,0.124
22.81,53.42,0.124
22.84,53.56,0.124
22.87,53.70,0.125
22.89,53.84,0.125
22.92,53.98,0.125
22.95,54.13,0.125
22.98,54.27,0.125
23.01,54.41,0.125
23.03,54.55,0.125
23.06,54.69,0.125
23.09,54.83,0.125
23.12,54.98,0.125
23.15,55.12,0.125
23.18,55.26,0.126
23.21,55.40,0.126
23.23,55.54,0.126
23.26,55.68,0.126
23.29,55.83,0.126
23.32,55.97,0.126
23.35,56.11,0.126
23.38,56.25,0.126
23.40,56.39,0.126
23.43,56.53,0.127
23.46,56.68,0.127
23.49,56.82,0.127
23.52,56.96,0.127
23.54,57.10,0.127
23.57,57.24,0.127
23.60,57.38,0.127
23.63,57.53,0.127
23.66,57.67,0.127
23.69,57.81,0.127
23.72,57.95,0.128
23.74,58.09,0.128
23.77,58.23,0.128
23.80,58.38,0.128
23.83,58.52,0.128
23.86,58.66,0.128
23.88,58.80,0.128
23.91,58.94,0.128
23.94,59.08,0.129
23.97,59.23,0.129
24.00,59.37,0.129
24.03,59.51,0.129
24.06,59.65,0.129
24.08,59.79,0.129
24.11,59.93,0.129
24.14,60.08,0.129
24.17,60.22,0.130
24.20,60.36,0.130
24.23,60.50,0.130
24.25,60.64,0.130
24.28,60.78,0.130
24.31,60.93,0.130
24.34,61.07,0.130
24.37,61.21,0.130
24.39,61.35,0.131
24.42,61.49,0.131
24.45,61.63,0.131
24.48,61.77,0.131
24.51,61.92,0.131
24.54,62.06,0.131
24.57,62.20,0.131
24.59,62.34,0.132
24.62,62.48,0.132
24.65,62.62,0.132
24.68,62.77,0.132
24.71,62.91,0.132
24.73,63.05,0.132
24.76,63.19,0.132
24.79,63.33,0.133
24.82,63.47,0.133
24.85,63.62,0.133
24.88,63.76,0.133
24.91,63.90,0.133
24.93,64.04,0.133
24.96,64.18,0.133
24.99,64.33,0.134
25.02,64.47,0.134
25.05,64.61,0.134
25.08,64.75,0.134
25.10,64.89,0.134
25.13,65.03,0.134
25.16,65.18,0.134
25.19,65.32,0.134
25.22,65.46,0.135
25.24,65.60,0.135
25.27,65.74,0.135
25.30,65.88,0.135
25.33,66.03,0.135
25.36,66.17,0.135
25.39,66.31,0.135
25.42,66.45,0.135
25.44,66.59,0.136
25.47,66.73,0.136
25.50,66.88,0.136
25.53,67.02,0.136
25.56,67.16,0.136
25.58,67.30,0.136
25.61,67.44,0.136
25.64,67.58,0.137
25.67,67.73,0.137
25.70,67.87,0.137
25.73,68.01,0.137
25.76,68.15,0.137
25.78,68.29,0.137
25.81,68.43,0.137
25.84,68.57,0.138
25.87,68.72,0.138
25.90,68.86,0.138
25.93,69.00,0.138
25.95,69.14,0.138
25.98,69.28,0.139
26.01,69.42,0.139
26.04,69.57,0.139
26.07,69.71,0.139
26.09,69.85,0.140
26.12,69.99,0.140
26.15,70.13,0.140
26.18,70.27,0.141
26.21,70.41,0.141
26.24,70.55,0.141
26.27,70.70,0.141
26.29,70.84,0.142
26.32,70.98,0.142
26.35,71.12,0.143
26.38,71.26,0.143
26.41,71.40,0.144
26.43,71.54,0.144
26.46,71.69,0.144
26.49,71.83,0.145
26.52,71.97,0.145
26.55,72.11,0.146
26.58,72.25,0.147
26.61,72.39,0.147
26.63,72.53,0.148
26.66,72.68,0.149
26.69,72.82,0.149
26.72,72.96,0.150
26.75,73.10,0.150
26.78,73.24,0.151
26.80,73.38,0.152
26.83,73.52,0.153
26.86,73.66,0.153
26.89,73.80,0.154
26.92,73.94,0.155
26.94,74.09,0.156
26.97,74.23,0.157
27.00,74.37,0.158
27.03,74.51,0.160
27.06,74.65,0.161
27.09,74.79,0.162
27.12,74.93,0.163
27.14,75.07,0.164
27.17,75.21,0.165
27.20,75.35,0.167
27.23,75.49,0.168
27.26,75.63,0.170
27.28,75.77,0.171
27.31,75.92,0.173
27.34,76.05,0.175
27.37,76.20,0.176
27.40,76.34,0.178
27.43,76.48,0.180
27.46,76.62,0.182
27.48,76.76,0.184
27.51,76.90,0.186
27.54,77.04,0.188
27.57,77.18,0.190
27.60,77.32,0.194
27.63,77.45,0.196
27.65,77.59,0.199
27.68,77.73,0.202
27.71,77.87,0.204
27.74,78.01,0.207
27.77,78.15,0.211
27.79,78.29,0.214
27.82,78.43,0.218
27.85,78.57,0.221
27.88,78.71,0.226
27.91,78.84,0.230
27.94,78.98,0.234
27.97,79.12,0.238
27.99,79.26,0.243
28.02,79.39,0.248
28.05,79.53,0.254
28.08,79.67,0.259
28.11,79.81,0.266
28.13,79.94,0.271
28.16,80.08,0.278
28.19,80.21,0.284
28.22,80.35,0.292
28.25,80.49,0.299
28.28,80.62,0.307
28.31,80.76,0.314
28.33,80.89,0.323
28.36,81.02,0.330
28.39,81.16,0.339
28.42,81.29,0.349
28.45,81.42,0.358
28.48,81.56,0.368
28.50,81.69,0.377
28.53,81.82,0.388
28.56,81.96,0.398
28.59,82.09,0.408
28.62,82.22,0.418
28.64,82.35,0.428
28.67,82.49,0.439
28.70,82.62,0.450
28.73,82.75,0.461
28.76,82.88,0.472
28.79,83.01,0.483
28.82,83.14,0.493
28.84,83.28,0.504
28.87,83.41,0.514
28.90,83.54,0.526
28.93,83.67,0.537
28.96,83.80,0.547
28.98,83.94,0.557
29.01,84.07,0.567
29.04,84.20,0.577
29.07,84.33,0.587
29.10,84.47,0.596
29.13,84.60,0.605
29.16,84.73,0.614
29.18,84.87,0.622
29.21,85.00,0.629
29.24,85.13,0.637
29.27,85.27,0.644
29.30,85.40,0.651
29.33,85.54,0.659
29.35,85.67,0.664
29.38,85.81,0.668
29.41,85.95,0.673
29.44,86.08,0.676
29.47,86.22,0.681
29.49,86.36,0.684
29.52,86.50,0.689
29.55,86.64,0.697
29.58,86.77,0.695
29.61,86.92,0.691
29.64,87.06,0.684
29.67,87.20,0.680
29.69,87.35,0.671
29.72,87.50,0.663
29.75,87.65,0.649
29.78,87.80,0.630
29.81,87.96,0.610
29.83,88.12,0.590
29.86,88.28,0.567
29.89,88.44,0.542
29.92,88.60,0.517
29.95,88.77,0.490
29.98,88.93,0.462
30.01,89.10,0.436
30.03,89.26,0.407
30.06,89.43,0.380
30.09,89.60,0.355
30.12,89.76,0.329
30.15,89.93,0.306
30.18,90.09,0.284
30.20,90.26,0.265
30.23,90.42,0.248
30.26,90.58,0.233
30.29,90.73,0.220
30.32,90.89,0.210
30.34,91.04,0.201
30.37,91.19,0.195
30.40,91.34,0.188
30.43,91.49,0.184
30.46,91.63,0.181
30.49,91.78,0.178
30.52,91.93,0.176
30.54,92.07,0.174
30.57,92.22,0.173
30.60,92.36,0.172
30.63,92.50,0.172
30.66,92.65,0.171
30.68,92.79,0.171
30.71,92.93,0.171
30.74,93.08,0.170
30.77,93.22,0.170
30.80,93.36,0.170
30.83,93.50,0.169
30.86,93.64,0.169
30.88,93.78,0.169
30.91,93.93,0.169
30.94,94.07,0.168
30.97,94.21,0.168
31.00,94.35,0.168
31.03,94.49,0.168
31.05,94.64,0.168
31.08,94.78,0.168
31.11,94.92,0.168
31.14,95.06,0.168
31.17,95.20,0.168
31.19,95.34,0.167
31.22,95.49,0.167
31.25,95.63,0.167
31.28,95.77,0.167
31.31,95.91,0.167
31.34,96.05,0.167
31.37,96.19,0.167
31.39,96.33,0.167
31.42,96.48,0.167
31.45,96.62,0.167
31.48,96.76,0.167
31.51,96.90,0.167
31.53,97.04,0.167
31.56,97.18,0.167
31.59,97.33,0.167
31.62,97.47,0.167
31.65,97.61,0.167
31.68,97.75,0.167
31.71,97.89,0.167
31.73,98.04,0.167
31.76,98.18,0.167
31.79,98.32,0.168
31.82,98.46,0.168
31.85,98.60,0.168
31.88,98.74,0.168
31.90,98.88,0.168
31.93,99.03,0.168
31.96,99.17,0.168
31.99,99.31,0.168
32.02,99.45,0.168
32.04,99.59,0.168
32.07,99.74,0.168
32.10,99.88,0.168
32.13,100.02,0.168
32.16,100.16,0.168
32.19,100.30,0.168
32.22,100.44,0.168
32.24,100.59,0.168
32.27,100.73,0.168
32.30,100.87,0.168
32.33,101.01,0.168
32.36,101.15,0.168
32.38,101.29,0.168
32.41,101.44,0.169
32.44,101.58,0.169
32.47,101.72,0.169
32.50,101.86,0.169
32.53,102.00,0.169
32.56,102.15,0.169
32.58,102.29,0.169
32.61,102.43,0.169
32.64,102.57,0.169
32.67,102.71,0.169
32.70,102.85,0.169
32.73,103.00,0.169
32.75,103.14,0.169
32.78,103.28,0.169
32.81,103.42,0.169
32.84,103.56,0.169
32.87,103.70,0.169
32.89,103.85,0.169
32.92,103.99,0.169
32.95,104.13,0.169
32.98,104.27,0.169
33.01,104.41,0.169
33.04,104.55,0.169
33.07,104.70,0.169
33.09,104.84,0.170
33.12,104.98,0.170
33.15,105.12,0.170
33.18,105.26,0.170
33.21,105.40,0.170
33.23,105.55,0.170
33.26,105.69,0.170
33.29,105.83,0.170
33.32,105.97,0.170
33.35,106.11,0.170
33.38,106.26,0.170
33.41,106.40,0.170
33.43,106.54,0.170
33.46,106.68,0.170
33.49,106.82,0.170
33.52,106.96,0.170
33.55,107.11,0.170
33.58,107.25,0.170
33.60,107.39,0.171
33.63,107.53,0.171
33.66,107.67,0.171
33.69,107.81,0.171
33.72,107.96,0.171
33.74,108.10,0.171
33.77,108.24,0.171
33.80,108.38,0.171
33.83,108.52,0.171
33.86,108.66,0.171
33.89,108.81,0.171
33.92,108.95,0.171
33.94,109.09,0.171
33.97,109.23,0.171
34.00,109.37,0.171
34.03,109.51,0.171
34.06,109.66,0.171
34.08,109.80,0.171
34.11,109.94,0.171
34.14,110.08,0.171
34.17,110.22,0.171
34.20,110.36,0.172
34.23,110.50,0.172
34.26,110.65,0.172
34.28,110.79,0.172
34.31,110.93,0.172
34.34,111.07,0.172
34.37,111.21,0.172
34.40,111.36,0.172
34.43,111.50,0.172
34.45,111.64,0.172
34.48,111.78,0.172
34.51,111.92,0.172
34.54,112.06,0.172
34.57,112.21,0.172
34.59,112.35,0.172
34.62,112.49,0.172
34.65,112.63,0.173
34.68,112.77,0.173
34.71,112.91,0.173
34.74,113.06,0.173
34.76,113.20,0.173
34.79,113.34,0.173
34.82,113.48,0.173
34.85,113.62,0.173
34.88,113.76,0.173
34.91,113.91,0.173
34.94,114.05,0.173
34.96,114.19,0.173
34.99,114.33,0.173
35.02,114.47,0.173
35.05,114.62,0.173
35.08,114.76,0.173
35.11,114.90,0.173
35.13,115.04,0.173
35.16,115.18,0.174
35.19,115.32,0.174
35.22,115.47,0.174
35.25,115.61,0.174
35.28,115.75,0.174
35.30,115.89,0.174
35.33,116.03,0.174
35.36,116.17,0.174
35.39,116.31,0.174
35.42,116.46,0.174
35.44,116.60,0.174
35.47,116.74,0.174
35.50,116.88,0.174
35.53,117.02,0.174
35.56,117.17,0.174
35.59,117.31,0.174
35.61,117.45,0.174
35.64,117.59,0.175
35.67,117.73,0.175
35.70,117.87,0.175
35.73,118.01,0.175
35.76,118.16,0.175
35.79,118.30,0.175
35.81,118.44,0.175
35.84,118.58,0.175
35.87,118.72,0.175
35.90,118.86,0.175
35.93,119.01,0.175
35.96,119.15,0.175
35.98,119.29,0.175
36.01,119.43,0.175
36.04,119.57,0.175
36.07,119.72,0.176
36.10,119.86,0.176
36.13,120.00,0.176
36.15,120.14,0.176
36.18,120.28,0.176
36.21,120.42,0.176
36.24,120.57,0.176
36.27,120.71,0.176
36.29,120.85,0.176
36.32,120.99,0.176
36.35,121.13,0.176
36.38,121.27,0.176
36.41,121.42,0.176
36.44,121.56,0.176
36.46,121.70,0.176
36.49,121.84,0.177
36.52,121.98,0.177
36.55,122.12,0.177
36.58,122.27,0.177
36.61,122.41,0.177
36.64,122.55,0.177
36.66,122.69,0.177
36.69,122.83,0.177
36.72,122.97,0.177
36.75,123.11,0.177
36.78,123.26,0.177
36.81,123.40,0.177
36.83,123.54,0.177
36.86,123.68,0.177
36.89,123.82,0.178
36.92,123.97,0.178
36.95,124.11,0.178
36.98,124.25,0.178
37.00,124.39,0.178
37.03,124.53,0.178
37.06,124.67,0.178
37.09,124.81,0.178
37.12,124.96,0.178
37.14,125.10,0.178
37.17,125.24,0.178
37.20,125.38,0.179
37.23,125.52,0.179
37.26,125.67,0.179
37.29,125.81,0.179
37.31,125.95,0.179
37.34,126.09,0.179
37.37,126.23,0.179
37.40,126.37,0.179
37.43,126.52,0.179
37.46,126.66,0.179
37.49,126.80,0.179
37.51,126.94,0.179
37.54,127.08,0.180
37.57,127.22,0.180
37.60,127.37,0.180
37.63,127.51,0.180
37.66,127.65,0.180
37.68,127.79,0.180
37.71,127.93,0.180
37.74,128.08,0.180
37.77,128.22,0.180
37.80,128.36,0.180
37.83,128.50,0.180
37.85,128.64,0.180
37.88,128.78,0.180
37.91,128.92,0.181
37.94,129.07,0.181
37.97,129.21,0.181
37.99,129.35,0.181
38.02,129.49,0.181
38.05,129.63,0.181
38.08,129.77,0.181
38.11,129.92,0.181
38.14,130.06,0.181
38.16,130.20,0.181
38.19,130.34,0.181
38.22,130.48,0.181
38.25,130.63,0.179
38.28,130.77,0.177
38.31,130.91,0.178
38.34,131.05,0.179
38.36,131.19,0.179
38.39,131.33,0.179
38.42,131.48,0.180
38.45,131.62,0.180
38.48,131.76,0.180
38.51,131.90,0.180
38.53,132.04,0.180
38.56,132.18,0.181
38.59,132.33,0.181
38.62,132.47,0.181
38.65,132.61,0.181
38.68,132.75,0.181
38.70,132.89,0.182
38.73,133.03,0.182
38.76,133.17,0.182
38.79,133.32,0.182
38.82,133.46,0.182
38.84,133.60,0.182
38.87,133.74,0.182
38.90,133.88,0.182
38.93,134.03,0.183
38.96,134.17,0.183
38.99,134.31,0.183
39.01,134.45,0.183
39.04,134.59,0.183
39.07,134.73,0.183
39.10,134.87,0.183
39.13,135.02,0.183
39.16,135.16,0.183
39.19,135.30,0.183
39.21,135.44,0.184
39.24,135.58,0.184
39.27,135.72,0.184
39.30,135.87,0.184
39.33,136.01,0.184
39.36,136.15,0.184
39.38,136.29,0.184
39.41,136.43,0.184
39.44,136.57,0.184
39.47,136.72,0.184
39.50,136.86,0.185
39.53,137.00,0.185
39.55,137.14,0.185
39.58,137.28,0.185
39.61,137.42,0.185
39.64,137.57,0.185
39.67,137.71,0.185
39.69,137.85,0.185
39.72,137.99,0.185
39.75,138.13,0.186
39.78,138.27,0.186
39.81,138.42,0.186
39.84,138.56,0.186
39.86,138.70,0.186
39.89,138.84,0.186
39.92,138.98,0.186
39.95,139.12,0.186
39.98,139.27,0.186
40.01,139.41,0.187
40.04,139.55,0.187
40.06,139.69,0.187
40.09,139.83,0.187
40.12,139.97,0.187
40.15,140.12,0.187
40.18,140.26,0.187
40.21,140.40,0.188
40.23,140.54,0.188
40.26,140.68,0.188
40.29,140.83,0.188
40.32,140.97,0.188
40.35,141.11,0.188
40.38,141.25,0.188
40.40,141.39,0.188
40.43,141.53,0.188
40.46,141.67,0.188
40.49,141.82,0.189
40.52,141.96,0.189
40.54,142.10,0.189
40.57,142.24,0.189
40.60,142.38,0.189
40.63,142.52,0.189
40.66,142.66,0.189
40.69,142.81,0.189
40.71,142.95,0.190
40.74,143.09,0.190
40.77,143.23,0.190
40.80,143.37,0.190
40.83,143.51,0.190
40.86,143.66,0.191
40.89,143.80,0.195
40.91,143.94,0.196
40.94,144.08,0.196
40.97,144.22,0.196
41.00,144.36,0.196
41.03,144.50,0.196
41.06,144.64,0.196
41.08,144.79,0.196
41.11,144.93,0.197
41.14,145.07,0.197
41.17,145.21,0.198
41.20,145.35,0.198
41.23,145.49,0.198
41.25,145.63,0.199
41.28,145.78,0.200
41.31,145.92,0.201
41.34,146.06,0.202
41.37,146.19,0.223
41.39,146.33,0.222
41.42,146.47,0.221
41.45,146.61,0.220
41.48,146.75,0.219
41.51,146.89,0.218
41.54,147.03,0.216
41.56,147.18,0.215
41.59,147.32,0.215
41.62,147.46,0.215
41.65,147.61,0.214
41.68,147.75,0.214
41.71,147.89,0.214
41.74,148.03,0.214
41.76,148.17,0.214
41.79,148.31,0.214
41.82,148.46,0.214
41.85,148.60,0.214
41.88,148.74,0.214
41.91,148.88,0.214
41.93,149.02,
41.96,149.16,
41.99,,

[step]
Ramp 10.00 °C/min to -60.00 °C
Time,Temperature,Heat Flow (Normalized)
min,°C,W/g
42.09,149.73,0.206
42.10,149.78,0.201
42.12,149.82,0.193
42.13,149.85,0.183
42.15,149.88,0.170
42.16,149.89,0.156
42.18,149.89,0.138
42.19,149.87,0.114
42.21,149.83,0.085
42.22,149.78,0.051
42.24,149.72,0.015
42.25,149.65,-0.022
42.27,149.56,-0.057
42.28,149.48,-0.091
42.30,149.38,-0.119
42.31,149.28,-0.146
42.33,149.17,-0.168
42.34,149.06,-0.189
42.36,148.95,-0.207
42.37,148.83,-0.223
42.39,148.71,-0.238
42.40,148.58,-0.251
42.42,148.46,-0.263
42.43,148.33,-0.273
42.45,148.20,-0.283
42.46,148.06,-0.292
42.48,147.93,-0.299
42.49,147.80,-0.306
42.51,147.66,-0.312
42.52,147.52,-0.318
42.54,147.38,-0.323
42.55,147.24,-0.327
42.57,147.10,-0.332
42.58,146.96,-0.335
42.60,146.82,-0.338
42.61,146.67,-0.341
42.63,146.53,-0.344
42.64,146.39,-0.346
42.66,146.24,-0.348
42.67,146.10,-0.351
42.69,145.95,-0.352
42.70,145.81,-0.353
42.72,145.66,-0.355
42.73,145.52,-0.357
42.75,145.37,-0.357
42.76,145.22,-0.359
42.78,145.08,-0.360
42.79,144.93,-0.361
42.81,144.78,-0.361
42.82,144.64,-0.362
42.84,144.49,-0.362
42.85,144.34,-0.363
42.87,144.20,-0.364
42.88,144.05,-0.364
42.90,143.90,-0.365
42.91,143.75,-0.366
42.93,143.61,-0.366
42.94,143.46,-0.366
42.96,143.31,-0.367
42.97,143.16,-0.367
42.99,143.01,-0.368
43.00,142.86,-0.368
43.02,142.71,-0.369
43.03,142.57,-0.369
43.05,142.42,-0.370
43.06,142.27,-0.370
43.08,142.12,-0.370
43.09,141.97,-0.371
43.11,141.83,-0.371
43.12,141.68,-0.371
43.14,141.53,-0.371
43.15,141.38,-0.371
43.17,141.23,-0.371
43.18,141.08,-0.372
43.20,140.93,-0.372
43.21,140.78,-0.372
43.23,140.63,-0.372
43.24,140.49,-0.372
43.26,140.34,-0.373
43.27,140.19,-0.373
43.29,140.04,-0.373
43.30,139.89,-0.373
43.32,139.74,-0.373
43.33,139.59,-0.373
43.35,139.44,-0.374
43.36,139.29,-0.374
43.38,139.14,-0.374
43.39,138.99,-0.374
43.41,138.84,-0.374
43.42,138.70,-0.374
43.44,138.55,-0.374
43.45,138.40,-0.375
43.47,138.25,-0.375
43.48,138.10,-0.375
43.50,137.95,-0.375
43.51,137.80,-0.375
43.53,137.65,-0.375
43.54,137.50,-0.375
43.56,137.35,-0.375
43.57,137.20,-0.375
43.59,137.05,-0.375
43.60,136.90,-0.375
43.62,136.75,-0.375
43.63,136.60,-0.376
43.65,136.45,-0.376
43.66,136.31,-0.376
43.68,136.16,-0.376
43.69,136.01,-0.376
43.71,135.86,-0.376
43.72,135.71,-0.376
43.74,135.56,-0.376
43.75,135.41,-0.376
43.77,135.26,-0.376
43.78,135.11,-0.376
43.80,134.96,-0.376
43.81,134.81,-0.376
43.83,134.66,-0.376
43.84,134.51,-0.376
43.86,134.36,-0.376
43.87,134.21,-0.377
43.89,134.06,-0.377
43.90,133.91,-0.377
43.92,133.76,-0.377
43.93,133.61,-0.377
43.95,133.46,-0.377
43.96,133.31,-0.377
43.98,133.16,-0.377
43.99,133.01,-0.377
44.01,132.86,-0.377
44.02,132.71,-0.377
44.04,132.57,-0.377
44.05,132.41,-0.377
44.07,132.27,-0.377
44.08,132.12,-0.377
44.10,131.97,-0.377
44.11,131.82,-0.377
44.13,131.67,-0.377
44.14,131.52,-0.377
44.16,131.37,-0.377
44.17,131.22,-0.377
44.19,131.07,-0.377
44.20,130.92,-0.377
44.22,130.77,-0.377
44.23,130.62,-0.377
44.25,130.47,-0.377
44.26,130.32,-0.378
44.28,130.17,-0.377
44.29,130.02,-0.378
44.31,129.87,-0.378
44.32,129.72,-0.378
44.34,129.57,-0.378
44.35,129.42,-0.378
44.37,129.27,-0.378
44.38,129.12,-0.378
44.40,128.97,-0.378
44.41,128.82,-0.378
44.43,128.67,-0.378
44.44,128.52,-0.378
44.46,128.37,-0.378
44.47,128.23,-0.378
44.49,128.07,-0.378
44.50,127.92,-0.378
44.52,127.78,-0.378
44.53,127.63,-0.378
44.55,127.48,-0.378
44.56,127.33,-0.378
44.58,127.18,-0.378
44.59,127.03,-0.378
44.61,126.88,-0.378
44.62,126.73,-0.378
44.64,126.58,-0.378
44.65,126.43,-0.378
44.67,126.28,-0.378
44.68,126.13,-0.378
44.70,125.98,-0.378
44.71,125.83,-0.378
44.73,125.68,-0.378
44.74,125.53,-0.378
44.76,125.38,-0.378
44.77,125.23,-0.378
44.79,125.08,-0.378
44.80,124.93,-0.378
44.82,124.78,-0.378
44.83,124.63,-0.378
44.85,124.48,-0.378
44.86,124.33,-0.378
44.88,124.18,-0.378
44.89,124.03,-0.378
44.91,123.88,-0.378
44.92,123.73,-0.378
44.94,123.58,-0.378
44.95,123.43,-0.378
44.97,123.28,-0.378
44.98,123.13,-0.378
45.00,122.98,-0.378
45.01,122.83,-0.378
45.03,122.68,-0.378
45.04,122.53,-0.378
45.06,122.38,-0.377
45.07,122.23,-0.377
45.09,122.08,-0.377
45.10,121.94,-0.377
45.12,121.79,-0.377
45.13,121.64,-0.377
45.15,121.49,-0.377
45.16,121.34,-0.377
45.18,121.19,-0.377
45.19,121.04,-0.377
45.21,120.89,-0.377
45.22,120.74,-0.377
45.24,120.59,-0.377
45.25,120.44,-0.377
45.27,120.29,-0.377
45.28,120.14,-0.377
45.30,119.99,-0.377
45.31,119.84,-0.377
45.33,119.69,-0.377
45.34,119.54,-0.377
45.36,119.39,-0.377
45.37,119.24,-0.377
45.39,119.09,-0.377
45.40,118.94,-0.377
45.42,118.79,-0.377
45.43,118.64,-0.377
45.45,118.49,-0.377
45.46,118.34,-0.377
45.48,118.19,-0.377
45.49,118.04,-0.377
45.51,117.89,-0.377
45.52,117.74,-0.377
45.54,117.59,-0.377
45.55,117.44,-0.377
45.57,117.29,-0.377
45.58,117.14,-0.377
45.60,116.99,-0.377
45.61,116.84,-0.377
45.63,116.69,-0.377
45.64,116.54,-0.377
45.66,116.39,-0.376
45.67,116.24,-0.376
45.69,116.09,-0.376
45.70,115.94,-0.376
45.72,115.79,-0.376
45.73,115.64,-0.376
45.75,115.49,-0.376
45.76,115.34,-0.376
45.78,115.20,-0.376
45.79,115.05,-0.376
45.81,114.90,-0.376
45.82,114.74,-0.376
45.84,114.59,-0.376
45.85,114.45,-0.376
45.87,114.30,-0.376
45.88,114.15,-0.376
45.90,114.00,-0.376
45.91,113.85,-0.376
45.93,113.70,-0.376
45.94,113.55,-0.376
45.96,113.40,-0.376
45.97,113.25,-0.376
45.99,113.10,-0.376
46.00,112.95,-0.376
46.02,112.80,-0.376
46.03,112.65,-0.376
46.05,112.50,-0.376
46.06,112.35,-0.376
46.08,112.20,-0.376
46.09,112.05,-0.376
46.11,111.90,-0.376
46.12,111.75,-0.375
46.14,111.60,-0.375
46.15,111.45,-0.375
46.17,111.30,-0.375
46.18,111.15,-0.375
46.20,111.00,-0.375
46.21,110.85,-0.375
46.23,110.70,-0.375
46.24,110.55,-0.375
46.26,110.40,-0.375
46.27,110.25,-0.375
46.29,110.10,-0.375
46.30,109.95,-0.375
46.32,109.80,-0.375
46.33,109.65,-0.374
46.35,109.50,-0.374
46.36,109.35,-0.374
46.38,109.20,-0.374
46.39,109.05,-0.374
46.41,108.90,-0.374
46.42,108.75,-0.374
46.44,108.60,-0.374
46.45,108.45,-0.374
46.47,108.30,-0.374
46.48,108.15,-0.374
46.50,108.01,-0.374
46.51,107.86,-0.374
46.53,107.71,-0.374
46.54,107.56,-0.374
46.56,107.41,-0.374
46.57,107.26,-0.373
46.59,107.11,-0.373
46.60,106.96,-0.373
46.62,106.81,-0.373
46.63,106.66,-0.373
46.65,106.51,-0.373
46.66,106.36,-0.373
46.68,106.21,-0.373
46.69,106.06,-0.373
46.71,105.91,-0.373
46.72,105.76,-0.373
46.74,105.61,-0.373
46.75,105.46,-0.373
46.77,105.31,-0.373
46.78,105.16,-0.372
46.80,105.01,-0.372
46.81,104.86,-0.372
46.83,104.71,-0.372
46.84,104.56,-0.372
46.86,104.41,-0.372
46.87,104.26,-0.372
46.89,104.11,-0.372
46.90,103.96,-0.372
46.92,103.81,-0.372
46.93,103.66,-0.372
46.95,103.51,-0.372
46.96,103.36,-0.372
46.98,103.21,-0.372
46.99,103.06,-0.372
47.01,102.91,-0.372
47.02,102.76,-0.372
47.04,102.61,-0.372
47.05,102.46,-0.372
47.07,102.31,-0.372
47.08,102.16,-0.371
47.10,102.01,-0.371
47.11,101.86,-0.371
47.13,101.71,-0.371
47.14,101.56,-0.371
47.16,101.41,-0.371
47.17,101.26,-0.371
47.19,101.11,-0.371
47.20,100.96,-0.371
[...]
132.38,-39.89,0.058
132.39,-39.82,0.058
132.40,-39.75,0.058
132.41,-39.68,0.058
132.43,-39.62,0.058
132.44,-39.55,0.058
132.45,-39.48,0.058
132.47,-39.42,0.059
132.48,-39.35,0.059
132.50,-39.28,0.059
132.51,-39.22,0.059
132.52,-39.15,0.059
132.54,-39.09,0.059
132.55,-39.02,0.059
132.56,-38.95,0.059
132.58,-38.88,0.059
132.59,-38.82,0.059
132.60,-38.75,0.059
132.61,-38.68,0.059
132.63,-38.62,0.059
132.64,-38.55,0.059
132.65,-38.49,0.059
132.67,-38.42,0.059
132.68,-38.35,0.059
132.70,-38.28,0.059
132.71,-38.22,0.059
132.72,-38.15,0.059
132.74,-38.08,0.059
132.75,-38.02,0.059
132.76,-37.95,0.059
132.78,-37.88,0.059
132.79,-37.82,0.059
132.80,-37.75,0.059
132.81,-37.68,0.059
132.83,-37.62,0.059
132.84,-37.55,0.059
132.85,-37.48,0.059
132.87,-37.42,0.059
132.88,-37.35,0.059
132.90,-37.28,0.059
132.91,-37.22,0.059
132.92,-37.15,0.059
132.94,-37.08,0.059
132.95,-37.02,0.059
132.96,-36.95,0.059
132.98,-36.88,0.059
132.99,-36.82,0.059
133.00,-36.75,0.059
133.01,-36.68,0.059
133.03,-36.61,0.059
133.04,-36.55,0.059
133.05,-36.48,0.059
133.07,-36.42,0.059
133.08,-36.35,0.059
133.10,-36.28,0.059
133.11,-36.21,0.059
133.12,-36.15,0.059
133.14,-36.08,0.059
133.15,-36.01,0.060
133.16,-35.95,0.060
133.18,-35.88,0.060
133.19,-35.81,0.060
133.20,-35.75,0.060
133.21,-35.68,0.060
133.23,-35.62,0.060
133.24,-35.55,0.060
133.25,-35.48,0.060
133.27,-35.41,0.060
133.28,-35.35,0.060
133.30,-35.28,0.060
133.31,-35.21,0.060
133.32,-35.15,0.060
133.34,-35.08,0.060
133.35,-35.02,0.060
133.36,-34.95,0.060
133.38,-34.88,0.060
133.39,-34.81,0.060
133.40,-34.75,0.060
133.41,-34.68,0.060
133.43,-34.61,0.060
133.44,-34.55,0.060
133.45,-34.48,0.060
133.47,-34.41,0.060
133.48,-34.35,0.060
133.50,-34.28,0.060
133.51,-34.21,0.060
133.52,-34.15,0.060
133.54,-34.08,0.060
133.55,-34.01,0.060
133.56,-33.95,0.060
133.58,-33.88,0.060
133.59,-33.81,0.060
133.60,-33.75,0.060
133.61,-33.68,0.060
133.63,-33.61,0.060
133.64,-33.55,0.060
133.65,-33.48,0.060
133.67,-33.41,0.060
133.68,-33.35,0.060
133.70,-33.28,0.060
133.71,-33.21,0.060
133.72,-33.15,0.060
133.74,-33.08,0.060
133.75,-33.01,0.060
133.76,-32.95,0.060
133.78,-32.88,0.060
133.79,-32.81,0.060
133.80,-32.75,0.060
133.81,-32.68,0.060
133.83,-32.61,0.060
133.84,-32.54,0.060
133.85,-32.48,0.060
133.87,-32.41,0.060
133.88,-32.34,0.060
133.90,-32.28,0.060
133.91,-32.21,0.060
133.92,-32.15,0.060
133.94,-32.08,0.060
133.95,-32.01,0.060
133.96,-31.94,0.060
133.98,-31.88,0.061
133.99,-31.81,0.061
134.00,-31.75,0.061
134.01,-31.68,0.061
134.03,-31.61,0.061
134.04,-31.54,0.061
134.05,-31.48,0.061
134.07,-31.41,0.061
134.08,-31.34,0.061
134.10,-31.28,0.061
134.11,-31.21,0.061
134.12,-31.14,0.061
134.14,-31.08,0.061
134.15,-31.01,0.061
134.16,-30.94,0.061
134.18,-30.88,0.061
134.19,-30.81,0.061
134.20,-30.74,0.061
134.21,-30.68,0.061
134.23,-30.61,0.061
134.24,-30.54,0.061
134.25,-30.48,0.061
134.27,-30.41,0.061
134.28,-30.34,0.061
134.30,-30.28,0.061
134.31,-30.21,0.061
134.32,-30.14,0.061
134.34,-30.08,0.061
134.35,-30.01,0.061
134.36,-29.94,0.061
134.38,-29.88,0.061
134.39,-29.81,0.061
134.40,-29.74,0.061
134.41,-29.68,0.061
134.43,-29.61,0.061
134.44,-29.54,0.061
134.45,-29.48,0.061
134.47,-29.41,0.061
134.48,-29.34,0.061
134.50,-29.28,0.061
134.51,-29.21,0.061
134.52,-29.14,0.061
134.54,-29.08,0.061
134.55,-29.01,0.061
134.56,-28.94,0.061
134.58,-28.88,0.061
134.59,-28.81,0.061
134.60,-28.74,0.061
134.61,-28.67,0.061
134.63,-28.61,0.062
134.64,-28.54,0.062
134.65,-28.48,0.062
134.67,-28.41,0.062
134.68,-28.34,0.062
134.70,-28.27,0.062
134.71,-28.21,0.062
134.72,-28.14,0.062
134.74,-28.08,0.062
134.75,-28.01,0.062
134.76,-27.94,0.062
134.78,-27.88,0.062
134.79,-27.81,0.062
134.80,-27.74,0.062
134.81,-27.67,0.062
134.83,-27.61,0.062
134.84,-27.54,0.062
134.85,-27.48,0.062
134.87,-27.41,0.062
134.88,-27.34,0.062
134.90,-27.28,0.062
134.91,-27.21,0.062
134.92,-27.14,0.062
134.94,-27.08,0.062
134.95,-27.01,0.062
134.96,-26.94,0.062
134.98,-26.88,0.062
134.99,-26.81,0.062
135.00,-26.74,0.062
135.01,-26.67,0.062
135.03,-26.61,0.062
135.04,-26.54,0.062
135.05,-26.47,0.062
135.07,-26.41,0.062
135.08,-26.34,0.062
135.10,-26.28,0.062
135.11,-26.21,0.062
135.12,-26.14,0.062
135.14,-26.08,0.062
135.15,-26.01,0.062
135.16,-25.94,0.062
135.18,-25.87,0.062
135.19,-25.81,0.062
135.20,-25.74,0.062
135.21,-25.67,0.062
135.23,-25.61,0.062
135.24,-25.54,0.062
135.25,-25.47,0.062
135.27,-25.41,0.062
135.28,-25.34,0.062
135.30,-25.27,0.063
135.31,-25.21,0.063
135.32,-25.14,0.063
135.34,-25.07,0.063
135.35,-25.01,0.063
135.36,-24.94,0.063
135.38,-24.87,0.063
135.39,-24.81,0.063
135.40,-24.74,0.063
135.41,-24.67,0.063
135.43,-24.61,0.063
135.44,-24.54,0.063
135.45,-24.47,0.063
135.47,-24.41,0.063
135.48,-24.34,0.063
135.50,-24.27,0.063
135.51,-24.21,0.063
135.52,-24.14,0.063
135.54,-24.07,0.063
135.55,-24.01,0.063
135.56,-23.94,0.063
135.58,-23.87,0.063
135.59,-23.81,0.063
135.60,-23.74,0.063
135.61,-23.67,0.063
135.63,-23.61,0.063
135.64,-23.54,0.063
135.65,-23.47,0.063
135.67,-23.41,0.063
135.68,-23.34,0.063
135.70,-23.27,0.063
135.71,-23.21,0.063
135.72,-23.14,0.063
135.74,-23.07,0.063
135.75,-23.01,0.063
135.76,-22.94,0.063
135.78,-22.87,0.063
135.79,-22.81,0.063
135.80,-22.74,0.063
135.81,-22.67,0.063
135.83,-22.61,0.063
135.84,-22.54,0.063
135.85,-22.47,0.063
135.87,-22.41,0.064
135.88,-22.34,0.064
135.90,-22.27,0.064
135.91,-22.21,0.064
135.92,-22.14,0.064
135.94,-22.07,0.064
135.95,-22.00,0.064
135.96,-21.94,0.064
135.98,-21.87,0.064
135.99,-21.80,0.064
136.00,-21.74,0.064
136.01,-21.67,0.064
136.03,-21.60,0.064
136.04,-21.54,0.064
136.05,-21.47,0.064
136.07,-21.40,0.064
136.08,-21.34,0.064
136.10,-21.27,0.064
136.11,-21.21,0.064
136.12,-21.14,0.064
136.14,-21.07,0.064
136.15,-21.00,0.064
136.16,-20.94,0.064
136.18,-20.87,0.064
136.19,-20.81,0.064
136.20,-20.74,0.064
136.21,-20.67,0.064
136.23,-20.60,0.064
136.24,-20.54,0.064
136.25,-20.47,0.064
136.27,-20.40,0.064
136.28,-20.34,0.064
136.30,-20.27,0.064
136.31,-20.20,0.064
136.32,-20.14,0.064
136.34,-20.07,0.064
136.35,-20.00,0.064
136.36,-19.94,0.064
136.38,-19.87,0.064
136.39,-19.80,0.064
136.40,-19.74,0.064
136.41,-19.67,0.064
136.43,-19.60,0.064
136.44,-19.54,0.064
136.45,-19.47,0.064
136.47,-19.40,0.065
136.48,-19.34,0.065
136.50,-19.27,0.065
136.51,-19.20,0.065
136.52,-19.14,0.065
136.53,-19.07,0.065
136.55,-19.00,0.065
136.56,-18.94,0.065
136.58,-18.87,0.065
136.59,-18.80,0.065
136.60,-18.73,0.065
136.62,-18.67,0.065
136.63,-18.60,0.065
136.64,-18.54,0.065
136.65,-18.47,0.065
136.67,-18.40,0.065
136.68,-18.34,0.065
136.70,-18.27,0.065
136.71,-18.20,0.065
136.72,-18.14,0.065
136.73,-18.07,0.065
136.75,-18.00,0.065
136.76,-17.94,0.065
136.78,-17.87,0.065
136.79,-17.80,0.065
136.80,-17.74,0.065
136.82,-17.67,0.065
136.83,-17.60,0.065
136.84,-17.54,0.065
136.85,-17.47,0.065
136.87,-17.40,0.065
136.88,-17.34,0.065
136.90,-17.27,0.065
136.91,-17.20,0.065
136.92,-17.14,0.065
136.93,-17.07,0.065
136.95,-17.00,0.065
136.96,-16.94,0.065
136.98,-16.87,0.066
136.99,-16.80,0.066
137.00,-16.74,0.066
137.02,-16.67,0.066
137.03,-16.60,0.066
137.04,-16.54,0.066
137.05,-16.47,0.066
137.07,-16.40,0.066
137.08,-16.34,0.066
137.10,-16.27,0.066
137.11,-16.20,0.066
137.12,-16.14,0.066
137.13,-16.07,0.066
137.15,-16.00,0.066
137.16,-15.94,0.066
137.18,-15.87,0.066
137.19,-15.80,0.066
137.20,-15.74,0.066
137.22,-15.67,0.066
137.23,-15.60,0.066
137.24,-15.54,0.066
137.25,-15.47,0.066
137.27,-15.40,0.066
137.28,-15.33,0.066
137.30,-15.27,0.066
137.31,-15.20,0.066
137.32,-15.13,0.066
137.33,-15.07,0.067
137.35,-15.00,0.067
137.36,-14.94,0.067
137.38,-14.87,0.067
137.39,-14.80,0.067
137.40,-14.74,0.067
137.42,-14.67,0.067
137.43,-14.60,0.067
137.44,-14.54,0.067
137.45,-14.47,0.067
137.47,-14.40,0.067
137.48,-14.34,0.067
137.50,-14.27,0.067
137.51,-14.20,0.067
137.52,-14.14,0.067
137.53,-14.07,0.067
137.55,-14.00,0.067
137.56,-13.94,0.067
137.58,-13.87,0.067
137.59,-13.80,0.067
137.60,-13.74,0.067
137.62,-13.67,0.067
137.63,-13.60,0.067
137.64,-13.54,0.067
137.65,-13.47,0.067
137.67,-13.40,0.068
137.68,-13.34,0.068
137.70,-13.27,0.068
137.71,-13.20,0.068
137.72,-13.14,0.068
137.73,-13.07,0.068
137.75,-13.00,0.068
137.76,-12.94,0.068
137.78,-12.87,0.068
137.79,-12.80,0.068
137.80,-12.74,0.068
137.82,-12.67,0.068
137.83,-12.60,0.068
137.84,-12.54,0.068
137.85,-12.47,0.068
137.87,-12.40,0.068
137.88,-12.34,0.068
137.90,-12.27,0.068
137.91,-12.20,0.068
137.92,-12.14,0.068
137.93,-12.07,0.068
137.95,-12.00,0.068
137.96,-11.94,0.069
137.98,-11.87,0.069
137.99,-11.80,0.069
138.00,-11.74,0.069
138.02,-11.67,0.069
138.03,-11.60,0.069
138.04,-11.54,0.069
138.05,-11.47,0.069
138.07,-11.40,0.069
138.08,-11.34,0.069
138.10,-11.27,0.069
138.11,-11.20,0.069
138.12,-11.14,0.069
138.13,-11.07,0.069
138.15,-11.00,0.069
138.16,-10.94,0.069
138.18,-10.87,0.070
138.19,-10.80,0.070
138.20,-10.74,0.070
138.22,-10.67,0.070
138.23,-10.60,0.070
138.24,-10.54,0.070
138.25,-10.47,0.070
138.27,-10.40,0.070
138.28,-10.34,0.070
138.30,-10.27,0.070
138.31,-10.20,0.070
138.32,-10.14,0.070
138.33,-10.07,0.070
138.35,-10.00,0.070
138.36,-9.94,0.070
138.38,-9.87,0.070
138.39,-9.80,0.071
138.40,-9.74,0.071
138.42,-9.67,0.071
138.43,-9.60,0.071
138.44,-9.54,0.071
138.45,-9.47,0.071
138.47,-9.40,0.071
138.48,-9.34,0.071
138.50,-9.27,0.071
138.51,-9.20,0.071
138.52,-9.14,0.071
138.53,-9.07,0.071
138.55,-9.00,0.072
138.56,-8.94,0.072
138.58,-8.87,0.072
138.59,-8.80,0.072
138.60,-8.74,0.072
138.62,-8.67,0.072
138.63,-8.60,0.072
138.64,-8.54,0.072
138.65,-8.47,0.072
138.67,-8.41,0.072
138.68,-8.34,0.072
138.70,-8.27,0.072
138.71,-8.20,0.073
138.72,-8.14,0.073
138.73,-8.07,0.073
138.75,-8.00,0.073
138.76,-7.94,0.073
138.78,-7.87,0.073
138.79,-7.81,0.073
138.80,-7.74,0.073
138.82,-7.67,0.073
138.83,-7.61,0.074
138.84,-7.54,0.074
138.85,-7.47,0.074
138.87,-7.40,0.074
138.88,-7.34,0.074
138.90,-7.27,0.074
138.91,-7.20,0.074
138.92,-7.14,0.074
138.93,-7.07,0.074
138.95,-7.01,0.074
138.96,-6.94,0.075
138.98,-6.87,0.075
138.99,-6.81,0.075
139.00,-6.74,0.075
139.02,-6.67,0.075
139.03,-6.61,0.075
139.04,-6.54,0.075
139.05,-6.47,0.075
139.07,-6.40,0.075
139.08,-6.34,0.076
139.10,-6.27,0.076
139.11,-6.21,0.076
139.12,-6.14,0.076
139.13,-6.07,0.076
139.15,-6.01,0.076
139.16,-5.94,0.076
139.18,-5.87,0.076
139.19,-5.81,0.077
139.20,-5.74,0.077
139.22,-5.67,0.077
139.23,-5.61,0.077
139.24,-5.54,0.077
139.25,-5.48,0.077
139.27,-5.41,0.077
139.28,-5.34,0.078
139.30,-5.28,0.078
139.31,-5.21,0.078
139.32,-5.14,0.078
139.33,-5.07,0.078
139.35,-5.01,0.078
139.36,-4.94,0.078
139.38,-4.87,0.079
139.39,-4.81,0.079
139.40,-4.74,0.079
139.42,-4.68,0.079
139.43,-4.61,0.079
139.44,-4.54,0.079
139.45,-4.48,0.080
139.47,-4.41,0.080
139.48,-4.35,0.080
139.50,-4.28,0.080
139.51,-4.21,0.080
139.52,-4.14,0.080
139.53,-4.08,0.081
139.55,-4.01,0.081
139.56,-3.94,0.081
139.58,-3.88,0.081
139.59,-3.81,0.081
139.60,-3.74,0.082
139.62,-3.68,0.082
139.63,-3.61,0.082
139.64,-3.55,0.082
139.65,-3.48,0.083
139.67,-3.41,0.083
139.68,-3.35,0.083
139.70,-3.28,0.083
139.71,-3.21,0.083
139.72,-3.15,0.084
139.73,-3.08,0.084
139.75,-3.01,0.084
139.76,-2.95,0.084
139.78,-2.88,0.085
139.79,-2.81,0.085
139.80,-2.75,0.085
139.82,-2.68,0.085
139.83,-2.62,0.085
139.84,-2.55,0.086
139.85,-2.48,0.086
139.87,-2.42,0.086
139.88,-2.35,0.086
139.90,-2.28,0.086
139.91,-2.22,0.087
139.92,-2.15,0.087
139.93,-2.08,0.087
139.95,-2.01,0.088
139.96,-1.95,0.088
139.98,-1.88,0.088
139.99,-1.82,0.088
140.00,-1.75,0.089
140.02,-1.68,0.089
140.03,-1.62,0.089
140.04,-1.55,0.090
140.05,-1.48,0.090
140.07,-1.42,0.090
140.08,-1.35,0.090
140.10,-1.28,0.091
140.11,-1.22,0.091
140.12,-1.15,0.091
140.13,-1.09,0.091
140.15,-1.02,0.091
140.16,-0.95,0.092
140.18,-0.89,0.092
140.19,-0.82,0.092
140.20,-0.75,0.092
140.22,-0.69,0.093
140.23,-0.62,0.093
140.24,-0.55,0.093
140.25,-0.49,0.093
140.27,-0.42,0.093
140.28,-0.35,0.094
140.30,-0.29,0.094
140.31,-0.22,0.094
140.32,-0.15,0.094
140.33,-0.09,0.094
140.35,-0.02,0.095
140.36,0.04,0.095
140.38,0.11,0.095
140.39,0.18,0.095
140.40,0.24,0.095
140.42,0.31,0.096
140.43,0.38,0.096
140.44,0.44,0.096
140.45,0.51,0.097
140.47,0.58,0.097
140.48,0.64,0.097
140.50,0.71,0.097
140.51,0.77,0.097
140.52,0.84,0.098
140.53,0.91,0.098
140.55,0.97,0.098
140.56,1.04,0.098
140.58,1.11,0.098
140.59,1.17,0.098
140.60,1.24,0.099
140.62,1.31,0.099
140.63,1.37,0.099
140.64,1.44,0.099
140.65,1.51,0.099
140.67,1.57,0.100
140.68,1.64,0.100
140.70,1.71,0.100
140.71,1.77,0.100
140.72,1.84,0.101
140.73,1.91,0.101
140.75,1.97,0.101
140.76,2.04,0.101
140.78,2.11,0.101
140.79,2.17,0.101
140.80,2.24,0.101
140.82,2.31,0.102
140.83,2.37,0.102
140.84,2.44,0.102
140.85,2.50,0.102
140.87,2.57,0.102
140.88,2.64,0.102
140.90,2.70,0.102
140.91,2.77,0.102
140.92,2.84,0.103
140.93,2.90,0.103
140.95,2.97,0.103
140.96,3.04,0.103
140.98,3.11,0.103
140.99,3.17,0.103
141.00,3.24,0.103
141.02,3.31,0.103
141.03,3.37,0.103
141.04,3.44,0.103
141.05,3.50,0.104
141.07,3.57,0.104
141.08,3.64,0.104
141.10,3.71,0.104
141.11,3.77,0.104
141.12,3.84,0.104
141.13,3.91,0.104
141.15,3.97,0.104
141.16,4.04,0.104
141.18,4.10,0.104
141.19,4.17,0.104
141.20,4.24,0.104
141.22,4.30,0.104
141.23,4.37,0.104
141.24,4.44,0.104
141.25,4.51,0.105
141.27,4.57,0.105
141.28,4.64,0.105
141.30,4.71,0.105
141.31,4.77,0.105
141.32,4.84,0.105
141.33,4.91,0.105
141.35,4.97,0.105
141.36,5.04,0.105
141.38,5.11,0.105
141.39,5.17,0.105
141.40,5.24,0.105
141.42,5.31,0.105
141.43,5.37,0.105
141.44,5.44,0.105
141.45,5.51,0.105
141.47,5.57,0.105
141.48,5.64,0.105
141.50,5.71,0.105
141.51,5.77,0.105
141.52,5.84,0.105
141.53,5.91,0.105
141.55,5.97,0.105
141.56,6.04,0.105
141.58,6.11,0.105
141.59,6.17,0.105
141.60,6.24,0.105
141.62,6.31,0.105
141.63,6.37,0.105
141.64,6.44,0.105
141.65,6.51,0.105
141.67,6.58,0.105
141.68,6.64,0.105
141.70,6.71,0.104
141.71,6.78,0.104
141.72,6.84,0.104
141.73,6.91,0.104
141.75,6.98,0.104
141.76,7.04,0.104
141.78,7.11,0.104
141.79,7.18,0.104
141.80,7.24,0.104
141.82,7.31,0.104
141.83,7.38,0.104
141.84,7.44,0.104
141.85,7.51,0.104
141.87,7.58,0.104
141.88,7.64,0.104
141.90,7.71,0.104
141.91,7.78,0.104
141.92,7.84,0.104
141.93,7.91,0.104
141.95,7.98,0.104
141.96,8.05,0.104
141.98,8.11,0.104
141.99,8.18,0.104
142.00,8.24,0.104
142.02,8.31,0.104
142.03,8.38,0.104
142.04,8.44,0.104
142.05,8.51,0.104
142.07,8.58,0.104
142.08,8.64,0.104
142.10,8.71,0.104
142.11,8.78,0.104
142.12,8.85,0.104
142.13,8.91,0.104
142.15,8.98,0.104
142.16,9.05,0.104
142.18,9.11,0.104
142.19,9.18,0.104
142.20,9.25,0.104
142.22,9.31,0.104
142.23,9.38,0.104
142.24,9.45,0.104
142.25,9.51,0.104
142.27,9.58,0.104
142.28,9.65,0.104
142.30,9.71,0.104
142.31,9.78,0.104
142.32,9.85,0.104
142.33,9.91,0.104
142.35,9.98,0.104
142.36,10.05,0.104
142.38,10.11,0.104
142.39,10.18,0.104
142.40,10.25,0.104
142.42,10.31,0.104
142.43,10.38,0.104
142.44,10.45,0.104
142.45,10.51,0.104
142.47,10.58,0.104
142.48,10.65,0.104
142.50,10.71,0.104
142.51,10.78,0.104
142.52,10.85,0.104
142.53,10.91,0.104
142.55,10.98,0.104
142.56,11.05,0.104
142.58,11.11,0.104
142.59,11.18,0.104
142.60,11.25,0.104
142.62,11.31,0.104
142.63,11.38,0.104
142.64,11.45,0.104
142.65,11.51,0.104
142.67,11.58,0.104
142.68,11.65,0.104
142.70,11.71,0.104
142.71,11.78,0.104
142.72,11.85,0.104
142.73,11.91,0.104
142.75,11.98,0.104
142.76,12.05,0.104
142.78,12.11,0.104
142.79,12.18,0.104
142.80,12.25,0.104
142.82,12.31,0.104
142.83,12.38,0.104
142.84,12.45,0.104
142.85,12.51,0.104
142.87,12.58,0.104
142.88,12.65,0.104
142.90,12.71,0.104
142.91,12.78,0.104
142.92,12.85,0.104
142.93,12.92,0.104
142.95,12.98,0.104
142.96,13.05,0.104
142.98,13.12,0.104
142.99,13.18,0.104
143.00,13.25,0.104
143.02,13.32,0.104
143.03,13.38,0.104
143.04,13.45,0.104
143.05,13.52,0.104
143.07,13.58,0.104
143.08,13.65,0.104
143.10,13.72,0.104
143.11,13.78,0.104
143.12,13.85,0.104
143.13,13.92,0.104
143.15,13.98,0.104
143.16,14.05,0.104
143.18,14.12,0.104
143.19,14.18,0.104
143.20,14.25,0.104
143.22,14.32,0.104
143.23,14.38,0.104
143.24,14.45,0.104
143.25,14.52,0.104
143.27,14.58,0.104
143.28,14.65,0.104
143.30,14.72,0.104
143.31,14.78,0.104
143.32,14.85,0.104
143.33,14.92,0.104
143.35,14.98,0.104
143.36,15.05,0.104
143.38,15.12,0.104
143.39,15.18,0.104
143.40,15.25,0.104
143.42,15.32,0.104
143.43,15.38,0.104
143.44,15.45,0.104
143.45,15.52,0.104
143.47,15.58,0.104
143.48,15.65,0.104
143.50,15.72,0.104
143.51,15.78,0.104
143.52,15.85,0.104
143.53,15.92,0.104
143.55,15.98,0.104
143.56,16.05,0.104
143.58,16.12,0.104
143.59,16.18,0.104
143.60,16.25,0.104
143.62,16.32,0.104
143.63,16.38,0.104
143.64,16.45,0.104
143.65,16.52,0.104
143.67,16.58,0.104
143.68,16.65,0.104
143.70,16.72,0.104
143.71,16.78,0.105
143.72,16.85,0.105
143.73,16.92,0.105
143.75,16.98,0.105
143.76,17.05,0.105
143.78,17.12,0.105
143.79,17.19,0.105
143.80,17.25,0.105
143.82,17.32,0.105
143.83,17.38,0.105
143.84,17.45,0.105
143.85,17.52,0.105
143.87,17.59,0.105
143.88,17.65,0.105
143.90,17.72,0.105
143.91,17.79,0.105
143.92,17.85,0.105
143.93,17.92,0.105
143.95,17.98,0.105
143.96,18.05,0.105
143.98,18.12,0.105
143.99,18.18,0.105
144.00,18.25,0.105
144.02,18.32,0.105
144.03,18.38,0.105
144.04,18.45,0.105
144.05,18.52,0.105
144.07,18.59,0.105
144.08,18.65,0.105
144.10,18.72,0.105
144.11,18.79,0.105
144.12,18.85,0.105
144.13,18.92,0.105
144.15,18.99,0.105
144.16,19.05,0.105
144.18,19.12,0.105
144.19,19.19,0.106
144.20,19.25,0.106
144.22,19.32,0.106
144.23,19.39,0.106
144.24,19.45,0.106
144.25,19.52,0.106
144.27,19.58,0.106
144.28,19.65,0.106
144.30,19.72,0.106
144.31,19.79,0.106
144.32,19.85,0.106
144.33,19.92,0.106
144.35,19.99,0.106
144.36,20.05,0.106
144.38,20.12,0.106
144.39,20.19,0.106
144.40,20.25,0.106
144.42,20.32,0.106
144.43,20.39,0.106
144.44,20.45,0.106
144.45,20.52,0.106
144.47,20.59,0.106
144.48,20.65,0.106
144.50,20.72,0.106
144.51,20.78,0.106
144.52,20.85,0.106
144.53,20.92,0.106
144.55,20.99,0.106
144.56,21.05,0.106
144.58,21.12,0.106
144.59,21.19,0.106
144.60,21.25,0.106
144.62,21.32,0.106
144.63,21.39,0.106
144.64,21.45,0.106
144.65,21.52,0.106
144.67,21.59,0.106
144.68,21.65,0.106
144.70,21.72,0.106
144.71,21.79,0.106
144.72,21.85,0.106
144.73,21.92,0.106
144.75,21.99,0.106
144.76,22.05,0.106
144.78,22.12,0.106
144.79,22.19,0.106
144.80,22.25,0.106
144.82,22.32,0.106
144.83,22.39,0.106
144.84,22.45,0.106
144.85,22.52,0.106
144.87,22.59,0.106
144.88,22.65,0.106
144.90,22.72,0.106
144.91,22.79,0.106
144.92,22.85,0.107
144.93,22.92,0.107
144.95,22.99,0.107
144.96,23.05,0.107
144.98,23.12,0.107
144.99,23.19,0.107
145.00,23.25,0.106
145.02,23.32,0.106
145.03,23.39,0.106
145.04,23.46,0.106
145.05,23.52,0.107
145.07,23.59,0.107
145.08,23.66,0.107
145.10,23.72,0.107
145.11,23.79,0.107
145.12,23.86,0.107
145.13,23.92,0.107
145.15,23.99,0.107
145.16,24.06,0.107
145.18,24.12,0.107
145.19,24.19,0.107
145.20,24.26,0.107
145.22,24.32,0.107
145.23,24.39,0.107
145.24,24.46,0.107
145.25,24.52,0.107
145.27,24.59,0.107
145.28,24.66,0.107
145.30,24.72,0.107
145.31,24.79,0.107
145.32,24.86,0.107
145.33,24.92,0.107
145.35,24.99,0.107
145.36,25.06,0.107
145.38,25.12,0.107
145.39,25.19,0.107
145.40,25.26,0.107
145.42,25.32,0.107
145.43,25.39,0.107
145.44,25.46,0.107
145.45,25.52,0.107
145.47,25.59,0.107
145.48,25.65,0.107
145.50,25.72,0.107
145.51,25.79,0.107
145.52,25.86,0.107
145.53,25.92,0.107
145.55,25.99,0.107
145.56,26.06,0.108
145.58,26.12,0.108
145.59,26.19,0.108
145.60,26.26,0.108
145.62,26.32,0.108
145.63,26.39,0.108
145.64,26.46,0.108
145.65,26.52,0.108
145.67,26.59,0.108
145.68,26.66,0.108
145.70,26.72,0.108
145.71,26.79,0.108
145.72,26.86,0.108
145.73,26.92,0.108
145.75,26.99,0.108
145.76,27.06,0.108
145.78,27.12,0.108
145.79,27.19,0.108
145.80,27.26,0.108
145.82,27.33,0.108
145.83,27.39,0.108
145.84,27.46,0.108
145.85,27.53,0.108
145.87,27.59,0.108
145.88,27.66,0.108
145.90,27.73,0.108
145.91,27.79,0.108
145.92,27.86,0.108
145.93,27.93,0.108
145.95,27.99,0.108
145.96,28.06,0.108
145.98,28.13,0.108
145.99,28.19,0.108
146.00,28.26,0.108
146.02,28.32,0.108
146.03,28.39,0.108
146.04,28.46,0.108
146.05,28.53,0.108
146.07,28.59,0.108
146.08,28.66,0.108
146.10,28.73,0.108
146.11,28.79,0.108
146.12,28.86,0.108
146.13,28.93,0.108
146.15,28.99,
146.16,29.06,
146.18,29.13,
146.19,29.19,
146.20,,