File: DSC/2025_04_18_Indium_n60C_200C_5Cmin_x3.csv
Filename,2025_04_18_Indium_n60C_200C_5Cmin_x3
Instrument name,DSC2A-00468 (192.168.1.100)
Operator,Yarger
rundate,4/18/2025
Sample name,2025_04_18_Indium_n60C_200C_5Cmin_x3
proceduresegments,Data Off ; Equilibrate -60.00 °C; Data On ; Ramp 5.00 °C/min to 200.00 °C; Data Off ; Isothermal 0.1 min; Data On ; Ramp 10.00 °C/min to -60.00 °C; Data Off ; Isothermal 1.0 min; Data On ; Ramp 5.00 °C/min to 200.00 °C; Data Off ; Isothermal 0.1 min; Data On ; Ramp 10.00 °C/min to -60.00 °C; Data Off ; Isothermal 1.0 min; Data On ; Ramp 5.00 °C/min to 30.00 °C
[File Parameters]
Run date,4/18/2025 9:27:19 PM
Trios version,5.1.1.46572
Original File Name,
Current File Name,D:\DSC2500\JYarger\2025_04_18_Indium_n60C_200C_5Cmin_x3.tri
[Procedure]
Procedure Name,In_n60_170C_5Cmin_x3
Sample Name,2025_04_18_Indium_n60C_200C_5Cmin_x3
Sample Mass,20.72 mg
Reference Sample Mass,0 mg
Pan Mass,53.8 mg
Pan Number,52
Reference Pan Mass,53.66 mg
Reference Pan Number,46
Pan Type,Tzero Aluminum Hermetic
Comments,Hermetic Sealed Al DSC Consumables Pan/Lids.
Project Name,CA
Operator,Yarger
Test,Custom
Unload Max Temperature,30
Unload Min Temperature,30
Load Max Temperature,30
Load Min Temperature,30
Stop on Gas Flow Error,Yes
[Signal List]
Signal #1,Time (min)
Signal #2,Temperature (°C)
Signal #3,Heat Flow (mW)
Signal #4,Delta T (µV)
Signal #5,Delta Tzero (µV)
Signal #6,Tzero Temperature (°C)
Signal #7,Cell Purge (mL/min)
Signal #8,Heater Temp (°C)
Signal #9,Power Delivered (W)
Signal #10,Reference Junction Temperature (°C)
Signal #11,Flange Temperature (°C)
Signal #12,Heat Flow Phase (rad)
Signal #13,Total Heat Capacity (J/°C)
Signal #14,Heat Capacity (J/°C)
[Configuration]
Company Name,ASU
Instrument Name,DSC2A-00468
Instrument Type,DSC2500
Serial Number,DSC2A-00468
IP,192.168.1.100
Location of Instrument,MRRC
DisplayType,Unknown
Sample Interval ,0.1 s/pt
Selected Heat Flow,T4P
Exotherm Direction,Down
Cell Serial,DRC2-00792
Lid Type,Standard
Cooler,RCS 90
Leave Cooler on at End of Sequence,On
Gas 2,Nitrogen
Gas Selected,Channel 1
Flow Rate,50 mL/min
Secondary Purge,On
Licensed Heat Flow,Heat Flow T4P
Modulation Licensed,Yes
[Versions]
Common IDD Version,1
Cortex Version,VER 2.10.2.31
Driver,5.0.0.6
GDM Version,1.0.3.3
TouchscreenVersion,1.0.0.16145
FEP Version,1.2.1.21
FEP Bootloader,2.0.0.5
AutoSampler Version,2.1.1.26
Auto Sampler Bootloader,2.0.0.5
FCM Version,1.1.0.3
FCM Bootloader,2.0.0.5
[Experiment Logs]
Experiment Log Entry # 1,Data On set to 0
Experiment Log Entry # 3,Equilibrate Segment -60 (C) Started
Experiment Log Entry # 5,Air Cool is off.
Experiment Log Entry # 7,Data On set to 1
Experiment Log Entry # 9,Ramp Segment 5 C/min to 200 Started
Experiment Log Entry # 11,Data On set to 0
Experiment Log Entry # 13,Isothermal Segment 0.1 min started
Experiment Log Entry # 15,Data On set to 1
Experiment Log Entry # 17,Ramp Segment 10 C/min to -60 Started
Experiment Log Entry # 19,Data On set to 0
Experiment Log Entry # 21,Isothermal Segment 1 min started
Experiment Log Entry # 23,Data On set to 1
Experiment Log Entry # 25,Ramp Segment 5 C/min to 200 Started
Experiment Log Entry # 27,Data On set to 0
Experiment Log Entry # 29,Isothermal Segment 0.1 min started
Experiment Log Entry # 31,Data On set to 1
Experiment Log Entry # 33,Ramp Segment 10 C/min to -60 Started
Experiment Log Entry # 35,Data On set to 0
Experiment Log Entry # 37,Isothermal Segment 1 min started
Experiment Log Entry # 39,Data On set to 1
Experiment Log Entry # 41,Ramp Segment 5 C/min to 30 Started
[Method Log]
Method Log Entry # 1,Data Off
Method Log Entry # 2,Equilibrate -60 °C
Method Log Entry # 3,Data On
Method Log Entry # 4,(Ramp 103213) Ramp 5 °C/minute to 200 °C
Method Log Entry # 5,Data Off
Method Log Entry # 6,Isothermal 0.1 minutes
Method Log Entry # 7,Data On
Method Log Entry # 8,(Ramp 103217) Ramp 10 °C/minute to -60 °C
Method Log Entry # 9,Data Off
Method Log Entry # 10,Isothermal 1 minutes
Method Log Entry # 11,Data On
Method Log Entry # 12,(Ramp 103221) Ramp 5 °C/minute to 200 °C
Method Log Entry # 13,Data Off
Method Log Entry # 14,Isothermal 0.1 minutes
Method Log Entry # 15,Data On
Method Log Entry # 16,(Ramp 103225) Ramp 10 °C/minute to -60 °C
Method Log Entry # 17,Data Off
Method Log Entry # 18,Isothermal 1 minutes
Method Log Entry # 19,Data On
Method Log Entry # 20,(Ramp 103229) Ramp 5 °C/minute to 30 °C
Cell Serial,DRC2-00792
[T1 Calibration]
Slope,-0.008529666
Offset,9.636258
Initial Temperature,98.23
GUID,f8bfdadc-4977-4fdf-ba6d-0ba9134940c3
[TZero Calibration]
Date Applied,11/29/2022 4:06:13 PM
Description,From -89.059 °C to 396.009 °C at 20.000°C/min
Gas Type,Nitrogen
Pan Type,None
Source Files 1,C:\Users\yargerlab\Desktop\DSC Data\General\TZero_calibration_11_29_22_2nd(2).tri
Source Files 2,C:\Users\yargerlab\Desktop\DSC Data\General\TZero_calibration_11_29_22_2nd(3).tri
Delta T Offset,13.05235
Delta T Slope,-0.007271007
Delta T0 Offset,-13.69128
Delta T0 Slope,0.06063341
[Temperature Calibration]
Date Applied,11/29/2022 7:12:28 PM
Description,From 106.590 °C to 186.590 °C at 10.000°C/min
Gas Type,Nitrogen
Pan Type,Tzero Aluminum Hermetic
Source Files 1,C:\Users\yargerlab\Desktop\DSC Data\General\Indium(6).tri
Measured 1,157.391
Known 1,156.598
[Cell Constant Calibration]
Date Applied,11/29/2022 7:12:29 PM
Description,From 106.590 °C to 186.590 °C at 10.000°C/min
Gas Type,Nitrogen
Pan Type,Tzero Aluminum Hermetic
Source Files 1,C:\Users\yargerlab\Desktop\DSC Data\General\Indium(6).tri
T4P KCell,1.006051
Onset Slope,63.26126 mW/°C
[Direct Cp Calibration]
Date Applied,11/30/2022 11:04:51 AM
Description,From -79.983 °C to 298.409 °C at 10.000°C/min
Gas Type,Nitrogen
Pan Type,Tzero Aluminum Hermetic
Source Files 1,C:\Users\yargerlab\Desktop\DSC Data\General\Sapphire_Heat_Capacity_11_30_22.tri
[Rev Cp Calibration]
Date Applied,11/30/2022 1:58:51 PM
Description,From -79.996 °C to 292.812 °C at 3.000°C/min
Gas Type,Nitrogen
Pan Type,Tzero Aluminum Hermetic
Source Files 1,C:\Users\yargerlab\Desktop\DSC Data\General\Sapphire_MDSC_Calibration_11_30_22.tri
[step]
Ramp 5.00 °C/min to 200.00 °C
Time,Temperature,Heat Flow (Normalized)
min,°C,W/g
0.00,-59.68,-0.009
0.03,-59.70,-0.009
0.07,-59.70,-0.007
0.11,-59.65,-0.006
0.14,-59.57,-0.002
0.18,-59.45,0.002
0.21,-59.32,0.007
0.24,-59.18,0.010
0.28,-59.03,0.012
0.31,-58.88,0.014
0.35,-58.72,0.015
0.39,-58.56,0.016
0.42,-58.40,0.017
0.45,-58.23,0.017
0.49,-58.07,0.017
0.53,-57.90,0.018
0.56,-57.73,0.018
0.60,-57.56,0.018
0.63,-57.39,0.018
0.67,-57.22,0.018
0.70,-57.05,0.018
0.73,-56.88,0.018
0.77,-56.71,0.018
0.80,-56.54,0.019
0.84,-56.37,0.019
0.88,-56.20,0.019
0.91,-56.02,0.019
0.95,-55.85,0.019
0.98,-55.68,0.019
1.02,-55.50,0.019
1.05,-55.33,0.019
1.08,-55.16,0.019
1.12,-54.99,0.019
1.16,-54.81,0.019
1.19,-54.64,0.019
1.23,-54.46,0.019
1.26,-54.29,0.019
1.29,-54.12,0.019
1.33,-53.94,0.019
1.37,-53.77,0.019
1.40,-53.60,0.019
1.43,-53.42,0.019
1.47,-53.25,0.019
1.51,-53.07,0.019
1.54,-52.90,0.019
1.58,-52.72,0.019
1.61,-52.55,0.019
1.64,-52.38,0.019
1.68,-52.20,0.019
1.72,-52.03,0.019
1.75,-51.85,0.019
1.78,-51.68,0.019
1.82,-51.50,0.019
1.86,-51.33,0.019
1.89,-51.15,0.019
1.93,-50.98,0.019
1.96,-50.81,0.019
1.99,-50.63,0.019
2.03,-50.45,0.019
2.07,-50.28,0.019
2.10,-50.11,0.018
2.14,-49.93,0.018
2.17,-49.76,0.018
2.21,-49.58,0.018
2.24,-49.41,0.018
2.28,-49.23,0.018
2.31,-49.06,0.018
2.34,-48.88,0.018
2.38,-48.71,0.018
2.41,-48.53,0.018
2.45,-48.36,0.018
2.49,-48.18,0.018
2.52,-48.01,0.018
2.56,-47.83,0.018
2.59,-47.66,0.018
2.63,-47.48,0.018
2.66,-47.31,0.018
2.69,-47.13,0.018
2.73,-46.96,0.018
2.76,-46.78,0.018
2.80,-46.61,0.018
2.84,-46.43,0.018
2.87,-46.26,0.018
2.91,-46.08,0.018
2.94,-45.91,0.018
2.98,-45.73,0.018
3.01,-45.56,0.018
3.04,-45.38,0.018
3.08,-45.21,0.018
3.11,-45.03,0.018
3.15,-44.86,0.018
3.19,-44.68,0.018
3.22,-44.51,0.018
3.26,-44.33,0.018
3.29,-44.16,0.018
3.33,-43.99,0.018
3.36,-43.81,0.018
3.39,-43.63,0.018
3.43,-43.46,0.018
3.46,-43.28,0.018
3.50,-43.11,0.018
3.54,-42.93,0.018
3.57,-42.76,0.018
3.61,-42.58,0.018
3.64,-42.41,0.018
3.68,-42.23,0.018
3.71,-42.06,0.018
3.74,-41.88,0.018
3.78,-41.71,0.018
3.81,-41.53,0.018
3.85,-41.36,0.018
3.89,-41.18,0.018
3.92,-41.01,0.018
3.96,-40.83,0.018
3.99,-40.66,0.018
4.03,-40.48,0.018
4.06,-40.31,0.018
4.09,-40.13,0.018
4.13,-39.95,0.018
4.16,-39.78,0.018
4.20,-39.60,0.018
4.24,-39.43,0.018
4.27,-39.26,0.018
4.30,-39.08,0.018
4.34,-38.90,0.018
4.38,-38.73,0.018
4.41,-38.55,0.018
4.45,-38.38,0.018
4.48,-38.20,0.018
4.51,-38.03,0.018
4.55,-37.85,0.018
4.59,-37.68,0.018
4.62,-37.50,0.018
4.65,-37.33,0.018
4.69,-37.15,0.017
4.73,-36.98,0.017
4.76,-36.80,0.017
4.80,-36.63,0.017
4.83,-36.45,0.017
4.86,-36.28,0.017
4.90,-36.10,0.017
4.94,-35.93,0.017
4.97,-35.75,0.017
5.00,-35.58,0.017
5.04,-35.40,0.017
5.08,-35.23,0.017
5.11,-35.05,0.017
5.15,-34.88,0.017
5.18,-34.70,0.017
5.21,-34.53,0.017
5.25,-34.35,0.017
5.29,-34.17,0.017
5.32,-34.00,0.017
5.35,-33.82,0.017
5.39,-33.65,0.017
5.43,-33.47,0.017
5.46,-33.30,0.017
5.50,-33.12,0.017
5.53,-32.95,0.017
5.56,-32.77,0.017
5.60,-32.60,0.017
5.64,-32.42,0.017
5.67,-32.25,0.017
5.70,-32.07,0.017
5.74,-31.90,0.017
5.78,-31.72,0.017
5.81,-31.54,0.017
5.85,-31.37,0.017
5.88,-31.19,0.017
5.91,-31.02,0.017
5.95,-30.84,0.017
5.99,-30.67,0.017
6.02,-30.49,0.017
6.05,-30.32,0.017
6.09,-30.14,0.017
6.13,-29.97,0.017
6.16,-29.79,0.017
6.20,-29.62,0.017
6.23,-29.44,0.017
6.26,-29.27,0.017
6.30,-29.09,0.017
6.34,-28.92,0.017
6.37,-28.74,0.017
6.40,-28.57,0.017
6.44,-28.39,0.017
6.48,-28.22,0.017
6.51,-28.04,0.017
6.55,-27.87,0.017
6.58,-27.69,0.017
6.61,-27.52,0.017
6.65,-27.34,0.017
6.69,-27.17,0.017
6.72,-26.99,0.017
6.75,-26.82,0.017
6.79,-26.64,0.017
6.83,-26.47,0.017
6.86,-26.29,0.017
6.90,-26.11,0.017
6.93,-25.94,0.017
6.96,-25.76,0.017
7.00,-25.59,0.017
7.04,-25.41,0.017
7.07,-25.24,0.017
7.10,-25.06,0.017
7.14,-24.89,0.017
7.18,-24.71,0.017
7.21,-24.54,0.017
7.25,-24.36,0.017
7.28,-24.19,0.017
7.31,-24.01,0.017
7.35,-23.84,0.017
7.39,-23.66,0.017
7.42,-23.49,0.017
7.45,-23.31,0.017
7.49,-23.14,0.017
7.53,-22.96,0.017
7.56,-22.79,0.017
7.60,-22.61,0.017
7.63,-22.44,0.017
7.66,-22.26,0.017
7.70,-22.09,0.017
7.74,-21.91,0.017
7.77,-21.74,0.017
7.80,-21.56,0.017
7.84,-21.39,0.017
7.88,-21.21,0.017
7.91,-21.04,0.017
7.95,-20.86,0.017
7.98,-20.68,0.017
8.01,-20.51,0.017
8.05,-20.33,0.017
8.09,-20.16,0.017
8.12,-19.98,0.017
8.15,-19.81,0.017
8.19,-19.63,0.017
8.23,-19.46,0.017
8.26,-19.28,0.017
8.30,-19.11,0.017
8.33,-18.93,0.017
8.36,-18.76,0.017
8.40,-18.58,0.017
8.44,-18.41,0.017
8.47,-18.23,0.017
8.50,-18.06,0.017
8.54,-17.88,0.017
8.58,-17.71,0.017
8.61,-17.53,0.017
8.65,-17.36,0.017
8.68,-17.18,0.017
8.72,-17.01,0.017
8.75,-16.83,0.017
8.78,-16.66,0.017
8.82,-16.48,0.017
8.85,-16.31,0.017
8.89,-16.13,0.017
8.93,-15.95,0.017
8.96,-15.78,0.017
9.00,-15.60,0.017
9.03,-15.43,0.017
9.07,-15.26,0.017
9.10,-15.08,0.017
9.13,-14.90,0.017
9.17,-14.73,0.017
9.20,-14.55,0.017
9.24,-14.38,0.017
9.28,-14.20,0.017
9.31,-14.03,0.017
9.35,-13.85,0.017
9.38,-13.68,0.017
9.42,-13.50,0.017
9.45,-13.33,0.017
9.48,-13.15,0.017
9.52,-12.98,0.017
9.55,-12.80,0.017
9.59,-12.63,0.017
9.63,-12.45,0.017
9.66,-12.28,0.017
9.70,-12.10,0.017
9.73,-11.93,0.017
9.77,-11.75,0.017
9.80,-11.58,0.017
9.83,-11.40,0.017
9.87,-11.23,0.017
9.90,-11.05,0.017
9.94,-10.88,0.017
9.98,-10.70,0.017
10.01,-10.53,0.017
10.05,-10.35,0.017
10.08,-10.18,0.017
10.12,-10.00,0.017
10.15,-9.83,0.017
10.18,-9.65,0.017
10.22,-9.48,0.017
10.25,-9.30,0.017
10.29,-9.12,0.017
10.33,-8.95,0.017
10.36,-8.78,0.016
10.40,-8.60,0.016
10.43,-8.42,0.016
10.47,-8.25,0.016
10.50,-8.07,0.016
10.53,-7.90,0.016
10.57,-7.72,0.016
10.60,-7.55,0.016
10.64,-7.37,0.016
10.68,-7.20,0.016
10.71,-7.02,0.017
10.75,-6.85,0.016
10.78,-6.67,0.017
10.82,-6.50,0.017
10.85,-6.32,0.017
10.88,-6.14,0.017
10.92,-5.97,0.017
10.95,-5.80,0.017
10.99,-5.62,0.017
11.03,-5.44,0.016
11.06,-5.27,0.016
11.10,-5.10,0.016
11.13,-4.92,0.016
11.17,-4.75,0.016
11.20,-4.57,0.016
11.23,-4.40,0.016
11.27,-4.22,0.016
11.30,-4.04,0.016
11.34,-3.87,0.016
11.38,-3.69,0.016
11.41,-3.52,0.016
11.45,-3.34,0.016
11.48,-3.17,0.016
11.52,-2.99,0.016
11.55,-2.82,0.016
11.58,-2.64,0.016
11.62,-2.47,0.016
11.65,-2.29,0.016
11.69,-2.12,0.016
11.73,-1.94,0.016
11.76,-1.77,0.016
11.80,-1.59,0.016
11.83,-1.42,0.016
11.87,-1.24,0.016
11.90,-1.07,0.016
11.93,-0.89,0.016
11.97,-0.72,0.016
12.00,-0.54,0.016
12.04,-0.37,0.016
12.08,-0.19,0.016
12.11,-0.02,0.016
12.15,0.16,0.016
12.18,0.33,0.016
12.22,0.51,0.016
12.25,0.68,0.016
12.28,0.86,0.016
12.32,1.04,0.016
12.35,1.21,0.016
12.39,1.38,0.016
12.43,1.56,0.016
12.46,1.74,0.016
12.50,1.91,0.016
12.53,2.08,0.016
12.57,2.26,0.016
12.60,2.44,0.016
12.63,2.61,0.016
12.67,2.78,0.016
12.70,2.96,0.016
12.74,3.14,0.016
12.78,3.31,0.016
12.81,3.49,0.016
12.85,3.66,0.016
12.88,3.84,0.016
12.92,4.01,0.016
12.95,4.19,0.016
12.98,4.36,0.016
13.02,4.54,0.016
13.05,4.71,0.016
13.09,4.89,0.016
13.13,5.06,0.016
13.16,5.24,0.016
13.20,5.41,0.016
13.23,5.59,0.016
13.27,5.76,0.016
13.30,5.94,0.016
13.33,6.11,0.016
13.37,6.29,0.016
13.40,6.47,0.016
13.44,6.64,0.016
13.48,6.82,0.016
13.51,6.99,0.016
13.55,7.17,0.016
13.58,7.34,0.016
13.62,7.51,0.016
13.65,7.69,0.016
13.68,7.87,0.016
13.72,8.04,0.016
13.75,8.22,0.016
13.79,8.39,0.016
13.83,8.57,0.016
13.86,8.74,0.016
13.90,8.92,0.016
13.93,9.09,0.016
13.97,9.27,0.016
14.00,9.44,0.016
14.03,9.62,0.016
14.07,9.79,0.016
14.10,9.97,0.016
14.14,10.14,0.016
14.18,10.32,0.016
14.21,10.49,0.016
14.25,10.67,0.016
14.28,10.84,0.016
14.32,11.02,0.016
14.35,11.19,0.016
14.38,11.37,0.016
14.42,11.54,0.016
14.45,11.72,0.016
14.49,11.89,0.016
14.53,12.07,0.016
14.56,12.24,0.016
14.60,12.42,0.016
14.63,12.59,0.016
14.67,12.77,0.016
14.70,12.94,0.016
14.73,13.12,0.016
14.77,13.29,0.016
14.80,13.47,0.016
14.84,13.65,0.016
14.88,13.82,0.016
14.91,14.00,0.016
14.95,14.17,0.016
14.98,14.35,0.016
15.02,14.52,0.016
15.05,14.70,0.016
15.08,14.87,0.016
15.12,15.05,0.016
15.15,15.22,0.016
15.19,15.40,0.016
15.23,15.57,0.016
15.26,15.75,0.016
15.30,15.92,0.016
15.33,16.10,0.016
15.37,16.27,0.016
15.40,16.45,0.016
15.43,16.62,0.016
15.47,16.80,0.016
15.50,16.97,0.016
15.54,17.15,0.016
15.58,17.32,0.016
15.61,17.50,0.016
15.65,17.67,0.016
15.68,17.85,0.016
15.72,18.02,0.016
15.75,18.20,0.016
15.78,18.37,0.016
15.82,18.55,0.016
15.85,18.72,0.016
15.89,18.90,0.016
15.93,19.07,0.016
15.96,19.25,0.016
16.00,19.42,0.016
16.03,19.60,0.016
16.07,19.77,0.016
16.10,19.95,0.016
16.13,20.13,0.016
16.17,20.30,0.016
16.20,20.47,0.016
16.24,20.65,0.016
16.28,20.82,0.016
16.31,21.00,0.016
16.35,21.18,0.016
16.38,21.35,0.016
16.42,21.53,0.016
16.45,21.70,0.016
16.48,21.88,0.016
16.52,22.05,0.016
16.55,22.23,0.016
16.59,22.40,0.016
16.63,22.58,0.016
16.66,22.75,0.016
16.70,22.93,0.016
16.73,23.10,0.016
16.77,23.28,0.016
16.80,23.45,0.016
16.83,23.63,0.016
16.87,23.80,0.016
16.90,23.98,0.016
16.94,24.15,0.016
16.98,24.33,0.016
17.01,24.50,0.016
17.05,24.68,0.016
17.08,24.85,0.016
17.12,25.03,0.016
17.15,25.20,0.016
17.18,25.38,0.016
17.22,25.56,0.016
17.26,25.73,0.016
17.29,25.90,0.016
17.33,26.08,0.016
17.36,26.25,0.016
17.39,26.43,0.016
17.43,26.61,0.016
17.47,26.78,0.016
17.50,26.95,0.016
17.53,27.13,0.016
17.57,27.30,0.016
17.61,27.48,0.016
17.64,27.65,0.016
17.68,27.83,0.016
17.71,28.01,0.016
17.74,28.18,0.016
17.78,28.36,0.016
17.82,28.53,0.016
17.85,28.71,0.016
17.88,28.88,0.016
17.92,29.06,0.016
17.96,29.23,0.016
17.99,29.41,0.016
18.03,29.58,0.016
18.06,29.76,0.016
18.09,29.93,0.016
18.13,30.11,0.016
18.17,30.28,0.016
18.20,30.46,0.016
18.23,30.63,0.016
18.27,30.81,0.016
18.31,30.98,0.016
18.34,31.16,0.016
18.38,31.33,0.016
18.41,31.51,0.016
18.44,31.68,0.016
18.48,31.86,0.016
18.52,32.03,0.016
18.55,32.21,0.016
18.58,32.38,0.016
18.62,32.56,0.016
18.66,32.73,0.016
18.69,32.91,0.016
18.73,33.08,0.016
18.76,33.26,0.016
18.79,33.43,0.016
18.83,33.61,0.016
18.87,33.79,0.016
18.90,33.96,0.016
18.93,34.13,0.016
18.97,34.31,0.016
19.01,34.48,0.016
19.04,34.66,0.016
19.08,34.84,0.016
19.11,35.01,0.016
19.14,35.19,0.016
19.18,35.36,0.016
19.22,35.54,0.016
19.25,35.71,0.016
19.28,35.89,0.016
19.32,36.06,0.016
19.36,36.24,0.016
19.39,36.41,0.016
19.43,36.59,0.016
19.46,36.76,0.016
19.49,36.94,0.016
19.53,37.11,0.016
19.57,37.29,0.016
19.60,37.46,0.016
19.63,37.64,0.016
19.67,37.81,0.016
19.71,37.99,0.016
19.74,38.16,0.016
19.78,38.34,0.016
19.81,38.51,0.016
19.84,38.69,0.016
19.88,38.86,0.016
19.92,39.04,0.016
19.95,39.21,0.016
19.98,39.39,0.016
20.02,39.56,0.016
20.06,39.74,0.016
20.09,39.91,0.016
20.13,40.09,0.016
20.16,40.26,0.016
20.19,40.44,0.016
20.23,40.61,0.016
20.27,40.79,0.016
20.30,40.96,0.016
20.33,41.14,0.016
20.37,41.32,0.016
20.41,41.49,0.016
20.44,41.67,0.016
20.48,41.84,0.016
20.51,42.02,0.016
20.54,42.19,0.016
20.58,42.37,0.016
20.62,42.54,0.016
20.65,42.72,0.016
20.68,42.89,0.016
20.72,43.07,0.016
20.76,43.24,0.016
20.79,43.42,0.016
20.83,43.59,0.017
20.86,43.77,0.016
20.89,43.94,0.016
20.93,44.12,0.017
20.97,44.29,0.017
21.00,44.47,0.017
21.03,44.64,0.017
21.07,44.82,0.017
21.11,44.99,0.017
21.14,45.17,0.017
21.18,45.34,0.017
21.21,45.52,0.017
21.24,45.69,0.017
21.28,45.87,0.017
21.32,46.04,0.017
21.35,46.22,0.017
21.38,46.39,0.017
21.42,46.57,0.017
21.46,46.74,0.017
21.49,46.92,0.017
21.53,47.09,0.017
21.56,47.27,0.017
21.59,47.44,0.017
21.63,47.62,0.017
21.67,47.79,0.017
21.70,47.97,0.017
21.73,48.14,0.017
21.77,48.32,0.017
21.81,48.49,0.017
21.84,48.67,0.017
21.88,48.84,0.017
21.91,49.02,0.017
21.94,49.20,0.017
21.98,49.37,0.017
22.02,49.55,0.017
22.05,49.72,0.017
22.08,49.90,0.017
22.12,50.07,0.017
22.16,50.25,0.017
22.19,50.42,0.017
22.23,50.59,0.017
22.26,50.77,0.017
22.29,50.95,0.017
22.33,51.12,0.017
22.37,51.30,0.017
22.40,51.47,0.017
22.43,51.65,0.017
22.47,51.82,0.017
22.51,52.00,0.017
22.54,52.17,0.017
22.58,52.35,0.017
22.61,52.52,0.017
22.64,52.70,0.017
22.68,52.87,0.017
22.72,53.05,0.017
22.75,53.22,0.017
22.78,53.40,0.017
22.82,53.57,0.017
22.86,53.75,0.017
22.89,53.92,0.017
22.93,54.10,0.017
22.96,54.27,0.017
22.99,54.45,0.017
23.03,54.62,0.017
23.07,54.80,0.017
23.10,54.97,0.017
23.13,55.15,0.017
23.17,55.32,0.017
23.21,55.50,0.017
23.24,55.67,0.017
23.28,55.85,0.017
23.31,56.02,0.017
23.34,56.20,0.017
23.38,56.37,0.017
23.42,56.55,0.017
23.45,56.73,0.017
23.48,56.90,0.017
23.52,57.08,0.017
23.56,57.25,0.017
23.59,57.43,0.017
23.63,57.60,0.017
23.66,57.78,0.017
23.69,57.95,0.017
23.73,58.12,0.017
23.77,58.30,0.017
23.80,58.47,0.017
23.83,58.65,0.017
23.87,58.83,0.017
23.91,59.00,0.017
23.94,59.18,0.017
23.98,59.35,0.017
24.01,59.53,0.017
24.04,59.70,0.017
24.08,59.88,0.017
24.12,60.05,0.017
24.15,60.23,0.017
24.18,60.40,0.017
24.22,60.58,0.017
24.26,60.75,0.017
24.29,60.93,0.017
24.33,61.10,0.017
24.36,61.28,0.017
24.39,61.45,0.017
24.43,61.63,0.017
24.47,61.80,0.017
24.50,61.98,0.017
24.53,62.15,0.017
24.57,62.33,0.017
24.61,62.50,0.017
24.64,62.68,0.017
24.68,62.85,0.017
24.71,63.03,0.017
24.74,63.20,0.017
24.78,63.38,0.017
24.82,63.55,0.017
24.85,63.73,0.017
24.88,63.90,0.017
24.92,64.08,0.017
24.96,64.25,0.017
24.99,64.43,0.017
25.03,64.60,0.017
25.06,64.78,0.017
25.09,64.95,0.017
25.13,65.13,0.017
25.17,65.30,0.017
25.20,65.48,0.017
25.23,65.65,0.017
25.27,65.83,0.017
25.31,66.00,0.017
25.34,66.18,0.017
25.38,66.35,0.017
25.41,66.53,0.017
25.44,66.71,0.017
25.48,66.88,0.017
25.52,67.06,0.017
25.55,67.23,0.017
25.58,67.41,0.017
25.62,67.58,0.017
25.66,67.76,0.017
25.69,67.93,0.017
25.73,68.11,0.017
25.76,68.28,0.017
25.79,68.46,0.017
25.83,68.63,0.017
25.87,68.81,0.017
25.90,68.98,0.017
25.93,69.16,0.017
25.97,69.33,0.017
26.01,69.51,0.017
26.04,69.68,0.017
26.08,69.86,0.017
26.11,70.03,0.017
26.14,70.21,0.017
26.18,70.38,0.017
26.22,70.56,0.017
26.25,70.73,0.017
26.28,70.91,0.017
26.32,71.08,0.017
26.36,71.26,0.017
26.39,71.43,0.017
26.43,71.61,0.017
26.46,71.78,0.017
26.49,71.96,0.017
26.53,72.13,0.017
26.57,72.31,0.017
26.60,72.48,0.017
26.63,72.66,0.017
26.67,72.83,0.017
26.71,73.01,0.017
26.74,73.18,0.017
26.78,73.36,0.017
26.81,73.53,0.017
26.84,73.71,0.017
26.88,73.88,0.017
26.92,74.06,0.017
26.95,74.24,0.017
26.98,74.41,0.017
27.02,74.58,0.017
27.06,74.76,0.017
27.09,74.94,0.017
27.13,75.11,0.017
27.16,75.28,0.017
27.19,75.46,0.017
27.23,75.63,0.017
27.27,75.81,0.017
27.30,75.99,0.017
27.33,76.16,0.017
27.37,76.34,0.017
27.41,76.51,0.017
27.44,76.69,0.017
27.48,76.86,0.017
27.51,77.04,0.017
27.54,77.21,0.017
27.58,77.39,0.017
27.62,77.56,0.017
27.65,77.74,0.017
27.68,77.91,0.017
27.72,78.09,0.017
27.76,78.26,0.017
27.79,78.44,0.017
27.83,78.61,0.017
27.86,78.79,0.017
27.89,78.96,0.017
27.93,79.14,0.017
27.97,79.31,0.017
28.00,79.49,0.017
28.03,79.66,0.017
28.07,79.84,0.017
28.11,80.01,0.017
28.14,80.19,0.017
28.18,80.36,0.017
28.21,80.54,0.017
28.24,80.71,0.017
28.28,80.89,0.017
28.32,81.06,0.017
28.35,81.24,0.017
28.38,81.41,0.017
28.42,81.59,0.017
28.46,81.76,0.017
28.49,81.94,0.017
28.53,82.11,0.017
28.56,82.29,0.017
28.59,82.46,0.017
28.63,82.64,0.017
28.67,82.81,0.017
28.70,82.99,0.017
28.73,83.16,0.017
28.77,83.34,0.017
28.81,83.51,0.017
28.84,83.69,0.017
28.88,83.86,0.017
28.91,84.04,0.017
28.94,84.21,0.017
28.98,84.39,0.017
29.02,84.56,0.017
29.05,84.74,0.017
29.08,84.91,0.017
29.12,85.09,0.017
29.16,85.27,0.017
29.19,85.44,0.017
29.23,85.61,0.017
29.26,85.79,0.017
29.29,85.97,0.017
29.33,86.14,0.017
29.37,86.32,0.017
29.40,86.49,0.017
29.43,86.67,0.017
29.47,86.84,0.017
29.51,87.02,0.017
29.54,87.19,0.017
29.58,87.37,0.017
29.61,87.54,0.017
29.64,87.72,0.018
29.68,87.89,0.018
29.72,88.07,0.018
29.75,88.24,0.018
29.78,88.42,0.018
29.82,88.59,0.018
29.86,88.77,0.018
29.89,88.94,0.018
29.93,89.12,0.018
29.96,89.29,0.018
29.99,89.47,0.018
30.03,89.64,0.018
30.07,89.82,0.018
30.10,89.99,0.018
30.13,90.17,0.018
30.17,90.34,0.018
30.21,90.52,0.018
30.24,90.69,0.018
30.28,90.87,0.018
30.31,91.04,0.018
30.34,91.22,0.018
30.38,91.39,0.018
30.42,91.57,0.018
30.45,91.74,0.018
30.48,91.92,0.018
30.52,92.09,0.018
30.56,92.27,0.018
30.59,92.44,0.018
30.63,92.62,0.018
30.66,92.79,0.018
30.69,92.97,0.018
30.73,93.14,0.018
30.77,93.32,0.018
30.80,93.49,0.018
30.83,93.67,0.018
30.87,93.84,0.018
30.91,94.02,0.018
30.94,94.19,0.018
30.98,94.37,0.018
31.01,94.54,0.018
31.04,94.72,0.018
31.08,94.90,0.018
31.12,95.07,0.018
31.15,95.25,0.018
31.18,95.42,0.018
31.22,95.60,0.018
31.26,95.77,0.018
31.29,95.94,0.018
31.33,96.12,0.018
31.36,96.30,0.018
31.39,96.47,0.018
31.43,96.65,0.018
31.47,96.82,0.018
31.50,97.00,0.018
31.53,97.17,0.018
31.57,97.35,0.018
31.61,97.52,0.018
31.64,97.70,0.018
31.68,97.87,0.018
31.71,98.05,0.018
31.74,98.22,0.018
31.78,98.40,0.018
31.82,98.57,0.018
31.85,98.75,0.018
31.88,98.92,0.018
31.92,99.10,0.018
31.96,99.27,0.018
31.99,99.45,0.018
32.03,99.62,0.018
32.06,99.80,0.018
32.09,99.97,0.018
32.13,100.15,0.018
32.17,100.32,0.018
32.20,100.50,0.018
32.23,100.67,0.018
32.27,100.85,0.018
32.31,101.02,0.018
32.34,101.20,0.018
32.38,101.37,0.018
32.41,101.55,0.018
32.44,101.72,0.018
32.48,101.90,0.018
32.52,102.07,0.018
32.55,102.25,0.018
32.58,102.42,0.018
32.62,102.60,0.018
32.66,102.77,0.018
32.69,102.95,0.018
32.73,103.12,0.018
32.76,103.30,0.018
32.79,103.47,0.018
32.83,103.65,0.018
32.87,103.82,0.018
32.90,104.00,0.018
32.93,104.17,0.018
32.97,104.35,0.018
33.01,104.52,0.018
33.04,104.70,0.018
33.08,104.87,0.018
33.11,105.05,0.018
33.14,105.22,0.018
33.18,105.40,0.018
33.22,105.58,0.018
33.25,105.75,0.018
33.28,105.92,0.018
33.32,106.10,0.018
33.36,106.27,0.018
33.39,106.45,0.018
33.43,106.63,0.018
33.46,106.80,0.018
33.49,106.97,0.018
33.53,107.15,0.018
33.57,107.32,0.018
33.60,107.50,0.018
33.63,107.67,0.018
33.67,107.85,0.018
33.71,108.03,0.018
33.74,108.20,0.018
33.78,108.38,0.018
33.81,108.55,0.018
33.84,108.73,0.018
33.88,108.90,0.018
33.92,109.07,0.018
33.95,109.25,0.018
33.98,109.43,0.018
34.02,109.60,0.018
34.06,109.78,0.018
34.09,109.95,0.018
34.13,110.13,0.018
34.16,110.30,0.018
34.19,110.48,0.018
34.23,110.65,0.018
34.26,110.83,0.018
34.30,111.00,0.018
34.34,111.18,0.018
34.37,111.35,0.018
34.41,111.53,0.018
34.44,111.70,0.018
34.48,111.88,0.018
34.51,112.05,0.018
34.54,112.23,0.018
34.58,112.40,0.018
34.61,112.58,0.018
34.65,112.75,0.018
34.69,112.93,0.018
34.72,113.10,0.018
34.76,113.28,0.018
34.79,113.45,0.018
34.83,113.63,0.018
34.86,113.80,0.018
34.89,113.98,0.018
34.93,114.15,0.018
34.96,114.33,0.018
35.00,114.50,0.018
35.04,114.68,0.018
35.07,114.85,0.018
35.11,115.03,0.018
35.14,115.20,0.018
35.18,115.38,0.018
35.21,115.55,0.019
35.24,115.73,0.019
35.28,115.90,0.019
35.31,116.08,0.019
35.35,116.25,0.019
35.39,116.43,0.019
35.42,116.60,0.019
35.46,116.78,0.019
35.49,116.95,0.019
35.53,117.13,0.019
35.56,117.30,0.019
35.59,117.48,0.019
35.63,117.65,0.019
35.66,117.83,0.019
35.70,118.00,0.019
35.74,118.18,0.019
35.77,118.35,0.019
35.81,118.53,0.019
35.84,118.70,0.019
35.88,118.88,0.019
35.91,119.06,0.019
35.94,119.23,0.019
35.98,119.41,0.019
36.01,119.58,0.019
36.05,119.76,0.019
36.09,119.93,0.019
36.12,120.11,0.019
36.16,120.28,0.019
36.19,120.46,0.019
36.23,120.63,0.019
36.26,120.81,0.019
36.29,120.98,0.019
36.33,121.16,0.019
36.36,121.33,0.019
36.40,121.51,0.019
36.44,121.68,0.019
36.47,121.86,0.018
36.51,122.03,0.018
36.54,122.21,0.018
36.58,122.38,0.019
36.61,122.56,0.019
36.64,122.73,0.019
36.68,122.91,0.019
36.71,123.08,0.019
36.75,123.26,0.019
36.79,123.43,0.019
36.82,123.61,0.018
36.86,123.78,0.018
36.89,123.96,0.019
36.93,124.13,0.019
36.96,124.31,0.019
36.99,124.48,0.019
37.03,124.66,0.019
37.06,124.83,0.019
37.10,125.01,0.019
37.14,125.18,0.019
37.17,125.36,0.019
37.21,125.53,0.019
37.24,125.71,0.019
37.28,125.88,0.019
37.31,126.06,0.019
37.34,126.23,0.019
37.38,126.41,0.019
37.41,126.58,0.019
37.45,126.76,0.019
37.49,126.93,0.019
37.52,127.11,0.019
37.56,127.28,0.019
37.59,127.46,0.019
37.63,127.63,0.019
37.66,127.81,0.019
37.69,127.98,0.019
37.73,128.16,0.019
37.76,128.33,0.019
37.80,128.51,0.019
37.84,128.68,0.019
37.87,128.86,0.019
37.91,129.03,0.019
37.94,129.21,0.019
37.98,129.38,0.019
38.01,129.56,0.019
38.04,129.73,0.019
38.08,129.91,0.019
38.11,130.08,0.019
38.15,130.26,0.019
38.19,130.43,0.019
38.22,130.61,0.019
38.26,130.78,0.019
38.29,130.96,0.019
38.33,131.13,0.019
38.36,131.31,0.019
38.39,131.48,0.019
38.43,131.66,0.019
38.46,131.83,0.019
38.50,132.01,0.019
38.54,132.19,0.019
38.57,132.36,0.019
38.61,132.53,0.019
38.64,132.71,0.019
38.68,132.89,0.019
38.71,133.06,0.019
38.74,133.23,0.019
38.78,133.41,0.019
38.81,133.58,0.019
38.85,133.76,0.019
38.89,133.93,0.019
38.92,134.11,0.019
38.96,134.28,0.019
38.99,134.46,0.019
39.03,134.63,0.019
39.06,134.81,0.019
39.09,134.98,0.019
39.13,135.16,0.019
39.16,135.33,0.019
39.20,135.51,0.019
39.24,135.68,0.019
39.27,135.86,0.019
39.31,136.04,0.019
39.34,136.21,0.019
39.38,136.38,0.019
39.41,136.56,0.019
39.44,136.74,0.019
39.48,136.91,0.019
39.51,137.08,0.019
39.55,137.26,0.019
39.59,137.43,0.019
39.62,137.61,0.019
39.66,137.79,0.019
39.69,137.96,0.019
39.73,138.14,0.019
39.76,138.31,0.019
39.79,138.49,0.019
39.83,138.66,0.019
39.86,138.83,0.019
39.90,139.01,0.019
39.94,139.19,0.019
39.97,139.36,0.019
40.01,139.54,0.019
40.04,139.71,0.019
40.08,139.89,0.019
40.11,140.06,0.019
40.14,140.24,0.019
40.18,140.41,0.019
40.21,140.59,0.019
40.25,140.76,0.019
40.29,140.93,0.019
40.32,141.11,0.019
40.36,141.29,0.019
40.39,141.46,0.019
40.43,141.64,0.019
40.46,141.81,0.019
40.49,141.99,0.019
40.53,142.16,0.019
40.56,142.34,0.019
40.60,142.51,0.019
40.64,142.68,0.019
40.67,142.86,0.019
40.71,143.04,0.019
40.74,143.21,0.019
40.78,143.39,0.019
40.81,143.56,0.019
40.84,143.74,0.019
40.88,143.91,0.019
40.91,144.09,0.019
40.95,144.26,0.019
40.99,144.44,0.019
41.02,144.61,0.019
41.06,144.79,0.019
41.09,144.96,0.019
41.13,145.14,0.019
41.16,145.31,0.019
41.19,145.49,0.019
41.23,145.66,0.019
41.26,145.84,0.019
41.30,146.01,0.019
41.34,146.19,0.019
41.37,146.36,0.019
41.41,146.54,0.019
41.44,146.71,0.019
41.48,146.89,0.019
41.51,147.06,0.019
41.54,147.24,0.019
41.58,147.41,0.019
41.61,147.59,0.019
41.65,147.76,0.019
41.69,147.94,0.019
41.72,148.11,0.019
41.76,148.29,0.019
41.79,148.46,0.019
41.83,148.64,0.019
41.86,148.81,0.019
41.89,148.99,0.019
41.93,149.16,0.019
41.96,149.34,0.019
42.00,149.51,0.019
42.04,149.69,0.019
42.07,149.86,0.019
42.11,150.04,0.019
42.14,150.21,0.019
42.18,150.39,0.019
42.21,150.56,0.019
42.24,150.74,0.019
42.28,150.91,0.019
42.31,151.09,0.019
42.35,151.26,0.019
42.39,151.44,0.019
42.42,151.61,0.019
42.46,151.79,0.019
42.49,151.96,0.019
42.53,152.14,0.019
42.56,152.31,0.019
42.59,152.49,0.019
42.63,152.66,0.019
42.66,152.84,0.020
42.70,153.01,0.020
42.74,153.19,0.020
42.77,153.36,0.020
42.81,153.54,0.020
42.84,153.71,0.020
42.88,153.89,0.020
42.91,154.06,0.020
42.94,154.24,0.020
42.98,154.41,0.020
43.01,154.59,0.020
43.05,154.76,0.020
43.09,154.94,0.020
43.12,155.11,0.020
43.16,155.29,0.020
43.19,155.46,0.020
43.23,155.64,0.020
43.26,155.81,0.020
43.29,155.99,0.020
43.33,156.16,0.020
43.36,156.34,0.020
43.40,156.51,0.021
43.44,156.68,0.029
43.47,156.84,0.065
43.51,156.98,0.125
43.54,157.09,0.179
43.58,157.21,0.229
43.61,157.32,0.280
43.64,157.43,0.333
43.68,157.54,0.394
43.71,157.64,0.457
43.75,157.75,0.510
43.79,157.85,0.559
43.82,157.97,0.611
43.86,158.08,0.658
43.89,158.21,0.661
43.93,158.35,0.693
43.96,158.49,0.731
43.99,158.62,0.768
44.03,158.75,0.802
44.06,158.89,0.813
44.10,159.05,0.823
44.14,159.22,0.777
44.17,159.43,0.738
44.21,159.64,0.682
44.24,159.94,0.522
44.28,160.21,0.483
44.31,160.46,0.451
44.34,160.77,0.220
44.38,161.10,0.138
44.41,161.38,0.097
44.45,161.63,0.071
44.49,161.85,0.054
44.52,162.05,0.042
44.56,162.25,0.034
44.59,162.44,0.030
44.63,162.62,0.026
44.66,162.80,0.024
44.69,162.98,0.023
44.73,163.16,0.022
44.76,163.34,0.021
44.80,163.51,0.021
44.84,163.69,0.021
44.87,163.86,0.021
44.91,164.04,0.021
44.94,164.22,0.020
44.98,164.39,0.020
45.01,164.57,0.020
45.04,164.74,0.020
45.08,164.92,0.020
45.11,165.09,0.020
45.15,165.27,0.020
45.19,165.44,0.020
45.22,165.62,0.020
45.26,165.79,0.020
45.29,165.97,0.020
45.33,166.14,0.020
45.36,166.32,0.020
45.39,166.49,0.020
45.43,166.67,0.020
45.46,166.84,0.020
45.50,167.02,0.020
45.54,167.19,0.020
45.57,167.37,0.020
45.61,167.54,0.020
45.64,167.72,0.020
45.68,167.89,0.020
45.71,168.07,0.020
45.74,168.24,0.020
45.78,168.42,0.020
45.81,168.59,0.020
45.85,168.77,0.020
45.89,168.94,0.020
45.92,169.12,0.020
45.96,169.29,0.020
45.99,169.47,0.020
46.03,169.64,0.020
46.06,169.81,0.020
46.09,169.99,0.020
46.13,170.17,0.020
46.16,170.34,0.020
46.20,170.52,0.020
46.24,170.69,0.020
46.27,170.87,0.020
46.31,171.04,0.020
46.34,171.22,0.020
46.38,171.39,0.020
46.41,171.57,0.020
46.44,171.74,0.020
46.48,171.92,0.020
46.51,172.09,0.020
46.55,172.27,0.020
46.59,172.44,0.020
46.62,172.62,0.020
46.66,172.79,0.020
46.69,172.97,0.020
46.73,173.14,0.020
46.76,173.32,0.020
46.79,173.49,0.020
46.83,173.67,0.020
46.86,173.84,0.020
46.90,174.02,0.020
46.94,174.19,0.020
46.97,174.37,0.020
47.01,174.54,0.020
47.04,174.72,0.020
47.08,174.89,0.020
47.11,175.07,0.020
47.14,175.24,0.020
47.18,175.42,0.020
47.21,175.59,0.020
47.25,175.77,0.020
47.29,175.94,0.020
47.32,176.12,0.020
47.36,176.29,0.020
47.39,176.47,0.020
47.43,176.64,0.020
47.46,176.82,0.020
47.49,176.99,0.020
47.53,177.17,0.020
47.56,177.34,0.020
47.60,177.52,0.020
47.64,177.69,0.020
47.67,177.87,0.020
47.71,178.04,0.020
47.74,178.22,0.020
47.78,178.39,0.020
47.81,178.57,0.020
47.84,178.74,0.020
47.88,178.92,0.020
47.91,179.09,0.020
47.95,179.27,0.020
47.99,179.44,0.020
48.02,179.62,0.020
48.06,179.79,0.020
48.09,179.97,0.020
48.13,180.14,0.020
48.16,180.32,0.020
48.19,180.49,0.020
48.23,180.67,0.020
48.26,180.85,0.020
48.30,181.02,0.020
48.34,181.19,0.020
48.37,181.37,0.020
48.41,181.54,0.020
48.44,181.72,0.020
48.48,181.89,0.020
48.51,182.07,0.020
48.54,182.24,0.020
48.58,182.42,0.020
48.61,182.59,0.020
48.65,182.77,0.020
48.69,182.94,0.020
48.72,183.12,0.020
48.76,183.29,0.020
48.79,183.47,0.020
48.83,183.64,0.020
48.86,183.82,0.020
48.89,183.99,0.020
48.93,184.17,0.020
48.96,184.34,0.020
49.00,184.52,0.020
49.04,184.69,0.020
49.07,184.87,0.020
49.11,185.04,0.020
49.14,185.22,0.020
49.18,185.39,0.020
49.21,185.57,0.020
49.24,185.74,0.020
49.28,185.92,0.020
49.31,186.10,0.020
49.35,186.27,0.020
49.39,186.45,0.020
49.42,186.62,0.020
49.46,186.80,0.020
49.49,186.97,0.020
49.53,187.14,0.020
49.56,187.32,0.020
49.59,187.49,0.020
49.63,187.67,0.020
49.66,187.84,0.020
49.70,188.02,0.020
49.74,188.19,0.020
49.77,188.37,0.020
49.81,188.54,0.020
49.84,188.72,0.020
49.88,188.89,0.020
49.91,189.07,0.020
49.94,189.25,0.020
49.98,189.42,0.020
50.01,189.60,0.020
50.05,189.77,0.020
50.09,189.94,0.020
50.12,190.12,0.020
50.16,190.29,0.020
50.19,190.47,0.020
50.23,190.64,0.020
50.26,190.82,0.020
50.29,190.99,0.020
50.33,191.17,0.020
50.36,191.34,0.020
50.40,191.52,0.020
50.44,191.69,0.020
50.47,191.87,0.020
50.51,192.04,0.020
50.54,192.22,0.020
50.58,192.39,0.020
50.61,192.57,0.020
50.64,192.75,0.020
50.68,192.92,0.020
50.71,193.10,0.020
50.75,193.27,0.020
50.79,193.45,0.020
50.82,193.62,0.020
50.86,193.79,0.020
50.89,193.97,0.020
50.93,194.14,0.020
50.96,194.32,0.020
50.99,194.49,0.020
51.03,194.67,0.020
51.06,194.84,0.020
51.10,195.02,0.020
51.14,195.19,0.020
51.17,195.37,0.020
51.21,195.54,0.020
51.24,195.72,0.020
51.28,195.89,0.020
51.31,196.07,0.020
51.34,196.24,0.020
51.38,196.42,0.020
51.41,196.59,0.020
51.45,196.77,0.020
51.49,196.95,0.020
51.52,197.12,0.020
51.56,197.30,0.020
51.59,197.47,0.020
51.63,197.65,0.020
51.66,197.82,0.020
51.69,198.00,0.020
51.73,198.17,0.020
51.76,198.35,0.020
51.80,198.52,0.020
51.84,198.69,0.020
51.87,198.87,0.020
51.91,199.04,0.020
51.94,199.22,
51.98,199.39,
51.99,,

[step]
Ramp 10.00 °C/min to -60.00 °C
Time,Temperature,Heat Flow (Normalized)
min,°C,W/g
52.09,199.90,0.019
52.11,199.95,0.017
52.12,200.00,0.014
52.14,200.03,0.011
52.16,200.04,0.007
52.18,200.03,0.003
52.20,200.00,-0.003
52.21,199.94,-0.009
52.23,199.85,-0.017
52.25,199.75,-0.024
52.27,199.62,-0.031
52.29,199.49,-0.037
52.31,199.34,-0.042
52.33,199.19,-0.046
52.34,199.04,-0.049
52.36,198.87,-0.052
52.38,198.71,-0.054
52.40,198.54,-0.056
52.42,198.37,-0.057
52.44,198.20,-0.058
52.45,198.03,-0.059
52.47,197.85,-0.060
52.49,197.68,-0.060
52.51,197.50,-0.061
52.53,197.32,-0.061
52.54,197.14,-0.062
52.56,196.97,-0.062
52.58,196.79,-0.062
52.60,196.61,-0.062
52.62,196.43,-0.062
52.64,196.25,-0.063
52.66,196.07,-0.063
52.67,195.89,-0.063
52.69,195.71,-0.063
52.71,195.53,-0.063
52.73,195.35,-0.063
52.75,195.17,-0.063
52.76,194.99,-0.063
52.78,194.81,-0.063
52.80,194.63,-0.063
52.82,194.45,-0.063
52.84,194.26,-0.063
52.86,194.08,-0.063
52.88,193.90,-0.063
52.89,193.72,-0.064
52.91,193.54,-0.064
52.93,193.36,-0.064
52.95,193.18,-0.064
52.97,192.99,-0.064
52.99,192.81,-0.064
53.00,192.63,-0.064
53.02,192.45,-0.064
53.04,192.27,-0.064
53.06,192.08,-0.064
53.08,191.90,-0.064
53.09,191.72,-0.064
53.11,191.54,-0.064
53.13,191.36,-0.064
53.15,191.17,-0.064
53.17,190.99,-0.064
53.19,190.81,-0.064
53.21,190.63,-0.064
53.22,190.45,-0.064
53.24,190.26,-0.064
53.26,190.08,-0.064
53.28,189.90,-0.064
53.30,189.72,-0.064
53.31,189.53,-0.064
53.33,189.35,-0.064
53.35,189.17,-0.064
53.37,188.99,-0.064
53.39,188.80,-0.064
53.41,188.62,-0.064
53.43,188.44,-0.064
53.44,188.26,-0.064
53.46,188.07,-0.064
53.48,187.89,-0.064
53.50,187.71,-0.064
53.52,187.52,-0.064
53.54,187.34,-0.064
53.55,187.16,-0.064
53.57,186.98,-0.064
53.59,186.79,-0.064
53.61,186.61,-0.064
53.63,186.43,-0.064
53.64,186.25,-0.064
53.66,186.06,-0.064
53.68,185.88,-0.064
53.70,185.70,-0.064
53.72,185.51,-0.064
53.74,185.33,-0.064
53.76,185.15,-0.064
53.77,184.97,-0.064
53.79,184.78,-0.064
53.81,184.60,-0.064
53.83,184.42,-0.064
53.85,184.23,-0.064
53.86,184.05,-0.064
53.88,183.87,-0.064
53.90,183.68,-0.064
53.92,183.50,-0.064
53.94,183.32,-0.064
53.96,183.13,-0.064
53.98,182.95,-0.064
53.99,182.77,-0.064
54.01,182.59,-0.064
54.03,182.40,-0.064
54.05,182.22,-0.064
54.07,182.04,-0.064
54.09,181.86,-0.064
54.10,181.67,-0.064
54.12,181.49,-0.064
54.14,181.31,-0.064
54.16,181.12,-0.064
54.18,180.94,-0.064
54.19,180.76,-0.064
54.21,180.57,-0.064
54.23,180.39,-0.064
54.25,180.21,-0.064
54.27,180.02,-0.064
54.29,179.84,-0.064
54.31,179.66,-0.064
54.32,179.47,-0.064
54.34,179.29,-0.064
54.36,179.11,-0.064
54.38,178.93,-0.064
54.40,178.74,-0.064
54.41,178.56,-0.064
54.43,178.38,-0.064
54.45,178.19,-0.064
54.47,178.01,-0.064
54.49,177.83,-0.064
54.51,177.64,-0.064
54.53,177.46,-0.064
54.54,177.28,-0.064
54.56,177.10,-0.064
54.58,176.91,-0.064
54.60,176.73,-0.064
54.62,176.55,-0.064
54.64,176.36,-0.064
54.65,176.18,-0.064
54.67,176.00,-0.064
54.69,175.81,-0.064
54.71,175.63,-0.064
54.73,175.45,-0.064
54.74,175.26,-0.064
54.76,175.08,-0.064
54.78,174.90,-0.064
54.80,174.71,-0.064
54.82,174.53,-0.064
54.84,174.35,-0.064
54.86,174.17,-0.064
54.87,173.98,-0.064
54.89,173.80,-0.064
54.91,173.62,-0.064
54.93,173.43,-0.064
54.95,173.25,-0.064
54.96,173.07,-0.064
54.98,172.88,-0.064
55.00,172.70,-0.064
55.02,172.52,-0.064
55.04,172.33,-0.064
55.06,172.15,-0.064
55.08,171.97,-0.064
55.09,171.78,-0.064
55.11,171.60,-0.064
55.13,171.42,-0.064
55.15,171.24,-0.064
55.17,171.05,-0.064
55.19,170.87,-0.064
55.20,170.69,-0.064
55.22,170.50,-0.064
55.24,170.32,-0.063
55.26,170.14,-0.063
55.28,169.95,-0.063
55.29,169.77,-0.063
55.31,169.59,-0.063
55.33,169.40,-0.063
55.35,169.22,-0.063
55.37,169.04,-0.063
55.39,168.86,-0.063
55.41,168.67,-0.063
55.42,168.49,-0.063
55.44,168.31,-0.063
55.46,168.12,-0.063
55.48,167.94,-0.063
55.50,167.76,-0.063
55.51,167.57,-0.063
55.53,167.39,-0.063
55.55,167.21,-0.063
55.57,167.03,-0.063
55.59,166.84,-0.063
55.61,166.66,-0.063
55.63,166.48,-0.063
55.64,166.29,-0.063
55.66,166.11,-0.063
55.68,165.93,-0.063
55.70,165.74,-0.063
55.72,165.56,-0.063
55.74,165.38,-0.063
55.75,165.19,-0.063
55.77,165.01,-0.063
55.79,164.83,-0.063
55.81,164.64,-0.063
55.83,164.46,-0.063
55.84,164.28,-0.063
55.86,164.09,-0.063
55.88,163.91,-0.063
55.90,163.73,-0.063
55.92,163.55,-0.063
55.94,163.36,-0.063
55.96,163.18,-0.063
55.97,163.00,-0.063
55.99,162.81,-0.063
56.01,162.63,-0.063
56.03,162.45,-0.063
56.05,162.26,-0.063
56.06,162.08,-0.063
56.08,161.90,-0.063
56.10,161.71,-0.063
56.12,161.53,-0.063
56.14,161.35,-0.063
56.16,161.17,-0.063
56.18,160.98,-0.063
56.19,160.80,-0.063
56.21,160.62,-0.063
56.23,160.43,-0.063
56.25,160.25,-0.063
56.27,160.07,-0.063
56.29,159.88,-0.063
56.30,159.70,-0.063
56.32,159.52,-0.063
56.34,159.33,-0.063
56.36,159.15,-0.063
56.38,158.97,-0.063
56.39,158.78,-0.063
56.41,158.60,-0.063
56.43,158.42,-0.063
56.45,158.23,-0.063
56.47,158.05,-0.063
56.49,157.87,-0.063
56.51,157.69,-0.063
56.52,157.50,-0.063
56.54,157.32,-0.063
56.56,157.14,-0.063
56.58,156.95,-0.063
56.60,156.77,-0.063
56.61,156.59,-0.063
56.63,156.41,-0.063
56.65,156.22,-0.063
56.67,156.04,-0.063
56.69,155.86,-0.063
56.71,155.67,-0.063
56.73,155.49,-0.063
56.74,155.31,-0.063
56.76,155.12,-0.063
56.78,154.94,-0.063
56.80,154.76,-0.063
56.82,154.57,-0.063
56.84,154.39,-0.063
56.85,154.21,-0.074
56.87,154.11,-0.642
56.89,154.16,-0.920
56.91,154.17,-0.973
56.93,154.15,-0.997
56.94,154.10,-1.042
56.96,154.02,-1.080
56.98,153.93,-1.118
57.00,153.83,-1.154
57.02,153.72,-1.154
57.04,153.59,-1.174
57.06,153.45,-1.213
57.07,153.32,-1.254
57.09,153.19,-1.294
57.11,153.05,-1.332
57.13,152.92,-1.349
57.15,152.77,-1.372
57.16,152.63,-1.377
57.18,152.45,-1.283
57.20,152.26,-1.290
57.22,152.07,-1.168
57.24,151.80,-0.928
57.26,151.51,-0.888
57.28,151.25,-0.854
57.29,150.94,-0.480
57.31,150.56,-0.272
57.33,150.20,-0.209
57.35,149.87,-0.177
57.37,149.57,-0.155
57.39,149.29,-0.137
57.40,149.03,-0.122
57.42,148.78,-0.111
57.44,148.55,-0.101
57.46,148.33,-0.094
57.48,148.11,-0.088
57.49,147.90,-0.083
57.51,147.70,-0.079
57.53,147.50,-0.076
57.55,147.30,-0.073
57.57,147.11,-0.071
57.59,146.92,-0.070
57.61,146.73,-0.069
57.62,146.54,-0.067
57.64,146.35,-0.066
57.66,146.16,-0.066
57.68,145.98,-0.065
57.70,145.79,-0.065
57.71,145.61,-0.065
57.73,145.42,-0.064
57.75,145.24,-0.064
57.77,145.05,-0.064
57.79,144.87,-0.064
57.81,144.69,-0.064
57.83,144.50,-0.064
57.84,144.32,-0.063
57.86,144.14,-0.063
57.88,143.95,-0.063
57.90,143.77,-0.063
57.92,143.59,-0.063
57.94,143.40,-0.063
57.95,143.22,-0.063
57.97,143.04,-0.063
57.99,142.85,-0.063
58.01,142.67,-0.063
58.03,142.49,-0.063
58.04,142.30,-0.063
[...]
162.38,-39.84,0.018
162.39,-39.77,0.019
162.40,-39.71,0.019
162.42,-39.64,0.019
162.43,-39.57,0.019
162.45,-39.51,0.018
162.46,-39.44,0.019
162.47,-39.37,0.018
162.48,-39.30,0.018
162.50,-39.24,0.018
162.51,-39.17,0.018
162.53,-39.11,0.018
162.54,-39.04,0.018
162.55,-38.97,0.018
162.57,-38.90,0.018
162.58,-38.84,0.018
162.59,-38.77,0.018
162.60,-38.70,0.018
162.62,-38.64,0.018
162.63,-38.57,0.018
162.65,-38.50,0.018
162.66,-38.44,0.018
162.67,-38.37,0.018
162.68,-38.30,0.018
162.70,-38.24,0.018
162.71,-38.17,0.018
162.73,-38.10,0.018
162.74,-38.04,0.018
162.75,-37.97,0.018
162.77,-37.90,0.018
162.78,-37.84,0.018
162.79,-37.77,0.018
162.80,-37.70,0.018
162.82,-37.64,0.018
162.83,-37.57,0.018
162.85,-37.50,0.018
162.86,-37.44,0.018
162.87,-37.37,0.018
162.88,-37.30,0.018
162.90,-37.24,0.018
162.91,-37.17,0.018
162.93,-37.10,0.018
162.94,-37.03,0.018
162.95,-36.97,0.018
162.97,-36.90,0.018
162.98,-36.83,0.018
162.99,-36.77,0.018
163.00,-36.70,0.018
163.02,-36.63,0.018
163.03,-36.57,0.018
163.05,-36.50,0.018
163.06,-36.43,0.018
163.07,-36.37,0.018
163.08,-36.30,0.018
163.10,-36.24,0.018
163.11,-36.17,0.018
163.13,-36.10,0.018
163.14,-36.03,0.018
163.15,-35.97,0.018
163.17,-35.90,0.018
163.18,-35.83,0.018
163.19,-35.77,0.018
163.20,-35.70,0.018
163.22,-35.63,0.018
163.23,-35.57,0.018
163.25,-35.50,0.018
163.26,-35.43,0.018
163.27,-35.37,0.018
163.28,-35.30,0.018
163.30,-35.23,0.018
163.31,-35.17,0.018
163.33,-35.10,0.018
163.34,-35.03,0.018
163.35,-34.97,0.018
163.37,-34.90,0.018
163.38,-34.83,0.018
163.39,-34.77,0.018
163.40,-34.70,0.018
163.42,-34.63,0.018
163.43,-34.57,0.018
163.45,-34.50,0.018
163.46,-34.43,0.018
163.47,-34.36,0.018
163.48,-34.30,0.018
163.50,-34.23,0.018
163.51,-34.17,0.018
163.53,-34.10,0.018
163.54,-34.03,0.018
163.55,-33.96,0.018
163.57,-33.90,0.018
163.58,-33.83,0.018
163.59,-33.76,0.018
163.60,-33.70,0.018
163.62,-33.63,0.018
163.63,-33.57,0.018
163.65,-33.50,0.018
163.66,-33.43,0.018
163.67,-33.36,0.018
163.68,-33.30,0.018
163.70,-33.23,0.018
163.71,-33.16,0.018
163.73,-33.10,0.018
163.74,-33.03,0.018
163.75,-32.96,0.018
163.77,-32.90,0.018
163.78,-32.83,0.018
163.79,-32.76,0.018
163.80,-32.70,0.018
163.82,-32.63,0.018
163.83,-32.56,0.018
163.85,-32.50,0.018
163.86,-32.43,0.018
163.87,-32.36,0.018
163.88,-32.30,0.018
163.90,-32.23,0.018
163.91,-32.16,0.018
163.93,-32.10,0.018
163.94,-32.03,0.018
163.95,-31.96,0.018
163.97,-31.90,0.018
163.98,-31.83,0.018
163.99,-31.76,0.018
164.00,-31.69,0.018
164.02,-31.63,0.018
164.03,-31.56,0.018
164.05,-31.50,0.018
164.06,-31.43,0.018
164.07,-31.36,0.018
164.08,-31.30,0.018
164.10,-31.23,0.018
164.11,-31.16,0.018
164.13,-31.09,0.018
164.14,-31.03,0.018
164.15,-30.96,0.018
164.17,-30.89,0.018
164.18,-30.83,0.018
164.19,-30.76,0.018
164.20,-30.69,0.018
164.22,-30.63,0.018
164.23,-30.56,0.018
164.25,-30.49,0.018
164.26,-30.43,0.018
164.27,-30.36,0.018
164.28,-30.29,0.018
164.30,-30.23,0.018
164.31,-30.16,0.018
164.33,-30.09,0.018
164.34,-30.03,0.018
164.35,-29.96,0.018
164.37,-29.89,0.018
164.38,-29.83,0.018
164.39,-29.76,0.018
164.40,-29.69,0.018
164.42,-29.63,0.018
164.43,-29.56,0.018
164.45,-29.49,0.018
164.46,-29.43,0.018
164.47,-29.36,0.018
164.48,-29.29,0.018
164.50,-29.23,0.018
164.51,-29.16,0.018
164.53,-29.09,0.018
164.54,-29.03,0.018
164.55,-28.96,0.018
164.57,-28.89,0.018
164.58,-28.83,0.018
164.59,-28.76,0.018
164.60,-28.69,0.018
164.62,-28.63,0.018
164.63,-28.56,0.018
164.65,-28.49,0.018
164.66,-28.43,0.018
164.67,-28.36,0.018
164.68,-28.29,0.018
164.70,-28.23,0.018
164.71,-28.16,0.018
164.73,-28.09,0.018
164.74,-28.02,0.018
164.75,-27.96,0.018
164.77,-27.89,0.018
164.78,-27.82,0.018
164.79,-27.76,0.018
164.80,-27.69,0.018
164.82,-27.62,0.018
164.83,-27.56,0.018
164.85,-27.49,0.018
164.86,-27.42,0.018
164.87,-27.36,0.018
164.88,-27.29,0.018
164.90,-27.22,0.018
164.91,-27.16,0.018
164.93,-27.09,0.018
164.94,-27.02,0.018
164.95,-26.96,0.018
164.97,-26.89,0.018
164.98,-26.82,0.018
164.99,-26.76,0.018
165.00,-26.69,0.018
165.02,-26.62,0.018
165.03,-26.56,0.018
165.05,-26.49,0.018
165.06,-26.42,0.018
165.07,-26.36,0.018
165.08,-26.29,0.018
165.10,-26.22,0.018
165.11,-26.16,0.018
165.13,-26.09,0.018
165.14,-26.02,0.018
165.15,-25.96,0.018
165.17,-25.89,0.018
165.18,-25.82,0.018
165.19,-25.76,0.018
165.20,-25.69,0.018
165.22,-25.62,0.018
165.23,-25.56,0.018
165.25,-25.49,0.018
165.26,-25.42,0.018
165.27,-25.36,0.018
165.28,-25.29,0.018
165.30,-25.22,0.018
165.31,-25.16,0.018
165.33,-25.09,0.018
165.34,-25.02,0.018
165.35,-24.96,0.018
165.37,-24.89,0.018
165.38,-24.82,0.018
165.39,-24.76,0.018
165.40,-24.69,0.018
165.42,-24.62,0.018
165.43,-24.56,0.018
165.45,-24.49,0.018
165.46,-24.42,0.018
165.47,-24.35,0.018
165.48,-24.29,0.018
165.50,-24.22,0.018
165.51,-24.16,0.018
165.53,-24.09,0.018
165.54,-24.02,0.018
165.55,-23.95,0.018
165.57,-23.89,0.018
165.58,-23.82,0.018
165.59,-23.75,0.018
165.60,-23.69,0.018
165.62,-23.62,0.018
165.63,-23.56,0.018
165.65,-23.49,0.018
165.66,-23.42,0.018
165.67,-23.35,0.018
165.68,-23.29,0.018
165.70,-23.22,0.018
165.71,-23.15,0.018
165.73,-23.09,0.018
165.74,-23.02,0.018
165.75,-22.95,0.018
165.77,-22.89,0.018
165.78,-22.82,0.018
165.79,-22.75,0.018
165.80,-22.69,0.018
165.82,-22.62,0.018
165.83,-22.55,0.018
165.85,-22.49,0.018
165.86,-22.42,0.018
165.87,-22.35,0.018
165.88,-22.29,0.018
165.90,-22.22,0.018
165.91,-22.15,0.018
165.93,-22.09,0.018
165.94,-22.02,0.018
165.95,-21.95,0.018
165.97,-21.89,0.018
165.98,-21.82,0.018
165.99,-21.75,0.018
166.00,-21.69,0.018
166.02,-21.62,0.018
166.03,-21.55,0.018
166.05,-21.49,0.018
166.06,-21.42,0.018
166.07,-21.35,0.018
166.08,-21.29,0.018
166.10,-21.22,0.018
166.11,-21.15,0.018
166.13,-21.09,0.018
166.14,-21.02,0.018
166.15,-20.95,0.018
166.17,-20.89,0.018
166.18,-20.82,0.018
166.19,-20.75,0.018
166.20,-20.69,0.018
166.22,-20.62,0.018
166.23,-20.55,0.018
166.25,-20.49,0.018
166.26,-20.42,0.018
166.27,-20.35,0.018
166.28,-20.29,0.018
166.30,-20.22,0.018
166.31,-20.15,0.018
166.33,-20.09,0.018
166.34,-20.02,0.018
166.35,-19.95,0.018
166.37,-19.88,0.018
166.38,-19.82,0.018
166.39,-19.75,0.018
166.40,-19.69,0.018
166.42,-19.62,0.018
166.43,-19.55,0.018
166.45,-19.48,0.018
166.46,-19.42,0.018
166.47,-19.35,0.018
166.48,-19.28,0.018
166.50,-19.22,0.018
166.51,-19.15,0.018
166.53,-19.08,0.018
166.54,-19.02,0.018
166.55,-18.95,0.018
166.57,-18.88,0.018
166.58,-18.82,0.018
166.59,-18.75,0.018
166.60,-18.68,0.018
166.62,-18.62,0.018
166.63,-18.55,0.018
166.65,-18.48,0.018
166.66,-18.42,0.018
166.67,-18.35,0.018
166.68,-18.28,0.018
166.70,-18.22,0.018
166.71,-18.15,0.018
166.73,-18.08,0.018
166.74,-18.02,0.018
166.75,-17.95,0.018
166.77,-17.88,0.018
166.78,-17.82,0.018
166.79,-17.75,0.018
166.80,-17.68,0.018
166.82,-17.62,0.018
166.83,-17.55,0.018
166.85,-17.48,0.018
166.86,-17.42,0.018
166.87,-17.35,0.018
166.88,-17.28,0.018
166.90,-17.22,0.018
166.91,-17.15,0.018
166.93,-17.08,0.018
166.94,-17.02,0.018
166.95,-16.95,0.018
166.97,-16.88,0.018
166.98,-16.82,0.018
166.99,-16.75,0.018
167.00,-16.68,0.018
167.02,-16.61,0.018
167.03,-16.55,0.018
167.05,-16.48,0.018
167.06,-16.42,0.018
167.07,-16.35,0.018
167.08,-16.28,0.018
167.10,-16.22,0.018
167.11,-16.15,0.018
167.13,-16.08,0.018
167.14,-16.01,0.018
167.15,-15.95,0.018
167.17,-15.88,0.018
167.18,-15.82,0.018
167.19,-15.75,0.018
167.20,-15.68,0.018
167.22,-15.62,0.018
167.23,-15.55,0.018
167.25,-15.48,0.018
167.26,-15.41,0.018
167.27,-15.35,0.018
167.28,-15.28,0.018
167.30,-15.21,0.018
167.31,-15.15,0.018
167.33,-15.08,0.018
167.34,-15.01,0.018
167.35,-14.95,0.018
167.37,-14.88,0.018
167.38,-14.81,0.018
167.39,-14.75,0.018
167.40,-14.68,0.018
167.42,-14.61,0.018
167.43,-14.55,0.018
167.45,-14.48,0.018
167.46,-14.41,0.018
167.47,-14.35,0.018
167.48,-14.28,0.018
167.50,-14.21,0.018
167.51,-14.15,0.018
167.53,-14.08,0.018
167.54,-14.01,0.018
167.55,-13.95,0.018
167.57,-13.88,0.018
167.58,-13.81,0.018
167.59,-13.75,0.018
167.60,-13.68,0.018
167.62,-13.61,0.018
167.63,-13.55,0.018
167.65,-13.48,0.018
167.66,-13.41,0.018
167.67,-13.35,0.018
167.68,-13.28,0.018
167.70,-13.21,0.018
167.71,-13.15,0.018
167.73,-13.08,0.018
167.74,-13.01,0.018
167.75,-12.95,0.018
167.77,-12.88,0.018
167.78,-12.81,0.018
167.79,-12.75,0.018
167.80,-12.68,0.018
167.82,-12.61,0.018
167.83,-12.54,0.018
167.85,-12.48,0.018
167.86,-12.41,0.018
167.87,-12.34,0.018
167.88,-12.28,0.018
167.90,-12.21,0.018
167.91,-12.15,0.018
167.93,-12.08,0.018
167.94,-12.01,0.018
167.95,-11.95,0.018
167.97,-11.88,0.018
167.98,-11.81,0.018
167.99,-11.75,0.018
168.00,-11.68,0.018
168.02,-11.61,0.018
168.03,-11.55,0.018
168.05,-11.48,0.018
168.06,-11.41,0.018
168.07,-11.34,0.018
168.08,-11.28,0.018
168.10,-11.21,0.018
168.11,-11.14,0.018
168.13,-11.08,0.018
168.14,-11.01,0.018
168.15,-10.94,0.018
168.17,-10.88,0.018
168.18,-10.81,0.018
168.19,-10.74,0.018
168.20,-10.68,0.018
168.22,-10.61,0.018
168.23,-10.54,0.018
168.25,-10.48,0.018
168.26,-10.41,0.018
168.27,-10.34,0.018
168.28,-10.28,0.018
168.30,-10.21,0.018
168.31,-10.14,0.018
168.33,-10.08,0.018
168.34,-10.01,0.018
168.35,-9.94,0.018
168.37,-9.88,0.018
168.38,-9.81,0.018
168.39,-9.74,0.018
168.40,-9.68,0.018
168.42,-9.61,0.018
168.43,-9.54,0.018
168.45,-9.48,0.018
168.46,-9.41,0.018
168.47,-9.34,0.018
168.48,-9.28,0.018
168.50,-9.21,0.018
168.51,-9.14,0.018
168.53,-9.08,0.018
168.54,-9.01,0.018
168.55,-8.94,0.018
168.57,-8.88,0.018
168.58,-8.81,0.018
168.59,-8.74,0.018
168.60,-8.67,0.018
168.62,-8.61,0.018
168.63,-8.54,0.018
168.65,-8.48,0.018
168.66,-8.41,0.018
168.67,-8.34,0.018
168.68,-8.27,0.018
168.70,-8.21,0.018
168.71,-8.14,0.018
168.73,-8.08,0.018
168.74,-8.01,0.018
168.75,-7.94,0.018
168.77,-7.87,0.018
168.78,-7.81,0.018
168.79,-7.74,0.018
168.80,-7.68,0.018
168.82,-7.61,0.018
168.83,-7.54,0.018
168.85,-7.48,0.018
168.86,-7.41,0.018
168.87,-7.34,0.018
168.88,-7.28,0.018
168.90,-7.21,0.018
168.91,-7.14,0.018
168.93,-7.08,0.018
168.94,-7.01,0.018
168.95,-6.94,0.018
168.97,-6.88,0.018
168.98,-6.81,0.018
168.99,-6.74,0.018
169.00,-6.68,0.018
169.02,-6.61,0.018
169.03,-6.54,0.018
169.05,-6.48,0.018
169.06,-6.41,0.018
169.07,-6.34,0.018
169.08,-6.27,0.018
169.10,-6.21,0.018
169.11,-6.14,0.018
169.13,-6.07,0.018
169.14,-6.01,0.018
169.15,-5.94,0.018
169.17,-5.87,0.018
169.18,-5.81,0.018
169.19,-5.74,0.018
169.20,-5.67,0.018
169.22,-5.60,0.018
169.23,-5.54,0.018
169.25,-5.47,0.018
169.26,-5.40,0.018
169.27,-5.34,0.018
169.28,-5.27,0.018
169.30,-5.20,0.018
169.31,-5.13,0.018
169.33,-5.07,0.018
169.34,-5.00,0.018
169.35,-4.94,0.018
169.37,-4.87,0.018
169.38,-4.80,0.018
169.39,-4.73,0.018
169.40,-4.67,0.018
169.42,-4.60,0.018
169.43,-4.54,0.018
169.45,-4.47,0.018
169.46,-4.40,0.018
169.47,-4.34,0.018
169.48,-4.27,0.018
169.50,-4.20,0.018
169.51,-4.14,0.018
169.53,-4.07,0.018
169.54,-4.00,0.018
169.55,-3.94,0.018
169.57,-3.87,0.018
169.58,-3.80,0.018
169.59,-3.73,0.018
169.60,-3.67,0.018
169.62,-3.60,0.018
169.63,-3.54,0.018
169.65,-3.47,0.018
169.66,-3.40,0.018
169.67,-3.34,0.018
169.68,-3.27,0.018
169.70,-3.20,0.018
169.71,-3.14,0.018
169.73,-3.07,0.018
169.74,-3.00,0.018
169.75,-2.94,0.018
169.77,-2.87,0.018
169.78,-2.80,0.018
169.79,-2.74,0.018
169.80,-2.67,0.018
169.82,-2.60,0.018
169.83,-2.54,0.018
169.85,-2.47,0.018
169.86,-2.40,0.018
169.87,-2.34,0.018
169.88,-2.27,0.018
169.90,-2.20,0.018
169.91,-2.13,0.018
169.93,-2.07,0.018
169.94,-2.00,0.018
169.95,-1.94,0.018
169.97,-1.87,0.018
169.98,-1.80,0.018
169.99,-1.73,0.018
170.00,-1.67,0.018
170.02,-1.60,0.018
170.03,-1.53,0.018
170.05,-1.47,0.018
170.06,-1.40,0.018
170.07,-1.34,0.018
170.08,-1.27,0.018
170.10,-1.20,0.018
170.11,-1.14,0.018
170.13,-1.07,0.018
170.14,-1.00,0.018
170.15,-0.94,0.018
170.17,-0.87,0.018
170.18,-0.80,0.018
170.19,-0.73,0.018
170.20,-0.67,0.018
170.22,-0.60,0.018
170.23,-0.53,0.018
170.25,-0.47,0.018
170.26,-0.40,0.018
170.27,-0.34,0.018
170.28,-0.27,0.018
170.30,-0.20,0.018
170.31,-0.14,0.018
170.33,-0.07,0.018
170.34,0.00,0.018
170.35,0.07,0.018
170.37,0.13,0.018
170.38,0.20,0.018
170.39,0.27,0.018
170.40,0.33,0.018
170.42,0.40,0.018
170.43,0.47,0.018
170.45,0.53,0.018
170.46,0.60,0.018
170.47,0.67,0.018
170.48,0.73,0.018
170.50,0.80,0.018
170.51,0.87,0.018
170.53,0.93,0.018
170.54,1.00,0.018
170.55,1.07,0.018
170.57,1.13,0.018
170.58,1.20,0.018
170.59,1.27,0.018
170.60,1.33,0.018
170.62,1.40,0.018
170.63,1.47,0.018
170.65,1.53,0.018
170.66,1.60,0.018
170.67,1.67,0.018
170.68,1.73,0.018
170.70,1.80,0.018
170.71,1.87,0.018
170.73,1.93,0.018
170.74,2.00,0.018
170.75,2.07,0.018
170.77,2.13,0.018
170.78,2.20,0.018
170.79,2.27,0.018
170.80,2.34,0.018
170.82,2.40,0.018
170.83,2.47,0.018
170.85,2.53,0.018
170.86,2.60,0.018
170.87,2.67,0.018
170.88,2.73,0.018
170.90,2.80,0.018
170.91,2.87,0.018
170.93,2.93,0.018
170.94,3.00,0.018
170.95,3.07,0.018
170.97,3.13,0.018
170.98,3.20,0.018
170.99,3.27,0.018
171.00,3.33,0.018
171.02,3.40,0.018
171.03,3.47,0.018
171.05,3.53,0.018
171.06,3.60,0.018
171.07,3.67,0.018
171.08,3.74,0.018
171.10,3.80,0.018
171.11,3.87,0.018
171.13,3.93,0.018
171.14,4.00,0.018
171.15,4.07,0.018
171.17,4.13,0.018
171.18,4.20,0.018
171.19,4.27,0.018
171.20,4.34,0.018
171.22,4.40,0.018
171.23,4.47,0.018
171.25,4.54,0.018
171.26,4.60,0.018
171.27,4.67,0.018
171.28,4.74,0.018
171.30,4.80,0.018
171.31,4.87,0.018
171.33,4.94,0.018
171.34,5.00,0.018
171.35,5.07,0.018
171.37,5.14,0.018
171.38,5.20,0.018
171.39,5.27,0.018
171.40,5.34,0.018
171.42,5.40,0.018
171.43,5.47,0.018
171.45,5.54,0.018
171.46,5.60,0.018
171.47,5.67,0.018
171.48,5.74,0.018
171.50,5.80,0.018
171.51,5.87,0.018
171.53,5.94,0.018
171.54,6.00,0.018
171.55,6.07,0.018
171.57,6.14,0.018
171.58,6.20,0.018
171.59,6.27,0.018
171.60,6.34,0.018
171.62,6.40,0.018
171.63,6.47,0.018
171.65,6.54,0.018
171.66,6.61,0.018
171.67,6.67,0.018
171.68,6.74,0.018
171.70,6.80,0.018
171.71,6.87,0.018
171.73,6.94,0.018
171.74,7.01,0.018
171.75,7.07,0.018
171.77,7.14,0.018
171.78,7.20,0.018
171.79,7.27,0.018
171.80,7.34,0.018
171.82,7.40,0.018
171.83,7.47,0.018
171.85,7.54,0.018
171.86,7.61,0.018
171.87,7.67,0.018
171.88,7.74,0.018
171.90,7.80,0.018
171.91,7.87,0.018
171.93,7.94,0.018
171.94,8.00,0.018
171.95,8.07,0.018
171.97,8.14,0.018
171.98,8.21,0.018
171.99,8.27,0.018
172.00,8.34,0.018
172.02,8.41,0.018
172.03,8.47,0.018
172.05,8.54,0.018
172.06,8.61,0.018
172.07,8.67,0.018
172.08,8.74,0.018
172.10,8.81,0.018
172.11,8.87,0.018
172.13,8.94,0.018
172.14,9.01,0.018
172.15,9.07,0.018
172.17,9.14,0.018
172.18,9.21,0.018
172.19,9.27,0.018
172.20,9.34,0.018
172.22,9.41,0.018
172.23,9.47,0.018
172.25,9.54,0.018
172.26,9.61,0.018
172.27,9.67,0.018
172.28,9.74,0.018
172.30,9.81,0.018
172.31,9.87,0.018
172.33,9.94,0.018
172.34,10.01,0.018
172.35,10.07,0.018
172.37,10.14,0.018
172.38,10.21,0.018
172.39,10.27,0.018
172.40,10.34,0.018
172.42,10.41,0.018
172.43,10.47,0.018
172.45,10.54,0.018
172.46,10.61,0.018
172.47,10.67,0.018
172.48,10.74,0.018
172.50,10.81,0.018
172.51,10.87,0.018
172.53,10.94,0.018
172.54,11.01,0.018
172.55,11.08,0.018
172.57,11.14,0.018
172.58,11.21,0.018
172.59,11.27,0.018
172.60,11.34,0.018
172.62,11.41,0.018
172.63,11.47,0.018
172.65,11.54,0.018
172.66,11.61,0.018
172.67,11.67,0.018
172.68,11.74,0.018
172.70,11.81,0.018
172.71,11.87,0.018
172.73,11.94,0.018
172.74,12.01,0.018
172.75,12.07,0.018
172.77,12.14,0.018
172.78,12.21,0.018
172.79,12.27,0.018
172.80,12.34,0.018
172.82,12.41,0.018
172.83,12.48,0.018
172.85,12.54,0.018
172.86,12.61,0.018
172.87,12.68,0.018
172.88,12.74,0.018
172.90,12.81,0.018
172.91,12.87,0.018
172.93,12.94,0.018
172.94,13.01,0.018
172.95,13.08,0.018
172.97,13.14,0.018
172.98,13.21,0.018
172.99,13.28,0.018
173.00,13.34,0.018
173.02,13.41,0.018
173.03,13.48,0.018
173.05,13.54,0.018
173.06,13.61,0.018
173.07,13.68,0.018
173.08,13.74,0.018
173.10,13.81,0.018
173.11,13.88,0.018
173.13,13.94,0.018
173.14,14.01,0.018
173.15,14.08,0.018
173.17,14.14,0.018
173.18,14.21,0.018
173.19,14.28,0.018
173.20,14.34,0.018
173.22,14.41,0.018
173.23,14.48,0.018
173.25,14.54,0.018
173.26,14.61,0.018
173.27,14.68,0.018
173.28,14.74,0.018
173.30,14.81,0.018
173.31,14.88,0.018
173.33,14.95,0.018
173.34,15.01,0.018
173.35,15.08,0.018
173.37,15.14,0.018
173.38,15.21,0.018
173.39,15.28,0.018
173.40,15.34,0.018
173.42,15.41,0.018
173.43,15.48,0.018
173.45,15.54,0.018
173.46,15.61,0.018
173.47,15.68,0.018
173.48,15.75,0.018
173.50,15.81,0.018
173.51,15.88,0.018
173.53,15.94,0.018
173.54,16.01,0.018
173.55,16.08,0.018
173.57,16.14,0.018
173.58,16.21,0.018
173.59,16.28,0.018
173.60,16.35,0.018
173.62,16.41,0.018
173.63,16.48,0.018
173.65,16.55,0.018
173.66,16.61,0.018
173.67,16.68,0.018
173.68,16.74,0.018
173.70,16.81,0.018
173.71,16.88,0.018
173.73,16.95,0.018
173.74,17.01,0.018
173.75,17.08,0.018
173.77,17.15,0.018
173.78,17.21,0.018
173.79,17.28,0.018
173.80,17.35,0.018
173.82,17.41,0.018
173.83,17.48,0.018
173.85,17.55,0.018
173.86,17.61,0.018
173.87,17.68,0.018
173.88,17.75,0.018
173.90,17.81,0.018
173.91,17.88,0.018
173.93,17.95,0.018
173.94,18.01,0.018
173.95,18.08,0.018
173.97,18.15,0.018
173.98,18.21,0.018
173.99,18.28,0.018
174.00,18.35,0.018
174.02,18.41,0.018
174.03,18.48,0.018
174.05,18.55,0.018
174.06,18.61,0.018
174.07,18.68,0.018
174.08,18.75,0.018
174.10,18.81,0.018
174.11,18.88,0.018
174.13,18.95,0.018
174.14,19.01,0.018
174.15,19.08,0.018
174.17,19.15,0.018
174.18,19.21,0.018
174.19,19.28,0.018
174.20,19.35,0.018
174.22,19.42,0.018
174.23,19.48,0.018
174.25,19.55,0.018
174.26,19.61,0.018
174.27,19.68,0.018
174.28,19.75,0.018
174.30,19.81,0.018
174.31,19.88,0.018
174.33,19.95,0.018
174.34,20.02,0.018
174.35,20.08,0.018
174.37,20.15,0.018
174.38,20.22,0.018
174.39,20.28,0.018
174.40,20.35,0.018
174.42,20.42,0.018
174.43,20.48,0.018
174.45,20.55,0.018
174.46,20.61,0.018
174.47,20.68,0.018
174.48,20.75,0.018
174.50,20.81,0.018
174.51,20.88,0.018
174.53,20.95,0.018
174.54,21.01,0.018
174.55,21.08,0.018
174.57,21.15,0.018
174.58,21.21,0.018
174.59,21.28,0.018
174.60,21.35,0.018
174.62,21.41,0.018
174.63,21.48,0.018
174.65,21.55,0.018
174.66,21.61,0.018
174.67,21.68,0.018
174.68,21.75,0.018
174.70,21.81,0.018
174.71,21.88,0.018
174.73,21.95,0.018
174.74,22.01,0.018
174.75,22.08,0.018
174.77,22.15,0.018
174.78,22.22,0.018
174.79,22.28,0.018
174.80,22.35,0.018
174.82,22.42,0.018
174.83,22.48,0.018
174.85,22.55,0.018
174.86,22.61,0.018
174.87,22.68,0.018
174.88,22.75,0.018
174.90,22.82,0.018
174.91,22.88,0.018
174.93,22.95,0.018
174.94,23.02,0.018
174.95,23.08,0.018
174.97,23.15,0.018
174.98,23.22,0.018
174.99,23.28,0.018
175.00,23.35,0.018
175.02,23.42,0.018
175.03,23.48,0.018
175.05,23.55,0.018
175.06,23.62,0.018
175.07,23.68,0.018
175.08,23.75,0.018
175.10,23.82,0.018
175.11,23.88,0.018
175.13,23.95,0.018
175.14,24.02,0.018
175.15,24.08,0.018
175.17,24.15,0.018
175.18,24.22,0.018
175.19,24.28,0.018
175.20,24.35,0.018
175.22,24.42,0.018
175.23,24.48,0.018
175.25,24.55,0.018
175.26,24.62,0.018
175.27,24.68,0.018
175.28,24.75,0.018
175.30,24.82,0.018
175.31,24.88,0.018
175.33,24.95,0.018
175.34,25.02,0.018
175.35,25.08,0.018
175.37,25.15,0.018
175.38,25.22,0.018
175.39,25.28,0.018
175.40,25.35,0.018
175.42,25.42,0.018
175.43,25.48,0.018
175.45,25.55,0.018
175.46,25.62,0.018
175.47,25.69,0.018
175.48,25.75,0.018
175.50,25.82,0.018
175.51,25.89,0.018
175.53,25.95,0.018
175.54,26.02,0.018
175.55,26.08,0.018
175.57,26.15,0.018
175.58,26.22,0.018
175.59,26.28,0.018
175.60,26.35,0.018
175.62,26.42,0.018
175.63,26.49,0.018
175.65,26.55,0.018
175.66,26.62,0.018
175.67,26.69,0.018
175.68,26.75,0.018
175.70,26.82,0.018
175.71,26.89,0.018
175.73,26.95,0.018
175.74,27.02,0.018
175.75,27.09,0.018
175.77,27.15,0.018
175.78,27.22,0.018
175.79,27.29,0.018
175.80,27.35,0.018
175.82,27.42,0.018
175.83,27.49,0.018
175.85,27.55,0.018
175.86,27.62,0.018
175.87,27.69,0.018
175.88,27.75,0.018
175.90,27.82,0.018
175.91,27.89,0.018
175.93,27.95,0.018
175.94,28.02,0.018
175.95,28.09,0.018
175.97,28.15,0.018
175.98,28.22,0.018
175.99,28.29,0.018
176.00,28.35,0.018
176.02,28.42,0.018
176.03,28.49,0.018
176.05,28.55,0.018
176.06,28.62,0.018
176.07,28.69,0.018
176.08,28.75,0.018
176.10,28.82,0.018
176.11,28.89,0.018
176.13,28.95,0.018
176.14,29.02,0.018
176.15,29.09,
176.17,29.16,
176.18,29.22,
176.19,29.29,
176.20,,