File: DSC/2025_04_13_CBD_Isolate_Powder_n60C_150C_10Cmin_x3.csv
Filename,2025_04_13_CBD_Isolate_Powder_n60C_150C_10Cmin_x3
Instrument name,DSC2A-00468 (192.168.1.100)
Operator,Yarger
rundate,4/13/2025
Sample name,2025_04_13_CBD_Isolate_Powder_n60C_150C_10Cmin_x3
proceduresegments,Data Off ; Equilibrate -60.00 °C; Data On ; Ramp 10.00 °C/min to 150.00 °C; Data Off ; Isothermal 1.0 min; Data On ; Ramp 10.00 °C/min to -60.00 °C; Data Off ; Isothermal 1.0 min; Data On ; Ramp 10.00 °C/min to 150.00 °C; Data Off ; Isothermal 1.0 min; Data On ; Ramp 10.00 °C/min to -60.00 °C; Data Off ; Isothermal 1.0 min; Data On ; Ramp 10.00 °C/min to 150.00 °C
[File Parameters]
Run date,4/13/2025 2:05:58 AM
Trios version,5.1.1.46572
Original File Name,
Current File Name,D:\DSC2500\JYarger\2025_04_13_CBD_Isolate_Powder_n60C_150C_10Cmin_x3.tri
[Procedure]
Procedure Name,CBD_n60_150C_10Cmin_x3
Sample Name,2025_04_13_CBD_Isolate_Powder_n60C_150C_10Cmin_x3
Sample Mass,6.94 mg
Reference Sample Mass,0 mg
Pan Mass,52.98 mg
Pan Number,41
Reference Pan Mass,53.32 mg
Reference Pan Number,10
Pan Type,Tzero Aluminum Hermetic
Comments,Hermetic Sealed Al DSC Consumables Pan/Lids.
Project Name,CA
Operator,Yarger
Test,Custom
Unload Max Temperature,30
Unload Min Temperature,30
Load Max Temperature,30
Load Min Temperature,30
Stop on Gas Flow Error,Yes
[Signal List]
Signal #1,Time (min)
Signal #2,Temperature (°C)
Signal #3,Heat Flow (mW)
Signal #4,Delta T (µV)
Signal #5,Delta Tzero (µV)
Signal #6,Tzero Temperature (°C)
Signal #7,Cell Purge (mL/min)
Signal #8,Heater Temp (°C)
Signal #9,Power Delivered (W)
Signal #10,Reference Junction Temperature (°C)
Signal #11,Flange Temperature (°C)
Signal #12,Heat Flow Phase (rad)
Signal #13,Total Heat Capacity (J/°C)
Signal #14,Heat Capacity (J/°C)
[Configuration]
Company Name,ASU
Instrument Name,DSC2A-00468
Instrument Type,DSC2500
Serial Number,DSC2A-00468
IP,192.168.1.100
Location of Instrument,MRRC
DisplayType,Unknown
Sample Interval ,0.1 s/pt
Selected Heat Flow,T4P
Exotherm Direction,Down
Cell Serial,DRC2-00792
Lid Type,Standard
Cooler,RCS 90
Leave Cooler on at End of Sequence,On
Gas 2,Nitrogen
Gas Selected,Channel 1
Flow Rate,50 mL/min
Secondary Purge,On
Licensed Heat Flow,Heat Flow T4P
Modulation Licensed,Yes
[Versions]
Common IDD Version,1
Cortex Version,VER 2.10.2.31
Driver,5.0.0.6
GDM Version,1.0.3.3
TouchscreenVersion,1.0.0.16145
FEP Version,1.2.1.21
FEP Bootloader,2.0.0.5
AutoSampler Version,2.1.1.26
Auto Sampler Bootloader,2.0.0.5
FCM Version,1.1.0.3
FCM Bootloader,2.0.0.5
[Experiment Logs]
Experiment Log Entry # 1,Data On set to 0
Experiment Log Entry # 3,Equilibrate Segment -60 (C) Started
Experiment Log Entry # 5,Air Cool is off.
Experiment Log Entry # 7,Data On set to 1
Experiment Log Entry # 9,Ramp Segment 10 C/min to 150 Started
Experiment Log Entry # 11,Data On set to 0
Experiment Log Entry # 13,Isothermal Segment 1 min started
Experiment Log Entry # 15,Data On set to 1
Experiment Log Entry # 17,Ramp Segment 10 C/min to -60 Started
Experiment Log Entry # 19,Data On set to 0
Experiment Log Entry # 21,Isothermal Segment 1 min started
Experiment Log Entry # 23,Data On set to 1
Experiment Log Entry # 25,Ramp Segment 10 C/min to 150 Started
Experiment Log Entry # 27,Data On set to 0
Experiment Log Entry # 29,Isothermal Segment 1 min started
Experiment Log Entry # 31,Data On set to 1
Experiment Log Entry # 33,Ramp Segment 10 C/min to -60 Started
Experiment Log Entry # 35,Data On set to 0
Experiment Log Entry # 37,Isothermal Segment 1 min started
Experiment Log Entry # 39,Data On set to 1
Experiment Log Entry # 41,Ramp Segment 10 C/min to 150 Started
[Method Log]
Method Log Entry # 1,Data Off
Method Log Entry # 2,Equilibrate -60 °C
Method Log Entry # 3,Data On
Method Log Entry # 4,(Ramp 294755) Ramp 10 °C/minute to 150 °C
Method Log Entry # 5,Data Off
Method Log Entry # 6,Isothermal 1 minutes
Method Log Entry # 7,Data On
Method Log Entry # 8,(Ramp 294759) Ramp 10 °C/minute to -60 °C
Method Log Entry # 9,Data Off
Method Log Entry # 10,Isothermal 1 minutes
Method Log Entry # 11,Data On
Method Log Entry # 12,(Ramp 294763) Ramp 10 °C/minute to 150 °C
Method Log Entry # 13,Data Off
Method Log Entry # 14,Isothermal 1 minutes
Method Log Entry # 15,Data On
Method Log Entry # 16,(Ramp 294767) Ramp 10 °C/minute to -60 °C
Method Log Entry # 17,Data Off
Method Log Entry # 18,Isothermal 1 minutes
Method Log Entry # 19,Data On
Method Log Entry # 20,(Ramp 294771) Ramp 10 °C/minute to 150 °C
Cell Serial,DRC2-00792
[T1 Calibration]
Slope,-0.008529666
Offset,9.636258
Initial Temperature,98.23
GUID,f8bfdadc-4977-4fdf-ba6d-0ba9134940c3
[TZero Calibration]
Date Applied,11/29/2022 4:06:13 PM
Description,From -89.059 °C to 396.009 °C at 20.000°C/min
Gas Type,Nitrogen
Pan Type,None
Source Files 1,C:\Users\yargerlab\Desktop\DSC Data\General\TZero_calibration_11_29_22_2nd(2).tri
Source Files 2,C:\Users\yargerlab\Desktop\DSC Data\General\TZero_calibration_11_29_22_2nd(3).tri
Delta T Offset,13.05235
Delta T Slope,-0.007271007
Delta T0 Offset,-13.69128
Delta T0 Slope,0.06063341
[Temperature Calibration]
Date Applied,11/29/2022 7:12:28 PM
Description,From 106.590 °C to 186.590 °C at 10.000°C/min
Gas Type,Nitrogen
Pan Type,Tzero Aluminum Hermetic
Source Files 1,C:\Users\yargerlab\Desktop\DSC Data\General\Indium(6).tri
Measured 1,157.391
Known 1,156.598
[Cell Constant Calibration]
Date Applied,11/29/2022 7:12:29 PM
Description,From 106.590 °C to 186.590 °C at 10.000°C/min
Gas Type,Nitrogen
Pan Type,Tzero Aluminum Hermetic
Source Files 1,C:\Users\yargerlab\Desktop\DSC Data\General\Indium(6).tri
T4P KCell,1.006051
Onset Slope,63.26126 mW/°C
[Direct Cp Calibration]
Date Applied,11/30/2022 11:04:51 AM
Description,From -79.983 °C to 298.409 °C at 10.000°C/min
Gas Type,Nitrogen
Pan Type,Tzero Aluminum Hermetic
Source Files 1,C:\Users\yargerlab\Desktop\DSC Data\General\Sapphire_Heat_Capacity_11_30_22.tri
[Rev Cp Calibration]
Date Applied,11/30/2022 1:58:51 PM
Description,From -79.996 °C to 292.812 °C at 3.000°C/min
Gas Type,Nitrogen
Pan Type,Tzero Aluminum Hermetic
Source Files 1,C:\Users\yargerlab\Desktop\DSC Data\General\Sapphire_MDSC_Calibration_11_30_22.tri
[step]
Ramp 10.00 °C/min to 150.00 °C
Time,Temperature,Heat Flow (Normalized)
min,°C,W/g
0.00,-59.67,-0.056
0.01,-59.68,-0.056
0.03,-59.69,-0.051
0.05,-59.69,-0.047
0.06,-59.69,-0.046
0.08,-59.68,-0.045
0.09,-59.65,-0.045
0.11,-59.61,-0.045
0.12,-59.55,-0.041
0.14,-59.48,-0.031
0.15,-59.41,-0.019
0.16,-59.32,-0.005
0.18,-59.22,0.010
0.19,-59.11,0.026
0.21,-59.01,0.044
0.23,-58.89,0.059
0.24,-58.77,0.074
0.26,-58.65,0.088
0.27,-58.52,0.100
0.29,-58.40,0.111
0.30,-58.27,0.122
0.31,-58.14,0.129
0.33,-58.00,0.138
0.35,-57.87,0.145
0.36,-57.73,0.150
0.38,-57.60,0.157
0.39,-57.46,0.161
0.40,-57.32,0.165
0.42,-57.18,0.169
0.44,-57.04,0.172
0.45,-56.90,0.175
0.46,-56.76,0.179
0.48,-56.62,0.181
0.50,-56.48,0.183
0.51,-56.33,0.184
0.53,-56.19,0.187
0.54,-56.05,0.188
0.55,-55.90,0.189
0.57,-55.76,0.190
0.58,-55.62,0.192
0.60,-55.47,0.192
0.62,-55.32,0.193
0.63,-55.18,0.194
0.65,-55.03,0.195
0.66,-54.89,0.196
0.68,-54.74,0.196
0.69,-54.60,0.197
0.70,-54.45,0.197
0.72,-54.30,0.198
0.73,-54.16,0.198
0.75,-54.01,0.198
0.77,-53.86,0.199
0.78,-53.72,0.199
0.80,-53.57,0.199
0.81,-53.42,0.199
0.83,-53.28,0.200
0.84,-53.13,0.200
0.85,-52.98,0.201
0.87,-52.83,0.201
0.88,-52.68,0.201
0.90,-52.54,0.201
0.92,-52.39,0.202
0.93,-52.24,0.202
0.95,-52.09,0.202
0.96,-51.95,0.202
0.98,-51.80,0.203
0.99,-51.65,0.203
1.00,-51.50,0.203
1.02,-51.35,0.204
1.03,-51.20,0.204
1.05,-51.06,0.204
1.07,-50.91,0.204
1.08,-50.76,0.205
1.09,-50.61,0.205
1.11,-50.46,0.205
1.13,-50.31,0.205
1.14,-50.16,0.205
1.16,-50.01,0.205
1.17,-49.87,0.206
1.18,-49.72,0.206
1.20,-49.57,0.206
1.22,-49.42,0.206
1.23,-49.27,0.206
1.24,-49.12,0.206
1.26,-48.97,0.207
1.28,-48.82,0.207
1.29,-48.67,0.207
1.31,-48.52,0.207
1.32,-48.37,0.207
1.33,-48.22,0.208
1.35,-48.08,0.208
1.37,-47.93,0.208
1.38,-47.78,0.208
1.39,-47.63,0.208
1.41,-47.48,0.208
1.43,-47.33,0.208
1.44,-47.18,0.209
1.46,-47.03,0.209
1.47,-46.88,0.209
1.48,-46.73,0.209
1.50,-46.58,0.209
1.52,-46.43,0.209
1.53,-46.28,0.209
1.54,-46.13,0.209
1.56,-45.98,0.210
1.58,-45.83,0.210
1.59,-45.68,0.210
1.61,-45.53,0.210
1.62,-45.38,0.210
1.63,-45.23,0.210
1.65,-45.08,0.210
1.67,-44.93,0.211
1.68,-44.78,0.211
1.69,-44.63,0.211
1.71,-44.48,0.211
1.73,-44.33,0.211
1.74,-44.19,0.211
1.76,-44.03,0.211
1.77,-43.89,0.211
1.78,-43.73,0.211
1.80,-43.59,0.211
1.82,-43.43,0.211
1.83,-43.28,0.212
1.84,-43.13,0.212
1.86,-42.99,0.212
1.88,-42.83,0.212
1.89,-42.69,0.212
1.91,-42.53,0.212
1.92,-42.38,0.212
1.93,-42.23,0.212
1.95,-42.09,0.212
1.97,-41.94,0.212
1.98,-41.78,0.212
1.99,-41.63,0.213
2.01,-41.49,0.213
2.03,-41.33,0.213
2.04,-41.18,0.213
2.06,-41.03,0.213
2.07,-40.89,0.213
2.08,-40.73,0.213
2.10,-40.58,0.213
2.12,-40.43,0.213
2.13,-40.28,0.213
2.14,-40.13,0.213
2.16,-39.98,0.213
2.18,-39.84,0.213
2.19,-39.68,0.214
2.21,-39.53,0.214
2.22,-39.38,0.214
2.24,-39.23,0.214
2.25,-39.08,0.214
2.26,-38.93,0.214
2.28,-38.78,0.214
2.29,-38.63,0.214
2.31,-38.48,0.214
2.33,-38.33,0.214
2.34,-38.18,0.214
2.36,-38.03,0.214
2.37,-37.88,0.215
2.39,-37.73,0.215
2.40,-37.58,0.215
2.41,-37.43,0.215
2.43,-37.28,0.215
2.44,-37.13,0.215
2.46,-36.98,0.215
2.48,-36.83,0.215
2.49,-36.68,0.215
2.51,-36.53,0.215
2.52,-36.38,0.215
2.54,-36.23,0.215
2.55,-36.08,0.215
2.56,-35.93,0.216
2.58,-35.78,0.216
2.59,-35.63,0.216
2.61,-35.48,0.216
2.63,-35.33,0.216
2.64,-35.18,0.216
2.66,-35.03,0.216
2.67,-34.88,0.216
2.69,-34.73,0.216
2.70,-34.58,0.216
2.71,-34.43,0.216
2.73,-34.28,0.216
2.74,-34.13,0.216
2.76,-33.98,0.216
2.78,-33.83,0.216
2.79,-33.68,0.217
2.81,-33.53,0.217
2.82,-33.38,0.217
2.84,-33.23,0.217
2.85,-33.08,0.217
2.86,-32.93,0.217
2.88,-32.78,0.217
2.89,-32.63,0.217
2.91,-32.48,0.217
2.93,-32.33,0.217
2.94,-32.17,0.217
2.96,-32.03,0.217
2.97,-31.87,0.217
2.99,-31.73,0.217
3.00,-31.58,0.217
3.01,-31.42,0.217
3.03,-31.27,0.218
3.04,-31.12,0.218
3.06,-30.97,0.218
3.08,-30.82,0.218
3.09,-30.67,0.218
3.11,-30.52,0.218
3.12,-30.37,0.218
3.14,-30.22,0.218
3.15,-30.07,0.218
3.16,-29.92,0.218
3.18,-29.77,0.218
3.19,-29.62,0.218
3.21,-29.47,0.218
3.23,-29.32,0.218
3.24,-29.17,0.218
3.26,-29.02,0.219
3.27,-28.87,0.219
3.29,-28.72,0.219
3.30,-28.57,0.219
3.31,-28.42,0.219
3.33,-28.27,0.219
3.34,-28.12,0.219
3.36,-27.97,0.219
3.38,-27.82,0.219
3.39,-27.67,0.219
3.41,-27.52,0.219
3.42,-27.37,0.219
3.44,-27.22,0.219
3.45,-27.07,0.220
3.46,-26.92,0.220
3.48,-26.77,0.220
3.49,-26.62,0.220
3.51,-26.47,0.220
3.53,-26.32,0.220
3.54,-26.17,0.220
3.56,-26.02,0.220
3.57,-25.87,0.220
3.59,-25.72,0.220
3.60,-25.57,0.220
3.61,-25.42,0.220
3.63,-25.27,0.220
3.64,-25.12,0.220
3.66,-24.97,0.220
3.68,-24.82,0.221
3.69,-24.67,0.221
3.71,-24.52,0.221
3.72,-24.37,0.221
3.74,-24.22,0.221
3.75,-24.07,0.221
3.76,-23.92,0.221
3.78,-23.77,0.221
3.79,-23.61,0.221
3.81,-23.47,0.221
3.83,-23.32,0.221
3.84,-23.16,0.221
3.86,-23.01,0.221
3.87,-22.86,0.221
3.89,-22.71,0.221
3.90,-22.56,0.221
3.91,-22.41,0.221
3.93,-22.26,0.222
3.94,-22.11,0.222
3.96,-21.96,0.222
3.98,-21.81,0.222
3.99,-21.66,0.222
4.01,-21.51,0.222
4.02,-21.36,0.222
4.04,-21.21,0.222
4.05,-21.06,0.222
4.06,-20.91,0.222
4.08,-20.76,0.222
4.09,-20.61,0.222
4.11,-20.46,0.222
4.13,-20.31,0.222
4.14,-20.16,0.222
4.16,-20.01,0.223
4.17,-19.86,0.223
4.19,-19.71,0.223
4.20,-19.56,0.223
4.21,-19.41,0.223
4.23,-19.26,0.223
4.24,-19.11,0.223
4.26,-18.96,0.223
4.28,-18.81,0.223
4.29,-18.66,0.223
4.30,-18.51,0.223
4.32,-18.36,0.223
4.34,-18.21,0.223
4.35,-18.06,0.223
4.36,-17.91,0.223
4.38,-17.76,0.224
4.40,-17.61,0.224
4.41,-17.46,0.224
4.43,-17.31,0.224
4.44,-17.16,0.224
4.45,-17.01,0.224
4.47,-16.86,0.224
4.49,-16.71,0.224
4.50,-16.56,0.224
4.51,-16.41,0.224
4.53,-16.26,0.224
4.55,-16.11,0.224
4.56,-15.96,0.224
4.58,-15.81,0.224
4.59,-15.66,0.224
4.60,-15.51,0.224
4.62,-15.35,0.225
4.64,-15.21,0.225
4.65,-15.06,0.225
4.66,-14.91,0.225
4.68,-14.75,0.225
4.70,-14.61,0.225
4.71,-14.45,0.225
4.73,-14.30,0.225
4.74,-14.15,0.225
4.75,-14.00,0.225
4.77,-13.85,0.225
4.79,-13.70,0.225
4.80,-13.55,0.225
4.81,-13.40,0.225
4.83,-13.25,0.225
4.85,-13.10,0.225
4.86,-12.95,0.225
4.88,-12.80,0.225
4.89,-12.65,0.226
4.90,-12.50,0.226
4.92,-12.35,0.226
4.94,-12.20,0.226
4.95,-12.05,0.226
4.96,-11.90,0.226
4.98,-11.75,0.226
5.00,-11.60,0.226
5.01,-11.45,0.226
5.03,-11.30,0.226
5.04,-11.15,0.226
5.05,-11.00,0.226
5.07,-10.85,0.226
5.09,-10.70,0.226
5.10,-10.55,0.226
5.11,-10.40,0.227
5.13,-10.25,0.227
5.15,-10.10,0.227
5.16,-9.95,0.227
5.18,-9.80,0.227
5.19,-9.65,0.227
5.20,-9.50,0.227
5.22,-9.35,0.227
5.24,-9.20,0.227
5.25,-9.05,0.227
5.26,-8.90,0.227
5.28,-8.75,0.227
5.30,-8.60,0.228
5.31,-8.45,0.228
5.33,-8.30,0.228
5.34,-8.15,0.228
5.35,-8.00,0.228
5.37,-7.85,0.228
5.39,-7.70,0.228
5.40,-7.55,0.228
5.41,-7.40,0.228
5.43,-7.25,0.228
5.45,-7.10,0.228
5.46,-6.95,0.228
5.48,-6.80,0.229
5.49,-6.65,0.229
5.50,-6.50,0.229
5.52,-6.35,0.229
5.54,-6.20,0.229
5.55,-6.05,0.229
5.56,-5.90,0.229
5.58,-5.74,0.229
5.60,-5.59,0.229
5.61,-5.44,0.229
5.63,-5.30,0.229
5.64,-5.14,0.230
5.65,-4.99,0.230
5.67,-4.84,0.230
5.69,-4.69,0.230
5.70,-4.54,0.230
5.71,-4.39,0.230
5.73,-4.24,0.230
5.75,-4.09,0.230
5.76,-3.94,0.230
5.78,-3.79,0.230
5.79,-3.64,0.230
5.80,-3.49,0.230
5.82,-3.34,0.231
5.84,-3.19,0.231
5.85,-3.04,0.231
5.86,-2.89,0.231
5.88,-2.74,0.231
5.90,-2.59,0.231
5.91,-2.44,0.231
5.93,-2.29,0.231
5.94,-2.14,0.231
5.95,-1.99,0.231
5.97,-1.84,0.231
5.99,-1.69,0.231
6.00,-1.54,0.231
6.01,-1.39,0.232
6.03,-1.24,0.232
6.05,-1.09,0.232
6.06,-0.94,0.232
6.08,-0.79,0.232
6.09,-0.64,0.232
6.10,-0.49,0.232
6.12,-0.34,0.232
6.14,-0.19,0.232
6.15,-0.04,0.232
6.16,0.11,0.232
6.18,0.26,0.232
6.20,0.41,0.232
6.21,0.56,0.233
6.23,0.71,0.233
6.24,0.86,0.233
6.25,1.01,0.233
6.27,1.16,0.233
6.29,1.31,0.233
6.30,1.46,0.233
6.31,1.61,0.233
6.33,1.76,0.233
6.35,1.91,0.233
6.36,2.06,0.233
6.38,2.21,0.233
6.39,2.36,0.234
6.40,2.51,0.234
6.42,2.66,0.234
6.44,2.81,0.234
6.45,2.96,0.234
6.46,3.12,0.234
6.48,3.26,0.234
6.50,3.42,0.234
6.51,3.56,0.234
6.53,3.72,0.234
6.54,3.87,0.234
6.55,4.02,0.235
6.57,4.17,0.235
6.59,4.32,0.235
6.60,4.47,0.235
6.61,4.62,0.235
6.63,4.77,0.235
6.65,4.92,0.235
6.66,5.07,0.235
6.68,5.22,0.235
6.69,5.37,0.236
6.70,5.52,0.236
6.72,5.67,0.236
6.74,5.82,0.236
6.75,5.97,0.236
6.76,6.12,0.236
6.78,6.27,0.236
6.80,6.42,0.236
6.81,6.57,0.236
6.83,6.72,0.236
6.84,6.87,0.236
6.85,7.02,0.237
6.87,7.17,0.237
6.89,7.32,0.237
6.90,7.47,0.237
6.91,7.62,0.237
6.93,7.77,0.237
6.95,7.92,0.237
6.96,8.07,0.237
6.98,8.22,0.237
6.99,8.37,0.237
7.00,8.52,0.238
7.02,8.67,0.238
7.04,8.82,0.238
7.05,8.97,0.238
7.06,9.12,0.238
7.08,9.27,0.238
7.10,9.42,0.238
7.11,9.57,0.238
7.13,9.72,0.238
7.14,9.87,0.238
7.15,10.03,0.239
7.17,10.17,0.239
7.19,10.32,0.239
7.20,10.48,0.239
7.21,10.63,0.239
7.23,10.78,0.239
7.25,10.93,0.239
7.26,11.08,0.239
7.28,11.23,0.239
7.29,11.37,0.239
7.30,11.52,0.240
7.32,11.68,0.240
7.34,11.83,0.240
7.35,11.98,0.240
7.36,12.13,0.240
7.38,12.28,0.240
7.40,12.43,0.240
7.41,12.58,0.240
7.43,12.73,0.240
7.44,12.88,0.240
7.45,13.03,0.240
7.47,13.18,0.241
7.49,13.33,0.241
7.50,13.48,0.241
7.51,13.63,0.241
7.53,13.78,0.241
7.55,13.93,0.241
7.56,14.08,0.241
7.58,14.23,0.241
7.59,14.38,0.242
7.60,14.53,0.242
7.62,14.68,0.242
7.64,14.83,0.242
7.65,14.98,0.242
7.66,15.13,0.242
7.68,15.28,0.242
7.70,15.43,0.242
7.71,15.58,0.242
7.73,15.73,0.243
7.74,15.88,0.243
7.75,16.03,0.243
7.77,16.18,0.243
7.79,16.33,0.243
7.80,16.48,0.243
7.81,16.63,0.243
7.83,16.78,0.243
7.85,16.93,0.243
7.86,17.08,0.243
7.88,17.23,0.243
7.89,17.38,0.243
7.90,17.53,0.244
7.92,17.68,0.244
7.94,17.83,0.244
7.95,17.98,0.244
7.96,18.13,0.244
7.98,18.28,0.244
8.00,18.43,0.244
8.01,18.58,0.244
8.03,18.73,0.244
8.04,18.88,0.245
8.05,19.03,0.245
8.07,19.18,0.245
8.09,19.33,0.245
8.10,19.48,0.245
8.11,19.63,0.245
8.13,19.79,0.245
8.15,19.93,0.245
8.16,20.08,0.246
8.18,20.23,0.246
8.19,20.38,0.246
8.20,20.53,0.246
8.22,20.68,0.246
8.24,20.84,0.246
8.25,20.98,0.246
8.26,21.14,0.246
8.28,21.29,0.246
8.30,21.44,0.247
8.31,21.59,0.247
8.33,21.74,0.247
8.34,21.88,0.247
8.35,22.04,0.247
8.37,22.19,0.247
8.39,22.34,0.247
8.40,22.49,0.247
8.41,22.64,0.248
8.43,22.79,0.248
8.45,22.94,0.248
8.46,23.09,0.248
8.48,23.24,0.248
8.49,23.39,0.248
8.50,23.54,0.248
8.52,23.69,0.248
8.53,23.84,0.248
8.55,23.99,0.249
8.57,24.14,0.249
8.58,24.29,0.249
8.60,24.44,0.249
8.61,24.59,0.249
8.63,24.74,0.249
8.64,24.89,0.249
8.65,25.04,0.249
8.67,25.19,0.249
8.68,25.34,0.249
8.70,25.49,0.250
8.72,25.64,0.250
8.73,25.79,0.250
8.75,25.94,0.250
8.76,26.09,0.250
8.78,26.24,0.250
8.79,26.39,0.250
8.80,26.54,0.250
8.82,26.69,0.251
8.83,26.84,0.251
8.85,26.99,0.251
8.87,27.14,0.251
8.88,27.29,0.251
8.90,27.44,0.251
8.91,27.59,0.252
8.93,27.74,0.252
8.94,27.89,0.252
8.95,28.04,0.252
8.97,28.19,0.252
8.98,28.34,0.252
9.00,28.49,0.252
9.02,28.64,0.252
9.03,28.79,0.253
9.05,28.94,0.253
9.06,29.09,0.253
9.08,29.24,0.253
9.09,29.39,0.253
9.10,29.54,0.253
9.12,29.69,0.253
9.13,29.84,0.253
9.15,29.99,0.254
9.17,30.14,0.254
9.18,30.29,0.254
9.20,30.44,0.254
9.21,30.59,0.254
9.23,30.74,0.254
9.24,30.89,0.254
9.25,31.05,0.254
9.27,31.19,0.255
9.28,31.34,0.255
9.30,31.49,0.255
9.32,31.65,0.255
9.33,31.79,0.255
9.35,31.94,0.255
9.36,32.10,0.255
9.38,32.24,0.255
9.39,32.40,0.255
9.40,32.55,0.256
9.42,32.70,0.256
9.43,32.85,0.256
9.45,33.00,0.256
9.47,33.15,0.256
9.48,33.30,0.256
9.50,33.45,0.256
9.51,33.60,0.256
9.53,33.75,0.257
9.54,33.90,0.257
9.55,34.05,0.257
9.57,34.20,0.257
9.58,34.35,0.257
9.60,34.50,0.257
9.62,34.65,0.257
9.63,34.80,0.257
9.65,34.95,0.258
9.66,35.10,0.258
9.68,35.25,0.258
9.69,35.40,0.258
9.70,35.55,0.258
9.72,35.70,0.258
9.73,35.85,0.258
9.75,36.00,0.258
9.77,36.15,0.259
9.78,36.30,0.259
9.80,36.45,0.259
9.81,36.60,0.259
9.83,36.75,0.259
9.84,36.90,0.259
9.85,37.05,0.259
9.87,37.20,0.259
9.88,37.35,0.259
9.90,37.50,0.260
9.92,37.65,0.260
9.93,37.80,0.260
9.95,37.95,0.260
9.96,38.10,0.260
9.98,38.25,0.260
9.99,38.40,0.260
10.00,38.55,0.261
10.02,38.70,0.261
10.03,38.85,0.261
10.05,39.00,0.261
10.07,39.15,0.261
10.08,39.30,0.261
10.10,39.45,0.261
10.11,39.60,0.261
10.13,39.75,0.261
10.14,39.90,0.262
10.15,40.05,0.262
10.17,40.20,0.262
10.18,40.35,0.262
10.20,40.50,0.262
10.22,40.65,0.262
10.23,40.80,0.262
10.25,40.95,0.262
10.26,41.10,0.263
10.28,41.25,0.263
10.29,41.40,0.263
10.30,41.55,0.263
10.32,41.70,0.263
10.33,41.85,0.263
10.35,42.00,0.263
10.37,42.15,0.263
10.38,42.30,0.264
10.40,42.45,0.264
10.41,42.60,0.264
10.43,42.75,0.264
10.44,42.90,0.264
10.45,43.05,0.264
10.47,43.20,0.264
10.48,43.35,0.264
10.50,43.51,0.265
10.52,43.65,0.265
10.53,43.81,0.265
10.55,43.95,0.265
10.56,44.11,0.265
10.58,44.25,0.265
10.59,44.41,0.265
10.60,44.56,0.265
10.62,44.71,0.266
10.63,44.86,0.266
10.65,45.01,0.266
10.67,45.16,0.266
10.68,45.31,0.266
10.70,45.46,0.266
10.71,45.61,0.266
10.73,45.76,0.267
10.74,45.91,0.267
10.75,46.06,0.267
10.77,46.21,0.267
10.78,46.36,0.267
10.80,46.51,0.267
10.82,46.66,0.267
10.83,46.81,0.268
10.85,46.96,0.268
10.86,47.11,0.268
10.88,47.26,0.268
10.89,47.41,0.268
10.90,47.56,0.268
10.92,47.71,0.268
10.93,47.86,0.268
10.95,48.01,0.269
10.97,48.16,0.269
10.98,48.31,0.269
11.00,48.46,0.269
11.01,48.61,0.269
11.03,48.76,0.269
11.04,48.91,0.269
11.05,49.06,0.270
11.07,49.21,0.270
11.08,49.36,0.270
11.10,49.51,0.270
11.12,49.66,0.270
11.13,49.81,0.270
11.15,49.96,0.270
11.16,50.11,0.271
11.18,50.26,0.271
11.19,50.41,0.271
11.20,50.56,0.271
11.22,50.71,0.271
11.23,50.86,0.271
11.25,51.01,0.271
11.27,51.16,0.272
11.28,51.31,0.272
11.30,51.46,0.272
11.31,51.61,0.272
11.33,51.76,0.272
11.34,51.91,0.272
11.35,52.06,0.273
11.37,52.21,0.273
11.38,52.36,0.273
11.40,52.51,0.273
11.42,52.66,0.273
11.43,52.81,0.273
11.45,52.96,0.273
11.46,53.11,0.274
11.48,53.26,0.274
11.49,53.41,0.274
11.50,53.56,0.275
11.52,53.71,0.275
11.53,53.86,0.275
11.55,54.01,0.275
11.57,54.17,0.275
11.58,54.31,0.275
11.60,54.46,0.276
11.61,54.61,0.276
11.63,54.76,0.276
11.64,54.91,0.276
11.65,55.07,0.276
11.67,55.22,0.277
11.68,55.37,0.277
11.70,55.52,0.277
11.72,55.67,0.277
11.73,55.82,0.278
11.75,55.97,0.278
11.76,56.12,0.278
11.78,56.27,0.278
11.79,56.42,0.279
11.80,56.57,0.279
11.82,56.72,0.279
11.83,56.87,0.279
11.85,57.02,0.280
11.87,57.17,0.280
11.88,57.32,0.281
11.90,57.47,0.281
11.91,57.62,0.281
11.93,57.77,0.281
11.94,57.92,0.282
11.95,58.07,0.283
11.97,58.22,0.283
11.98,58.37,0.284
12.00,58.51,0.284
12.02,58.67,0.285
12.03,58.82,0.285
12.05,58.97,0.286
12.06,59.12,0.287
12.08,59.27,0.288
12.09,59.42,0.289
12.10,59.57,0.290
12.12,59.72,0.291
12.13,59.86,0.293
12.15,60.02,0.294
12.17,60.17,0.295
12.18,60.31,0.297
12.20,60.46,0.299
12.21,60.61,0.302
12.23,60.76,0.303
12.24,60.91,0.305
12.25,61.06,0.307
12.27,61.21,0.310
12.28,61.36,0.312
12.30,61.51,0.315
12.32,61.66,0.318
12.33,61.81,0.322
12.35,61.96,0.326
12.36,62.11,0.330
12.38,62.25,0.336
12.39,62.40,0.341
12.40,62.55,0.347
12.42,62.70,0.354
12.43,62.85,0.362
12.45,62.99,0.372
12.47,63.14,0.381
12.48,63.29,0.393
12.50,63.43,0.405
12.51,63.58,0.422
12.53,63.72,0.439
12.54,63.87,0.459
12.55,64.01,0.483
12.57,64.15,0.509
12.58,64.29,0.537
12.60,64.43,0.570
12.62,64.57,0.609
12.63,64.70,0.649
12.65,64.84,0.699
12.66,64.97,0.755
12.68,65.10,0.816
12.69,65.23,0.885
12.70,65.35,0.958
12.72,65.47,1.038
12.73,65.59,1.120
12.75,65.71,1.225
12.77,65.82,1.312
12.78,65.93,1.412
12.80,66.04,1.506
12.81,66.15,1.599
12.83,66.26,1.698
12.84,66.36,1.783
12.85,66.47,1.863
12.87,66.58,1.951
12.88,66.69,2.037
12.90,66.80,2.118
12.92,66.91,2.200
12.93,67.02,2.279
12.95,67.13,2.356
12.96,67.24,2.425
12.98,67.35,2.489
12.99,67.47,2.558
13.00,67.58,2.652
13.02,67.69,2.751
13.03,67.81,2.791
13.05,67.93,2.803
13.07,68.05,2.783
13.08,68.19,2.731
13.10,68.34,2.669
13.11,68.49,2.584
13.13,68.66,2.471
13.14,68.84,2.350
13.15,69.02,2.225
13.17,69.21,2.097
13.18,69.40,1.960
13.20,69.61,1.817
13.22,69.81,1.675
13.23,70.02,1.540
13.25,70.23,1.410
13.26,70.44,1.291
13.28,70.65,1.181
13.29,70.85,1.077
13.30,71.06,0.982
13.32,71.26,0.896
13.33,71.45,0.820
13.35,71.65,0.754
13.37,71.84,0.700
13.38,72.03,0.649
13.40,72.21,0.607
13.41,72.39,0.568
13.43,72.57,0.536
13.44,72.74,0.512
13.45,72.91,0.492
13.47,73.08,0.475
13.48,73.25,0.458
13.50,73.41,0.445
13.52,73.57,0.432
13.53,73.73,0.423
13.55,73.89,0.414
13.56,74.05,0.405
13.58,74.21,0.400
13.59,74.36,0.394
13.60,74.52,0.388
13.62,74.67,0.384
13.63,74.83,0.380
13.65,74.98,0.377
13.67,75.13,0.376
13.68,75.29,0.373
13.70,75.44,0.371
13.71,75.59,0.370
13.73,75.74,0.368
13.74,75.90,0.366
13.75,76.05,0.365
13.77,76.20,0.365
13.78,76.35,0.363
13.80,76.50,0.363
13.82,76.65,0.362
13.83,76.80,0.362
13.85,76.95,0.362
13.86,77.10,0.361
13.88,77.25,0.361
13.89,77.40,0.361
13.90,77.55,0.360
13.92,77.70,0.360
13.93,77.86,0.360
13.95,78.00,0.360
13.97,78.16,0.360
13.98,78.31,0.360
14.00,78.46,0.360
14.01,78.61,0.360
14.03,78.76,0.359
14.04,78.91,0.359
14.05,79.06,0.359
14.07,79.21,0.359
14.08,79.36,0.359
14.10,79.51,0.359
14.12,79.66,0.359
14.13,79.81,0.359
14.15,79.96,0.359
14.16,80.11,0.359
14.18,80.26,0.359
14.19,80.41,0.359
14.20,80.56,0.358
14.22,80.71,0.358
14.23,80.86,0.358
14.25,81.01,0.358
14.27,81.16,0.358
14.28,81.31,0.358
14.30,81.46,0.358
14.31,81.61,0.358
14.33,81.76,0.358
14.34,81.91,0.358
14.35,82.06,0.358
14.37,82.21,0.358
14.38,82.36,0.358
14.40,82.51,0.358
14.42,82.66,0.358
14.43,82.81,0.358
14.45,82.96,0.359
14.46,83.11,0.359
14.48,83.26,0.359
14.49,83.41,0.359
14.50,83.56,0.359
14.52,83.71,0.359
14.53,83.86,0.359
14.55,84.01,0.359
14.57,84.16,0.359
14.58,84.31,0.359
14.60,84.46,0.359
14.61,84.61,0.359
14.63,84.76,0.359
14.64,84.91,0.359
14.65,85.06,0.359
14.67,85.21,0.359
14.68,85.36,0.359
14.70,85.51,0.359
14.72,85.66,0.359
14.73,85.81,0.359
14.75,85.96,0.359
14.76,86.11,0.359
14.78,86.26,0.359
14.79,86.41,0.359
14.80,86.57,0.359
14.82,86.71,0.359
14.83,86.87,0.359
14.85,87.02,0.360
14.87,87.17,0.360
14.88,87.32,0.360
14.90,87.47,0.360
14.91,87.62,0.360
14.93,87.77,0.360
14.94,87.92,0.360
14.95,88.07,0.360
14.97,88.22,0.360
14.98,88.37,0.360
15.00,88.52,0.360
15.02,88.67,0.360
15.03,88.82,0.360
15.05,88.97,0.360
15.06,89.12,0.360
15.08,89.27,0.360
15.09,89.42,0.360
15.10,89.57,0.360
15.12,89.72,0.361
15.13,89.87,0.361
15.15,90.02,0.361
15.17,90.17,0.361
15.18,90.32,0.361
15.20,90.47,0.361
15.21,90.62,0.361
15.23,90.77,0.361
15.24,90.92,0.361
15.25,91.07,0.361
15.27,91.22,0.362
15.28,91.37,0.362
15.30,91.52,0.362
15.32,91.67,0.362
15.33,91.82,0.362
15.35,91.97,0.362
15.36,92.12,0.362
15.38,92.27,0.362
15.39,92.42,0.362
15.40,92.57,0.362
15.42,92.72,0.362
15.43,92.87,0.363
15.45,93.02,0.363
15.47,93.17,0.363
15.48,93.32,0.363
15.50,93.47,0.363
15.51,93.62,0.363
15.53,93.77,0.363
15.54,93.92,0.363
15.55,94.07,0.363
15.57,94.22,0.363
15.58,94.37,0.363
15.60,94.52,0.363
15.62,94.67,0.363
15.63,94.82,0.363
15.65,94.97,0.364
15.66,95.12,0.364
15.68,95.27,0.364
15.69,95.42,0.364
15.70,95.57,0.364
15.72,95.72,0.364
15.73,95.87,0.364
15.75,96.02,0.364
15.77,96.17,0.364
15.78,96.32,0.364
15.80,96.47,0.364
15.81,96.62,0.364
15.83,96.77,0.364
15.84,96.92,0.364
15.85,97.08,0.365
15.87,97.23,0.365
15.88,97.38,0.365
15.90,97.53,0.365
15.92,97.68,0.365
15.93,97.83,0.365
15.95,97.98,0.365
15.96,98.13,0.365
15.98,98.28,0.365
15.99,98.43,0.365
16.00,98.58,0.365
16.02,98.73,0.365
16.03,98.88,0.365
16.05,99.03,0.365
16.07,99.18,0.365
16.08,99.33,0.365
16.10,99.48,0.366
16.11,99.63,0.366
16.13,99.78,0.366
16.14,99.93,0.366
16.15,100.08,0.366
16.17,100.23,0.366
16.18,100.38,0.366
16.20,100.53,0.366
16.22,100.68,0.366
16.23,100.83,0.366
16.25,100.98,0.366
16.26,101.13,0.366
16.28,101.28,0.366
16.29,101.43,0.366
16.30,101.58,0.366
16.32,101.73,0.366
16.33,101.88,0.366
16.35,102.03,0.367
16.37,102.18,0.367
16.38,102.33,0.367
16.40,102.48,0.367
16.41,102.63,0.367
16.43,102.78,0.367
16.44,102.93,0.367
16.45,103.08,0.367
16.47,103.23,0.367
16.48,103.38,0.367
16.50,103.53,0.367
16.52,103.68,0.367
16.53,103.83,0.367
16.55,103.98,0.368
16.56,104.13,0.368
16.58,104.28,0.368
16.59,104.43,0.368
16.60,104.58,0.368
16.62,104.73,0.368
16.63,104.88,0.368
16.65,105.03,0.368
16.67,105.18,0.368
16.68,105.33,0.368
16.70,105.48,0.368
16.71,105.63,0.368
16.73,105.78,0.368
16.74,105.93,0.368
16.75,106.08,0.369
16.77,106.23,0.369
16.78,106.38,0.369
16.80,106.53,0.369
16.82,106.68,0.369
16.83,106.83,0.369
16.85,106.98,0.369
16.86,107.13,0.369
16.88,107.28,0.369
16.89,107.43,0.369
16.90,107.58,0.369
16.92,107.73,0.369
16.93,107.88,0.369
16.95,108.03,0.369
16.97,108.18,0.369
16.98,108.33,0.369
17.00,108.49,0.370
17.01,108.63,0.370
17.03,108.78,0.370
17.04,108.94,0.370
17.05,109.08,0.370
17.07,109.24,0.370
17.08,109.39,0.370
17.10,109.54,0.370
17.12,109.69,0.370
17.13,109.84,0.370
17.14,109.99,0.370
17.16,110.14,0.371
17.18,110.29,0.371
17.19,110.44,0.371
17.21,110.59,0.371
17.22,110.74,0.371
17.23,110.89,0.371
17.25,111.04,0.371
17.27,111.19,0.371
17.28,111.34,0.371
17.29,111.49,0.371
17.31,111.64,0.371
17.33,111.79,0.371
17.34,111.94,0.371
17.36,112.09,0.371
17.37,112.24,0.371
17.38,112.39,0.371
17.40,112.54,0.371
17.42,112.69,0.371
17.43,112.84,0.372
17.44,112.99,0.372
17.46,113.14,0.372
17.48,113.29,0.372
17.49,113.44,0.372
17.51,113.59,0.372
17.52,113.74,0.372
17.53,113.89,0.372
17.55,114.04,0.372
17.57,114.19,0.372
17.58,114.34,0.372
17.59,114.49,0.372
17.61,114.64,0.372
17.63,114.79,0.372
17.64,114.94,0.372
17.66,115.09,0.372
17.67,115.24,0.372
17.68,115.39,0.373
17.70,115.54,0.373
17.72,115.69,0.373
17.73,115.84,0.373
17.74,115.99,0.373
17.76,116.14,0.373
17.78,116.29,0.373
17.79,116.44,0.373
17.81,116.59,0.373
17.82,116.74,0.373
17.83,116.89,0.373
17.85,117.04,0.373
17.87,117.19,0.373
17.88,117.34,0.373
17.89,117.49,0.373
17.91,117.64,0.373
17.93,117.79,0.374
17.94,117.94,0.374
17.96,118.09,0.374
17.97,118.24,0.374
17.98,118.39,0.374
18.00,118.54,0.374
18.02,118.69,0.374
18.03,118.84,0.374
18.04,118.99,0.374
18.06,119.14,0.374
18.08,119.29,0.374
18.09,119.44,0.374
18.11,119.59,0.375
18.12,119.74,0.375
18.13,119.89,0.375
18.15,120.04,0.375
18.17,120.19,0.375
18.18,120.34,0.375
18.19,120.49,0.375
18.21,120.64,0.375
18.23,120.79,0.375
18.24,120.94,0.375
18.26,121.09,0.375
18.27,121.25,0.375
18.28,121.40,0.375
18.30,121.54,0.375
18.32,121.69,0.375
18.33,121.85,0.375
18.34,122.00,0.376
18.36,122.15,0.376
18.38,122.30,0.376
18.39,122.44,0.376
18.41,122.59,0.376
18.42,122.75,0.376
18.43,122.89,0.376
18.45,123.05,0.376
18.47,123.20,0.376
18.48,123.35,0.376
18.49,123.50,0.376
18.51,123.65,0.376
18.53,123.80,0.376
18.54,123.95,0.376
18.56,124.10,0.376
18.57,124.25,0.377
18.58,124.40,0.377
18.60,124.55,0.377
18.62,124.70,0.377
18.63,124.85,0.377
18.64,125.00,0.377
18.66,125.15,0.377
18.68,125.30,0.377
18.69,125.45,0.377
18.71,125.60,0.377
18.72,125.75,0.377
18.73,125.90,0.377
18.75,126.05,0.377
18.77,126.20,0.377
18.78,126.35,0.377
18.79,126.50,0.377
18.81,126.65,0.377
18.83,126.80,0.377
18.84,126.95,0.378
18.86,127.10,0.378
18.87,127.25,0.378
18.88,127.40,0.378
18.90,127.55,0.378
18.92,127.70,0.378
18.93,127.85,0.378
18.94,128.00,0.378
18.96,128.15,0.378
18.98,128.30,0.378
18.99,128.45,0.378
19.01,128.60,0.378
19.02,128.75,0.378
19.03,128.90,0.378
19.05,129.05,0.378
19.07,129.20,0.378
19.08,129.35,0.378
19.09,129.50,0.378
19.11,129.65,0.378
19.13,129.80,0.378
19.14,129.95,0.378
19.16,130.10,0.378
19.17,130.25,0.379
19.18,130.40,0.379
19.20,130.55,0.379
19.22,130.70,0.379
19.23,130.85,0.379
19.24,131.00,0.379
19.26,131.15,0.379
19.28,131.30,0.379
19.29,131.45,0.379
19.31,131.61,0.379
19.32,131.75,0.379
19.33,131.90,0.379
19.35,132.05,0.379
19.37,132.20,0.379
19.38,132.35,0.379
19.39,132.50,0.379
19.41,132.65,0.379
19.43,132.80,0.379
19.44,132.95,0.379
19.46,133.10,0.379
19.47,133.25,0.380
19.48,133.40,0.380
19.50,133.55,0.380
19.52,133.70,0.380
19.53,133.86,0.380
19.54,134.01,0.380
19.56,134.16,0.380
19.58,134.31,0.380
19.59,134.46,0.380
19.61,134.61,0.380
19.62,134.76,0.380
19.63,134.91,0.380
19.65,135.06,0.380
19.67,135.21,0.381
19.68,135.36,0.381
19.69,135.51,0.381
19.71,135.66,0.381
19.73,135.81,0.381
19.74,135.96,0.381
19.76,136.11,0.381
19.77,136.26,0.381
19.78,136.41,0.381
19.80,136.56,0.381
19.82,136.71,0.381
19.83,136.86,0.381
19.84,137.01,0.381
19.86,137.16,0.381
19.88,137.31,0.381
19.89,137.46,0.382
19.91,137.61,0.382
19.92,137.76,0.382
19.93,137.91,0.382
19.95,138.06,0.382
19.97,138.21,0.382
19.98,138.36,0.382
19.99,138.51,0.382
20.01,138.66,0.382
20.03,138.81,0.382
20.04,138.96,0.382
20.06,139.11,0.382
20.07,139.26,0.382
20.08,139.41,0.382
20.10,139.56,0.382
20.12,139.71,0.382
20.13,139.86,0.382
20.14,140.01,0.382
20.16,140.16,0.382
20.18,140.31,0.382
20.19,140.46,0.382
20.21,140.61,0.382
20.22,140.76,0.382
20.23,140.91,0.382
20.25,141.06,0.383
20.27,141.21,0.383
20.28,141.36,0.383
20.29,141.51,0.383
20.31,141.66,0.383
20.33,141.81,0.383
20.34,141.96,0.383
20.36,142.11,0.383
20.37,142.26,0.383
20.38,142.41,0.383
20.40,142.56,0.383
20.42,142.71,0.383
20.43,142.86,0.383
20.44,143.01,0.383
20.46,143.16,0.383
20.48,143.31,0.383
20.49,143.46,0.383
20.51,143.61,0.383
20.52,143.76,0.383
20.53,143.91,0.383
20.55,144.06,0.383
20.57,144.21,0.384
20.58,144.36,0.384
20.59,144.51,0.384
20.61,144.66,0.384
20.63,144.81,0.384
20.64,144.96,0.384
20.66,145.11,0.384
20.67,145.26,0.384
20.68,145.41,0.384
20.70,145.56,0.384
20.72,145.71,0.384
20.73,145.86,0.384
20.74,146.01,0.384
20.76,146.16,0.384
20.78,146.31,0.384
20.79,146.46,0.384
20.81,146.61,0.384
20.82,146.77,0.385
20.83,146.92,0.385
20.85,147.07,0.385
20.87,147.22,0.385
20.88,147.37,0.385
20.89,147.52,0.385
20.91,147.67,0.385
20.93,147.82,0.385
20.94,147.97,
20.96,148.12,
20.97,148.27,
20.98,,
20.99,,

[step]
Ramp 10.00 °C/min to -60.00 °C
Time,Temperature,Heat Flow (Normalized)
min,°C,W/g
21.99,150.09,-0.031
22.01,150.09,-0.031
22.02,150.09,-0.031
22.04,150.08,-0.031
22.05,150.07,-0.031
22.07,150.05,-0.031
22.08,150.01,-0.032
22.10,149.96,-0.051
22.11,149.89,-0.076
22.13,149.82,-0.108
22.14,149.73,-0.145
22.16,149.63,-0.182
22.17,149.52,-0.218
22.19,149.41,-0.248
22.20,149.30,-0.275
22.22,149.18,-0.297
22.23,149.05,-0.316
22.25,148.93,-0.334
22.26,148.80,-0.347
22.28,148.67,-0.361
22.29,148.53,-0.371
22.31,148.40,-0.381
22.32,148.26,-0.389
22.34,148.12,-0.397
22.35,147.98,-0.402
22.37,147.84,-0.410
22.38,147.70,-0.413
22.40,147.56,-0.418
22.41,147.41,-0.421
22.43,147.27,-0.426
22.44,147.12,-0.427
22.46,146.98,-0.430
22.47,146.83,-0.432
22.49,146.69,-0.433
22.50,146.54,-0.435
22.52,146.40,-0.436
22.53,146.25,-0.437
22.55,146.10,-0.438
22.56,145.96,-0.439
22.58,145.81,-0.440
22.59,145.66,-0.441
22.61,145.52,-0.441
22.62,145.37,-0.442
22.64,145.22,-0.443
22.65,145.07,-0.443
22.67,144.92,-0.443
22.68,144.78,-0.443
22.70,144.63,-0.444
22.71,144.48,-0.444
22.73,144.33,-0.444
22.74,144.18,-0.444
22.76,144.04,-0.444
22.77,143.89,-0.445
22.79,143.74,-0.445
22.80,143.59,-0.445
22.82,143.44,-0.445
22.83,143.29,-0.445
22.85,143.14,-0.445
22.86,143.00,-0.445
22.88,142.85,-0.446
22.89,142.70,-0.446
22.91,142.55,-0.446
22.92,142.40,-0.446
22.94,142.25,-0.446
22.95,142.10,-0.446
22.97,141.95,-0.446
22.98,141.80,-0.446
23.00,141.66,-0.447
23.01,141.51,-0.447
23.03,141.36,-0.447
23.04,141.21,-0.447
23.06,141.06,-0.447
23.07,140.91,-0.447
23.09,140.76,-0.447
23.10,140.61,-0.447
23.12,140.46,-0.447
23.13,140.31,-0.447
23.15,140.16,-0.447
23.16,140.01,-0.447
23.18,139.86,-0.447
23.19,139.71,-0.447
23.21,139.56,-0.447
23.22,139.41,-0.447
23.24,139.27,-0.447
23.25,139.12,-0.447
23.27,138.97,-0.447
23.28,138.82,-0.447
23.30,138.67,-0.447
23.31,138.52,-0.447
23.33,138.37,-0.447
23.34,138.22,-0.447
23.36,138.07,-0.447
23.37,137.92,-0.447
23.39,137.77,-0.447
23.40,137.62,-0.447
23.42,137.47,-0.447
23.43,137.32,-0.447
23.45,137.17,-0.447
23.46,137.02,-0.447
23.48,136.87,-0.447
23.49,136.72,-0.446
23.51,136.57,-0.446
23.52,136.42,-0.446
23.54,136.27,-0.446
23.55,136.12,-0.446
23.57,135.97,-0.446
23.58,135.82,-0.446
23.60,135.68,-0.446
23.61,135.53,-0.446
23.63,135.38,-0.446
23.64,135.23,-0.446
23.66,135.08,-0.445
23.67,134.93,-0.445
23.69,134.78,-0.445
23.70,134.63,-0.445
23.72,134.48,-0.445
23.73,134.33,-0.445
23.75,134.18,-0.445
23.76,134.03,-0.445
23.78,133.88,-0.445
23.79,133.73,-0.445
23.81,133.58,-0.445
23.82,133.43,-0.445
23.84,133.28,-0.444
23.85,133.13,-0.444
23.87,132.98,-0.444
23.88,132.83,-0.444
23.90,132.68,-0.444
23.91,132.53,-0.444
23.93,132.38,-0.444
23.94,132.23,-0.444
23.96,132.08,-0.444
23.97,131.93,-0.444
23.99,131.78,-0.444
24.00,131.63,-0.443
24.02,131.48,-0.443
24.03,131.33,-0.443
24.05,131.18,-0.443
24.06,131.03,-0.443
24.08,130.88,-0.443
24.09,130.73,-0.443
24.11,130.58,-0.443
24.12,130.43,-0.443
24.14,130.29,-0.442
24.15,130.14,-0.442
24.17,129.99,-0.442
24.18,129.84,-0.442
24.20,129.69,-0.442
24.21,129.54,-0.442
24.23,129.39,-0.442
24.24,129.24,-0.442
24.26,129.09,-0.442
24.27,128.94,-0.441
24.29,128.79,-0.441
24.30,128.64,-0.441
24.32,128.49,-0.441
24.33,128.34,-0.441
24.35,128.19,-0.441
24.36,128.04,-0.441
24.38,127.89,-0.441
24.39,127.74,-0.441
24.41,127.59,-0.441
24.42,127.44,-0.440
24.44,127.29,-0.440
24.45,127.14,-0.440
24.47,126.99,-0.440
24.48,126.84,-0.440
24.50,126.69,-0.440
24.51,126.54,-0.440
24.53,126.39,-0.440
24.54,126.24,-0.440
24.56,126.09,-0.440
24.57,125.94,-0.439
24.59,125.79,-0.439
24.60,125.64,-0.439
24.62,125.49,-0.439
24.63,125.34,-0.439
24.65,125.19,-0.439
24.66,125.04,-0.439
24.68,124.89,-0.439
24.69,124.74,-0.438
24.71,124.59,-0.438
24.72,124.44,-0.438
24.74,124.29,-0.438
24.75,124.14,-0.438
24.77,123.99,-0.438
24.78,123.84,-0.438
24.80,123.69,-0.438
24.81,123.54,-0.438
24.83,123.39,-0.438
24.84,123.24,-0.437
24.86,123.09,-0.437
24.87,122.94,-0.437
24.89,122.79,-0.437
24.90,122.64,-0.437
24.92,122.49,-0.437
24.93,122.34,-0.437
24.95,122.20,-0.437
24.96,122.04,-0.436
24.98,121.90,-0.436
24.99,121.75,-0.436
25.01,121.60,-0.436
25.02,121.45,-0.436
25.04,121.30,-0.436
25.05,121.15,-0.436
25.07,121.00,-0.436
25.08,120.85,-0.436
25.10,120.70,-0.435
25.11,120.55,-0.435
25.13,120.40,-0.435
25.14,120.25,-0.435
25.16,120.10,-0.435
25.17,119.95,-0.435
25.19,119.80,-0.435
25.20,119.65,-0.435
25.22,119.50,-0.435
25.23,119.35,-0.435
25.25,119.20,-0.435
25.26,119.05,-0.435
25.28,118.90,-0.434
25.29,118.75,-0.434
25.31,118.60,-0.434
25.32,118.45,-0.434
25.34,118.30,-0.434
25.35,118.15,-0.434
25.37,118.00,-0.434
25.38,117.85,-0.434
25.40,117.70,-0.434
25.41,117.55,-0.434
25.43,117.40,-0.433
25.44,117.25,-0.433
25.46,117.10,-0.433
25.47,116.95,-0.433
25.49,116.80,-0.433
25.50,116.65,-0.433
25.52,116.50,-0.433
25.53,116.35,-0.433
25.55,116.20,-0.433
25.56,116.05,-0.433
25.58,115.90,-0.432
25.59,115.75,-0.432
25.61,115.60,-0.432
25.62,115.45,-0.432
25.64,115.30,-0.432
25.65,115.15,-0.432
25.67,115.00,-0.432
25.68,114.85,-0.432
25.70,114.70,-0.432
25.71,114.55,-0.432
25.73,114.40,-0.431
25.74,114.25,-0.431
25.76,114.10,-0.431
25.77,113.95,-0.431
25.79,113.80,-0.431
25.80,113.65,-0.431
25.82,113.50,-0.431
25.83,113.35,-0.431
25.85,113.21,-0.431
25.86,113.05,-0.430
25.88,112.91,-0.430
25.89,112.75,-0.430
25.91,112.61,-0.430
25.92,112.46,-0.430
25.94,112.31,-0.430
25.95,112.16,-0.430
25.97,112.01,-0.430
25.98,111.86,-0.430
26.00,111.71,-0.430
26.01,111.56,-0.430
26.03,111.41,-0.429
26.04,111.26,-0.429
26.06,111.11,-0.429
26.07,110.96,-0.429
26.09,110.81,-0.429
26.10,110.66,-0.429
26.12,110.51,-0.429
26.13,110.36,-0.429
26.15,110.21,-0.429
26.16,110.06,-0.429
26.18,109.91,-0.429
26.19,109.76,-0.428
26.21,109.61,-0.428
26.22,109.46,-0.428
26.24,109.31,-0.428
26.25,109.16,-0.428
26.27,109.01,-0.428
26.28,108.86,-0.428
26.30,108.71,-0.428
26.31,108.56,-0.428
26.33,108.41,-0.428
26.34,108.26,-0.428
26.36,108.11,-0.428
26.37,107.96,-0.427
26.39,107.81,-0.427
26.40,107.66,-0.427
26.42,107.51,-0.427
26.43,107.36,-0.427
26.45,107.21,-0.427
26.46,107.06,-0.427
26.48,106.91,-0.427
26.49,106.76,-0.427
26.51,106.61,-0.427
26.52,106.46,-0.426
26.54,106.31,-0.426
26.55,106.16,-0.426
26.57,106.01,-0.426
26.58,105.86,-0.426
26.60,105.71,-0.426
26.61,105.56,-0.426
26.63,105.41,-0.426
26.64,105.26,-0.426
26.66,105.11,-0.426
26.67,104.96,-0.426
26.69,104.81,-0.426
26.70,104.66,-0.425
26.72,104.51,-0.425
26.73,104.36,-0.425
26.75,104.21,-0.425
26.76,104.07,-0.425
26.78,103.91,-0.425
26.79,103.76,-0.425
26.81,103.62,-0.425
26.82,103.47,-0.425
26.84,103.32,-0.425
26.85,103.17,-0.425
26.87,103.02,-0.425
26.88,102.87,-0.424
26.90,102.72,-0.424
26.91,102.57,-0.424
26.93,102.42,-0.424
26.94,102.27,-0.424
26.96,102.12,-0.424
26.97,101.97,-0.424
26.99,101.82,-0.424
27.00,101.67,-0.424
27.02,101.52,-0.424
27.03,101.37,-0.424
27.05,101.22,-0.424
27.06,101.07,-0.424
27.08,100.92,-0.423
27.09,100.77,-0.423
27.11,100.62,-0.423
27.12,100.47,-0.423
27.14,100.32,-0.423
27.15,100.17,-0.423
27.17,100.02,-0.423
27.18,99.87,-0.423
27.20,99.72,-0.423
27.21,99.57,-0.422
27.23,99.42,-0.422
27.24,99.27,-0.422
27.26,99.12,-0.422
27.27,98.97,-0.422
27.29,98.82,-0.422
27.30,98.67,-0.422
27.32,98.52,-0.422
27.33,98.37,-0.422
27.35,98.22,-0.422
27.36,98.07,-0.422
27.38,97.92,-0.422
27.39,97.77,-0.422
27.41,97.62,-0.421
27.42,97.47,-0.421
27.44,97.32,-0.421
27.45,97.17,-0.421
27.47,97.02,-0.421
27.48,96.87,-0.421
27.50,96.72,-0.421
27.51,96.57,-0.421
27.53,96.42,-0.421
27.54,96.27,-0.420
27.56,96.12,-0.420
27.57,95.97,-0.420
27.59,95.82,-0.420
27.60,95.67,-0.420
27.62,95.53,-0.420
27.63,95.38,-0.420
27.65,95.23,-0.420
27.66,95.08,-0.420
27.68,94.93,-0.420
27.69,94.78,-0.419
27.71,94.63,-0.419
27.72,94.48,-0.419
27.74,94.33,-0.419
27.75,94.18,-0.419
27.77,94.03,-0.419
27.78,93.88,-0.419
27.80,93.73,-0.418
27.81,93.58,-0.418
27.83,93.43,-0.418
27.84,93.28,-0.418
27.86,93.13,-0.418
27.87,92.98,-0.418
27.89,92.83,-0.418
27.90,92.68,-0.418
27.92,92.53,-0.418
27.93,92.38,-0.418
27.95,92.23,-0.417
27.96,92.08,-0.417
27.98,91.93,-0.417
27.99,91.78,-0.417
28.01,91.63,-0.417
28.02,91.48,-0.417
28.04,91.33,-0.417
28.05,91.18,-0.417
28.07,91.03,-0.417
28.08,90.88,-0.417
28.10,90.73,-0.417
28.11,90.58,-0.417
28.13,90.43,-0.416
28.14,90.28,-0.416
28.16,90.13,-0.416
28.17,89.98,-0.416
28.19,89.83,-0.416
28.20,89.68,-0.416
28.22,89.53,-0.416
28.23,89.38,-0.416
28.25,89.23,-0.415
28.26,89.08,-0.415
28.28,88.93,-0.415
28.29,88.78,-0.415
28.31,88.63,-0.415
28.32,88.48,-0.415
28.34,88.33,-0.415
28.35,88.18,-0.415
28.37,88.03,-0.415
28.38,87.88,-0.415
28.40,87.73,-0.414
28.41,87.58,-0.414
28.43,87.43,-0.414
28.44,87.29,-0.414
28.46,87.13,-0.414
28.47,86.99,-0.414
28.49,86.84,-0.414
[...]
93.05,-11.16,0.324
93.06,-11.02,0.325
93.08,-10.87,0.325
93.09,-10.72,0.325
93.11,-10.57,0.325
93.12,-10.42,0.324
93.14,-10.27,0.324
93.15,-10.12,0.323
93.17,-9.96,0.321
93.18,-9.81,0.320
93.20,-9.66,0.318
93.21,-9.51,0.315
93.23,-9.36,0.314
93.24,-9.21,0.312
93.26,-9.06,0.311
93.27,-8.91,0.310
93.29,-8.76,0.309
93.30,-8.61,0.308
93.32,-8.45,0.307
93.33,-8.30,0.306
93.35,-8.15,0.306
93.36,-8.00,0.306
93.38,-7.85,0.305
93.39,-7.70,0.305
93.41,-7.55,0.304
93.42,-7.40,0.304
93.44,-7.25,0.304
93.45,-7.10,0.303
93.47,-6.95,0.303
93.48,-6.80,0.303
93.50,-6.65,0.303
93.51,-6.50,0.303
93.53,-6.35,0.303
93.54,-6.20,0.302
93.56,-6.05,0.302
93.57,-5.90,0.302
93.59,-5.75,0.302
93.60,-5.59,0.302
93.62,-5.44,0.302
93.63,-5.29,0.302
93.65,-5.14,0.301
93.66,-4.99,0.301
93.68,-4.84,0.301
93.69,-4.69,0.301
93.71,-4.54,0.301
93.72,-4.39,0.301
93.74,-4.24,0.301
93.75,-4.09,0.301
93.77,-3.94,0.301
93.78,-3.79,0.301
93.80,-3.64,0.301
93.81,-3.49,0.301
93.83,-3.34,0.301
93.84,-3.19,0.301
93.86,-3.04,0.301
93.87,-2.89,0.301
93.89,-2.74,0.301
93.90,-2.59,0.300
93.92,-2.44,0.300
93.93,-2.29,0.300
93.95,-2.14,0.301
93.96,-1.99,0.300
93.98,-1.84,0.301
93.99,-1.69,0.301
94.01,-1.54,0.301
94.02,-1.39,0.301
94.04,-1.24,0.301
94.05,-1.09,0.301
94.07,-0.94,0.301
94.08,-0.79,0.301
94.10,-0.64,0.301
94.11,-0.49,0.301
94.13,-0.34,0.301
94.14,-0.19,0.301
94.16,-0.04,0.301
94.17,0.11,0.301
94.19,0.26,0.301
94.20,0.41,0.301
94.22,0.56,0.301
94.23,0.71,0.301
94.25,0.86,0.301
94.26,1.01,0.301
94.28,1.16,0.301
94.29,1.32,0.301
94.31,1.47,0.301
94.32,1.62,0.302
94.34,1.77,0.302
94.35,1.92,0.302
94.37,2.07,0.302
94.38,2.22,0.302
94.40,2.37,0.302
94.41,2.52,0.302
94.43,2.67,0.302
94.44,2.82,0.302
94.46,2.97,0.302
94.47,3.12,0.302
94.49,3.27,0.302
94.50,3.42,0.302
94.52,3.57,0.302
94.53,3.72,0.303
94.55,3.87,0.303
94.56,4.02,0.303
94.58,4.17,0.303
94.59,4.32,0.303
94.61,4.47,0.303
94.62,4.62,0.303
94.64,4.77,0.303
94.65,4.92,0.303
94.67,5.07,0.303
94.68,5.22,0.303
94.70,5.37,0.303
94.71,5.52,0.304
94.73,5.67,0.304
94.74,5.82,0.304
94.76,5.97,0.304
94.77,6.12,0.304
94.79,6.27,0.304
94.80,6.42,0.304
94.82,6.57,0.304
94.83,6.72,0.304
94.85,6.87,0.305
94.86,7.02,0.305
94.88,7.17,0.305
94.89,7.32,0.305
94.91,7.47,0.305
94.92,7.62,0.305
94.94,7.77,0.305
94.95,7.92,0.305
94.97,8.07,0.305
94.98,8.22,0.305
95.00,8.37,0.305
95.01,8.53,0.306
95.03,8.67,0.306
95.04,8.83,0.306
95.06,8.98,0.306
95.07,9.13,0.306
95.09,9.28,0.306
95.10,9.42,0.306
95.12,9.58,0.306
95.13,9.73,0.306
95.15,9.88,0.306
95.16,10.03,0.307
95.18,10.18,0.307
95.19,10.33,0.307
95.21,10.48,0.307
95.22,10.63,0.307
95.24,10.78,0.307
95.25,10.93,0.307
95.27,11.08,0.307
95.28,11.23,0.307
95.30,11.38,0.307
95.31,11.53,0.308
95.33,11.68,0.308
95.34,11.83,0.308
95.36,11.98,0.308
95.37,12.13,0.308
95.39,12.28,0.308
95.40,12.43,0.308
95.42,12.58,0.308
95.43,12.73,0.308
95.45,12.88,0.309
95.46,13.03,0.309
95.48,13.18,0.309
95.49,13.33,0.309
95.51,13.48,0.309
95.52,13.63,0.309
95.54,13.78,0.309
95.55,13.93,0.309
95.57,14.08,0.309
95.58,14.23,0.309
95.60,14.38,0.310
95.61,14.53,0.310
95.63,14.68,0.310
95.64,14.83,0.310
95.66,14.98,0.310
95.67,15.13,0.310
95.69,15.28,0.310
95.70,15.43,0.310
95.72,15.58,0.310
95.73,15.73,0.310
95.75,15.88,0.311
95.76,16.03,0.311
95.78,16.18,0.311
95.79,16.33,0.311
95.81,16.48,0.311
95.82,16.63,0.311
95.84,16.78,0.311
95.85,16.94,0.311
95.87,17.08,0.311
95.88,17.24,0.311
95.90,17.38,0.311
95.91,17.53,0.311
95.93,17.68,0.312
95.94,17.83,0.312
95.96,17.99,0.312
95.97,18.13,0.312
95.99,18.29,0.312
96.00,18.43,0.312
96.02,18.59,0.312
96.03,18.74,0.312
96.05,18.89,0.312
96.06,19.04,0.313
96.08,19.19,0.313
96.09,19.34,0.313
96.11,19.49,0.313
96.12,19.64,0.313
96.14,19.79,0.313
96.15,19.94,0.313
96.17,20.09,0.313
96.18,20.24,0.313
96.20,20.39,0.314
96.21,20.54,0.314
96.23,20.69,0.314
96.24,20.84,0.314
96.26,20.99,0.314
96.27,21.14,0.314
96.29,21.29,0.314
96.30,21.44,0.314
96.32,21.59,0.314
96.33,21.74,0.314
96.35,21.89,0.314
96.36,22.04,0.315
96.38,22.19,0.315
96.39,22.34,0.315
96.41,22.49,0.315
96.42,22.64,0.315
96.44,22.79,0.315
96.45,22.94,0.315
96.47,23.09,0.315
96.48,23.24,0.315
96.50,23.39,0.316
96.51,23.54,0.316
96.53,23.69,0.316
96.54,23.84,0.316
96.56,23.99,0.316
96.57,24.14,0.316
96.59,24.29,0.316
96.60,24.44,0.316
96.62,24.59,0.316
96.63,24.74,0.316
96.65,24.89,0.316
96.66,25.04,0.317
96.68,25.19,0.317
96.69,25.34,0.317
96.71,25.49,0.317
96.72,25.64,0.317
96.74,25.79,0.317
96.75,25.94,0.317
96.77,26.09,0.317
96.78,26.24,0.318
96.80,26.39,0.318
96.81,26.54,0.318
96.83,26.69,0.318
96.84,26.84,0.318
96.86,26.99,0.318
96.87,27.14,0.318
96.89,27.30,0.318
96.90,27.44,0.318
96.92,27.60,0.319
96.93,27.74,0.319
96.95,27.89,0.319
96.96,28.05,0.319
96.98,28.19,0.319
96.99,28.35,0.319
97.01,28.50,0.319
97.02,28.65,0.319
97.04,28.80,0.320
97.05,28.95,0.320
97.07,29.10,0.320
97.08,29.25,0.320
97.10,29.40,0.320
97.11,29.55,0.320
97.13,29.70,0.320
97.14,29.85,0.320
97.16,30.00,0.321
97.17,30.15,0.321
97.19,30.30,0.321
97.20,30.45,0.321
97.22,30.60,0.321
97.23,30.75,0.321
97.25,30.90,0.321
97.26,31.05,0.321
97.28,31.20,0.321
97.29,31.35,0.322
97.31,31.50,0.322
97.32,31.65,0.322
97.34,31.80,0.322
97.35,31.95,0.322
97.37,32.10,0.322
97.38,32.25,0.322
97.40,32.40,0.322
97.41,32.55,0.322
97.43,32.70,0.323
97.44,32.85,0.323
97.46,33.00,0.323
97.47,33.15,0.323
97.49,33.30,0.323
97.50,33.45,0.323
97.52,33.60,0.323
97.53,33.75,0.323
97.55,33.90,0.323
97.56,34.05,0.323
97.58,34.20,0.323
97.59,34.35,0.323
97.61,34.50,0.324
97.62,34.65,0.324
97.64,34.80,0.324
97.65,34.95,0.324
97.67,35.10,0.324
97.68,35.25,0.324
97.70,35.40,0.324
97.71,35.55,0.324
97.73,35.70,0.324
97.74,35.85,0.324
97.76,36.00,0.324
97.77,36.15,0.325
97.79,36.30,0.325
97.80,36.46,0.325
97.82,36.61,0.325
97.83,36.75,0.325
97.85,36.91,0.325
97.86,37.06,0.325
97.88,37.21,0.325
97.89,37.35,0.325
97.91,37.51,0.325
97.92,37.66,0.325
97.94,37.81,0.326
97.95,37.96,0.326
97.97,38.11,0.326
97.98,38.26,0.326
98.00,38.41,0.326
98.01,38.56,0.326
98.03,38.71,0.326
98.04,38.86,0.326
98.06,39.01,0.326
98.07,39.16,0.326
98.09,39.31,0.326
98.10,39.46,0.327
98.12,39.61,0.327
98.13,39.76,0.327
98.15,39.91,0.327
98.16,40.06,0.327
98.18,40.21,0.327
98.19,40.36,0.327
98.21,40.51,0.327
98.22,40.66,0.327
98.24,40.81,0.327
98.25,40.96,0.328
98.27,41.11,0.328
98.28,41.26,0.328
98.30,41.41,0.328
98.31,41.56,0.328
98.33,41.71,0.328
98.34,41.86,0.328
98.36,42.01,0.328
98.37,42.16,0.328
98.39,42.31,0.329
98.40,42.46,0.329
98.42,42.61,0.329
98.43,42.76,0.329
98.45,42.91,0.329
98.46,43.06,0.329
98.48,43.21,0.329
98.49,43.36,0.329
98.51,43.51,0.329
98.52,43.66,0.330
98.54,43.81,0.330
98.55,43.96,0.330
98.57,44.11,0.330
98.58,44.26,0.330
98.60,44.41,0.330
98.61,44.56,0.330
98.63,44.71,0.330
98.64,44.86,0.330
98.66,45.01,0.330
98.67,45.16,0.330
98.69,45.32,0.331
98.70,45.47,0.331
98.72,45.61,0.331
98.73,45.77,0.331
98.75,45.92,0.331
98.76,46.06,0.331
98.78,46.21,0.331
98.79,46.36,0.331
98.81,46.52,0.331
98.82,46.67,0.331
98.84,46.81,0.331
98.85,46.96,0.332
98.87,47.12,0.332
98.88,47.27,0.332
98.90,47.42,0.332
98.91,47.57,0.332
98.93,47.72,0.332
98.94,47.87,0.332
98.96,48.02,0.332
98.97,48.17,0.332
98.99,48.32,0.332
99.00,48.47,0.333
99.02,48.62,0.333
99.03,48.77,0.333
99.05,48.92,0.333
99.06,49.07,0.333
99.08,49.22,0.333
99.09,49.37,0.333
99.11,49.52,0.333
99.12,49.67,0.333
99.14,49.82,0.334
99.15,49.97,0.334
99.17,50.12,0.334
99.18,50.27,0.334
99.20,50.42,0.334
99.21,50.57,0.334
99.23,50.72,0.334
99.24,50.87,0.334
99.26,51.02,0.334
99.27,51.17,0.334
99.29,51.32,0.334
99.30,51.47,0.334
99.32,51.62,0.335
99.33,51.77,0.335
99.35,51.92,0.335
99.36,52.07,0.335
99.38,52.22,0.335
99.39,52.37,0.335
99.41,52.52,0.335
99.42,52.67,0.335
99.44,52.82,0.335
99.45,52.97,0.335
99.47,53.12,0.335
99.48,53.27,0.336
99.50,53.42,0.336
99.51,53.57,0.336
99.53,53.73,0.336
99.54,53.87,0.336
99.56,54.02,0.336
99.57,54.17,0.336
99.59,54.33,0.336
99.60,54.48,0.336
99.62,54.63,0.336
99.63,54.77,0.336
99.65,54.93,0.337
99.66,55.08,0.337
99.68,55.23,0.337
99.69,55.38,0.337
99.71,55.53,0.337
99.72,55.68,0.337
99.74,55.83,0.337
99.75,55.98,0.337
99.77,56.13,0.337
99.78,56.28,0.337
99.80,56.43,0.337
99.81,56.58,0.337
99.83,56.73,0.338
99.84,56.88,0.338
99.86,57.03,0.338
99.87,57.18,0.338
99.89,57.33,0.338
99.90,57.48,0.338
99.92,57.63,0.338
99.93,57.78,0.338
99.95,57.93,0.338
99.96,58.08,0.338
99.98,58.23,0.338
99.99,58.38,0.339
100.01,58.53,0.339
100.02,58.68,0.339
100.04,58.83,0.339
100.05,58.98,0.339
100.07,59.13,0.339
100.08,59.28,0.339
100.10,59.43,0.339
100.11,59.58,0.339
100.13,59.73,0.339
100.14,59.88,0.339
100.16,60.03,0.340
100.17,60.18,0.340
100.19,60.33,0.340
100.20,60.48,0.340
100.22,60.63,0.340
100.23,60.78,0.340
100.25,60.93,0.340
100.26,61.08,0.340
100.28,61.23,0.340
100.29,61.38,0.340
100.31,61.53,0.340
100.32,61.68,0.340
100.34,61.83,0.341
100.35,61.98,0.341
100.37,62.13,0.341
100.38,62.29,0.341
100.40,62.43,0.341
100.41,62.58,0.341
100.43,62.73,0.341
100.44,62.88,0.341
100.46,63.03,0.341
100.47,63.18,0.341
100.49,63.33,0.341
100.50,63.48,0.341
100.52,63.64,0.341
100.53,63.78,0.342
100.55,63.94,0.342
100.56,64.09,0.342
100.58,64.24,0.342
100.59,64.38,0.342
100.61,64.54,0.342
100.62,64.69,0.342
100.64,64.83,0.342
100.65,64.99,0.342
100.67,65.14,0.342
100.68,65.29,0.342
100.70,65.43,0.342
100.71,65.59,0.343
100.73,65.74,0.343
100.74,65.89,0.343
100.76,66.04,0.343
100.77,66.19,0.343
100.79,66.34,0.343
100.80,66.49,0.343
100.82,66.64,0.343
100.83,66.79,0.343
100.85,66.94,0.343
100.86,67.09,0.343
100.88,67.24,0.343
100.89,67.39,0.344
100.91,67.54,0.344
100.92,67.69,0.344
100.94,67.84,0.344
100.95,67.99,0.344
100.97,68.14,0.344
100.98,68.29,0.344
101.00,68.44,0.344
101.01,68.59,0.344
101.03,68.74,0.344
101.04,68.89,0.344
101.06,69.04,0.344
101.07,69.19,0.345
101.09,69.34,0.345
101.10,69.49,0.345
101.12,69.64,0.345
101.13,69.79,0.345
101.15,69.94,0.345
101.16,70.09,0.345
101.18,70.24,0.345
101.19,70.39,0.345
101.21,70.54,0.345
101.22,70.69,0.346
101.24,70.84,0.346
101.25,70.99,0.346
101.27,71.14,0.346
101.28,71.29,0.346
101.30,71.44,0.346
101.31,71.59,0.346
101.33,71.74,0.346
101.34,71.89,0.346
101.36,72.04,0.347
101.37,72.19,0.347
101.39,72.34,0.347
101.40,72.49,0.347
101.42,72.64,0.347
101.43,72.79,0.347
101.45,72.94,0.347
101.46,73.09,0.347
101.48,73.24,0.347
101.49,73.39,0.347
101.51,73.54,0.347
101.52,73.69,0.347
101.54,73.84,0.347
101.55,73.99,0.348
101.57,74.14,0.348
101.58,74.29,0.348
101.60,74.44,0.348
101.61,74.59,0.348
101.63,74.74,0.348
101.64,74.90,0.348
101.66,75.05,0.348
101.67,75.20,0.348
101.69,75.35,0.348
101.70,75.50,0.348
101.72,75.65,0.348
101.73,75.80,0.348
101.75,75.95,0.349
101.76,76.10,0.349
101.78,76.25,0.349
101.79,76.40,0.349
101.81,76.55,0.349
101.82,76.70,0.349
101.84,76.85,0.349
101.85,77.00,0.349
101.87,77.15,0.349
101.88,77.30,0.349
101.90,77.45,0.349
101.91,77.60,0.349
101.93,77.75,0.350
101.94,77.90,0.350
101.96,78.05,0.350
101.97,78.20,0.350
101.99,78.35,0.350
102.00,78.50,0.350
102.02,78.65,0.350
102.03,78.80,0.350
102.05,78.95,0.350
102.06,79.10,0.350
102.08,79.25,0.350
102.09,79.40,0.350
102.11,79.55,0.350
102.12,79.70,0.350
102.14,79.85,0.351
102.15,80.00,0.351
102.17,80.15,0.351
102.18,80.30,0.351
102.20,80.45,0.351
102.21,80.60,0.351
102.23,80.75,0.351
102.24,80.90,0.351
102.26,81.05,0.351
102.27,81.20,0.351
102.29,81.35,0.351
102.30,81.50,0.351
102.32,81.65,0.351
102.33,81.80,0.351
102.35,81.95,0.351
102.36,82.10,0.352
102.38,82.25,0.352
102.39,82.40,0.352
102.41,82.55,0.352
102.42,82.70,0.352
102.44,82.85,0.352
102.45,83.00,0.352
102.47,83.15,0.352
102.48,83.30,0.352
102.50,83.45,0.352
102.51,83.60,0.352
102.53,83.75,0.352
102.54,83.90,0.352
102.56,84.05,0.352
102.57,84.20,0.352
102.59,84.35,0.352
102.60,84.50,0.352
102.62,84.65,0.353
102.63,84.80,0.353
102.65,84.96,0.353
102.66,85.10,0.353
102.68,85.26,0.353
102.69,85.41,0.353
102.71,85.56,0.353
102.72,85.71,0.353
102.74,85.86,0.353
102.75,86.01,0.353
102.77,86.16,0.353
102.78,86.31,0.353
102.80,86.46,0.353
102.81,86.61,0.353
102.83,86.76,0.353
102.84,86.91,0.353
102.86,87.06,0.353
102.87,87.21,0.353
102.89,87.36,0.354
102.90,87.51,0.354
102.92,87.66,0.354
102.93,87.81,0.354
102.95,87.96,0.354
102.96,88.11,0.354
102.98,88.26,0.354
102.99,88.41,0.354
103.01,88.56,0.354
103.02,88.71,0.354
103.04,88.86,0.354
103.05,89.01,0.354
103.07,89.16,0.354
103.08,89.31,0.354
103.10,89.46,0.355
103.11,89.61,0.355
103.13,89.76,0.355
103.14,89.91,0.355
103.16,90.06,0.355
103.17,90.21,0.355
103.19,90.36,0.355
103.20,90.51,0.355
103.22,90.66,0.355
103.23,90.81,0.355
103.25,90.96,0.355
103.26,91.11,0.356
103.28,91.26,0.356
103.29,91.41,0.356
103.31,91.56,0.356
103.32,91.71,0.356
103.34,91.86,0.356
103.35,92.01,0.356
103.37,92.16,0.356
103.38,92.31,0.356
103.40,92.46,0.356
103.41,92.61,0.357
103.43,92.76,0.357
103.44,92.91,0.357
103.46,93.06,0.357
103.47,93.21,0.357
103.49,93.36,0.357
103.50,93.51,0.357
103.52,93.66,0.357
103.53,93.81,0.357
103.55,93.96,0.357
103.56,94.11,0.357
103.58,94.26,0.357
103.59,94.41,0.358
103.61,94.56,0.358
103.62,94.71,0.358
103.64,94.86,0.358
103.65,95.01,0.358
103.67,95.17,0.358
103.68,95.32,0.358
103.70,95.47,0.358
103.71,95.62,0.358
103.73,95.77,0.358
103.74,95.91,0.358
103.76,96.07,0.358
103.77,96.22,0.359
103.79,96.37,0.359
103.80,96.52,0.359
103.82,96.67,0.359
103.83,96.82,0.359
103.85,96.97,0.359
103.86,97.12,0.359
103.88,97.27,0.359
103.89,97.42,0.359
103.91,97.57,0.359
103.92,97.72,0.359
103.94,97.87,0.359
103.95,98.02,0.360
103.97,98.17,0.360
103.98,98.32,0.360
104.00,98.47,0.360
104.01,98.62,0.360
104.03,98.77,0.360
104.04,98.92,0.360
104.06,99.07,0.360
104.07,99.22,0.360
104.09,99.37,0.360
104.10,99.52,0.360
104.12,99.67,0.360
104.13,99.82,0.360
104.15,99.97,0.360
104.16,100.12,0.360
104.18,100.27,0.360
104.19,100.42,0.361
104.21,100.57,0.361
104.22,100.72,0.361
104.24,100.87,0.361
104.25,101.02,0.361
104.27,101.17,0.361
104.28,101.32,0.361
104.30,101.47,0.361
104.31,101.62,0.361
104.33,101.77,0.361
104.34,101.92,0.361
104.36,102.07,0.361
104.37,102.22,0.361
104.39,102.37,0.361
104.40,102.52,0.361
104.42,102.67,0.361
104.43,102.82,0.362
104.45,102.97,0.362
104.46,103.12,0.362
104.48,103.27,0.362
104.49,103.42,0.362
104.51,103.57,0.362
104.52,103.72,0.362
104.54,103.87,0.362
104.55,104.02,0.362
104.57,104.17,0.362
104.58,104.32,0.362
104.60,104.47,0.362
104.61,104.62,0.362
104.63,104.77,0.362
104.64,104.92,0.363
104.66,105.07,0.363
104.67,105.22,0.363
104.69,105.37,0.363
104.70,105.52,0.363
104.72,105.67,0.363
104.73,105.82,0.363
104.75,105.97,0.363
104.76,106.12,0.363
104.78,106.27,0.363
104.79,106.42,0.363
104.81,106.57,0.363
104.82,106.72,0.363
104.84,106.88,0.363
104.85,107.02,0.363
104.87,107.18,0.363
104.88,107.33,0.364
104.90,107.48,0.364
104.91,107.63,0.364
104.93,107.78,0.364
104.94,107.93,0.364
104.96,108.08,0.364
104.97,108.23,0.364
104.99,108.38,0.364
105.00,108.53,0.364
105.02,108.68,0.364
105.03,108.83,0.364
105.05,108.98,0.364
105.06,109.13,0.364
105.08,109.28,0.364
105.09,109.43,0.364
105.11,109.58,0.365
105.12,109.73,0.365
105.14,109.88,0.365
105.15,110.03,0.365
105.17,110.18,0.365
105.18,110.33,0.365
105.20,110.48,0.365
105.21,110.63,0.365
105.23,110.78,0.365
105.24,110.93,0.365
105.26,111.08,0.365
105.27,111.23,0.365
105.29,111.38,0.365
105.30,111.53,0.365
105.32,111.68,0.365
105.33,111.83,0.365
105.35,111.98,0.365
105.36,112.13,0.366
105.38,112.28,0.366
105.39,112.43,0.366
105.41,112.58,0.366
105.42,112.73,0.366
105.44,112.88,0.366
105.45,113.03,0.366
105.47,113.18,0.366
105.48,113.33,0.366
105.50,113.48,0.366
105.51,113.63,0.366
105.53,113.78,0.366
105.54,113.93,0.366
105.56,114.08,0.366
105.57,114.23,0.366
105.59,114.38,0.366
105.60,114.53,0.366
105.62,114.68,0.367
105.63,114.83,0.367
105.65,114.98,0.367
105.66,115.13,0.367
105.68,115.28,0.367
105.69,115.43,0.367
105.71,115.58,0.367
105.72,115.73,0.367
105.74,115.88,0.367
105.75,116.03,0.367
105.77,116.18,0.367
105.78,116.33,0.367
105.80,116.48,0.367
105.81,116.63,0.367
105.83,116.78,0.367
105.84,116.93,0.367
105.86,117.08,0.368
105.87,117.23,0.368
105.89,117.38,0.368
105.90,117.53,0.368
105.92,117.68,0.368
105.93,117.83,0.368
105.95,117.98,0.368
105.96,118.13,0.368
105.98,118.29,0.368
105.99,118.44,0.368
106.01,118.59,0.368
106.02,118.74,0.368
106.04,118.89,0.368
106.05,119.04,0.368
106.07,119.19,0.368
106.08,119.34,0.368
106.10,119.49,0.368
106.11,119.64,0.368
106.13,119.79,0.368
106.14,119.94,0.369
106.16,120.09,0.369
106.17,120.24,0.369
106.19,120.39,0.369
106.20,120.54,0.369
106.22,120.69,0.369
106.23,120.84,0.369
106.25,120.99,0.369
106.26,121.14,0.369
106.28,121.29,0.369
106.29,121.44,0.369
106.31,121.59,0.369
106.32,121.74,0.369
106.34,121.89,0.369
106.35,122.04,0.369
106.37,122.19,0.369
106.38,122.34,0.369
106.40,122.49,0.369
106.41,122.64,0.369
106.43,122.79,0.369
106.44,122.94,0.369
106.46,123.09,0.370
106.47,123.24,0.370
106.49,123.39,0.370
106.50,123.54,0.370
106.52,123.69,0.370
106.53,123.84,0.370
106.55,123.99,0.370
106.56,124.14,0.370
106.58,124.29,0.370
106.59,124.44,0.370
106.61,124.59,0.370
106.62,124.74,0.370
106.64,124.89,0.370
106.65,125.04,0.370
106.67,125.19,0.370
106.68,125.34,0.370
106.70,125.49,0.370
106.71,125.64,0.370
106.73,125.79,0.370
106.74,125.94,0.370
106.76,126.09,0.370
106.77,126.24,0.370
106.79,126.39,0.370
106.80,126.54,0.371
106.82,126.69,0.371
106.83,126.84,0.371
106.85,126.99,0.371
106.86,127.14,0.371
106.88,127.29,0.371
106.89,127.44,0.371
106.91,127.59,0.371
106.92,127.74,0.371
106.94,127.89,0.371
106.95,128.04,0.371
106.97,128.19,0.371
106.98,128.34,0.371
107.00,128.49,0.371
107.01,128.64,0.371
107.03,128.79,0.371
107.04,128.94,0.371
107.06,129.09,0.371
107.07,129.24,0.371
107.09,129.39,0.371
107.10,129.54,0.372
107.12,129.69,0.372
107.13,129.85,0.372
107.15,129.99,0.372
107.16,130.14,0.372
107.18,130.29,0.372
107.19,130.45,0.372
107.21,130.60,0.372
107.22,130.75,0.372
107.24,130.90,0.372
107.25,131.05,0.372
107.27,131.20,0.372
107.28,131.35,0.372
107.30,131.50,0.372
107.31,131.65,0.372
107.33,131.80,0.372
107.34,131.95,0.372
107.36,132.10,0.372
107.37,132.25,0.372
107.39,132.40,0.372
107.40,132.55,0.372
107.42,132.70,0.372
107.43,132.85,0.372
107.45,133.00,0.372
107.46,133.15,0.372
107.48,133.30,0.372
107.49,133.45,0.372
107.51,133.60,0.372
107.52,133.75,0.372
107.54,133.90,0.372
107.55,134.05,0.372
107.57,134.20,0.373
107.58,134.35,0.373
107.60,134.50,0.373
107.61,134.65,0.373
107.63,134.80,0.373
107.64,134.95,0.373
107.66,135.10,0.373
107.67,135.25,0.373
107.69,135.40,0.373
107.70,135.55,0.373
107.72,135.70,0.373
107.73,135.85,0.373
107.75,136.00,0.373
107.76,136.15,0.373
107.78,136.30,0.373
107.79,136.45,0.373
107.81,136.60,0.373
107.82,136.75,0.373
107.84,136.90,0.373
107.85,137.05,0.373
107.87,137.20,0.373
107.88,137.35,0.373
107.90,137.50,0.373
107.91,137.65,0.373
107.93,137.80,0.373
107.94,137.95,0.373
107.96,138.10,0.373
107.97,138.25,0.373
107.99,138.40,0.373
108.00,138.55,0.373
108.02,138.70,0.373
108.03,138.85,0.373
108.05,139.00,0.373
108.06,139.15,0.373
108.08,139.30,0.373
108.09,139.45,0.373
108.11,139.60,0.373
108.12,139.75,0.373
108.14,139.90,0.373
108.15,140.05,0.373
108.17,140.20,0.373
108.18,140.35,0.374
108.20,140.50,0.374
108.21,140.65,0.374
108.23,140.80,0.374
108.24,140.95,0.374
108.26,141.10,0.374
108.27,141.25,0.374
108.29,141.40,0.374
108.30,141.55,0.374
108.32,141.70,0.374
108.33,141.85,0.374
108.35,142.00,0.374
108.36,142.16,0.374
108.38,142.31,0.374
108.39,142.46,0.374
108.41,142.61,0.374
108.42,142.75,0.374
108.44,142.91,0.374
108.45,143.06,0.374
108.47,143.21,0.374
108.48,143.36,0.374
108.50,143.51,0.374
108.51,143.66,0.374
108.53,143.81,0.374
108.54,143.96,0.374
108.56,144.11,0.374
108.57,144.26,0.374
108.59,144.41,0.374
108.60,144.56,0.374
108.62,144.71,0.374
108.63,144.86,0.374
108.65,145.01,0.374
108.66,145.16,0.374
108.68,145.31,0.374
108.69,145.46,0.374
108.71,145.61,0.374
108.72,145.76,0.374
108.74,145.91,0.374
108.75,146.06,0.374
108.77,146.21,0.374
108.78,146.36,0.374
108.80,146.51,0.374
108.81,146.66,0.374
108.83,146.81,0.374
108.84,146.96,0.374
108.86,147.11,0.374
108.87,147.26,0.374
108.89,147.41,0.374
108.90,147.56,0.374
108.92,147.71,0.374
108.93,147.86,0.374
108.95,148.01,
108.96,148.16,
108.98,148.31,
108.99,,