File: DSC/2025_04_12_Proline_n60C_150C_10Cmin_x3.csv
Filename,2025_04_12_Proline_n60C_150C_10Cmin_x3
Instrument name,DSC2A-00468 (192.168.1.100)
Operator,Yarger
rundate,4/12/2025
Sample name,2025_04_12_Proline_n60C_150C_10Cmin_x3
proceduresegments,Data Off ; Equilibrate -60.00 °C; Data On ; Ramp 10.00 °C/min to 150.00 °C; Data Off ; Isothermal 1.0 min; Data On ; Ramp 10.00 °C/min to -60.00 °C; Data Off ; Isothermal 1.0 min; Data On ; Ramp 10.00 °C/min to 150.00 °C; Data Off ; Isothermal 1.0 min; Data On ; Ramp 10.00 °C/min to -60.00 °C; Data Off ; Isothermal 1.0 min; Data On ; Ramp 10.00 °C/min to 150.00 °C
[File Parameters]
Run date,4/12/2025 8:10:27 PM
Trios version,5.1.1.46572
Original File Name,
Current File Name,D:\DSC2500\JYarger\2025_04_12_Proline_n60C_150C_10Cmin_x3.tri
[Procedure]
Procedure Name,Pro_n60_150C_10Cmin_x3
Sample Name,2025_04_12_Proline_n60C_150C_10Cmin_x3
Sample Mass,3.34 mg
Reference Sample Mass,0 mg
Pan Mass,53.52 mg
Pan Number,8
Reference Pan Mass,53.32 mg
Reference Pan Number,10
Pan Type,Tzero Aluminum Hermetic
Comments,Hermetic Sealed Al DSC Consumables Pan/Lids.
Project Name,CA
Operator,Yarger
Test,Custom
Unload Max Temperature,30
Unload Min Temperature,30
Load Max Temperature,30
Load Min Temperature,30
Stop on Gas Flow Error,Yes
[Signal List]
Signal #1,Time (min)
Signal #2,Temperature (°C)
Signal #3,Heat Flow (mW)
Signal #4,Delta T (µV)
Signal #5,Delta Tzero (µV)
Signal #6,Tzero Temperature (°C)
Signal #7,Cell Purge (mL/min)
Signal #8,Heater Temp (°C)
Signal #9,Power Delivered (W)
Signal #10,Reference Junction Temperature (°C)
Signal #11,Flange Temperature (°C)
Signal #12,Heat Flow Phase (rad)
Signal #13,Total Heat Capacity (J/°C)
Signal #14,Heat Capacity (J/°C)
[Configuration]
Company Name,ASU
Instrument Name,DSC2A-00468
Instrument Type,DSC2500
Serial Number,DSC2A-00468
IP,192.168.1.100
Location of Instrument,MRRC
DisplayType,Unknown
Sample Interval ,0.1 s/pt
Selected Heat Flow,T4P
Exotherm Direction,Down
Cell Serial,DRC2-00792
Lid Type,Standard
Cooler,RCS 90
Leave Cooler on at End of Sequence,On
Gas 2,Nitrogen
Gas Selected,Channel 1
Flow Rate,50 mL/min
Secondary Purge,On
Licensed Heat Flow,Heat Flow T4P
Modulation Licensed,Yes
[Versions]
Common IDD Version,1
Cortex Version,VER 2.10.2.31
Driver,5.0.0.6
GDM Version,1.0.3.3
TouchscreenVersion,1.0.0.16145
FEP Version,1.2.1.21
FEP Bootloader,2.0.0.5
AutoSampler Version,2.1.1.26
Auto Sampler Bootloader,2.0.0.5
FCM Version,1.1.0.3
FCM Bootloader,2.0.0.5
[Experiment Logs]
Experiment Log Entry # 1,Data On set to 0
Experiment Log Entry # 3,Equilibrate Segment -60 (C) Started
Experiment Log Entry # 5,Air Cool is off.
Experiment Log Entry # 7,Data On set to 1
Experiment Log Entry # 9,Ramp Segment 10 C/min to 150 Started
Experiment Log Entry # 11,Data On set to 0
Experiment Log Entry # 13,Isothermal Segment 1 min started
Experiment Log Entry # 15,Data On set to 1
Experiment Log Entry # 17,Ramp Segment 10 C/min to -60 Started
Experiment Log Entry # 19,Data On set to 0
Experiment Log Entry # 21,Isothermal Segment 1 min started
Experiment Log Entry # 23,Data On set to 1
Experiment Log Entry # 25,Ramp Segment 10 C/min to 150 Started
Experiment Log Entry # 27,Data On set to 0
Experiment Log Entry # 29,Isothermal Segment 1 min started
Experiment Log Entry # 31,Data On set to 1
Experiment Log Entry # 33,Ramp Segment 10 C/min to -60 Started
Experiment Log Entry # 35,Data On set to 0
Experiment Log Entry # 37,Isothermal Segment 1 min started
Experiment Log Entry # 39,Data On set to 1
Experiment Log Entry # 41,Ramp Segment 10 C/min to 150 Started
[Method Log]
Method Log Entry # 1,Data Off
Method Log Entry # 2,Equilibrate -60 °C
Method Log Entry # 3,Data On
Method Log Entry # 4,(Ramp 217108) Ramp 10 °C/minute to 150 °C
Method Log Entry # 5,Data Off
Method Log Entry # 6,Isothermal 1 minutes
Method Log Entry # 7,Data On
Method Log Entry # 8,(Ramp 217112) Ramp 10 °C/minute to -60 °C
Method Log Entry # 9,Data Off
Method Log Entry # 10,Isothermal 1 minutes
Method Log Entry # 11,Data On
Method Log Entry # 12,(Ramp 217116) Ramp 10 °C/minute to 150 °C
Method Log Entry # 13,Data Off
Method Log Entry # 14,Isothermal 1 minutes
Method Log Entry # 15,Data On
Method Log Entry # 16,(Ramp 217120) Ramp 10 °C/minute to -60 °C
Method Log Entry # 17,Data Off
Method Log Entry # 18,Isothermal 1 minutes
Method Log Entry # 19,Data On
Method Log Entry # 20,(Ramp 217124) Ramp 10 °C/minute to 150 °C
Cell Serial,DRC2-00792
[T1 Calibration]
Slope,-0.008529666
Offset,9.636258
Initial Temperature,98.23
GUID,f8bfdadc-4977-4fdf-ba6d-0ba9134940c3
[TZero Calibration]
Date Applied,11/29/2022 4:06:13 PM
Description,From -89.059 °C to 396.009 °C at 20.000°C/min
Gas Type,Nitrogen
Pan Type,None
Source Files 1,C:\Users\yargerlab\Desktop\DSC Data\General\TZero_calibration_11_29_22_2nd(2).tri
Source Files 2,C:\Users\yargerlab\Desktop\DSC Data\General\TZero_calibration_11_29_22_2nd(3).tri
Delta T Offset,13.05235
Delta T Slope,-0.007271007
Delta T0 Offset,-13.69128
Delta T0 Slope,0.06063341
[Temperature Calibration]
Date Applied,11/29/2022 7:12:28 PM
Description,From 106.590 °C to 186.590 °C at 10.000°C/min
Gas Type,Nitrogen
Pan Type,Tzero Aluminum Hermetic
Source Files 1,C:\Users\yargerlab\Desktop\DSC Data\General\Indium(6).tri
Measured 1,157.391
Known 1,156.598
[Cell Constant Calibration]
Date Applied,11/29/2022 7:12:29 PM
Description,From 106.590 °C to 186.590 °C at 10.000°C/min
Gas Type,Nitrogen
Pan Type,Tzero Aluminum Hermetic
Source Files 1,C:\Users\yargerlab\Desktop\DSC Data\General\Indium(6).tri
T4P KCell,1.006051
Onset Slope,63.26126 mW/°C
[Direct Cp Calibration]
Date Applied,11/30/2022 11:04:51 AM
Description,From -79.983 °C to 298.409 °C at 10.000°C/min
Gas Type,Nitrogen
Pan Type,Tzero Aluminum Hermetic
Source Files 1,C:\Users\yargerlab\Desktop\DSC Data\General\Sapphire_Heat_Capacity_11_30_22.tri
[Rev Cp Calibration]
Date Applied,11/30/2022 1:58:51 PM
Description,From -79.996 °C to 292.812 °C at 3.000°C/min
Gas Type,Nitrogen
Pan Type,Tzero Aluminum Hermetic
Source Files 1,C:\Users\yargerlab\Desktop\DSC Data\General\Sapphire_MDSC_Calibration_11_30_22.tri
[step]
Ramp 10.00 °C/min to 150.00 °C
Time,Temperature,Heat Flow (Normalized)
min,°C,W/g
0.00,-59.70,-0.041
0.01,-59.71,-0.040
0.03,-59.71,-0.036
0.05,-59.72,-0.033
0.06,-59.71,-0.031
0.08,-59.69,-0.031
0.09,-59.67,-0.032
0.11,-59.62,-0.032
0.12,-59.57,-0.033
0.14,-59.50,-0.033
0.15,-59.42,-0.028
0.16,-59.33,-0.009
0.18,-59.23,0.008
0.19,-59.12,0.022
0.21,-59.00,0.042
0.23,-58.88,0.057
0.24,-58.76,0.070
0.26,-58.64,0.083
0.27,-58.51,0.094
0.29,-58.38,0.104
0.30,-58.24,0.113
0.31,-58.11,0.121
0.33,-57.97,0.123
0.35,-57.84,0.130
0.36,-57.70,0.136
0.38,-57.56,0.137
0.39,-57.42,0.143
0.40,-57.28,0.144
0.42,-57.13,0.147
0.44,-56.99,0.148
0.45,-56.85,0.149
0.46,-56.71,0.152
0.48,-56.56,0.153
0.50,-56.42,0.154
0.51,-56.28,0.155
0.53,-56.13,0.155
0.54,-55.98,0.156
0.55,-55.84,0.156
0.57,-55.69,0.157
0.58,-55.55,0.157
0.60,-55.40,0.158
0.62,-55.26,0.158
0.63,-55.11,0.158
0.65,-54.97,0.158
0.66,-54.82,0.159
0.68,-54.67,0.159
0.69,-54.53,0.159
0.70,-54.38,0.160
0.72,-54.23,0.160
0.73,-54.09,0.160
0.75,-53.94,0.160
0.77,-53.79,0.160
0.78,-53.64,0.161
0.80,-53.50,0.161
0.81,-53.35,0.161
0.83,-53.20,0.161
0.84,-53.05,0.161
0.85,-52.91,0.161
0.87,-52.76,0.161
0.88,-52.61,0.161
0.90,-52.46,0.161
0.92,-52.31,0.161
0.93,-52.17,0.162
0.95,-52.02,0.162
0.96,-51.87,0.162
0.98,-51.72,0.162
0.99,-51.57,0.162
1.00,-51.43,0.162
1.02,-51.28,0.162
1.03,-51.13,0.162
1.05,-50.98,0.162
1.07,-50.83,0.162
1.08,-50.68,0.162
1.09,-50.53,0.162
1.11,-50.39,0.162
1.13,-50.24,0.162
1.14,-50.09,0.162
1.16,-49.94,0.162
1.17,-49.79,0.162
1.18,-49.64,0.162
1.20,-49.49,0.162
1.22,-49.34,0.162
1.23,-49.19,0.162
1.24,-49.04,0.162
1.26,-48.89,0.162
1.28,-48.75,0.162
1.29,-48.59,0.162
1.31,-48.45,0.162
1.32,-48.30,0.162
1.33,-48.15,0.162
1.35,-48.00,0.162
1.37,-47.85,0.162
1.38,-47.70,0.162
1.39,-47.55,0.161
1.41,-47.40,0.162
1.43,-47.25,0.162
1.44,-47.10,0.161
1.46,-46.95,0.161
1.47,-46.80,0.161
1.48,-46.65,0.161
1.50,-46.50,0.161
1.52,-46.35,0.161
1.53,-46.20,0.161
1.54,-46.05,0.161
1.56,-45.90,0.161
1.58,-45.75,0.161
1.59,-45.60,0.161
1.61,-45.45,0.161
1.62,-45.30,0.161
1.63,-45.15,0.161
1.65,-45.00,0.161
1.67,-44.85,0.161
1.68,-44.70,0.161
1.69,-44.56,0.161
1.71,-44.41,0.161
1.73,-44.26,0.161
1.74,-44.11,0.161
1.76,-43.96,0.161
1.77,-43.81,0.161
1.78,-43.66,0.161
1.80,-43.51,0.161
1.82,-43.36,0.161
1.83,-43.21,0.161
1.84,-43.06,0.161
1.86,-42.91,0.161
1.88,-42.76,0.161
1.89,-42.61,0.161
1.91,-42.46,0.161
1.92,-42.31,0.161
1.93,-42.16,0.161
1.95,-42.01,0.161
1.97,-41.86,0.161
1.98,-41.71,0.161
1.99,-41.55,0.161
2.01,-41.41,0.161
2.03,-41.25,0.161
2.04,-41.11,0.160
2.06,-40.95,0.161
2.07,-40.81,0.161
2.08,-40.66,0.160
2.10,-40.50,0.161
2.12,-40.36,0.160
2.13,-40.21,0.160
2.14,-40.05,0.160
2.16,-39.90,0.160
2.18,-39.75,0.160
2.19,-39.60,0.160
2.21,-39.46,0.160
2.22,-39.30,0.160
2.24,-39.15,0.160
2.25,-39.00,0.160
2.26,-38.85,0.160
2.28,-38.70,0.160
2.29,-38.55,0.160
2.31,-38.40,0.160
2.33,-38.25,0.160
2.34,-38.10,0.160
2.36,-37.95,0.160
2.37,-37.80,0.160
2.39,-37.65,0.160
2.40,-37.50,0.160
2.41,-37.35,0.160
2.43,-37.20,0.160
2.44,-37.05,0.160
2.46,-36.90,0.160
2.48,-36.75,0.160
2.49,-36.60,0.160
2.51,-36.45,0.160
2.52,-36.30,0.160
2.54,-36.15,0.160
2.55,-36.00,0.160
2.56,-35.85,0.160
2.58,-35.70,0.160
2.59,-35.55,0.160
2.61,-35.40,0.160
2.63,-35.25,0.160
2.64,-35.10,0.160
2.66,-34.95,0.160
2.67,-34.80,0.160
2.69,-34.65,0.160
2.70,-34.50,0.160
2.71,-34.35,0.160
2.73,-34.20,0.160
2.74,-34.05,0.160
2.76,-33.90,0.160
2.78,-33.75,0.160
2.79,-33.60,0.160
2.81,-33.45,0.160
2.82,-33.30,0.160
2.84,-33.15,0.160
2.85,-33.00,0.160
2.86,-32.85,0.160
2.88,-32.70,0.160
2.89,-32.55,0.160
2.91,-32.39,0.160
2.93,-32.25,0.160
2.94,-32.09,0.160
2.96,-31.95,0.160
2.97,-31.79,0.160
2.99,-31.65,0.160
3.00,-31.50,0.160
3.01,-31.34,0.160
3.03,-31.19,0.160
3.04,-31.04,0.160
3.06,-30.89,0.160
3.08,-30.74,0.160
3.09,-30.59,0.160
3.11,-30.44,0.160
3.12,-30.29,0.160
3.14,-30.14,0.160
3.15,-29.99,0.160
3.16,-29.84,0.160
3.18,-29.69,0.160
3.19,-29.54,0.160
3.21,-29.39,0.160
3.23,-29.24,0.160
3.24,-29.09,0.160
3.26,-28.94,0.160
3.27,-28.79,0.160
3.29,-28.64,0.160
3.30,-28.49,0.160
3.31,-28.34,0.160
3.33,-28.19,0.160
3.34,-28.04,0.160
3.36,-27.89,0.160
3.38,-27.74,0.160
3.39,-27.59,0.160
3.41,-27.44,0.160
3.42,-27.29,0.160
3.44,-27.14,0.160
3.45,-26.99,0.160
3.46,-26.84,0.160
3.48,-26.69,0.160
3.49,-26.54,0.160
3.51,-26.39,0.160
3.53,-26.24,0.160
3.54,-26.09,0.160
3.56,-25.94,0.160
3.57,-25.78,0.160
3.59,-25.64,0.160
3.60,-25.49,0.160
3.61,-25.34,0.160
3.63,-25.19,0.160
3.64,-25.04,0.160
3.66,-24.89,0.160
3.68,-24.74,0.160
3.69,-24.58,0.160
3.71,-24.44,0.160
3.72,-24.28,0.160
3.74,-24.13,0.160
3.75,-23.98,0.160
3.76,-23.83,0.160
3.78,-23.68,0.160
3.79,-23.53,0.160
3.81,-23.38,0.160
3.83,-23.23,0.161
3.84,-23.08,0.160
3.86,-22.93,0.160
3.87,-22.78,0.161
3.89,-22.63,0.160
3.90,-22.48,0.160
3.91,-22.33,0.161
3.93,-22.18,0.161
3.94,-22.03,0.161
3.96,-21.88,0.161
3.98,-21.73,0.161
3.99,-21.58,0.161
4.01,-21.43,0.161
4.02,-21.28,0.161
4.04,-21.13,0.161
4.05,-20.98,0.161
4.06,-20.83,0.161
4.08,-20.68,0.161
4.09,-20.53,0.161
4.11,-20.38,0.161
4.13,-20.23,0.161
4.14,-20.08,0.161
4.16,-19.93,0.161
4.17,-19.78,0.161
4.19,-19.63,0.161
4.20,-19.48,0.161
4.21,-19.33,0.161
4.23,-19.18,0.161
4.24,-19.03,0.161
4.26,-18.88,0.161
4.28,-18.73,0.161
4.29,-18.58,0.161
4.30,-18.43,0.161
4.32,-18.28,0.161
4.34,-18.13,0.161
4.35,-17.98,0.161
4.36,-17.83,0.161
4.38,-17.68,0.161
4.40,-17.53,0.161
4.41,-17.38,0.161
4.43,-17.23,0.161
4.44,-17.08,0.161
4.45,-16.93,0.161
4.47,-16.78,0.161
4.49,-16.63,0.161
4.50,-16.47,0.161
4.51,-16.33,0.161
4.53,-16.17,0.161
4.55,-16.02,0.161
4.56,-15.88,0.161
4.58,-15.72,0.161
4.59,-15.57,0.161
4.60,-15.42,0.161
4.62,-15.27,0.161
4.64,-15.12,0.161
4.65,-14.97,0.161
4.66,-14.82,0.161
4.68,-14.67,0.161
4.70,-14.52,0.161
4.71,-14.37,0.161
4.73,-14.22,0.161
4.74,-14.07,0.161
4.75,-13.92,0.162
4.77,-13.77,0.162
4.79,-13.62,0.161
4.80,-13.47,0.162
4.81,-13.32,0.162
4.83,-13.17,0.162
4.85,-13.02,0.162
4.86,-12.87,0.162
4.88,-12.72,0.162
4.89,-12.57,0.162
4.90,-12.42,0.162
4.92,-12.27,0.162
4.94,-12.12,0.162
4.95,-11.97,0.162
4.96,-11.82,0.162
4.98,-11.67,0.162
5.00,-11.52,0.162
5.01,-11.37,0.162
5.03,-11.22,0.162
5.04,-11.07,0.162
5.05,-10.92,0.162
5.07,-10.77,0.162
5.09,-10.62,0.162
5.10,-10.47,0.162
5.11,-10.32,0.162
5.13,-10.17,0.162
5.15,-10.02,0.162
5.16,-9.87,0.162
5.18,-9.72,0.162
5.19,-9.57,0.162
5.20,-9.42,0.162
5.22,-9.27,0.162
5.24,-9.12,0.162
5.25,-8.97,0.162
5.26,-8.82,0.162
5.28,-8.67,0.162
5.30,-8.52,0.162
5.31,-8.37,0.162
5.33,-8.22,0.163
5.34,-8.07,0.163
5.35,-7.92,0.163
5.37,-7.77,0.163
5.39,-7.61,0.163
5.40,-7.47,0.163
5.41,-7.31,0.163
5.43,-7.16,0.163
5.45,-7.01,0.163
5.46,-6.87,0.163
5.48,-6.71,0.163
5.49,-6.56,0.163
5.50,-6.41,0.163
5.52,-6.26,0.163
5.54,-6.11,0.163
5.55,-5.96,0.163
5.56,-5.81,0.163
5.58,-5.66,0.163
5.60,-5.51,0.163
5.61,-5.36,0.163
5.63,-5.21,0.163
5.64,-5.06,0.163
5.65,-4.91,0.164
5.67,-4.76,0.164
5.69,-4.61,0.164
5.70,-4.46,0.164
5.71,-4.31,0.164
5.73,-4.16,0.164
5.75,-4.01,0.164
5.76,-3.86,0.164
5.78,-3.71,0.164
5.79,-3.56,0.164
5.80,-3.41,0.164
5.82,-3.26,0.164
5.84,-3.11,0.164
5.85,-2.96,0.164
5.86,-2.81,0.164
5.88,-2.66,0.164
5.90,-2.51,0.164
5.91,-2.36,0.164
5.93,-2.21,0.164
5.94,-2.06,0.164
5.95,-1.91,0.165
5.97,-1.76,0.165
5.99,-1.61,0.165
6.00,-1.46,0.165
6.01,-1.31,0.165
6.03,-1.16,0.165
6.05,-1.01,0.165
6.06,-0.86,0.165
6.08,-0.71,0.165
6.09,-0.56,0.165
6.10,-0.40,0.165
6.12,-0.26,0.165
6.14,-0.11,0.165
6.15,0.05,0.165
6.16,0.19,0.165
6.18,0.35,0.165
6.20,0.49,0.165
6.21,0.65,0.165
6.23,0.80,0.165
6.24,0.95,0.165
6.25,1.10,0.165
6.27,1.25,0.165
6.29,1.40,0.166
6.30,1.55,0.166
6.31,1.70,0.166
6.33,1.85,0.166
6.35,2.00,0.166
6.36,2.15,0.166
6.38,2.30,0.166
6.39,2.45,0.166
6.40,2.60,0.166
6.42,2.75,0.166
6.44,2.90,0.166
6.45,3.05,0.166
6.46,3.20,0.166
6.48,3.35,0.166
6.50,3.50,0.166
6.51,3.65,0.166
6.53,3.80,0.166
6.54,3.95,0.166
6.55,4.10,0.166
6.57,4.25,0.166
6.59,4.40,0.166
6.60,4.55,0.166
6.61,4.70,0.167
6.63,4.85,0.167
6.65,5.00,0.167
6.66,5.15,0.167
6.68,5.30,0.167
6.69,5.45,0.167
6.70,5.60,0.167
6.72,5.75,0.167
6.74,5.90,0.167
6.75,6.05,0.167
6.76,6.20,0.167
6.78,6.35,0.167
6.80,6.50,0.167
6.81,6.65,0.168
6.83,6.80,0.168
6.84,6.95,0.168
6.85,7.10,0.168
6.87,7.25,0.168
6.89,7.40,0.168
6.90,7.55,0.168
6.91,7.70,0.168
6.93,7.85,0.168
6.95,8.00,0.168
6.96,8.15,0.168
6.98,8.30,0.168
6.99,8.45,0.168
7.00,8.60,0.168
7.02,8.75,0.169
7.04,8.90,0.169
7.05,9.05,0.169
7.06,9.20,0.169
7.08,9.36,0.169
7.10,9.50,0.169
7.11,9.66,0.169
7.13,9.81,0.169
7.14,9.96,0.169
7.15,10.11,0.169
7.17,10.26,0.170
7.19,10.41,0.170
7.20,10.56,0.170
7.21,10.71,0.170
7.23,10.86,0.170
7.25,11.01,0.170
7.26,11.16,0.170
7.28,11.31,0.170
7.29,11.46,0.170
7.30,11.61,0.170
7.32,11.76,0.170
7.34,11.91,0.170
7.35,12.06,0.171
7.36,12.21,0.171
7.38,12.36,0.171
7.40,12.51,0.171
7.41,12.66,0.171
7.43,12.81,0.171
7.44,12.96,0.171
7.45,13.11,0.171
7.47,13.26,0.171
7.49,13.41,0.171
7.50,13.56,0.171
7.51,13.71,0.172
7.53,13.86,0.172
7.55,14.01,0.172
7.56,14.16,0.172
7.58,14.31,0.172
7.59,14.46,0.172
7.60,14.61,0.172
7.62,14.76,0.172
7.64,14.91,0.172
7.65,15.06,0.172
7.66,15.21,0.172
7.68,15.36,0.173
7.70,15.51,0.173
7.71,15.66,0.173
7.73,15.81,0.173
7.74,15.96,0.173
7.75,16.11,0.173
7.77,16.26,0.173
7.79,16.41,0.173
7.80,16.56,0.173
7.81,16.71,0.173
7.83,16.86,0.174
7.85,17.01,0.174
7.86,17.16,0.174
7.88,17.31,0.174
7.89,17.46,0.174
7.90,17.61,0.174
7.92,17.76,0.174
7.94,17.91,0.174
7.95,18.06,0.174
7.96,18.21,0.174
7.98,18.36,0.174
8.00,18.51,0.174
8.01,18.67,0.174
8.03,18.82,0.174
8.04,18.97,0.175
8.05,19.12,0.175
8.07,19.27,0.175
8.09,19.42,0.175
8.10,19.56,0.175
8.11,19.72,0.175
8.13,19.87,0.176
8.15,20.02,0.176
8.16,20.17,0.176
8.18,20.32,0.176
8.19,20.47,0.176
8.20,20.62,0.176
8.22,20.77,0.176
8.24,20.92,0.177
8.25,21.07,0.177
8.26,21.22,0.177
8.28,21.37,0.177
8.30,21.52,0.177
8.31,21.67,0.177
8.33,21.82,0.177
8.34,21.97,0.177
8.35,22.12,0.177
8.37,22.27,0.178
8.39,22.42,0.178
8.40,22.57,0.178
8.41,22.72,0.178
8.43,22.87,0.178
8.45,23.02,0.178
8.46,23.17,0.178
8.48,23.32,0.178
8.49,23.47,0.178
8.50,23.62,0.179
8.52,23.77,0.179
8.53,23.92,0.179
8.55,24.07,0.179
8.57,24.22,0.179
8.58,24.37,0.179
8.60,24.52,0.179
8.61,24.67,0.179
8.63,24.82,0.179
8.64,24.97,0.179
8.65,25.12,0.179
8.67,25.27,0.179
8.68,25.42,0.179
8.70,25.57,0.179
8.72,25.72,0.179
8.73,25.87,0.179
8.75,26.02,0.179
8.76,26.17,0.179
8.78,26.32,0.179
8.79,26.47,0.180
8.80,26.62,0.180
8.82,26.77,0.180
8.83,26.92,0.180
8.85,27.07,0.180
8.87,27.22,0.180
8.88,27.37,0.180
8.90,27.52,0.180
8.91,27.67,0.180
8.93,27.82,0.180
8.94,27.97,0.180
8.95,28.12,0.181
8.97,28.27,0.181
8.98,28.42,0.181
9.00,28.57,0.181
9.02,28.72,0.181
9.03,28.88,0.181
9.05,29.02,0.181
9.06,29.18,0.181
9.08,29.32,0.181
9.09,29.48,0.181
9.10,29.62,0.181
9.12,29.78,0.181
9.13,29.93,0.181
9.15,30.08,0.181
9.17,30.23,0.182
9.18,30.38,0.182
9.20,30.53,0.182
9.21,30.68,0.182
9.23,30.83,0.182
9.24,30.98,0.182
9.25,31.13,0.182
9.27,31.28,0.182
9.28,31.43,0.182
9.30,31.58,0.182
9.32,31.73,0.182
9.33,31.88,0.182
9.35,32.03,0.182
9.36,32.18,0.182
9.38,32.33,0.182
9.39,32.48,0.183
9.40,32.63,0.183
9.42,32.78,0.183
9.43,32.93,0.183
9.45,33.08,0.183
9.47,33.23,0.183
9.48,33.38,0.183
9.50,33.53,0.183
9.51,33.68,0.183
9.53,33.83,0.183
9.54,33.98,0.183
9.55,34.13,0.183
9.57,34.28,0.183
9.58,34.43,0.183
9.60,34.58,0.183
9.62,34.73,0.183
9.63,34.88,0.183
9.65,35.03,0.183
9.66,35.18,0.184
9.68,35.33,0.184
9.69,35.48,0.184
9.70,35.63,0.184
9.72,35.78,0.184
9.73,35.93,0.184
9.75,36.08,0.184
9.77,36.23,0.184
9.78,36.38,0.184
9.80,36.53,0.184
9.81,36.68,0.184
9.83,36.83,0.184
9.84,36.98,0.184
9.85,37.13,0.184
9.87,37.28,0.184
9.88,37.43,0.185
9.90,37.58,0.185
9.92,37.73,0.185
9.93,37.88,0.185
9.95,38.03,0.185
9.96,38.19,0.185
9.98,38.34,0.185
9.99,38.49,0.185
10.00,38.64,0.185
10.02,38.79,0.185
10.03,38.94,0.185
10.05,39.09,0.185
10.07,39.24,0.185
10.08,39.39,0.185
10.10,39.54,0.185
10.11,39.69,0.186
10.13,39.84,0.186
10.14,39.99,0.186
10.15,40.14,0.186
10.17,40.29,0.186
10.18,40.44,0.186
10.20,40.59,0.186
10.22,40.74,0.186
10.23,40.89,0.186
10.25,41.04,0.186
10.26,41.19,0.186
10.28,41.34,0.187
10.29,41.49,0.187
10.30,41.64,0.187
10.32,41.79,0.187
10.33,41.94,0.187
10.35,42.09,0.187
10.37,42.24,0.187
10.38,42.39,0.187
10.40,42.54,0.187
10.41,42.69,0.187
10.43,42.84,0.187
10.44,42.99,0.187
10.45,43.14,0.187
10.47,43.29,0.187
10.48,43.44,0.188
10.50,43.59,0.188
10.52,43.74,0.188
10.53,43.89,0.188
10.55,44.04,0.188
10.56,44.19,0.188
10.58,44.34,0.188
10.59,44.49,0.188
10.60,44.64,0.188
10.62,44.79,0.188
10.63,44.94,0.189
10.65,45.09,0.189
10.67,45.24,0.189
10.68,45.39,0.189
10.70,45.54,0.189
10.71,45.69,0.189
10.73,45.84,0.189
10.74,45.99,0.189
10.75,46.14,0.189
10.77,46.29,0.189
10.78,46.44,0.190
10.80,46.59,0.190
10.82,46.74,0.190
10.83,46.90,0.190
10.85,47.05,0.190
10.86,47.20,0.190
10.88,47.35,0.190
10.89,47.50,0.190
10.90,47.65,0.190
10.92,47.80,0.190
10.93,47.95,0.191
10.95,48.10,0.191
10.97,48.25,0.191
10.98,48.40,0.191
11.00,48.55,0.191
11.01,48.70,0.191
11.03,48.85,0.191
11.04,49.00,0.191
11.05,49.15,0.191
11.07,49.30,0.191
11.08,49.45,0.192
11.10,49.60,0.192
11.12,49.75,0.192
11.13,49.90,0.192
11.15,50.05,0.192
11.16,50.20,0.192
11.18,50.35,0.192
11.19,50.50,0.192
11.20,50.65,0.192
11.22,50.80,0.192
11.23,50.95,0.193
11.25,51.10,0.193
11.27,51.25,0.193
11.28,51.40,0.193
11.30,51.55,0.193
11.31,51.70,0.193
11.33,51.85,0.193
11.34,52.00,0.193
11.35,52.15,0.193
11.37,52.30,0.193
11.38,52.45,0.194
11.40,52.60,0.194
11.42,52.75,0.194
11.43,52.90,0.194
11.45,53.05,0.194
11.46,53.20,0.194
11.48,53.35,0.194
11.49,53.50,0.194
11.50,53.65,0.194
11.52,53.80,0.195
11.53,53.95,0.195
11.55,54.10,0.195
11.57,54.25,0.195
11.58,54.40,0.195
11.60,54.55,0.195
11.61,54.70,0.195
11.63,54.85,0.195
11.64,55.00,0.196
11.65,55.15,0.196
11.67,55.30,0.196
11.68,55.45,0.196
11.70,55.60,0.196
11.72,55.75,0.196
11.73,55.90,0.196
11.75,56.05,0.196
11.76,56.20,0.196
11.78,56.35,0.196
11.79,56.50,0.196
11.80,56.65,0.197
11.82,56.80,0.197
11.83,56.95,0.197
11.85,57.10,0.197
11.87,57.25,0.197
11.88,57.41,0.197
11.90,57.56,0.197
11.91,57.71,0.197
11.93,57.86,0.198
11.94,58.01,0.198
11.95,58.16,0.198
11.97,58.31,0.198
11.98,58.46,0.198
12.00,58.61,0.198
12.02,58.76,0.198
12.03,58.91,0.198
12.05,59.06,0.198
12.06,59.21,0.199
12.08,59.36,0.199
12.09,59.51,0.199
12.10,59.66,0.199
12.12,59.81,0.199
12.13,59.96,0.199
12.15,60.11,0.199
12.17,60.26,0.199
12.18,60.41,0.200
12.20,60.56,0.200
12.21,60.71,0.200
12.23,60.86,0.200
12.24,61.01,0.200
12.25,61.16,0.200
12.27,61.31,0.200
12.28,61.46,0.200
12.30,61.61,0.200
12.32,61.76,0.200
12.33,61.91,0.200
12.35,62.06,0.200
12.36,62.21,0.200
12.38,62.36,0.200
12.39,62.51,0.200
12.40,62.66,0.200
12.42,62.81,0.200
12.43,62.96,0.201
12.45,63.11,0.201
12.47,63.26,0.201
12.48,63.41,0.201
12.50,63.56,0.201
12.51,63.71,0.201
12.53,63.86,0.201
12.54,64.01,0.202
12.55,64.16,0.202
12.57,64.31,0.202
12.58,64.46,0.202
12.60,64.61,0.202
12.62,64.76,0.202
12.63,64.91,0.202
12.65,65.06,0.203
12.66,65.21,0.203
12.68,65.36,0.203
12.69,65.51,0.203
12.70,65.66,0.203
12.72,65.81,0.203
12.73,65.96,0.203
12.75,66.11,0.203
12.77,66.26,0.203
12.78,66.41,0.203
12.80,66.56,0.204
12.81,66.71,0.204
12.83,66.86,0.204
12.84,67.01,0.204
12.85,67.16,0.204
12.87,67.31,0.204
12.88,67.47,0.204
12.90,67.61,0.204
12.92,67.77,0.204
12.93,67.91,0.205
12.95,68.07,0.205
12.96,68.22,0.205
12.98,68.36,0.205
12.99,68.52,0.205
13.00,68.67,0.205
13.02,68.82,0.205
13.03,68.97,0.205
13.05,69.12,0.206
13.07,69.27,0.206
13.08,69.42,0.206
13.10,69.57,0.206
13.11,69.72,0.206
13.13,69.87,0.206
13.14,70.02,0.206
13.15,70.17,0.206
13.17,70.32,0.206
13.18,70.47,0.206
13.20,70.62,0.207
13.22,70.77,0.207
13.23,70.92,0.207
13.25,71.07,0.207
13.26,71.22,0.207
13.28,71.37,0.207
13.29,71.52,0.207
13.30,71.67,0.207
13.32,71.82,0.208
13.33,71.97,0.208
13.35,72.12,0.208
13.37,72.27,0.208
13.38,72.42,0.208
13.40,72.57,0.208
13.41,72.72,0.208
13.43,72.87,0.208
13.44,73.02,0.209
13.45,73.17,0.209
13.47,73.32,0.209
13.48,73.47,0.209
13.50,73.62,0.209
13.52,73.77,0.209
13.53,73.92,0.209
13.55,74.07,0.209
13.56,74.22,0.209
13.58,74.37,0.209
13.59,74.52,0.210
13.60,74.67,0.210
13.62,74.82,0.210
13.63,74.97,0.210
13.65,75.12,0.210
13.67,75.27,0.210
13.68,75.42,0.210
13.70,75.57,0.210
13.71,75.72,0.210
13.73,75.87,0.211
13.74,76.02,0.211
13.75,76.17,0.211
13.77,76.32,0.211
13.78,76.47,0.211
13.80,76.62,0.211
13.82,76.77,0.211
13.83,76.92,0.211
13.85,77.07,0.212
13.86,77.22,0.212
13.88,77.37,0.212
13.89,77.52,0.212
13.90,77.67,0.212
13.92,77.82,0.212
13.93,77.97,0.212
13.95,78.12,0.212
13.97,78.27,0.212
13.98,78.42,0.212
14.00,78.57,0.213
14.01,78.72,0.213
14.03,78.87,0.213
14.04,79.02,0.213
14.05,79.17,0.213
14.07,79.32,0.213
14.08,79.48,0.213
14.10,79.62,0.214
14.12,79.77,0.214
14.13,79.92,0.214
14.15,80.07,0.214
14.16,80.22,0.214
14.18,80.37,0.214
14.19,80.52,0.214
14.20,80.68,0.214
14.22,80.82,0.214
14.23,80.98,0.214
14.25,81.13,0.214
14.27,81.28,0.214
14.28,81.42,0.214
14.30,81.57,0.214
14.31,81.73,0.214
14.33,81.88,0.215
14.34,82.03,0.215
14.35,82.18,0.215
14.37,82.33,0.215
14.38,82.48,0.215
14.40,82.63,0.215
14.42,82.78,0.215
14.43,82.93,0.215
14.45,83.08,0.215
14.46,83.23,0.215
14.48,83.38,0.215
14.49,83.53,0.215
14.50,83.68,0.215
14.52,83.83,0.216
14.53,83.98,0.216
14.55,84.13,0.216
14.57,84.28,0.216
14.58,84.43,0.216
14.60,84.58,0.216
14.61,84.73,0.216
14.63,84.88,0.216
14.64,85.03,0.216
14.65,85.18,0.216
14.67,85.33,0.216
14.68,85.48,0.216
14.70,85.63,0.216
14.72,85.78,0.216
14.73,85.93,0.216
14.75,86.08,0.217
14.76,86.23,0.217
14.78,86.38,0.217
14.79,86.53,0.217
14.80,86.68,0.217
14.82,86.83,0.217
14.83,86.98,0.217
14.85,87.13,0.217
14.87,87.28,0.217
14.88,87.43,0.217
14.90,87.58,0.217
14.91,87.73,0.218
14.93,87.88,0.218
14.94,88.03,0.218
14.95,88.18,0.218
14.97,88.33,0.218
14.98,88.48,0.218
15.00,88.63,0.218
15.02,88.78,0.218
15.03,88.93,0.218
15.05,89.08,0.219
15.06,89.23,0.219
15.08,89.38,0.219
15.09,89.53,0.219
15.10,89.68,0.219
15.12,89.83,0.219
15.13,89.98,0.219
15.15,90.13,0.219
15.17,90.28,0.220
15.18,90.43,0.220
15.20,90.58,0.220
15.21,90.74,0.220
15.23,90.88,0.220
15.24,91.03,0.220
15.25,91.18,0.220
15.27,91.33,0.221
15.28,91.49,0.221
15.30,91.64,0.221
15.32,91.79,0.221
15.33,91.93,0.221
15.35,92.09,0.221
15.36,92.24,0.222
15.38,92.38,0.222
15.39,92.54,0.222
15.40,92.69,0.222
15.42,92.84,0.222
15.43,92.99,0.222
15.45,93.14,0.222
15.47,93.29,0.222
15.48,93.44,0.222
15.50,93.59,0.222
15.51,93.74,0.223
15.53,93.89,0.223
15.54,94.04,0.223
15.55,94.19,0.223
15.57,94.33,0.223
15.58,94.49,0.223
15.60,94.64,0.223
15.62,94.79,0.223
15.63,94.94,0.224
15.65,95.09,0.224
15.66,95.24,0.224
15.68,95.39,0.224
15.69,95.54,0.224
15.70,95.69,0.224
15.72,95.84,0.224
15.73,95.99,0.224
15.75,96.14,0.224
15.77,96.29,0.225
15.78,96.44,0.225
15.80,96.59,0.225
15.81,96.74,0.225
15.83,96.89,0.225
15.84,97.04,0.225
15.85,97.19,0.225
15.87,97.34,0.225
15.88,97.49,0.225
15.90,97.64,0.226
15.92,97.79,0.226
15.93,97.94,0.226
15.95,98.09,0.226
15.96,98.24,0.226
15.98,98.39,0.226
15.99,98.54,0.226
16.00,98.69,0.226
16.02,98.84,0.226
16.03,98.99,0.226
16.05,99.14,0.227
16.07,99.29,0.227
16.08,99.44,0.227
16.10,99.59,0.227
16.11,99.74,0.227
16.13,99.89,0.227
16.14,100.04,0.227
16.15,100.19,0.227
16.17,100.34,0.228
16.18,100.49,0.228
16.20,100.64,0.228
16.22,100.79,0.228
16.23,100.94,0.228
16.25,101.09,0.228
16.26,101.24,0.228
16.28,101.39,0.228
16.29,101.54,0.228
16.30,101.69,0.229
16.32,101.84,0.229
16.33,101.99,0.229
16.35,102.14,0.229
16.37,102.29,0.229
16.38,102.44,0.229
16.40,102.59,0.229
16.41,102.74,0.229
16.43,102.89,0.230
16.44,103.04,0.230
16.45,103.19,0.230
16.47,103.34,0.230
16.48,103.49,0.230
16.50,103.64,0.230
16.52,103.79,0.230
16.53,103.94,0.230
16.55,104.09,0.230
16.56,104.24,0.231
16.58,104.39,0.231
16.59,104.54,0.231
16.60,104.70,0.231
16.62,104.84,0.231
16.63,105.00,0.231
16.65,105.15,0.231
16.67,105.30,0.231
16.68,105.45,0.231
16.70,105.60,0.232
16.71,105.75,0.232
16.73,105.90,0.232
16.74,106.05,0.232
16.75,106.20,0.232
16.77,106.35,0.232
16.78,106.50,0.232
16.80,106.65,0.232
16.82,106.80,0.233
16.83,106.95,0.233
16.85,107.10,0.233
16.86,107.25,0.233
16.88,107.40,0.233
16.89,107.55,0.233
16.90,107.70,0.233
16.92,107.85,0.233
16.93,108.00,0.233
16.95,108.15,0.234
16.97,108.30,0.234
16.98,108.45,0.234
17.00,108.60,0.234
17.01,108.75,0.234
17.03,108.90,0.234
17.04,109.05,0.234
17.05,109.20,0.234
17.07,109.35,0.234
17.08,109.50,0.235
17.10,109.65,0.235
17.12,109.80,0.235
17.13,109.95,0.235
17.14,110.10,0.235
17.16,110.25,0.235
17.18,110.40,0.235
17.19,110.55,0.235
17.21,110.70,0.235
17.22,110.85,0.236
17.23,111.00,0.236
17.25,111.15,0.236
17.27,111.30,0.236
17.28,111.45,0.236
17.29,111.60,0.236
17.31,111.75,0.236
17.33,111.90,0.236
17.34,112.05,0.236
17.36,112.20,0.236
17.37,112.35,0.236
17.38,112.50,0.237
17.40,112.65,0.237
17.42,112.80,0.237
17.43,112.95,0.237
17.44,113.10,0.237
17.46,113.25,0.237
17.48,113.40,0.237
17.49,113.55,0.237
17.51,113.70,0.237
17.52,113.85,0.238
17.53,114.00,0.238
17.55,114.15,0.238
17.57,114.30,0.238
17.58,114.45,0.238
17.59,114.60,0.238
17.61,114.75,0.238
17.63,114.90,0.238
17.64,115.05,0.238
17.66,115.20,0.238
17.67,115.35,0.239
17.68,115.50,0.239
17.70,115.65,0.239
17.72,115.80,0.239
17.73,115.95,0.239
17.74,116.10,0.239
17.76,116.25,0.239
17.78,116.40,0.239
17.79,116.55,0.239
17.81,116.70,0.240
17.82,116.85,0.240
17.83,117.00,0.240
17.85,117.15,0.240
17.87,117.30,0.240
17.88,117.45,0.240
17.89,117.60,0.240
17.91,117.75,0.240
17.93,117.90,0.240
17.94,118.05,0.240
17.96,118.20,0.240
17.97,118.35,0.241
17.98,118.50,0.241
18.00,118.65,0.241
18.02,118.81,0.241
18.03,118.96,0.241
18.04,119.11,0.241
18.06,119.26,0.241
18.08,119.41,0.241
18.09,119.56,0.241
18.11,119.71,0.241
18.12,119.86,0.241
18.13,120.01,0.242
18.15,120.16,0.242
18.17,120.31,0.242
18.18,120.46,0.242
18.19,120.61,0.242
18.21,120.76,0.242
18.23,120.91,0.242
18.24,121.06,0.242
18.26,121.21,0.243
18.27,121.36,0.243
18.28,121.51,0.243
18.30,121.66,0.243
18.32,121.81,0.243
18.33,121.96,0.243
18.34,122.11,0.243
18.36,122.26,0.243
18.38,122.41,0.243
18.39,122.56,0.243
18.41,122.71,0.243
18.42,122.86,0.243
18.43,123.01,0.243
18.45,123.16,0.244
18.47,123.31,0.244
18.48,123.46,0.244
18.49,123.61,0.244
18.51,123.76,0.244
18.53,123.91,0.244
18.54,124.06,0.244
18.56,124.21,0.244
18.57,124.36,0.244
18.58,124.51,0.244
18.60,124.66,0.244
18.62,124.81,0.244
18.63,124.96,0.244
18.64,125.11,0.245
18.66,125.26,0.245
18.68,125.41,0.245
18.69,125.56,0.245
18.71,125.71,0.245
18.72,125.86,0.245
18.73,126.01,0.245
18.75,126.16,0.245
18.77,126.31,0.245
18.78,126.46,0.245
18.79,126.61,0.245
18.81,126.76,0.246
18.83,126.91,0.246
18.84,127.06,0.246
18.86,127.21,0.246
18.87,127.36,0.246
18.88,127.51,0.246
18.90,127.66,0.246
18.92,127.81,0.246
18.93,127.96,0.246
18.94,128.11,0.246
18.96,128.26,0.246
18.98,128.41,0.246
18.99,128.56,0.246
19.01,128.71,0.246
19.02,128.86,0.246
19.03,129.01,0.247
19.05,129.16,0.247
19.07,129.31,0.247
19.08,129.46,0.247
19.09,129.61,0.247
19.11,129.76,0.247
19.13,129.91,0.247
19.14,130.06,0.247
19.16,130.21,0.247
19.17,130.36,0.247
19.18,130.51,0.247
19.20,130.66,0.248
19.22,130.81,0.248
19.23,130.96,0.248
19.24,131.11,0.248
19.26,131.26,0.248
19.28,131.41,0.248
19.29,131.56,0.248
19.31,131.71,0.248
19.32,131.87,0.248
19.33,132.01,0.248
19.35,132.17,0.248
19.37,132.32,0.249
19.38,132.46,0.249
19.39,132.61,0.249
19.41,132.76,0.249
19.43,132.92,0.249
19.44,133.07,0.249
19.46,133.22,0.249
19.47,133.37,0.249
19.48,133.52,0.249
19.50,133.67,0.249
19.52,133.82,0.249
19.53,133.97,0.249
19.54,134.12,0.249
19.56,134.27,0.249
19.58,134.42,0.250
19.59,134.57,0.250
19.61,134.72,0.250
19.62,134.87,0.250
19.63,135.02,0.250
19.65,135.17,0.250
19.67,135.32,0.250
19.68,135.47,0.250
19.69,135.62,0.250
19.71,135.77,0.250
19.73,135.92,0.250
19.74,136.07,0.250
19.76,136.22,0.251
19.77,136.37,0.251
19.78,136.52,0.251
19.80,136.67,0.251
19.82,136.82,0.251
19.83,136.97,0.251
19.84,137.12,0.251
19.86,137.27,0.251
19.88,137.42,0.251
19.89,137.57,0.251
19.91,137.72,0.251
19.92,137.87,0.251
19.93,138.02,0.251
19.95,138.17,0.251
19.97,138.32,0.251
19.98,138.47,0.252
19.99,138.62,0.252
20.01,138.77,0.252
20.03,138.92,0.252
20.04,139.07,0.252
20.06,139.22,0.252
20.07,139.37,0.252
20.08,139.52,0.252
20.10,139.67,0.252
20.12,139.82,0.252
20.13,139.97,0.252
20.14,140.12,0.252
20.16,140.27,0.252
20.18,140.42,0.252
20.19,140.57,0.253
20.21,140.72,0.253
20.22,140.87,0.253
20.23,141.02,0.253
20.25,141.17,0.253
20.27,141.32,0.253
20.28,141.47,0.253
20.29,141.62,0.253
20.31,141.77,0.253
20.33,141.92,0.253
20.34,142.07,0.253
20.36,142.22,0.253
20.37,142.37,0.253
20.38,142.52,0.253
20.40,142.67,0.254
20.42,142.82,0.254
20.43,142.97,0.254
20.44,143.12,0.254
20.46,143.27,0.254
20.48,143.42,0.254
20.49,143.57,0.254
20.51,143.72,0.254
20.52,143.87,0.254
20.53,144.02,0.254
20.55,144.17,0.254
20.57,144.32,0.254
20.58,144.47,0.255
20.59,144.62,0.255
20.61,144.77,0.255
20.63,144.92,0.255
20.64,145.07,0.255
20.66,145.22,0.255
20.67,145.37,0.255
20.68,145.52,0.255
20.70,145.67,0.255
20.72,145.82,0.255
20.73,145.97,0.255
20.74,146.12,0.255
20.76,146.27,0.255
20.78,146.42,0.255
20.79,146.57,0.255
20.81,146.72,0.255
20.82,146.87,0.255
20.83,147.02,0.255
20.85,147.17,0.256
20.87,147.32,0.256
20.88,147.47,0.256
20.89,147.62,0.256
20.91,147.77,0.256
20.93,147.92,0.256
20.94,148.07,
20.96,148.22,
20.97,148.37,
20.98,,
20.99,,

[step]
Ramp 10.00 °C/min to -60.00 °C
Time,Temperature,Heat Flow (Normalized)
min,°C,W/g
21.99,150.09,-0.058
22.01,150.09,-0.059
22.02,150.09,-0.059
22.04,150.08,-0.059
22.05,150.07,-0.057
22.07,150.04,-0.046
22.08,150.01,-0.037
22.10,149.95,-0.035
22.11,149.88,-0.037
22.13,149.80,-0.071
22.14,149.71,-0.104
22.16,149.60,-0.138
22.17,149.49,-0.170
22.19,149.37,-0.202
22.20,149.25,-0.228
22.22,149.13,-0.249
22.23,149.00,-0.264
22.25,148.87,-0.282
22.26,148.73,-0.292
22.28,148.60,-0.305
22.29,148.46,-0.314
22.31,148.32,-0.320
22.32,148.18,-0.329
22.34,148.04,-0.334
22.35,147.90,-0.339
22.37,147.75,-0.345
22.38,147.61,-0.347
22.40,147.47,-0.350
22.41,147.32,-0.353
22.43,147.18,-0.355
22.44,147.03,-0.357
22.46,146.88,-0.358
22.47,146.74,-0.359
22.49,146.59,-0.360
22.50,146.44,-0.361
22.52,146.30,-0.362
22.53,146.15,-0.362
22.55,146.00,-0.363
22.56,145.85,-0.364
22.58,145.71,-0.364
22.59,145.56,-0.365
22.61,145.41,-0.365
22.62,145.26,-0.366
22.64,145.12,-0.366
22.65,144.97,-0.366
22.67,144.82,-0.366
22.68,144.67,-0.367
22.70,144.52,-0.367
22.71,144.37,-0.367
22.73,144.23,-0.367
22.74,144.08,-0.368
22.76,143.93,-0.368
22.77,143.78,-0.368
22.79,143.63,-0.368
22.80,143.48,-0.368
22.82,143.33,-0.369
22.83,143.19,-0.369
22.85,143.03,-0.369
22.86,142.89,-0.369
22.88,142.74,-0.369
22.89,142.59,-0.370
22.91,142.44,-0.370
22.92,142.29,-0.370
22.94,142.14,-0.370
22.95,141.99,-0.370
22.97,141.85,-0.370
22.98,141.70,-0.370
23.00,141.55,-0.370
23.01,141.40,-0.370
23.03,141.25,-0.370
23.04,141.10,-0.370
23.06,140.95,-0.370
23.07,140.80,-0.370
23.09,140.65,-0.370
23.10,140.50,-0.370
23.12,140.35,-0.370
23.13,140.20,-0.370
23.15,140.05,-0.370
23.16,139.90,-0.370
23.18,139.76,-0.370
23.19,139.61,-0.370
23.21,139.46,-0.370
23.22,139.31,-0.370
23.24,139.16,-0.370
23.25,139.01,-0.370
23.27,138.86,-0.369
23.28,138.71,-0.369
23.30,138.56,-0.369
23.31,138.41,-0.369
23.33,138.26,-0.369
23.34,138.11,-0.369
23.36,137.96,-0.369
23.37,137.81,-0.369
23.39,137.66,-0.369
23.40,137.51,-0.369
23.42,137.36,-0.369
23.43,137.21,-0.369
23.45,137.06,-0.368
23.46,136.91,-0.368
23.48,136.76,-0.368
23.49,136.62,-0.368
23.51,136.46,-0.368
23.52,136.32,-0.368
23.54,136.17,-0.368
23.55,136.02,-0.368
23.57,135.87,-0.367
23.58,135.72,-0.367
23.60,135.57,-0.367
23.61,135.42,-0.367
23.63,135.27,-0.367
23.64,135.12,-0.367
23.66,134.97,-0.367
23.67,134.82,-0.366
23.69,134.67,-0.366
23.70,134.52,-0.366
23.72,134.37,-0.366
23.73,134.22,-0.366
23.75,134.07,-0.366
23.76,133.92,-0.366
23.78,133.77,-0.365
23.79,133.62,-0.365
23.81,133.47,-0.365
23.82,133.32,-0.365
23.84,133.17,-0.365
23.85,133.02,-0.365
23.87,132.87,-0.364
23.88,132.72,-0.364
23.90,132.57,-0.364
23.91,132.42,-0.364
23.93,132.27,-0.364
23.94,132.12,-0.364
23.96,131.97,-0.364
23.97,131.82,-0.363
23.99,131.67,-0.363
24.00,131.52,-0.363
24.02,131.37,-0.363
24.03,131.22,-0.363
24.05,131.07,-0.363
24.06,130.92,-0.363
24.08,130.77,-0.362
24.09,130.63,-0.362
24.11,130.48,-0.362
24.12,130.32,-0.362
24.14,130.18,-0.362
24.15,130.03,-0.362
24.17,129.88,-0.362
24.18,129.73,-0.361
24.20,129.58,-0.361
24.21,129.43,-0.361
24.23,129.28,-0.361
24.24,129.13,-0.361
24.26,128.98,-0.361
24.27,128.83,-0.361
24.29,128.68,-0.360
24.30,128.53,-0.360
24.32,128.38,-0.360
24.33,128.23,-0.360
24.35,128.08,-0.360
24.36,127.93,-0.360
24.38,127.78,-0.359
24.39,127.63,-0.359
24.41,127.48,-0.359
24.42,127.33,-0.359
24.44,127.18,-0.359
24.45,127.03,-0.359
24.47,126.88,-0.358
24.48,126.73,-0.358
24.50,126.58,-0.358
24.51,126.43,-0.358
24.53,126.28,-0.358
24.54,126.13,-0.358
24.56,125.98,-0.358
24.57,125.83,-0.357
24.59,125.68,-0.357
24.60,125.53,-0.357
24.62,125.38,-0.357
24.63,125.23,-0.357
24.65,125.08,-0.357
24.66,124.93,-0.357
24.68,124.78,-0.356
24.69,124.63,-0.356
24.71,124.48,-0.356
24.72,124.33,-0.356
24.74,124.18,-0.356
24.75,124.03,-0.356
24.77,123.88,-0.356
24.78,123.73,-0.356
24.80,123.58,-0.356
24.81,123.43,-0.355
24.83,123.28,-0.355
24.84,123.13,-0.355
24.86,122.98,-0.355
24.87,122.83,-0.355
24.89,122.68,-0.355
24.90,122.53,-0.354
24.92,122.38,-0.354
24.93,122.23,-0.354
24.95,122.08,-0.354
24.96,121.94,-0.354
24.98,121.79,-0.354
24.99,121.64,-0.353
25.01,121.49,-0.353
25.02,121.34,-0.353
25.04,121.19,-0.353
25.05,121.04,-0.353
25.07,120.89,-0.353
25.08,120.74,-0.353
25.10,120.59,-0.352
25.11,120.44,-0.352
25.13,120.29,-0.352
25.14,120.14,-0.352
25.16,119.99,-0.352
25.17,119.84,-0.352
25.19,119.69,-0.352
25.20,119.54,-0.351
25.22,119.39,-0.351
25.23,119.24,-0.351
25.25,119.09,-0.351
25.26,118.94,-0.351
25.28,118.79,-0.351
25.29,118.64,-0.350
25.31,118.49,-0.350
25.32,118.34,-0.350
25.34,118.19,-0.350
25.35,118.04,-0.350
25.37,117.89,-0.350
25.38,117.74,-0.350
25.40,117.59,-0.349
25.41,117.44,-0.349
25.43,117.29,-0.349
25.44,117.14,-0.349
25.46,116.99,-0.349
25.47,116.84,-0.349
25.49,116.69,-0.349
25.50,116.54,-0.349
25.52,116.39,-0.348
25.53,116.24,-0.348
25.55,116.09,-0.348
25.56,115.94,-0.348
25.58,115.79,-0.348
25.59,115.64,-0.348
25.61,115.49,-0.347
25.62,115.34,-0.347
25.64,115.19,-0.347
25.65,115.04,-0.347
25.67,114.89,-0.347
25.68,114.74,-0.347
25.70,114.59,-0.346
25.71,114.44,-0.346
25.73,114.29,-0.346
25.74,114.14,-0.346
25.76,113.99,-0.346
25.77,113.84,-0.346
25.79,113.69,-0.346
25.80,113.54,-0.346
25.82,113.39,-0.345
25.83,113.24,-0.345
25.85,113.09,-0.345
25.86,112.94,-0.345
25.88,112.79,-0.345
25.89,112.65,-0.345
25.91,112.49,-0.345
25.92,112.34,-0.345
25.94,112.20,-0.344
25.95,112.04,-0.344
25.97,111.90,-0.344
25.98,111.75,-0.344
26.00,111.60,-0.344
26.01,111.45,-0.344
26.03,111.30,-0.344
26.04,111.15,-0.343
26.06,111.00,-0.343
26.07,110.85,-0.343
26.09,110.70,-0.343
26.10,110.55,-0.343
26.12,110.40,-0.343
26.13,110.25,-0.343
26.15,110.10,-0.343
26.16,109.95,-0.342
26.18,109.80,-0.342
26.19,109.65,-0.342
26.21,109.50,-0.342
26.22,109.35,-0.342
26.24,109.20,-0.342
26.25,109.05,-0.342
26.27,108.90,-0.342
26.28,108.75,-0.341
26.30,108.60,-0.341
26.31,108.45,-0.341
26.33,108.30,-0.341
26.34,108.15,-0.341
26.36,108.00,-0.340
26.37,107.85,-0.340
26.39,107.70,-0.340
26.40,107.55,-0.340
26.42,107.40,-0.340
26.43,107.25,-0.340
26.45,107.10,-0.340
26.46,106.95,-0.340
26.48,106.80,-0.339
26.49,106.65,-0.339
26.51,106.50,-0.339
26.52,106.35,-0.339
26.54,106.20,-0.339
26.55,106.05,-0.339
26.57,105.90,-0.339
26.58,105.75,-0.339
26.60,105.60,-0.338
26.61,105.45,-0.338
26.63,105.30,-0.338
26.64,105.15,-0.338
26.66,105.00,-0.338
26.67,104.85,-0.338
26.69,104.70,-0.338
26.70,104.55,-0.338
26.72,104.40,-0.337
26.73,104.25,-0.337
26.75,104.10,-0.337
26.76,103.95,-0.337
26.78,103.80,-0.337
26.79,103.65,-0.337
26.81,103.50,-0.337
26.82,103.35,-0.336
26.84,103.20,-0.336
26.85,103.05,-0.336
26.87,102.90,-0.336
26.88,102.75,-0.336
26.90,102.61,-0.336
26.91,102.45,-0.335
26.93,102.31,-0.335
26.94,102.16,-0.335
26.96,102.00,-0.335
26.97,101.86,-0.335
26.99,101.70,-0.335
27.00,101.55,-0.335
27.02,101.40,-0.335
27.03,101.25,-0.335
27.05,101.10,-0.334
27.06,100.95,-0.334
27.08,100.81,-0.334
27.09,100.66,-0.334
27.11,100.51,-0.334
27.12,100.36,-0.334
27.14,100.21,-0.333
27.15,100.06,-0.333
27.17,99.91,-0.333
27.18,99.76,-0.333
27.20,99.61,-0.333
27.21,99.46,-0.333
27.23,99.31,-0.333
27.24,99.16,-0.332
27.26,99.01,-0.332
27.27,98.86,-0.332
27.29,98.71,-0.332
27.30,98.56,-0.332
27.32,98.41,-0.332
27.33,98.26,-0.332
27.35,98.11,-0.332
27.36,97.96,-0.332
27.38,97.81,-0.331
27.39,97.66,-0.331
27.41,97.51,-0.331
27.42,97.36,-0.331
27.44,97.21,-0.331
27.45,97.06,-0.331
27.47,96.91,-0.330
27.48,96.76,-0.330
27.50,96.61,-0.330
27.51,96.46,-0.330
27.53,96.31,-0.330
27.54,96.16,-0.330
27.56,96.01,-0.330
27.57,95.86,-0.329
27.59,95.71,-0.329
27.60,95.56,-0.329
27.62,95.41,-0.329
27.63,95.26,-0.329
27.65,95.11,-0.329
27.66,94.96,-0.328
27.68,94.81,-0.328
27.69,94.66,-0.328
27.71,94.51,-0.328
27.72,94.36,-0.328
27.74,94.21,-0.328
27.75,94.06,-0.328
27.77,93.91,-0.328
27.78,93.76,-0.327
27.80,93.61,-0.327
27.81,93.46,-0.327
27.83,93.31,-0.327
27.84,93.16,-0.327
27.86,93.02,-0.327
27.87,92.86,-0.326
27.89,92.71,-0.326
27.90,92.56,-0.326
27.92,92.41,-0.326
27.93,92.26,-0.326
27.95,92.12,-0.326
27.96,91.96,-0.326
27.98,91.82,-0.325
27.99,91.66,-0.325
28.01,91.52,-0.325
28.02,91.37,-0.325
28.04,91.22,-0.325
28.05,91.07,-0.324
28.07,90.92,-0.324
28.08,90.77,-0.324
28.10,90.62,-0.324
28.11,90.47,-0.324
28.13,90.32,-0.324
28.14,90.17,-0.324
28.16,90.02,-0.323
28.17,89.87,-0.323
28.19,89.72,-0.323
28.20,89.57,-0.323
28.22,89.42,-0.323
28.23,89.27,-0.322
28.25,89.12,-0.322
28.26,88.97,-0.322
28.28,88.82,-0.321
28.29,88.67,-0.321
28.31,88.52,-0.321
28.32,88.37,-0.321
28.34,88.22,-0.321
28.35,88.07,-0.321
28.37,87.92,-0.320
28.38,87.77,-0.320
28.40,87.62,-0.320
28.41,87.47,-0.320
28.43,87.32,-0.320
28.44,87.17,-0.320
28.46,87.02,-0.320
28.47,86.87,-0.319
28.49,86.72,-0.319
28.50,86.57,-0.319
28.52,86.42,-0.319
28.53,86.27,-0.318
[...]
93.05,-11.04,0.163
93.06,-10.89,0.164
93.08,-10.74,0.164
93.09,-10.58,0.164
93.11,-10.43,0.164
93.12,-10.28,0.164
93.14,-10.13,0.164
93.15,-9.98,0.164
93.17,-9.83,0.164
93.18,-9.68,0.164
93.20,-9.53,0.164
93.21,-9.38,0.164
93.23,-9.23,0.164
93.24,-9.08,0.164
93.26,-8.93,0.164
93.27,-8.78,0.164
93.29,-8.63,0.164
93.30,-8.48,0.164
93.32,-8.33,0.164
93.33,-8.18,0.164
93.35,-8.03,0.164
93.36,-7.88,0.164
93.38,-7.73,0.165
93.39,-7.58,0.165
93.41,-7.43,0.165
93.42,-7.28,0.165
93.44,-7.13,0.165
93.45,-6.98,0.165
93.47,-6.83,0.165
93.48,-6.68,0.165
93.50,-6.53,0.165
93.51,-6.38,0.165
93.53,-6.23,0.165
93.54,-6.08,0.165
93.56,-5.93,0.165
93.57,-5.78,0.165
93.59,-5.63,0.165
93.60,-5.48,0.165
93.62,-5.33,0.165
93.63,-5.18,0.166
93.65,-5.03,0.166
93.66,-4.88,0.166
93.68,-4.73,0.166
93.69,-4.58,0.166
93.71,-4.43,0.166
93.72,-4.28,0.166
93.74,-4.13,0.166
93.75,-3.98,0.166
93.77,-3.83,0.166
93.78,-3.68,0.166
93.80,-3.53,0.166
93.81,-3.38,0.166
93.83,-3.23,0.166
93.84,-3.08,0.166
93.86,-2.93,0.166
93.87,-2.78,0.166
93.89,-2.63,0.166
93.90,-2.48,0.166
93.92,-2.33,0.166
93.93,-2.18,0.167
93.95,-2.03,0.167
93.96,-1.88,0.167
93.98,-1.73,0.167
93.99,-1.58,0.167
94.01,-1.43,0.167
94.02,-1.28,0.167
94.04,-1.13,0.167
94.05,-0.98,0.167
94.07,-0.83,0.167
94.08,-0.68,0.167
94.10,-0.53,0.167
94.11,-0.38,0.167
94.13,-0.23,0.167
94.14,-0.08,0.167
94.16,0.07,0.167
94.17,0.22,0.167
94.19,0.37,0.167
94.20,0.52,0.167
94.22,0.67,0.167
94.23,0.82,0.167
94.25,0.97,0.168
94.26,1.12,0.168
94.28,1.27,0.168
94.29,1.42,0.168
94.31,1.58,0.168
94.32,1.73,0.168
94.34,1.88,0.168
94.35,2.03,0.168
94.37,2.18,0.168
94.38,2.33,0.168
94.40,2.48,0.168
94.41,2.63,0.168
94.43,2.78,0.168
94.44,2.93,0.168
94.46,3.08,0.168
94.47,3.23,0.168
94.49,3.38,0.168
94.50,3.53,0.168
94.52,3.68,0.168
94.53,3.83,0.169
94.55,3.98,0.169
94.56,4.13,0.169
94.58,4.28,0.169
94.59,4.43,0.169
94.61,4.58,0.169
94.62,4.73,0.169
94.64,4.88,0.169
94.65,5.03,0.169
94.67,5.18,0.169
94.68,5.33,0.169
94.70,5.48,0.169
94.71,5.63,0.169
94.73,5.78,0.169
94.74,5.93,0.170
94.76,6.08,0.170
94.77,6.23,0.170
94.79,6.38,0.170
94.80,6.53,0.170
94.82,6.68,0.170
94.83,6.83,0.170
94.85,6.98,0.170
94.86,7.13,0.170
94.88,7.28,0.170
94.89,7.43,0.170
94.91,7.58,0.170
94.92,7.73,0.170
94.94,7.88,0.171
94.95,8.03,0.171
94.97,8.18,0.171
94.98,8.33,0.171
95.00,8.48,0.171
95.01,8.63,0.171
95.03,8.78,0.171
95.04,8.93,0.171
95.06,9.08,0.171
95.07,9.24,0.171
95.09,9.38,0.171
95.10,9.53,0.171
95.12,9.68,0.171
95.13,9.83,0.172
95.15,9.98,0.172
95.16,10.13,0.172
95.18,10.29,0.172
95.19,10.43,0.172
95.21,10.59,0.172
95.22,10.74,0.172
95.24,10.89,0.172
95.25,11.04,0.172
95.27,11.19,0.172
95.28,11.34,0.172
95.30,11.49,0.173
95.31,11.64,0.173
95.33,11.79,0.173
95.34,11.94,0.173
95.36,12.09,0.173
95.37,12.24,0.173
95.39,12.39,0.173
95.40,12.54,0.173
95.42,12.69,0.173
95.43,12.84,0.173
95.45,12.99,0.173
95.46,13.14,0.173
95.48,13.29,0.173
95.49,13.44,0.173
95.51,13.59,0.174
95.52,13.74,0.174
95.54,13.89,0.174
95.55,14.04,0.174
95.57,14.19,0.174
95.58,14.34,0.174
95.60,14.49,0.174
95.61,14.64,0.174
95.63,14.79,0.174
95.64,14.94,0.174
95.66,15.09,0.174
95.67,15.24,0.175
95.69,15.39,0.175
95.70,15.54,0.175
95.72,15.69,0.175
95.73,15.84,0.175
95.75,15.99,0.175
95.76,16.14,0.175
95.78,16.29,0.175
95.79,16.44,0.175
95.81,16.59,0.176
95.82,16.74,0.176
95.84,16.89,0.176
95.85,17.04,0.176
95.87,17.19,0.176
95.88,17.34,0.176
95.90,17.49,0.176
95.91,17.64,0.176
95.93,17.79,0.176
95.94,17.94,0.176
95.96,18.09,0.176
95.97,18.24,0.176
95.99,18.39,0.176
96.00,18.54,0.177
96.02,18.69,0.177
96.03,18.84,0.177
96.05,18.99,0.177
96.06,19.14,0.177
96.08,19.29,0.177
96.09,19.44,0.177
96.11,19.60,0.178
96.12,19.75,0.178
96.14,19.90,0.178
96.15,20.05,0.178
96.17,20.20,0.178
96.18,20.35,0.178
96.20,20.50,0.178
96.21,20.65,0.178
96.23,20.80,0.179
96.24,20.95,0.179
96.26,21.10,0.179
96.27,21.25,0.179
96.29,21.40,0.179
96.30,21.55,0.179
96.32,21.70,0.179
96.33,21.85,0.179
96.35,22.00,0.179
96.36,22.15,0.180
96.38,22.30,0.180
96.39,22.45,0.180
96.41,22.60,0.180
96.42,22.75,0.180
96.44,22.90,0.180
96.45,23.05,0.180
96.47,23.20,0.180
96.48,23.35,0.180
96.50,23.50,0.180
96.51,23.65,0.181
96.53,23.80,0.181
96.54,23.95,0.181
96.56,24.10,0.181
96.57,24.25,0.181
96.59,24.40,0.181
96.60,24.55,0.181
96.62,24.70,0.181
96.63,24.85,0.181
96.65,25.00,0.181
96.66,25.15,0.182
96.68,25.30,0.182
96.69,25.45,0.182
96.71,25.60,0.182
96.72,25.75,0.182
96.74,25.90,0.182
96.75,26.05,0.182
96.77,26.20,0.182
96.78,26.35,0.182
96.80,26.50,0.182
96.81,26.65,0.183
96.83,26.80,0.183
96.84,26.95,0.183
96.86,27.10,0.183
96.87,27.25,0.183
96.89,27.40,0.183
96.90,27.55,0.183
96.92,27.70,0.183
96.93,27.85,0.183
96.95,28.00,0.184
96.96,28.15,0.184
96.98,28.30,0.184
96.99,28.45,0.184
97.01,28.60,0.184
97.02,28.75,0.184
97.04,28.91,0.184
97.05,29.06,0.184
97.07,29.21,0.184
97.08,29.36,0.184
97.10,29.51,0.184
97.11,29.66,0.184
97.13,29.81,0.184
97.14,29.96,0.184
97.16,30.11,0.184
97.17,30.26,0.185
97.19,30.41,0.185
97.20,30.56,0.185
97.22,30.71,0.185
97.23,30.86,0.185
97.25,31.01,0.185
97.26,31.16,0.185
97.28,31.31,0.185
97.29,31.46,0.185
97.31,31.61,0.185
97.32,31.76,0.185
97.34,31.91,0.185
97.35,32.06,0.185
97.37,32.21,0.185
97.38,32.36,0.185
97.40,32.51,0.185
97.41,32.66,0.185
97.43,32.81,0.186
97.44,32.96,0.186
97.46,33.11,0.186
97.47,33.26,0.186
97.49,33.41,0.186
97.50,33.56,0.186
97.52,33.71,0.186
97.53,33.86,0.186
97.55,34.01,0.186
97.56,34.16,0.186
97.58,34.31,0.186
97.59,34.46,0.186
97.61,34.61,0.186
97.62,34.76,0.187
97.64,34.91,0.187
97.65,35.06,0.187
97.67,35.21,0.187
97.68,35.36,0.187
97.70,35.51,0.187
97.71,35.66,0.187
97.73,35.81,0.187
97.74,35.96,0.187
97.76,36.11,0.187
97.77,36.26,0.187
97.79,36.41,0.187
97.80,36.56,0.187
97.82,36.71,0.187
97.83,36.86,0.187
97.85,37.01,0.187
97.86,37.16,0.188
97.88,37.31,0.188
97.89,37.46,0.188
97.91,37.62,0.188
97.92,37.76,0.188
97.94,37.91,0.188
97.95,38.07,0.188
97.97,38.21,0.188
97.98,38.37,0.188
98.00,38.52,0.188
98.01,38.67,0.188
98.03,38.82,0.188
98.04,38.97,0.188
98.06,39.12,0.188
98.07,39.27,0.188
98.09,39.42,0.188
98.10,39.57,0.188
98.12,39.72,0.189
98.13,39.87,0.189
98.15,40.02,0.189
98.16,40.17,0.189
98.18,40.32,0.189
98.19,40.47,0.189
98.21,40.62,0.189
98.22,40.77,0.189
98.24,40.92,0.189
98.25,41.07,0.189
98.27,41.22,0.189
98.28,41.37,0.190
98.30,41.52,0.190
98.31,41.67,0.190
98.33,41.82,0.190
98.34,41.97,0.190
98.36,42.12,0.190
98.37,42.27,0.190
98.39,42.42,0.190
98.40,42.57,0.190
98.42,42.72,0.190
98.43,42.87,0.190
98.45,43.02,0.190
98.46,43.17,0.191
98.48,43.32,0.191
98.49,43.47,0.191
98.51,43.62,0.191
98.52,43.77,0.191
98.54,43.92,0.191
98.55,44.07,0.191
98.57,44.22,0.191
98.58,44.37,0.191
98.60,44.52,0.191
98.61,44.67,0.191
98.63,44.82,0.191
98.64,44.97,0.191
98.66,45.12,0.192
98.67,45.27,0.192
98.69,45.42,0.192
98.70,45.57,0.192
98.72,45.72,0.192
98.73,45.87,0.192
98.75,46.02,0.192
98.76,46.17,0.192
98.78,46.32,0.192
98.79,46.47,0.192
98.81,46.62,0.192
98.82,46.77,0.193
98.84,46.92,0.193
98.85,47.07,0.193
98.87,47.22,0.193
98.88,47.38,0.193
98.90,47.53,0.193
98.91,47.67,0.193
98.93,47.83,0.193
98.94,47.98,0.193
98.96,48.13,0.194
98.97,48.28,0.194
98.99,48.43,0.194
99.00,48.58,0.194
99.02,48.73,0.194
99.03,48.88,0.194
99.05,49.03,0.194
99.06,49.18,0.194
99.08,49.33,0.194
99.09,49.48,0.194
99.11,49.63,0.194
99.12,49.78,0.195
99.14,49.93,0.195
99.15,50.08,0.195
99.17,50.23,0.195
99.18,50.38,0.195
99.20,50.53,0.195
99.21,50.68,0.195
99.23,50.83,0.195
99.24,50.98,0.195
99.26,51.13,0.196
99.27,51.28,0.196
99.29,51.43,0.196
99.30,51.58,0.196
99.32,51.73,0.196
99.33,51.88,0.196
99.35,52.03,0.196
99.36,52.18,0.196
99.38,52.33,0.196
99.39,52.48,0.196
99.41,52.63,0.197
99.42,52.78,0.197
99.44,52.93,0.197
99.45,53.08,0.197
99.47,53.23,0.197
99.48,53.38,0.197
99.50,53.53,0.197
99.51,53.68,0.197
99.53,53.83,0.197
99.54,53.98,0.197
99.56,54.13,0.197
99.57,54.28,0.198
99.59,54.43,0.198
99.60,54.58,0.198
99.62,54.73,0.198
99.63,54.88,0.198
99.65,55.03,0.198
99.66,55.18,0.198
99.68,55.33,0.198
99.69,55.48,0.198
99.71,55.63,0.198
99.72,55.78,0.198
99.74,55.93,0.198
99.75,56.08,0.198
99.77,56.23,0.199
99.78,56.38,0.199
99.80,56.53,0.199
99.81,56.68,0.199
99.83,56.83,0.199
99.84,56.98,0.199
99.86,57.14,0.199
99.87,57.29,0.199
99.89,57.44,0.199
99.90,57.59,0.199
99.92,57.74,0.199
99.93,57.89,0.200
99.95,58.04,0.200
99.96,58.19,0.200
99.98,58.34,0.200
99.99,58.49,0.200
100.01,58.64,0.200
100.02,58.79,0.200
100.04,58.94,0.200
100.05,59.09,0.200
100.07,59.24,0.200
100.08,59.39,0.201
100.10,59.54,0.201
100.11,59.69,0.201
100.13,59.84,0.201
100.14,59.99,0.201
100.16,60.14,0.201
100.17,60.29,0.201
100.19,60.44,0.201
100.20,60.59,0.201
100.22,60.74,0.202
100.23,60.89,0.202
100.25,61.04,0.202
100.26,61.19,0.202
100.28,61.34,0.202
100.29,61.49,0.202
100.31,61.64,0.202
100.32,61.79,0.202
100.34,61.94,0.202
100.35,62.09,0.202
100.37,62.24,0.202
100.38,62.39,0.202
100.40,62.54,0.203
100.41,62.69,0.203
100.43,62.84,0.203
100.44,62.99,0.203
100.46,63.14,0.203
100.47,63.29,0.203
100.49,63.44,0.203
100.50,63.59,0.203
100.52,63.74,0.203
100.53,63.89,0.203
100.55,64.04,0.204
100.56,64.19,0.204
100.58,64.34,0.204
100.59,64.49,0.204
100.61,64.64,0.204
100.62,64.79,0.204
100.64,64.94,0.204
100.65,65.09,0.204
100.67,65.24,0.204
100.68,65.39,0.204
100.70,65.55,0.204
100.71,65.69,0.205
100.73,65.84,0.205
100.74,65.99,0.205
100.76,66.14,0.205
100.77,66.29,0.205
100.79,66.44,0.205
100.80,66.60,0.205
100.82,66.74,0.205
100.83,66.89,0.205
100.85,67.04,0.205
100.86,67.19,0.205
100.88,67.34,0.206
100.89,67.50,0.206
100.91,67.65,0.206
100.92,67.80,0.206
100.94,67.95,0.206
100.95,68.10,0.206
100.97,68.25,0.206
100.98,68.40,0.206
101.00,68.55,0.206
101.01,68.70,0.207
101.03,68.85,0.206
101.04,69.00,0.207
101.06,69.15,0.207
101.07,69.30,0.207
101.09,69.45,0.207
101.10,69.60,0.207
101.12,69.75,0.207
101.13,69.90,0.207
101.15,70.05,0.207
101.16,70.20,0.207
101.18,70.35,0.207
101.19,70.50,0.208
101.21,70.65,0.208
101.22,70.80,0.208
101.24,70.95,0.208
101.25,71.10,0.208
101.27,71.25,0.208
101.28,71.40,0.208
101.30,71.55,0.208
101.31,71.70,0.208
101.33,71.85,0.208
101.34,72.00,0.208
101.36,72.15,0.208
101.37,72.30,0.209
101.39,72.45,0.209
101.40,72.60,0.209
101.42,72.75,0.209
101.43,72.90,0.209
101.45,73.05,0.209
101.46,73.20,0.209
101.48,73.35,0.209
101.49,73.50,0.209
101.51,73.65,0.209
101.52,73.80,0.210
101.54,73.95,0.210
101.55,74.10,0.210
101.57,74.25,0.210
101.58,74.40,0.210
101.60,74.55,0.210
101.61,74.70,0.210
101.63,74.85,0.210
101.64,75.00,0.210
101.66,75.15,0.211
101.67,75.30,0.211
101.69,75.45,0.211
101.70,75.60,0.211
101.72,75.75,0.211
101.73,75.90,0.211
101.75,76.05,0.211
101.76,76.20,0.211
101.78,76.35,0.211
101.79,76.50,0.212
101.81,76.65,0.212
101.82,76.80,0.212
101.84,76.95,0.212
101.85,77.10,0.212
101.87,77.25,0.212
101.88,77.40,0.212
101.90,77.55,0.212
101.91,77.70,0.212
101.93,77.85,0.212
101.94,78.00,0.213
101.96,78.15,0.213
101.97,78.31,0.213
101.99,78.45,0.213
102.00,78.60,0.213
102.02,78.75,0.213
102.03,78.90,0.213
102.05,79.05,0.213
102.06,79.20,0.214
102.08,79.36,0.214
102.09,79.51,0.214
102.11,79.66,0.214
102.12,79.80,0.214
102.14,79.96,0.214
102.15,80.11,0.214
102.17,80.26,0.214
102.18,80.41,0.214
102.20,80.56,0.214
102.21,80.71,0.215
102.23,80.86,0.215
102.24,81.01,0.215
102.26,81.16,0.215
102.27,81.31,0.215
102.29,81.46,0.215
102.30,81.61,0.215
102.32,81.76,0.215
102.33,81.91,0.215
102.35,82.06,0.215
102.36,82.21,0.215
102.38,82.36,0.215
102.39,82.51,0.215
102.41,82.66,0.215
102.42,82.81,0.216
102.44,82.96,0.216
102.45,83.11,0.216
102.47,83.26,0.216
102.48,83.41,0.216
102.50,83.56,0.216
102.51,83.71,0.216
102.53,83.86,0.216
102.54,84.01,0.216
102.56,84.16,0.216
102.57,84.31,0.216
102.59,84.46,0.216
102.60,84.61,0.217
102.62,84.76,0.217
102.63,84.91,0.217
102.65,85.06,0.217
102.66,85.21,0.217
102.68,85.36,0.217
102.69,85.51,0.217
102.71,85.66,0.217
102.72,85.81,0.217
102.74,85.96,0.217
102.75,86.11,0.217
102.77,86.26,0.217
102.78,86.41,0.217
102.80,86.56,0.217
102.81,86.71,0.217
102.83,86.86,0.218
102.84,87.01,0.218
102.86,87.16,0.218
102.87,87.31,0.218
102.89,87.46,0.218
102.90,87.61,0.218
102.92,87.76,0.218
102.93,87.91,0.218
102.95,88.06,0.218
102.96,88.21,0.219
102.98,88.36,0.219
102.99,88.51,0.219
103.01,88.66,0.219
103.02,88.81,0.219
103.04,88.96,0.219
103.05,89.11,0.219
103.07,89.26,0.219
103.08,89.41,0.219
103.10,89.56,0.219
103.11,89.71,0.220
103.13,89.86,0.220
103.14,90.01,0.220
103.16,90.16,0.220
103.17,90.32,0.220
103.19,90.46,0.220
103.20,90.61,0.220
103.22,90.77,0.221
103.23,90.92,0.221
103.25,91.07,0.221
103.26,91.22,0.221
103.28,91.37,0.221
103.29,91.52,0.221
103.31,91.67,0.221
103.32,91.82,0.222
103.34,91.97,0.222
103.35,92.12,0.222
103.37,92.27,0.222
103.38,92.42,0.222
103.40,92.57,0.222
103.41,92.72,0.222
103.43,92.87,0.223
103.44,93.02,0.223
103.46,93.17,0.223
103.47,93.32,0.223
103.49,93.47,0.223
103.50,93.62,0.223
103.52,93.77,0.223
103.53,93.92,0.224
103.55,94.07,0.224
103.56,94.22,0.224
103.58,94.37,0.224
103.59,94.52,0.224
103.61,94.67,0.224
103.62,94.82,0.224
103.64,94.97,0.224
103.65,95.12,0.225
103.67,95.27,0.225
103.68,95.42,0.225
103.70,95.57,0.225
103.71,95.72,0.225
103.73,95.87,0.225
103.74,96.02,0.225
103.76,96.17,0.225
103.77,96.32,0.226
103.79,96.47,0.226
103.80,96.62,0.226
103.82,96.77,0.226
103.83,96.92,0.226
103.85,97.07,0.226
103.86,97.22,0.226
103.88,97.37,0.226
103.89,97.52,0.227
103.91,97.67,0.227
103.92,97.82,0.227
103.94,97.97,0.227
103.95,98.12,0.227
103.97,98.27,0.227
103.98,98.42,0.227
104.00,98.57,0.227
104.01,98.72,0.227
104.03,98.87,0.228
104.04,99.02,0.228
104.06,99.17,0.228
104.07,99.32,0.228
104.09,99.47,0.228
104.10,99.62,0.228
104.12,99.77,0.228
104.13,99.92,0.228
104.15,100.07,0.228
104.16,100.22,0.229
104.18,100.37,0.229
104.19,100.52,0.229
104.21,100.67,0.229
104.22,100.82,0.229
104.24,100.97,0.229
104.25,101.12,0.229
104.27,101.27,0.230
104.28,101.42,0.230
104.30,101.57,0.230
104.31,101.72,0.230
104.33,101.87,0.230
104.34,102.02,0.230
104.36,102.17,0.230
104.37,102.32,0.230
104.39,102.47,0.230
104.40,102.62,0.230
104.42,102.77,0.231
104.43,102.92,0.231
104.45,103.07,0.231
104.46,103.22,0.231
104.48,103.37,0.231
104.49,103.52,0.231
104.51,103.67,0.231
104.52,103.83,0.231
104.54,103.98,0.231
104.55,104.13,0.232
104.57,104.28,0.232
104.58,104.43,0.232
104.60,104.58,0.232
104.61,104.73,0.232
104.63,104.87,0.232
104.64,105.03,0.232
104.66,105.18,0.232
104.67,105.33,0.232
104.69,105.48,0.233
104.70,105.63,0.233
104.72,105.78,0.233
104.73,105.93,0.233
104.75,106.08,0.233
104.76,106.23,0.233
104.78,106.38,0.233
104.79,106.53,0.233
104.81,106.68,0.233
104.82,106.83,0.233
104.84,106.98,0.234
104.85,107.13,0.234
104.87,107.28,0.234
104.88,107.43,0.234
104.90,107.58,0.234
104.91,107.73,0.234
104.93,107.88,0.234
104.94,108.03,0.234
104.96,108.18,0.234
104.97,108.33,0.234
104.99,108.48,0.235
105.00,108.63,0.235
105.02,108.78,0.235
105.03,108.93,0.235
105.05,109.08,0.235
105.06,109.23,0.235
105.08,109.38,0.235
105.09,109.53,0.235
105.11,109.68,0.235
105.12,109.83,0.236
105.14,109.98,0.236
105.15,110.13,0.236
105.17,110.28,0.236
105.18,110.43,0.236
105.20,110.58,0.236
105.21,110.73,0.236
105.23,110.88,0.236
105.24,111.03,0.236
105.26,111.18,0.236
105.27,111.33,0.237
105.29,111.48,0.237
105.30,111.63,0.237
105.32,111.78,0.237
105.33,111.93,0.237
105.35,112.08,0.237
105.36,112.23,0.237
105.38,112.38,0.237
105.39,112.53,0.237
105.41,112.68,0.237
105.42,112.83,0.238
105.44,112.98,0.238
105.45,113.13,0.238
105.47,113.28,0.238
105.48,113.43,0.238
105.50,113.58,0.238
105.51,113.73,0.238
105.53,113.88,0.238
105.54,114.03,0.238
105.56,114.18,0.238
105.57,114.33,0.239
105.59,114.48,0.239
105.60,114.63,0.239
105.62,114.78,0.239
105.63,114.93,0.239
105.65,115.08,0.239
105.66,115.23,0.239
105.68,115.38,0.239
105.69,115.53,0.239
105.71,115.68,0.239
105.72,115.83,0.240
105.74,115.98,0.240
105.75,116.14,0.240
105.77,116.28,0.240
105.78,116.43,0.240
105.80,116.58,0.240
105.81,116.73,0.240
105.83,116.89,0.240
105.84,117.03,0.240
105.86,117.18,0.240
105.87,117.33,0.241
105.89,117.48,0.241
105.90,117.63,0.241
105.92,117.79,0.241
105.93,117.94,0.241
105.95,118.09,0.241
105.96,118.23,0.241
105.98,118.39,0.241
105.99,118.54,0.241
106.01,118.69,0.241
106.02,118.84,0.241
106.04,118.99,0.241
106.05,119.14,0.241
106.07,119.29,0.241
106.08,119.44,0.242
106.10,119.59,0.242
106.11,119.74,0.242
106.13,119.89,0.242
106.14,120.04,0.242
106.16,120.19,0.242
106.17,120.34,0.242
106.19,120.49,0.242
106.20,120.64,0.242
106.22,120.79,0.242
106.23,120.94,0.243
106.25,121.09,0.243
106.26,121.24,0.243
106.28,121.39,0.243
106.29,121.54,0.243
106.31,121.69,0.243
106.32,121.84,0.243
106.34,121.99,0.243
106.35,122.14,0.243
106.37,122.29,0.243
106.38,122.44,0.243
106.40,122.59,0.243
106.41,122.74,0.243
106.43,122.89,0.244
106.44,123.04,0.244
106.46,123.19,0.244
106.47,123.34,0.244
106.49,123.49,0.244
106.50,123.64,0.244
106.52,123.79,0.244
106.53,123.94,0.244
106.55,124.09,0.244
106.56,124.24,0.244
106.58,124.39,0.244
106.59,124.54,0.244
106.61,124.69,0.244
106.62,124.84,0.245
106.64,124.99,0.245
106.65,125.14,0.245
106.67,125.29,0.245
106.68,125.44,0.245
106.70,125.59,0.245
106.71,125.74,0.245
106.73,125.89,0.245
106.74,126.04,0.245
106.76,126.19,0.245
106.77,126.34,0.245
106.79,126.49,0.246
106.80,126.64,0.246
106.82,126.79,0.246
106.83,126.94,0.246
106.85,127.09,0.246
106.86,127.24,0.246
106.88,127.39,0.246
106.89,127.54,0.246
106.91,127.69,0.246
106.92,127.84,0.246
106.94,127.99,0.246
106.95,128.14,0.246
106.97,128.29,0.246
106.98,128.44,0.246
107.00,128.59,0.247
107.01,128.74,0.247
107.03,128.89,0.247
107.04,129.04,0.247
107.06,129.19,0.247
107.07,129.34,0.247
107.09,129.49,0.247
107.10,129.64,0.247
107.12,129.79,0.247
107.13,129.94,0.247
107.15,130.09,0.247
107.16,130.24,0.247
107.18,130.39,0.248
107.19,130.54,0.248
107.21,130.69,0.248
107.22,130.84,0.248
107.24,130.99,0.248
107.25,131.14,0.248
107.27,131.30,0.248
107.28,131.44,0.248
107.30,131.59,0.248
107.31,131.74,0.248
107.33,131.89,0.248
107.34,132.04,0.248
107.36,132.19,0.249
107.37,132.34,0.249
107.39,132.50,0.249
107.40,132.65,0.249
107.42,132.80,0.249
107.43,132.95,0.249
107.45,133.10,0.249
107.46,133.25,0.249
107.48,133.39,0.249
107.49,133.55,0.249
107.51,133.70,0.249
107.52,133.85,0.249
107.54,134.00,0.249
107.55,134.15,0.249
107.57,134.30,0.250
107.58,134.45,0.250
107.60,134.60,0.250
107.61,134.75,0.250
107.63,134.90,0.250
107.64,135.05,0.250
107.66,135.20,0.250
107.67,135.35,0.250
107.69,135.50,0.250
107.70,135.65,0.250
107.72,135.80,0.250
107.73,135.95,0.250
107.75,136.10,0.250
107.76,136.25,0.251
107.78,136.40,0.251
107.79,136.55,0.251
107.81,136.70,0.251
107.82,136.85,0.251
107.84,137.00,0.251
107.85,137.15,0.251
107.87,137.30,0.251
107.88,137.45,0.251
107.90,137.60,0.251
107.91,137.75,0.251
107.93,137.90,0.251
107.94,138.05,0.251
107.96,138.20,0.251
107.97,138.35,0.251
107.99,138.50,0.252
108.00,138.65,0.252
108.02,138.80,0.252
108.03,138.95,0.252
108.05,139.10,0.252
108.06,139.25,0.252
108.08,139.40,0.252
108.09,139.55,0.252
108.11,139.70,0.252
108.12,139.85,0.252
108.14,140.00,0.252
108.15,140.15,0.252
108.17,140.30,0.252
108.18,140.45,0.253
108.20,140.60,0.253
108.21,140.75,0.253
108.23,140.90,0.253
108.24,141.05,0.253
108.26,141.20,0.253
108.27,141.35,0.253
108.29,141.50,0.253
108.30,141.65,0.253
108.32,141.80,0.253
108.33,141.95,0.253
108.35,142.10,0.253
108.36,142.25,0.253
108.38,142.40,0.253
108.39,142.55,0.253
108.41,142.70,0.254
108.42,142.85,0.254
108.44,143.00,0.254
108.45,143.15,0.254
108.47,143.30,0.254
108.48,143.45,0.254
108.50,143.60,0.254
108.51,143.75,0.254
108.53,143.90,0.254
108.54,144.05,0.254
108.56,144.20,0.254
108.57,144.35,0.254
108.59,144.50,0.254
108.60,144.65,0.255
108.62,144.80,0.255
108.63,144.95,0.255
108.65,145.10,0.255
108.66,145.25,0.255
108.68,145.40,0.255
108.69,145.55,0.255
108.71,145.71,0.255
108.72,145.85,0.255
108.74,146.00,0.255
108.75,146.15,0.255
108.77,146.30,0.255
108.78,146.46,0.255
108.80,146.61,0.255
108.81,146.76,0.255
108.83,146.91,0.255
108.84,147.06,0.255
108.86,147.21,0.256
108.87,147.36,0.256
108.89,147.51,0.256
108.90,147.66,0.256
108.92,147.81,0.256
108.93,147.96,0.256
108.95,148.11,
108.96,148.26,
108.98,148.41,
108.99,,